Workbook

Sheet READ FIRST
A1: Testahil — Riyadh Cables Group Company (Tadawul: 4142)
A3: Companion model · Independent Valuation Study · Educational analysis · Not investment advice
A5: What this workbook is. A transparent companion to the Riyadh Cables valuation study. Every blue cell is an
A6: input; every black cell is a formula; green cells link across sheets.
A8: IT IS FORMULA-DRIVEN. Every figure derivable from a driver is a live formula, so you can change a blue cell
A9: on Assumptions and watch the model reprice: the cost of capital is built from the risk-free rate net of the
A10: sovereign spread, beta and the premium; the discount factors compound from the cost-of-debt glide; the DCF
A11: waterfall, the terminal block, the statement roll-forwards, all four lenses and every ratio chain off the
A12: same cells.
A14: THREE CLASSES OF CELL ARE PASTED VALUES, and it is worth knowing exactly which. First, audited and disclosed
A15: history — the primary record (FY2023-25 income statement and balance sheet, the FY2025 cost-stack base the
A16: ground-up build starts from), not a calculation. Second, there is NO flattened unit-build paste: the cable
... A41: Ratios · Peer & Sector.

Sheet Summary
A1: Testahil — Riyadh Cables Group Company (Tadawul: 4142)
A2: Independent valuation study · educational · not investment advice
A4: Lens | B4: Bear | C4: Base | D4: Bull | E4: Weight | G4: vs spot
A5: Discounted cash flow (primary) | B5: ='Fundamental Valuation'!B5 | C5: ='Fundamental Valuation'!C5 | D5: ='Fundamental Valuation'!D5 | E5: ='Fundamental Valuation'!E5 | G5: =C5/Assumptions!$C$5-1
A6: Relative multiples | B6: ='Fundamental Valuation'!B6 | C6: ='Fundamental Valuation'!C6 | D6: ='Fundamental Valuation'!D6 | E6: ='Fundamental Valuation'!E6 | G6: =C6/Assumptions!$C$5-1
A7: Normalised earnings power | B7: ='Fundamental Valuation'!B7 | C7: ='Fundamental Valuation'!C7 | D7: ='Fundamental Valuation'!D7 | E7: ='Fundamental Valuation'!E7 | G7: =C7/Assumptions!$C$5-1
A8: Book value and sustainable return | B8: ='Fundamental Valuation'!B8 | C8: ='Fundamental Valuation'!C8 | D8: ='Fundamental Valuation'!D8 | E8: ='Fundamental Valuation'!E8 | G8: =C8/Assumptions!$C$5-1
A9: Weighted central | C9: ='Fundamental Valuation'!C9 | G9: =C9/Assumptions!$C$5-1
A10: Terminal value as % of DCF EV | C10: =DCF!C42
A11: Expert panel median | C11: ='Fundamental Valuation'!C11
A12: Market price (anchor) | C12: =Assumptions!$C$5
A13: Market capitalisation (SAR mn) | C13: =Assumptions!$C$5*Assumptions!$C$6

Sheet Fundamental Valuation
A1: Fundamental valuation — four lenses, one field
A2: Every base value links live to its source sheet
A4: Lens | B4: Bear | C4: Base | D4: Bull | E4: Weight | F4: Contribution | G4: vs spot
A5: Discounted cash flow (primary) | B5: =DCF!C55 | C5: =DCF!C51 | D5: =DCF!C57 | E5: =Assumptions!$C$39 | F5: =C5*E5 | G5: =C5/Assumptions!$C$5-1
A6: Relative multiples | B6: ='Relative & Normalized'!C9 | C6: ='Relative & Normalized'!C8 | D6: ='Relative & Normalized'!D9 | E6: =Assumptions!$C$40 | F6: =C6*E6 | G6: =C6/Assumptions!$C$5-1
A7: Normalised earnings power | B7: ='Relative & Normalized'!C17 | C7: ='Relative & Normalized'!C16 | D7: ='Relative & Normalized'!D17 | E7: =Assumptions!$C$41 | F7: =C7*E7 | G7: =C7/Assumptions!$C$5-1
A8: Book value and sustainable return | B8: ='Relative & Normalized'!C23 | C8: ='Relative & Normalized'!C22 | D8: ='Relative & Normalized'!D23 | E8: =Assumptions!$C$42 | F8: =C8*E8 | G8: =C8/Assumptions!$C$5-1
A9: Weighted central | B9: =MIN(B5:B8) | C9: =SUM(F5:F8) | D9: =MAX(D5:D8) | E9: =SUM(E5:E8) | G9: =C9/Assumptions!$C$5-1
A11: Expert panel median (whole-model — pasted) | C11: 143.72409
A12: Market price (anchor) | C12: =Assumptions!$C$5
A14: Central contested judgement — sustained gross margin, both ways
A15: H1-2026 anchor (15.26%) — DCF value | C15: =DCF!C51
A16: FY2025-peak framing (16.0%) — DCF value (pasted re-run) | C16: 159.29871
A17: Further-compression framing (14.5%) — DCF value (pasted re-run) | C17: 132.18374

Sheet Assumptions
A1: Assumptions — every blue cell is a driver
A2: Change one and the model reprices
A4: Anchors & market
A5: Spot price (SAR) | C5: 104.8
A6: Shares outstanding (mn) | C6: 149.7175
A7: Net financial debt at FY2025 (SAR mn, disclosed) | C7: 385.17321
A8: Cost of capital — explicit window
A9: Risk-free rate (10-year SAR sukuk) | C9: 0.0485
A10: Sovereign default spread (netted out) | C10: 0.0051
A11: Equity risk premium (rating basis) | C11: 0.0501
A12: Beta (own-stock vs TASI) | C12: 1.129
A13: Cost of debt, marginal pre-tax | C13: 0.059
A14: Effective zakat and income tax rate | C14: 0.095
A15: Cost of capital — terminal
A16: Terminal risk-free rate | C16: 0.0434
A17: Terminal equity risk premium | C17: 0.0475
A18: Terminal beta | C18: 1
A19: Terminal cost of debt | C19: 0.055
A20: Terminal net-debt weight | C20: 0.05
A21: Terminal growth | C21: 0.04
A22: Forecast drivers — ground-up cost stack
A23: Cable volume index growth | C23: 0.1 | D23: 0.075 | E23: 0.065 | F23: 0.055 | G23: 0.05
A24: Metal content price growth | C24: -0.01 | D24: 0 | E24: 0.01 | F24: 0.01 | G24: 0.01
A25: Conversion cost inflation | C25: 0.03 | D25: 0.03 | E25: 0.03 | F25: 0.03 | G25: 0.03
A26: Sustained gross margin (H1-2026 anchor) | C26: 0.1526
A27: Gross-margin glide (added to anchor) | C27: 0 | D27: 0.001 | E27: 0.001 | F27: 0.0015 | G27: 0.0015
A28: Operating expenses / revenue | C28: 0.043 | D28: 0.043 | E28: 0.0425 | F28: 0.042 | G28: 0.042
A29: Depreciation and amortisation / revenue | C29: 0.0085
A30: Capital expenditure / revenue | C30: 0.019 | D30: 0.018 | E30: 0.017 | F30: 0.016 | G30: 0.016
A31: Net working capital / revenue | C31: 0.28
A32: Cost-of-debt path | C32: 0.059 | D32: 0.058 | E32: 0.057 | F32: 0.056 | G32: 0.055
A33: Forecast dividend payout ratio | C33: 0.55
A34: Yield on surplus cash | C34: 0.04
A35: Lens inputs
A36: Justified EV/EBITDA | C36: 9
A37: Justified price/earnings | C37: 13
A38: Sustainable return on equity | C38: 0.28
A39: Weight — discounted cash flow | C39: 0.45
A40: Weight — relative | C40: 0.2
A41: Weight — normalised | C41: 0.2
...

Sheet SOTP Bridge
A1: Enterprise value to equity bridge
A2: All rows link to the DCF sheet; terminal-value share shown to the reader
A4: Enterprise value | C4: =DCF!C41
A5: of which terminal value | C5: =DCF!C40
A6: terminal value as % of EV | C6: =DCF!C42
A7: Less: net financial debt | C7: =DCF!C45
A8: Add: associates + non-operating assets | C8: =DCF!C46
A9: Less: non-controlling interests | C9: =DCF!C47
A10: Equity attributable (31-Dec-2025) | C10: =DCF!C48
A11: Value per share at anchor (SAR) | C11: =DCF!C51

Sheet Segments
A1: Segments — ground-up cost-stack build
A2: Materials on the metal path; conversion on domestic inflation; gross margin is the OUTPUT
A4: SAR mn / index | B4: FY2025 | C4: FY2026E | D4: FY2027E | E4: FY2028E | F4: FY2029E | G4: FY2030E
A5: Cable volume index (FY2025=100) | B5: 100 | C5: =B5*(1+Assumptions!C$23) | D5: =C5*(1+Assumptions!D$23) | E5: =D5*(1+Assumptions!E$23) | F5: =E5*(1+Assumptions!F$23) | G5: =F5*(1+Assumptions!G$23)
A6: Metal content per unit | B6: =Assumptions!$C$47/100.0 | C6: =B6*(1+Assumptions!C$24) | D6: =C6*(1+Assumptions!D$24) | E6: =D6*(1+Assumptions!E$24) | F6: =E6*(1+Assumptions!F$24) | G6: =F6*(1+Assumptions!G$24)
A7: Conversion cost per unit | B7: =Assumptions!$C$48/100.0 | C7: =B7*(1+Assumptions!C$25) | D7: =C7*(1+Assumptions!D$25) | E7: =D7*(1+Assumptions!E$25) | F7: =E7*(1+Assumptions!F$25) | G7: =F7*(1+Assumptions!G$25)
A8: Materials (metal leg) | B8: =B5*B6 | C8: =C5*C6 | D8: =D5*D6 | E8: =E5*E6 | F8: =F5*F6 | G8: =G5*G6
A9: Conversion cost | B9: =B5*B7 | C9: =C5*C7 | D9: =D5*D7 | E9: =E5*E7 | F9: =F5*F7 | G9: =G5*G7
A10: Cost of revenue | B10: =B8+B9 | C10: =C8+C9 | D10: =D8+D9 | E10: =E8+E9 | F10: =F8+F9 | G10: =G8+G9
A11: Gross margin (target = anchor + glide) | B11: 0.16239405 | C11: =Assumptions!$C$26+Assumptions!C$27 | D11: =Assumptions!$C$26+Assumptions!D$27 | E11: =Assumptions!$C$26+Assumptions!E$27 | F11: =Assumptions!$C$26+Assumptions!F$27 | G11: =Assumptions!$C$26+Assumptions!G$27
A12: Revenue | B12: 10673.604 | C12: =C10/(1-C11) | D12: =D10/(1-D11) | E12: =E10/(1-E11) | F12: =F10/(1-F11) | G12: =G10/(1-G11)
A13: Gross profit | B13: 1733.3299 | C13: =C12-C10 | D13: =D12-D10 | E13: =E12-E10 | F13: =F12-F10 | G13: =G12-G10
A14: Operating expenses | C14: =Assumptions!C$28*C12 | D14: =Assumptions!D$28*D12 | E14: =Assumptions!E$28*E12 | F14: =Assumptions!F$28*F12 | G14: =Assumptions!G$28*G12
A15: Depreciation & amortisation | C15: =Assumptions!$C$29*C12 | D15: =Assumptions!$C$29*D12 | E15: =Assumptions!$C$29*E12 | F15: =Assumptions!$C$29*F12 | G15: =Assumptions!$C$29*G12
A16: EBIT | C16: =C13-C14 | D16: =D13-D14 | E16: =E13-E14 | F16: =F13-F14 | G16: =G13-G14
A17: EBITDA | C17: =C16+C15 | D17: =D16+D15 | E17: =E16+E15 | F17: =F16+F15 | G17: =G16+G15
A18: EBITDA margin | C18: =C17/C12 | D18: =D17/D12 | E18: =E17/E12 | F18: =F17/F12 | G18: =G17/G12
A20: FY2025 disclosed segment revenue (Note 40)
A21: Cables and wires | B21: 10414.171 | C21: =B21/B12
A22: High-voltage cables (turnkey projects) | B22: 230.83918 | C22: =B22/B12
A23: Other (telephone cables & services) | B23: 28.594413 | C23: =B23/B12

Sheet Relative & Normalized
A1: Relative, normalised-earnings & book lenses
A2: Each base value is a live formula; bear/bull vary the multiple
A4: Relative — EV/EBITDA on FY2027E
A5: FY2027E EBITDA | C5: =Segments!D17
A6: Justified EV/EBITDA | C6: =Assumptions!$C$36
A7: PV of interim FY2026-27E FCFF | C7: =DCF!C28+DCF!D28
A8: Relative lens — implied value (base) | C8: =((C6*C5*DCF!D19+C7-Assumptions!$C$7+Assumptions!$C$53+Assumptions!$C$54-Assumptions!$C$55)/Assumptions!$C$6)*DCF!$C$50-Assumptions!$C$45
A9: Bear (7.5x) / Bull (11.0x) | C9: =((7.5*C5*DCF!D19+C7-Assumptions!$C$7+Assumptions!$C$53+Assumptions!$C$54-Assumptions!$C$55)/Assumptions!$C$6)*DCF!$C$50-Assumptions!$C$45 | D9: =((11*C5*DCF!D19+C7-Assumptions!$C$7+Assumptions!$C$53+Assumptions!$C$54-Assumptions!$C$55)/Assumptions!$C$6)*DCF!$C$50-Assumptions!$C$45
A11: Normalised earnings power
A12: Mid-cycle EBITDA margin (FY2028E) | C12: =Segments!E18
A13: FY2026E revenue | C13: =Segments!C12
A14: FY2026E net interest | C14: ='Balance Sheet'!C19
A15: Normalised EPS | C15: =((C12*C13-Assumptions!$C$29*C13)-C14)*(1-Assumptions!$C$14)*(1-0.004060669885351275)/Assumptions!$C$6
A16: Normalised lens — implied value (base) | C16: =(Assumptions!$C$37*C15)*DCF!$C$50-Assumptions!$C$45
A17: Bear (10x) / Bull (16x) | C17: =(10*C15)*DCF!$C$50-Assumptions!$C$45 | D17: =(16*C15)*DCF!$C$50-Assumptions!$C$45
A19: Book value & sustainable return
A20: Book value per share | C20: =Assumptions!$C$52/Assumptions!$C$6
A21: Justified price / book | C21: =(Assumptions!$C$38-Assumptions!$C$21)/(DCF!C11-Assumptions!$C$21)
A22: Book lens — implied value (base) | C22: =(C21*C20)*DCF!$C$50-Assumptions!$C$45
A23: Bear / Bull | C23: =(((Assumptions!$C$38)-0.05-Assumptions!$C$21)/(DCF!C6-Assumptions!$C$21)*C20)*DCF!$C$50-Assumptions!$C$45 | D23: =(((Assumptions!$C$38)+0.03-Assumptions!$C$21)/(DCF!C11-Assumptions!$C$21)*C20)*DCF!$C$50-Assumptions!$C$45

Sheet DCF
A1: Discounted cash flow
A2: Cost of capital built from drivers; glide from the cost-of-debt path; terminal ROIC-consistent
A4: Cost of capital
A5: Normalised risk-free rate rf* | C5: =Assumptions!$C$9-Assumptions!$C$10
A6: Cost of equity Ke | C6: =C5+Assumptions!$C$12*Assumptions!$C$11
A7: Cost of debt after tax | C7: =Assumptions!$C$13*(1-Assumptions!$C$14)
A8: Market capitalisation | C8: =Assumptions!$C$5*Assumptions!$C$6
A9: Net-debt weight | C9: =Assumptions!$C$7/(Assumptions!$C$7+C8)
A10: WACC — explicit window | C10: =(1-C9)*C6+C9*C7
A11: Terminal cost of equity | C11: =Assumptions!$C$16+Assumptions!$C$18*Assumptions!$C$17
A12: Terminal cost of debt after tax | C12: =Assumptions!$C$19*(1-Assumptions!$C$14)
A13: WACC — terminal | C13: =(1-Assumptions!$C$20)*C11+Assumptions!$C$20*C12
A15: Discount-rate glide & waterfall
A16: SAR mn | B16: FY2026E | C16: FY2027E | D16: FY2028E | E16: FY2029E | F16: FY2030E
A17: Glide fraction (from Kd path) | C17: =(Assumptions!C$32-Assumptions!C$32)/(Assumptions!C$32-Assumptions!G$32) | D17: =(Assumptions!C$32-Assumptions!D$32)/(Assumptions!C$32-Assumptions!G$32) | E17: =(Assumptions!C$32-Assumptions!E$32)/(Assumptions!C$32-Assumptions!G$32) | F17: =(Assumptions!C$32-Assumptions!F$32)/(Assumptions!C$32-Assumptions!G$32) | G17: =(Assumptions!C$32-Assumptions!G$32)/(Assumptions!C$32-Assumptions!G$32)
A18: Forward WACC | C18: =C10-(C10-C13)*C17 | D18: =C10-(C10-C13)*D17 | E18: =C10-(C10-C13)*E17 | F18: =C10-(C10-C13)*F17 | G18: =C10-(C10-C13)*G17
A19: Discount factor | C19: =1/(1+C18) | D19: =C19/(1+D18) | E19: =D19/(1+E18) | F19: =E19/(1+F18) | G19: =F19/(1+G18)
A20: EBIT | C20: =Segments!C16 | D20: =Segments!D16 | E20: =Segments!E16 | F20: =Segments!F16 | G20: =Segments!G16
A21: NOPAT = EBIT x (1 - tax) | C21: =C20*(1-Assumptions!$C$14) | D21: =D20*(1-Assumptions!$C$14) | E21: =E20*(1-Assumptions!$C$14) | F21: =F20*(1-Assumptions!$C$14) | G21: =G20*(1-Assumptions!$C$14)
A22: + Depreciation & amortisation | C22: =Segments!C15 | D22: =Segments!D15 | E22: =Segments!E15 | F22: =Segments!F15 | G22: =Segments!G15
A23: Revenue (memo) | C23: =Segments!C12 | D23: =Segments!D12 | E23: =Segments!E12 | F23: =Segments!F12 | G23: =Segments!G12
A24: - Capital expenditure | C24: =Assumptions!C$30*C23 | D24: =Assumptions!D$30*D23 | E24: =Assumptions!E$30*E23 | F24: =Assumptions!F$30*F23 | G24: =Assumptions!G$30*G23
A25: Net working capital | C25: =Assumptions!$C$31*C23 | D25: =Assumptions!$C$31*D23 | E25: =Assumptions!$C$31*E23 | F25: =Assumptions!$C$31*F23 | G25: =Assumptions!$C$31*G23
A26: - Change in working capital | C26: =C25-Assumptions!$C$49 | D26: =D25-C25 | E26: =E25-D25 | F26: =F25-E25 | G26: =G25-F25
A27: Free cash flow to firm | C27: =C21+C22-C24-C26 | D27: =D21+D22-D24-D26 | E27: =E21+E22-E24-E26 | F27: =F21+F22-F24-F26 | G27: =G21+G22-G24-G26
A28: PV of FCFF | C28: =C27*C19 | D28: =D27*D19 | E28: =E27*E19 | F28: =F27*F19 | G28: =G27*G19
A30: Invested capital & terminal
A31: PP&E roll-forward | C31: =Assumptions!$C$50+C24-C22 | D31: =C31+D24-D22 | E31: =D31+E24-E22 | F31: =E31+F24-F22 | G31: =F31+G24-G22
A32: Invested capital = NWC + PP&E | C32: =C25+C31 | D32: =D25+D31 | E32: =E25+E31 | F32: =F25+F31 | G32: =G25+G31
A33: ROIC = NOPAT / invested capital | C33: =C21/C32 | D33: =D21/D32 | E33: =E21/E32 | F33: =F21/F32 | G33: =G21/G32
A35: PV of explicit FCFF (5 years) | C35: =SUM(C28:G28)
A36: Terminal ROIC | C36: =G21*(1+Assumptions!$C$21)/G32
A37: Terminal reinvestment rate = g / ROIC | C37: =Assumptions!$C$21/C36
A38: Terminal NOPAT (next year) | C38: =G21*(1+Assumptions!$C$21)
A39: Terminal value | C39: =C38*(1-C37)/(C13-Assumptions!$C$21)
A40: PV of terminal value | C40: =C39*G19
A41: Enterprise value | C41: =C35+C40
A42: Terminal value as % of EV | C42: =C40/C41
A44: Enterprise value to equity
A45: Less: net financial debt | C45: =-Assumptions!$C$7
...

Sheet Income Statement
A1: Income statement — 3y audited + 5y forecast
A2: SAR mn
A4: SAR mn | B4: FY2023 | C4: FY2024 | D4: FY2025 | E4: FY26E | F4: FY27E | G4: FY28E | H4: FY29E | I4: FY30E
A5: Revenue | C5: 7825.3781 | D5: 9007.3609 | E5: 10673.604 | F5: =Segments!C12 | G5: =Segments!D12 | H5: =Segments!E12 | I5: =Segments!F12 | J5: =Segments!G12
A6: Gross profit | C6: 972.76344 | D6: 1286.5224 | E6: 1733.3299 | F6: =Segments!C13 | G6: =Segments!D13 | H6: =Segments!E13 | I6: =Segments!F13 | J6: =Segments!G13
A7: Gross margin | C7: =C6/C5 | D7: =D6/D5 | E7: =E6/E5 | F7: =F6/F5 | G7: =G6/G5 | H7: =H6/H5 | I7: =I6/I5 | J7: =J6/J5
A8: Operating expenses | C8: =C6-C11 | D8: =D6-D11 | E8: =E6-E11 | F8: =Segments!C14 | G8: =Segments!D14 | H8: =Segments!E14 | I8: =Segments!F14 | J8: =Segments!G14
A9: EBITDA | C9: =C11+C10 | D9: =D11+D10 | E9: =E11+E10 | F9: =Segments!C17 | G9: =Segments!D17 | H9: =Segments!E17 | I9: =Segments!F17 | J9: =Segments!G17
A10: Depreciation & amortisation | C10: 68.643861 | D10: 68.643861 | E10: 85.395637 | F10: =Segments!C15 | G10: =Segments!D15 | H10: =Segments!E15 | I10: =Segments!F15 | J10: =Segments!G15
A11: Operating profit (EBIT) | C11: 647.60678 | D11: 968.43915 | E11: 1266.6368 | F11: =Segments!C16 | G11: =Segments!D16 | H11: =Segments!E16 | I11: =Segments!F16 | J11: =Segments!G16
A12: Net finance cost | C12: -89.014334 | D12: -87.666699 | E12: -74.153995 | F12: =-'Balance Sheet'!C19 | G12: =-'Balance Sheet'!D19 | H12: =-'Balance Sheet'!E19 | I12: =-'Balance Sheet'!F19 | J12: =-'Balance Sheet'!G19
A13: Profit before zakat | C13: =C11+C12 | D13: =D11+D12 | E13: =E11+E12 | F13: =F11+F12 | G13: =G11+G12 | H13: =H11+H12 | I13: =I11+I12 | J13: =J11+J12
A14: Zakat & income tax | C14: -39.126206 | D14: -63.891298 | E14: -107.68179 | F14: =-F13*Assumptions!$C$14 | G14: =-G13*Assumptions!$C$14 | H14: =-H13*Assumptions!$C$14 | I14: =-I13*Assumptions!$C$14 | J14: =-J13*Assumptions!$C$14
A15: Profit for the year | C15: 518.49262 | D15: 816.88116 | E15: 1084.8011 | F15: =F13+F14 | G15: =G13+G14 | H15: =H13+H14 | I15: =I13+I14 | J15: =J13+J14
A16: Attributable profit | E16: 1080.396 | F16: ='Balance Sheet'!C22 | G16: ='Balance Sheet'!D22 | H16: ='Balance Sheet'!E22 | I16: ='Balance Sheet'!F22 | J16: ='Balance Sheet'!G22

Sheet Balance Sheet
A1: Balance sheet — audited history + forecast roll-forward
A2: SAR mn; FY2023-25 audited, FY2026E-30E rolled forward from the cash flow
A4: SAR mn | B4: FY2023 | C4: FY2024 | D4: FY2025 | E4: FY26E | F4: FY27E | G4: FY28E | H4: FY29E | I4: FY30E
A5: Property, plant & equipment | C5: 1206.6599 | D5: 1336.0389 | E5: 1491.8631 | F5: =DCF!C31 | G5: =DCF!D31 | H5: =DCF!E31 | I5: =DCF!F31 | J5: =DCF!G31
A6: Inventory | C6: 1909.1114 | D6: 2126.0367 | E6: 2411.0493
A7: Trade & other receivables | C7: 1418.9208 | D7: 2112.0986 | E7: 2712.6771
A8: Cash & equivalents | C8: 150.05163 | D8: 90.672725 | E8: 236.04301
A9: Total assets | C9: 4830.9291 | D9: 5811.5841 | E9: 7281.5817
A10: Gross borrowings incl. leases | C10: 730.61184 | D10: 440.4456 | E10: 621.21622 | F10: =Assumptions!$C$51 | G10: =Assumptions!$C$51 | H10: =Assumptions!$C$51 | I10: =Assumptions!$C$51 | J10: =Assumptions!$C$51
A11: Trade & other payables | C11: 1220.3877 | D11: 2040.7072 | E11: 2190.4675
A12: Net working capital | C12: 2107.6446 | D12: 2197.4281 | E12: 2933.2589 | F12: =DCF!C25 | G12: =DCF!D25 | H12: =DCF!E25 | I12: =DCF!F25 | J12: =DCF!G25
A13: Net financial debt | C13: 580.56021 | D13: 349.77287 | E13: 385.17321 | F13: =C24 | G13: =D24 | H13: =E24 | I13: =F24 | J13: =G24
A14: Equity attributable | D14: 2624.3537 | E14: 3246.1369 | F14: =C25 | G14: =D25 | H14: =E25 | I14: =F25 | J14: =G25
A16: Forecast roll-forward (feeds the income statement & lenses)
A17: Net debt, start of year | C17: =Assumptions!$C$7 | D17: =C24 | E17: =D24 | F17: =E24 | G17: =F24
A18: Surplus cash | C18: =Assumptions!$C$51-C17 | D18: =Assumptions!$C$51-D17 | E18: =Assumptions!$C$51-E17 | F18: =Assumptions!$C$51-F17 | G18: =Assumptions!$C$51-G17
A19: Net interest | C19: =Assumptions!C$32*Assumptions!$C$51-Assumptions!$C$34*MAX(C18,0) | D19: =Assumptions!D$32*Assumptions!$C$51-Assumptions!$C$34*MAX(D18,0) | E19: =Assumptions!E$32*Assumptions!$C$51-Assumptions!$C$34*MAX(E18,0) | F19: =Assumptions!F$32*Assumptions!$C$51-Assumptions!$C$34*MAX(F18,0) | G19: =Assumptions!G$32*Assumptions!$C$51-Assumptions!$C$34*MAX(G18,0)
A20: EBIT (from DCF) | C20: =DCF!C20 | D20: =DCF!D20 | E20: =DCF!E20 | F20: =DCF!F20 | G20: =DCF!G20
A21: Profit before zakat | C21: =C20-C19 | D21: =D20-D19 | E21: =E20-E19 | F21: =F20-F19 | G21: =G20-G19
A22: Attributable profit | C22: =C21*(1-Assumptions!$C$14)*(1-0.004060669885351275) | D22: =D21*(1-Assumptions!$C$14)*(1-0.004060669885351275) | E22: =E21*(1-Assumptions!$C$14)*(1-0.004060669885351275) | F22: =F21*(1-Assumptions!$C$14)*(1-0.004060669885351275) | G22: =G21*(1-Assumptions!$C$14)*(1-0.004060669885351275)
A23: Dividend | C23: =Assumptions!$C$33*C22 | D23: =Assumptions!$C$33*D22 | E23: =Assumptions!$C$33*E22 | F23: =Assumptions!$C$33*F22 | G23: =Assumptions!$C$33*G22
A24: Net debt, end of year | C24: =C17-(DCF!C27-C19*(1-Assumptions!$C$14))+C23 | D24: =D17-(DCF!D27-D19*(1-Assumptions!$C$14))+D23 | E24: =E17-(DCF!E27-E19*(1-Assumptions!$C$14))+E23 | F24: =F17-(DCF!F27-F19*(1-Assumptions!$C$14))+F23 | G24: =G17-(DCF!G27-G19*(1-Assumptions!$C$14))+G23
A25: Equity attributable | C25: =Assumptions!$C$52+C22-C23 | D25: =C25+D22-D23 | E25: =D25+E22-E23 | F25: =E25+F22-F23 | G25: =F25+G22-G23

Sheet Cash Flow
A1: Cash flow — free cash flow to the firm
A2: SAR mn; the DCF waterfall as a statement
A4: SAR mn | B4: FY26E | C4: FY27E | D4: FY28E | E4: FY29E | F4: FY30E
A5: NOPAT | C5: =DCF!C21 | D5: =DCF!D21 | E5: =DCF!E21 | F5: =DCF!F21 | G5: =DCF!G21
A6: + Depreciation & amortisation | C6: =DCF!C22 | D6: =DCF!D22 | E6: =DCF!E22 | F6: =DCF!F22 | G6: =DCF!G22
A7: - Capital expenditure | C7: =-DCF!C24 | D7: =-DCF!D24 | E7: =-DCF!E24 | F7: =-DCF!F24 | G7: =-DCF!G24
A8: - Change in working capital | C8: =-DCF!C26 | D8: =-DCF!D26 | E8: =-DCF!E26 | F8: =-DCF!F26 | G8: =-DCF!G26
A9: Free cash flow to firm | C9: =C5+C6+C7+C8 | D9: =D5+D6+D7+D8 | E9: =E5+E6+E7+E8 | F9: =F5+F6+F7+F8 | G9: =G5+G6+G7+G8
A10: Discount factor | C10: =DCF!C19 | D10: =DCF!D19 | E10: =DCF!E19 | F10: =DCF!F19 | G10: =DCF!G19
A11: PV of FCFF | C11: =C9*C10 | D11: =D9*D10 | E11: =E9*E10 | F11: =F9*F10 | G11: =G9*G10

Sheet Summary Financials
A1: Summary financials
A2: SAR mn; forecast links to the model
A4: SAR mn | B4: FY26E | C4: FY27E | D4: FY28E | E4: FY29E | F4: FY30E
A5: Revenue | C5: =DCF!C23 | D5: =DCF!D23 | E5: =DCF!E23 | F5: =DCF!F23 | G5: =DCF!G23
A6: EBITDA | C6: =Segments!C17 | D6: =Segments!D17 | E6: =Segments!E17 | F6: =Segments!F17 | G6: =Segments!G17
A7: NOPAT | C7: =DCF!C21 | D7: =DCF!D21 | E7: =DCF!E21 | F7: =DCF!F21 | G7: =DCF!G21
A8: FCFF | C8: =DCF!C27 | D8: =DCF!D27 | E8: =DCF!E27 | F8: =DCF!F27 | G8: =DCF!G27
A9: Invested capital | C9: =DCF!C32 | D9: =DCF!D32 | E9: =DCF!E32 | F9: =DCF!F32 | G9: =DCF!G32
A10: ROIC | C10: =DCF!C33 | D10: =DCF!D33 | E10: =DCF!E33 | F10: =DCF!F33 | G10: =DCF!G33

Sheet Monte Carlo
A1: Monte Carlo — calibrated forward price cone
A2: Engine output (50,000 paths, seed 42); pasted whole-model re-runs, not driver formulas
A4: Percentile | B4: 1-month | C4: 3-month
A5: P5 | B5: 87.21321 | C5: 76.54889
A6: P25 | B6: 97.611262 | C6: 92.869099
A7: P50 | B7: 104.7866 | C7: 105.05937
A8: P75 | B8: 112.61609 | C8: 118.70948
A9: P95 | B9: 126.17671 | C9: 144.05634
A10: Spot | B10: 104.8 | C10: 104.8
A11: P(above spot) | B11: 0.4997 | C11: 0.50542
A12: Annualised vol | B12: 0.3614704 | C12: 0.36705756
A14: 3-month calibration: PARITY vs the random walk; coverage 0.70/0.80/0.90; PIT mean 0.49.

Sheet Sensitivity
A1: Sensitivity — whole-model re-runs (pasted)
A2: Each cell is a complete revaluation and does NOT redraw when a driver changes
A4: DCF value per share: terminal WACC (rows) x terminal growth (cols)
B5: g=2% | C5: g=3% | D5: g=4% | E5: g=5% | F5: g=6%
A6: WACC_t=6.88% | B6: 161.68702 | C6: 191.87364 | D6: 242.792 | E6: 328.60546 | F6: 316.28987
A7: WACC_t=7.88% | B7: 134.95425 | C7: 153.64627 | D7: 181.81784 | E7: 229.32849 | F7: 309.29395
A8: WACC_t=8.88% | B8: 115.9876 | C8: 128.40804 | D8: 145.80182 | E8: 172.01 | F8: 216.2003
A9: WACC_t=9.88% | B9: 101.83188 | C9: 110.49857 | D9: 122.01969 | E9: 138.14846 | F9: 162.44348
A10: WACC_t=10.88% | B10: 90.862448 | C10: 97.12921 | D10: 105.14033 | E10: 115.78511 | F10: 130.68117
A12: Beta sensitivity (DCF value/share)
A13: 0.7 | B13: 209.30358
A14: 0.9 | B14: 164.19729
A15: 1.129 | B15: 130.90061
A16: 1.3 | B16: 113.26627
A17: 1.5 | B17: 97.508284
A19: Metal price x sensitivity (DCF value/share)
A20: 0.85 | B20: 158.40026
A21: 0.925 | B21: 152.08968
A22: 1.0 | B22: 145.80182
A23: 1.075 | B23: 139.53415
A24: 1.15 | B24: 133.28458
A26: Sustained gross margin sensitivity (DCF value/share)
A27: 0.14 | B27: 123.35596
A28: 0.145 | B28: 132.18374
A29: 0.1526 | B29: 145.80182
A30: 0.155 | B30: 150.15325
A31: 0.16 | B31: 159.29871
A33: Volume x sensitivity (DCF value/share)
A34: 0.9 | B34: 132.95543
A35: 0.95 | B35: 139.38345
A36: 1.0 | B36: 145.80182
A37: 1.05 | B37: 152.21125
A38: 1.1 | B38: 158.61238
A40: Net working capital / revenue sensitivity (DCF value/share)
A41: 0.24 | B41: 151.77451
A42: 0.26 | B42: 148.78817
A43: 0.28 | B43: 145.80182
A44: 0.3 | B44: 142.81548
A45: 0.32 | B45: 139.82913

Sheet Per-Share & Ratios
A1: Per-share & ratios
B4: FY2025 | C4: FY26E | D4: FY27E | E4: FY28E | F4: FY29E | G4: FY30E
A5: EPS (SAR) | B5: 7.2162308 | C5: ='Balance Sheet'!C22/Assumptions!$C$6 | D5: ='Balance Sheet'!D22/Assumptions!$C$6 | E5: ='Balance Sheet'!E22/Assumptions!$C$6 | F5: ='Balance Sheet'!F22/Assumptions!$C$6 | G5: ='Balance Sheet'!G22/Assumptions!$C$6
A6: Book value per share (SAR) | B6: =Assumptions!$C$52/Assumptions!$C$6 | C6: ='Balance Sheet'!F14/Assumptions!$C$6 | D6: ='Balance Sheet'!G14/Assumptions!$C$6 | E6: ='Balance Sheet'!H14/Assumptions!$C$6 | F6: ='Balance Sheet'!I14/Assumptions!$C$6 | G6: ='Balance Sheet'!J14/Assumptions!$C$6
A7: ROE (%) | B7: 0.36807692
A8: Net debt / EBITDA (x) | B8: =Assumptions!$C$7/(Segments!B10*0+1352.0324810000002) | C8: ='Balance Sheet'!F13/Segments!C17 | D8: ='Balance Sheet'!G13/Segments!D17 | E8: ='Balance Sheet'!H13/Segments!E17 | F8: ='Balance Sheet'!I13/Segments!F17 | G8: ='Balance Sheet'!J13/Segments!G17
A9: Trailing EV/EBITDA (x) | B9: 11.889927
A10: Trailing P/E (x) | B10: 14.522817

Sheet Peer & Sector
A1: Peer & sector context
A2: Cross-check multiples only — never a source for the subject historicals
A4: Peer | B4: Market | C4: Fwd EV/EBITDA | D4: Note
A5: Riyadh Cables (subject) | B5: Tadawul | C5: 11.889927 | D5: trailing; ~14.5x P/E
A6: Prysmian | B6: Milan | C6: 8.5 | D6: global cable major
A7: Nexans | B7: Paris | C7: 7.5 | D7: global cable major
A8: Polycab India | B8: NSE | C8: 26 | D8: high-growth EM premium
A9: KEI Industries | B9: NSE | C9: 24 | D9: high-growth EM premium
A10: Ducab (private) | B10: UAE | D10: regional peer, not listed
A12: Justified EV/EBITDA applied in the relative lens: 9.0x (mid-range, single-country discount).
