Workbook

Sheet READ FIRST
A1: Testahil — Electro Cable Egypt Co. S.A.E. (EGX: ELEC)
A3: Companion model · Independent Valuation Study · Educational analysis · Not investment advice
A5: What this workbook is. A transparent companion to the ELEC valuation study. Every blue cell is an input; every
A6: black cell is a formula; green cells link across sheets. All inputs live on the Assumptions sheet — change one
A7: (volumes, copper, the EGP path, conversion EBITDA per tonne, the working-capital intensity, the net-debt
A8: anchor) and the whole model reprices. The forecast is a bottom-up TONNAGE build: revenue = volume x (LME x
A9: EGP x 1.387 fabrication uplift); EBITDA = volume x conversion EBITDA/t. Margins are outputs, not inputs.
A11: What it is not. It is not investment advice, a recommendation, or a price target. Values are model outputs
A12: shown as ranges. The preparer is not licensed by any securities regulator and may hold a position.
A14: Sourcing note, up front. ELEC's audited statements were unreachable through available channels. Headline
A15: revenue/profit/assets are multiply-sourced from bourse-disclosure reporting; several lines (interest, capex,
A16: the working-capital split, the FY25 net-debt anchor) are DERIVED — each is annotated where it appears and
... A26: Balance Sheet · Cash Flow · Summary Financials · Monte Carlo · Sensitivity · Per-Share & Ratios · Peer & Sector.

Sheet Summary
A1: Valuation summary — Electro Cable Egypt (EGX: ELEC)
A2: Four-lens fair value vs spot. Base cells link live; bear/bull are engine scenario outputs (study §1.5).
B5: Bear | C5: Base | D5: Bull | E5: Weight
A6: FCFF DCF (glide schedule) | B6: 0.01 | C6: =DCF!B33 | D6: 1.02 | E6: =Assumptions!B35
A7: Relative (EV/EBITDA) | B7: 0.05 | C7: ='Relative & Normalized'!C6 | D7: 0.05 | E7: =Assumptions!B36
A8: Normalized earnings | B8: 0.24 | C8: ='Relative & Normalized'!C7 | D8: 1.36 | E8: =Assumptions!B37
A9: Book / replacement | B9: 0.48 | C9: ='Relative & Normalized'!C9 | D9: 1.33 | E9: =Assumptions!B38
A10: Weighted central | B10: =SUMPRODUCT(B6:B9,$E$6:$E$9) | C10: =SUMPRODUCT(C6:C9,$E$6:$E$9) | D10: =SUMPRODUCT(D6:D9,$E$6:$E$9)
A12: Spot price (EGP) | B12: =Assumptions!B5
A13: Upside / (downside) to central base | B13: =C10/Assumptions!B5-1
A14: Terminal value share of DCF enterprise value | B14: =DCF!B27
A16: Read: meaningfully overvalued — the price capitalises devaluation-era earnings; the swing factors are working-capital collection, margin normalisation, and the easing path.

Sheet Fundamental Valuation
A1: Fundamental valuation — football-field data
A2: Bear/base/bull per lens (links to Summary).
A5: Lens | B5: Bear | C5: Base | D5: Bull
A6: FCFF DCF (glide schedule) | B6: =Summary!B6 | C6: =Summary!C6 | D6: =Summary!D6
A7: Relative (EV/EBITDA) | B7: =Summary!B7 | C7: =Summary!C7 | D7: =Summary!D7
A8: Normalized earnings | B8: =Summary!B8 | C8: =Summary!C8 | D8: =Summary!D8
A9: Book / replacement | B9: =Summary!B9 | C9: =Summary!C9 | D9: =Summary!D9
A10: Weighted central | B10: =Summary!B10 | C10: =Summary!C10 | D10: =Summary!D10
A11: Spot | B11: =Assumptions!B5

Sheet Assumptions
A1: Assumptions — the single input layer
A2: All blue cells are inputs. Every other sheet links here.
A4: ANCHORS
A5: Spot price (EGP/share) | B5: 2.08 | C5: 2026-09-03 close, uploaded EGX history
A6: Shares outstanding (mn) | B6: 3313.5404 | C6: Mubasher paid-in capital 662,708,074.60 / par 0.20; EPS arithmetic confirms
A7: Tax rate | B7: 0.225 | C7: PwC Tax Summaries Egypt — 22.5% unchanged
A8: COST OF CAPITAL — sovereign double-count removed; sliding schedule below
A9: Egypt 10Y local yield (observed) | B9: 0.2231 | C9: investing.com print 21-Jul-2026; May-26 window avg 21.3% corroborates
A10: Sovereign default spread (CDS-implied) | B10: 0.034 | C10: Damodaran Jan-2026 original file; market 5Y CDS ~330bp May-26
A11: rf* for the equity build | B11: =B9-B10
A12: ERP — Egypt, CDS-based (primary) | B12: 0.0941 | C12: Damodaran ORIGINAL ctryprem, Egypt row, Jan-2026 (rating basis 13.94% in sensitivity)
A13: Beta (own weekly regression, 5yr) | B13: 0.964 | C13: vs 30-name equal-weight EGX composite: R2 0.222, n=257, SE 0.113, CI90 [0.78,1.15]
A14: Ke = rf* + beta × ERP | B14: =B11+B13*B12
A15: Kd pre-tax (marginal EGP) | B15: 0.22 | C15: Corridor + credit margin; effective-rate checks 23.5% (FY24) / 22.1% (FY25, triangulated debt path) inside 150bp
A16: Kd after tax | B16: =B15*(1-B7)
A17: Market cap (spot × shares) | B17: =B5*B6
A18: Total debt for weights (FY25, triangulated) | B18: 10465 | C18: Balance-sheet residual: disclosed assets 16,460 − rolled equity 4,100 − non-debt liabilities ~1,890; = 96% of the disclosed 10.9bn facilities
A19: Equity weight E/(D+E) | B19: =B17/(B17+B18)
A20: WACC — explicit window | B20: =B19*B14+(1-B19)*B16
A21: Terminal rf (norm-built) | B21: 0.105 | C21: House terminal inflation 7.00% + the 3.5pp real-rate convention (engine/macro_paths/EG.json)
A22: Terminal ERP (normalised) | B22: 0.07 | C22: Below the crisis-era 9.41%, toward the B-rating norm
A23: Terminal Ke | B23: =B21+B13*B22
A24: Terminal Kd | B24: 0.15 | C24: Egyptian long-run corporate norm 14-16%, midpoint
A25: WACC — terminal (normalized structure, see B56) | B25: =(1-$B$56)*B23+$B$56*B24*(1-B7)
A26: Terminal growth g | B26: 0.07 | C26: DERIVED, not typed: zero stated real growth on the house terminal inflation of 7.00% (engine/macro_paths/EG.json)
A27: BRIDGE
A28: Net debt (FY25, triangulated) | B28: 9805 | C28: Roll-forward from FY24 audited comparatives: drawn debt 10,465 − cash ~665; two methods agree ~9,800, facilities-as-drawn 10,235 is the upper check; range 9,120-10,360 (~±EGP 0.19/sh) — see study §1.6
A29: Non-controlling interests | B29: 0 | C29: Consolidated-vs-attributable gap ~1.1mn FY25 — immaterial
A30: LENS INPUTS
A31: EV/EBITDA multiple (base) | B31: 5.5 | C31: SWDY ~7.1x COMPUTED from its FY25 filing (prior 6.0x aggregator print did not reproduce); discount for leverage/concentration
A32: Normalized P/E (base) | B32: 6.5 | C32: SWDY 11.3x COMPUTED (prior 10.4x did not reproduce); ~42% discount held deliberately deep
A33: Sustainable ROE (book lens) | B33: 0.14 | C33: Normalized NP ~700 on ~4.6-5bn book
A34: Equity FY25e (book, derived) | B34: 4100 | C34: FY24 equity 3,600 + FY25 NP 500.3, no dividends
A35: Weight: DCF | B35: 0.4
A36: Weight: Relative | B36: 0.2
A37: Weight: Normalized | B37: 0.2
A38: Weight: Book | B38: 0.2
A39: FORECAST DRIVERS (FY26E-FY30E)
A40: Driver \ year | C40: FY26E | D40: FY27E | E40: FY28E | F40: FY29E | G40: FY30E
A41: Volume (kt) | C41: 10.4 | D41: 11.9 | E41: 13.4 | F41: 14.8 | G41: 16 | H41: Q1-26 implied ~2.4kt/qtr sets FY26E (~42% util.); recovery to 64% by FY30E on the grid-capex cycle
...

Sheet SOTP Bridge
A1: EV → equity bridge
A2: Single-business company: the bridge is the DCF EV less net claims. Links to DCF / Assumptions.
A5: Core enterprise value (DCF) | B5: =DCF!B26
A6: + Surplus / non-core assets | B6: 0
A7: − Net debt (FY25: triangulated — study §1.6) | B7: =-Assumptions!B28
A8: − Non-controlling interests | B8: =-Assumptions!B29
A9: Equity value — intrinsic (may be negative) | B9: =B5+B6+B7+B8
A10: Equity value — floored (limited liability) | B10: =MAX(B9,0)
A11: per share (EGP) — floored | B11: =MAX(B10/Assumptions!B6,0.01)
A12: Upside / (downside) vs spot | B12: =B11/Assumptions!B5-1
A14: Market-implied read (the same bridge run backwards)
A15: Market cap at spot | B15: =Assumptions!B17
A16: + Net debt = market-implied EV | B16: =B15+Assumptions!B28
A17: Market-implied EV / FY27E EBITDA | B17: =B16/Segments!F15
A18: Market-implied EV / FY25 EBITDA (windfall-vintage) | B18: =B16/Segments!D15
A20: The market pays a peer-level multiple on windfall-vintage EBITDA — the study’s central observation.

Sheet Segments
A1: Segment view — the revenue and margin build
A2: Single-segment build (power ~2/3, telecom ~1/3 of revenue — memo estimate; no segment disclosure). Forecast links to Assumptions.
B4: FY23 | C4: FY24 | D4: FY25 | E4: FY26E | F4: FY27E | G4: FY28E | H4: FY29E | I4: FY30E
A6: Volume (kt) — implied hist / driver fwd | B6: 24 | C6: 24 | D6: 15.8 | E6: =Assumptions!C41 | F6: =Assumptions!D41 | G6: =Assumptions!E41 | H6: =Assumptions!F41 | I6: =Assumptions!G41
A7: Utilization (÷ 25 kt capacity) | B7: =B6/Assumptions!$B$57 | C7: =C6/Assumptions!$B$57 | D7: =D6/Assumptions!$B$57 | E7: =E6/Assumptions!$B$57 | F7: =F6/Assumptions!$B$57 | G7: =G6/Assumptions!$B$57 | H7: =H6/Assumptions!$B$57 | I7: =I6/Assumptions!$B$57
A8: LME copper (USD/t, avg) | B8: 8478 | C8: 9147 | D8: 10000 | E8: =Assumptions!C42 | F8: =Assumptions!D42 | G8: =Assumptions!E42 | H8: =Assumptions!F42 | I8: =Assumptions!G42
A9: EGP/USD (avg) | B9: 30.7 | C9: 45.3 | D9: 49.5 | E9: =Assumptions!C43 | F9: =Assumptions!D43 | G9: =Assumptions!E43 | H9: =Assumptions!F43 | I9: =Assumptions!G43
A10: Price per tonne (EGP, = Cu × EGP × k) | B10: =B8*B9*Assumptions!$B$55 | C10: =C8*C9*Assumptions!$B$55 | D10: =D8*D9*Assumptions!$B$55 | E10: =E8*E9*Assumptions!$B$55 | F10: =F8*F9*Assumptions!$B$55 | G10: =G8*G9*Assumptions!$B$55 | H10: =H8*H9*Assumptions!$B$55 | I10: =I8*I9*Assumptions!$B$55
A11: Revenue (= volume × price/t) | B11: 8673.4 | C11: 13778.2 | D11: 10819 | E11: =E6*E10/1000 | F11: =F6*F10/1000 | G11: =G6*G10/1000 | H11: =H6*H10/1000 | I11: =I6*I10/1000
A12: memo: power cables (~2/3, est.) | E12: =E11*2/3 | F12: =F11*2/3 | G12: =G11*2/3 | H12: =H11*2/3 | I12: =I11*2/3
A13: memo: telecom & other (~1/3, est.) | E13: =E11/3 | F13: =F11/3 | G13: =G11/3 | H13: =H11/3 | I13: =I11/3
A14: Conversion EBITDA per tonne (k EGP/t) | B14: 111 | C14: 146 | D14: 182 | E14: =Assumptions!C44 | F14: =Assumptions!D44 | G14: =Assumptions!E44 | H14: =Assumptions!F44 | I14: =Assumptions!G44
A15: EBITDA (= volume × EBITDA/t) | B15: 2661.0364 | C15: 3490 | D15: 2871.2943 | E15: =E6*E14 | F15: =F6*F14 | G15: =G6*G14 | H15: =H6*H14 | I15: =I6*I14
A16: EBITDA margin — OUTPUT | B16: =B15/B11 | C16: =C15/C11 | D16: =D15/D11 | E16: =E15/E11 | F16: =F15/F11 | G16: =G15/G11 | H16: =H15/H11 | I16: =I15/I11
A17: D&A | B17: 60.7138 | C17: 90 | D17: 75.733 | E17: =E11*Assumptions!C46 | F17: =F11*Assumptions!D46 | G17: =G11*Assumptions!E46 | H17: =H11*Assumptions!F46 | I17: =I11*Assumptions!G46
A18: EBIT | B18: 2600.3226 | C18: 3400 | D18: 2795.5613 | E18: =E15-E17 | F18: =F15-F17 | G18: =G15-G17 | H18: =H15-H17 | I18: =I15-I17
A20: BOTTOM-UP TONNAGE BUILD. Historical volumes are IMPLIED (revenue ÷ [LME × EGP × k]; k = 1.387 from the industry copper-share norm; FY24 back-solves to 24.0kt = 96% of stated capacity — the validation). Historical conversion EBITDA/t: 111 (FY23) / 146 (FY24) / 182 (FY25, copper-gain inflated) / 11 (Q1-26 annualized ~9.5kt, 38% utilization). Q1-26 disclosed: GM 5.7%, operating profit ~0. Forecast volumes/copper/EGP/EBITDA-per-t are Assumptions drivers; margins are outputs. Capacity single-sourced, possibly parent-only — utilization indicative.
A21: FY23 note: at the 2023 parallel rate (~38 vs official 30.7) implied volume is 19.4kt (78%) — the honest range for that year.

Sheet Relative & Normalized
A1: Relative & normalized-earnings lenses
A2: Links to Assumptions / Segments / Balance Sheet.
A5: Lens | B5: Workings | C5: EGP/share
A6: Relative EV/EBITDA | B6: FY27E EBITDA × multiple − net debt end-FY26E, /sh | C6: =MAX((Assumptions!B31*Segments!F15-'Balance Sheet'!D11)/Assumptions!B6,0.05)
A7: Normalized earnings power | B7: FY28E EBIT − 15% money on 6,000 mid-cycle ND, × (1−t), × P/E, /sh | C7: =(Segments!G18-Assumptions!B24*6000)*(1-Assumptions!B7)*Assumptions!B32/Assumptions!B6
A8: normalized EPS (EGP) | C8: =(Segments!G18-Assumptions!B24*6000)*(1-Assumptions!B7)/Assumptions!B6
A9: Book lens: justified P/B × BVPS | B9: (ROE−g)/(Ke_term−g) × FY25e book/sh | C9: =MAX((Assumptions!B33-Assumptions!B26)/(Assumptions!B23-Assumptions!B26),0.1)*Assumptions!B34/Assumptions!B6
A11: P/B at spot (memo) | C11: =Assumptions!B5/(Assumptions!B34/Assumptions!B6)

Sheet DCF
A1: DCF — explicit 5-year FCFF on the forward-WACC schedule
A2: Revenue -> EBITDA -> D&A -> EBIT -> NOPAT -> +D&A -> -Capex -> -dWC -> FCFF -> forward WACC -> cumulative DF -> PV. Terminal is ROIC-consistent.
B4: FY26E | C4: FY27E | D4: FY28E | E4: FY29E | F4: FY30E
A6: Revenue | B6: =Segments!E11 | C6: =Segments!F11 | D6: =Segments!G11 | E6: =Segments!H11 | F6: =Segments!I11
A7: EBITDA | B7: =Segments!E15 | C7: =Segments!F15 | D7: =Segments!G15 | E7: =Segments!H15 | F7: =Segments!I15
A8: − D&A | B8: =-Segments!E17 | C8: =-Segments!F17 | D8: =-Segments!G17 | E8: =-Segments!H17 | F8: =-Segments!I17
A9: EBIT | B9: =Segments!E18 | C9: =Segments!F18 | D9: =Segments!G18 | E9: =Segments!H18 | F9: =Segments!I18
A10: NOPAT = EBIT × (1 − tax) | B10: =B9*(1-Assumptions!$B$7) | C10: =C9*(1-Assumptions!$B$7) | D10: =D9*(1-Assumptions!$B$7) | E10: =E9*(1-Assumptions!$B$7) | F10: =F9*(1-Assumptions!$B$7)
A11: + D&A | B11: =Segments!E17 | C11: =Segments!F17 | D11: =Segments!G17 | E11: =Segments!H17 | F11: =Segments!I17
A12: − Capex | B12: =-Assumptions!C45 | C12: =-Assumptions!D45 | D12: =-Assumptions!E45 | E12: =-Assumptions!F45 | F12: =-Assumptions!G45
A13: Net working capital | B13: =B6*Assumptions!C47 | C13: =C6*Assumptions!D47 | D13: =D6*Assumptions!E47 | E13: =E6*Assumptions!F47 | F13: =F6*Assumptions!G47
A14: − Δ working capital | B14: =-(B13-Assumptions!$B$54) | C14: =-(C13-B13) | D14: =-(D13-C13) | E14: =-(E13-D13) | F14: =-(F13-E13)
A15: Free cash flow to firm | B15: =B10+B11+B12+B14 | C15: =C10+C11+C12+C14 | D15: =D10+D11+D12+D14 | E15: =E10+E11+E12+E14 | F15: =F10+F11+F12+F14
A16: Forward WACC (that year) | B16: =Assumptions!C50 | C16: =Assumptions!D50 | D16: =Assumptions!E50 | E16: =Assumptions!F50 | F16: =Assumptions!G50
A17: Cumulative discount factor | B17: =Assumptions!C51 | C17: =Assumptions!D51 | D17: =Assumptions!E51 | E17: =Assumptions!F51 | F17: =Assumptions!G51
A18: PV of FCFF | B18: =B15*B17 | C18: =C15*C17 | D18: =D15*D17 | E18: =E15*E17 | F18: =F15*F17
A20: Σ PV of explicit FCFF (FY26–30E) | B20: =SUM(B18:F18)
A21: Terminal ROIC (NOPAT ÷ [NWC + 5% of revenue]) | B21: =F10/(F13+0.05*F6)
A22: Terminal reinvestment rate = g ÷ ROIC | B22: =Assumptions!$B$26/B21
A23: Terminal FCFF = NOPAT × (1+g) × (1 − RR) | B23: =F10*(1+Assumptions!$B$26)*(1-B22)
A24: Terminal value (at terminal WACC) | B24: =B23/(Assumptions!$B$25-Assumptions!$B$26)
A25: PV of terminal value (year-5 factor) | B25: =B24*F17
A26: Enterprise value | B26: =B20+B25
A27: Terminal value as % of EV | B27: =B25/B26
A28: less: net debt | B28: =-Assumptions!$B$28
A29: less: non-controlling interests | B29: =-Assumptions!$B$29
A30: Equity value — INTRINSIC (may be negative) | B30: =B26-Assumptions!$B$28-Assumptions!$B$29
A31: Equity value — floored at zero (limited liability) | B31: =MAX(B30,0)
A32: Intrinsic per share (EGP, unfloored) | B32: =B30/Assumptions!$B$6
A33: Fair value per share (EGP) — floored | B33: =MAX(B31/Assumptions!$B$6,0.01)
A34: Upside / (downside) vs spot | B34: =B33/Assumptions!$B$5-1
A36: The glide: each year at its own forward WACC (22.6% -> 14.1%), shape from the forward Kd path; the terminal is capitalised at the terminal WACC and discounted at the identical year-5 cumulative factor.

Sheet Income Statement
A1: Income statement (EGP mn, consolidated)
A2: FY23–FY25 as sourced/derived (blue; (d)-flagged in the study); FY26E–FY30E formulas. Interest on OPENING net debt at that year’s forward Kd; tax on positive EBT net of loss carryforward.
B4: FY23 | C4: FY24 | D4: FY25 | E4: FY26E | F4: FY27E | G4: FY28E | H4: FY29E | I4: FY30E
A6: Revenue | B6: 8673.4 | C6: 13778.2 | D6: 10819 | E6: =Segments!E11 | F6: =Segments!F11 | G6: =Segments!G11 | H6: =Segments!H11 | I6: =Segments!I11
A7: EBITDA | B7: 2661.0364 | C7: 3490 | D7: 2871.2943 | E7: =Segments!E15 | F7: =Segments!F15 | G7: =Segments!G15 | H7: =Segments!H15 | I7: =Segments!I15
A8: D&A | B8: -60.7138 | C8: -90 | D8: -75.733 | E8: =-Segments!E17 | F8: =-Segments!F17 | G8: =-Segments!G17 | H8: =-Segments!H17 | I8: =-Segments!I17
A9: EBIT | B9: 2600.3226 | C9: 3400 | D9: 2795.5613 | E9: =Segments!E18 | F9: =Segments!F18 | G9: =Segments!G18 | H9: =Segments!H18 | I9: =Segments!I18
A10: Net finance cost | B10: -990 | C10: -1700 | D10: -2150 | E10: =-Assumptions!C48*Assumptions!$B$28 | F10: =-Assumptions!D48*'Balance Sheet'!D11 | G10: =-Assumptions!E48*'Balance Sheet'!E11 | H10: =-Assumptions!F48*'Balance Sheet'!F11 | I10: =-Assumptions!G48*'Balance Sheet'!G11
A11: Earnings before tax | B11: 1610.3226 | C11: 1700 | D11: 645.56129 | E11: =E9+E10 | F11: =F9+F10 | G11: =G9+G10 | H11: =H9+H10 | I11: =I9+I10
A12: Cumulative EBT since FY26E (memo) | E12: =SUM($E$11:E11) | F12: =SUM($E$11:F11) | G12: =SUM($E$11:G11) | H12: =SUM($E$11:H11) | I12: =SUM($E$11:I11)
A13: Income tax (22.5% of positive cumulative EBT, incremental) | B13: -362.32258 | C13: -372.2 | D13: -145.25129 | E13: =-Assumptions!$B$7*MAX(0,E12) | F13: =-(Assumptions!$B$7*MAX(0,F12)-Assumptions!$B$7*MAX(0,C12)) | G13: =-(Assumptions!$B$7*MAX(0,G12)-Assumptions!$B$7*MAX(0,D12)) | H13: =-(Assumptions!$B$7*MAX(0,H12)-Assumptions!$B$7*MAX(0,E12)) | I13: =-(Assumptions!$B$7*MAX(0,I12)-Assumptions!$B$7*MAX(0,F12))
A14: Net profit (attributable) | B14: 1248 | C14: 1327.8 | D14: 500.31 | E14: =E11+E13 | F14: =F11+F13 | G14: =G11+G13 | H14: =H11+H13 | I14: =I11+I13
A15: EPS (EGP) | B15: =B14/Assumptions!$B$6 | C15: =C14/Assumptions!$B$6 | D15: =D14/Assumptions!$B$6 | E15: =E14/Assumptions!$B$6 | F15: =F14/Assumptions!$B$6 | G15: =G14/Assumptions!$B$6 | H15: =H14/Assumptions!$B$6 | I15: =I14/Assumptions!$B$6
A17: Historical net finance cost is (d)-derived (FY24 via the disclosed 2.0x coverage; FY23/FY25 back-solved to the reported NP). Loss carryforward per Egyptian tax law (5yr) modelled via cumulative-EBT tax.

Sheet Balance Sheet
A1: Balance sheet — condensed invested-capital layout (EGP mn)
A2: IC = NWC + PP&E + other assets; financed by net debt + equity + flat non-debt liabilities. Check row is zero by construction.
B4: FY24 | C4: FY25e | D4: FY26E | E4: FY27E | F4: FY28E | G4: FY29E | H4: FY30E
A6: Net working capital | B6: 10500 | C6: =Assumptions!B54 | D6: =DCF!B13 | E6: =DCF!C13 | F6: =DCF!D13 | G6: =DCF!E13 | H6: =DCF!F13
A7: PP&E (roll: + capex - D&A) | B7: 650 | C7: 680 | D7: =C7-DCF!B12-Segments!E17 | E7: =D7-DCF!C12-Segments!F17 | F7: =E7-DCF!D12-Segments!G17 | G7: =F7-DCF!E12-Segments!H17 | H7: =G7-DCF!F12-Segments!I17
A8: Other assets (held flat) | B8: 3000 | C8: 2980 | D8: =C8 | E8: =D8 | F8: =E8 | G8: =F8 | H8: =G8
A9: Invested capital (net of payables) | B9: =SUM(B6:B8) | C9: =SUM(C6:C8) | D9: =SUM(D6:D8) | E9: =SUM(E6:E8) | F9: =SUM(F6:F8) | G9: =SUM(G6:G8) | H9: =SUM(H6:H8)
A11: Net debt (schedule: opening − equity FCF) | B11: 9805 | C11: =Assumptions!B28 | D11: =Assumptions!$B$28-'Cash Flow'!C12 | E11: =D11-'Cash Flow'!D12 | F11: =E11-'Cash Flow'!E12 | G11: =F11-'Cash Flow'!F12 | H11: =G11-'Cash Flow'!G12
A12: Equity (roll: + net profit, no dividends) | B12: =Assumptions!B34-500.31 | C12: =Assumptions!B34 | D12: =C12+'Income Statement'!E14 | E12: =D12+'Income Statement'!F14 | F12: =E12+'Income Statement'!G14 | G12: =F12+'Income Statement'!H14 | H12: =G12+'Income Statement'!I14
A13: Non-debt liabilities & other (flat plug at FY25e) | B13: =B9-B11-B12 | C13: =C9-C11-C12 | D13: =$C13 | E13: =$C13 | F13: =$C13 | G13: =$C13 | H13: =$C13
A14: Total financing | B14: =B11+B12+B13 | C14: =C11+C12+C13 | D14: =D11+D12+D13 | E14: =E11+E12+E13 | F14: =F11+F12+F13 | G14: =G11+G12+G13 | H14: =H11+H12+H13
A15: Balance check (IC − financing) | B15: =B9-B14 | C15: =C9-C14 | D15: =D9-D14 | E15: =E9-E14 | F15: =F9-F14 | G15: =G9-G14 | H15: =H9-H14
A17: FY24 column: SWS-sourced anchors (debt 9,000/cash 828/equity 3,600); FY25e column: derived (study §1.6). The forecast check row is zero by construction: PP&E rolls with capex − D&A, NWC with its driver, net debt with the cash-flow sheet, equity with net profit, and the non-debt-liabilities plug is held flat.

Sheet Cash Flow
A1: Cash flow (EGP mn, forecast)
A2: Equity free cash flow feeds the net-debt schedule (surplus repays debt; deficit is drawn). FCFF memo ties to the DCF.
C4: FY26E | D4: FY27E | E4: FY28E | F4: FY29E | G4: FY30E
A6: Net profit | C6: ='Income Statement'!E14 | D6: ='Income Statement'!F14 | E6: ='Income Statement'!G14 | F6: ='Income Statement'!H14 | G6: ='Income Statement'!I14
A7: + D&A | C7: =Segments!E17 | D7: =Segments!F17 | E7: =Segments!G17 | F7: =Segments!H17 | G7: =Segments!I17
A8: − Δ working capital | C8: =DCF!B14 | D8: =DCF!C14 | E8: =DCF!D14 | F8: =DCF!E14 | G8: =DCF!F14
A9: − Capex | C9: =DCF!B12 | D9: =DCF!C12 | E9: =DCF!D12 | F9: =DCF!E12 | G9: =DCF!F12
A10: Operating − investing cash flow | C10: =SUM(C6:C9) | D10: =SUM(D6:D9) | E10: =SUM(E6:E9) | F10: =SUM(F6:F9) | G10: =SUM(G6:G9)
A11: Dividends | C11: 0 | D11: 0 | E11: 0 | F11: 0 | G11: 0
A12: Equity free cash flow (repays / draws net debt) | C12: =C10+C11 | D12: =D10+D11 | E12: =E10+E11 | F12: =F10+F11 | G12: =G10+G11
A14: memo: FCFF (ties to DCF row) | C14: =DCF!B15 | D14: =DCF!C15 | E14: =DCF!D15 | F14: =DCF!E15 | G14: =DCF!F15
A15: memo: net debt, closing | C15: ='Balance Sheet'!D11 | D15: ='Balance Sheet'!E11 | E15: ='Balance Sheet'!F11 | F15: ='Balance Sheet'!G11 | G15: ='Balance Sheet'!H11
A17: No dividends modelled — none in the disclosed record and the balance sheet argues against a first.

Sheet Summary Financials
A1: Summary financials (EGP mn)
A2: Every forecast cell links to the statement sheets; history as sourced/derived.
B4: FY23 | C4: FY24 | D4: FY25 | E4: FY26E | F4: FY27E | G4: FY28E | H4: FY29E | I4: FY30E
A6: Revenue | B6: 8673.4 | C6: 13778.2 | D6: 10819 | E6: ='Income Statement'!E6 | F6: ='Income Statement'!F6 | G6: ='Income Statement'!G6 | H6: ='Income Statement'!H6 | I6: ='Income Statement'!I6
A7: EBITDA | B7: 2661.0364 | C7: 3490 | D7: 2871.2943 | E7: ='Income Statement'!E7 | F7: ='Income Statement'!F7 | G7: ='Income Statement'!G7 | H7: ='Income Statement'!H7 | I7: ='Income Statement'!I7
A8: EBIT | B8: 2600.3226 | C8: 3400 | D8: 2795.5613 | E8: ='Income Statement'!E9 | F8: ='Income Statement'!F9 | G8: ='Income Statement'!G9 | H8: ='Income Statement'!H9 | I8: ='Income Statement'!I9
A9: Net profit (attributable) | B9: 1248 | C9: 1327.8 | D9: 500.31 | E9: ='Income Statement'!E14 | F9: ='Income Statement'!F14 | G9: ='Income Statement'!G14 | H9: ='Income Statement'!H14 | I9: ='Income Statement'!I14
A10: Net debt (closing) | D10: =Assumptions!B28 | E10: ='Balance Sheet'!D11 | F10: ='Balance Sheet'!E11 | G10: ='Balance Sheet'!F11 | H10: ='Balance Sheet'!G11 | I10: ='Balance Sheet'!H11
A11: Equity (attributable) | D11: =Assumptions!B34 | E11: ='Balance Sheet'!D12 | F11: ='Balance Sheet'!E12 | G11: ='Balance Sheet'!F12 | H11: ='Balance Sheet'!G12 | I11: ='Balance Sheet'!H12
A12: FCFF (forecast) | E12: =DCF!B15 | F12: =DCF!C15 | G12: =DCF!D15 | H12: =DCF!E15 | I12: =DCF!F15

Sheet Monte Carlo
A1: Monte Carlo — engine outputs (carry-anchored YZ-HAR-t)
A2: 50,000 paths · Student-t(6) · width calibrated on the 30-name Egyptian panel · drift = local carry (19.50%) · values computed by the engine, not a sheet simulation.
A5: The probability read (3 months)
A6: P(price above spot) | B6: 0.7286
A7: P(+10%) vs P(−10%) — odds | B7: 50% vs 11% · 4.4:1
A8: Median level (EGP) and % move | B8: 2.29 (+10.2%)
A9: 50% band (25th–75th) | B9: 2.06 – 2.55
A10: Touch(+10%) / touch(−10%) | B10: 80% / 24%
A12: Percentile map (EGP/share)
A13: Horizon | B13: p5 | C13: p25 | D13: p50 | E13: p75 | F13: p95
A14: 1 month | B14: 1.91 | C14: 2.1 | D14: 2.22 | E14: 2.35 | F14: 2.59
A15: 3 months | B15: 1.71 | C15: 2.06 | D15: 2.29 | E15: 2.55 | F15: 3.07
A17: Level-touch ladder (probability of touching by horizon)
A18: Level (EGP) | B18: 1 month | C18: 3 months
A19: 3 | B19: 0.00645 | C19: 0.09835
A20: 2.75 | B20: 0.0259 | C20: 0.21765
A21: 2.5 | B21: 0.1412 | C21: 0.47315
A22: 2.35 | B22: 0.39565 | C22: 0.70025
A23: 2.08 | B23: 0.40075 | C23: 0.6178
A24: 2.05 | B24: 0.31065 | C24: 0.54345
A25: 1.9 | B25: 0.07835 | C25: 0.27225
A26: 1.7 | B26: 0.0113 | C26: 0.09345
A28: Probability zones (3 months)
A29: Deep downside | B29: < 1.80 | C29: 0.0814
A30: Lower band | B30: 1.80–2.05 | C30: 0.1618
A31: Around spot | B31: 2.05–2.35 | C31: 0.32145
A32: Upper band | B32: 2.35–2.70 | C32: 0.27745
A33: Strong upside | B33: > 2.70 | C33: 0.1579

Sheet Sensitivity
A1: Sensitivity — engine grids (values) + the live base cell
A2: Grids are engine outputs under the full glide re-computation; the base cell reprices live off Assumptions.
A5: Live base DCF (links to the DCF sheet) | B5: =DCF!B33
A7: Terminal WACC × terminal g (EGP/share)
A8: Terminal WACC \ g | B8: 0.03 | C8: 0.04 | D8: 0.05 | E8: 0.06 | F8: 0.07
A9: 0.129988 | B9: -1.31 | C9: -1.4 | D9: -1.51 | E9: -1.66 | F9: -1.87
A10: 0.139988 | B10: -1.47 | C10: -1.56 | D10: -1.67 | E10: -1.82 | F10: -2.02
A11: 0.149988 | B11: -1.61 | C11: -1.7 | D11: -1.81 | E11: -1.94 | F11: -2.12
A12: 0.159988 | B12: -1.72 | C12: -1.81 | D12: -1.91 | E12: -2.04 | F12: -2.21
A13: 0.169988 | B13: -1.82 | C13: -1.9 | D13: -2 | E13: -2.12 | F13: -2.28
A15: Explicit-window WACC × terminal WACC (EGP/share)
A16: Explicit \ terminal | B16: 0.129988 | C16: 0.139988 | D16: 0.149988 | E16: 0.159988 | F16: 0.169988
A17: 0.19390565 | B17: -1.83 | C17: -1.98 | D17: -2.09 | E17: -2.18 | F17: -2.25
A18: 0.20390565 | B18: -1.85 | C18: -2 | D18: -2.11 | E18: -2.19 | F18: -2.26
A19: 0.21390565 | B19: -1.87 | C19: -2.02 | D19: -2.12 | E19: -2.21 | F19: -2.28
A20: 0.22390565 | B20: -1.89 | C20: -2.03 | D20: -2.14 | E20: -2.22 | F20: -2.29
A21: 0.23390565 | B21: -1.91 | C21: -2.05 | D21: -2.15 | E21: -2.23 | F21: -2.3
A23: EBITDA-margin shift × terminal NWC intensity (EGP/share)
A24: Margin shift \ NWC % | B24: 1 | C24: 0.94 | D24: 0.88 | E24: 0.82 | F24: 0.76
A25: -0.3 | B25: 0 | C25: 0 | D25: 0 | E25: 0 | F25: 0
A26: -0.15 | B26: 0 | C26: 0 | D26: -2.7 | E26: -2.4 | F26: -2.1
A27: 0 | B27: -2.72 | C27: -2.42 | D27: -2.12 | E27: -1.82 | F27: -1.52
A28: 0.15 | B28: -2.14 | C28: -1.84 | D28: -1.54 | E28: -1.24 | F28: -0.95
A29: 0.3 | B29: -1.56 | C29: -1.26 | D29: -0.96 | E29: -0.67 | F29: -0.37
A31: Terminal-ROIC grid (drives RR = g/ROIC and the inverted g-gradient)
A32: Terminal ROIC | B32: RR for g=5% | C32: Terminal value | D32: DCF (EGP/sh, unfloored)
A33: 0.077 | B33: 0.90909091 | C33: 1821 | D33: -2.51
A34: 0.085 | B34: 0.82352941 | C34: 3534 | D34: -2.28
A35: 0.091708146 | B35: 0.76329097 | C35: 4741 | D35: -2.12
A36: 0.12 | B36: 0.58333333 | C36: 8345 | D36: -1.65
A37: 0.15 | B37: 0.46666667 | C37: 10681 | D37: -1.34
A39: Challenged net-debt reading (unverified aggregator 10,386): DCF unfloored | E39: -2.3
A41: Beta grid (Ke / WACCs / DCF)
A42: Beta | B42: Ke | C42: WACC explicit | D42: WACC terminal | E42: DCF (EGP/sh)
A43: 0.6 | B43: 0.24556 | C43: 0.20030474 | D43: 0.1347 | E43: -1.94
A44: 0.78 | B44: 0.262498 | C44: 0.20703047 | D44: 0.14226 | E44: -2.04
A45: 0.8 | B45: 0.26438 | C45: 0.20777777 | D45: 0.1431 | E45: -2.05
A46: 0.964 | B46: 0.2798124 | C46: 0.21390565 | D46: 0.149988 | E46: -2.12
A47: 1 | B47: 0.2832 | C47: 0.21525079 | D47: 0.1515 | E47: -2.14
A48: 1.15 | B48: 0.297315 | C48: 0.22085556 | D48: 0.1578 | E48: -2.19
...

Sheet Per-Share & Ratios
A1: Per-share & ratios — the standing dashboard
A2: Links to statements / Assumptions.
B4: FY23 | C4: FY24 | D4: FY25 | E4: FY26E | F4: FY27E | G4: FY28E | H4: FY29E | I4: FY30E
A6: EPS (EGP) | B6: ='Income Statement'!B14/Assumptions!$B$6 | C6: ='Income Statement'!C14/Assumptions!$B$6 | D6: ='Income Statement'!D14/Assumptions!$B$6 | E6: ='Income Statement'!E14/Assumptions!$B$6 | F6: ='Income Statement'!F14/Assumptions!$B$6 | G6: ='Income Statement'!G14/Assumptions!$B$6 | H6: ='Income Statement'!H14/Assumptions!$B$6 | I6: ='Income Statement'!I14/Assumptions!$B$6
A7: P/E at spot (×) | B7: =IF('Income Statement'!B14>0,Assumptions!$B$5/('Income Statement'!B14/Assumptions!$B$6),"n.m.") | C7: =IF('Income Statement'!C14>0,Assumptions!$B$5/('Income Statement'!C14/Assumptions!$B$6),"n.m.") | D7: =IF('Income Statement'!D14>0,Assumptions!$B$5/('Income Statement'!D14/Assumptions!$B$6),"n.m.") | E7: =IF('Income Statement'!E14>0,Assumptions!$B$5/('Income Statement'!E14/Assumptions!$B$6),"n.m.") | F7: =IF('Income Statement'!F14>0,Assumptions!$B$5/('Income Statement'!F14/Assumptions!$B$6),"n.m.") | G7: =IF('Income Statement'!G14>0,Assumptions!$B$5/('Income Statement'!G14/Assumptions!$B$6),"n.m.") | H7: =IF('Income Statement'!H14>0,Assumptions!$B$5/('Income Statement'!H14/Assumptions!$B$6),"n.m.") | I7: =IF('Income Statement'!I14>0,Assumptions!$B$5/('Income Statement'!I14/Assumptions!$B$6),"n.m.")
A8: EBITDA margin | B8: ='Income Statement'!B7/'Income Statement'!B6 | C8: ='Income Statement'!C7/'Income Statement'!C6 | D8: ='Income Statement'!D7/'Income Statement'!D6 | E8: ='Income Statement'!E7/'Income Statement'!E6 | F8: ='Income Statement'!F7/'Income Statement'!F6 | G8: ='Income Statement'!G7/'Income Statement'!G6 | H8: ='Income Statement'!H7/'Income Statement'!H6 | I8: ='Income Statement'!I7/'Income Statement'!I6
A9: Net margin | B9: ='Income Statement'!B14/'Income Statement'!B6 | C9: ='Income Statement'!C14/'Income Statement'!C6 | D9: ='Income Statement'!D14/'Income Statement'!D6 | E9: ='Income Statement'!E14/'Income Statement'!E6 | F9: ='Income Statement'!F14/'Income Statement'!F6 | G9: ='Income Statement'!G14/'Income Statement'!G6 | H9: ='Income Statement'!H14/'Income Statement'!H6 | I9: ='Income Statement'!I14/'Income Statement'!I6
A10: Revenue YoY | C10: ='Income Statement'!C6/'Income Statement'!B6-1 | D10: ='Income Statement'!D6/'Income Statement'!C6-1 | E10: ='Income Statement'!E6/'Income Statement'!D6-1 | F10: ='Income Statement'!F6/'Income Statement'!E6-1 | G10: ='Income Statement'!G6/'Income Statement'!F6-1 | H10: ='Income Statement'!H6/'Income Statement'!G6-1 | I10: ='Income Statement'!I6/'Income Statement'!H6-1
A11: Book value / share (EGP) | D11: =Assumptions!$B$34/Assumptions!$B$6 | E11: ='Balance Sheet'!D12/Assumptions!$B$6 | F11: ='Balance Sheet'!E12/Assumptions!$B$6 | G11: ='Balance Sheet'!F12/Assumptions!$B$6 | H11: ='Balance Sheet'!G12/Assumptions!$B$6 | I11: ='Balance Sheet'!H12/Assumptions!$B$6
A12: P/B at spot (×) | D12: =Assumptions!$B$5/(Assumptions!$B$34/Assumptions!$B$6) | E12: =Assumptions!$B$5/('Balance Sheet'!D12/Assumptions!$B$6) | F12: =Assumptions!$B$5/('Balance Sheet'!E12/Assumptions!$B$6) | G12: =Assumptions!$B$5/('Balance Sheet'!F12/Assumptions!$B$6) | H12: =Assumptions!$B$5/('Balance Sheet'!G12/Assumptions!$B$6) | I12: =Assumptions!$B$5/('Balance Sheet'!H12/Assumptions!$B$6)
A13: Net debt / EBITDA (×) | D13: =Assumptions!$B$28/'Income Statement'!D7 | E13: ='Balance Sheet'!D11/'Income Statement'!E7 | F13: ='Balance Sheet'!E11/'Income Statement'!F7 | G13: ='Balance Sheet'!F11/'Income Statement'!G7 | H13: ='Balance Sheet'!G11/'Income Statement'!H7 | I13: ='Balance Sheet'!H11/'Income Statement'!I7
A14: Net debt / equity | D14: =Assumptions!$B$28/Assumptions!$B$34 | E14: ='Balance Sheet'!D11/'Balance Sheet'!D12 | F14: ='Balance Sheet'!E11/'Balance Sheet'!E12 | G14: ='Balance Sheet'!F11/'Balance Sheet'!F12 | H14: ='Balance Sheet'!G11/'Balance Sheet'!G12 | I14: ='Balance Sheet'!H11/'Balance Sheet'!H12
A15: ROE (attributable) | E15: ='Income Statement'!E14/'Balance Sheet'!D12 | F15: ='Income Statement'!F14/'Balance Sheet'!E12 | G15: ='Income Statement'!G14/'Balance Sheet'!F12 | H15: ='Income Statement'!H14/'Balance Sheet'!G12 | I15: ='Income Statement'!I14/'Balance Sheet'!H12
A17: Historical per-share ratios beyond EPS are omitted where the year-end balance sheet was never published (flagged gap).

Sheet Peer & Sector
A1: Peer set & sector
A2: One giant (Elsewedy) above a tier of mid-caps competing on price and local content in tenders.
A5: Name | B5: Mkt cap | C5: P/E | D5: EV/EBITDA | E5: D/E | F5: Note
A6: El Sewedy Electric (EGX: SWDY) | B6: EGP 196bn (21-Jul; ~205bn 27-Jul) | C6: 11.3x computed | D6: ~7.1x computed | E6: moderate | F6: FY25 rev 281bn, NP 17.3bn, EBITDA 30.7bn, net bank debt 19.8bn (filed); W&C grew low-teens FY25 (+66% is FY2024)
A7: Riyadh Cables (Tadawul: 4142) | B7: SAR 15.4bn (30-Jul) | C7: 14.3x | D7: ~12.5x derived | E7: ~0.5x | F7: Same industry, clean balance sheet, different market; BS inputs unverified
A8: Electro Cable Egypt (ELEC) | B8: EGP 7.3bn | C8: 14.6x trailing | D8: ~5.3x FY25e | E8: ~2.5x | F8: Loss-making 1Q26; ~5.5x on FY24 windfall EPS
A9: Giza Cables (private) | B9: — | C9: — | D9: — | E9: — | F9: No public financials
A11: Sector: EETC EGP 45bn FY25/26 transmission plan + EU €690mn package + Egypt–Saudi interconnector (95% complete) drive demand; LME-linked pass-through pricing keeps margins thin; copper +51% y/y strains working capital at 20%+ funding.
A12: Analyst context: none exists — ELEC is uncovered; no rating and no target here either (house rule).
