Workbook

Sheet READ FIRST
A1: Testahil — Americana Restaurants International PLC (Abu Dhabi Securities Exchange: AMR)
A2: Companion model · Independent valuation study · Educational analysis · Not investment advice
A4: WHAT THIS WORKBOOK IS. A transparent companion to the Americana Restaurants valuation study. Blue cells are inputs, black cells are formulas, green cells link across sheets.
A6: IT CALCULATES. Every figure that can be derived arithmetically from a driver is a live formula, so you can change a blue cell on the Assumptions sheet and watch the model reprice. The cost of capital is built from the risk-free rate, the sovereign spread, beta and the premium rather than pasted. The glide the discount rate walks down is derived from the tax path. The discount factors compound. The cash-flow waterfall chains: EBITDA less depreciation gives EBIT, EBIT after tax gives NOPAT, and free cash flow to the firm falls out of NOPAT, depreciation, capital expenditure and the change in working capital. The terminal block chains too: the reinvestment rate is growth divided by the return on capital, and the terminal value follows from terminal NOPAT, that reinvestment rate, the terminal cost of capital and growth. The statements roll forward — property, right-of-use assets, working capital, equity, cash and the lease liability each carry from one year to the next — and every ratio and per-share figure on every sheet is a formula.
A8: FOUR CLASSES OF CELL ARE PASTED, AND ONLY FOUR.
A9: 1. Audited and disclosed history. The primary record is not a calculation. Where a line is both disclosed and derivable, the disclosed figure is carried.
A10: 2. The probability map. Each figure on the Monte Carlo sheet is the output of a fifty-thousand-path simulation, not a formula.
A11: 3. The sensitivity grids. Each cell there is a complete re-run of the whole model with joint driver shifts, so it cannot be a single formula. Those grids do NOT redraw when a driver is changed.
A12: 4. Two whole-model re-runs named individually: the bear and bull of the cash-flow lens on the Summary sheet, whose joint driver sets (margin plus or minus 1.5 points, cost of capital minus or plus 1.5 points, terminal growth 2% or 4%, like-for-like plus or minus 1 point) are stated beside them; and the leases-as-operating-cost reading on the Fundamental Valuation sheet. The expert panel, both readings of the margin question, the cyclical value and every lens bear and bull are LIVE FORMULAS in this edition.
A13: Anything else pasted would be a defect. The formula and pasted-value counts are reported at the foot of this sheet.
A15: HOW REVENUE IS BUILT. Not as one growth rate. The restaurant estate is disclosed country by country at each period end and segment revenue is disclosed for the same units, so revenue is built as restaurants times revenue per restaurant across seven market units. The restaurant count grows on the company's own net-new-store guidance; the revenue per restaurant grows on disclosed like-for-like sales growth, less a currency drag applied only to the two markets whose currencies are not pegged to the dollar. The build reproduces reported revenue exactly in all three audited years. Margins are an OUTPUT of the cost stack, not an input: eight cost classes are each escalated on their own driver, never on one blended index.
A17: CURRENCY. The company reports in US dollars. The shares trade in dirhams in Abu Dhabi and in riyals in Riyadh, and the dirham has been pegged at 3.6725 to the dollar since 1997. The model runs in US dollars — the reporting and functional currency — and converts to dirhams at the peg. Figures are USD million unless stated; per-share figures are shown in both currencies.
... A23: COUNTS. This workbook carries 897 formula cells against 406 pasted values — 307 audited or disclosed history, 29 engine outputs, and 70 sensitivity-grid cells. Every one of the 897 formula cells is checked against the model that wrote it.

Sheet Summary
A1: Summary — the valuation at a glance
A2: All values link live to their source sheets. AED per share unless stated.
A4: Lens | B4: Bear | C4: Base | D4: Bull | E4: Weight | F4: Contribution | G4: Terminal value share | H4: vs market
A5: Discounted cash flow | B5: 1.3612963 | C5: =DCF!C39 | D5: 4.05937 | E5: =Assumptions!$C$103 | F5: =C5*E5 | G5: =DCF!C32 | H5: =C5/$C$12-1
A6: Relative multiples | B6: ='Relative & Normalized'!C13 | C6: ='Relative & Normalized'!B12 | D6: ='Relative & Normalized'!D13 | E6: =Assumptions!$C$104 | F6: =C6*E6 | H6: =C6/$C$12-1
A7: Normalised earnings power | B7: ='Relative & Normalized'!C32 | C7: ='Relative & Normalized'!B31 | D7: ='Relative & Normalized'!D32 | E7: =Assumptions!$C$105 | F7: =C7*E7 | H7: =C7/$C$12-1
A8: Book value and sustainable return | B8: ='Relative & Normalized'!C41 | C8: ='Relative & Normalized'!B40 | D8: ='Relative & Normalized'!D41 | E8: =Assumptions!$C$106 | F8: =C8*E8 | H8: =C8/$C$12-1
A10: Weighted central — outer columns are the weighted bear and bull | B10: =B5*E5+B6*E6+B7*E7+B8*E8 | C10: =SUM(F5:F8) | D10: =D5*E5+D6*E6+D7*E7+D8*E8 | E10: =SUM(E5:E8) | H10: =C10/$C$12-1
A11: Range across the lenses (widest bear to widest bull, unweighted) | B11: =MIN(B5:B8) | D11: =MAX(D5:D8)
A12: Market price (anchor, 7 August 2026) | C12: =Assumptions!$C$5
A13: Expert panel median | C13: ='Fundamental Valuation'!C29 | H13: =C13/$C$12-1
A14: The open question — the margin, both ways
A15: Structural: the first-half gains hold | C15: ='Fundamental Valuation'!C13 | H15: =C15/$C$12-1
A16: Cyclical: the margin reverts to the three-year average | C16: ='Fundamental Valuation'!C14 | H16: =C16/$C$12-1
A18: Key figures
A19: Shares outstanding, net of treasury (million) | C19: =Assumptions!$C$7
A20: Market capitalisation (USD million) | C20: =DCF!C56
A21: Net debt at 31 December 2025 (USD million) | C21: ='Balance Sheet'!D17
A22: FY2025 revenue (USD million) | C22: ='Income Statement'!D5
A23: FY2025 EBITDA (USD million) | C23: ='Income Statement'!D8
A24: FY2025 profit attributable to shareholders (USD million) | C24: ='Income Statement'!D19
A25: Restaurants at 31 December 2025 | C25: =Segments!B12
A26: Cost of capital — explicit window | C26: =DCF!C46
A27: Cost of capital — terminal | C27: =DCF!C53
A28: Terminal growth | C28: =DCF!C22
A29: Terminal value as a share of enterprise value | C29: =DCF!C32
A30: Trailing enterprise value / EBITDA | C30: ='Relative & Normalized'!B16
A31: Dividend yield on the declared FY2025 distribution | C31: =Assumptions!$C$126/DCF!C56
A33: The terminal value share is shown beside the cash-flow lens above and again in the key figures, and it is a live link to the DCF sheet in both places.

Sheet Fundamental Valuation
A1: Fundamental valuation — the four lenses, the open question, and the panel
A4: Lens | B4: Basis | C4: AED per share
A5: Discounted cash flow | B5: the full waterfall on the DCF sheet | C5: =DCF!C39
A6: Relative multiples | B6: 8.5x forward EBITDA | C6: ='Relative & Normalized'!B12
A7: Normalised earnings power | B7: 17x mid-cycle earnings | C7: ='Relative & Normalized'!B31
A8: Book value and sustainable return | B8: justified price to book on a sustainable return | C8: ='Relative & Normalized'!B40
A10: Weighted central | C10: =Summary!C10
A12: THE OPEN QUESTION — the margin, computed both ways
A13: Structural — the gains hold and improve slowly | B13: The base case. Food and packaging stays near the 27.4% of revenue the company actually recorded in the first half of 2026, and the EBITDA margin runs from 25.4% to a peak of 25.4% before the growing delivery channel eases it to 24.9%. | C13: =DCF!C39
A14: Cyclical — the gains are competed away | B14: The first half of 2026 is banked, and the EBITDA margin then reverts in a straight line to the three-year audited average of 22.8% by FY2030. | C14: =DCF!C79
A15: The gap | C15: =C14/C13-1
A16: Both readings are LIVE in this workbook: the structural value is the DCF sheet headline and the cyclical value is the parallel formula block at the foot of the DCF sheet, sharing every driver except the margin path. They are published side by side and never averaged.
A18: A SECOND READING — how the lease estate is treated
A19: Leases capitalised, as the accounts present them | C19: 2.2222179
A20: Leases as an operating cost | C20: 2.1959244
A21: The gap | C21: =C20/C19-1
A22: The two readings differ by under two percent once each is built consistently — charging the right-of-use additions as investment on the capitalised reading, and charging the whole rent bill as a cost on the other. That is a result worth stating: the accounting choice that dominates the balance sheet turns out not to be the thing that decides the value.
A24: THE EXPERT PANEL
A25: Expert | B25: Method | C25: Base (AED) | D25: Low | E25: High
A26: Expert 1 | B26: Restaurant-level unit economics | C26: =(((2*Assumptions!$C$124-Assumptions!$C$125-Assumptions!$C$62*DCF!B5-Assumptions!$C$65*DCF!B5)*(1-Assumptions!$C$71)/DCF!C61+Assumptions!$C$88-Assumptions!$C$90)/Assumptions!$C$7*DCF!$E$38-Assumptions!$C$118)*Assumptions!$C$6 | D26: =(((2*Assumptions!$C$124-Assumptions!$C$125-Assumptions!$C$62*DCF!B5-Assumptions!$C$65*DCF!B5)*(1-Assumptions!$C$71)/(DCF!C61+0.015)+Assumptions!$C$88-Assumptions!$C$90)/Assumptions!$C$7*DCF!$E$38-Assumptions!$C$118)*Assumptions!$C$6 | E26: =(((2*Assumptions!$C$124-Assumptions!$C$125-Assumptions!$C$62*DCF!B5-Assumptions!$C$65*DCF!B5)*(1-Assumptions!$C$71)/(DCF!C61-0.01)+Assumptions!$C$88-Assumptions!$C$90)/Assumptions!$C$7*DCF!$E$38-Assumptions!$C$118)*Assumptions!$C$6
A27: Expert 2 | B27: Distributable cash as a perpetuity | C27: =(Assumptions!$C$126/Assumptions!$C$7*(1+Assumptions!$C$84)/(DCF!C61-Assumptions!$C$84)*DCF!$E$38-Assumptions!$C$118)*Assumptions!$C$6 | D27: =(Assumptions!$C$126/Assumptions!$C$7*1.02/(DCF!C61+0.01-0.02)*DCF!$E$38-Assumptions!$C$118)*Assumptions!$C$6 | E27: =(Assumptions!$C$126/Assumptions!$C$7*1.04/(DCF!C61-0.005-0.04)*DCF!$E$38-Assumptions!$C$118)*Assumptions!$C$6
A28: Expert 3 | B28: Return on capital against the cost of capital | C28: =((DCF!B12/DCF!C53+DCF!B12*(DCF!B12/'Balance Sheet'!E18-DCF!C53)/(DCF!B12/'Balance Sheet'!E18)*Assumptions!$C$84/(DCF!C53*(DCF!C53-Assumptions!$C$84))+DCF!C33+DCF!C34+DCF!C35+DCF!C36)/Assumptions!$C$7*DCF!$E$38-Assumptions!$C$118)*Assumptions!$C$6 | D28: =((DCF!B12/(DCF!C53+0.01)+DCF!C33+DCF!C34+DCF!C35+DCF!C36)/Assumptions!$C$7*DCF!$E$38-Assumptions!$C$118)*Assumptions!$C$6 | E28: =(((DCF!B12/DCF!C53+DCF!B12*(DCF!B12/'Balance Sheet'!E18-DCF!C53)/(DCF!B12/'Balance Sheet'!E18)*Assumptions!$C$84/(DCF!C53*(DCF!C53-Assumptions!$C$84)))*1.18+DCF!C33+DCF!C34+DCF!C35+DCF!C36)/Assumptions!$C$7*DCF!$E$38-Assumptions!$C$118)*Assumptions!$C$6
A29: Panel median | C29: =MEDIAN(C26:C28)

Sheet Assumptions
A1: Assumptions — every driver in the model
A2: Blue cells are inputs. Change one and the model reprices: everything downstream of this sheet is a formula.
A3: Driver | B3: FY2026E | C3: FY2027E | D3: FY2028E | E3: FY2029E | F3: FY2030E
A4: Anchors
A5: Market price (AED per share) | C5: 2.39
A6: Dirhams per US dollar (the peg) | C6: 3.6725
A7: Shares outstanding, net of treasury (million) — issued less treasury | C7: =C8-E8
A8: Shares issued (million) | C8: 8423.6331 | D8: less treasury (million) | E8: 25
A10: Volume — the restaurant estate
A11: Net new restaurants a year | B11: 125 | C11: 130 | D11: 130 | E11: 125 | F11: 120
A12: Share of net additions, by market
A13: UAE | C13: 0.26
A14: Saudi Arabia | C14: 0.3
A15: Kuwait | C15: 0.06
A16: Egypt | C16: 0.12
A17: Morocco | C17: 0.04
A18: Lower Gulf | C18: 0.1
A19: Other markets | C19: 0.12
A20: Restaurants at 31 December 2025, by market
A21: UAE | C21: 652
A22: Saudi Arabia | C22: 766
A23: Kuwait | C23: 276
A24: Egypt | C24: 450
A25: Morocco | C25: 55
A26: Lower Gulf | C26: 287
A27: Other markets | C27: 263
A29: Price — revenue per restaurant
A30: Like-for-like sales growth | B30: 0.055 | C30: 0.045 | D30: 0.04 | E30: 0.037 | F30: 0.035
A31: Currency drag on US dollar revenue per restaurant, by market
A32: UAE | C32: 0
A33: Saudi Arabia | C33: 0
A34: Kuwait | C34: 0
A35: Egypt | C35: 0.025
A36: Morocco | C36: 0.005
A37: Lower Gulf | C37: 0
A38: Other markets | C38: 0.015
A39: Revenue per restaurant in FY2025 (USD thousand), by market
A40: UAE | C40: 1295.4801
A41: Saudi Arabia | C41: 822.33681
A42: Kuwait | C42: 1257.1341
...

Sheet SOTP Bridge
A1: Enterprise value to equity — the bridge
A2: A single operating business, so the bridge is one leg, not a sum of parts. Every line links live to the cash-flow sheet.
A4: Step | B4: USD million | C4: AED per share
A5: Present value of the five forecast years | B5: =DCF!C29 | C5: =B5/Assumptions!$C$7*Assumptions!$C$6
A6: Present value of the terminal value | B6: =DCF!C30 | C6: =B6/Assumptions!$C$7*Assumptions!$C$6
A7: Enterprise value | B7: =B5+B6 | C7: =B7/Assumptions!$C$7*Assumptions!$C$6
A8: Less lease liabilities | B8: =-Assumptions!$C$87 | C8: =B8/Assumptions!$C$7*Assumptions!$C$6
A9: Plus cash and bank deposits | B9: =Assumptions!$C$88 | C9: =B9/Assumptions!$C$7*Assumptions!$C$6
A10: Less bank debt | B10: =-Assumptions!$C$89 | C10: =B10/Assumptions!$C$7*Assumptions!$C$6
A11: Less non-controlling interests | B11: =-Assumptions!$C$90 | C11: =B11/Assumptions!$C$7*Assumptions!$C$6
A12: Equity attributable to shareholders | B12: =B7+B8+B9+B10+B11 | C12: =B12/Assumptions!$C$7*Assumptions!$C$6
A14: Terminal value as a share of enterprise value | B14: =DCF!C32
A15: Present value of the five forecast years, as a share of enterprise value | B15: =B5/B7
A17: Just over half the enterprise value sits beyond the fifth forecast year. That is what a growing business with a nine-and-a-half per cent cost of capital and three per cent long-run growth looks like, and it is the reason the terminal assumptions are sensitised on their own sheet rather than buried.

Sheet Segments
A1: The unit build — restaurants times revenue per restaurant, market by market
A2: The historical columns are the disclosed record. Every forecast cell is a formula: the restaurant count grows on the net-new-store programme and the revenue per restaurant on like-for-like growth net of currency.
A4: Restaurants at year end | B4: FY2025 | C4: FY2026E | D4: FY2027E | E4: FY2028E | F4: FY2029E | G4: FY2030E
A5: UAE | B5: =Assumptions!$C$21 | C5: =B5+Assumptions!B$11*Assumptions!$C$13 | D5: =C5+Assumptions!C$11*Assumptions!$C$13 | E5: =D5+Assumptions!D$11*Assumptions!$C$13 | F5: =E5+Assumptions!E$11*Assumptions!$C$13 | G5: =F5+Assumptions!F$11*Assumptions!$C$13
A6: Saudi Arabia | B6: =Assumptions!$C$22 | C6: =B6+Assumptions!B$11*Assumptions!$C$14 | D6: =C6+Assumptions!C$11*Assumptions!$C$14 | E6: =D6+Assumptions!D$11*Assumptions!$C$14 | F6: =E6+Assumptions!E$11*Assumptions!$C$14 | G6: =F6+Assumptions!F$11*Assumptions!$C$14
A7: Kuwait | B7: =Assumptions!$C$23 | C7: =B7+Assumptions!B$11*Assumptions!$C$15 | D7: =C7+Assumptions!C$11*Assumptions!$C$15 | E7: =D7+Assumptions!D$11*Assumptions!$C$15 | F7: =E7+Assumptions!E$11*Assumptions!$C$15 | G7: =F7+Assumptions!F$11*Assumptions!$C$15
A8: Egypt | B8: =Assumptions!$C$24 | C8: =B8+Assumptions!B$11*Assumptions!$C$16 | D8: =C8+Assumptions!C$11*Assumptions!$C$16 | E8: =D8+Assumptions!D$11*Assumptions!$C$16 | F8: =E8+Assumptions!E$11*Assumptions!$C$16 | G8: =F8+Assumptions!F$11*Assumptions!$C$16
A9: Morocco | B9: =Assumptions!$C$25 | C9: =B9+Assumptions!B$11*Assumptions!$C$17 | D9: =C9+Assumptions!C$11*Assumptions!$C$17 | E9: =D9+Assumptions!D$11*Assumptions!$C$17 | F9: =E9+Assumptions!E$11*Assumptions!$C$17 | G9: =F9+Assumptions!F$11*Assumptions!$C$17
A10: Lower Gulf | B10: =Assumptions!$C$26 | C10: =B10+Assumptions!B$11*Assumptions!$C$18 | D10: =C10+Assumptions!C$11*Assumptions!$C$18 | E10: =D10+Assumptions!D$11*Assumptions!$C$18 | F10: =E10+Assumptions!E$11*Assumptions!$C$18 | G10: =F10+Assumptions!F$11*Assumptions!$C$18
A11: Other markets | B11: =Assumptions!$C$27 | C11: =B11+Assumptions!B$11*Assumptions!$C$19 | D11: =C11+Assumptions!C$11*Assumptions!$C$19 | E11: =D11+Assumptions!D$11*Assumptions!$C$19 | F11: =E11+Assumptions!E$11*Assumptions!$C$19 | G11: =F11+Assumptions!F$11*Assumptions!$C$19
A12: Total restaurants | B12: =SUM(B5:B11) | C12: =SUM(C5:C11) | D12: =SUM(D5:D11) | E12: =SUM(E5:E11) | F12: =SUM(F5:F11) | G12: =SUM(G5:G11)
A14: Revenue per restaurant (USD thousand) | B14: FY2024 | C14: FY2025 | D14: FY2026E | E14: FY2027E | F14: FY2028E | G14: FY2029E | H14: FY2030E
A15: UAE | B15: 1237.7091 | C15: =Assumptions!$C$40 | D15: =C15*(1+Assumptions!B$30)*(1-Assumptions!$C$32) | E15: =D15*(1+Assumptions!C$30)*(1-Assumptions!$C$32) | F15: =E15*(1+Assumptions!D$30)*(1-Assumptions!$C$32) | G15: =F15*(1+Assumptions!E$30)*(1-Assumptions!$C$32) | H15: =G15*(1+Assumptions!F$30)*(1-Assumptions!$C$32)
A16: Saudi Arabia | B16: 794.25613 | C16: =Assumptions!$C$41 | D16: =C16*(1+Assumptions!B$30)*(1-Assumptions!$C$33) | E16: =D16*(1+Assumptions!C$30)*(1-Assumptions!$C$33) | F16: =E16*(1+Assumptions!D$30)*(1-Assumptions!$C$33) | G16: =F16*(1+Assumptions!E$30)*(1-Assumptions!$C$33) | H16: =G16*(1+Assumptions!F$30)*(1-Assumptions!$C$33)
A17: Kuwait | B17: 1167.7481 | C17: =Assumptions!$C$42 | D17: =C17*(1+Assumptions!B$30)*(1-Assumptions!$C$34) | E17: =D17*(1+Assumptions!C$30)*(1-Assumptions!$C$34) | F17: =E17*(1+Assumptions!D$30)*(1-Assumptions!$C$34) | G17: =F17*(1+Assumptions!E$30)*(1-Assumptions!$C$34) | H17: =G17*(1+Assumptions!F$30)*(1-Assumptions!$C$34)
A18: Egypt | B18: 294.41722 | C18: =Assumptions!$C$43 | D18: =C18*(1+Assumptions!B$30)*(1-Assumptions!$C$35) | E18: =D18*(1+Assumptions!C$30)*(1-Assumptions!$C$35) | F18: =E18*(1+Assumptions!D$30)*(1-Assumptions!$C$35) | G18: =F18*(1+Assumptions!E$30)*(1-Assumptions!$C$35) | H18: =G18*(1+Assumptions!F$30)*(1-Assumptions!$C$35)
A19: Morocco | B19: 918.93333 | C19: =Assumptions!$C$44 | D19: =C19*(1+Assumptions!B$30)*(1-Assumptions!$C$36) | E19: =D19*(1+Assumptions!C$30)*(1-Assumptions!$C$36) | F19: =E19*(1+Assumptions!D$30)*(1-Assumptions!$C$36) | G19: =F19*(1+Assumptions!E$30)*(1-Assumptions!$C$36) | H19: =G19*(1+Assumptions!F$30)*(1-Assumptions!$C$36)
A20: Lower Gulf | B20: 776.804 | C20: =Assumptions!$C$45 | D20: =C20*(1+Assumptions!B$30)*(1-Assumptions!$C$37) | E20: =D20*(1+Assumptions!C$30)*(1-Assumptions!$C$37) | F20: =E20*(1+Assumptions!D$30)*(1-Assumptions!$C$37) | G20: =F20*(1+Assumptions!E$30)*(1-Assumptions!$C$37) | H20: =G20*(1+Assumptions!F$30)*(1-Assumptions!$C$37)
A21: Other markets | B21: 889.27386 | C21: =Assumptions!$C$46 | D21: =C21*(1+Assumptions!B$30)*(1-Assumptions!$C$38) | E21: =D21*(1+Assumptions!C$30)*(1-Assumptions!$C$38) | F21: =E21*(1+Assumptions!D$30)*(1-Assumptions!$C$38) | G21: =F21*(1+Assumptions!E$30)*(1-Assumptions!$C$38) | H21: =G21*(1+Assumptions!F$30)*(1-Assumptions!$C$38)
A24: Revenue before eliminations (USD million) | B24: FY2023 | C24: FY2024 | D24: FY2025 | E24: FY2026E | F24: FY2027E | G24: FY2028E | H24: FY2029E | I24: FY2030E
A25: UAE | B25: 750.972 | C25: 748.814 | D25: 844.653 | E25: =D15*C5/1000 | F25: =E15*D5/1000 | G25: =F15*E5/1000 | H25: =G15*F5/1000 | I25: =H15*G5/1000
A26: Saudi Arabia | B26: 594.518 | C26: 582.984 | D26: 629.91 | E26: =D16*C6/1000 | F26: =E16*D6/1000 | G26: =F16*E6/1000 | H26: =G16*F6/1000 | I26: =H16*G6/1000
A27: Kuwait | B27: 339.181 | C27: 305.95 | D27: 346.969 | E27: =D17*C7/1000 | F27: =E17*D7/1000 | G27: =F17*E7/1000 | H27: =G17*F7/1000 | I27: =H17*G7/1000
A28: Egypt | B28: 195.018 | C28: 133.371 | D28: 172.557 | E28: =D18*C8/1000 | F28: =E18*D8/1000 | G28: =F18*E8/1000 | H28: =G18*F8/1000 | I28: =H18*G8/1000
A29: Morocco | B29: 42.806 | C29: 41.352 | D29: 50.679 | E29: =D19*C9/1000 | F29: =E19*D9/1000 | G29: =F19*E9/1000 | H29: =G19*F9/1000 | I29: =H19*G9/1000
A30: Lower Gulf | B30: 278.081 | C30: 194.201 | D30: 257.901 | E30: =D20*C10/1000 | F30: =E20*D10/1000 | G30: =F20*E10/1000 | H30: =G20*F10/1000 | I30: =H20*G10/1000
A31: Other markets | B31: 249.264 | C31: 214.315 | D31: 238.075 | E31: =D21*C11/1000 | F31: =E21*D11/1000 | G31: =F21*E11/1000 | H31: =G21*F11/1000 | I31: =H21*G11/1000
A32: Total before eliminations | B32: =SUM(B25:B31) | C32: =SUM(C25:C31) | D32: =SUM(D25:D31) | E32: =SUM(E25:E31) | F32: =SUM(F25:F31) | G32: =SUM(G25:G31) | H32: =SUM(H25:H31) | I32: =SUM(I25:I31)
A33: Less intercompany eliminations | E33: =-E32*Assumptions!$C$95 | F33: =-F32*Assumptions!$C$95 | G33: =-G32*Assumptions!$C$95 | H33: =-H32*Assumptions!$C$95 | I33: =-I32*Assumptions!$C$95
A34: Revenue on the unit build | E34: =E32+E33 | F34: =F32+F33 | G34: =G32+G33 | H34: =H32+H33 | I34: =I32+I33
A35: FY2026 implied by the disclosed first half | E35: =Assumptions!$C$96
A36: Revenue adopted | E36: =AVERAGE(E34,E35) | F36: =F34 | G36: =G34 | H36: =H34 | I36: =I34
A38: FY2026 is half disclosed and half built. The unit build and the first-half run rate are averaged rather than one being chosen over the other; the two are within two per cent of each other. The historical columns tie exactly to reported revenue in all three audited years.
A40: THE BRAND BUILD — product by product, volume x price, the cross-check spine
A41: Restaurants by brand | B41: FY2024 | C41: FY2025 | D41: FY2026E | E41: FY2027E | F41: FY2028E | G41: FY2029E | H41: FY2030E
A42: KFC | B42: 1089 | C42: 1146 | D42: =C42+Assumptions!B$11*0.4 | E42: =D42+Assumptions!C$11*0.4 | F42: =E42+Assumptions!D$11*0.4 | G42: =F42+Assumptions!E$11*0.4 | H42: =G42+Assumptions!F$11*0.4
A43: Pizza Hut | B43: 432 | C43: 457 | D43: =C43+Assumptions!B$11*0.15 | E43: =D43+Assumptions!C$11*0.15 | F43: =E43+Assumptions!D$11*0.15 | G43: =F43+Assumptions!E$11*0.15 | H43: =G43+Assumptions!F$11*0.15
A44: Hardee's | B44: 410 | C44: 458 | D44: =C44+Assumptions!B$11*0.16 | E44: =D44+Assumptions!C$11*0.16 | F44: =E44+Assumptions!D$11*0.16 | G44: =F44+Assumptions!E$11*0.16 | H44: =G44+Assumptions!F$11*0.16
A45: Krispy Kreme | B45: 388 | C45: 395 | D45: =C45+Assumptions!B$11*0.12 | E45: =D45+Assumptions!C$11*0.12 | F45: =E45+Assumptions!D$11*0.12 | G45: =F45+Assumptions!E$11*0.12 | H45: =G45+Assumptions!F$11*0.12
A46: Growth, niche and other brands | B46: 271 | C46: 293 | D46: =C46+Assumptions!B$11*0.17 | E46: =D46+Assumptions!C$11*0.17 | F46: =E46+Assumptions!D$11*0.17 | G46: =F46+Assumptions!E$11*0.17 | H46: =G46+Assumptions!F$11*0.17
...

Sheet Relative & Normalized
A1: Relative multiples, normalised earnings power, and the book lens
A4: Relative lens | B4: Value
A5: FY2027E EBITDA (USD million) | B5: =DCF!C8
A6: Justified enterprise value / EBITDA | B6: =Assumptions!$C$100
A7: Implied enterprise value at the end of FY2027 (USD million) | B7: =B5*B6
A8: Discount factor back to the valuation date | B8: =DCF!C18
A9: Plus the present value of the FY2026 AND FY2027 free cash flows — a two-year discount makes both years intervening | B9: =DCF!B19+DCF!C19
A10: Implied enterprise value today (USD million) | B10: =B7*B8+B9
A11: Implied equity value (USD million) | B11: =B10+DCF!C33+DCF!C34+DCF!C35+DCF!C36
A12: Implied value per share (AED), rolled to the anchor | B12: =(B11/Assumptions!$C$7*DCF!$E$38-Assumptions!$C$118)*Assumptions!$C$6
A13: Bear at 7.0 times (column C) and bull at 10.5 times (column D), same construction | C13: =((B5*7*B8+B9+DCF!C33+DCF!C34+DCF!C35+DCF!C36)/Assumptions!$C$7*DCF!$E$38-Assumptions!$C$118)*Assumptions!$C$6 | D13: =((B5*10.5*B8+B9+DCF!C33+DCF!C34+DCF!C35+DCF!C36)/Assumptions!$C$7*DCF!$E$38-Assumptions!$C$118)*Assumptions!$C$6
A15: The company’s own trailing multiples
A16: Trailing enterprise value / EBITDA | B16: =(DCF!C56-DCF!C34+DCF!C57)/'Income Statement'!D8
A17: Trailing price / earnings | B17: =Assumptions!$C$5/Assumptions!$C$6/'Income Statement'!D20
A18: Trailing price / book | B18: =Assumptions!$C$5/Assumptions!$C$6/('Balance Sheet'!D14/Assumptions!$C$7)
A19: Net debt / EBITDA | B19: ='Balance Sheet'!D20
A21: Normalised earnings lens — the mid-cycle margin at today’s scale
A22: Current-scale revenue, FY2026E (USD million) | B22: =DCF!B5
A23: Mid-cycle EBITDA margin — the midpoint of the structural and cyclical FY2028 readings | B23: =(DCF!D9+Assumptions!$D$119)/2
A24: Normalised EBITDA (USD million) | B24: =B22*B23
A25: Less depreciation and amortisation | B25: =-'Cash Flow'!E8
A26: Normalised EBIT, after the recurring impairment charge (USD million) | B26: =B24+B25-B22*Assumptions!$C$115
A27: Net finance result (USD million) | B27: ='Income Statement'!E13-Assumptions!$C$82*'Balance Sheet'!D12-Assumptions!$C$74*B22
A28: Normalised earnings after tax (USD million) | B28: =(B26+B27)*(1-Assumptions!$C$71)
A29: Normalised earnings per share (USD) | B29: =B28/Assumptions!$C$7
A30: Justified price / earnings | B30: =Assumptions!$C$101
A31: Implied value per share (AED), rolled to the anchor | B31: =(B29*B30*DCF!$E$38-Assumptions!$C$118)*Assumptions!$C$6
A32: Bear at 13 times (column C) and bull at 21 times (column D) | C32: =(B29*13*DCF!$E$38-Assumptions!$C$118)*Assumptions!$C$6 | D32: =(B29*21*DCF!$E$38-Assumptions!$C$118)*Assumptions!$C$6
A34: Book value and sustainable return
A35: Book value per share (USD) | B35: =Assumptions!$C$97/Assumptions!$C$7
A36: Sustainable return on equity | B36: =Assumptions!$C$102
A37: Trailing return on equity | B37: ='Income Statement'!D19/(('Balance Sheet'!C14+'Balance Sheet'!D14)/2)
A38: Terminal cost of equity | B38: =DCF!C61
A39: Justified price / book | B39: =(B36-Assumptions!$C$84)/(B38-Assumptions!$C$84) | E39: Roll factor from the 30 June book date (38 days) | F39: =(1+DCF!C52)^(38/365)
A40: Implied value per share (AED), rolled from the book date to the anchor | B40: =B35*B39*F39*Assumptions!$C$6
A41: Bear at a 34% return (column C) and bull at 48% (column D) | C41: =B35*((0.34-Assumptions!$C$84)/(B38+0.02-Assumptions!$C$84))*F39*Assumptions!$C$6 | D41: =B35*((0.48-Assumptions!$C$84)/(B38-0.01-Assumptions!$C$84))*F39*Assumptions!$C$6
A43: The book lens is the weakest of the four here and carries the lowest weight for that reason. An operator that leases its estate and distributes almost all its earnings holds very little book equity, so a justified price-to-book multiple divides a large return by a small base and is unstable in both directions.

Sheet DCF
A1: Discounted cash flow — the full waterfall
A2: Every line is a live formula. The cost of capital is built below rather than pasted, the glide is inherited from the tax path, the discount factors compound, and the terminal value is capitalised at the terminal rate.
A4: USD million | B4: FY2026E | C4: FY2027E | D4: FY2028E | E4: FY2029E | F4: FY2030E
A5: Revenue | B5: =Segments!E36 | C5: =Segments!F36 | D5: =Segments!G36 | E5: =Segments!H36 | F5: =Segments!I36
A6: Cash operating costs — six escalator classes as shares, staff and delivery as unit builds (headcount x wage; channel share x unit cost) | B6: =-B5*(Assumptions!B$49+Assumptions!B$50+Assumptions!B$53+Assumptions!B$54+Assumptions!B$55+Assumptions!B$56+Assumptions!$C$57)-((Segments!B12+Segments!C12)/2*Assumptions!B$109/1000+Assumptions!$C$112)*Assumptions!$C$110*(1+Assumptions!$C$111)^1-B5*Assumptions!B$113*Assumptions!B$114 | C6: =-C5*(Assumptions!C$49+Assumptions!C$50+Assumptions!C$53+Assumptions!C$54+Assumptions!C$55+Assumptions!C$56+Assumptions!$C$57)-((Segments!C12+Segments!D12)/2*Assumptions!C$109/1000+Assumptions!$C$112)*Assumptions!$C$110*(1+Assumptions!$C$111)^2-C5*Assumptions!C$113*Assumptions!C$114 | D6: =-D5*(Assumptions!D$49+Assumptions!D$50+Assumptions!D$53+Assumptions!D$54+Assumptions!D$55+Assumptions!D$56+Assumptions!$C$57)-((Segments!D12+Segments!E12)/2*Assumptions!D$109/1000+Assumptions!$C$112)*Assumptions!$C$110*(1+Assumptions!$C$111)^3-D5*Assumptions!D$113*Assumptions!D$114 | E6: =-E5*(Assumptions!E$49+Assumptions!E$50+Assumptions!E$53+Assumptions!E$54+Assumptions!E$55+Assumptions!E$56+Assumptions!$C$57)-((Segments!E12+Segments!F12)/2*Assumptions!E$109/1000+Assumptions!$C$112)*Assumptions!$C$110*(1+Assumptions!$C$111)^4-E5*Assumptions!E$113*Assumptions!E$114 | F6: =-F5*(Assumptions!F$49+Assumptions!F$50+Assumptions!F$53+Assumptions!F$54+Assumptions!F$55+Assumptions!F$56+Assumptions!$C$57)-((Segments!F12+Segments!G12)/2*Assumptions!F$109/1000+Assumptions!$C$112)*Assumptions!$C$110*(1+Assumptions!$C$111)^5-F5*Assumptions!F$113*Assumptions!F$114
A7: Other income | B7: =B5*Assumptions!$C$58 | C7: =C5*Assumptions!$C$58 | D7: =D5*Assumptions!$C$58 | E7: =E5*Assumptions!$C$58 | F7: =F5*Assumptions!$C$58
A8: EBITDA | B8: =B5+B6+B7 | C8: =C5+C6+C7 | D8: =D5+D6+D7 | E8: =E5+E6+E7 | F8: =F5+F6+F7
A9: EBITDA margin | B9: =B8/B5 | C9: =C8/C5 | D9: =D8/D5 | E9: =E8/E5 | F9: =F8/F5
A10: Less depreciation and amortisation | B10: =-'Cash Flow'!E8 | C10: =-'Cash Flow'!F8 | D10: =-'Cash Flow'!G8 | E10: =-'Cash Flow'!H8 | F10: =-'Cash Flow'!I8
A11: EBIT, after the recurring impairment charge | B11: =B8+B10-B5*Assumptions!$C$115 | C11: =C8+C10-C5*Assumptions!$C$115 | D11: =D8+D10-D5*Assumptions!$C$115 | E11: =E8+E10-E5*Assumptions!$C$115 | F11: =F8+F10-F5*Assumptions!$C$115
A12: NOPAT — EBIT after tax | B12: =B11*(1-Assumptions!B$71) | C12: =C11*(1-Assumptions!C$71) | D12: =D11*(1-Assumptions!D$71) | E12: =E11*(1-Assumptions!E$71) | F12: =F11*(1-Assumptions!F$71)
A13: Add back depreciation and amortisation | B13: =-B10 | C13: =-C10 | D13: =-D10 | E13: =-E10 | F13: =-F10
A14: Less capital expenditure, including right-of-use additions | B14: =-'Cash Flow'!E12 | C14: =-'Cash Flow'!F12 | D14: =-'Cash Flow'!G12 | E14: =-'Cash Flow'!H12 | F14: =-'Cash Flow'!I12
A15: Less change in working capital | B15: =-'Cash Flow'!E13 | C15: =-'Cash Flow'!F13 | D15: =-'Cash Flow'!G13 | E15: =-'Cash Flow'!H13 | F15: =-'Cash Flow'!I13
A16: Free cash flow to the firm | B16: =B12+B13+B14+B15 | C16: =C12+C13+C14+C15 | D16: =D12+D13+D14+D15 | E16: =E12+E13+E14+E15 | F16: =F12+F13+F14+F15
A17: Forward cost of capital | B17: =$C$46-($C$46-$C$53)*B44 | C17: =$C$46-($C$46-$C$53)*C44 | D17: =$C$46-($C$46-$C$53)*D44 | E17: =$C$46-($C$46-$C$53)*E44 | F17: =$C$46-($C$46-$C$53)*F44
A18: Discount factor | B18: =1/(1+B17) | C18: =B18/(1+C17) | D18: =C18/(1+D17) | E18: =D18/(1+E17) | F18: =E18/(1+F17)
A19: Present value of free cash flow to the firm | B19: =B16*B18 | C19: =C16*C18 | D19: =D16*D18 | E19: =E16*E18 | F19: =F16*F18
A21: TERMINAL VALUE AND THE BRIDGE TO EQUITY
A22: Terminal growth | C22: =Assumptions!$C$84
A23: Terminal-year NOPAT grown one year | C23: =F12*(1+C22)
A24: Invested capital at the end of the forecast | C24: ='Balance Sheet'!I18
A25: Terminal return on incremental capital — the payback-anchored fade | C25: =Assumptions!$C$116
A26: Required reinvestment rate — growth divided by the return on capital | C26: =C22/C25
A27: Terminal cost of capital | C27: =C53
A28: Terminal value | C28: =C23*(1-C26)/(C27-C22)
A29: Present value of the five forecast years | C29: =SUM(B19:F19)
A30: Present value of the terminal value | C30: =C28*F18
A31: Enterprise value | C31: =C29+C30
A32: Terminal value as a share of enterprise value | C32: =C30/C31
A33: Less lease liabilities | C33: =-Assumptions!$C$87
A34: Plus cash and bank deposits | C34: =Assumptions!$C$88
A35: Less bank debt | C35: =-Assumptions!$C$89
A36: Less non-controlling interests | C36: =-Assumptions!$C$90
A37: Equity value | C37: =C31+C33+C34+C35+C36
A38: Fair value per share at 31 December 2025 (USD) | C38: =C37/Assumptions!$C$7 | D38: Anchor roll factor | E38: =(1+C52)^(Assumptions!$C$117/365)
A39: Fair value per share at the 7 August 2026 anchor (AED) — rolled at the cost of equity, net of the dividend paid in the window | C39: =(C38*E38-Assumptions!$C$118)*Assumptions!$C$6
A41: THE COST OF CAPITAL — BUILT HERE, NOT PASTED
A42: The glide | B42: FY2026E | C42: FY2027E | D42: FY2028E | E42: FY2029E | F42: FY2030E
A43: Effective tax rate path | B43: =Assumptions!B$71 | C43: =Assumptions!C$71 | D43: =Assumptions!D$71 | E43: =Assumptions!E$71 | F43: =Assumptions!F$71
...

Sheet Income Statement
A1: Income statement — three years of history, five of forecast
A2: USD million, consolidated. Every historical figure is the audited record; every forecast line is a formula.
A4: USD million | B4: FY2023 | C4: FY2024 | D4: FY2025 | E4: FY2026E | F4: FY2027E | G4: FY2028E | H4: FY2029E | I4: FY2030E
A5: Revenue | B5: 2413.134 | C5: 2196.751 | D5: 2508.821 | E5: =Segments!E36 | F5: =Segments!F36 | G5: =Segments!G36 | H5: =Segments!H36 | I5: =Segments!I36
A6: Cost of revenues | B6: -1151.575 | C6: -1029.357 | D6: -1143.928 | E6: - | F6: - | G6: - | H6: - | I6: -
A7: Gross profit | B7: =B5+B6 | C7: =C5+C6 | D7: =D5+D6 | E7: - | F7: - | G7: - | H7: - | I7: -
A8: EBITDA | B8: 545.957 | C8: 483.685 | D8: 595.604 | E8: =DCF!B8 | F8: =DCF!C8 | G8: =DCF!D8 | H8: =DCF!E8 | I8: =DCF!F8
A9: EBITDA margin | B9: =B8/B5 | C9: =C8/C5 | D9: =D8/D5 | E9: =E8/E5 | F9: =F8/F5 | G9: =G8/G5 | H9: =H8/H5 | I9: =I8/I5
A10: Depreciation and amortisation | B10: =-'Cash Flow'!B8 | C10: =-'Cash Flow'!C8 | D10: =-'Cash Flow'!D8 | E10: =-'Cash Flow'!E8 | F10: =-'Cash Flow'!F8 | G10: =-'Cash Flow'!G8 | H10: =-'Cash Flow'!H8 | I10: =-'Cash Flow'!I8
A11: EBIT, before the impairment line beneath | B11: =B8+B10 | C11: =C8+C10 | D11: =D8+D10 | E11: =E8+E10 | F11: =F8+F10 | G11: =G8+G10 | H11: =H8+H10 | I11: =I8+I10
A12: Impairment losses — audited history, and the recurring charge in the forecast | B12: -2.386 | C12: -13.724 | D12: -5.81 | E12: =-E5*Assumptions!$C$115 | F12: =-F5*Assumptions!$C$115 | G12: =-G5*Assumptions!$C$115 | H12: =-H5*Assumptions!$C$115 | I12: =-I5*Assumptions!$C$115
A13: Finance income | B13: 15.312 | C13: 16.116 | D13: 15.508 | E13: =Assumptions!$C$73*'Balance Sheet'!D9 | F13: =Assumptions!$C$73*'Balance Sheet'!E9 | G13: =Assumptions!$C$73*'Balance Sheet'!F9 | H13: =Assumptions!$C$73*'Balance Sheet'!G9 | I13: =Assumptions!$C$73*'Balance Sheet'!H9
A14: Finance costs | B14: -31.014 | C14: -35.793 | D14: -44.135 | E14: =-Assumptions!$C$82*'Balance Sheet'!D12-Assumptions!$C$74*E5 | F14: =-Assumptions!$C$82*'Balance Sheet'!E12-Assumptions!$C$74*F5 | G14: =-Assumptions!$C$82*'Balance Sheet'!F12-Assumptions!$C$74*G5 | H14: =-Assumptions!$C$82*'Balance Sheet'!G12-Assumptions!$C$74*H5 | I14: =-Assumptions!$C$82*'Balance Sheet'!H12-Assumptions!$C$74*I5
A15: Profit before tax | B15: =B11+B12+B13+B14 | C15: =C11+C12+C13+C14 | D15: =D11+D12+D13+D14 | E15: =E11+E12+E13+E14 | F15: =F11+F12+F13+F14 | G15: =G11+G12+G13+G14 | H15: =H11+H12+H13+H14 | I15: =I11+I12+I13+I14
A16: Income tax and zakat | B16: -13.041 | C16: -20.727 | D16: -35.651 | E16: =-E15*Assumptions!B$71 | F16: =-F15*Assumptions!C$71 | G16: =-G15*Assumptions!D$71 | H16: =-H15*Assumptions!E$71 | I16: =-I15*Assumptions!F$71
A17: Profit for the year | B17: =B15+B16 | C17: =C15+C16 | D17: =D15+D16 | E17: =E15+E16 | F17: =F15+F16 | G17: =G15+G16 | H17: =H15+H16 | I17: =I15+I16
A18: Non-controlling interests | B18: -2.865 | C18: 7.355 | D18: 0.673 | E18: - | F18: - | G18: - | H18: - | I18: -
A19: Profit attributable to shareholders | B19: =B17+B18 | C19: =C17+C18 | D19: =D17+D18 | E19: =E17 | F19: =F17 | G19: =G17 | H19: =H17 | I19: =I17
A20: Earnings per share (USD) | B20: =B19/Assumptions!$C$7 | C20: =C19/Assumptions!$C$7 | D20: =D19/Assumptions!$C$7 | E20: =E19/Assumptions!$C$7 | F20: =F19/Assumptions!$C$7 | G20: =G19/Assumptions!$C$7 | H20: =H19/Assumptions!$C$7 | I20: =I19/Assumptions!$C$7
A22: EBIT here is EBITDA less depreciation, so it sits ABOVE the impairment charges; the audited operating profit is EBIT after those charges. Impairments are a recurring feature of a large restaurant estate — some brand-country units are always underperforming — but they are not forecast as a line, so the forecast columns carry none and the free-cash-flow waterfall is struck before them. The non-controlling interest is a rounding item, 0.98 million of a 490 million equity at the last year end and negative at the half year, so the forecast carries none.

Sheet Balance Sheet
A1: Balance sheet — condensed, three years of history and five of forecast
A2: USD million. Every historical line is the audited closing figure. Every forecast line rolls forward: assets from capital expenditure less depreciation, working capital off revenue, equity from profit less dividends, and the lease liability from additions, interest and payments.
A4: USD million | B4: FY2023 | C4: FY2024 | D4: FY2025 | E4: FY2026E | F4: FY2027E | G4: FY2028E | H4: FY2029E | I4: FY2030E
A5: Property, equipment, intangibles and investment property | B5: 399.465 | C5: 391.318 | D5: =Assumptions!$C$93 | E5: =D5+'Cash Flow'!E10-'Cash Flow'!E6 | F5: =E5+'Cash Flow'!F10-'Cash Flow'!F6 | G5: =F5+'Cash Flow'!G10-'Cash Flow'!G6 | H5: =G5+'Cash Flow'!H10-'Cash Flow'!H6 | I5: =H5+'Cash Flow'!I10-'Cash Flow'!I6
A6: Right-of-use assets | B6: 498.503 | C6: 566.054 | D6: =Assumptions!$C$94 | E6: =D6+'Cash Flow'!E11-'Cash Flow'!E7 | F6: =E6+'Cash Flow'!F11-'Cash Flow'!F7 | G6: =F6+'Cash Flow'!G11-'Cash Flow'!G7 | H6: =G6+'Cash Flow'!H11-'Cash Flow'!H7 | I6: =H6+'Cash Flow'!I11-'Cash Flow'!I7
A7: Inventories | B7: 155.593 | C7: 134.399 | D7: 155.08
A8: Trade and other receivables | B8: 109.332 | C8: 110.421 | D8: 128.007
A9: Cash and bank deposits | B9: 383.541 | C9: 295.165 | D9: 417.41 | E9: =D9+'Cash Flow'!E18 | F9: =E9+'Cash Flow'!F18 | G9: =F9+'Cash Flow'!G18 | H9: =G9+'Cash Flow'!H18 | I9: =H9+'Cash Flow'!I18
A10: Net working capital | B10: -222.444 | C10: -195.475 | D10: =Assumptions!$C$92 | E10: =Assumptions!$C$68*'Income Statement'!E5 | F10: =Assumptions!$C$68*'Income Statement'!F5 | G10: =Assumptions!$C$68*'Income Statement'!G5 | H10: =Assumptions!$C$68*'Income Statement'!H5 | I10: =Assumptions!$C$68*'Income Statement'!I5
A11: Payables, tax and provisions (the company’s own working-capital aggregate) | B11: 487.369 | C11: 440.295 | D11: 531.102
A12: Lease liabilities | B12: 507.182 | C12: 578.831 | D12: 637.466 | E12: =D12+'Cash Flow'!E11+Assumptions!$C$82*D12-'Cash Flow'!E16 | F12: =E12+'Cash Flow'!F11+Assumptions!$C$82*E12-'Cash Flow'!F16 | G12: =F12+'Cash Flow'!G11+Assumptions!$C$82*F12-'Cash Flow'!G16 | H12: =G12+'Cash Flow'!H11+Assumptions!$C$82*G12-'Cash Flow'!H16 | I12: =H12+'Cash Flow'!I11+Assumptions!$C$82*H12-'Cash Flow'!I16
A13: Bank debt | B13: 4.375 | C13: 0 | D13: 0
A14: Equity attributable to shareholders | B14: 439.366 | C14: 394.438 | D14: =Assumptions!$C$91 | E14: =D14+'Income Statement'!E17-'Cash Flow'!E17 | F14: =E14+'Income Statement'!F17-'Cash Flow'!F17 | G14: =F14+'Income Statement'!G17-'Cash Flow'!G17 | H14: =G14+'Income Statement'!H17-'Cash Flow'!H17 | I14: =H14+'Income Statement'!I17-'Cash Flow'!I17
A15: Non-controlling interests | B15: 12.014 | C15: 3.686 | D15: 0.984
A16: Total assets | B16: 1556.859 | C16: 1507.4 | D16: 1734.126
A17: Net debt — lease liabilities and bank debt less cash and deposits | B17: =B12+B13-B9 | C17: =C12+C13-C9 | D17: =D12+D13-D9 | E17: =E12-E9 | F17: =F12-F9 | G17: =G12-G9 | H17: =H12-H9 | I17: =I12-I9
A18: Invested capital — owned assets, right-of-use assets and working capital | E18: =E5+E6+E10 | F18: =F5+F6+F10 | G18: =G5+G6+G10 | H18: =H5+H6+H10 | I18: =I5+I6+I10
A19: Return on invested capital | E19: =DCF!B12/E18 | F19: =DCF!C12/F18 | G19: =DCF!D12/G18 | H19: =DCF!E12/H18 | I19: =DCF!F12/I18
A20: Net debt / EBITDA | B20: =B17/'Income Statement'!B8 | C20: =C17/'Income Statement'!C8 | D20: =D17/'Income Statement'!D8 | E20: =E17/'Income Statement'!E8 | F20: =F17/'Income Statement'!F8 | G20: =G17/'Income Statement'!G8 | H20: =H17/'Income Statement'!H8 | I20: =I17/'Income Statement'!I8
A22: This is a CONDENSED layout: it does not foot to zero, because the provisions, employee end-of-service liability, deferred tax and related-party balances are not shown as separate lines. The lines that do appear are the audited closing figures.

Sheet Cash Flow
A1: Cash flow — historical markers and the forecast waterfall
A2: USD million. The forecast columns are the engine of the whole model: the depreciation, capital-expenditure and working-capital lines the discounted cash flow reads are computed here.
A4: USD million | B4: FY2023 | C4: FY2024 | D4: FY2025 | E4: FY2026E | F4: FY2027E | G4: FY2028E | H4: FY2029E | I4: FY2030E
A5: EBITDA | B5: ='Income Statement'!B8 | C5: ='Income Statement'!C8 | D5: ='Income Statement'!D8 | E5: ='Income Statement'!E8 | F5: ='Income Statement'!F8 | G5: ='Income Statement'!G8 | H5: ='Income Statement'!H8 | I5: ='Income Statement'!I8
A6: Owned-asset depreciation and amortisation | B6: 79.796 | C6: 94.343 | D6: 101.5 | E6: =Assumptions!$C$67*'Balance Sheet'!D5 | F6: =Assumptions!$C$67*'Balance Sheet'!E5 | G6: =Assumptions!$C$67*'Balance Sheet'!F5 | H6: =Assumptions!$C$67*'Balance Sheet'!G5 | I6: =Assumptions!$C$67*'Balance Sheet'!H5
A7: Right-of-use depreciation | B7: 172.701 | C7: 183.81 | D7: 205.566 | E7: =Assumptions!$C$66*'Balance Sheet'!D6 | F7: =Assumptions!$C$66*'Balance Sheet'!E6 | G7: =Assumptions!$C$66*'Balance Sheet'!F6 | H7: =Assumptions!$C$66*'Balance Sheet'!G6 | I7: =Assumptions!$C$66*'Balance Sheet'!H6
A8: Depreciation and amortisation | B8: =B6+B7 | C8: =C6+C7 | D8: =D6+D7 | E8: =E6+E7 | F8: =F6+F7 | G8: =G6+G7 | H8: =H6+H7 | I8: =I6+I7
A9: Gross openings — net additions plus closures | E9: =Assumptions!B$11+Segments!C12*Assumptions!$C$63 | F9: =Assumptions!C$11+Segments!D12*Assumptions!$C$63 | G9: =Assumptions!D$11+Segments!E12*Assumptions!$C$63 | H9: =Assumptions!E$11+Segments!F12*Assumptions!$C$63 | I9: =Assumptions!F$11+Segments!G12*Assumptions!$C$63
A10: Owned capital expenditure | B10: 149.819 | C10: 124.309 | D10: 108.776 | E10: =E9*Assumptions!$C$61/1000+Assumptions!$C$62*'Income Statement'!E5 | F10: =F9*Assumptions!$C$61/1000+Assumptions!$C$62*'Income Statement'!F5 | G10: =G9*Assumptions!$C$61/1000+Assumptions!$C$62*'Income Statement'!G5 | H10: =H9*Assumptions!$C$61/1000+Assumptions!$C$62*'Income Statement'!H5 | I10: =I9*Assumptions!$C$61/1000+Assumptions!$C$62*'Income Statement'!I5
A11: Additions to right-of-use assets | C11: 279.4 | D11: 255.162 | E11: =Assumptions!$C$64*'Income Statement'!E5 | F11: =Assumptions!$C$64*'Income Statement'!F5 | G11: =Assumptions!$C$64*'Income Statement'!G5 | H11: =Assumptions!$C$64*'Income Statement'!H5 | I11: =Assumptions!$C$64*'Income Statement'!I5
A12: Capital expenditure, including right-of-use additions | E12: =E10+E11 | F12: =F10+F11 | G12: =G10+G11 | H12: =H10+H11 | I12: =I10+I11
A13: Change in net working capital | E13: ='Balance Sheet'!E10-'Balance Sheet'!D10 | F13: ='Balance Sheet'!F10-'Balance Sheet'!E10 | G13: ='Balance Sheet'!G10-'Balance Sheet'!F10 | H13: ='Balance Sheet'!H10-'Balance Sheet'!G10 | I13: ='Balance Sheet'!I10-'Balance Sheet'!H10
A14: Tax | B14: 13.041 | C14: 20.727 | D14: 35.651 | E14: ='Income Statement'!E16*-1 | F14: ='Income Statement'!F16*-1 | G14: ='Income Statement'!G16*-1 | H14: ='Income Statement'!H16*-1 | I14: ='Income Statement'!I16*-1
A15: Free cash flow to the firm | E15: =DCF!B16 | F15: =DCF!C16 | G15: =DCF!D16 | H15: =DCF!E16 | I15: =DCF!F16
A16: Lease payments — principal and interest | B16: 200.138 | C16: 211.917 | D16: 233.272 | E16: =Assumptions!$C$65*'Income Statement'!E5 | F16: =Assumptions!$C$65*'Income Statement'!F5 | G16: =Assumptions!$C$65*'Income Statement'!G5 | H16: =Assumptions!$C$65*'Income Statement'!H5 | I16: =Assumptions!$C$65*'Income Statement'!I5
A17: Dividends paid | B17: 103.312 | C17: 179.424 | D17: 126.987 | E17: =Assumptions!$C$72*'Income Statement'!E17 | F17: =Assumptions!$C$72*'Income Statement'!F17 | G17: =Assumptions!$C$72*'Income Statement'!G17 | H17: =Assumptions!$C$72*'Income Statement'!H17 | I17: =Assumptions!$C$72*'Income Statement'!I17
A18: Movement in cash and deposits | E18: =E5+'Income Statement'!E13-'Income Statement'!E5*Assumptions!$C$74-E14-E13-E10-E16-E17 | F18: =F5+'Income Statement'!F13-'Income Statement'!F5*Assumptions!$C$74-F14-F13-F10-F16-F17 | G18: =G5+'Income Statement'!G13-'Income Statement'!G5*Assumptions!$C$74-G14-G13-G10-G16-G17 | H18: =H5+'Income Statement'!H13-'Income Statement'!H5*Assumptions!$C$74-H14-H13-H10-H16-H17 | I18: =I5+'Income Statement'!I13-'Income Statement'!I5*Assumptions!$C$74-I14-I13-I10-I16-I17
A19: Cash and deposits, closing | E19: ='Balance Sheet'!E9 | F19: ='Balance Sheet'!F9 | G19: ='Balance Sheet'!G9 | H19: ='Balance Sheet'!H9 | I19: ='Balance Sheet'!I9
A20: Cash generated from operations, as reported | B20: 539.787 | C20: 432.801 | D20: 588.997
A22: The forecast free-cash-flow line is free cash flow to the FIRM on the capitalised-lease reading: taking a new restaurant lease is an investment, so right-of-use additions are charged as capital expenditure and the matching lease liability is deducted in the bridge to equity. Adding back right-of-use depreciation without charging the additions would count the shield and never pay for the asset.

Sheet Summary Financials
A1: Summary financials — the eight-year picture
A2: USD million unless stated. Every cell on this sheet is a link or a ratio; nothing is typed twice.
A4: USD million | B4: FY2023 | C4: FY2024 | D4: FY2025 | E4: FY2026E | F4: FY2027E | G4: FY2028E | H4: FY2029E | I4: FY2030E
A5: Revenue | B5: ='Income Statement'!B5 | C5: ='Income Statement'!C5 | D5: ='Income Statement'!D5 | E5: ='Income Statement'!E5 | F5: ='Income Statement'!F5 | G5: ='Income Statement'!G5 | H5: ='Income Statement'!H5 | I5: ='Income Statement'!I5
A6: EBITDA | B6: ='Income Statement'!B8 | C6: ='Income Statement'!C8 | D6: ='Income Statement'!D8 | E6: ='Income Statement'!E8 | F6: ='Income Statement'!F8 | G6: ='Income Statement'!G8 | H6: ='Income Statement'!H8 | I6: ='Income Statement'!I8
A7: EBITDA margin | B7: ='Income Statement'!B9 | C7: ='Income Statement'!C9 | D7: ='Income Statement'!D9 | E7: ='Income Statement'!E9 | F7: ='Income Statement'!F9 | G7: ='Income Statement'!G9 | H7: ='Income Statement'!H9 | I7: ='Income Statement'!I9
A8: EBIT (before impairments in the forecast) | B8: ='Income Statement'!B11 | C8: ='Income Statement'!C11 | D8: ='Income Statement'!D11 | E8: ='Income Statement'!E11 | F8: ='Income Statement'!F11 | G8: ='Income Statement'!G11 | H8: ='Income Statement'!H11 | I8: ='Income Statement'!I11
A9: Profit attributable to shareholders | B9: ='Income Statement'!B19 | C9: ='Income Statement'!C19 | D9: ='Income Statement'!D19 | E9: ='Income Statement'!E19 | F9: ='Income Statement'!F19 | G9: ='Income Statement'!G19 | H9: ='Income Statement'!H19 | I9: ='Income Statement'!I19
A10: Net debt | B10: ='Balance Sheet'!B17 | C10: ='Balance Sheet'!C17 | D10: ='Balance Sheet'!D17 | E10: ='Balance Sheet'!E17 | F10: ='Balance Sheet'!F17 | G10: ='Balance Sheet'!G17 | H10: ='Balance Sheet'!H17 | I10: ='Balance Sheet'!I17
A11: Revenue growth | B11: - | C11: =C5/B5-1 | D11: =D5/C5-1 | E11: =E5/D5-1 | F11: =F5/E5-1 | G11: =G5/F5-1 | H11: =H5/G5-1 | I11: =I5/H5-1
A12: Free cash flow to the firm | B12: - | C12: - | D12: - | E12: ='Cash Flow'!E15 | F12: ='Cash Flow'!F15 | G12: ='Cash Flow'!G15 | H12: ='Cash Flow'!H15 | I12: ='Cash Flow'!I15
A13: Invested capital | B13: - | C13: - | D13: - | E13: ='Balance Sheet'!E18 | F13: ='Balance Sheet'!F18 | G13: ='Balance Sheet'!G18 | H13: ='Balance Sheet'!H18 | I13: ='Balance Sheet'!I18
A14: Return on invested capital | B14: - | C14: - | D14: - | E14: ='Balance Sheet'!E19 | F14: ='Balance Sheet'!F19 | G14: ='Balance Sheet'!G19 | H14: ='Balance Sheet'!H19 | I14: ='Balance Sheet'!I19

Sheet Monte Carlo
A1: The probability price map
A2: A map of price dispersion. It carries no view on value and is never blended with the valuation. Each figure is an engine output — fifty thousand simulated paths — not a formula, so it does not redraw when a driver changes.
A4: Horizon | B4: 5th | C4: 25th | D4: Median | E4: 75th | F4: 95th | G4: Chance above the market
A5: One month — to 2026-09-07 | B5: 1.9343752 | C5: 2.1266922 | D5: 2.2417207 | E5: 2.3631805 | F5: 2.6046186 | G5: 0.52706
A6: Three months — to 2026-11-09 | B6: 1.7299964 | C6: 2.0531236 | D6: 2.2529117 | E6: 2.4712445 | F6: 2.9373235 | G6: 0.53034
A8: Level event | B8: One month | C8: Three months
A9: Finishes 10% or more above the market price | B9: 0.13496 | C9: 0.26606
A10: Finishes 10% or more below the market price | B10: 0.09548 | C10: 0.2041
A11: Touches 10% above at any point | B11: 0.21854 | C11: 0.47326
A12: Touches 10% below at any point | B12: 0.15958 | C12: 0.38804
A14: Engine setting | B14: Value
A15: Simulated paths | B15: 50000
A16: Anchor date | B16: 2026-08-07
A17: Market price at the anchor (AED) | B17: 2.23
A18: Annualised volatility at the anchor | B18: 0.35617193
A19: Dividend yield inside the drift anchor | B19: 0.036878661

Sheet Sensitivity
A1: Sensitivity — what the valuation needs the world to do
A2: AED per share. Each cell is a complete re-run of the model, including the unit build, so these grids are engine outputs rather than formulas and do NOT redraw when a driver is changed.
A4: Cost of capital (rows) against terminal growth (columns)
B5: 2.0% | C5: 2.5% | D5: 3.0% | E5: 3.5% | F5: 4.0%
A6: 8.23% | B6: 2.5848793 | C6: 2.7398861 | D6: 2.9240349 | E6: 3.1465492 | F6: 3.4210037
A7: 8.98% | B7: 2.2792869 | C7: 2.3947521 | D7: 2.5291213 | E7: 2.6875602 | F7: 2.8773049
A8: 9.73% | B8: 2.0331363 | C8: 2.1212971 | D8: 2.2222179 | E8: 2.3389663 | F8: 2.4756788
A9: 10.48% | B9: 1.8306656 | C9: 1.8993289 | D9: 1.9768807 | E9: 2.0652285 | F9: 2.1668679
A10: 11.23% | B10: 1.661231 | C10: 1.715587 | D10: 1.7762943 | E10: 1.8445839 | F10: 1.922027
A12: Cost of capital (rows) against the EBITDA margin (columns)
B13: -2.0pp | C13: -1.0pp | D13: +0.0pp | E13: +1.0pp | F13: +2.0pp
A14: 8.23% | B14: 2.4760738 | C14: 2.7000543 | D14: 2.9240349 | E14: 3.1480154 | F14: 3.371996
A15: 8.98% | B15: 2.1370593 | C15: 2.3330903 | D15: 2.5291213 | E15: 2.7251524 | F15: 2.9211834
A16: 9.73% | B16: 1.8736319 | C16: 2.0479249 | D16: 2.2222179 | E16: 2.3965109 | F16: 2.570804
A17: 10.48% | B17: 1.6630788 | C17: 1.8199798 | D17: 1.9768807 | E17: 2.1337816 | F17: 2.2906826
A18: 11.23% | B18: 1.4909573 | C18: 1.6336258 | D18: 1.7762943 | E18: 1.9189627 | F18: 2.0616312
A20: One driver at a time — five re-runs a row, the grid shown beside the name | H20: Swing
A21: Like-for-like sales growth (−1.0pp / −0.5pp / base / +0.5pp / +1.0pp) | B21: 2.0788977 | C21: 2.1498485 | D21: 2.2222179 | E21: 2.296027 | F21: 2.371297 | H21: =MAX(B21:F21)-MIN(B21:F21)
A22: EBITDA margin (−2.0pp / −1.0pp / base / +1.0pp / +2.0pp) | B22: 1.8736319 | C22: 2.0479249 | D22: 2.2222179 | E22: 2.3965109 | F22: 2.570804 | H22: =MAX(B22:F22)-MIN(B22:F22)
A23: Cost of capital (−1.5pp / −0.75pp / base / +0.75pp / +1.5pp) | B23: 2.9240349 | C23: 2.5291213 | D23: 2.2222179 | E23: 1.9768807 | F23: 1.7762943 | H23: =MAX(B23:F23)-MIN(B23:F23)
A24: Terminal growth (2.0% / 2.5% / 3.0% / 3.5% / 4.0%) | B24: 2.0331363 | C24: 2.1212971 | D24: 2.2222179 | E24: 2.3389663 | F24: 2.4756788 | H24: =MAX(B24:F24)-MIN(B24:F24)
A26: The margin row is the one that matters. A two-point swing in the EBITDA margin is worth more than the whole plausible range of the cost of capital, which is why the structural-versus-cyclical question is the study's central judgement rather than a footnote.

Sheet Per-Share & Ratios
A1: Per-share and ratio analysis
A2: The indicator set a multi-country restaurant operator is actually judged on: like-for-like growth, revenue per restaurant, the four-wall margin, the return on the capital a restaurant costs, and the cash it converts. Every ratio is a formula off the statements.
A4: Measure | B4: FY2023 | C4: FY2024 | D4: FY2025 | E4: FY2026E | F4: FY2027E | G4: FY2028E | H4: FY2029E | I4: FY2030E
A5: Earnings per share (USD) | B5: ='Income Statement'!B20 | C5: ='Income Statement'!C20 | D5: ='Income Statement'!D20 | E5: ='Income Statement'!E20 | F5: ='Income Statement'!F20 | G5: ='Income Statement'!G20 | H5: ='Income Statement'!H20 | I5: ='Income Statement'!I20
A6: Earnings per share (AED) | B6: =B5*Assumptions!$C$6 | C6: =C5*Assumptions!$C$6 | D6: =D5*Assumptions!$C$6 | E6: =E5*Assumptions!$C$6 | F6: =F5*Assumptions!$C$6 | G6: =G5*Assumptions!$C$6 | H6: =H5*Assumptions!$C$6 | I6: =I5*Assumptions!$C$6
A7: Book value per share (USD) | B7: ='Balance Sheet'!B14/Assumptions!$C$7 | C7: ='Balance Sheet'!C14/Assumptions!$C$7 | D7: ='Balance Sheet'!D14/Assumptions!$C$7 | E7: ='Balance Sheet'!E14/Assumptions!$C$7 | F7: ='Balance Sheet'!F14/Assumptions!$C$7 | G7: ='Balance Sheet'!G14/Assumptions!$C$7 | H7: ='Balance Sheet'!H14/Assumptions!$C$7 | I7: ='Balance Sheet'!I14/Assumptions!$C$7
A8: EBITDA margin | B8: ='Income Statement'!B9 | C8: ='Income Statement'!C9 | D8: ='Income Statement'!D9 | E8: ='Income Statement'!E9 | F8: ='Income Statement'!F9 | G8: ='Income Statement'!G9 | H8: ='Income Statement'!H9 | I8: ='Income Statement'!I9
A9: EBIT margin | B9: ='Income Statement'!B11/'Income Statement'!B5 | C9: ='Income Statement'!C11/'Income Statement'!C5 | D9: ='Income Statement'!D11/'Income Statement'!D5 | E9: ='Income Statement'!E11/'Income Statement'!E5 | F9: ='Income Statement'!F11/'Income Statement'!F5 | G9: ='Income Statement'!G11/'Income Statement'!G5 | H9: ='Income Statement'!H11/'Income Statement'!H5 | I9: ='Income Statement'!I11/'Income Statement'!I5
A10: Net margin | B10: ='Income Statement'!B19/'Income Statement'!B5 | C10: ='Income Statement'!C19/'Income Statement'!C5 | D10: ='Income Statement'!D19/'Income Statement'!D5 | E10: ='Income Statement'!E19/'Income Statement'!E5 | F10: ='Income Statement'!F19/'Income Statement'!F5 | G10: ='Income Statement'!G19/'Income Statement'!G5 | H10: ='Income Statement'!H19/'Income Statement'!H5 | I10: ='Income Statement'!I19/'Income Statement'!I5
A11: Revenue per restaurant (USD thousand) | B11: - | C11: - | D11: - | E11: ='Income Statement'!E5/Segments!C12*1000 | F11: ='Income Statement'!F5/Segments!D12*1000 | G11: ='Income Statement'!G5/Segments!E12*1000 | H11: ='Income Statement'!H5/Segments!F12*1000 | I11: ='Income Statement'!I5/Segments!G12*1000
A12: Restaurants at year end | B12: - | C12: - | D12: - | E12: =Segments!C12 | F12: =Segments!D12 | G12: =Segments!E12 | H12: =Segments!F12 | I12: =Segments!G12
A13: Return on equity | B13: - | C13: ='Income Statement'!C19/(('Balance Sheet'!B14+'Balance Sheet'!C14)/2) | D13: ='Income Statement'!D19/(('Balance Sheet'!C14+'Balance Sheet'!D14)/2) | E13: ='Income Statement'!E19/(('Balance Sheet'!D14+'Balance Sheet'!E14)/2) | F13: ='Income Statement'!F19/(('Balance Sheet'!E14+'Balance Sheet'!F14)/2) | G13: ='Income Statement'!G19/(('Balance Sheet'!F14+'Balance Sheet'!G14)/2) | H13: ='Income Statement'!H19/(('Balance Sheet'!G14+'Balance Sheet'!H14)/2) | I13: ='Income Statement'!I19/(('Balance Sheet'!H14+'Balance Sheet'!I14)/2)
A14: Return on invested capital | B14: - | C14: - | D14: - | E14: ='Balance Sheet'!E19 | F14: ='Balance Sheet'!F19 | G14: ='Balance Sheet'!G19 | H14: ='Balance Sheet'!H19 | I14: ='Balance Sheet'!I19
A15: Net debt / EBITDA | B15: ='Balance Sheet'!B20 | C15: ='Balance Sheet'!C20 | D15: ='Balance Sheet'!D20 | E15: ='Balance Sheet'!E20 | F15: ='Balance Sheet'!F20 | G15: ='Balance Sheet'!G20 | H15: ='Balance Sheet'!H20 | I15: ='Balance Sheet'!I20
A16: Net working capital / revenue | B16: ='Balance Sheet'!B10/'Income Statement'!B5 | C16: ='Balance Sheet'!C10/'Income Statement'!C5 | D16: ='Balance Sheet'!D10/'Income Statement'!D5 | E16: ='Balance Sheet'!E10/'Income Statement'!E5 | F16: ='Balance Sheet'!F10/'Income Statement'!F5 | G16: ='Balance Sheet'!G10/'Income Statement'!G5 | H16: ='Balance Sheet'!H10/'Income Statement'!H5 | I16: ='Balance Sheet'!I10/'Income Statement'!I5
A17: Capital expenditure / revenue | B17: ='Cash Flow'!B10/'Income Statement'!B5 | C17: ='Cash Flow'!C10/'Income Statement'!C5 | D17: ='Cash Flow'!D10/'Income Statement'!D5 | E17: ='Cash Flow'!E12/'Income Statement'!E5 | F17: ='Cash Flow'!F12/'Income Statement'!F5 | G17: ='Cash Flow'!G12/'Income Statement'!G5 | H17: ='Cash Flow'!H12/'Income Statement'!H5 | I17: ='Cash Flow'!I12/'Income Statement'!I5
A18: Dividend per share (USD) | B18: ='Cash Flow'!B17/Assumptions!$C$7 | C18: ='Cash Flow'!C17/Assumptions!$C$7 | D18: ='Cash Flow'!D17/Assumptions!$C$7 | E18: ='Cash Flow'!E17/Assumptions!$C$7 | F18: ='Cash Flow'!F17/Assumptions!$C$7 | G18: ='Cash Flow'!G17/Assumptions!$C$7 | H18: ='Cash Flow'!H17/Assumptions!$C$7 | I18: ='Cash Flow'!I17/Assumptions!$C$7

Sheet Peer & Sector
A1: Peer frame and sector context
A2: A cross-check, not an independent valuation. No figure on this sheet enters the build; Americana’s own historicals come exclusively from its audited consolidated financial statements.
A4: Company | B4: Market | C4: EV / EBITDA | D4: Price / earnings | E4: EBITDA margin | F4: Why it is here
A5: Alamar Foods | B5: Saudi Arabia | C5: 115.53 | D5: - | E5: 0.02580007 | F5: Regional franchisee operator (Domino’s, Wendy’s MENA)
A6: Herfy Food Services | B6: Saudi Arabia | C6: 17.61 | D6: - | E6: 0.075627633 | F6: Saudi QSR operator and food manufacturer
A7: Halwani Bros | B7: Saudi Arabia | C7: 11.25 | D7: 23.08 | E7: 0.12148904 | F7: Saudi packaged-food peer (consumer cross-check)
A8: Alsea | B8: Mexico | C8: 6.02 | D8: 16.43 | E8: 0.15295141 | F8: Largest Latin-American franchisee operator (Starbucks, Domino’s, BK)
A9: Jubilant FoodWorks | B9: India | C9: 23.05 | D9: 85.5 | E9: 0.14542687 | F9: Master franchisee, Domino’s India
A10: Devyani International | B10: India | C10: 33.28 | D10: - | E10: 0.10449152 | F10: Master franchisee, KFC/Pizza Hut India — closest structural analogue
A11: Sapphire Foods | B11: India | C11: 27.59 | D11: - | E11: 0.094884119 | F11: Master franchisee, KFC/Pizza Hut India
A12: Yum! Brands | B12: United States | C12: 17.56 | D12: 18.96 | E12: 0.35175419 | F12: Franchisor of KFC, Pizza Hut, Taco Bell
A13: Yum China | B13: China | C13: 9.47 | D13: 17.48 | E13: 0.15106931 | F13: Licensee-operator of KFC/Pizza Hut in China
A14: Restaurant Brands Intl. | B14: Canada | C14: 14.32 | D14: 18.57 | E14: 0.30147437 | F14: Franchisor of Burger King, Tim Hortons, Popeyes
A15: Domino's Pizza | B15: United States | C15: 16.19 | D15: 19.88 | E15: 0.20357034 | F15: Franchisor, delivery-led QSR
A17: Peer median, enterprise value / EBITDA — MEDIAN over the rows inside the stated band of 4x to 40x (one exclusion: the row whose multiple is an arithmetic artefact of a depressed year) | C17: =MEDIAN(C6,C7,C8,C9,C10,C11,C12,C13,C14,C15)
A18: Peer median, price / earnings — MEDIAN over the rows inside the stated band of 5x to 45x | D18: =MEDIAN(D7,D8,D12,D13,D14,D15)
A20: Americana — trailing enterprise value / EBITDA | C20: ='Relative & Normalized'!B16
A21: Americana — trailing price / earnings | D21: ='Relative & Normalized'!B17
A22: Justified multiple applied in the relative lens | C22: ='Relative & Normalized'!B6
A24: The set splits cleanly in two, and that split is why the justified multiple sits below the peer median. The global names — Yum! Brands, Restaurant Brands, Domino's — are franchisORS: they collect a royalty on someone else's sales and carry EBITDA margins of 20% to 35% on a fraction of the revenue. Americana is on the other side of that contract. It is the operator, it PAYS the royalty (5.6% of revenue in FY2025), and it carries the restaurants, the staff and the leases. The right comparators are the listed franchisees — Alsea in Mexico, Devyani and Sapphire in India, both of which run the same two brands Americana runs — and those trade across a very wide range on growth expectations rather than on any stable multiple.
