Workbook

Sheet READ FIRST
A1: Testahil — Elsewedy Electric Company S.A.E. (EGX: SWDY)
A3: Companion model · Independent Valuation Study · Educational analysis · Not investment advice
A5: What this workbook is. A transparent companion to the SWDY valuation study. Every blue cell is an input;
A6: every black cell is a formula; green cells link across sheets.
A8: IT IS FORMULA-DRIVEN. Every figure that can be derived arithmetically from a driver is a live formula, so
A9: you can change a blue cell on Assumptions and watch the model reprice: the cost of capital is built from
A10: the risk-free rate, beta and the premium rather than pasted; the discount factors compound from the glide;
A11: and the income statement, balance sheet, cash flow, ratios and all four lenses chain off the same cells.
A13: THREE THINGS ARE PASTED VALUES, and it is worth knowing exactly which. First, audited and disclosed history
A14: — the primary record, not a calculation. Second, the segment build: revenue and profit for the three
A15: segments the company itself discloses (Cables and its accessories, Constructions and infrastructure,
A16: Electrical products and digital solutions) are pasted for FY2025 and grown on their own drivers; only its
... A55: Ratios · Peer & Sector.

Sheet Summary
A1: Summary — valuation at a glance
A2: All values link live to their source sheets
A4: Lens | B4: Bear | C4: Base | D4: Bull | E4: Role | G4: vs price
A5: Discounted cash flow (the answer) | B5: 19.638024 | C5: =DCF!C62 | D5: 101.30676 | E5: THE CENTRAL — the class primary | G5: =C5/$C$16-1
A6: Relative multiples | B6: ='Relative & Normalized'!C12 | C6: ='Relative & Normalized'!C11 | D6: ='Relative & Normalized'!D12 | E6: cross-check | G6: =C6/$C$16-1
A7: Normalised earnings power | B7: ='Relative & Normalized'!E28 | C7: ='Relative & Normalized'!C28 | D7: ='Relative & Normalized'!F28 | E7: REMOVED — not a lens this class publishes | G7: =C7/$C$16-1
A8: Book value and sustainable return | B8: ='Relative & Normalized'!E36 | C8: ='Relative & Normalized'!C36 | D8: ='Relative & Normalized'!F36 | E8: a disclosed floor, never weighted | G8: =C8/$C$16-1
A9: THE CENTRAL — the cash-flow lens, not an average | B9: =B5 | C9: =C5 | D9: =D5 | E9: the class primary | G9: =C9/$C$16-1
A10: NOT AVERAGED — the retired 45/20/20/15 blend, published unused | C10: =C5*0.45+C6*0.2+C7*0.2+C8*0.15 | E10: retired 04-Sep-2026 | G10: =C10/$C$16-1
A11: Span across the lenses (min/max) — a spread between METHODS, not a range around the answer | B11: =MIN(B5:B8) | D11: =MAX(D5:D8)
A13: Alternative reading — currency of discounting | C13: ='Fundamental Valuation'!C18 | G13: =C13/$C$16-1
A14: Terminal value share of DCF enterprise value | C14: =DCF!C28
A15: Expert panel median | C15: ='Fundamental Valuation'!C26 | G15: =C15/$C$16-1
A16: Market price (anchor) | C16: 130
A18: Key figure | B18: Value
A19: Shares outstanding (mn) | C19: =Assumptions!$C$6
A20: Market capitalisation (EGP mn) | C20: =$C$16*C19
A21: Net bank debt, FY2025 (EGP mn) | C21: ='Balance Sheet'!D17
A22: FY2025 revenue (EGP mn) | C22: ='Income Statement'!D5
A23: FY2025 EBITDA (EGP mn) | C23: ='Income Statement'!D7
A24: FY2025 attributable profit (EGP mn) | C24: ='Income Statement'!D17
A25: Cost of capital — explicit window | C25: =DCF!C46
A26: Cost of capital — terminal | C26: =DCF!C53
A27: Terminal growth | C27: =DCF!C23

Sheet Fundamental Valuation
A1: Fundamental valuation — the four lenses and the alternative reading
A4: Lens / step | B4: Basis | C4: EGP per share
A5: Discounted cash flow | B5: links to the DCF sheet | C5: =DCF!C62
A6: bear | B6: margin −1.5pp, weaker currency path, +2pp cost of capital, g 3% | C6: 19.638024
A7: bull | B7: margin +1.5pp, stronger currency path, −2pp cost of capital, g 6% | C7: 101.30676
A8: Relative multiples | B8: 6.5x mid-cycle EV/EBITDA | C8: ='Relative & Normalized'!C11
A9: Normalised earnings power | B9: 9.0x normalised earnings per share | C9: ='Relative & Normalized'!C28
A10: Book value and sustainable return | B10: justified price-to-book on sustainable return on equity | C10: ='Relative & Normalized'!C36
A12: THE CENTRAL — the cash-flow lens itself, not an average of the four | C12: =Summary!C9
A14: THE CURRENCY-OF-DISCOUNTING QUESTION
A15: Share of forecast revenue earned in hard currency | C15: 0.52548567
A16: Cost of capital applied in the primary model (explicit → terminal) | C16: 26.9% → 15.9%
A17: Hard-currency cost of capital for the foreign leg | C17: =(1-Assumptions!$C$65)*(Assumptions!$C$62+Assumptions!$C$33*Assumptions!$C$63)+Assumptions!$C$65*Assumptions!$C$64*(1-Assumptions!$C$7)
A18: Fair value if the foreign leg is discounted at the hard-currency rate | C18: 70.847783
A19: Market price | C19: =Summary!C16
A21: EXPERT PANEL
A22: Expert | B22: Method | C22: Base (EGP/share) | D22: Low | E22: High
A23: Expert 1 | B23: earnings power | C23: 151.42235 | D23: 111.08752 | E23: 191.75718
A24: Expert 2 | B24: owner cash earnings | C24: 74.307968 | D24: 36.900474 | E24: 67.071416
A25: Expert 3 | B25: cash returns vs cost of capital | C25: 55.216839 | D25: 47.647163 | E25: 70.847783
A26: Panel median | C26: =MEDIAN(C23:C25)

Sheet Assumptions
A1: Assumptions — every input in the model
A2: Blue cells are inputs. Change one and the model reprices: everything downstream is a formula.
A3: Input | B3: FY26E | C3: FY27E | D3: FY28E | E3: FY29E | F3: FY30E
A4: Anchors
A5: Spot price (EGP) | C5: 130
A6: Shares outstanding (mn) | C6: 2140.7779
A7: Effective tax rate | C7: 0.245
A8: Statutory corporate tax rate | C8: 0.225
A9: FY2025 average USD/EGP | C9: 49.5
A11: Revenue drivers — the three disclosed segments
A12: Copper (USD/tonne) | B12: 13400 | C12: 14000 | D12: 14000 | E12: 14000 | F12: 14000
A13: USD/EGP path | B13: 51 | C13: 54 | D13: 57.5 | E13: 61 | F13: 64.5
A14: Cables — real (volume) growth over copper x FX | B14: 0.03 | C14: 0.03 | D14: 0.03 | E14: 0.03 | F14: 0.03
A15: Constructions and infrastructure — revenue growth | B15: 0.18 | C15: 0.14 | D15: 0.11 | E15: 0.09 | F15: 0.08
A16: Electrical products and digital solutions — revenue growth | B16: 0.2 | C16: 0.16 | D16: 0.13 | E16: 0.11 | F16: 0.1
A18: Segment gross margins and corporate cost load
A19: Cables — gross/segment margin | B19: 0.114341 | C19: 0.114341 | D19: 0.114341 | E19: 0.114341 | F19: 0.114341
A20: Constructions and infrastructure — segment margin | B20: 0.089871 | C20: 0.089871 | D20: 0.089871 | E20: 0.089871 | F20: 0.089871
A21: Electrical products and digital solutions — segment margin | B21: 0.236221 | C21: 0.236221 | D21: 0.236221 | E21: 0.236221 | F21: 0.236221
A22: Corporate cost load (% of revenue) — the bridge from segment profit to EBIT | B22: 0.0307 | C22: 0.0307 | D22: 0.0307 | E22: 0.0307 | F22: 0.0307
A24: Capital intensity
A25: Working capital / revenue | C25: 0.199
A26: Capital expenditure / revenue | B26: 0.044 | C26: 0.04 | D26: 0.036 | E26: 0.033 | F26: 0.031
A27: Depreciation and amortisation / revenue | C27: 0.0125
A29: Cost of capital
A30: Risk-free rate (10-year local currency) | C30: 0.2231
A31: Sovereign default spread (netted out) | C31: 0.034
A32: Equity risk premium | C32: 0.0941
A33: Beta | C33: 1.009
A34: Cost of debt, blended | C34: 0.095
A35: Cost of debt path | B35: 0.095 | C35: 0.089 | D35: 0.084 | E35: 0.08 | F35: 0.077
A36: Terminal risk-free rate | C36: 0.105
A37: Terminal equity risk premium | C37: 0.07
A38: Terminal cost of debt | C38: 0.0888
A39: Terminal debt weight | C39: 0.15
A40: Terminal growth | C40: 0.07
A42: Balance-sheet and bridge anchors
A43: Net bank debt at FY2025 (EGP mn, disclosed) | C43: 20560.003
A44: Equity-accounted investees at carrying value (EGP mn) | C44: 6757.6505
A45: Intangible assets and goodwill (EGP mn) | C45: 1748.8169
...

Sheet SOTP Bridge
A1: Enterprise value to equity — the bridge
A4: Step | B4: EGP mn | C4: Per share (EGP)
A5: Present value of the five forecast years | C5: =DCF!C26 | D5: =C5/Assumptions!$C$6
A6: Present value of the terminal value | C6: =DCF!C27 | D6: =C6/Assumptions!$C$6
A7: Enterprise value | C7: =C5+C6 | D7: =C7/Assumptions!$C$6
A8: Less net bank debt | C8: =-Assumptions!$C$43 | D8: =C8/Assumptions!$C$6
A9: Plus equity-accounted investees at carrying value | C9: =Assumptions!$C$44 | D9: =C9/Assumptions!$C$6
A10: Equity before minority interests | C10: =C7+C8+C9 | D10: =C10/Assumptions!$C$6
A11: Less minority interests at their share of group profit | C11: =-C10*$C$17 | D11: =C11/Assumptions!$C$6
A12: Less the employees' statutory share of profit | C12: =-(C10+C11)*$C$18 | D12: =C12/Assumptions!$C$6
A13: Equity attributable to ordinary shareholders | C13: =C10+C11+C12 | D13: =C13/Assumptions!$C$6
A15: Terminal value as a share of enterprise value | C15: =DCF!C28
A17: Minority share of group profit | C17: =(Assumptions!$C$46-Assumptions!$C$47)/Assumptions!$C$46
A18: Employees' statutory share of profit — an appropriation disclosed only in the earnings-per-share note, below profit attributable to owners | C18: =Assumptions!$C$59

Sheet Segments
A1: Segments — the margin build
A2: FY2025 disclosed shares and gross margins; forecast revenue and gross profit come from the unit build, and EBITDA is computed from them
A4: Segment | B4: FY2025 revenue | C4: Share | D4: Segment margin | E4: FY26E | F4: FY27E | G4: FY28E | H4: FY29E | I4: FY30E
A5: Cables and its accessories | B5: 155792.93 | C5: =B5/$B$8 | D5: 0.13489955 | E5: 221541.32 | F5: 252428.73 | G5: 276853.55 | H5: 302516.67 | I5: 329470.41
A6: Constructions and infrastructure | B6: 90958.55 | C6: =B6/$B$8 | D6: 0.064522693 | E6: 107331.09 | F6: 122357.44 | G6: 135816.76 | H6: 148040.27 | I6: 159883.49
A7: Electrical products and digital solutions | B7: 34297.602 | C7: =B7/$B$8 | D7: 0.22173004 | E7: 41157.122 | F7: 47742.262 | G7: 53948.756 | H7: 59883.119 | I7: 65871.431
A8: Total revenue | B8: =SUM(B5:B7) | C8: =SUM(C5:C7) | E8: =SUM(E5:E7) | F8: =SUM(F5:F7) | G8: =SUM(G5:G7) | H8: =SUM(H5:H7) | I8: =SUM(I5:I7)
A10: Segment profit by segment (Note 16 basis) | B10: FY26E | C10: FY27E | D10: FY28E | E10: FY29E | F10: FY30E
A11: Cables and its accessories | B11: 25331.256 | C11: 28862.954 | D11: 31655.712 | E11: 34590.059 | F11: 37671.976
A12: Constructions and infrastructure | B12: 9645.9523 | C12: 10996.386 | D12: 12205.988 | E12: 13304.527 | F12: 14368.889
A13: Electrical products and digital solutions | B13: 9722.1765 | C13: 11277.725 | D13: 12743.829 | E13: 14145.65 | F13: 15560.215
A14: Group segment profit | B14: =SUM(B11:B13) | C14: =SUM(C11:C13) | D14: =SUM(D11:D13) | E14: =SUM(E11:E13) | F14: =SUM(F11:F13)
A15: Group segment-profit margin | B15: =B14/E$8 | C15: =C14/F$8 | D15: =D14/G$8 | E15: =E14/H$8 | F15: =F14/I$8
A17: Segment EBIT contribution — segment profit less the pro-rata corporate load | B17: FY26E | C17: FY27E | D17: FY28E | E17: FY29E | F17: FY30E
A18: Cables and its accessories | B18: =B11-Assumptions!$B$22*E5 | C18: =C11-Assumptions!$C$22*F5 | D18: =D11-Assumptions!$D$22*G5 | E18: =E11-Assumptions!$E$22*H5 | F18: =F11-Assumptions!$F$22*I5
A19: Constructions and infrastructure | B19: =B12-Assumptions!$B$22*E6 | C19: =C12-Assumptions!$C$22*F6 | D19: =D12-Assumptions!$D$22*G6 | E19: =E12-Assumptions!$E$22*H6 | F19: =F12-Assumptions!$F$22*I6
A20: Electrical products and digital solutions | B20: =B13-Assumptions!$B$22*E7 | C20: =C13-Assumptions!$C$22*F7 | D20: =D13-Assumptions!$D$22*G7 | E20: =E13-Assumptions!$E$22*H7 | F20: =F13-Assumptions!$F$22*I7
A21: Group EBIT | B21: =SUM(B18:B20) | C21: =SUM(C18:C20) | D21: =SUM(D18:D20) | E21: =SUM(E18:E20) | F21: =SUM(F18:F20)
A22: Add back depreciation and amortisation | B22: =Assumptions!$C$27*E8 | C22: =Assumptions!$C$27*F8 | D22: =Assumptions!$C$27*G8 | E22: =Assumptions!$C$27*H8 | F22: =Assumptions!$C$27*I8
A23: Group EBITDA | B23: =B21+B22 | C23: =C21+C22 | D23: =D21+D22 | E23: =E21+E22 | F23: =F21+F22
A24: Group EBITDA margin | B24: =B23/E$8 | C24: =C23/F$8 | D24: =D23/G$8 | E24: =E23/H$8 | F24: =F23/I$8
A25: The corporate load is stated on the segment-profit-to-EBIT basis — the same basis as the audited historical bridge — so EBIT falls out first and EBITDA is EBIT plus D&A, not the other way round.

Sheet Relative & Normalized
A1: Relative multiples and normalised earnings power
A4: Relative lens | B4: Value
A5: FY2027E EBITDA (EGP mn) | C5: =DCF!C6
A6: Justified enterprise value / EBITDA | C6: =Assumptions!$C$69
A7: Implied enterprise value AS AT end-FY2027 (EGP mn) | C7: =C5*C6
A8: Discount factor back to the valuation date (year-2) | C8: =DCF!C16
A9: Plus present value of the interim FY26-27 free cash flows (EGP mn) | C9: =DCF!B17+DCF!C17
A10: Implied enterprise value at 31-Dec-2025 (EGP mn) | C10: =C7*C8+C9
A11: Implied value per share, rolled to the anchor (EGP) | C11: =((C10-Assumptions!$C$43+Assumptions!$C$44)*(1-'SOTP Bridge'!$C$17)*(1-'SOTP Bridge'!$C$18)/Assumptions!$C$6)*DCF!$C$61-Assumptions!$C$49
A12: Bear at 5.5× (C) / bull at 8.0× (D), same construction | C12: =((5.5*C5*C8+C9-Assumptions!$C$43+Assumptions!$C$44)*(1-'SOTP Bridge'!$C$17)*(1-'SOTP Bridge'!$C$18)/Assumptions!$C$6)*DCF!$C$61-Assumptions!$C$49 | D12: =((8.0*C5*C8+C9-Assumptions!$C$43+Assumptions!$C$44)*(1-'SOTP Bridge'!$C$17)*(1-'SOTP Bridge'!$C$18)/Assumptions!$C$6)*DCF!$C$61-Assumptions!$C$49
A13: Trailing enterprise value / EBITDA | C13: =((Assumptions!$C$5*Assumptions!$C$6)+Assumptions!$C$43)/'Income Statement'!D7
A14: Trailing price / earnings | C14: =Assumptions!$C$5/'Income Statement'!D18
A15: Trailing price / book | C15: =Assumptions!$C$5/C31
A16: Net bank debt / EBITDA | C16: =Assumptions!$C$43/'Income Statement'!D7
A18: Normalised earnings lens — mid-cycle margin (FY2028E) at current (FY2026E) scale | B18: Value
A19: Current-scale revenue (FY2026E, EGP mn) | C19: =DCF!B5
A20: Mid-cycle EBITDA margin (FY2028E) | C20: =DCF!D7
A21: Normalised EBITDA (EGP mn) | C21: =C19*C20
A22: Normalised EBIT (EGP mn) | C22: =C21-C19*Assumptions!$C$27
A23: Net finance cost (FY2026E, EGP mn) | C23: ='Income Statement'!E11
A24: Share of equity-accounted investees (FY2026E, EGP mn) | C24: ='Income Statement'!E12
A25: Normalised attributable earnings (EGP mn) | C25: =(C22+C23+C24)*(1-Assumptions!$C$7)*(1-'SOTP Bridge'!$C$17)*(1-'SOTP Bridge'!$C$18)
A26: Normalised earnings per share (EGP) | C26: =C25/Assumptions!$C$6
A27: Justified price / earnings | C27: =Assumptions!$C$70
A28: Implied value per share, rolled to the anchor (EGP) | C28: =C26*C27*DCF!$C$61-Assumptions!$C$49 | D28: bear 7.0× (E) / bull 11.5× (F): | E28: =C26*7*DCF!$C$61-Assumptions!$C$49 | F28: =C26*11.5*DCF!$C$61-Assumptions!$C$49
A30: Book lens | B30: Value
A31: Book value per share (EGP) | C31: ='Balance Sheet'!D14/Assumptions!$C$6
A32: Sustainable return on equity | C32: =Assumptions!$C$71
A33: Trailing return on equity | C33: ='Income Statement'!D17/(('Balance Sheet'!C14+'Balance Sheet'!D14)/2)
A34: Perpetual (terminal) cost of equity — a steady-state multiple takes a steady-state rate | C34: =DCF!C49
A35: Justified price / book | C35: =(C32-Assumptions!$C$40)/(C34-Assumptions!$C$40)
A36: Implied value per share, rolled to the anchor (EGP) | C36: =C31*C35*DCF!$C$61-Assumptions!$C$49 | D36: bear / bull constructions (E / F): | E36: =((Assumptions!$C$71-0.03)/((DCF!C39+DCF!C49)/2-0.03))*C31*DCF!$C$61-Assumptions!$C$49 | F36: =((Assumptions!$C$71+0.02-Assumptions!$C$40)/(DCF!C49-Assumptions!$C$40))*C31*DCF!$C$61-Assumptions!$C$49

Sheet DCF
A1: Discounted cash flow — the full waterfall
A2: Every line is a live formula: the cost of capital is built below, the glide is derived from the cost-of-debt path, and the terminal value is capitalised at the terminal rate and discounted at the year-5 factor
A4: EGP mn | B4: FY26E | C4: FY27E | D4: FY28E | E4: FY29E | F4: FY30E
A5: Revenue | B5: =Segments!E8 | C5: =Segments!F8 | D5: =Segments!G8 | E5: =Segments!H8 | F5: =Segments!I8
A6: EBITDA | B6: =Segments!B23 | C6: =Segments!C23 | D6: =Segments!D23 | E6: =Segments!E23 | F6: =Segments!F23
A7: EBITDA margin | B7: =B6/B5 | C7: =C6/C5 | D7: =D6/D5 | E7: =E6/E5 | F7: =F6/F5
A8: Less depreciation and amortisation | B8: =-B5*Assumptions!$C$27 | C8: =-C5*Assumptions!$C$27 | D8: =-D5*Assumptions!$C$27 | E8: =-E5*Assumptions!$C$27 | F8: =-F5*Assumptions!$C$27
A9: EBIT | B9: =B6+B8 | C9: =C6+C8 | D9: =D6+D8 | E9: =E6+E8 | F9: =F6+F8
A10: NOPAT — EBIT x (1 - 24%) | B10: =B9*(1-Assumptions!$C$7) | C10: =C9*(1-Assumptions!$C$7) | D10: =D9*(1-Assumptions!$C$7) | E10: =E9*(1-Assumptions!$C$7) | F10: =F9*(1-Assumptions!$C$7)
A11: Add back depreciation and amortisation | B11: =-B8 | C11: =-C8 | D11: =-D8 | E11: =-E8 | F11: =-F8
A12: Less capital expenditure | B12: =-B5*Assumptions!$B$26 | C12: =-C5*Assumptions!$C$26 | D12: =-D5*Assumptions!$D$26 | E12: =-E5*Assumptions!$E$26 | F12: =-F5*Assumptions!$F$26
A13: Less change in working capital | B13: =-(B5*Assumptions!$C$25-'Balance Sheet'!D16) | C13: =-(C5-B5)*Assumptions!$C$25 | D13: =-(D5-C5)*Assumptions!$C$25 | E13: =-(E5-D5)*Assumptions!$C$25 | F13: =-(F5-E5)*Assumptions!$C$25
A14: Free cash flow to the firm | B14: =B10+B11+B12+B13 | C14: =C10+C11+C12+C13 | D14: =D10+D11+D12+D13 | E14: =E10+E11+E12+E13 | F14: =F10+F11+F12+F13
A15: Forward cost of capital | B15: =$C$46-($C$46-$C$53)*B57 | C15: =$C$46-($C$46-$C$53)*C57 | D15: =$C$46-($C$46-$C$53)*D57 | E15: =$C$46-($C$46-$C$53)*E57 | F15: =$C$46-($C$46-$C$53)*F57
A16: Discount factor | B16: =1/(1+B15) | C16: =B16/(1+C15) | D16: =C16/(1+D15) | E16: =D16/(1+E15) | F16: =E16/(1+F15)
A17: Present value of FCFF | B17: =B14*B16 | C17: =C14*C16 | D17: =D14*D16 | E17: =E14*E16 | F17: =F14*F16
A19: TERMINAL VALUE, BRIDGE AND THE ANCHOR ROLL
A20: Terminal-year NOPAT — the LAST EXPLICIT year (FY2030), NOT grown (EGP mn) | C20: =F10
A21: Add back FY2030 book depreciation and amortisation (EGP mn) | C21: =-F8
A22: Terminal free cash flow to the firm — C20 + C21 less the capital charge on rows 65-67 | C22: =C20+C21+C65+C66+C67
A23: Terminal growth (nominal, derived from zero real growth and terminal inflation) | C23: =Assumptions!$C$40
A24: Terminal cost of capital | C24: =C53
A25: Terminal value — C22 grown one year and capitalised at (C24 − C23) (EGP mn) | C25: =C22*(1+C23)/(C24-C23)
A26: Present value of the five forecast years (EGP mn) | C26: =SUM(B17:F17)
A27: Present value of the terminal value (EGP mn) | C27: =C25*F16
A28: Terminal value as a share of enterprise value | C28: =C27/(C26+C27)
A29: Enterprise value (EGP mn) | C29: =C26+C27
A30: Equity attributable to ordinary shareholders (EGP mn) | C30: ='SOTP Bridge'!C13
A31: Fair value per share at 31-Dec-2025 (EGP) | C31: =C30/Assumptions!$C$6
A33: COST OF CAPITAL — BUILT HERE, NOT ASSUMED
A34: Risk-free rate, 10-year local currency | C34: =Assumptions!$C$30
A35: Less sovereign default spread (removed to avoid double-counting) | C35: =Assumptions!$C$31
A36: Risk-free rate net of the sovereign spread | C36: =C34-C35
A37: Beta | C37: =Assumptions!$C$33
A38: Equity risk premium | C38: =Assumptions!$C$32
A39: Cost of equity, explicit window | C39: =C36+C37*C38
A40: Cost of debt, blended | C40: =Assumptions!$C$34
A41: Cost of debt after tax | C41: =C40*(1-Assumptions!$C$7)
A42: Market capitalisation (EGP mn) | C42: =Assumptions!$C$5*Assumptions!$C$6
A43: Net bank debt (EGP mn) | C43: =Assumptions!$C$43
...

Sheet Income Statement
A1: Income statement — three years historical, five years forecast
A2: EGP mn, consolidated. History is the audited record; every forecast line is a formula
A4: EGP mn | B4: FY2023 | C4: FY2024 | D4: FY2025 | E4: FY26E | F4: FY27E | G4: FY28E | H4: FY29E | I4: FY30E
A5: Revenue | B5: 152186.25 | C5: 231981.84 | D5: 281049.08 | E5: =DCF!B5 | F5: =DCF!C5 | G5: =DCF!D5 | H5: =DCF!E5 | I5: =DCF!F5
A6: Gross profit | B6: 29077.289 | C6: 43898.521 | D6: 40762.108 | E6: =Segments!B14 | F6: =Segments!C14 | G6: =Segments!D14 | H6: =Segments!E14 | I6: =Segments!F14
A7: EBITDA | B7: 20035.105 | C7: 31601.465 | D7: 28363.203 | E7: =DCF!B6 | F7: =DCF!C6 | G7: =DCF!D6 | H7: =DCF!E6 | I7: =DCF!F6
A8: EBITDA margin | B8: =B7/B5 | C8: =C7/C5 | D8: =D7/D5 | E8: =E7/E5 | F8: =F7/F5 | G8: =G7/G5 | H8: =H7/H5 | I8: =I7/I5
A9: Depreciation and amortisation | B9: -2295.987 | C9: -2259.7458 | D9: -3008.9776 | E9: =DCF!B8 | F9: =DCF!C8 | G9: =DCF!D8 | H9: =DCF!E8 | I9: =DCF!F8
A10: EBIT | B10: =B7+B9 | C10: =C7+C9 | D10: =D7+D9 | E10: =E7+E9 | F10: =F7+F9 | G10: =G7+G9 | H10: =H7+H9 | I10: =I7+I9
A11: Net finance costs | B11: -2124.3623 | C11: -3515.3659 | D11: -2145.4388 | E11: =-(Assumptions!$B$35*'Balance Sheet'!$D$11-Assumptions!$C$52*MAX('Balance Sheet'!$D$11-'Balance Sheet'!D17,0)) | F11: =-(Assumptions!$C$35*'Balance Sheet'!$D$11-Assumptions!$C$52*MAX('Balance Sheet'!$D$11-'Balance Sheet'!E17,0)) | G11: =-(Assumptions!$D$35*'Balance Sheet'!$D$11-Assumptions!$C$52*MAX('Balance Sheet'!$D$11-'Balance Sheet'!F17,0)) | H11: =-(Assumptions!$E$35*'Balance Sheet'!$D$11-Assumptions!$C$52*MAX('Balance Sheet'!$D$11-'Balance Sheet'!G17,0)) | I11: =-(Assumptions!$F$35*'Balance Sheet'!$D$11-Assumptions!$C$52*MAX('Balance Sheet'!$D$11-'Balance Sheet'!H17,0))
A12: Share of equity-accounted investees | B12: 603.62497 | C12: 1132.3663 | D12: 1568.903 | E12: =D12*(1+Assumptions!$C$51) | F12: =E12*(1+Assumptions!$C$51) | G12: =F12*(1+Assumptions!$C$51) | H12: =G12*(1+Assumptions!$C$51) | I12: =H12*(1+Assumptions!$C$51)
A13: Profit before tax | B13: =B10+B11+B12 | C13: =C10+C11+C12 | D13: =D10+D11+D12 | E13: =E10+E11+E12 | F13: =F10+F11+F12 | G13: =G10+G11+G12 | H13: =H10+H11+H12 | I13: =I10+I11+I12
A14: Income tax | B14: -5080.4067 | C14: -8121.5101 | D14: -5591.1398 | E14: =-E13*Assumptions!$C$7 | F14: =-F13*Assumptions!$C$7 | G14: =-G13*Assumptions!$C$7 | H14: =-H13*Assumptions!$C$7 | I14: =-I13*Assumptions!$C$7
A15: Profit for the year | B15: 11137.974 | C15: 18837.209 | D15: 19186.55 | E15: =E13+E14 | F15: =F13+F14 | G15: =G13+G14 | H15: =H13+H14 | I15: =I13+I14
A16: Non-controlling interests | B16: -1022.2725 | C16: -1375.8507 | D16: -1856.3051 | E16: =-E15*'SOTP Bridge'!$C$17 | F16: =-F15*'SOTP Bridge'!$C$17 | G16: =-G15*'SOTP Bridge'!$C$17 | H16: =-H15*'SOTP Bridge'!$C$17 | I16: =-I15*'SOTP Bridge'!$C$17
A17: Profit attributable to shareholders | B17: 10115.702 | C17: 17461.359 | D17: 17330.245 | E17: =E15+E16 | F17: =F15+F16 | G17: =G15+G16 | H17: =H15+H16 | I17: =I15+I16
A18: Earnings per share (EGP) | B18: =B17/Assumptions!$C$6 | C18: =C17/Assumptions!$C$6 | D18: =D17/Assumptions!$C$6 | E18: =E17/Assumptions!$C$6 | F18: =F17/Assumptions!$C$6 | G18: =G17/Assumptions!$C$6 | H18: =H17/Assumptions!$C$6 | I18: =I17/Assumptions!$C$6
A20: Note: every FY2023-25 statement line is the audited figure — no closure or derivation is used for any historical year (the EBITDA and EPS rows are labelled house derivations). In the forecast the finance charge is computed on the gross debt book less the cash the business is accumulating, so it moves with net debt rather than being frozen at the FY2025 balance; profit is therefore struck after interest and differs from the pre-financing DCF waterfall by construction.

Sheet Balance Sheet
A1: Balance sheet — condensed
A2: EGP mn, consolidated. Every FY2023-25 line is the audited closing figure — no triangulation is needed for any year, including FY2025, because the full filing is in hand
A4: EGP mn | B4: FY2023 | C4: FY2024 | D4: FY2025 | E4: FY26E | F4: FY27E | G4: FY28E | H4: FY29E | I4: FY30E
A5: Property, plant and equipment | B5: 18009.166 | C5: 27543.763 | D5: 35961.077 | E5: =D5-DCF!B12+DCF!B8 | F5: =E5-DCF!C12+DCF!C8 | G5: =F5-DCF!D12+DCF!D8 | H5: =G5-DCF!E12+DCF!E8 | I5: =H5-DCF!F12+DCF!F8
A6: Inventories | B6: 30881.822 | C6: 56795.884 | D6: 59860.045
A7: Contract assets | B7: 16179.634 | C7: 18051.967 | D7: 29894.58
A8: Trade and other receivables | B8: 46591.885 | C8: 86736.309 | D8: 116259.8
A9: Cash and cash equivalents | B9: 25552.045 | C9: 38180.002 | D9: =D11-D17
A10: Total assets | B10: 151448.65 | C10: 249527.14 | D10: 311099.09
A11: Loans and borrowings | B11: 41766.492 | C11: 59082.942 | D11: 62509.212
A12: Trade and other payables | B12: 31938.122 | C12: 54808.185 | D12: 68895.662
A13: Contract liabilities | B13: 25060.328 | C13: 53281.057 | D13: 81266.225
A14: Equity attributable to shareholders | B14: 35724.466 | C14: 55274.913 | D14: 66870.867 | E14: =D14+'Income Statement'!E17*(1-Assumptions!$C$50) | F14: =E14+'Income Statement'!F17*(1-Assumptions!$C$50) | G14: =F14+'Income Statement'!G17*(1-Assumptions!$C$50) | H14: =G14+'Income Statement'!H17*(1-Assumptions!$C$50) | I14: =H14+'Income Statement'!I17*(1-Assumptions!$C$50)
A15: Non-controlling interests | B15: 2384.0134 | C15: 4251.7719 | D15: 5118.9784
A16: Net working capital | B16: 36654.891 | C16: 53494.918 | D16: 55852.535 | E16: ='Income Statement'!E5*Assumptions!$C$25 | F16: ='Income Statement'!F5*Assumptions!$C$25 | G16: ='Income Statement'!G5*Assumptions!$C$25 | H16: ='Income Statement'!H5*Assumptions!$C$25 | I16: ='Income Statement'!I5*Assumptions!$C$25
A17: Net bank debt | B17: 16214.447 | C17: 20902.939 | D17: =Assumptions!$C$43 | E17: =D17-DCF!B14-'Income Statement'!E11*(1-Assumptions!$C$7)+Assumptions!$C$50*'Income Statement'!E17 | F17: =E17-DCF!C14-'Income Statement'!F11*(1-Assumptions!$C$7)+Assumptions!$C$50*'Income Statement'!F17 | G17: =F17-DCF!D14-'Income Statement'!G11*(1-Assumptions!$C$7)+Assumptions!$C$50*'Income Statement'!G17 | H17: =G17-DCF!E14-'Income Statement'!H11*(1-Assumptions!$C$7)+Assumptions!$C$50*'Income Statement'!H17 | I17: =H17-DCF!F14-'Income Statement'!I11*(1-Assumptions!$C$7)+Assumptions!$C$50*'Income Statement'!I17
A18: Net debt / EBITDA | B18: =B17/'Income Statement'!B7 | C18: =C17/'Income Statement'!C7 | D18: =D17/'Income Statement'!D7 | E18: =E17/'Income Statement'!E7 | F18: =F17/'Income Statement'!F7 | G18: =G17/'Income Statement'!G7 | H18: =H17/'Income Statement'!H7 | I18: =I17/'Income Statement'!I7
A19: Residual: other liabilities, provisions and deferred tax not shown separately (total assets less the lines above) | B19: =B10-(B11+B12+B13+B14+B15) | C19: =C10-(C11+C12+C13+C14+C15) | D19: =D10-(D11+D12+D13+D14+D15)
A21: Note: this is a CONDENSED layout, so it does not foot to zero — the residual row above is the block of other liabilities, provisions, deferred tax and related-party balances that is not shown separately. For FY2024 that residual is 22,828, which reconciles to the audited statements (provisions 13,440 + 943, deferred tax 3,670, related parties 2,050 + 95, other liabilities 2,631 = 22,829). Every line, including FY2025, is now the audited closing figure — no triangulation or roll-forward is used for any historical year.

Sheet Cash Flow
A1: Cash flow — historical markers and the forecast waterfall
A2: EGP mn
A4: EGP mn | B4: FY2024 | C4: FY2025 | D4: FY26E | E4: FY27E | F4: FY28E | G4: FY29E | H4: FY30E
A5: EBITDA | B5: ='Income Statement'!C7 | C5: ='Income Statement'!D7 | D5: ='Income Statement'!E7 | E5: ='Income Statement'!F7 | F5: ='Income Statement'!G7 | G5: ='Income Statement'!H7 | H5: ='Income Statement'!I7
A6: Interest paid | B6: - | C6: -5740.3124
A7: Income tax paid | B7: - | C7: -8298.7521
A8: Operating cash flow after interest and tax | B8: - | C8: 12765.923
A9: NOPAT | B9: - | C9: - | D9: =DCF!B10 | E9: =DCF!C10 | F9: =DCF!D10 | G9: =DCF!E10 | H9: =DCF!F10
A10: Add back depreciation and amortisation | B10: - | C10: - | D10: =DCF!B11 | E10: =DCF!C11 | F10: =DCF!D11 | G10: =DCF!E11 | H10: =DCF!F11
A11: Capital expenditure | B11: -8489.7809 | C11: -13112.05 | D11: =DCF!B12 | E11: =DCF!C12 | F11: =DCF!D12 | G11: =DCF!E12 | H11: =DCF!F12
A12: Change in working capital | B12: - | C12: =-('Balance Sheet'!D16-'Balance Sheet'!C16) | D12: =DCF!B13 | E12: =DCF!C13 | F12: =DCF!D13 | G12: =DCF!E13 | H12: =DCF!F13
A13: Free cash flow to the firm | B13: - | C13: - | D13: =D9+D10+D11+D12 | E13: =E9+E10+E11+E12 | F13: =F9+F10+F11+F12 | G13: =G9+G10+G11+G12 | H13: =H9+H10+H11+H12
A15: Cash conversion — operating cash flow as a share of EBITDA, FY2025 | C15: =C8/C5
A16: This single ratio is the crux of the valuation: the company earned far more EBITDA than it converted to cash, because growth was funded through working capital.

Sheet Summary Financials
A1: Summary financials — the eight-year picture
A2: EGP mn unless stated. Every cell on this sheet is a link or a ratio; nothing is typed twice
A4: EGP mn | B4: FY2023 | C4: FY2024 | D4: FY2025 | E4: FY26E | F4: FY27E | G4: FY28E | H4: FY29E | I4: FY30E
A5: Revenue | B5: ='Income Statement'!B5 | C5: ='Income Statement'!C5 | D5: ='Income Statement'!D5 | E5: ='Income Statement'!E5 | F5: ='Income Statement'!F5 | G5: ='Income Statement'!G5 | H5: ='Income Statement'!H5 | I5: ='Income Statement'!I5
A6: Revenue growth | B6: - | C6: =C5/B5-1 | D6: =D5/C5-1 | E6: =E5/D5-1 | F6: =F5/E5-1 | G6: =G5/F5-1 | H6: =H5/G5-1 | I6: =I5/H5-1
A7: EBITDA | B7: ='Income Statement'!B7 | C7: ='Income Statement'!C7 | D7: ='Income Statement'!D7 | E7: ='Income Statement'!E7 | F7: ='Income Statement'!F7 | G7: ='Income Statement'!G7 | H7: ='Income Statement'!H7 | I7: ='Income Statement'!I7
A8: EBITDA margin | B8: =B7/B5 | C8: =C7/C5 | D8: =D7/D5 | E8: =E7/E5 | F8: =F7/F5 | G8: =G7/G5 | H8: =H7/H5 | I8: =I7/I5
A9: EBIT | B9: ='Income Statement'!B10 | C9: ='Income Statement'!C10 | D9: ='Income Statement'!D10 | E9: ='Income Statement'!E10 | F9: ='Income Statement'!F10 | G9: ='Income Statement'!G10 | H9: ='Income Statement'!H10 | I9: ='Income Statement'!I10
A10: Attributable profit | B10: ='Income Statement'!B17 | C10: ='Income Statement'!C17 | D10: ='Income Statement'!D17 | E10: ='Income Statement'!E17 | F10: ='Income Statement'!F17 | G10: ='Income Statement'!G17 | H10: ='Income Statement'!H17 | I10: ='Income Statement'!I17
A11: Free cash flow to the firm | B11: - | C11: - | D11: - | E11: ='Cash Flow'!D13 | F11: ='Cash Flow'!E13 | G11: ='Cash Flow'!F13 | H11: ='Cash Flow'!G13 | I11: ='Cash Flow'!H13
A12: Net bank debt | B12: ='Balance Sheet'!B17 | C12: ='Balance Sheet'!C17 | D12: ='Balance Sheet'!D17 | E12: ='Balance Sheet'!E17 | F12: ='Balance Sheet'!F17 | G12: ='Balance Sheet'!G17 | H12: ='Balance Sheet'!H17 | I12: ='Balance Sheet'!I17
A13: Invested capital | B13: - | C13: - | D13: ='Balance Sheet'!D16+'Balance Sheet'!D5+Assumptions!$C$45 | E13: ='Balance Sheet'!E16+'Balance Sheet'!E5+Assumptions!$C$45 | F13: ='Balance Sheet'!F16+'Balance Sheet'!F5+Assumptions!$C$45 | G13: ='Balance Sheet'!G16+'Balance Sheet'!G5+Assumptions!$C$45 | H13: ='Balance Sheet'!H16+'Balance Sheet'!H5+Assumptions!$C$45 | I13: ='Balance Sheet'!I16+'Balance Sheet'!I5+Assumptions!$C$45
A14: Return on invested capital | B14: - | C14: - | D14: - | E14: =DCF!B10/E13 | F14: =DCF!C10/F13 | G14: =DCF!D10/G13 | H14: =DCF!E10/H13 | I14: =DCF!F10/I13
A16: Return on invested capital is the DCF's NOPAT over the same year's invested capital, which is why the FY2025 column carries capital but no return: FY2025 NOPAT is struck on a different, post-financing basis and is reported in the terminal-growth reconciliation on the Per-Share & Ratios sheet.

Sheet Monte Carlo
A1: Probabilistic price map
A2: A map of price dispersion. It carries no view on value and is never blended with the valuation. Each figure is an engine output, not a formula.
A4: Horizon | B4: 5th | C4: 25th | D4: Median | E4: 75th | F4: 95th | G4: P(above spot)
A5: One month — to 2026-09-06 | B5: 87.472838 | C5: 99.107095 | D5: 106.68249 | E5: 114.89823 | F5: 130.16822 | G5: 0.55144
A6: Three months — to 2026-11-05 | B6: 78.29508 | C6: 96.936702 | D6: 109.90758 | E6: 124.45812 | F6: 154.19342 | G6: 0.59456
A8: Level event | B8: One month | C8: Three months
A9: Finishes 10% or more above spot | B9: 0.23044 | C9: 0.3878
A10: Finishes 10% or more below spot | B10: 0.14414 | C10: 0.21232
A11: Touches 10% above spot at any point | B11: 0.36882 | C11: 0.6306
A12: Touches 10% below spot at any point | B12: 0.2549 | C12: 0.446
A14: Engine setting | B14: Value
A15: Simulated paths | C15: 50000
A16: Annualised volatility (3-month anchor) | C16: 0.48380943
A17: Spot price (EGP) | C17: =Summary!C16
A18: Anchor date | C18: 2026-08-05

Sheet Sensitivity
A1: Sensitivity — what the valuation needs the world to do
A2: EGP per share. Each cell is a complete re-run of the model, including the unit build, so these grids are engine outputs rather than formulas and do NOT redraw when a driver is changed.
A4: Terminal cost of capital (rows) x terminal growth (columns)
B5: 3% | C5: 4% | D5: 5% | E5: 6% | F5: 7%
A6: 13.9% | B6: 64.923806 | C6: 67.814543 | D6: 71.265755 | E6: 75.489361 | F6: 80.819529
A7: 14.9% | B7: 58.182808 | C7: 60.280974 | D7: 62.72546 | E7: 65.632553 | F7: 69.177171
A8: 15.9% | B8: 52.497998 | C8: 54.022589 | D8: 55.758521 | E8: 57.769618 | F8: 60.148277
A9: 16.9% | B9: 47.641488 | C9: 48.743162 | D9: 49.969025 | E9: 51.353152 | F9: 52.943336
A10: 17.9% | B10: 43.446448 | C10: 44.231523 | D10: 45.083512 | E10: 46.019237 | F10: 47.061673
A12: Explicit-window cost of capital (columns) x terminal cost of capital (rows)
B13: 23.9% | C13: 25.4% | D13: 26.9% | E13: 28.4% | F13: 29.9%
A14: terminal 13.9% | B14: 85.845455 | C14: 83.287263 | D14: 80.819529 | E14: 78.438257 | F14: 76.139667
A15: terminal 14.9% | B15: 73.540468 | C15: 71.319635 | D15: 69.177171 | E15: 67.109622 | F15: 65.113716
A16: terminal 15.9% | B16: 63.99791 | C16: 62.038592 | D16: 60.148277 | E16: 58.323927 | F16: 56.562668
A17: terminal 16.9% | B17: 56.383263 | C17: 54.632532 | D17: 52.943336 | E17: 51.312971 | F17: 49.738876
A18: terminal 17.9% | B18: 50.16731 | C18: 48.586769 | D18: 47.061673 | E18: 45.589588 | F18: 44.168212
A20: Single-driver sensitivities — five engine re-runs per row; the parameter grid for each row is shown beside its name
A21: Driver (parameter grid) | H21: Swing
A22: Beta (0.60 / 0.80 / 1.01 / 1.15 / 1.30) | B22: 93.452774 | C22: 74.446742 | D22: 60.148277 | E22: 52.633014 | F22: 45.99373 | H22: =MAX(B22:F22)-MIN(B22:F22)
A23: Exchange-rate path multiplier (0.90x / 1.00x / 1.20x / 1.45x / 1.70x) | B23: 50.793654 | C23: 52.69689 | D23: 56.503362 | E23: 61.261453 | F23: 66.019543 | H23: =MAX(B23:F23)-MIN(B23:F23)
A24: Segment margins, multiplicative (0.850x / 0.925x / 1.000x / 1.075x / 1.150x) | B24: 29.481747 | C24: 41.089319 | D24: 52.69689 | E24: 64.304461 | F24: 75.912033 | H24: =MAX(B24:F24)-MIN(B24:F24)
A25: Copper price multiplier (0.850x / 0.925x / 1.000x / 1.075x / 1.150x) | B25: 49.842036 | C25: 51.269463 | D25: 52.69689 | E25: 54.124317 | F25: 55.551744 | H25: =MAX(B25:F25)-MIN(B25:F25)
A26: Working capital / revenue (17.0% / 18.5% / 19.9% / 21.5% / 23.0%) | B26: 59.905632 | C26: 56.176972 | D26: 52.69689 | E26: 48.719653 | F26: 44.990993 | H26: =MAX(B26:F26)-MIN(B26:F26)
A27: Terminal return on invested capital (15.0% / 18.0% / 20.1% / 26.0% / 30.0%) | B27: 49.622729 | C27: 56.535111 | D27: 60.148277 | E27: 67.169545 | F27: 70.359875 | H27: =MAX(B27:F27)-MIN(B27:F27)
A28: Terminal growth (at base cost of capital) (3% / 4% / 5% / 6% / 7%) | B28: 52.497998 | C28: 54.022589 | D28: 55.758521 | E28: 57.769618 | F28: 60.148277 | H28: =MAX(B28:F28)-MIN(B28:F28)

Sheet Per-Share & Ratios
A1: Per-share and ratio analysis
A2: The indicator set for a diversified industrial with a contracting arm. Every ratio is a formula off the statements.
A4: Measure | B4: FY2023 | C4: FY2024 | D4: FY2025 | E4: FY26E | F4: FY27E | G4: FY28E | H4: FY29E | I4: FY30E
A5: Earnings per share (EGP) | B5: ='Income Statement'!B18 | C5: ='Income Statement'!C18 | D5: ='Income Statement'!D18 | E5: ='Income Statement'!E18 | F5: ='Income Statement'!F18 | G5: ='Income Statement'!G18 | H5: ='Income Statement'!H18 | I5: ='Income Statement'!I18
A6: Book value per share (EGP) | B6: ='Balance Sheet'!B14/Assumptions!$C$6 | C6: ='Balance Sheet'!C14/Assumptions!$C$6 | D6: ='Balance Sheet'!D14/Assumptions!$C$6 | E6: ='Balance Sheet'!E14/Assumptions!$C$6 | F6: ='Balance Sheet'!F14/Assumptions!$C$6 | G6: ='Balance Sheet'!G14/Assumptions!$C$6 | H6: ='Balance Sheet'!H14/Assumptions!$C$6 | I6: ='Balance Sheet'!I14/Assumptions!$C$6
A7: Free cash flow per share (EGP) | B7: - | C7: - | D7: - | E7: ='Summary Financials'!E11/Assumptions!$C$6 | F7: ='Summary Financials'!F11/Assumptions!$C$6 | G7: ='Summary Financials'!G11/Assumptions!$C$6 | H7: ='Summary Financials'!H11/Assumptions!$C$6 | I7: ='Summary Financials'!I11/Assumptions!$C$6
A8: Gross margin | B8: ='Income Statement'!B6/'Income Statement'!B5 | C8: ='Income Statement'!C6/'Income Statement'!C5 | D8: ='Income Statement'!D6/'Income Statement'!D5 | E8: ='Income Statement'!E6/'Income Statement'!E5 | F8: ='Income Statement'!F6/'Income Statement'!F5 | G8: ='Income Statement'!G6/'Income Statement'!G5 | H8: ='Income Statement'!H6/'Income Statement'!H5 | I8: ='Income Statement'!I6/'Income Statement'!I5
A9: EBITDA margin | B9: ='Income Statement'!B8 | C9: ='Income Statement'!C8 | D9: ='Income Statement'!D8 | E9: ='Income Statement'!E8 | F9: ='Income Statement'!F8 | G9: ='Income Statement'!G8 | H9: ='Income Statement'!H8 | I9: ='Income Statement'!I8
A10: EBIT margin | B10: ='Income Statement'!B10/'Income Statement'!B5 | C10: ='Income Statement'!C10/'Income Statement'!C5 | D10: ='Income Statement'!D10/'Income Statement'!D5 | E10: ='Income Statement'!E10/'Income Statement'!E5 | F10: ='Income Statement'!F10/'Income Statement'!F5 | G10: ='Income Statement'!G10/'Income Statement'!G5 | H10: ='Income Statement'!H10/'Income Statement'!H5 | I10: ='Income Statement'!I10/'Income Statement'!I5
A11: Net margin (attributable) | B11: ='Income Statement'!B17/'Income Statement'!B5 | C11: ='Income Statement'!C17/'Income Statement'!C5 | D11: ='Income Statement'!D17/'Income Statement'!D5 | E11: ='Income Statement'!E17/'Income Statement'!E5 | F11: ='Income Statement'!F17/'Income Statement'!F5 | G11: ='Income Statement'!G17/'Income Statement'!G5 | H11: ='Income Statement'!H17/'Income Statement'!H5 | I11: ='Income Statement'!I17/'Income Statement'!I5
A12: Return on equity | B12: - | C12: ='Income Statement'!C17/(('Balance Sheet'!B14+'Balance Sheet'!C14)/2) | D12: ='Income Statement'!D17/(('Balance Sheet'!C14+'Balance Sheet'!D14)/2) | E12: ='Income Statement'!E17/(('Balance Sheet'!D14+'Balance Sheet'!E14)/2) | F12: ='Income Statement'!F17/(('Balance Sheet'!E14+'Balance Sheet'!F14)/2) | G12: ='Income Statement'!G17/(('Balance Sheet'!F14+'Balance Sheet'!G14)/2) | H12: ='Income Statement'!H17/(('Balance Sheet'!G14+'Balance Sheet'!H14)/2) | I12: ='Income Statement'!I17/(('Balance Sheet'!H14+'Balance Sheet'!I14)/2)
A13: Return on invested capital | B13: - | C13: - | D13: - | E13: ='Summary Financials'!E14 | F13: ='Summary Financials'!F14 | G13: ='Summary Financials'!G14 | H13: ='Summary Financials'!H14 | I13: ='Summary Financials'!I14
A14: Net debt / EBITDA | B14: ='Balance Sheet'!B18 | C14: ='Balance Sheet'!C18 | D14: ='Balance Sheet'!D18 | E14: ='Balance Sheet'!E18 | F14: ='Balance Sheet'!F18 | G14: ='Balance Sheet'!G18 | H14: ='Balance Sheet'!H18 | I14: ='Balance Sheet'!I18
A15: Interest cover (EBIT / net interest) | B15: - | C15: =-'Income Statement'!C10/'Income Statement'!C11 | D15: =-'Income Statement'!D10/'Income Statement'!D11 | E15: =-'Income Statement'!E10/'Income Statement'!E11 | F15: =-'Income Statement'!F10/'Income Statement'!F11 | G15: =-'Income Statement'!G10/'Income Statement'!G11 | H15: =-'Income Statement'!H10/'Income Statement'!H11 | I15: =-'Income Statement'!I10/'Income Statement'!I11
A16: Working capital / revenue | B16: ='Balance Sheet'!B16/'Income Statement'!B5 | C16: ='Balance Sheet'!C16/'Income Statement'!C5 | D16: ='Balance Sheet'!D16/'Income Statement'!D5 | E16: ='Balance Sheet'!E16/'Income Statement'!E5 | F16: ='Balance Sheet'!F16/'Income Statement'!F5 | G16: ='Balance Sheet'!G16/'Income Statement'!G5 | H16: ='Balance Sheet'!H16/'Income Statement'!H5 | I16: ='Balance Sheet'!I16/'Income Statement'!I5
A17: Capital expenditure / revenue | B17: - | C17: =-'Cash Flow'!B11/'Income Statement'!C5 | D17: =-'Cash Flow'!C11/'Income Statement'!D5 | E17: =-'Cash Flow'!D11/'Income Statement'!E5 | F17: =-'Cash Flow'!E11/'Income Statement'!F5 | G17: =-'Cash Flow'!F11/'Income Statement'!G5 | H17: =-'Cash Flow'!G11/'Income Statement'!H5 | I17: =-'Cash Flow'!H11/'Income Statement'!I5
A18: Reinvestment rate | B18: 0.20125165 | C18: 0.30375803 | D18: 0.51462851 | E18: - | F18: - | G18: - | H18: - | I18: -
A19: Implied growth (return on capital x reinvestment) | B19: 0.04486693 | C19: 0.075517522 | D19: 0.10798215 | E19: - | F19: - | G19: - | H19: - | I19: -
A21: Terminal growth reconciliation: actual NOPAT compound growth FY2023–FY2025 was 26.9%; the implied growth from stable years only (FY2024 excluded as a debt-funded capacity burst) is 7.6%; the adopted terminal growth is 7.0%, below the blended nominal ceiling of 11.1%.

Sheet Peer & Sector
A1: Peer frame and sector context
A2: No clean comparable exists; this is a sanity check, not an independent valuation
A4: Company / frame | B4: Market | C4: Relevance | D4: Caution
A5: Riyadh Cables | B5: Saudi Arabia | C5: nearest listed regional cable manufacturer | D5: far smaller, no contracting arm, lighter balance sheet, pegged currency
A6: Electro Cable Egypt | B6: Egypt | C6: the only other listed Egyptian cable manufacturer | D6: much smaller, domestic, heavily levered, currently loss-making
A7: European cable majors | B7: Europe | C7: closest match on business model — cables plus projects | D7: developed-market cost of capital; no convertibility risk
A8: Regional engineering and construction contractors | B8: Gulf and North Africa | C8: the right frame for the roughly 32% that is the Constructions and infrastructure segment | D8: project accounting and backlog quality are not comparable
A10: Own multiples | B10: Value
A11: Trailing enterprise value / EBITDA | B11: ='Relative & Normalized'!C13
A12: Trailing price / earnings | B12: ='Relative & Normalized'!C14
A13: Trailing price / book | B13: ='Relative & Normalized'!C15
A14: Justified enterprise value / EBITDA applied | B14: ='Relative & Normalized'!C6
A15: Justified price / earnings applied | B15: ='Relative & Normalized'!C27
