Workbook

Sheet READ FIRST
A1: Testahil — Air Arabia PJSC (DFM: AIRARABIA)
A3: Companion model · Independent Valuation Study · Educational analysis · Not investment advice
A5: What this workbook is. A transparent companion to the Air Arabia valuation study. Every blue cell is an
A6: input; every black cell is a formula; green cells link across sheets.
A8: IT IS FORMULA-DRIVEN. Every figure that can be derived arithmetically from a driver is a live formula, so
A9: you can change a blue cell on Assumptions and watch the model reprice: the cost of capital is built from
A10: the dirham government-bond yield net of the sovereign spread, beta and the premium rather than pasted; the
A11: discount factors compound from the cost-of-debt glide; revenue is passengers times revenue per passenger;
A12: the cost stack is passengers times cost per passenger, line by line; and the income statement, balance
A13: sheet, cash flow, ratios and all four lenses chain off the same cells.
A15: THREE THINGS ARE PASTED VALUES, and it is worth knowing exactly which. First, audited and disclosed
A16: history — the primary record, not a calculation; where a line is both disclosed and derivable the
... A56: Ratios · Peer & Sector.

Sheet Summary
A1: Summary — valuation at a glance
A2: All values link live to their source sheets
A4: Lens | B4: Bear | C4: Base | D4: Bull | E4: Weight | F4: Contribution | G4: vs spot
A5: Discounted cash flow (primary) | B5: 0.47035755 | C5: ='Fundamental Valuation'!C5 | D5: 7.2283224 | E5: =Assumptions!$C$83 | F5: =C5*E5 | G5: =C5/$C$16-1
A6: Relative multiples | B6: ='Relative & Normalized'!C12 | C6: ='Relative & Normalized'!C11 | D6: ='Relative & Normalized'!C13 | E6: =Assumptions!$C$84 | F6: =C6*E6 | G6: =C6/$C$16-1
A7: Normalised earnings power | B7: ='Relative & Normalized'!C31 | C7: ='Relative & Normalized'!C29 | D7: ='Relative & Normalized'!C32 | E7: =Assumptions!$C$85 | F7: =C7*E7 | G7: =C7/$C$16-1
A8: Book value and sustainable return | B8: ='Relative & Normalized'!C39 | C8: ='Relative & Normalized'!C37 | D8: ='Relative & Normalized'!C40 | E8: =Assumptions!$C$86 | F8: =C8*E8 | G8: =C8/$C$16-1
A9: Weighted central (range weighted like the base) | B9: =B5*E5+B6*E6+B7*E7+B8*E8 | C9: =SUM(F5:F8) | D9: =D5*E5+D6*E6+D7*E7+D8*E8 | E9: =SUM(E5:E8) | G9: =C9/$C$16-1
A10: DCF — JV network capitalised (contested judgement, other framing) | C10: ='SOTP Bridge'!C20 | G10: =C10/$C$16-1
A11: Weighted central on that framing | C11: =C9+Assumptions!$C$83*('SOTP Bridge'!C20-'Fundamental Valuation'!C5) | G11: =C11/$C$16-1
A12: Terminal value share of DCF enterprise value | C12: =DCF!C57
A13: Expert panel median | C13: ='Fundamental Valuation'!C23 | G13: =C13/$C$16-1
A14: DCF on the high-fuel alternative (whole-model re-run) | C14: 1.8559232 | G14: =C14/$C$16-1
A15: Widest single-lens span (the DCF scenarios) — labelled, not the weighted range | B15: =MIN(B5:B8) | D15: =MAX(D5:D8)
A16: Market price (7-Aug-2026 close) | C16: =Assumptions!$C$52
A18: Key figure | C18: Value
A19: Shares outstanding (mn) | C19: =Assumptions!$C$53
A20: Market capitalisation (AED mn) | C20: =DCF!C14
A21: Net cash incl. fixed deposits, FY2025 (AED mn) | C21: ='SOTP Bridge'!C6
A22: FY2025 revenue (AED mn) | C22: ='Income Statement'!D5
A23: FY2025 EBITDA (AED mn) | C23: ='Income Statement'!D9
A24: FY2025 attributable profit (AED mn) | C24: ='Income Statement'!D20
A25: Cost of capital — explicit window | C25: =DCF!C17
A26: Cost of capital — terminal | C26: =DCF!C24
A27: Terminal growth | C27: =Assumptions!$C$47

Sheet Fundamental Valuation
A1: Fundamental valuation — the four lenses and the alternatives
A4: Lens | B4: Basis | C4: AED per share
A5: Discounted cash flow (primary) | B5: FCFF, glide-discounted, JV at carrying value | C5: ='SOTP Bridge'!C15
A6: Relative multiples | B6: 6.5x FY2027E EBITDA, discounted | C6: ='Relative & Normalized'!C11
A7: Normalised earnings power | B7: 13x mid-cycle EPS at current scale | C7: ='Relative & Normalized'!C29
A8: Book value and sustainable return | B8: Justified price-to-book on FY2025 equity | C8: ='Relative & Normalized'!C37
A10: Weighted central | C10: =Summary!C9
A12: Alternative readings (whole-model re-runs unless linked) | C12: AED per share
A13: DCF with the JV network capitalised (the contested judgement, other framing) | C13: ='SOTP Bridge'!C20
A14: DCF on the high-fuel alternative (airline-association path held) | C14: 1.8559232
A15: DCF bear scenario (high fuel + weaker traffic + tighter money) | C15: 0.47035755
A16: DCF bull scenario (fuel relief + stronger traffic + JV capitalised) | C16: 7.2283224
A18: Expert panel (each leg is a complete model of its own) | C18: AED per share
A19: Expert 1 — earnings power at a justified multiple (live formula) | C19: =13*(('Segments'!D30*'Segments'!D14+'Segments'!D28-Assumptions!D21+('Cash Flow'!D13-'Cash Flow'!D14)+'Income Statement'!G15)*(1-Assumptions!$C$36)*(1-Assumptions!$C$81)/Assumptions!$C$53)*DCF!C61-Assumptions!$C$54 | D19: =10*(('Segments'!D30*'Segments'!D14+'Segments'!D28-Assumptions!D21+('Cash Flow'!D13-'Cash Flow'!D14)+'Income Statement'!G15)*(1-Assumptions!$C$36)*(1-Assumptions!$C$81)/Assumptions!$C$53)*DCF!C61-Assumptions!$C$54 | E19: =16*(('Segments'!D30*'Segments'!D14+'Segments'!D28-Assumptions!D21+('Cash Flow'!D13-'Cash Flow'!D14)+'Income Statement'!G15)*(1-Assumptions!$C$36)*(1-Assumptions!$C$81)/Assumptions!$C$53)*DCF!C61-Assumptions!$C$54
A20: Expert 2 — owner cash earnings capitalised (live formula) | C20: =(((AVERAGE('Cash Flow'!D9:F9)+('Cash Flow'!E13-'Cash Flow'!E14)*(1-Assumptions!$C$36)+'Income Statement'!H15*(1-Assumptions!$C$36)*0.4)*(1-Assumptions!$C$81))*(1+Assumptions!$C$47)/(DCF!C21-Assumptions!$C$47)+0.5*(Assumptions!$C$76-Assumptions!$C$75))/Assumptions!$C$53*DCF!C61-Assumptions!$C$54 | D20: =((AVERAGE('Cash Flow'!D9:F9)+('Cash Flow'!E13-'Cash Flow'!E14)*(1-Assumptions!$C$36)+'Income Statement'!H15*(1-Assumptions!$C$36)*0.4)*(1-Assumptions!$C$81))*1.015/(0.5*(DCF!C10+DCF!C21)-0.015)/Assumptions!$C$53*DCF!C61-Assumptions!$C$54 | E20: =(((AVERAGE('Cash Flow'!D9:F9)+('Cash Flow'!E13-'Cash Flow'!E14)*(1-Assumptions!$C$36)+'Income Statement'!H15*(1-Assumptions!$C$36)*0.4)*(1-Assumptions!$C$81))*1.035/(DCF!C21-0.035)+2*0.5*(Assumptions!$C$76-Assumptions!$C$75))/Assumptions!$C$53*DCF!C61-Assumptions!$C$54
A21: Expert 3 — cash returns vs the cost of capital (whole-model re-run; full chain in Appendix C) | C21: 3.4611617 | D21: 2.6697461 | E21: 4.0069238
A23: Panel median | C23: =MEDIAN(C19,C20,C21)
A25: Columns D and E carry each expert's own low and high. The spot price on the anchor date is AED 5.24.

Sheet Assumptions
A1: Assumptions — every driver of the model
A2: Blue cells are inputs. Change one and the model reprices.
A4: Driver | B4: FY26E | C4: FY27E | D4: FY28E | E4: FY29E | F4: FY30E
A5: Passengers (millions) | B5: 12.85 | C5: 13.95 | D5: 15.15 | E5: 16.35 | F5: 17.55
A6: Passenger + baggage revenue per passenger (AED) | B6: 488 | C6: 480 | D6: 484 | E6: 489 | F6: 494
A7: Ancillary revenue per passenger (AED) | B7: 67.4 | C7: 70.1 | D7: 72.9 | E7: 75.8 | F7: 78.8
A8: Cargo revenue growth | B8: 0.05 | C8: 0.05 | D8: 0.05 | E8: 0.05 | F8: 0.05
A9: Service revenue growth | B9: 0.04 | C9: 0.04 | D9: 0.04 | E9: 0.04 | F9: 0.04
A10: Hotel revenue growth | B10: 0.03 | C10: 0.03 | D10: 0.03 | E10: 0.03 | F10: 0.03
A11: Aircraft-lease revenue growth | B11: 0.1 | C11: 0.1 | D11: 0.08 | E11: 0.06 | F11: 0.05
A12: Effective jet fuel price (USD/bbl) — base path | B12: 100.7 | C12: 85.2 | D12: 86.9 | E12: 88.6 | F12: 90.4
A13: Effective jet fuel price (USD/bbl) — high-fuel alternative | B13: 108.4 | C13: 105.8 | D13: 106.4 | E13: 107.5 | F13: 108.5
A14: Staff cost per passenger (AED) | B14: 84.4 | C14: 86.9 | D14: 89.5 | E14: 92.2 | F14: 94.9
A15: Maintenance cost per passenger (AED) | B15: 63.8 | C15: 66.3 | D15: 69 | E15: 71.7 | F15: 74.6
A16: Landing & overflying charges per passenger (AED) | B16: 36.7 | C16: 37.4 | D16: 38.2 | E16: 38.9 | F16: 39.7
... A31: Dividend payout ratio | B31: 1 | C31: 0.9 | D31: 0.85 | E31: 0.85 | F31: 0.85
A33: Scalar driver | B33: Value
A34: Selling & marketing / revenue | C34: 0.0146
A35: Working capital / revenue | C35: -0.64
A36: Tax rate | C36: 0.15
A37: AED government bond yield (January-2031 tranche) | C37: 0.0448
A38: Observed sovereign spread at the auction (netted out) | C38: 0.0004
A39: Rating-table sovereign spread (alternative netting, disclosed) | C39: 0.0042
A40: Beta (five-year weekly, vs the Dubai index) | C40: 1.086
A41: Equity risk premium | C41: 0.0487
A42: Terminal risk-free rate | C42: 0.04
A43: Terminal equity risk premium | C43: 0.0475
A44: Marginal cost of debt | C44: 0.055
A45: Terminal cost of debt | C45: 0.05
... A90: Normalised lens — bull P/E | C90: 16

Sheet SOTP Bridge
A1: SOTP / EV-to-equity bridge — both JV framings
A2: The joint-venture network is the contested judgement: both framings shown, never averaged.
A4: Bridge — base framing (JV at audited carrying value) | C4: AED mn
A5: Enterprise value of the airline (DCF) | C5: =DCF!C56
A6: plus net cash (cash + deposits - borrowings - leases) | C6: =Assumptions!$C$76-Assumptions!$C$75
A7: plus non-operating assets | C7: =Assumptions!$C$80
A8: plus JV network at audited carrying value | C8: =Assumptions!$C$79
A9: Equity before minorities | C9: =SUM(C5:C8)
A11: less minorities at audited carrying value | C11: =Assumptions!$C$60
A13: Equity attributable to shareholders | C13: =C9-C11
A14: Per share at 31-Dec-2025 | C14: =C13/Assumptions!$C$53
A15: Per share at the anchor — operating equity rolled at the cost of equity, cash and near-cash legs at the deposit yield | C15: =(C5*DCF!C61+(C6+C7+C8)*DCF!C63-C11)/Assumptions!$C$53-Assumptions!$C$54
A17: Alternative framing (JV capitalised at a growth multiple) | C17: AED mn
A18: JV network capitalised (multiple x FY2025 profit share) | C18: =Assumptions!$C$48*Assumptions!$C$73
A19: Equity attributable on this framing | C19: =C5+C6+C7+C18-C11
A20: Per share at the anchor — JV capitalised | C20: =(C5*DCF!C61+(C6+C7+C18)*DCF!C63-C11)/Assumptions!$C$53-Assumptions!$C$54
A22: Non-operating assets, itemised (audited FY2025) | C22: AED mn
A23: Investments at fair value through OCI | C23: 457.528
A24: Investment property (book; disclosed fair value AED 334mn) | C24: 277.09
A25: Net investment in lease (aircraft subleased to the JV airlines) | C25: 334.666
A26: Total non-operating assets | C26: =SUM(C23:C25)
A28: The JV network: Air Arabia Abu Dhabi (49%), Air Arabia Egypt (49%, raised from 40% in 2025), Fly Jinnah (45%), Air Arabia Maroc (44.13%), Air Arabia DMM — Saudi Arabia (49%, pre-operational). FY2025 profit share AED 190.0mn; audited carrying value AED 363.4mn.

Sheet Segments
A1: Segments — the unit build, live
A2: Revenue = passengers x rate; costs = passengers x unit cost. All formula.
A4: Revenue build (AED mn) | B4: FY26E | C4: FY27E | D4: FY28E | E4: FY29E | F4: FY30E
A5: Passengers (millions) | B5: =Assumptions!B5*Assumptions!$C$61 | C5: =Assumptions!C5*Assumptions!$C$61 | D5: =Assumptions!D5*Assumptions!$C$61 | E5: =Assumptions!E5*Assumptions!$C$61 | F5: =Assumptions!F5*Assumptions!$C$61
A6: Revenue per passenger — fare + baggage (AED) | B6: =Assumptions!B6*Assumptions!$C$62 | C6: =Assumptions!C6*Assumptions!$C$62 | D6: =Assumptions!D6*Assumptions!$C$62 | E6: =Assumptions!E6*Assumptions!$C$62 | F6: =Assumptions!F6*Assumptions!$C$62
A7: Passenger and baggage revenue | B7: =B5*B6 | C7: =C5*C6 | D7: =D5*D6 | E7: =E5*E6 | F7: =F5*F6
A8: Ancillary rate (AED per passenger) | B8: =Assumptions!B7 | C8: =Assumptions!C7 | D8: =Assumptions!D7 | E8: =Assumptions!E7 | F8: =Assumptions!F7
A9: Ancillary revenue | B9: =B5*B8 | C9: =C5*C8 | D9: =D5*D8 | E9: =E5*E8 | F9: =F5*F8
A10: Cargo revenue | B10: =Assumptions!$C$68*(1+Assumptions!B8) | C10: =B10*(1+Assumptions!C8) | D10: =C10*(1+Assumptions!D8) | E10: =D10*(1+Assumptions!E8) | F10: =E10*(1+Assumptions!F8)
A11: Service revenue | B11: =Assumptions!$C$69*(1+Assumptions!B9) | C11: =B11*(1+Assumptions!C9) | D11: =C11*(1+Assumptions!D9) | E11: =D11*(1+Assumptions!E9) | F11: =E11*(1+Assumptions!F9)
A12: Hotel revenue | B12: =Assumptions!$C$70*(1+Assumptions!B10) | C12: =B12*(1+Assumptions!C10) | D12: =C12*(1+Assumptions!D10) | E12: =D12*(1+Assumptions!E10) | F12: =E12*(1+Assumptions!F10)
A13: Aircraft-lease revenue (JV network) | B13: =Assumptions!$C$71*(1+Assumptions!B11) | C13: =B13*(1+Assumptions!C11) | D13: =C13*(1+Assumptions!D11) | E13: =D13*(1+Assumptions!E11) | F13: =E13*(1+Assumptions!F11)
A14: Total revenue | B14: =B7+B9+B10+B11+B12+B13 | C14: =C7+C9+C10+C11+C12+C13 | D14: =D7+D9+D10+D11+D12+D13 | E14: =E7+E9+E10+E11+E12+E13 | F14: =F7+F9+F10+F11+F12+F13
A16: Cost build (AED per passenger) | B16: FY26E | C16: FY27E | D16: FY28E | E16: FY29E | F16: FY30E
A17: Fuel cost per passenger (intensity x effective jet price) | B17: =Assumptions!$C$56*(Assumptions!B12*(1-Assumptions!$C$66)+Assumptions!B13*Assumptions!$C$66)*Assumptions!$C$63 | C17: =Assumptions!$C$56*(Assumptions!C12*(1-Assumptions!$C$66)+Assumptions!C13*Assumptions!$C$66)*Assumptions!$C$63 | D17: =Assumptions!$C$56*(Assumptions!D12*(1-Assumptions!$C$66)+Assumptions!D13*Assumptions!$C$66)*Assumptions!$C$63 | E17: =Assumptions!$C$56*(Assumptions!E12*(1-Assumptions!$C$66)+Assumptions!E13*Assumptions!$C$66)*Assumptions!$C$63 | F17: =Assumptions!$C$56*(Assumptions!F12*(1-Assumptions!$C$66)+Assumptions!F13*Assumptions!$C$66)*Assumptions!$C$63
A18: Staff | B18: =Assumptions!B14 | C18: =Assumptions!C14 | D18: =Assumptions!D14 | E18: =Assumptions!E14 | F18: =Assumptions!F14
A19: Maintenance | B19: =Assumptions!B15 | C19: =Assumptions!C15 | D19: =Assumptions!D15 | E19: =Assumptions!E15 | F19: =Assumptions!F15
A20: Landing & overflying | B20: =Assumptions!B16 | C20: =Assumptions!C16 | D20: =Assumptions!D16 | E20: =Assumptions!E16 | F20: =Assumptions!F16
A21: Handling | B21: =Assumptions!B17 | C21: =Assumptions!C17 | D21: =Assumptions!D17 | E21: =Assumptions!E17 | F21: =Assumptions!F17
A22: Other direct | B22: =Assumptions!B18 | C22: =Assumptions!C18 | D22: =Assumptions!D18 | E22: =Assumptions!E18 | F22: =Assumptions!F18
A23: Cash cost per passenger | B23: =SUM(B17:B22) | C23: =SUM(C17:C22) | D23: =SUM(D17:D22) | E23: =SUM(E17:E22) | F23: =SUM(F17:F22)
A24: Direct cash operating costs (AED mn) | B24: =B5*B23 | C24: =C5*C23 | D24: =D5*D23 | E24: =E5*E23 | F24: =F5*F23
A25: Administrative costs (cash) | B25: =Assumptions!$C$67*(1+Assumptions!B19) | C25: =B25*(1+Assumptions!C19) | D25: =C25*(1+Assumptions!D19) | E25: =D25*(1+Assumptions!E19) | F25: =E25*(1+Assumptions!F19)
A26: Selling & marketing | B26: =Assumptions!$C$34*B14 | C26: =Assumptions!$C$34*C14 | D26: =Assumptions!$C$34*D14 | E26: =Assumptions!$C$34*E14 | F26: =Assumptions!$C$34*F14
A27: EBITDA | B27: =B14-B24-B25-B26 | C27: =C14-C24-C25-C26 | D27: =D14-D24-D25-D26 | E27: =E14-E24-E25-E26 | F27: =F14-F24-F25-F26
A28: Other income (management fees from the JV network and misc.) | B28: =Assumptions!$C$72*(1+Assumptions!B20) | C28: =B28*(1+Assumptions!C20) | D28: =C28*(1+Assumptions!D20) | E28: =D28*(1+Assumptions!E20) | F28: =E28*(1+Assumptions!F20)
A29: EBITDA including fees and other income | B29: =B27+B28 | C29: =C27+C28 | D29: =D27+D28 | E29: =E27+E28 | F29: =F27+F28
A30: EBITDA margin | B30: =B27/B14 | C30: =C27/C14 | D30: =D27/D14 | E30: =E27/E14 | F30: =F27/F14
A33: Disclosed history | B33: FY2023 | C33: FY2024 | D33: FY2025
A34: Passengers (millions) | B34: 10.11 | C34: 11.22 | D34: 13.06
A35: Seat load factor | B35: 0.804 | C35: 0.82 | D35: 0.853
A36: Passenger + baggage revenue (AED mn) | B36: n/d | C36: 5552.393 | D36: 6251.713
A37: Ancillary revenue (AED mn) | B37: n/d | C37: 677.506 | D37: 846
A38: Fuel cost (AED mn) | B38: 1690.639 | C38: 1924.547 | D38: 2251.363
A39: Staff cost, direct (AED mn) | B39: 774.751 | C39: 885.104 | D39: 1069.366
A40: Maintenance (AED mn) | B40: 438.924 | C40: 685.639 | D40: 800.577
A41: Landing & overflying (AED mn) | B41: 361.209 | C41: 405.084 | D41: 470.049
A42: Handling (AED mn) | B42: 312.891 | C42: 344.585 | D42: 384.125
A44: FY2023 revenue lines are on the pre-restatement basis (commissions netted); seat/ASK data is not disclosed by the company — passengers x rate is the finest disclosed level.

Sheet Relative & Normalized
A1: Relative multiples · normalised earnings · book value
A4: Relative lens | C4: Value
A5: FY2027E EBITDA EXCLUDING fees/other income (AED mn) — peer basis | C5: =Segments!C27
A6: Justified EV/EBITDA (peer median, primary filings) | C6: =Assumptions!$C$49
A7: Fee/other-income stream valued separately (after-tax annuity) | C7: =Segments!C28*(1-Assumptions!$C$36)/(DCF!C24-Assumptions!$C$47)
A8: Enterprise value at end-FY2027 | C8: =C5*C6+C7
A9: Year-2 discount factor | C9: =DCF!C30
A10: PV of FY2026-27 free cash flow | C10: =DCF!B44+DCF!C44
A11: Implied value per share at the anchor (split roll) | C11: =((C5*C6+C7)*C9+C10)*DCF!C61/Assumptions!$C$53+((Assumptions!$C$76-Assumptions!$C$75+Assumptions!$C$80+Assumptions!$C$79)*DCF!C63-Assumptions!$C$60)/Assumptions!$C$53-Assumptions!$C$54
A12: Bear (5.0x) | C12: =((C5*Assumptions!$C$87+C7)*C9+C10)*DCF!C61/Assumptions!$C$53+((Assumptions!$C$76-Assumptions!$C$75+Assumptions!$C$80+Assumptions!$C$79)*DCF!C63-Assumptions!$C$60)/Assumptions!$C$53-Assumptions!$C$54
A13: Bull (8.0x) | C13: =((C5*Assumptions!$C$88+C7)*C9+C10)*DCF!C61/Assumptions!$C$53+((Assumptions!$C$76-Assumptions!$C$75+Assumptions!$C$80+Assumptions!$C$79)*DCF!C63-Assumptions!$C$60)/Assumptions!$C$53-Assumptions!$C$54
A15: Trailing context (formulas at spot)
A16: EV / FY2025 EBITDA at spot — EX fees (peer basis) | C16: =(DCF!C14+Assumptions!$C$75-Assumptions!$C$76)/'Income Statement'!D9
A17: Price / FY2025 earnings at spot | C17: =Assumptions!$C$52/'Income Statement'!D21
A18: EV / FY2025 EBITDA at spot — INCLUDING fees (both bases published) | C18: =(DCF!C14+Assumptions!$C$75-Assumptions!$C$76)/('Income Statement'!D9+'Income Statement'!D12)
A20: Normalised earnings power | C20: Value
A21: Mid-cycle EBITDA margin (FY2028E) | C21: =Segments!D30
A22: FY2026E revenue (current scale) | C22: =Segments!B14
A23: Normalised EBITDA incl. fees and other income | C23: =C21*C22+Segments!B28
A24: less depreciation & amortisation | C24: =Assumptions!B21
A25: Normalised EBIT | C25: =C23-C24
A26: Net finance income (FY2026E) | C26: ='Cash Flow'!B13-'Cash Flow'!B14
A27: JV share EXCLUDED from the multiplied base (enters at book below) — the base framing carries the JV at carrying value in every lens
A28: Normalised earnings per share (ex-JV) | C28: =(C25+C26)*(1-Assumptions!$C$36)*(1-Assumptions!$C$81)/Assumptions!$C$53
A29: Normalised value per share at the anchor | C29: =Assumptions!$C$50*C28*DCF!C61+Assumptions!$C$79/Assumptions!$C$53*DCF!C63-Assumptions!$C$54
A31: Bear (10x) | C31: =Assumptions!$C$89*C28*DCF!C61+Assumptions!$C$79/Assumptions!$C$53*DCF!C63-Assumptions!$C$54
A32: Bull (16x) | C32: =Assumptions!$C$90*C28*DCF!C61+Assumptions!$C$79/Assumptions!$C$53*DCF!C63-Assumptions!$C$54
A35: Book value and sustainable return | C35: Value
A36: Book value per share (FY2025, audited) | C36: =Assumptions!$C$82/Assumptions!$C$53
A37: Justified price-to-book value per share at the anchor | C37: =((Assumptions!$C$51-Assumptions!$C$47)/(DCF!C21-Assumptions!$C$47))*C36*DCF!C61-Assumptions!$C$54
A38: Justified P/B multiple | C38: =(Assumptions!$C$51-Assumptions!$C$47)/(DCF!C21-Assumptions!$C$47)
A39: Bear construction | C39: =((Assumptions!$C$51-0.02-0.015)/(0.5*(DCF!C10+DCF!C21)-0.015))*C36*DCF!C61-Assumptions!$C$54
A40: Bull construction | C40: =((Assumptions!$C$51+0.02-Assumptions!$C$47)/(DCF!C21-Assumptions!$C$47))*C36*DCF!C61-Assumptions!$C$54
A41: The bear leg holds the same Gordon identity as base and bull: (ROE_bear - g_bear)/(k_bear - g_bear).

Sheet DCF
A1: DCF — cost of capital, glide, waterfall, terminal
A2: Everything here is built, not pasted.
A4: Cost of capital — explicit window
A5: AED government bond yield | C5: =Assumptions!$C$37
A6: less the observed auction spread over US Treasuries | C6: =Assumptions!$C$38
A7: Net risk-free rate | C7: =C5-C6
A8: Beta | C8: =Assumptions!$C$40
A9: Equity risk premium | C9: =Assumptions!$C$41
A10: Cost of equity | C10: =C7+C8*C9
A11: Marginal cost of debt | C11: =Assumptions!$C$44
A12: Tax rate | C12: =Assumptions!$C$36
A13: Cost of debt after tax | C13: =C11*(1-C12)
A14: Market capitalisation (AED mn) | C14: =Assumptions!$C$52*Assumptions!$C$53
A15: Gross debt (audited) | C15: =Assumptions!$C$75
A16: Debt weight (gross) | C16: =C15/(C15+C14)
A17: Cost of capital — explicit window | C17: =(1-C16)*C10+C16*C13+Assumptions!$C$65
A19: Cost of capital — terminal
A20: Terminal risk-free rate | C20: =Assumptions!$C$42
A21: Terminal cost of equity | C21: =C20+Assumptions!$C$40*Assumptions!$C$43
A22: Terminal cost of debt after tax | C22: =Assumptions!$C$45*(1-C12)
A23: Terminal debt weight | C23: =Assumptions!$C$46
A24: Cost of capital — terminal | C24: =(1-C23)*C21+C23*C22+Assumptions!$C$65
A26: Glide & discounting | B26: FY26E | C26: FY27E | D26: FY28E | E26: FY29E | F26: FY30E
A27: Cost-of-debt path | B27: =Assumptions!B28 | C27: =Assumptions!C28 | D27: =Assumptions!D28 | E27: =Assumptions!E28 | F27: =Assumptions!F28
A28: Glide fraction (path progress) | B28: =(Assumptions!$B28-B27)/(Assumptions!B28-Assumptions!F28) | C28: =(Assumptions!$B28-C27)/(Assumptions!B28-Assumptions!F28) | D28: =(Assumptions!$B28-D27)/(Assumptions!B28-Assumptions!F28) | E28: =(Assumptions!$B28-E27)/(Assumptions!B28-Assumptions!F28) | F28: =(Assumptions!$B28-F27)/(Assumptions!B28-Assumptions!F28)
A29: Forward cost of capital | B29: =$C$17-($C$17-$C$24)*B28 | C29: =$C$17-($C$17-$C$24)*C28 | D29: =$C$17-($C$17-$C$24)*D28 | E29: =$C$17-($C$17-$C$24)*E28 | F29: =$C$17-($C$17-$C$24)*F28
A30: Cumulative discount factor | B30: =1/(1+B29) | C30: =B30/(1+C29) | D30: =C30/(1+D29) | E30: =D30/(1+E29) | F30: =E30/(1+F29)
A32: FCFF waterfall (AED mn) | B32: FY26E | C32: FY27E | D32: FY28E | E32: FY29E | F32: FY30E
A33: Revenue | B33: =Segments!B14 | C33: =Segments!C14 | D33: =Segments!D14 | E33: =Segments!E14 | F33: =Segments!F14
A34: EBITDA incl. fees and other income | B34: =Segments!B29 | C34: =Segments!C29 | D34: =Segments!D29 | E34: =Segments!E29 | F34: =Segments!F29
A35: less depreciation & amortisation | B35: =Assumptions!B21 | C35: =Assumptions!C21 | D35: =Assumptions!D21 | E35: =Assumptions!E21 | F35: =Assumptions!F21
A36: EBIT | B36: =B34-B35 | C36: =C34-C35 | D36: =D34-D35 | E36: =E34-E35 | F36: =F34-F35
A37: NOPAT (EBIT x (1 - tax)) | B37: =B36*(1-$C$12) | C37: =C36*(1-$C$12) | D37: =D36*(1-$C$12) | E37: =E36*(1-$C$12) | F37: =F36*(1-$C$12)
A38: add back depreciation & amortisation | B38: =B35 | C38: =C35 | D38: =D35 | E38: =E35 | F38: =F35
A39: less owned capex + pre-delivery payments | B39: =Assumptions!B22*Assumptions!$C$64 | C39: =Assumptions!C22*Assumptions!$C$64 | D39: =Assumptions!D22*Assumptions!$C$64 | E39: =Assumptions!E22*Assumptions!$C$64 | F39: =Assumptions!F22*Assumptions!$C$64
A40: Working capital balance | B40: =Assumptions!$C$35*B33 | C40: =Assumptions!$C$35*C33 | D40: =Assumptions!$C$35*D33 | E40: =Assumptions!$C$35*E33 | F40: =Assumptions!$C$35*F33
A41: less change in working capital | B41: =B40-Assumptions!$C$74 | C41: =C40-B40 | D41: =D40-C40 | E41: =E40-D40 | F41: =F40-E40
A42: Free cash flow to the firm | B42: =B37+B38-B39-B41-B45 | C42: =C37+C38-C39-C41-C45 | D42: =D37+D38-D39-D41-D45 | E42: =E37+E38-E39-E41-E45 | F42: =F37+F38-F39-F41-F45
A43: Discount factor | B43: =B30 | C43: =C30 | D43: =D30 | E43: =E30 | F43: =F30
A44: PV of FCFF | B44: =B42*B43 | C44: =C42*C43 | D44: =D42*D43 | E44: =E42*E43 | F44: =F42*F43
...

Sheet Income Statement
A1: Income statement — 3 years audited + 5 years forecast
A2: FY2023 as reported; FY2024 as restated in the FY2025 filing; forecast chains from the Segments unit build.
B4: FY2023 | C4: FY2024 | D4: FY2025 | E4: FY26E | F4: FY27E | G4: FY28E | H4: FY29E | I4: FY30E
A5: Revenue | B5: 5999.75 | C5: 6765.852 | D5: 7787.581 | E5: =Segments!B14 | F5: =Segments!C14 | G5: =Segments!D14 | H5: =Segments!E14 | I5: =Segments!F14
A6: Direct operating costs (cash) | B6: 3725.597 | C6: 4587.789 | D6: 5506.415 | E6: =Segments!B24 | F6: =Segments!C24 | G6: =Segments!D24 | H6: =Segments!E24 | I6: =Segments!F24
A7: Administrative expenses (cash) | B7: 299.466 | C7: 241.532 | D7: 276.183 | E7: =Segments!B25 | F7: =Segments!C25 | G7: =Segments!D25 | H7: =Segments!E25 | I7: =Segments!F25
A8: Selling & marketing | B8: 88.793 | C8: 103.843 | D8: 113.605 | E8: =Segments!B26 | F8: =Segments!C26 | G8: =Segments!D26 | H8: =Segments!E26 | I8: =Segments!F26
A9: EBITDA | B9: =B5-B6-B7-B8 | C9: =C5-C6-C7-C8 | D9: =D5-D6-D7-D8 | E9: =E5-E6-E7-E8 | F9: =F5-F6-F7-F8 | G9: =G5-G6-G7-G8 | H9: =H5-H6-H7-H8 | I9: =I5-I6-I7-I8
A10: Depreciation & amortisation | B10: 647.327 | C10: 648.588 | D10: 621.798 | E10: =Assumptions!B21 | F10: =Assumptions!C21 | G10: =Assumptions!D21 | H10: =Assumptions!E21 | I10: =Assumptions!F21
A11: Operating profit (EBIT) | B11: =B9-B10 | C11: =C9-C10 | D11: =D9-D10 | E11: =E9-E10 | F11: =F9-F10 | G11: =G9-G10 | H11: =H9-H10 | I11: =I9-I10
A12: Other income | B12: 113.471 | C12: 131.68 | D12: 197.132 | E12: =Segments!B28 | F12: =Segments!C28 | G12: =Segments!D28 | H12: =Segments!E28 | I12: =Segments!F28
A13: Finance income | B13: 209.994 | C13: 250.698 | D13: 240.774 | E13: ='Cash Flow'!B13 | F13: ='Cash Flow'!C13 | G13: ='Cash Flow'!D13 | H13: ='Cash Flow'!E13 | I13: ='Cash Flow'!F13
A14: Finance costs | B14: 102.457 | C14: 82.092 | D14: 66.672 | E14: ='Cash Flow'!B14 | F14: ='Cash Flow'!C14 | G14: ='Cash Flow'!D14 | H14: ='Cash Flow'!E14 | I14: ='Cash Flow'!F14
A15: Share of JV and associate profit | B15: 88.121 | C15: 124.752 | D15: 189.975 | E15: =Assumptions!$C$73*(1+Assumptions!B30) | F15: =E15*(1+Assumptions!C30) | G15: =F15*(1+Assumptions!D30) | H15: =G15*(1+Assumptions!E30) | I15: =H15*(1+Assumptions!F30)
A16: Profit before tax (before the JV share, forecast) | B16: =B11+B12+B13-B14+B15 | C16: =C11+C12+C13-C14+C15 | D16: =D11+D12+D13-D14+D15 | E16: =E11+E12+E13-E14 | F16: =F11+F12+F13-F14 | G16: =G11+G12+G13-G14 | H16: =H11+H12+H13-H14 | I16: =I11+I12+I13-I14
A17: Income tax | B17: 0 | C17: 141.508 | D17: 202.054 | E17: =E16*Assumptions!$C$36 | F17: =F16*Assumptions!$C$36 | G17: =G16*Assumptions!$C$36 | H17: =H16*Assumptions!$C$36 | I17: =I16*Assumptions!$C$36
A18: Profit for the year | B18: =B16-B17 | C18: =C16-C17 | D18: =D16-D17 | E18: =E16-E17+E15 | F18: =F16-F17+F15 | G18: =G16-G17+G15 | H18: =H16-H17+H15 | I18: =I16-I17+I15
A19: Minorities | B19: =B18-B20 | C19: =C18-C20 | D19: =D18-D20 | E19: =E18*Assumptions!$C$81 | F19: =F18*Assumptions!$C$81 | G19: =G18*Assumptions!$C$81 | H19: =H18*Assumptions!$C$81 | I19: =I18*Assumptions!$C$81
A20: Attributable to owners | B20: 1547.132 | C20: 1466.986 | D20: 1628.475 | E20: =E18-E19 | F20: =F18-F19 | G20: =G18-G19 | H20: =H18-H19 | I20: =I18-I19
A21: Earnings per share (AED) | B21: =B20/Assumptions!$C$53 | C21: =C20/Assumptions!$C$53 | D21: =D20/Assumptions!$C$53 | E21: =E20/Assumptions!$C$53 | F21: =F20/Assumptions!$C$53 | G21: =G20/Assumptions!$C$53 | H21: =H20/Assumptions!$C$53 | I21: =I20/Assumptions!$C$53
A22: EBITDA margin | B22: =B9/B5 | C22: =C9/C5 | D22: =D9/D5 | E22: =E9/E5 | F22: =F9/F5 | G22: =G9/G5 | H22: =H9/H5 | I22: =I9/I5
A24: The forecast income statement carries EBIT excluding fees/other income on row 11; the DCF taxes EBIT including that recurring line (row 12), exactly as the study text describes.

Sheet Balance Sheet
A1: Balance sheet — 3 years audited + roll-forward
A2: FY2023 column is the restated 1-Jan-2024 position from the FY2025 filing.
B4: FY2023 | C4: FY2024 | D4: FY2025 | E4: FY26E | F4: FY27E | G4: FY28E | H4: FY29E | I4: FY30E
A5: Fleet assets (PP&E + right-of-use + aircraft advances) | B5: 6415.231 | C5: 6708.975 | D5: 8670.864 | E5: =DCF!B46 | F5: =DCF!C46 | G5: =DCF!D46 | H5: =DCF!E46 | I5: =DCF!F46
A6: Intangible assets | D6: 1362.497 | E6: =Assumptions!$C$78 | F6: =Assumptions!$C$78 | G6: =Assumptions!$C$78 | H6: =Assumptions!$C$78 | I6: =Assumptions!$C$78
A7: Other non-current assets
A8: Inventories | B8: 48.719 | C8: 53.456 | D8: 97.042
A9: Trade and other receivables (current) | B9: 858.576 | C9: 824.296 | D9: 896.388
A10: Cash and fixed deposits | B10: 5246.377 | C10: 5319.517 | D10: 5198.732
A12: Borrowings + lease liabilities | B12: 2278.957 | C12: 2101.441 | D12: 2781.435
A13: Payables, deferred income, provisions (operating) | B13: 4825.511 | C13: 5085.292 | D13: 6180.264
A15: Equity attributable to owners | B15: 7534.006 | C15: 7950.33 | D15: 8408.904 | E15: =Assumptions!$C$82+'Income Statement'!E20-'Cash Flow'!B15 | F15: =E15+'Income Statement'!F20-'Cash Flow'!C15 | G15: =F15+'Income Statement'!G20-'Cash Flow'!D15 | H15: =G15+'Income Statement'!H20-'Cash Flow'!E15 | I15: =H15+'Income Statement'!I20-'Cash Flow'!F15
A16: Working capital (from the lines above) | B16: =B8+B9-B13 | C16: =C8+C9-C13 | D16: =D8+D9-D13 | E16: =DCF!B40 | F16: =DCF!C40 | G16: =DCF!D40 | H16: =DCF!E40 | I16: =DCF!F40
A17: Net debt (negative = net cash) | B17: =B12-B10 | C17: =C12-C10 | D17: =D12-D10 | E17: ='Cash Flow'!B16 | F17: ='Cash Flow'!C16 | G17: ='Cash Flow'!D16 | H17: ='Cash Flow'!E16 | I17: ='Cash Flow'!F16
A18: Net debt / EBITDA | B18: =B17/'Income Statement'!B9 | C18: =C17/'Income Statement'!C9 | D18: =D17/'Income Statement'!D9 | E18: =E17/'Income Statement'!E9 | F18: =F17/'Income Statement'!F9 | G18: =G17/'Income Statement'!G9 | H18: =H17/'Income Statement'!H9 | I18: =I17/'Income Statement'!I9
A20: The forecast rolls fleet assets (capex less depreciation plus leased-fleet additions), working capital (ratio x revenue), net debt (opening less retained cash generation plus dividends) and equity (profit less dividends). Deferred income, maintenance provisions and staff benefits are inside working capital — never double-counted against net debt.

Sheet Cash Flow
A1: Cash flow — FCFF and the financing walk
A2: Links to the DCF waterfall; net debt rolls forward.
A4: FCFF build (AED mn) | B4: FY26E | C4: FY27E | D4: FY28E | E4: FY29E | F4: FY30E
A5: NOPAT | B5: =DCF!B37 | C5: =DCF!C37 | D5: =DCF!D37 | E5: =DCF!E37 | F5: =DCF!F37
A6: add depreciation & amortisation | B6: =DCF!B38 | C6: =DCF!C38 | D6: =DCF!D38 | E6: =DCF!E38 | F6: =DCF!F38
A7: less owned capex + pre-delivery payments | B7: =DCF!B39 | C7: =DCF!C39 | D7: =DCF!D39 | E7: =DCF!E39 | F7: =DCF!F39
A8: less change in working capital | B8: =DCF!B41 | C8: =DCF!C41 | D8: =DCF!D41 | E8: =DCF!E41 | F8: =DCF!F41
A9: Free cash flow to the firm | B9: =B5+B6-B7-B8-B10 | C9: =C5+C6-C7-C8-C10 | D9: =D5+D6-D7-D8-D10 | E9: =E5+E6-E7-E8-E10 | F9: =F5+F6-F7-F8-F10
A10: less leased-fleet additions (gross) | B10: =DCF!B45 | C10: =DCF!C45 | D10: =DCF!D45 | E10: =DCF!E45 | F10: =DCF!F45
A11: Financing walk (AED mn) | B11: FY26E | C11: FY27E | D11: FY28E | E11: FY29E | F11: FY30E
A12: Opening net debt (negative = net cash) | B12: =Assumptions!$C$75-Assumptions!$C$76 | C12: =B16 | D12: =C16 | E12: =D16 | F12: =E16
A13: Finance income (deposit yield x opening cash and deposits) | B13: =Assumptions!B29*(B17-B12) | C13: =Assumptions!C29*(C17-C12) | D13: =Assumptions!D29*(D17-D12) | E13: =Assumptions!E29*(E17-E12) | F13: =Assumptions!F29*(F17-F12)
A14: Finance costs (booked rate x average gross debt) | B14: =Assumptions!B26*(B17+B18)/2 | C14: =Assumptions!C26*(C17+C18)/2 | D14: =Assumptions!D26*(D17+D18)/2 | E14: =Assumptions!E26*(E17+E18)/2 | F14: =Assumptions!F26*(F17+F18)/2
A15: Dividends paid (payout, floored at 30 fils) | B15: =MAX(Assumptions!B31*'Income Statement'!E20,Assumptions!$C$59) | C15: =MAX(Assumptions!C31*'Income Statement'!F20,Assumptions!$C$59) | D15: =MAX(Assumptions!D31*'Income Statement'!G20,Assumptions!$C$59) | E15: =MAX(Assumptions!E31*'Income Statement'!H20,Assumptions!$C$59) | F15: =MAX(Assumptions!F31*'Income Statement'!I20,Assumptions!$C$59)
A16: Closing net debt | B16: =B12-(B9+(B13-B14)*(1-Assumptions!$C$36))+B15 | C16: =C12-(C9+(C13-C14)*(1-Assumptions!$C$36))+C15 | D16: =D12-(D9+(D13-D14)*(1-Assumptions!$C$36))+D15 | E16: =E12-(E9+(E13-E14)*(1-Assumptions!$C$36))+E15 | F16: =F12-(F9+(F13-F14)*(1-Assumptions!$C$36))+F15
A17: Opening gross debt (borrowings + leases) | B17: =Assumptions!$C$75 | C17: =B18 | D17: =C18 | E17: =D18 | F17: =E18
A18: Closing gross debt (+ new leases + aircraft loans - amortisation) | B18: =B17+DCF!B45+Assumptions!B23*Assumptions!$C$58-Assumptions!B27 | C18: =C17+DCF!C45+Assumptions!C23*Assumptions!$C$58-Assumptions!C27 | D18: =D17+DCF!D45+Assumptions!D23*Assumptions!$C$58-Assumptions!D27 | E18: =E17+DCF!E45+Assumptions!E23*Assumptions!$C$58-Assumptions!E27 | F18: =F17+DCF!F45+Assumptions!F23*Assumptions!$C$58-Assumptions!F27
A20: Audited history (AED mn) | B20: FY2023 | C20: FY2024 | D20: FY2025
A21: Net cash from operating activities | B21: 2304.108 | C21: 2278.691 | D21: 2860.401
A22: Fleet capex incl. aircraft advances | B22: 378.035 | C22: 579.654 | D22: 2327.603
A23: Dividends paid to owners | B23: 700.005 | C23: 933.34 | D23: 1167.376
A24: Depreciation & amortisation | B24: 647.327 | C24: 648.588 | D24: 621.798

Sheet Summary Financials
A1: Summary financials — history and forecast in one grid
B4: FY2023 | C4: FY2024 | D4: FY2025 | E4: FY26E | F4: FY27E | G4: FY28E | H4: FY29E | I4: FY30E
A5: Revenue (AED mn) | B5: ='Income Statement'!B5 | C5: ='Income Statement'!C5 | D5: ='Income Statement'!D5 | E5: ='Income Statement'!E5 | F5: ='Income Statement'!F5 | G5: ='Income Statement'!G5 | H5: ='Income Statement'!H5 | I5: ='Income Statement'!I5
A6: Revenue growth | C6: =C5/B5-1 | D6: =D5/C5-1 | E6: =E5/D5-1 | F6: =F5/E5-1 | G6: =G5/F5-1 | H6: =H5/G5-1 | I6: =I5/H5-1
A7: EBITDA (AED mn) | B7: ='Income Statement'!B9 | C7: ='Income Statement'!C9 | D7: ='Income Statement'!D9 | E7: ='Income Statement'!E9 | F7: ='Income Statement'!F9 | G7: ='Income Statement'!G9 | H7: ='Income Statement'!H9 | I7: ='Income Statement'!I9
A8: EBITDA margin | B8: ='Income Statement'!B22 | C8: ='Income Statement'!C22 | D8: ='Income Statement'!D22 | E8: ='Income Statement'!E22 | F8: ='Income Statement'!F22 | G8: ='Income Statement'!G22 | H8: ='Income Statement'!H22 | I8: ='Income Statement'!I22
A9: Attributable profit (AED mn) | B9: ='Income Statement'!B20 | C9: ='Income Statement'!C20 | D9: ='Income Statement'!D20 | E9: ='Income Statement'!E20 | F9: ='Income Statement'!F20 | G9: ='Income Statement'!G20 | H9: ='Income Statement'!H20 | I9: ='Income Statement'!I20
A10: Earnings per share (AED) | B10: ='Income Statement'!B21 | C10: ='Income Statement'!C21 | D10: ='Income Statement'!D21 | E10: ='Income Statement'!E21 | F10: ='Income Statement'!F21 | G10: ='Income Statement'!G21 | H10: ='Income Statement'!H21 | I10: ='Income Statement'!I21
A11: Dividend per share (AED) | B11: 0.2 | C11: 0.25 | D11: 0.3 | E11: ='Cash Flow'!B15/Assumptions!$C$53 | F11: ='Cash Flow'!C15/Assumptions!$C$53 | G11: ='Cash Flow'!D15/Assumptions!$C$53 | H11: ='Cash Flow'!E15/Assumptions!$C$53 | I11: ='Cash Flow'!F15/Assumptions!$C$53
A12: Net debt (AED mn, negative = net cash) | B12: ='Balance Sheet'!B17 | C12: ='Balance Sheet'!C17 | D12: ='Balance Sheet'!D17 | E12: ='Balance Sheet'!E17 | F12: ='Balance Sheet'!F17 | G12: ='Balance Sheet'!G17 | H12: ='Balance Sheet'!H17 | I12: ='Balance Sheet'!I17
A13: Invested capital (AED mn) | E13: =DCF!B47 | F13: =DCF!C47 | G13: =DCF!D47 | H13: =DCF!E47 | I13: =DCF!F47
A14: Return on invested capital | E14: =DCF!B37/DCF!B47 | F14: =DCF!C37/DCF!C47 | G14: =DCF!D37/DCF!D47 | H14: =DCF!E37/DCF!E47 | I14: =DCF!F37/DCF!F47
A15: Return on equity (attributable, opening equity) | E15: ='Income Statement'!E20/Assumptions!$C$82 | F15: ='Income Statement'!F20/'Balance Sheet'!E15 | G15: ='Income Statement'!G20/'Balance Sheet'!F15 | H15: ='Income Statement'!H20/'Balance Sheet'!G15 | I15: ='Income Statement'!I20/'Balance Sheet'!H15
A16: Passengers (millions) | B16: 10.11 | C16: 11.22 | D16: 13.06 | E16: =Segments!B5 | F16: =Segments!C5 | G16: =Segments!D5 | H16: =Segments!E5 | I16: =Segments!F5
A17: Revenue per passenger (AED, total revenue basis) | B17: =B5/B16 | C17: =C5/C16 | D17: =D5/D16 | E17: =E5/E16 | F17: =F5/F16 | G17: =G5/G16 | H17: =H5/H16 | I17: =I5/I16

Sheet Monte Carlo
A1: Monte Carlo price map — 50,000 simulated paths
A2: Whole-model engine output: pasted, does not redraw with drivers.
A4: Horizon | B4: 1 month | C4: 3 months
A5: Check date | B5: 2026-09-07 | C5: 2026-11-09
A6: 5th percentile (AED) | B6: 4.4652043 | C6: 3.9614958
A7: 25th percentile | B7: 4.9252962 | C7: 4.7055653
A8: Median | B8: 5.231036 | C8: 5.2196425
A9: 75th percentile | B9: 5.5562634 | C9: 5.7922137
A10: 95th percentile | B10: 6.1357942 | C10: 6.8896817
A11: Probability of finishing above spot | B11: 0.49236 | C11: 0.48994
A12: Probability of +10% or better at the check date | B12: 0.14406 | C12: 0.25934
A13: Probability of -10% or worse at the check date | B13: 0.1286 | C13: 0.25472
A14: Probability of TOUCHING +10% at any point | B14: 0.24206 | C14: 0.48584
A15: Probability of TOUCHING -10% at any point | B15: 0.21184 | C15: 0.46226
A17: Struck at AED 5.24 on 2026-08-07 with a 5.7% trailing dividend yield netted from the drift. How much to trust these bands: over the stock's full history the simulation's probability bands beat a naive random-walk benchmark by a small margin on a standard probabilistic accuracy score (+0.7% over the full 58-window history, 2012-2026), and over the recent four-plus years the two are statistically indistinguishable — the bands are honest, not clairvoyant. Realised outcomes landed inside the 80% band 79% of the time and inside the 90% band 86% of the time over that same full history — ONE window set, quoted identically in the study.

Sheet Sensitivity
A1: Sensitivity — each cell is a complete revaluation
A2: Whole-model re-runs: pasted, do not redraw with drivers.
A4: Fair value per share: terminal cost of capital x terminal growth
A5: terminal cost of capital \ terminal growth | B5: 1.5% | C5: 2.0% | D5: 2.5% | E5: 3.0% | F5: 3.5%
A6: 6.67% | B6: 4.5637274 | C6: 4.8268338 | D6: 5.1512507 | E6: 5.5620529 | F6: 6.100147
A7: 7.67% | B7: 3.8448941 | C7: 4.002252 | D7: 4.1886364 | E7: 4.413375 | F7: 4.6902722
A8: 8.67% | B8: 3.3282047 | C8: 3.4265656 | D8: 3.5397164 | E8: 3.6715713 | F8: 3.8275595
A9: 9.67% | B9: 2.93935 | C9: 3.0023329 | D9: 3.0731357 | E9: 3.1535175 | F9: 3.2458081
A10: 10.67% | B10: 2.6364461 | C10: 2.6770831 | D10: 2.7218713 | E10: 2.7716229 | F10: 2.8273765
A12: Fair value per share: explicit x terminal cost of capital
A13: explicit \ terminal | B13: 6.67% | C13: 7.67% | D13: 8.67% | E13: 9.67% | F13: 10.67%
A14: 7.21% | B14: 5.3040185 | C14: 4.3093537 | D14: 3.6388372 | E14: 3.156736 | F14: 2.7937934
A15: 8.21% | B15: 5.2267476 | C15: 4.2482948 | D15: 3.5887024 | E15: 3.1144518 | F15: 2.7574163
A16: 9.21% | B16: 5.1512507 | C16: 4.1886364 | D16: 3.5397164 | E16: 3.0731357 | F16: 2.7218713
A17: 10.21% | B17: 5.0774743 | C17: 4.1303362 | D17: 3.4918447 | E17: 3.0327586 | F17: 2.6871335
A18: 11.21% | B18: 5.0053668 | C18: 4.0733536 | D18: 3.4450539 | E18: 2.9932924 | F18: 2.6531787
A20: Beta
B21: 0.85 | C21: 0.95 | D21: 1.086 | E21: 1.2 | F21: 1.35
A22: Fair value per share (AED) | B22: 4.2572538 | C22: 3.9209136 | D22: 3.5397164 | E22: 3.2726185 | F22: 2.9769108
A24: Fuel cost per passenger (multiplier on the base path)
B25: 0.85 | C25: 0.925 | D25: 1.0 | E25: 1.075 | F25: 1.15
A26: Fair value per share (AED) | B26: 4.772475 | C26: 4.1425392 | D26: 3.5126035 | E26: 2.8826677 | F26: 2.2527319
A28: Passenger volumes (multiplier)
B29: 0.9 | C29: 0.95 | D29: 1.0 | E29: 1.05 | F29: 1.1
A30: Fair value per share (AED) | B30: 2.8373891 | C30: 3.1749963 | D30: 3.5126035 | E30: 3.8502107 | F30: 4.1878178
A32: Fare per passenger (multiplier)
B33: 0.94 | C33: 0.97 | D33: 1.0 | E33: 1.03 | F33: 1.06
A34: Fair value per share (AED) | B34: 2.0309232 | C34: 2.7717633 | D34: 3.5126035 | E34: 4.2534436 | F34: 4.9942837
A36: Fleet capex (multiplier)
B37: 0.8 | C37: 0.9 | D37: 1.0 | E37: 1.15 | F37: 1.3
A38: Fair value per share (AED) | B38: 4.0471062 | C38: 3.7798548 | D38: 3.5126035 | E38: 3.1117264 | F38: 2.7108494
A40: JV network value in the bridge (AED mn)
B41: 363 | C41: 1,520 | D41: 2,280 | E41: 2,850 | F41: 3,800
A42: Fair value per share (AED) | B42: 3.5126035 | C42: 3.7664516 | D42: 3.9332596 | E42: 4.0583656 | F42: 4.2668757
A44: Working capital / revenue
B45: -58% | C45: -61% | D45: -64% | E45: -67% | F45: -70%
A46: Fair value per share (AED) | B46: 3.3443509 | C46: 3.4284772 | D46: 3.5126035 | E46: 3.5967297 | F46: 3.680856
A48: Published scenario driver vectors — type these into the Scenario cells on Assumptions to reproduce each pasted output LIVE in this workbook
A49: Scenario | B49: Passenger x | C49: Fare x | D49: Fuel path | E49: Capex x | F49: Rate shift | G49: Terminal g | H49: Output (AED/sh)
A50: High-fuel alternative | B50: 1 | C50: 1 | D50: alternative (switch=1) | E50: 1 | F50: 0bp | G50: 2.5% | H50: 1.8559232
...

Sheet Per-Share & Ratios
A1: Per-share figures and ratios — all formulas
A4: Per share (AED) | B4: FY2025 | C4: FY2026E | D4: FY2028E | E4: FY2030E
A5: Earnings per share | B5: ='Income Statement'!D21 | C5: ='Income Statement'!E21 | D5: ='Income Statement'!G21 | E5: ='Income Statement'!I21
A6: Dividend per share | B6: =Assumptions!$C$54 | C6: ='Cash Flow'!B15/Assumptions!$C$53 | D6: ='Cash Flow'!D15/Assumptions!$C$53 | E6: ='Cash Flow'!F15/Assumptions!$C$53
A7: Book value per share | B7: =Assumptions!$C$82/Assumptions!$C$53 | C7: ='Balance Sheet'!E15/Assumptions!$C$53 | D7: ='Balance Sheet'!G15/Assumptions!$C$53 | E7: ='Balance Sheet'!I15/Assumptions!$C$53
A8: Free cash flow to the firm per share | C8: ='Cash Flow'!B9/Assumptions!$C$53 | D8: ='Cash Flow'!D9/Assumptions!$C$53 | E8: ='Cash Flow'!F9/Assumptions!$C$53
A9: Net cash per share | B9: ='SOTP Bridge'!C6/Assumptions!$C$53
A11: At the spot price | C11: Value
A12: Trailing price/earnings | C12: =Assumptions!$C$52/'Income Statement'!D21
A13: Forward price/earnings (FY2027E) | C13: =Assumptions!$C$52/'Income Statement'!F21
A14: Price / book (FY2025) | C14: =Assumptions!$C$52/((Assumptions!$C$82)/Assumptions!$C$53)
A15: EV / EBITDA (trailing, incl. fees) | C15: =(DCF!C14+Assumptions!$C$75-Assumptions!$C$76)/('Income Statement'!D9+'Income Statement'!D12)
A16: Dividend yield (FY2025 dividend at spot) | C16: =Assumptions!$C$54/Assumptions!$C$52

Sheet Peer & Sector
A1: Peer frame — cross-check only, never a build source
A2: Peer figures from public reporting and reputable aggregators, as dated; Air Arabia rows are live formulas.
A4: Carrier | B4: Trailing P/E | C4: EV/EBITDA | D4: Basis / date
A5: Ryanair | B5: 12.6 | C5: 7.81 | D5: TTM USD ADR, 09-Aug-2026 (aggregator)
A6: easyJet | B6: 12.39 | C6: 3.48 | D6: TTM GBP, 07-Aug-2026 (aggregator)
A7: IndiGo | B7: n/m | C7: 11.09 | D7: TTM INR, 09-Aug-2026; P/E n/m (FX loss year)
A8: Pegasus | B8: 8.9 | C8: 6.58 | D8: TRY statutory basis — treat with caution
A9: Wizz Air | B9: n/m | C9: n/m | D9: n/m — near-zero FY2026 earnings
A10: Jazeera Airways | B10: 17.7 | C10: n/m | D10: computed: mcap / FY2025 net, KWD, 07-Aug-2026
A11: Air transport sector (Damodaran, Jan-2026) | B11: 12.87 | C11: 7.58 | D11: profitable firms / positive-EBITDA firms
A12: Air Arabia (live formulas) | B12: =Assumptions!$C$52/'Income Statement'!D21 | C12: =(DCF!C14+Assumptions!$C$75-Assumptions!$C$76)/('Income Statement'!D9+'Income Statement'!D12) | D12: FY2025 audited, spot 07-Aug-2026
A14: Justified multiples adopted: EV/EBITDA 7.5x (sector centre), P/E 13x (between the mature European carriers ~12.5x and Jazeera ~17.7x). Air Arabia trades above the peer set on both trailing multiples — the relative lens question is whether its net cash, franchise margin and growing JV network justify the premium.
