Workbook

Sheet READ FIRST
A1: EGYPTIAN CHEMICAL INDUSTRIES (KIMA) — EGX: EGCH — VALUATION MODEL
A4: WHAT THIS FILE IS
A5: A live formula model of a single-site Egyptian nitrogen-fertilizer producer. Revenue is built product by product as tonnes times price; cost is built as physical consumption times a unit price; the cost of capital, the discount-rate glide, the free-cash-flow waterfall, the terminal block, the statement roll-forwards and every ratio are calculated in the sheet. Change a blue cell on Assumptions and the valuation recomputes.
A7: BLUE IS AN INPUT. BLACK IS A FORMULA. GREEN IS A LINK TO ANOTHER SHEET.
A9: THE THREE CLASSES OF PASTED CELL, AND THERE ARE NO OTHERS
A10: 1. AUDITED AND DISCLOSED HISTORY. The Income Statement, Balance Sheet and Cash Flow sheets carry the figures exactly as issued in the company's own audited statements for the years ended 30 June 2023, 2024 and 2025 and its reviewed nine-month accounts to 31 March 2026. Where a line is both disclosed and derivable, the DISCLOSED figure is carried and the derivation sits beside it as a check.
A11: 2. THE UNIT BUILD'S OUTPUT. Production tonnages, the split of those tonnes between the subsidised, local free-market and export channels, and the realised price in each channel are the output of a reconciliation against the audited revenue note that would be unreadable flattened into a grid. They are pasted on Assumptions; everything downstream is a formula.
A12: 3. WHOLE-MODEL RE-RUNS AND SIMULATION OUTPUT. Every cell of the Sensitivity grid is a complete revaluation at a different pair of inputs, and the Monte Carlo sheet reports statistics of a fifty-thousand-path simulation. NEITHER REDRAWS WHEN A DRIVER CHANGES, and both say so on their own sheet.
A14: THE CONTESTED JUDGEMENT IS CARRIED BOTH WAYS, NEVER AVERAGED
A15: This company is building a nitric-acid and ammonium-nitrate complex whose bank-approved cost is about three quarters of its own stock-market value. Whether that programme is carried through or stopped is worth more than three pounds a share — more than twice the central estimate itself. Averaging the two would report a number that is true in neither world, so both are computed and both are published: on Summary, on Fundamental Valuation, in the DCF sheet's two columns, and in the expert panel.
A17: This is a valuation study. It is not a rating and not a price target: it reports a range of fair values and the distribution around them.

Sheet Summary
A1: SUMMARY — EVERY READ AT A GLANCE
A2: Every figure here is a formula reading the valuation sheets. The contested judgement appears as two columns and is never averaged into one.
A4: Lens | B4: Programme carried through (EGP/share) | C4: Programme stopped (EGP/share) | D4: Against spot | E4: What it measures
A5: Cash flow — the primary lens | B5: ='DCF'!B44 | C5: ='DCF'!D44 | D5: =B5/$B$14-1 | E5: Free cash flow to the firm, discounted on a glided cost of capital
A6: Book value and sustainable return | B6: ='Fundamental Valuation'!B18 | C6: ='Fundamental Valuation'!B18 | D6: =B6/$B$14-1 | E6: Book equity at the justified multiple implied by its own sustainable return
A7: Relative multiples | B7: ='Relative & Normalized'!B12 | C7: ='Relative & Normalized'!B12 | D7: =B7/$B$14-1 | E7: Forward EBITDA at the mid-point of the Egyptian industrial range
A8: Normalised earnings power | B8: ='Relative & Normalized'!B31 | C8: ='Relative & Normalized'!B31 | D8: =B8/$B$14-1 | E8: Mid-cycle operating profit after tax at a justified multiple
A10: THE FIELD — the range of the published reads, never an average of them
A11: Low | B11: =MIN(B5,C5,B7,B8)
A12: High | B12: =MAX(B5,C5,B7,B8)
A13: Spread across the published reads | B13: =B12-B11
A14: Spot price, 3 September 2026 | B14: 14.41
A15: Shares outstanding | B15: 1986578999
A16: Market capitalisation (EGP m) | B16: =B14*B15/1000000
A18: THE CONTESTED JUDGEMENT — BOTH WAYS, NEVER AVERAGED
A19: Is the ANNA capital programme carried through, or stopped?
A20: Carried through (EGP/share) | B20: =B5
A21: Stopped (EGP/share) | B21: =C5
A22: The gap (EGP/share) | B22: =B21-B20
A23: The gap (EGP m of equity) | B23: =B22*$B$15/1000000
A25: Discount rate implied by the traded price (flat, nominal) | B25: 0.14981365
A26: Sovereign ten-year yield the same day, for comparison | B26: 0.23
A27: Cost of capital built in this model, year one | B27: ='Assumptions'!C115
A28: Cost of capital on the RATING premium basis, year one — the published alternative | B28: ='Assumptions'!C113*'Assumptions'!C104+'Assumptions'!C114*'Assumptions'!C111*(1-'Assumptions'!C112)
A29: Both premium bases are published and neither is mixed with the other's risk-free rate.
A31: Terminal value as a share of enterprise value is reported beside the cash-flow lens on the DCF sheet, in both columns, because on this company it is the number that decides the answer.
A33: THE ANSWER — TWO BRANCHES, PUBLISHED SIDE BY SIDE AND NEVER AVERAGED
A34: Cash-flow lens — ANNA programme CARRIED THROUGH (EGP/share) | B34: =B5
A35: Against spot | B35: =B34/$B$14-1
A36: Cash-flow lens — ANNA programme STOPPED (EGP/share) | B36: 12.772344
A37: Against spot | B37: =B36/$B$14-1
A38: RETIRED — the 45/20/20/15 weighted blend, published unused | B38: 9.6151489
A39: Why it is retired | B39: the weights were typed and had never cleared an out-of-sample test
A40: The judgement is BINARY and its two answers straddle the interesting range, so an average would describe a half-built plant — a world nobody is proposing and the company is not in. Both branches are published; neither is weighted into the other. Bear and full are the field's floor and ceiling.

Sheet Fundamental Valuation
A1: FUNDAMENTAL VALUATION — THE FOUR LENSES, ONE FIELD
A2: The cash-flow lens is primary; the other three test it from directions it cannot test itself.
A4: Lens 2 — book value and sustainable return | B4: Value | C4: Derivation
A5: Book equity, 31 March 2026 (EGP m) | B5: 16206.086 | C5: Paid-in capital plus reserves, as reported
A6: Book value per share (EGP) | B6: =B5*1000000/'Assumptions'!C6
A7: Underlying profit FY2023/24 (EGP m) | B7: 503.361 | C7: Reported profit less the one-off investment-property revaluation gain
A8: Underlying profit FY2024/25 (EGP m) | B8: 986.964 | C8: As reported
A9: Opening equity FY2023/24 (EGP m) | B9: 7249.581 | C9: Prior-year closing equity
A10: Opening equity FY2024/25 (EGP m) | B10: 14560.104 | C10: Prior-year closing equity
A11: Return on equity FY2023/24 | B11: =B7/B9
A12: Return on equity FY2024/25 | B12: =B8/B10
A13: Sustainable return on equity | B13: =(B11+B12)/2 | C13: The two-year average on underlying profit
A14: Cost of equity | B14: ='Assumptions'!C105 | C14: Built on the Assumptions sheet
A15: Terminal growth | B15: ='Assumptions'!C122
A16: Justified price-to-book, before flooring | B16: =(B13-B15)/(B14-B15) | C16: The sustainable return does not cover even nominal maintenance growth, so this is NEGATIVE. That is the finding, not a rounding artefact.
A17: Justified price-to-book | B17: =MAX(0,B16) | C17: Floored at zero
A18: Value per share on this lens (EGP) | B18: =B17*B6
A19: Price-to-book the market pays | B19: =B14*0+'Assumptions'!C7*'Assumptions'!C6/1000000/B5 | C19: For comparison
A21: WHAT THE FOUR LENSES SAY TOGETHER
A22: Lens | B22: EGP per share | C22: Note
A23: Cash flow — programme carried through | B23: 9.2353793
A24: Cash flow — programme stopped | B24: 12.772344
A25: Book value, disclosed (a floor, never weighted) | B25: 8.1577858
A26: Relative multiples | B26: 19.929335
A27: Normalised earnings power | B27: 7.3668064
A29: The field, low to high | B29: =MAX(0,MIN(B23:B27)) | C29: =MAX(B23:B27)
A31: The two cash-flow readings are the contested judgement. They are the two sides of one question and are never averaged; the other three lenses are read against both. Note that the lens giving the highest number — relative multiples — is also the one that never asks what the capital programme does to cash, which is exactly the question the cash-flow lens exists to answer.

Sheet Assumptions
A1: ASSUMPTIONS — THE LIVE DRIVERS
A2: Blue cells are inputs. Change one and the model reprices. Each carries its source. Every value on this sheet comes from the study's input register.
A4: Driver | B4: Unit | C4: Value | D4: Source
A5: THE CAPITALISATION
A6: Shares outstanding | B6: shares | C6: 1986578999 | D6: Audited financial statements, year ended 30 June 2025 (Central Auditing Organization, report dated 23 September 2025), note 14 share capital
A7: Anchor price | B7: EGP | C7: 14.41 | D7: EGCH closing price on the Egyptian Exchange, 3 September 2026. The previous edition was struck on the 6 August close of 13.98
A8: Exchange rate, FY2024/25 average | B8: EGP/US$ | C8: 49 | D8: Constructed: the rate that reconciles note 20 export revenue to the disclosed export price and the implied export tonnage
A9: Normalised-earnings multiple, low | B9: x | C9: 8 | D9: Multiple applied to mid-cycle profit after tax, low end
A10: Normalised-earnings multiple, central | B10: x | C10: 10 | D10: Multiple applied to mid-cycle profit after tax, central
A11: Normalised-earnings multiple, high | B11: x | C11: 12 | D11: Multiple applied to mid-cycle profit after tax, high end
A12: CAPACITY AND VOLUME
A13: Urea design capacity | B13: tonnes/year | C13: 574875 | D13: Constructed: 1,575 t/day contractual plate times 365 days
A14: Ammonia design capacity | B14: tonnes/year | C14: 438000 | D14: Audited financial statements, year ended 30 June 2025 (Central Auditing Organization, report dated 23 September 2025), note 28
A15: Ammonia per tonne of urea | B15: tonnes | C15: 0.61988956 | D15: Constructed: FY2024/25 ammonia output divided by FY2024/25 urea output, both from the auditor's product cost table
A16: Urea capacity utilisation — FY2026/27 | B16: % of plate | C16: 0.913 | D16: Constructed: utilisation path. Audited output ran 586.4kt in FY2022/23 (2% above plate), 521.9kt in FY2023/24 and 513.4kt in FY2024/25; the path never returns to plate because the summer gas curtailment is structural.
A17: Urea capacity utilisation — FY2027/28 | B17: % of plate | C17: 0.922 | D17: Constructed: utilisation path. Audited output ran 586.4kt in FY2022/23 (2% above plate), 521.9kt in FY2023/24 and 513.4kt in FY2024/25; the path never returns to plate because the summer gas curtailment is structural.
A18: Urea capacity utilisation — FY2028/29 | B18: % of plate | C18: 0.93 | D18: Constructed: utilisation path. Audited output ran 586.4kt in FY2022/23 (2% above plate), 521.9kt in FY2023/24 and 513.4kt in FY2024/25; the path never returns to plate because the summer gas curtailment is structural.
A19: Urea capacity utilisation — FY2029/30 | B19: % of plate | C19: 0.939 | D19: Constructed: utilisation path. Audited output ran 586.4kt in FY2022/23 (2% above plate), 521.9kt in FY2023/24 and 513.4kt in FY2024/25; the path never returns to plate because the summer gas curtailment is structural.
A20: Urea capacity utilisation — FY2030/31 | B20: % of plate | C20: 0.948 | D20: Constructed: utilisation path. Audited output ran 586.4kt in FY2022/23 (2% above plate), 521.9kt in FY2023/24 and 513.4kt in FY2024/25; the path never returns to plate because the summer gas curtailment is structural.
A21: Subsidised deliveries — FY2026/27 | B21: tonnes | C21: 155000 | D21: Constructed: subsidised delivery path. The company met 147kt of a 322kt requirement in the fourteen months to August 2025, a 46% compliance rate the forecast does not assume away.
A22: Subsidised deliveries — FY2027/28 | B22: tonnes | C22: 160000 | D22: Constructed: subsidised delivery path. The company met 147kt of a 322kt requirement in the fourteen months to August 2025, a 46% compliance rate the forecast does not assume away.
A23: Subsidised deliveries — FY2028/29 | B23: tonnes | C23: 165000 | D23: Constructed: subsidised delivery path. The company met 147kt of a 322kt requirement in the fourteen months to August 2025, a 46% compliance rate the forecast does not assume away.
A24: Subsidised deliveries — FY2029/30 | B24: tonnes | C24: 170000 | D24: Constructed: subsidised delivery path. The company met 147kt of a 322kt requirement in the fourteen months to August 2025, a 46% compliance rate the forecast does not assume away.
... A30: Local free-market volume — FY2030/31 | B30: tonnes | C30: 44000 | D30: Constructed: local free-market volume path from the 37.1kt implied for FY2024/25.
A32: PRICES
A33: Export urea price — FY2026/27 | B33: US$/tonne | C33: 530 | D33: Held FLAT in nominal dollars at the opening level. No forecast of a traded commodity price is defensible, which is the convention this house applies to the same class of input elsewhere; the previous path fell 17% over five years on a construction nothing sourced.
A34: Export urea price — FY2027/28 | B34: US$/tonne | C34: 530 | D34: Held FLAT in nominal dollars at the opening level. No forecast of a traded commodity price is defensible, which is the convention this house applies to the same class of input elsewhere; the previous path fell 17% over five years on a construction nothing sourced.
A35: Export urea price — FY2028/29 | B35: US$/tonne | C35: 530 | D35: Held FLAT in nominal dollars at the opening level. No forecast of a traded commodity price is defensible, which is the convention this house applies to the same class of input elsewhere; the previous path fell 17% over five years on a construction nothing sourced.
A36: Export urea price — FY2029/30 | B36: US$/tonne | C36: 530 | D36: Held FLAT in nominal dollars at the opening level. No forecast of a traded commodity price is defensible, which is the convention this house applies to the same class of input elsewhere; the previous path fell 17% over five years on a construction nothing sourced.
A37: Export urea price — FY2030/31 | B37: US$/tonne | C37: 530 | D37: Held FLAT in nominal dollars at the opening level. No forecast of a traded commodity price is defensible, which is the convention this house applies to the same class of input elsewhere; the previous path fell 17% over five years on a construction nothing sourced.
A38: Egyptian pounds per US dollar, spot | B38: EGP/US$ | C38: 49.79 | D38: Market quote
A39: Long-run United States inflation | B39: % | C39: 0.024 | D39: Long-run United States inflation, the other leg of the purchasing-power wedge
A40: Currency wedge — FY2026/27 | B40: % | C40: =(1+'Assumptions'!C84)/(1+'Assumptions'!C39)-1 | D40: Derived: the relative-purchasing-power depreciation the inflation path implies against long-run US inflation, the SAME wedge that carries the dollar debt in that year
A41: Egyptian pounds per US dollar — FY2026/27 | B41: EGP/US$ | C41: ='Assumptions'!C38*(1+'Assumptions'!C40) | D41: Derived: the prior year's rate carried on that year's wedge
A42: Currency wedge — FY2027/28 | B42: % | C42: =(1+'Assumptions'!C85)/(1+'Assumptions'!C39)-1 | D42: Derived: the relative-purchasing-power depreciation the inflation path implies against long-run US inflation, the SAME wedge that carries the dollar debt in that year
A43: Egyptian pounds per US dollar — FY2027/28 | B43: EGP/US$ | C43: ='Assumptions'!C41*(1+'Assumptions'!C42) | D43: Derived: the prior year's rate carried on that year's wedge
A44: Currency wedge — FY2028/29 | B44: % | C44: =(1+'Assumptions'!C86)/(1+'Assumptions'!C39)-1 | D44: Derived: the relative-purchasing-power depreciation the inflation path implies against long-run US inflation, the SAME wedge that carries the dollar debt in that year
A45: Egyptian pounds per US dollar — FY2028/29 | B45: EGP/US$ | C45: ='Assumptions'!C43*(1+'Assumptions'!C44) | D45: Derived: the prior year's rate carried on that year's wedge
A46: Currency wedge — FY2029/30 | B46: % | C46: =(1+'Assumptions'!C87)/(1+'Assumptions'!C39)-1 | D46: Derived: the relative-purchasing-power depreciation the inflation path implies against long-run US inflation, the SAME wedge that carries the dollar debt in that year
A47: Egyptian pounds per US dollar — FY2029/30 | B47: EGP/US$ | C47: ='Assumptions'!C45*(1+'Assumptions'!C46) | D47: Derived: the prior year's rate carried on that year's wedge
...

Sheet SOTP Bridge
A1: ENTERPRISE VALUE TO EQUITY — THE BRIDGE, BOTH SIDES OF THE JUDGEMENT
A2: This company has one operating business, so there are no parts to sum. What the bridge does carry is the non-operating stack and the net debt, and it carries them for both sides of the contested judgement.
A4: Component | B4: Programme carried through (EGP m) | C4: Programme stopped (EGP m) | D4: Source
A5: Present value of the explicit window | B5: ='DCF'!B36 | C5: ='DCF'!D36 | D5: Five years of free cash flow to the firm, discounted on the glide
A6: Present value of the terminal value | B6: ='DCF'!B33 | C6: ='DCF'!D33 | D6: The perpetuity, capitalised at the terminal cost of capital
A7: Enterprise value | B7: ='DCF'!B37 | C7: ='DCF'!D37
A8: Terminal value as a share of enterprise value | B8: ='DCF'!B38 | C8: ='DCF'!D38 | D8: Reported because on this company it is the number that decides the answer
A9: Less net debt | B9: =-'DCF'!B41 | C9: =-'DCF'!D41 | D9: Gross debt less cash at 31 March 2026
A10: Plus listed equity stakes at market | B10: ='DCF'!B42 | C10: ='DCF'!D42 | D10: Remaining holdings after the partial disposal in the first half
A11: Plus investment property | B11: ='DCF'!B43 | C11: ='DCF'!D43 | D11: Carried at the revalued amount in the statements
A12: Equity value | B12: ='DCF'!B45 | C12: ='DCF'!D45
A13: Value per share (EGP) | B13: ='DCF'!B44 | C13: ='DCF'!D44

Sheet Segments
A1: SEGMENTS — THE UNIT BUILD, TONNES TIMES PRICE
A2: The company reports one operating segment, so the build goes below it to the product and the channel, which is the finest level the statements source.
A4: Tonnes and prices | B4: FY2026/27 | C4: FY2027/28 | D4: FY2028/29 | E4: FY2029/30 | F4: FY2030/31
A5: Urea production (tonnes) | B5: ='Assumptions'!C13*'Assumptions'!C16 | C5: ='Assumptions'!C13*'Assumptions'!C17 | D5: ='Assumptions'!C13*'Assumptions'!C18 | E5: ='Assumptions'!C13*'Assumptions'!C19 | F5: ='Assumptions'!C13*'Assumptions'!C20
A6: Ammonia produced, capped at the design plate | B6: =MIN(B5*'Assumptions'!C15,'Assumptions'!C14) | C6: =MIN(C5*'Assumptions'!C15,'Assumptions'!C14) | D6: =MIN(D5*'Assumptions'!C15,'Assumptions'!C14) | E6: =MIN(E5*'Assumptions'!C15,'Assumptions'!C14) | F6: =MIN(F5*'Assumptions'!C15,'Assumptions'!C14)
A7: Subsidised volume (tonnes) | B7: ='Assumptions'!C21 | C7: ='Assumptions'!C22 | D7: ='Assumptions'!C23 | E7: ='Assumptions'!C24 | F7: ='Assumptions'!C25
A8: Local free-market volume (tonnes) | B8: ='Assumptions'!C26 | C8: ='Assumptions'!C27 | D8: ='Assumptions'!C28 | E8: ='Assumptions'!C29 | F8: ='Assumptions'!C30
A9: Export volume (tonnes) | B9: =B5-B7-B8 | C9: =C5-C7-C8 | D9: =D5-D7-D8 | E9: =E5-E7-E8 | F9: =F5-F7-F8
A10: Export price net of duty (EGP/tonne) | B10: ='Assumptions'!C33*'Assumptions'!C41*(1-'Assumptions'!C50) | C10: ='Assumptions'!C34*'Assumptions'!C43*(1-'Assumptions'!C50) | D10: ='Assumptions'!C35*'Assumptions'!C45*(1-'Assumptions'!C50) | E10: ='Assumptions'!C36*'Assumptions'!C47*(1-'Assumptions'!C50) | F10: ='Assumptions'!C37*'Assumptions'!C49*(1-'Assumptions'!C50)
A11: Local free-market price (EGP/tonne) | B11: ='Assumptions'!C33*'Assumptions'!C41*'Assumptions'!C56 | C11: ='Assumptions'!C34*'Assumptions'!C43*'Assumptions'!C56 | D11: ='Assumptions'!C35*'Assumptions'!C45*'Assumptions'!C56 | E11: ='Assumptions'!C36*'Assumptions'!C47*'Assumptions'!C56 | F11: ='Assumptions'!C37*'Assumptions'!C49*'Assumptions'!C56
A12: Nitrate price (EGP/tonne) | B12: ='Assumptions'!C62*'Assumptions'!C41/'Assumptions'!C8 | C12: ='Assumptions'!C62*'Assumptions'!C43/'Assumptions'!C8 | D12: ='Assumptions'!C62*'Assumptions'!C45/'Assumptions'!C8 | E12: ='Assumptions'!C62*'Assumptions'!C47/'Assumptions'!C8 | F12: ='Assumptions'!C62*'Assumptions'!C49/'Assumptions'!C8
A13: Export revenue (EGP m) | B13: =B9*B10/1000000 | C13: =C9*C10/1000000 | D13: =D9*D10/1000000 | E13: =E9*E10/1000000 | F13: =F9*F10/1000000
A14: Subsidised revenue (EGP m) | B14: =B7*'Assumptions'!C51/1000000 | C14: =C7*'Assumptions'!C52/1000000 | D14: =D7*'Assumptions'!C53/1000000 | E14: =E7*'Assumptions'!C54/1000000 | F14: =F7*'Assumptions'!C55/1000000
A15: Local free-market revenue (EGP m) | B15: =B8*B11/1000000 | C15: =C8*C11/1000000 | D15: =D8*D11/1000000 | E15: =E8*E11/1000000 | F15: =F8*F11/1000000
A16: Nitrate revenue (EGP m) | B16: ='Assumptions'!C57*B12/1000000 | C16: ='Assumptions'!C58*C12/1000000 | D16: ='Assumptions'!C59*D12/1000000 | E16: ='Assumptions'!C60*E12/1000000 | F16: ='Assumptions'!C61*F12/1000000
A17: Other revenue (EGP m) | B17: ='Assumptions'!C63 | C17: ='Assumptions'!C64 | D17: ='Assumptions'!C65 | E17: ='Assumptions'!C66 | F17: ='Assumptions'!C67
A18: REVENUE (EGP m) | B18: =SUM(B13:B17) | C18: =SUM(C13:C17) | D18: =SUM(D13:D17) | E18: =SUM(E13:E17) | F18: =SUM(F13:F17)
A19: Gas price (EGP per m3) | B19: ='Assumptions'!C71*'Assumptions'!C72*'Assumptions'!C41 | C19: ='Assumptions'!C71*'Assumptions'!C72*'Assumptions'!C43 | D19: ='Assumptions'!C71*'Assumptions'!C72*'Assumptions'!C45 | E19: ='Assumptions'!C71*'Assumptions'!C72*'Assumptions'!C47 | F19: ='Assumptions'!C71*'Assumptions'!C72*'Assumptions'!C49
A20: Natural gas (EGP m) | B20: =B6*'Assumptions'!C70*B19/1000000 | C20: =C6*'Assumptions'!C70*C19/1000000 | D20: =D6*'Assumptions'!C70*D19/1000000 | E20: =E6*'Assumptions'!C70*E19/1000000 | F20: =F6*'Assumptions'!C70*F19/1000000
A21: Cumulative inflation index | B21: =(1+'Assumptions'!C84) | C21: =(1+'Assumptions'!C84)*(1+'Assumptions'!C85) | D21: =(1+'Assumptions'!C84)*(1+'Assumptions'!C85)*(1+'Assumptions'!C86) | E21: =(1+'Assumptions'!C84)*(1+'Assumptions'!C85)*(1+'Assumptions'!C86)*(1+'Assumptions'!C87) | F21: =(1+'Assumptions'!C84)*(1+'Assumptions'!C85)*(1+'Assumptions'!C86)*(1+'Assumptions'!C87)*(1+'Assumptions'!C88)
A22: Other materials (EGP m) | B22: =B5*'Assumptions'!C73*B21/1000000 | C22: =C5*'Assumptions'!C73*C21/1000000 | D22: =D5*'Assumptions'!C73*D21/1000000 | E22: =E5*'Assumptions'!C73*E21/1000000 | F22: =F5*'Assumptions'!C73*F21/1000000
A23: Wages (EGP m) | B23: ='Assumptions'!C74*B21 | C23: ='Assumptions'!C74*C21 | D23: ='Assumptions'!C74*D21 | E23: ='Assumptions'!C74*E21 | F23: ='Assumptions'!C74*F21
A24: Purchased services (EGP m) | B24: ='Assumptions'!C75*B21 | C24: ='Assumptions'!C75*C21 | D24: ='Assumptions'!C75*D21 | E24: ='Assumptions'!C75*E21 | F24: ='Assumptions'!C75*F21
A25: Depreciation and amortisation (EGP m) | B25: ='Assumptions'!C127*(1+'Assumptions'!C134*0)+'Assumptions'!C128 | C25: ='Assumptions'!C127*(1+'Assumptions'!C134*1)+'Assumptions'!C128+SUM('Assumptions'!C129:C129)*'Assumptions'!C135 | D25: ='Assumptions'!C127*(1+'Assumptions'!C134*2)+'Assumptions'!C128+SUM('Assumptions'!C129:C130)*'Assumptions'!C135 | E25: ='Assumptions'!C127*(1+'Assumptions'!C134*3)+'Assumptions'!C128+SUM('Assumptions'!C129:C131)*'Assumptions'!C135 | F25: ='Assumptions'!C127*(1+'Assumptions'!C134*4)+'Assumptions'!C128+SUM('Assumptions'!C129:C132)*'Assumptions'!C135
A26: COST OF SALES (EGP m) | B26: =B20+B22+B23+B24+B25 | C26: =C20+C22+C23+C24+C25 | D26: =D20+D22+D23+D24+D25 | E26: =E20+E22+E23+E24+E25 | F26: =F20+F22+F23+F24+F25
A27: GROSS PROFIT (EGP m) | B27: =B18-B26 | C27: =C18-C26 | D27: =D18-D26 | E27: =E18-E26 | F27: =F18-F26
A28: Gross margin — an OUTPUT, never an input | B28: =B27/B18 | C28: =C27/C18 | D28: =D27/D18 | E28: =E27/E18 | F28: =F27/F18
A29: Inland freight to port (EGP m) | B29: =B9*'Assumptions'!C76*B21/1000000 | C29: =C9*'Assumptions'!C76*C21/1000000 | D29: =D9*'Assumptions'!C76*D21/1000000 | E29: =E9*'Assumptions'!C76*E21/1000000 | F29: =F9*'Assumptions'!C76*F21/1000000
A30: Other selling cost (EGP m) | B30: ='Assumptions'!C77*B21 | C30: ='Assumptions'!C77*C21 | D30: ='Assumptions'!C77*D21 | E30: ='Assumptions'!C77*E21 | F30: ='Assumptions'!C77*F21
A31: Administrative (EGP m) | B31: ='Assumptions'!C78*B21 | C31: ='Assumptions'!C78*C21 | D31: ='Assumptions'!C78*D21 | E31: ='Assumptions'!C78*E21 | F31: ='Assumptions'!C78*F21
A32: Stoppage and abnormal gas cost (EGP m) | B32: ='Assumptions'!C79 | C32: ='Assumptions'!C80 | D32: ='Assumptions'!C81 | E32: ='Assumptions'!C82 | F32: ='Assumptions'!C83
A33: EBIT (EGP m) | B33: =B27-B29-B30-B31-B32 | C33: =C27-C29-C30-C31-C32 | D33: =D27-D29-D30-D31-D32 | E33: =E27-E29-E30-E31-E32 | F33: =F27-F29-F30-F31-F32
A34: EBITDA (EGP m) | B34: =B33+B25 | C34: =C33+C25 | D34: =D33+D25 | E34: =E33+E25 | F34: =F33+F25
A35: EBITDA margin — an OUTPUT | B35: =B34/B18 | C35: =C34/C18 | D35: =D34/D18 | E35: =E34/E18 | F35: =F34/F18
A37: Margins are outputs of the build, not inputs to it. Nothing on this sheet sets a margin; each one falls out of tonnes, prices and physical consumption.

Sheet Relative & Normalized
A1: LENS 3 — RELATIVE MULTIPLES · LENS 4 — NORMALISED EARNINGS POWER
A2: Two cross-checks on the cash-flow lens, each reaching the answer from a direction the cash-flow model cannot reach it from.
A4: Relative multiples | B4: Value | C4: Note
A5: Forward EBITDA, FY2026/27 (EGP m) | B5: ='Segments'!B34 | C5: From the unit build
A6: Egyptian industrial range, low | B6: 6 | C6: Observed trading and transaction range
A7: Egyptian industrial range, high | B7: 9.9 | C7: Observed trading and transaction range
A8: Mid-point | B8: =(B6+B7)/2
A9: Enterprise value at the mid-point (EGP m) | B9: =B5*B8
A10: Less net debt (EGP m) | B10: =-'DCF'!B41 | C10: 31 March 2026
A11: Plus non-operating assets (EGP m) | B11: ='DCF'!B42+'DCF'!B43 | C11: Listed stakes and investment property
A12: Value per share on this lens (EGP) | B12: =(B9+B10+B11)*1000000/'Assumptions'!C6
A13: At the low multiple (EGP) | B13: =(B5*B6+B10+B11)*1000000/'Assumptions'!C6
A14: At the high multiple (EGP) | B14: =(B5*B7+B10+B11)*1000000/'Assumptions'!C6
A15: Multiple the market pays | B15: =('Summary'!B16+'DCF'!B41)/B5 | C15: The gap between this line and the next is the whole disagreement in one number
A16: Multiple this model's cash-flow lens implies | B16: ='DCF'!B37/B5
A18: This lens gives the highest of the four answers, and it is worth saying why: a multiple of forward EBITDA never asks what the capital programme does to cash. It values the plant as though the money being spent on the new complex were not being spent. That is exactly the question the cash-flow lens exists to answer, which is why this one is a cross-check and not the primary read.
A20: Normalised earnings power — every intermediate line | B20: Value | C20: Note
A21: Mid-cycle urea output (tonnes) | B21: 540542 | C21: Three-year average of audited output: 586.4kt, 521.9kt and 513.4kt
A22: Export tonnes at mid-cycle | B22: =B21-'Assumptions'!C21-'Assumptions'!C26 | C22: Output less the subsidised and free-market legs
A23: Mid-cycle export price (US$/tonne) | B23: 400 | C23: Above the 2015-2020 average of roughly US$250 and well below the August 2026 quote of US$545
A24: Exchange rate used | B24: 55.89 | C24: The second year of the currency path
A25: Export revenue (EGP m) | B25: =B22*B23*B24*(1-'Assumptions'!C50)/1000000
A26: Other revenue legs (EGP m) | B26: 2704.4644 | C26: Subsidised, local free market, nitrates and other, on the same paths as the main build
A27: Mid-cycle revenue (EGP m) | B27: =B25+B26
A28: Mid-cycle cash cost (EGP m) | B28: 6828.7391 | C28: Gas, other materials, wages, services, freight, other selling and administration, each escalated on its own driver
A29: Mid-cycle EBITDA (EGP m) | B29: =B27-B28
A30: Mid-cycle operating profit after tax (EGP m) | B30: =(B29-'Assumptions'!C127-'Assumptions'!C128)*(1-'Assumptions'!C112) | C30: After depreciation and tax
A31: Value per share at the central multiple (EGP) | B31: =(B30*'Assumptions'!C10+B10+B11)*1000000/'Assumptions'!C6 | C31: A mature single-asset industrial in a high-inflation economy does not deserve more
A32: At the low multiple (EGP) | B32: =(B30*'Assumptions'!C9+B10+B11)*1000000/'Assumptions'!C6
A33: At the high multiple (EGP) | B33: =(B30*'Assumptions'!C11+B10+B11)*1000000/'Assumptions'!C6

Sheet DCF
A1: DISCOUNTED CASH FLOW — THE CONTESTED JUDGEMENT IN TWO COLUMNS
A2: Column B carries the programme through; column D stops it. Both are complete valuations. They are never averaged.
A4: EGP million | B4: FY2026/27 | C4: FY2027/28 | D4: FY2028/29 | E4: FY2029/30 | F4: FY2030/31 | H4: Case switches
A5: Revenue | B5: ='Segments'!B18 | C5: ='Segments'!C18 | D5: ='Segments'!D18 | E5: ='Segments'!E18 | F5: ='Segments'!F18 | H5: Programme carried through (1 = yes) | I5: 1
A6: EBITDA | B6: ='Segments'!B34 | C6: ='Segments'!C34 | D6: ='Segments'!D34 | E6: ='Segments'!E34 | F6: ='Segments'!F34 | H6: Wind-down cost if stopped (EGP m) | I6: 1000
A7: EBITDA margin | B7: =B6/B5 | C7: =C6/C5 | D7: =D6/D5 | E7: =E6/E5 | F7: =F6/F5
A8: Depreciation and amortisation | B8: ='Segments'!B25 | C8: ='Segments'!C25 | D8: ='Segments'!D25 | E8: ='Segments'!E25 | F8: ='Segments'!F25
A9: EBIT | B9: =B6-B8 | C9: =C6-C8 | D9: =D6-D8 | E9: =E6-E8 | F9: =F6-F8
A10: NOPAT = EBIT x (1 - tax rate) | B10: =B9*(1-'Assumptions'!C112) | C10: =C9*(1-'Assumptions'!C112) | D10: =D9*(1-'Assumptions'!C112) | E10: =E9*(1-'Assumptions'!C112) | F10: =F9*(1-'Assumptions'!C112)
A11: Add back depreciation | B11: =B8 | C11: =C8 | D11: =D8 | E11: =E8 | F11: =F8
A12: Less capital expenditure | B12: =-($I$5*'Assumptions'!C129+$I$6*(1-$I$5)+B5*'Assumptions'!C141) | C12: =-($I$5*'Assumptions'!C130+C5*'Assumptions'!C141) | D12: =-($I$5*'Assumptions'!C131+D5*'Assumptions'!C141) | E12: =-($I$5*'Assumptions'!C132+E5*'Assumptions'!C141) | F12: =-($I$5*'Assumptions'!C133+F5*'Assumptions'!C141)
A13: Less change in working capital | B13: =-'Cash Flow'!B12 | C13: =-'Cash Flow'!C12 | D13: =-'Cash Flow'!D12 | E13: =-'Cash Flow'!E12 | F13: =-'Cash Flow'!F12
A14: FREE CASH FLOW TO THE FIRM | B14: =B10+B11+B12+B13 | C14: =C10+C11+C12+C13 | D14: =D10+D11+D12+D13 | E14: =E10+E11+E12+E13 | F14: =F10+F11+F12+F13
A15: Discount rate from the glide | B15: ='Assumptions'!C115 | C15: ='Assumptions'!C113*(('Assumptions'!C98+('Assumptions'!C118-'Assumptions'!C98)*1/5)+'Assumptions'!C97*'Assumptions'!C103+'Assumptions'!C102)+'Assumptions'!C114*('Assumptions'!C110*'Assumptions'!C106+(1-'Assumptions'!C110)*((1+'Assumptions'!C107)*(1+'Assumptions'!C42)-1))*(1-'Assumptions'!C112) | D15: ='Assumptions'!C113*(('Assumptions'!C98+('Assumptions'!C118-'Assumptions'!C98)*2/5)+'Assumptions'!C97*'Assumptions'!C103+'Assumptions'!C102)+'Assumptions'!C114*('Assumptions'!C110*'Assumptions'!C106+(1-'Assumptions'!C110)*((1+'Assumptions'!C107)*(1+'Assumptions'!C44)-1))*(1-'Assumptions'!C112) | E15: ='Assumptions'!C113*(('Assumptions'!C98+('Assumptions'!C118-'Assumptions'!C98)*3/5)+'Assumptions'!C97*'Assumptions'!C103+'Assumptions'!C102)+'Assumptions'!C114*('Assumptions'!C110*'Assumptions'!C106+(1-'Assumptions'!C110)*((1+'Assumptions'!C107)*(1+'Assumptions'!C46)-1))*(1-'Assumptions'!C112) | F15: ='Assumptions'!C113*(('Assumptions'!C98+('Assumptions'!C118-'Assumptions'!C98)*4/5)+'Assumptions'!C97*'Assumptions'!C103+'Assumptions'!C102)+'Assumptions'!C114*('Assumptions'!C110*'Assumptions'!C106+(1-'Assumptions'!C110)*((1+'Assumptions'!C107)*(1+'Assumptions'!C48)-1))*(1-'Assumptions'!C112)
A16: Discount factor, compounded | B16: =1/(1+B15) | C16: =B16/(1+C15) | D16: =C16/(1+D15) | E16: =D16/(1+E15) | F16: =E16/(1+F15)
A17: PRESENT VALUE OF FREE CASH FLOW | B17: =B14*B16 | C17: =C14*C16 | D17: =D14*D16 | E17: =E14*E16 | F17: =F14*F16
A19: TERMINAL BLOCK AND THE BRIDGE — BOTH SIDES
B20: Programme carried through | D20: Programme stopped
A21: Year-five profit before interest and tax, the project's own depreciation added back, grown at terminal growth | B21: =(F9+SUM('Assumptions'!C129:C132)*'Assumptions'!C135)*(1+'Assumptions'!C122) | D21: =(F9+SUM('Assumptions'!C129:C132)*'Assumptions'!C135)*(1+'Assumptions'!C122)
A22: Project revenue in the terminal year | B22: ='Assumptions'!C144*'Assumptions'!C146*'Assumptions'!C147*('Assumptions'!C49*(1+'Assumptions'!C122-'Assumptions'!C138))/1000000 | D22: ='Assumptions'!C144*0*'Assumptions'!C147*('Assumptions'!C49*(1+'Assumptions'!C122-'Assumptions'!C138))/1000000
A23: Project operating profit, after its own depreciation | B23: =B22*'Assumptions'!C148-'Assumptions'!C139*'Assumptions'!C140*'Assumptions'!C135 | D23: =D22*'Assumptions'!C148-0*'Assumptions'!C140*'Assumptions'!C135
A24: Terminal EBIT | B24: =B21+B23 | D24: =D21+D23
A25: Terminal profit after tax | B25: =B24*(1-'Assumptions'!C112) | D25: =D24*(1-'Assumptions'!C112)
A26: Plus book depreciation and amortisation in the terminal year | B26: =(F8-SUM('Assumptions'!C129:C132)*'Assumptions'!C135)*(1+'Assumptions'!C122)+'Assumptions'!C139*'Assumptions'!C140*'Assumptions'!C135 | D26: =(F8-SUM('Assumptions'!C129:C132)*'Assumptions'!C135)*(1+'Assumptions'!C122)+0*'Assumptions'!C140*'Assumptions'!C135
A27: Less capital maintenance at replacement cost — the book charge escalated over the measured average age of the base | B27: =-B26*(1+'Assumptions'!C116)^'Assumptions'!C123 | D27: =-D26*(1+'Assumptions'!C116)^'Assumptions'!C123
A28: Less capital for REAL growth — the stated real growth is zero, so none | B28: =-((1+'Assumptions'!C122)/(1+'Assumptions'!C116)-1)*(-B27*'Assumptions'!C124) | D28: =-((1+'Assumptions'!C122)/(1+'Assumptions'!C116)-1)*(-D27*'Assumptions'!C124)
A29: Less inflation on the working capital the business carries | B29: =-'Assumptions'!C116*'Cash Flow'!F10*(1+'Assumptions'!C122) | D29: =-'Assumptions'!C116*'Cash Flow'!F10*(1+'Assumptions'!C122)
A30: Terminal free cash flow | B30: =SUM(B25:B29) | D30: =SUM(D25:D29)
A31: TERMINAL VALUE | B31: =B30/('Assumptions'!C121-'Assumptions'!C122) | D31: =D30/('Assumptions'!C121-'Assumptions'!C122)
A32: Memo — the no-growth perpetuity at book depreciation (a diagnostic, not a bound) | B32: =B25/'Assumptions'!C121 | D32: =D25/'Assumptions'!C121
A33: Present value of the terminal value | B33: =B31*F16 | D33: =D31*F16
A36: Present value of the explicit window | B36: =SUM(B17:F17) | D36: =SUM(B54:F54)
A37: ENTERPRISE VALUE | B37: =B36+B33 | D37: =D36+D33
A38: TERMINAL VALUE AS A SHARE OF ENTERPRISE VALUE | B38: =B33/B37 | D38: =D33/D37
A39: Gross debt, 31 March 2026 | B39: 14639.005
A40: Cash and equivalents | B40: 4606.522
A41: Net debt | B41: =B39-B40 | D41: =B41
A42: Listed equity stakes at market | B42: 1509.1126 | D42: =B42
A43: Investment property | B43: 2155.061 | D43: =B43
A44: VALUE PER SHARE (EGP) | B44: =B45*1000000/'Assumptions'!C6 | D44: =D45*1000000/'Assumptions'!C6
...

Sheet Income Statement
A1: INCOME STATEMENT — THREE YEARS HISTORICAL, FIVE YEARS FORECAST
A2: History is carried exactly as issued. The forecast is a formula reading the unit build.
A4: EGP million | B4: FY2022/23 | C4: FY2023/24 | D4: FY2024/25 | E4: FY2025/26E | F4: FY2026/27 | G4: FY2027/28 | H4: FY2028/29 | I4: FY2029/30 | J4: FY2030/31
A5: Revenue | B5: 6612.226 | C5: 6532.126 | D5: 8602.606 | E5: 10378.73 | F5: ='Segments'!B18 | G5: ='Segments'!C18 | H5: ='Segments'!D18 | I5: ='Segments'!E18 | J5: ='Segments'!F18
A6: Cost of sales | B6: 3574.483 | C6: 4395.788 | D6: 5300.31 | E6: 5825.2132 | F6: ='Segments'!B26 | G6: ='Segments'!C26 | H6: ='Segments'!D26 | I6: ='Segments'!E26 | J6: ='Segments'!F26
A7: Gross profit | B7: =B5-B6 | C7: =C5-C6 | D7: =D5-D6 | E7: =E5-E6 | F7: ='Segments'!B27 | G7: ='Segments'!C27 | H7: ='Segments'!D27 | I7: ='Segments'!E27 | J7: ='Segments'!F27
A8: Selling and distribution | B8: 473.72 | C8: 562.527 | D8: 786.463 | E8: 979.60933 | F8: ='Segments'!B29+'Segments'!B30 | G8: ='Segments'!C29+'Segments'!C30 | H8: ='Segments'!D29+'Segments'!D30 | I8: ='Segments'!E29+'Segments'!E30 | J8: ='Segments'!F29+'Segments'!F30
A9: Administrative | B9: 188.851 | C9: 297.887 | D9: 359.624 | E9: 365.108 | F9: ='Segments'!B31 | G9: ='Segments'!C31 | H9: ='Segments'!D31 | I9: ='Segments'!E31 | J9: ='Segments'!F31
A10: EBIT before other items | B10: =B7-B8-B9 | C10: =C7-C8-C9 | D10: =D7-D8-D9 | E10: =E7-E8-E9 | F10: ='Segments'!B33 | G10: ='Segments'!C33 | H10: ='Segments'!D33 | I10: ='Segments'!E33 | J10: ='Segments'!F33
A11: Depreciation and amortisation | B11: 719.213 | C11: 772.634 | D11: 895.849 | E11: 890.591 | F11: ='Segments'!B25 | G11: ='Segments'!C25 | H11: ='Segments'!D25 | I11: ='Segments'!E25 | J11: ='Segments'!F25
A12: EBITDA | B12: =B10+B11 | C12: =C10+C11 | D12: =D10+D11 | E12: =E10+E11 | F12: ='Segments'!B34 | G12: ='Segments'!C34 | H12: ='Segments'!D34 | I12: ='Segments'!E34 | J12: ='Segments'!F34
A13: Gross margin | B13: =B7/B5 | C13: =C7/C5 | D13: =D7/D5 | E13: =E7/E5 | F13: =F7/F5 | G13: =G7/G5 | H13: =H7/H5 | I13: =I7/I5 | J13: =J7/J5
A14: EBITDA margin | B14: =B12/B5 | C14: =C12/C5 | D14: =D12/D5 | E14: =E12/E5 | F14: =F12/F5 | G14: =G12/G5 | H14: =H12/H5 | I14: =I12/I5 | J14: =J12/J5
A16: Net profit as reported | B16: 1150.767 | C16: 2537.934 | D16: 986.964 | E16: 531.31
A17: Less one-off investment-property revaluation | C17: 2034.573
A18: Net profit, underlying | C18: =C16-C17
A20: The EBIT line is struck before provisions, currency translation and other income and expense, so it measures trading rather than the statements' own operating result, which mixes all three. FY2025/26 is nine months reviewed plus a fourth quarter run-rated on the third quarter, with the translation line set to zero: a swing on dollar debt is not forecastable and is carried as a sensitivity instead.

Sheet Balance Sheet
A1: BALANCE SHEET — AS ISSUED, AND ROLLED FORWARD
A2: History exactly as issued at each reporting date. The forecast rolls property on capital expenditure less depreciation and working capital on the disclosed day counts.
A4: EGP million | B4: 30 Jun 2023 | C4: 30 Jun 2024 | D4: 30 Jun 2025 | E4: 31 Mar 2026
A5: Net fixed assets | B5: 11300.438 | C5: 14144.067 | D5: 13587.193 | E5: 13057.606
A6: Construction in progress | B6: 56.405 | C6: 2535.135 | D6: 3790.155 | E6: 5653.51
A7: Investment property | B7: 0 | C7: 2034.589 | D7: 2160.62 | E7: 2155.061
A8: Investments at fair value | B8: 1855.435 | C8: 2491.189 | D8: 2163.27 | E8: 1382.886
A9: Intangible assets | B9: 1908.612 | C9: 2376.211 | D9: 2256.834 | E9: 2170.5
A10: Inventory | B10: 1391.802 | C10: 1615.47 | D10: 2399.625 | E10: 3378.16
A11: Receivables | B11: 798.577 | C11: 858.39 | D11: 631.047 | E11: 1230.232
A12: Cash and equivalents | B12: 1416.243 | C12: 3103.365 | D12: 3057.028 | E12: 4606.522
A13: Total assets | B13: =SUM(B5:B12) | C13: =SUM(C5:C12) | D13: =SUM(D5:D12) | E13: =SUM(E5:E12)
A15: Paid-in capital | B15: 5932.895 | C15: 9932.895 | D15: 9932.895 | E15: 9932.895
A16: Reserves and retained earnings | B16: 1316.686 | C16: 4627.209 | D16: 5430.17 | E16: 6273.191
A17: Long-term bank loans | B17: 8424.871 | C17: 11226.246 | D17: 11183.315 | E17: 14386.056
A18: Holding-company loans | B18: 50.266 | C18: 0 | D18: 596.896 | E18: 45.955
A19: Deferred tax liability | B19: 1469.472 | C19: 1001.464 | D19: 990.863 | E19: 961.184
A20: Provisions | B20: 144.359 | C20: 432.156 | D20: 309.113 | E20: 291.769
A21: Payables and other | B21: 1367.845 | C21: 1587.001 | D21: 1207.768 | E21: 1538.968
A22: Current portion of long-term debt | B22: 21.391 | C22: 354.051 | D22: 397.314 | E22: 206.994
A23: Total equity and liabilities | B23: =SUM(B15:B22) | C23: =SUM(C15:C22) | D23: =SUM(D15:D22) | E23: =SUM(E15:E22)
A24: Gross interest-bearing debt | B24: =B17+B18+B22 | C24: =C17+C18+C22 | D24: =D17+D18+D22 | E24: =E17+E18+E22
A25: Net debt | B25: =B24-B12 | C25: =C24-C12 | D25: =D24-D12 | E25: =E24-E12
A27: FORECAST ROLL-FORWARD
A28: EGP million | B28: FY2026/27 | C28: FY2027/28 | D28: FY2028/29 | E28: FY2029/30 | F28: FY2030/31
A29: Property and construction, opening | B29: 18711.116 | C29: =B32 | D29: =C32 | E29: =D32 | F29: =E32
A30: Capital expenditure | B30: =-'DCF'!B12 | C30: =-'DCF'!C12 | D30: =-'DCF'!D12 | E30: =-'DCF'!E12 | F30: =-'DCF'!F12
A31: Depreciation and amortisation | B31: ='Segments'!B25 | C31: ='Segments'!C25 | D31: ='Segments'!D25 | E31: ='Segments'!E25 | F31: ='Segments'!F25
A32: Property and construction, closing | B32: =B29+B30-B31 | C32: =C29+C30-C31 | D32: =D29+D30-D31 | E32: =E29+E30-E31 | F32: =F29+F30-F31

Sheet Cash Flow
A1: CASH FLOW — WORKING CAPITAL FROM THE DISCLOSED DAY COUNTS
A2: No plugs: receivables, inventory and payables are projected from the day counts the audited statements themselves imply, and the change feeds the free-cash-flow waterfall.
A4: EGP million | B4: FY2026/27 | C4: FY2027/28 | D4: FY2028/29 | E4: FY2029/30 | F4: FY2030/31
A5: Revenue | B5: ='Segments'!B18 | C5: ='Segments'!C18 | D5: ='Segments'!D18 | E5: ='Segments'!E18 | F5: ='Segments'!F18
A6: Cost of sales | B6: ='Segments'!B26 | C6: ='Segments'!C26 | D6: ='Segments'!D26 | E6: ='Segments'!E26 | F6: ='Segments'!F26
A7: Receivables | B7: =B5*'Assumptions'!C149/365 | C7: =C5*'Assumptions'!C149/365 | D7: =D5*'Assumptions'!C149/365 | E7: =E5*'Assumptions'!C149/365 | F7: =F5*'Assumptions'!C149/365
A8: Inventory | B8: =B6*'Assumptions'!C150/365 | C8: =C6*'Assumptions'!C150/365 | D8: =D6*'Assumptions'!C150/365 | E8: =E6*'Assumptions'!C150/365 | F8: =F6*'Assumptions'!C150/365
A9: Payables | B9: =B6*'Assumptions'!C151/365 | C9: =C6*'Assumptions'!C151/365 | D9: =D6*'Assumptions'!C151/365 | E9: =E6*'Assumptions'!C151/365 | F9: =F6*'Assumptions'!C151/365
A10: Net working capital | B10: =B7+B8-B9 | C10: =C7+C8-C9 | D10: =D7+D8-D9 | E10: =E7+E8-E9 | F10: =F7+F8-F9
A11: Opening net working capital, 31 March 2026 as reported, net of the documentary credits inside the inventory line (note 11) | B11: 1662.024
A12: Change in net working capital | B12: =B10-B11 | C12: =C10-B10 | D12: =D10-C10 | E12: =E10-D10 | F12: =F10-E10
A14: Free cash flow to the firm | B14: ='DCF'!B14 | C14: ='DCF'!C14 | D14: ='DCF'!D14 | E14: ='DCF'!E14 | F14: ='DCF'!F14
A20: CAPITAL EXPENDITURE RECORD — WHAT THE COMPANY ACTUALLY SPENDS
A21: Year | B21: Capital expenditure paid (EGP m) | C21: Revenue (EGP m) | D21: Of revenue | E21: What it was
A22: FY2021/22 | B22: 80.847245 | C22: 4440.701 | D22: =B22/C22 | E22: Before the project
A23: FY2022/23 | B23: 42.470154 | C23: 6612.226 | D23: =B23/C23 | E23: Before the project
A24: FY2023/24 | B24: 2396.6083 | C24: 6532.126 | D24: =B24/C24 | E24: The build begins
A25: FY2024/25 | B25: 1545.0538 | C25: 8602.606 | D25: =B25/C25 | E25: Building
A26: 9M FY2025/26 | B26: 1949.1345 | C26: 7314.933 | D26: =B26/C26 | E26: Nine months actual
A28: Pre-project maintenance rate, the two clean years pooled | D28: =(B22+B23)/(C22+C23) | E28: THE MAINTENANCE DRIVER. Assumptions reads this cell.
A29: Replacement-rate framing, the published alternative | B29: 17022.493 | C29: 0.0395 | D29: =B29*C29/B5 | E29: Gross fixed assets at the disclosed machinery rate, over first-forecast-year revenue. NOT used in the valuation — the downside case, published beside the central and never averaged in.
A30: Full-year project spend at the observed run rate | B30: =B26*4/3 | E30: THE PROJECT PATH'S FIRST YEAR. Assumptions reads this cell.
A31: Rate when the facility was signed, 25 June 2025 | B31: 50 | E31: EGP per US dollar
A32: Approved cost of the programme (EGP m) | B32: 6422.418 | C32: 278.385 | D32: =B32+C32*B31 | E32: EGP tranche, dollar tranche, and the two in one currency
A33: Spent by 31 March 2026 (construction in progress) | B33: 5653.51
A34: Still to spend | D34: =D32-B33 | E34: THE PROJECT PATH'S LAST YEAR is this less the four before it, so the path completes the programme by construction
A36: The two shaded years at the top are the answer to the question this block exists to settle. With nothing being built, this plant cost EGP 80.8m and then EGP 42.5m a year to keep running. Everything above that is the new complex, and it stops when the complex is finished.

Sheet Summary Financials
A1: SUMMARY FINANCIALS — THE WHOLE MODEL ON ONE PAGE
A4: EGP million | B4: FY2026/27 | C4: FY2027/28 | D4: FY2028/29 | E4: FY2029/30 | F4: FY2030/31
A5: Revenue | B5: ='DCF'!B5 | C5: ='DCF'!C5 | D5: ='DCF'!D5 | E5: ='DCF'!E5 | F5: ='DCF'!F5
A6: EBITDA | B6: ='DCF'!B6 | C6: ='DCF'!C6 | D6: ='DCF'!D6 | E6: ='DCF'!E6 | F6: ='DCF'!F6
A7: EBITDA margin | B7: ='DCF'!B7 | C7: ='DCF'!C7 | D7: ='DCF'!D7 | E7: ='DCF'!E7 | F7: ='DCF'!F7
A8: EBIT | B8: ='DCF'!B9 | C8: ='DCF'!C9 | D8: ='DCF'!D9 | E8: ='DCF'!E9 | F8: ='DCF'!F9
A9: NOPAT | B9: ='DCF'!B10 | C9: ='DCF'!C10 | D9: ='DCF'!D10 | E9: ='DCF'!E10 | F9: ='DCF'!F10
A10: Capital expenditure | B10: =-'DCF'!B12 | C10: =-'DCF'!C12 | D10: =-'DCF'!D12 | E10: =-'DCF'!E12 | F10: =-'DCF'!F12
A11: Free cash flow to the firm | B11: ='DCF'!B14 | C11: ='DCF'!C14 | D11: ='DCF'!D14 | E11: ='DCF'!E14 | F11: ='DCF'!F14
A12: Present value | B12: ='DCF'!B17 | C12: ='DCF'!C17 | D12: ='DCF'!D17 | E12: ='DCF'!E17 | F12: ='DCF'!F17
A13: Urea output (tonnes) | B13: ='Segments'!B5 | C13: ='Segments'!C5 | D13: ='Segments'!D5 | E13: ='Segments'!E5 | F13: ='Segments'!F5
A14: Export tonnes | B14: ='Segments'!B9 | C14: ='Segments'!C9 | D14: ='Segments'!D9 | E14: ='Segments'!E9 | F14: ='Segments'!F9
A15: Export price (US$/t) | B15: ='Assumptions'!C33 | C15: ='Assumptions'!C34 | D15: ='Assumptions'!C35 | E15: ='Assumptions'!C36 | F15: ='Assumptions'!C37
A17: YEARS THREE TO FIVE AS RANGES — multipliers measured on the company's own history
A18: Every figure below carries the number of tested cases it rests on; years one and two are left as points.
A19: Revenue — low multiplier | B19: x | D19: 0.10696868 | E19: 0.035520119 | F19: 0.081108773
A20: Revenue — high multiplier | B20: x | D20: 1.1753021 | E20: 1.2004229 | F20: 1.3291614
A21: Revenue — low of the range (EGP m) | D21: ='DCF'!D5*D19 | E21: ='DCF'!E5*E19 | F21: ='DCF'!F5*F19
A22: Revenue — high of the range (EGP m) | D22: ='DCF'!D5*D20 | E22: ='DCF'!E5*E20 | F22: ='DCF'!F5*F20
A23: Tested cases behind the revenue band | D23: 11 | E23: 10 | F23: 9

Sheet Monte Carlo
A1: PROBABILISTIC PRICE MAP — SIMULATION OUTPUT
A2: PASTED CLASS 3. These are statistics of a fifty-thousand-path simulation of the traded price, run on the same cleaned price history the rest of the study uses. THIS SHEET DOES NOT REDRAW when a valuation driver changes: it is a map of where the price may go, not of what the business is worth.
A4: Percentile | B4: One month (EGP) | C4: Three months (EGP) | D4: Against spot, 1M | E4: Against spot, 3M
A5: Percentile 5 | B5: 12.12 | C5: 10.84 | D5: =B5/$B$12-1 | E5: =C5/$B$12-1
A6: Percentile 25 | B6: 13.45 | C6: 13.21 | D6: =B6/$B$12-1 | E6: =C6/$B$12-1
A7: Percentile 50 | B7: 14.26 | C7: 14.77 | D7: =B7/$B$12-1 | E7: =C7/$B$12-1
A8: Percentile 75 | B8: 15.11 | C8: 16.5 | D8: =B8/$B$12-1 | E8: =C8/$B$12-1
A9: Percentile 95 | B9: 16.77 | C9: 20.09 | D9: =B9/$B$12-1 | E9: =C9/$B$12-1
A11: Probability the price ends above today's | B11: 0.59134 | C11: 0.63116
A12: Spot at the anchor date | B12: 14.41
A13: Anchor date | B13: 2026-08-06
A14: Check date | B14: 2026-09-06 | C14: 2026-11-08
A16: LEVEL-TOUCH LADDER — probability the price TRADES THROUGH a level at any point before the check date
A17: Level | B17: One month | C17: Three months
A18: Up 5% | B18: 0.56936 | C18: 0.79774
A19: Up 10% | B19: 0.30078 | C19: 0.62622
A20: Up 15% | B20: 0.1504 | C20: 0.47416
A21: Up 20% | B21: 0.07576 | C21: 0.3513
A22: Down 5% | B22: 0.40288 | C22: 0.60252
A23: Down 10% | B23: 0.16326 | C23: 0.3747
A24: Down 15% | B24: 0.062 | C24: 0.22228
A25: Down 20% | B25: 0.0241 | C25: 0.13014
A27: How this was tested. The same method was run backwards over the company's own fifteen-year price history in non-overlapping three-month windows and scored against a random walk. Over the last five years of those windows it beat the random walk, and the outcomes fell across the predicted bands roughly evenly. The statistics are quoted in the study text.

Sheet Sensitivity
A1: SENSITIVITY — WHOLE-MODEL RE-RUNS
A2: PASTED CLASS 3. Each cell is a complete revaluation at that pair of inputs. THIS GRID DOES NOT REDRAW when a driver changes on Assumptions.
A4: Value per share (EGP) — long-run export price against the terminal cost of capital
B5: 17.0% terminal | C5: 18.5% terminal | D5: 20.4% terminal | E5: 22.0% terminal | F5: 24.0% terminal
A6: US$ 380/t long-run export price | B6: -0.3 | C6: -0.67 | D6: -1.02 | E6: -1.25 | F6: -1.48
A7: US$ 420/t long-run export price | B7: 2.23 | C7: 1.65 | D7: 1.1 | E7: 0.75 | F7: 0.4
A8: US$ 460/t long-run export price | B8: 4.76 | C8: 3.97 | D8: 3.22 | E8: 2.74 | F8: 2.27
A9: US$ 500/t long-run export price | B9: 7.28 | C9: 6.29 | D9: 5.35 | E9: 4.74 | F9: 4.14
A10: US$ 540/t long-run export price | B10: 9.81 | C10: 8.61 | D10: 7.47 | E10: 6.74 | F10: 6.02
A13: The crux in observable units. Both inputs are observable rather than matters of opinion: the first prints daily on a listed futures contract, the second can be read against the sovereign's own borrowing cost. A reader who believes urea holds above US$540 for a decade, or that Egyptian equity risk clears below its sovereign, is reading a different cell rather than disagreeing with the arithmetic.
A15: THE CONTESTED CONSTRUCTIONS — one component moved, model re-run | C15: The published answer | D15: ='DCF'!B44
A16: Choice made | B16: The alternative | C16: EGP/share | D16: Against the published
A17: No export duty, because Ministerial Decision 340 of 2026 cancelled the levy with effect from 1 August 2026 — five weeks before this study's strike | B17: The 10% ad-valorem duty back, charged on every export tonne for ever (6.0079), or at half that rate (7.6216) | C17: 6.007894 | D17: =C17-$D$15
A18: The new complex's granulated ammonium nitrate priced at the SAME PRODUCT'S OWN DISCLOSED REALISED PRICE — EGP 20,000/t from note 20, carried on the currency exactly as the existing nitrate business is | B18: Priced at the retired typed US$280/t, the weakest-sourced input in a 304-input register, whose source string was four words long and named no assessor, series, date or basis (8.5859) | C18: 8.5859045 | D18: =C18-$D$15
A19: Country risk priced off the sovereign's traded default swap | B19: Priced off the sovereign's credit rating instead, which is the wider of the two spreads and gives a cost of capital 104 basis points higher | C19: 6.0492386 | D19: =C19-$D$15
A20: A cost of capital that glides from its spot build to a terminal rate made from its own long-run components | B20: One flat spot rate applied to every explicit year and to the perpetuity | C20: 3.145577 | D20: =C20-$D$15
A21: Terminal growth at the central bank's medium-term inflation target | B21: Two percentage points below it, which is negative real maintenance growth | C21: 5.8481757 | D21: =C21-$D$15
A22: The cost of debt at the company's own disclosed rates — 19.4% on the local facility, 11.7% in dollars on the project loan carried at local-equivalent cost on the derived currency path, 24.4% in year one gliding to 13.9% at the terminal | B22: Every leg floored at the 23.00% sovereign ten-year yield — the company's own facilities print no spread above the policy rate, so no spread is added | C22: 6.7623866 | D22: =C22-$D$15
A23: Beta from the five-year weekly regression of the share against the published EGX30 index | B23: The lower bound of that regression's own 90% confidence interval | C23: 10.727558 | D23: =C23-$D$15
A24: Gas at the realised price the company's own loss disclosure implies | B24: The contract formula price in the operating agreement, which is higher | C24: 5.9888769 | D24: =C24-$D$15
A25: The new complex earning at half its derived nameplate in the terminal year | B25: Seventy per cent, which is what a well-run nitrate line achieves | C25: 10.062736 | D25: =C25-$D$15
A26: Maintenance capital expenditure at the company's own observed pre-project rate of 1.12% of revenue | B26: Replacement-rate maintenance: gross fixed assets at the disclosed 3.95% machinery depreciation rate, or 6.11% of revenue | C26: 8.2372258 | D26: =C26-$D$15
A27: Capital maintenance charged at what replacing the plant costs today, on the 4.45-year average age the accounts MEASURE — accumulated depreciation over the year's own charge | B27: Half the 22.1-year life the same accounts imply, 11.04 years, which is what has to be assumed where a company does not disclose enough to measure it | C27: 6.2766788 | D27: =C27-$D$15
A28: Gas consumption at 1,292 cubic metres a tonne of ammonia — the rate implied by allocating three quarters of the single disclosed materials line to gas, which carries the plant's disclosed losses as well as its standard usage | B28: The auditor's own disclosed STANDARD rate of 1,200 cubic metres a tonne, which is what the plant consumes when it runs to specification and excludes the losses | C28: 10.2465 | D28: =C28-$D$15
A29: Project spending anchored on the observed run rate: the nine-month actual extended to a full year | B29: The faster profile the first issue of this study used, opening at EGP 3,000m | C29: 9.0320176 | D29: =C29-$D$15
A31: Each row is a complete re-run of the model through the same case machinery with one component moved and everything else held. Column C is pasted class 3 and DOES NOT REDRAW; column D is a formula against the published answer so the gap can never drift from the values beside it.

Sheet Per-Share & Ratios
A1: PER-SHARE FIGURES AND RATIOS
A2: Every line a formula.
A4: Measure | B4: Value | C4: Basis
A5: Book value per share (EGP) | B5: ='Fundamental Valuation'!B6 | C5: Paid-in capital plus reserves at 31 March 2026 over the share count
A6: Price to book the market pays | B6: ='Summary'!B16/'Fundamental Valuation'!B5
A7: Sustainable return on equity | B7: ='Fundamental Valuation'!B13 | C7: Two-year average on underlying profit
A8: Cost of equity | B8: ='Assumptions'!C105 | C8: Built on the Assumptions sheet, on the CDS premium basis
A9: The gap the company has to close | B9: =B8-B7 | C9: A company earning below its cost of equity destroys value by growing
A10: Net debt to EBITDA, FY2026/27 | B10: ='DCF'!B41/'DCF'!B6 | C10: On the forward year
A11: Enterprise value to EBITDA at the model's value | B11: ='DCF'!B37/'DCF'!B6
A12: Enterprise value to EBITDA at the market price | B12: =('Summary'!B16+'DCF'!B41)/'DCF'!B6
A13: Free cash flow per share, FY2026/27 (EGP) | B13: ='DCF'!B14*1000000/'Assumptions'!C6
A14: Free cash flow per share, FY2030/31 (EGP) | B14: ='DCF'!F14*1000000/'Assumptions'!C6
A15: Dividend per share | B15: 0 | C15: #,##0.00

Sheet Peer & Sector
A1: PEER FRAME AND SECTOR
A2: Cross-check only. Peer data is never a source for this company's own reported history.
A4: Company | B4: Market | C4: Urea capacity (kt/yr) | D4: Location | E4: Why it matters here
A5: Egyptian Chemical Industries | B5: EGX | C5: 574.875 | D5: Aswan, 1,000 km inland | E5: The subject. The only Egyptian nitrogen producer off the coast, which is why freight to port is its own disclosed cost line.
A6: Abu Qir Fertilizers | B6: EGX | C6: 2000 | D6: Alexandria, coastal | E6: The listed comparator, and the marketer of the subject's ammonia exports for a fee of 12% of the export price. The subject held 2.7% of it and began selling down.
A7: MOPCO | B7: Unlisted | C7: 1800 | D7: Damietta, coastal | E7: Curtailed alongside the rest of the industry in the 2026 gas squeeze; the subject's own urea is warehoused at Damietta for export.
A8: Helwan Fertilizers and NCIC | B8: Unlisted | C8: 1300 | D8: Helwan and Ain Sokhna | E8: Completes the supply picture against which the export share is allocated.
A10: Egyptian nitrogen capacity (kt/yr) | B10: 7250
A11: The subject's share of it | B11: =C5/B10
A12: Inland freight per export tonne (EGP) | B12: ='Assumptions'!C76
A14: The freight line is the difference that matters. A coastal producer does not carry it, and on the subject it ran to EGP 610.2 million in the year to June 2025.
