Workbook

Sheet READ FIRST
A1: Read this first
A5: THE RULE
A6: IT CALCULATES. IT DOES NOT STORE.
A8: Exactly ONE class of cell is pasted in this workbook: a figure read off an audited or disclosed filing, or a stated house judgement. Those are the blue cells on Assumptions, and the blue lever cells that define each sensitivity grid point. Everything else is a live formula.
A10: The previous edition also pasted its sensitivity grids, its beta sweep and its bear and bull columns, on the grounds that each is a whole-model re-run and a re-run cannot be written inside a grid. That was 27.6% of the file, and it was the part a reader would most want to interrogate. Three of those pasted rows turned out not to reproduce.
A12: The Sensitivity sheet now writes the entire forecast engine out again, in formulas, once for every grid point. Change any driver on Assumptions and every sensitivity cell in the file moves with it.
A14: WHAT IS AUDITED AND WHAT IS NOT
A15: The base year is the twelve months to 30 June 2026. The first half of it — July to December 2025 — is AUDITED by Crowe with an unqualified opinion. The second half — January to June 2026 — is REPORTED: a disclosure to the Egyptian Exchange dated 29-30 July 2026, not a filing. Half of this base year is a press release and the study says so wherever it uses it.
A17: The gross profit of that reported half is NOT used as released. Run through the company's own first-quarter expense run rates the released figure implies a profit after tax about 12.6% above the profit the same release reports. The gross profit used here is solved from the profit line, which passes two independent coherence tests. Base Year rows 13 to 17 show the whole test.
A19: THE ONE OPERATING INPUT THAT IS NOT READ OFF A FILING
A20: Note 15-A discloses the cost stack for the company and not by line. The processing-intensity weights on Assumptions are therefore a judgement, and the per-line margins depend on them. They are registered, dated and sensitised like every other input rather than hidden inside a formula.

Sheet Assumptions
A1: Assumptions — every driver, with the filing it was read from
A2: Blue cells are the ONLY pasted values in this workbook. Every one is a figure read off an audited or disclosed filing, or a stated house judgement. There is no third class: the previous edition also pasted its sensitivity grids and its bear and bull columns because each is a whole-model re-run; those re-runs are now written out as live formula blocks on the Sensitivity sheet, so a reader can change a driver here and watch every one of them move.
A5: Driver | B5: Value | C5: Ring | D5: Date | E5: Source
A6: MARKET AND CAPITAL
A7: Spot price, EGP | B7: 9.1 | C7: Company | D7: 2026-08-06 | E7: AMOC closing price on the Egyptian Exchange, 6 August 2026
A8: Shares outstanding, mn | B8: 1291.5 | C8: Company | D8: 2025-12-31 | E8: Issued and paid-up capital EGP 1,291,500,000 at EGP 1 par = 1,291,500,000 shares (note 18-L, share split to EGP 1 par recorded in the Commercial Register 24-Jan-2018)
A9: THE TWELVE MONTHS TO 30 JUNE 2026 — the base year
A10: Net sales, 6M to 31-Dec-2025 (AUDITED) | B10: 20735725812 | C10: Company | D10: 2025-12-31 | E10: Net sales, six months to 31-Dec-2025. Audited consolidated FS, transition period 1-Jul-2025 to 31-Dec-2025, Crowe unqualified, 18-Feb-2026
A11: Cost of sales, 6M to 31-Dec-2025 (AUDITED) | B11: 19461550746 | C11: Company | D11: 2025-12-31 | E11: Cost of sales, six months to 31-Dec-2025. Audited consolidated FS, transition period 1-Jul-2025 to 31-Dec-2025, Crowe unqualified, 18-Feb-2026
A12: Net sales, 6M to 30-Jun-2026 (REPORTED) | B12: 26223000000 | C12: Company | D12: 2026-06-30 | E12: Net sales, six months to 30-Jun-2026. Half-year results for 1-Jan to 30-Jun-2026, disclosed to the Egyptian Exchange 29-30 July 2026. REPORTED, NOT AUDITED — a press release, not a filing
A13: Profit after tax, 6M to 30-Jun-2026 (REPORTED) | B13: 1903000000 | C13: Company | D13: 2026-06-30 | E13: Net profit after tax, six months to 30-Jun-2026. Half-year results for 1-Jan to 30-Jun-2026, disclosed to the Egyptian Exchange 29-30 July 2026. REPORTED, NOT AUDITED — a press release, not a filing
A14: Gross profit as RELEASED — rejected, see coherence test | B14: 3258000000 | C14: Company | D14: 2026-06-30 | E14: Gross profit, six months to 30-Jun-2026, AS RELEASED. This study does NOT use this figure: run through the company's own Q1-2026 expense run rates it implies a profit after tax about 12.6% above the profit the same release reports. The gross profit actually used is SOLVED from the release's own profit line, which two independent coherence tests confirm. Half-year results for 1-Jan to 30-Jun-2026, disclosed to the Egyptian Exchange 29-30 July 2026. REPORTED, NOT AUDITED — a press release, not a filing
A15: Net sales, 3M to 31-Mar-2026 (reviewed) | B15: 10510779160 | C15: Company | D15: 2026-03-31 | E15: Net sales, three months to 31-Mar-2026. Reviewed consolidated FS, three months to 31-Mar-2026
A16: Cost of sales, 3M to 31-Mar-2026 (reviewed) | B16: 9439744195 | C16: Company | D16: 2026-03-31 | E16: Cost of sales, three months to 31-Mar-2026. Reviewed consolidated FS, three months to 31-Mar-2026
A17: Administrative expense, 3M to 31-Mar-2026 | B17: 365952237 | C17: Company | D17: 2026-03-31 | E17: General and administrative expenses, three months to 31-Mar-2026. Reviewed consolidated FS, three months to 31-Mar-2026
A18: Selling expense, 3M to 31-Mar-2026 | B18: 60830975 | C18: Company | D18: 2026-03-31 | E18: Marketing and selling expenses, three months to 31-Mar-2026. Reviewed consolidated FS, three months to 31-Mar-2026
A19: Other operating expense, 3M to 31-Mar-2026 | B19: 1080000 | C19: Company | D19: 2026-03-31 | E19: Other operating expenses, three months to 31-Mar-2026. Reviewed consolidated FS, three months to 31-Mar-2026
A20: Other revenue, 3M to 31-Mar-2026 | B20: 225556509 | C20: Company | D20: 2026-03-31 | E20: Other revenue, three months to 31-Mar-2026. Reviewed consolidated FS, three months to 31-Mar-2026
A21: Formed provisions, 3M to 31-Mar-2026 | B21: 30000000 | C21: Company | D21: 2026-03-31 | E21: Formed provisions, three months to 31-Mar-2026. Reviewed consolidated FS, three months to 31-Mar-2026
... A44: Finance cost, 6M to 31-Dec-2025 | B44: 1892108 | C44: Company | D44: 2025-12-31 | E44: Finance expenses, six months to 31-Dec-2025 (note 15-E): loan interest and charges 1,130,556, lease interest 761,552. Audited consolidated FS, transition period 1-Jul-2025 to 31-Dec-2025, Crowe unqualified, 18-Feb-2026
A45: NOTE 14-A — the audited product table, 6M to 31-Dec-2025
A46: Base and special oils — tonnes sold | B46: 54968.98 | C46: Company | D46: 2025-12-31 | E46: Tonnes sold by product line, six months to 31-Dec-2025 (note 14-A). Audited consolidated FS, transition period 1-Jul-2025 to 31-Dec-2025, Crowe unqualified, 18-Feb-2026
A47: Paraffin wax — tonnes sold | B47: 41774.2 | C47: Company | D47: 2025-12-31 | E47: Tonnes sold by product line, six months to 31-Dec-2025 (note 14-A). Audited consolidated FS, transition period 1-Jul-2025 to 31-Dec-2025, Crowe unqualified, 18-Feb-2026
A48: Gas oil — tonnes sold | B48: 171684.88 | C48: Company | D48: 2025-12-31 | E48: Tonnes sold by product line, six months to 31-Dec-2025 (note 14-A). Audited consolidated FS, transition period 1-Jul-2025 to 31-Dec-2025, Crowe unqualified, 18-Feb-2026
A49: Naphtha — tonnes sold | B49: 41430.857 | C49: Company | D49: 2025-12-31 | E49: Tonnes sold by product line, six months to 31-Dec-2025 (note 14-A). Audited consolidated FS, transition period 1-Jul-2025 to 31-Dec-2025, Crowe unqualified, 18-Feb-2026
A50: Liquefied petroleum gas — tonnes sold | B50: 23735.778 | C50: Company | D50: 2025-12-31 | E50: Tonnes sold by product line, six months to 31-Dec-2025 (note 14-A). Audited consolidated FS, transition period 1-Jul-2025 to 31-Dec-2025, Crowe unqualified, 18-Feb-2026
A51: Fuel oil (mix) — tonnes sold | B51: 460153.6 | C51: Company | D51: 2025-12-31 | E51: Tonnes sold by product line, six months to 31-Dec-2025 (note 14-A). Audited consolidated FS, transition period 1-Jul-2025 to 31-Dec-2025, Crowe unqualified, 18-Feb-2026
A52: Heavy fuel oil — tonnes sold | B52: 14327.52 | C52: Company | D52: 2025-12-31 | E52: Tonnes sold by product line, six months to 31-Dec-2025 (note 14-A). Audited consolidated FS, transition period 1-Jul-2025 to 31-Dec-2025, Crowe unqualified, 18-Feb-2026
A53: Waste — tonnes sold | B53: 7.82 | C53: Company | D53: 2025-12-31 | E53: Tonnes sold by product line, six months to 31-Dec-2025 (note 14-A). Audited consolidated FS, transition period 1-Jul-2025 to 31-Dec-2025, Crowe unqualified, 18-Feb-2026
A54: Base and special oils — sales value, EGP | B54: 2597280264 | C54: Company | D54: 2025-12-31 | E54: Sales value by product line, EGP, six months to 31-Dec-2025 (note 14-A). Audited consolidated FS, transition period 1-Jul-2025 to 31-Dec-2025, Crowe unqualified, 18-Feb-2026
A55: Paraffin wax — sales value, EGP | B55: 2041969329 | C55: Company | D55: 2025-12-31 | E55: Sales value by product line, EGP, six months to 31-Dec-2025 (note 14-A). Audited consolidated FS, transition period 1-Jul-2025 to 31-Dec-2025, Crowe unqualified, 18-Feb-2026
A56: Gas oil — sales value, EGP | B56: 5121703599 | C56: Company | D56: 2025-12-31 | E56: Sales value by product line, EGP, six months to 31-Dec-2025 (note 14-A). Audited consolidated FS, transition period 1-Jul-2025 to 31-Dec-2025, Crowe unqualified, 18-Feb-2026
A57: Naphtha — sales value, EGP | B57: 958746631 | C57: Company | D57: 2025-12-31 | E57: Sales value by product line, EGP, six months to 31-Dec-2025 (note 14-A). Audited consolidated FS, transition period 1-Jul-2025 to 31-Dec-2025, Crowe unqualified, 18-Feb-2026
... A61: Waste — sales value, EGP | B61: 87400 | C61: Company | D61: 2025-12-31 | E61: Sales value by product line, EGP, six months to 31-Dec-2025 (note 14-A). Audited consolidated FS, transition period 1-Jul-2025 to 31-Dec-2025, Crowe unqualified, 18-Feb-2026
A62: NOTE 15-A — the audited cost stack, 6M to 31-Dec-2025
A63: Raw materials | B63: 17650102725 | C63: Company | D63: 2025-12-31 | E63: Cost of sales — RAW MATERIALS, six months to 31-Dec-2025 (note 15-A). 90.7% of cost of sales and 85.1% of revenue: this single line is what the company is. Audited consolidated FS, transition period 1-Jul-2025 to 31-Dec-2025, Crowe unqualified, 18-Feb-2026
A64: Salaries | B64: 881019497 | C64: Company | D64: 2025-12-31 | E64: Cost of sales — salaries, six months to 31-Dec-2025 (note 15-A). Audited consolidated FS, transition period 1-Jul-2025 to 31-Dec-2025, Crowe unqualified, 18-Feb-2026
A65: Other expenses | B65: 807146755 | C65: Company | D65: 2025-12-31 | E65: Cost of sales — other expenses, six months to 31-Dec-2025 (note 15-A): natural gas, operating electricity, operating water, spare parts, maintenance, and the operating management and technical support contract with the Egyptian Projects Operations & Maintenance Company (EPROM). Audited consolidated FS, transition period 1-Jul-2025 to 31-Dec-2025, Crowe unqualified, 18-Feb-2026
A66: Supporting materials (chemicals and additives) | B66: 64533723 | C66: Company | D66: 2025-12-31 | E66: Cost of sales — supporting materials (chemicals and additives), six months to 31-Dec-2025 (note 15-A). The previous edition estimated this charge at roughly five times the disclosed figure
A67: Depreciation | B67: 58748046 | C67: Company | D67: 2025-12-31 | E67: Cost of sales — depreciation, six months to 31-Dec-2025 (note 15-A). Audited consolidated FS, transition period 1-Jul-2025 to 31-Dec-2025, Crowe unqualified, 18-Feb-2026
...

Sheet Base Year
A1: Base year — twelve contiguous months to 30 June 2026
A2: The gross profit of the reported half is NOT taken as released. It is solved from the release's own profit line, and the released figure is shown beside it with the profit it would have implied. Every cell below is a formula.
B5: EGP | C5: Check
A6: Administrative + selling + other, 3M to 31-Mar-2026 | B6: =Assumptions!$B$17+Assumptions!$B$18+Assumptions!$B$19
A7: Scaled to the half (x2) | B7: =B6*2
A8: Other revenue, half | B8: =Assumptions!$B$20*2
A9: Provisions and expected credit losses, half | B9: =(Assumptions!$B$21+Assumptions!$B$22)*2
A10: Finance cost, half | B10: =Assumptions!$B$23*2
A11: Effective tax rate, nine months (for the solve only) | B11: =(Assumptions!$B$38-Assumptions!$B$39+Assumptions!$B$40-Assumptions!$B$41)/((Assumptions!$B$38-Assumptions!$B$39+Assumptions!$B$40-Assumptions!$B$41)/0.22118761296853667)
A13: GROSS PROFIT, 6M to 30-Jun-2026 — SOLVED from the profit | B13: =Assumptions!$B$13/(1-B11)+B7-B8+B9+B10
A14: Gross profit AS RELEASED — rejected | B14: =Assumptions!$B$14
A15: Profit the released gross profit would imply | B15: =(B14-B7+B8-B9-B10)*(1-B11)
A16: against the profit the same release reports | B16: =Assumptions!$B$13
A17: Overstatement in the released gross-profit line | B17: =B15/B16-1
A19: BASE-YEAR REVENUE — twelve months to 30-Jun-2026 | B19: =(Assumptions!$B$10+Assumptions!$B$12)/10^6
A20: BASE-YEAR GROSS PROFIT | B20: =(Assumptions!$B$10-Assumptions!$B$11+B13)/10^6
A21: BASE-YEAR COST OF SALES | B21: =B19-B20
A22: BASE-YEAR GROSS MARGIN | B22: =B20/B19
A24: Alternative base: nine audited months x 4/3 | B24: =(Assumptions!$B$10+Assumptions!$B$15)/10^6*4/3
A25: its gross margin | B25: =(Assumptions!$B$10+Assumptions!$B$15-Assumptions!$B$11-Assumptions!$B$16)/(Assumptions!$B$10+Assumptions!$B$15)
A27: Operating lines, SAME twelve months
A28: Administrative expense | B28: =(Assumptions!$B$24+Assumptions!$B$17*2)/10^6
A29: Selling expense | B29: =(Assumptions!$B$25+Assumptions!$B$18*2)/10^6
A30: Other operating expense | B30: =(Assumptions!$B$26+Assumptions!$B$19*2)/10^6
A31: Provisions and credit losses | B31: =(Assumptions!$B$27+(Assumptions!$B$21+Assumptions!$B$22)*2)/10^6
A32: Depreciation | B32: =(Assumptions!$B$28+Assumptions!$B$29*2)/10^6
A33: Cash capital expenditure | B33: =(Assumptions!$B$30+Assumptions!$B$31*2)/10^6
A34: Credit interest | B34: =(Assumptions!$B$32+Assumptions!$B$33*2)/10^6
A35: Employees' profit share | B35: =(Assumptions!$B$34*2)/10^6
A37: Every operating line is struck on the SAME twelve months as revenue and gross profit. The previous edition built revenue from the six-month product table doubled while taking cost of sales from the nine months scaled by four thirds, so its base-year gross margin of 7.081% corresponded to no filed period at all. One period, both sides, or the margin is an artefact of the scalars.
A39: RATES — solved, not assumed
A40: Employees' profit share, % of profit after tax | B40: =B35/((Assumptions!$B$35+Assumptions!$B$13)/10^6)
A41: Minority interest, % of OPERATING profit, whole base year | B41: =((Assumptions!$B$36+Assumptions!$B$37*2)/10^6)/((Assumptions!$B$35+Assumptions!$B$13)/10^6-B34*(1-0.22118761296853667))
A42: Implied asset life, years = fixed assets at cost / depreciation | B42: =Assumptions!$B$70/10^6/B32
A43: Maintenance capital expenditure at cost over that life | B43: =Assumptions!$B$70/10^6/B42
A44: Inventory days of cost of sales | B44: =Assumptions!$B$72/10^6/B21*365
A45: Receivable days of revenue | B45: =(Assumptions!$B$73+Assumptions!$B$74)/10^6/B19*365
A46: Operating payable days of cost of sales — dividends payable REMOVED | B46: =(Assumptions!$B$75+Assumptions!$B$76-Assumptions!$B$77)/10^6/B21*365

Sheet Product and Cost
A1: The eight disclosed product lines — revenue AND cost, per line
A2: Note 14-A gives tonnes and value per line. Note 15-A gives the cost stack for the company and NOT by line, so conversion is allocated on the registered processing-intensity weights and feedstock is then allocated on NET REALISABLE VALUE — the standard joint-product method. Every cell here is a formula.
A5: Line | B5: Tonnes, 6M | C5: Value, EGP 6M | D5: Realisation EGP/t | E5: Base tonnes mn | F5: Base realisation | G5: Conversion EGP/t | H5: Feedstock EGP/t | I5: Spread EGP/t
A6: Base and special oils | B6: =Assumptions!$B$46 | C6: =Assumptions!$B$54 | D6: =C6/B6 | E6: =B6*2/10^6 | F6: =D6*$B$16 | G6: =$B$22*H6/$B$23 | H6: =Assumptions!$B$93 | I6: =F6-G6
A7: Paraffin wax | B7: =Assumptions!$B$47 | C7: =Assumptions!$B$55 | D7: =C7/B7 | E7: =B7*2/10^6 | F7: =D7*$B$16 | G7: =$B$22*H7/$B$23 | H7: =Assumptions!$B$94 | I7: =F7-G7
A8: Gas oil | B8: =Assumptions!$B$48 | C8: =Assumptions!$B$56 | D8: =C8/B8 | E8: =B8*2/10^6 | F8: =D8*$B$16 | G8: =$B$22*H8/$B$23 | H8: =Assumptions!$B$95 | I8: =F8-G8
A9: Naphtha | B9: =Assumptions!$B$49 | C9: =Assumptions!$B$57 | D9: =C9/B9 | E9: =B9*2/10^6 | F9: =D9*$B$16 | G9: =$B$22*H9/$B$23 | H9: =Assumptions!$B$96 | I9: =F9-G9
A10: Liquefied petroleum gas | B10: =Assumptions!$B$50 | C10: =Assumptions!$B$58 | D10: =C10/B10 | E10: =B10*2/10^6 | F10: =D10*$B$16 | G10: =$B$22*H10/$B$23 | H10: =Assumptions!$B$97 | I10: =F10-G10
A11: Fuel oil (mix) | B11: =Assumptions!$B$51 | C11: =Assumptions!$B$59 | D11: =C11/B11 | E11: =B11*2/10^6 | F11: =D11*$B$16 | G11: =$B$22*H11/$B$23 | H11: =Assumptions!$B$98 | I11: =F11-G11
A12: Heavy fuel oil | B12: =Assumptions!$B$52 | C12: =Assumptions!$B$60 | D12: =C12/B12 | E12: =B12*2/10^6 | F12: =D12*$B$16 | G12: =$B$22*H12/$B$23 | H12: =Assumptions!$B$99 | I12: =F12-G12
A13: Waste | B13: =Assumptions!$B$53 | C13: =Assumptions!$B$61 | D13: =C13/B13 | E13: =B13*2/10^6 | F13: =D13*$B$16 | G13: =$B$22*H13/$B$23 | H13: =Assumptions!$B$100 | I13: =F13-G13
A14: TOTAL | B14: =SUM(B6:B13) | C14: =SUM(C6:C13) | E14: =SUM(E6:E13) | F14: =SUMPRODUCT(E6:E13,F6:F13)
A15: Revenue at the disclosed realisations, annualised | B15: =SUMPRODUCT(E6:E13,D6:D13)
A16: REALISATION INDEX — solved so the base year foots | B16: ='Base Year'!B19/B15
A18: COST ALLOCATION
A19: Cost of sales, base year | B19: ='Base Year'!B21
A20: Feedstock share of cost (note 15-A) | B20: =Assumptions!$B$63/(Assumptions!$B$63+Assumptions!$B$64+Assumptions!$B$65+Assumptions!$B$66+Assumptions!$B$67)
A21: Feedstock total | B21: =B19*B20
A22: Conversion total | B22: =B19-B21
A23: Processing-weighted tonnage | B23: =SUMPRODUCT(E6:E13,H6:H13)
A24: Net realisable value weighted tonnage | B24: =SUMPRODUCT(E6:E13,I6:I13)
A26: Line | B26: Conversion EGP/t | C26: Net realisable EGP/t | D26: Feedstock EGP/t | E26: Total cost EGP/t | F26: Realisation EGP/t | G26: Spread EGP/t | H26: Gross margin
A27: Base and special oils | B27: =G6 | C27: =I6 | D27: =$B$21*I6/$B$24 | E27: =D27+B27 | F27: =F6 | G27: =F27-E27 | H27: =G27/F27
A28: Paraffin wax | B28: =G7 | C28: =I7 | D28: =$B$21*I7/$B$24 | E28: =D28+B28 | F28: =F7 | G28: =F28-E28 | H28: =G28/F28
A29: Gas oil | B29: =G8 | C29: =I8 | D29: =$B$21*I8/$B$24 | E29: =D29+B29 | F29: =F8 | G29: =F29-E29 | H29: =G29/F29
A30: Naphtha | B30: =G9 | C30: =I9 | D30: =$B$21*I9/$B$24 | E30: =D30+B30 | F30: =F9 | G30: =F30-E30 | H30: =G30/F30
A31: Liquefied petroleum gas | B31: =G10 | C31: =I10 | D31: =$B$21*I10/$B$24 | E31: =D31+B31 | F31: =F10 | G31: =F31-E31 | H31: =G31/F31
A32: Fuel oil (mix) | B32: =G11 | C32: =I11 | D32: =$B$21*I11/$B$24 | E32: =D32+B32 | F32: =F11 | G32: =F32-E32 | H32: =G32/F32
A33: Heavy fuel oil | B33: =G12 | C33: =I12 | D33: =$B$21*I12/$B$24 | E33: =D33+B33 | F33: =F12 | G33: =F33-E33 | H33: =G33/F33
A34: Waste | B34: =G13 | C34: =I13 | D34: =$B$21*I13/$B$24 | E34: =D34+B34 | F34: =F13 | G34: =F34-E34 | H34: =G34/F34
A35: Cost of sales rebuilt from the per-line allocation | B35: =SUMPRODUCT(E6:E13,E27:E34)
A36: must equal the base-year cost of sales — difference | B36: =B35-'Base Year'!B21
A38: Row 36 is the footing test: the eight per-line costs must rebuild the disclosed cost of sales exactly. Feedstock allocated flat per tonne would make fuel oil sell below the cost of its own feed; feedstock allocated on relative sales value would make base oils and paraffin wax — the products this plant exists for — loss-making. Net realisable value is the standard joint-product method and the only one of the three that leaves every disclosed line with a positive spread.

Sheet Forecast
A1: Forecast engine — eight lines by five years, all formulas
A2: This is the block the Sensitivity sheet replicates twenty-five times, once per grid point, so that every sensitivity cell in this workbook is a live re-run rather than a pasted number.
A5: Levers for this block — the base case sets them all neutral
A6: Volume growth added a year | B6: 0
A7: Gross-margin shift | B7: 0
A8: Realisation-path multiplier | B8: 1
A9: Working-capital cycle multiplier | B9: 1
A10: Explicit cost of capital | B10: =Assumptions!$B$152-Assumptions!$B$153+Assumptions!$B$155*Assumptions!$B$154
A11: Equity weight | B11: =Assumptions!$B$7*Assumptions!$B$8/(Assumptions!$B$7*Assumptions!$B$8+(Assumptions!$B$82+Assumptions!$B$83-Assumptions!$B$79)/10^6)
A12: Debt weight | B12: =1-B11
A13: After-tax cost of net debt | B13: =(Assumptions!$B$157*(Assumptions!$B$82+Assumptions!$B$83)/10^6-Assumptions!$B$156*Assumptions!$B$79/10^6)/((Assumptions!$B$82+Assumptions!$B$83-Assumptions!$B$79)/10^6)*(1-0.22118761296853667)
A14: WACC — explicit window | B14: =B11*B10+B12*B13
A15: Terminal risk-free — DERIVED from the target in force | B15: =Assumptions!$B$158+Assumptions!$B$159
A16: Terminal cost of equity | B16: =B15+Assumptions!$B$155*Assumptions!$B$160
A17: WACC — terminal | B17: =(1-Assumptions!$B$162)*B16+Assumptions!$B$162*Assumptions!$B$161*(1-0.22118761296853667)
A19: BASE CASE | B19: 2026E | C19: 2027E | D19: 2028E | E19: 2029E | F19: 2030E
A20: Inflation index, cumulative | C20: =Assumptions!$B$146 | D20: =C20*Assumptions!$B$147 | E20: =D20*Assumptions!$B$148 | F20: =E20*Assumptions!$B$149 | G20: =F20*Assumptions!$B$150
A21: Realisation index, cumulative | C21: =(1+Assumptions!$B$101*$B$8) | D21: =C21*(1+Assumptions!$B$102*$B$8) | E21: =D21*(1+Assumptions!$B$103*$B$8) | F21: =E21*(1+Assumptions!$B$104*$B$8) | G21: =F21*(1+Assumptions!$B$105*$B$8)
A22: Volume — Base and special oils, mn t | C22: ='Product and Cost'!E6*(1+Assumptions!$B$106+$B$6) | D22: =C22*(1+Assumptions!$B$107+$B$6) | E22: =D22*(1+Assumptions!$B$108+$B$6) | F22: =E22*(1+Assumptions!$B$109+$B$6) | G22: =F22*(1+Assumptions!$B$110+$B$6)
A23: Volume — Paraffin wax, mn t | C23: ='Product and Cost'!E7*(1+Assumptions!$B$111+$B$6) | D23: =C23*(1+Assumptions!$B$112+$B$6) | E23: =D23*(1+Assumptions!$B$113+$B$6) | F23: =E23*(1+Assumptions!$B$114+$B$6) | G23: =F23*(1+Assumptions!$B$115+$B$6)
A24: Volume — Gas oil, mn t | C24: ='Product and Cost'!E8*(1+Assumptions!$B$116+$B$6) | D24: =C24*(1+Assumptions!$B$117+$B$6) | E24: =D24*(1+Assumptions!$B$118+$B$6) | F24: =E24*(1+Assumptions!$B$119+$B$6) | G24: =F24*(1+Assumptions!$B$120+$B$6)
A25: Volume — Naphtha, mn t | C25: ='Product and Cost'!E9*(1+Assumptions!$B$121+$B$6) | D25: =C25*(1+Assumptions!$B$122+$B$6) | E25: =D25*(1+Assumptions!$B$123+$B$6) | F25: =E25*(1+Assumptions!$B$124+$B$6) | G25: =F25*(1+Assumptions!$B$125+$B$6)
A26: Volume — Liquefied petroleum gas, mn t | C26: ='Product and Cost'!E10*(1+Assumptions!$B$126+$B$6) | D26: =C26*(1+Assumptions!$B$127+$B$6) | E26: =D26*(1+Assumptions!$B$128+$B$6) | F26: =E26*(1+Assumptions!$B$129+$B$6) | G26: =F26*(1+Assumptions!$B$130+$B$6)
A27: Volume — Fuel oil (mix), mn t | C27: ='Product and Cost'!E11*(1+Assumptions!$B$131+$B$6) | D27: =C27*(1+Assumptions!$B$132+$B$6) | E27: =D27*(1+Assumptions!$B$133+$B$6) | F27: =E27*(1+Assumptions!$B$134+$B$6) | G27: =F27*(1+Assumptions!$B$135+$B$6)
A28: Volume — Heavy fuel oil, mn t | C28: ='Product and Cost'!E12*(1+Assumptions!$B$136+$B$6) | D28: =C28*(1+Assumptions!$B$137+$B$6) | E28: =D28*(1+Assumptions!$B$138+$B$6) | F28: =E28*(1+Assumptions!$B$139+$B$6) | G28: =F28*(1+Assumptions!$B$140+$B$6)
A29: Volume — Waste, mn t | C29: ='Product and Cost'!E13*(1+Assumptions!$B$141+$B$6) | D29: =C29*(1+Assumptions!$B$142+$B$6) | E29: =D29*(1+Assumptions!$B$143+$B$6) | F29: =E29*(1+Assumptions!$B$144+$B$6) | G29: =F29*(1+Assumptions!$B$145+$B$6)
A30: Total volume, mn t | C30: =SUM(C22:C29) | D30: =SUM(D22:D29) | E30: =SUM(E22:E29) | F30: =SUM(F22:F29) | G30: =SUM(G22:G29)
A31: REVENUE | C31: =C22*'Product and Cost'!$F$6*C21+C23*'Product and Cost'!$F$7*C21+C24*'Product and Cost'!$F$8*C21+C25*'Product and Cost'!$F$9*C21+C26*'Product and Cost'!$F$10*C21+C27*'Product and Cost'!$F$11*C21+C28*'Product and Cost'!$F$12*C21+C29*'Product and Cost'!$F$13*C21 | D31: =D22*'Product and Cost'!$F$6*D21+D23*'Product and Cost'!$F$7*D21+D24*'Product and Cost'!$F$8*D21+D25*'Product and Cost'!$F$9*D21+D26*'Product and Cost'!$F$10*D21+D27*'Product and Cost'!$F$11*D21+D28*'Product and Cost'!$F$12*D21+D29*'Product and Cost'!$F$13*D21 | E31: =E22*'Product and Cost'!$F$6*E21+E23*'Product and Cost'!$F$7*E21+E24*'Product and Cost'!$F$8*E21+E25*'Product and Cost'!$F$9*E21+E26*'Product and Cost'!$F$10*E21+E27*'Product and Cost'!$F$11*E21+E28*'Product and Cost'!$F$12*E21+E29*'Product and Cost'!$F$13*E21 | F31: =F22*'Product and Cost'!$F$6*F21+F23*'Product and Cost'!$F$7*F21+F24*'Product and Cost'!$F$8*F21+F25*'Product and Cost'!$F$9*F21+F26*'Product and Cost'!$F$10*F21+F27*'Product and Cost'!$F$11*F21+F28*'Product and Cost'!$F$12*F21+F29*'Product and Cost'!$F$13*F21 | G31: =G22*'Product and Cost'!$F$6*G21+G23*'Product and Cost'!$F$7*G21+G24*'Product and Cost'!$F$8*G21+G25*'Product and Cost'!$F$9*G21+G26*'Product and Cost'!$F$10*G21+G27*'Product and Cost'!$F$11*G21+G28*'Product and Cost'!$F$12*G21+G29*'Product and Cost'!$F$13*G21
A32: Cost of sales | C32: =C22*('Product and Cost'!$D$27*C21*Assumptions!$B$88+'Product and Cost'!$B$27*(0.4863620081*C20+0.4455809638*C20+0.0356254898*C21+0.0324315384))+C23*('Product and Cost'!$D$28*C21*Assumptions!$B$88+'Product and Cost'!$B$28*(0.4863620081*C20+0.4455809638*C20+0.0356254898*C21+0.0324315384))+C24*('Product and Cost'!$D$29*C21*Assumptions!$B$88+'Product and Cost'!$B$29*(0.4863620081*C20+0.4455809638*C20+0.0356254898*C21+0.0324315384))+C25*('Product and Cost'!$D$30*C21*Assumptions!$B$88+'Product and Cost'!$B$30*(0.4863620081*C20+0.4455809638*C20+0.0356254898*C21+0.0324315384))+C26*('Product and Cost'!$D$31*C21*Assumptions!$B$88+'Product and Cost'!$B$31*(0.4863620081*C20+0.4455809638*C20+0.0356254898*C21+0.0324315384))+C27*('Product and Cost'!$D$32*C21*Assumptions!$B$88+'Product and Cost'!$B$32*(0.4863620081*C20+0.4455809638*C20+0.0356254898*C21+0.0324315384))+C28*('Product and Cost'!$D$33*C21*Assumptions!$B$88+'Product and Cost'!$B$33*(0.4863620081*C20+0.4455809638*C20+0.0356254898*C21+0.0324315384))+C29*('Product and Cost'!$D$34*C21*Assumptions!$B$88+'Product and Cost'!$B$34*(0.4863620081*C20+0.4455809638*C20+0.0356254898*C21+0.0324315384)) | D32: =D22*('Product and Cost'!$D$27*D21*Assumptions!$B$88+'Product and Cost'!$B$27*(0.4863620081*D20+0.4455809638*D20+0.0356254898*D21+0.0324315384))+D23*('Product and Cost'!$D$28*D21*Assumptions!$B$88+'Product and Cost'!$B$28*(0.4863620081*D20+0.4455809638*D20+0.0356254898*D21+0.0324315384))+D24*('Product and Cost'!$D$29*D21*Assumptions!$B$88+'Product and Cost'!$B$29*(0.4863620081*D20+0.4455809638*D20+0.0356254898*D21+0.0324315384))+D25*('Product and Cost'!$D$30*D21*Assumptions!$B$88+'Product and Cost'!$B$30*(0.4863620081*D20+0.4455809638*D20+0.0356254898*D21+0.0324315384))+D26*('Product and Cost'!$D$31*D21*Assumptions!$B$88+'Product and Cost'!$B$31*(0.4863620081*D20+0.4455809638*D20+0.0356254898*D21+0.0324315384))+D27*('Product and Cost'!$D$32*D21*Assumptions!$B$88+'Product and Cost'!$B$32*(0.4863620081*D20+0.4455809638*D20+0.0356254898*D21+0.0324315384))+D28*('Product and Cost'!$D$33*D21*Assumptions!$B$88+'Product and Cost'!$B$33*(0.4863620081*D20+0.4455809638*D20+0.0356254898*D21+0.0324315384))+D29*('Product and Cost'!$D$34*D21*Assumptions!$B$88+'Product and Cost'!$B$34*(0.4863620081*D20+0.4455809638*D20+0.0356254898*D21+0.0324315384)) | E32: =E22*('Product and Cost'!$D$27*E21*Assumptions!$B$88+'Product and Cost'!$B$27*(0.4863620081*E20+0.4455809638*E20+0.0356254898*E21+0.0324315384))+E23*('Product and Cost'!$D$28*E21*Assumptions!$B$88+'Product and Cost'!$B$28*(0.4863620081*E20+0.4455809638*E20+0.0356254898*E21+0.0324315384))+E24*('Product and Cost'!$D$29*E21*Assumptions!$B$88+'Product and Cost'!$B$29*(0.4863620081*E20+0.4455809638*E20+0.0356254898*E21+0.0324315384))+E25*('Product and Cost'!$D$30*E21*Assumptions!$B$88+'Product and Cost'!$B$30*(0.4863620081*E20+0.4455809638*E20+0.0356254898*E21+0.0324315384))+E26*('Product and Cost'!$D$31*E21*Assumptions!$B$88+'Product and Cost'!$B$31*(0.4863620081*E20+0.4455809638*E20+0.0356254898*E21+0.0324315384))+E27*('Product and Cost'!$D$32*E21*Assumptions!$B$88+'Product and Cost'!$B$32*(0.4863620081*E20+0.4455809638*E20+0.0356254898*E21+0.0324315384))+E28*('Product and Cost'!$D$33*E21*Assumptions!$B$88+'Product and Cost'!$B$33*(0.4863620081*E20+0.4455809638*E20+0.0356254898*E21+0.0324315384))+E29*('Product and Cost'!$D$34*E21*Assumptions!$B$88+'Product and Cost'!$B$34*(0.4863620081*E20+0.4455809638*E20+0.0356254898*E21+0.0324315384)) | F32: =F22*('Product and Cost'!$D$27*F21*Assumptions!$B$88+'Product and Cost'!$B$27*(0.4863620081*F20+0.4455809638*F20+0.0356254898*F21+0.0324315384))+F23*('Product and Cost'!$D$28*F21*Assumptions!$B$88+'Product and Cost'!$B$28*(0.4863620081*F20+0.4455809638*F20+0.0356254898*F21+0.0324315384))+F24*('Product and Cost'!$D$29*F21*Assumptions!$B$88+'Product and Cost'!$B$29*(0.4863620081*F20+0.4455809638*F20+0.0356254898*F21+0.0324315384))+F25*('Product and Cost'!$D$30*F21*Assumptions!$B$88+'Product and Cost'!$B$30*(0.4863620081*F20+0.4455809638*F20+0.0356254898*F21+0.0324315384))+F26*('Product and Cost'!$D$31*F21*Assumptions!$B$88+'Product and Cost'!$B$31*(0.4863620081*F20+0.4455809638*F20+0.0356254898*F21+0.0324315384))+F27*('Product and Cost'!$D$32*F21*Assumptions!$B$88+'Product and Cost'!$B$32*(0.4863620081*F20+0.4455809638*F20+0.0356254898*F21+0.0324315384))+F28*('Product and Cost'!$D$33*F21*Assumptions!$B$88+'Product and Cost'!$B$33*(0.4863620081*F20+0.4455809638*F20+0.0356254898*F21+0.0324315384))+F29*('Product and Cost'!$D$34*F21*Assumptions!$B$88+'Product and Cost'!$B$34*(0.4863620081*F20+0.4455809638*F20+0.0356254898*F21+0.0324315384)) | G32: =G22*('Product and Cost'!$D$27*G21*Assumptions!$B$88+'Product and Cost'!$B$27*(0.4863620081*G20+0.4455809638*G20+0.0356254898*G21+0.0324315384))+G23*('Product and Cost'!$D$28*G21*Assumptions!$B$88+'Product and Cost'!$B$28*(0.4863620081*G20+0.4455809638*G20+0.0356254898*G21+0.0324315384))+G24*('Product and Cost'!$D$29*G21*Assumptions!$B$88+'Product and Cost'!$B$29*(0.4863620081*G20+0.4455809638*G20+0.0356254898*G21+0.0324315384))+G25*('Product and Cost'!$D$30*G21*Assumptions!$B$88+'Product and Cost'!$B$30*(0.4863620081*G20+0.4455809638*G20+0.0356254898*G21+0.0324315384))+G26*('Product and Cost'!$D$31*G21*Assumptions!$B$88+'Product and Cost'!$B$31*(0.4863620081*G20+0.4455809638*G20+0.0356254898*G21+0.0324315384))+G27*('Product and Cost'!$D$32*G21*Assumptions!$B$88+'Product and Cost'!$B$32*(0.4863620081*G20+0.4455809638*G20+0.0356254898*G21+0.0324315384))+G28*('Product and Cost'!$D$33*G21*Assumptions!$B$88+'Product and Cost'!$B$33*(0.4863620081*G20+0.4455809638*G20+0.0356254898*G21+0.0324315384))+G29*('Product and Cost'!$D$34*G21*Assumptions!$B$88+'Product and Cost'!$B$34*(0.4863620081*G20+0.4455809638*G20+0.0356254898*G21+0.0324315384))
A33: GROSS PROFIT | C33: =C31-C32+$B$7*C31 | D33: =D31-D32+$B$7*D31 | E33: =E31-E32+$B$7*E31 | F33: =F31-F32+$B$7*F31 | G33: =G31-G32+$B$7*G31
A34: Gross margin | C34: =C33/C31 | D34: =D33/D31 | E34: =E33/E31 | F34: =F33/F31 | G34: =G33/G31
A35: Operating expense | C35: =('Base Year'!$B$28*C20)+('Base Year'!$B$29*C20*C30/'Product and Cost'!$E$14)+('Base Year'!$B$30*C20)+('Base Year'!$B$31*C20) | D35: =('Base Year'!$B$28*D20)+('Base Year'!$B$29*D20*D30/'Product and Cost'!$E$14)+('Base Year'!$B$30*D20)+('Base Year'!$B$31*D20) | E35: =('Base Year'!$B$28*E20)+('Base Year'!$B$29*E20*E30/'Product and Cost'!$E$14)+('Base Year'!$B$30*E20)+('Base Year'!$B$31*E20) | F35: =('Base Year'!$B$28*F20)+('Base Year'!$B$29*F20*F30/'Product and Cost'!$E$14)+('Base Year'!$B$30*F20)+('Base Year'!$B$31*F20) | G35: =('Base Year'!$B$28*G20)+('Base Year'!$B$29*G20*G30/'Product and Cost'!$E$14)+('Base Year'!$B$30*G20)+('Base Year'!$B$31*G20)
A36: EBITDA | C36: =C33-C35 | D36: =D33-D35 | E36: =E33-E35 | F36: =F33-F35 | G36: =G33-G35
A37: Capital expenditure — maintenance + growth | C37: ='Base Year'!$B$43*C20+MAX(C30-'Product and Cost'!$E$14,0)*1947.901031*C20 | D37: ='Base Year'!$B$43*D20+MAX(D30-C30,0)*1947.901031*D20 | E37: ='Base Year'!$B$43*E20+MAX(E30-D30,0)*1947.901031*E20 | F37: ='Base Year'!$B$43*F20+MAX(F30-E30,0)*1947.901031*F20 | G37: ='Base Year'!$B$43*G20+MAX(G30-F30,0)*1947.901031*G20
A38: Fixed assets at cost, closing | C38: =(Assumptions!$B$70+Assumptions!$B$71)/10^6+C37 | D38: =C38+D37 | E38: =D38+E37 | F38: =E38+F37 | G38: =F38+G37
A39: Depreciation — rolls off the asset register | C39: =(Assumptions!$B$70+Assumptions!$B$71)/10^6/'Base Year'!$B$42 | D39: =C38/'Base Year'!$B$42 | E39: =D38/'Base Year'!$B$42 | F39: =E38/'Base Year'!$B$42 | G39: =F38/'Base Year'!$B$42
A40: Fixed assets, net book, closing | C40: =(Assumptions!$B$69+Assumptions!$B$71)/10^6+C37-C39 | D40: =C40+D37-D39 | E40: =D40+E37-E39 | F40: =E40+F37-F39 | G40: =F40+G37-G39
A41: EBIT | C41: =C36-C39 | D41: =D36-D39 | E41: =E36-E39 | F41: =F36-F39 | G41: =G36-G39
A42: NOPAT before the profit share | C42: =C41*(1-Assumptions!$B$87) | D42: =D41*(1-Assumptions!$B$87) | E42: =E41*(1-Assumptions!$B$87) | F42: =F41*(1-Assumptions!$B$87) | G42: =G41*(1-Assumptions!$B$87)
A43: less employees' profit share and board bonuses | C43: =MAX(C42,0)*'Base Year'!$B$40 | D43: =MAX(D42,0)*'Base Year'!$B$40 | E43: =MAX(E42,0)*'Base Year'!$B$40 | F43: =MAX(F42,0)*'Base Year'!$B$40 | G43: =MAX(G42,0)*'Base Year'!$B$40
...

Sheet Sensitivity
A1: Sensitivity — every grid point is the whole engine, again, in formulas
A2: The previous edition pasted these rows because each point is a whole-model re-run and its builder could not express a re-run inside a grid. Three of the pasted rows turned out not to reproduce: a working-capital row whose grid was never sorted, a beta row whose centre did not return the base case, and a volume row whose label described a different scenario from the one it ran. None of that can happen here, because there is nothing to paste.
A4: Summary — every cell points at its own live block below
A5: Gross margin, shifted on every forecast year
A6: grid point 1: -1.0% | C6: -0.01 | I6: =B95
A7: grid point 2: -0.5% | C7: -0.005 | I7: =B144
A8: grid point 3: +0.0% | C8: 0 | I8: =B193 | J8: =B193-Forecast!B65
A9: grid point 4: +0.5% | C9: 0.005 | I9: =B242
A10: grid point 5: +1.0% | C10: 0.01 | I10: =B291
A12: Volume growth path, as a multiple of the assumed path
A13: grid point 1: -6.0% | B13: -0.06 | I13: =B340
A14: grid point 2: -3.0% | B14: -0.03 | I14: =B389
A15: grid point 3: +0.0% | B15: 0 | I15: =B438 | J15: =B438-Forecast!B65
A16: grid point 4: +3.0% | B16: 0.03 | I16: =B487
A17: grid point 5: +6.0% | B17: 0.06 | I17: =B536
A19: Realisation path, as a multiple of the assumed path
A20: grid point 1: 0.90x | D20: 0.9 | I20: =B585
A21: grid point 2: 0.95x | D21: 0.95 | I21: =B634
A22: grid point 3: 1.00x | D22: 1 | I22: =B683 | J22: =B683-Forecast!B65
A23: grid point 4: 1.05x | D23: 1.05 | I23: =B732
A24: grid point 5: 1.10x | D24: 1.1 | I24: =B781
A26: Beta
A27: grid point 1: 0.6000 | F27: 0.27533624 | G27: 0.16198219 | I27: =B830
A28: grid point 2: 0.8000 | F28: 0.29909374 | G28: 0.17458219 | I28: =B879
A29: grid point 3: 0.9080 | F29: 0.31192279 | G29: 0.18138619 | I29: =B928 | J29: =B928-Forecast!B65
A30: grid point 4: 1.1500 | F30: 0.34066938 | G30: 0.19663219 | I30: =B977
A31: grid point 5: 1.3000 | F31: 0.35848751 | G31: 0.20608219 | I31: =B1026
A33: Working-capital cycle, as a multiple of the solved days
A34: grid point 1: 0.50x | E34: 0.5 | I34: =B1075
A35: grid point 2: 0.75x | E35: 0.75 | I35: =B1124
A36: grid point 3: 1.00x | E36: 1 | I36: =B1173 | J36: =B1173-Forecast!B65
A37: grid point 4: 1.25x | E37: 1.25 | I37: =B1222
A38: grid point 5: 1.50x | E38: 1.5 | I38: =B1271
A40: Terminal growth
A41: grid point 1: 3.0% | H41: 0.03 | I41: =B1320
A42: grid point 2: 4.0% | H42: 0.04 | I42: =B1369
A43: grid point 3: 5.0% | H43: 0.05 | I43: =B1418 | J43: =B1418-Forecast!B65
A44: grid point 4: 6.0% | H44: 0.06 | I44: =B1467
A45: grid point 5: 7.0% | H45: 0.07 | I45: =B1516
A47: GATE — every row must return the base case at its own base point
...

Sheet Lenses
A1: Four lenses, one bridge, one valuation date
A2: Lens 2 is on the TRAILING metric so it borrows no discount factor from lens 1. Lens 3 is forward-dated and is therefore DISCOUNTED to the valuation date at the cost of equity, with net cash added at face outside the multiple. Lens 4 uses the same cost-of-equity glide lens 1 uses. All formulas.
A5: Base-year EBITDA | B5: ='Base Year'!B20-'Base Year'!B28-'Base Year'!B29-'Base Year'!B30-'Base Year'!B31+'Base Year'!B32
A6: Enterprise value at spot | B6: =Assumptions!$B$7*Assumptions!$B$8+(Assumptions!$B$82+Assumptions!$B$83-Assumptions!$B$79)/10^6
A7: The company's OWN trailing EV/EBITDA | B7: =B6/B5
A8: Justified multiple = trailing x (1 + re-rating) | B8: =B7*(1+Assumptions!$B$92)
A10: LENS 1 — discounted cash flow | B10: =Forecast!B65
A11: LENS 2 — relative multiples, on the trailing metric | B11: =(B8*B5-(Assumptions!$B$82+Assumptions!$B$83-Assumptions!$B$79)/10^6)*(1-'Base Year'!B41)-(Assumptions!$B$78+Assumptions!$B$77-Assumptions!$B$81-Assumptions!$B$80)/10^6 | C11: =B11/Assumptions!$B$8
A12: LENS 3 — normalised earnings power, DISCOUNTED | B12: =Forecast!E41 | C12: =B12*(1-Assumptions!$B$87)*(1-'Base Year'!B40)*(1-'Base Year'!B41)/Assumptions!$B$8 | D12: =C12*Assumptions!$B$91/(1+Forecast!B10)^2.4+((Assumptions!$B$79-Assumptions!$B$82-Assumptions!$B$83-Assumptions!$B$78-Assumptions!$B$77)/10^6)/Assumptions!$B$8
A13: LENS 4 — book value and sustainable return | B13: =Assumptions!$B$84/10^6/Assumptions!$B$8 | C13: =0.2338665864 | D13: =(Assumptions!$B$90-Assumptions!$B$89)/(C13-Assumptions!$B$89) | E13: =B13*D13
A15: WEIGHTED CENTRAL | B15: =B10*Assumptions!$B$168+C11*Assumptions!$B$169+D12*Assumptions!$B$170+E13*Assumptions!$B$171
A16: against spot | B16: =B15/Assumptions!$B$7-1
A18: The weighted range on the Summary sheet is the bear and bull columns weighted with these same weights. The previous edition labelled a row "weighted central" and then took the minimum and maximum across the four lenses — both of which came from the cash-flow lens alone — so the word "weighted" applied to the centre and not to the ends, and the published spread was about two and a half times too wide.
