Workbook

Sheet READ FIRST
A1: Testahil — Alexandria Mineral Oils Company S.A.E. (EGX: AMOC)
A4: Companion model · Independent valuation study · Educational analysis · Not investment advice
A6: WHAT THIS WORKBOOK IS. A transparent companion to the AMOC valuation study. Blue cells are inputs;
A7: black cells are formulas; green cells link across sheets.
A9: IT CALCULATES — IT DOES NOT STORE. Every figure that can be derived arithmetically from a driver is a
A10: live formula. Change a blue cell on Assumptions and the model reprices: the cost of equity is built from
A11: the risk-free rate net of the sovereign default spread, beta and the equity risk premium; the cost of net
A12: debt is blended from what the borrowing costs and what the cash earns; the glide fractions are derived
A13: from the cost-of-debt path and the discount factors compound; the waterfall chains gross margin to EBITDA
A14: to EBIT to NOPAT to free cash flow to present value; the terminal block chains reinvestment = growth over
A15: return; the statements roll forward; and every ratio and per-share figure on every sheet is a formula.
A16: This claim has been tested, not asserted: see the two gates named at the foot of this sheet.
... A76: HEADLINE FIGURES — ALL LIVE LINKS
A77: Spot price (EGP) | C77: =Assumptions!$C$5
A78: Weighted central fair value (EGP) | C78: =Summary!C10
A79: Implied against spot | C79: =Summary!C12
A80: Discounted cash flow lens (EGP) | C80: ='EV Bridge'!$B$12
A81: Terminal value as a share of enterprise value | C81: =DCF!$B$35
A82: Weighted cost of capital — explicit | C82: =DCF!$B$54
A83: Weighted cost of capital — terminal | C83: =DCF!$B$62
A85: TWO GATES RUN ON THIS DELIVERED FILE, NOT ON THE SCRIPT THAT WROTE IT.
A86: · Cell-level agreement. The builder records the model's own value for every formula cell as it
A87: writes it. An independent evaluator then re-evaluates the workbook and asserts that every formula
A88: cell reproduces that value and that none is left unchecked. A formula that computes the right thing
A89: the wrong way, or points one row off, fails here rather than shipping a different number.
A90: · Driver propagation. Every input is perturbed in place, the whole workbook is re-evaluated, and the
A91: headline is required to move in the asserted direction, with a dead-input sweep over the rest.
A92: The live-driver claim above is only made because this test passes.
A94: THE CENSUS. The exact split of formula cells against pasted numeric cells is counted on the delivered
A95: file and printed by the build, then restated in the study's quality-control gate. Text labels and
A96: headings are counted separately and form no part of the claim in either direction. Every pasted numeric
A97: cell falls into one of the two classes named above; there is no third bucket and no residual category.

Sheet Summary
A1: Testahil — Alexandria Mineral Oils Company S.A.E. (EGX: AMOC)
A2: Summary valuation. Educational analysis, not investment advice. No rating and no price target — a fair-value range and a distribution.
A4: SUMMARY VALUATION TABLE
A5: Lens | B5: Bear (EGP) | C5: Base (EGP) | D5: Bull (EGP) | E5: Weight | F5: Note
A6: Discounted cash flow (primary) | B6: ='Fundamental Valuation'!B5 | C6: ='Fundamental Valuation'!C5 | D6: ='Fundamental Valuation'!D5 | E6: ='Fundamental Valuation'!E5 | F6: terminal value share -> | G6: =DCF!$B$35
A7: Relative multiples | B7: ='Fundamental Valuation'!B6 | C7: ='Fundamental Valuation'!C6 | D7: ='Fundamental Valuation'!D6 | E7: ='Fundamental Valuation'!E6
A8: Normalised earnings power | B8: ='Fundamental Valuation'!B7 | C8: ='Fundamental Valuation'!C7 | D8: ='Fundamental Valuation'!D7 | E8: ='Fundamental Valuation'!E7
A9: Book value and sustainable return | B9: ='Fundamental Valuation'!B8 | C9: ='Fundamental Valuation'!C8 | D9: ='Fundamental Valuation'!D8 | E9: ='Fundamental Valuation'!E8
A10: WEIGHTED CENTRAL FAIR VALUE | B10: =MIN(B6:B9) | C10: =SUM(C6*E6,C7*E7,C8*E8,C9*E9) | D10: =MAX(D6:D9) | E10: =SUM(E6:E9)
A11: Spot price | C11: =Assumptions!$C$5
A12: Implied against spot | C12: =C10/C11-1
A14: THE COMPANY IN NUMBERS
A15: Market capitalisation (EGP mn) | C15: =Assumptions!$C$5*Assumptions!$C$6
A16: Net cash (EGP mn) | C16: =0-DCF!$B$49
A17: Enterprise value (EGP mn) | C17: =C15-C16
A18: Calendar 2025 revenue (EGP mn) | C18: ='Product Lines'!E26
A19: Calendar 2025 profit after tax (EGP mn) | C19: ='Product Lines'!B56
A20: Trailing price / earnings | C20: ='Relative & Normalized'!$B$14
A21: Dividend yield on the declared dividend | C21: =Assumptions!$C$52/Assumptions!$C$5
A22: Weighted central fair value in dollars (USD) | C22: =C10/Assumptions!$C$40
A23: Weighted cost of capital — explicit window | C23: =DCF!$B$54
A24: Weighted cost of capital — terminal | C24: =DCF!$B$62
A25: Terminal growth | C25: =Assumptions!$C$66
A27: Terminal value as a share of enterprise value is shown beside the discounted cash flow lens above and again on the bridge, linked live to the discounted cash flow sheet in both places and typed in neither.

Sheet Fundamental Valuation
A1: Fundamental valuation — four lenses, weighted
A4: Lens | B4: Bear (EGP) | C4: Base (EGP) | D4: Bull (EGP) | E4: Weight | F4: Contribution
A5: Discounted cash flow (primary) | B5: 5.6992127 | C5: ='EV Bridge'!$B$12 | D5: 15.96968 | E5: =Assumptions!$C$99 | F5: =C5*E5
A6: Relative multiples | B6: 7.3142674 | C6: ='Relative & Normalized'!$B$12 | D6: 10.286114 | E6: =Assumptions!$C$100 | F6: =C6*E6
A7: Normalised earnings power | B7: 8.6239928 | C7: ='Relative & Normalized'!$B$24 | D7: 14.895988 | E7: =Assumptions!$C$101 | F7: =C7*E7
A8: Book value and sustainable return | B8: 3.8258438 | C8: ='Relative & Normalized'!$B$32 | D8: 7.9940594 | E8: =Assumptions!$C$102 | F8: =C8*E8
A9: WEIGHTED CENTRAL FAIR VALUE (EGP) | B9: =MIN(B5:B8) | C9: =SUM(F5:F8) | D9: =MAX(D5:D8) | E9: =SUM(E5:E8)
A11: CROSS-CHECKS
A12: Spot price (EGP) | C12: =Assumptions!$C$5
A13: Implied against spot | C13: =C9/C12-1
A14: Terminal value as a share of enterprise value | C14: =DCF!$B$35
A16: THE EXPERT PANEL, LIVE — and why the median is not a check
A17: Expert 1 — earnings power: 2028E attributable earnings per share | B17: ='Relative & Normalized'!$B$22
A18: × Expert 1 justified multiple | B18: =Assumptions!$C$77
A19: = Expert 1 fair value (EGP) | C19: =B17*B18
A20: Expert 2 — free cash flow to equity: present value of the explicit years | B20: 4772.8864
A21: plus the present value of the terminal block | B21: 6492.2099
A22: = Expert 2 fair value (EGP) | C22: =(B20+B21)/Assumptions!$C$6
A23: Expert 3 — economic profit. LINKED, not recomputed: an economic-profit build off the same NOPAT, capital and discount path IS the cash-flow lens | C23: ='EV Bridge'!$B$12
A24: Expert 3 less the cash-flow lens — MUST be zero, and that is the point | C24: =C23-'EV Bridge'!$B$12
A25: Expert panel median (EGP) — NOT an independent check, see note | C25: =MEDIAN(C19,C22,C23)
A26: Spread between the two INDEPENDENT reads (Expert 1 less Expert 2) | C26: =C19-C22
A28: Currency-of-discounting alternative (EGP) | C28: 9.985524
A29: Rating-basis cost of capital alternative (EGP) | C29: 7.7956129
A30: Gross-debt weighting alternative, rejected (EGP) | C30: 9.8758287
A32: Bear and bull columns are whole-model re-runs — each is a complete revaluation at a different set of drivers, so they are values rather than formulas. The base column, the weights, the contributions and the weighted central are all live.

Sheet Assumptions
A1: Assumptions — every blue cell is a live driver
A2: Change one and the model reprices. Values in EGP mn unless stated.
A4: MARKET AND SHARE COUNT
A5: Share price | B5: EGP | C5: 9.1 | D5: EGX close, 6 Aug 2026
A6: Shares outstanding | B6: mn | C6: 1291.56 | D6: reported; payout cross-check
A8: DISCLOSED HISTORY — REVENUE AND PROFIT
A9: FY2022/23 revenue | B9: EGP mn | C9: 22515.65 | D9: cost of sales + gross profit
A10: FY2022/23 gross profit | B10: EGP mn | C10: 1297.01 | D10: disclosed
A11: FY2022/23 cost of sales | B11: EGP mn | C11: 21218.64 | D11: disclosed
A12: FY2022/23 profit after tax | B12: EGP mn | C12: 1320 | D12: consolidated
A13: FY2023/24 revenue — method A | B13: EGP mn | C13: 33770 | D13: prior-year comparative
A14: FY2023/24 revenue — method B | B14: EGP mn | C14: 33303 | D14: back-solved from +10.8%
A15: FY2023/24 profit after tax | B15: EGP mn | C15: 1500 | D15: consolidated
A16: FY2024/25 revenue — method A | B16: EGP mn | C16: 36900 | D16: company release
A17: FY2024/25 revenue — method B | B17: EGP mn | C17: 37620 | D17: aggregator
A18: FY2024/25 revenue — method C | B18: EGP mn | C18: 38000 | D18: same release, revenues line
A19: FY2024/25 profit after tax | B19: EGP mn | C19: 1550 | D19: consolidated
A20: Jul-Dec 2024 revenue | B20: EGP mn | C20: 18246 | D20: disclosed comparative
... A23: Jul-Dec 2025 profit after tax | B23: EGP mn | C23: 656.428 | D23: transition period
A25: VOLUMES AND THE UNIT BUILD
A26: FY2024/25 sales volume | B26: mn tonnes | C26: 1.26 | D26: disclosed
A27: FY2024/25 oils and waxes output | B27: mn tonnes | C27: 0.172 | D27: disclosed, 172kt
A28: Jul-Dec 2025 sales volume | B28: mn tonnes | C28: 0.808 | D28: disclosed, 808kt
A29: Base oils sold, year to Jun-2024 | B29: tonnes | C29: 111256 | D29: disclosed product table
A30: Base oils, sales value | B30: EGP mn | C30: 4454.085 | D30: disclosed
A31: Paraffin wax sold, year to Jun-2024 | B31: tonnes | C31: 65742 | D31: disclosed
A32: Paraffin wax, sales value | B32: EGP mn | C32: 2408.747 | D32: disclosed
A33: Total tonnes, year to Jun-2024 | B33: tonnes | C33: 1433340 | D33: disclosed
A34: Total sales value, year to Jun-2024 | B34: EGP mn | C34: 33312.101 | D34: disclosed
A35: USD/EGP average, year to Jun-2024 | B35: EGP | C35: 36.4 | D35: month-weighted across the float
A36: Specialty tonnage ramp to the base year | B36: % | C36: 0.1 | D36: on the disclosed +40% export rise
A37: Base oils as a share of specialty tonnage | B37: % | C37: 0.62857207 | D37: from the disclosed table
A38: Specialty margin as a multiple of the fuel margin | B38: x | C38: 3.5 | D38: the one judgment parameter behind the margin
A39: USD/EGP average, calendar 2025 | B39: EGP | C39: 48.7
A40: USD/EGP spot | B40: EGP | C40: 50.25 | D40: 6 Aug 2026
A42: BALANCE SHEET — DISCLOSED SNAPSHOT AND DAYS DRIVERS
A43: Total assets | B43: EGP mn | C43: 8136.42 | D43: disclosed
A44: Total liabilities | B44: EGP mn | C44: 3189.56 | D44: disclosed
A45: Cash and equivalents | B45: EGP mn | C45: 2463.52 | D45: disclosed
A46: Gross debt | B46: EGP mn | C46: 25.26 | D46: disclosed
...

Sheet EV Bridge
A1: Enterprise value to equity — the bridge
A2: Net debt is negative on this name, so the cash pile is ADDED rather than subtracted.
B4: EGP mn | C4: per share
A5: Enterprise value (discounted cash flow) | B5: =DCF!$B$36 | C5: =B5/Assumptions!$C$6
A6: Minority share of group profit | B6: =Assumptions!$C$70
A7: less minority interests — ON THE ENTERPRISE VALUE, BEFORE THE CASH | B7: =B5*B6 | C7: =B7/Assumptions!$C$6
A8: Operating assets attributable to shareholders | B8: =B5-B7 | C8: =B8/Assumptions!$C$6
A9: less net debt (negative = net cash added, IN FULL) | B9: =DCF!$B$49 | C9: =B9/Assumptions!$C$6
A10: EQUITY ATTRIBUTABLE TO SHAREHOLDERS | B10: =B8-B9
A11: Shares outstanding (mn) | B11: =Assumptions!$C$6
A12: FAIR VALUE PER SHARE (EGP) | B12: =B10/B11
A13: TERMINAL VALUE AS A SHARE OF ENTERPRISE VALUE | B13: =DCF!$B$35
A14: Spot price (EGP) | B14: =Assumptions!$C$5
A15: Implied against spot | B15: =B12/B14-1
A16: MEMO — what the WRONG order would have given
A17: Minority taken AFTER the cash, on the combined total (the rejected order) | B17: =(B5-B9)*(1-B6) | C17: =B17/Assumptions!$C$6
A18: Value the rejected order would have handed the minority | B18: =B10-B17 | C18: =B18/Assumptions!$C$6
A20: THE ORDER OF THESE ROWS IS THE SUBSTANTIVE POINT. The minority is deducted from the OPERATING enterprise value, before the cash is added, and the cash is then added back in full because it belongs to the parent. An earlier edition of this model did it the other way round — added the cash first, then took the minority share off the combined total — and defended it in a note reading "the minority deduction is taken on the equity value AFTER net debt, so the minority does not carry a share of the parent's cash". That defence was algebraically inverted: deducting a percentage of a total that ALREADY includes the cash is exactly how you hand the minority a slice of it. An external review caught it, the correction is accepted, and the memo rows above compute what the rejected order would have produced so the reader can see the size of it rather than take it on trust. Doubling the minority share to 6% is a separate contested choice, computed on the Fundamental Valuation sheet.

Sheet Product Lines
A1: Revenue and margin built from the disclosed product table
A2: Three lines, each a tonnage times a dollar realisation times an exchange rate. No price is calibrated and none is a residual. The blended gross margin is an OUTPUT of the mix.
A4: THE DISCLOSED PRODUCT TABLE — year to 30 June 2024
B5: Tonnes | C5: Value (EGP mn) | D5: EGP / tonne | E5: USD / tonne | F5: Share of tonnage | G5: Share of value
A6: Base oils | B6: =Assumptions!$C$29 | C6: =Assumptions!$C$30 | D6: =C6*1000000/B6 | E6: =D6/Assumptions!$C$35 | F6: =B6/B9 | G6: =C6/C9
A7: Paraffin wax | B7: =Assumptions!$C$31 | C7: =Assumptions!$C$32 | D7: =C7*1000000/B7 | E7: =D7/Assumptions!$C$35 | F7: =B7/B9 | G7: =C7/C9
A8: Fuel and by-products | B8: =Assumptions!$C$33-B6-B7 | C8: =Assumptions!$C$34-C6-C7 | D8: =C8*1000000/B8 | E8: =D8/Assumptions!$C$35 | F8: =B8/B9 | G8: =C8/C9
A9: Total (disclosed) | B9: =Assumptions!$C$33 | C9: =Assumptions!$C$34
A11: Every realisation on this sheet is DERIVED from the disclosed tonnage and value. The previous build had a specialty price that was a free input and a fuel price that was the residual of the base-year revenue — which meant the "implied fuel price" offered as a plausibility check was a residual of the very construction it was said to validate. Nothing here is a residual.
A12: THE CALENDAR-2025 BASE — volume built the same way as revenue
A13: Jul-Dec 2025 tonnage (disclosed) | B13: =Assumptions!$C$28
A14: Jul-Dec 2024, off the disclosed +14.5% | B14: =B13/1.145
A15: FY2024/25 tonnage (disclosed) | B15: =Assumptions!$C$26
A16: Jan-Jun 2025 (the residual half) | B16: =B15-B14
A17: CALENDAR 2025 TONNAGE | B17: =B16+B13
A18: Specialty tonnage (FY2024/25 disclosed, plus the export ramp) | B18: =Assumptions!$C$27*(1+Assumptions!$C$36)
A20: BASE-YEAR LINES AND THE RECONCILIATION
B21: Tonnes (mn) | C21: USD / tonne | D21: USD/EGP | E21: Revenue (EGP mn)
A22: Base oils | B22: =B18*Assumptions!$C$37 | C22: =E6*(1+Assumptions!$B$88)^1.5 | D22: =Assumptions!$C$39 | E22: =B22*C22*D22
A23: Paraffin wax | B23: =B18*(1-Assumptions!$C$37) | C23: =E7*(1+Assumptions!$B$89)^1.5 | D23: =Assumptions!$C$39 | E23: =B23*C23*D23
A24: Fuel and by-products | B24: =B17-B18 | C24: =E8*(1+Assumptions!$B$90)^1.5 | D24: =Assumptions!$C$39 | E24: =B24*C24*D24
A25: Bottom-up total | E25: =E22+E23+E24
A26: Calendar-2025 revenue from two disclosed halves | E26: =(Assumptions!$C$16+Assumptions!$C$17+Assumptions!$C$18)/3-Assumptions!$C$20+Assumptions!$C$22
A27: RECONCILIATION FACTOR | E27: =E26/E25
A29: Two independent routes to the same base-year revenue, agreeing within the factor shown. The factor is APPLIED to every line and every forecast year and it is on the face of the sheet — a bottom-up build that absorbs its own gap into one residual line is not a bottom-up build.
A30: THE TWO LEG MARGINS, SOLVED FROM ONE DISCLOSED BLEND
A31: Specialty share of base-year revenue | B31: =(E22+E23)/E25
A32: Base-year blended gross margin (disclosed anchor path) | B32: =Assumptions!$E$95
A33: Specialty margin as a multiple of the fuel margin | B33: =Assumptions!$C$38
A34: Fuel and by-product gross margin (solved) | B34: =B32/(B31*B33+1-B31)
A35: Specialty gross margin (solved) | B35: =B33*B34
A36: Check: the two remix to the disclosed blend | B36: =B31*B35+(1-B31)*B34
A38: THE FORECAST
B39: 2026E | C39: 2027E | D39: 2028E | E39: 2029E | F39: 2030E
A40: Base oils — tonnes (mn) | C40: =B22*(1+Assumptions!$B$85) | D40: =C40*(1+Assumptions!$C$85) | E40: =D40*(1+Assumptions!$D$85) | F40: =E40*(1+Assumptions!$E$85) | G40: =F40*(1+Assumptions!$F$85)
A41: Paraffin wax — tonnes (mn) | C41: =B23*(1+Assumptions!$B$86) | D41: =C41*(1+Assumptions!$C$86) | E41: =D41*(1+Assumptions!$D$86) | F41: =E41*(1+Assumptions!$E$86) | G41: =F41*(1+Assumptions!$F$86)
A42: Fuel and by-products — tonnes (mn) | C42: =B24*(1+Assumptions!$B$87) | D42: =C42*(1+Assumptions!$C$87) | E42: =D42*(1+Assumptions!$D$87) | F42: =E42*(1+Assumptions!$E$87) | G42: =F42*(1+Assumptions!$F$87)
A43: Base oils — USD / tonne | C43: =C22*(1+Assumptions!$B$88) | D43: =C43*(1+Assumptions!$C$88) | E43: =D43*(1+Assumptions!$D$88) | F43: =E43*(1+Assumptions!$E$88) | G43: =F43*(1+Assumptions!$F$88)
A44: Paraffin wax — USD / tonne | C44: =C23*(1+Assumptions!$B$89) | D44: =C44*(1+Assumptions!$C$89) | E44: =D44*(1+Assumptions!$D$89) | F44: =E44*(1+Assumptions!$E$89) | G44: =F44*(1+Assumptions!$F$89)
A45: Fuel and by-products — USD / tonne | C45: =C24*(1+Assumptions!$B$90) | D45: =C45*(1+Assumptions!$C$90) | E45: =D45*(1+Assumptions!$D$90) | F45: =E45*(1+Assumptions!$E$90) | G45: =F45*(1+Assumptions!$F$90)
...

Sheet Relative & Normalized
A1: Relative multiples, normalised earnings power and book value
A2: The three cross-check lenses, each built on the sheet.
A4: LENS 2 — RELATIVE MULTIPLES
A5: 2027E EBITDA | B5: =DCF!C9
A6: Justified enterprise value / EBITDA | B6: =Assumptions!$C$72
A7: Enterprise value as at end-2027 | B7: =B5*B6
A8: Year-2 discount factor | B8: =DCF!C19
A9: Enterprise value discounted to today | B9: =B7*B8
A10: add the interim free cash flow the multiple year does not cover | B10: =DCF!B20+DCF!C20
A11: less net debt (net cash added) | B11: =DCF!$B$49
A12: IMPLIED VALUE PER SHARE (EGP) | B12: =(B9+B10)*(1-Assumptions!$C$70)/Assumptions!$C$6-B11/Assumptions!$C$6
A13: Trailing enterprise value / EBITDA (company) | B13: =(Assumptions!$C$5*Assumptions!$C$6+DCF!$B$49)/'Income Statement'!E9
A14: Trailing price / earnings (company) | B14: =Assumptions!$C$5/'Income Statement'!E20
A16: LENS 3 — NORMALISED EARNINGS POWER
A17: 2028E EBITDA | B17: =DCF!D9
A18: less depreciation and amortisation | B18: =DCF!D11
A19: EBIT | B19: =B17-B18
A20: add net finance income | B20: ='Cash Flow'!D16
A21: Attributable normalised earnings | B21: =(B19+B20)*(1-Assumptions!$C$61)*(1-Assumptions!$C$70)
A22: Normalised earnings per share (EGP) | B22: =B21/Assumptions!$C$6
A23: Justified price / earnings | B23: =Assumptions!$C$75
A24: IMPLIED VALUE PER SHARE (EGP) | B24: =B22*B23
A26: LENS 4 — BOOK VALUE AND SUSTAINABLE RETURN
A27: Attributable book value per share (EGP) | B27: ='Balance Sheet'!E20/Assumptions!$C$6
A28: Sustainable return on equity | B28: =Assumptions!$C$76
A29: Perpetual cost of equity | B29: =DCF!$B$59
A30: Terminal growth | B30: =Assumptions!$C$66
A31: Justified price / book | B31: =(B28-B30)/(B29-B30)
A32: IMPLIED VALUE PER SHARE (EGP) | B32: =B31*B27
A33: Trailing return on average attributable equity | B33: ='Income Statement'!E19/(('Balance Sheet'!D20+'Balance Sheet'!E20)/2)
A35: The relative lens discounts a FORWARD enterprise value back to today; a multiple applied to a future year produces a value as at that year, not now. The book lens uses the PERPETUAL cost of equity inside the perpetuity identity, because a blended rate inside a perpetuity formula is internally inconsistent.

Sheet DCF
A1: Discounted cash flow — the primary lens
A2: Cost of capital built in the sheet; glide inherited from the cost-of-debt path; waterfall chained to the present value of free cash flow to the firm.
A4: Free cash flow to the firm (EGP mn) | B4: 2026E | C4: 2027E | D4: 2028E | E4: 2029E | F4: 2030E
A5: Revenue | B5: ='Product Lines'!$C$50 | C5: ='Product Lines'!$D$50 | D5: ='Product Lines'!$E$50 | E5: ='Product Lines'!$F$50 | F5: ='Product Lines'!$G$50
A6: Gross margin (from the product-line mix) | B6: ='Product Lines'!$C$53 | C6: ='Product Lines'!$D$53 | D6: ='Product Lines'!$E$53 | E6: ='Product Lines'!$F$53 | F6: ='Product Lines'!$G$53
A7: Gross profit | B7: ='Product Lines'!$C$52 | C7: ='Product Lines'!$D$52 | D7: ='Product Lines'!$E$52 | E7: ='Product Lines'!$F$52 | F7: ='Product Lines'!$G$52
A8: less operating cost load | B8: =B5*Assumptions!$B$84 | C8: =C5*Assumptions!$C$84 | D8: =D5*Assumptions!$D$84 | E8: =E5*Assumptions!$E$84 | F8: =F5*Assumptions!$F$84
A9: EBITDA | B9: =B7-B8 | C9: =C7-C8 | D9: =D7-D8 | E9: =E7-E8 | F9: =F7-F8
A10: EBITDA margin | B10: =B9/B5 | C10: =C9/C5 | D10: =D9/D5 | E10: =E9/E5 | F10: =F9/F5
A11: less depreciation and amortisation | B11: =B5*Assumptions!$C$69 | C11: =C5*Assumptions!$C$69 | D11: =D5*Assumptions!$C$69 | E11: =E5*Assumptions!$C$69 | F11: =F5*Assumptions!$C$69
A12: EBIT | B12: =B9-B11 | C12: =C9-C11 | D12: =D9-D11 | E12: =E9-E11 | F12: =F9-F11
A13: NOPAT = EBIT x (1 - tax) | B13: =B12*(1-Assumptions!$C$61) | C13: =C12*(1-Assumptions!$C$61) | D13: =D12*(1-Assumptions!$C$61) | E13: =E12*(1-Assumptions!$C$61) | F13: =F12*(1-Assumptions!$C$61)
A14: add back depreciation and amortisation | B14: =B11 | C14: =C11 | D14: =D11 | E14: =E11 | F14: =F11
A15: less capital expenditure | B15: =B5*Assumptions!$B$83 | C15: =C5*Assumptions!$C$83 | D15: =D5*Assumptions!$D$83 | E15: =E5*Assumptions!$E$83 | F15: =F5*Assumptions!$F$83
A16: Net working capital | B16: =B5*'Balance Sheet'!$E$26 | C16: =C5*'Balance Sheet'!$E$26 | D16: =D5*'Balance Sheet'!$E$26 | E16: =E5*'Balance Sheet'!$E$26 | F16: =F5*'Balance Sheet'!$E$26
A17: less change in net working capital | B17: =B16-'Balance Sheet'!$E$25 | C17: =C16-B16 | D17: =D16-C16 | E17: =E16-D16 | F17: =F16-E16
A18: FREE CASH FLOW TO THE FIRM | B18: =B13+B11-B15-B17 | C18: =C13+C11-C15-C17 | D18: =D13+D11-D15-D17 | E18: =E13+E11-E15-E17 | F18: =F13+F11-F15-F17
A19: Discount factor | B19: =B69 | C19: =C69 | D19: =D69 | E19: =E69 | F19: =F69
A20: PRESENT VALUE OF FREE CASH FLOW | B20: =B18*B19 | C20: =C18*C19 | D20: =D18*D19 | E20: =E18*E19 | F20: =F18*F19
A22: INVESTED CAPITAL AND THE TERMINAL BLOCK
A23: Property, plant and equipment (roll-forward) | B23: ='Balance Sheet'!$E$9+B15-B11 | C23: =B23+C15-C11 | D23: =C23+D15-D11 | E23: =D23+E15-E11 | F23: =E23+F15-F11
A24: Invested capital | B24: =B16+B23 | C24: =C16+C23 | D24: =D16+D23 | E24: =E16+E23 | F24: =F16+F23
A25: Return on invested capital | B25: =B13/B24 | C25: =C13/C24 | D25: =D13/D24 | E25: =E13/E24 | F25: =F13/F24
A26: Terminal growth | B26: =Assumptions!$C$66
A27: Terminal return on invested capital | B27: =F13*(1+B26)/F24
A28: Required reinvestment rate = g / return | B28: =B26/B27
A29: Terminal NOPAT | B29: =F13*(1+B26)
A30: TERMINAL VALUE | B30: =B29*(1-B28)/(B62-B26)
A32: ENTERPRISE VALUE
A33: Present value of the explicit window | B33: =SUM(B20:F20)
A34: Present value of the terminal value | B34: =B30*F19
A35: Terminal value as a share of enterprise value | B35: =B34/(B33+B34)
A36: ENTERPRISE VALUE | B36: =B33+B34
A37: Fair value per share (from the bridge) | B37: ='EV Bridge'!$B$12
A39: One date, one price of time: the terminal value is capitalised at the terminal cost of capital and discounted at the SAME year-5 cumulative factor as year 5 cash flow. Discounting a terminal value at a lower rate than the cash flow arriving on the same day is the commonest way a target price is manufactured, and it is not done here.
A40: COST OF CAPITAL — EXPLICIT WINDOW
A41: Risk-free rate (Egypt 10-year) | B41: =Assumptions!$C$55
A42: less sovereign default spread | B42: =Assumptions!$C$56
A43: Risk-free net of sovereign risk | B43: =B41-B42
A44: Beta | B44: =Assumptions!$C$58
...

Sheet Income Statement
A1: Income statement — four historical periods and five forecast years
A2: Historical periods are the reported June financial years plus the constructed calendar-2025 base; the forecast runs on calendar years after the year-end change.
A4: EGP mn | B4: FY2022/23 | C4: FY2023/24 | D4: FY2024/25 | E4: CY2025 | F4: 2026E | G4: 2027E | H4: 2028E | I4: 2029E | J4: 2030E
A5: Revenue | B5: =Assumptions!$C$9 | C5: =(Assumptions!$C$13+Assumptions!$C$14)/2 | D5: =(Assumptions!$C$16+Assumptions!$C$17+Assumptions!$C$18)/3 | E5: ='Product Lines'!E26 | F5: =DCF!B5 | G5: =DCF!C5 | H5: =DCF!D5 | I5: =DCF!E5 | J5: =DCF!F5
A6: Gross margin | B6: =Assumptions!$B$95 | C6: =Assumptions!$C$95 | D6: =Assumptions!$D$95 | E6: =Assumptions!$E$95 | F6: =DCF!B6 | G6: =DCF!C6 | H6: =DCF!D6 | I6: =DCF!E6 | J6: =DCF!F6
A7: Gross profit | B7: =B5*B6 | C7: =C5*C6 | D7: =D5*D6 | E7: =E5*E6 | F7: =F5*F6 | G7: =G5*G6 | H7: =H5*H6 | I7: =I5*I6 | J7: =J5*J6
A8: Operating cost load | B8: =B5*Assumptions!$C$51 | C8: =C5*Assumptions!$C$51 | D8: =D5*Assumptions!$C$51 | E8: =E5*Assumptions!$C$51 | F8: =DCF!B8 | G8: =DCF!C8 | H8: =DCF!D8 | I8: =DCF!E8 | J8: =DCF!F8
A9: EBITDA | B9: =B7-B8 | C9: =C7-C8 | D9: =D7-D8 | E9: =E7-E8 | F9: =F7-F8 | G9: =G7-G8 | H9: =H7-H8 | I9: =I7-I8 | J9: =J7-J8
A10: EBITDA margin | B10: =B9/B5 | C10: =C9/C5 | D10: =D9/D5 | E10: =E9/E5 | F10: =F9/F5 | G10: =G9/G5 | H10: =H9/H5 | I10: =I9/I5 | J10: =J9/J5
A11: Depreciation and amortisation | B11: =B5*Assumptions!$C$69 | C11: =C5*Assumptions!$C$69 | D11: =D5*Assumptions!$C$69 | E11: =E5*Assumptions!$C$69 | F11: =DCF!B11 | G11: =DCF!C11 | H11: =DCF!D11 | I11: =DCF!E11 | J11: =DCF!F11
A12: EBIT | B12: =B9-B11 | C12: =C9-C11 | D12: =D9-D11 | E12: =E9-E11 | F12: =F9-F11 | G12: =G9-G11 | H12: =H9-H11 | I12: =I9-I11 | J12: =J9-J11
A13: Net finance income | B13: =$E$13*B5/$E$5*0.85 | C13: =$E$13*C5/$E$5*0.85 | D13: =$E$13*D5/$E$5*0.85 | E13: =Assumptions!$C$60*Assumptions!$C$45-Assumptions!$C$59*Assumptions!$C$46 | F13: ='Cash Flow'!B16 | G13: ='Cash Flow'!C16 | H13: ='Cash Flow'!D16 | I13: ='Cash Flow'!E16 | J13: ='Cash Flow'!F16
A14: Profit after tax (disclosed for history) | B14: =Assumptions!$C$12 | C14: =Assumptions!$C$15 | D14: =Assumptions!$C$19 | E14: ='Product Lines'!B56 | F14: =(F12+F13)*(1-Assumptions!$C$61) | G14: =(G12+G13)*(1-Assumptions!$C$61) | H14: =(H12+H13)*(1-Assumptions!$C$61) | I14: =(I12+I13)*(1-Assumptions!$C$61) | J14: =(J12+J13)*(1-Assumptions!$C$61)
A15: Profit before tax | B15: =B14/(1-Assumptions!$C$61) | C15: =C14/(1-Assumptions!$C$61) | D15: =D14/(1-Assumptions!$C$61) | E15: =E14/(1-Assumptions!$C$61) | F15: =F14/(1-Assumptions!$C$61) | G15: =G14/(1-Assumptions!$C$61) | H15: =H14/(1-Assumptions!$C$61) | I15: =I14/(1-Assumptions!$C$61) | J15: =J14/(1-Assumptions!$C$61)
A16: Other and non-operating income | B16: =B15-B12-B13 | C16: =C15-C12-C13 | D16: =D15-D12-D13 | E16: =E15-E12-E13 | F16: =F15-F12-F13 | G16: =G15-G12-G13 | H16: =H15-H12-H13 | I16: =I15-I12-I13 | J16: =J15-J12-J13
A17: Tax | B17: =B14-B15 | C17: =C14-C15 | D17: =D14-D15 | E17: =E14-E15 | F17: =F14-F15 | G17: =G14-G15 | H17: =H14-H15 | I17: =I14-I15 | J17: =J14-J15
A18: Minority interests | B18: =B14*Assumptions!$C$70 | C18: =C14*Assumptions!$C$70 | D18: =D14*Assumptions!$C$70 | E18: =E14*Assumptions!$C$70 | F18: =F14*Assumptions!$C$70 | G18: =G14*Assumptions!$C$70 | H18: =H14*Assumptions!$C$70 | I18: =I14*Assumptions!$C$70 | J18: =J14*Assumptions!$C$70
A19: PROFIT ATTRIBUTABLE TO SHAREHOLDERS | B19: =B14-B18 | C19: =C14-C18 | D19: =D14-D18 | E19: =E14-E18 | F19: =F14-F18 | G19: =G14-G18 | H19: =H14-H18 | I19: =I14-I18 | J19: =J14-J18
A20: Earnings per share (EGP) | B20: =B19/Assumptions!$C$6 | C20: =C19/Assumptions!$C$6 | D20: =D19/Assumptions!$C$6 | E20: =E19/Assumptions!$C$6 | F20: =F19/Assumptions!$C$6 | G20: =G19/Assumptions!$C$6 | H20: =H19/Assumptions!$C$6 | I20: =I19/Assumptions!$C$6 | J20: =J19/Assumptions!$C$6
A22: Only the historical PROFIT AFTER TAX is a pasted value — it is the disclosed figure. Every other line in every column is a formula. Note the OTHER INCOME line: it is the residual between disclosed profit and the operating result, and it is large in the devaluation years and small now. The forecast carries NONE of it, which is why forecast attributable profit is not a simple extrapolation of the reported record.

Sheet Balance Sheet
A1: Balance sheet — four historical periods and five forecast years
A2: History rolled back from the disclosed snapshot through disclosed profit and dividends; the forecast rolls forward off the waterfall.
A4: EGP mn | B4: FY2022/23 | C4: FY2023/24 | D4: FY2024/25 | E4: CY2025 | F4: 2026E | G4: 2027E | H4: 2028E | I4: 2029E | J4: 2030E
A5: Revenue (memo) | B5: ='Income Statement'!B5 | C5: ='Income Statement'!C5 | D5: ='Income Statement'!D5 | E5: ='Income Statement'!E5 | F5: =DCF!B5 | G5: =DCF!C5 | H5: =DCF!D5 | I5: =DCF!E5 | J5: =DCF!F5
A6: Cost of sales (memo) | B6: ='Income Statement'!B5-'Income Statement'!B7 | C6: ='Income Statement'!C5-'Income Statement'!C7 | D6: ='Income Statement'!D5-'Income Statement'!D7 | E6: ='Income Statement'!E5-'Income Statement'!E7 | F6: =DCF!B5-DCF!B7 | G6: =DCF!C5-DCF!C7 | H6: =DCF!D5-DCF!D7 | I6: =DCF!E5-DCF!E7 | J6: =DCF!F5-DCF!F7
A8: ASSETS
A9: Property, plant and equipment | B9: =$E$9*(B5/$E$5)^0.5 | C9: =$E$9*(C5/$E$5)^0.5 | D9: =$E$9*(D5/$E$5)^0.5 | E9: =Assumptions!$C$43-Assumptions!$C$45-E10-E11-Assumptions!$C$50 | F9: =DCF!B23 | G9: =DCF!C23 | H9: =DCF!D23 | I9: =DCF!E23 | J9: =DCF!F23
A10: Inventories | B10: =B6*Assumptions!$C$48/365 | C10: =C6*Assumptions!$C$48/365 | D10: =D6*Assumptions!$C$48/365 | E10: =E6*Assumptions!$C$48/365 | F10: =F6*Assumptions!$C$48/365 | G10: =G6*Assumptions!$C$48/365 | H10: =H6*Assumptions!$C$48/365 | I10: =I6*Assumptions!$C$48/365 | J10: =J6*Assumptions!$C$48/365
A11: Trade receivables | B11: =B5*Assumptions!$C$47/365 | C11: =C5*Assumptions!$C$47/365 | D11: =D5*Assumptions!$C$47/365 | E11: =E5*Assumptions!$C$47/365 | F11: =F5*Assumptions!$C$47/365 | G11: =G5*Assumptions!$C$47/365 | H11: =H5*Assumptions!$C$47/365 | I11: =I5*Assumptions!$C$47/365 | J11: =J5*Assumptions!$C$47/365
A12: Other current assets | B12: =Assumptions!$C$50 | C12: =Assumptions!$C$50 | D12: =Assumptions!$C$50 | E12: =Assumptions!$C$50 | F12: =Assumptions!$C$50 | G12: =Assumptions!$C$50 | H12: =Assumptions!$C$50 | I12: =Assumptions!$C$50 | J12: =Assumptions!$C$50
A13: Cash and equivalents | B13: =B20+B21+B17+B19+Assumptions!$C$46-B9-B10-B11-Assumptions!$C$50 | C13: =C20+C21+C17+C19+Assumptions!$C$46-C9-C10-C11-Assumptions!$C$50 | D13: =D20+D21+D17+D19+Assumptions!$C$46-D9-D10-D11-Assumptions!$C$50 | E13: =Assumptions!$C$45 | F13: =Assumptions!$C$46-'Cash Flow'!B$22 | G13: =Assumptions!$C$46-'Cash Flow'!C$22 | H13: =Assumptions!$C$46-'Cash Flow'!D$22 | I13: =Assumptions!$C$46-'Cash Flow'!E$22 | J13: =Assumptions!$C$46-'Cash Flow'!F$22
A14: TOTAL ASSETS | B14: =B9+B10+B11+B12+B13 | C14: =C9+C10+C11+C12+C13 | D14: =D9+D10+D11+D12+D13 | E14: =E9+E10+E11+E12+E13 | F14: =F9+F10+F11+F12+F13 | G14: =G9+G10+G11+G12+G13 | H14: =H9+H10+H11+H12+H13 | I14: =I9+I10+I11+I12+I13 | J14: =J9+J10+J11+J12+J13
A16: LIABILITIES AND EQUITY
A17: Trade payables | B17: =B6*Assumptions!$C$49/365 | C17: =C6*Assumptions!$C$49/365 | D17: =D6*Assumptions!$C$49/365 | E17: =E6*Assumptions!$C$49/365 | F17: =F6*Assumptions!$C$49/365 | G17: =G6*Assumptions!$C$49/365 | H17: =H6*Assumptions!$C$49/365 | I17: =I6*Assumptions!$C$49/365 | J17: =J6*Assumptions!$C$49/365
A18: Gross debt | B18: =Assumptions!$C$46 | C18: =Assumptions!$C$46 | D18: =Assumptions!$C$46 | E18: =Assumptions!$C$46 | F18: =Assumptions!$C$46 | G18: =Assumptions!$C$46 | H18: =Assumptions!$C$46 | I18: =Assumptions!$C$46 | J18: =Assumptions!$C$46
A19: Other liabilities, provisions and tax | B19: =$E$19*B5/$E$5 | C19: =$E$19*C5/$E$5 | D19: =$E$19*D5/$E$5 | E19: =Assumptions!$C$44-Assumptions!$C$46-E17 | F19: =F5/E5*E19 | G19: =G5/E5*E19 | H19: =H5/E5*E19 | I19: =I5/E5*E19 | J19: =J5/E5*E19
A20: Shareholders equity (attributable) | B20: =C20/(1-Assumptions!$C$70)-Assumptions!$C$15+Assumptions!$C$52*Assumptions!$C$6-(C20/(1-Assumptions!$C$70)-Assumptions!$C$15+Assumptions!$C$52*Assumptions!$C$6)*Assumptions!$C$70 | C20: =D20/(1-Assumptions!$C$70)-Assumptions!$C$19+Assumptions!$C$52*Assumptions!$C$6-(D20/(1-Assumptions!$C$70)-Assumptions!$C$19+Assumptions!$C$52*Assumptions!$C$6)*Assumptions!$C$70 | D20: =E20/(1-Assumptions!$C$70)-Assumptions!$C$23+0.5*Assumptions!$C$52*Assumptions!$C$6-(E20/(1-Assumptions!$C$70)-Assumptions!$C$23+0.5*Assumptions!$C$52*Assumptions!$C$6)*Assumptions!$C$70 | E20: =(Assumptions!$C$43-Assumptions!$C$44)*(1-Assumptions!$C$70) | F20: ='Cash Flow'!B$25 | G20: ='Cash Flow'!C$25 | H20: ='Cash Flow'!D$25 | I20: ='Cash Flow'!E$25 | J20: ='Cash Flow'!F$25
A21: Minority interests | B21: =B20/(1-Assumptions!$C$70)*Assumptions!$C$70 | C21: =C20/(1-Assumptions!$C$70)*Assumptions!$C$70 | D21: =D20/(1-Assumptions!$C$70)*Assumptions!$C$70 | E21: =E20/(1-Assumptions!$C$70)*Assumptions!$C$70 | F21: =F20/(1-Assumptions!$C$70)*Assumptions!$C$70 | G21: =G20/(1-Assumptions!$C$70)*Assumptions!$C$70 | H21: =H20/(1-Assumptions!$C$70)*Assumptions!$C$70 | I21: =I20/(1-Assumptions!$C$70)*Assumptions!$C$70 | J21: =J20/(1-Assumptions!$C$70)*Assumptions!$C$70
A22: TOTAL LIABILITIES AND EQUITY | B22: =B17+B18+B19+B20+B21 | C22: =C17+C18+C19+C20+C21 | D22: =D17+D18+D19+D20+D21 | E22: =E17+E18+E19+E20+E21 | F22: =F17+F18+F19+F20+F21 | G22: =G17+G18+G19+G20+G21 | H22: =H17+H18+H19+H20+H21 | I22: =I17+I18+I19+I20+I21 | J22: =J17+J18+J19+J20+J21
A24: DERIVED
A25: Net working capital | B25: =B10+B11+B12-B17 | C25: =C10+C11+C12-C17 | D25: =D10+D11+D12-D17 | E25: =E10+E11+E12-E17 | F25: =DCF!B16 | G25: =DCF!C16 | H25: =DCF!D16 | I25: =DCF!E16 | J25: =DCF!F16
A26: Net working capital, % of revenue | B26: =B25/B5 | C26: =C25/C5 | D26: =D25/D5 | E26: =E25/E5 | F26: =F25/F5 | G26: =G25/G5 | H26: =H25/H5 | I26: =I25/I5 | J26: =J25/J5
A27: Net debt (negative = net cash) | B27: =B18-B13 | C27: =C18-C13 | D27: =D18-D13 | E27: =E18-E13 | F27: =F18-F13 | G27: =G18-G13 | H27: =H18-H13 | I27: =I18-I13 | J27: =J18-J13
A28: Net cash per share (EGP) | B28: =-B27/Assumptions!$C$6 | C28: =-C27/Assumptions!$C$6 | D28: =-D27/Assumptions!$C$6 | E28: =-E27/Assumptions!$C$6 | F28: =-F27/Assumptions!$C$6 | G28: =-G27/Assumptions!$C$6 | H28: =-H27/Assumptions!$C$6 | I28: =-I27/Assumptions!$C$6 | J28: =-J27/Assumptions!$C$6
A29: Balance check (assets less liabilities and equity) | B29: =B14-B22 | C29: =C14-C22 | D29: =D14-D22 | E29: =E14-E22
A31: The historical balance sheets are a reconstruction, and the workbook says so: only total assets, total liabilities, cash and gross debt are disclosed at one date. Everything else is built from days drivers and a roll-back through disclosed profit and dividends. The reconstruction is checked two ways — implied remaining asset life, and share capital plus disclosed reserves against total equity.

Sheet Cash Flow
A1: Cash flow — linked to the waterfall, not restated
A2: Every line points at the discounted cash flow sheet or at the roll-forward, so the two cannot drift apart.
A4: EGP mn | B4: 2026E | C4: 2027E | D4: 2028E | E4: 2029E | F4: 2030E
A5: EBITDA | B5: =DCF!B9 | C5: =DCF!C9 | D5: =DCF!D9 | E5: =DCF!E9 | F5: =DCF!F9
A6: less depreciation and amortisation | B6: =DCF!B11 | C6: =DCF!C11 | D6: =DCF!D11 | E6: =DCF!E11 | F6: =DCF!F11
A7: EBIT | B7: =B5-B6 | C7: =C5-C6 | D7: =D5-D6 | E7: =E5-E6 | F7: =F5-F6
A8: Cash tax on EBIT | B8: =B7*Assumptions!$C$61 | C8: =C7*Assumptions!$C$61 | D8: =D7*Assumptions!$C$61 | E8: =E7*Assumptions!$C$61 | F8: =F7*Assumptions!$C$61
A9: NOPAT | B9: =B7-B8 | C9: =C7-C8 | D9: =D7-D8 | E9: =E7-E8 | F9: =F7-F8
A10: add back depreciation and amortisation | B10: =DCF!B11 | C10: =DCF!C11 | D10: =DCF!D11 | E10: =DCF!E11 | F10: =DCF!F11
A11: less change in net working capital | B11: =DCF!B17 | C11: =DCF!C17 | D11: =DCF!D17 | E11: =DCF!E17 | F11: =DCF!F17
A12: OPERATING CASH FLOW | B12: =B9+B10-B11 | C12: =C9+C10-C11 | D12: =D9+D10-D11 | E12: =E9+E10-E11 | F12: =F9+F10-F11
A13: less capital expenditure | B13: =DCF!B15 | C13: =DCF!C15 | D13: =DCF!D15 | E13: =DCF!E15 | F13: =DCF!F15
A14: FREE CASH FLOW TO THE FIRM | B14: =B12-B13 | C14: =C12-C13 | D14: =D12-D13 | E14: =E12-E13 | F14: =F12-F13
A15: Opening cash (gross debt less opening net debt) | B15: =MAX(Assumptions!$C$46-B$21,0) | C15: =MAX(Assumptions!$C$46-C$21,0) | D15: =MAX(Assumptions!$C$46-D$21,0) | E15: =MAX(Assumptions!$C$46-E$21,0) | F15: =MAX(Assumptions!$C$46-F$21,0)
A16: Net finance income | B16: =Assumptions!$B$91*B15-Assumptions!$B$81*Assumptions!$C$46 | C16: =Assumptions!$C$91*C15-Assumptions!$C$81*Assumptions!$C$46 | D16: =Assumptions!$D$91*D15-Assumptions!$D$81*Assumptions!$C$46 | E16: =Assumptions!$E$91*E15-Assumptions!$E$81*Assumptions!$C$46 | F16: =Assumptions!$F$91*F15-Assumptions!$F$81*Assumptions!$C$46
A17: Attributable profit | B17: =(B7+B16)*(1-Assumptions!$C$61)*(1-Assumptions!$C$70) | C17: =(C7+C16)*(1-Assumptions!$C$61)*(1-Assumptions!$C$70) | D17: =(D7+D16)*(1-Assumptions!$C$61)*(1-Assumptions!$C$70) | E17: =(E7+E16)*(1-Assumptions!$C$61)*(1-Assumptions!$C$70) | F17: =(F7+F16)*(1-Assumptions!$C$61)*(1-Assumptions!$C$70)
A18: Dividends paid | B18: =Assumptions!$C$71*B17 | C18: =Assumptions!$C$71*C17 | D18: =Assumptions!$C$71*D17 | E18: =Assumptions!$C$71*E17 | F18: =Assumptions!$C$71*F17
A20: NET CASH ROLL-FORWARD
A21: Opening net debt | B21: ='Balance Sheet'!$E$27 | C21: =B$22 | D21: =C$22 | E21: =D$22 | F21: =E$22
A22: Closing net debt | B22: =B21-(B14+B16*(1-Assumptions!$C$61))+B18 | C22: =C21-(C14+C16*(1-Assumptions!$C$61))+C18 | D22: =D21-(D14+D16*(1-Assumptions!$C$61))+D18 | E22: =E21-(E14+E16*(1-Assumptions!$C$61))+E18 | F22: =F21-(F14+F16*(1-Assumptions!$C$61))+F18
A23: Closing net cash | B23: =-B22 | C23: =-C22 | D23: =-D22 | E23: =-E22 | F23: =-F22
A24: Opening attributable equity | B24: ='Balance Sheet'!$E$20 | C24: =B$25 | D24: =C$25 | E24: =D$25 | F24: =E$25
A25: Closing attributable equity | B25: =B24+B17-B18 | C25: =C24+C17-C18 | D25: =D24+D17-D18 | E25: =E24+E17-E18 | F25: =F24+F17-F18
A27: The net-cash roll-forward closes: opening net debt less free cash flow, less the after-tax finance income the cash itself earns, plus dividends paid, equals closing net debt. It is one roll-forward, computed once here and consumed by the balance sheet, the ratios and the equity-side expert method.

Sheet Summary Financials
A1: Summary financials — the lines a reader checks first
A4: EGP mn | B4: FY2022/23 | C4: FY2023/24 | D4: FY2024/25 | E4: CY2025 | F4: 2026E | G4: 2027E | H4: 2028E | I4: 2029E | J4: 2030E
A5: Revenue | B5: ='Income Statement'!B5 | C5: ='Income Statement'!C5 | D5: ='Income Statement'!D5 | E5: ='Income Statement'!E5 | F5: ='Income Statement'!F5 | G5: ='Income Statement'!G5 | H5: ='Income Statement'!H5 | I5: ='Income Statement'!I5 | J5: ='Income Statement'!J5
A6: EBITDA | B6: ='Income Statement'!B9 | C6: ='Income Statement'!C9 | D6: ='Income Statement'!D9 | E6: ='Income Statement'!E9 | F6: ='Income Statement'!F9 | G6: ='Income Statement'!G9 | H6: ='Income Statement'!H9 | I6: ='Income Statement'!I9 | J6: ='Income Statement'!J9
A7: EBIT | B7: ='Income Statement'!B12 | C7: ='Income Statement'!C12 | D7: ='Income Statement'!D12 | E7: ='Income Statement'!E12 | F7: ='Income Statement'!F12 | G7: ='Income Statement'!G12 | H7: ='Income Statement'!H12 | I7: ='Income Statement'!I12 | J7: ='Income Statement'!J12
A8: Attributable profit | B8: ='Income Statement'!B19 | C8: ='Income Statement'!C19 | D8: ='Income Statement'!D19 | E8: ='Income Statement'!E19 | F8: ='Income Statement'!F19 | G8: ='Income Statement'!G19 | H8: ='Income Statement'!H19 | I8: ='Income Statement'!I19 | J8: ='Income Statement'!J19
A9: Total assets | B9: ='Balance Sheet'!B14 | C9: ='Balance Sheet'!C14 | D9: ='Balance Sheet'!D14 | E9: ='Balance Sheet'!E14 | F9: ='Balance Sheet'!F14 | G9: ='Balance Sheet'!G14 | H9: ='Balance Sheet'!H14 | I9: ='Balance Sheet'!I14 | J9: ='Balance Sheet'!J14
A10: Shareholders equity | B10: ='Balance Sheet'!B20 | C10: ='Balance Sheet'!C20 | D10: ='Balance Sheet'!D20 | E10: ='Balance Sheet'!E20 | F10: ='Balance Sheet'!F20 | G10: ='Balance Sheet'!G20 | H10: ='Balance Sheet'!H20 | I10: ='Balance Sheet'!I20 | J10: ='Balance Sheet'!J20
A11: Net cash | B11: =0-'Balance Sheet'!B27 | C11: =0-'Balance Sheet'!C27 | D11: =0-'Balance Sheet'!D27 | E11: =0-'Balance Sheet'!E27 | F11: =0-'Balance Sheet'!F27 | G11: =0-'Balance Sheet'!G27 | H11: =0-'Balance Sheet'!H27 | I11: =0-'Balance Sheet'!I27 | J11: =0-'Balance Sheet'!J27
A13: Invested capital | F13: =DCF!B24 | G13: =DCF!C24 | H13: =DCF!D24 | I13: =DCF!E24 | J13: =DCF!F24
A14: Return on invested capital | F14: =DCF!B13/DCF!B24 | G14: =DCF!C13/DCF!C24 | H14: =DCF!D13/DCF!D24 | I14: =DCF!E13/DCF!E24 | J14: =DCF!F13/DCF!F24
A15: Free cash flow to the firm | F15: =DCF!B18 | G15: =DCF!C18 | H15: =DCF!D18 | I15: =DCF!E18 | J15: =DCF!F18

Sheet Monte Carlo
A1: Forward price distribution — engine output
A2: PASTED VALUES. Each percentile is the output of a 50,000-path simulation and is not recomputed by this workbook. Changing a driver does NOT redraw this sheet.
B4: 1 month | C4: 3 months
A5: Sessions to the check date | B5: 20 | C5: 62
A6: Target date | B6: 2026-09-06 | C6: 2026-11-06
A7: Grade date | B7: 2026-09-06 | C7: 2026-11-08
A8: 5th percentile (EGP) | B8: 7.7095612 | C8: 6.9017095
A9: 25th percentile (EGP) | B9: 8.598973 | C9: 8.3442309
A10: 50th percentile (EGP) | B10: 9.1709726 | C10: 9.3294301
A11: 75th percentile (EGP) | B11: 9.785587 | C11: 10.41935
A12: 95th percentile (EGP) | B12: 10.913622 | C12: 12.604538
A13: Probability above spot | B13: 0.53284 | C13: 0.56048
A14: Probability 10% or more up | B14: 0.18262 | C14: 0.3318
A15: Probability 10% or more down | B15: 0.12658 | C15: 0.21574
A16: Probability of touching +10% | B16: 0.2999 | C16: 0.56412
A17: Probability of touching -10% | B17: 0.21706 | C17: 0.42922
A18: Annualised volatility at the anchor | B18: 0.41799078 | C18: 0.40852251
A20: CALIBRATION OF THE ENGINE THAT PRODUCED THIS
A21: Windows scored (post-break) | B21: 17
A22: First origin | B22: 2022-04-05
A23: Last origin | B23: 2026-04-12
A24: Skill against a carry-anchored random walk | B24: 0.0067589847
A25: Verdict | B25: PARITY
A26: Coverage of the 90% band | B26: 0.94117647
A27: Probability-integral-transform mean | B27: 0.4612
A28: Cone width against the benchmark | B28: 0.96938093
A29: Market panel verdict | B29: PASS
A30: Market panel skill | B30: 0.0158

Sheet Sensitivity
A1: Sensitivity — the cost-of-capital grids are LIVE formulas
A2: Each cell re-runs the discount path, the terminal block and the bridge off this sheet. Only the sweeps that change REVENUE are pasted, because those need the product build re-run and cannot be a formula in a grid.
A4: GRID 1 — TERMINAL COST OF CAPITAL x TERMINAL GROWTH (EGP per share, LIVE)
A5: row: terminal rate · helper columns C:G are that row's discount factors
A6: Terminal WACC | B6: PV explicit | C6: df1 | D6: df2 | E6: df3 | F6: df4 | G6: df5
A7: 0.1452265 | B7: =DCF!B$18*C7+DCF!C$18*D7+DCF!D$18*E7+DCF!E$18*F7+DCF!F$18*G7 | C7: =1/(1+(DCF!$B$54-(DCF!$B$54-$A$7)*DCF!B$67)) | D7: =C7/(1+(DCF!$B$54-(DCF!$B$54-$A$7)*DCF!C$67)) | E7: =D7/(1+(DCF!$B$54-(DCF!$B$54-$A$7)*DCF!D$67)) | F7: =E7/(1+(DCF!$B$54-(DCF!$B$54-$A$7)*DCF!E$67)) | G7: =F7/(1+(DCF!$B$54-(DCF!$B$54-$A$7)*DCF!F$67))
A8: 0.1552265 | B8: =DCF!B$18*C8+DCF!C$18*D8+DCF!D$18*E8+DCF!E$18*F8+DCF!F$18*G8 | C8: =1/(1+(DCF!$B$54-(DCF!$B$54-$A$8)*DCF!B$67)) | D8: =C8/(1+(DCF!$B$54-(DCF!$B$54-$A$8)*DCF!C$67)) | E8: =D8/(1+(DCF!$B$54-(DCF!$B$54-$A$8)*DCF!D$67)) | F8: =E8/(1+(DCF!$B$54-(DCF!$B$54-$A$8)*DCF!E$67)) | G8: =F8/(1+(DCF!$B$54-(DCF!$B$54-$A$8)*DCF!F$67))
A9: 0.1652265 | B9: =DCF!B$18*C9+DCF!C$18*D9+DCF!D$18*E9+DCF!E$18*F9+DCF!F$18*G9 | C9: =1/(1+(DCF!$B$54-(DCF!$B$54-$A$9)*DCF!B$67)) | D9: =C9/(1+(DCF!$B$54-(DCF!$B$54-$A$9)*DCF!C$67)) | E9: =D9/(1+(DCF!$B$54-(DCF!$B$54-$A$9)*DCF!D$67)) | F9: =E9/(1+(DCF!$B$54-(DCF!$B$54-$A$9)*DCF!E$67)) | G9: =F9/(1+(DCF!$B$54-(DCF!$B$54-$A$9)*DCF!F$67))
A10: 0.1752265 | B10: =DCF!B$18*C10+DCF!C$18*D10+DCF!D$18*E10+DCF!E$18*F10+DCF!F$18*G10 | C10: =1/(1+(DCF!$B$54-(DCF!$B$54-$A$10)*DCF!B$67)) | D10: =C10/(1+(DCF!$B$54-(DCF!$B$54-$A$10)*DCF!C$67)) | E10: =D10/(1+(DCF!$B$54-(DCF!$B$54-$A$10)*DCF!D$67)) | F10: =E10/(1+(DCF!$B$54-(DCF!$B$54-$A$10)*DCF!E$67)) | G10: =F10/(1+(DCF!$B$54-(DCF!$B$54-$A$10)*DCF!F$67))
A11: 0.1852265 | B11: =DCF!B$18*C11+DCF!C$18*D11+DCF!D$18*E11+DCF!E$18*F11+DCF!F$18*G11 | C11: =1/(1+(DCF!$B$54-(DCF!$B$54-$A$11)*DCF!B$67)) | D11: =C11/(1+(DCF!$B$54-(DCF!$B$54-$A$11)*DCF!C$67)) | E11: =D11/(1+(DCF!$B$54-(DCF!$B$54-$A$11)*DCF!D$67)) | F11: =E11/(1+(DCF!$B$54-(DCF!$B$54-$A$11)*DCF!E$67)) | G11: =F11/(1+(DCF!$B$54-(DCF!$B$54-$A$11)*DCF!F$67))
A13: Terminal WACC \ terminal g | B13: 3% | C13: 4% | D13: 5% | E13: 6% | F13: 7%
A14: =A7 | B14: =((B7+DCF!F$13*(1+0.03)*(1-0.03/(DCF!F$13*(1+0.03)/DCF!F$24))/(A7-0.03)*G7))*(1-Assumptions!$C$70)/Assumptions!$C$6-DCF!$B$49/Assumptions!$C$6 | C14: =((B7+DCF!F$13*(1+0.04)*(1-0.04/(DCF!F$13*(1+0.04)/DCF!F$24))/(A7-0.04)*G7))*(1-Assumptions!$C$70)/Assumptions!$C$6-DCF!$B$49/Assumptions!$C$6 | D14: =((B7+DCF!F$13*(1+0.05)*(1-0.05/(DCF!F$13*(1+0.05)/DCF!F$24))/(A7-0.05)*G7))*(1-Assumptions!$C$70)/Assumptions!$C$6-DCF!$B$49/Assumptions!$C$6 | E14: =((B7+DCF!F$13*(1+0.06)*(1-0.06/(DCF!F$13*(1+0.06)/DCF!F$24))/(A7-0.06)*G7))*(1-Assumptions!$C$70)/Assumptions!$C$6-DCF!$B$49/Assumptions!$C$6 | F14: =((B7+DCF!F$13*(1+0.07)*(1-0.07/(DCF!F$13*(1+0.07)/DCF!F$24))/(A7-0.07)*G7))*(1-Assumptions!$C$70)/Assumptions!$C$6-DCF!$B$49/Assumptions!$C$6
A15: =A8 | B15: =((B8+DCF!F$13*(1+0.03)*(1-0.03/(DCF!F$13*(1+0.03)/DCF!F$24))/(A8-0.03)*G8))*(1-Assumptions!$C$70)/Assumptions!$C$6-DCF!$B$49/Assumptions!$C$6 | C15: =((B8+DCF!F$13*(1+0.04)*(1-0.04/(DCF!F$13*(1+0.04)/DCF!F$24))/(A8-0.04)*G8))*(1-Assumptions!$C$70)/Assumptions!$C$6-DCF!$B$49/Assumptions!$C$6 | D15: =((B8+DCF!F$13*(1+0.05)*(1-0.05/(DCF!F$13*(1+0.05)/DCF!F$24))/(A8-0.05)*G8))*(1-Assumptions!$C$70)/Assumptions!$C$6-DCF!$B$49/Assumptions!$C$6 | E15: =((B8+DCF!F$13*(1+0.06)*(1-0.06/(DCF!F$13*(1+0.06)/DCF!F$24))/(A8-0.06)*G8))*(1-Assumptions!$C$70)/Assumptions!$C$6-DCF!$B$49/Assumptions!$C$6 | F15: =((B8+DCF!F$13*(1+0.07)*(1-0.07/(DCF!F$13*(1+0.07)/DCF!F$24))/(A8-0.07)*G8))*(1-Assumptions!$C$70)/Assumptions!$C$6-DCF!$B$49/Assumptions!$C$6
A16: =A9 | B16: =((B9+DCF!F$13*(1+0.03)*(1-0.03/(DCF!F$13*(1+0.03)/DCF!F$24))/(A9-0.03)*G9))*(1-Assumptions!$C$70)/Assumptions!$C$6-DCF!$B$49/Assumptions!$C$6 | C16: =((B9+DCF!F$13*(1+0.04)*(1-0.04/(DCF!F$13*(1+0.04)/DCF!F$24))/(A9-0.04)*G9))*(1-Assumptions!$C$70)/Assumptions!$C$6-DCF!$B$49/Assumptions!$C$6 | D16: =((B9+DCF!F$13*(1+0.05)*(1-0.05/(DCF!F$13*(1+0.05)/DCF!F$24))/(A9-0.05)*G9))*(1-Assumptions!$C$70)/Assumptions!$C$6-DCF!$B$49/Assumptions!$C$6 | E16: =((B9+DCF!F$13*(1+0.06)*(1-0.06/(DCF!F$13*(1+0.06)/DCF!F$24))/(A9-0.06)*G9))*(1-Assumptions!$C$70)/Assumptions!$C$6-DCF!$B$49/Assumptions!$C$6 | F16: =((B9+DCF!F$13*(1+0.07)*(1-0.07/(DCF!F$13*(1+0.07)/DCF!F$24))/(A9-0.07)*G9))*(1-Assumptions!$C$70)/Assumptions!$C$6-DCF!$B$49/Assumptions!$C$6
A17: =A10 | B17: =((B10+DCF!F$13*(1+0.03)*(1-0.03/(DCF!F$13*(1+0.03)/DCF!F$24))/(A10-0.03)*G10))*(1-Assumptions!$C$70)/Assumptions!$C$6-DCF!$B$49/Assumptions!$C$6 | C17: =((B10+DCF!F$13*(1+0.04)*(1-0.04/(DCF!F$13*(1+0.04)/DCF!F$24))/(A10-0.04)*G10))*(1-Assumptions!$C$70)/Assumptions!$C$6-DCF!$B$49/Assumptions!$C$6 | D17: =((B10+DCF!F$13*(1+0.05)*(1-0.05/(DCF!F$13*(1+0.05)/DCF!F$24))/(A10-0.05)*G10))*(1-Assumptions!$C$70)/Assumptions!$C$6-DCF!$B$49/Assumptions!$C$6 | E17: =((B10+DCF!F$13*(1+0.06)*(1-0.06/(DCF!F$13*(1+0.06)/DCF!F$24))/(A10-0.06)*G10))*(1-Assumptions!$C$70)/Assumptions!$C$6-DCF!$B$49/Assumptions!$C$6 | F17: =((B10+DCF!F$13*(1+0.07)*(1-0.07/(DCF!F$13*(1+0.07)/DCF!F$24))/(A10-0.07)*G10))*(1-Assumptions!$C$70)/Assumptions!$C$6-DCF!$B$49/Assumptions!$C$6
A18: =A11 | B18: =((B11+DCF!F$13*(1+0.03)*(1-0.03/(DCF!F$13*(1+0.03)/DCF!F$24))/(A11-0.03)*G11))*(1-Assumptions!$C$70)/Assumptions!$C$6-DCF!$B$49/Assumptions!$C$6 | C18: =((B11+DCF!F$13*(1+0.04)*(1-0.04/(DCF!F$13*(1+0.04)/DCF!F$24))/(A11-0.04)*G11))*(1-Assumptions!$C$70)/Assumptions!$C$6-DCF!$B$49/Assumptions!$C$6 | D18: =((B11+DCF!F$13*(1+0.05)*(1-0.05/(DCF!F$13*(1+0.05)/DCF!F$24))/(A11-0.05)*G11))*(1-Assumptions!$C$70)/Assumptions!$C$6-DCF!$B$49/Assumptions!$C$6 | E18: =((B11+DCF!F$13*(1+0.06)*(1-0.06/(DCF!F$13*(1+0.06)/DCF!F$24))/(A11-0.06)*G11))*(1-Assumptions!$C$70)/Assumptions!$C$6-DCF!$B$49/Assumptions!$C$6 | F18: =((B11+DCF!F$13*(1+0.07)*(1-0.07/(DCF!F$13*(1+0.07)/DCF!F$24))/(A11-0.07)*G11))*(1-Assumptions!$C$70)/Assumptions!$C$6-DCF!$B$49/Assumptions!$C$6
A20: Every cell above is a formula. Change the terminal cost of capital in column A, or the growth rate in the header, and the grid redraws. The previous edition pasted all 25 cells, which is how a stale sweep can ship beside a base case it no longer reproduces.
A22: GRID 2 — BETA (EGP per share, LIVE)
A23: Beta | B23: 0.60 | C23: 0.80 | D23: 0.94 | E23: 1.15 | F23: 1.30
A24: Cost of equity, explicit | B24: =DCF!$B$43+0.6*DCF!$B$45 | C24: =DCF!$B$43+0.8*DCF!$B$45 | D24: =DCF!$B$43+0.9405*DCF!$B$45 | E24: =DCF!$B$43+1.15*DCF!$B$45 | F24: =DCF!$B$43+1.3*DCF!$B$45
A25: Cost of equity, terminal | B25: =Assumptions!$C$62+0.6*Assumptions!$C$63 | C25: =Assumptions!$C$62+0.8*Assumptions!$C$63 | D25: =Assumptions!$C$62+0.9405*Assumptions!$C$63 | E25: =Assumptions!$C$62+1.15*Assumptions!$C$63 | F25: =Assumptions!$C$62+1.3*Assumptions!$C$63
A26: WACC explicit | B26: =DCF!$B$52*B24+DCF!$B$51*DCF!$B$53 | C26: =DCF!$B$52*C24+DCF!$B$51*DCF!$B$53 | D26: =DCF!$B$52*D24+DCF!$B$51*DCF!$B$53 | E26: =DCF!$B$52*E24+DCF!$B$51*DCF!$B$53 | F26: =DCF!$B$52*F24+DCF!$B$51*DCF!$B$53
A27: WACC terminal | B27: =(1-Assumptions!$C$65)*B25+Assumptions!$C$65*DCF!$B$60 | C27: =(1-Assumptions!$C$65)*C25+Assumptions!$C$65*DCF!$B$60 | D27: =(1-Assumptions!$C$65)*D25+Assumptions!$C$65*DCF!$B$60 | E27: =(1-Assumptions!$C$65)*E25+Assumptions!$C$65*DCF!$B$60 | F27: =(1-Assumptions!$C$65)*F25+Assumptions!$C$65*DCF!$B$60
A28: df1 | B28: =1/(1+(B26-(B26-B27)*DCF!B$67)) | C28: =1/(1+(C26-(C26-C27)*DCF!B$67)) | D28: =1/(1+(D26-(D26-D27)*DCF!B$67)) | E28: =1/(1+(E26-(E26-E27)*DCF!B$67)) | F28: =1/(1+(F26-(F26-F27)*DCF!B$67))
A29: df2 | B29: =B28/(1+(B26-(B26-B27)*DCF!C$67)) | C29: =C28/(1+(C26-(C26-C27)*DCF!C$67)) | D29: =D28/(1+(D26-(D26-D27)*DCF!C$67)) | E29: =E28/(1+(E26-(E26-E27)*DCF!C$67)) | F29: =F28/(1+(F26-(F26-F27)*DCF!C$67))
A30: df3 | B30: =B29/(1+(B26-(B26-B27)*DCF!D$67)) | C30: =C29/(1+(C26-(C26-C27)*DCF!D$67)) | D30: =D29/(1+(D26-(D26-D27)*DCF!D$67)) | E30: =E29/(1+(E26-(E26-E27)*DCF!D$67)) | F30: =F29/(1+(F26-(F26-F27)*DCF!D$67))
A31: df4 | B31: =B30/(1+(B26-(B26-B27)*DCF!E$67)) | C31: =C30/(1+(C26-(C26-C27)*DCF!E$67)) | D31: =D30/(1+(D26-(D26-D27)*DCF!E$67)) | E31: =E30/(1+(E26-(E26-E27)*DCF!E$67)) | F31: =F30/(1+(F26-(F26-F27)*DCF!E$67))
A32: df5 | B32: =B31/(1+(B26-(B26-B27)*DCF!F$67)) | C32: =C31/(1+(C26-(C26-C27)*DCF!F$67)) | D32: =D31/(1+(D26-(D26-D27)*DCF!F$67)) | E32: =E31/(1+(E26-(E26-E27)*DCF!F$67)) | F32: =F31/(1+(F26-(F26-F27)*DCF!F$67))
A33: PV explicit | B33: =DCF!B$18*B28+DCF!C$18*B29+DCF!D$18*B30+DCF!E$18*B31+DCF!F$18*B32 | C33: =DCF!B$18*C28+DCF!C$18*C29+DCF!D$18*C30+DCF!E$18*C31+DCF!F$18*C32 | D33: =DCF!B$18*D28+DCF!C$18*D29+DCF!D$18*D30+DCF!E$18*D31+DCF!F$18*D32 | E33: =DCF!B$18*E28+DCF!C$18*E29+DCF!D$18*E30+DCF!E$18*E31+DCF!F$18*E32 | F33: =DCF!B$18*F28+DCF!C$18*F29+DCF!D$18*F30+DCF!E$18*F31+DCF!F$18*F32
A35: FAIR VALUE (EGP per share) | B35: =(((B33)+DCF!F$13*(1+Assumptions!$C$66)*(1-DCF!$B$28)/(B27-Assumptions!$C$66)*B32))*(1-Assumptions!$C$70)/Assumptions!$C$6-DCF!$B$49/Assumptions!$C$6 | C35: =(((C33)+DCF!F$13*(1+Assumptions!$C$66)*(1-DCF!$B$28)/(C27-Assumptions!$C$66)*C32))*(1-Assumptions!$C$70)/Assumptions!$C$6-DCF!$B$49/Assumptions!$C$6 | D35: =(((D33)+DCF!F$13*(1+Assumptions!$C$66)*(1-DCF!$B$28)/(D27-Assumptions!$C$66)*D32))*(1-Assumptions!$C$70)/Assumptions!$C$6-DCF!$B$49/Assumptions!$C$6 | E35: =(((E33)+DCF!F$13*(1+Assumptions!$C$66)*(1-DCF!$B$28)/(E27-Assumptions!$C$66)*E32))*(1-Assumptions!$C$70)/Assumptions!$C$6-DCF!$B$49/Assumptions!$C$6 | F35: =(((F33)+DCF!F$13*(1+Assumptions!$C$66)*(1-DCF!$B$28)/(F27-Assumptions!$C$66)*F32))*(1-Assumptions!$C$70)/Assumptions!$C$6-DCF!$B$49/Assumptions!$C$6
A36: Check: the base column must reproduce the base case | D36: =D35-'EV Bridge'!$B$12
A38: The base column of this sweep is now a formula off the same cells the base case uses, so it cannot drift from it — the row above proves it to four decimals. The previous edition pasted this sweep and it had drifted: its centre column read 10.04 against a base case of 9.91.
A40: GRID 3 — EXPLICIT x TERMINAL COST OF CAPITAL (EGP per share, LIVE)
A41: each anchor varied independently around its own base; one formula a cell, no helper block
A42: Explicit \ terminal | B42: 0.1452265 | C42: 0.1552265 | D42: 0.1652265 | E42: 0.1752265 | F42: 0.1852265
A43: 0.28632746 | B43: =(DCF!B$18/((1+($A$43-($A$43-B$42)*DCF!B$67)))+DCF!C$18/((1+($A$43-($A$43-B$42)*DCF!B$67))*(1+($A$43-($A$43-B$42)*DCF!C$67)))+DCF!D$18/((1+($A$43-($A$43-B$42)*DCF!B$67))*(1+($A$43-($A$43-B$42)*DCF!C$67))*(1+($A$43-($A$43-B$42)*DCF!D$67)))+DCF!E$18/((1+($A$43-($A$43-B$42)*DCF!B$67))*(1+($A$43-($A$43-B$42)*DCF!C$67))*(1+($A$43-($A$43-B$42)*DCF!D$67))*(1+($A$43-($A$43-B$42)*DCF!E$67)))+DCF!F$18/((1+($A$43-($A$43-B$42)*DCF!B$67))*(1+($A$43-($A$43-B$42)*DCF!C$67))*(1+($A$43-($A$43-B$42)*DCF!D$67))*(1+($A$43-($A$43-B$42)*DCF!E$67))*(1+($A$43-($A$43-B$42)*DCF!F$67)))+DCF!F$13*(1+Assumptions!$C$66)*(1-DCF!$B$28)/(B$42-Assumptions!$C$66)/((1+($A$43-($A$43-B$42)*DCF!B$67))*(1+($A$43-($A$43-B$42)*DCF!C$67))*(1+($A$43-($A$43-B$42)*DCF!D$67))*(1+($A$43-($A$43-B$42)*DCF!E$67))*(1+($A$43-($A$43-B$42)*DCF!F$67))))*(1-Assumptions!$C$70)/Assumptions!$C$6-DCF!$B$49/Assumptions!$C$6 | C43: =(DCF!B$18/((1+($A$43-($A$43-C$42)*DCF!B$67)))+DCF!C$18/((1+($A$43-($A$43-C$42)*DCF!B$67))*(1+($A$43-($A$43-C$42)*DCF!C$67)))+DCF!D$18/((1+($A$43-($A$43-C$42)*DCF!B$67))*(1+($A$43-($A$43-C$42)*DCF!C$67))*(1+($A$43-($A$43-C$42)*DCF!D$67)))+DCF!E$18/((1+($A$43-($A$43-C$42)*DCF!B$67))*(1+($A$43-($A$43-C$42)*DCF!C$67))*(1+($A$43-($A$43-C$42)*DCF!D$67))*(1+($A$43-($A$43-C$42)*DCF!E$67)))+DCF!F$18/((1+($A$43-($A$43-C$42)*DCF!B$67))*(1+($A$43-($A$43-C$42)*DCF!C$67))*(1+($A$43-($A$43-C$42)*DCF!D$67))*(1+($A$43-($A$43-C$42)*DCF!E$67))*(1+($A$43-($A$43-C$42)*DCF!F$67)))+DCF!F$13*(1+Assumptions!$C$66)*(1-DCF!$B$28)/(C$42-Assumptions!$C$66)/((1+($A$43-($A$43-C$42)*DCF!B$67))*(1+($A$43-($A$43-C$42)*DCF!C$67))*(1+($A$43-($A$43-C$42)*DCF!D$67))*(1+($A$43-($A$43-C$42)*DCF!E$67))*(1+($A$43-($A$43-C$42)*DCF!F$67))))*(1-Assumptions!$C$70)/Assumptions!$C$6-DCF!$B$49/Assumptions!$C$6 | D43: =(DCF!B$18/((1+($A$43-($A$43-D$42)*DCF!B$67)))+DCF!C$18/((1+($A$43-($A$43-D$42)*DCF!B$67))*(1+($A$43-($A$43-D$42)*DCF!C$67)))+DCF!D$18/((1+($A$43-($A$43-D$42)*DCF!B$67))*(1+($A$43-($A$43-D$42)*DCF!C$67))*(1+($A$43-($A$43-D$42)*DCF!D$67)))+DCF!E$18/((1+($A$43-($A$43-D$42)*DCF!B$67))*(1+($A$43-($A$43-D$42)*DCF!C$67))*(1+($A$43-($A$43-D$42)*DCF!D$67))*(1+($A$43-($A$43-D$42)*DCF!E$67)))+DCF!F$18/((1+($A$43-($A$43-D$42)*DCF!B$67))*(1+($A$43-($A$43-D$42)*DCF!C$67))*(1+($A$43-($A$43-D$42)*DCF!D$67))*(1+($A$43-($A$43-D$42)*DCF!E$67))*(1+($A$43-($A$43-D$42)*DCF!F$67)))+DCF!F$13*(1+Assumptions!$C$66)*(1-DCF!$B$28)/(D$42-Assumptions!$C$66)/((1+($A$43-($A$43-D$42)*DCF!B$67))*(1+($A$43-($A$43-D$42)*DCF!C$67))*(1+($A$43-($A$43-D$42)*DCF!D$67))*(1+($A$43-($A$43-D$42)*DCF!E$67))*(1+($A$43-($A$43-D$42)*DCF!F$67))))*(1-Assumptions!$C$70)/Assumptions!$C$6-DCF!$B$49/Assumptions!$C$6 | E43: =(DCF!B$18/((1+($A$43-($A$43-E$42)*DCF!B$67)))+DCF!C$18/((1+($A$43-($A$43-E$42)*DCF!B$67))*(1+($A$43-($A$43-E$42)*DCF!C$67)))+DCF!D$18/((1+($A$43-($A$43-E$42)*DCF!B$67))*(1+($A$43-($A$43-E$42)*DCF!C$67))*(1+($A$43-($A$43-E$42)*DCF!D$67)))+DCF!E$18/((1+($A$43-($A$43-E$42)*DCF!B$67))*(1+($A$43-($A$43-E$42)*DCF!C$67))*(1+($A$43-($A$43-E$42)*DCF!D$67))*(1+($A$43-($A$43-E$42)*DCF!E$67)))+DCF!F$18/((1+($A$43-($A$43-E$42)*DCF!B$67))*(1+($A$43-($A$43-E$42)*DCF!C$67))*(1+($A$43-($A$43-E$42)*DCF!D$67))*(1+($A$43-($A$43-E$42)*DCF!E$67))*(1+($A$43-($A$43-E$42)*DCF!F$67)))+DCF!F$13*(1+Assumptions!$C$66)*(1-DCF!$B$28)/(E$42-Assumptions!$C$66)/((1+($A$43-($A$43-E$42)*DCF!B$67))*(1+($A$43-($A$43-E$42)*DCF!C$67))*(1+($A$43-($A$43-E$42)*DCF!D$67))*(1+($A$43-($A$43-E$42)*DCF!E$67))*(1+($A$43-($A$43-E$42)*DCF!F$67))))*(1-Assumptions!$C$70)/Assumptions!$C$6-DCF!$B$49/Assumptions!$C$6 | F43: =(DCF!B$18/((1+($A$43-($A$43-F$42)*DCF!B$67)))+DCF!C$18/((1+($A$43-($A$43-F$42)*DCF!B$67))*(1+($A$43-($A$43-F$42)*DCF!C$67)))+DCF!D$18/((1+($A$43-($A$43-F$42)*DCF!B$67))*(1+($A$43-($A$43-F$42)*DCF!C$67))*(1+($A$43-($A$43-F$42)*DCF!D$67)))+DCF!E$18/((1+($A$43-($A$43-F$42)*DCF!B$67))*(1+($A$43-($A$43-F$42)*DCF!C$67))*(1+($A$43-($A$43-F$42)*DCF!D$67))*(1+($A$43-($A$43-F$42)*DCF!E$67)))+DCF!F$18/((1+($A$43-($A$43-F$42)*DCF!B$67))*(1+($A$43-($A$43-F$42)*DCF!C$67))*(1+($A$43-($A$43-F$42)*DCF!D$67))*(1+($A$43-($A$43-F$42)*DCF!E$67))*(1+($A$43-($A$43-F$42)*DCF!F$67)))+DCF!F$13*(1+Assumptions!$C$66)*(1-DCF!$B$28)/(F$42-Assumptions!$C$66)/((1+($A$43-($A$43-F$42)*DCF!B$67))*(1+($A$43-($A$43-F$42)*DCF!C$67))*(1+($A$43-($A$43-F$42)*DCF!D$67))*(1+($A$43-($A$43-F$42)*DCF!E$67))*(1+($A$43-($A$43-F$42)*DCF!F$67))))*(1-Assumptions!$C$70)/Assumptions!$C$6-DCF!$B$49/Assumptions!$C$6
