Workbook

Sheet READ FIRST
A1: Read this first
A5: THE RULE
A6: IT CALCULATES. IT DOES NOT STORE.
A8: Exactly ONE class of cell is pasted in this workbook: a figure read off an audited or disclosed filing, or a stated house judgement. Those are the blue cells on Assumptions, and the blue lever cells that define each sensitivity grid point. Everything else is a live formula.
A10: The previous edition also pasted its sensitivity grids, its beta sweep and its bear and bull columns, on the grounds that each is a whole-model re-run and a re-run cannot be written inside a grid. That was 27.6% of the file, and it was the part a reader would most want to interrogate. Three of those pasted rows turned out not to reproduce.
A12: The Sensitivity sheet now writes the entire forecast engine out again, in formulas, once for every grid point. Change any driver on Assumptions and every sensitivity cell in the file moves with it.
A14: WHAT IS AUDITED AND WHAT IS NOT
A15: The base year is the twelve months to 30 June 2026. The first half of it — July to December 2025 — is AUDITED by Crowe with an unqualified opinion. The second half — January to June 2026 — is REPORTED: a disclosure to the Egyptian Exchange dated 29-30 July 2026, not a filing. Half of this base year is a press release and the study says so wherever it uses it.
A17: The gross profit of that reported half is NOT used as released. Run through the company's own first-quarter expense run rates the released figure implies a profit after tax about 12.6% above the profit the same release reports. The gross profit used here is solved from the profit line, which passes two independent coherence tests. Base Year rows 13 to 17 show the whole test.
A19: THE ONE OPERATING INPUT THAT IS NOT READ OFF A FILING
A20: Note 15-A discloses the cost stack for the company and not by line. The processing-intensity weights on Assumptions are therefore a judgement, and the per-line margins depend on them. They are registered, dated and sensitised like every other input rather than hidden inside a formula.

Sheet Assumptions
A1: Assumptions — every driver, with the filing it was read from
A2: Blue cells are the ONLY pasted values in this workbook. Every one is a figure read off an audited or disclosed filing, or a stated house judgement. There is no third class: the previous edition also pasted its sensitivity grids and its bear and bull columns because each is a whole-model re-run; those re-runs are now written out as live formula blocks on the Sensitivity sheet, so a reader can change a driver here and watch every one of them move.
A5: Driver | B5: Value | C5: Ring | D5: Date | E5: Source
A6: MARKET AND CAPITAL
A7: Spot price, EGP | B7: 9.1 | C7: Company | D7: 2026-08-06 | E7: AMOC closing price on the Egyptian Exchange, 6 August 2026
A8: Shares outstanding, mn | B8: 1291.5 | C8: Company | D8: 2025-12-31 | E8: Issued and paid-up capital EGP 1,291,500,000 at EGP 1 par = 1,291,500,000 shares (note 18-L, share split to EGP 1 par recorded in the Commercial Register 24-Jan-2018)
A9: THE TWELVE MONTHS TO 30 JUNE 2026 — the base year
A10: Net sales, 6M to 31-Dec-2025 (AUDITED) | B10: 20735725812 | C10: Company | D10: 2025-12-31 | E10: Net sales, six months to 31-Dec-2025. Audited consolidated FS, transition period 1-Jul-2025 to 31-Dec-2025, Crowe unqualified, 18-Feb-2026
A11: Cost of sales, 6M to 31-Dec-2025 (AUDITED) | B11: 19461550746 | C11: Company | D11: 2025-12-31 | E11: Cost of sales, six months to 31-Dec-2025. Audited consolidated FS, transition period 1-Jul-2025 to 31-Dec-2025, Crowe unqualified, 18-Feb-2026
A12: Net sales, 6M to 30-Jun-2026 (REPORTED) | B12: 26223000000 | C12: Company | D12: 2026-06-30 | E12: Net sales, six months to 30-Jun-2026. Half-year results for 1-Jan to 30-Jun-2026, disclosed to the Egyptian Exchange 29-30 July 2026. REPORTED, NOT AUDITED — a press release, not a filing
A13: Profit after tax, 6M to 30-Jun-2026 (REPORTED) | B13: 1903000000 | C13: Company | D13: 2026-06-30 | E13: Net profit after tax, six months to 30-Jun-2026. Half-year results for 1-Jan to 30-Jun-2026, disclosed to the Egyptian Exchange 29-30 July 2026. REPORTED, NOT AUDITED — a press release, not a filing
A14: Gross profit as RELEASED — rejected, see coherence test | B14: 3258000000 | C14: Company | D14: 2026-06-30 | E14: Gross profit, six months to 30-Jun-2026, AS RELEASED. This study does NOT use this figure: run through the company's own Q1-2026 expense run rates it implies a profit after tax about 12.6% above the profit the same release reports. The gross profit actually used is SOLVED from the release's own profit line, which two independent coherence tests confirm. Half-year results for 1-Jan to 30-Jun-2026, disclosed to the Egyptian Exchange 29-30 July 2026. REPORTED, NOT AUDITED — a press release, not a filing
A15: Net sales, 3M to 31-Mar-2026 (reviewed) | B15: 10510779160 | C15: Company | D15: 2026-03-31 | E15: Net sales, three months to 31-Mar-2026. Reviewed consolidated FS, three months to 31-Mar-2026
A16: Cost of sales, 3M to 31-Mar-2026 (reviewed) | B16: 9439744195 | C16: Company | D16: 2026-03-31 | E16: Cost of sales, three months to 31-Mar-2026. Reviewed consolidated FS, three months to 31-Mar-2026
A17: Administrative expense, 3M to 31-Mar-2026 | B17: 365952237 | C17: Company | D17: 2026-03-31 | E17: General and administrative expenses, three months to 31-Mar-2026. Reviewed consolidated FS, three months to 31-Mar-2026
A18: Selling expense, 3M to 31-Mar-2026 | B18: 60830975 | C18: Company | D18: 2026-03-31 | E18: Marketing and selling expenses, three months to 31-Mar-2026. Reviewed consolidated FS, three months to 31-Mar-2026
A19: Other operating expense, 3M to 31-Mar-2026 | B19: 1080000 | C19: Company | D19: 2026-03-31 | E19: Other operating expenses, three months to 31-Mar-2026. Reviewed consolidated FS, three months to 31-Mar-2026
A20: Other revenue, 3M to 31-Mar-2026 | B20: 225556509 | C20: Company | D20: 2026-03-31 | E20: Other revenue, three months to 31-Mar-2026. Reviewed consolidated FS, three months to 31-Mar-2026
A21: Formed provisions, 3M to 31-Mar-2026 | B21: 30000000 | C21: Company | D21: 2026-03-31 | E21: Formed provisions, three months to 31-Mar-2026. Reviewed consolidated FS, three months to 31-Mar-2026
... A44: Finance cost, 6M to 31-Dec-2025 | B44: 1892108 | C44: Company | D44: 2025-12-31 | E44: Finance expenses, six months to 31-Dec-2025 (note 15-E): loan interest and charges 1,130,556, lease interest 761,552. Audited consolidated FS, transition period 1-Jul-2025 to 31-Dec-2025, Crowe unqualified, 18-Feb-2026
A45: NOTE 14-A — the audited product table, 6M to 31-Dec-2025
A46: Base and special oils — tonnes sold | B46: 54968.98 | C46: Company | D46: 2025-12-31 | E46: Tonnes sold by product line, six months to 31-Dec-2025 (note 14-A). Audited consolidated FS, transition period 1-Jul-2025 to 31-Dec-2025, Crowe unqualified, 18-Feb-2026
A47: Paraffin wax — tonnes sold | B47: 41774.2 | C47: Company | D47: 2025-12-31 | E47: Tonnes sold by product line, six months to 31-Dec-2025 (note 14-A). Audited consolidated FS, transition period 1-Jul-2025 to 31-Dec-2025, Crowe unqualified, 18-Feb-2026
A48: Gas oil — tonnes sold | B48: 171684.88 | C48: Company | D48: 2025-12-31 | E48: Tonnes sold by product line, six months to 31-Dec-2025 (note 14-A). Audited consolidated FS, transition period 1-Jul-2025 to 31-Dec-2025, Crowe unqualified, 18-Feb-2026
A49: Naphtha — tonnes sold | B49: 41430.857 | C49: Company | D49: 2025-12-31 | E49: Tonnes sold by product line, six months to 31-Dec-2025 (note 14-A). Audited consolidated FS, transition period 1-Jul-2025 to 31-Dec-2025, Crowe unqualified, 18-Feb-2026
A50: Liquefied petroleum gas — tonnes sold | B50: 23735.778 | C50: Company | D50: 2025-12-31 | E50: Tonnes sold by product line, six months to 31-Dec-2025 (note 14-A). Audited consolidated FS, transition period 1-Jul-2025 to 31-Dec-2025, Crowe unqualified, 18-Feb-2026
A51: Fuel oil (mix) — tonnes sold | B51: 460153.6 | C51: Company | D51: 2025-12-31 | E51: Tonnes sold by product line, six months to 31-Dec-2025 (note 14-A). Audited consolidated FS, transition period 1-Jul-2025 to 31-Dec-2025, Crowe unqualified, 18-Feb-2026
A52: Heavy fuel oil — tonnes sold | B52: 14327.52 | C52: Company | D52: 2025-12-31 | E52: Tonnes sold by product line, six months to 31-Dec-2025 (note 14-A). Audited consolidated FS, transition period 1-Jul-2025 to 31-Dec-2025, Crowe unqualified, 18-Feb-2026
A53: Waste — tonnes sold | B53: 7.82 | C53: Company | D53: 2025-12-31 | E53: Tonnes sold by product line, six months to 31-Dec-2025 (note 14-A). Audited consolidated FS, transition period 1-Jul-2025 to 31-Dec-2025, Crowe unqualified, 18-Feb-2026
A54: Base and special oils — sales value, EGP | B54: 2597280264 | C54: Company | D54: 2025-12-31 | E54: Sales value by product line, EGP, six months to 31-Dec-2025 (note 14-A). Audited consolidated FS, transition period 1-Jul-2025 to 31-Dec-2025, Crowe unqualified, 18-Feb-2026
A55: Paraffin wax — sales value, EGP | B55: 2041969329 | C55: Company | D55: 2025-12-31 | E55: Sales value by product line, EGP, six months to 31-Dec-2025 (note 14-A). Audited consolidated FS, transition period 1-Jul-2025 to 31-Dec-2025, Crowe unqualified, 18-Feb-2026
A56: Gas oil — sales value, EGP | B56: 5121703599 | C56: Company | D56: 2025-12-31 | E56: Sales value by product line, EGP, six months to 31-Dec-2025 (note 14-A). Audited consolidated FS, transition period 1-Jul-2025 to 31-Dec-2025, Crowe unqualified, 18-Feb-2026
A57: Naphtha — sales value, EGP | B57: 958746631 | C57: Company | D57: 2025-12-31 | E57: Sales value by product line, EGP, six months to 31-Dec-2025 (note 14-A). Audited consolidated FS, transition period 1-Jul-2025 to 31-Dec-2025, Crowe unqualified, 18-Feb-2026
... A61: Waste — sales value, EGP | B61: 87400 | C61: Company | D61: 2025-12-31 | E61: Sales value by product line, EGP, six months to 31-Dec-2025 (note 14-A). Audited consolidated FS, transition period 1-Jul-2025 to 31-Dec-2025, Crowe unqualified, 18-Feb-2026
A62: NOTE 15-A — the audited cost stack, 6M to 31-Dec-2025
A63: Raw materials | B63: 17650102725 | C63: Company | D63: 2025-12-31 | E63: Cost of sales — RAW MATERIALS, six months to 31-Dec-2025 (note 15-A). 90.7% of cost of sales and 85.1% of revenue: this single line is what the company is. Audited consolidated FS, transition period 1-Jul-2025 to 31-Dec-2025, Crowe unqualified, 18-Feb-2026
A64: Salaries | B64: 881019497 | C64: Company | D64: 2025-12-31 | E64: Cost of sales — salaries, six months to 31-Dec-2025 (note 15-A). Audited consolidated FS, transition period 1-Jul-2025 to 31-Dec-2025, Crowe unqualified, 18-Feb-2026
A65: Other expenses | B65: 807146755 | C65: Company | D65: 2025-12-31 | E65: Cost of sales — other expenses, six months to 31-Dec-2025 (note 15-A): natural gas, operating electricity, operating water, spare parts, maintenance, and the operating management and technical support contract with the Egyptian Projects Operations & Maintenance Company (EPROM). Audited consolidated FS, transition period 1-Jul-2025 to 31-Dec-2025, Crowe unqualified, 18-Feb-2026
A66: Supporting materials (chemicals and additives) | B66: 64533723 | C66: Company | D66: 2025-12-31 | E66: Cost of sales — supporting materials (chemicals and additives), six months to 31-Dec-2025 (note 15-A). The previous edition estimated this charge at roughly five times the disclosed figure
A67: Depreciation | B67: 58748046 | C67: Company | D67: 2025-12-31 | E67: Cost of sales — depreciation, six months to 31-Dec-2025 (note 15-A). Audited consolidated FS, transition period 1-Jul-2025 to 31-Dec-2025, Crowe unqualified, 18-Feb-2026
...

Sheet Base Year
A1: Base year — twelve contiguous months to 30 June 2026
A2: The gross profit of the reported half is NOT taken as released. It is solved from the release's own profit line, and the released figure is shown beside it with the profit it would have implied. Every cell below is a formula.
B5: EGP | C5: Check
A6: Administrative + selling + other, 3M to 31-Mar-2026 | B6: =Assumptions!$B$17+Assumptions!$B$18+Assumptions!$B$19 -> 427863212
A7: Scaled to the half (x2) | B7: =B6*2 -> 855726424
A8: Other revenue, half | B8: =Assumptions!$B$20*2 -> 451113018
A9: Provisions and expected credit losses, half | B9: =(Assumptions!$B$21+Assumptions!$B$22)*2 -> 100646246
A10: Finance cost, half | B10: =Assumptions!$B$23*2 -> 1964438
A11: Effective tax rate, nine months (for the solve only) | B11: =(Assumptions!$B$38-Assumptions!$B$39+Assumptions!$B$40-Assumptions!$B$41)/((Assumptions!$B$38-Assumptions!$B$39+Assumptions!$B$40-Assumptions!$B$41)/0.22118761296853667) -> 0.22118761
A13: GROSS PROFIT, 6M to 30-Jun-2026 — SOLVED from the profit | B13: =Assumptions!$B$13/(1-B11)+B7-B8+B9+B10 -> 2.9506881e+09
A14: Gross profit AS RELEASED — rejected | B14: =Assumptions!$B$14 -> 3258000000
A15: Profit the released gross profit would imply | B15: =(B14-B7+B8-B9-B10)*(1-B11) -> 2.1423384e+09
A16: against the profit the same release reports | B16: =Assumptions!$B$13 -> 1903000000
A17: Overstatement in the released gross-profit line | B17: =B15/B16-1 -> 0.12576897
A19: BASE-YEAR REVENUE — twelve months to 30-Jun-2026 | B19: =(Assumptions!$B$10+Assumptions!$B$12)/10^6 -> 46958.726
A20: BASE-YEAR GROSS PROFIT | B20: =(Assumptions!$B$10-Assumptions!$B$11+B13)/10^6 -> 4224.8631
A21: BASE-YEAR COST OF SALES | B21: =B19-B20 -> 42733.863
A22: BASE-YEAR GROSS MARGIN | B22: =B20/B19 -> 0.089969714
A24: Alternative base: nine audited months x 4/3 | B24: =(Assumptions!$B$10+Assumptions!$B$15)/10^6*4/3 -> 41662.007
A25: its gross margin | B25: =(Assumptions!$B$10+Assumptions!$B$15-Assumptions!$B$11-Assumptions!$B$16)/(Assumptions!$B$10+Assumptions!$B$15) -> 0.075055115
A27: Operating lines, SAME twelve months
A28: Administrative expense | B28: =(Assumptions!$B$24+Assumptions!$B$17*2)/10^6 -> 1317.5406
A29: Selling expense | B29: =(Assumptions!$B$25+Assumptions!$B$18*2)/10^6 -> 215.39115
A30: Other operating expense | B30: =(Assumptions!$B$26+Assumptions!$B$19*2)/10^6 -> 110.94131
A31: Provisions and credit losses | B31: =(Assumptions!$B$27+(Assumptions!$B$21+Assumptions!$B$22)*2)/10^6 -> 103.11401
A32: Depreciation | B32: =(Assumptions!$B$28+Assumptions!$B$29*2)/10^6 -> 151.32049
A33: Cash capital expenditure | B33: =(Assumptions!$B$30+Assumptions!$B$31*2)/10^6 -> 160.32626
A34: Credit interest | B34: =(Assumptions!$B$32+Assumptions!$B$33*2)/10^6 -> 301.42477
A35: Employees' profit share | B35: =(Assumptions!$B$34*2)/10^6 -> 134.93574
A37: Every operating line is struck on the SAME twelve months as revenue and gross profit. The previous edition built revenue from the six-month product table doubled while taking cost of sales from the nine months scaled by four thirds, so its base-year gross margin of 7.081% corresponded to no filed period at all. One period, both sides, or the margin is an artefact of the scalars.
A39: RATES — solved, not assumed
A40: Employees' profit share, % of profit after tax | B40: =B35/((Assumptions!$B$35+Assumptions!$B$13)/10^6) -> 0.052721039
A41: Minority interest, % of OPERATING profit, whole base year | B41: =((Assumptions!$B$36+Assumptions!$B$37*2)/10^6)/((Assumptions!$B$35+Assumptions!$B$13)/10^6-B34*(1-0.22118761296853667)) -> 0.032582443
A42: Implied asset life, years = fixed assets at cost / depreciation | B42: =Assumptions!$B$70/10^6/B32 -> 18.112621
A43: Maintenance capital expenditure at cost over that life | B43: =Assumptions!$B$70/10^6/B42 -> 151.32049
A44: Inventory days of cost of sales | B44: =Assumptions!$B$72/10^6/B21*365 -> 24.320251
A45: Receivable days of revenue | B45: =(Assumptions!$B$73+Assumptions!$B$74)/10^6/B19*365 -> 7.2998005
A46: Operating payable days of cost of sales — dividends payable REMOVED | B46: =(Assumptions!$B$75+Assumptions!$B$76-Assumptions!$B$77)/10^6/B21*365 -> 13.111985

Sheet Product and Cost
A1: The eight disclosed product lines — revenue AND cost, per line
A2: Note 14-A gives tonnes and value per line. Note 15-A gives the cost stack for the company and NOT by line, so conversion is allocated on the registered processing-intensity weights and feedstock is then allocated on NET REALISABLE VALUE — the standard joint-product method. Every cell here is a formula.
A5: Line | B5: Tonnes, 6M | C5: Value, EGP 6M | D5: Realisation EGP/t | E5: Base tonnes mn | F5: Base realisation | G5: Conversion EGP/t | H5: Feedstock EGP/t | I5: Spread EGP/t
A6: Base and special oils | B6: =Assumptions!$B$46 -> 54968.98 | C6: =Assumptions!$B$54 -> 2597280264 | D6: =C6/B6 -> 47249.926 | E6: =B6*2/10^6 -> 0.10993796 | F6: =D6*$B$16 -> 53501.777 | G6: =$B$22*H6/$B$23 -> 10957.495 | H6: =Assumptions!$B$93 -> 1 | I6: =F6-G6 -> 42544.282
A7: Paraffin wax | B7: =Assumptions!$B$47 -> 41774.2 | C7: =Assumptions!$B$55 -> 2041969329 | D7: =C7/B7 -> 48881.112 | E7: =B7*2/10^6 -> 0.0835484 | F7: =D7*$B$16 -> 55348.791 | G7: =$B$22*H7/$B$23 -> 12601.119 | H7: =Assumptions!$B$94 -> 1.15 | I7: =F7-G7 -> 42747.672
A8: Gas oil | B8: =Assumptions!$B$48 -> 171684.88 | C8: =Assumptions!$B$56 -> 5121703599 | D8: =C8/B8 -> 29832.001 | E8: =B8*2/10^6 -> 0.34336976 | F8: =D8*$B$16 -> 33779.208 | G8: =$B$22*H8/$B$23 -> 2739.3737 | H8: =Assumptions!$B$95 -> 0.25 | I8: =F8-G8 -> 31039.834
A9: Naphtha | B9: =Assumptions!$B$49 -> 41430.857 | C9: =Assumptions!$B$57 -> 958746631 | D9: =C9/B9 -> 23140.883 | E9: =B9*2/10^6 -> 0.082861714 | F9: =D9*$B$16 -> 26202.758 | G9: =$B$22*H9/$B$23 -> 2191.4989 | H9: =Assumptions!$B$96 -> 0.2 | I9: =F9-G9 -> 24011.259
A10: Liquefied petroleum gas | B10: =Assumptions!$B$50 -> 23735.778 | C10: =Assumptions!$B$58 -> 816258520 | D10: =C10/B10 -> 34389.373 | E10: =B10*2/10^6 -> 0.047471556 | F10: =D10*$B$16 -> 38939.585 | G10: =$B$22*H10/$B$23 -> 1643.6242 | H10: =Assumptions!$B$97 -> 0.15 | I10: =F10-G10 -> 37295.961
A11: Fuel oil (mix) | B11: =Assumptions!$B$51 -> 460153.6 | C11: =Assumptions!$B$59 -> 8975569716 | D11: =C11/B11 -> 19505.595 | E11: =B11*2/10^6 -> 0.9203072 | F11: =D11*$B$16 -> 22086.468 | G11: =$B$22*H11/$B$23 -> 547.87473 | H11: =Assumptions!$B$98 -> 0.05 | I11: =F11-G11 -> 21538.593
A12: Heavy fuel oil | B12: =Assumptions!$B$52 -> 14327.52 | C12: =Assumptions!$B$60 -> 224110353 | D12: =C12/B12 -> 15641.95 | E12: =B12*2/10^6 -> 0.02865504 | F12: =D12*$B$16 -> 17711.607 | G12: =$B$22*H12/$B$23 -> 547.87473 | H12: =Assumptions!$B$99 -> 0.05 | I12: =F12-G12 -> 17163.732
A13: Waste | B13: =Assumptions!$B$53 -> 7.82 | C13: =Assumptions!$B$61 -> 87400 | D13: =C13/B13 -> 11176.471 | E13: =B13*2/10^6 -> 1.564e-05 | F13: =D13*$B$16 -> 12655.28 | G13: =$B$22*H13/$B$23 -> 0 | H13: =Assumptions!$B$100 -> 0 | I13: =F13-G13 -> 12655.28
A14: TOTAL | B14: =SUM(B6:B13) -> 808083.64 | C14: =SUM(C6:C13) -> 20735725812 | E14: =SUM(E6:E13) -> 1.6161673 | F14: =SUMPRODUCT(E6:E13,F6:F13) -> 46958.726
A15: Revenue at the disclosed realisations, annualised | B15: =SUMPRODUCT(E6:E13,D6:D13) -> 41471.452
A16: REALISATION INDEX — solved so the base year foots | B16: ='Base Year'!B19/B15 -> 1.1323145
A18: COST ALLOCATION
A19: Cost of sales, base year | B19: ='Base Year'!B21 -> 42733.863
A20: Feedstock share of cost (note 15-A) | B20: =Assumptions!$B$63/(Assumptions!$B$63+Assumptions!$B$64+Assumptions!$B$65+Assumptions!$B$66+Assumptions!$B$67) -> 0.9069217
A21: Feedstock total | B21: =B19*B20 -> 38756.267
A22: Conversion total | B22: =B19-B21 -> 3977.5952
A23: Processing-weighted tonnage | B23: =SUMPRODUCT(E6:E13,H6:H13) -> 0.36300225
A24: Net realisable value weighted tonnage | B24: =SUMPRODUCT(E6:E13,I6:I13) -> 42981.131
A26: Line | B26: Conversion EGP/t | C26: Net realisable EGP/t | D26: Feedstock EGP/t | E26: Total cost EGP/t | F26: Realisation EGP/t | G26: Spread EGP/t | H26: Gross margin
A27: Base and special oils | B27: =G6 -> 10957.495 | C27: =I6 -> 42544.282 | D27: =$B$21*I6/$B$24 -> 38362.359 | E27: =D27+B27 -> 49319.854 | F27: =F6 -> 53501.777 | G27: =F27-E27 -> 4181.9227 | H27: =G27/F27 -> 0.078164185
A28: Paraffin wax | B28: =G7 -> 12601.119 | C28: =I7 -> 42747.672 | D28: =$B$21*I7/$B$24 -> 38545.757 | E28: =D28+B28 -> 51146.876 | F28: =F7 -> 55348.791 | G28: =F28-E28 -> 4201.9151 | H28: =G28/F28 -> 0.075917018
A29: Gas oil | B29: =G8 -> 2739.3737 | C29: =I8 -> 31039.834 | D29: =$B$21*I8/$B$24 -> 27988.75 | E29: =D29+B29 -> 30728.123 | F29: =F8 -> 33779.208 | G29: =F29-E29 -> 3051.0842 | H29: =G29/F29 -> 0.090324328
A30: Naphtha | B30: =G9 -> 2191.4989 | C30: =I9 -> 24011.259 | D30: =$B$21*I9/$B$24 -> 21651.054 | E30: =D30+B30 -> 23842.553 | F30: =F9 -> 26202.758 | G30: =F30-E30 -> 2360.2051 | H30: =G30/F30 -> 0.090074681
A31: Liquefied petroleum gas | B31: =G10 -> 1643.6242 | C31: =I10 -> 37295.961 | D31: =$B$21*I10/$B$24 -> 33629.926 | E31: =D31+B31 -> 35273.55 | F31: =F10 -> 38939.585 | G31: =F31-E31 -> 3666.035 | H31: =G31/F31 -> 0.09414674
A32: Fuel oil (mix) | B32: =G11 -> 547.87473 | C32: =I11 -> 21538.593 | D32: =$B$21*I11/$B$24 -> 19421.441 | E32: =D32+B32 -> 19969.315 | F32: =F11 -> 22086.468 | G32: =F32-E32 -> 2117.1525 | H32: =G32/F32 -> 0.09585745
A33: Heavy fuel oil | B33: =G12 -> 547.87473 | C33: =I12 -> 17163.732 | D33: =$B$21*I12/$B$24 -> 15476.61 | E33: =D33+B33 -> 16024.485 | F33: =F12 -> 17711.607 | G33: =F33-E33 -> 1687.1222 | H33: =G33/F33 -> 0.095255173
A34: Waste | B34: =G13 -> 0 | C34: =I13 -> 12655.28 | D34: =$B$21*I13/$B$24 -> 11411.319 | E34: =D34+B34 -> 11411.319 | F34: =F13 -> 12655.28 | G34: =F34-E34 -> 1243.9604 | H34: =G34/F34 -> 0.098295765
A35: Cost of sales rebuilt from the per-line allocation | B35: =SUMPRODUCT(E6:E13,E27:E34) -> 42733.863
A36: must equal the base-year cost of sales — difference | B36: =B35-'Base Year'!B21 -> 0
A38: Row 36 is the footing test: the eight per-line costs must rebuild the disclosed cost of sales exactly. Feedstock allocated flat per tonne would make fuel oil sell below the cost of its own feed; feedstock allocated on relative sales value would make base oils and paraffin wax — the products this plant exists for — loss-making. Net realisable value is the standard joint-product method and the only one of the three that leaves every disclosed line with a positive spread.

Sheet Forecast
A1: Forecast engine — eight lines by five years, all formulas
A2: This is the block the Sensitivity sheet replicates twenty-five times, once per grid point, so that every sensitivity cell in this workbook is a live re-run rather than a pasted number.
A5: Levers for this block — the base case sets them all neutral
A6: Growth-path multiplier | B6: 1
A7: Gross-margin shift | B7: 0
A8: Realisation-path multiplier | B8: 1
A9: Working-capital cycle multiplier | B9: 1
A10: Explicit cost of capital | B10: =Assumptions!$B$152-Assumptions!$B$153+Assumptions!$B$155*Assumptions!$B$154 -> 0.27760105
A11: Equity weight | B11: =Assumptions!$B$7*Assumptions!$B$8/(Assumptions!$B$7*Assumptions!$B$8+(Assumptions!$B$82+Assumptions!$B$83-Assumptions!$B$79)/10^6) -> 1.2623542
A12: Debt weight | B12: =1-B11 -> -0.26235417
A13: After-tax cost of net debt | B13: =(Assumptions!$B$157*(Assumptions!$B$82+Assumptions!$B$83)/10^6-Assumptions!$B$156*Assumptions!$B$79/10^6)/((Assumptions!$B$82+Assumptions!$B$83-Assumptions!$B$79)/10^6)*(1-0.22118761296853667) -> 0.13206367
A14: WACC — explicit window | B14: =B11*B10+B12*B13 -> 0.31578339
A15: Terminal risk-free — DERIVED from the target in force | B15: =Assumptions!$B$158+Assumptions!$B$159 -> 0.125
A16: Terminal cost of equity | B16: =B15+Assumptions!$B$155*Assumptions!$B$160 -> 0.190835
A17: WACC — terminal | B17: =(1-Assumptions!$B$162)*B16+Assumptions!$B$162*Assumptions!$B$161*(1-0.22118761296853667) -> 0.18343369
A19: BASE CASE | B19: 2026E | C19: 2027E | D19: 2028E | E19: 2029E | F19: 2030E
A20: Inflation index, cumulative | C20: =Assumptions!$B$146 -> 1.145 | D20: =C20*Assumptions!$B$147 -> 1.29385 | E20: =D20*Assumptions!$B$148 -> 1.4426428 | F20: =E20*Assumptions!$B$149 -> 1.586907 | G20: =F20*Assumptions!$B$150 -> 1.7376632
A21: Realisation index, cumulative | C21: =(1+Assumptions!$B$101*$B$8) -> 1.09 | D21: =C21*(1+Assumptions!$B$102*$B$8) -> 1.17175 | E21: =D21*(1+Assumptions!$B$103*$B$8) -> 1.2479137 | F21: =E21*(1+Assumptions!$B$104*$B$8) -> 1.3202927 | G21: =F21*(1+Assumptions!$B$105*$B$8) -> 1.388948
A22: Volume — Base and special oils, mn t | C22: ='Product and Cost'!E6*(1+Assumptions!$B$106*$B$6) -> 0.11488517 | D22: =C22*(1+Assumptions!$B$107*$B$6) -> 0.11948057 | E22: =D22*(1+Assumptions!$B$108*$B$6) -> 0.1236624 | F22: =E22*(1+Assumptions!$B$109*$B$6) -> 0.12737227 | G22: =F22*(1+Assumptions!$B$110*$B$6) -> 0.13093869
A23: Volume — Paraffin wax, mn t | C23: ='Product and Cost'!E7*(1+Assumptions!$B$111*$B$6) -> 0.089396788 | D23: =C23*(1+Assumptions!$B$112*$B$6) -> 0.094313611 | E23: =D23*(1+Assumptions!$B$113*$B$6) -> 0.098557724 | F23: =E23*(1+Assumptions!$B$114*$B$6) -> 0.10230292 | G23: =F23*(1+Assumptions!$B$115*$B$6) -> 0.10557661
A24: Volume — Gas oil, mn t | C24: ='Product and Cost'!E8*(1+Assumptions!$B$116*$B$6) -> 0.35023716 | D24: =C24*(1+Assumptions!$B$117*$B$6) -> 0.3572419 | E24: =D24*(1+Assumptions!$B$118*$B$6) -> 0.36367225 | F24: =E24*(1+Assumptions!$B$119*$B$6) -> 0.36949101 | G24: =F24*(1+Assumptions!$B$120*$B$6) -> 0.37503338
A25: Volume — Naphtha, mn t | C25: ='Product and Cost'!E9*(1+Assumptions!$B$121*$B$6) -> 0.08410464 | D25: =C25*(1+Assumptions!$B$122*$B$6) -> 0.085618523 | E25: =D25*(1+Assumptions!$B$123*$B$6) -> 0.087159657 | F25: =E25*(1+Assumptions!$B$124*$B$6) -> 0.088554211 | G25: =F25*(1+Assumptions!$B$125*$B$6) -> 0.089882524
A26: Volume — Liquefied petroleum gas, mn t | C26: ='Product and Cost'!E10*(1+Assumptions!$B$126*$B$6) -> 0.048658345 | D26: =C26*(1+Assumptions!$B$127*$B$6) -> 0.049728828 | E26: =D26*(1+Assumptions!$B$128*$B$6) -> 0.050723405 | F26: =E26*(1+Assumptions!$B$129*$B$6) -> 0.051636426 | G26: =F26*(1+Assumptions!$B$130*$B$6) -> 0.052462609
A27: Volume — Fuel oil (mix), mn t | C27: ='Product and Cost'!E11*(1+Assumptions!$B$131*$B$6) -> 0.94791642 | D27: =C27*(1+Assumptions!$B$132*$B$6) -> 0.97256224 | E27: =D27*(1+Assumptions!$B$133*$B$6) -> 0.99395861 | F27: =E27*(1+Assumptions!$B$134*$B$6) -> 1.0138378 | G27: =F27*(1+Assumptions!$B$135*$B$6) -> 1.0320869
A28: Volume — Heavy fuel oil, mn t | C28: ='Product and Cost'!E12*(1+Assumptions!$B$136*$B$6) -> 0.029228141 | D28: =C28*(1+Assumptions!$B$137*$B$6) -> 0.029754247 | E28: =D28*(1+Assumptions!$B$138*$B$6) -> 0.030230315 | F28: =E28*(1+Assumptions!$B$139*$B$6) -> 0.03068377 | G28: =F28*(1+Assumptions!$B$140*$B$6) -> 0.031113343
A29: Volume — Waste, mn t | C29: ='Product and Cost'!E13*(1+Assumptions!$B$141*$B$6) -> 1.564e-05 | D29: =C29*(1+Assumptions!$B$142*$B$6) -> 1.564e-05 | E29: =D29*(1+Assumptions!$B$143*$B$6) -> 1.564e-05 | F29: =E29*(1+Assumptions!$B$144*$B$6) -> 1.564e-05 | G29: =F29*(1+Assumptions!$B$145*$B$6) -> 1.564e-05
A30: Total volume, mn t | C30: =SUM(C22:C29) -> 1.6644423 | D30: =SUM(D22:D29) -> 1.7087156 | E30: =SUM(E22:E29) -> 1.74798 | F30: =SUM(F22:F29) -> 1.783894 | G30: =SUM(G22:G29) -> 1.8171097
A31: REVENUE | C31: =C22*'Product and Cost'!$F$6*C21+C23*'Product and Cost'!$F$7*C21+C24*'Product and Cost'!$F$8*C21+C25*'Product and Cost'!$F$9*C21+C26*'Product and Cost'!$F$10*C21+C27*'Product and Cost'!$F$11*C21+C28*'Product and Cost'!$F$12*C21+C29*'Product and Cost'!$F$13*C21 -> 52840.811 | D31: =D22*'Product and Cost'!$F$6*D21+D23*'Product and Cost'!$F$7*D21+D24*'Product and Cost'!$F$8*D21+D25*'Product and Cost'!$F$9*D21+D26*'Product and Cost'!$F$10*D21+D27*'Product and Cost'!$F$11*D21+D28*'Product and Cost'!$F$12*D21+D29*'Product and Cost'!$F$13*D21 -> 58432.167 | E31: =E22*'Product and Cost'!$F$6*E21+E23*'Product and Cost'!$F$7*E21+E24*'Product and Cost'!$F$8*E21+E25*'Product and Cost'!$F$9*E21+E26*'Product and Cost'!$F$10*E21+E27*'Product and Cost'!$F$11*E21+E28*'Product and Cost'!$F$12*E21+E29*'Product and Cost'!$F$13*E21 -> 63772.637 | F31: =F22*'Product and Cost'!$F$6*F21+F23*'Product and Cost'!$F$7*F21+F24*'Product and Cost'!$F$8*F21+F25*'Product and Cost'!$F$9*F21+F26*'Product and Cost'!$F$10*F21+F27*'Product and Cost'!$F$11*F21+F28*'Product and Cost'!$F$12*F21+F29*'Product and Cost'!$F$13*F21 -> 68952.179 | G31: =G22*'Product and Cost'!$F$6*G21+G23*'Product and Cost'!$F$7*G21+G24*'Product and Cost'!$F$8*G21+G25*'Product and Cost'!$F$9*G21+G26*'Product and Cost'!$F$10*G21+G27*'Product and Cost'!$F$11*G21+G28*'Product and Cost'!$F$12*G21+G29*'Product and Cost'!$F$13*G21 -> 73977.843
A32: Cost of sales | C32: =C22*('Product and Cost'!$D$27*C21*Assumptions!$B$88+'Product and Cost'!$B$27*(0.4863620081*C20+0.4455809638*C20+0.0356254898*C21+0.0324315384))+C23*('Product and Cost'!$D$28*C21*Assumptions!$B$88+'Product and Cost'!$B$28*(0.4863620081*C20+0.4455809638*C20+0.0356254898*C21+0.0324315384))+C24*('Product and Cost'!$D$29*C21*Assumptions!$B$88+'Product and Cost'!$B$29*(0.4863620081*C20+0.4455809638*C20+0.0356254898*C21+0.0324315384))+C25*('Product and Cost'!$D$30*C21*Assumptions!$B$88+'Product and Cost'!$B$30*(0.4863620081*C20+0.4455809638*C20+0.0356254898*C21+0.0324315384))+C26*('Product and Cost'!$D$31*C21*Assumptions!$B$88+'Product and Cost'!$B$31*(0.4863620081*C20+0.4455809638*C20+0.0356254898*C21+0.0324315384))+C27*('Product and Cost'!$D$32*C21*Assumptions!$B$88+'Product and Cost'!$B$32*(0.4863620081*C20+0.4455809638*C20+0.0356254898*C21+0.0324315384))+C28*('Product and Cost'!$D$33*C21*Assumptions!$B$88+'Product and Cost'!$B$33*(0.4863620081*C20+0.4455809638*C20+0.0356254898*C21+0.0324315384))+C29*('Product and Cost'!$D$34*C21*Assumptions!$B$88+'Product and Cost'!$B$34*(0.4863620081*C20+0.4455809638*C20+0.0356254898*C21+0.0324315384)) -> 48291.16 | D32: =D22*('Product and Cost'!$D$27*D21*Assumptions!$B$88+'Product and Cost'!$B$27*(0.4863620081*D20+0.4455809638*D20+0.0356254898*D21+0.0324315384))+D23*('Product and Cost'!$D$28*D21*Assumptions!$B$88+'Product and Cost'!$B$28*(0.4863620081*D20+0.4455809638*D20+0.0356254898*D21+0.0324315384))+D24*('Product and Cost'!$D$29*D21*Assumptions!$B$88+'Product and Cost'!$B$29*(0.4863620081*D20+0.4455809638*D20+0.0356254898*D21+0.0324315384))+D25*('Product and Cost'!$D$30*D21*Assumptions!$B$88+'Product and Cost'!$B$30*(0.4863620081*D20+0.4455809638*D20+0.0356254898*D21+0.0324315384))+D26*('Product and Cost'!$D$31*D21*Assumptions!$B$88+'Product and Cost'!$B$31*(0.4863620081*D20+0.4455809638*D20+0.0356254898*D21+0.0324315384))+D27*('Product and Cost'!$D$32*D21*Assumptions!$B$88+'Product and Cost'!$B$32*(0.4863620081*D20+0.4455809638*D20+0.0356254898*D21+0.0324315384))+D28*('Product and Cost'!$D$33*D21*Assumptions!$B$88+'Product and Cost'!$B$33*(0.4863620081*D20+0.4455809638*D20+0.0356254898*D21+0.0324315384))+D29*('Product and Cost'!$D$34*D21*Assumptions!$B$88+'Product and Cost'!$B$34*(0.4863620081*D20+0.4455809638*D20+0.0356254898*D21+0.0324315384)) -> 53647.982 | E32: =E22*('Product and Cost'!$D$27*E21*Assumptions!$B$88+'Product and Cost'!$B$27*(0.4863620081*E20+0.4455809638*E20+0.0356254898*E21+0.0324315384))+E23*('Product and Cost'!$D$28*E21*Assumptions!$B$88+'Product and Cost'!$B$28*(0.4863620081*E20+0.4455809638*E20+0.0356254898*E21+0.0324315384))+E24*('Product and Cost'!$D$29*E21*Assumptions!$B$88+'Product and Cost'!$B$29*(0.4863620081*E20+0.4455809638*E20+0.0356254898*E21+0.0324315384))+E25*('Product and Cost'!$D$30*E21*Assumptions!$B$88+'Product and Cost'!$B$30*(0.4863620081*E20+0.4455809638*E20+0.0356254898*E21+0.0324315384))+E26*('Product and Cost'!$D$31*E21*Assumptions!$B$88+'Product and Cost'!$B$31*(0.4863620081*E20+0.4455809638*E20+0.0356254898*E21+0.0324315384))+E27*('Product and Cost'!$D$32*E21*Assumptions!$B$88+'Product and Cost'!$B$32*(0.4863620081*E20+0.4455809638*E20+0.0356254898*E21+0.0324315384))+E28*('Product and Cost'!$D$33*E21*Assumptions!$B$88+'Product and Cost'!$B$33*(0.4863620081*E20+0.4455809638*E20+0.0356254898*E21+0.0324315384))+E29*('Product and Cost'!$D$34*E21*Assumptions!$B$88+'Product and Cost'!$B$34*(0.4863620081*E20+0.4455809638*E20+0.0356254898*E21+0.0324315384)) -> 58815.401 | F32: =F22*('Product and Cost'!$D$27*F21*Assumptions!$B$88+'Product and Cost'!$B$27*(0.4863620081*F20+0.4455809638*F20+0.0356254898*F21+0.0324315384))+F23*('Product and Cost'!$D$28*F21*Assumptions!$B$88+'Product and Cost'!$B$28*(0.4863620081*F20+0.4455809638*F20+0.0356254898*F21+0.0324315384))+F24*('Product and Cost'!$D$29*F21*Assumptions!$B$88+'Product and Cost'!$B$29*(0.4863620081*F20+0.4455809638*F20+0.0356254898*F21+0.0324315384))+F25*('Product and Cost'!$D$30*F21*Assumptions!$B$88+'Product and Cost'!$B$30*(0.4863620081*F20+0.4455809638*F20+0.0356254898*F21+0.0324315384))+F26*('Product and Cost'!$D$31*F21*Assumptions!$B$88+'Product and Cost'!$B$31*(0.4863620081*F20+0.4455809638*F20+0.0356254898*F21+0.0324315384))+F27*('Product and Cost'!$D$32*F21*Assumptions!$B$88+'Product and Cost'!$B$32*(0.4863620081*F20+0.4455809638*F20+0.0356254898*F21+0.0324315384))+F28*('Product and Cost'!$D$33*F21*Assumptions!$B$88+'Product and Cost'!$B$33*(0.4863620081*F20+0.4455809638*F20+0.0356254898*F21+0.0324315384))+F29*('Product and Cost'!$D$34*F21*Assumptions!$B$88+'Product and Cost'!$B$34*(0.4863620081*F20+0.4455809638*F20+0.0356254898*F21+0.0324315384)) -> 63847.573 | G32: =G22*('Product and Cost'!$D$27*G21*Assumptions!$B$88+'Product and Cost'!$B$27*(0.4863620081*G20+0.4455809638*G20+0.0356254898*G21+0.0324315384))+G23*('Product and Cost'!$D$28*G21*Assumptions!$B$88+'Product and Cost'!$B$28*(0.4863620081*G20+0.4455809638*G20+0.0356254898*G21+0.0324315384))+G24*('Product and Cost'!$D$29*G21*Assumptions!$B$88+'Product and Cost'!$B$29*(0.4863620081*G20+0.4455809638*G20+0.0356254898*G21+0.0324315384))+G25*('Product and Cost'!$D$30*G21*Assumptions!$B$88+'Product and Cost'!$B$30*(0.4863620081*G20+0.4455809638*G20+0.0356254898*G21+0.0324315384))+G26*('Product and Cost'!$D$31*G21*Assumptions!$B$88+'Product and Cost'!$B$31*(0.4863620081*G20+0.4455809638*G20+0.0356254898*G21+0.0324315384))+G27*('Product and Cost'!$D$32*G21*Assumptions!$B$88+'Product and Cost'!$B$32*(0.4863620081*G20+0.4455809638*G20+0.0356254898*G21+0.0324315384))+G28*('Product and Cost'!$D$33*G21*Assumptions!$B$88+'Product and Cost'!$B$33*(0.4863620081*G20+0.4455809638*G20+0.0356254898*G21+0.0324315384))+G29*('Product and Cost'!$D$34*G21*Assumptions!$B$88+'Product and Cost'!$B$34*(0.4863620081*G20+0.4455809638*G20+0.0356254898*G21+0.0324315384)) -> 68797.186
A33: GROSS PROFIT | C33: =C31-C32+$B$7*C31 -> 4549.6506 | D33: =D31-D32+$B$7*D31 -> 4784.1849 | E33: =E31-E32+$B$7*E31 -> 4957.236 | F33: =F31-F32+$B$7*F31 -> 5104.6058 | G33: =G31-G32+$B$7*G31 -> 5180.6573
A34: Gross margin | C34: =C33/C31 -> 0.086101075 | D34: =D33/D31 -> 0.081875877 | E34: =E33/E31 -> 0.077732962 | F34: =F33/F31 -> 0.074031102 | G34: =G33/G31 -> 0.07002985
A35: Operating expense | C35: =('Base Year'!$B$28*C20)+('Base Year'!$B$29*C20*C30/'Product and Cost'!$E$14)+('Base Year'!$B$30*C20)+('Base Year'!$B$31*C20) -> 2007.6668 | D35: =('Base Year'!$B$28*D20)+('Base Year'!$B$29*D20*D30/'Product and Cost'!$E$14)+('Base Year'!$B$30*D20)+('Base Year'!$B$31*D20) -> 2276.2978 | E35: =('Base Year'!$B$28*E20)+('Base Year'!$B$29*E20*E30/'Product and Cost'!$E$14)+('Base Year'!$B$30*E20)+('Base Year'!$B$31*E20) -> 2545.6212 | F35: =('Base Year'!$B$28*F20)+('Base Year'!$B$29*F20*F30/'Product and Cost'!$E$14)+('Base Year'!$B$30*F20)+('Base Year'!$B$31*F20) -> 2807.7788 | G35: =('Base Year'!$B$28*G20)+('Base Year'!$B$29*G20*G30/'Product and Cost'!$E$14)+('Base Year'!$B$30*G20)+('Base Year'!$B$31*G20) -> 3082.21
A36: EBITDA | C36: =C33-C35 -> 2541.9838 | D36: =D33-D35 -> 2507.8872 | E36: =E33-E35 -> 2411.6148 | F36: =F33-F35 -> 2296.827 | G36: =G33-G35 -> 2098.4473
A37: Capital expenditure — maintenance + growth | C37: ='Base Year'!$B$43*C20+MAX(C30-'Product and Cost'!$E$14,0)*1947.901031*C20 -> 280.932 | D37: ='Base Year'!$B$43*D20+MAX(D30-C30,0)*1947.901031*D20 -> 307.36758 | E37: ='Base Year'!$B$43*E20+MAX(E30-D30,0)*1947.901031*E20 -> 328.63939 | F37: ='Base Year'!$B$43*F20+MAX(F30-E30,0)*1947.901031*F20 -> 351.14675 | G37: ='Base Year'!$B$43*G20+MAX(G30-F30,0)*1947.901031*G20 -> 375.37218
A38: Fixed assets at cost, closing | C38: =(Assumptions!$B$70+Assumptions!$B$71)/10^6+C37 -> 3429.0659 | D38: =C38+D37 -> 3736.4335 | E38: =D38+E37 -> 4065.0729 | F38: =E38+F37 -> 4416.2196 | G38: =F38+G37 -> 4791.5918
A39: Depreciation — rolls off the asset register | C39: =(Assumptions!$B$70+Assumptions!$B$71)/10^6/'Base Year'!$B$42 -> 173.80885 | D39: =C38/'Base Year'!$B$42 -> 189.31914 | E39: =D38/'Base Year'!$B$42 -> 206.28895 | F39: =E38/'Base Year'!$B$42 -> 224.43317 | G39: =F38/'Base Year'!$B$42 -> 243.82002
A40: Fixed assets, net book, closing | C40: =(Assumptions!$B$69+Assumptions!$B$71)/10^6+C37-C39 -> 1407.4626 | D40: =C40+D37-D39 -> 1525.5111 | E40: =D40+E37-E39 -> 1647.8615 | F40: =E40+F37-F39 -> 1774.5751 | G40: =F40+G37-G39 -> 1906.1272
A41: EBIT | C41: =C36-C39 -> 2368.175 | D41: =D36-D39 -> 2318.568 | E41: =E36-E39 -> 2205.3259 | F41: =F36-F39 -> 2072.3938 | G41: =G36-G39 -> 1854.6273
A42: NOPAT before the profit share | C42: =C41*(1-Assumptions!$B$87) -> 1835.3356 | D42: =D41*(1-Assumptions!$B$87) -> 1796.8902 | E42: =E41*(1-Assumptions!$B$87) -> 1709.1276 | F42: =F41*(1-Assumptions!$B$87) -> 1606.1052 | G42: =G41*(1-Assumptions!$B$87) -> 1437.3361
A43: less employees' profit share and board bonuses | C43: =MAX(C42,0)*'Base Year'!$B$40 -> 96.760801 | D43: =MAX(D42,0)*'Base Year'!$B$40 -> 94.73392 | E43: =MAX(E42,0)*'Base Year'!$B$40 -> 90.106981 | F43: =MAX(F42,0)*'Base Year'!$B$40 -> 84.675535 | G43: =MAX(G42,0)*'Base Year'!$B$40 -> 75.777855
...

Sheet Sensitivity
A1: Sensitivity — every grid point is the whole engine, again, in formulas
A2: The previous edition pasted these rows because each point is a whole-model re-run and its builder could not express a re-run inside a grid. Three of the pasted rows turned out not to reproduce: a working-capital row whose grid was never sorted, a beta row whose centre did not return the base case, and a volume row whose label described a different scenario from the one it ran. None of that can happen here, because there is nothing to paste.
A4: Summary — every cell points at its own live block below
A5: Gross margin, shifted on every forecast year
A6: grid point 1: -1.0% | C6: -0.01 | I6: =B95 -> 3.5279033
A7: grid point 2: -0.5% | C7: -0.005 | I7: =B144 -> 4.5139377
A8: grid point 3: +0.0% | C8: 0 | I8: =B193 -> 5.4999722 | J8: =B193-Forecast!B65 -> 0
A9: grid point 4: +0.5% | C9: 0.005 | I9: =B242 -> 6.4860066
A10: grid point 5: +1.0% | C10: 0.01 | I10: =B291 -> 7.4720411
A12: Volume growth path, as a multiple of the assumed path
A13: grid point 1: 0.00x | B13: 0 | I13: =B340 -> 4.827847
A14: grid point 2: 0.50x | B14: 0.5 | I14: =B389 -> 5.1577708
A15: grid point 3: 1.00x | B15: 1 | I15: =B438 -> 5.4999722 | J15: =B438-Forecast!B65 -> 0
A16: grid point 4: 1.50x | B16: 1.5 | I16: =B487 -> 5.8548333
A17: grid point 5: 2.00x | B17: 2 | I17: =B536 -> 6.222745
A19: Realisation path, as a multiple of the assumed path
A20: grid point 1: 0.90x | D20: 0.9 | I20: =B585 -> 4.661187
A21: grid point 2: 0.95x | D21: 0.95 | I21: =B634 -> 5.0782512
A22: grid point 3: 1.00x | D22: 1 | I22: =B683 -> 5.4999722 | J22: =B683-Forecast!B65 -> 0
A23: grid point 4: 1.05x | D23: 1.05 | I23: =B732 -> 5.9263909
A24: grid point 5: 1.10x | D24: 1.1 | I24: =B781 -> 6.3575484
A26: Beta
A27: grid point 1: 0.6000 | F27: 0.27533624 | G27: 0.16198219 | I27: =B830 -> 6.3325863
A28: grid point 2: 0.8000 | F28: 0.29909374 | G28: 0.17458219 | I28: =B879 -> 5.8089209
A29: grid point 3: 0.9405 | F29: 0.31578339 | G29: 0.18343369 | I29: =B928 -> 5.4999722 | J29: =B928-Forecast!B65 -> -8.8817842e-16
A30: grid point 4: 1.1500 | F30: 0.34066938 | G30: 0.19663219 | I30: =B977 -> 5.1083087
A31: grid point 5: 1.3000 | F31: 0.35848751 | G31: 0.20608219 | I31: =B1026 -> 4.8684118
A33: Working-capital cycle, as a multiple of the solved days
A34: grid point 1: 0.50x | E34: 0.5 | I34: =B1075 -> 6.5772729
A35: grid point 2: 0.75x | E35: 0.75 | I35: =B1124 -> 6.0386225
A36: grid point 3: 1.00x | E36: 1 | I36: =B1173 -> 5.4999722 | J36: =B1173-Forecast!B65 -> 0
A37: grid point 4: 1.25x | E37: 1.25 | I37: =B1222 -> 4.9613218
A38: grid point 5: 1.50x | E38: 1.5 | I38: =B1271 -> 4.4226715
A40: Terminal growth
A41: grid point 1: 3.0% | H41: 0.03 | I41: =B1320 -> 5.4815809
A42: grid point 2: 4.0% | H42: 0.04 | I42: =B1369 -> 5.4901354
A43: grid point 3: 5.0% | H43: 0.05 | I43: =B1418 -> 5.4999722 | J43: =B1418-Forecast!B65 -> 0
A44: grid point 4: 6.0% | H44: 0.06 | I44: =B1467 -> 5.5114028
A45: grid point 5: 7.0% | H45: 0.07 | I45: =B1516 -> 5.5248488
A47: GATE — every row must return the base case at its own base point
...

Sheet Lenses
A1: Four lenses, one bridge, one valuation date
A2: Lens 2 is on the TRAILING metric so it borrows no discount factor from lens 1. Lens 3 is forward-dated and is therefore DISCOUNTED to the valuation date at the cost of equity, with net cash added at face outside the multiple. Lens 4 uses the same cost-of-equity glide lens 1 uses. All formulas.
A5: Base-year EBITDA | B5: ='Base Year'!B20-'Base Year'!B28-'Base Year'!B29-'Base Year'!B30-'Base Year'!B31+'Base Year'!B32 -> 2629.1966
A6: Enterprise value at spot | B6: =Assumptions!$B$7*Assumptions!$B$8+(Assumptions!$B$82+Assumptions!$B$83-Assumptions!$B$79)/10^6 -> 9310.1051
A7: The company's OWN trailing EV/EBITDA | B7: =B6/B5 -> 3.5410457
A8: Justified multiple = trailing x (1 + re-rating) | B8: =B7*(1+Assumptions!$B$92) -> 3.5410457
A10: LENS 1 — discounted cash flow | B10: =Forecast!B65 -> 5.4999722
A11: LENS 2 — relative multiples, on the trailing metric | B11: =(B8*B5-(Assumptions!$B$82+Assumptions!$B$83-Assumptions!$B$79)/10^6)*(1-'Base Year'!B41)-(Assumptions!$B$78+Assumptions!$B$77-Assumptions!$B$81-Assumptions!$B$80)/10^6 -> 10509.388 | C11: =B11/Assumptions!$B$8 -> 8.1373506
A12: LENS 3 — normalised earnings power, DISCOUNTED | B12: =Forecast!E41 -> 2205.3259 | C12: =B12*(1-Assumptions!$B$87)*(1-'Base Year'!B40)*(1-'Base Year'!B41)/Assumptions!$B$8 -> 1.2127518 | D12: =C12*Assumptions!$B$91/(1+Forecast!B10)^2.4+((Assumptions!$B$79-Assumptions!$B$82-Assumptions!$B$83-Assumptions!$B$78-Assumptions!$B$77)/10^6)/Assumptions!$B$8 -> 5.8295249
A13: LENS 4 — book value and sustainable return | B13: =Assumptions!$B$84/10^6/Assumptions!$B$8 -> 3.7094045 | C13: =0.2366443942 -> 0.23664439 | D13: =(Assumptions!$B$90-Assumptions!$B$89)/(C13-Assumptions!$B$89) -> 1.2322899 | E13: =B13*D13 -> 4.5710617
A15: WEIGHTED CENTRAL | B15: =B10*Assumptions!$B$168+C11*Assumptions!$B$169+D12*Assumptions!$B$170+E13*Assumptions!$B$171 -> 5.9540218
A16: against spot | B16: =B15/Assumptions!$B$7-1 -> -0.34571189
A18: The weighted range on the Summary sheet is the bear and bull columns weighted with these same weights. The previous edition labelled a row "weighted central" and then took the minimum and maximum across the four lenses — both of which came from the cash-flow lens alone — so the word "weighted" applied to the centre and not to the ends, and the published spread was about two and a half times too wide.
