Workbook

Sheet READ FIRST
A1: Testahil · Independent Valuation Study — Educational Analysis · Not investment advice
A4: Apple Inc. (NASDAQ: AAPL) — valuation model workbook
A6: This workbook accompanies the Testahil valuation study. It is an educational model, not investment advice,
A7: not a recommendation, and not a price target. Testahil publishes fair-value ranges and probability
A8: distributions — never a buy / sell / hold rating.
A10: How the model is wired
A11: • The Assumptions sheet is the single blue-cell input layer. Every blue cell is an input you can change.
A12: • All downstream sheets link back to Assumptions — change one growth rate, margin, multiple or the WACC
A13: and the whole model reprices.
A14: • Black text = formulas / calculations. Blue text = hard-coded inputs. Green text = cross-sheet links.
A15: • Historical figures (FY2023–FY2025) are from Apple's Form 10-K filings; forecasts (FY2026E–FY2030E)
A16: are the model's own, driven from Assumptions.
... A23: The preparer may hold, and may in the future take or dispose of, a position in the security discussed.

Sheet Summary
A1: Summary — Apple Inc. (NASDAQ: AAPL)
A3: Item | B3: Value
A4: Spot price (USD) | B4: =Assumptions!$B$4
A5: Shares outstanding (bn) | B5: =Assumptions!$B$5
A6: Market cap (USD bn) | B6: =Assumptions!$B$4*Assumptions!$B$5
A7: Weighted central fair value — base (USD) | B7: ='Fundamental Valuation'!C8
A8: Central range — bear→bull (USD) | B8: ='Fundamental Valuation'!B8&" – "&TEXT('Fundamental Valuation'!D8,"$0.00")
A9: Spot vs central (base) | B9: ='Fundamental Valuation'!C10
A10: DCF fair value — base (USD) | B10: =DCF!B23
A11: WACC | Ke = rf+β·ERP | g | B11: =Assumptions!$B$11
A12: Monte Carlo — P(above spot) T+60 | B12: 0.40154
A13: Monte Carlo — median T+60 (USD) | B13: 302.58906
A14: Monte Carlo — 50% band T+60 (USD) | B14: 276 – 333
A16: Educational analysis — not investment advice, not a rating, not a price target.

Sheet Fundamental Valuation
A1: Fundamental valuation — four-lens synthesis
A3: Lens | B3: Bear | C3: Base | D3: Bull | E3: Weight
A4: Consolidated DCF | B4: 143.1 | C4: =DCF!B23 | D4: 199.8 | E4: =Assumptions!B35
A5: Relative multiples | B5: ='Relative & Normalized'!B6 | C5: ='Relative & Normalized'!C6 | D5: ='Relative & Normalized'!D6 | E5: =Assumptions!B36
A6: Normalized earnings | B6: ='Relative & Normalized'!B9 | C6: ='Relative & Normalized'!C9 | D6: ='Relative & Normalized'!D9 | E6: =Assumptions!B37
A7: Segment sum-of-parts | B7: 157 | C7: =SOTP!B12 | D7: 210.9 | E7: =Assumptions!B38
A8: Weighted central | B8: =SUMPRODUCT(B4:B7,$E4:$E7) | C8: =SUMPRODUCT(C4:C7,$E4:$E7) | D8: =SUMPRODUCT(D4:D7,$E4:$E7)
A9: Spot price | C9: =Assumptions!$B$4
A10: Spot vs central (base) | C10: =C9/C8-1

Sheet Assumptions
A1: Assumptions — the single blue-cell input layer
A3: Market data & cost of capital | B3: Value
A4: Spot price (USD) | B4: 313.09
A5: Shares outstanding (bn) | B5: 14.776
A6: Net cash (USD bn) | B6: 34.4
A7: Risk-free rate (rf) | B7: 0.045
A8: Equity risk premium (ERP) | B8: 0.05
A9: Beta | B9: 1.1
A10: Cost of equity Ke = rf + β·ERP | B10: =B7+B9*B8
A11: WACC (base) | B11: 0.095
A12: Terminal growth g (base) | B12: 0.035
A13: Normalized tax rate | B13: 0.16
A15: Segment revenue growth (YoY) | B15: FY26E | C15: FY27E | D15: FY28E | E15: FY29E | F15: FY30E
A16: iPhone | B16: 0.04 | C16: 0.03 | D16: 0.03 | E16: 0.025 | F16: 0.02
A17: Mac | B17: 0.05 | C17: 0.04 | D17: 0.04 | E17: 0.03 | F17: 0.03
A18: iPad | B18: 0.03 | C18: 0.03 | D18: 0.02 | E18: 0.02 | F18: 0.02
A19: Wearables | B19: 0.01 | C19: 0.02 | D19: 0.03 | E19: 0.03 | F19: 0.03
A20: Services | B20: 0.13 | C20: 0.12 | D20: 0.11 | E20: 0.1 | F20: 0.1
A21: EBIT margin | B21: 0.325 | C21: 0.33 | D21: 0.335 | E21: 0.34 | F21: 0.345
A22: Depreciation & amort. (USD bn) | B22: 12.5 | C22: 13.2 | D22: 13.9 | E22: 14.6 | F22: 15.3
A23: Capex (USD bn) | B23: 12.5 | C23: 13 | D23: 13.5 | E23: 14 | F23: 14.5
A24: Δ net working capital (USD bn) | B24: 2 | C24: 2 | D24: 2 | E24: 2 | F24: 2
A25: Diluted shares (bn) | B25: 14.55 | C25: 14.15 | D25: 13.8 | E25: 13.5 | F25: 13.25
A27: Valuation-lens inputs | B27: Bear | C27: Base | D27: Bull
A28: Forward P/E multiple (×) | B28: 26 | C28: 30 | D28: 34
A29: Normalized EPS (USD) | B29: 7.9 | C29: Normalized P/E (×)
A30: Normalized P/E (×) | B30: 27 | C30: 32 | D30: 36
A31: Services EBIT margin (of svc rev) | B31: 0.42
A32: Products EBIT margin (of prod rev) | B32: 0.3
A33: Services EV / EBIT multiple (×) | B33: 22 | C33: 26 | D33: 30
A34: Products EV / EBIT multiple (×) | B34: 12 | C34: 14 | D34: 16
A35: Lens weight — DCF | B35: 0.3
A36: Lens weight — Relative | B36: 0.3
A37: Lens weight — Normalized | B37: 0.2
A38: Lens weight — Segment SOTP | B38: 0.2
A40: Monte Carlo parameters | B40: Value
A41: Paths | B41: 50000
A42: Seed | B42: 42
A43: Horizon (trading days) | B43: 60
A44: Diffusion vol — YZ-HAR (ann.) | B44: 0.28432086
...

Sheet SOTP
A1: Segment sum-of-parts — Services vs Products (base case)
B3: USD bn
A4: Services revenue (FY26E) | B4: =Segments!E8
A5: Services EBIT (× margin) | B5: =B4*Assumptions!B31
A6: Services value (× EV/EBIT base) | B6: =B5*Assumptions!C33
A7: Products revenue (FY26E) | B7: =Segments!E11
A8: Products EBIT (× margin) | B8: =B7*Assumptions!B32
A9: Products value (× EV/EBIT base) | B9: =B8*Assumptions!C34
A10: + Net cash | B10: =Assumptions!$B$6
A11: Equity value | B11: =B6+B9+B10
A12: Fair value per share (USD) | B12: =B11/Assumptions!$B$5

Sheet Segments
A1: Segment revenue — actual (10-K) and forecast
A3: USD bn | B3: FY23 | C3: FY24 | D3: FY25 | E3: FY26E | F3: FY27E | G3: FY28E | H3: FY29E | I3: FY30E
A4: iPhone | B4: 200.583 | C4: 201.183 | D4: 209.59 | E4: =D4*(1+Assumptions!$B$16) | F4: =E4*(1+Assumptions!$C$16) | G4: =F4*(1+Assumptions!$D$16) | H4: =G4*(1+Assumptions!$E$16) | I4: =H4*(1+Assumptions!$F$16)
A5: Mac | B5: 29.357 | C5: 29.984 | D5: 33.71 | E5: =D5*(1+Assumptions!$B$17) | F5: =E5*(1+Assumptions!$C$17) | G5: =F5*(1+Assumptions!$D$17) | H5: =G5*(1+Assumptions!$E$17) | I5: =H5*(1+Assumptions!$F$17)
A6: iPad | B6: 28.3 | C6: 26.694 | D6: 28.02 | E6: =D6*(1+Assumptions!$B$18) | F6: =E6*(1+Assumptions!$C$18) | G6: =F6*(1+Assumptions!$D$18) | H6: =G6*(1+Assumptions!$E$18) | I6: =H6*(1+Assumptions!$F$18)
A7: Wearables | B7: 39.845 | C7: 37.005 | D7: 35.69 | E7: =D7*(1+Assumptions!$B$19) | F7: =E7*(1+Assumptions!$C$19) | G7: =F7*(1+Assumptions!$D$19) | H7: =G7*(1+Assumptions!$E$19) | I7: =H7*(1+Assumptions!$F$19)
A8: Services | B8: 85.2 | C8: 96.169 | D8: 109.16 | E8: =D8*(1+Assumptions!$B$20) | F8: =E8*(1+Assumptions!$C$20) | G8: =F8*(1+Assumptions!$D$20) | H8: =G8*(1+Assumptions!$E$20) | I8: =H8*(1+Assumptions!$F$20)
A9: Total revenue | B9: =SUM(B4:B8) | C9: =SUM(C4:C8) | D9: =SUM(D4:D8) | E9: =SUM(E4:E8) | F9: =SUM(F4:F8) | G9: =SUM(G4:G8) | H9: =SUM(H4:H8) | I9: =SUM(I4:I8)
A10: Services % of revenue | B10: =B8/B9 | C10: =C8/C9 | D10: =D8/D9 | E10: =E8/E9 | F10: =F8/F9 | G10: =G8/G9 | H10: =H8/H9 | I10: =I8/I9
A11: Products revenue | B11: =B9-B8 | C11: =C9-C8 | D11: =D9-D8 | E11: =E9-E8 | F11: =F9-F8 | G11: =G9-G8 | H11: =H9-H8 | I11: =I9-I8

Sheet Relative & Normalized
A1: Relative multiples & normalized earnings power
B3: Bear | C3: Base | D3: Bull
A4: Forward EPS FY26E (USD) | B4: ='Income Statement'!E16 | C4: ='Income Statement'!E16 | D4: ='Income Statement'!E16
A5: Forward P/E multiple (×) | B5: =Assumptions!B28 | C5: =Assumptions!C28 | D5: =Assumptions!D28
A6: Relative fair value (USD) | B6: =B4*B5 | C6: =C4*C5 | D6: =D4*D5
A7: Normalized EPS (USD) | B7: =Assumptions!B29 | C7: =Assumptions!B29 | D7: =Assumptions!B29
A8: Normalized P/E (×) | B8: =Assumptions!B30 | C8: =Assumptions!C30 | D8: =Assumptions!D30
A9: Normalized fair value (USD) | B9: =B7*B8 | C9: =C7*C8 | D9: =D7*D8

Sheet DCF
A1: Discounted cash flow — consolidated, five-year explicit (USD bn)
A3: USD bn | B3: FY26E | C3: FY27E | D3: FY28E | E3: FY29E | F3: FY30E
A4: Revenue | B4: ='Income Statement'!E4 | C4: ='Income Statement'!F4 | D4: ='Income Statement'!G4 | E4: ='Income Statement'!H4 | F4: ='Income Statement'!I4
A5: EBITDA | B5: ='Income Statement'!E11 | C5: ='Income Statement'!F11 | D5: ='Income Statement'!G11 | E5: ='Income Statement'!H11 | F5: ='Income Statement'!I11
A6: Depreciation & amortization | B6: ='Income Statement'!E10 | C6: ='Income Statement'!F10 | D6: ='Income Statement'!G10 | E6: ='Income Statement'!H10 | F6: ='Income Statement'!I10
A7: EBIT | B7: ='Income Statement'!E8 | C7: ='Income Statement'!F8 | D7: ='Income Statement'!G8 | E7: ='Income Statement'!H8 | F7: ='Income Statement'!I8
A8: NOPAT = EBIT × (1 − t) | B8: =B7*(1-Assumptions!$B$13) | C8: =C7*(1-Assumptions!$B$13) | D8: =D7*(1-Assumptions!$B$13) | E8: =E7*(1-Assumptions!$B$13) | F8: =F7*(1-Assumptions!$B$13)
A9: + Depreciation & amortization | B9: =B6 | C9: =C6 | D9: =D6 | E9: =E6 | F9: =F6
A10: − Capex | B10: =-Assumptions!B23 | C10: =-Assumptions!C23 | D10: =-Assumptions!D23 | E10: =-Assumptions!E23 | F10: =-Assumptions!F23
A11: − Δ working capital | B11: =-Assumptions!B24 | C11: =-Assumptions!C24 | D11: =-Assumptions!D24 | E11: =-Assumptions!E24 | F11: =-Assumptions!F24
A12: Free cash flow to firm (FCFF) | B12: =B8+B9+B10+B11 | C12: =C8+C9+C10+C11 | D12: =D8+D9+D10+D11 | E12: =E8+E9+E10+E11 | F12: =F8+F9+F10+F11
A13: Discount factor @ WACC | B13: =1/(1+Assumptions!$B$11)^1 | C13: =1/(1+Assumptions!$B$11)^2 | D13: =1/(1+Assumptions!$B$11)^3 | E13: =1/(1+Assumptions!$B$11)^4 | F13: =1/(1+Assumptions!$B$11)^5
A14: PV of FCFF | B14: =B12*B13 | C14: =C12*C13 | D14: =D12*D13 | E14: =E12*E13 | F14: =F12*F13
A16: Sum PV of explicit FCFF | B16: =SUM(B14:F14)
A17: Terminal value = FCFF₅·(1+g)/(WACC−g) | B17: =F12*(1+Assumptions!$B$12)/(Assumptions!$B$11-Assumptions!$B$12)
A18: PV of terminal value | B18: =B17/(1+Assumptions!$B$11)^5
A19: Enterprise value | B19: =B16+B18
A20: TV as % of EV | B20: =B18/B19
A21: + Net cash | B21: =Assumptions!$B$6
A22: Equity value | B22: =B19+B21
A23: Fair value per share (USD) | B23: =B22/Assumptions!$B$5
A24: Ke = rf + β·ERP | WACC | g | B24: =Assumptions!$B$10 | C24: =Assumptions!$B$11 | D24: =Assumptions!$B$12

Sheet Income Statement
A1: Income statement — 3 years actual + 5-year forecast (USD bn)
A3: USD bn | B3: FY23 | C3: FY24 | D3: FY25 | E3: FY26E | F3: FY27E | G3: FY28E | H3: FY29E | I3: FY30E
A4: Revenue | B4: =Segments!B9 | C4: =Segments!C9 | D4: =Segments!D9 | E4: =Segments!E9 | F4: =Segments!F9 | G4: =Segments!G9 | H4: =Segments!H9 | I4: =Segments!I9
A5: Gross profit | B5: 169.148 | C5: 180.683 | D5: 195.201 | E5: =E4*0.469 | F5: =F4*0.472 | G5: =G4*0.475 | H5: =H4*0.478 | I5: =I4*0.48
A6: Gross margin | B6: =B5/B4 | C6: =C5/C4 | D6: =D5/D4 | E6: =E5/E4 | F6: =F5/F4 | G6: =G5/G4 | H6: =H5/H4 | I6: =I5/I4
A7: Operating expenses | B7: 54.847 | C7: 57.467 | D7: 62.151 | E7: =E5-E8 | F7: =F5-F8 | G7: =G5-G8 | H7: =H5-H8 | I7: =I5-I8
A8: Operating income (EBIT) | B8: 114.301 | C8: 123.216 | D8: 133.05 | E8: =E4*Assumptions!$B$21 | F8: =F4*Assumptions!$C$21 | G8: =G4*Assumptions!$D$21 | H8: =H4*Assumptions!$E$21 | I8: =I4*Assumptions!$F$21
A9: EBIT margin | B9: =B8/B4 | C9: =C8/C4 | D9: =D8/D4 | E9: =E8/E4 | F9: =F8/F4 | G9: =G8/G4 | H9: =H8/H4 | I9: =I8/I4
A10: Depreciation & amortization | B10: 11.519 | C10: 11.445 | D10: 12 | E10: =Assumptions!B22 | F10: =Assumptions!C22 | G10: =Assumptions!D22 | H10: =Assumptions!E22 | I10: =Assumptions!F22
A11: EBITDA | B11: =B8+B10 | C11: =C8+C10 | D11: =D8+D10 | E11: =E8+E10 | F11: =F8+F10 | G11: =G8+G10 | H11: =H8+H10 | I11: =I8+I10
A12: Pre-tax income | B12: 113.736 | C12: 123.485 | D12: 132.729 | E12: =E8 | F12: =F8 | G12: =G8 | H12: =H8 | I12: =I8
A13: Income tax | B13: 16.741 | C13: 29.749 | D13: 20.719 | E13: =E12*Assumptions!$B$13 | F13: =F12*Assumptions!$B$13 | G13: =G12*Assumptions!$B$13 | H13: =H12*Assumptions!$B$13 | I13: =I12*Assumptions!$B$13
A14: Net income | B14: 96.995 | C14: 93.736 | D14: 112.01 | E14: =E12-E13 | F14: =F12-F13 | G14: =G12-G13 | H14: =H12-H13 | I14: =I12-I13
A15: Diluted shares (bn) | B15: 15.813 | C15: 15.408 | D15: 15 | E15: =Assumptions!B25 | F15: =Assumptions!C25 | G15: =Assumptions!D25 | H15: =Assumptions!E25 | I15: =Assumptions!F25
A16: Diluted EPS (USD) | B16: =B14/B15 | C16: =C14/C15 | D16: =D14/D15 | E16: =E14/E15 | F16: =F14/F15 | G16: =G14/G15 | H16: =H14/H15 | I16: =I14/I15

Sheet Balance Sheet
A1: Balance sheet — 3 years actual + 5-year forecast (USD bn)
A3: USD bn | B3: FY23 | C3: FY24 | D3: FY25 | E3: FY26E | F3: FY27E | G3: FY28E | H3: FY29E | I3: FY30E
A4: Cash & marketable securities | B4: 166 | C4: 140.8 | D4: 132.4 | E4: =D4 | F4: =E4 | G4: =F4 | H4: =G4 | I4: =H4
A5: Other assets | B5: 186.6 | C5: 224.2 | D5: 212.6 | E5: =D5*1.02 | F5: =E5*1.02 | G5: =F5*1.02 | H5: =G5*1.02 | I5: =H5*1.02
A6: Total assets | B6: =B4+B5 | C6: =C4+C5 | D6: =D4+D5 | E6: =E4+E5 | F6: =F4+F5 | G6: =G4+G5 | H6: =H4+H5 | I6: =I4+I5
A7: Total debt | B7: 111.1 | C7: 106.6 | D7: 98 | E7: =D7 | F7: =E7 | G7: =F7 | H7: =G7 | I7: =H7
A8: Other liabilities | B8: 179.3 | C8: 201.4 | D8: 186 | E8: =D8 | F8: =E8 | G8: =F8 | H8: =G8 | I8: =H8
A9: Total liabilities | B9: =B7+B8 | C9: =C7+C8 | D9: =D7+D8 | E9: =E7+E8 | F9: =F7+F8 | G9: =G7+G8 | H9: =H7+H8 | I9: =I7+I8
A10: Shareholders' equity | B10: 62.146 | C10: 56.95 | D10: 61 | E10: =D10+'Income Statement'!E14*0.05 | F10: =E10+'Income Statement'!F14*0.05 | G10: =F10+'Income Statement'!G14*0.05 | H10: =G10+'Income Statement'!H14*0.05 | I10: =H10+'Income Statement'!I14*0.05

Sheet Cash Flow
A1: Cash flow — five-year forecast (USD bn)
A3: USD bn | B3: FY26E | C3: FY27E | D3: FY28E | E3: FY29E | F3: FY30E
A4: Net income | B4: ='Income Statement'!E14 | C4: ='Income Statement'!F14 | D4: ='Income Statement'!G14 | E4: ='Income Statement'!H14 | F4: ='Income Statement'!I14
A5: + Depreciation & amortization | B5: ='Income Statement'!E10 | C5: ='Income Statement'!F10 | D5: ='Income Statement'!G10 | E5: ='Income Statement'!H10 | F5: ='Income Statement'!I10
A6: − Δ working capital | B6: =-Assumptions!B24 | C6: =-Assumptions!C24 | D6: =-Assumptions!D24 | E6: =-Assumptions!E24 | F6: =-Assumptions!F24
A7: Operating cash flow | B7: =B4+B5+B6 | C7: =C4+C5+C6 | D7: =D4+D5+D6 | E7: =E4+E5+E6 | F7: =F4+F5+F6
A8: − Capex | B8: =-Assumptions!B23 | C8: =-Assumptions!C23 | D8: =-Assumptions!D23 | E8: =-Assumptions!E23 | F8: =-Assumptions!F23
A9: Free cash flow | B9: =B7+B8 | C9: =C7+C8 | D9: =D7+D8 | E9: =E7+E8 | F9: =F7+F8
A10: Capital returned (buyback + dividend) | B10: =-B9*0.95 | C10: =-C9*0.95 | D10: =-D9*0.95 | E10: =-E9*0.95 | F10: =-F9*0.95
A11: Net change in cash | B11: =B9+B10 | C11: =C9+C10 | D11: =D9+D10 | E11: =E9+E10 | F11: =F9+F10

Sheet Summary Financials
A1: Summary financials — links to statement sheets (USD bn)
A3: USD bn | B3: FY23 | C3: FY24 | D3: FY25 | E3: FY26E | F3: FY27E | G3: FY28E | H3: FY29E | I3: FY30E
A4: Revenue | B4: ='Income Statement'!B4 | C4: ='Income Statement'!C4 | D4: ='Income Statement'!D4 | E4: ='Income Statement'!E4 | F4: ='Income Statement'!F4 | G4: ='Income Statement'!G4 | H4: ='Income Statement'!H4 | I4: ='Income Statement'!I4
A5: Gross profit | B5: ='Income Statement'!B5 | C5: ='Income Statement'!C5 | D5: ='Income Statement'!D5 | E5: ='Income Statement'!E5 | F5: ='Income Statement'!F5 | G5: ='Income Statement'!G5 | H5: ='Income Statement'!H5 | I5: ='Income Statement'!I5
A6: EBIT | B6: ='Income Statement'!B8 | C6: ='Income Statement'!C8 | D6: ='Income Statement'!D8 | E6: ='Income Statement'!E8 | F6: ='Income Statement'!F8 | G6: ='Income Statement'!G8 | H6: ='Income Statement'!H8 | I6: ='Income Statement'!I8
A7: EBITDA | B7: ='Income Statement'!B11 | C7: ='Income Statement'!C11 | D7: ='Income Statement'!D11 | E7: ='Income Statement'!E11 | F7: ='Income Statement'!F11 | G7: ='Income Statement'!G11 | H7: ='Income Statement'!H11 | I7: ='Income Statement'!I11
A8: Net income | B8: ='Income Statement'!B14 | C8: ='Income Statement'!C14 | D8: ='Income Statement'!D14 | E8: ='Income Statement'!E14 | F8: ='Income Statement'!F14 | G8: ='Income Statement'!G14 | H8: ='Income Statement'!H14 | I8: ='Income Statement'!I14
A9: Diluted EPS (USD) | B9: ='Income Statement'!B16 | C9: ='Income Statement'!C16 | D9: ='Income Statement'!D16 | E9: ='Income Statement'!E16 | F9: ='Income Statement'!F16 | G9: ='Income Statement'!G16 | H9: ='Income Statement'!H16 | I9: ='Income Statement'!I16
A10: Revenue growth | C10: =C4/B4-1 | D10: =D4/C4-1 | E10: =E4/D4-1 | F10: =F4/E4-1 | G10: =G4/F4-1 | H10: =H4/G4-1 | I10: =I4/H4-1

Sheet Monte Carlo
A1: Monte Carlo — probability read & percentiles (50,000 paths, seed 42)
A3: The probability read (T+60) | B3: Value
A4: P(price above spot) | B4: 0.40154
A5: P(+10%) vs P(−10%) | B5: 18% vs 30%
A6: Up:down odds ratio | B6: 0.59326288
A7: Median level (USD) / % move | B7: 303 (-3.4%)
A8: 50% band 25th–75th (USD) | B8: 276 – 333
A9: Touch(+10%) / Touch(−10%) | B9: 37% / 50%
A11: Percentile (USD) | B11: 5th | C11: 25th | D11: 50th | E11: 75th | F11: 95th
A12: T+20 | B12: 267.17772 | C12: 293.22996 | D12: 309.94584 | E12: 327.07601 | F12: 356.3433
A13: T+60 | B13: 236.77552 | C13: 275.53699 | D13: 302.58906 | E13: 332.74858 | F13: 386.10493
A15: Touch ladder — level (USD) | B15: by T+20 | C15: by T+60
A16: 250 | B16: 0.01902 | C16: 0.1541
A17: 266 | B17: 0.06702 | C17: 0.2945
A18: 282 | B18: 0.20558 | C18: 0.5005
A19: 297 | B19: 0.47444 | C19: 0.71952
A20: 329 | B20: 0.41156 | C20: 0.59512
A21: 344 | B21: 0.17614 | C21: 0.37784
A22: 360 | B22: 0.06732 | C22: 0.22632
A23: 376 | B23: 0.026 | C23: 0.1335
A25: Diffusion sized by YZ-HAR; zero drift (international); Student-t(5) innovations; presentation-only read.

Sheet Sensitivity
A1: DCF sensitivity — fair value per share, WACC × terminal g (USD)
A3: WACC ↓ / g → | B3: 0.025 | C3: 0.03 | D3: 0.035 | E3: 0.04 | F3: 0.045
A4: 0.085 | B4: 157.7 | C4: 169.2 | D4: 183 | E4: 199.8 | F4: 220.9
A5: 0.09 | B5: 145.5 | C5: 155.1 | D5: 166.4 | E5: 179.9 | F5: 196.4
A6: 0.095 | B6: 135.1 | C6: 143.1 | D6: 152.5 | E6: 163.6 | F6: 176.9
A7: 0.1 | B7: 126.1 | C7: 132.9 | D7: 140.8 | E7: 150 | F7: 160.9
A8: 0.105 | B8: 118.2 | C8: 124 | D8: 130.8 | E8: 138.5 | F8: 147.5
A10: Base case shaded. Ke = rf + β·ERP = 10.0%.

Sheet Per-Share & Ratios
A1: Per-share & ratios dashboard
A3: Metric | B3: FY23 | C3: FY24 | D3: FY25 | E3: FY26E | F3: FY27E | G3: FY28E | H3: FY29E | I3: FY30E
A4: Diluted EPS (USD) | B4: ='Income Statement'!B16 | C4: ='Income Statement'!C16 | D4: ='Income Statement'!D16 | E4: ='Income Statement'!E16 | F4: ='Income Statement'!F16 | G4: ='Income Statement'!G16 | H4: ='Income Statement'!H16 | I4: ='Income Statement'!I16
A5: Revenue (USD bn) | B5: ='Income Statement'!B4 | C5: ='Income Statement'!C4 | D5: ='Income Statement'!D4 | E5: ='Income Statement'!E4 | F5: ='Income Statement'!F4 | G5: ='Income Statement'!G4 | H5: ='Income Statement'!H4 | I5: ='Income Statement'!I4
A6: EBITDA (USD bn) | B6: ='Income Statement'!B11 | C6: ='Income Statement'!C11 | D6: ='Income Statement'!D11 | E6: ='Income Statement'!E11 | F6: ='Income Statement'!F11 | G6: ='Income Statement'!G11 | H6: ='Income Statement'!H11 | I6: ='Income Statement'!I11
A7: Net income (USD bn) | B7: ='Income Statement'!B14 | C7: ='Income Statement'!C14 | D7: ='Income Statement'!D14 | E7: ='Income Statement'!E14 | F7: ='Income Statement'!F14 | G7: ='Income Statement'!G14 | H7: ='Income Statement'!H14 | I7: ='Income Statement'!I14
A8: Gross margin | B8: ='Income Statement'!B6 | C8: ='Income Statement'!C6 | D8: ='Income Statement'!D6 | E8: ='Income Statement'!E6 | F8: ='Income Statement'!F6 | G8: ='Income Statement'!G6 | H8: ='Income Statement'!H6 | I8: ='Income Statement'!I6
A9: EBIT margin | B9: ='Income Statement'!B9 | C9: ='Income Statement'!C9 | D9: ='Income Statement'!D9 | E9: ='Income Statement'!E9 | F9: ='Income Statement'!F9 | G9: ='Income Statement'!G9 | H9: ='Income Statement'!H9 | I9: ='Income Statement'!I9
A10: P/E (× spot) | B10: =Assumptions!$B$4/'Income Statement'!B16 | C10: =Assumptions!$B$4/'Income Statement'!C16 | D10: =Assumptions!$B$4/'Income Statement'!D16 | E10: =Assumptions!$B$4/'Income Statement'!E16 | F10: =Assumptions!$B$4/'Income Statement'!F16 | G10: =Assumptions!$B$4/'Income Statement'!G16 | H10: =Assumptions!$B$4/'Income Statement'!H16 | I10: =Assumptions!$B$4/'Income Statement'!I16
A11: EV/EBITDA (× spot) | B11: =(Assumptions!$B$4*Assumptions!$B$5-Assumptions!$B$6)/'Income Statement'!B11 | C11: =(Assumptions!$B$4*Assumptions!$B$5-Assumptions!$B$6)/'Income Statement'!C11 | D11: =(Assumptions!$B$4*Assumptions!$B$5-Assumptions!$B$6)/'Income Statement'!D11 | E11: =(Assumptions!$B$4*Assumptions!$B$5-Assumptions!$B$6)/'Income Statement'!E11 | F11: =(Assumptions!$B$4*Assumptions!$B$5-Assumptions!$B$6)/'Income Statement'!F11 | G11: =(Assumptions!$B$4*Assumptions!$B$5-Assumptions!$B$6)/'Income Statement'!G11 | H11: =(Assumptions!$B$4*Assumptions!$B$5-Assumptions!$B$6)/'Income Statement'!H11 | I11: =(Assumptions!$B$4*Assumptions!$B$5-Assumptions!$B$6)/'Income Statement'!I11
A12: FCF yield (spot mkt cap) | E12: ='Cash Flow'!B9/(Assumptions!$B$4*Assumptions!$B$5) | F12: ='Cash Flow'!C9/(Assumptions!$B$4*Assumptions!$B$5) | G12: ='Cash Flow'!D9/(Assumptions!$B$4*Assumptions!$B$5) | H12: ='Cash Flow'!E9/(Assumptions!$B$4*Assumptions!$B$5) | I12: ='Cash Flow'!F9/(Assumptions!$B$4*Assumptions!$B$5)
A13: Net cash (USD bn) | B13: ='Balance Sheet'!B4-'Balance Sheet'!B7 | C13: ='Balance Sheet'!C4-'Balance Sheet'!C7 | D13: ='Balance Sheet'!D4-'Balance Sheet'!D7 | E13: ='Balance Sheet'!E4-'Balance Sheet'!E7 | F13: ='Balance Sheet'!F4-'Balance Sheet'!F7 | G13: ='Balance Sheet'!G4-'Balance Sheet'!G7 | H13: ='Balance Sheet'!H4-'Balance Sheet'!H7 | I13: ='Balance Sheet'!I4-'Balance Sheet'!I7

Sheet Peer & Sector
A1: Peer set & sector context — mega-cap technology
A3: Company | B3: Fwd P/E (×) | C3: EV/EBITDA (×) | D3: Rev growth | E3: Note
A4: Apple (AAPL) | B4: 38 | C4: 27 | D4: 0.06 | E4: subject
A5: Microsoft (MSFT) | B5: 32 | C5: 22 | D5: 0.13 | E5: cloud/AI
A6: Alphabet (GOOGL) | B6: 22 | C6: 15 | D6: 0.13 | E6: search/cloud
A7: Amazon (AMZN) | B7: 34 | C7: 16 | D7: 0.11 | E7: retail/AWS
A8: Nvidia (NVDA) | B8: 34 | C8: 30 | D8: 0.5 | E8: AI compute
A9: Meta (META) | B9: 24 | C9: 14 | D9: 0.16 | E9: ads/AI
A10: Mega-cap median | B10: 31 | C10: 18 | D10: 0.13 | E10: ex-AAPL
