Workbook

Sheet READ FIRST
A1: Testahil — Abu Dhabi Islamic Bank – Egypt (EGX: ADIB)
A2: Companion model · Independent Valuation Study · Educational analysis · Not investment advice
A4: What this workbook is. A transparent companion to the ADIB-Egypt valuation study. Every blue cell is an input; every
A5: black cell is a formula; green cells link across sheets. All inputs live on the Assumptions sheet — change one
A6: (the cost of equity, the terminal ROE, a growth driver) and the whole model reprices.
A7: What it is not. It is not investment advice, a recommendation, or a price target. Values are model outputs shown
A8: as ranges. The preparer is not licensed by any securities regulator and may hold a position in the security.
A9: Currency. EGP millions unless stated; per-share figures in EGP. Spot EGP 46.64 (01 Jul 2026, EGX). Per-share figures use
A10: 1,500mn shares PRO-FORMA: 1,200mn issued at 31-Mar-26 (Q1-26 statements) plus the approved EGP 12bn→15bn cash increase.
A11: Entity note. This model concerns ADIB-Egypt (EGX: ADIB), the Cairo-listed subsidiary; ADIB Group (ADX: ADIB) is the
A12: Abu Dhabi-listed parent and majority shareholder — a different security. Historical financials are company disclosure
A13: (FY2025 statements, Feb 2026; Q1-2026 condensed consolidated statements, May 2026; FY2023 results, Mar 2024). Several
... A18: Income Statement · Balance Sheet · Cash Flow · Summary Financials · Monte Carlo · Sensitivity · Per-Share & Ratios · Peer & Sector.

Sheet Summary
A1: Valuation summary — ADIB-Egypt (EGX: ADIB)
A2: Four-lens fair value vs spot. Base cases link live; bear/bull are study scenario outputs.
B3: Bear | C3: Base | D3: Bull | E3: Weight
A4: Dividend discount (primary) | B4: 26.4 | C4: =DDM!C16 -> 53.771418 | D4: 113.4 | E4: =Assumptions!$B$27 -> 0.4
A5: Equity DCF (FCFE) | B5: 31.3 | C5: =DCF!C19 -> 54.356282 | D5: 97.4 | E5: =Assumptions!$B$28 -> 0.2
A6: Relative multiples | B6: 42.2 | C6: ='Relative & Normalized'!C4 -> 56.299958 | D6: 71.7 | E6: =Assumptions!$B$29 -> 0.15
A7: Normalized earnings | B7: 33.8 | C7: ='Relative & Normalized'!C6 -> 54 | D7: 78.8 | E7: =Assumptions!$B$30 -> 0.25
A8: Weighted central | B8: =SUMPRODUCT(B4:B7,$E$4:$E$7) -> 31.6 | C8: =SUMPRODUCT(C4:C7,$E$4:$E$7) -> 54.324817 | D8: =SUMPRODUCT(D4:D7,$E$4:$E$7) -> 95.295
A10: Spot price (EGP) | C10: =Assumptions!$B$4 -> 46.64
A11: Upside/(downside) to central base | C11: =C8/C10-1 -> 0.16476881
A13: Read: modestly undervalued; the whole question is how much of a 44% ROE survives disinflation and credit seasoning.

Sheet Fundamental Valuation
A1: Fundamental valuation — four lenses, one blend
A3: Lens | B3: Weight | C3: Bear | D3: Base | E3: Bull
A4: Dividend discount (primary) | B4: =Assumptions!$B$27 -> 0.4 | C4: 26.4 | D4: =DDM!C16 -> 53.771418 | E4: 113.4
A5: Equity DCF (FCFE) | B5: =Assumptions!$B$28 -> 0.2 | C5: 31.3 | D5: =DCF!C19 -> 54.356282 | E5: 97.4
A6: Relative multiples | B6: =Assumptions!$B$29 -> 0.15 | C6: 42.2 | D6: ='Relative & Normalized'!C4 -> 56.299958 | E6: 71.7
A7: Normalized earnings | B7: =Assumptions!$B$30 -> 0.25 | C7: 33.8 | D7: ='Relative & Normalized'!C6 -> 54 | E7: 78.8
A8: Weighted central | B8: =SUM(B4:B7) -> 1 | C8: =SUMPRODUCT(C4:C7,$B$4:$B$7) -> 31.6 | D8: =SUMPRODUCT(D4:D7,$B$4:$B$7) -> 54.324817 | E8: =SUMPRODUCT(E4:E7,$B$4:$B$7) -> 95.295
A10: Spot price (EGP) | D10: =Assumptions!$B$4 -> 46.64
A11: Upside/(downside) to central base | D11: =D8/D10-1 -> 0.16476881
A13: Trailing P/E at spot | D13: =Assumptions!$B$4/'Income Statement'!D14 -> 5.557674
A14: P/B at spot | D14: =Assumptions!$B$4/DDM!D7 -> 1.8756032
A15: P/E at central fair value (FY26E) | D15: =D8/'Income Statement'!E14 -> 5.1609902
A16: P/B at central fair value | D16: =D8/DDM!D7 -> 2.1846441
A18: Read: modestly undervalued — a 44%-ROE compounder at ~5.6x earnings; the swing factors are how fast the CBE easing compresses returns and the through-cycle cost of risk.

Sheet Assumptions
A1: Assumptions — the single input layer
A2: All blue cells are inputs. Every other sheet links here.
A3: ANCHORS
A4: Spot price (EGP/share) | B4: 46.64 | H4: EGX close, 01 Jul 2026 (attached price history)
A5: Shares outstanding (mn, pro-forma) | B5: 1500 | H5: 1,200mn issued at 31-Mar-26 (Q1-26 statements) + approved EGP 12→15bn increase
A6: Study date | B6: 01 Jul 2026
A7: Equity attributable, FY25 pro-forma (EGP mn) | B7: 37300 | H7: 34,300e reported basis (ROE 44% on avg) + EGP 3bn approved cash increase
A8: Total assets, FY25 pro-forma (EGP mn) | B8: 350000 | H8: 347,000 reported (FY25 results) + 3bn hike cash
A9: Non-controlling interests, FY25 (EGP mn) | B9: 500 | H9: e
A10: Customer financing, FY25 (EGP mn) | B10: 159000 | H10: FY25 results (+53% YoY)
A12: VALUATION SCENARIOS | C12: Bear | D12: Base | E12: Bull
A13: Cost of equity | C13: 0.26 | D13: 0.23 | E13: 0.2 | H13: Base ≈ EGP 10yr ~20% + ~0.9β × ~7% premium — an EGP discount rate
A14: Terminal growth (nominal EGP) | C14: 0.1 | D14: 0.11 | E14: 0.12
A15: Terminal (sustainable) ROE | C15: 0.24 | D15: 0.28 | E15: 0.32
A17: DIVIDEND POLICY (payout of attributable EPS) | C17: FY26E | D17: FY27E | E17: FY28E | F17: FY29E | G17: FY30E
A18: Payout ratio (cash dividends begin FY27E) | C18: 0 | D18: 0.1 | E18: 0.15 | F18: 0.2 | G18: 0.25 | H18: ADIB-Egypt currently pays no cash dividend; retention funds growth
A20: RELATIVE & NORMALIZED
A21: P/B multiple (relative lens) | B21: 2.2 | H21: CIB ~2.3x at ~38% ROE; EGX banks 1.5–2.5x
A22: Forward P/E (relative lens) | B22: 5.5 | H22: EGX bank sector ~5–7x
A23: Normalized (mid-cycle) EPS (EGP) | B23: 9 | H23: ~30% ROE on FY26E book as CBE easing lands
A24: Justified P/E (normalized lens) | B24: 6 | H24: Quality premium within the EGX bank range
A26: SYNTHESIS WEIGHTS
A27: Dividend discount (primary) | B27: 0.4
A28: Equity DCF (FCFE) | B28: 0.2
A29: Relative multiples | B29: 0.15
A30: Normalized earnings | B30: 0.25
A32: MONTE CARLO — engine parameters
A33: HAR-projected annualized vol | B33: 0.43206752
A34: Secular 60-day drift (log) | B34: 0.10949822
A35: Net continuous-factor drift (3m) | B35: 0.035
A36: Paths | B36: 50000
A37: Seed | B37: 42
A38: Horizon (sessions) | B38: 60
A40: FORECAST DRIVERS (FY26E–FY30E) | C40: FY26E | D40: FY27E | E40: FY28E | F40: FY29E | G40: FY30E
A41: Total revenue growth | C41: 0.235 | D41: 0.195 | E41: 0.175 | F41: 0.155 | G41: 0.135 | H41: FY25 revenue +31%; fades with CBE cuts
A42: Cost-to-income ratio | C42: 0.18 | D42: 0.185 | E42: 0.19 | F42: 0.195 | G42: 0.2
A43: Customer-financing growth | C43: 0.3 | D43: 0.25 | E43: 0.2 | F43: 0.18 | G43: 0.15
A44: Cost of risk (avg financing) | C44: 0.011 | D44: 0.011 | E44: 0.01 | F44: 0.01 | G44: 0.009 | H44: Egyptian through-cycle CoR well above today's
A45: Effective tax rate | C45: 0.275 | D45: 0.278 | E45: 0.28 | F45: 0.28 | G45: 0.28
A46: Non-controlling profit (EGP mn) | C46: 80 | D46: 90 | E46: 100 | F46: 110 | G46: 120
...

Sheet DDM
A1: Dividend discount — the primary lens
A2: Multi-stage DDM on distributable earnings, adapted to a zero-payout compounder: dividends begin FY27E; the terminal is a justified P/B on the retained book. Valuation date 01 Jul 2026.
D3: FY25 | E3: FY26E | F3: FY27E | G3: FY28E | H3: FY29E | I3: FY30E
A4: Attributable EPS (EGP) | D4: ='Income Statement'!D14 -> 8.392 | E4: ='Income Statement'!E14 -> 10.526046 | F4: ='Income Statement'!F14 -> 12.371928 | G4: ='Income Statement'!G14 -> 14.480608 | H4: ='Income Statement'!H14 -> 16.568819 | I4: ='Income Statement'!I14 -> 18.822212
A5: Payout ratio | E5: =Assumptions!C18 -> 0 | F5: =Assumptions!D18 -> 0.1 | G5: =Assumptions!E18 -> 0.15 | H5: =Assumptions!F18 -> 0.2 | I5: =Assumptions!G18 -> 0.25
A6: Dividend per share (EGP) | E6: =E4*E5 -> 0 | F6: =F4*F5 -> 1.2371928 | G6: =G4*G5 -> 2.1720913 | H6: =H4*H5 -> 3.3137638 | I6: =I4*I5 -> 4.7055529
A7: Book value per share (EGP) | D7: =Assumptions!$B$7/Assumptions!$B$5 -> 24.866667 | E7: =D7+E4-E6 -> 35.392712 | F7: =E7+F4-F6 -> 46.527447 | G7: =F7+G4-G6 -> 58.835965 | H7: =G7+H4-H6 -> 72.09102 | I7: =H7+I4-I6 -> 86.207678
A8: Discount period (years) | E8: 0.5 | F8: =E8+1 -> 1.5 | G8: =F8+1 -> 2.5 | H8: =G8+1 -> 3.5 | I8: =H8+1 -> 4.5
A9: Discount factor | E9: =1/(1+Assumptions!$D$13)^E8 -> 0.90166963 | F9: =1/(1+Assumptions!$D$13)^F8 -> 0.73306474 | G9: =1/(1+Assumptions!$D$13)^G8 -> 0.5959876 | H9: =1/(1+Assumptions!$D$13)^H8 -> 0.48454276 | I9: =1/(1+Assumptions!$D$13)^I8 -> 0.3939372
A10: PV of dividend (EGP) | E10: =E6*E9 -> 0 | F10: =F6*F9 -> 0.90694243 | G10: =G6*G9 -> 1.2945395 | H10: =H6*H9 -> 1.6056602 | I10: =I6*I9 -> 1.8536924
A12: Sum, PV of dividends FY26–FY30 | C12: =SUM(E10:I10) -> 5.6608345
A13: Terminal P/B =(ROEt − g)/(COE − g) | C13: =(Assumptions!$D$15-Assumptions!$D$14)/(Assumptions!$D$13-Assumptions!$D$14) -> 1.4166667
A14: Terminal value, end-FY30 (EGP/share) | C14: =C13*I7 -> 122.12754
A15: PV of terminal value | C15: =C14*I9 -> 48.110583
A16: DDM fair value (EGP/share) | C16: =C12+C15 -> 53.771418
A18: Scenario outputs (study §1.1) | C18: Bear | D18: Base | E18: Bull
C19: 26.4 | D19: =C16 -> 53.771418 | E19: 113.4 | K19: Bear/bull: scenario COE/ROEt/growth sets (Assumptions C13:E15), study compute engine

Sheet Segments
A1: Segments — where the franchise earns
A3: FINANCING MIX (FY25, EGP 159bn) — estimated
A4: Segment | B4: Share e | C4: EGP mn | D4: Note
A5: Corporate & syndications | B5: 0.55 | C5: =B5*Assumptions!$B$10 -> 87450 | D5: Large-corporate Islamic finance; ADI Capital deal flow
A6: Retail & personal finance | B6: 0.3 | C6: =B6*Assumptions!$B$10 -> 47700 | D6: 75-branch network; payroll & consumer
A7: SME & microfinance | B7: 0.1 | C7: =B7*Assumptions!$B$10 -> 15900 | D7: Fast-growing, CBE-mandated segment
A8: Other | B8: 0.05 | C8: =B8*Assumptions!$B$10 -> 7950 | D8: Subsidiaries: leasing, capital, real estate
A9: Total | B9: =SUM(B5:B8) -> 1 | C9: =SUM(C5:C8) -> 159000
A11: REVENUE MIX (FY25, EGP 23.6bn)
A12: Line | B12: Share | C12: EGP mn | D12: Note
A13: Net income from funds | B13: 0.854 | C13: =B13*'Income Statement'!$D$6 -> 20154.4 | D13: Financing + the large sovereign-securities book
A14: Fees, commissions & other | B14: 0.146 | C14: =B14*'Income Statement'!$D$6 -> 3445.6 | D14: Trade, cards, ADI Capital investment banking
A16: Splits marked e are preparer estimates; ADIB-Egypt reports segments in the annual financial statements.

Sheet Relative & Normalized
A1: Relative multiples & normalized earnings power
A3: RELATIVE MULTIPLES
A4: Relative fair value — blend of the two legs | C4: =(Assumptions!$B$21*DDM!$D$7+Assumptions!$B$22*'Income Statement'!$E$14)/2 -> 56.299958
A5: leg 1: P/B × BVPS · leg 2: forward P/E × FY26E EPS | B5: =Assumptions!$B$21*DDM!$D$7 -> 54.706667 | C5: =Assumptions!$B$22*'Income Statement'!$E$14 -> 57.89325
A6: Normalized-earnings fair value = mid-cycle EPS × justified P/E | C6: =Assumptions!$B$23*Assumptions!$B$24 -> 54
A8: Context — ADIB-Egypt at spot
A9: Trailing P/E (FY25 attributable) | C9: =Assumptions!$B$4/'Income Statement'!$D$14 -> 5.557674 | K9: ≈5.6x on year-end shares · reported weighted EPS 11.25 → ≈4.1x
A10: P/B | C10: =Assumptions!$B$4/DDM!$D$7 -> 1.8756032
A11: FY25 ROE (reported) | C11: 0.44

Sheet DCF
A1: Equity DCF — five years of free cash flow to equity
A2: FCFE = attributable profit less the equity retained to hold the FY25 capital intensity (equity/assets) through the growth; discounted at the cost of equity (the WACC of an all-equity claim). Its own book path assumes FCFE is distributed.
D3: FY25 | E3: FY26E | F3: FY27E | G3: FY28E | H3: FY29E | I3: FY30E
A4: Attributable net profit (EGP mn) | E4: ='Income Statement'!E13 -> 15789.068 | F4: ='Income Statement'!F13 -> 18557.892 | G4: ='Income Statement'!G13 -> 21720.913 | H4: ='Income Statement'!H13 -> 24853.228 | I4: ='Income Statement'!I13 -> 28233.318
A5: Total assets (EGP mn) | D5: ='Balance Sheet'!D8 -> 350000 | E5: ='Balance Sheet'!E8 -> 453890.65 | F5: ='Balance Sheet'!F8 -> 565067.64 | G5: ='Balance Sheet'!G8 -> 678387.02 | H5: ='Balance Sheet'!H8 -> 800798.69 | I5: ='Balance Sheet'!I8 -> 923332.79
A6: Δ Total assets (EGP mn) | E6: =E5-D5 -> 103890.65 | F6: =F5-E5 -> 111177 | G6: =G5-F5 -> 113319.37 | H6: =H5-G5 -> 122411.68 | I6: =I5-H5 -> 122534.1
A7: Required equity ratio (equity/assets, FY25) | C7: =Assumptions!$B$52 -> 0.10657143
A8: Equity retained to fund growth = ratio × ΔTA | E8: =$C$7*E6 -> 11071.775 | F8: =$C$7*F6 -> 11848.291 | G8: =$C$7*G6 -> 12076.607 | H8: =$C$7*H6 -> 13045.587 | I8: =$C$7*I6 -> 13058.634
A9: Free cash flow to equity (EGP mn) | E9: =MAX(E4-E8,0) -> 4717.2936 | F9: =MAX(F4-F8,0) -> 6709.6007 | G9: =MAX(G4-G8,0) -> 9644.3054 | H9: =MAX(H4-H8,0) -> 11807.641 | I9: =MAX(I4-I8,0) -> 15174.684
A10: FCFE per share (EGP) | E10: =E9/Assumptions!$B$5 -> 3.1448624 | F10: =F9/Assumptions!$B$5 -> 4.4730672 | G10: =G9/Assumptions!$B$5 -> 6.4295369 | H10: =H9/Assumptions!$B$5 -> 7.8717605 | I10: =I9/Assumptions!$B$5 -> 10.116456
A11: Discount rate — cost of equity | C11: =Assumptions!$D$13 -> 0.23 | K11: The WACC of the equity claim; deposits are operating funding
A12: BVPS under FCFE distribution (EGP) | D12: =DDM!D7 -> 24.866667 | E12: =D12+'Income Statement'!E14-E10 -> 32.24785 | F12: =E12+'Income Statement'!F14-F10 -> 40.146711 | G12: =F12+'Income Statement'!G14-G10 -> 48.197782 | H12: =G12+'Income Statement'!H14-H10 -> 56.894841 | I12: =H12+'Income Statement'!I14-I10 -> 65.600597
A13: Discount factor | E13: =1/(1+$C$11)^DDM!E8 -> 0.90166963 | F13: =1/(1+$C$11)^DDM!F8 -> 0.73306474 | G13: =1/(1+$C$11)^DDM!G8 -> 0.5959876 | H13: =1/(1+$C$11)^DDM!H8 -> 0.48454276 | I13: =1/(1+$C$11)^DDM!I8 -> 0.3939372
A14: PV of FCFE (EGP/share) | E14: =E10*E13 -> 2.8356269 | F14: =F10*F13 -> 3.2790478 | G14: =G10*G13 -> 3.8319243 | H14: =H10*H13 -> 3.8142046 | I14: =I10*I13 -> 3.9852483
A16: Sum, PV of FCFE FY26–FY30 (EGP/share) | C16: =SUM(E14:I14) -> 17.746052
A17: Terminal value, end-FY30 = justified P/B × FY30 book | C17: =DDM!C13*I12 -> 92.934178
A18: PV of terminal value | C18: =C17*I13 -> 36.61023
A19: DCF fair value (EGP/share) | C19: =C16+C18 -> 54.356282
A21: Scenario outputs (study §1.2) | C21: Bear | D21: Base | E21: Bull
C22: 31.3 | D22: =C19 -> 54.356282 | E22: 97.4

Sheet Income Statement
A1: Income statement — ADIB-Egypt (consolidated)
A2: EGP mn. FY23–FY25 as reported / derived to reported totals (e). Sources: FY25 statements Feb-26; FY23 results Mar-24.
B3: FY23 | C3: FY24 | D3: FY25 | E3: FY26E | F3: FY27E | G3: FY28E | H3: FY29E | I3: FY30E
A4: Net income from funds | B4: 8900 | C4: 15252 | D4: 20152 | E4: =D4*(1+Assumptions!C41) -> 24887.72 | F4: =E4*(1+Assumptions!D41) -> 29740.825 | G4: =F4*(1+Assumptions!E41) -> 34945.47 | H4: =G4*(1+Assumptions!F41) -> 40362.018 | I4: =H4*(1+Assumptions!G41) -> 45810.89 | K4: FY25/FY24 reported; FY23 per results release (e)
A5: Fees & other operating income | B5: 2000 | C5: 2758 | D5: 3448 | E5: =D5*(1+Assumptions!C41) -> 4258.28 | F5: =E5*(1+Assumptions!D41) -> 5088.6446 | G5: =F5*(1+Assumptions!E41) -> 5979.1574 | H5: =G5*(1+Assumptions!F41) -> 6905.9268 | I5: =H5*(1+Assumptions!G41) -> 7838.2269
A6: Total operating income | B6: =B4+B5 -> 10900 | C6: =C4+C5 -> 18010 | D6: =D4+D5 -> 23600 | E6: =E4+E5 -> 29146 | F6: =F4+F5 -> 34829.47 | G6: =G4+G5 -> 40924.627 | H6: =H4+H5 -> 47267.944 | I6: =I4+I5 -> 53649.117
A7: Operating expenses | B7: -2830 | C7: -3420 | D7: -4060 | E7: =-Assumptions!C42*E6 -> -5246.28 | F7: =-Assumptions!D42*F6 -> -6443.4519 | G7: =-Assumptions!E42*G6 -> -7775.6792 | H7: =-Assumptions!F42*H6 -> -9217.2492 | I7: =-Assumptions!G42*I6 -> -10729.823 | K7: From C/I 26.0e / 19.0e / 17.2% (reported)
A8: Provision for impairment | B8: -1470 | C8: -2180 | D8: -1940 | E8: =-Assumptions!C44*(('Balance Sheet'!D6+'Balance Sheet'!E6)/2) -> -2011.35 | F8: =-Assumptions!D44*(('Balance Sheet'!E6+'Balance Sheet'!F6)/2) -> -2557.9125 | G8: =-Assumptions!E44*(('Balance Sheet'!F6+'Balance Sheet'!G6)/2) -> -2842.125 | H8: =-Assumptions!F44*(('Balance Sheet'!G6+'Balance Sheet'!H6)/2) -> -3379.545 | I8: =-Assumptions!G44*(('Balance Sheet'!H6+'Balance Sheet'!I6)/2) -> -3539.6858
A9: Profit before tax | B9: =B6+B7+B8 -> 6600 | C9: =C6+C7+C8 -> 12410 | D9: =D6+D7+D8 -> 17600 | E9: =E6+E7+E8 -> 21888.37 | F9: =F6+F7+F8 -> 25828.106 | G9: =G6+G7+G8 -> 30306.823 | H9: =H6+H7+H8 -> 34671.15 | I9: =I6+I7+I8 -> 39379.608
A10: Taxation | B10: -1810 | C10: -3290 | D10: -4880 | E10: =-Assumptions!C45*E9 -> -6019.3017 | F10: =-Assumptions!D45*F9 -> -7180.2133 | G10: =-Assumptions!E45*G9 -> -8485.9105 | H10: =-Assumptions!F45*H9 -> -9707.9221 | I10: =-Assumptions!G45*I9 -> -11026.29 | K10: FY25 taxes paid EGP 4.88bn; FY24/FY23 derived (e)
A11: Profit after tax | B11: =B9+B10 -> 4790 | C11: =C9+C10 -> 9120 | D11: =D9+D10 -> 12720 | E11: =E9+E10 -> 15869.068 | F11: =F9+F10 -> 18647.892 | G11: =G9+G10 -> 21820.913 | H11: =H9+H10 -> 24963.228 | I11: =I9+I10 -> 28353.318
A12: Non-controlling interests | B12: -90 | C12: -112 | D12: -132 | E12: =-Assumptions!C46 -> -80 | F12: =-Assumptions!D46 -> -90 | G12: =-Assumptions!E46 -> -100 | H12: =-Assumptions!F46 -> -110 | I12: =-Assumptions!G46 -> -120
A13: Attributable net profit | B13: =B11+B12 -> 4700 | C13: =C11+C12 -> 9008 | D13: =D11+D12 -> 12588 | E13: =E11+E12 -> 15789.068 | F13: =F11+F12 -> 18557.892 | G13: =G11+G12 -> 21720.913 | H13: =H11+H12 -> 24853.228 | I13: =I11+I12 -> 28233.318
A14: EPS on current 1,500mn shares (EGP) | B14: =B13/Assumptions!$B$5 -> 3.1333333 | C14: =C13/Assumptions!$B$5 -> 6.0053333 | D14: =D13/Assumptions!$B$5 -> 8.392 | E14: =E13/Assumptions!$B$5 -> 10.526046 | F14: =F13/Assumptions!$B$5 -> 12.371928 | G14: =G13/Assumptions!$B$5 -> 14.480608 | H14: =H13/Assumptions!$B$5 -> 16.568819 | I14: =I13/Assumptions!$B$5 -> 18.822212 | K14: Reported weighted EPS: FY24 14.02, FY25 11.25 (share count rose via capital hikes)
A16: memo: Cost-to-income | B16: =-B7/B6 -> 0.25963303 | C16: =-C7/C6 -> 0.1898945 | D16: =-D7/D6 -> 0.1720339 | E16: =-E7/E6 -> 0.18 | F16: =-F7/F6 -> 0.185 | G16: =-G7/G6 -> 0.19 | H16: =-H7/H6 -> 0.195 | I16: =-I7/I6 -> 0.2
A17: memo: Cost of risk | C17: =-C8/(('Balance Sheet'!B6+'Balance Sheet'!C6)/2) -> 0.025437573 | D17: =-D8/(('Balance Sheet'!C6+'Balance Sheet'!D6)/2) -> 0.014730448 | E17: =-E8/(('Balance Sheet'!D6+'Balance Sheet'!E6)/2) -> 0.011 | F17: =-F8/(('Balance Sheet'!E6+'Balance Sheet'!F6)/2) -> 0.011 | G17: =-G8/(('Balance Sheet'!F6+'Balance Sheet'!G6)/2) -> 0.01 | H17: =-H8/(('Balance Sheet'!G6+'Balance Sheet'!H6)/2) -> 0.01 | I17: =-I8/(('Balance Sheet'!H6+'Balance Sheet'!I6)/2) -> 0.009
A18: memo: Effective tax rate | B18: =-B10/B9 -> 0.27424242 | C18: =-C10/C9 -> 0.26510878 | D18: =-D10/D9 -> 0.27727273 | E18: =-E10/E9 -> 0.275 | F18: =-F10/F9 -> 0.278 | G18: =-G10/G9 -> 0.28 | H18: =-H10/H9 -> 0.28 | I18: =-I10/I9 -> 0.28

Sheet Balance Sheet
A1: Balance sheet — ADIB-Egypt (consolidated)
A2: EGP mn. Totals anchored to disclosure (assets 162.3 / 260.5 / 347bn); lines marked e estimated to balance.
B3: FY23 | C3: FY24 | D3: FY25 | E3: FY26E | F3: FY27E | G3: FY28E | H3: FY29E | I3: FY30E
A4: Cash & due from banks | B4: 22300 | C4: 32100 | D4: 41000 | E4: =E12+E18-SUM(E5:E7) -> 56990.647 | F4: =F12+F18-SUM(F5:F7) -> 72384.645 | G4: =G12+G18-SUM(G5:G7) -> 88377.415 | H4: =H12+H18-SUM(H5:H7) -> 108318.66 | I4: =I12+I18-SUM(I5:I7) -> 127712.81 | K4: balancing (e); FY25 incl. 3bn hike cash pro-forma
A5: Treasury & investment securities | B5: 65000 | C5: 115000 | D5: 140000 | E5: =D5*(1+Assumptions!C47) -> 179200 | F5: =E5*(1+Assumptions!D47) -> 222208 | G5: =F5*(1+Assumptions!E47) -> 266649.6 | H5: =G5*(1+Assumptions!F47) -> 311980.03 | I5: =H5*(1+Assumptions!G47) -> 358777.04 | K5: e — large sovereign book
A6: Customer financing, net | B6: 67000 | C6: 104400 | D6: 159000 | E6: =D6*(1+Assumptions!C43) -> 206700 | F6: =E6*(1+Assumptions!D43) -> 258375 | G6: =F6*(1+Assumptions!E43) -> 310050 | H6: =G6*(1+Assumptions!F43) -> 365859 | I6: =H6*(1+Assumptions!G43) -> 420737.85 | K6: reported
A7: Fixed & other assets | B7: 8000 | C7: 9000 | D7: 10000 | E7: =D7*(1+Assumptions!$B$49) -> 11000 | F7: =E7*(1+Assumptions!$B$49) -> 12100 | G7: =F7*(1+Assumptions!$B$49) -> 13310 | H7: =G7*(1+Assumptions!$B$49) -> 14641 | I7: =H7*(1+Assumptions!$B$49) -> 16105.1 | K7: e
A8: Total assets | B8: =SUM(B4:B7) -> 162300 | C8: =SUM(C4:C7) -> 260500 | D8: =SUM(D4:D7) -> 350000 | E8: =SUM(E4:E7) -> 453890.65 | F8: =SUM(F4:F7) -> 565067.64 | G8: =SUM(G4:G7) -> 678387.02 | H8: =SUM(H4:H7) -> 800798.69 | I8: =SUM(I4:I7) -> 923332.79 | K8: 162.3 / 260.5 / 347bn reported; FY25 shown pro-forma (+3bn)
A10: Depositors' accounts | B10: 127000 | C10: 200000 | D10: 278000 | E10: =E6/Assumptions!$B$48 -> 362631.58 | F10: =F6/Assumptions!$B$48 -> 453289.47 | G10: =G6/Assumptions!$B$48 -> 543947.37 | H10: =H6/Assumptions!$B$48 -> 641857.89 | I10: =I6/Assumptions!$B$48 -> 738136.58 | K10: reported
A11: Due to banks, sub-financing & other liab. | B11: 20100 | C11: 37100 | D11: 34200 | E11: =D11*(1+Assumptions!$B$50) -> 37620 | F11: =E11*(1+Assumptions!$B$50) -> 41382 | G11: =F11*(1+Assumptions!$B$50) -> 45520.2 | H11: =G11*(1+Assumptions!$B$50) -> 50072.22 | I11: =H11*(1+Assumptions!$B$50) -> 55079.442 | K11: balancing (e); incl. ~US$195mn parent+IFC subordinated Wakala/Murabaha
A12: Total liabilities | B12: =B10+B11 -> 147100 | C12: =C10+C11 -> 237100 | D12: =D10+D11 -> 312200 | E12: =E10+E11 -> 400251.58 | F12: =F10+F11 -> 494671.47 | G12: =G10+G11 -> 589467.57 | H12: =H10+H11 -> 691930.11 | I12: =I10+I11 -> 793216.02
A14: Paid-in capital | B14: 6000 | C14: 12000 | D14: 15000 | E14: =D14 -> 15000 | F14: =E14 -> 15000 | G14: =F14 -> 15000 | H14: =G14 -> 15000 | I14: =H14 -> 15000 | K14: Issued 12,000 at 31-Dec-25 (Q1-26 stmts); FY25 shown pro-forma the approved 12→15bn increase
A15: Retained earnings & reserves | B15: 8900 | C15: 11000 | D15: 22300 | E15: =D15+'Income Statement'!E13-Assumptions!C18*'Income Statement'!E14*Assumptions!$B$5 -> 38089.068 | F15: =E15+'Income Statement'!F13-Assumptions!D18*'Income Statement'!F14*Assumptions!$B$5 -> 54791.171 | G15: =F15+'Income Statement'!G13-Assumptions!E18*'Income Statement'!G14*Assumptions!$B$5 -> 73253.947 | H15: =G15+'Income Statement'!H13-Assumptions!F18*'Income Statement'!H14*Assumptions!$B$5 -> 93136.53 | I15: =H15+'Income Statement'!I13-Assumptions!G18*'Income Statement'!I14*Assumptions!$B$5 -> 114311.52 | K15: balancing (e)
A16: Equity attributable to shareholders | B16: =B14+B15 -> 14900 | C16: =C14+C15 -> 23000 | D16: =D14+D15 -> 37300 | E16: =E14+E15 -> 53089.068 | F16: =F14+F15 -> 69791.171 | G16: =G14+G15 -> 88253.947 | H16: =H14+H15 -> 108136.53 | I16: =I14+I15 -> 129311.52
A17: Non-controlling interests | B17: 300 | C17: 400 | D17: 500 | E17: =D17*(1+Assumptions!$B$51) -> 550 | F17: =E17*(1+Assumptions!$B$51) -> 605 | G17: =F17*(1+Assumptions!$B$51) -> 665.5 | H17: =G17*(1+Assumptions!$B$51) -> 732.05 | I17: =H17*(1+Assumptions!$B$51) -> 805.255 | K17: e
A18: Total equity | B18: =B16+B17 -> 15200 | C18: =C16+C17 -> 23400 | D18: =D16+D17 -> 37800 | E18: =E16+E17 -> 53639.068 | F18: =F16+F17 -> 70396.171 | G18: =G16+G17 -> 88919.447 | H18: =H16+H17 -> 108868.58 | I18: =I16+I17 -> 130116.77
A20: Check: assets − liabilities − equity | B20: =B8-B12-B18 -> 0 | C20: =C8-C12-C18 -> 0 | D20: =D8-D12-D18 -> 0 | E20: =E8-E12-E18 -> 0 | F20: =F8-F12-F18 -> 0 | G20: =G8-G12-G18 -> 0 | H20: =H8-H12-H18 -> 0 | I20: =I8-I12-I18 -> 0
A22: memo: NPL / coverage · capital | B22: CAR 19.44% (FY25, reported) | K22: FY25 results; NPL detail in annual report

Sheet Cash Flow
A1: Cash flow — bank presentation (derived)
A2: EGP mn. History from FY24 (FY23 opening stocks estimated). 'Other movements' closes equity FX/reserve items.
B3: FY23 | C3: FY24 | D3: FY25 | E3: FY26E | F3: FY27E | G3: FY28E | H3: FY29E | I3: FY30E
A4: Profit after tax | C4: ='Income Statement'!C11 -> 9120 | D4: ='Income Statement'!D11 -> 12720 | E4: ='Income Statement'!E11 -> 15869.068 | F4: ='Income Statement'!F11 -> 18647.892 | G4: ='Income Statement'!G11 -> 21820.913 | H4: ='Income Statement'!H11 -> 24963.228 | I4: ='Income Statement'!I11 -> 28353.318
A5: Impairment charge (non-cash) | C5: =-'Income Statement'!C8 -> 2180 | D5: =-'Income Statement'!D8 -> 1940 | E5: =-'Income Statement'!E8 -> 2011.35 | F5: =-'Income Statement'!F8 -> 2557.9125 | G5: =-'Income Statement'!G8 -> 2842.125 | H5: =-'Income Statement'!H8 -> 3379.545 | I5: =-'Income Statement'!I8 -> 3539.6858
A6: Δ Customer financing (gross of impairment) | C6: =-('Balance Sheet'!C6-'Balance Sheet'!B6)+'Income Statement'!C8 -> -39580 | D6: =-('Balance Sheet'!D6-'Balance Sheet'!C6)+'Income Statement'!D8 -> -56540 | E6: =-('Balance Sheet'!E6-'Balance Sheet'!D6)+'Income Statement'!E8 -> -49711.35 | F6: =-('Balance Sheet'!F6-'Balance Sheet'!E6)+'Income Statement'!F8 -> -54232.912 | G6: =-('Balance Sheet'!G6-'Balance Sheet'!F6)+'Income Statement'!G8 -> -54517.125 | H6: =-('Balance Sheet'!H6-'Balance Sheet'!G6)+'Income Statement'!H8 -> -59188.545 | I6: =-('Balance Sheet'!I6-'Balance Sheet'!H6)+'Income Statement'!I8 -> -58418.536
A7: Δ Depositors' accounts | C7: ='Balance Sheet'!C10-'Balance Sheet'!B10 -> 73000 | D7: ='Balance Sheet'!D10-'Balance Sheet'!C10 -> 78000 | E7: ='Balance Sheet'!E10-'Balance Sheet'!D10 -> 84631.579 | F7: ='Balance Sheet'!F10-'Balance Sheet'!E10 -> 90657.895 | G7: ='Balance Sheet'!G10-'Balance Sheet'!F10 -> 90657.895 | H7: ='Balance Sheet'!H10-'Balance Sheet'!G10 -> 97910.526 | I7: ='Balance Sheet'!I10-'Balance Sheet'!H10 -> 96278.684
A8: Δ Due to banks & other liabilities | C8: ='Balance Sheet'!C11-'Balance Sheet'!B11 -> 17000 | D8: ='Balance Sheet'!D11-'Balance Sheet'!C11 -> -2900 | E8: ='Balance Sheet'!E11-'Balance Sheet'!D11 -> 3420 | F8: ='Balance Sheet'!F11-'Balance Sheet'!E11 -> 3762 | G8: ='Balance Sheet'!G11-'Balance Sheet'!F11 -> 4138.2 | H8: ='Balance Sheet'!H11-'Balance Sheet'!G11 -> 4552.02 | I8: ='Balance Sheet'!I11-'Balance Sheet'!H11 -> 5007.222
A9: Δ Fixed & other assets | C9: =-('Balance Sheet'!C7-'Balance Sheet'!B7) -> -1000 | D9: =-('Balance Sheet'!D7-'Balance Sheet'!C7) -> -1000 | E9: =-('Balance Sheet'!E7-'Balance Sheet'!D7) -> -1000 | F9: =-('Balance Sheet'!F7-'Balance Sheet'!E7) -> -1100 | G9: =-('Balance Sheet'!G7-'Balance Sheet'!F7) -> -1210 | H9: =-('Balance Sheet'!H7-'Balance Sheet'!G7) -> -1331 | I9: =-('Balance Sheet'!I7-'Balance Sheet'!H7) -> -1464.1
A10: Net cash from operating activities | C10: =SUM(C4:C9) -> 60720 | D10: =SUM(D4:D9) -> 32220 | E10: =SUM(E4:E9) -> 55220.647 | F10: =SUM(F4:F9) -> 60292.787 | G10: =SUM(G4:G9) -> 63732.007 | H10: =SUM(H4:H9) -> 70285.775 | I10: =SUM(I4:I9) -> 73296.274
A12: Δ Treasury & investment securities | C12: =-('Balance Sheet'!C5-'Balance Sheet'!B5) -> -50000 | D12: =-('Balance Sheet'!D5-'Balance Sheet'!C5) -> -25000 | E12: =-('Balance Sheet'!E5-'Balance Sheet'!D5) -> -39200 | F12: =-('Balance Sheet'!F5-'Balance Sheet'!E5) -> -43008 | G12: =-('Balance Sheet'!G5-'Balance Sheet'!F5) -> -44441.6 | H12: =-('Balance Sheet'!H5-'Balance Sheet'!G5) -> -45330.432 | I12: =-('Balance Sheet'!I5-'Balance Sheet'!H5) -> -46797.005
A13: Net cash from investing activities | C13: =C12 -> -50000 | D13: =D12 -> -25000 | E13: =E12 -> -39200 | F13: =F12 -> -43008 | G13: =G12 -> -44441.6 | H13: =H12 -> -45330.432 | I13: =I12 -> -46797.005
A15: Dividends paid | C15: 0 | D15: 0 | E15: =-Assumptions!C18*'Income Statement'!E14*Assumptions!$B$5 -> 0 | F15: =-Assumptions!D18*'Income Statement'!F14*Assumptions!$B$5 -> -1855.7892 | G15: =-Assumptions!E18*'Income Statement'!G14*Assumptions!$B$5 -> -3258.1369 | H15: =-Assumptions!F18*'Income Statement'!H14*Assumptions!$B$5 -> -4970.6456 | I15: =-Assumptions!G18*'Income Statement'!I14*Assumptions!$B$5 -> -7058.3294 | K15: No cash dividends paid to date
A16: Capital increase / equity & reserve movements | C16: =('Balance Sheet'!C18-'Balance Sheet'!B18)-'Income Statement'!C11-C15 -> -920 | D16: =('Balance Sheet'!D18-'Balance Sheet'!C18)-'Income Statement'!D11-D15 -> 1680 | E16: =('Balance Sheet'!E18-'Balance Sheet'!D18)-'Income Statement'!E11-E15 -> -30 | F16: =('Balance Sheet'!F18-'Balance Sheet'!E18)-'Income Statement'!F11-F15 -> -35 | G16: =('Balance Sheet'!G18-'Balance Sheet'!F18)-'Income Statement'!G11-G15 -> -39.5 | H16: =('Balance Sheet'!H18-'Balance Sheet'!G18)-'Income Statement'!H11-H15 -> -43.45 | I16: =('Balance Sheet'!I18-'Balance Sheet'!H18)-'Income Statement'!I11-I15 -> -46.795 | K16: FY25 includes the EGP 3bn cash capital increase
A17: Net cash from financing activities | C17: =C15+C16 -> -920 | D17: =D15+D16 -> 1680 | E17: =E15+E16 -> -30 | F17: =F15+F16 -> -1890.7892 | G17: =G15+G16 -> -3297.6369 | H17: =H15+H16 -> -5014.0956 | I17: =I15+I16 -> -7105.1244
A18: Net change in cash | C18: =C10+C13+C17 -> 9800 | D18: =D10+D13+D17 -> 8900 | E18: =E10+E13+E17 -> 15990.647 | F18: =F10+F13+F17 -> 15393.998 | G18: =G10+G13+G17 -> 15992.77 | H18: =H10+H13+H17 -> 19941.247 | I18: =I10+I13+I17 -> 19394.145
A19: Cash & due from banks, opening | C19: ='Balance Sheet'!B4 -> 22300 | D19: ='Balance Sheet'!C4 -> 32100 | E19: ='Balance Sheet'!D4 -> 41000 | F19: ='Balance Sheet'!E4 -> 56990.647 | G19: ='Balance Sheet'!F4 -> 72384.645 | H19: ='Balance Sheet'!G4 -> 88377.415 | I19: ='Balance Sheet'!H4 -> 108318.66
A20: Cash & due from banks, closing | C20: =C19+C18 -> 32100 | D20: =D19+D18 -> 41000 | E20: =E19+E18 -> 56990.647 | F20: =F19+F18 -> 72384.645 | G20: =G19+G18 -> 88377.415 | H20: =H19+H18 -> 108318.66 | I20: =I19+I18 -> 127712.81
A21: Check vs balance sheet | C21: =C20-'Balance Sheet'!C4 -> 0 | D21: =D20-'Balance Sheet'!D4 -> 0 | E21: =E20-'Balance Sheet'!E4 -> 0 | F21: =F20-'Balance Sheet'!F4 -> 0 | G21: =G20-'Balance Sheet'!G4 -> 0 | H21: =H20-'Balance Sheet'!H4 -> 0 | I21: =I20-'Balance Sheet'!I4 -> 0

Sheet Summary Financials
A1: Summary financials — all cells link to the statement sheets
B3: FY23 | C3: FY24 | D3: FY25 | E3: FY26E | F3: FY27E | G3: FY28E | H3: FY29E | I3: FY30E
A4: Total operating income | B4: ='Income Statement'!B6 -> 10900 | C4: ='Income Statement'!C6 -> 18010 | D4: ='Income Statement'!D6 -> 23600 | E4: ='Income Statement'!E6 -> 29146 | F4: ='Income Statement'!F6 -> 34829.47 | G4: ='Income Statement'!G6 -> 40924.627 | H4: ='Income Statement'!H6 -> 47267.944 | I4: ='Income Statement'!I6 -> 53649.117
A5: Operating expenses | B5: ='Income Statement'!B7 -> -2830 | C5: ='Income Statement'!C7 -> -3420 | D5: ='Income Statement'!D7 -> -4060 | E5: ='Income Statement'!E7 -> -5246.28 | F5: ='Income Statement'!F7 -> -6443.4519 | G5: ='Income Statement'!G7 -> -7775.6792 | H5: ='Income Statement'!H7 -> -9217.2492 | I5: ='Income Statement'!I7 -> -10729.823
A6: Provision for impairment | B6: ='Income Statement'!B8 -> -1470 | C6: ='Income Statement'!C8 -> -2180 | D6: ='Income Statement'!D8 -> -1940 | E6: ='Income Statement'!E8 -> -2011.35 | F6: ='Income Statement'!F8 -> -2557.9125 | G6: ='Income Statement'!G8 -> -2842.125 | H6: ='Income Statement'!H8 -> -3379.545 | I6: ='Income Statement'!I8 -> -3539.6858
A7: Profit before tax | B7: ='Income Statement'!B9 -> 6600 | C7: ='Income Statement'!C9 -> 12410 | D7: ='Income Statement'!D9 -> 17600 | E7: ='Income Statement'!E9 -> 21888.37 | F7: ='Income Statement'!F9 -> 25828.106 | G7: ='Income Statement'!G9 -> 30306.823 | H7: ='Income Statement'!H9 -> 34671.15 | I7: ='Income Statement'!I9 -> 39379.608
A8: Attributable net profit | B8: ='Income Statement'!B13 -> 4700 | C8: ='Income Statement'!C13 -> 9008 | D8: ='Income Statement'!D13 -> 12588 | E8: ='Income Statement'!E13 -> 15789.068 | F8: ='Income Statement'!F13 -> 18557.892 | G8: ='Income Statement'!G13 -> 21720.913 | H8: ='Income Statement'!H13 -> 24853.228 | I8: ='Income Statement'!I13 -> 28233.318
A9: EPS, current shares (EGP) | B9: ='Income Statement'!B14 -> 3.1333333 | C9: ='Income Statement'!C14 -> 6.0053333 | D9: ='Income Statement'!D14 -> 8.392 | E9: ='Income Statement'!E14 -> 10.526046 | F9: ='Income Statement'!F14 -> 12.371928 | G9: ='Income Statement'!G14 -> 14.480608 | H9: ='Income Statement'!H14 -> 16.568819 | I9: ='Income Statement'!I14 -> 18.822212
A10: Total assets | B10: ='Balance Sheet'!B8 -> 162300 | C10: ='Balance Sheet'!C8 -> 260500 | D10: ='Balance Sheet'!D8 -> 350000 | E10: ='Balance Sheet'!E8 -> 453890.65 | F10: ='Balance Sheet'!F8 -> 565067.64 | G10: ='Balance Sheet'!G8 -> 678387.02 | H10: ='Balance Sheet'!H8 -> 800798.69 | I10: ='Balance Sheet'!I8 -> 923332.79
A11: Customer financing, net | B11: ='Balance Sheet'!B6 -> 67000 | C11: ='Balance Sheet'!C6 -> 104400 | D11: ='Balance Sheet'!D6 -> 159000 | E11: ='Balance Sheet'!E6 -> 206700 | F11: ='Balance Sheet'!F6 -> 258375 | G11: ='Balance Sheet'!G6 -> 310050 | H11: ='Balance Sheet'!H6 -> 365859 | I11: ='Balance Sheet'!I6 -> 420737.85
A12: Depositors' accounts | B12: ='Balance Sheet'!B10 -> 127000 | C12: ='Balance Sheet'!C10 -> 200000 | D12: ='Balance Sheet'!D10 -> 278000 | E12: ='Balance Sheet'!E10 -> 362631.58 | F12: ='Balance Sheet'!F10 -> 453289.47 | G12: ='Balance Sheet'!G10 -> 543947.37 | H12: ='Balance Sheet'!H10 -> 641857.89 | I12: ='Balance Sheet'!I10 -> 738136.58
A13: Equity attributable | B13: ='Balance Sheet'!B16 -> 14900 | C13: ='Balance Sheet'!C16 -> 23000 | D13: ='Balance Sheet'!D16 -> 37300 | E13: ='Balance Sheet'!E16 -> 53089.068 | F13: ='Balance Sheet'!F16 -> 69791.171 | G13: ='Balance Sheet'!G16 -> 88253.947 | H13: ='Balance Sheet'!H16 -> 108136.53 | I13: ='Balance Sheet'!I16 -> 129311.52
A14: Cost-to-income | B14: ='Income Statement'!B16 -> 0.25963303 | C14: ='Income Statement'!C16 -> 0.1898945 | D14: ='Income Statement'!D16 -> 0.1720339 | E14: ='Income Statement'!E16 -> 0.18 | F14: ='Income Statement'!F16 -> 0.185 | G14: ='Income Statement'!G16 -> 0.19 | H14: ='Income Statement'!H16 -> 0.195 | I14: ='Income Statement'!I16 -> 0.2

Sheet Monte Carlo
A1: Monte Carlo — the §3 probabilistic price map
A2: YZ-HAR width · Student-t(5) innovations · secular drift ON (Step-0 winner) · 16 factors (egx_bank) · 50,000 paths · seed 42.
A3: Paths diffuse from spot; the §1 value gap is deliberately kept out of the drift (lens independence).
A5: ENGINE PARAMETERS
A6: Anchor (spot, EGP) | C6: =Assumptions!$B$4 -> 46.64
A7: HAR-projected annualized vol | C7: =Assumptions!$B$33 -> 0.43206752
A8: Simulated annualized path vol (incl. events) | C8: 0.49254847
A9: Secular 60-day drift (log) | C9: =Assumptions!$B$34 -> 0.10949822
A10: Net continuous-factor drift (3m) | C10: =Assumptions!$B$35 -> 0.035
A11: Expected discrete-event drift (Σ p×impact) | C11: -0.018
A12: Paths / seed / horizon | C12: 50,000 / 42 / 60
A14: CONTINUOUS FACTORS (7) — egx_bank class; magnitudes calibrated=False
A15: Factor | B15: Dir. | C15: 3m drift | D15: 3m vol | G15: Channel
A16: CBE policy-rate path | B16: + | C16: 0.02 | D16: 0.04 | G16: NIM on the T-bill & repricing book vs funding cost
A17: EGP/USD rate | B17: + | C17: 0.01 | D17: 0.06 | G17: FX position gains, dollarization, nominal repricing
A18: Inflation (CPI) | B18: + | C18: 0.01 | D18: 0.04 | G18: nominal financing growth, fee income
A19: EGX30 & foreign flows | B19: + | C19: 0.015 | D19: 0.07 | G19: index weight, EM/frontier flows
A20: Private-sector credit growth | B20: + | C20: 0.01 | D20: 0.04 | G20: financing-book expansion as crowding-out unwinds
A21: Easing-cycle NIM compression | B21: - | C21: -0.02 | D21: 0.05 | G21: CBE cuts reprice the asset book down
A22: Positioning / valuation drag after the run | B22: - | C22: -0.01 | D22: 0.05 | G22: profit-taking pressure after a 12-month double
A24: DISCRETE EVENTS (9)
A25: Event | B25: Tier | C25: Prob. | D25: Mean | E25: Spread | G25: Channel
A26: Geopolitical / regional security shock | B26: M | C26: 0.3 | D26: -0.1 | E26: 0.05 | G26: risk premium, deposit-flight tail
A27: Asset-quality / NPL-cycle shift | B27: M | C27: 0.3 | D27: -0.06 | E27: 0.04 | G27: ECL regime after +53% book growth
A28: Sovereign rating / T-bill yield regime | B28: M | C28: 0.3 | D28: 0.02 | E28: 0.05 | G28: large government-securities book
A29: EGP step-devaluation | B29: M | C29: 0.25 | D29: 0.03 | E29: 0.05 | G29: FX gains & nominal repricing for banks
A30: Capital / dividend-policy change | B30: M | C30: 0.25 | D30: 0.02 | E30: 0.05 | G30: first cash dividend vs further retention
A31: Earnings surprise (NIM / ECL / fees) | B31: E | C31: 0.5 | D31: 0.02 | E31: 0.06 | G31: quarterly print
A32: M&A / capital action | B32: E | C32: 0.3 | D32: 0.03 | E32: 0.06 | G32: group support, stake moves
A33: Rights issue / dilution overhang | B33: E | C33: 0.25 | D33: -0.03 | E33: 0.04 | G33: further capital hike to fund growth
A34: Non-recurring ECL release / one-off | B34: E | C34: 0.3 | D34: 0 | E34: 0.05 | G34: normalize per COMI rule
A36: PERCENTILE MAP (EGP/share) — engine output, mc_v2 run
A37: Horizon | B37: p5 | C37: p25 | D37: p50 | E37: p75 | F37: p95
A38: T+20 sessions | B38: 38.5 | C38: 44.5 | D38: 48.2 | E38: 52.2 | F38: 59.7
A39: T+60 sessions | B39: 35.3 | C39: 44.7 | D39: 51.5 | E39: 59.3 | F39: 74.4
A41: LEVEL-TOUCH LADDER — P(touch by horizon)
A42: Level (EGP) | B42: T+20 | C42: T+60
A43: 55 | B43: 0.21 | C43: 0.55
A44: 52 | B44: 0.39 | C44: 0.7
A45: 50 | B45: 0.57 | C45: 0.81
...

Sheet Sensitivity
A1: DDM sensitivity — cost of equity × terminal ROE
A2: Live formulas. Dividend path and book value held at base; the grid varies the discount rate and the terminal P/B.
B5: COE \ terminal ROE | C5: 0.22 | D5: 0.25 | E5: 0.28 | F5: 0.31 | G5: 0.34
B6: 0.2 | C6: =DDM!$E$6/(1+$B6)^DDM!$E$8+DDM!$F$6/(1+$B6)^DDM!$F$8+DDM!$G$6/(1+$B6)^DDM!$G$8+DDM!$H$6/(1+$B6)^DDM!$H$8+DDM!$I$6/(1+$B6)^DDM!$I$8+((C$5-Assumptions!$D$14)/($B6-Assumptions!$D$14))*DDM!$I$7/(1+$B6)^DDM!$I$8 -> 52.525601 | D6: =DDM!$E$6/(1+$B6)^DDM!$E$8+DDM!$F$6/(1+$B6)^DDM!$F$8+DDM!$G$6/(1+$B6)^DDM!$G$8+DDM!$H$6/(1+$B6)^DDM!$H$8+DDM!$I$6/(1+$B6)^DDM!$I$8+((D$5-Assumptions!$D$14)/($B6-Assumptions!$D$14))*DDM!$I$7/(1+$B6)^DDM!$I$8 -> 65.176142 | E6: =DDM!$E$6/(1+$B6)^DDM!$E$8+DDM!$F$6/(1+$B6)^DDM!$F$8+DDM!$G$6/(1+$B6)^DDM!$G$8+DDM!$H$6/(1+$B6)^DDM!$H$8+DDM!$I$6/(1+$B6)^DDM!$I$8+((E$5-Assumptions!$D$14)/($B6-Assumptions!$D$14))*DDM!$I$7/(1+$B6)^DDM!$I$8 -> 77.826683 | F6: =DDM!$E$6/(1+$B6)^DDM!$E$8+DDM!$F$6/(1+$B6)^DDM!$F$8+DDM!$G$6/(1+$B6)^DDM!$G$8+DDM!$H$6/(1+$B6)^DDM!$H$8+DDM!$I$6/(1+$B6)^DDM!$I$8+((F$5-Assumptions!$D$14)/($B6-Assumptions!$D$14))*DDM!$I$7/(1+$B6)^DDM!$I$8 -> 90.477223 | G6: =DDM!$E$6/(1+$B6)^DDM!$E$8+DDM!$F$6/(1+$B6)^DDM!$F$8+DDM!$G$6/(1+$B6)^DDM!$G$8+DDM!$H$6/(1+$B6)^DDM!$H$8+DDM!$I$6/(1+$B6)^DDM!$I$8+((G$5-Assumptions!$D$14)/($B6-Assumptions!$D$14))*DDM!$I$7/(1+$B6)^DDM!$I$8 -> 103.12776
B7: 0.23 | C7: =DDM!$E$6/(1+$B7)^DDM!$E$8+DDM!$F$6/(1+$B7)^DDM!$F$8+DDM!$G$6/(1+$B7)^DDM!$G$8+DDM!$H$6/(1+$B7)^DDM!$H$8+DDM!$I$6/(1+$B7)^DDM!$I$8+((C$5-Assumptions!$D$14)/($B7-Assumptions!$D$14))*DDM!$I$7/(1+$B7)^DDM!$I$8 -> 36.791212 | D7: =DDM!$E$6/(1+$B7)^DDM!$E$8+DDM!$F$6/(1+$B7)^DDM!$F$8+DDM!$G$6/(1+$B7)^DDM!$G$8+DDM!$H$6/(1+$B7)^DDM!$H$8+DDM!$I$6/(1+$B7)^DDM!$I$8+((D$5-Assumptions!$D$14)/($B7-Assumptions!$D$14))*DDM!$I$7/(1+$B7)^DDM!$I$8 -> 45.281315 | E7: =DDM!$E$6/(1+$B7)^DDM!$E$8+DDM!$F$6/(1+$B7)^DDM!$F$8+DDM!$G$6/(1+$B7)^DDM!$G$8+DDM!$H$6/(1+$B7)^DDM!$H$8+DDM!$I$6/(1+$B7)^DDM!$I$8+((E$5-Assumptions!$D$14)/($B7-Assumptions!$D$14))*DDM!$I$7/(1+$B7)^DDM!$I$8 -> 53.771418 | F7: =DDM!$E$6/(1+$B7)^DDM!$E$8+DDM!$F$6/(1+$B7)^DDM!$F$8+DDM!$G$6/(1+$B7)^DDM!$G$8+DDM!$H$6/(1+$B7)^DDM!$H$8+DDM!$I$6/(1+$B7)^DDM!$I$8+((F$5-Assumptions!$D$14)/($B7-Assumptions!$D$14))*DDM!$I$7/(1+$B7)^DDM!$I$8 -> 62.261521 | G7: =DDM!$E$6/(1+$B7)^DDM!$E$8+DDM!$F$6/(1+$B7)^DDM!$F$8+DDM!$G$6/(1+$B7)^DDM!$G$8+DDM!$H$6/(1+$B7)^DDM!$H$8+DDM!$I$6/(1+$B7)^DDM!$I$8+((G$5-Assumptions!$D$14)/($B7-Assumptions!$D$14))*DDM!$I$7/(1+$B7)^DDM!$I$8 -> 70.751624
B8: 0.26 | C8: =DDM!$E$6/(1+$B8)^DDM!$E$8+DDM!$F$6/(1+$B8)^DDM!$F$8+DDM!$G$6/(1+$B8)^DDM!$G$8+DDM!$H$6/(1+$B8)^DDM!$H$8+DDM!$I$6/(1+$B8)^DDM!$I$8+((C$5-Assumptions!$D$14)/($B8-Assumptions!$D$14))*DDM!$I$7/(1+$B8)^DDM!$I$8 -> 27.577562 | D8: =DDM!$E$6/(1+$B8)^DDM!$E$8+DDM!$F$6/(1+$B8)^DDM!$F$8+DDM!$G$6/(1+$B8)^DDM!$G$8+DDM!$H$6/(1+$B8)^DDM!$H$8+DDM!$I$6/(1+$B8)^DDM!$I$8+((D$5-Assumptions!$D$14)/($B8-Assumptions!$D$14))*DDM!$I$7/(1+$B8)^DDM!$I$8 -> 33.671647 | E8: =DDM!$E$6/(1+$B8)^DDM!$E$8+DDM!$F$6/(1+$B8)^DDM!$F$8+DDM!$G$6/(1+$B8)^DDM!$G$8+DDM!$H$6/(1+$B8)^DDM!$H$8+DDM!$I$6/(1+$B8)^DDM!$I$8+((E$5-Assumptions!$D$14)/($B8-Assumptions!$D$14))*DDM!$I$7/(1+$B8)^DDM!$I$8 -> 39.765732 | F8: =DDM!$E$6/(1+$B8)^DDM!$E$8+DDM!$F$6/(1+$B8)^DDM!$F$8+DDM!$G$6/(1+$B8)^DDM!$G$8+DDM!$H$6/(1+$B8)^DDM!$H$8+DDM!$I$6/(1+$B8)^DDM!$I$8+((F$5-Assumptions!$D$14)/($B8-Assumptions!$D$14))*DDM!$I$7/(1+$B8)^DDM!$I$8 -> 45.859817 | G8: =DDM!$E$6/(1+$B8)^DDM!$E$8+DDM!$F$6/(1+$B8)^DDM!$F$8+DDM!$G$6/(1+$B8)^DDM!$G$8+DDM!$H$6/(1+$B8)^DDM!$H$8+DDM!$I$6/(1+$B8)^DDM!$I$8+((G$5-Assumptions!$D$14)/($B8-Assumptions!$D$14))*DDM!$I$7/(1+$B8)^DDM!$I$8 -> 51.953901
B9: 0.29 | C9: =DDM!$E$6/(1+$B9)^DDM!$E$8+DDM!$F$6/(1+$B9)^DDM!$F$8+DDM!$G$6/(1+$B9)^DDM!$G$8+DDM!$H$6/(1+$B9)^DDM!$H$8+DDM!$I$6/(1+$B9)^DDM!$I$8+((C$5-Assumptions!$D$14)/($B9-Assumptions!$D$14))*DDM!$I$7/(1+$B9)^DDM!$I$8 -> 21.598746 | D9: =DDM!$E$6/(1+$B9)^DDM!$E$8+DDM!$F$6/(1+$B9)^DDM!$F$8+DDM!$G$6/(1+$B9)^DDM!$G$8+DDM!$H$6/(1+$B9)^DDM!$H$8+DDM!$I$6/(1+$B9)^DDM!$I$8+((D$5-Assumptions!$D$14)/($B9-Assumptions!$D$14))*DDM!$I$7/(1+$B9)^DDM!$I$8 -> 26.166902 | E9: =DDM!$E$6/(1+$B9)^DDM!$E$8+DDM!$F$6/(1+$B9)^DDM!$F$8+DDM!$G$6/(1+$B9)^DDM!$G$8+DDM!$H$6/(1+$B9)^DDM!$H$8+DDM!$I$6/(1+$B9)^DDM!$I$8+((E$5-Assumptions!$D$14)/($B9-Assumptions!$D$14))*DDM!$I$7/(1+$B9)^DDM!$I$8 -> 30.735059 | F9: =DDM!$E$6/(1+$B9)^DDM!$E$8+DDM!$F$6/(1+$B9)^DDM!$F$8+DDM!$G$6/(1+$B9)^DDM!$G$8+DDM!$H$6/(1+$B9)^DDM!$H$8+DDM!$I$6/(1+$B9)^DDM!$I$8+((F$5-Assumptions!$D$14)/($B9-Assumptions!$D$14))*DDM!$I$7/(1+$B9)^DDM!$I$8 -> 35.303216 | G9: =DDM!$E$6/(1+$B9)^DDM!$E$8+DDM!$F$6/(1+$B9)^DDM!$F$8+DDM!$G$6/(1+$B9)^DDM!$G$8+DDM!$H$6/(1+$B9)^DDM!$H$8+DDM!$I$6/(1+$B9)^DDM!$I$8+((G$5-Assumptions!$D$14)/($B9-Assumptions!$D$14))*DDM!$I$7/(1+$B9)^DDM!$I$8 -> 39.871373
B10: 0.32 | C10: =DDM!$E$6/(1+$B10)^DDM!$E$8+DDM!$F$6/(1+$B10)^DDM!$F$8+DDM!$G$6/(1+$B10)^DDM!$G$8+DDM!$H$6/(1+$B10)^DDM!$H$8+DDM!$I$6/(1+$B10)^DDM!$I$8+((C$5-Assumptions!$D$14)/($B10-Assumptions!$D$14))*DDM!$I$7/(1+$B10)^DDM!$I$8 -> 17.449945 | D10: =DDM!$E$6/(1+$B10)^DDM!$E$8+DDM!$F$6/(1+$B10)^DDM!$F$8+DDM!$G$6/(1+$B10)^DDM!$G$8+DDM!$H$6/(1+$B10)^DDM!$H$8+DDM!$I$6/(1+$B10)^DDM!$I$8+((D$5-Assumptions!$D$14)/($B10-Assumptions!$D$14))*DDM!$I$7/(1+$B10)^DDM!$I$8 -> 20.980681 | E10: =DDM!$E$6/(1+$B10)^DDM!$E$8+DDM!$F$6/(1+$B10)^DDM!$F$8+DDM!$G$6/(1+$B10)^DDM!$G$8+DDM!$H$6/(1+$B10)^DDM!$H$8+DDM!$I$6/(1+$B10)^DDM!$I$8+((E$5-Assumptions!$D$14)/($B10-Assumptions!$D$14))*DDM!$I$7/(1+$B10)^DDM!$I$8 -> 24.511417 | F10: =DDM!$E$6/(1+$B10)^DDM!$E$8+DDM!$F$6/(1+$B10)^DDM!$F$8+DDM!$G$6/(1+$B10)^DDM!$G$8+DDM!$H$6/(1+$B10)^DDM!$H$8+DDM!$I$6/(1+$B10)^DDM!$I$8+((F$5-Assumptions!$D$14)/($B10-Assumptions!$D$14))*DDM!$I$7/(1+$B10)^DDM!$I$8 -> 28.042153 | G10: =DDM!$E$6/(1+$B10)^DDM!$E$8+DDM!$F$6/(1+$B10)^DDM!$F$8+DDM!$G$6/(1+$B10)^DDM!$G$8+DDM!$H$6/(1+$B10)^DDM!$H$8+DDM!$I$6/(1+$B10)^DDM!$I$8+((G$5-Assumptions!$D$14)/($B10-Assumptions!$D$14))*DDM!$I$7/(1+$B10)^DDM!$I$8 -> 31.572888
A12: Spot 46.64 sits inside the grid — around a ~26% COE on a 26–28% terminal ROE, or ~23% on 24%.

Sheet Per-Share & Ratios
A1: Per-share & ratios
B3: FY23 | C3: FY24 | D3: FY25 | E3: FY26E | F3: FY27E | G3: FY28E | H3: FY29E | I3: FY30E
A4: EPS, current 1,500mn shares (EGP) | B4: ='Income Statement'!B14 -> 3.1333333 | C4: ='Income Statement'!C14 -> 6.0053333 | D4: ='Income Statement'!D14 -> 8.392 | E4: ='Income Statement'!E14 -> 10.526046 | F4: ='Income Statement'!F14 -> 12.371928 | G4: ='Income Statement'!G14 -> 14.480608 | H4: ='Income Statement'!H14 -> 16.568819 | I4: ='Income Statement'!I14 -> 18.822212
A5: DPS declared (EGP) | B5: 0 | C5: 0 | D5: 0 | E5: ='Income Statement'!E14*Assumptions!C18 -> 0 | F5: ='Income Statement'!F14*Assumptions!D18 -> 1.2371928 | G5: ='Income Statement'!G14*Assumptions!E18 -> 2.1720913 | H5: ='Income Statement'!H14*Assumptions!F18 -> 3.3137638 | I5: ='Income Statement'!I14*Assumptions!G18 -> 4.7055529 | K5: No cash dividends to date; growth funded by retention + capital hikes
A6: BVPS (EGP) | B6: ='Balance Sheet'!B16/Assumptions!$B$5 -> 9.9333333 | C6: ='Balance Sheet'!C16/Assumptions!$B$5 -> 15.333333 | D6: =DDM!D7 -> 24.866667 | E6: =DDM!E7 -> 35.392712 | F6: =DDM!F7 -> 46.527447 | G6: =DDM!G7 -> 58.835965 | H6: =DDM!H7 -> 72.09102 | I6: =DDM!I7 -> 86.207678
A7: Payout ratio | E7: =E5/E4 -> 0 | F7: =F5/F4 -> 0.1 | G7: =G5/G4 -> 0.15 | H7: =H5/H4 -> 0.2 | I7: =I5/I4 -> 0.25
A8: ROE (avg attributable equity) | C8: ='Income Statement'!C13/(('Balance Sheet'!B16+'Balance Sheet'!C16)/2) -> 0.4753562 | D8: ='Income Statement'!D13/(('Balance Sheet'!C16+'Balance Sheet'!D16)/2) -> 0.41751244 | E8: ='Income Statement'!E13/(('Balance Sheet'!D16+'Balance Sheet'!E16)/2) -> 0.34935792 | F8: ='Income Statement'!F13/(('Balance Sheet'!E16+'Balance Sheet'!F16)/2) -> 0.30204844 | G8: ='Income Statement'!G13/(('Balance Sheet'!F16+'Balance Sheet'!G16)/2) -> 0.27486977 | H8: ='Income Statement'!H13/(('Balance Sheet'!G16+'Balance Sheet'!H16)/2) -> 0.25310014 | I8: ='Income Statement'!I13/(('Balance Sheet'!H16+'Balance Sheet'!I16)/2) -> 0.23780627 | K8: Reported ROE 44% (FY25) uses the company basis; model ROE is on avg attributable equity
A9: ROAA | C9: ='Income Statement'!C11/(('Balance Sheet'!B8+'Balance Sheet'!C8)/2) -> 0.043140965 | D9: ='Income Statement'!D11/(('Balance Sheet'!C8+'Balance Sheet'!D8)/2) -> 0.041670762 | E9: ='Income Statement'!E11/(('Balance Sheet'!D8+'Balance Sheet'!E8)/2) -> 0.039480664 | F9: ='Income Statement'!F11/(('Balance Sheet'!E8+'Balance Sheet'!F8)/2) -> 0.036601875 | G9: ='Income Statement'!G11/(('Balance Sheet'!F8+'Balance Sheet'!G8)/2) -> 0.035097239 | H9: ='Income Statement'!H11/(('Balance Sheet'!G8+'Balance Sheet'!H8)/2) -> 0.033752663 | I9: ='Income Statement'!I11/(('Balance Sheet'!H8+'Balance Sheet'!I8)/2) -> 0.032889971
A10: Cost-to-income | B10: ='Income Statement'!B16 -> 0.25963303 | C10: ='Income Statement'!C16 -> 0.1898945 | D10: ='Income Statement'!D16 -> 0.1720339 | E10: ='Income Statement'!E16 -> 0.18 | F10: ='Income Statement'!F16 -> 0.185 | G10: ='Income Statement'!G16 -> 0.19 | H10: ='Income Statement'!H16 -> 0.195 | I10: ='Income Statement'!I16 -> 0.2
A11: P/E at spot | B11: =Assumptions!$B$4/B4 -> 14.885106 | C11: =Assumptions!$B$4/C4 -> 7.7664298 | D11: =Assumptions!$B$4/D4 -> 5.557674 | E11: =Assumptions!$B$4/E4 -> 4.4309138 | F11: =Assumptions!$B$4/F4 -> 3.7698247 | G11: =Assumptions!$B$4/G4 -> 3.2208591 | H11: =Assumptions!$B$4/H4 -> 2.8149261 | I11: =Assumptions!$B$4/I4 -> 2.4779235
A12: P/B at spot | B12: =Assumptions!$B$4/B6 -> 4.695302 | C12: =Assumptions!$B$4/C6 -> 3.0417391 | D12: =Assumptions!$B$4/D6 -> 1.8756032 | E12: =Assumptions!$B$4/E6 -> 1.3177854 | F12: =Assumptions!$B$4/F6 -> 1.0024191 | G12: =Assumptions!$B$4/G6 -> 0.79271242 | H12: =Assumptions!$B$4/H6 -> 0.64695992 | I12: =Assumptions!$B$4/I6 -> 0.54101909
A13: Dividend yield at spot | B13: =B5/Assumptions!$B$4 -> 0 | C13: =C5/Assumptions!$B$4 -> 0 | D13: =D5/Assumptions!$B$4 -> 0 | E13: =E5/Assumptions!$B$4 -> 0 | F13: =F5/Assumptions!$B$4 -> 0.026526433 | G13: =G5/Assumptions!$B$4 -> 0.046571425 | H13: =H5/Assumptions!$B$4 -> 0.071049823 | I13: =I5/Assumptions!$B$4 -> 0.10089093

Sheet Peer & Sector
A1: Peer set & sector structure
A3: ADIB-EGYPT VS THE EGYPTIAN BANK COMPLEX (approximate mid-2026 marks)
A4: Metric | B4: EGX banks (typ.) | C4: ADIB-Egypt | D4: Premium
A5: P/E (trailing) | B5: 5–7x | C5: =Assumptions!$B$4/'Income Statement'!$D$14 -> 5.557674
A6: P/B | B6: 1.5–2.5x | C6: =Assumptions!$B$4/DDM!$D$7 -> 1.8756032
A7: ROE | B7: 30–40% | C7: 0.44
A8: Cost-to-income | B8: ~25–30% | C8: 0.172
A9: CAR | B9: ~18–20% | C9: 0.1944
A11: PEERS — roles in the comparison
A12: Peer | E12: Role
A13: Commercial International Bank (CIB) | E13: Egypt's private-sector benchmark — ~2.3x book, ~38% ROE; the quality yardstick
A14: QNB Alahli | E14: Foreign-owned scale peer; corporate-led, similar T-bill carry economics
A15: Faisal Islamic Bank of Egypt | E15: The listed Islamic incumbent — the direct Shariah comparison, cheaper and slower-growing
A16: Banque du Caire / Baraka | E16: State & Islamic mid-tier context; Banque du Caire FY25 profit +30%
A18: PRINCIPAL RISKS
A19: Disinflation & CBE easing compress the T-bill carry and NIM that produced a 44% ROE
A20: Credit seasoning after +53% financing growth in a single year; today's benign CoR is a boom-cycle reading
A21: EGP regime risk — a further step-devaluation cuts USD value even as EGP earnings reprice up
A22: Sovereign concentration: the securities book ties the bank to Egypt's fiscal path and IMF program
A23: Dilution: growth has been funded by repeated capital increases (12→15bn in 2025); more may follow
A24: Free-float, liquidity and majority control (ADIB Group) — minority-shareholder considerations
