Workbook

Sheet READ FIRST
A1: Testahil — Al Rajhi Bank (Tadawul: 1120)
A2: Companion model · Independent Valuation Study — Educational Analysis · Not investment advice
A5: What this workbook is. A transparent companion to the Al Rajhi Bank valuation study. Every blue cell is an input; every
A6: black cell is a formula; green cells link across sheets. Change one input on the Assumptions sheet (Ke, a NIM, the
A7: terminal growth, the payout path) and the whole model re-prices. The single input layer is the Assumptions sheet.
A9: What it is not. It is not investment advice, a recommendation, or a price target. It is a valuation exercise, published
A10: free for education. Outputs are ranges and distributions, not a single number. The preparer is not licensed by any
A11: securities regulator and may hold a position in the security. See the study's Disclosure & Disclaimer.
A13: Bank lens. Al Rajhi is valued as a bank: the primary lens is a dividend discount model (DDM), cross-checked by a
A14: residual-income (excess-return) model, a free-cash-flow-to-equity (FCFE) discount model, relative P/B and P/E, and a
A15: normalized through-cycle-ROE read. The 'DCF' sheet is the bank-appropriate FCFE build required for the study.
A17: Currency. SAR millions unless stated; per-share figures in SAR. SAR is pegged to USD at 3.75. Anchor: SAR 66.00,
... A20: sheet lines are estimated to tie to disclosed totals. Forward inputs are the preparer's judgments and are flagged.

Sheet Summary
A1: Valuation summary — Al Rajhi Bank (Tadawul: 1120)
A2: Five-lens fair value vs spot. Base links live; bear/bull are input scenarios.
B3: Bear | C3: Base | D3: Bull | E3: Weight
A4: Dividend discount (DDM) | B4: 52 | C4: =DDM!B15 -> 58.230306 | D4: 80 | E4: =Assumptions!$B$32 -> 0.25
A5: Residual income | B5: 60 | C5: =DDM!B26 -> 76.844952 | D5: 94 | E5: =Assumptions!$B$33 -> 0.25
A6: FCFE (DCF) | B6: 54 | C6: =DCF!B17 -> 0 | D6: 84 | E6: =Assumptions!$B$34 -> 0.15
A7: Relative (justified P/B) | B7: 56 | C7: ='Relative & Normalized'!C4 -> 75.656787 | D7: 92 | E7: =Assumptions!$B$35 -> 0.15
A8: Normalized earnings | B8: 54 | C8: ='Relative & Normalized'!C9 -> 65.2575 | D8: 82 | E8: =Assumptions!$B$36 -> 0.2
A9: Weighted central | B9: =SUMPRODUCT(B4:B8,$E$4:$E$8) -> 55.3 | C9: =SUMPRODUCT(C4:C8,$E$4:$E$8) -> 58.168833 | D9: =SUMPRODUCT(D4:D8,$E$4:$E$8) -> 86.3 | E9: =SUM(E4:E8) -> 1
A11: Spot price (SAR) | C11: =Assumptions!$B$4 -> 66
A12: Upside to central base | C12: =C9/C11-1 -> -0.11865405
A14: Read: roughly fairly valued; the dividend lens is cautious, the excess-return/P/B lens sees modest upside — the
A15: spread is the value the market puts on Al Rajhi’s high-ROE retained-earnings franchise and NIM resilience.

Sheet Fundamental Valuation
A1: Fundamental valuation — football field
A2: Bear/base/bull per lens (links to Summary).
B3: Bear | C3: Base | D3: Bull
A4: Dividend discount (DDM) | B4: =Summary!B4 -> 52 | C4: =Summary!C4 -> 58.230306 | D4: =Summary!D4 -> 80
A5: Residual income | B5: =Summary!B5 -> 60 | C5: =Summary!C5 -> 76.844952 | D5: =Summary!D5 -> 94
A6: FCFE (DCF) | B6: =Summary!B6 -> 54 | C6: =Summary!C6 -> 0 | D6: =Summary!D6 -> 84
A7: Relative (justified P/B) | B7: =Summary!B7 -> 56 | C7: =Summary!C7 -> 75.656787 | D7: =Summary!D7 -> 92
A8: Normalized earnings | B8: =Summary!B8 -> 54 | C8: =Summary!C8 -> 65.2575 | D8: =Summary!D8 -> 82
A9: Weighted central | B9: =Summary!B9 -> 55.3 | C9: =Summary!C9 -> 58.168833 | D9: =Summary!D9 -> 86.3
A10: Spot | C10: =Assumptions!$B$4 -> 66

Sheet Assumptions
A1: Assumptions — the single input layer
A2: All blue cells are inputs. Every other sheet links here.
A3: ANCHORS
A4: Spot price (SAR/share) | B4: 66
A5: Shares outstanding (mn) | B5: 6000
A6: FY25 net income (SAR mn) | B6: 24792
A7: FY25 common equity (SAR mn) | B7: 113000
A8: FY25 net financing (SAR mn) | B8: 752800
A9: FY25 total assets (SAR mn) | B9: 1043000
A10: FY25 investments (SAR mn) | B10: 174000
A12: COST OF EQUITY (Ke = rf + β × ERP)
A13: Risk-free rate (10y KSA govt) | B13: 0.0525
A14: Equity risk premium (ERP) | B14: 0.0475
A15: Beta | B15: 0.9
A16: Cost of equity (Ke) | B16: =B13+B15*B14 -> 0.09525
A17: Terminal growth (g) | B17: 0.05
A18: Zakat & income tax rate | B18: 0.115
A20: RELATIVE & NORMALIZED
A21: Target P/B (own, ~3.5x) | B21: 3.5
A22: Peer median P/B | B22: 1.6
A23: Peer median P/E | B23: 10.5
A24: Through-cycle ROE | B24: 0.21
A25: Justified P/E (normalized) | B25: 16.5
A27: CAPITAL
A28: RWA density (RWA / total assets) | B28: 0.585
A29: CET1 target | B29: 0.185
A31: SYNTHESIS WEIGHTS (five lenses)
A32: DDM weight | B32: 0.25
A33: Residual income weight | B33: 0.25
A34: FCFE (DCF) weight | B34: 0.15
A35: Relative weight | B35: 0.15
A36: Normalized-earnings weight | B36: 0.2
A38: MONTE CARLO (YZ-HAR width; KVOL retired)
A39: Diffusion volatility (annualized, YZ-HAR) | B39: 0.1781
A40: Net 3-month external drift | B40: 0.012
A42: FORECAST DRIVERS (FY26E–FY30E)
E43: FY26E | F43: FY27E | G43: FY28E | H43: FY29E | I43: FY30E
A44: Financing growth | E44: 0.055 | F44: 0.07 | G44: 0.08 | H44: 0.075 | I44: 0.07
A45: Net interest margin (NIM, %) | E45: 3.45 | F45: 3.5 | G45: 3.4 | H45: 3.3 | I45: 3.25
A46: Cost-to-income (%) | E46: 23.5 | F46: 23.5 | G46: 23 | H46: 22.8 | I46: 22.5
...

Sheet DDM
A1: Dividend discount model & residual income (primary lens)
A2: DPS discounted at Ke; residual income cross-checks on excess return over Ke. Terminal via Gordon.
E3: FY26E | F3: FY27E | G3: FY28E | H3: FY29E | I3: FY30E
A4: Net income (SAR mn) | E4: ='Income Statement'!E13 -> 27963.838 | F4: ='Income Statement'!F13 -> 30104.011 | G4: ='Income Statement'!G13 -> 31744.001 | H4: ='Income Statement'!H13 -> 33480.484 | I4: ='Income Statement'!I13 -> 35713.867
A5: Payout ratio | E5: =Assumptions!E50 -> 0.45 | F5: =Assumptions!F50 -> 0.48 | G5: =Assumptions!G50 -> 0.5 | H5: =Assumptions!H50 -> 0.52 | I5: =Assumptions!I50 -> 0.55
A6: Dividends (SAR mn) | E6: =E4*E5 -> 12583.727 | F6: =F4*F5 -> 14449.925 | G6: =G4*G5 -> 15872.001 | H6: =H4*H5 -> 17409.852 | I6: =I4*I5 -> 19642.627
A7: DPS (SAR/share) | E7: =E6/Assumptions!$B$5 -> 2.0972878 | F7: =F6/Assumptions!$B$5 -> 2.4083209 | G7: =G6/Assumptions!$B$5 -> 2.6453334 | H7: =H6/Assumptions!$B$5 -> 2.9016419 | I7: =I6/Assumptions!$B$5 -> 3.2737711
A8: Discount factor @ Ke | E8: =1/(1+Assumptions!$B$16)^1 -> 0.91303355 | F8: =1/(1+Assumptions!$B$16)^2 -> 0.83363027 | G8: =1/(1+Assumptions!$B$16)^3 -> 0.76113241 | H8: =1/(1+Assumptions!$B$16)^4 -> 0.69493943 | I8: =1/(1+Assumptions!$B$16)^5 -> 0.63450302
A9: PV of DPS | E9: =E7*E8 -> 1.9148942 | F9: =F7*F8 -> 2.0076492 | G9: =G7*G8 -> 2.013449 | H9: =H7*H8 -> 2.0164654 | I9: =I7*I8 -> 2.0772176
A11: Σ PV of explicit DPS (FY26–FY30) | B11: =SUM(E9:I9) -> 10.029675
A12: Terminal DPS (FY31) = DPS30×(1+g) | B12: =I7*(1+Assumptions!$B$17) -> 3.4374597
A13: Terminal value = TDPS/(Ke−g) | B13: =B12/(Assumptions!$B$16-Assumptions!$B$17) -> 75.96596
A14: PV of terminal value | B14: =B13/(1+Assumptions!$B$16)^5 -> 48.20063
A15: DDM fair value per share (SAR) | B15: =B11+B14 -> 58.230306
A16: TV % of value | B16: =B14/B15 -> 0.8277585
A18: Residual income (excess-return) cross-check
A19: Opening common equity (SAR mn) | E19: =Assumptions!$B$7 -> 113000 | F19: =E19+E4-E6 -> 128380.11 | G19: =F19+F4-F6 -> 144034.2 | H19: =G19+G4-G6 -> 159906.2 | I19: =H19+H4-H6 -> 175976.83
A20: Residual income = NI − Ke×opening equity | E20: =E4-Assumptions!$B$16*E19 -> 17200.588 | F20: =F4-Assumptions!$B$16*F19 -> 17875.806 | G20: =G4-Assumptions!$B$16*G19 -> 18024.744 | H20: =H4-Assumptions!$B$16*H19 -> 18249.419 | I20: =I4-Assumptions!$B$16*I19 -> 18952.074
A21: PV of residual income | E21: =E20/(1+Assumptions!$B$16)^1 -> 15704.714 | F21: =F20/(1+Assumptions!$B$16)^2 -> 14901.813 | G21: =G20/(1+Assumptions!$B$16)^3 -> 13719.217 | H21: =H20/(1+Assumptions!$B$16)^4 -> 12682.241 | I21: =I20/(1+Assumptions!$B$16)^5 -> 12025.148
A22: Σ PV residual income | B22: =SUM(E21:I21) -> 69033.132
A23: Terminal RI = RI30×(1+g)/(Ke−g) | B23: =I20*(1+Assumptions!$B$17)/(Assumptions!$B$16-Assumptions!$B$17) -> 439771.88
A24: PV of terminal RI | B24: =B23/(1+Assumptions!$B$16)^5 -> 279036.58
A25: RI equity value = BV0 + ΣPV + PV term | B25: =Assumptions!$B$7+B22+B24 -> 461069.71
A26: RI fair value per share (SAR) | B26: =B25/Assumptions!$B$5 -> 76.844952

Sheet Segments
A1: Segment view — operating income by segment
A2: Al Rajhi reports Retail, Corporate, Treasury, and Investment Services & Brokerage. FY25 split (blue) held on total op income.
B3: FY23 | C3: FY24 | D3: FY25 | E3: FY26E | F3: FY27E | G3: FY28E | H3: FY29E | I3: FY30E
A4: Retail — operating income | B4: ='Income Statement'!B6*0.58 -> 16182 | C4: ='Income Statement'!C6*0.58 -> 18589 | D4: ='Income Statement'!D6*0.58 -> 22674.52 | E4: ='Income Statement'!E6*0.58 -> 26008.878 | F4: ='Income Statement'!F6*0.58 -> 28158.004 | G4: ='Income Statement'!G6*0.58 -> 29681.002 | H4: ='Income Statement'!H6*0.58 -> 31283.826 | I4: ='Income Statement'!I6*0.58 -> 33257.755
A5: Corporate — operating income | B5: ='Income Statement'!B6*0.2 -> 5580 | C5: ='Income Statement'!C6*0.2 -> 6410 | D5: ='Income Statement'!D6*0.2 -> 7818.8 | E5: ='Income Statement'!E6*0.2 -> 8968.5788 | F5: ='Income Statement'!F6*0.2 -> 9709.6565 | G5: ='Income Statement'!G6*0.2 -> 10234.828 | H5: ='Income Statement'!H6*0.2 -> 10787.526 | I5: ='Income Statement'!I6*0.2 -> 11468.191
A6: Treasury — operating income | B6: ='Income Statement'!B6*0.15 -> 4185 | C6: ='Income Statement'!C6*0.15 -> 4807.5 | D6: ='Income Statement'!D6*0.15 -> 5864.1 | E6: ='Income Statement'!E6*0.15 -> 6726.4341 | F6: ='Income Statement'!F6*0.15 -> 7282.2424 | G6: ='Income Statement'!G6*0.15 -> 7676.1212 | H6: ='Income Statement'!H6*0.15 -> 8090.6447 | I6: ='Income Statement'!I6*0.15 -> 8601.1434
A7: Investment & brokerage — operating income | B7: ='Income Statement'!B6*0.07 -> 1953 | C7: ='Income Statement'!C6*0.07 -> 2243.5 | D7: ='Income Statement'!D6*0.07 -> 2736.58 | E7: ='Income Statement'!E6*0.07 -> 3139.0026 | F7: ='Income Statement'!F6*0.07 -> 3398.3798 | G7: ='Income Statement'!G6*0.07 -> 3582.1899 | H7: ='Income Statement'!H6*0.07 -> 3775.6342 | I7: ='Income Statement'!I6*0.07 -> 4013.8669
A8: Total operating income | B8: ='Income Statement'!B6 -> 27900 | C8: ='Income Statement'!C6 -> 32050 | D8: ='Income Statement'!D6 -> 39094 | E8: ='Income Statement'!E6 -> 44842.894 | F8: ='Income Statement'!F6 -> 48548.283 | G8: ='Income Statement'!G6 -> 51174.141 | H8: ='Income Statement'!H6 -> 53937.631 | I8: ='Income Statement'!I6 -> 57340.956
A9: Retail % of op income | B9: =B4/B8 -> 0.58 | C9: =C4/C8 -> 0.58 | D9: =D4/D8 -> 0.58 | E9: =E4/E8 -> 0.58 | F9: =F4/F8 -> 0.58 | G9: =G4/G8 -> 0.58 | H9: =H4/H8 -> 0.58 | I9: =I4/I8 -> 0.58
A10: Financing (loans, SAR mn) | B10: ='Balance Sheet'!B5 -> 602000 | C10: ='Balance Sheet'!C5 -> 693400 | D10: ='Balance Sheet'!D5 -> 752800 | E10: ='Balance Sheet'!E5 -> 794204 | F10: ='Balance Sheet'!F5 -> 849798.28 | G10: ='Balance Sheet'!G5 -> 917782.14 | H10: ='Balance Sheet'!H5 -> 986615.8 | I10: ='Balance Sheet'!I5 -> 1055678.9

Sheet Relative & Normalized
A1: Relative & normalized-earnings lenses
A2: Justified P/B (Gordon) is the relative anchor; peer multiples shown as context. Links to Assumptions.
B3: Workings | C3: SAR/share
A4: Justified P/B (Gordon) | B4: (ROEtc−g)/(Ke−g) × fwd BVPS | C4: =(Assumptions!$B$24-Assumptions!$B$17)/(Assumptions!$B$16-Assumptions!$B$17)*('Balance Sheet'!E13/Assumptions!$B$5) -> 75.656787
A5: justified P/B multiple (x) | B5: for reference | C5: =(Assumptions!$B$24-Assumptions!$B$17)/(Assumptions!$B$16-Assumptions!$B$17) -> 3.5359116
A6: Own current P/B applied | B6: target P/B × fwd BVPS (no re-rating) | C6: =Assumptions!$B$21*('Balance Sheet'!E13/Assumptions!$B$5) -> 74.888398
A7: Peer-median P/B applied | B7: sector 1.6x × fwd BVPS (ignores ROE gap) | C7: =Assumptions!$B$22*('Balance Sheet'!E13/Assumptions!$B$5) -> 34.234696
A8: Peer-median P/E applied | B8: sector 10.5x × fwd EPS | C8: =Assumptions!$B$23*('Income Statement'!E13/Assumptions!$B$5) -> 48.936716
A9: Normalized earnings power | B9: through-cycle ROE×BVPS × justified P/E | C9: =Assumptions!$B$24*('Balance Sheet'!D13/Assumptions!$B$5)*Assumptions!$B$25 -> 65.2575
A10: normalized EPS (SAR) | B10: ROEtc × current BVPS | C10: =Assumptions!$B$24*('Balance Sheet'!D13/Assumptions!$B$5) -> 3.955
A12: Relative lens → Summary uses the justified-P/B value (row 4); normalized → row 9.

Sheet DCF
A1: Discounted cash flow — equity DCF (FCFE)
A2: Bank equity is valued by discounting free cash flow to equity (FCFE) at the cost of equity Ke. A debt-inclusive WACC is not used for a bank — deposits/funding are operating, not financing — so the equity discount rate Ke is the DCF discount rate.
A4: Discount rate (WACC for the equity claim = cost of equity Ke)
A5: Risk-free rate (Saudi 10-yr, SAR) | B5: =Assumptions!B13 -> 0.0525
A6: Equity risk premium (ERP) | B6: =Assumptions!B14 -> 0.0475
A7: Beta (levered, 0.8–1.3 band) | B7: =Assumptions!B15 -> 0.9
A8: Cost of equity Ke = rf + β × ERP (the WACC used) | B8: =Assumptions!B16 -> 0.09525
A9: Terminal growth g | B9: =Assumptions!B17 -> 0.05
A11: FCFE build (SAR mn) | C11: FY26E | D11: FY27E | E11: FY28E | F11: FY29E | G11: FY30E
A12: Net income | C12: ='Income Statement'!E13 -> 27963.838 | D12: ='Income Statement'!F13 -> 30104.011 | E12: ='Income Statement'!G13 -> 31744.001 | F12: ='Income Statement'!H13 -> 33480.484 | G12: ='Income Statement'!I13 -> 35713.867
A13: Risk-weighted assets (RWA) | C13: ='Balance Sheet'!E18 -> 640905.53 | D13: ='Balance Sheet'!F18 -> 681298.75 | E13: ='Balance Sheet'!G18 -> 731188.71 | F13: ='Balance Sheet'!H18 -> 781780.61 | G13: ='Balance Sheet'!I18 -> 832662.61
A14: Required CET1 capital (target × RWA) | C14: =Assumptions!$B$29*C13 -> 118567.52 | D14: =Assumptions!$B$29*D13 -> 126040.27 | E14: =Assumptions!$B$29*E13 -> 135269.91 | F14: =Assumptions!$B$29*F13 -> 144629.41 | G14: =Assumptions!$B$29*G13 -> 154042.58
A15: − Increase in required capital | C15: =-(C14-Assumptions!$B$29*'Balance Sheet'!D18) -> -5688.8471 | D15: =-(D14-C14) -> -7472.7469 | E15: =-(E14-D14) -> -9229.6427 | F15: =-(F14-E14) -> -9359.5007 | G15: =-(G14-F14) -> -9413.171
A16: FCFE = Net income − Δ required capital | C16: =C12+C15 -> 22274.991 | D16: =D12+D15 -> 22631.264 | E16: =E12+E15 -> 22514.359 | F16: =F12+F15 -> 24120.983 | G16: =G12+G15 -> 26300.696
A17: Discount period (years) | C17: 1 | D17: 2 | E17: 3 | F17: 4 | G17: 5
A18: Discount factor = 1/(1+Ke)^t | C18: =1/(1+$B$8)^C17 -> 0.91303355 | D18: =1/(1+$B$8)^D17 -> 0.83363027 | E18: =1/(1+$B$8)^E17 -> 0.76113241 | F18: =1/(1+$B$8)^F17 -> 0.69493943 | G18: =1/(1+$B$8)^G17 -> 0.63450302
A19: PV of FCFE @ Ke | C19: =C16*C18 -> 20337.814 | D19: =D16*D18 -> 18866.107 | E19: =E16*E18 -> 17136.408 | F19: =F16*F18 -> 16762.622 | G19: =G16*G18 -> 16687.871
A21: Σ PV of explicit FCFE (FY26–30E) | B21: =SUM(C19:G19) -> 89790.822
A22: Terminal FCFE (FY31) = FCFE₃₀ × (1+g) | B22: =G16*(1+$B$9) -> 27615.731
A23: Terminal value = Terminal FCFE / (Ke − g) | B23: =B22/($B$8-$B$9) -> 610292.39
A24: PV of terminal value = TV / (1+Ke)^5 | B24: =B23/(1+$B$8)^5 -> 387232.36
A25: Equity value = Σ PV(FCFE) + PV(TV) | B25: =B21+B24 -> 477023.18
A26: Shares outstanding (mn) | B26: =Assumptions!B5 -> 6000
A27: DCF fair value per share (SAR) | B27: =B25/B26 -> 79.503864
A28: Terminal value as % of equity value | B28: =B24/B25 -> 0.81176843
A30: Sensitivity — DCF value per share (WACC/Ke × terminal g)
A31: Ke ↓ g → | B31: 0.04 | C31: 0.045 | D31: 0.05 | E31: 0.055 | F31: 0.06
A32: Ke 8.5% | B32: =(($C$16/(1+0.085)^1+$D$16/(1+0.085)^2+$E$16/(1+0.085)^3+$F$16/(1+0.085)^4+$G$16/(1+0.085)^5)+(($G$16*(1+0.04)/(0.085-0.04))/(1+0.085)^5))/$B$26 -> 82.752864 | C32: =(($C$16/(1+0.085)^1+$D$16/(1+0.085)^2+$E$16/(1+0.085)^3+$F$16/(1+0.085)^4+$G$16/(1+0.085)^5)+(($G$16*(1+0.045)/(0.085-0.045))/(1+0.085)^5))/$B$26 -> 91.538932 | D32: =(($C$16/(1+0.085)^1+$D$16/(1+0.085)^2+$E$16/(1+0.085)^3+$F$16/(1+0.085)^4+$G$16/(1+0.085)^5)+(($G$16*(1+0.05)/(0.085-0.05))/(1+0.085)^5))/$B$26 -> 102.8353 | E32: =(($C$16/(1+0.085)^1+$D$16/(1+0.085)^2+$E$16/(1+0.085)^3+$F$16/(1+0.085)^4+$G$16/(1+0.085)^5)+(($G$16*(1+0.055)/(0.085-0.055))/(1+0.085)^5))/$B$26 -> 117.89713 | F32: =(($C$16/(1+0.085)^1+$D$16/(1+0.085)^2+$E$16/(1+0.085)^3+$F$16/(1+0.085)^4+$G$16/(1+0.085)^5)+(($G$16*(1+0.06)/(0.085-0.06))/(1+0.085)^5))/$B$26 -> 138.9837
A33: Ke 9.0% | B33: =(($C$16/(1+0.09)^1+$D$16/(1+0.09)^2+$E$16/(1+0.09)^3+$F$16/(1+0.09)^4+$G$16/(1+0.09)^5)+(($G$16*(1+0.04)/(0.09-0.04))/(1+0.09)^5))/$B$26 -> 74.433117 | C33: =(($C$16/(1+0.09)^1+$D$16/(1+0.09)^2+$E$16/(1+0.09)^3+$F$16/(1+0.09)^4+$G$16/(1+0.09)^5)+(($G$16*(1+0.045)/(0.09-0.045))/(1+0.09)^5))/$B$26 -> 81.333886 | D33: =(($C$16/(1+0.09)^1+$D$16/(1+0.09)^2+$E$16/(1+0.09)^3+$F$16/(1+0.09)^4+$G$16/(1+0.09)^5)+(($G$16*(1+0.05)/(0.09-0.05))/(1+0.09)^5))/$B$26 -> 89.959847 | E33: =(($C$16/(1+0.09)^1+$D$16/(1+0.09)^2+$E$16/(1+0.09)^3+$F$16/(1+0.09)^4+$G$16/(1+0.09)^5)+(($G$16*(1+0.055)/(0.09-0.055))/(1+0.09)^5))/$B$26 -> 101.05037 | F33: =(($C$16/(1+0.09)^1+$D$16/(1+0.09)^2+$E$16/(1+0.09)^3+$F$16/(1+0.09)^4+$G$16/(1+0.09)^5)+(($G$16*(1+0.06)/(0.09-0.06))/(1+0.09)^5))/$B$26 -> 115.83773
A34: Ke 9.5% (base) | B34: =(($C$16/(1+0.095)^1+$D$16/(1+0.095)^2+$E$16/(1+0.095)^3+$F$16/(1+0.095)^4+$G$16/(1+0.095)^5)+(($G$16*(1+0.04)/(0.095-0.04))/(1+0.095)^5))/$B$26 -> 67.627174 | C34: =(($C$16/(1+0.095)^1+$D$16/(1+0.095)^2+$E$16/(1+0.095)^3+$F$16/(1+0.095)^4+$G$16/(1+0.095)^5)+(($G$16*(1+0.045)/(0.095-0.045))/(1+0.095)^5))/$B$26 -> 73.170837 | D34: =(($C$16/(1+0.095)^1+$D$16/(1+0.095)^2+$E$16/(1+0.095)^3+$F$16/(1+0.095)^4+$G$16/(1+0.095)^5)+(($G$16*(1+0.05)/(0.095-0.05))/(1+0.095)^5))/$B$26 -> 79.946425 | E34: =(($C$16/(1+0.095)^1+$D$16/(1+0.095)^2+$E$16/(1+0.095)^3+$F$16/(1+0.095)^4+$G$16/(1+0.095)^5)+(($G$16*(1+0.055)/(0.095-0.055))/(1+0.095)^5))/$B$26 -> 88.41591 | F34: =(($C$16/(1+0.095)^1+$D$16/(1+0.095)^2+$E$16/(1+0.095)^3+$F$16/(1+0.095)^4+$G$16/(1+0.095)^5)+(($G$16*(1+0.06)/(0.095-0.06))/(1+0.095)^5))/$B$26 -> 99.305248
A35: Ke 10.0% | B35: =(($C$16/(1+0.1)^1+$D$16/(1+0.1)^2+$E$16/(1+0.1)^3+$F$16/(1+0.1)^4+$G$16/(1+0.1)^5)+(($G$16*(1+0.04)/(0.1-0.04))/(1+0.1)^5))/$B$26 -> 61.956555 | C35: =(($C$16/(1+0.1)^1+$D$16/(1+0.1)^2+$E$16/(1+0.1)^3+$F$16/(1+0.1)^4+$G$16/(1+0.1)^5)+(($G$16*(1+0.045)/(0.1-0.045))/(1+0.1)^5))/$B$26 -> 66.49285 | D35: =(($C$16/(1+0.1)^1+$D$16/(1+0.1)^2+$E$16/(1+0.1)^3+$F$16/(1+0.1)^4+$G$16/(1+0.1)^5)+(($G$16*(1+0.05)/(0.1-0.05))/(1+0.1)^5))/$B$26 -> 71.936404 | E35: =(($C$16/(1+0.1)^1+$D$16/(1+0.1)^2+$E$16/(1+0.1)^3+$F$16/(1+0.1)^4+$G$16/(1+0.1)^5)+(($G$16*(1+0.055)/(0.1-0.055))/(1+0.1)^5))/$B$26 -> 78.589637 | F35: =(($C$16/(1+0.1)^1+$D$16/(1+0.1)^2+$E$16/(1+0.1)^3+$F$16/(1+0.1)^4+$G$16/(1+0.1)^5)+(($G$16*(1+0.06)/(0.1-0.06))/(1+0.1)^5))/$B$26 -> 86.906178
A36: Ke 10.5% | B36: =(($C$16/(1+0.105)^1+$D$16/(1+0.105)^2+$E$16/(1+0.105)^3+$F$16/(1+0.105)^4+$G$16/(1+0.105)^5)+(($G$16*(1+0.04)/(0.105-0.04))/(1+0.105)^5))/$B$26 -> 57.159235 | C36: =(($C$16/(1+0.105)^1+$D$16/(1+0.105)^2+$E$16/(1+0.105)^3+$F$16/(1+0.105)^4+$G$16/(1+0.105)^5)+(($G$16*(1+0.045)/(0.105-0.045))/(1+0.105)^5))/$B$26 -> 60.928635 | D36: =(($C$16/(1+0.105)^1+$D$16/(1+0.105)^2+$E$16/(1+0.105)^3+$F$16/(1+0.105)^4+$G$16/(1+0.105)^5)+(($G$16*(1+0.05)/(0.105-0.05))/(1+0.105)^5))/$B$26 -> 65.383381 | E36: =(($C$16/(1+0.105)^1+$D$16/(1+0.105)^2+$E$16/(1+0.105)^3+$F$16/(1+0.105)^4+$G$16/(1+0.105)^5)+(($G$16*(1+0.055)/(0.105-0.055))/(1+0.105)^5))/$B$26 -> 70.729076 | F36: =(($C$16/(1+0.105)^1+$D$16/(1+0.105)^2+$E$16/(1+0.105)^3+$F$16/(1+0.105)^4+$G$16/(1+0.105)^5)+(($G$16*(1+0.06)/(0.105-0.06))/(1+0.105)^5))/$B$26 -> 77.262703

Sheet Income Statement
A1: Income statement (SAR mn, consolidated — bank format)
A2: FY23–FY25 disclosed (blue); FY26E–FY30E forecast from Assumptions drivers.
B3: FY23 | C3: FY24 | D3: FY25 | E3: FY26E | F3: FY27E | G3: FY28E | H3: FY29E | I3: FY30E
A4: Net financing & investment income | B4: 22600 | C4: 25400 | D4: 30500 | E4: =Assumptions!E45/100*0.95*AVERAGE('Balance Sheet'!D8,'Balance Sheet'!E8) -> 35045.734 | F4: =Assumptions!F45/100*0.95*AVERAGE('Balance Sheet'!E8,'Balance Sheet'!F8) -> 37575.463 | G4: =Assumptions!G45/100*0.95*AVERAGE('Balance Sheet'!F8,'Balance Sheet'!G8) -> 38994.312 | H4: =Assumptions!H45/100*0.95*AVERAGE('Balance Sheet'!G8,'Balance Sheet'!H8) -> 40539.819 | I4: =Assumptions!I45/100*0.95*AVERAGE('Balance Sheet'!H8,'Balance Sheet'!I8) -> 42603.363
A5: Fee, FX & other income | B5: 5300 | C5: 6650 | D5: 8594 | E5: =D5*(1+Assumptions!E48) -> 9797.16 | F5: =E5*(1+Assumptions!F48) -> 10972.819 | G5: =F5*(1+Assumptions!G48) -> 12179.829 | H5: =G5*(1+Assumptions!H48) -> 13397.812 | I5: =H5*(1+Assumptions!I48) -> 14737.593
A6: Total operating income | B6: =SUM(B4:B5) -> 27900 | C6: =SUM(C4:C5) -> 32050 | D6: =SUM(D4:D5) -> 39094 | E6: =SUM(E4:E5) -> 44842.894 | F6: =SUM(F4:F5) -> 48548.283 | G6: =SUM(G4:G5) -> 51174.141 | H6: =SUM(H4:H5) -> 53937.631 | I6: =SUM(I4:I5) -> 57340.956
A8: Operating expenses | B8: -7400 | C8: -7980 | D8: -9110 | E8: =-Assumptions!E46/100*E6 -> -10538.08 | F8: =-Assumptions!F46/100*F6 -> -11408.846 | G8: =-Assumptions!G46/100*G6 -> -11770.053 | H8: =-Assumptions!H46/100*H6 -> -12297.78 | I8: =-Assumptions!I46/100*I6 -> -12901.715
A9: Pre-provision operating profit | B9: =B6+B8 -> 20500 | C9: =C6+C8 -> 24070 | D9: =D6+D8 -> 29984 | E9: =E6+E8 -> 34304.814 | F9: =F6+F8 -> 37139.436 | G9: =G6+G8 -> 39404.089 | H9: =H6+H8 -> 41639.851 | I9: =I6+I8 -> 44439.241
A10: Impairment charge (cost of risk) | B10: -2500 | C10: -2120 | D10: -2320 | E10: =-Assumptions!E47/10000*AVERAGE('Balance Sheet'!D5,'Balance Sheet'!E5) -> -2707.257 | F10: =-Assumptions!F47/10000*AVERAGE('Balance Sheet'!E5,'Balance Sheet'!F5) -> -3123.6043 | G10: =-Assumptions!G47/10000*AVERAGE('Balance Sheet'!F5,'Balance Sheet'!G5) -> -3535.1608 | H10: =-Assumptions!H47/10000*AVERAGE('Balance Sheet'!G5,'Balance Sheet'!H5) -> -3808.7959 | I10: =-Assumptions!I47/10000*AVERAGE('Balance Sheet'!H5,'Balance Sheet'!I5) -> -4084.5894
A11: Net income before zakat & tax | B11: =B9+B10 -> 18000 | C11: =C9+C10 -> 21950 | D11: =D9+D10 -> 27664 | E11: =E9+E10 -> 31597.557 | F11: =F9+F10 -> 34015.832 | G11: =G9+G10 -> 35868.928 | H11: =H9+H10 -> 37831.055 | I11: =I9+I10 -> 40354.652
A12: Zakat & income tax | B12: -1380 | C12: -2230 | D12: -2872 | E12: =-Assumptions!$B$18*E11 -> -3633.719 | F12: =-Assumptions!$B$18*F11 -> -3911.8207 | G12: =-Assumptions!$B$18*G11 -> -4124.9267 | H12: =-Assumptions!$B$18*H11 -> -4350.5714 | I12: =-Assumptions!$B$18*I11 -> -4640.7849
A13: Net income | B13: =B11+B12 -> 16620 | C13: =C11+C12 -> 19720 | D13: =D11+D12 -> 24792 | E13: =E11+E12 -> 27963.838 | F13: =F11+F12 -> 30104.011 | G13: =G11+G12 -> 31744.001 | H13: =H11+H12 -> 33480.484 | I13: =I11+I12 -> 35713.867
A15: memo: NIM (%) | B15: 3.05 | C15: 3.13 | D15: 3.16 | E15: =Assumptions!E45 -> 3.45 | F15: =Assumptions!F45 -> 3.5 | G15: =Assumptions!G45 -> 3.4 | H15: =Assumptions!H45 -> 3.3 | I15: =Assumptions!I45 -> 3.25
A16: memo: cost-to-income | B16: =-B8/B6 -> 0.26523297 | C16: =-C8/C6 -> 0.24898596 | D16: =-D8/D6 -> 0.23302809 | E16: =-E8/E6 -> 0.235 | F16: =-F8/F6 -> 0.235 | G16: =-G8/G6 -> 0.23 | H16: =-H8/H6 -> 0.228 | I16: =-I8/I6 -> 0.225
A17: memo: net income YoY | C17: =C13/B13-1 -> 0.18652226 | D17: =D13/C13-1 -> 0.25720081 | E17: =E13/D13-1 -> 0.12793796 | F17: =F13/E13-1 -> 0.076533607 | G17: =G13/F13-1 -> 0.05447746 | H17: =H13/G13-1 -> 0.054702705 | I17: =I13/H13-1 -> 0.066707001
A19: Source: Al Rajhi FY23–FY25 results (argaam, IR); Q1-2026 (28-Apr-2026). Forecast: house drivers on Assumptions.

Sheet Balance Sheet
A1: Balance sheet (SAR mn, consolidated — bank format)
A2: Historical anchored to disclosed equity/financing/deposits/assets; term-debt & sukuk is the balancing plug.
B3: FY23 | C3: FY24 | D3: FY25 | E3: FY26E | F3: FY27E | G3: FY28E | H3: FY29E | I3: FY30E
A4: Cash & balances with SAMA | B4: 78000 | C4: 86000 | D4: 90000 | E4: =D4*(1+Assumptions!E51) -> 94500 | F4: =E4*(1+Assumptions!F51) -> 100642.5 | G4: =F4*(1+Assumptions!G51) -> 108190.69 | H4: =G4*(1+Assumptions!H51) -> 115764.04 | I4: =H4*(1+Assumptions!I51) -> 123288.7
A5: Net financing (loans) | B5: 602000 | C5: 693400 | D5: 752800 | E5: =D5*(1+Assumptions!E44) -> 794204 | F5: =E5*(1+Assumptions!F44) -> 849798.28 | G5: =F5*(1+Assumptions!G44) -> 917782.14 | H5: =G5*(1+Assumptions!H44) -> 986615.8 | I5: =H5*(1+Assumptions!I44) -> 1055678.9
A6: Investments (mostly sukuk) | B6: 140000 | C6: 164000 | D6: 174000 | E6: =D6*(1+Assumptions!E49) -> 179220 | F6: =E6*(1+Assumptions!F49) -> 184596.6 | G6: =F6*(1+Assumptions!G49) -> 191980.46 | H6: =G6*(1+Assumptions!H49) -> 199659.68 | I6: =H6*(1+Assumptions!I49) -> 207646.07
A7: Other assets (PP&E, intangibles, other) | B7: 26000 | C7: 30600 | D7: 26200 | E7: =D7*(1+Assumptions!E44) -> 27641 | F7: =E7*(1+Assumptions!F44) -> 29575.87 | G7: =F7*(1+Assumptions!G44) -> 31941.94 | H7: =G7*(1+Assumptions!H44) -> 34337.585 | I7: =H7*(1+Assumptions!I44) -> 36741.216
A8: Total assets | B8: =SUM(B4:B7) -> 846000 | C8: =SUM(C4:C7) -> 974000 | D8: =SUM(D4:D7) -> 1043000 | E8: =SUM(E4:E7) -> 1095565 | F8: =SUM(F4:F7) -> 1164613.2 | G8: =SUM(G4:G7) -> 1249895.2 | H8: =SUM(H4:H7) -> 1336377.1 | I8: =SUM(I4:I7) -> 1423354.9
A10: Customer deposits | B10: 564000 | C10: 624000 | D10: 667000 | E10: =D10*(1+Assumptions!E51) -> 700350 | F10: =E10*(1+Assumptions!F51) -> 745872.75 | G10: =F10*(1+Assumptions!G51) -> 801813.21 | H10: =G10*(1+Assumptions!H51) -> 857940.13 | I10: =H10*(1+Assumptions!I51) -> 913706.24
A11: Due to banks & other funding | B11: 45000 | C11: 55000 | D11: 65000 | E11: =D11*(1+Assumptions!E44) -> 68575 | F11: =E11*(1+Assumptions!F44) -> 73375.25 | G11: =F11*(1+Assumptions!G44) -> 79245.27 | H11: =G11*(1+Assumptions!H44) -> 85188.665 | I11: =H11*(1+Assumptions!I44) -> 91151.872
A12: Other liabilities | B12: 60000 | C12: 70000 | D12: 85000 | E12: =D12*(1+Assumptions!E44) -> 89675 | F12: =E12*(1+Assumptions!F44) -> 95952.25 | G12: =F12*(1+Assumptions!G44) -> 103628.43 | H12: =G12*(1+Assumptions!H44) -> 111400.56 | I12: =H12*(1+Assumptions!I44) -> 119198.6
A13: Common equity | B13: 88000 | C13: 99000 | D13: 113000 | E13: =D13+'Income Statement'!E13*(1-Assumptions!E50) -> 128380.11 | F13: =E13+'Income Statement'!F13*(1-Assumptions!F50) -> 144034.2 | G13: =F13+'Income Statement'!G13*(1-Assumptions!G50) -> 159906.2 | H13: =G13+'Income Statement'!H13*(1-Assumptions!H50) -> 175976.83 | I13: =H13+'Income Statement'!I13*(1-Assumptions!I50) -> 192048.07
A14: Term debt & sukuk incl. AT1 (plug) | B14: =B8-(B10+B11+B12+B13) -> 89000 | C14: =C8-(C10+C11+C12+C13) -> 126000 | D14: =D8-(D10+D11+D12+D13) -> 113000 | E14: =E8-(E10+E11+E12+E13) -> 108584.89 | F14: =F8-(F10+F11+F12+F13) -> 105378.8 | G14: =G8-(G10+G11+G12+G13) -> 105302.13 | H14: =H8-(H10+H11+H12+H13) -> 105870.92 | I14: =I8-(I10+I11+I12+I13) -> 107250.11
A15: Total liabilities & equity | B15: =SUM(B10:B14) -> 846000 | C15: =SUM(C10:C14) -> 974000 | D15: =SUM(D10:D14) -> 1043000 | E15: =SUM(E10:E14) -> 1095565 | F15: =SUM(F10:F14) -> 1164613.2 | G15: =SUM(G10:G14) -> 1249895.2 | H15: =SUM(H10:H14) -> 1336377.1 | I15: =SUM(I10:I14) -> 1423354.9
A17: Balance check (assets − L&E) | B17: =B8-B15 -> 0 | C17: =C8-C15 -> 0 | D17: =D8-D15 -> 0 | E17: =E8-E15 -> 0 | F17: =F8-F15 -> 0 | G17: =G8-G15 -> 0 | H17: =H8-H15 -> 0 | I17: =I8-I15 -> 0
A18: memo: RWA (density × assets) | B18: =Assumptions!$B$28*B8 -> 494910 | C18: =Assumptions!$B$28*C8 -> 569790 | D18: =Assumptions!$B$28*D8 -> 610155 | E18: =Assumptions!$B$28*E8 -> 640905.53 | F18: =Assumptions!$B$28*F8 -> 681298.75 | G18: =Assumptions!$B$28*G8 -> 731188.71 | H18: =Assumptions!$B$28*H8 -> 781780.61 | I18: =Assumptions!$B$28*I8 -> 832662.61
A19: memo: CET1 ratio (equity / RWA) | B19: =B13/B18 -> 0.17781011 | C19: =C13/C18 -> 0.17374822 | D19: =D13/D18 -> 0.18519884 | E19: =E13/E18 -> 0.20031051 | F19: =F13/F18 -> 0.21141121 | G19: =G13/G18 -> 0.21869347 | H19: =H13/H18 -> 0.22509746 | I19: =I13/I18 -> 0.23064332
A20: memo: loan-to-deposit ratio | B20: =B5/B10 -> 1.0673759 | C20: =C5/C10 -> 1.1112179 | D20: =D5/D10 -> 1.1286357 | E20: =E5/E10 -> 1.1340101 | F20: =F5/F10 -> 1.1393341 | G20: =G5/G10 -> 1.1446334 | H20: =H5/H10 -> 1.1499821 | I20: =I5/I10 -> 1.1553811

Sheet Cash Flow
A1: Cash flow (SAR mn, forecast — sources & uses of equity)
A2: For a bank the relevant flow is distributable capital: net income less the capital retained to fund RWA growth.
E3: FY26E | F3: FY27E | G3: FY28E | H3: FY29E | I3: FY30E
A4: Net income | E4: ='Income Statement'!E13 -> 27963.838 | F4: ='Income Statement'!F13 -> 30104.011 | G4: ='Income Statement'!G13 -> 31744.001 | H4: ='Income Statement'!H13 -> 33480.484 | I4: ='Income Statement'!I13 -> 35713.867
A5: − Increase in required CET1 capital | E5: =-(Assumptions!$B$29*'Balance Sheet'!E18-Assumptions!$B$29*'Balance Sheet'!D18) -> -5688.8471 | F5: =-(Assumptions!$B$29*'Balance Sheet'!F18-Assumptions!$B$29*'Balance Sheet'!E18) -> -7472.7469 | G5: =-(Assumptions!$B$29*'Balance Sheet'!G18-Assumptions!$B$29*'Balance Sheet'!F18) -> -9229.6427 | H5: =-(Assumptions!$B$29*'Balance Sheet'!H18-Assumptions!$B$29*'Balance Sheet'!G18) -> -9359.5007 | I5: =-(Assumptions!$B$29*'Balance Sheet'!I18-Assumptions!$B$29*'Balance Sheet'!H18) -> -9413.171
A6: Free cash flow to equity (FCFE) | E6: =E4+E5 -> 22274.991 | F6: =F4+F5 -> 22631.264 | G6: =G4+G5 -> 22514.359 | H6: =H4+H5 -> 24120.983 | I6: =I4+I5 -> 26300.696
A7: − Dividends paid | E7: =-'Income Statement'!E13*Assumptions!E50 -> -12583.727 | F7: =-'Income Statement'!F13*Assumptions!F50 -> -14449.925 | G7: =-'Income Statement'!G13*Assumptions!G50 -> -15872.001 | H7: =-'Income Statement'!H13*Assumptions!H50 -> -17409.852 | I7: =-'Income Statement'!I13*Assumptions!I50 -> -19642.627
A8: Retained surplus (capital build) | E8: =E6+E7 -> 9691.2637 | F8: =F6+F7 -> 8181.339 | G8: =G6+G7 -> 6642.358 | H8: =H6+H7 -> 6711.1316 | I8: =I6+I7 -> 6658.069
A10: memo: dividend payout | E10: =Assumptions!E50 -> 0.45 | F10: =Assumptions!F50 -> 0.48 | G10: =Assumptions!G50 -> 0.5 | H10: =Assumptions!H50 -> 0.52 | I10: =Assumptions!I50 -> 0.55
A11: memo: FCFE per share (SAR) | E11: =E6/Assumptions!$B$5 -> 3.7124984 | F11: =F6/Assumptions!$B$5 -> 3.7718774 | G11: =G6/Assumptions!$B$5 -> 3.7523931 | H11: =H6/Assumptions!$B$5 -> 4.0201639 | I11: =I6/Assumptions!$B$5 -> 4.3834493

Sheet Summary Financials
A1: Summary financials (SAR mn)
A2: Every cell links to the statement sheets.
B3: FY23 | C3: FY24 | D3: FY25 | E3: FY26E | F3: FY27E | G3: FY28E | H3: FY29E | I3: FY30E
A4: Total operating income | B4: ='Income Statement'!B6 -> 27900 | C4: ='Income Statement'!C6 -> 32050 | D4: ='Income Statement'!D6 -> 39094 | E4: ='Income Statement'!E6 -> 44842.894 | F4: ='Income Statement'!F6 -> 48548.283 | G4: ='Income Statement'!G6 -> 51174.141 | H4: ='Income Statement'!H6 -> 53937.631 | I4: ='Income Statement'!I6 -> 57340.956
A5: Pre-provision profit | B5: ='Income Statement'!B9 -> 20500 | C5: ='Income Statement'!C9 -> 24070 | D5: ='Income Statement'!D9 -> 29984 | E5: ='Income Statement'!E9 -> 34304.814 | F5: ='Income Statement'!F9 -> 37139.436 | G5: ='Income Statement'!G9 -> 39404.089 | H5: ='Income Statement'!H9 -> 41639.851 | I5: ='Income Statement'!I9 -> 44439.241
A6: Net income | B6: ='Income Statement'!B13 -> 16620 | C6: ='Income Statement'!C13 -> 19720 | D6: ='Income Statement'!D13 -> 24792 | E6: ='Income Statement'!E13 -> 27963.838 | F6: ='Income Statement'!F13 -> 30104.011 | G6: ='Income Statement'!G13 -> 31744.001 | H6: ='Income Statement'!H13 -> 33480.484 | I6: ='Income Statement'!I13 -> 35713.867
A7: Total assets | B7: ='Balance Sheet'!B8 -> 846000 | C7: ='Balance Sheet'!C8 -> 974000 | D7: ='Balance Sheet'!D8 -> 1043000 | E7: ='Balance Sheet'!E8 -> 1095565 | F7: ='Balance Sheet'!F8 -> 1164613.2 | G7: ='Balance Sheet'!G8 -> 1249895.2 | H7: ='Balance Sheet'!H8 -> 1336377.1 | I7: ='Balance Sheet'!I8 -> 1423354.9
A8: Net financing | B8: ='Balance Sheet'!B5 -> 602000 | C8: ='Balance Sheet'!C5 -> 693400 | D8: ='Balance Sheet'!D5 -> 752800 | E8: ='Balance Sheet'!E5 -> 794204 | F8: ='Balance Sheet'!F5 -> 849798.28 | G8: ='Balance Sheet'!G5 -> 917782.14 | H8: ='Balance Sheet'!H5 -> 986615.8 | I8: ='Balance Sheet'!I5 -> 1055678.9
A9: Customer deposits | B9: ='Balance Sheet'!B10 -> 564000 | C9: ='Balance Sheet'!C10 -> 624000 | D9: ='Balance Sheet'!D10 -> 667000 | E9: ='Balance Sheet'!E10 -> 700350 | F9: ='Balance Sheet'!F10 -> 745872.75 | G9: ='Balance Sheet'!G10 -> 801813.21 | H9: ='Balance Sheet'!H10 -> 857940.13 | I9: ='Balance Sheet'!I10 -> 913706.24
A10: Common equity | B10: ='Balance Sheet'!B13 -> 88000 | C10: ='Balance Sheet'!C13 -> 99000 | D10: ='Balance Sheet'!D13 -> 113000 | E10: ='Balance Sheet'!E13 -> 128380.11 | F10: ='Balance Sheet'!F13 -> 144034.2 | G10: ='Balance Sheet'!G13 -> 159906.2 | H10: ='Balance Sheet'!H13 -> 175976.83 | I10: ='Balance Sheet'!I13 -> 192048.07
A11: RWA | B11: ='Balance Sheet'!B18 -> 494910 | C11: ='Balance Sheet'!C18 -> 569790 | D11: ='Balance Sheet'!D18 -> 610155 | E11: ='Balance Sheet'!E18 -> 640905.53 | F11: ='Balance Sheet'!F18 -> 681298.75 | G11: ='Balance Sheet'!G18 -> 731188.71 | H11: ='Balance Sheet'!H18 -> 781780.61 | I11: ='Balance Sheet'!I18 -> 832662.61

Sheet Monte Carlo
A1: Monte Carlo — engine outputs
A2: 50,000 paths · 16 factors · seed 42 · YZ-HAR width, Student-t(5) shape, zero drift (international).
A3: Percentile map (SAR/share)
B4: p5 | C4: p25 | D4: p50 | E4: p75 | F4: p95
A5: T+20 sessions | B5: 58.7 | C5: 63.53 | D5: 66.08 | E5: 68.62 | F5: 73.15
A6: T+60 sessions | B6: 54.27 | C6: 61.32 | D6: 65.95 | E6: 70.75 | F6: 78.7
A8: Diffusion vol (annualized) | D8: =Assumptions!$B$39 -> 0.1781
A9: Net 3-month drift | D9: =Assumptions!$B$40 -> 0.012
A10: Realized path vol (with 16 factors) | D10: 0.243
A11: Level-touch ladder
A12: Level | B12: T+20 | C12: T+60
A13: 74 | B13: 0.06 | C13: 0.24
A14: 72 | B14: 0.12 | C14: 0.35
A15: 70 | B15: 0.24 | C15: 0.5
A16: 68 | B16: 0.49 | C16: 0.7
A17: 66 | B17: 1 | C17: 1
A18: 64 | B18: 0.46 | C18: 0.67
A19: 62 | B19: 0.23 | C19: 0.48
A20: 60 | B20: 0.12 | C20: 0.33

Sheet Sensitivity
A1: DDM sensitivity — Ke × terminal growth
A2: DDM fair value (SAR/share) across the cost of equity and terminal growth. The §3.5-G WACC×g grid.
A4: Ke \ g | B4: 0.04 | C4: 0.045 | D4: 0.05 | E4: 0.055 | F4: 0.06
A5: 0.085 | B5: =(DDM!$E$7/(1+$A5)^1+DDM!$F$7/(1+$A5)^2+DDM!$G$7/(1+$A5)^3+DDM!$H$7/(1+$A5)^4+DDM!$I$7/(1+$A5)^5)+(DDM!$I$7*(1+B$4)/($A5-B$4))/(1+$A5)^5 -> 60.638416 | C5: =(DDM!$E$7/(1+$A5)^1+DDM!$F$7/(1+$A5)^2+DDM!$G$7/(1+$A5)^3+DDM!$H$7/(1+$A5)^4+DDM!$I$7/(1+$A5)^5)+(DDM!$I$7*(1+C$4)/($A5-C$4))/(1+$A5)^5 -> 67.200274 | D5: =(DDM!$E$7/(1+$A5)^1+DDM!$F$7/(1+$A5)^2+DDM!$G$7/(1+$A5)^3+DDM!$H$7/(1+$A5)^4+DDM!$I$7/(1+$A5)^5)+(DDM!$I$7*(1+D$4)/($A5-D$4))/(1+$A5)^5 -> 75.63695 | E5: =(DDM!$E$7/(1+$A5)^1+DDM!$F$7/(1+$A5)^2+DDM!$G$7/(1+$A5)^3+DDM!$H$7/(1+$A5)^4+DDM!$I$7/(1+$A5)^5)+(DDM!$I$7*(1+E$4)/($A5-E$4))/(1+$A5)^5 -> 86.88585 | F5: =(DDM!$E$7/(1+$A5)^1+DDM!$F$7/(1+$A5)^2+DDM!$G$7/(1+$A5)^3+DDM!$H$7/(1+$A5)^4+DDM!$I$7/(1+$A5)^5)+(DDM!$I$7*(1+F$4)/($A5-F$4))/(1+$A5)^5 -> 102.63431
A6: 0.09 | B6: =(DDM!$E$7/(1+$A6)^1+DDM!$F$7/(1+$A6)^2+DDM!$G$7/(1+$A6)^3+DDM!$H$7/(1+$A6)^4+DDM!$I$7/(1+$A6)^5)+(DDM!$I$7*(1+B$4)/($A6-B$4))/(1+$A6)^5 -> 54.433872 | C6: =(DDM!$E$7/(1+$A6)^1+DDM!$F$7/(1+$A6)^2+DDM!$G$7/(1+$A6)^3+DDM!$H$7/(1+$A6)^4+DDM!$I$7/(1+$A6)^5)+(DDM!$I$7*(1+C$4)/($A6-C$4))/(1+$A6)^5 -> 59.587698 | D6: =(DDM!$E$7/(1+$A6)^1+DDM!$F$7/(1+$A6)^2+DDM!$G$7/(1+$A6)^3+DDM!$H$7/(1+$A6)^4+DDM!$I$7/(1+$A6)^5)+(DDM!$I$7*(1+D$4)/($A6-D$4))/(1+$A6)^5 -> 66.029982 | E6: =(DDM!$E$7/(1+$A6)^1+DDM!$F$7/(1+$A6)^2+DDM!$G$7/(1+$A6)^3+DDM!$H$7/(1+$A6)^4+DDM!$I$7/(1+$A6)^5)+(DDM!$I$7*(1+E$4)/($A6-E$4))/(1+$A6)^5 -> 74.312917 | F6: =(DDM!$E$7/(1+$A6)^1+DDM!$F$7/(1+$A6)^2+DDM!$G$7/(1+$A6)^3+DDM!$H$7/(1+$A6)^4+DDM!$I$7/(1+$A6)^5)+(DDM!$I$7*(1+F$4)/($A6-F$4))/(1+$A6)^5 -> 85.356832
A7: 0.095 | B7: =(DDM!$E$7/(1+$A7)^1+DDM!$F$7/(1+$A7)^2+DDM!$G$7/(1+$A7)^3+DDM!$H$7/(1+$A7)^4+DDM!$I$7/(1+$A7)^5)+(DDM!$I$7*(1+B$4)/($A7-B$4))/(1+$A7)^5 -> 49.359779 | C7: =(DDM!$E$7/(1+$A7)^1+DDM!$F$7/(1+$A7)^2+DDM!$G$7/(1+$A7)^3+DDM!$H$7/(1+$A7)^4+DDM!$I$7/(1+$A7)^5)+(DDM!$I$7*(1+C$4)/($A7-C$4))/(1+$A7)^5 -> 53.500054 | D7: =(DDM!$E$7/(1+$A7)^1+DDM!$F$7/(1+$A7)^2+DDM!$G$7/(1+$A7)^3+DDM!$H$7/(1+$A7)^4+DDM!$I$7/(1+$A7)^5)+(DDM!$I$7*(1+D$4)/($A7-D$4))/(1+$A7)^5 -> 58.56039 | E7: =(DDM!$E$7/(1+$A7)^1+DDM!$F$7/(1+$A7)^2+DDM!$G$7/(1+$A7)^3+DDM!$H$7/(1+$A7)^4+DDM!$I$7/(1+$A7)^5)+(DDM!$I$7*(1+E$4)/($A7-E$4))/(1+$A7)^5 -> 64.885809 | F7: =(DDM!$E$7/(1+$A7)^1+DDM!$F$7/(1+$A7)^2+DDM!$G$7/(1+$A7)^3+DDM!$H$7/(1+$A7)^4+DDM!$I$7/(1+$A7)^5)+(DDM!$I$7*(1+F$4)/($A7-F$4))/(1+$A7)^5 -> 73.018491
A8: 0.1 | B8: =(DDM!$E$7/(1+$A8)^1+DDM!$F$7/(1+$A8)^2+DDM!$G$7/(1+$A8)^3+DDM!$H$7/(1+$A8)^4+DDM!$I$7/(1+$A8)^5)+(DDM!$I$7*(1+B$4)/($A8-B$4))/(1+$A8)^5 -> 45.133474 | C8: =(DDM!$E$7/(1+$A8)^1+DDM!$F$7/(1+$A8)^2+DDM!$G$7/(1+$A8)^3+DDM!$H$7/(1+$A8)^4+DDM!$I$7/(1+$A8)^5)+(DDM!$I$7*(1+C$4)/($A8-C$4))/(1+$A8)^5 -> 48.521398 | D8: =(DDM!$E$7/(1+$A8)^1+DDM!$F$7/(1+$A8)^2+DDM!$G$7/(1+$A8)^3+DDM!$H$7/(1+$A8)^4+DDM!$I$7/(1+$A8)^5)+(DDM!$I$7*(1+D$4)/($A8-D$4))/(1+$A8)^5 -> 52.586906 | E8: =(DDM!$E$7/(1+$A8)^1+DDM!$F$7/(1+$A8)^2+DDM!$G$7/(1+$A8)^3+DDM!$H$7/(1+$A8)^4+DDM!$I$7/(1+$A8)^5)+(DDM!$I$7*(1+E$4)/($A8-E$4))/(1+$A8)^5 -> 57.555861 | F8: =(DDM!$E$7/(1+$A8)^1+DDM!$F$7/(1+$A8)^2+DDM!$G$7/(1+$A8)^3+DDM!$H$7/(1+$A8)^4+DDM!$I$7/(1+$A8)^5)+(DDM!$I$7*(1+F$4)/($A8-F$4))/(1+$A8)^5 -> 63.767055
A9: 0.105 | B9: =(DDM!$E$7/(1+$A9)^1+DDM!$F$7/(1+$A9)^2+DDM!$G$7/(1+$A9)^3+DDM!$H$7/(1+$A9)^4+DDM!$I$7/(1+$A9)^5)+(DDM!$I$7*(1+B$4)/($A9-B$4))/(1+$A9)^5 -> 41.559265 | C9: =(DDM!$E$7/(1+$A9)^1+DDM!$F$7/(1+$A9)^2+DDM!$G$7/(1+$A9)^3+DDM!$H$7/(1+$A9)^4+DDM!$I$7/(1+$A9)^5)+(DDM!$I$7*(1+C$4)/($A9-C$4))/(1+$A9)^5 -> 44.374435 | D9: =(DDM!$E$7/(1+$A9)^1+DDM!$F$7/(1+$A9)^2+DDM!$G$7/(1+$A9)^3+DDM!$H$7/(1+$A9)^4+DDM!$I$7/(1+$A9)^5)+(DDM!$I$7*(1+D$4)/($A9-D$4))/(1+$A9)^5 -> 47.701454 | E9: =(DDM!$E$7/(1+$A9)^1+DDM!$F$7/(1+$A9)^2+DDM!$G$7/(1+$A9)^3+DDM!$H$7/(1+$A9)^4+DDM!$I$7/(1+$A9)^5)+(DDM!$I$7*(1+E$4)/($A9-E$4))/(1+$A9)^5 -> 51.693877 | F9: =(DDM!$E$7/(1+$A9)^1+DDM!$F$7/(1+$A9)^2+DDM!$G$7/(1+$A9)^3+DDM!$H$7/(1+$A9)^4+DDM!$I$7/(1+$A9)^5)+(DDM!$I$7*(1+F$4)/($A9-F$4))/(1+$A9)^5 -> 56.573504
A11: Base case Ke 9.5% × g 5.0% is the centre cell; the grid shows the dividend lens’ sensitivity.

Sheet Per-Share & Ratios
A1: Per-share & ratios (the Data Miner panel)
A2: Links to statements / Assumptions.
B3: FY23 | C3: FY24 | D3: FY25 | E3: FY26E | F3: FY27E | G3: FY28E | H3: FY29E | I3: FY30E
A4: EPS (SAR) | B4: ='Income Statement'!B13/Assumptions!$B$5 -> 2.77 | C4: ='Income Statement'!C13/Assumptions!$B$5 -> 3.2866667 | D4: ='Income Statement'!D13/Assumptions!$B$5 -> 4.132 | E4: ='Income Statement'!E13/Assumptions!$B$5 -> 4.6606396 | F4: ='Income Statement'!F13/Assumptions!$B$5 -> 5.0173352 | G4: ='Income Statement'!G13/Assumptions!$B$5 -> 5.2906669 | H4: ='Income Statement'!H13/Assumptions!$B$5 -> 5.5800807 | I4: ='Income Statement'!I13/Assumptions!$B$5 -> 5.9523111
A5: DPS (SAR) | B5: ='Income Statement'!B13/Assumptions!$B$5*IF(ISNUMBER(Assumptions!B50),Assumptions!B50,0) -> 0 | C5: ='Income Statement'!C13/Assumptions!$B$5*IF(ISNUMBER(Assumptions!C50),Assumptions!C50,0) -> 0 | D5: ='Income Statement'!D13/Assumptions!$B$5*IF(ISNUMBER(Assumptions!D50),Assumptions!D50,0) -> 0 | E5: ='Income Statement'!E13/Assumptions!$B$5*IF(ISNUMBER(Assumptions!E50),Assumptions!E50,0) -> 2.0972878 | F5: ='Income Statement'!F13/Assumptions!$B$5*IF(ISNUMBER(Assumptions!F50),Assumptions!F50,0) -> 2.4083209 | G5: ='Income Statement'!G13/Assumptions!$B$5*IF(ISNUMBER(Assumptions!G50),Assumptions!G50,0) -> 2.6453334 | H5: ='Income Statement'!H13/Assumptions!$B$5*IF(ISNUMBER(Assumptions!H50),Assumptions!H50,0) -> 2.9016419 | I5: ='Income Statement'!I13/Assumptions!$B$5*IF(ISNUMBER(Assumptions!I50),Assumptions!I50,0) -> 3.2737711
A6: Book value/share (SAR) | B6: ='Balance Sheet'!B13/Assumptions!$B$5 -> 14.666667 | C6: ='Balance Sheet'!C13/Assumptions!$B$5 -> 16.5 | D6: ='Balance Sheet'!D13/Assumptions!$B$5 -> 18.833333 | E6: ='Balance Sheet'!E13/Assumptions!$B$5 -> 21.396685 | F6: ='Balance Sheet'!F13/Assumptions!$B$5 -> 24.005699 | G6: ='Balance Sheet'!G13/Assumptions!$B$5 -> 26.651033 | H6: ='Balance Sheet'!H13/Assumptions!$B$5 -> 29.329472 | I6: ='Balance Sheet'!I13/Assumptions!$B$5 -> 32.008012
A7: P/E (x) | B7: =Assumptions!$B$4/B4 -> 23.826715 | C7: =Assumptions!$B$4/C4 -> 20.081136 | D7: =Assumptions!$B$4/D4 -> 15.972894 | E7: =Assumptions!$B$4/E4 -> 14.161146 | F7: =Assumptions!$B$4/F4 -> 13.154393 | G7: =Assumptions!$B$4/G4 -> 12.474798 | H7: =Assumptions!$B$4/H4 -> 11.827786 | I7: =Assumptions!$B$4/I4 -> 11.08813
A8: P/B (x) | B8: =Assumptions!$B$4/B6 -> 4.5 | C8: =Assumptions!$B$4/C6 -> 4 | D8: =Assumptions!$B$4/D6 -> 3.5044248 | E8: =Assumptions!$B$4/E6 -> 3.08459 | F8: =Assumptions!$B$4/F6 -> 2.7493471 | G8: =Assumptions!$B$4/G6 -> 2.4764519 | H8: =Assumptions!$B$4/H6 -> 2.2502963 | I8: =Assumptions!$B$4/I6 -> 2.0619838
A9: ROAE (%) | C9: ='Income Statement'!C13/AVERAGE('Balance Sheet'!B13,'Balance Sheet'!C13) -> 0.21090909 | D9: ='Income Statement'!D13/AVERAGE('Balance Sheet'!C13,'Balance Sheet'!D13) -> 0.23388679 | E9: ='Income Statement'!E13/AVERAGE('Balance Sheet'!D13,'Balance Sheet'!E13) -> 0.2316996 | F9: ='Income Statement'!F13/AVERAGE('Balance Sheet'!E13,'Balance Sheet'!F13) -> 0.22101637 | G9: ='Income Statement'!G13/AVERAGE('Balance Sheet'!F13,'Balance Sheet'!G13) -> 0.20888307 | H9: ='Income Statement'!H13/AVERAGE('Balance Sheet'!G13,'Balance Sheet'!H13) -> 0.199358 | I9: ='Income Statement'!I13/AVERAGE('Balance Sheet'!H13,'Balance Sheet'!I13) -> 0.19408397
A10: ROAA (%) | C10: ='Income Statement'!C13/AVERAGE('Balance Sheet'!B8,'Balance Sheet'!C8) -> 0.02167033 | D10: ='Income Statement'!D13/AVERAGE('Balance Sheet'!C8,'Balance Sheet'!D8) -> 0.024583044 | E10: ='Income Statement'!E13/AVERAGE('Balance Sheet'!D8,'Balance Sheet'!E8) -> 0.026151964 | F10: ='Income Statement'!F13/AVERAGE('Balance Sheet'!E8,'Balance Sheet'!F8) -> 0.026638617 | G10: ='Income Statement'!G13/AVERAGE('Balance Sheet'!F8,'Balance Sheet'!G8) -> 0.02629438 | H10: ='Income Statement'!H13/AVERAGE('Balance Sheet'!G8,'Balance Sheet'!H8) -> 0.025890919 | I10: ='Income Statement'!I13/AVERAGE('Balance Sheet'!H8,'Balance Sheet'!I8) -> 0.025882127
A11: Dividend yield (%) | B11: =B5/Assumptions!$B$4 -> 0 | C11: =C5/Assumptions!$B$4 -> 0 | D11: =D5/Assumptions!$B$4 -> 0 | E11: =E5/Assumptions!$B$4 -> 0.031777088 | F11: =F5/Assumptions!$B$4 -> 0.036489711 | G11: =G5/Assumptions!$B$4 -> 0.04008081 | H11: =H5/Assumptions!$B$4 -> 0.043964272 | I11: =I5/Assumptions!$B$4 -> 0.049602593
A12: Cost-to-income (%) | B12: ='Income Statement'!B16 -> 0.26523297 | C12: ='Income Statement'!C16 -> 0.24898596 | D12: ='Income Statement'!D16 -> 0.23302809 | E12: ='Income Statement'!E16 -> 0.235 | F12: ='Income Statement'!F16 -> 0.235 | G12: ='Income Statement'!G16 -> 0.23 | H12: ='Income Statement'!H16 -> 0.228 | I12: ='Income Statement'!I16 -> 0.225
A13: Cost of risk (bps) | D13: =-'Income Statement'!D10/AVERAGE('Balance Sheet'!C5,'Balance Sheet'!D5)*10000 -> 32.084082 | E13: =-'Income Statement'!E10/AVERAGE('Balance Sheet'!D5,'Balance Sheet'!E5)*10000 -> 35 | F13: =-'Income Statement'!F10/AVERAGE('Balance Sheet'!E5,'Balance Sheet'!F5)*10000 -> 38 | G13: =-'Income Statement'!G10/AVERAGE('Balance Sheet'!F5,'Balance Sheet'!G5)*10000 -> 40 | H13: =-'Income Statement'!H10/AVERAGE('Balance Sheet'!G5,'Balance Sheet'!H5)*10000 -> 40 | I13: =-'Income Statement'!I10/AVERAGE('Balance Sheet'!H5,'Balance Sheet'!I5)*10000 -> 40
A14: CET1 ratio (%) | B14: ='Balance Sheet'!B19 -> 0.17781011 | C14: ='Balance Sheet'!C19 -> 0.17374822 | D14: ='Balance Sheet'!D19 -> 0.18519884 | E14: ='Balance Sheet'!E19 -> 0.20031051 | F14: ='Balance Sheet'!F19 -> 0.21141121 | G14: ='Balance Sheet'!G19 -> 0.21869347 | H14: ='Balance Sheet'!H19 -> 0.22509746 | I14: ='Balance Sheet'!I19 -> 0.23064332
A15: Loan-to-deposit (%) | B15: ='Balance Sheet'!B20 -> 1.0673759 | C15: ='Balance Sheet'!C20 -> 1.1112179 | D15: ='Balance Sheet'!D20 -> 1.1286357 | E15: ='Balance Sheet'!E20 -> 1.1340101 | F15: ='Balance Sheet'!F20 -> 1.1393341 | G15: ='Balance Sheet'!G20 -> 1.1446334 | H15: ='Balance Sheet'!H20 -> 1.1499821 | I15: ='Balance Sheet'!I20 -> 1.1553811

Sheet Peer & Sector
A1: Peer set & sector
A2: Saudi + GCC large-cap banks. Al Rajhi commands a P/B premium justified by its ROE.
B3: P/B (x) | C3: P/E (x) | D3: ROAE
A4: Al Rajhi (1120) | B4: 3.5 | C4: 16.9 | D4: 0.234
A5: Saudi National Bank (1180) | B5: 1.6 | C5: 11.5 | D5: 0.135
A6: Riyad Bank (1010) | B6: 1.7 | C6: 10.5 | D6: 0.15
A7: SAB / Saudi Awwal (1060) | B7: 1.3 | C7: 10 | D7: 0.13
A8: Alinma Bank (1150) | B8: 2 | C8: 12 | D8: 0.165
A9: Banque Saudi Fransi (1050) | B9: 1.2 | C9: 9.5 | D9: 0.125
A10: QNB (Qatar) | B10: 1.8 | C10: 11 | D10: 0.17
A11: FAB (UAE) | B11: 1.4 | C11: 10.5 | D11: 0.155
A12: Emirates NBD (UAE) | B12: 1.3 | C12: 7.5 | D12: 0.19
A14: Al Rajhi’s ~3.5x P/B (vs sector ~1.6x) is ~120% premium, tracking its ~23% ROAE vs sector ~15%. Sourced: sell-side notes, argaam.
