Workbook

Sheet READ FIRST
A1: Testahil · Independent Valuation Study — Educational Analysis · Not investment advice
A3: Saudi Aramco (TADAWUL: 2222) — companion model.
A5: Educational valuation exercise; NOT investment advice, NOT a recommendation, NOT personalised. The preparer is not
A6: licensed by any securities regulator. All values are model outputs shown as ranges/distributions.
A8: Wiring: every downstream cell links to the Assumptions sheet (the single blue-cell input layer). Change one blue
A9: input — the oil-linked revenue growth, an EBIT margin, the WACC, the required yield, a reserve mark — and the whole
A10: integrated model (3-year actual + 5-year forecast IS/BS/CF, the 5-year FCFF DCF, and the five-lens synthesis)
A11: reprices. Blue = input; black = formula; green = link from another sheet.
A13: Reporting currency SAR; financials in USD millions as Aramco reports, converted at the 3.75 peg. Company figures are
A14: Aramco FY2023–FY2025 disclosure; forward inputs are the preparer's judgments and are flagged. Spot as of 1 Jul 2026.
A16: Primary lens: explicit 5-year FCFF DCF, cross-checked by a dividend-yield model, relative multiples, a reserves-NAV
A17: and through-cycle earnings power.

Sheet Summary
A1: Summary — Saudi Aramco (TADAWUL: 2222) · Independent Valuation Study
A3: Spot price (SAR) | B3: =Assumptions!$B$4 -> 26.24
A4: Weighted central estimate (SAR) | B4: ='Fundamental Valuation'!$B$15 -> 25.035773
A5: vs spot | B5: ='Fundamental Valuation'!$B$15/Assumptions!$B$4-1 -> -0.045892785
A6: DCF (FCFF, 5-yr) — primary (SAR) | B6: =DCF!$B$20 -> 23.467736
A7: Dividend-yield support (SAR) | B7: ='Fundamental Valuation'!$B$6 -> 26.092657
A8: Relative multiples (SAR) | B8: ='Relative & Normalized'!$B$9 -> 21.475723
A9: Reserves-NAV / SOTP (SAR) | B9: ='Reserves-NAV'!$B$12 -> 29.632748
A10: Normalized earnings (SAR) | B10: ='Relative & Normalized'!$B$16 -> 23.243802
A11: Fwd dividend yield | B11: =Assumptions!$B$21/Assumptions!$B$4 -> 0.05170801
A12: MC median T+60 (SAR) | B12: 26.12
A13: MC P5–P95 T+60 (SAR) | B13: 21.99 – 30.35

Sheet Fundamental Valuation
A1: Fundamental valuation — five lenses, weighted synthesis
A3: Dividend-yield support model
A4: Fwd base dividend / share (SAR) | B4: =Assumptions!$B$21 -> 1.3568182
A5: Required dividend yield | B5: =Assumptions!$B$22 -> 0.052
A6: Value per share (SAR) = div / yield | B6: =B4/B5 -> 26.092657
A8: Five-lens synthesis
A9: Lens | B9: Fair value (SAR) | C9: vs spot | D9: Weight | E9: Contribution
A10: DCF (FCFF) — primary | B10: =DCF!$B$20 -> 23.467736 | C10: =B10/Assumptions!$B$4-1 -> -0.10565031 | D10: =Assumptions!$B$24 -> 0.3 | E10: =B10*D10 -> 7.0403208
A11: Dividend-yield support | B11: ='Fundamental Valuation'!$B$6 -> 26.092657 | C11: =B11/Assumptions!$B$4-1 -> -0.0056151927 | D11: =Assumptions!$B$25 -> 0.25 | E11: =B11*D11 -> 6.5231643
A12: Relative multiples | B12: ='Relative & Normalized'!$B$9 -> 21.475723 | C12: =B12/Assumptions!$B$4-1 -> -0.18156543 | D12: =Assumptions!$B$26 -> 0.15 | E12: =B12*D12 -> 3.2213585
A13: Reserves-NAV / SOTP | B13: ='Reserves-NAV'!$B$12 -> 29.632748 | C13: =B13/Assumptions!$B$4-1 -> 0.1292968 | D13: =Assumptions!$B$27 -> 0.2 | E13: =B13*D13 -> 5.9265496
A14: Normalized earnings power | B14: ='Relative & Normalized'!$B$16 -> 23.243802 | C14: =B14/Assumptions!$B$4-1 -> -0.11418439 | D14: =Assumptions!$B$28 -> 0.1 | E14: =B14*D14 -> 2.3243802
A15: Weighted central estimate (SAR) | B15: =SUM(E10:E14) -> 25.035773 | C15: =B15/Assumptions!$B$4-1 -> -0.045892785

Sheet Assumptions
A1: ASSUMPTIONS — the single input layer (blue = input, black/green = formula/link)
A3: ANCHORS
A4: Spot price (SAR) | B4: 26.24 | C4: TADAWUL close 01-Jul-2026 (attached OHLC)
A5: Shares outstanding (m) | B5: 242000 | C5: Aramco FY2025 financials: 242bn shares
A6: USD/SAR peg | B6: 3.75 | C6: SAMA peg
A7: Consolidated net debt ($m) | B7: 18100 | C7: gearing 3.8% Dec-25 → ~$18bn
A8: WACC | B8: 0.0675 | C8: sovereign-adjusted; low leverage
A9: Terminal growth | B9: 0.015 | C9: mature; small volume/gas offset
A10: Effective tax & govt take | B10: 0.52 | C10: EBIT→NI bridge FY25 (royalty in COGS; income tax+zakat)
A11: RESERVES-NAV / SOTP (primary asset lens)
A12: Proved reserves (bn boe) | B12: 247.2 | C12: Aramco investor overview end-2025
A13: Net value per boe ($) | B13: 7 | C13: after royalty/tax/concession haircut
A14: Downstream & chemicals EV ($m) | B14: 200000 | C14: refining+chemicals franchise
A15: RELATIVE & NORMALIZED
A16: Normalized EBITDA ($m) | B16: 234000 | C16: ~EBIT 199 + D&A 35 at mid-cycle
A17: Fair EV/EBITDA (x) | B17: 6 | C17: premium to majors ~5x, below Aramco 7.3x
A18: Mid-cycle net income ($m) | B18: 100000 | C18: through-cycle at ~$72 oil
A19: Justified P/E (x) | B19: 15 | C19: premium to majors, discount to peak
A20: DIVIDEND-YIELD SUPPORT
A21: Fwd base dividend / share (SAR) | B21: =87560/Assumptions!$B$5*Assumptions!$B$6 -> 1.3568182 | C21: base run-rate $87.56bn (Q4-25 base ×4)
A22: Required dividend yield | B22: 0.052 | C22: Aramco's own 5.0-5.3% band
A23: SYNTHESIS WEIGHTS (sum = 100%)
A24: w DCF | B24: 0.3
A25: w Dividend-yield | B25: 0.25
A26: w Relative | B26: 0.15
A27: w Reserves-NAV | B27: 0.2
A28: w Normalized | B28: 0.1
A29: WORKING CAPITAL (% of revenue)
A30: Inventory % | B30: 0.055
A31: Receivables % | B31: 0.09
A32: Payables % | B32: 0.11
A33: MONTE CARLO
A34: Diffusion vol (annualized) | B34: 0.1512 | C34: trailing 252-day
A35: Net 3-month drift | B35: 0.006 | C35: 7 continuous factors
A36: KVOL (calibration multiplier) | B36: 1 | C36: Step 0: passes at 1.00, no fudge
A37: FORECAST DRIVERS (FY26E–FY30E)
B38: FY26E | C38: FY27E | D38: FY28E | E38: FY29E | F38: FY30E
A39: Revenue growth | B39: 0.01 | C39: 0.03 | D39: 0.02 | E39: 0.01 | F39: 0
A40: EBIT margin | B40: 0.445 | C40: 0.45 | D40: 0.45 | E40: 0.445 | F40: 0.445
A41: D&A (% of revenue) | B41: 0.078 | C41: 0.077 | D41: 0.076 | E41: 0.075 | F41: 0.074
...

Sheet Reserves-NAV
A1: Reserves-based NAV / SOTP — asset cross-check
A4: Proved reserves (bn boe) | B4: =Assumptions!$B$12 -> 247.2
A5: Net value per boe ($) | B5: =Assumptions!$B$13 -> 7
A6: Upstream NAV ($m) | B6: =B4*B5*1000 -> 1730400
A7: Downstream & chemicals EV ($m) | B7: =Assumptions!$B$14 -> 200000
A8: Gross asset value ($m) | B8: =B6+B7 -> 1930400
A9: Less net debt ($m) | B9: =-Assumptions!$B$7 -> -18100
A10: Equity NAV ($m) | B10: =B8+B9 -> 1912300
A11: Equity NAV (SAR m) | B11: =B10*Assumptions!$B$6 -> 7171125
A12: NAV per share (SAR) | B12: =B11/Assumptions!$B$5 -> 29.632748
A13: vs spot | B13: =B12/Assumptions!$B$4-1 -> 0.1292968
A14: Reserves marked conservatively for the concession/royalty/income-tax take; the equity claim is encumbered.

Sheet Segments
A1: Segment & operating scorecard (FY2025)
A3: Segment | B3: Character | C3: Read
A4: Upstream | B4: ~9 mmbd crude under OPEC+; MSC ~12 mmbd; ~$3.75 lifting | C4: Cash engine; lowest-cost barrel
A5: Downstream | B5: Refining, marketing, trading; integrated | C5: Scale + integration; margin-cyclical
A6: Chemicals | B6: SABIC-anchored; feedstock advantage | C6: Growth optionality; margin pressure
A7: Gas / new energies | B7: Jafurah, Tanajib; +~80% sales gas by 2030 | C7: Volume-growth leg; long-dated
A8: Reserves | B8: 247.2bn boe hydrocarbon base | C8: Multi-decade; concession-encumbered

Sheet Relative & Normalized
A1: Relative multiples & through-cycle normalized earnings
A3: A · Relative multiples
A4: Normalized EBITDA ($m) | B4: =Assumptions!$B$16 -> 234000
A5: Fair EV/EBITDA (x) | B5: =Assumptions!$B$17 -> 6
A6: Implied EV ($m) | B6: =B4*B5 -> 1404000
A7: Less net debt ($m) | B7: =-Assumptions!$B$7 -> -18100
A8: Equity value ($m) | B8: =B6+B7 -> 1385900
A9: Value per share (SAR) | B9: =B8*Assumptions!$B$6/Assumptions!$B$5 -> 21.475723
A10: vs spot | B10: =B9/Assumptions!$B$4-1 -> -0.18156543
A12: B · Through-cycle normalized earnings
A13: Mid-cycle net income ($m) | B13: =Assumptions!$B$18 -> 100000
A14: Normalized EPS (SAR) | B14: =B13*Assumptions!$B$6/Assumptions!$B$5 -> 1.5495868
A15: Justified P/E (x) | B15: =Assumptions!$B$19 -> 15
A16: Value per share (SAR) | B16: =B14*B15 -> 23.243802
A17: vs spot | B17: =B16/Assumptions!$B$4-1 -> -0.11418439

Sheet DCF
A1: Discounted cash flow — explicit 5-year FCFF (primary lens)
A2: NOPAT + D&A − capex − ΔWC, discounted at WACC. Links to Income Statement / Balance Sheet / Assumptions.
A3: ($m) | B3: FY26E | C3: FY27E | D3: FY28E | E3: FY29E | F3: FY30E
A4: EBIT | B4: ='Income Statement'!E5 -> 200319.86 | C4: ='Income Statement'!F5 -> 208647.77 | D4: ='Income Statement'!G5 -> 212820.72 | E4: ='Income Statement'!H5 -> 212560.61 | F4: ='Income Statement'!I5 -> 212560.61
A5: NOPAT = EBIT×(1−tax) | B5: =B4*(1-Assumptions!$B$10) -> 96153.535 | C5: =C4*(1-Assumptions!$B$10) -> 100150.93 | D5: =D4*(1-Assumptions!$B$10) -> 102153.95 | E5: =E4*(1-Assumptions!$B$10) -> 102029.09 | F5: =F4*(1-Assumptions!$B$10) -> 102029.09
A6: + D&A | B6: ='Income Statement'!E6 -> 35112.246 | C6: ='Income Statement'!F6 -> 35701.952 | D6: ='Income Statement'!G6 -> 35943.056 | E6: ='Income Statement'!H6 -> 35824.822 | F6: ='Income Statement'!I6 -> 35347.158
A7: − Capex | B7: =-Assumptions!$B$44 -> -53000 | C7: =-Assumptions!$C$44 -> -54000 | D7: =-Assumptions!$D$44 -> -53000 | E7: =-Assumptions!$E$44 -> -52000 | F7: =-Assumptions!$F$44 -> -52000
A8: − Increase in net WC | B8: =-(('Balance Sheet'!E5+'Balance Sheet'!E6-'Balance Sheet'!E15)-('Balance Sheet'!D5+'Balance Sheet'!D6-'Balance Sheet'!D15)) -> -155.995 | C8: =-(('Balance Sheet'!F5+'Balance Sheet'!F6-'Balance Sheet'!F15)-('Balance Sheet'!E5+'Balance Sheet'!E6-'Balance Sheet'!E15)) -> -472.66485 | D8: =-(('Balance Sheet'!G5+'Balance Sheet'!G6-'Balance Sheet'!G15)-('Balance Sheet'!F5+'Balance Sheet'!F6-'Balance Sheet'!F15)) -> -324.5632 | E8: =-(('Balance Sheet'!H5+'Balance Sheet'!H6-'Balance Sheet'!H15)-('Balance Sheet'!G5+'Balance Sheet'!G6-'Balance Sheet'!G15)) -> -165.52723 | F8: =-(('Balance Sheet'!I5+'Balance Sheet'!I6-'Balance Sheet'!I15)-('Balance Sheet'!H5+'Balance Sheet'!H6-'Balance Sheet'!H15)) -> 0
A9: FCFF | B9: =B5+B6+B7+B8 -> 78109.786 | C9: =C5+C6+C7+C8 -> 81380.216 | D9: =D5+D6+D7+D8 -> 84772.441 | E9: =E5+E6+E7+E8 -> 85688.388 | F9: =F5+F6+F7+F8 -> 85376.251
A10: Discount factor | B10: =1/(1+Assumptions!$B$8)^1 -> 0.93676815 | C10: =1/(1+Assumptions!$B$8)^2 -> 0.87753457 | D10: =1/(1+Assumptions!$B$8)^3 -> 0.82204643 | E10: =1/(1+Assumptions!$B$8)^4 -> 0.77006692 | F10: =1/(1+Assumptions!$B$8)^5 -> 0.72137416
A11: PV of FCFF | B11: =B9*B10 -> 73170.76 | C11: =C9*C10 -> 71413.953 | D11: =D9*D10 -> 69686.882 | E11: =E9*E10 -> 65985.793 | F11: =F9*F10 -> 61588.221
A13: Σ PV of explicit FCFF (FY26–30) | B13: =SUM(B11:F11) -> 341845.61
A14: Terminal value (Gordon) | B14: =F9*(1+Assumptions!$B$9)/(Assumptions!$B$8-Assumptions!$B$9) -> 1650607.5
A15: PV of terminal value | B15: =B14*F10 -> 1190705.6
A16: Enterprise value | B16: =B13+B15 -> 1532551.2
A17: less: consolidated net debt | B17: =-Assumptions!$B$7 -> -18100
A18: Equity value | B18: =B16+B17 -> 1514451.2
A19: Equity value (SAR m) | B19: =B18*Assumptions!$B$6 -> 5679192.1
A20: Fair value per share (SAR) | B20: =B19/Assumptions!$B$5 -> 23.467736
A21: % terminal of EV | B21: =B15/B16 -> 0.77694344
A22: vs spot | B22: =B20/Assumptions!$B$4-1 -> -0.10565031
A24: A full 5-year FCFF build off the integrated statements — not a perpetuity shortcut. WACC and terminal growth are the swing inputs (§1.9).

Sheet Income Statement
A1: Income statement ($m, consolidated)
A2: FY23–FY25 disclosed (blue); FY26E–FY30E forecast (formulas linking to Assumptions). Source: Aramco FY press releases 2023–2025.
A3: ($m) | B3: FY23 | C3: FY24 | D3: FY25 | E3: FY26E | F3: FY27E | G3: FY28E | H3: FY29E | I3: FY30E
A4: Total revenue & other income | B4: 440900 | C4: 480400 | D4: 445700 | E4: =D4*(1+Assumptions!$B$39) -> 450157 | F4: =E4*(1+Assumptions!$C$39) -> 463661.71 | G4: =F4*(1+Assumptions!$D$39) -> 472934.94 | H4: =G4*(1+Assumptions!$E$39) -> 477664.29 | I4: =H4*(1+Assumptions!$F$39) -> 477664.29
A5: EBIT | B5: 230000 | C5: 210000 | D5: 199000 | E5: =E4*Assumptions!$B$40 -> 200319.86 | F5: =F4*Assumptions!$C$40 -> 208647.77 | G5: =G4*Assumptions!$D$40 -> 212820.72 | H5: =H4*Assumptions!$E$40 -> 212560.61 | I5: =I4*Assumptions!$F$40 -> 212560.61
A6: D&A | B6: 32000 | C6: 34000 | D6: 35000 | E6: =E4*Assumptions!$B$41 -> 35112.246 | F6: =F4*Assumptions!$C$41 -> 35701.952 | G6: =G4*Assumptions!$D$41 -> 35943.056 | H6: =H4*Assumptions!$E$41 -> 35824.822 | I6: =I4*Assumptions!$F$41 -> 35347.158
A7: EBITDA | B7: =B5+B6 -> 262000 | C7: =C5+C6 -> 244000 | D7: =D5+D6 -> 234000 | E7: =E5+E6 -> 235432.11 | F7: =F5+F6 -> 244349.72 | G7: =G5+G6 -> 248763.78 | H7: =H5+H6 -> 248385.43 | I7: =I5+I6 -> 247907.77
A8: EBITDA margin | B8: =B7/B4 -> 0.59423906 | C8: =C7/C4 -> 0.50791007 | D8: =D7/D4 -> 0.52501683 | E8: =E7/E4 -> 0.523 | F8: =F7/F4 -> 0.527 | G8: =G7/G4 -> 0.526 | H8: =H7/H4 -> 0.52 | I8: =I7/I4 -> 0.519
A9: Finance cost | B9: 3000 | C9: 4000 | D9: 5000 | E9: =Assumptions!$B$42 -> 5000 | F9: =Assumptions!$C$42 -> 4800 | G9: =Assumptions!$D$42 -> 4600 | H9: =Assumptions!$E$42 -> 4400 | I9: =Assumptions!$F$42 -> 4200
A10: Other income | B10: 3000 | C10: 3000 | D10: 3000 | E10: =Assumptions!$B$43 -> 3000 | F10: =Assumptions!$C$43 -> 3000 | G10: =Assumptions!$D$43 -> 3000 | H10: =Assumptions!$E$43 -> 3000 | I10: =Assumptions!$F$43 -> 3000
A11: PBT | B11: =B5-B9+B10 -> 230000 | C11: =C5-C9+C10 -> 209000 | D11: =D5-D9+D10 -> 197000 | E11: =E5-E9+E10 -> 198319.86 | F11: =F5-F9+F10 -> 206847.77 | G11: =G5-G9+G10 -> 211220.72 | H11: =H5-H9+H10 -> 211160.61 | I11: =I5-I9+I10 -> 211360.61
A12: Tax & government take | B12: =B11-B13 -> 108700 | C12: =C11-C13 -> 102754 | D12: =D11-D13 -> 103600 | E12: =MAX(0,E11)*Assumptions!$B$10 -> 103126.33 | F12: =MAX(0,F11)*Assumptions!$B$10 -> 107560.84 | G12: =MAX(0,G11)*Assumptions!$B$10 -> 109834.78 | H12: =MAX(0,H11)*Assumptions!$B$10 -> 109803.52 | I12: =MAX(0,I11)*Assumptions!$B$10 -> 109907.52
A13: PAT (net income) | B13: 121300 | C13: 106246 | D13: 93400 | E13: =E11-E12 -> 95193.535 | F13: =F11-F12 -> 99286.929 | G13: =G11-G12 -> 101385.95 | H13: =H11-H12 -> 101357.09 | I13: =I11-I12 -> 101453.09
A15: Single revenue line with a blended EBIT margin; Aramco does not disclose clean segment revenue. Forecast revenue growth tracks the oil deck (§1.9).

Sheet Balance Sheet
A1: Balance sheet ($m, consolidated)
A2: Historical anchored to disclosed/estimated equity, borrowings, cash; PP&E plugs to balance. Forecast rolls forward.
A3: ($m) | B3: FY23 | C3: FY24 | D3: FY25 | E3: FY26E | F3: FY27E | G3: FY28E | H3: FY29E | I3: FY30E
A4: PP&E + intangibles (plug/roll) | B4: =(B12+B13+B14+B15+B16)-(B5+B6+B7+B8+B9) -> 456268.5 | C4: =(C12+C13+C14+C15+C16)-(C5+C6+C7+C8+C9) -> 537886 | D4: =(D12+D13+D14+D15+D16)-(D5+D6+D7+D8+D9) -> 561632.5 | E4: =D4+Assumptions!$B$44-'Income Statement'!E6 -> 579520.25 | F4: =E4+Assumptions!$C$44-'Income Statement'!F6 -> 597818.3 | G4: =F4+Assumptions!$D$44-'Income Statement'!G6 -> 614875.25 | H4: =G4+Assumptions!$E$44-'Income Statement'!H6 -> 631050.42 | I4: =H4+Assumptions!$F$44-'Income Statement'!I6 -> 647703.27
A5: Inventory | B5: ='Income Statement'!B4*Assumptions!$B$30 -> 24249.5 | C5: ='Income Statement'!C4*Assumptions!$B$30 -> 26422 | D5: ='Income Statement'!D4*Assumptions!$B$30 -> 24513.5 | E5: ='Income Statement'!E4*Assumptions!$B$30 -> 24758.635 | F5: ='Income Statement'!F4*Assumptions!$B$30 -> 25501.394 | G5: ='Income Statement'!G4*Assumptions!$B$30 -> 26011.422 | H5: ='Income Statement'!H4*Assumptions!$B$30 -> 26271.536 | I5: ='Income Statement'!I4*Assumptions!$B$30 -> 26271.536
A6: Receivables | B6: ='Income Statement'!B4*Assumptions!$B$31 -> 39681 | C6: ='Income Statement'!C4*Assumptions!$B$31 -> 43236 | D6: ='Income Statement'!D4*Assumptions!$B$31 -> 40113 | E6: ='Income Statement'!E4*Assumptions!$B$31 -> 40514.13 | F6: ='Income Statement'!F4*Assumptions!$B$31 -> 41729.554 | G6: ='Income Statement'!G4*Assumptions!$B$31 -> 42564.145 | H6: ='Income Statement'!H4*Assumptions!$B$31 -> 42989.786 | I6: ='Income Statement'!I4*Assumptions!$B$31 -> 42989.786
A7: Cash & equivalents | B7: 50000 | C7: 40000 | D7: 42000 | E7: =D7+('Income Statement'!E13+'Income Statement'!E6-((E5+E6-E15)-(D5+D6-D15))-Assumptions!$B$44-Assumptions!$B$45+Assumptions!$B$46) -> 41549.786 | F7: =E7+('Income Statement'!F13+'Income Statement'!F6-((F5+F6-F15)-(E5+E6-E15))-Assumptions!$C$44-Assumptions!$C$45+Assumptions!$C$46) -> 41066.002 | G7: =F7+('Income Statement'!G13+'Income Statement'!G6-((G5+G6-G15)-(F5+F6-F15))-Assumptions!$D$44-Assumptions!$D$45+Assumptions!$D$46) -> 40070.443 | H7: =G7+('Income Statement'!H13+'Income Statement'!H6-((H5+H6-H15)-(G5+G6-G15))-Assumptions!$E$44-Assumptions!$E$45+Assumptions!$E$46) -> 37086.831 | I7: =H7+('Income Statement'!I13+'Income Statement'!I6-((I5+I6-I15)-(H5+H6-H15))-Assumptions!$F$44-Assumptions!$F$45+Assumptions!$F$46) -> 30887.082
A8: Current investments | B8: 20000 | C8: 18000 | D8: 18000 | E8: =D8 -> 18000 | F8: =E8 -> 18000 | G8: =F8 -> 18000 | H8: =G8 -> 18000 | I8: =H8 -> 18000
A9: Other assets | B9: 30000 | C9: 32000 | D9: 34000 | E9: =D9 -> 34000 | F9: =E9 -> 34000 | G9: =F9 -> 34000 | H9: =G9 -> 34000 | I9: =H9 -> 34000
A10: Total assets | B10: =SUM(B4:B9) -> 620199 | C10: =SUM(C4:C9) -> 697544 | D10: =SUM(D4:D9) -> 720259 | E10: =SUM(E4:E9) -> 738342.81 | F10: =SUM(F4:F9) -> 758115.25 | G10: =SUM(G4:G9) -> 775521.26 | H10: =SUM(H4:H9) -> 789398.58 | I10: =SUM(I4:I9) -> 799851.67
A12: Equity | B12: 426700 | C12: 442700 | D12: 459132 | E12: =D12+'Income Statement'!E13-Assumptions!$B$45 -> 466725.54 | F12: =E12+'Income Statement'!F13-Assumptions!$C$45 -> 475012.46 | G12: =F12+'Income Statement'!G13-Assumptions!$D$45 -> 481398.41 | H12: =G12+'Income Statement'!H13-Assumptions!$E$45 -> 483755.51 | I12: =H12+'Income Statement'!I13-Assumptions!$F$45 -> 482208.6
A13: Borrowings | B13: 45000 | C13: 80000 | D13: 78100 | E13: =D13+Assumptions!$B$46 -> 88100 | F13: =E13+Assumptions!$C$46 -> 98100 | G13: =F13+Assumptions!$D$46 -> 108100 | H13: =G13+Assumptions!$E$46 -> 119100 | I13: =H13+Assumptions!$F$46 -> 131100
A14: Provisions | B14: 40000 | C14: 42000 | D14: 44000 | E14: =D14 -> 44000 | F14: =E14 -> 44000 | G14: =F14 -> 44000 | H14: =G14 -> 44000 | I14: =H14 -> 44000
A15: Payables | B15: ='Income Statement'!B4*Assumptions!$B$32 -> 48499 | C15: ='Income Statement'!C4*Assumptions!$B$32 -> 52844 | D15: ='Income Statement'!D4*Assumptions!$B$32 -> 49027 | E15: ='Income Statement'!E4*Assumptions!$B$32 -> 49517.27 | F15: ='Income Statement'!F4*Assumptions!$B$32 -> 51002.788 | G15: ='Income Statement'!G4*Assumptions!$B$32 -> 52022.844 | H15: ='Income Statement'!H4*Assumptions!$B$32 -> 52543.072 | I15: ='Income Statement'!I4*Assumptions!$B$32 -> 52543.072
A16: Other liabilities | B16: 60000 | C16: 80000 | D16: 90000 | E16: =D16 -> 90000 | F16: =E16 -> 90000 | G16: =F16 -> 90000 | H16: =G16 -> 90000 | I16: =H16 -> 90000
A17: Total liabilities & equity | B17: =B12+B13+B14+B15+B16 -> 620199 | C17: =C12+C13+C14+C15+C16 -> 697544 | D17: =D12+D13+D14+D15+D16 -> 720259 | E17: =E12+E13+E14+E15+E16 -> 738342.81 | F17: =F12+F13+F14+F15+F16 -> 758115.25 | G17: =G12+G13+G14+G15+G16 -> 775521.26 | H17: =H12+H13+H14+H15+H16 -> 789398.58 | I17: =I12+I13+I14+I15+I16 -> 799851.67
A18: Balance check (assets − L&E) | B18: =B10-B17 -> 0 | C18: =C10-C17 -> 0 | D18: =D10-D17 -> 0 | E18: =E10-E17 -> 0 | F18: =F10-F17 -> 0 | G18: =G10-G17 -> 0 | H18: =H10-H17 -> 0 | I18: =I10-I17 -> 0
A19: Net debt | B19: =B13-B7-B8 -> -25000 | C19: =C13-C7-C8 -> 22000 | D19: =D13-D7-D8 -> 18100 | E19: =E13-E7-E8 -> 28550.214 | F19: =F13-F7-F8 -> 39033.998 | G19: =G13-G7-G8 -> 50029.557 | H19: =H13-H7-H8 -> 64013.169 | I19: =I13-I7-I8 -> 82212.918
A21: PP&E is the historical balancing plug (TMPV convention); the FY26E–FY30E balance-check row is identically zero by construction.

Sheet Cash Flow
A1: Cash flow ($m, forecast) — derived from IS & BS; closing cash ties to the Balance Sheet
A3: ($m) | B3: FY26E | C3: FY27E | D3: FY28E | E3: FY29E | F3: FY30E
A4: PAT | B4: ='Income Statement'!E13 -> 95193.535 | C4: ='Income Statement'!F13 -> 99286.929 | D4: ='Income Statement'!G13 -> 101385.95 | E4: ='Income Statement'!H13 -> 101357.09 | F4: ='Income Statement'!I13 -> 101453.09
A5: + D&A | B5: ='Income Statement'!E6 -> 35112.246 | C5: ='Income Statement'!F6 -> 35701.952 | D5: ='Income Statement'!G6 -> 35943.056 | E5: ='Income Statement'!H6 -> 35824.822 | F5: ='Income Statement'!I6 -> 35347.158
A6: − Increase in net working capital | B6: =-(('Balance Sheet'!E5+'Balance Sheet'!E6-'Balance Sheet'!E15)-('Balance Sheet'!D5+'Balance Sheet'!D6-'Balance Sheet'!D15)) -> -155.995 | C6: =-(('Balance Sheet'!F5+'Balance Sheet'!F6-'Balance Sheet'!F15)-('Balance Sheet'!E5+'Balance Sheet'!E6-'Balance Sheet'!E15)) -> -472.66485 | D6: =-(('Balance Sheet'!G5+'Balance Sheet'!G6-'Balance Sheet'!G15)-('Balance Sheet'!F5+'Balance Sheet'!F6-'Balance Sheet'!F15)) -> -324.5632 | E6: =-(('Balance Sheet'!H5+'Balance Sheet'!H6-'Balance Sheet'!H15)-('Balance Sheet'!G5+'Balance Sheet'!G6-'Balance Sheet'!G15)) -> -165.52723 | F6: =-(('Balance Sheet'!I5+'Balance Sheet'!I6-'Balance Sheet'!I15)-('Balance Sheet'!H5+'Balance Sheet'!H6-'Balance Sheet'!H15)) -> 0
A7: Operating cash flow | B7: =B4+B5+B6 -> 130149.79 | C7: =C4+C5+C6 -> 134516.22 | D7: =D4+D5+D6 -> 137004.44 | E7: =E4+E5+E6 -> 137016.39 | F7: =F4+F5+F6 -> 136800.25
A8: − Capex | B8: =-Assumptions!$B$44 -> -53000 | C8: =-Assumptions!$C$44 -> -54000 | D8: =-Assumptions!$D$44 -> -53000 | E8: =-Assumptions!$E$44 -> -52000 | F8: =-Assumptions!$F$44 -> -52000
A9: Free cash flow | B9: =B7+B8 -> 77149.786 | C9: =C7+C8 -> 80516.216 | D9: =D7+D8 -> 84004.441 | E9: =E7+E8 -> 85016.388 | F9: =F7+F8 -> 84800.251
A10: − Dividend | B10: =-Assumptions!$B$45 -> -87600 | C10: =-Assumptions!$C$45 -> -91000 | D10: =-Assumptions!$D$45 -> -95000 | E10: =-Assumptions!$E$45 -> -99000 | F10: =-Assumptions!$F$45 -> -103000
A11: + Debt drawdown | B11: =Assumptions!$B$46 -> 10000 | C11: =Assumptions!$C$46 -> 10000 | D11: =Assumptions!$D$46 -> 10000 | E11: =Assumptions!$E$46 -> 11000 | F11: =Assumptions!$F$46 -> 12000
A12: Net change in cash | B12: =B9+B10+B11 -> -450.2138 | C12: =C9+C10+C11 -> -483.78382 | D12: =D9+D10+D11 -> -995.55949 | E12: =E9+E10+E11 -> -2983.6121 | F12: =F9+F10+F11 -> -6199.7491
A13: Opening cash | B13: ='Balance Sheet'!D7 -> 42000 | C13: ='Balance Sheet'!E7 -> 41549.786 | D13: ='Balance Sheet'!F7 -> 41066.002 | E13: ='Balance Sheet'!G7 -> 40070.443 | F13: ='Balance Sheet'!H7 -> 37086.831
A14: Closing cash | B14: =B13+B12 -> 41549.786 | C14: =C13+C12 -> 41066.002 | D14: =D13+D12 -> 40070.443 | E14: =E13+E12 -> 37086.831 | F14: =F13+F12 -> 30887.082
A16: FCF = OCF − capex. At the deck, the dividend exceeds FCF in the early years; debt drawdown funds the gap and closing cash ties to the Balance Sheet.

Sheet Summary Financials
A1: Summary financials — every cell links to the statement sheets
A3: ($m unless noted) | B3: FY23 | C3: FY24 | D3: FY25 | E3: FY26E | F3: FY27E | G3: FY28E | H3: FY29E | I3: FY30E
A4: Revenue | B4: ='Income Statement'!B4 -> 440900 | C4: ='Income Statement'!C4 -> 480400 | D4: ='Income Statement'!D4 -> 445700 | E4: ='Income Statement'!E4 -> 450157 | F4: ='Income Statement'!F4 -> 463661.71 | G4: ='Income Statement'!G4 -> 472934.94 | H4: ='Income Statement'!H4 -> 477664.29 | I4: ='Income Statement'!I4 -> 477664.29
A5: EBIT | B5: ='Income Statement'!B5 -> 230000 | C5: ='Income Statement'!C5 -> 210000 | D5: ='Income Statement'!D5 -> 199000 | E5: ='Income Statement'!E5 -> 200319.86 | F5: ='Income Statement'!F5 -> 208647.77 | G5: ='Income Statement'!G5 -> 212820.72 | H5: ='Income Statement'!H5 -> 212560.61 | I5: ='Income Statement'!I5 -> 212560.61
A6: EBITDA | B6: ='Income Statement'!B7 -> 262000 | C6: ='Income Statement'!C7 -> 244000 | D6: ='Income Statement'!D7 -> 234000 | E6: ='Income Statement'!E7 -> 235432.11 | F6: ='Income Statement'!F7 -> 244349.72 | G6: ='Income Statement'!G7 -> 248763.78 | H6: ='Income Statement'!H7 -> 248385.43 | I6: ='Income Statement'!I7 -> 247907.77
A7: Net income (PAT) | B7: ='Income Statement'!B13 -> 121300 | C7: ='Income Statement'!C13 -> 106246 | D7: ='Income Statement'!D13 -> 93400 | E7: ='Income Statement'!E13 -> 95193.535 | F7: ='Income Statement'!F13 -> 99286.929 | G7: ='Income Statement'!G13 -> 101385.95 | H7: ='Income Statement'!H13 -> 101357.09 | I7: ='Income Statement'!I13 -> 101453.09
A8: Net debt | B8: ='Balance Sheet'!B19 -> -25000 | C8: ='Balance Sheet'!C19 -> 22000 | D8: ='Balance Sheet'!D19 -> 18100 | E8: ='Balance Sheet'!E19 -> 28550.214 | F8: ='Balance Sheet'!F19 -> 39033.998 | G8: ='Balance Sheet'!G19 -> 50029.557 | H8: ='Balance Sheet'!H19 -> 64013.169 | I8: ='Balance Sheet'!I19 -> 82212.918
A9: Equity | B9: ='Balance Sheet'!B12 -> 426700 | C9: ='Balance Sheet'!C12 -> 442700 | D9: ='Balance Sheet'!D12 -> 459132 | E9: ='Balance Sheet'!E12 -> 466725.54 | F9: ='Balance Sheet'!F12 -> 475012.46 | G9: ='Balance Sheet'!G12 -> 481398.41 | H9: ='Balance Sheet'!H12 -> 483755.51 | I9: ='Balance Sheet'!I12 -> 482208.6
A11: Free cash flow (forecast) | E11: ='Cash Flow'!B9 -> 77149.786 | F11: ='Cash Flow'!C9 -> 80516.216 | G11: ='Cash Flow'!D9 -> 84004.441 | H11: ='Cash Flow'!E9 -> 85016.388 | I11: ='Cash Flow'!F9 -> 84800.251

Sheet Monte Carlo
A1: Monte Carlo — 16 factors (7C+9 discrete), 50,000 paths, seed 42 (outputs from engine)
A3: Spot (SAR) | B3: 26.24
A4: Realized vol (1Y) | B4: 0.1511665
A5: Net continuous drift 3M | B5: 0.006
A6: Sim path vol (with events) | B6: 0.20457385
A8: Percentile | B8: P5 | C8: P25 | D8: P50 | E8: P75 | F8: P95
A9: T+20 | B9: 23.8 | C9: 25.33 | D9: 26.23 | E9: 27.13 | F9: 28.57
A10: T+60 | B10: 21.99 | C10: 24.47 | D10: 26.12 | E10: 27.78 | F10: 30.35
A12: T+60 touch probabilities
A13: P(touch SAR 23 by T+60) | B13: 0.163
A14: P(touch SAR 24 by T+60) | B14: 0.312
A15: P(touch SAR 25 by T+60) | B15: 0.542
A16: P(touch SAR 27 by T+60) | B16: 0.672
A17: P(touch SAR 28 by T+60) | B17: 0.403
A18: P(touch SAR 29 by T+60) | B18: 0.223
A20: Paths diffuse from spot; the §1 value gap is kept OUT of the drift — fundamental and probabilistic lenses stay independent.

Sheet Sensitivity
A1: Sensitivity — DCF fair value per share (SAR): terminal growth × WACC
A3: WACC ↓ / term g → | B3: 0.5% | C3: 1.0% | D3: 1.5% | E3: 2.0% | F3: 2.5%
A4: 6.00% | B4: =((DCF!$B$13)+(DCF!$F$9*(1+0.005)/(0.06-0.005))*(1/(1+0.06)^5)-Assumptions!$B$7)*Assumptions!$B$6/Assumptions!$B$5 -> 23.081264 | C4: =((DCF!$B$13)+(DCF!$F$9*(1+0.01)/(0.06-0.01))*(1/(1+0.06)^5)-Assumptions!$B$7)*Assumptions!$B$6/Assumptions!$B$5 -> 24.986579 | D4: =((DCF!$B$13)+(DCF!$F$9*(1+0.015)/(0.06-0.015))*(1/(1+0.06)^5)-Assumptions!$B$7)*Assumptions!$B$6/Assumptions!$B$5 -> 27.315298 | E4: =((DCF!$B$13)+(DCF!$F$9*(1+0.02)/(0.06-0.02))*(1/(1+0.06)^5)-Assumptions!$B$7)*Assumptions!$B$6/Assumptions!$B$5 -> 30.226196 | F4: =((DCF!$B$13)+(DCF!$F$9*(1+0.025)/(0.06-0.025))*(1/(1+0.06)^5)-Assumptions!$B$7)*Assumptions!$B$6/Assumptions!$B$5 -> 33.96878
A5: 6.50% | B5: =((DCF!$B$13)+(DCF!$F$9*(1+0.005)/(0.065-0.005))*(1/(1+0.065)^5)-Assumptions!$B$7)*Assumptions!$B$6/Assumptions!$B$5 -> 21.190805 | C5: =((DCF!$B$13)+(DCF!$F$9*(1+0.01)/(0.065-0.01))*(1/(1+0.065)^5)-Assumptions!$B$7)*Assumptions!$B$6/Assumptions!$B$5 -> 22.74896 | D5: =((DCF!$B$13)+(DCF!$F$9*(1+0.015)/(0.065-0.015))*(1/(1+0.065)^5)-Assumptions!$B$7)*Assumptions!$B$6/Assumptions!$B$5 -> 24.618746 | E5: =((DCF!$B$13)+(DCF!$F$9*(1+0.02)/(0.065-0.02))*(1/(1+0.065)^5)-Assumptions!$B$7)*Assumptions!$B$6/Assumptions!$B$5 -> 26.90404 | F5: =((DCF!$B$13)+(DCF!$F$9*(1+0.025)/(0.065-0.025))*(1/(1+0.065)^5)-Assumptions!$B$7)*Assumptions!$B$6/Assumptions!$B$5 -> 29.760657
A6: 6.75% | B6: =((DCF!$B$13)+(DCF!$F$9*(1+0.005)/(0.0675-0.005))*(1/(1+0.0675)^5)-Assumptions!$B$7)*Assumptions!$B$6/Assumptions!$B$5 -> 20.362875 | C6: =((DCF!$B$13)+(DCF!$F$9*(1+0.01)/(0.0675-0.01))*(1/(1+0.0675)^5)-Assumptions!$B$7)*Assumptions!$B$6/Assumptions!$B$5 -> 21.780312 | D6: =((DCF!$B$13)+(DCF!$F$9*(1+0.015)/(0.0675-0.015))*(1/(1+0.0675)^5)-Assumptions!$B$7)*Assumptions!$B$6/Assumptions!$B$5 -> 23.467736 | E6: =((DCF!$B$13)+(DCF!$F$9*(1+0.02)/(0.0675-0.02))*(1/(1+0.0675)^5)-Assumptions!$B$7)*Assumptions!$B$6/Assumptions!$B$5 -> 25.510407 | F6: =((DCF!$B$13)+(DCF!$F$9*(1+0.025)/(0.0675-0.025))*(1/(1+0.0675)^5)-Assumptions!$B$7)*Assumptions!$B$6/Assumptions!$B$5 -> 28.033708
A7: 7.00% | B7: =((DCF!$B$13)+(DCF!$F$9*(1+0.005)/(0.07-0.005))*(1/(1+0.07)^5)-Assumptions!$B$7)*Assumptions!$B$6/Assumptions!$B$5 -> 19.60106 | C7: =((DCF!$B$13)+(DCF!$F$9*(1+0.01)/(0.07-0.01))*(1/(1+0.07)^5)-Assumptions!$B$7)*Assumptions!$B$6/Assumptions!$B$5 -> 20.895027 | D7: =((DCF!$B$13)+(DCF!$F$9*(1+0.015)/(0.07-0.015))*(1/(1+0.07)^5)-Assumptions!$B$7)*Assumptions!$B$6/Assumptions!$B$5 -> 22.424261 | E7: =((DCF!$B$13)+(DCF!$F$9*(1+0.02)/(0.07-0.02))*(1/(1+0.07)^5)-Assumptions!$B$7)*Assumptions!$B$6/Assumptions!$B$5 -> 24.259342 | F7: =((DCF!$B$13)+(DCF!$F$9*(1+0.025)/(0.07-0.025))*(1/(1+0.07)^5)-Assumptions!$B$7)*Assumptions!$B$6/Assumptions!$B$5 -> 26.502218
A8: 7.50% | B8: =((DCF!$B$13)+(DCF!$F$9*(1+0.005)/(0.075-0.005))*(1/(1+0.075)^5)-Assumptions!$B$7)*Assumptions!$B$6/Assumptions!$B$5 -> 18.247293 | C8: =((DCF!$B$13)+(DCF!$F$9*(1+0.01)/(0.075-0.01))*(1/(1+0.075)^5)-Assumptions!$B$7)*Assumptions!$B$6/Assumptions!$B$5 -> 19.335917 | D8: =((DCF!$B$13)+(DCF!$F$9*(1+0.015)/(0.075-0.015))*(1/(1+0.075)^5)-Assumptions!$B$7)*Assumptions!$B$6/Assumptions!$B$5 -> 20.605977 | E8: =((DCF!$B$13)+(DCF!$F$9*(1+0.02)/(0.075-0.02))*(1/(1+0.075)^5)-Assumptions!$B$7)*Assumptions!$B$6/Assumptions!$B$5 -> 22.106958 | F8: =((DCF!$B$13)+(DCF!$F$9*(1+0.025)/(0.075-0.025))*(1/(1+0.075)^5)-Assumptions!$B$7)*Assumptions!$B$6/Assumptions!$B$5 -> 23.908136
A10: Holds the explicit-period PV fixed and flexes the terminal value; the DCF sheet is the base. Spot SAR 26.24 for reference.

Sheet Per-Share & Ratios
A1: Per-share & ratio dashboard (links to Assumptions & statements)
A3: Spot (SAR) | B3: =Assumptions!$B$4 -> 26.24
A4: Shares (m) | B4: =Assumptions!$B$5 -> 242000
A5: Market cap (SAR m) | B5: =Assumptions!$B$4*Assumptions!$B$5 -> 6350080
A6: Market cap ($m) | B6: =Assumptions!$B$4*Assumptions!$B$5/Assumptions!$B$6 -> 1693354.7
A7: EV ($m) | B7: =Assumptions!$B$4*Assumptions!$B$5/Assumptions!$B$6+Assumptions!$B$7 -> 1711454.7
A8: EPS FY25 (SAR) | B8: ='Income Statement'!D13*Assumptions!$B$6/Assumptions!$B$5 -> 1.447314
A9: P/E FY25 (x) | B9: =Assumptions!$B$4/('Income Statement'!D13*Assumptions!$B$6/Assumptions!$B$5) -> 18.130136
A10: EV/EBITDA FY25 (x) | B10: =(Assumptions!$B$4*Assumptions!$B$5/Assumptions!$B$6+Assumptions!$B$7)/'Income Statement'!D7 -> 7.3139088
A11: Fwd base div/share (SAR) | B11: =Assumptions!$B$21 -> 1.3568182
A12: Fwd dividend yield | B12: =Assumptions!$B$21/Assumptions!$B$4 -> 0.05170801
A13: Dividend / FY25 FCF (payout) | B13: =87560/85400 -> 1.0252927
A14: Gearing FY25 | B14: ='Balance Sheet'!D19/('Balance Sheet'!D19+'Balance Sheet'!D12) -> 0.037927046

Sheet Peer & Sector
A1: Peer set & sector context (international majors & NOC comparators)
A3: Company | B3: EV/EBITDA (x) | C3: P/E (x) | D3: Div yield | E3: Note
A4: Saudi Aramco (2222) | B4: ='Per-Share & Ratios'!B10 -> 7.3139088 | C4: ='Per-Share & Ratios'!B8 -> 1.447314 | D4: ='Per-Share & Ratios'!B12 -> 0.05170801 | E4: lowest-cost; sovereign; premium multiple
A5: ExxonMobil (XOM) | B5: 5.5 | C5: 13 | D5: 0.035 | E5: integrated major
A6: Chevron (CVX) | B6: 5.8 | C6: 13.5 | D6: 0.045 | E6: integrated major
A7: Shell (SHEL) | B7: 4.5 | C7: 9.5 | D7: 0.04 | E7: integrated + LNG
A8: TotalEnergies (TTE) | B8: 4.2 | C8: 8.5 | D8: 0.055 | E8: integrated + power
A9: PetroChina (857) | B9: 3.5 | C9: 8 | D9: 0.06 | E9: NOC comparator
