Workbook

Sheet READ FIRST
A1: Testahil — Cleopatra Hospitals Group S.A.E. (EGX: CLHO)
A3: Companion model · Independent Valuation Study · Educational analysis · Not investment advice
A5: What this workbook is. A transparent companion to the CLHO valuation study. Every blue cell is an input; every
A6: black cell is a formula; green cells link across sheets. All inputs live on the Assumptions sheet — change one
A7: (a growth rate, the EBITDA-margin path, the normalized-stage WACC, a P/E band, an EV-per-bed mark) and the model reprices.
A9: What it is not. It is not investment advice, a recommendation, or a price target. Values are model outputs shown
A10: as ranges. The preparer is not licensed by any securities regulator and may hold a position in the security.
A12: Entity note. Cleopatra Hospitals Group (CLHO.CA, listed June 2016) is Egypt’s largest private hospital group:
A13: seven hospitals (Cleopatra, Cairo Specialized, Nile Badrawi, Al Shorouk, El Katib, Cleopatra El Tagamoa, Cleopatra
A14: October), five polyclinics and Bedaya IVF — 14 facilities, ~880 operational beds (Q4-25) heading to ~1,320 by 2027.
A15: House lens for an operating company: FCFF DCF (two-stage Egyptian rate path) cross-read against relative multiples,
A16: normalized earnings power and an EV-per-operational-bed transaction lens.
... A24: Peer & Sector · Summary Financials

Sheet Assumptions
A1: Assumptions — the single input layer (blue cells)
A2: Change a blue cell and every downstream sheet reprices. Sources per cell in column D/E.
A4: Spot (EGP, 2026-07-12 close) | B4: 16.31 | D4: Uploaded CLHO daily OHLC, last close
A5: Shares outstanding (mn) | B5: 1449.4 | D5: CHG 1Q2026 ER shareholder info (1,449mn); african-markets 1,449.44mn
A6: Market cap (EGP mn) | B6: =B4*B5 -> 23639.714
A7: Net financial debt incl IFRS-16 leases (EGP mn, 31-Mar-26) | B7: 3164.1 | D7: 1Q26 ER: reported net financial debt EGP 3.16bn incl. ~170mn IFRS-16 leases
A8: Non-controlling interest (book, 31-Mar-26) | B8: 452.8 | D8: CHG 1Q2026 ER balance sheet
A9: Investment in associates (31-Mar-26) | B9: 18.6 | D9: CHG 1Q2026 ER balance sheet
A10: Gross borrowings + leases (weights) | B10: 3913.7 | D10: 1Q26 ER: 3,743.3 borrowings + 170.4 leases
A13: Risk-free rate rf (Egypt 10Y) | B13: 0.2255 | D13: Egypt 10Y local-currency govt bond yield, investing.com (cached Cost_of_Capital_Reference.md) · 2026-07-03
A14: ERP — CDS-based (primary) | B14: 0.0941 | D14: Damodaran ORIGINAL country-risk file, Egypt CDS-based ERP (Last updated Jan 2026)
A15: ERP — rating-based (alt) | B15: 0.1394 | D15: Damodaran ORIGINAL country-risk file, Egypt rating-based ERP
A16: Beta (regression, gate-passed) | B16: 0.446 | D16: Own weekly regression vs equal-weight 27-name EGX composite (Testahil raw_ohlc EG library), usability gate PASSED
A17: Ke — PRIMARY = (rf − CDS) + β_adopted × ERP [rev.2 §3: sovereign double-count removed] | B17: =(B13-B82)+B80*B14 -> 0.26728
A18: Ke — rating basis (alt) | B18: =(B13-B82)+B80*B15 -> 0.30352
A19: Kd pre-tax (EGP) | B19: 0.2015 | D19: REBUILT 13-Jul-2026 (was 0.207, a CBE weighted-average AGGREGATOR print). Now fully sourced: today's CBE lending corridor 19.50% + CLHO's OWN AUDITED bank spread of +65bp. The spread is not asserted — FY2024 audited FS note 5.1.2 discloses actual contractual rates of 28.90% on loans / 28.35% on overdrafts against a 28.25% corridor at Dec-2024, and 20.90% vs a 20.25% corridor at Dec-2023: the same +65bp at two independent year-ends. Currency: 100% EGP, ZERO foreign-currency liabilities (same note) — no blend available or required. All debt is VARIABLE-rate (audited sensitivity: +/-600bp moves profit by -/+120.9mn), which is the mechanical reason a SLIDING discount schedule is the right structure: the interest bill re-prices with the corridor automatically, no refinancing required.
A20: Tax rate (statutory) | B20: 0.225 | D20: Egypt corporate income-tax rate; CHG's own 1Q26 ER normalizes at 22.5%
A21: Kd after tax | B21: =B19*(1-B20) -> 0.1561625
A22: We = E/(D+E) | B22: =B6/(B6+B10) -> 0.85795953
A23: Wd | B23: =1-B22 -> 0.14204047
A24: WACC — spot, CDS ERP (primary) | B24: =B22*B17+B23*B21 -> 0.25149682
A25: WACC — spot, rating ERP | B25: =B22*B18+B23*B21 -> 0.28258927
A27: Normalized-stage rf (house view, GC-06) | B27: 0.125 | D27: PROTOCOL rev.2 §4 CONSTRUCTION (was 14.5%, a free house view): terminal rf = the central bank's OWN stated medium-term inflation target (CBE 7%, MPC 9-Jul-2026) + the standard EM real-rate convention (~5.5pp) = 12.5%. Deliberately NOT a historical average that cannot be re-verified live.
A28: Normalized-stage Kd pre-tax | B28: 0.15 | D28: PROTOCOL rev.2 §4: terminal Kd = Egypt's long-run corporate-borrowing norm, band 14-16%, MIDPOINT 15% absent a name-specific reason to deviate. (Was 16.0%, the top of the band.) The audited +65bp spread over a normalised corridor would give ~15.5% — inside the band either way; the house midpoint is adopted as primary and sensitized.
A29: Ke — terminal (norm-built; constructed rf carries no CDS) | B29: =B27+B80*B83 -> 0.189
A30: WACC — normalized stage | B30: =B22*B29+B23*B28*(1-B20) -> 0.17866656
A31: Terminal growth g (two-stage base) | B31: 0.05 | D31: STANDING PROCEDURE (13-Jul-2026): default terminal g center = 5%, matching standard analyst convention for well-established Egyptian/EM companies post-currency-turbulence/hyperinflation; sensitized 3/4/5/6/7%. Replaces the earlier CBE-target-derived 11% point estimate.
A32: Terminal growth g (flat-rate scenario) | B32: 0.05 | D32: STANDING PROCEDURE: same 5% center applied to the flat-crisis-rate scenario for consistency — terminal growth is a steady-state/macro question, independent of which discount-rate path is assumed.
A33: FY2025 revenue (EGP mn) | B33: 7227.3 | D33: CHG FY2025 ER (official)
A34: FY2025 net working capital (EGP mn) | B34: -116.6 | D34: Inv+AR+other receivables − creditors, FY25 BS
A35: Forward effective tax (income statement) | B35: 0.245 | D35: HOUSE VIEW: between 22.5% statutory and FY25 effective 26.6% — driver-ledger GC row
A38: Forecast drivers | B38: FY26E | C38: FY27E | D38: FY28E | E38: FY29E | F38: FY30E | H38: Driver-ledger ref
A39: Revenue growth y/y (DERIVED — bottom-up build, not a direct input) | B39: =DCF!B4/$B$33-1 -> 0.28036487 | C39: =DCF!C4/DCF!B4-1 -> 0.32954797 | D39: =DCF!D4/DCF!C4-1 -> 0.283121 | E39: =DCF!E4/DCF!D4-1 -> 0.20769033 | F39: =DCF!F4/DCF!E4-1 -> 0.14457873 | H39: GC-CLHO-01 (see Facilities & Volumes for the full bottom-up build)
A40: EBITDA margin (reported basis) | B40: 0.215 | C40: 0.245 | D40: 0.265 | E40: 0.275 | F40: 0.28 | H40: GC-CLHO-02
A41: Gross margin | B41: 0.355 | C41: 0.385 | D41: 0.395 | E41: 0.4 | F41: 0.4 | H41: GC-CLHO-02
A42: D&A (EGP mn) | B42: 480 | C42: 560 | D42: 620 | E42: 680 | F42: 740 | H42: GC-CLHO-03
A43: Capex (EGP mn) | B43: 1400 | C43: 1100 | D43: 1150 | E43: 1220 | F43: 1280 | H43: GC-CLHO-03
A44: NWC as % of revenue | B44: 0 | C44: 0.008 | D44: 0.01 | E44: 0.01 | F44: 0.01 | H44: GC-CLHO-04
A45: Net interest (EGP mn) | B45: -255 | C45: -230 | D45: -160 | E45: -90 | F45: -30 | H45: GC-CLHO-11
A46: Parent share of NP | B46: 0.84 | C46: 0.85 | D46: 0.85 | E46: 0.85 | F46: 0.85 | H46: GC-CLHO-11
...

Sheet Facilities & Volumes
A1: Facilities, volumes and unit prices — company disclosure
A2: Units × average revenue per case (ARP), FY24→FY25; hospital revenue mix FY25 and 1Q26.
A3: Core KPI (consolidated) | B3: FY24 volume | C3: FY25 volume | D3: Δ% | E3: FY24 ARP (EGP) | F3: FY25 ARP (EGP) | G3: Δ%
A4: Paid outpatient consultations | B4: 1068211 | C4: 1204807 | D4: =C4/B4-1 -> 0.12787361 | E4: 457 | F4: 506 | G4: =F4/E4-1 -> 0.10722101
A5: Inpatients | B5: 66859 | C5: 75107 | D5: =C5/B5-1 -> 0.12336409 | E5: 18446 | F5: 21266 | G5: =F5/E5-1 -> 0.15287867
A6: Surgical procedures | B6: 42558 | C6: 43415 | D6: =C6/B6-1 -> 0.020137224 | E6: 24951 | F6: 30086 | G6: =F6/E6-1 -> 0.20580337
A7: Emergency visits | B7: 174597 | C7: 192620 | D7: =C7/B7-1 -> 0.10322629 | E7: 1043 | F7: 1348 | G7: =F7/E7-1 -> 0.2924257
A8: Catheterizations | B8: 5510 | C8: 6089 | D8: =C8/B8-1 -> 0.10508167 | E8: 71124 | F8: 78253 | G8: =F8/E8-1 -> 0.1002334
A10: Cases served FY25 (inpatient + paid outpatient + ER) | B10: 1472534
A11: Facilities / operational beds Q4-25 / adds to 2027 | B11: 14 | C11: 880 | D11: 440
A13: Revenue by facility (EGP mn) | B13: FY24 | C13: FY25 | D13: Δ% | E13: 1Q26 | F13: share 1Q26
A14: Cleopatra Hospital (CHC) | B14: 1910 | C14: 2461 | D14: =C14/B14-1 -> 0.28848168 | E14: 623 | F14: 0.31
A15: Cairo Specialized (CSH) | B15: 1179 | C15: 1579 | D15: =C15/B15-1 -> 0.33927057 | E15: 420 | F15: 0.21
A16: Al Shorouk (ASH) | B16: 814 | C16: 1074 | D16: =C16/B16-1 -> 0.31941032 | E16: 269 | F16: 0.13
A17: Nile Badrawi (NBH) | B17: 827 | C17: 1057 | D17: =C17/B17-1 -> 0.27811366 | E17: 240 | F17: 0.12
A18: El Katib (AKH) | B18: 257 | C18: 354 | D18: =C18/B18-1 -> 0.37743191 | E18: 81 | F18: 0.04
A19: Cleopatra October (COH) | B19: 248 | E19: 108 | F19: 0.05
A20: Cleopatra El Tagamoa (CTH) | B20: 0 | E20: 154 | F20: 0.08
A22: Source: CHG FY2024/FY2025/1Q2026 earnings releases (official). CTH launched 27-Jan-2026; +40% bed capacity as floors open.
A24: Bottom-up revenue build, FY2026E–FY2030E
A25: 5 disclosed KPI lines built volume × ARP (blue = assumption); the other ~41% of revenue (pharmacy/lab/IVF, no disclosed volume/price split) grows top-down at capacity growth + a flat re-pricing kicker.
A27: Effective operational beds | B27: FY26E | C27: FY27E | D27: FY28E | E27: FY29E | F27: FY30E
A28: CTH ramp (of 240 incremental beds) | B28: 0.25 | C28: 0.6 | D28: 0.85 | E28: 1 | F28: 1
A29: October BTS ramp (of 200 incremental beds) | B29: 0 | C29: 0.25 | D29: 0.6 | E29: 0.85 | F29: 1
A30: Effective operational beds | B30: =880+240*B28+200*B29 -> 940 | C30: =880+240*C28+200*C29 -> 1074 | D30: =880+240*D28+200*D29 -> 1204 | E30: =880+240*E28+200*E29 -> 1290 | F30: =880+240*F28+200*F29 -> 1320
A31: Bed-capacity growth y/y | B31: =B30/880-1 -> 0.068181818 | C31: =C30/B30-1 -> 0.14255319 | D31: =D30/C30-1 -> 0.12104283 | E31: =E30/D30-1 -> 0.071428571 | F31: =F30/E30-1 -> 0.023255814
A33: Line — volume × ARP | B33: FY26E | C33: FY27E | D33: FY28E | E33: FY29E | F33: FY30E
A34: Outpatient — volume | B34: =1204807*(1+B35)*(1+$K$34*B31) -> 1395385.6 | C34: =B34*(1+C35)*(1+$K$34*C31) -> 1659276.7 | D34: =C34*(1+D35)*(1+$K$34*D31) -> 1935668.3 | E34: =D34*(1+E35)*(1+$K$34*E31) -> 2185231.3 | F34: =E34*(1+F35)*(1+$K$34*F31) -> 2387492.2 | K34: 0.5 | L34: ← cap_weight: share of bed-capacity growth accruing to this line (1.0 = fully bed-constrained; 0.5 = partially)
A35: organic growth (blue) | B35: 0.12 | C35: 0.11 | D35: 0.1 | E35: 0.09 | F35: 0.08
A36: ARP (EGP) | B36: =J36*(1+0.1) -> 556.6 | C36: =B36*(1+0.09) -> 606.694 | D36: =C36*(1+0.08) -> 655.22952 | E36: =D36*(1+0.07) -> 701.09559 | F36: =E36*(1+0.06) -> 743.16132 | J36: 506
A37: → line revenue (EGP mn) | B37: =B34*B36/1000000 -> 776.6716 | C37: =C34*C36/1000000 -> 1006.6732 | D37: =D34*D36/1000000 -> 1268.307 | E37: =E34*E36/1000000 -> 1532.056 | F37: =F34*F36/1000000 -> 1774.2919
A38: Inpatient — volume | B38: =75107*(1+B39)*(1+$K$38*B31) -> 89053.004 | C38: =B38*(1+C39)*(1+$K$38*C31) -> 111922.57 | D38: =C38*(1+D39)*(1+$K$38*D31) -> 136762.3 | E38: =D38*(1+E39)*(1+$K$38*E31) -> 156788.21 | F38: =E38*(1+F39)*(1+$K$38*F31) -> 170060.51 | K38: 1 | L38: ← cap_weight: share of bed-capacity growth accruing to this line (1.0 = fully bed-constrained; 0.5 = partially)
A39: organic growth (blue) | B39: 0.11 | C39: 0.1 | D39: 0.09 | E39: 0.07 | F39: 0.06
A40: ARP (EGP) | B40: =J40*(1+0.14) -> 24243.24 | C40: =B40*(1+0.12) -> 27152.429 | D40: =C40*(1+0.1) -> 29867.672 | E40: =D40*(1+0.08) -> 32257.085 | F40: =E40*(1+0.07) -> 34515.081 | J40: 21266
A41: → line revenue (EGP mn) | B41: =B38*B40/1000000 -> 2158.9334 | C41: =C38*C40/1000000 -> 3038.9697 | D41: =D38*D40/1000000 -> 4084.7714 | E41: =E38*E40/1000000 -> 5057.5306 | F41: =F38*F40/1000000 -> 5869.6524
A42: Surgical — volume | B42: =43415*(1+B43)*(1+$K$42*B31) -> 47766.367 | C42: =B42*(1+C43)*(1+$K$42*C31) -> 56758.64 | D42: =C42*(1+D43)*(1+$K$42*D31) -> 66810.309 | E42: =D42*(1+E43)*(1+$K$42*E31) -> 75519.51 | F42: =E42*(1+F43)*(1+$K$42*F31) -> 81912.325 | K42: 1 | L42: ← cap_weight: share of bed-capacity growth accruing to this line (1.0 = fully bed-constrained; 0.5 = partially)
A43: organic growth (blue) | B43: 0.03 | C43: 0.04 | D43: 0.05 | E43: 0.055 | F43: 0.06
A44: ARP (EGP) | B44: =J44*(1+0.15) -> 34598.9 | C44: =B44*(1+0.12) -> 38750.768 | D44: =C44*(1+0.09) -> 42238.337 | E44: =D44*(1+0.07) -> 45195.021 | F44: =E44*(1+0.06) -> 47906.722 | J44: 30086
A45: → line revenue (EGP mn) | B45: =B42*B44/1000000 -> 1652.6638 | C45: =C42*C44/1000000 -> 2199.4409 | D45: =D42*D44/1000000 -> 2821.9564 | E45: =E42*E44/1000000 -> 3413.1058 | F45: =F42*F44/1000000 -> 3924.151
A46: Er — volume | B46: =192620*(1+B47)*(1+$K$46*B31) -> 219105.25 | C46: =B46*(1+C47)*(1+$K$46*C31) -> 255847.34 | D46: =C46*(1+D47)*(1+$K$46*D31) -> 293038.1 | E46: =D46*(1+E47)*(1+$K$46*E31) -> 324749.01 | F46: =E46*(1+F47)*(1+$K$46*F31) -> 348236.68 | K46: 0.5 | L46: ← cap_weight: share of bed-capacity growth accruing to this line (1.0 = fully bed-constrained; 0.5 = partially)
...

Sheet DCF
A1: FCFF DCF — two-stage Egyptian rate path (primary) with flat-rate and fast-normalization scenarios
A2: WACC — sliding schedule (rev.2 §1/§2). Glide shape INHERITED from kd_path, never invented.
A3: EGP mn | B3: FY26E | C3: FY27E | D3: FY28E | E3: FY29E | F3: FY30E | H3: Terminal value — the calculation, step by step | I3: value
A4: Revenue | B4: ='Facilities & Volumes'!B65 -> 9253.581 | C4: ='Facilities & Volumes'!C65 -> 12303.08 | D4: ='Facilities & Volumes'!D65 -> 15786.34 | E4: ='Facilities & Volumes'!E65 -> 19065.01 | F4: ='Facilities & Volumes'!F65 -> 21821.405 | H4: 1 · FCFF, final explicit year (FY30E) | I4: =F13 -> 3594.181
A5: EBITDA (reported basis) | B5: =B4*Assumptions!B40 -> 1989.5199 | C5: =C4*Assumptions!C40 -> 3014.2546 | D5: =D4*Assumptions!D40 -> 4183.3801 | E5: =E4*Assumptions!E40 -> 5242.8778 | F5: =F4*Assumptions!F40 -> 6109.9934 | H5: 2 · × (1 + terminal g) | I5: =I4*(1+Assumptions!B31) -> 3773.89
A6: (-) D&A | B6: =-Assumptions!B42 -> -480 | C6: =-Assumptions!C42 -> -560 | D6: =-Assumptions!D42 -> -620 | E6: =-Assumptions!E42 -> -680 | F6: =-Assumptions!F42 -> -740 | H6: 3 · Capitalization rate = WACCn − g | I6: =Assumptions!B30-Assumptions!B31 -> 0.12866656
A7: EBIT | B7: =B5+B6 -> 1509.5199 | C7: =C5+C6 -> 2454.2546 | D7: =D5+D6 -> 3563.3801 | E7: =E5+E6 -> 4562.8778 | F7: =F5+F6 -> 5369.9934 | H7: 4 · Terminal value (end FY30E) = step2÷step3 | I7: =I5/I6 -> 29330.777
A8: NOPAT = EBIT × (1 − tax 22.5%) | B8: =B7*(1-Assumptions!$B$20) -> 1169.8779 | C8: =C7*(1-Assumptions!$B$20) -> 1902.0473 | D8: =D7*(1-Assumptions!$B$20) -> 2761.6196 | E8: =E7*(1-Assumptions!$B$20) -> 3536.2303 | F8: =F7*(1-Assumptions!$B$20) -> 4161.7449 | H8: 5 · Discount factor, FY30E (year 5) | I8: =F15 -> 0.3863686
A9: (+) D&A | B9: =-B6 -> 480 | C9: =-C6 -> 560 | D9: =-D6 -> 620 | E9: =-E6 -> 680 | F9: =-F6 -> 740 | H9: 6 · PV of terminal value = step4×step5 | I9: =I7*I8 -> 11332.491
A10: (-) Capex | B10: =-Assumptions!B43 -> -1400 | C10: =-Assumptions!C43 -> -1100 | D10: =-Assumptions!D43 -> -1150 | E10: =-Assumptions!E43 -> -1220 | F10: =-Assumptions!F43 -> -1280 | H10: 7 · Cross-check vs B19/B20 (should be ~0) | I10: =I7-B19 -> 4802.3367
A11: Net working capital | B11: =B4*Assumptions!B44 -> 0 | C11: =C4*Assumptions!C44 -> 98.424639 | D11: =D4*Assumptions!D44 -> 157.8634 | E11: =E4*Assumptions!E44 -> 190.6501 | F11: =F4*Assumptions!F44 -> 218.21405
A12: (-) Δ working capital | B12: =-(B11-Assumptions!$B$34) -> -116.6 | C12: =-(C11-B11) -> -98.424639 | D12: =-(D11-C11) -> -59.438762 | E12: =-(E11-D11) -> -32.786702 | F12: =-(F11-E11) -> -27.563949 | H12: Formula: TV = FCFF_FY30E x (1+g) / (WACCn - g); PV(TV) = TV x discount factor for FY30E.
A13: Free cash flow to the firm (FCFF) | B13: =B8+B9+B10+B12 -> 133.27794 | C13: =C8+C9+C10+C12 -> 1263.6226 | D13: =D8+D9+D10+D12 -> 2172.1808 | E13: =E8+E9+E10+E12 -> 2963.4436 | F13: =F8+F9+F10+F12 -> 3594.181
A14: WACC applied — SLIDING (rev.2; the two-stage-flat convention is RETIRED) | B14: =B48 -> 0.25149682 | C14: =C48 -> 0.22816285 | D14: =D48 -> 0.2034147 | E14: =E48 -> 0.18715163 | F14: =F48 -> 0.17866656 | H14: Check (a) actual NOPAT CAGR FY21-25: 31.0% | Check (b) ROIC x RR implied g, 2022 stable year only: 3.3%
A15: Discount factor (from the sliding schedule, row 49) | B15: =1/(1+B14) -> 0.79904318 | C15: =C49 -> 0.65060035 | D15: =D49 -> 0.54062856 | E15: =E49 -> 0.45539975 | F15: =F49 -> 0.3863686 | H15: g=5% sits between these two bounds (standing procedure); full reconciliation table on the Sensitivity sheet.
A16: PV of FCFF | B16: =B13*B15 -> 106.49483 | C16: =C13*C15 -> 822.11334 | D16: =D13*D15 -> 1174.343 | E16: =E13*E15 -> 1349.5515 | F16: =F13*F15 -> 1388.6787
A18: PV of explicit FCFF (FY26-30E) | B18: =SUM(B16:F16) -> 4841.1813
A19: Terminal value = NOPAT31 × (1 − g/ROIC) / (WACCn − g) [VALUE-DRIVER] | B19: =F8*(1+Assumptions!B31)*(1-Assumptions!B31/Assumptions!B84)/(Assumptions!B30-Assumptions!B31) -> 24528.44
A20: PV of terminal value | B20: =B19*F15 -> 9477.0191
A21: Enterprise value | B21: =B18+B20 -> 14318.2
A22: TV as % of EV (disclosed — high-terminal DCF) | B22: =B20/B21 -> 0.66188619
A23: (-) Net debt incl leases | B23: =-Assumptions!B7 -> -3164.1
A24: (-) Non-controlling interest (FAIR VALUE — CSH mini-SOTP, not book) | B24: =-Assumptions!B85 -> -781.9
A25: (+) Associates | B25: =Assumptions!B9 -> 18.6
A26: Equity value | B26: =B21+B23+B24+B25 -> 10390.8
A27: Fair value per share (EGP) — scenario B (base) | B27: =B26/Assumptions!B5 -> 7.1690357
A28: vs spot | B28: =B27/Assumptions!B4-1 -> -0.56045152
A30: Scenario A — flat crisis rates: no CBE easing at all. Every year AND the terminal discounted at the explicit-window WACC. g = 5%. This is the El Nino / Hormuz scenario (SR-26).
A32: Discount factors — scenario A | B32: =1/(1+Assumptions!$B$24)^1 -> 0.79904318 | C32: =1/(1+Assumptions!$B$24)^2 -> 0.63847001 | D32: =1/(1+Assumptions!$B$24)^3 -> 0.51016511 | E32: =1/(1+Assumptions!$B$24)^4 -> 0.40764395 | F32: =1/(1+Assumptions!$B$24)^5 -> 0.32572512
A33: Enterprise value — scenario A | B33: =SUMPRODUCT(B13:F13,B32:F32)+F8*(1+Assumptions!B32)*(1-Assumptions!B32/Assumptions!B84)/(Assumptions!B24-Assumptions!B32)*F32 -> 9501.9398
A34: Fair value per share — scenario A | B34: =(B33-Assumptions!B7-Assumptions!B85+Assumptions!B9)/Assumptions!B5 -> 3.8461017
A35: TV as % of EV — scenario A | B35: =F8*(1+Assumptions!B32)*(1-Assumptions!B32/Assumptions!B84)/(Assumptions!B24-Assumptions!B32)*F32/B33 -> 0.53691606
A37: Scenario C — faster normalization (normalized-stage WACC − 1pp from year 3)
A38: Discount factors — scenario C | B38: =1/(1+B48-0.01) -> 0.80547931 | C38: =B38/(1+C48-0.01) -> 0.66122465 | D38: =C38/(1+D48-0.01) -> 0.55406109 | E38: =D38/(1+E48-0.01) -> 0.47067946 | F38: =E38/(1+F48-0.01) -> 0.40274915
A39: Enterprise value — scenario C | B39: =SUMPRODUCT(B13:F13,B38:F38)+F8*(1+Assumptions!B31)*(1-Assumptions!B31/Assumptions!B84)/(Assumptions!B30-0.01-Assumptions!B31)*F38 -> 15700.09
A40: Fair value per share — scenario C | B40: =(B39-Assumptions!B7-Assumptions!B85+Assumptions!B9)/Assumptions!B5 -> 8.1224577
A41: TV as % of EV — scenario C | B41: =F8*(1+Assumptions!B31)*(1-Assumptions!B31/Assumptions!B84)/(Assumptions!B30-0.01-Assumptions!B31)*F38/B39 -> 0.68224404
A43: Engine cross-check (study_numbers.json): scenario A 3.85 · B 7.17 · C 8.12 EGP/share — this sheet must reproduce all three.
A45: Discount-rate schedule | B45: FY26E | C45: FY27E | D45: FY28E | E45: FY29E | F45: FY30E
A46: Kd path (blue) | B46: 0.2015 | C46: 0.185 | D46: 0.1675 | E46: 0.156 | F46: 0.15
...

Sheet Income Statement
A1: Consolidated income statement — 3 actual + 5 forecast columns
A2: FY23–FY25 = company disclosure (official earnings releases). FY26E–FY30E driven off Assumptions.
A3: EGP mn | B3: FY23A | C3: FY24A | D3: FY25A | E3: FY26E | F3: FY27E | G3: FY28E | H3: FY29E | I3: FY30E
A4: Revenue | B4: 3595.3 | C4: 5420.4 | D4: 7227.3 | E4: =DCF!B4 -> 9253.581 | F4: =DCF!C4 -> 12303.08 | G4: =DCF!D4 -> 15786.34 | H4: =DCF!E4 -> 19065.01 | I4: =DCF!F4 -> 21821.405
A5: Cost of sales | B5: -2386.7 | C5: -3407.1 | D5: -4368.8 | E5: =-E4*(1-Assumptions!B41) -> -5968.5598 | F5: =-F4*(1-Assumptions!C41) -> -7566.3941 | G5: =-G4*(1-Assumptions!D41) -> -9550.7358 | H5: =-H4*(1-Assumptions!E41) -> -11439.006 | I5: =-I4*(1-Assumptions!F41) -> -13092.843
A6: Gross profit | B6: =B4+B5 -> 1208.6 | C6: =C4+C5 -> 2013.3 | D6: =D4+D5 -> 2858.5 | E6: =E4+E5 -> 3285.0213 | F6: =F4+F5 -> 4736.6857 | G6: =G4+G5 -> 6235.6043 | H6: =H4+H5 -> 7626.0041 | I6: =I4+I5 -> 8728.5621
A7: G&A, provisions & other, net | B7: -559.2 | C7: -850.6 | D7: -1358.7 | E7: =DCF!B7-E6 -> -1775.5013 | F7: =DCF!C7-F6 -> -2282.4312 | G7: =DCF!D7-G6 -> -2672.2242 | H7: =DCF!E7-H6 -> -3063.1263 | I7: =DCF!F7-I6 -> -3358.5686
A8: EBIT | B8: 649.4 | C8: 1162.8 | D8: 1499.8 | E8: =DCF!B7 -> 1509.5199 | F8: =DCF!C7 -> 2454.2546 | G8: =DCF!D7 -> 3563.3801 | H8: =DCF!E7 -> 4562.8778 | I8: =DCF!F7 -> 5369.9934
A9: Net interest (income − expense) | B9: -41.7 | C9: -79.1 | D9: -180.7 | E9: =Assumptions!B45 -> -255 | F9: =Assumptions!C45 -> -230 | G9: =Assumptions!D45 -> -160 | H9: =Assumptions!E45 -> -90 | I9: =Assumptions!F45 -> -30
A10: Profit before tax | B10: =B8+B9 -> 607.7 | C10: =C8+C9 -> 1083.7 | D10: =D8+D9 -> 1319.1 | E10: =E8+E9 -> 1254.5199 | F10: =F8+F9 -> 2224.2546 | G10: =G8+G9 -> 3403.3801 | H10: =H8+H9 -> 4472.8778 | I10: =I8+I9 -> 5339.9934
A11: Income tax (incl deferred) | B11: -138.4 | C11: -266.7 | D11: -351.2 | E11: =-E10*Assumptions!$B$35 -> -307.35738 | F11: =-F10*Assumptions!$B$35 -> -544.94237 | G11: =-G10*Assumptions!$B$35 -> -833.82813 | H11: =-H10*Assumptions!$B$35 -> -1095.8551 | I11: =-I10*Assumptions!$B$35 -> -1308.2984
A12: Net profit | B12: =B10+B11 -> 469.3 | C12: =C10+C11 -> 817 | D12: =D10+D11 -> 967.9 | E12: =E10+E11 -> 947.16254 | F12: =F10+F11 -> 1679.3122 | G12: =G10+G11 -> 2569.552 | H12: =H10+H11 -> 3377.0228 | I12: =I10+I11 -> 4031.6951
A13: — attributable to parent | B13: 418.2 | C13: 723.3 | D13: 823.9 | E13: =E12*Assumptions!B46 -> 795.61653 | F13: =F12*Assumptions!C46 -> 1427.4154 | G13: =G12*Assumptions!D46 -> 2184.1192 | H13: =H12*Assumptions!E46 -> 2870.4693 | I13: =I12*Assumptions!F46 -> 3426.9408
A14: — non-controlling interests | B14: 51.1 | C14: 93.7 | D14: 144 | E14: =E12-E13 -> 151.54601 | F14: =F12-F13 -> 251.89683 | G14: =G12-G13 -> 385.4328 | H14: =H12-H13 -> 506.55341 | I14: =I12-I13 -> 604.75426
A15: EPS (EGP, parent) | B15: =B13/Assumptions!$B$5 -> 0.28853319 | C15: =C13/Assumptions!$B$5 -> 0.49903408 | D15: =D13/Assumptions!$B$5 -> 0.56844211 | E15: =E13/Assumptions!$B$5 -> 0.5489282 | F15: =F13/Assumptions!$B$5 -> 0.98483191 | G15: =G13/Assumptions!$B$5 -> 1.5069127 | H15: =H13/Assumptions!$B$5 -> 1.9804535 | I15: =I13/Assumptions!$B$5 -> 2.3643858
A16: Adjusted EBITDA (company definition, disclosed) | B16: 954 | C16: 1529 | D16: 2137
A17: memo: reported-basis EBITDA = EBIT + D&A | B17: 810.8 | C17: 1347.1 | D17: 1719.5 | E17: =DCF!B5 -> 1989.5199 | F17: =DCF!C5 -> 3014.2546 | G17: =DCF!D5 -> 4183.3801 | H17: =DCF!E5 -> 5242.8778 | I17: =DCF!F5 -> 6109.9934
A19: Historical columns are the company’s own disclosure; note FY23 EBIT includes −14.1 intangible write-off and +12.7 discontinued operations.

Sheet Balance Sheet
A1: Consolidated balance sheet — 3 actual + 5 forecast columns
A2: FY23–FY25 company disclosure; forecast rolls fixed assets on capex−D&A, working capital on days, cash is the balancing item.
A3: EGP mn | B3: FY23A | C3: FY24A | D3: FY25A | E3: FY26E | F3: FY27E | G3: FY28E | H3: FY29E | I3: FY30E
A4: Fixed assets & other non-current | B4: 2720.9 | C4: 5131.5 | D4: 7877.9 | E4: =D4+Assumptions!B43-Assumptions!B42 -> 8797.9 | F4: =E4+Assumptions!C43-Assumptions!C42 -> 9337.9 | G4: =F4+Assumptions!D43-Assumptions!D42 -> 9867.9 | H4: =G4+Assumptions!E43-Assumptions!E42 -> 10407.9 | I4: =H4+Assumptions!F43-Assumptions!F42 -> 10947.9
A5: Inventory | B5: 292 | C5: 320.5 | D5: 281.3 | E5: =-'Income Statement'!E5/365*Assumptions!$B$59 -> 376.10103 | F5: =-'Income Statement'!F5/365*Assumptions!$B$59 -> 476.78648 | G5: =-'Income Statement'!G5/365*Assumptions!$B$59 -> 601.82719 | H5: =-'Income Statement'!H5/365*Assumptions!$B$59 -> 720.81409 | I5: =-'Income Statement'!I5/365*Assumptions!$B$59 -> 825.02847
A6: Accounts receivable | B6: 648.5 | C6: 1046.8 | D6: 1241.5 | E6: ='Income Statement'!E4/365*Assumptions!$B$60 -> 1597.1934 | F6: ='Income Statement'!F4/365*Assumptions!$B$60 -> 2123.5453 | G6: ='Income Statement'!G4/365*Assumptions!$B$60 -> 2724.7656 | H6: ='Income Statement'!H4/365*Assumptions!$B$60 -> 3290.673 | I6: ='Income Statement'!I4/365*Assumptions!$B$60 -> 3766.4343
A7: Other receivables & related parties | B7: 468.8 | C7: 617.7 | D7: 293 | E7: ='Income Statement'!E4*Assumptions!$B$61 -> 323.87534 | F7: ='Income Statement'!F4*Assumptions!$B$61 -> 430.60779 | G7: ='Income Statement'!G4*Assumptions!$B$61 -> 552.5219 | H7: ='Income Statement'!H4*Assumptions!$B$61 -> 667.27536 | I7: ='Income Statement'!I4*Assumptions!$B$61 -> 763.74918
A8: Cash (balancing item in forecast) | B8: 357.9 | C8: 473.2 | D8: 547.5 | E8: =E17-E4-E5-E6-E7 -> 748.46705 | F8: =F17-F4-F5-F6-F7 -> 1368.8591 | G8: =G17-G4-G5-G6-G7 -> 2705.2141 | H8: =H17-H4-H5-H6-H7 -> 4676.1901 | I8: =I17-I4-I5-I6-I7 -> 7118.3541
A9: Total assets | B9: =SUM(B4:B8) -> 4488.1 | C9: =SUM(C4:C8) -> 7589.7 | D9: =SUM(D4:D8) -> 10241.2 | E9: =SUM(E4:E8) -> 11843.537 | F9: =SUM(F4:F8) -> 13737.699 | G9: =SUM(G4:G8) -> 16452.229 | H9: =SUM(H4:H8) -> 19762.853 | I9: =SUM(I4:I8) -> 23421.466
A11: Equity — parent | B11: 2249.8 | C11: 2899.6 | D11: 3622.3 | E11: =D11+'Income Statement'!E13-Assumptions!B47*0.85 -> 4290.4165 | F11: =E11+'Income Statement'!F13-Assumptions!C47*0.85 -> 5547.8319 | G11: =F11+'Income Statement'!G13-Assumptions!D47*0.85 -> 7476.9511 | H11: =G11+'Income Statement'!H13-Assumptions!E47*0.85 -> 9964.9204 | I11: =H11+'Income Statement'!I13-Assumptions!F47*0.85 -> 12881.861
A12: Non-controlling interests | B12: 196.5 | C12: 278.2 | D12: 418 | E12: =D12+'Income Statement'!E14-Assumptions!B47*0.15 -> 547.04601 | F12: =E12+'Income Statement'!F14-Assumptions!C47*0.15 -> 768.94284 | G12: =F12+'Income Statement'!G14-Assumptions!D47*0.15 -> 1109.3756 | H12: =G12+'Income Statement'!H14-Assumptions!E47*0.15 -> 1548.429 | I12: =H12+'Income Statement'!I14-Assumptions!F47*0.15 -> 2063.1833
A13: Borrowings + lease liabilities | B13: 873.5 | C13: 2457.7 | D13: 3702.7 | E13: =Assumptions!B48 -> 3900 | F13: =Assumptions!C48 -> 3400 | G13: =Assumptions!D48 -> 2800 | H13: =Assumptions!E48 -> 2200 | I13: =Assumptions!F48 -> 1600
A14: Creditors & other credit balances | B14: 928.1 | C14: 1523.4 | D14: 1932.4 | E14: ='Income Statement'!E4*Assumptions!$B$62 -> 2405.9311 | F14: ='Income Statement'!F4*Assumptions!$B$62 -> 3198.8008 | G14: ='Income Statement'!G4*Assumptions!$B$62 -> 4104.4484 | H14: ='Income Statement'!H4*Assumptions!$B$62 -> 4956.9027 | I14: ='Income Statement'!I4*Assumptions!$B$62 -> 5673.5653
A15: Current income tax | B15: 75.6 | C15: 199 | D15: 284.2 | E15: ='Income Statement'!E4*Assumptions!$B$63 -> 370.14324 | F15: ='Income Statement'!F4*Assumptions!$B$63 -> 492.12319 | G15: ='Income Statement'!G4*Assumptions!$B$63 -> 631.4536 | H15: ='Income Statement'!H4*Assumptions!$B$63 -> 762.60041 | I15: ='Income Statement'!I4*Assumptions!$B$63 -> 872.85621
A16: Provisions, DTL, LTIP & other | B16: 164.6 | C16: 231.9 | D16: 281.5 | E16: =Assumptions!$B$64 -> 330 | F16: =Assumptions!$B$64 -> 330 | G16: =Assumptions!$B$64 -> 330 | H16: =Assumptions!$B$64 -> 330 | I16: =Assumptions!$B$64 -> 330
A17: Total equity & liabilities | B17: =SUM(B11:B16) -> 4488.1 | C17: =SUM(C11:C16) -> 7589.8 | D17: =SUM(D11:D16) -> 10241.1 | E17: =SUM(E11:E16) -> 11843.537 | F17: =SUM(F11:F16) -> 13737.699 | G17: =SUM(G11:G16) -> 16452.229 | H17: =SUM(H11:H16) -> 19762.853 | I17: =SUM(I11:I16) -> 23421.466
A18: Check: TA − TE&L (historical; forecast balances by construction) | B18: =B9-B17 -> 0 | C18: =C9-C17 -> -0.1 | D18: =D9-D17 -> 0.1
A20: FY25 note: creditors line here excludes the 74.0 current LTIP (grouped in row 16). Balance ties to the disclosed TA of 4,488.0 / 7,589.8 / 10,241.3.

Sheet Cash Flow
A1: Cash flow — disclosed history and forecast funds flow
A2: History = company statement of cash flows; forecast is the model funds-flow identity.
A3: EGP mn | B3: FY23A | C3: FY24A | D3: FY25A | E3: FY26E | F3: FY27E | G3: FY28E | H3: FY29E | I3: FY30E
A4: Operating cash flow | B4: 521.6 | C4: 1423.3 | D4: 1835.5
A5: Investing cash flow | B5: -797.7 | C5: -2665.6 | D5: -2599.3
A6: Financing cash flow | B6: 291.1 | C6: 1357.6 | D6: 840.6
A7: Dividends paid (group, incl NCI) | B7: -64.9 | C7: -113.2 | D7: -146.3
A8: Capex (FA + projects under construction) | B8: -825.2 | C8: -2704 | D8: -2650.5
A10: Forecast funds flow:
A11: Net profit | E11: ='Income Statement'!E12 -> 947.16254 | F11: ='Income Statement'!F12 -> 1679.3122 | G11: ='Income Statement'!G12 -> 2569.552 | H11: ='Income Statement'!H12 -> 3377.0228 | I11: ='Income Statement'!I12 -> 4031.6951
A12: (+) D&A | E12: =Assumptions!B42 -> 480 | F12: =Assumptions!C42 -> 560 | G12: =Assumptions!D42 -> 620 | H12: =Assumptions!E42 -> 680 | I12: =Assumptions!F42 -> 740
A13: (−) Δ working capital (from the BALANCE SHEET, not a separate driver) | E13: =-(('Balance Sheet'!E5-'Balance Sheet'!D5)+('Balance Sheet'!E6-'Balance Sheet'!D6)+('Balance Sheet'!E7-'Balance Sheet'!D7)-('Balance Sheet'!E14-'Balance Sheet'!D14)) -> -7.8387326 | F13: =-(('Balance Sheet'!F5-'Balance Sheet'!E5)+('Balance Sheet'!F6-'Balance Sheet'!E6)+('Balance Sheet'!F7-'Balance Sheet'!E7)-('Balance Sheet'!F14-'Balance Sheet'!E14)) -> 59.099931 | G13: =-(('Balance Sheet'!G5-'Balance Sheet'!F5)+('Balance Sheet'!G6-'Balance Sheet'!F6)+('Balance Sheet'!G7-'Balance Sheet'!F7)-('Balance Sheet'!G14-'Balance Sheet'!F14)) -> 57.472587 | H13: =-(('Balance Sheet'!H5-'Balance Sheet'!G5)+('Balance Sheet'!H6-'Balance Sheet'!G6)+('Balance Sheet'!H7-'Balance Sheet'!G7)-('Balance Sheet'!H14-'Balance Sheet'!G14)) -> 52.806432 | I13: =-(('Balance Sheet'!I5-'Balance Sheet'!H5)+('Balance Sheet'!I6-'Balance Sheet'!H6)+('Balance Sheet'!I7-'Balance Sheet'!H7)-('Balance Sheet'!I14-'Balance Sheet'!H14)) -> 40.213158
A14: (−) Capex | E14: =-Assumptions!B43 -> -1400 | F14: =-Assumptions!C43 -> -1100 | G14: =-Assumptions!D43 -> -1150 | H14: =-Assumptions!E43 -> -1220 | I14: =-Assumptions!F43 -> -1280
A15: (−) Dividends (group) | E15: =-Assumptions!B47 -> -150 | F15: =-Assumptions!C47 -> -200 | G15: =-Assumptions!D47 -> -300 | H15: =-Assumptions!E47 -> -450 | I15: =-Assumptions!F47 -> -600
A16: (±) Δ borrowings & leases | E16: ='Balance Sheet'!E13-'Balance Sheet'!D13 -> 197.3 | F16: ='Balance Sheet'!F13-'Balance Sheet'!E13 -> -500 | G16: ='Balance Sheet'!G13-'Balance Sheet'!F13 -> -600 | H16: ='Balance Sheet'!H13-'Balance Sheet'!G13 -> -600 | I16: ='Balance Sheet'!I13-'Balance Sheet'!H13 -> -600
A17: (±) Δ tax payable, provisions & other liabilities | E17: =('Balance Sheet'!E15-'Balance Sheet'!D15)+('Balance Sheet'!E16-'Balance Sheet'!D16) -> 134.44324 | F17: =('Balance Sheet'!F15-'Balance Sheet'!E15)+('Balance Sheet'!F16-'Balance Sheet'!E16) -> 121.97995 | G17: =('Balance Sheet'!G15-'Balance Sheet'!F15)+('Balance Sheet'!G16-'Balance Sheet'!F16) -> 139.33041 | H17: =('Balance Sheet'!H15-'Balance Sheet'!G15)+('Balance Sheet'!H16-'Balance Sheet'!G16) -> 131.14681 | I17: =('Balance Sheet'!I15-'Balance Sheet'!H15)+('Balance Sheet'!I16-'Balance Sheet'!H16) -> 110.2558
A18: Δ cash | E18: =SUM(E11:E17) -> 201.06705 | F18: =SUM(F11:F17) -> 620.39208 | G18: =SUM(G11:G17) -> 1336.355 | H18: =SUM(H11:H17) -> 1970.976 | I18: =SUM(I11:I17) -> 2442.164
A19: Δ borrowings in FY26E is measured against the 31-Mar-2026 gross borrowings + leases (Assumptions!B10).
A21: CROSS-SHEET TIE-OUT — CF Δcash vs BS cash movement (this check did not exist before)
B22: FY26E | C22: FY27E | D22: FY28E | E22: FY29E | F22: FY30E
A23: Δ cash per the Cash Flow statement | B23: =E18 -> 201.06705 | C23: =F18 -> 620.39208 | D23: =G18 -> 1336.355 | E23: =H18 -> 1970.976 | F23: =I18 -> 2442.164
A24: Δ cash per the Balance Sheet (cash line, y/y) | B24: ='Balance Sheet'!E8-'Balance Sheet'!D8 -> 200.96705 | C24: ='Balance Sheet'!F8-'Balance Sheet'!E8 -> 620.39208 | D24: ='Balance Sheet'!G8-'Balance Sheet'!F8 -> 1336.355 | E24: ='Balance Sheet'!H8-'Balance Sheet'!G8 -> 1970.976 | F24: ='Balance Sheet'!I8-'Balance Sheet'!H8 -> 2442.164
A25: GAP (must be 0) | B25: =B23-B24 -> 0.1 | C25: =C23-C24 -> 0 | D25: =D23-D24 -> 0 | E25: =E23-E24 -> 0 | F25: =F23-F24 -> 0
A26: ASSERT | B26: =IF(ABS(B25)<1,"PASS","FAIL") -> PASS | C26: =IF(ABS(C25)<1,"PASS","FAIL") -> PASS | D26: =IF(ABS(D25)<1,"PASS","FAIL") -> PASS | E26: =IF(ABS(E25)<1,"PASS","FAIL") -> PASS | F26: =IF(ABS(F25)<1,"PASS","FAIL") -> PASS
A27: The Balance Sheet carries cash as the balancing plug; the Cash Flow statement derives it independently. If they disagree, one of them is wrong. Reconciling items (Δdebt base, WC definition, tax liability, provisions) are now aligned to a single definition.

Sheet EV per Bed
A1: EV per operational bed — the transaction lens
A2: Applied to ~1,320 end-2027 operational beds; bridge deducts net debt (incl leases) and NCI, adds associates.
B3: bear | C3: base | D3: bull
A4: EV/bed mark (EGP mn) — RE-ANCHORED on CLHO's own build cost | B4: =Assumptions!B54 -> 14 | C4: =Assumptions!C54 -> 18 | D4: =Assumptions!D54 -> 22
A5: Forward operational beds (end-2027) | B5: =Assumptions!D55 -> 1320
A6: Enterprise value | B6: =B4*$B$5 -> 18480 | C6: =C4*$B$5 -> 23760 | D6: =D4*$B$5 -> 29040
A7: Discount factor to present (WACC_exp, 1.47 yrs — the beds are guided operational in 2027) | B7: 0.71908175
A8: Enterprise value, DISCOUNTED to today | B8: =B6*$B$7 -> 13288.631 | C8: =C6*$B$7 -> 17085.382 | D8: =D6*$B$7 -> 20882.134
A9: (−) Net debt incl leases · (−) NCI at FAIR VALUE · (+) associates | B9: =-Assumptions!$B$7-Assumptions!$B$85+Assumptions!$B$9 -> -3927.4 | C9: =-Assumptions!$B$7-Assumptions!$B$85+Assumptions!$B$9 -> -3927.4 | D9: =-Assumptions!$B$7-Assumptions!$B$85+Assumptions!$B$9 -> -3927.4
A10: Equity value | B10: =B8+B9 -> 9361.2308 | C10: =C8+C9 -> 13157.982 | D10: =D8+D9 -> 16954.734
A11: Per share (EGP) — PRESENT VALUE (this is the blended lens) | B11: =B10/Assumptions!$B$5 -> 6.4586938 | C11: =C10/Assumptions!$B$5 -> 9.0782272 | D11: =D10/Assumptions!$B$5 -> 11.697761
A13: Memo — the other two readings, disclosed, NOT blended:
A14: (a) full-execution ceiling: 1,320 beds, UNDISCOUNTED (the retired construction) | B14: 10.04 | C14: 13.68 | D14: 17.33
A15: (b) today's 880 operational beds, no forward credit | B15: 5.79 | C15: 8.22 | D15: 10.65
A16: (a) and (b) bracket the blended lens. That (b) and the discounted-forward reading nearly agree is a good sign the discounting is not doing anything exotic.
A18: MARKS RE-ANCHORED 13-Jul-2026 (was 20/27.5/35 — imported Gulf transaction marks).
A19: CLHO built Cleopatra El Tagamoa for ~EGP 4,124mn (FY25 capex 1,754 incl. capitalised interest + FY24 projects-in-progress ~2,370) across 240 beds = EGP 17.2mn/bed REPLACEMENT COST.
A20: A buyer pays above replacement only when ROIC > WACC. CLHO earns 17-23% against a ~17.9% terminal WACC — that justifies about 1.0x replacement, not the 1.6x the retired 27.5mn mark implied.
A21: Cross-check: Gulf marks of ~32mn/bed struck at a ~11% WACC, rescaled to Egypt's (WACC−g) of ~12.9%, imply ~20mn/bed. Adopted band 14/18/22 = 0.8x / 1.05x / 1.3x replacement.
A22: Context: spot EV = EGP 27,238mn = 31.0mn per current (880) bed and 20.6mn per forward bed — the market is paying ABOVE replacement cost.

Sheet Relative & Normalized
A1: Relative multiples and normalized earnings power
A2: Both lenses rebuilt 13-Jul-2026. Relative: FY27E parent EPS x band, DISCOUNTED BACK to a present value. Normalized: interest NORMALISED to the terminal Kd, not deleted — a P/E may only be applied to a post-interest number.
A4: FY27E EPS (parent) | B4: ='Income Statement'!F15 -> 0.98483191
A5: Discount factor to present (Ke_explicit, 1.47 yrs) | B5: 0.70595547
A6: Relative lens | B6: bear | C6: base | D6: bull
A7: Justified P/E x | B7: =Assumptions!B52 -> 15 | C7: =Assumptions!C52 -> 19 | D7: =Assumptions!D52 -> 23
A8: Value at end-FY2027 (the FORWARD reading) | B8: =B7*$B$4 -> 14.772479 | C8: =C7*$B$4 -> 18.711806 | D8: =D7*$B$4 -> 22.651134
A9: Fair value per share — PRESENT VALUE | B9: =B8*$B$5 -> 10.428712 | C9: =C8*$B$5 -> 13.209702 | D9: =D8*$B$5 -> 15.990692
A10: A multiple applied to FY27E earnings returns a value at end-2027, not today. Blending it with a DCF without discounting prices one date and reads it as another.
A12: NORMALIZED LENS — REBUILT. The prior version added net interest BACK (producing NOPAT, an UNLEVERED figure) and then applied a P/E to it: it capitalised debt-free earnings and never deducted the debt.
A13: Normalised interest = net debt x terminal Kd | B13: =Assumptions!B7*Assumptions!B28 -> 474.615
A14: FY26E normalised PARENT net income = (EBIT − normalised interest) x (1 − tax) x parent share | B14: =(DCF!B7-B13)*(1-Assumptions!B20)*Assumptions!B46 -> 673.7231
A15: Normalized lens | B15: bear | C15: base | D15: bull
A16: Through-cycle P/E x | B16: =Assumptions!B53 -> 15 | C16: =Assumptions!C53 -> 18 | D16: =Assumptions!D53 -> 22
A17: Fair value per share | B17: =B16*$B$14/Assumptions!$B$5 -> 6.9724345 | C17: =C16*$B$14/Assumptions!$B$5 -> 8.3669214 | D17: =D16*$B$14/Assumptions!$B$5 -> 10.226237
A19: The lens exists to strip the temporary RATE spike, not the DEBT. So the interest charge is re-priced at the long-run Kd, not removed.

Sheet Summary
A1: Summary — every lens at a glance
A2: Weighted central = SUMPRODUCT of lens bases and the declared weights (Assumptions row 56).
A3: Lens | B3: bear | C3: base | D3: bull | E3: weight | F3: vs spot (base)
A4: DCF — rate path (primary) | B4: =DCF!B34 -> 3.8461017 | C4: =DCF!B27 -> 7.1690357 | D4: =DCF!B40 -> 8.1224577 | E4: =Assumptions!B56 -> 0.4 | F4: =C4/Assumptions!B4-1 -> -0.56045152
A5: Relative multiples | B5: ='Relative & Normalized'!B9 -> 10.428712 | C5: ='Relative & Normalized'!C9 -> 13.209702 | D5: ='Relative & Normalized'!D9 -> 15.990692 | E5: =Assumptions!C56 -> 0.25 | F5: =C5/Assumptions!B4-1 -> -0.19008572
A6: Normalized earnings | B6: ='Relative & Normalized'!B17 -> 6.9724345 | C6: ='Relative & Normalized'!C17 -> 8.3669214 | D6: ='Relative & Normalized'!D17 -> 10.226237 | E6: =Assumptions!D56 -> 0.2 | F6: =C6/Assumptions!B4-1 -> -0.48700666
A7: EV per bed | B7: ='EV per Bed'!B11 -> 6.4586938 | C7: ='EV per Bed'!C11 -> 9.0782272 | D7: ='EV per Bed'!D11 -> 11.697761 | E7: =Assumptions!E56 -> 0.15 | F7: =C7/Assumptions!B4-1 -> -0.44339502
A8: Weighted central | B8: =SUMPRODUCT(B4:B7,$E$4:$E$7) -> 6.5089096 | C8: =SUMPRODUCT(C4:C7,$E$4:$E$7) -> 9.2051581 | D8: =SUMPRODUCT(D4:D7,$E$4:$E$7) -> 11.046568 | F8: =C8/Assumptions!B4-1 -> -0.43561262
A10: Engine cross-check: bear 6.51 / base 9.21 / bull 11.05 vs spot 16.31.
A12: Monte Carlo (T+60, 50k paths, live EG fit): p5 12.12 · p50 17.02 · p95 23.83 · P(>spot) 60%

Sheet Fundamental Valuation
A1: Fundamental valuation — the bridge in one place
A2: EV → equity → per share, per scenario; identical algebra to the compute layer’s ASSERT block.
A3: EGP mn / EGP per share | B3: Scen A flat rates | C3: Scen B rate path (base) | D3: Scen C fast normalization
A4: Enterprise value | B4: =DCF!B33 -> 9501.9398 | C4: =DCF!B21 -> 14318.2 | D4: =DCF!B39 -> 15700.09
A5: (−) Net debt incl IFRS-16 leases | B5: =-Assumptions!$B$7 -> -3164.1 | C5: =-Assumptions!$B$7 -> -3164.1 | D5: =-Assumptions!$B$7 -> -3164.1
A6: (−) NCI at FAIR VALUE (CSH mini-SOTP; book was 452.8) · (+) associates | B6: =-Assumptions!$B$85+Assumptions!$B$9 -> -763.3 | C6: =-Assumptions!$B$85+Assumptions!$B$9 -> -763.3 | D6: =-Assumptions!$B$85+Assumptions!$B$9 -> -763.3
A7: Equity value | B7: =B4+B5+B6 -> 5574.5398 | C7: =C4+C5+C6 -> 10390.8 | D7: =D4+D5+D6 -> 11772.69
A8: Per share (EGP) | B8: =B7/Assumptions!$B$5 -> 3.8461017 | C8: =C7/Assumptions!$B$5 -> 7.1690357 | D8: =D7/Assumptions!$B$5 -> 8.1224577
A9: TV as % of EV (disclosed) | B9: =DCF!B35 -> 0.53691606 | C9: =DCF!B22 -> 0.66188619 | D9: =DCF!B41 -> 0.68224404
A11: Dual framing (net debt): EGP 2994mn excluding leases · EGP 3164mn including IFRS-16 leases (used here).

Sheet Summary Financials
A1: Summary financials FY22–FY30E
A2: FY22 from the company’s FY25-release chart pack; FY23–25 statements; FY26E+ model.
A3: EGP mn | B3: FY22A | C3: FY23A | D3: FY24A | E3: FY25A | F3: FY26E | G3: FY27E | H3: FY28E | I3: FY29E | J3: FY30E
A4: Revenue | B4: 2646 | C4: 3595.3 | D4: 5420.4 | E4: 7227.3 | F4: 9253.581 | G4: 12303.08 | H4: 15786.34 | I4: 19065.01 | J4: 21821.405
A5: Gross profit | B5: 873 | C5: 1208.6 | D5: 2013.3 | E5: 2858.5 | F5: 3285.0213 | G5: 4736.6857 | H5: 6235.6043 | I5: 7626.0041 | J5: 8728.5621
A6: Adjusted EBITDA (disclosed) | B6: 709 | C6: 954 | D6: 1529 | E6: 2137
A7: EBITDA (reported basis, model) | C7: 810.8 | D7: 1347.1 | E7: 1719.5 | F7: 1989.5199 | G7: 3014.2546 | H7: 4183.3801 | I7: 5242.8778 | J7: 6109.9934
A8: EBIT | C8: 649.4 | D8: 1162.8 | E8: 1499.8 | F8: 1509.5199 | G8: 2454.2546 | H8: 3563.3801 | I8: 4562.8778 | J8: 5369.9934
A9: Net profit | B9: 357 | C9: 469.3 | D9: 817 | E9: 967.9 | F9: 947.16254 | G9: 1679.3122 | H9: 2569.552 | I9: 3377.0228 | J9: 4031.6951
A10: — parent | C10: 418.2 | D10: 723.3 | E10: 823.9 | F10: 795.61653 | G10: 1427.4154 | H10: 2184.1192 | I10: 2870.4693 | J10: 3426.9408
A11: EPS (EGP) | C11: 0.29 | D11: 0.5 | E11: 0.67 | F11: 0.5489282 | G11: 0.98483191 | H11: 1.5069127 | I11: 1.9804535 | J11: 2.3643858
A12: Capex | C12: 825.2 | D12: 2704 | E12: 2650.5 | F12: 1400 | G12: 1100 | H12: 1150 | I12: 1220 | J12: 1280
A13: FCFF (model) | F13: 133.27794 | G13: 1263.6226 | H13: 2172.1808 | I13: 2963.4436 | J13: 3594.181
A15: Growth y/y (revenue) | C15: =C4/B4-1 -> 0.35876795 | D15: =D4/C4-1 -> 0.50763497 | E15: =E4/D4-1 -> 0.33335178 | F15: =F4/E4-1 -> 0.28036487 | G15: =G4/F4-1 -> 0.32954797 | H15: =H4/G4-1 -> 0.283121 | I15: =I4/H4-1 -> 0.20769033 | J15: =J4/I4-1 -> 0.14457873

Sheet Monte Carlo
A1: Monte Carlo — engine outputs (mc_v3, 50,000 paths, seed 42)
A2: Carry-anchored YZ-HAR-t under the live EG fit: ν=4, width 0.909, carry-only; rf 19.50%, q 0.24%. Values are engine outputs, not spreadsheet formulas.
A3: Percentile | B3: p1 | C3: p5 | D3: p10 | E3: p25 | F3: p50 | G3: p75 | H3: p90 | I3: p95
A4: T+20 (EGP) | B4: 11.754523 | C4: 13.591562 | D4: 14.369404 | E4: 15.460593 | F4: 16.542715 | G4: 17.713583 | H4: 19.075577 | I4: 20.166373
A5: T+60 (EGP) | B5: 9.2562941 | C5: 12.119333 | D5: 13.346135 | E5: 15.128578 | F5: 17.017866 | G5: 19.150608 | H5: 21.723078 | I5: 23.832127
A7: Probability read (T+60) | B7: value | D7: Level-touch (within window) | E7: P T+20 | F7: P T+60
A8: P(price > spot) | B8: 0.59962 | D8: touch 18 | E8: 0.32718 | F8: 0.60402
A9: P(+10% or more) | B9: 0.37802 | D9: touch 20 | E9: 0.08562 | F9: 0.3013
A10: P(−10% or worse) | B10: 0.20266 | D10: touch 22 | E10: 0.02904 | F10: 0.1504
A11: P(+20% or more) | B11: 0.21542 | D11: touch 15 | E11: 0.30844 | F11: 0.49994
A12: P(−20% or worse) | B12: 0.08402 | D12: touch 13 | E12: 0.04916 | F12: 0.16336
A13: P(within ±10%) | B13: 0.41932 | D13: touch 11 | E13: 0.00894 | F13: 0.04876
A16: Drift (60d) 0.0419 log · σ60 0.2266 · anchored annual vol 51.1%.
A17: Step 0: name verdict PARITY (robust across bootstrap blocks 2/3/4); EG panel PASS +2.70% CI[+1.8,+3.8]. cov90 = 1.00 → the cone over-covers this low-beta name (known market-level width limitation).

Sheet Sensitivity
A1: Sensitivity — the honest ranges around the sourced base
A2: Grid 1: normalized-stage WACC × terminal g. Grid 2: FY28-30E EBITDA-margin delivery × terminal g. Beta grid from the WACC builder.
A3: normalized WACC \ g | B3: 3% | C3: 4% | D3: 5% | E3: 6% | F3: 7%
A4: 15.9% | B4: 8.6 | C4: 8.8 | D4: 9 | E4: 9.2 | F4: 9.4
A5: 16.9% | B5: 7.8 | C5: 7.9 | D5: 8 | E5: 8.2 | F5: 8.3
A6: 17.9% | B6: 7.1 | C6: 7.2 | D6: 7.2 | E6: 7.3 | F6: 7.4
A7: 18.9% | B7: 6.5 | C7: 6.5 | D7: 6.6 | E7: 6.6 | F7: 6.6
A8: 19.9% | B8: 6 | C8: 6 | D8: 6 | E8: 6 | F8: 6
A11: EBITDA-margin shift \ g | B11: 3% | C11: 4% | D11: 5% | E11: 6% | F11: 7%
A12: -4pp | B12: 5.5 | C12: 6 | D12: 6.5 | E12: 7.1 | F12: 7.8
A13: -2pp | B13: 6.4 | C13: 6.9 | D13: 7.5 | E13: 8.2 | F13: 9
A14: +0pp | B14: 7.3 | C14: 7.9 | D14: 8.5 | E14: 9.3 | F14: 10.2
A15: +2pp | B15: 8.2 | C15: 8.8 | D15: 9.6 | E15: 10.4 | F15: 11.3
A16: +4pp | B16: 9.2 | C16: 9.8 | D16: 10.6 | E16: 11.4 | F16: 12.5
A19: Beta sensitivity (CDS-based ERP):
A20: Beta sensitivity (cds-based ERP = 9.41%):
A22: beta | Ke | WACC
A23: ------------------------------
A24: 0.45 | 26.75% | 25.17% <- assumed
A25: 0.60 | 28.20% | 26.41%
A26: 0.80 | 30.08% | 28.02%
A27: 1.00 | 31.96% | 29.64%
A28: 1.15 | 33.37% | 30.85%
A29: 1.30 | 34.78% | 32.06%
A31: Historical reconciliation (standing procedure) | B31: Capex | C31: Capex/EBITDA | D31: Character | E31: NOPAT | F31: Actual g | G31: ROIC | H31: RR | I31: Implied g
A32: 2021 | B32: 282 | C32: 0.37 | D32: stable (aggregator) | E32: 394.9
A33: 2022 | B33: 331.7 | C33: 0.47 | D33: stable (aggregator) | E33: 344.2 | F33: -0.128 | G33: 0.17 | H33: 0.193 | I33: 0.03281
A34: 2023 | B34: 825.2 | C34: 0.99 | D34: burst begins | E34: 503.3 | F34: 0.462 | G34: 0.211 | H34: 1.319 | I34: 0.278309
A35: 2024 | B35: 2704 | C35: 1.89 | D35: burst | E35: 901.2 | F35: 0.791 | G35: 0.23 | H35: 2.796 | I35: 0.64308
A36: 2025 | B36: 2650.5 | C36: 1.5 | D36: burst | E36: 1162.3 | F36: 0.29 | G36: 0.179 | H36: 2.091 | I36: 0.374289
A38: Check (a): historical NOPAT CAGR FY21-25 = 31.0%
A39: Check (b): ROIC×RR implied g, stable years only (2022) = 3.3% — burst years (2023-25) excluded, debt-funded, contaminate the identity
A40: New terminal g = 5% (standing procedure, was 11%). Model's own FY30E reinvestment rate (13.6%) implies terminal ROIC 36.7% — consistent with realized book ROIC 17-23% (2022-25), not the 67% implied at the retired 11% assumption.

Sheet Per-Share & Ratios
A1: Per-share values and ratios
A2: Formulas off the statement sheets; multiples at spot and at the weighted central.
B3: FY24A | C3: FY25A | D3: FY26E | E3: FY27E | F3: FY28E
A4: EPS (EGP) | B4: ='Income Statement'!C15 -> 0.49903408 | C4: ='Income Statement'!D15 -> 0.56844211 | D4: ='Income Statement'!E15 -> 0.5489282 | E4: ='Income Statement'!F15 -> 0.98483191 | F4: ='Income Statement'!G15 -> 1.5069127
A5: Revenue / share | B5: ='Income Statement'!C4/Assumptions!$B$5 -> 3.7397544 | C5: ='Income Statement'!D4/Assumptions!$B$5 -> 4.9864082 | D5: ='Income Statement'!E4/Assumptions!$B$5 -> 6.3844218 | E5: ='Income Statement'!F4/Assumptions!$B$5 -> 8.4883951 | F5: ='Income Statement'!G4/Assumptions!$B$5 -> 10.891638
A6: BVPS (parent) | B6: ='Balance Sheet'!C11/Assumptions!$B$5 -> 2.000552 | C6: ='Balance Sheet'!D11/Assumptions!$B$5 -> 2.4991721 | D6: ='Balance Sheet'!E11/Assumptions!$B$5 -> 2.9601328 | E6: ='Balance Sheet'!F11/Assumptions!$B$5 -> 3.8276748 | F6: ='Balance Sheet'!G11/Assumptions!$B$5 -> 5.1586526
A7: Net debt (borrowings+leases − cash) | B7: ='Balance Sheet'!C13-'Balance Sheet'!C8 -> 1984.5 | C7: ='Balance Sheet'!D13-'Balance Sheet'!D8 -> 3155.2 | D7: ='Balance Sheet'!E13-'Balance Sheet'!E8 -> 3151.533 | E7: ='Balance Sheet'!F13-'Balance Sheet'!F8 -> 2031.1409 | F7: ='Balance Sheet'!G13-'Balance Sheet'!G8 -> 94.785878
A8: Net debt / EBITDA (reported) | B8: =B7/'Income Statement'!C17 -> 1.4731646 | C8: =C7/'Income Statement'!D17 -> 1.834952 | D8: =D7/'Income Statement'!E17 -> 1.584067 | E8: =E7/'Income Statement'!F17 -> 0.67384517 | F8: =F7/'Income Statement'!G17 -> 0.022657725
A10: Multiples | B10: at spot | C10: at central base
A11: P/E FY26E | B11: =Assumptions!B4/'Income Statement'!E15 -> 29.712447 | C11: =Summary!C8/'Income Statement'!E15 -> 16.76933
A12: P/E FY27E | B12: =Assumptions!B4/'Income Statement'!F15 -> 16.561202 | C12: =Summary!C8/'Income Statement'!F15 -> 9.3469333
A13: EV/EBITDA FY26E (reported) | B13: =(Assumptions!B6+Assumptions!B7+Assumptions!B8-Assumptions!B9)/DCF!B5 -> 13.690747 | C13: =(Summary!C8*Assumptions!B5+Assumptions!B7+Assumptions!B8-Assumptions!B9)/DCF!B5 -> 8.5147457
A14: EV/EBITDA FY27E (reported) | B14: =(Assumptions!B6+Assumptions!B7+Assumptions!B8-Assumptions!B9)/DCF!C5 -> 9.0364014 | C14: =(Summary!C8*Assumptions!B5+Assumptions!B7+Assumptions!B8-Assumptions!B9)/DCF!C5 -> 5.6200483
A15: EV / current bed (EGP mn) | B15: =(Assumptions!B6+Assumptions!B7+Assumptions!B8-Assumptions!B9)/Assumptions!B55 -> 30.952289
A16: EV / forward bed (EGP mn) | B16: =(Assumptions!B6+Assumptions!B7+Assumptions!B8-Assumptions!B9)/Assumptions!D55 -> 20.634859
A18: EV/EBITDA on FY25 adjusted EBITDA (disclosed): 12.7x at spot.

Sheet Peer & Sector
A1: Peer & sector context — cross-market, discount-rate-aware
A2: Regional multiples carry a 13-15pp LOWER cost of equity than Egypt — shown for context, never naively imported (EFG lesson).
A3: Operator | B3: Market | C3: P/E (approx) | D3: EV/EBITDA (approx) | E3: Note | F3: Source / date
A4: Dr Sulaiman Al Habib | B4: KSA | C4: 31x | D4: 24.3x | E4: regional premium franchise | F4: multiples.vc, Jul-2026
A5: Mouwasat | B5: KSA | C5: 23–26x | D5: 17–19x | E5: Eastern Province leader | F5: comp table / MarketScreener
A6: Dallah Healthcare | B6: KSA | C6: 29–35x | D6: 20–23x | E6: Riyadh, expansion phase | F6: MarketScreener, 2025
A7: Burjeel Holdings | B7: UAE | C7: 17–21x | D7: 11–13x | E7: UAE/Oman network | F7: regional comp table
A8: KSA healthcare industry | B8: KSA | C8: 30.0x (3y avg 44.8x) | D8: — | E8: de-rated but still rich | F8: simplywall.st, Jul-2026
A9: Egyptian healthcare industry | B9: EGX | C9: ~46.9x avg (thin sample) | D9: — | E9: includes small caps | F9: investing.com, Jul-2026
A10: CLHO at spot | B10: EGX | C10: 24.3x FY25A / 29.7x FY26E / 16.6x FY27E | D10: 12.7x FY25 adj / 9.0x FY27E rep | E10: EV/bed 31.0mn current | F10: this model
A12: Sector risks: UHI tariff/contracting terms once Greater Cairo phases in; medical staff inflation & retention; EGP step-devaluation (imported consumables ~32% of COGS); regulatory price approvals; competition (Saudi German, Andalusia, Alameda network) and new private capacity.
A13: Shareholders (Mar-26): Care Healthcare 32% · MCI Healthcare Partners 31% · free float 37%.
