Workbook

Sheet READ FIRST
A1: READ FIRST — DISCLOSURE & DISCLAIMER
A3: NATURE OF THIS WORKBOOK
A4: This workbook is an educational valuation exercise and an expression of personal analytical opinion, published free of charge. It shows how one analyst applies fundamental, technical and probabilistic methods to a listed company. It is NOT investment advice.
A6: NO ADVICE, NO RECOMMENDATION, NO RATING
A7: Nothing here constitutes investment, financial, legal or tax advice, nor an offer or solicitation to buy, sell or hold any security. There is no price target and no rating — only fair-value ranges and probability distributions.
A9: NO LICENSED ACTIVITY
A10: The preparer is not licensed or registered with any securities regulator in any jurisdiction, holds no brokerage or advisory authorisation, manages no money and accepts no clients or fees.
A12: ESTIMATES AND UNCERTAINTY
A13: All values are model outputs presented as ranges because no single number should be relied on. Reported financials are CIB's own disclosure; the cost of equity, the sustainable ROE, the terminal growth, the multiples, the DDM and the Monte-Carlo factor probabilities are the preparer's judgments and are flagged throughout.
A15: NO LIABILITY / READER'S RESPONSIBILITY
A16: Do your own research and consult a licensed professional before any decision. The preparer accepts no liability for any loss arising from use of this workbook.
A18: HOLDINGS DISCLOSURE
A19: The preparer may hold, and may in the future take or dispose of, a position in the security discussed in this report.

Sheet Summary
A1: COMMERCIAL INTERNATIONAL BANK (EGX: COMI) — VALUATION SUMMARY
A2: Bank justified-P/B / residual income (primary); DDM, relative & normalized cross-checks. EGP.
A4: HEADLINE — VALUE PER SHARE (EGP)
A5: Weighted central fundamental | B5: ='Fundamental Valuation'!B11 -> 123.31702 | C5: five-lens triangulation
A6: RI — base (justified P/B) | B6: =Assumptions!B18 -> 125.28492
A7: RI — bull | B7: =Assumptions!C18 -> 169.6981
A8: RI — bear | B8: =Assumptions!D18 -> 53.454901
A9: DDM (2-stage) | B9: =DDM!B20 -> 104.32726
A10: Relative blended | B10: =Assumptions!B28 -> 120.65068
A11: Normalized earnings power | B11: =Assumptions!B29 -> 114.74985
A12: Market price (29-Jun-26) | B12: =Assumptions!B5 -> 129.25
A13: Spot premium / (discount) to central | B13: =B12/B5-1 -> 0.048111639 | C13: positive = market above our central
A15: WHAT THE NUMBER RESTS ON
A16: BVPS Dec-2025e (EGP) | B16: =Assumptions!B8 -> 74.242918
A17: P/B at spot | B17: =B12/B16 -> 1.7409068
A18: Sustainable ROE (base) | B18: =Assumptions!B14 -> 0.295
A19: Cost of equity (base) | B19: =Assumptions!B15 -> 0.24
A20: ROE − CoE spread (the swing) | B20: =Assumptions!B14-Assumptions!B15 -> 0.055 | C20: knife-edge: ±1pp ≈ ±15-25% value
A21: MC T+60 median (EGP) | B21: ='Monte Carlo'!B30 -> 109.91 | C21: near-term price, not value
A23: Excess-return DCF (explicit, ROE fade) | B23: ='Excess Return DCF'!B20 -> 90.863565 | C23: the primary lens if the forecast ROE fade plays out without capital return — brackets RI base below

Sheet Fundamental Valuation
A1: FUNDAMENTAL VALUATION — FIVE METHODS
A2: Bank justified-P/B / residual income is the primary lens; weights below.
A4: THE METHODS — value per share (EGP)
A5: Method | B5: EGP/sh | C5: vs spot | D5: Weight | E5: Note
A6: RI — base (justified P/B) | B6: =Assumptions!B18 -> 125.28492 | C6: =B6/Assumptions!$B$5-1 -> -0.030677575 | D6: =Assumptions!B46 -> 0.3 | E6: primary lens
A7: RI — bull (ROE↑ / CoE↓) | B7: =Assumptions!C18 -> 169.6981 | C7: =B7/Assumptions!$B$5-1 -> 0.31294466 | D7: =Assumptions!B47 -> 0.1 | E7: ceiling if spread holds/widens
A8: DDM (2-stage) | B8: =DDM!B20 -> 104.32726 | C8: =B8/Assumptions!$B$5-1 -> -0.19282586 | D8: =Assumptions!B48 -> 0.15 | E8: conservative cash-flow cross-check
A9: Relative multiples (blended) | B9: =Assumptions!B28 -> 120.65068 | C9: =B9/Assumptions!$B$5-1 -> -0.066532452 | D9: =Assumptions!B49 -> 0.25 | E9: P/B & P/E vs peers
A10: Normalized earnings power | B10: =Assumptions!B29 -> 114.74985 | C10: =B10/Assumptions!$B$5-1 -> -0.11218682 | D10: =Assumptions!B50 -> 0.2 | E10: through-cycle, strip ECL release
A11: WEIGHTED CENTRAL FUNDAMENTAL VALUE | B11: =SUMPRODUCT(B6:B10,D6:D10) -> 123.31702 | C11: =B11/Assumptions!$B$5-1 -> -0.045903162 | D11: =SUM(D6:D10) -> 1
A12: Memo: spot price (29-Jun-26) | B12: =Assumptions!B5 -> 129.25
A13: Spot premium to central | B13: =B12/B11-1 -> 0.048111639 | E13: market prices CIB a touch above our central

Sheet Assumptions
A1: COMMERCIAL INTERNATIONAL BANK (EGX: COMI) — ASSUMPTIONS
A2: All blue cells are inputs. EGP bn unless per-share (EGP). Change an input and the whole model reprices.
A4: GLOBAL & CORPORATE
A5: Spot price (EGP, 29-Jun-26 close) | B5: 129.25 | E5: attached OHLC
A6: Shares outstanding (bn) | B6: 3.071 | E6: issued cap 30.71bn / par EGP10 (S1)
A7: Total equity attributable, Dec-2025e (EGP bn) | B7: 228 | E7: Sep-25 207.8 + Q4 (S1)
A8: BVPS Dec-2025e (EGP) | B8: =B7/B6 -> 74.242918
A9: Effective tax rate (forecast) | B9: 0.225 | E9: CIB effective ~22% (S1)
A10: Staff & board profit share | B10: 0.08 | E10: deducted in attributable EPS
A12: JUSTIFIED P/B — RESIDUAL INCOME (swing inputs)
B13: Base | C13: Bull | D13: Bear
A14: Sustainable ROE | B14: 0.295 | C14: 0.32 | D14: 0.24 | E14: reported 48.3 / ex-ECL 41.5 / Q1-26 31.9
A15: Cost of equity (nominal EGP) | B15: 0.24 | C15: 0.23 | D15: 0.275 | E15: EGP RF ~18-20 + ERP ~5-6
A16: Terminal growth g (nominal) | B16: 0.16 | C16: 0.16 | D16: 0.15 | E16: inflation ~11 + real ~5
A17: Justified P/B = (ROE-g)/(CoE-g) | B17: =(B14-B16)/(B15-B16) -> 1.6875 | C17: =(C14-C16)/(C15-C16) -> 2.2857143 | D17: =(D14-D16)/(D15-D16) -> 0.72
A18: RI value / share (EGP) | B18: =B17*$B$8 -> 125.28492 | C18: =C17*$B$8 -> 169.6981 | D18: =D17*$B$8 -> 53.454901
A20: RELATIVE & NORMALIZED
A21: Relative justified P/B blend (x) | B21: 1.55 | E21: vs EGX + EM bank peers
A22: Normalized through-cycle ROE | B22: 0.28 | E22: strip ECL release
A23: Normalized attributable EPS (EGP) | B23: =B22*B8*(1-B10) -> 19.124976
A24: Peer P/E — relative (x) | B24: 6.6 | E24: EM bank median premium
A25: Through-cycle fair P/E — normalized (x) | B25: 6 | E25: conservative
A26: Relative P/B value / share | B26: =B21*B8 -> 115.07652
A27: Relative P/E value / share | B27: =B23*B24 -> 126.22484
A28: Relative blended value / share | B28: =AVERAGE(B26,B27) -> 120.65068
A29: Normalized earnings-power value / share | B29: =B23*B25 -> 114.74985
A31: DDM — 2-STAGE (distributable earnings)
A32: 2026e net income (from Income Statement) | B32: ='Income Statement'!E14 -> 83.7
A33: NI growth 2027e (from IS, memo) | B33: ='Income Statement'!F14/'Income Statement'!E14-1 -> 0.078703704
A34: NI growth 2028e (from IS, memo) | B34: ='Income Statement'!G14/'Income Statement'!F14-1 -> 0.09527897
A35: NI growth 2029e (from IS, memo) | B35: ='Income Statement'!H14/'Income Statement'!G14-1 -> 0.095611285
A36: NI growth 2030e (from IS, memo) | B36: ='Income Statement'!I14/'Income Statement'!H14-1 -> 0.095135908
A37: Payout 2026e | B37: 0.27 | E37: FY25 25% rising as growth slows
A38: Payout 2027e | B38: 0.3
A39: Payout 2028e | B39: 0.33
A40: Payout 2029e | B40: 0.36
A41: Payout 2030e | B41: 0.4
A42: DDM discount rate (= base CoE) | B42: =B15 -> 0.24
A43: DDM terminal growth (= base g) | B43: =B16 -> 0.16
A45: FIVE-LENS WEIGHTS
...

Sheet Residual Income
A1: RESIDUAL INCOME / JUSTIFIED P/B — primary lens
A2: A bank is worth book plus the PV of returns earned above its cost of equity. Steady-state: P/B = (ROE−g)/(CoE−g).
B4: Base | C4: Bull | D4: Bear
A5: Sustainable ROE | B5: =Assumptions!B14 -> 0.295 | C5: =Assumptions!C14 -> 0.32 | D5: =Assumptions!D14 -> 0.24
A6: Cost of equity (CoE) | B6: =Assumptions!B15 -> 0.24 | C6: =Assumptions!C15 -> 0.23 | D6: =Assumptions!D15 -> 0.275
A7: Terminal growth g | B7: =Assumptions!B16 -> 0.16 | C7: =Assumptions!C16 -> 0.16 | D7: =Assumptions!D16 -> 0.15
A8: ROE − CoE spread | B8: =B5-B6 -> 0.055 | C8: =C5-C6 -> 0.09 | D8: =D5-D6 -> -0.035
A9: Justified P/B (x) | B9: =Assumptions!B17 -> 1.6875 | C9: =Assumptions!C17 -> 2.2857143 | D9: =Assumptions!D17 -> 0.72
A10: BVPS Dec-2025e (EGP) | B10: =Assumptions!B8 -> 74.242918 | C10: =Assumptions!B8 -> 74.242918 | D10: =Assumptions!B8 -> 74.242918
A11: FAIR VALUE / SHARE (EGP) | B11: =B9*B10 -> 125.28492 | C11: =C9*C10 -> 169.6981 | D11: =D9*D10 -> 53.454901
A12: vs spot | B12: =B11/Assumptions!$B$5-1 -> -0.030677575 | C12: =C11/Assumptions!$B$5-1 -> 0.31294466 | D12: =D11/Assumptions!$B$5-1 -> -0.58642243
A14: Reading the spread.
A15: At base (ROE 29.5%, CoE 24%, g 16%) CIB is worth ~1.69x book ≈ spot. The nominal arithmetic is knife-edge: a 1pp move in either ROE or CoE swings fair value 15-25%. The bear (ROE 24% barely over CoE 27.5%) collapses to <1x book; the bull (ROE 32%, CoE 23%) reaches ~2.3x. That spread, not loan growth, is the whole valuation.

Sheet Excess Return DCF
A1: EXCESS-RETURN (RESIDUAL INCOME) DCF — explicit 5-year
A2: The bank's discounted-cash-flow valuation: discount the return earned ABOVE the cost of equity on the actual projected book each year, plus a terminal. Distinct from the DDM (which discounts only distributed cash) and from the steady-state justified P/B (which assumes the spread holds from the start).
B4: 2026e | C4: 2027e | D4: 2028e | E4: 2029e | F4: 2030e
A5: Attributable EPS (EGP) | B5: ='Income Statement'!E16 -> 25.074569 | C5: ='Income Statement'!F16 -> 27.04803 | D5: ='Income Statement'!G16 -> 29.625138 | E5: ='Income Statement'!H16 -> 32.457636 | F5: ='Income Statement'!I16 -> 35.545523
A6: Beginning BVPS (EGP) | B6: =Assumptions!$B$8 -> 74.242918 | C6: ='Balance Sheet'!E19 -> 94.139043 | D6: ='Balance Sheet'!F19 -> 114.71907 | E6: ='Balance Sheet'!G19 -> 136.29389 | F6: ='Balance Sheet'!H19 -> 158.87312
A7: Cost of equity (CoE) | B7: =Assumptions!$B$15 -> 0.24 | C7: =Assumptions!$B$15 -> 0.24 | D7: =Assumptions!$B$15 -> 0.24 | E7: =Assumptions!$B$15 -> 0.24 | F7: =Assumptions!$B$15 -> 0.24
A8: Equity charge = CoE × begin BVPS | B8: =B7*B6 -> 17.8183 | C8: =C7*C6 -> 22.59337 | D8: =D7*D6 -> 27.532576 | E8: =E7*E6 -> 32.710535 | F8: =F7*F6 -> 38.129549
A9: Residual income / share (EGP) | B9: =B5-B8 -> 7.2562683 | C9: =C5-C8 -> 4.4546597 | D9: =D5-D8 -> 2.0925627 | E9: =E5-E8 -> -0.25289873 | F9: =F5-F8 -> -2.5840261
A10: Discount factor @ CoE | B10: =1/(1+Assumptions!$B$63)^1 -> 0.80645161 | C10: =1/(1+Assumptions!$B$63)^2 -> 0.6503642 | D10: =1/(1+Assumptions!$B$63)^3 -> 0.52448726 | E10: =1/(1+Assumptions!$B$63)^4 -> 0.4229736 | F10: =1/(1+Assumptions!$B$63)^5 -> 0.34110774
A11: PV of residual income (EGP) | B11: =B9*B10 -> 5.8518293 | C11: =C9*C10 -> 2.8971512 | D11: =D9*D10 -> 1.0975225 | E11: =E9*E10 -> -0.10696949 | F11: =F9*F10 -> -0.88143129
A13: VALUE BRIDGE (EGP / share)
A14: Book value Dec-2025e | B14: =Assumptions!$B$8 -> 74.242918
A15: PV of explicit residual income (2026e-2030e) | B15: =SUM(B11:F11) -> 8.8581022
A16: Terminal residual income 2031e | B16: =(Assumptions!$B$62-Assumptions!$B$15)*'Balance Sheet'!I19 -> 1.8205498
A17: Terminal value @ 2030 (Gordon) | B17: =B16/(Assumptions!$B$63-Assumptions!$B$64) -> 22.756873
A18: PV of terminal value | B18: =B17*F10 -> 7.7625454
A20: EXCESS-RETURN DCF VALUE / SHARE (EGP) | B20: =B14+B15+B18 -> 90.863565
A21: vs spot | B21: =B20/Assumptions!$B$5-1 -> -0.29699369
A23: Memo — justified-P/B steady state (spread holds) | B23: =Assumptions!B18 -> 125.28492
A24: Gap: steady-state − explicit DCF (the capital-discipline question) | B24: =B23-B20 -> 34.421358
A26: Reading. The explicit model uses the ACTUAL projected book and EPS, so as retained earnings compound the equity base faster than earnings grow, residual income fades — turning negative by 2029e as the return on beginning equity slips below the cost of equity. That is the over-retention drag made concrete. The steady-state justified P/B (spread holds) and this explicit fade bracket the value: the truth depends on whether CIB returns its excess capital to keep the spread alive. Change the terminal ROE (Assumptions B62) and the payout path (DDM row 6) to test it.

Sheet Bank Drivers
A1: BANK DRIVERS — where the earnings come from
A2: CIB is, structurally, a low-cost-deposit / sovereign-carry machine with a high-quality loan book on top.
A4: Dimension | B4: Sovereign-carry book | C4: Customer loan book | D4: Fee & non-interest
A5: What it is | B5: ~EGP 700bn T-bills + gov bonds (FVOCI + AC) ≈ 52% of assets | C5: Net loans ~EGP 490bn; gross +52% YoY; LDR ~53% | D5: Trade finance, cards, cash mgmt, FX
A6: Earnings driver | B6: Spread of CASA cost vs T-bill/bond yield (the carry) | C6: NIM on loans + fee origination | D6: Transaction & advisory volume
A7: Rate sensitivity | B7: HIGH — repriced lower as CBE cuts (825bps done) | C7: Moderate — asset yields reset | D7: Low — volume-linked
A8: Quality | B8: Egyptian sovereign (B/stable) concentration | C8: NPL 1.7%, coverage 337%; Stage-2 ~24% (watch) | D8: Stable, growing 12%+
A9: Profitability | B9: Dominant NII contributor | C9: Growing share; CAPEX-led demand | D9: ~8% of revenue; diversifier
A10: Valuation lens | B10: macro/CoE (Expert 3) — sovereign risk is the tail | C10: credit cycle (Expert 2) — through-cycle CoR | D10: capital & returns (Expert 1) — ROE
A12: The carry is the crux: ~52% of assets sit in Egyptian government securities. As policy rates fall, the spread between low-cost CASA (62% of deposits) and T-bill yields compresses — the central reason the post-devaluation ~30%+ ROE is unlikely to persist at the same level, and why cost of equity (sovereign risk) dominates the valuation.

Sheet Relative & Normalized
A1: RELATIVE MULTIPLES & NORMALIZED EARNINGS
A4: RELATIVE (EGP)
A5: BVPS Dec-2025e | B5: =Assumptions!B8 -> 74.242918 | C5: book per share
A6: Relative justified P/B (x) | B6: =Assumptions!B21 -> 1.55 | C6: vs EGX + EM bank peers
A7: value/share — P/B | B7: =Assumptions!B26 -> 115.07652
A8: Normalized attributable EPS | B8: =Assumptions!B23 -> 19.124976 | C8: ROE_norm × BVPS × (1−staff)
A9: Peer P/E (x) | B9: =Assumptions!B24 -> 6.6 | C9: EM bank premium
A10: value/share — P/E | B10: =Assumptions!B27 -> 126.22484
A11: RELATIVE BLENDED (EGP) | B11: =Assumptions!B28 -> 120.65068 | C11: avg of P/B and P/E
A13: NORMALIZED THROUGH-CYCLE (EGP)
A14: Normalized through-cycle ROE | B14: =Assumptions!B22 -> 0.28 | C14: strip the ECL release
A15: Normalized attributable EPS | B15: =Assumptions!B23 -> 19.124976
A16: Through-cycle fair P/E (x) | B16: =Assumptions!B25 -> 6 | C16: conservative
A17: NORMALIZED EARNINGS POWER (EGP) | B17: =Assumptions!B29 -> 114.74985 | C17: EPS × fair P/E

Sheet DDM
A1: DIVIDEND-DISCOUNT MODEL — 2-stage, distributable earnings
A2: Discount distributable dividends at the cost of equity; terminal Gordon value. Conservative because near-term payout is low.
B4: 2026e | C4: 2027e | D4: 2028e | E4: 2029e | F4: 2030e
A5: Net income (EGP bn) | B5: ='Income Statement'!E14 -> 83.7 | C5: ='Income Statement'!F14 -> 90.2875 | D5: ='Income Statement'!G14 -> 98.89 | E5: ='Income Statement'!H14 -> 108.345 | F5: ='Income Statement'!I14 -> 118.6525
A6: Payout ratio | B6: =Assumptions!B37 -> 0.27 | C6: =Assumptions!B38 -> 0.3 | D6: =Assumptions!B39 -> 0.33 | E6: =Assumptions!B40 -> 0.36 | F6: =Assumptions!B41 -> 0.4
A7: Dividends (EGP bn) | B7: =B5*B6 -> 22.599 | C7: =C5*C6 -> 27.08625 | D7: =D5*D6 -> 32.6337 | E7: =E5*E6 -> 39.0042 | F7: =F5*F6 -> 47.461
A8: DPS (EGP) | B8: =B7/Assumptions!$B$6 -> 7.3588408 | C8: =C7/Assumptions!$B$6 -> 8.8200098 | D8: =D7/Assumptions!$B$6 -> 10.626408 | E8: =E7/Assumptions!$B$6 -> 12.700814 | F8: =F7/Assumptions!$B$6 -> 15.454575
A9: Discount factor @ CoE | B9: =1/(1+Assumptions!$B$42)^1 -> 0.80645161 | C9: =1/(1+Assumptions!$B$42)^2 -> 0.6503642 | D9: =1/(1+Assumptions!$B$42)^3 -> 0.52448726 | E9: =1/(1+Assumptions!$B$42)^4 -> 0.4229736 | F9: =1/(1+Assumptions!$B$42)^5 -> 0.34110774
A10: PV of DPS (EGP) | B10: =B8*B9 -> 5.934549 | C10: =C8*C9 -> 5.7362186 | D10: =D8*D9 -> 5.5734158 | E10: =E8*E9 -> 5.372109 | F10: =F8*F9 -> 5.2716752
A12: VALUE BRIDGE (EGP / share)
A13: PV of explicit DPS (2026e-2030e) | B13: =SUM(B10:F10) -> 27.887968
A14: Terminal DPS (2030e × (1+g)) | B14: =F8*(1+Assumptions!B43) -> 17.927307
A15: Terminal value @ 2030 (Gordon) | B15: =B14/(Assumptions!B42-Assumptions!B43) -> 224.09134
A16: PV of terminal value | B16: =B15*F9 -> 76.43929
A20: DDM VALUE / SHARE (EGP) | B20: =B13+B16 -> 104.32726
A21: vs spot | B21: =B20/Assumptions!B5-1 -> -0.19282586

Sheet Income Statement
A1: CONSOLIDATED INCOME STATEMENT — EGP bn
A2: Actuals: CIB disclosure (S1-S5). FY2023 sub-lines estimated; NI per reported. Forecasts link to Assumptions.
B4: 2023a | C4: 2024a | D4: 2025a | E4: 2026e | F4: 2027e | G4: 2028e | H4: 2029e | I4: 2030e
A5: Net interest income | B5: 58 | C5: 88 | D5: 112 | E5: =Assumptions!B55 -> 120 | F5: =Assumptions!C55 -> 132 | G5: =Assumptions!D55 -> 146 | H5: =Assumptions!E55 -> 161 | I5: =Assumptions!F55 -> 177
A6: Net fee & commission | B6: 6 | C6: 7 | D6: 8.5 | E6: =Assumptions!B56 -> 9.5 | F6: =Assumptions!C56 -> 10.7 | G6: =Assumptions!D56 -> 12 | H6: =Assumptions!E56 -> 13.4 | I6: =Assumptions!F56 -> 14.9
A7: Net trading & other income | B7: 3.5 | C7: 6 | D7: 5 | E7: =Assumptions!B57 -> 4 | F7: =Assumptions!C57 -> 4.3 | G7: =Assumptions!D57 -> 4.6 | H7: =Assumptions!E57 -> 4.9 | I7: =Assumptions!F57 -> 5.2
A8: Total operating income | B8: =SUM(B5:B7) -> 67.5 | C8: =SUM(C5:C7) -> 101 | D8: =SUM(D5:D7) -> 125.5 | E8: =SUM(E5:E7) -> 133.5 | F8: =SUM(F5:F7) -> 147 | G8: =SUM(G5:G7) -> 162.6 | H8: =SUM(H5:H7) -> 179.3 | I8: =SUM(I5:I7) -> 197.1
A9: Operating expenses | B9: -13 | C9: -16 | D9: -18.5 | E9: =-Assumptions!B58 -> -22 | F9: =-Assumptions!C58 -> -25 | G9: =-Assumptions!D58 -> -28 | H9: =-Assumptions!E58 -> -31 | I9: =-Assumptions!F58 -> -34
A10: Pre-provision operating profit | B10: =B8+B9 -> 54.5 | C10: =C8+C9 -> 85 | D10: =D8+D9 -> 107 | E10: =E8+E9 -> 111.5 | F10: =F8+F9 -> 122 | G10: =G8+G9 -> 134.6 | H10: =H8+H9 -> 148.3 | I10: =I8+I9 -> 163.1
A11: Impairment (ECL) charge/(release) | B11: -4.29 | C11: -4.47 | D11: 6 | E11: =Assumptions!B59 -> -3.5 | F11: =Assumptions!C59 -> -5.5 | G11: =Assumptions!D59 -> -7 | H11: =Assumptions!E59 -> -8.5 | I11: =Assumptions!F59 -> -10
A12: Profit before tax | B12: =B10+B11 -> 50.21 | C12: =C10+C11 -> 80.53 | D12: =D10+D11 -> 113 | E12: =E10+E11 -> 108 | F12: =F10+F11 -> 116.5 | G12: =G10+G11 -> 127.6 | H12: =H10+H11 -> 139.8 | I12: =I10+I11 -> 153.1
A13: Income tax, profit share & other | B13: -20.51 | C13: -25.33 | D13: -30.8 | E13: =-E12*Assumptions!$B$9 -> -24.3 | F13: =-F12*Assumptions!$B$9 -> -26.2125 | G13: =-G12*Assumptions!$B$9 -> -28.71 | H13: =-H12*Assumptions!$B$9 -> -31.455 | I13: =-I12*Assumptions!$B$9 -> -34.4475
A14: Net profit (consolidated) | B14: =B12+B13 -> 29.7 | C14: =C12+C13 -> 55.2 | D14: =D12+D13 -> 82.2 | E14: =E12+E13 -> 83.7 | F14: =F12+F13 -> 90.2875 | G14: =G12+G13 -> 98.89 | H14: =H12+H13 -> 108.345 | I14: =I12+I13 -> 118.6525
A15: reported NI (primary, memo) | B15: 29.7 | C15: 55.2 | D15: 82.2
A16: Attributable EPS (EGP) | B16: =B14*(1-Assumptions!$B$10)/Assumptions!$B$6 -> 8.8974275 | C16: =C14*(1-Assumptions!$B$10)/Assumptions!$B$6 -> 16.536633 | D16: =D14*(1-Assumptions!$B$10)/Assumptions!$B$6 -> 24.625204 | E16: =E14*(1-Assumptions!$B$10)/Assumptions!$B$6 -> 25.074569 | F16: =F14*(1-Assumptions!$B$10)/Assumptions!$B$6 -> 27.04803 | G16: =G14*(1-Assumptions!$B$10)/Assumptions!$B$6 -> 29.625138 | H16: =H14*(1-Assumptions!$B$10)/Assumptions!$B$6 -> 32.457636 | I16: =I14*(1-Assumptions!$B$10)/Assumptions!$B$6 -> 35.545523
A18: Note. Forecast NI is built PPOP − ECL − tax; FY2023-25 NI ties to CIB's reported consolidated figures (row 15). FY2025 PBT/NI carry the one-off ECL recalibration release (+~EGP 6bn); the forecast normalizes the cost of risk to a charge.

Sheet Balance Sheet
A1: CONSOLIDATED BALANCE SHEET — EGP bn
A2: Dec-2024 & Sep-2025 per CIB interim statements (S1). Dec-2023 & forecasts estimated; totals anchored to disclosure.
B4: 2023a | C4: 2024a | D4: 2025a | E4: 2026e | F4: 2027e | G4: 2028e | H4: 2029e | I4: 2030e
A5: Cash & balances at CBE | B5: 80 | C5: 137 | D5: 25 | E5: 30 | F5: 32 | G5: 35 | H5: 38 | I5: 41
A6: Due from banks (net) | B6: 150 | C6: 271 | D6: 230 | E6: 250 | F6: 270 | G6: 292 | H6: 315 | I6: 340
A7: Net loans & advances to customers | B7: 300 | C7: 344 | D7: 490 | E7: 560 | F7: 638 | G7: 720 | H7: 807 | I7: 900
A8: Government securities (T-bills+bonds), plug | B8: =(B15+B16)-B5-B6-B7-B9 -> 290 | C8: =(C15+C16)-C5-C6-C7-C9 -> 395 | D8: =(D15+D16)-D5-D6-D7-D9 -> 658 | E8: =(E15+E16)-E5-E6-E7-E9 -> 751.101 | F8: =(F15+F16)-F5-F6-F7-F9 -> 830.30225 | G8: =(G15+G16)-G5-G6-G7-G9 -> 905.55855 | H8: =(H15+H16)-H5-H6-H7-H9 -> 982.89935 | I8: =(I15+I16)-I5-I6-I7-I9 -> 1064.0909
A9: Other assets | B9: 50 | C9: 68 | D9: 75 | E9: 80 | F9: 86 | G9: 92 | H9: 98 | I9: 105
A10: Total assets | B10: =SUM(B5:B9) -> 870 | C10: =SUM(C5:C9) -> 1215 | D10: =SUM(D5:D9) -> 1478 | E10: =SUM(E5:E9) -> 1671.101 | F10: =SUM(F5:F9) -> 1856.3022 | G10: =SUM(G5:G9) -> 2044.5585 | H10: =SUM(H5:H9) -> 2240.8994 | I10: =SUM(I5:I9) -> 2450.0909
A12: Due to customers (deposits) | B12: 720 | C12: 973 | D12: 1110 | E12: 1230 | F12: 1340 | G12: 1450 | H12: 1565 | I12: 1690
A13: Due to banks & other loans | B13: 20 | C13: 26 | D13: 38 | E13: 42 | F13: 46 | G13: 50 | H13: 54 | I13: 58
A14: Other liabilities & provisions | B14: 40 | C14: 63 | D14: 102 | E14: 110 | F14: 118 | G14: 126 | H14: 134 | I14: 143
A15: Total liabilities | B15: =SUM(B12:B14) -> 780 | C15: =SUM(C12:C14) -> 1062 | D15: =SUM(D12:D14) -> 1250 | E15: =SUM(E12:E14) -> 1382 | F15: =SUM(F12:F14) -> 1504 | G15: =SUM(G12:G14) -> 1626 | H15: =SUM(H12:H14) -> 1753 | I15: =SUM(I12:I14) -> 1891
A16: Total equity (attributable) | B16: 90 | C16: 153 | D16: 228 | E16: =D16+'Income Statement'!E14*(1-DDM!B6) -> 289.101 | F16: =E16+'Income Statement'!F14*(1-DDM!C6) -> 352.30225 | G16: =F16+'Income Statement'!G14*(1-DDM!D6) -> 418.55855 | H16: =G16+'Income Statement'!H14*(1-DDM!E6) -> 487.89935 | I16: =H16+'Income Statement'!I14*(1-DDM!F6) -> 559.09085
A17: Total liabilities & equity | B17: =B15+B16 -> 870 | C17: =C15+C16 -> 1215 | D17: =D15+D16 -> 1478 | E17: =E15+E16 -> 1671.101 | F17: =F15+F16 -> 1856.3022 | G17: =G15+G16 -> 2044.5585 | H17: =H15+H16 -> 2240.8994 | I17: =I15+I16 -> 2450.0909
A18: Balance check (assets − L&E) | B18: =B10-B17 -> 0 | C18: =C10-C17 -> 0 | D18: =D10-D17 -> 0 | E18: =E10-E17 -> 0 | F18: =F10-F17 -> 0 | G18: =G10-G17 -> 0 | H18: =H10-H17 -> 0 | I18: =I10-I17 -> 0
A19: BVPS — attributable (EGP) | B19: =B16/Assumptions!$B$6 -> 29.306415 | C19: =C16/Assumptions!$B$6 -> 49.820905 | D19: =D16/Assumptions!$B$6 -> 74.242918 | E19: =E16/Assumptions!$B$6 -> 94.139043 | F19: =F16/Assumptions!$B$6 -> 114.71907 | G19: =G16/Assumptions!$B$6 -> 136.29389 | H19: =H16/Assumptions!$B$6 -> 158.87312 | I19: =I16/Assumptions!$B$6 -> 182.05498
A20: CAR (reported, memo) | C20: 0.241 | D20: 0.27
A22: Note. The balance sheet balances by construction every year: the government-securities line is the residual funding bucket (= total liabilities + equity − the other asset lines), so total assets always equal liabilities plus equity (row 18 = 0). This mirrors how a deposit-funded bank parks surplus funding in sovereign paper. Actual-year totals are anchored to CIB's reported figures (S1) with sub-lines as approximate allocations; forecast equity rolls forward by retained earnings.

Sheet Cash Flow
A1: SIMPLIFIED FLOWS — EGP bn (bank)
A2: For a bank, distributable cash ≈ net income; capital builds via retained earnings. Illustrative.
B4: 2023a | C4: 2024a | D4: 2025a | E4: 2026e | F4: 2027e | G4: 2028e | H4: 2029e | I4: 2030e
A5: Net income (consolidated) | B5: ='Income Statement'!B14 -> 29.7 | C5: ='Income Statement'!C14 -> 55.2 | D5: ='Income Statement'!D14 -> 82.2 | E5: ='Income Statement'!E14 -> 83.7 | F5: ='Income Statement'!F14 -> 90.2875 | G5: ='Income Statement'!G14 -> 98.89 | H5: ='Income Statement'!H14 -> 108.345 | I5: ='Income Statement'!I14 -> 118.6525
A6: Dividends paid | B6: -5 | C6: -9 | D6: -15 | E6: =-'Income Statement'!E14*DDM!E6 -> -30.132 | F6: =-'Income Statement'!F14*DDM!F6 -> -36.115 | G6: =-'Income Statement'!G14*DDM!G6 -> 0 | H6: =-'Income Statement'!H14*DDM!H6 -> 0 | I6: =-'Income Statement'!I14*DDM!I6 -> 0
A7: Retained (to capital) | B7: =B5+B6 -> 24.7 | C7: =C5+C6 -> 46.2 | D7: =D5+D6 -> 67.2 | E7: =E5+E6 -> 53.568 | F7: =F5+F6 -> 54.1725 | G7: =G5+G6 -> 98.89 | H7: =H5+H6 -> 108.345 | I7: =I5+I6 -> 118.6525
A9: Note. Dividend payout per the DDM payout path; retained earnings feed the Balance Sheet equity roll. A bank's 'free cash flow' is not the right lens — capital adequacy and distributable earnings are.

Sheet Summary Financials
A1: SUMMARY FINANCIALS — EGP bn (every cell links to the statements)
B4: 2023a | C4: 2024a | D4: 2025a | E4: 2026e | F4: 2027e | G4: 2028e | H4: 2029e | I4: 2030e
A5: Total operating income | B5: ='Income Statement'!B8 -> 67.5 | C5: ='Income Statement'!C8 -> 101 | D5: ='Income Statement'!D8 -> 125.5 | E5: ='Income Statement'!E8 -> 133.5 | F5: ='Income Statement'!F8 -> 147 | G5: ='Income Statement'!G8 -> 162.6 | H5: ='Income Statement'!H8 -> 179.3 | I5: ='Income Statement'!I8 -> 197.1
A6: Pre-provision profit | B6: ='Income Statement'!B10 -> 54.5 | C6: ='Income Statement'!C10 -> 85 | D6: ='Income Statement'!D10 -> 107 | E6: ='Income Statement'!E10 -> 111.5 | F6: ='Income Statement'!F10 -> 122 | G6: ='Income Statement'!G10 -> 134.6 | H6: ='Income Statement'!H10 -> 148.3 | I6: ='Income Statement'!I10 -> 163.1
A7: Net profit | B7: ='Income Statement'!B14 -> 29.7 | C7: ='Income Statement'!C14 -> 55.2 | D7: ='Income Statement'!D14 -> 82.2 | E7: ='Income Statement'!E14 -> 83.7 | F7: ='Income Statement'!F14 -> 90.2875 | G7: ='Income Statement'!G14 -> 98.89 | H7: ='Income Statement'!H14 -> 108.345 | I7: ='Income Statement'!I14 -> 118.6525
A8: Attributable EPS (EGP) | B8: ='Income Statement'!B16 -> 8.8974275 | C8: ='Income Statement'!C16 -> 16.536633 | D8: ='Income Statement'!D16 -> 24.625204 | E8: ='Income Statement'!E16 -> 25.074569 | F8: ='Income Statement'!F16 -> 27.04803 | G8: ='Income Statement'!G16 -> 29.625138 | H8: ='Income Statement'!H16 -> 32.457636 | I8: ='Income Statement'!I16 -> 35.545523
A9: Total assets | B9: ='Balance Sheet'!B10 -> 870 | C9: ='Balance Sheet'!C10 -> 1215 | D9: ='Balance Sheet'!D10 -> 1478 | E9: ='Balance Sheet'!E10 -> 1671.101 | F9: ='Balance Sheet'!F10 -> 1856.3022 | G9: ='Balance Sheet'!G10 -> 2044.5585 | H9: ='Balance Sheet'!H10 -> 2240.8994 | I9: ='Balance Sheet'!I10 -> 2450.0909
A10: Net loans | B10: ='Balance Sheet'!B7 -> 300 | C10: ='Balance Sheet'!C7 -> 344 | D10: ='Balance Sheet'!D7 -> 490 | E10: ='Balance Sheet'!E7 -> 560 | F10: ='Balance Sheet'!F7 -> 638 | G10: ='Balance Sheet'!G7 -> 720 | H10: ='Balance Sheet'!H7 -> 807 | I10: ='Balance Sheet'!I7 -> 900
A11: Government securities | B11: ='Balance Sheet'!B8 -> 290 | C11: ='Balance Sheet'!C8 -> 395 | D11: ='Balance Sheet'!D8 -> 658 | E11: ='Balance Sheet'!E8 -> 751.101 | F11: ='Balance Sheet'!F8 -> 830.30225 | G11: ='Balance Sheet'!G8 -> 905.55855 | H11: ='Balance Sheet'!H8 -> 982.89935 | I11: ='Balance Sheet'!I8 -> 1064.0909
A12: Deposits | B12: ='Balance Sheet'!B12 -> 720 | C12: ='Balance Sheet'!C12 -> 973 | D12: ='Balance Sheet'!D12 -> 1110 | E12: ='Balance Sheet'!E12 -> 1230 | F12: ='Balance Sheet'!F12 -> 1340 | G12: ='Balance Sheet'!G12 -> 1450 | H12: ='Balance Sheet'!H12 -> 1565 | I12: ='Balance Sheet'!I12 -> 1690
A13: Total equity | B13: ='Balance Sheet'!B16 -> 90 | C13: ='Balance Sheet'!C16 -> 153 | D13: ='Balance Sheet'!D16 -> 228 | E13: ='Balance Sheet'!E16 -> 289.101 | F13: ='Balance Sheet'!F16 -> 352.30225 | G13: ='Balance Sheet'!G16 -> 418.55855 | H13: ='Balance Sheet'!H16 -> 487.89935 | I13: ='Balance Sheet'!I16 -> 559.09085
A14: BVPS (EGP) | B14: ='Balance Sheet'!B19 -> 29.306415 | C14: ='Balance Sheet'!C19 -> 49.820905 | D14: ='Balance Sheet'!D19 -> 74.242918 | E14: ='Balance Sheet'!E19 -> 94.139043 | F14: ='Balance Sheet'!F19 -> 114.71907 | G14: ='Balance Sheet'!G19 -> 136.29389 | H14: ='Balance Sheet'!H19 -> 158.87312 | I14: ='Balance Sheet'!I19 -> 182.05498
A15: ROE (NI / avg equity) | C15: ='Income Statement'!C14/AVERAGE('Balance Sheet'!C16,'Balance Sheet'!B16) -> 0.45432099 | D15: ='Income Statement'!D14/AVERAGE('Balance Sheet'!D16,'Balance Sheet'!C16) -> 0.43149606 | E15: ='Income Statement'!E14/AVERAGE('Balance Sheet'!E16,'Balance Sheet'!D16) -> 0.32372786 | F15: ='Income Statement'!F14/AVERAGE('Balance Sheet'!F16,'Balance Sheet'!E16) -> 0.28153116 | G15: ='Income Statement'!G14/AVERAGE('Balance Sheet'!G16,'Balance Sheet'!F16) -> 0.25657032 | H15: ='Income Statement'!H14/AVERAGE('Balance Sheet'!H16,'Balance Sheet'!G16) -> 0.23905137 | I15: ='Income Statement'!I14/AVERAGE('Balance Sheet'!I16,'Balance Sheet'!H16) -> 0.22665446

Sheet Monte Carlo
A1: MONTE CARLO — one 16-factor model, 50k paths, seed 42
A2: 7 continuous factors compose a 3M drift; 9 discrete events each fire with probability and impact. Diffusion vol = Step-0 calibrated 41%. Outputs from monte_carlo.py.
A4: CORE INPUTS
A5: Anchor price (EGP, 29-Jun-26) | B5: 129.25
A6: Diffusion volatility (Step-0 σ) | B6: 0.41
A7: Horizon T+20 (sessions) | B7: 20
A8: Horizon T+60 (sessions) | B8: 60
A9: Net expected 3M factor drift | B9: 0.014
A10: Simulated annualized path vol | B10: 0.47561926
A11: SMA50 / structure (EGP) | B11: 135.15
A12: SMA200 (EGP) | B12: 116.04
A13: 52-wk high (EGP) | B13: 143.51
A15: PERCENTILE TABLE (EGP) — from engine
A16: Horizon | B16: P5 | C16: P25 | D16: Median | E16: P75 | F16: P95
A17: T+20 (~1m) | B17: 103.44 | C17: 117.89 | D17: 128.87 | E17: 140.85 | F17: 159.92
A18: T+60 (~3m) | B18: 87.93 | C18: 109.91 | D18: 127.83 | E18: 148.88 | F18: 185.4
A20: TOUCH PROBABILITIES (any time in window)
A21: Level (EGP) | B21: by T+20 | C21: by T+60
A22: 135 | B22: 0.63304 | C22: 0.77718
A23: 140 | B23: 0.44516 | C23: 0.65262
A24: 150 | B24: 0.19912 | C24: 0.44612
A25: 160 | B25: 0.07742 | C25: 0.29372
A26: 125 | B26: 0.69764 | C26: 0.8283
A27: 120 | B27: 0.4863 | C27: 0.6991
A28: 110 | B28: 0.18196 | C28: 0.45062
A29: 100 | B29: 0.04572 | C29: 0.2429
A30: T+60 median (for Summary link) | B30: =C18 -> 109.91
A32: THE 16 FACTORS
A33: Continuous (7) — drift
A34: CBE policy-rate path / NIM (carry)
A35: EGP/USD rate
A36: Inflation / nominal balance-sheet growth
A37: EGX30 & foreign flows
A38: Private-sector credit growth
A39: Gov-securities yield / sovereign carry
A40: Fee & non-interest income / digital
A42: Discrete events (9) — prob × impact
A43: Geopolitical / regional security
A44: Asset-quality / NPL-cycle shift
... A51: Foreign-flow surge / reversal (EM re-rating)

Sheet Sensitivity
A1: SENSITIVITY — RI fair value/share (EGP)
A2: Justified P/B value = BVPS × (ROE − g)/(CoE − g). Rows = cost of equity; cols = sustainable ROE. g = base.
A4: CoE ↓ / ROE →
B5: 0.24 | C5: 0.27 | D5: 0.3 | E5: 0.33 | F5: 0.36
A6: 0.21 | B6: =Assumptions!$B$8*(0.24-Assumptions!$B$16)/(0.21-Assumptions!$B$16) -> 118.78867 | C6: =Assumptions!$B$8*(0.27-Assumptions!$B$16)/(0.21-Assumptions!$B$16) -> 163.33442 | D6: =Assumptions!$B$8*(0.3-Assumptions!$B$16)/(0.21-Assumptions!$B$16) -> 207.88017 | E6: =Assumptions!$B$8*(0.33-Assumptions!$B$16)/(0.21-Assumptions!$B$16) -> 252.42592 | F6: =Assumptions!$B$8*(0.36-Assumptions!$B$16)/(0.21-Assumptions!$B$16) -> 296.97167
A7: 0.23 | B7: =Assumptions!$B$8*(0.24-Assumptions!$B$16)/(0.23-Assumptions!$B$16) -> 84.849049 | C7: =Assumptions!$B$8*(0.27-Assumptions!$B$16)/(0.23-Assumptions!$B$16) -> 116.66744 | D7: =Assumptions!$B$8*(0.3-Assumptions!$B$16)/(0.23-Assumptions!$B$16) -> 148.48584 | E7: =Assumptions!$B$8*(0.33-Assumptions!$B$16)/(0.23-Assumptions!$B$16) -> 180.30423 | F7: =Assumptions!$B$8*(0.36-Assumptions!$B$16)/(0.23-Assumptions!$B$16) -> 212.12262
A8: 0.25 | B8: =Assumptions!$B$8*(0.24-Assumptions!$B$16)/(0.25-Assumptions!$B$16) -> 65.993705 | C8: =Assumptions!$B$8*(0.27-Assumptions!$B$16)/(0.25-Assumptions!$B$16) -> 90.741344 | D8: =Assumptions!$B$8*(0.3-Assumptions!$B$16)/(0.25-Assumptions!$B$16) -> 115.48898 | E8: =Assumptions!$B$8*(0.33-Assumptions!$B$16)/(0.25-Assumptions!$B$16) -> 140.23662 | F8: =Assumptions!$B$8*(0.36-Assumptions!$B$16)/(0.25-Assumptions!$B$16) -> 164.98426
A9: 0.27 | B9: =Assumptions!$B$8*(0.24-Assumptions!$B$16)/(0.27-Assumptions!$B$16) -> 53.994849 | C9: =Assumptions!$B$8*(0.27-Assumptions!$B$16)/(0.27-Assumptions!$B$16) -> 74.242918 | D9: =Assumptions!$B$8*(0.3-Assumptions!$B$16)/(0.27-Assumptions!$B$16) -> 94.490986 | E9: =Assumptions!$B$8*(0.33-Assumptions!$B$16)/(0.27-Assumptions!$B$16) -> 114.73905 | F9: =Assumptions!$B$8*(0.36-Assumptions!$B$16)/(0.27-Assumptions!$B$16) -> 134.98712
A10: 0.29 | B10: =Assumptions!$B$8*(0.24-Assumptions!$B$16)/(0.29-Assumptions!$B$16) -> 45.687949 | C10: =Assumptions!$B$8*(0.27-Assumptions!$B$16)/(0.29-Assumptions!$B$16) -> 62.82093 | D10: =Assumptions!$B$8*(0.3-Assumptions!$B$16)/(0.29-Assumptions!$B$16) -> 79.953911 | E10: =Assumptions!$B$8*(0.33-Assumptions!$B$16)/(0.29-Assumptions!$B$16) -> 97.086892 | F10: =Assumptions!$B$8*(0.36-Assumptions!$B$16)/(0.29-Assumptions!$B$16) -> 114.21987
A12: Reading: each cell is fair value at that ROE/CoE pair, g held at base. The steep gradient is the point — a 2pp CoE move or a 3pp ROE move re-rates CIB by a third.

Sheet Per-Share & Ratios
A1: PER-SHARE & RATIOS (at spot)
C4: reported EPS is net of staff profit share; inflated by ECL release
A5: Share price (EGP, 29-Jun-26) | B5: =Assumptions!B5 -> 129.25
A6: Shares outstanding (bn) | B6: =Assumptions!B6 -> 3.071
A7: Market cap (EGP bn) | B7: =Assumptions!B5*Assumptions!B6 -> 396.92675
A8: 2025a reported EPS (EGP) | B8: 18.2
A9: Normalized attributable EPS (EGP) | B9: =Assumptions!B23 -> 19.124976
A10: BVPS Dec-2025e (EGP) | B10: =Assumptions!B8 -> 74.242918
A11: P/E on 2025a reported (x) | B11: =B5/B8 -> 7.1016484
A12: P/E normalized (x) | B12: =B5/B9 -> 6.7581786
A13: P/B (x) | B13: =B5/B10 -> 1.7409068
A14: Sustainable ROE (base) | B14: =Assumptions!B14 -> 0.295
A15: Cost of equity (base) | B15: =Assumptions!B15 -> 0.24
A16: Dividend yield (2026e @ 27% payout) | B16: =Assumptions!B32*Assumptions!B37/Assumptions!B6/B5 -> 0.056934938

Sheet Peer & Sector
A1: PEER & SECTOR — Egyptian & EM banks
A2: External context (not model inputs). Peers approximate.
A4: Metric | B4: CIB (COMI) | C4: EGX bank peers | D4: EM bank median
A5: Business | B5: Largest private bank | C5: ADIB-Egypt, Faisal, QNBAA | D5: frontier/EM lenders
A6: P/B (x) | B6: ~1.75 | C6: ~1.0-1.4 | D6: ~1.1-1.5
A7: P/E (x) | B7: ~7 (rptd, ECL-flattered) | C7: ~4-6 | D7: ~6-8
A8: ROE | B8: ~30%+ (falling) | C8: ~25-35% | D8: ~15-22%
A9: NPL ratio | B9: 1.7% | C9: 2-5% | D9: 3-6%
A10: CAR | B10: 27% | C10: 18-22% | D10: 15-18%
A11: CASA / deposits | B11: 62% | C11: 40-55% | D11: 45-60%
A12: Gov-securities / assets | B12: ~52% | C12: high (Egypt banks) | D12: varies
A14: CIB screens at a premium to peers on P/B — justified by best-in-class ROE, asset quality and the scarcity/liquidity premium as the foreign-investor proxy for Egypt; the question is the durability of the ROE as rates fall.
