Workbook

Sheet READ FIRST
A1: Testahil · DSCW — Dice For Ready-Made Garments SAE · Valuation model companion (19-Jul-2026)
A3: Educational analysis. NOT investment advice, NOT a recommendation, NOT a rating or a price target. Outputs are fair-value ranges and probability distributions only.
A4: The preparer is not licensed by the FRA or any securities regulator, manages no money and accepts no clients. Consult a licensed financial advisor before any investment decision.
A5: Reported FY2023-FY2025 figures are the company's own disclosure (FY2025 earnings release, dice.eg). Q1-2026 figures are the EGX filing as carried by Arab Finance/Zawya — colour, not the model base.
A6: Colour code: BLUE = hardcoded input / scenario lever (change these) · BLACK = formula · GREEN = cross-sheet link · grey fill = solved/engine value brought in from compute.py with its check shown.
A7: Single assumptions layer: every forecast formula chains from the Assumptions sheet. Scenario grids and the Monte Carlo are model re-runs computed in compute.py (values, labelled as such).
A8: Companion to: DSCW_Valuation_Study_19-07-2026_public.docx. Engine: carry-anchored YZ-HAR-t (live EG profile), 50,000 paths, seed 42.

Sheet Assumptions
A1: Driver (blue = edit me) | B1: Unit | C1: FY26E | D1: FY27E | E1: FY28E | F1: FY29E | G1: FY30E | H1: Source / note
A2: Export pieces growth | B2: % | C2: 0.12 | D2: 0.1 | E2: 0.08 | F2: 0.06 | G2: 0.05 | H2: Q4-25 +21.4%; Helwan ramp; sector Jan-Apr-26 +15% (AEC via DailyNewsEgypt 8-Jun-26)
A3: Export USD ASP growth | B3: % | C3: 0.02 | D3: 0.02 | E3: 0.02 | F3: 0.02 | G3: 0.02 | H3: FY25 ASP $4.41 (+12.3% mix); normalised +2%/yr
A4: EGP/USD (annual avg) | B4: EGP | C4: 52 | D4: 53.6 | E4: 55.2 | F4: 56.8 | G4: 58.5 | H4: H1-26 actual ~48-52.9 (TE Mar-26 52.8; Wise Jul-26 ~52.7); +3%/yr thereafter
A5: Retail revenue growth | B5: % | C5: 0.3 | D5: 0.24 | E5: 0.18 | F5: 0.14 | G5: 0.12 | H5: +46.6% FY25; 402 stores; decelerating rollout
A6: Dyeing 3rd-party growth | B6: % | C6: 0.13 | D6: 0.13 | E6: 0.13 | F6: 0.13 | G6: 0.13 | H6: vol +5% (util 84.6%) x price +8%
A7: Printing 3rd-party growth | B7: % | C7: 0.1 | D7: 0.1 | E7: 0.1 | F7: 0.1 | G7: 0.1 | H7: small base
A8: Other-local net growth | B8: % | C8: 0.03 | D8: 0.03 | E8: 0.03 | F8: 0.03 | G8: 0.03 | H8: ~flat real
A9: Gross margin | B9: % | C9: 0.225 | D9: 0.245 | E9: 0.255 | F9: 0.26 | G9: 0.26 | H9: FY24 34.0% = deval-windfall peak, never re-adopted (EFG rule); FY25 25.2% mid-cycle; Q1-26 loss print starts FY26E low
A10: S&D % revenue | B10: % | C10: 0.057 | D10: 0.056 | E10: 0.055 | F10: 0.053 | G10: 0.052 | H10: 5.6% FY25
A11: G&A % revenue | B11: % | C11: 0.053 | D11: 0.052 | E11: 0.05 | F11: 0.049 | G11: 0.048 | H11: 5.3% FY25
A12: Export rebate % export rev | B12: % | C12: 0.012 | H12: FY25 1.5%, FY24 2.0% — conservative 1.2%
A13: Capex | B13: EGP mn | C13: 800 | D13: 700 | E13: 650 | F13: 600 | G13: 550 | H13: FY25 580.8; Helwan buildout + land-MoU balance front-loaded
A14: Owned depreciation rate (% avg NFA) | B14: % | C14: 0.085 | H14: FY25 7.9% rising with new plant
A15: ROU depreciation growth | B15: % | C15: 0.15 | H15: FY25 ROU dep 35.6, store rollout
A16: Inventory days (COGS) | B16: days | C16: 190 | D16: 180 | E16: 172 | F16: 166 | G16: 160 | H16: FY25 201.9; FY23 161.6 — normalisation
A17: AR days (revenue) | B17: days | C17: 72 | H17: FY25 73.1
A18: Debtors days (revenue) | B18: days | C18: 39.6 | H18: FY25 level held
A19: AP days (COGS) | B19: days | C19: 30 | H19: FY25 27.3
A20: Creditors days (revenue) | B20: days | C20: 25.3 | H20: FY25 level held
A21: Provisions % revenue | B21: % | C21: 0.0144 | H21: FY25 level held
A22: Cost of debt (blended fwd) | B22: % | C22: 0.165 | D22: 0.135 | E22: 0.12 | F22: 0.11 | G22: 0.105 | H22: FY26 blended 16.5% (H1 ~19-21% policy less ~5pp facility discount; H2 cuts); CBE easing path
A23: Interest income on cash | B23: % | C23: 0.12 | H23: deposit rates under easing
A24: Lease interest rate | B24: % | C24: 0.09 | H24: IFRS16 book
A25: Lease liabilities growth | B25: % | C25: 0.1 | H25: store rollout
A26: Other income/(expense) | B26: EGP mn | C26: -30 | D26: -30 | E26: -30 | F26: -30 | G26: -30 | H26: FY25 -44.2 incl one-offs
A27: Minimum operating cash | B27: EGP mn | C27: 150 | H27: overdraft is the revolver plug
A28: — Valuation layer —
A29: Tax rate | B29: % | C29: 0.225 | H29: Egypt corporate 22.5% (FY25 eff. 21.4%)
A30: Risk-free (Egypt 10Y) | B30: % | C30: 0.2255 | H30: investing.com 3-Jul-2026
A31: ERP — CDS basis (primary) | B31: % | C31: 0.0941 | H31: Damodaran original 5-Jan-2026
A32: ERP — rating basis | B32: % | C32: 0.1394 | H32: Damodaran original 5-Jan-2026
A33: Beta | B33: x | C33: 1 | H33: floor 0.8 respected; n=19 regression 1.034 fails n>=24 gate — grid published
A34: Kd pre-tax (company-implied) | B34: % | C34: 0.1568 | H34: 516.0 / avg IBD 3,290.95; CBE benchmark 20.7% dual-framed
A35: Terminal growth g | B35: % | C35: 0.05 | H35: nominal EGP; reconciliation table in study
A36: Terminal ROIC | B36: % | C36: 0.22 | H36: between FY25 15.9% and FY24 39.6%
A37: Spot / shares | B37: EGP / mn | C37: 1.94 | D37: 2680 | H37: 19-Jul-2026 close; 2,680mn sh (536/0.20 par)
A38: Normalized net margin | B38: % | C38: 0.075 | H38: through-cycle 7.5% — Driver-Ledger logged
A39: P/E band (bear/base/bull) | B39: x | C39: 6 | D39: 7.5 | E39: 9 | H39: EGX consumer band; DSCW trailing ran 5.8-14.2x — logged
A40: EV/EBITDA band (bear/base/bull) | B40: x | C40: 4.5 | D40: 5.5 | E40: 6.5 | H40: EGX industrial band on FY27E — logged
...

Sheet Hist IS
A1: EGP mn | B1: FY2023 | C1: FY2024 | D1: FY2025 | E1: note
A2: Revenue | B2: 3431.7073 | C2: 5768.7 | D2: 7129.7 | E2: FY23 = FY24/1.681 (stated +68.1%) — derived, disclosed
A3: COGS | B3: n/d | C3: 3806.6 | D3: 5335.3
A4: Gross profit | B4: 1021.9271 | C4: 1962.1 | D4: 1794.4 | E4: FY23 = FY24/1.92 (stated +92%)
A5: S&D | B5: n/d | C5: -185.7 | D5: -398.5
A6: G&A | B6: n/d | C6: -265.4 | D6: -380.2
A7: Export rebate | B7: n/d | C7: 84.4 | D7: 70.2 | E7: state export-support programme
A8: EBITDA | B8: 835.32984 | C8: 1595.48 | D8: 1086 | E8: FY23 = FY24/1.91 (stated ~+91-92%)
A9: D&A | B9: n/d | C9: -85.9 | D9: -120.4 | E9: FY25: owned 84.8 + ROU 35.6
A10: EBIT | B10: 765.32984 | C10: 1509.6 | D10: 965.6 | E10: FY23 approximated (D&A ~70) — disclosed
A11: Net interest | B11: n/d | C11: -319.5 | D11: -516
A12: Lease interest | B12: n/d | C12: -12.1 | D12: -24.6
A13: FX gain/(loss) | B13: n/d | C13: -10 | D13: 85.7 | E13: net USD receivables
A14: Other | B14: n/d | C14: -10.5 | D14: -44.2
A15: EBT | B15: n/d | C15: 1157.6 | D15: 466.5
A16: Tax | B16: n/d | C16: -256.6 | D16: -99.9 | E16: eff. 22.2% / 21.4%
A17: Net profit | B17: 447.8 | C17: 900.98 | D17: 366.55 | E17: FY23 from the FY25 BS column (headline +91% implies 471.7 — discrepancy disclosed)
A19: Ties asserted in compute.py: GP=Rev−COGS · EBITDA=GP−S&D−G&A+rebate · EBIT=EBITDA−D&A · EBT chain · NP=EBT−tax — all within 0.5

Sheet Hist BS
A1: EGP mn | B1: Dec-23 | C1: Dec-24 | D1: Dec-25
A2: Net fixed assets | B2: 589.1 | C2: 900.7 | D2: 1244.9
A3: Right-of-use assets | B3: 47 | C3: 85.6 | D3: 125.8
A4: Other non-current assets | B4: 26 | C4: 140.7 | D4: 291.1
A5: Cash & equivalents | B5: 154 | C5: 240.6 | D5: 157
A6: Inventory | B6: 1066.7 | C6: 2183.2 | D6: 2951.1
A7: Trade receivables | B7: 714.5 | C7: 1141.5 | D7: 1427.7
A8: Mutual funds | B8: 161 | C8: 0 | D8: 19
A9: Debtors & other debit | B9: 201.2 | C9: 501.4 | D9: 773.7
A10: — Liabilities —
A11: Banks overdraft | B11: 1184.4 | C11: 2299.5 | D11: 3438.8
A12: CPLTD | B12: 71.6 | C12: 158.1 | D12: 105.8
A13: Trade payables | B13: 252.1 | C13: 439.1 | D13: 399.2
A14: Provisions | B14: 55.3 | C14: 80.8 | D14: 102.9
A15: Due to related parties | B15: 15.4 | C15: 0 | D15: 136.4
A16: ROU liab. (current) | B16: 20.2 | C16: 18 | D16: 31
A17: Leasing (current) | B17: 0 | C17: 0 | D17: 24.1
A18: Creditors & other credit | B18: 179.7 | C18: 514.8 | D18: 494
A19: Long-term debt | B19: 65.7 | C19: 269.2 | D19: 310.5
A20: ROU liab. (non-current) | B20: 33.5 | C20: 77.8 | D20: 114.8
A21: Leasing (non-current) | B21: 0 | C21: 0 | D21: 118.2
A22: Deferred tax | B22: 46.6 | C22: 78.1 | D22: 112.9
A23: — Equity —
A24: Paid-in capital | B24: 357 | C24: 357 | D24: 536
A25: Reserves | B25: 28.9 | C25: 33.7 | D25: 75.4
A26: Retained earnings | B26: 180.4 | C26: -33.6 | D26: 622.7
A27: Net profit (year) | B27: 447.8 | C27: 900.6 | D27: 366.6
A28: Minority interest | B28: 20.5 | C28: 0.2 | D28: 1
A29: Total assets | B29: 2959.4 | C29: 5193.7 | D29: 6990.3
A30: Total equity | B30: 1034.9 | C30: 1258.2 | D30: 1601.6
A32: BS balance asserted in compute.py (assets = liabilities + equity, within 1.0). FY25 paid-in 536 vs 357: bonus capitalisation 1.787bn->2.68bn shares.
A33: BS cash 157.0 vs CF ending 133.7 (FY25) and 240.6 vs 227.5 (FY24) — a 13-23mn definitional wedge in the company's own presentation, disclosed; the forecast uses one cash definition and ties internally

Sheet Hist CF & Segments
A1: FY2025 cash flow (EGP mn) | B1: value | D1: FY2025 segments (external rev) | E1: EGP mn
A2: CFO | B2: -718.9 | D2: Export (garments + materials) | E2: 4624.254
A3: Capex | B3: -580.8 | D3: Retail (Dice stores) | E3: 1751.9
A4: Interest paid | B4: -523.5 | D4: Dyeing 3rd-party | E4: 278.81312
A5: Common dividends paid | B5: 0 | D5: Printing 3rd-party | E5: 86.174
A6: Ending cash (CF basis) | B6: 133.7 | D6: Other local (net) | E6: 388.5
D7: Sum (= consolidated, asserted) | E7: 7129.6411
A9: CFO was NEGATIVE (-718.9) against EBITDA +1,086 — the working-capital absorption that drives this study's crux. CCC ~248 days. | D9: Export pieces (000) | E9: 21585
D10: USD revenue (mn) | E10: 95.174
D11: USD ASP / piece | E11: 4.41
D12: Implied EGP/USD | E12: 48.59
D13: Capacity (000 pieces) | E13: 29700
D14: Utilisation | E14: 0.72676768

Sheet Segment drivers
A1: Driver build | B1: FY25A | C1: FY26E | D1: FY27E | E1: FY28E | F1: FY29E | G1: FY30E
A2: Export pieces (000) | B2: 21585 | C2: =B2*(1+Assumptions!C2) -> 24175.2 | D2: =C2*(1+Assumptions!D2) -> 26592.72 | E2: =D2*(1+Assumptions!E2) -> 28720.138 | F2: =E2*(1+Assumptions!F2) -> 30443.346 | G2: =F2*(1+Assumptions!G2) -> 31965.513
A3: USD ASP | B3: 4.41 | C3: =B3*(1+Assumptions!C3) -> 4.4982 | D3: =C3*(1+Assumptions!D3) -> 4.588164 | E3: =D3*(1+Assumptions!E3) -> 4.6799273 | F3: =E3*(1+Assumptions!F3) -> 4.7735258 | G3: =F3*(1+Assumptions!G3) -> 4.8689963
A4: USD revenue (mn) | B4: 95.174 | C4: =C2*C3/1000 -> 108.74488 | D4: =D2*D3/1000 -> 122.01176 | E4: =E2*E3/1000 -> 134.40816 | F4: =F2*F3/1000 -> 145.3221 | G4: =G2*G3/1000 -> 155.63997
A5: EGP/USD | B5: 48.59 | C5: =Assumptions!C4 -> 52 | D5: =Assumptions!D4 -> 53.6 | E5: =Assumptions!E4 -> 55.2 | F5: =Assumptions!F4 -> 56.8 | G5: =Assumptions!G4 -> 58.5
A6: Materials (elastic) scale | B6: -0.25066 | C6: =$B$6*C4/$B$4*C5/$B$5 -> -0.30650107 | D6: =$B$6*D4/$B$4*D5/$B$5 -> -0.35447556 | E6: =$B$6*E4/$B$4*E5/$B$5 -> -0.4021467 | F6: =$B$6*F4/$B$4*F5/$B$5 -> -0.44740394 | G6: =$B$6*G4/$B$4*G5/$B$5 -> -0.49351097
A7: Export revenue (EGP mn) | B7: 4624.254 | C7: =C4*C5+C6 -> 5654.4275 | D7: =D4*D5+D6 -> 6539.4759 | E7: =E4*E5+E6 -> 7418.928 | F7: =F4*F5+F6 -> 8253.8477 | G7: =G4*G5+G6 -> 9104.4445
A8: Retail | B8: 1751.9 | C8: =B8*(1+Assumptions!C5) -> 2277.47 | D8: =C8*(1+Assumptions!D5) -> 2824.0628 | E8: =D8*(1+Assumptions!E5) -> 3332.3941 | F8: =E8*(1+Assumptions!F5) -> 3798.9293 | G8: =F8*(1+Assumptions!G5) -> 4254.8008
A9: Dyeing 3rd-party | B9: 278.81312 | C9: =B9*(1+Assumptions!C6) -> 315.05882 | D9: =C9*(1+Assumptions!D6) -> 356.01647 | E9: =D9*(1+Assumptions!E6) -> 402.29861 | F9: =E9*(1+Assumptions!F6) -> 454.59743 | G9: =F9*(1+Assumptions!G6) -> 513.6951
A10: Printing 3rd-party | B10: 86.174 | C10: =B10*(1+Assumptions!C7) -> 94.7914 | D10: =C10*(1+Assumptions!D7) -> 104.27054 | E10: =D10*(1+Assumptions!E7) -> 114.69759 | F10: =E10*(1+Assumptions!F7) -> 126.16735 | G10: =F10*(1+Assumptions!G7) -> 138.78409
A11: Other local (net) | B11: 388.5 | C11: =B11*(1+Assumptions!C8) -> 400.155 | D11: =C11*(1+Assumptions!D8) -> 412.15965 | E11: =D11*(1+Assumptions!E8) -> 424.52444 | F11: =E11*(1+Assumptions!F8) -> 437.26017 | G11: =F11*(1+Assumptions!G8) -> 450.37798
A12: Total revenue | B12: 7129.7 | C12: =SUM(C7:C11) -> 8741.9027 | D12: =SUM(D7:D11) -> 10235.985 | E12: =SUM(E7:E11) -> 11692.843 | F12: =SUM(F7:F11) -> 13070.802 | G12: =SUM(G7:G11) -> 14462.102
A13: Capacity utilisation | B13: 0.72676768 | C13: =C2/29700 -> 0.8139798 | D13: =D2/29700 -> 0.89537778 | E13: =E2/29700 -> 0.967008 | F13: =F2/29700 -> 1.0250285 | G13: =G2/29700 -> 1.0762799
A15: Note: materials line scales with USD export volume and the EGP; capacity 29,700k pieces held flat pending the Helwan/land build-out ramps.

Sheet Fcst IS
A1: EGP mn | B1: FY26E | C1: FY27E | D1: FY28E | E1: FY29E | F1: FY30E
A2: Revenue | B2: ='Segment drivers'!C12 -> 8741.9027 | C2: ='Segment drivers'!D12 -> 10235.985 | D2: ='Segment drivers'!E12 -> 11692.843 | E2: ='Segment drivers'!F12 -> 13070.802 | F2: ='Segment drivers'!G12 -> 14462.102
A3: COGS | B3: =-B2*(1-Assumptions!C9) -> -6774.9746 | C3: =-C2*(1-Assumptions!D9) -> -7728.1689 | D3: =-D2*(1-Assumptions!E9) -> -8711.1679 | E3: =-E2*(1-Assumptions!F9) -> -9672.3935 | F3: =-F2*(1-Assumptions!G9) -> -10701.956
A4: Gross profit | B4: =B2+B3 -> 1966.9281 | C4: =C2+C3 -> 2507.8164 | D4: =D2+D3 -> 2981.6749 | E4: =E2+E3 -> 3398.4085 | F4: =F2+F3 -> 3760.1466
A5: S&D | B5: =-B2*Assumptions!C10 -> -498.28846 | C5: =-C2*Assumptions!D10 -> -573.21518 | D5: =-D2*Assumptions!E10 -> -643.10635 | E5: =-E2*Assumptions!F10 -> -692.7525 | F5: =-F2*Assumptions!G10 -> -752.02933
A6: G&A | B6: =-B2*Assumptions!C11 -> -463.32084 | C6: =-C2*Assumptions!D11 -> -532.27124 | D6: =-D2*Assumptions!E11 -> -584.64214 | E6: =-E2*Assumptions!F11 -> -640.4693 | F6: =-F2*Assumptions!G11 -> -694.18092
A7: Export rebate | B7: ='Segment drivers'!C7*Assumptions!$C$12 -> 67.85313 | C7: ='Segment drivers'!D7*Assumptions!$C$12 -> 78.473711 | D7: ='Segment drivers'!E7*Assumptions!$C$12 -> 89.027136 | E7: ='Segment drivers'!F7*Assumptions!$C$12 -> 99.046173 | F7: ='Segment drivers'!G7*Assumptions!$C$12 -> 109.25333
A8: EBITDA | B8: =B4+B5+B6+B7 -> 1073.1719 | C8: =C4+C5+C6+C7 -> 1480.8037 | D8: =D4+D5+D6+D7 -> 1842.9536 | E8: =E4+E5+E6+E7 -> 2164.2329 | F8: =F4+F5+F6+F7 -> 2423.1897
A9: Owned depreciation | B9: =-Assumptions!$C$14*('Fcst BS'!B2+Assumptions!C13/2) -> -139.8165 | C9: =-Assumptions!$C$14*('Fcst BS'!C2+Assumptions!D13/2) -> -191.6821 | D9: =-Assumptions!$C$14*('Fcst BS'!D2+Assumptions!E13/2) -> -232.76412 | E9: =-Assumptions!$C$14*('Fcst BS'!E2+Assumptions!F13/2) -> -266.10417 | F9: =-Assumptions!$C$14*('Fcst BS'!F2+Assumptions!G13/2) -> -292.36031
A10: ROU depreciation | B10: =-35.6*(1+Assumptions!$C$15)^1 -> -40.94 | C10: =-35.6*(1+Assumptions!$C$15)^2 -> -47.081 | D10: =-35.6*(1+Assumptions!$C$15)^3 -> -54.14315 | E10: =-35.6*(1+Assumptions!$C$15)^4 -> -62.264623 | F10: =-35.6*(1+Assumptions!$C$15)^5 -> -71.604316
A11: EBIT | B11: =B8+B9+B10 -> 892.41544 | C11: =C8+C9+C10 -> 1242.0406 | D11: =D8+D9+D10 -> 1556.0463 | E11: =E8+E9+E10 -> 1835.8641 | F11: =F8+F9+F10 -> 2059.2251
A12: Net interest | B12: =-(('Fcst BS'!B10+'Fcst BS'!B11+'Fcst BS'!B12)+('Fcst BS'!C10+'Fcst BS'!C11+'Fcst BS'!C12))/2*Assumptions!C22+('Fcst BS'!B5+Assumptions!$C$27)/2*Assumptions!$C$23 -> -725.76663 | C12: =-(('Fcst BS'!C10+'Fcst BS'!C11+'Fcst BS'!C12)+('Fcst BS'!D10+'Fcst BS'!D11+'Fcst BS'!D12))/2*Assumptions!D22+('Fcst BS'!C5+Assumptions!$C$27)/2*Assumptions!$C$23 -> -725.13737 | D12: =-(('Fcst BS'!D10+'Fcst BS'!D11+'Fcst BS'!D12)+('Fcst BS'!E10+'Fcst BS'!E11+'Fcst BS'!E12))/2*Assumptions!E22+('Fcst BS'!D5+Assumptions!$C$27)/2*Assumptions!$C$23 -> -702.94092 | E12: =-(('Fcst BS'!E10+'Fcst BS'!E11+'Fcst BS'!E12)+('Fcst BS'!F10+'Fcst BS'!F11+'Fcst BS'!F12))/2*Assumptions!F22+('Fcst BS'!E5+Assumptions!$C$27)/2*Assumptions!$C$23 -> -659.78593 | F12: =-(('Fcst BS'!F10+'Fcst BS'!F11+'Fcst BS'!F12)+('Fcst BS'!G10+'Fcst BS'!G11+'Fcst BS'!G12))/2*Assumptions!G22+('Fcst BS'!F5+Assumptions!$C$27)/2*Assumptions!$C$23 -> -611.74865
A13: Lease interest | B13: =-('Fcst BS'!B13+'Fcst BS'!C13)/2*Assumptions!$C$24 -> -13.44735 | C13: =-('Fcst BS'!C13+'Fcst BS'!D13)/2*Assumptions!$C$24 -> -14.792085 | D13: =-('Fcst BS'!D13+'Fcst BS'!E13)/2*Assumptions!$C$24 -> -16.271293 | E13: =-('Fcst BS'!E13+'Fcst BS'!F13)/2*Assumptions!$C$24 -> -17.898423 | F13: =-('Fcst BS'!F13+'Fcst BS'!G13)/2*Assumptions!$C$24 -> -19.688265
A14: Other | B14: =Assumptions!C26 -> -30 | C14: =Assumptions!D26 -> -30 | D14: =Assumptions!E26 -> -30 | E14: =Assumptions!F26 -> -30 | F14: =Assumptions!G26 -> -30
A15: EBT | B15: =B11+B12+B13+B14 -> 123.20147 | C15: =C11+C12+C13+C14 -> 472.11115 | D15: =D11+D12+D13+D14 -> 806.83407 | E15: =E11+E12+E13+E14 -> 1128.1797 | F15: =F11+F12+F13+F14 -> 1397.7882
A16: Tax | B16: =-MAX(B15,0)*Assumptions!$C$29 -> -27.72033 | C16: =-MAX(C15,0)*Assumptions!$C$29 -> -106.22501 | D16: =-MAX(D15,0)*Assumptions!$C$29 -> -181.53767 | E16: =-MAX(E15,0)*Assumptions!$C$29 -> -253.84044 | F16: =-MAX(F15,0)*Assumptions!$C$29 -> -314.50234
A17: Net profit | B17: =B15+B16 -> 95.481137 | C17: =C15+C16 -> 365.88614 | D17: =D15+D16 -> 625.2964 | E17: =E15+E16 -> 874.3393 | F17: =F15+F16 -> 1083.2858
A18: Net profit attributable | B18: =B17*(1-0.000625) -> 95.421461 | C18: =C17*(1-0.000625) -> 365.65746 | D18: =D17*(1-0.000625) -> 624.90559 | E18: =E17*(1-0.000625) -> 873.79284 | F18: =F17*(1-0.000625) -> 1082.6088
A19: EPS (EGP) | B19: =B18/Assumptions!$D$37 -> 0.035605023 | C19: =C18/Assumptions!$D$37 -> 0.13643935 | D19: =D18/Assumptions!$D$37 -> 0.23317373 | E19: =E18/Assumptions!$D$37 -> 0.3260421 | F19: =F18/Assumptions!$D$37 -> 0.40395851
A21: Margins
A22: Gross margin | B22: =B4/B2 -> 0.225 | C22: =C4/C2 -> 0.245 | D22: =D4/D2 -> 0.255 | E22: =E4/E2 -> 0.26 | F22: =F4/F2 -> 0.26
A23: EBITDA margin | B23: =B8/B2 -> 0.12276183 | C23: =C8/C2 -> 0.14466645 | D23: =D8/D2 -> 0.15761381 | E23: =E8/E2 -> 0.16557767 | F23: =F8/F2 -> 0.16755446
A24: Net margin | B24: =B17/B2 -> 0.010922237 | C24: =C17/C2 -> 0.035745082 | D24: =D17/D2 -> 0.05347685 | E24: =E17/E2 -> 0.066892552 | F24: =F17/F2 -> 0.074905142

Sheet Fcst BS
A1: EGP mn | B1: FY25A | C1: FY26E | D1: FY27E | E1: FY28E | F1: FY29E | G1: FY30E
A2: Net fixed assets | B2: 1244.9 | C2: =B2+Assumptions!C13+'Fcst IS'!B9 -> 1905.0835 | D2: =C2+Assumptions!D13+'Fcst IS'!C9 -> 2413.4014 | E2: =D2+Assumptions!E13+'Fcst IS'!D9 -> 2830.6373 | F2: =E2+Assumptions!F13+'Fcst IS'!E9 -> 3164.5331 | G2: =F2+Assumptions!G13+'Fcst IS'!F9 -> 3422.1728 | I2: grey = revolver balance solved by the compute.py fixed-point; the check row re-derives it from this sheet's own P&L and cash flow
A3: ROU assets | B3: 125.8 | C3: =B3-'Fcst IS'!B10*1.3+'Fcst IS'!B10 -> 138.082 | D3: =C3-'Fcst IS'!C10*1.3+'Fcst IS'!C10 -> 152.2063 | E3: =D3-'Fcst IS'!D10*1.3+'Fcst IS'!D10 -> 168.44924 | F3: =E3-'Fcst IS'!E10*1.3+'Fcst IS'!E10 -> 187.12863 | G3: =F3-'Fcst IS'!F10*1.3+'Fcst IS'!F10 -> 208.60993
A4: Other non-current assets (plug-adjusted) | B4: 291.1 | C4: =(C10+C11+C12+C13+C14+C15+C16+C17+C18+C19)-(C2+C3+C5+C6+C7+C8+C9) -> 283.282 | D4: =(D10+D11+D12+D13+D14+D15+D16+D17+D18+D19)-(D2+D3+D5+D6+D7+D8+D9) -> 297.4063 | E4: =(E10+E11+E12+E13+E14+E15+E16+E17+E18+E19)-(E2+E3+E5+E6+E7+E8+E9) -> 313.64924 | F4: =(F10+F11+F12+F13+F14+F15+F16+F17+F18+F19)-(F2+F3+F5+F6+F7+F8+F9) -> 332.32863 | G4: =(G10+G11+G12+G13+G14+G15+G16+G17+G18+G19)-(G2+G3+G5+G6+G7+G8+G9) -> 353.80993
A5: Cash | B5: 157 | C5: =Assumptions!$C$27 -> 150 | D5: =Assumptions!$C$27 -> 150 | E5: =Assumptions!$C$27 -> 150 | F5: =Assumptions!$C$27 -> 150 | G5: =Assumptions!$C$27 -> 150
A6: Inventory | B6: 2951.1 | C6: =-'Fcst IS'!B3*Assumptions!C16/365 -> 3526.6991 | D6: =-'Fcst IS'!C3*Assumptions!D16/365 -> 3811.1518 | E6: =-'Fcst IS'!D3*Assumptions!E16/365 -> 4104.9887 | F6: =-'Fcst IS'!E3*Assumptions!F16/365 -> 4398.9515 | G6: =-'Fcst IS'!F3*Assumptions!G16/365 -> 4691.2683
A7: Trade receivables | B7: 1427.7 | C7: ='Fcst IS'!B2*Assumptions!$C$17/365 -> 1724.4301 | D7: ='Fcst IS'!C2*Assumptions!$C$17/365 -> 2019.1533 | E7: ='Fcst IS'!D2*Assumptions!$C$17/365 -> 2306.5334 | F7: ='Fcst IS'!E2*Assumptions!$C$17/365 -> 2578.35 | G7: ='Fcst IS'!F2*Assumptions!$C$17/365 -> 2852.7983
A8: Mutual funds | B8: 19 | C8: =B8 -> 19 | D8: =C8 -> 19 | E8: =D8 -> 19 | F8: =E8 -> 19 | G8: =F8 -> 19
A9: Debtors & other debit | B9: 773.7 | C9: ='Fcst IS'!B2*Assumptions!$C$18/365 -> 948.43657 | D9: ='Fcst IS'!C2*Assumptions!$C$18/365 -> 1110.5343 | E9: ='Fcst IS'!D2*Assumptions!$C$18/365 -> 1268.5934 | F9: ='Fcst IS'!E2*Assumptions!$C$18/365 -> 1418.0925 | G9: ='Fcst IS'!F2*Assumptions!$C$18/365 -> 1569.0391
A10: Banks overdraft (solved revolver) | B10: 3438.8 | C10: 4749.044 | D10: 5427.7986 | E10: 5755.2834 | F10: 5735.497 | G10: 5427.1153
A11: CPLTD | B11: 105.8 | C11: =B11 -> 105.8 | D11: =C11 -> 105.8 | E11: =D11 -> 105.8 | F11: =E11 -> 105.8 | G11: =F11 -> 105.8
A12: Long-term debt | B12: 310.5 | C12: =B12 -> 310.5 | D12: =C12 -> 310.5 | E12: =D12 -> 310.5 | F12: =E12 -> 310.5 | G12: =F12 -> 310.5
A13: Lease liabilities | B13: 142.3 | C13: =B13*(1+Assumptions!$C$25) -> 156.53 | D13: =C13*(1+Assumptions!$C$25) -> 172.183 | E13: =D13*(1+Assumptions!$C$25) -> 189.4013 | F13: =E13*(1+Assumptions!$C$25) -> 208.34143 | G13: =F13*(1+Assumptions!$C$25) -> 229.17557
A14: ROU liabilities (= ROU assets, simplified) | B14: 145.8 | C14: =C3 -> 138.082 | D14: =D3 -> 152.2063 | E14: =E3 -> 168.44924 | F14: =F3 -> 187.12863 | G14: =G3 -> 208.60993
A15: Trade payables | B15: 399.2 | C15: =-'Fcst IS'!B3*Assumptions!$C$19/365 -> 556.84723 | D15: =-'Fcst IS'!C3*Assumptions!$C$19/365 -> 635.19197 | E15: =-'Fcst IS'!D3*Assumptions!$C$19/365 -> 715.9864 | F15: =-'Fcst IS'!E3*Assumptions!$C$19/365 -> 794.99124 | G15: =-'Fcst IS'!F3*Assumptions!$C$19/365 -> 879.61281
A16: Creditors & other credit | B16: 494 | C16: ='Fcst IS'!B2*Assumptions!$C$20/365 -> 605.94559 | D16: ='Fcst IS'!C2*Assumptions!$C$20/365 -> 709.50803 | E16: ='Fcst IS'!D2*Assumptions!$C$20/365 -> 810.4902 | F16: ='Fcst IS'!E2*Assumptions!$C$20/365 -> 906.00353 | G16: ='Fcst IS'!F2*Assumptions!$C$20/365 -> 1002.4416
A17: Provisions | B17: 102.9 | C17: ='Fcst IS'!B2*Assumptions!$C$21 -> 125.8834 | D17: ='Fcst IS'!C2*Assumptions!$C$21 -> 147.39819 | E17: ='Fcst IS'!D2*Assumptions!$C$21 -> 168.37694 | F17: ='Fcst IS'!E2*Assumptions!$C$21 -> 188.21955 | G17: ='Fcst IS'!F2*Assumptions!$C$21 -> 208.25428
A18: Due to related / deferred tax | B18: 249.3 | C18: =B18 -> 249.3 | D18: =C18 -> 249.3 | E18: =D18 -> 249.3 | F18: =E18 -> 249.3 | G18: =F18 -> 249.3
A19: Equity (roll: + NP attributable) | B19: 1601.6 | C19: =B19+'Fcst IS'!B17 -> 1697.0811 | D19: =C19+'Fcst IS'!C17 -> 2062.9673 | E19: =D19+'Fcst IS'!D17 -> 2688.2637 | F19: =E19+'Fcst IS'!E17 -> 3562.603 | G19: =F19+'Fcst IS'!F17 -> 4645.8888
A21: Total assets | C21: =SUM(C2:C9) -> 8695.0133 | D21: =SUM(D2:D9) -> 9972.8534 | E21: =SUM(E2:E9) -> 11161.851 | F21: =SUM(F2:F9) -> 12248.384 | G21: =SUM(G2:G9) -> 13266.698
A22: Liabilities + equity | C22: =SUM(C10:C19) -> 8695.0133 | D22: =SUM(D10:D19) -> 9972.8534 | E22: =SUM(E10:E19) -> 11161.851 | F22: =SUM(F10:F19) -> 12248.384 | G22: =SUM(G10:G19) -> 13266.698
A23: Balance check (=0) | C23: =C21-C22 -> 0 | D23: =D21-D22 -> 0 | E23: =E21-E22 -> 0 | F23: =F21-F22 -> 0 | G23: =G21-G22 -> 0
A24: Revolver fixed-point check (=0): od − [od_open + max(0, min-cash − pre-financing cash)] | C24: =C10-MAX(0,B10+Assumptions!$C$27-(B5+'Fcst CF'!B5+'Fcst CF'!B6+'Fcst CF'!B7)) -> -2.1901542e-08 | D24: =D10-MAX(0,C10+Assumptions!$C$27-(C5+'Fcst CF'!C5+'Fcst CF'!C6+'Fcst CF'!C7)) -> -3.6077836e-08 | E24: =E10-MAX(0,D10+Assumptions!$C$27-(D5+'Fcst CF'!D5+'Fcst CF'!D6+'Fcst CF'!D7)) -> -6.8257577e-09 | F24: =F10-MAX(0,E10+Assumptions!$C$27-(E5+'Fcst CF'!E5+'Fcst CF'!E6+'Fcst CF'!E7)) -> 4.8439688e-09 | G24: =G10-MAX(0,F10+Assumptions!$C$27-(F5+'Fcst CF'!F5+'Fcst CF'!F6+'Fcst CF'!F7)) -> 2.2218956e-09

Sheet Fcst CF
A1: EGP mn | B1: FY26E | C1: FY27E | D1: FY28E | E1: FY29E | F1: FY30E
A2: Net profit | B2: ='Fcst IS'!B17 -> 95.481137 | C2: ='Fcst IS'!C17 -> 365.88614 | D2: ='Fcst IS'!D17 -> 625.2964 | E2: ='Fcst IS'!E17 -> 874.3393 | F2: ='Fcst IS'!F17 -> 1083.2858
A3: + D&A | B3: =-'Fcst IS'!B9-'Fcst IS'!B10 -> 180.7565 | C3: =-'Fcst IS'!C9-'Fcst IS'!C10 -> 238.7631 | D3: =-'Fcst IS'!D9-'Fcst IS'!D10 -> 286.90727 | E3: =-'Fcst IS'!E9-'Fcst IS'!E10 -> 328.36879 | F3: =-'Fcst IS'!F9-'Fcst IS'!F10 -> 363.96463
A4: − Δ working capital | B4: =-(('Fcst BS'!C6+'Fcst BS'!C7+'Fcst BS'!C9-'Fcst BS'!C15-'Fcst BS'!C16-'Fcst BS'!C17)-('Fcst BS'!B6+'Fcst BS'!B7+'Fcst BS'!B9-'Fcst BS'!B15-'Fcst BS'!B16-'Fcst BS'!B17)) -> -754.48959 | C4: =-(('Fcst BS'!D6+'Fcst BS'!D7+'Fcst BS'!D9-'Fcst BS'!D15-'Fcst BS'!D16-'Fcst BS'!D17)-('Fcst BS'!C6+'Fcst BS'!C7+'Fcst BS'!C9-'Fcst BS'!C15-'Fcst BS'!C16-'Fcst BS'!C17)) -> -537.8516 | D4: =-(('Fcst BS'!E6+'Fcst BS'!E7+'Fcst BS'!E9-'Fcst BS'!E15-'Fcst BS'!E16-'Fcst BS'!E17)-('Fcst BS'!D6+'Fcst BS'!D7+'Fcst BS'!D9-'Fcst BS'!D15-'Fcst BS'!D16-'Fcst BS'!D17)) -> -536.52069 | E4: =-(('Fcst BS'!F6+'Fcst BS'!F7+'Fcst BS'!F9-'Fcst BS'!F15-'Fcst BS'!F16-'Fcst BS'!F17)-('Fcst BS'!E6+'Fcst BS'!E7+'Fcst BS'!E9-'Fcst BS'!E15-'Fcst BS'!E16-'Fcst BS'!E17)) -> -520.9178 | F4: =-(('Fcst BS'!G6+'Fcst BS'!G7+'Fcst BS'!G9-'Fcst BS'!G15-'Fcst BS'!G16-'Fcst BS'!G17)-('Fcst BS'!F6+'Fcst BS'!F7+'Fcst BS'!F9-'Fcst BS'!F15-'Fcst BS'!F16-'Fcst BS'!F17)) -> -516.61728
A5: Cash flow from operations | B5: =B2+B3+B4 -> -478.25196 | C5: =C2+C3+C4 -> 66.797631 | D5: =D2+D3+D4 -> 375.68298 | E5: =E2+E3+E4 -> 681.79029 | F5: =F2+F3+F4 -> 930.6332
A6: Capex (investing) | B6: =-Assumptions!C13 -> -800 | C6: =-Assumptions!D13 -> -700 | D6: =-Assumptions!E13 -> -650 | E6: =-Assumptions!F13 -> -600 | F6: =-Assumptions!G13 -> -550
A7: Lease principal (financing) | B7: =-('Fcst BS'!B13+'Fcst IS'!B10*-1.3-'Fcst BS'!C13) -> -38.992 | C7: =-('Fcst BS'!C13+'Fcst IS'!C10*-1.3-'Fcst BS'!D13) -> -45.5523 | D7: =-('Fcst BS'!D13+'Fcst IS'!D10*-1.3-'Fcst BS'!E13) -> -53.167795 | E7: =-('Fcst BS'!E13+'Fcst IS'!E10*-1.3-'Fcst BS'!F13) -> -62.003879 | F7: =-('Fcst BS'!F13+'Fcst IS'!F10*-1.3-'Fcst BS'!G13) -> -72.251468
A8: Revolver draw / (repay) | B8: ='Fcst BS'!C10-'Fcst BS'!B10 -> 1310.244 | C8: ='Fcst BS'!D10-'Fcst BS'!C10 -> 678.75467 | D8: ='Fcst BS'!E10-'Fcst BS'!D10 -> 327.48481 | E8: ='Fcst BS'!F10-'Fcst BS'!E10 -> -19.786412 | F8: ='Fcst BS'!G10-'Fcst BS'!F10 -> -308.38173
A9: Net change in cash | B9: =B5+B6+B7+B8 -> -7 | C9: =C5+C6+C7+C8 -> -3.6077836e-08 | D9: =D5+D6+D7+D8 -> -6.8254167e-09 | E9: =E5+E6+E7+E8 -> 4.8443951e-09 | F9: =F5+F6+F7+F8 -> 2.2221229e-09
A10: Δ cash per balance sheet | B10: ='Fcst BS'!C5-'Fcst BS'!B5 -> -7 | C10: ='Fcst BS'!D5-'Fcst BS'!C5 -> 0 | D10: ='Fcst BS'!E5-'Fcst BS'!D5 -> 0 | E10: ='Fcst BS'!F5-'Fcst BS'!E5 -> 0 | F10: ='Fcst BS'!G5-'Fcst BS'!F5 -> 0
A11: Cash tie-out check (=0) | B11: =B9-B10 -> -2.1901315e-08 | C11: =C9-C10 -> -3.6077836e-08 | D11: =D9-D10 -> -6.8254167e-09 | E11: =E9-E10 -> 4.8443951e-09 | F11: =F9-F10 -> 2.2221229e-09
A13: The tie-out row is QC item (q): CF Δcash equals BS Δcash in every forecast year — asserted in compute.py and live here.

Sheet FCFF & DCF
A1: EGP mn | B1: FY26E | C1: FY27E | D1: FY28E | E1: FY29E | F1: FY30E
A2: Revenue | B2: ='Fcst IS'!B2 -> 8741.9027 | C2: ='Fcst IS'!C2 -> 10235.985 | D2: ='Fcst IS'!D2 -> 11692.843 | E2: ='Fcst IS'!E2 -> 13070.802 | F2: ='Fcst IS'!F2 -> 14462.102
A3: EBITDA | B3: ='Fcst IS'!B8 -> 1073.1719 | C3: ='Fcst IS'!C8 -> 1480.8037 | D3: ='Fcst IS'!D8 -> 1842.9536 | E3: ='Fcst IS'!E8 -> 2164.2329 | F3: ='Fcst IS'!F8 -> 2423.1897
A4: − D&A | B4: ='Fcst IS'!B9+'Fcst IS'!B10 -> -180.7565 | C4: ='Fcst IS'!C9+'Fcst IS'!C10 -> -238.7631 | D4: ='Fcst IS'!D9+'Fcst IS'!D10 -> -286.90727 | E4: ='Fcst IS'!E9+'Fcst IS'!E10 -> -328.36879 | F4: ='Fcst IS'!F9+'Fcst IS'!F10 -> -363.96463
A5: EBIT | B5: ='Fcst IS'!B11 -> 892.41544 | C5: ='Fcst IS'!C11 -> 1242.0406 | D5: ='Fcst IS'!D11 -> 1556.0463 | E5: ='Fcst IS'!E11 -> 1835.8641 | F5: ='Fcst IS'!F11 -> 2059.2251
A6: NOPAT (EBIT × (1−t)) | B6: =B5*(1-Assumptions!$C$29) -> 691.62197 | C6: =C5*(1-Assumptions!$C$29) -> 962.58147 | D6: =D5*(1-Assumptions!$C$29) -> 1205.9359 | E6: =E5*(1-Assumptions!$C$29) -> 1422.7947 | F6: =F5*(1-Assumptions!$C$29) -> 1595.8995
A7: + D&A | B7: =-B4 -> 180.7565 | C7: =-C4 -> 238.7631 | D7: =-D4 -> 286.90727 | E7: =-E4 -> 328.36879 | F7: =-F4 -> 363.96463
A8: − Capex | B8: =-Assumptions!C13 -> -800 | C8: =-Assumptions!D13 -> -700 | D8: =-Assumptions!E13 -> -650 | E8: =-Assumptions!F13 -> -600 | F8: =-Assumptions!G13 -> -550
A9: − Δ working capital | B9: ='Fcst CF'!B4 -> -754.48959 | C9: ='Fcst CF'!C4 -> -537.8516 | D9: ='Fcst CF'!D4 -> -536.52069 | E9: ='Fcst CF'!E4 -> -520.9178 | F9: ='Fcst CF'!F4 -> -516.61728
A10: Free cash flow to firm | B10: =B6+B7+B8+B9 -> -682.11113 | C10: =C6+C7+C8+C9 -> -36.507037 | D10: =D6+D7+D8+D9 -> 306.32245 | E10: =E6+E7+E8+E9 -> 630.24566 | F10: =F6+F7+F8+F9 -> 893.24681
A11: Discount factor | B11: =1/(1+$B$14)^1 -> 0.80954462 | C11: =1/(1+$B$14)^2 -> 0.65536248 | D11: =1/(1+$B$14)^3 -> 0.53054517 | E11: =1/(1+$B$14)^4 -> 0.42949999 | F11: =1/(1+$B$14)^5 -> 0.3476994
A12: PV of FCFF | B12: =B10*B11 -> -552.19939 | C12: =C10*C11 -> -23.925343 | D12: =D10*D11 -> 162.5179 | E12: =E10*E11 -> 270.6905 | F12: =F10*F11 -> 310.58138
A14: WACC (CDS basis, from WACC sheet) | B14: =WACC!B12 -> 0.23526237
A15: Sum PV of FCFF | B15: =SUM(B12:F12) -> 167.66505
A16: Terminal: NOPAT FY31 = NOPAT30 × (1+g) | B16: =F6*(1+Assumptions!$C$35) -> 1675.6944
A17: Reinvestment rate = g / ROIC_t | B17: =Assumptions!$C$35/Assumptions!$C$36 -> 0.22727273
A18: TV = NOPAT31 × (1−RR) / (WACC−g) [value-driver formula — capitalising FCFF is banned] | B18: =B16*(1-B17)/(B14-Assumptions!$C$35) -> 6989.3027
A19: PV of terminal value | B19: =B18/(1+B14)^5 -> 2430.1764
A20: Enterprise value | B20: =B15+B19 -> 2597.8414
A21: TV % of EV (disclosed) | B21: =B19/B20 -> 0.93545986
A22: − Net debt (Dec-25: od+cpltd+ltd+leases+ROU−cash−MF) | B22: -3967.2
A23: − Minority interest (at ~fair = book, immaterial) | B23: -1
A24: Equity value | B24: =B20+B22+B23 -> -1370.3586
A25: Per share (EGP) | B25: =B24/Assumptions!$D$37 -> -0.51132783
A26: vs spot | B26: =B25/Assumptions!$C$37-1 -> -1.263571
A28: Scenario re-runs (compute.py): bear -0.94 · bull 0.06 · easing-path WACC 20.5% dual-frame -0.17 · market-implied WACC 13.05%

Sheet WACC
A1: Component | B1: Value | C1: Source
A2: Risk-free (Egypt 10Y) | B2: =Assumptions!$C$30 -> 0.2255 | C2: investing.com 3-Jul-2026 — local-currency even for EGP (house rule)
A3: ERP — CDS basis (primary) | B3: =Assumptions!$C$31 -> 0.0941 | C3: Damodaran ORIGINAL country file, 5-Jan-2026
A4: ERP — rating basis | B4: =Assumptions!$C$32 -> 0.1394 | C4: same file, rating-based
A5: Beta | B5: =Assumptions!$C$33 -> 1 | C5: assumed 1.0 (floor 0.8); n=19 regression 1.034/R2 0.281 fails n>=24 usability gate — grid below
A6: Ke = rf + β·ERP (CDS) | B6: =B2+B5*B3 -> 0.3196 | C6: published explicitly per house rule
A7: Ke = rf + β·ERP (rating) | B7: =B2+B5*B4 -> 0.3649
A8: Kd pre-tax (company-implied) | B8: =Assumptions!$C$34 -> 0.1568 | C8: FY25 net interest 516.0 / avg IBD 3,291; cash interest paid = P&L expense (no capitalised-interest wedge); CBE benchmark 20.7% dual-framed
A9: Kd after tax | B9: =B8*(1-Assumptions!$C$29) -> 0.12152
A10: Weight of equity | B10: =Assumptions!$C$37*Assumptions!$D$37/(Assumptions!$C$37*Assumptions!$D$37+3855.1) -> 0.5742244 | C10: mkt cap 5,199 vs IBD 3,855.1 (leases in the bridge, not the weights)
A11: Weight of debt | B11: =1-B10 -> 0.4257756
A12: WACC — CDS basis (primary) | B12: =B10*B6+B11*B9 -> 0.23526237 | C12: both published, deliberately
A13: WACC — rating basis | B13: =B10*B7+B11*B9 -> 0.26127473
A16: Beta ladder (Ke / WACC / DCF per share)
A17: Beta | B17: Ke (CDS) | C17: WACC | D17: DCF EGP/sh
A18: 0.8 | B18: =$B$2+A18*$B$3 -> 0.30078 | C18: =$B$10*B18+$B$11*$B$9 -> 0.22445547 | D18: -0.40344299
A19: 0.9 | B19: =$B$2+A19*$B$3 -> 0.31019 | C19: =$B$10*B19+$B$11*$B$9 -> 0.22985892 | D19: -0.4592121
A20: 1 | B20: =$B$2+A20*$B$3 -> 0.3196 | C20: =$B$10*B20+$B$11*$B$9 -> 0.23526237 | D20: -0.51132783
A21: 1.1 | B21: =$B$2+A21*$B$3 -> 0.32901 | C21: =$B$10*B21+$B$11*$B$9 -> 0.24066582 | D21: -0.5601102
A22: 1.2 | B22: =$B$2+A22*$B$3 -> 0.33842 | C22: =$B$10*B22+$B$11*$B$9 -> 0.24606927 | D22: -0.60584368
A23: 1.3 | B23: =$B$2+A23*$B$3 -> 0.34783 | C23: =$B$10*B23+$B$11*$B$9 -> 0.25147272 | D23: -0.64878196
A25: DCF column = compute.py model re-run per beta (grids cannot be a single live formula).

Sheet Sensitivity
A1: DCF value (EGP/share) — WACC × terminal growth (compute.py model re-runs)
B2: 0.03 | C2: 0.04 | D2: 0.05 | E2: 0.06 | F2: 0.07
A3: 0.20526237 | B3: -0.20510574 | C3: -0.18793673 | D3: -0.169927 | E3: -0.15090293 | F3: -0.13063954
A4: 0.21526237 | B4: -0.32338177 | C4: -0.31135935 | D4: -0.2991178 | E4: -0.28661477 | F4: -0.27379626
A5: 0.22526237 | B5: -0.42792672 | C5: -0.41987205 | D5: -0.41201675 | E5: -0.404397 | F5: -0.39705832
A6: 0.23526237 | B6: -0.52081871 | C6: -0.51583431 | D6: -0.51132783 | E6: -0.50738106 | F6: -0.50409562
A7: 0.24526237 | B7: -0.60374587 | C7: -0.60114216 | D7: -0.59919765 | E7: -0.59801907 | F7: -0.59773754
A8: 0.25526237 | B8: -0.67809316 | C8: -0.67733607 | D8: -0.67735145 | E8: -0.67825799 | F8: -0.6802
A10: DCF value — gross-margin shift × WACC
B11: 0.21526237 | C11: 0.22526237 | D11: 0.23526237 | E11: 0.24526237 | F11: 0.25526237
A12: -2% GPM | B12: -0.66836337 | C12: -0.76194251 | D12: -0.84395014 | E12: -0.91622675 | F12: -0.9802509
A13: -1% GPM | B13: -0.48374058 | C13: -0.58697963 | D13: -0.67763898 | E13: -0.7577122 | F13: -0.82880117
A14: +0% GPM | B14: -0.2991178 | C14: -0.41201675 | D14: -0.51132783 | E14: -0.59919765 | F14: -0.67735145
A15: +1% GPM | B15: -0.11449501 | C15: -0.23705387 | D15: -0.34501667 | E15: -0.4406831 | F15: -0.52590173
A16: +2% GPM | B16: 0.070127773 | C16: -0.062090993 | D16: -0.17870552 | E16: -0.28216854 | F16: -0.37445201
A18: The crux ladder — DCF across the WACC glidepath
A19: WACC | B19: DCF EGP/sh | C19: reading
A20: 0.23526237 | B20: -0.51132783 | C20: today's sourced WACC (CDS)
A21: 0.215 | B21: -0.29594962 | C21: −200bp
A22: 0.195 | B22: -0.016779455 | C22: −400bp: mid-easing
A23: 0.175 | B23: 0.36128297 | C23: −600bp
A24: 0.1304559 | B24: 1.94 | C24: market-implied — the rate spot assumes
A25: 0.15 | B25: 1.0651607 | C25: full easing + re-rating

Sheet Lenses & Central
A1: Lens | B1: Bear | C1: Base | D1: Bull | E1: Weight | F1: Note
A2: FCFF DCF @ sourced WACC (floored at 0) | B2: 0 | C2: 0 | D2: 0.062380353 | E2: =Assumptions!$C$41 -> 0.35 | F2: raw (unfloored): -0.94 / -0.51 / 0.06 — negative at today's rates, disclosed
A3: Normalized earnings power | B3: =Assumptions!$C$38*'Fcst IS'!B2/Assumptions!$D$37*Assumptions!$C$39 -> 1.4678568 | C3: =Assumptions!$C$38*'Fcst IS'!B2/Assumptions!$D$37*Assumptions!$D$39 -> 1.834821 | D3: =Assumptions!$C$38*'Fcst IS'!B2/Assumptions!$D$37*Assumptions!$E$39 -> 2.2017852 | E3: =Assumptions!$D$41 -> 0.35 | F3: 7.5% through-cycle margin × FY26E revenue × 6–9× — Driver-Ledger logged
A4: Relative EV/EBITDA (FY27E) | B4: =(Assumptions!$C$40*'Fcst IS'!C8-5999.5-1)/Assumptions!$D$37 -> 0.24743159 | C4: =(Assumptions!$D$40*'Fcst IS'!C8-5999.5-1)/Assumptions!$D$37 -> 0.79997029 | D4: =(Assumptions!$E$40*'Fcst IS'!C8-5999.5-1)/Assumptions!$D$37 -> 1.352509 | E4: =Assumptions!$E$41 -> 0.3 | F4: 4.5–6.5× FY27E EBITDA − FY27E net debt 5999 — logged
A5: Weighted central | B5: =SUMPRODUCT(B2:B4,$E$2:$E$4) -> 0.58797936 | C5: =SUMPRODUCT(C2:C4,$E$2:$E$4) -> 0.88217844 | D5: =SUMPRODUCT(D2:D4,$E$2:$E$4) -> 1.1982106 | E5: =SUM(E2:E4) -> 1 | F5: weights must sum to 100%
A7: Spot 1.94 sits above the bull central — at today's sourced cost of capital. The easing-path DCF (20.5% WACC: -0.17) and the market-implied WACC (13.0%) are the dual-framed reads of what the market is paying for; they are deliberately NOT blended into the central.

Sheet Monte Carlo
A1: Item | B1: Value | D1: Percentile | E1: T+20 | F1: T+60
A2: Engine | B2: carry-anchored YZ-HAR-t, nu=4.0 width_cal=0.972 (live EG pooled fit), 50k paths, seed 42 | D2: 5th | E2: 1.6526411 | F2: 1.5000682
A3: Carry (60 sessions) = ln(1+19.5%)×60/252 | B3: =LN(1+0.195)*60/252 -> 0.042415758 | D3: 25th | E3: 1.8530757 | F3: 1.8243897
A4: Event-ledger drift per quarter (external only) | B4: -0.00055 | D4: 50th | E4: 1.9677633 | F4: 2.0238245
A5: q (dividend yield) — sourced default 0 | B5: 0 | D5: 75th | E5: 2.0906215 | F5: 2.247496
A6: Independence note | B6: the fundamental value gap of the study's Sec.1 does not enter the drift | D6: 95th | E6: 2.3445223 | F6: 2.7340419
A8: Probability read | D8: carry-only (ledger-grade)
A9: P(above spot at T+60) | B9: 0.61136 | D9: 5th | E9: 1.6787586 | F9: 1.5006866
A10: P(≥+10%) vs P(≤−10%) | B10: 36.4% vs 17.7% → odds 2.05 | D10: 25th | E10: 1.8611126 | F10: 1.8253179
A11: Median (move) | B11: 2.02 (+4.3%) | D11: 50th | E11: 1.9675472 | F11: 2.0251872
A12: 50% band | B12: 1.82–2.25 (-6.0%/+15.9%) | D12: 75th | E12: 2.0806206 | F12: 2.2477209
A13: Touch ±10% within T+60 | B13: up 58% / down 37% | D13: 95th | E13: 2.3128265 | F13: 2.7265183
A15: Level-touch ladder | F15: Discrete events (P, impact)
A16: Level | B16: vs spot | C16: P(touch T+20) | D16: P(touch T+60) | F16: H1-2026 results release (~Sep) | G16: 0.85 | H16: -0.004
A17: 2.4 | B17: 0.2371134 | C17: 0.05662 | D17: 0.24042 | F17: CBE cut >=100bp (Aug/Oct MPC) | G17: 0.55 | H17: 0.008
A18: 2.3 | B18: 0.18556701 | C18: 0.10092 | D18: 0.3381 | F18: EGP step-slide >=5% (serial-deval regime) | G18: 0.15 | H18: 0.01
A19: 2.2 | B19: 0.13402062 | C19: 0.19108 | D19: 0.47324 | F19: Helwan land MoU final contracts/registration | G19: 0.5 | H19: 0.004
A20: 2.1 | B20: 0.082474227 | C20: 0.37432 | D20: 0.64844 | F20: New export client / capacity announcement | G20: 0.35 | H20: 0.006
A21: 2 | B21: 0.030927835 | C21: 0.68812 | D21: 0.84502 | F21: FY26 dividend initiation signalled | G21: 0.15 | H21: 0.006
A22: 1.9 | B22: -0.020618557 | C22: 0.6679 | D22: 0.77516 | F22: US tariff regime turns against Egypt | G22: 0.15 | H22: -0.012
A23: 1.8 | B23: -0.072164948 | C23: 0.3003 | D23: 0.487 | F23: Regional / Red Sea re-escalation | G23: 0.25 | H23: -0.01
A24: 1.7 | B24: -0.12371134 | C24: 0.12676 | D24: 0.29192 | F24: Equity raise to fund working capital | G24: 0.25 | H24: -0.015
A25: 1.6 | B25: -0.17525773 | C25: 0.05352 | D25: 0.17024

Sheet Technicals
A1: Indicator | B1: Value | C1: Reading
A2: Price vs SMA 20 / 50 | B2: 1.80 / 1.83 | C2: above both — July rebound intact
A3: Price vs SMA 100 / 200 | B3: 1.82 / 1.79 | C3: above both — stack reclaimed
A4: RSI (14) | B4: 70 | C4: overbought band — the rebound is extended
A5: MACD (12,26,9) | B5: 0.0221 / -0.0005 / +0.0226 | C5: fresh positive cross
A6: 52-week range | B6: 1.45 – 2.23 | C6: spot 1.94 sits 63% up the range
A7: Moves 20d / 60d / 252d | B7: +5.4% / -4.4% / -10.5% | C7: a rebound inside a down year
A8: Realised vol (252d) | B8: 32.4% | C8: small-cap EGX regime

Sheet Per-Share & Ratios
A1: Standardized ratio dashboard (EFG device A-5) — fixed panel, identical across studies. Values computed in compute-layer from study_numbers.json; FY23 partial (pre-detail history).
B3: FY23 | C3: FY24 | D3: FY25 | E3: FY26E | F3: FY27E | G3: FY28E | H3: FY29E | I3: FY30E
A4: Revenue (EGP mn) | B4: 3431.7073 | C4: 5768.7 | D4: 7129.7 | E4: 8741.9027 | F4: 10235.985 | G4: 11692.843 | H4: 13070.802 | I4: 14462.102
A5: EPS (EGP, bonus-adj 2,680mn sh) | B5: 0.16708955 | C5: 0.33618657 | D5: 0.13677239 | E5: 0.035605045 | F5: 0.13643944 | G5: 0.23317387 | H5: 0.32604231 | I5: 0.40395876
A6: BVPS (EGP) | B6: 0.38615672 | C6: 0.46947761 | D6: 0.59761194 | E6: 0.63327654 | F6: 0.76980122 | G6: 1.0031208 | H6: 1.3293668 | I6: 1.7335779
A7: Gross margin % | B7: 0.2977897 | C7: 0.34012863 | D7: 0.25167959 | E7: 0.225 | F7: 0.245 | G7: 0.255 | H7: 0.26 | I7: 0.26
A8: EBITDA margin % | B8: 0.24341523 | C8: 0.27657531 | D8: 0.15232057 | E8: 0.12276183 | F8: 0.14466645 | G8: 0.15761381 | H8: 0.16557767 | I8: 0.16755446
A9: Net margin % | B9: 0.13048898 | C9: 0.15618424 | D9: 0.0514117 | E9: 0.010915418 | F9: 0.035722764 | G9: 0.053443461 | H9: 0.066850786 | I9: 0.074858374
A10: ROIC % | B10: — | C10: 0.39421784 | D10: 0.15906898 | E10: 0.098970864 | F10: 0.11938913 | G10: 0.13327029 | H10: 0.14312433 | I10: 0.14834275
A11: Net debt (EGP mn) | B11: — | C11: — | D11: 3967.2 | E11: 5290.956 | F11: 5999.4879 | G11: 6360.434 | H11: 6378.2671 | I11: 6112.2008
A12: Net debt / EBITDA × | B12: — | C12: — | D12: 3.6530387 | E12: 4.9302034 | F12: 4.0515079 | G12: 3.4512177 | H12: 2.947126 | I12: 2.5223781
A13: EBIT interest cover × | B13: — | C13: — | D13: 1.7861635 | E13: 1.2072491 | F13: 1.6785933 | G13: 2.1635426 | H13: 2.7090254 | I13: 3.2611731
A14: Operating cash flow (EGP mn) | B14: — | C14: — | D14: -718.9 | E14: -478.25196 | F14: 66.797631 | G14: 375.68298 | H14: 681.79029 | I14: 930.6332
A15: OCF / Net income × | B15: — | C15: — | D15: -1.9612604 | E15: -5.0119926 | F15: 0.18267804 | G15: 0.60118321 | H15: 0.78026488 | I15: 0.85962041
A16: Capex (EGP mn) | B16: — | C16: 76.3 | D16: 580.8 | E16: 800 | F16: 700 | G16: 650 | H16: 600 | I16: 550
A17: FCFF (EGP mn) | B17: — | C17: — | D17: — | E17: -682.11113 | F17: -36.507037 | G17: 306.32245 | H17: 630.24566 | I17: 893.24681
A18: FCFF / share (EGP) | B18: — | C18: — | D18: — | E18: -0.25451908 | F18: -0.013622029 | G18: 0.11429942 | H18: 0.23516629 | I18: 0.33330105
A19: Inventory days | B19: — | C19: — | D19: 201.89146 | E19: 190 | F19: 180 | G19: 172 | H19: 166 | I19: 160
A20: Cash conversion cycle (days) | B20: — | C20: — | D20: 247.67138 | E20: — | F20: — | G20: — | H20: — | I20: —
A22: Notes: FY23 from the FY24 release comparatives; historical ROIC/CCC per the study text; forecast inventory days from the model working-capital block (202 -> 160 normalisation).

Sheet Sweep & QC
A1: Information Sweep (Step 2A) — four rings closed; full register ships as dscw_sweep_register.json. QC gate v2.3 table lives in the delivery message and the study.
A3: Ring | B3: Category | C3: Finding
A4: Global | B4: Rates/FX/commodities | C4: Fed 3.63% (TE); cotton ICE Oct ~79c 18-Jun-26, USDA 26/27 ~90c world (COGS headwind); Brent contained
A5: Country | B5: Sovereign/monetary | C5: CBE 19.50% since 2-Apr-26; Egypt 10Y 22.55% (3-Jul-26); EGP 48→52.9 Feb-Mar-26 slide, TE 12-mo ~51.7-52.8
A6: Country | B6: Trade regime | C6: US 10% tariff on Egypt vs ~20% on competitors (hgi.io Apr-26) — the priced advantage and its reversal risk
A7: Industry | B7: Demand | C7: Egypt RMG exports Jan-Apr-26 $1.15bn +15% (AEC via DailyNewsEgypt 8-Jun-26); 2026 target $4.4bn
A8: Company | B8: FY2025 release | C8: dice.eg — the FS base of this model; segments, volumes, capacity, land purchases, CBE-cut table
A9: Company | B9: Q1-2026 | C9: EGX filing via Arab Finance/Zawya: rev 1,709 (+19.6%), net loss −159.7 — the FY26E stress, colour not base
A10: Company | B10: Ownership | C10: Sep-2023 preliminary MTO (Toma consortium, 90% at 0.65) lapsed; ESIH 8.06% (Jan-21); family control; FY25 bonus 1.787→2.68bn sh
A11: Negative searches (dated 19-Jul-26) | C11: Q1-26 release on dice.eg: NOT FOUND (press print used, flagged) · FX-denominated debt: none disclosed · named new EGX-listed entrant: none · technology substitution: none material
A13: Peer snapshot — KABO (closest product comp; both make knitted underwear; FY-Jun, flagged)
A14: Revenue | B14: ~1,020 FY-Jun-24 (+72.5%); TTM Dec-24 ~1,130 | C14: DSCW 7,130 CY25 — ~6x scale
A15: Margins | B15: GPM ~16.1% / NPM 1.8% (from 14.7%) | C15: DSCW 25.2% / 5.1% — same collapse pattern, sectoral evidence
A16: Market cap / trailing P/E | B16: ~3,350 at ~108x (price 5.94, retrieved 19-Jul-26) | C16: asset play: Alexandria land + 26.55% Spinalex — NOT an earnings anchor
A17: Dividend / capacity move | B17: never paid / Dec-25 export-lines expansion announced | C17: register: INDUSTRY named-competitor finding
A19: Quarterly record (H1-25 earnings release dice.eg 19-Jul-26 + EGX filings as carried; derived = differencing official period totals) | E19: derivation check ->
A20: Q1-2024 | B20: rev 993.4 | NP +119.2 (der.) | NPM 12.0% | GPM 30.4% | net int (54.4) | C20: company Q1-25 release prints rev/GPM directly | E20: 485.8 | F20: 366.6 | G20: =E20-F20 -> 119.2
A21: Q2-2024 | B21: rev 1,390.7 | NP +366.6 | NPM 26.4% | GPM 44.0% | net int (77.2) | C21: the devaluation-windfall peak
A22: Q3-2024 | B22: rev 1,668.1 | NP +318.9 | NPM 19.1% | GPM 33.8% | C22: 9M-24 release + wire
A23: Q4-2024 | B23: rev 1,716.5 (der.) | NP +96.3 (der.) | NPM 5.6% | C23: decay already underway | E23: 900.98 | F23: 804.72 | G23: =E23-F23 -> 96.26
A24: Q1-2025 | B24: rev 1,429.1 | NP +90.5 att | NPM 6.3% | GPM 24.7% | net int (104.6) | C24: Q1 again profitable — no Q1-loss seasonality
A25: Q2-2025 | B25: rev 1,754.9 | NP +101.5 | NPM 5.8% | GPM 26.0% | net int (126.0) | C25: margin ~26% plateau
A26: Q3-2025 | B26: rev 1,946.0 (der.) | NP +109.6 | NPM 5.6% | C26: 9M-25 wire: 9M NP 301.66 ties Q1+Q2+Q3 exactly | E26: 301.66 | F26: 192.07 | G26: =E26-F26 -> 109.59
A27: Q4-2025 | B27: rev 1,999.7 (der.) | NP +64.9 (der.) | NPM 3.2% | C27: weakest pre-loss quarter — the slide accelerating | E27: 366.551 | F27: 301.66 | G27: =E27-F27 -> 64.891
A28: Q1-2026 | B28: rev 1,709.0 | NP (159.7) att | NPM -9.3% | C28: first non-pandemic loss quarter — trend, not season
A29: H1-25 cash (official) | B29: CFO (609.1); capex+PUC ~(129.5); FCF ~(738.6) | H1-24 CFO (602.5) | C29: burn predates the loss quarter; Q1-26 CF not carried
