Workbook

Sheet READ FIRST
A1: READ FIRST — Testahil · Independent Valuation Study — Educational Analysis
A3: This workbook accompanies the Edita Food Industries (EGX: EFID) independent valuation study dated 03 July 2026. It is an educational analysis, not investment advice, not a recommendation, and it contains no rating or price target.
A5: How to use it: all inputs live on the 'Assumptions' sheet as blue cells. Every downstream sheet links back to that single input layer, so changing one input (e.g. WACC, terminal growth, a segment growth rate or a target multiple) reprices the whole model. Black cells are formulas; green cells are cross-sheet links; yellow-shaded cells are Testahil estimates where the company has not disclosed the line, with the method noted in a cell comment.
A7: Structure: Summary -> Fundamental Valuation (five lenses) -> Assumptions -> FCFF Valuation (primary lens) -> Segments -> Relative & Normalized -> DCF -> Income Statement -> Balance Sheet -> Cash Flow -> Summary Financials -> Monte Carlo -> Sensitivity -> Per-Share & Ratios -> Peer & Sector.
A9: Sources: Edita earnings releases FY2023-FY2025 and 1Q2026 (IFRS management accounts), EGX disclosures via Mubasher, african-markets.com for share count. Each hardcoded figure carries its source and as-of date in a cell comment.
A11: The Monte Carlo sheet reports the mc_v2 (YZ-HAR, Student-t5, drift OFF for this asset class) simulation of 03-Jul-2026, seed 42, 50,000 paths. The paths diffuse from spot; the Section-1 fundamental value gap is deliberately kept out of the drift.
A13: Prepared by Testahil (testahil.com). The preparer is not licensed by the Egyptian Financial Regulatory Authority. The preparer may hold, and may in the future take or dispose of, a position in the security discussed in this report.

Sheet Summary
A1: Summary — Edita Food Industries (EGX: EFID) · 03-Jul-2026
A3: Anchor
A4: Spot (EGP) | B4: =Assumptions!B5 -> 27.34
A5: Shares (m) | B5: =Assumptions!B7 -> 1400.04
A6: Market cap (EGP m) | B6: =Assumptions!B5*Assumptions!B7 -> 38277.094
A7: Net cash (EGP m) | B7: =Assumptions!B8 -> 853.3
A8: Enterprise value (EGP m) | B8: =B6-B7 -> 37423.794
A10: Fair value
A11: Weighted fair value (EGP/share) | B11: ='Fundamental Valuation'!D9 -> 27.682327
A12: Upside vs spot | B12: ='Fundamental Valuation'!D11 -> 0.012521105
A13: DCF (primary lens) | B13: =DCF!B24 -> 29.73839
A14: Bear / Bull (FCFF scenarios) | B14: ='FCFF Valuation'!B19 -> 16.405015 | C14: ='FCFF Valuation'!B27 -> 42.7793
A16: Monte Carlo (T+60, from spot — value gap not in drift)
A17: Median | B17: ='Monte Carlo'!D7 -> 27.82
A18: 50% band (P25–P75) | B18: ='Monte Carlo'!C7 -> 24.4 | C18: ='Monte Carlo'!E7 -> 31.65
A19: 90% band (P5–P95) | B19: ='Monte Carlo'!B7 -> 19.4 | C19: ='Monte Carlo'!F7 -> 38.98
A20: P(above spot at T+60) | B20: 0.5358
A22: Verdict (educational, not advice)
A23: Quality compounder at a full-ish price: the weighted fair value sits modestly above spot, driven by a 30%-growth FY2026E and sustained ~19% EBITDA margins. The re-rating since 2022 has already captured most of the devaluation-repricing story; from here the case rests on volume-led growth, margin durability and the cash pile. Step 0: PASS (CRPS skill +1.6% vs zero-drift RW, drift OFF).

Sheet Fundamental Valuation
A1: Fundamental Valuation — five lenses, one weighted fair value (EGP/share)
A3: Lens | B3: Value | C3: Weight | D3: Contribution | E3: Low | F3: High
A4: DCF (FCFF) | B4: =DCF!B24 -> 29.73839 | C4: =Assumptions!B41 -> 0.35 | D4: =B4*C4 -> 10.408437 | E4: ='FCFF Valuation'!B19 -> 16.405015 | F4: ='FCFF Valuation'!B27 -> 42.7793
A5: Relative multiples | B5: ='Relative & Normalized'!B20 -> 29.09313 | C5: =Assumptions!B42 -> 0.25 | D5: =B5*C5 -> 7.2732824 | E5: =B5*0.85 -> 24.72916 | F5: =B5*1.15 -> 33.457099
A6: Normalized earnings power | B6: ='Relative & Normalized'!B28 -> 26.703338 | C6: =Assumptions!B43 -> 0.2 | D6: =B6*C6 -> 5.3406676 | E6: =B6*0.85 -> 22.697837 | F6: =B6*1.15 -> 30.708839
A7: Segment GP build | B7: =Segments!B20 -> 30.087158 | C7: =Assumptions!B44 -> 0.1 | D7: =B7*C7 -> 3.0087158 | E7: =B7*0.9 -> 27.078442 | F7: =B7*1.1 -> 33.095874
A8: DDM | B8: ='Relative & Normalized'!B34 -> 16.512246 | C8: =Assumptions!B45 -> 0.1 | D8: =B8*C8 -> 1.6512246 | E8: =B8*0.85 -> 14.035409 | F8: =B8*1.15 -> 18.989083
A9: Weighted fair value | D9: =SUM(D4:D8) -> 27.682327
A10: Spot | D10: =Assumptions!B5 -> 27.34
A11: Upside / (downside) | D11: =D9/D10-1 -> 0.012521105
A13: Low/High per lens feed the football field in the study; DCF low/high are the bear/bull scenarios.

Sheet Assumptions
A1: Assumptions — the single input layer
A2: All blue cells are inputs. Every other sheet links here.
A4: ANCHORS
A5: Spot price (EGP/share) | B5: 27.34
A6: Anchor date | B6: 01-Jul-2026
A7: Shares outstanding (m) | B7: 1400.04
A8: Net cash (EGP m, 31-Mar-2026) | B8: 853.3
A9: EGP/USD (indicative) | B9: 48
A11: WACC BUILD
A12: Risk-free rate (EGP 10-yr) | B12: 0.165
A13: Equity risk premium | B13: 0.07
A14: Beta | B14: 0.7
A15: Cost of debt (pre-tax) | B15: 0.19
A16: Debt weight | B16: 0.1
A17: Tax rate | B17: 0.265
A18: Cost of equity | B18: =B12+B14*B13 -> 0.214
A19: WACC | B19: =(1-B16)*B18+B16*B15*(1-B17) -> 0.206565
A20: Terminal growth (nominal EGP) | B20: 0.135
A22: DCF DRIVERS
B23: FY2026E | C23: FY2027E | D23: FY2028E | E23: FY2029E | F23: FY2030E
A24: Revenue growth | B24: 0.3 | C24: 0.22 | D24: 0.18 | E24: 0.15 | F24: 0.13
A25: EBITDA margin | B25: 0.192 | C25: 0.194 | D25: 0.195 | E25: 0.195 | F25: 0.195
A26: D&A % of revenue | B26: 0.026 | C26: 0.026 | D26: 0.026 | E26: 0.027 | F26: 0.027
A27: Capex % of revenue | B27: 0.065 | C27: 0.06 | D27: 0.055 | E27: 0.05 | F27: 0.05
A28: Gross margin | B28: 0.34 | C28: 0.342 | D28: 0.343 | E28: 0.343 | F28: 0.343
A29: Net finance income (EGP m) | B29: 700 | C29: 650 | D29: 600 | E29: 600 | F29: 650
A30: Change in NWC (% of Δ revenue) | B30: 0.02
A31: Dividend payout ratio | B31: 0.45
A33: RELATIVE & NORMALIZED
A34: Target P/E (x FY2026E EPS) | B34: 11.5
A35: Target EV/EBITDA (x FY2026E) | B35: 7
A36: Target EV/Gross profit (x FY2026E) | B36: 4.4
A37: Mid-cycle net margin (normalized) | B37: 0.11
A38: Justified P/E on normalized EPS | B38: 12.5
A40: SYNTHESIS WEIGHTS
A41: DCF (FCFF) | B41: 0.35
A42: Relative multiples | B42: 0.25
A43: Normalized earnings power | B43: 0.2
A44: Segment GP build | B44: 0.1
A45: DDM | B45: 0.1
...

Sheet FCFF Valuation
A1: FCFF Valuation — primary lens (EGP)
A3: Base case — bridge from the DCF sheet
A4: PV of explicit FCFF (EGP m) | B4: =DCF!B17 -> 9808.7194
A5: PV of terminal value | B5: =DCF!B19 -> 30972.917
A6: Enterprise value | B6: =DCF!B20 -> 40781.636
A7: + Net cash | B7: =DCF!B21 -> 853.3
A8: Equity value | B8: =DCF!B22 -> 41634.936
A9: Fair value per share (EGP) | B9: =DCF!B24 -> 29.73839
A10: Upside vs spot | B10: =B9/Assumptions!$B$5-1 -> 0.08772459
A11: Implied FY2026E P/E (x) | B11: =B9/('Income Statement'!E17/Assumptions!$B$7) -> 10.865331
A12: Implied FY2026E EV/EBITDA (x) | B12: =B6/'Income Statement'!E10 -> 7.8119619
A15: Scenarios — bear / base / bull
B16: FY2026E | C16: FY2027E | D16: FY2028E | E16: FY2029E | F16: FY2030E
A17: Bear — Revenue | B17: =20915.1*(1+Assumptions!B$24+Assumptions!$B$56) -> 26143.875 | C17: =B17*(1+Assumptions!C$24+Assumptions!$B$56) -> 30588.334 | D17: =C17*(1+Assumptions!D$24+Assumptions!$B$56) -> 34564.817 | E17: =D17*(1+Assumptions!E$24+Assumptions!$B$56) -> 38021.299 | F17: =E17*(1+Assumptions!F$24+Assumptions!$B$56) -> 41063.003
A18: Bear — FCFF | B18: =(B17*Assumptions!$C$56-B17*Assumptions!B$26)*(1-Assumptions!$B$17)+B17*Assumptions!B$26-B17*Assumptions!B$27-(B17-20915.1)*Assumptions!$B$30 -> 1835.0386 | C18: =(C17*Assumptions!$C$56-C17*Assumptions!C$26)*(1-Assumptions!$B$17)+C17*Assumptions!C$26-C17*Assumptions!C$27-(C17-B17)*Assumptions!$B$30 -> 2333.401 | D18: =(D17*Assumptions!$C$56-D17*Assumptions!D$26)*(1-Assumptions!$B$17)+D17*Assumptions!D$26-D17*Assumptions!D$27-(D17-C17)*Assumptions!$B$30 -> 2830.4823 | E18: =(E17*Assumptions!$C$56-E17*Assumptions!E$26)*(1-Assumptions!$B$17)+E17*Assumptions!E$26-E17*Assumptions!E$27-(E17-D17)*Assumptions!$B$30 -> 3332.0657 | F18: =(F17*Assumptions!$C$56-F17*Assumptions!F$26)*(1-Assumptions!$B$17)+F17*Assumptions!F$26-F17*Assumptions!F$27-(F17-E17)*Assumptions!$B$30 -> 3612.4568
A19: Bear — fair value per share | B19: =((B18/(1+Assumptions!$D$56)^1+C18/(1+Assumptions!$D$56)^2+D18/(1+Assumptions!$D$56)^3+E18/(1+Assumptions!$D$56)^4+F18/(1+Assumptions!$D$56)^5)+F18*(1+Assumptions!$E$56)/(Assumptions!$D$56-Assumptions!$E$56)/(1+Assumptions!$D$56)^5+Assumptions!$B$8)/Assumptions!$B$7 -> 16.405015
A21: Base — Revenue | B21: =DCF!B4 -> 27189.63 | C21: =DCF!C4 -> 33171.349 | D21: =DCF!D4 -> 39142.191 | E21: =DCF!E4 -> 45013.52 | F21: =DCF!F4 -> 50865.278
A22: Base — FCFF | B22: =DCF!B13 -> 2131.5206 | C22: =DCF!C13 -> 2848.5379 | D22: =DCF!D13 -> 3607.5069 | E22: =DCF!E13 -> 4405.5319 | F22: =DCF!F13 -> 4993.9079
A23: Base — fair value per share | B23: =((B22/(1+Assumptions!$B$19)^1+C22/(1+Assumptions!$B$19)^2+D22/(1+Assumptions!$B$19)^3+E22/(1+Assumptions!$B$19)^4+F22/(1+Assumptions!$B$19)^5)+F22*(1+Assumptions!$B$20)/(Assumptions!$B$19-Assumptions!$B$20)/(1+Assumptions!$B$19)^5+Assumptions!$B$8)/Assumptions!$B$7 -> 29.73839
A25: Bull — Revenue | B25: =20915.1*(1+Assumptions!B$24+Assumptions!$B$57) -> 28026.234 | C25: =B25*(1+Assumptions!C$24+Assumptions!$B$57) -> 35313.055 | D25: =C25*(1+Assumptions!D$24+Assumptions!$B$57) -> 43081.927 | E25: =D25*(1+Assumptions!E$24+Assumptions!$B$57) -> 51267.493 | F25: =E25*(1+Assumptions!F$24+Assumptions!$B$57) -> 59982.967
A26: Bull — FCFF | B26: =(B25*Assumptions!$C$57-B25*Assumptions!B$26)*(1-Assumptions!$B$17)+B25*Assumptions!B$26-B25*Assumptions!B$27-(B25-20915.1)*Assumptions!$B$30 -> 2452.0257 | C26: =(C25*Assumptions!$C$57-C25*Assumptions!C$26)*(1-Assumptions!$B$17)+C25*Assumptions!C$26-C25*Assumptions!C$27-(C25-B25)*Assumptions!$B$30 -> 3299.5818 | D26: =(D25*Assumptions!$C$57-D25*Assumptions!D$26)*(1-Assumptions!$B$17)+D25*Assumptions!D$26-D25*Assumptions!D$27-(D25-C25)*Assumptions!$B$30 -> 4263.3204 | E26: =(E25*Assumptions!$C$57-E25*Assumptions!E$26)*(1-Assumptions!$B$17)+E25*Assumptions!E$26-E25*Assumptions!E$27-(E25-D25)*Assumptions!$B$30 -> 5364.4624 | F26: =(F25*Assumptions!$C$57-F25*Assumptions!F$26)*(1-Assumptions!$B$17)+F25*Assumptions!F$26-F25*Assumptions!F$27-(F25-E25)*Assumptions!$B$30 -> 6293.6538
A27: Bull — fair value per share | B27: =((B26/(1+Assumptions!$D$57)^1+C26/(1+Assumptions!$D$57)^2+D26/(1+Assumptions!$D$57)^3+E26/(1+Assumptions!$D$57)^4+F26/(1+Assumptions!$D$57)^5)+F26*(1+Assumptions!$E$57)/(Assumptions!$D$57-Assumptions!$E$57)/(1+Assumptions!$D$57)^5+Assumptions!$B$8)/Assumptions!$B$7 -> 42.7793
A30: Bear/Bull re-run the FCFF engine with the scenario growth delta, EBITDA margin, WACC and terminal g from the Assumptions scenario block; capex, D&A and NWC intensities are held at base.

Sheet Segments
A1: Segments — revenue & gross profit by category (EGP m)
A3: Segment | B3: FY23 Rev | C3: FY23 GP | D3: FY24 Rev | E3: FY24 GP | F3: FY25 Rev | G3: FY25 GP | H3: FY25 GPM | I3: FY26E growth | J3: FY26E GPM | K3: FY26E Rev | L3: FY26E GP
A4: Cakes | B4: 6032.5 | C4: 2122.4 | D4: 8272.2 | E4: 2744.2 | F4: 10855.6 | G4: 3974 | H4: =G4/F4 -> 0.36607834 | I4: 0.27 | J4: 0.37 | K4: =F4*(1+I4) -> 13786.612 | L4: =K4*J4 -> 5101.0464
A5: Bakery (croissants & pate) | B5: 4066.6 | C5: 1211 | D5: 4657.4 | E5: 1313 | F5: 5885.4 | G5: 1968.6 | H5: =G5/F5 -> 0.33448873 | I5: 0.38 | J5: 0.335 | K5: =F5*(1+I5) -> 8121.852 | L5: =K5*J5 -> 2720.8204
A6: Wafers | B6: 1079 | C6: 350.2 | D6: 1734.8 | E6: 514.9 | F6: 2018.6 | G6: 626.5 | H6: =G6/F6 -> 0.31036362 | I6: 0.22 | J6: 0.315 | K6: =F6*(1+I6) -> 2462.692 | L6: =K6*J6 -> 775.74798
A7: Rusks | B7: 545 | C7: 153.3 | D7: 726.8 | E7: 175.2 | F7: 1084.7 | G7: 324.2 | H7: =G7/F7 -> 0.29888448 | I7: 0.4 | J7: 0.31 | K7: =F7*(1+I7) -> 1518.58 | L7: =K7*J7 -> 470.7598
A8: Candy | B8: 307.7 | C8: 86.6 | D8: 484.8 | E8: 142.6 | F8: 558 | G8: 151.1 | H8: =G8/F8 -> 0.27078853 | I8: 0.18 | J8: 0.285 | K8: =F8*(1+I8) -> 658.44 | L8: =K8*J8 -> 187.6554
A9: Biscuits | B9: 80.1 | C9: 14.6 | D9: 195.9 | E9: 35.9 | F9: 343.5 | G9: 74.9 | H9: =G9/F9 -> 0.21804949 | I9: 0.45 | J9: 0.245 | K9: =F9*(1+I9) -> 498.075 | L9: =K9*J9 -> 122.02837
A10: Frozen | B10: 14.9 | C10: -12.9 | D10: 72.3 | E10: -20 | F10: 62.2 | G10: -49.8 | H10: =G10/F10 -> -0.80064309 | I10: 0.3 | J10: -0.3 | K10: =F10*(1+I10) -> 80.86 | L10: =K10*J10 -> -24.258
A11: Raw chips & other | B11: 0 | C11: 0 | D11: 2.4 | E11: 0.4 | F11: 107.2 | G11: 16.2 | H11: =G11/F11 -> 0.1511194 | I11: 0.6 | J11: 0.15 | K11: =F11*(1+I11) -> 171.52 | L11: =K11*J11 -> 25.728
A12: Total | B12: =SUM(B4:B11) -> 12125.8 | C12: =SUM(C4:C11) -> 3925.2 | D12: =SUM(D4:D11) -> 16146.6 | E12: =SUM(E4:E11) -> 4906.2 | F12: =SUM(F4:F11) -> 20915.2 | G12: =SUM(G4:G11) -> 7085.7 | H12: =G12/F12 -> 0.33878232 | I12: =K12/F12-1 -> 0.30520535 | J12: =L12/K12 -> 0.3435897 | K12: =SUM(K4:K11) -> 27298.631 | L12: =SUM(L4:L11) -> 9379.5284
A14: Segment gross-profit build (cross-check lens)
A15: FY2026E group gross profit (EGP m) | B15: =L12 -> 9379.5284
A16: Target EV / gross profit (x) | B16: =Assumptions!$B$36 -> 4.4
A17: Implied enterprise value | B17: =B15*B16 -> 41269.925
A18: + Net cash | B18: =Assumptions!$B$8 -> 853.3
A19: Equity value | B19: =B17+B18 -> 42123.225
A20: Segment-build value per share (EGP) | B20: =B19/Assumptions!$B$7 -> 30.087158

Sheet Relative & Normalized
A1: Relative multiples, normalized earnings power, DDM (EGP)
A3: Peer multiples (Testahil estimates from public data, Jul-2026)
A4: Peer | B4: Mkt | C4: P/E (fwd) | D4: EV/EBITDA (fwd)
A5: Juhayna (JUFO) | B5: EGX | C5: 10.5 | D5: 6
A6: Obour Land (OLFI) | B6: EGX | C6: 8 | D6: 4.5
A7: Domty (DOMT) | B7: EGX | C7: 7.5 | D7: 5
A8: Eastern Company (EAST) | B8: EGX | C8: 7 | D8: 5.5
A9: Almarai (2280.SE) | B9: Tadawul | C9: 21 | D9: 12
A10: Edita (EFID) at spot | B10: EGX | C10: =Assumptions!$B$5/('Income Statement'!E17/Assumptions!$B$7) -> 9.9890462 | D10: =(Assumptions!$B$5*Assumptions!$B$7-Assumptions!$B$8)/'Income Statement'!E10 -> 7.1687475
A11: EGX peer median | C11: =MEDIAN(C5:C8) -> 7.75 | D11: =MEDIAN(D5:D8) -> 5.25
A13: Relative valuation
A14: FY2026E EPS (EGP) | B14: ='Income Statement'!E19 -> 2.7369981
A15: Target P/E (x) | B15: =Assumptions!$B$34 -> 11.5
A16: P/E value per share | B16: =B14*B15 -> 31.475478
A17: FY2026E EBITDA (EGP m) | B17: ='Income Statement'!E10 -> 5220.409
A18: Target EV/EBITDA (x) | B18: =Assumptions!$B$35 -> 7
A19: EV/EBITDA value per share | B19: =(B17*B18+Assumptions!$B$8)/Assumptions!$B$7 -> 26.710782
A20: Relative blend (average) | B20: =AVERAGE(B16,B19) -> 29.09313
A22: Normalized earnings power
A23: FY2026E revenue (EGP m) | B23: ='Income Statement'!E4 -> 27189.63
A24: Mid-cycle net margin | B24: =Assumptions!$B$37 -> 0.11
A25: Normalized net profit | B25: =B23*B24 -> 2990.8593
A26: Normalized EPS | B26: =B25/Assumptions!$B$7 -> 2.136267
A27: Justified P/E (x) | B27: =Assumptions!$B$38 -> 12.5
A28: Normalized value per share | B28: =B26*B27 -> 26.703338
A30: DDM sanity (two-stage, Ke discounting)
A31: DPS path FY26E-FY30E (EGP) | B31: ='Income Statement'!E17*Assumptions!$B$31/Assumptions!$B$7 -> 1.2316491 | C31: ='Income Statement'!F17*Assumptions!$B$31/Assumptions!$B$7 -> 1.4700913 | D31: ='Income Statement'!G17*Assumptions!$B$31/Assumptions!$B$7 -> 1.7045022 | E31: ='Income Statement'!H17*Assumptions!$B$31/Assumptions!$B$7 -> 1.9282815 | F31: ='Income Statement'!I17*Assumptions!$B$31/Assumptions!$B$7 -> 2.1723433
A32: PV of dividends | B32: =B31/(1+Assumptions!$B$18)^1+C31/(1+Assumptions!$B$18)^2+D31/(1+Assumptions!$B$18)^3+E31/(1+Assumptions!$B$18)^4+F31/(1+Assumptions!$B$18)^5 -> 4.6762775
A33: Gordon TV on FY2030E DPS | B33: =F31*(1+Assumptions!$B$20)/(Assumptions!$B$18-Assumptions!$B$20)/(1+Assumptions!$B$18)^5 -> 11.835968
A34: DDM value per share | B34: =B32+B33 -> 16.512246

Sheet DCF
A1: DCF — FCFF, five-year explicit forecast (EGP m)
B3: FY2026E | C3: FY2027E | D3: FY2028E | E3: FY2029E | F3: FY2030E
A4: Revenue | B4: ='Income Statement'!E4 -> 27189.63 | C4: ='Income Statement'!F4 -> 33171.349 | D4: ='Income Statement'!G4 -> 39142.191 | E4: ='Income Statement'!H4 -> 45013.52 | F4: ='Income Statement'!I4 -> 50865.278
A5: EBITDA | B5: ='Income Statement'!E10 -> 5220.409 | C5: ='Income Statement'!F10 -> 6435.2416 | D5: ='Income Statement'!G10 -> 7632.7273 | E5: ='Income Statement'!H10 -> 8777.6364 | F5: ='Income Statement'!I10 -> 9918.7291
A6: − D&A | B6: =-'Income Statement'!E12 -> -706.93038 | C6: =-'Income Statement'!F12 -> -862.45506 | D6: =-'Income Statement'!G12 -> -1017.697 | E6: =-'Income Statement'!H12 -> -1215.365 | F6: =-'Income Statement'!I12 -> -1373.3625
A7: EBIT | B7: =B5+B6 -> 4513.4786 | C7: =C5+C6 -> 5572.7866 | D7: =D5+D6 -> 6615.0303 | E7: =E5+E6 -> 7562.2714 | F7: =F5+F6 -> 8545.3666
A8: − Tax on EBIT | B8: =-B7*Assumptions!$B$17 -> -1196.0718 | C8: =-C7*Assumptions!$B$17 -> -1476.7884 | D8: =-D7*Assumptions!$B$17 -> -1752.983 | E8: =-E7*Assumptions!$B$17 -> -2004.0019 | F8: =-F7*Assumptions!$B$17 -> -2264.5222
A9: NOPAT | B9: =B7+B8 -> 3317.4068 | C9: =C7+C8 -> 4095.9981 | D9: =D7+D8 -> 4862.0473 | E9: =E7+E8 -> 5558.2695 | F9: =F7+F8 -> 6280.8445
A10: + D&A | B10: =-B6 -> 706.93038 | C10: =-C6 -> 862.45506 | D10: =-D6 -> 1017.697 | E10: =-E6 -> 1215.365 | F10: =-F6 -> 1373.3625
A11: − Capex | B11: =-B4*Assumptions!B$27 -> -1767.3259 | C11: =-C4*Assumptions!C$27 -> -1990.2809 | D11: =-D4*Assumptions!D$27 -> -2152.8205 | E11: =-E4*Assumptions!E$27 -> -2250.676 | F11: =-F4*Assumptions!F$27 -> -2543.2639
A12: − Δ NWC | B12: =-(B4-'Income Statement'!D4)*Assumptions!$B$30 -> -125.4906 | C12: =-(C4-'Income Statement'!E4)*Assumptions!$B$30 -> -119.63437 | D12: =-(D4-'Income Statement'!F4)*Assumptions!$B$30 -> -119.41685 | E12: =-(E4-'Income Statement'!G4)*Assumptions!$B$30 -> -117.42657 | F12: =-(F4-'Income Statement'!H4)*Assumptions!$B$30 -> -117.03515
A13: FCFF | B13: =SUM(B9:B12) -> 2131.5206 | C13: =SUM(C9:C12) -> 2848.5379 | D13: =SUM(D9:D12) -> 3607.5069 | E13: =SUM(E9:E12) -> 4405.5319 | F13: =SUM(F9:F12) -> 4993.9079
A14: Discount factor | B14: =1/(1+Assumptions!$B$19)^1 -> 0.82879911 | C14: =1/(1+Assumptions!$B$19)^2 -> 0.68690797 | D14: =1/(1+Assumptions!$B$19)^3 -> 0.56930871 | E14: =1/(1+Assumptions!$B$19)^4 -> 0.47184256 | F14: =1/(1+Assumptions!$B$19)^5 -> 0.39106269
A15: PV of FCFF | B15: =B13*B14 -> 1766.6024 | C15: =C13*C14 -> 1956.6834 | D15: =D13*D14 -> 2053.7851 | E15: =E13*E14 -> 2078.7174 | F15: =F13*F14 -> 1952.9311
A17: Sum PV of explicit FCFF | B17: =SUM(B15:F15) -> 9808.7194
A18: Terminal value (Gordon on FY2030E) | B18: =F13*(1+Assumptions!$B$20)/(Assumptions!$B$19-Assumptions!$B$20) -> 79201.922
A19: PV of terminal value | B19: =B18*F14 -> 30972.917
A20: Enterprise value | B20: =B17+B19 -> 40781.636
A21: + Net cash (31-Mar-2026) | B21: =Assumptions!$B$8 -> 853.3
A22: Equity value | B22: =B20+B21 -> 41634.936
A23: Shares outstanding (m) | B23: =Assumptions!$B$7 -> 1400.04
A24: DCF fair value per share (EGP) | B24: =B22/B23 -> 29.73839
A26: TV share of EV | B26: =B19/B20 -> 0.75948195
A27: WACC (links Assumptions) | B27: =Assumptions!B19 -> 0.206565
A28: Terminal growth (links Assumptions) | B28: =Assumptions!B20 -> 0.135

Sheet Income Statement
A1: Income Statement — EGP m (IFRS management accounts)
B3: FY2023A | C3: FY2024A | D3: FY2025A | E3: FY2026E | F3: FY2027E | G3: FY2028E | H3: FY2029E | I3: FY2030E
A4: Revenue | B4: 12125.5 | C4: 16146.5 | D4: 20915.1 | E4: =D4*(1+Assumptions!B$24) -> 27189.63 | F4: =E4*(1+Assumptions!C$24) -> 33171.349 | G4: =F4*(1+Assumptions!D$24) -> 39142.191 | H4: =G4*(1+Assumptions!E$24) -> 45013.52 | I4: =H4*(1+Assumptions!F$24) -> 50865.278
A5: Revenue growth | C5: =C4/B4-1 -> 0.33161519 | D5: =D4/C4-1 -> 0.29533335 | E5: =E4/D4-1 -> 0.3 | F5: =F4/E4-1 -> 0.22 | G5: =G4/F4-1 -> 0.18 | H5: =H4/G4-1 -> 0.15 | I5: =I4/H4-1 -> 0.13
A6: COGS | B6: =B4-B7 -> 8200.2 | C6: =C4-C7 -> 11240.2 | D6: =D4-D7 -> 13829.5 | E6: =E4*(1-Assumptions!B$28) -> 17945.156 | F6: =F4*(1-Assumptions!C$28) -> 21826.747 | G6: =G4*(1-Assumptions!D$28) -> 25716.42 | H6: =H4*(1-Assumptions!E$28) -> 29573.883 | I6: =I4*(1-Assumptions!F$28) -> 33418.487
A7: Gross profit | B7: 3925.3 | C7: 4906.3 | D7: 7085.6 | E7: =E4-E6 -> 9244.4742 | F7: =F4-F6 -> 11344.601 | G7: =G4-G6 -> 13425.772 | H7: =H4-H6 -> 15439.637 | I7: =I4-I6 -> 17446.79
A8: Gross margin | B8: =B7/B4 -> 0.32372273 | C8: =C7/C4 -> 0.30386152 | D8: =D7/D4 -> 0.33877916 | E8: =E7/E4 -> 0.34 | F8: =F7/F4 -> 0.342 | G8: =G7/G4 -> 0.343 | H8: =H7/H4 -> 0.343 | I8: =I7/I4 -> 0.343
A9: SG&A & other opex (net) | B9: =B7-B10 -> 1559.6 | C9: =C7-C10 -> 2368.8 | D9: =D7-D10 -> 3074.5 | E9: =E7-E10 -> 4024.0652 | F9: =F7-F10 -> 4909.3596 | G9: =G7-G10 -> 5793.0443 | H9: =H7-H10 -> 6662.001 | I9: =I7-I10 -> 7528.0611
A10: EBITDA | B10: 2365.7 | C10: 2537.5 | D10: 4011.1 | E10: =E4*Assumptions!B$25 -> 5220.409 | F10: =F4*Assumptions!C$25 -> 6435.2416 | G10: =G4*Assumptions!D$25 -> 7632.7273 | H10: =H4*Assumptions!E$25 -> 8777.6364 | I10: =I4*Assumptions!F$25 -> 9918.7291
A11: EBITDA margin | B11: =B10/B4 -> 0.19510123 | C11: =C10/C4 -> 0.1571548 | D11: =D10/D4 -> 0.1917801 | E11: =E10/E4 -> 0.192 | F11: =F10/F4 -> 0.194 | G11: =G10/G4 -> 0.195 | H11: =H10/H4 -> 0.195 | I11: =I10/I4 -> 0.195
A12: D&A | B12: 330 | C12: 380.2 | D12: 469 | E12: =E4*Assumptions!B$26 -> 706.93038 | F12: =F4*Assumptions!C$26 -> 862.45506 | G12: =G4*Assumptions!D$26 -> 1017.697 | H12: =H4*Assumptions!E$26 -> 1215.365 | I12: =I4*Assumptions!F$26 -> 1373.3625
A13: EBIT | B13: =B10-B12 -> 2035.7 | C13: =C10-C12 -> 2157.3 | D13: =D10-D12 -> 3542.1 | E13: =E10-E12 -> 4513.4786 | F13: =F10-F12 -> 5572.7866 | G13: =G10-G12 -> 6615.0303 | H13: =H10-H12 -> 7562.2714 | I13: =I10-I12 -> 8545.3666
A14: Net finance income/(cost) | B14: -80 | C14: -185.6 | D14: -91.3 | E14: =Assumptions!B$29 -> 700 | F14: =Assumptions!C$29 -> 650 | G14: =Assumptions!D$29 -> 600 | H14: =Assumptions!E$29 -> 600 | I14: =Assumptions!F$29 -> 650
A15: Profit before tax | B15: =B13+B14 -> 1955.7 | C15: =C13+C14 -> 1971.7 | D15: =D13+D14 -> 3450.8 | E15: =E13+E14 -> 5213.4786 | F15: =F13+F14 -> 6222.7866 | G15: =G13+G14 -> 7215.0303 | H15: =H13+H14 -> 8162.2714 | I15: =I13+I14 -> 9195.3666
A16: Income tax | B16: =B15-B17 -> 449.1 | C16: 556.3 | D16: 1008.5 | E16: =E15*Assumptions!$B$17 -> 1381.5718 | F16: =F15*Assumptions!$B$17 -> 1649.0384 | G16: =G15*Assumptions!$B$17 -> 1911.983 | H16: =H15*Assumptions!$B$17 -> 2163.0019 | I16: =I15*Assumptions!$B$17 -> 2436.7722
A17: Net profit (IFRS) | B17: 1506.6 | C17: =C15-C16 -> 1415.4 | D17: =D15-D16 -> 2442.3 | E17: =E15-E16 -> 3831.9068 | F17: =F15-F16 -> 4573.7481 | G17: =G15-G16 -> 5303.0473 | H17: =H15-H16 -> 5999.2695 | I17: =I15-I16 -> 6758.5945
A18: Net margin | B18: =B17/B4 -> 0.12425055 | C18: =C17/C4 -> 0.087659864 | D18: =D17/D4 -> 0.11677209 | E18: =E17/E4 -> 0.14093266 | F18: =F17/F4 -> 0.13788249 | G18: =G17/G4 -> 0.13548161 | H18: =H17/H4 -> 0.13327706 | I18: =I17/I4 -> 0.13287246
A19: EPS (EGP, current shares) | B19: =B17/Assumptions!$B$7 -> 1.0761121 | C19: =C17/Assumptions!$B$7 -> 1.0109711 | D19: =D17/Assumptions!$B$7 -> 1.7444502 | E19: =E17/Assumptions!$B$7 -> 2.7369981 | F19: =F17/Assumptions!$B$7 -> 3.2668696 | G19: =G17/Assumptions!$B$7 -> 3.7877827 | H19: =H17/Assumptions!$B$7 -> 4.28507 | I19: =I17/Assumptions!$B$7 -> 4.8274296
A21: FY2023 D&A and net finance are Testahil estimates (yellow); FY2023 tax is the PBT − reported-NP balancing figure. EPS uses the current 1,400.04m share count across all years for comparability.

Sheet Balance Sheet
A1: Balance Sheet — EGP m
B3: FY2023A | C3: FY2024A | D3: FY2025A | E3: FY2026E | F3: FY2027E | G3: FY2028E | H3: FY2029E | I3: FY2030E
A4: ASSETS
A5: Net PP&E & intangibles | B5: 4540 | C5: 5400 | D5: 6323.8 | E5: =D5+'Income Statement'!E4*Assumptions!B$27-'Income Statement'!E12 -> 7384.1956 | F5: =E5+'Income Statement'!F4*Assumptions!C$27-'Income Statement'!F12 -> 8512.0214 | G5: =F5+'Income Statement'!G4*Assumptions!D$27-'Income Statement'!G12 -> 9647.145 | H5: =G5+'Income Statement'!H4*Assumptions!E$27-'Income Statement'!H12 -> 10682.456 | I5: =H5+'Income Statement'!I4*Assumptions!F$27-'Income Statement'!I12 -> 11852.357
A6: Inventories | B6: 1867 | C6: 3034 | D6: 2315.1 | E6: ='Income Statement'!E4*Assumptions!$B$49 -> 3018.0489 | F6: ='Income Statement'!F4*Assumptions!$B$49 -> 3682.0197 | G6: ='Income Statement'!G4*Assumptions!$B$49 -> 4344.7832 | H6: ='Income Statement'!H4*Assumptions!$B$49 -> 4996.5007 | I6: ='Income Statement'!I4*Assumptions!$B$49 -> 5646.0458
A7: Trade & notes receivable | B7: 159.6 | C7: 174.8 | D7: 243.5 | E7: ='Income Statement'!E4*Assumptions!$B$50 -> 326.27556 | F7: ='Income Statement'!F4*Assumptions!$B$50 -> 398.05618 | G7: ='Income Statement'!G4*Assumptions!$B$50 -> 469.7063 | H7: ='Income Statement'!H4*Assumptions!$B$50 -> 540.16224 | I7: ='Income Statement'!I4*Assumptions!$B$50 -> 610.38333
A8: Other current & non-current assets (est.) | B8: 1000 | C8: 1300 | D8: 1600 | E8: =D8*(1+Assumptions!$B$52) -> 1760 | F8: =E8*(1+Assumptions!$B$52) -> 1936 | G8: =F8*(1+Assumptions!$B$52) -> 2129.6 | H8: =G8*(1+Assumptions!$B$52) -> 2342.56 | I8: =H8*(1+Assumptions!$B$52) -> 2576.816
A9: Cash & equivalents | B9: 1356.3 | C9: 1324.2 | D9: 4741.1 | E9: ='Cash Flow'!E17 -> 5761.9043 | F9: ='Cash Flow'!F17 -> 7117.2011 | G9: ='Cash Flow'!G17 -> 8848.4538 | H9: ='Cash Flow'!H17 -> 11040.693 | I9: ='Cash Flow'!I17 -> 13494.205
A10: Total assets | B10: =SUM(B5:B9) -> 8922.9 | C10: =SUM(C5:C9) -> 11233 | D10: =SUM(D5:D9) -> 15223.5 | E10: =SUM(E5:E9) -> 18250.424 | F10: =SUM(F5:F9) -> 21645.298 | G10: =SUM(G5:G9) -> 25439.688 | H10: =SUM(H5:H9) -> 29602.372 | I10: =SUM(I5:I9) -> 34179.807
A12: LIABILITIES & EQUITY
A13: Loans & borrowings | B13: 2030.5 | C13: 3468.2 | D13: 4474.6 | E13: =D13 -> 4474.6 | F13: =E13 -> 4474.6 | G13: =F13 -> 4474.6 | H13: =G13 -> 4474.6 | I13: =H13 -> 4474.6
A14: Bank overdrafts | B14: 596.7 | C14: 808.4 | D14: 771.4 | E14: =D14 -> 771.4 | F14: =E14 -> 771.4 | G14: =F14 -> 771.4 | H14: =G14 -> 771.4 | I14: =H14 -> 771.4
A15: Payables, provisions & other liabilities | B15: =B10-B13-B14-B17 -> 2495.7 | C15: =C10-C13-C14-C17 -> 1956.4 | D15: =D10-D13-D14-D17 -> 3077.5 | E15: ='Income Statement'!E4*Assumptions!$B$51 -> 3996.8756 | F15: ='Income Statement'!F4*Assumptions!$B$51 -> 4876.1882 | G15: ='Income Statement'!G4*Assumptions!$B$51 -> 5753.9021 | H15: ='Income Statement'!H4*Assumptions!$B$51 -> 6616.9874 | I15: ='Income Statement'!I4*Assumptions!$B$51 -> 7477.1958
A16: Total liabilities | B16: =SUM(B13:B15) -> 5122.9 | C16: =SUM(C13:C15) -> 6233 | D16: =SUM(D13:D15) -> 8323.5 | E16: =SUM(E13:E15) -> 9242.8756 | F16: =SUM(F13:F15) -> 10122.188 | G16: =SUM(G13:G15) -> 10999.902 | H16: =SUM(H13:H15) -> 11862.987 | I16: =SUM(I13:I15) -> 12723.196
A17: Shareholders' equity (incl. minority) | B17: 3800 | C17: 5000 | D17: 6900 | E17: =D17+'Income Statement'!E17+'Cash Flow'!E13 -> 9007.5487 | F17: =E17+'Income Statement'!F17+'Cash Flow'!F13 -> 11523.11 | G17: =F17+'Income Statement'!G17+'Cash Flow'!G13 -> 14439.786 | H17: =G17+'Income Statement'!H17+'Cash Flow'!H13 -> 17739.384 | I17: =H17+'Income Statement'!I17+'Cash Flow'!I13 -> 21456.611
A18: Total liabilities & equity | B18: =B16+B17 -> 8922.9 | C18: =C16+C17 -> 11233 | D18: =D16+D17 -> 15223.5 | E18: =E16+E17 -> 18250.424 | F18: =F16+F17 -> 21645.298 | G18: =G16+G17 -> 25439.688 | H18: =H16+H17 -> 29602.372 | I18: =I16+I17 -> 34179.807
A19: Balance check | B19: =B10-B18 -> 0 | C19: =C10-C18 -> 0 | D19: =D10-D18 -> 0 | E19: =E10-E18 -> 0 | F19: =F10-F18 -> 0 | G19: =G10-G18 -> 0 | H19: =H10-H18 -> 0 | I19: =I10-I18 -> 0
A21: Forecast debt & overdrafts held flat; payables/inventory/receivables scale with revenue; cash closes from the Cash Flow sheet. The balance check must read zero in every column.

Sheet Cash Flow
A1: Cash Flow — EGP m
B3: FY2023A | C3: FY2024A | D3: FY2025A | E3: FY2026E | F3: FY2027E | G3: FY2028E | H3: FY2029E | I3: FY2030E
A4: Net profit | D4: 2442.3 | E4: ='Income Statement'!E17 -> 3831.9068 | F4: ='Income Statement'!F17 -> 4573.7481 | G4: ='Income Statement'!G17 -> 5303.0473 | H4: ='Income Statement'!H17 -> 5999.2695 | I4: ='Income Statement'!I17 -> 6758.5945
A5: + D&A | D5: 469 | E5: ='Income Statement'!E12 -> 706.93038 | F5: ='Income Statement'!F12 -> 862.45506 | G5: ='Income Statement'!G12 -> 1017.697 | H5: ='Income Statement'!H12 -> 1215.365 | I5: ='Income Statement'!I12 -> 1373.3625
A6: − Δ Inventories | D6: =-(2315.1-3034) -> 718.9 | E6: =-('Balance Sheet'!E6-'Balance Sheet'!D6) -> -702.94893 | F6: =-('Balance Sheet'!F6-'Balance Sheet'!E6) -> -663.97076 | G6: =-('Balance Sheet'!G6-'Balance Sheet'!F6) -> -662.76355 | H6: =-('Balance Sheet'!H6-'Balance Sheet'!G6) -> -651.71749 | I6: =-('Balance Sheet'!I6-'Balance Sheet'!H6) -> -649.54509
A7: − Δ Receivables | D7: =-(243.5-174.8) -> -68.7 | E7: =-('Balance Sheet'!E7-'Balance Sheet'!D7) -> -82.77556 | F7: =-('Balance Sheet'!F7-'Balance Sheet'!E7) -> -71.780623 | G7: =-('Balance Sheet'!G7-'Balance Sheet'!F7) -> -71.650113 | H7: =-('Balance Sheet'!H7-'Balance Sheet'!G7) -> -70.455944 | I7: =-('Balance Sheet'!I7-'Balance Sheet'!H7) -> -70.221091
A8: − Δ Other assets | D8: =-(1600-1300) -> -300 | E8: =-('Balance Sheet'!E8-'Balance Sheet'!D8) -> -160 | F8: =-('Balance Sheet'!F8-'Balance Sheet'!E8) -> -176 | G8: =-('Balance Sheet'!G8-'Balance Sheet'!F8) -> -193.6 | H8: =-('Balance Sheet'!H8-'Balance Sheet'!G8) -> -212.96 | I8: =-('Balance Sheet'!I8-'Balance Sheet'!H8) -> -234.256
A9: + Δ Payables & other | D9: =3077.5-1956.4 -> 1121.1 | E9: ='Balance Sheet'!E15-'Balance Sheet'!D15 -> 919.37561 | F9: ='Balance Sheet'!F15-'Balance Sheet'!E15 -> 879.31263 | G9: ='Balance Sheet'!G15-'Balance Sheet'!F15 -> 877.71388 | H9: ='Balance Sheet'!H15-'Balance Sheet'!G15 -> 863.08532 | I9: ='Balance Sheet'!I15-'Balance Sheet'!H15 -> 860.20837
A10: Cash flow from operations | D10: =SUM(D4:D9) -> 4382.6 | E10: =SUM(E4:E9) -> 4512.4883 | F10: =SUM(F4:F9) -> 5403.7644 | G10: =SUM(G4:G9) -> 6270.4445 | H10: =SUM(H4:H9) -> 7142.5864 | I10: =SUM(I4:I9) -> 8038.1432
A11: − Capex | D11: -1392.8 | E11: =-'Income Statement'!E4*Assumptions!B$27 -> -1767.3259 | F11: =-'Income Statement'!F4*Assumptions!C$27 -> -1990.2809 | G11: =-'Income Statement'!G4*Assumptions!D$27 -> -2152.8205 | H11: =-'Income Statement'!H4*Assumptions!E$27 -> -2250.676 | I11: =-'Income Statement'!I4*Assumptions!F$27 -> -2543.2639
A12: Free cash flow | D12: =D10+D11 -> 2989.8 | E12: =E10+E11 -> 2745.1623 | F12: =F10+F11 -> 3413.4835 | G12: =G10+G11 -> 4117.624 | H12: =H10+H11 -> 4891.9104 | I12: =I10+I11 -> 5494.8793
A13: − Dividends paid | D13: -800.1 | E13: =-'Income Statement'!E17*Assumptions!$B$31 -> -1724.358 | F13: =-'Income Statement'!F17*Assumptions!$B$31 -> -2058.1867 | G13: =-'Income Statement'!G17*Assumptions!$B$31 -> -2386.3713 | H13: =-'Income Statement'!H17*Assumptions!$B$31 -> -2699.6713 | I13: =-'Income Statement'!I17*Assumptions!$B$31 -> -3041.3675
A14: + Δ Debt & overdrafts | D14: =(4474.6+771.4)-(3468.2+808.4) -> 969.4 | E14: 0 | F14: 0 | G14: 0 | H14: 0 | I14: 0
A15: Net change in cash | D15: =D12+D13+D14 -> 3159.1 | E15: =E12+E13+E14 -> 1020.8043 | F15: =F12+F13+F14 -> 1355.2969 | G15: =G12+G13+G14 -> 1731.2527 | H15: =H12+H13+H14 -> 2192.2391 | I15: =I12+I13+I14 -> 2453.5118
A16: Opening cash | D16: 1324.2 | E16: ='Balance Sheet'!D9 -> 4741.1 | F16: =E17 -> 5761.9043 | G16: =F17 -> 7117.2011 | H16: =G17 -> 8848.4538 | I16: =H17 -> 11040.693
A17: Closing cash | D17: =D16+D15 -> 4483.3 | E17: =E16+E15 -> 5761.9043 | F17: =F16+F15 -> 7117.2011 | G17: =G16+G15 -> 8848.4538 | H17: =H16+H15 -> 11040.693 | I17: =I16+I15 -> 13494.205
A19: FY2025A column is a Testahil derivation from disclosed period-end balances (net-debt walk); FY2023-24 full cash-flow statements were not restated here.

Sheet Summary Financials
A1: Summary Financials — all cells link to the statement sheets (EGP m)
B3: FY2023A | C3: FY2024A | D3: FY2025A | E3: FY2026E | F3: FY2027E | G3: FY2028E | H3: FY2029E | I3: FY2030E
A4: Revenue | B4: ='Income Statement'!B4 -> 12125.5 | C4: ='Income Statement'!C4 -> 16146.5 | D4: ='Income Statement'!D4 -> 20915.1 | E4: ='Income Statement'!E4 -> 27189.63 | F4: ='Income Statement'!F4 -> 33171.349 | G4: ='Income Statement'!G4 -> 39142.191 | H4: ='Income Statement'!H4 -> 45013.52 | I4: ='Income Statement'!I4 -> 50865.278
A5: EBITDA | B5: ='Income Statement'!B10 -> 2365.7 | C5: ='Income Statement'!C10 -> 2537.5 | D5: ='Income Statement'!D10 -> 4011.1 | E5: ='Income Statement'!E10 -> 5220.409 | F5: ='Income Statement'!F10 -> 6435.2416 | G5: ='Income Statement'!G10 -> 7632.7273 | H5: ='Income Statement'!H10 -> 8777.6364 | I5: ='Income Statement'!I10 -> 9918.7291
A6: EBIT | B6: ='Income Statement'!B13 -> 2035.7 | C6: ='Income Statement'!C13 -> 2157.3 | D6: ='Income Statement'!D13 -> 3542.1 | E6: ='Income Statement'!E13 -> 4513.4786 | F6: ='Income Statement'!F13 -> 5572.7866 | G6: ='Income Statement'!G13 -> 6615.0303 | H6: ='Income Statement'!H13 -> 7562.2714 | I6: ='Income Statement'!I13 -> 8545.3666
A7: Net profit | B7: ='Income Statement'!B17 -> 1506.6 | C7: ='Income Statement'!C17 -> 1415.4 | D7: ='Income Statement'!D17 -> 2442.3 | E7: ='Income Statement'!E17 -> 3831.9068 | F7: ='Income Statement'!F17 -> 4573.7481 | G7: ='Income Statement'!G17 -> 5303.0473 | H7: ='Income Statement'!H17 -> 5999.2695 | I7: ='Income Statement'!I17 -> 6758.5945
A8: EPS (EGP) | B8: ='Income Statement'!B19 -> 1.0761121 | C8: ='Income Statement'!C19 -> 1.0109711 | D8: ='Income Statement'!D19 -> 1.7444502 | E8: ='Income Statement'!E19 -> 2.7369981 | F8: ='Income Statement'!F19 -> 3.2668696 | G8: ='Income Statement'!G19 -> 3.7877827 | H8: ='Income Statement'!H19 -> 4.28507 | I8: ='Income Statement'!I19 -> 4.8274296
A9: Total assets | B9: ='Balance Sheet'!B10 -> 8922.9 | C9: ='Balance Sheet'!C10 -> 11233 | D9: ='Balance Sheet'!D10 -> 15223.5 | E9: ='Balance Sheet'!E10 -> 18250.424 | F9: ='Balance Sheet'!F10 -> 21645.298 | G9: ='Balance Sheet'!G10 -> 25439.688 | H9: ='Balance Sheet'!H10 -> 29602.372 | I9: ='Balance Sheet'!I10 -> 34179.807
A10: Equity | B10: ='Balance Sheet'!B17 -> 3800 | C10: ='Balance Sheet'!C17 -> 5000 | D10: ='Balance Sheet'!D17 -> 6900 | E10: ='Balance Sheet'!E17 -> 9007.5487 | F10: ='Balance Sheet'!F17 -> 11523.11 | G10: ='Balance Sheet'!G17 -> 14439.786 | H10: ='Balance Sheet'!H17 -> 17739.384 | I10: ='Balance Sheet'!I17 -> 21456.611
A11: Net debt/(cash) | B11: ='Balance Sheet'!B13+'Balance Sheet'!B14-'Balance Sheet'!B9 -> 1270.9 | C11: ='Balance Sheet'!C13+'Balance Sheet'!C14-'Balance Sheet'!C9 -> 2952.4 | D11: ='Balance Sheet'!D13+'Balance Sheet'!D14-'Balance Sheet'!D9 -> 504.9 | E11: ='Balance Sheet'!E13+'Balance Sheet'!E14-'Balance Sheet'!E9 -> -515.90427 | F11: ='Balance Sheet'!F13+'Balance Sheet'!F14-'Balance Sheet'!F9 -> -1871.2011 | G11: ='Balance Sheet'!G13+'Balance Sheet'!G14-'Balance Sheet'!G9 -> -3602.4538 | H11: ='Balance Sheet'!H13+'Balance Sheet'!H14-'Balance Sheet'!H9 -> -5794.6929 | I11: ='Balance Sheet'!I13+'Balance Sheet'!I14-'Balance Sheet'!I9 -> -8248.2047
A12: CFO | D12: ='Cash Flow'!D10 -> 4382.6 | E12: ='Cash Flow'!E10 -> 4512.4883 | F12: ='Cash Flow'!F10 -> 5403.7644 | G12: ='Cash Flow'!G10 -> 6270.4445 | H12: ='Cash Flow'!H10 -> 7142.5864 | I12: ='Cash Flow'!I10 -> 8038.1432
A13: Capex | D13: ='Cash Flow'!D11 -> -1392.8 | E13: ='Cash Flow'!E11 -> -1767.3259 | F13: ='Cash Flow'!F11 -> -1990.2809 | G13: ='Cash Flow'!G11 -> -2152.8205 | H13: ='Cash Flow'!H11 -> -2250.676 | I13: ='Cash Flow'!I11 -> -2543.2639
A14: Free cash flow | D14: ='Cash Flow'!D12 -> 2989.8 | E14: ='Cash Flow'!E12 -> 2745.1623 | F14: ='Cash Flow'!F12 -> 3413.4835 | G14: ='Cash Flow'!G12 -> 4117.624 | H14: ='Cash Flow'!H12 -> 4891.9104 | I14: ='Cash Flow'!I12 -> 5494.8793

Sheet Monte Carlo
A1: Monte Carlo — mc_v2 (YZ-HAR width, Student-t5, drift OFF), seed 42, 50,000 paths
A2: Anchor 27.34 (close 2026-07-01) · HAR daily σ 0.0260 · ann. path vol 41.3% · net factor drift 0.5%/3m · egx_staples 16-factor overlay (calibrated=False, Appendix-A defaults)
A4: Percentile table (EGP/share)
A5: Horizon | B5: P5 | C5: P25 | D5: P50 | E5: P75 | F5: P95
A6: T+20 | B6: 22.35 | C6: 25.48 | D6: 27.48 | E6: 29.62 | F6: 33.56
A7: T+60 | B7: 19.4 | C7: 24.4 | D7: 27.82 | E7: 31.65 | F7: 38.98
A9: Touch probabilities by T+60 (running max/min)
A10: Upside level | B10: P(touch) | D10: Downside level | E10: P(touch)
A11: 28 | B11: 0.8526 | D11: 27 | E11: 0.8708
A12: 29 | B12: 0.7243 | D12: 26 | E12: 0.7088
A13: 30 | B13: 0.6055 | D13: 25 | E13: 0.5586
A14: 31 | B14: 0.4994 | D14: 24 | E14: 0.4267
A15: 32 | B15: 0.4065 | D15: 23 | E15: 0.3156
A16: 33 | B16: 0.3291 | D16: 22 | E16: 0.2277
A17: 35 | B17: 0.2133 | D17: 20 | E17: 0.1092
A19: Terminal-price zones at T+60
A20: Zone (EGP) | B20: Probability
A21: 0-20 | B21: 0.0623
A22: 20-22 | B22: 0.062
A23: 22-24 | B23: 0.1021
A24: 24-26 | B24: 0.1334
A25: 26-28 | B25: 0.1543
A26: 28-30 | B26: 0.1414
A27: 30-32 | B27: 0.1122
A28: 32-34 | B28: 0.0782
A29: 34-∞ | B29: 0.1541
A30: P(T+60 close above spot) | B30: 0.5358
A32: These paths diffuse from spot and deliberately do not embed the fundamental value gap of Section 1 — lens independence. 50% band and T+20 lead the presentation; the 90% tail is context.

Sheet Sensitivity
A1: Sensitivity — DCF fair value per share (EGP): WACC × terminal growth
A3: WACC \ g | B3: 0.115 | C3: 0.125 | D3: 0.135 | E3: 0.145 | F3: 0.155
A4: 0.187 | B4: =((DCF!B13/(1+$A4)^1+DCF!C13/(1+$A4)^2+DCF!D13/(1+$A4)^3+DCF!E13/(1+$A4)^4+DCF!F13/(1+$A4)^5)+DCF!F13*(1+B$3)/($A4-B$3)/(1+$A4)^5+Assumptions!$B$8)/Assumptions!$B$7 -> 31.417339 | C4: =((DCF!B13/(1+$A4)^1+DCF!C13/(1+$A4)^2+DCF!D13/(1+$A4)^3+DCF!E13/(1+$A4)^4+DCF!F13/(1+$A4)^5)+DCF!F13*(1+C$3)/($A4-C$3)/(1+$A4)^5+Assumptions!$B$8)/Assumptions!$B$7 -> 35.442405 | D4: =((DCF!B13/(1+$A4)^1+DCF!C13/(1+$A4)^2+DCF!D13/(1+$A4)^3+DCF!E13/(1+$A4)^4+DCF!F13/(1+$A4)^5)+DCF!F13*(1+D$3)/($A4-D$3)/(1+$A4)^5+Assumptions!$B$8)/Assumptions!$B$7 -> 41.015573 | E4: =((DCF!B13/(1+$A4)^1+DCF!C13/(1+$A4)^2+DCF!D13/(1+$A4)^3+DCF!E13/(1+$A4)^4+DCF!F13/(1+$A4)^5)+DCF!F13*(1+E$3)/($A4-E$3)/(1+$A4)^5+Assumptions!$B$8)/Assumptions!$B$7 -> 49.242632 | F4: =((DCF!B13/(1+$A4)^1+DCF!C13/(1+$A4)^2+DCF!D13/(1+$A4)^3+DCF!E13/(1+$A4)^4+DCF!F13/(1+$A4)^5)+DCF!F13*(1+F$3)/($A4-F$3)/(1+$A4)^5+Assumptions!$B$8)/Assumptions!$B$7 -> 62.611602
A5: 0.197 | B5: =((DCF!B13/(1+$A5)^1+DCF!C13/(1+$A5)^2+DCF!D13/(1+$A5)^3+DCF!E13/(1+$A5)^4+DCF!F13/(1+$A5)^5)+DCF!F13*(1+B$3)/($A5-B$3)/(1+$A5)^5+Assumptions!$B$8)/Assumptions!$B$7 -> 27.525545 | C5: =((DCF!B13/(1+$A5)^1+DCF!C13/(1+$A5)^2+DCF!D13/(1+$A5)^3+DCF!E13/(1+$A5)^4+DCF!F13/(1+$A5)^5)+DCF!F13*(1+C$3)/($A5-C$3)/(1+$A5)^5+Assumptions!$B$8)/Assumptions!$B$7 -> 30.468456 | D5: =((DCF!B13/(1+$A5)^1+DCF!C13/(1+$A5)^2+DCF!D13/(1+$A5)^3+DCF!E13/(1+$A5)^4+DCF!F13/(1+$A5)^5)+DCF!F13*(1+D$3)/($A5-D$3)/(1+$A5)^5+Assumptions!$B$8)/Assumptions!$B$7 -> 34.360693 | E5: =((DCF!B13/(1+$A5)^1+DCF!C13/(1+$A5)^2+DCF!D13/(1+$A5)^3+DCF!E13/(1+$A5)^4+DCF!F13/(1+$A5)^5)+DCF!F13*(1+E$3)/($A5-E$3)/(1+$A5)^5+Assumptions!$B$8)/Assumptions!$B$7 -> 39.749945 | F5: =((DCF!B13/(1+$A5)^1+DCF!C13/(1+$A5)^2+DCF!D13/(1+$A5)^3+DCF!E13/(1+$A5)^4+DCF!F13/(1+$A5)^5)+DCF!F13*(1+F$3)/($A5-F$3)/(1+$A5)^5+Assumptions!$B$8)/Assumptions!$B$7 -> 47.705506
A6: 0.207 | B6: =((DCF!B13/(1+$A6)^1+DCF!C13/(1+$A6)^2+DCF!D13/(1+$A6)^3+DCF!E13/(1+$A6)^4+DCF!F13/(1+$A6)^5)+DCF!F13*(1+B$3)/($A6-B$3)/(1+$A6)^5+Assumptions!$B$8)/Assumptions!$B$7 -> 24.483084 | C6: =((DCF!B13/(1+$A6)^1+DCF!C13/(1+$A6)^2+DCF!D13/(1+$A6)^3+DCF!E13/(1+$A6)^4+DCF!F13/(1+$A6)^5)+DCF!F13*(1+C$3)/($A6-C$3)/(1+$A6)^5+Assumptions!$B$8)/Assumptions!$B$7 -> 26.710849 | D6: =((DCF!B13/(1+$A6)^1+DCF!C13/(1+$A6)^2+DCF!D13/(1+$A6)^3+DCF!E13/(1+$A6)^4+DCF!F13/(1+$A6)^5)+DCF!F13*(1+D$3)/($A6-D$3)/(1+$A6)^5+Assumptions!$B$8)/Assumptions!$B$7 -> 29.557437 | E6: =((DCF!B13/(1+$A6)^1+DCF!C13/(1+$A6)^2+DCF!D13/(1+$A6)^3+DCF!E13/(1+$A6)^4+DCF!F13/(1+$A6)^5)+DCF!F13*(1+E$3)/($A6-E$3)/(1+$A6)^5+Assumptions!$B$8)/Assumptions!$B$7 -> 33.32228 | F6: =((DCF!B13/(1+$A6)^1+DCF!C13/(1+$A6)^2+DCF!D13/(1+$A6)^3+DCF!E13/(1+$A6)^4+DCF!F13/(1+$A6)^5)+DCF!F13*(1+F$3)/($A6-F$3)/(1+$A6)^5+Assumptions!$B$8)/Assumptions!$B$7 -> 38.535139
A7: 0.217 | B7: =((DCF!B13/(1+$A7)^1+DCF!C13/(1+$A7)^2+DCF!D13/(1+$A7)^3+DCF!E13/(1+$A7)^4+DCF!F13/(1+$A7)^5)+DCF!F13*(1+B$3)/($A7-B$3)/(1+$A7)^5+Assumptions!$B$8)/Assumptions!$B$7 -> 22.040041 | C7: =((DCF!B13/(1+$A7)^1+DCF!C13/(1+$A7)^2+DCF!D13/(1+$A7)^3+DCF!E13/(1+$A7)^4+DCF!F13/(1+$A7)^5)+DCF!F13*(1+C$3)/($A7-C$3)/(1+$A7)^5+Assumptions!$B$8)/Assumptions!$B$7 -> 23.772847 | D7: =((DCF!B13/(1+$A7)^1+DCF!C13/(1+$A7)^2+DCF!D13/(1+$A7)^3+DCF!E13/(1+$A7)^4+DCF!F13/(1+$A7)^5)+DCF!F13*(1+D$3)/($A7-D$3)/(1+$A7)^5+Assumptions!$B$8)/Assumptions!$B$7 -> 25.928287 | E7: =((DCF!B13/(1+$A7)^1+DCF!C13/(1+$A7)^2+DCF!D13/(1+$A7)^3+DCF!E13/(1+$A7)^4+DCF!F13/(1+$A7)^5)+DCF!F13*(1+E$3)/($A7-E$3)/(1+$A7)^5+Assumptions!$B$8)/Assumptions!$B$7 -> 28.682462 | F7: =((DCF!B13/(1+$A7)^1+DCF!C13/(1+$A7)^2+DCF!D13/(1+$A7)^3+DCF!E13/(1+$A7)^4+DCF!F13/(1+$A7)^5)+DCF!F13*(1+F$3)/($A7-F$3)/(1+$A7)^5+Assumptions!$B$8)/Assumptions!$B$7 -> 32.325079
A8: 0.227 | B8: =((DCF!B13/(1+$A8)^1+DCF!C13/(1+$A8)^2+DCF!D13/(1+$A8)^3+DCF!E13/(1+$A8)^4+DCF!F13/(1+$A8)^5)+DCF!F13*(1+B$3)/($A8-B$3)/(1+$A8)^5+Assumptions!$B$8)/Assumptions!$B$7 -> 20.035762 | C8: =((DCF!B13/(1+$A8)^1+DCF!C13/(1+$A8)^2+DCF!D13/(1+$A8)^3+DCF!E13/(1+$A8)^4+DCF!F13/(1+$A8)^5)+DCF!F13*(1+C$3)/($A8-C$3)/(1+$A8)^5+Assumptions!$B$8)/Assumptions!$B$7 -> 21.413301 | D8: =((DCF!B13/(1+$A8)^1+DCF!C13/(1+$A8)^2+DCF!D13/(1+$A8)^3+DCF!E13/(1+$A8)^4+DCF!F13/(1+$A8)^5)+DCF!F13*(1+D$3)/($A8-D$3)/(1+$A8)^5+Assumptions!$B$8)/Assumptions!$B$7 -> 23.090304 | E8: =((DCF!B13/(1+$A8)^1+DCF!C13/(1+$A8)^2+DCF!D13/(1+$A8)^3+DCF!E13/(1+$A8)^4+DCF!F13/(1+$A8)^5)+DCF!F13*(1+E$3)/($A8-E$3)/(1+$A8)^5+Assumptions!$B$8)/Assumptions!$B$7 -> 25.176332 | F8: =((DCF!B13/(1+$A8)^1+DCF!C13/(1+$A8)^2+DCF!D13/(1+$A8)^3+DCF!E13/(1+$A8)^4+DCF!F13/(1+$A8)^5)+DCF!F13*(1+F$3)/($A8-F$3)/(1+$A8)^5+Assumptions!$B$8)/Assumptions!$B$7 -> 27.841812
A10: Grid re-discounts the base FCFF path; it does not re-run growth/margins. Base cell: WACC row 20.7%, g column 13.5%.

Sheet Per-Share & Ratios
A1: Per-Share & Ratios
B3: FY2023A | C3: FY2024A | D3: FY2025A | E3: FY2026E | F3: FY2027E | G3: FY2028E | H3: FY2029E | I3: FY2030E
A4: EPS (EGP) | B4: ='Income Statement'!B19 -> 1.0761121 | C4: ='Income Statement'!C19 -> 1.0109711 | D4: ='Income Statement'!D19 -> 1.7444502 | E4: ='Income Statement'!E19 -> 2.7369981 | F4: ='Income Statement'!F19 -> 3.2668696 | G4: ='Income Statement'!G19 -> 3.7877827 | H4: ='Income Statement'!H19 -> 4.28507 | I4: ='Income Statement'!I19 -> 4.8274296
A5: DPS (EGP) | D5: =-'Cash Flow'!D13/Assumptions!$B$7 -> 0.57148367 | E5: =-'Cash Flow'!E13/Assumptions!$B$7 -> 1.2316491 | F5: =-'Cash Flow'!F13/Assumptions!$B$7 -> 1.4700913 | G5: =-'Cash Flow'!G13/Assumptions!$B$7 -> 1.7045022 | H5: =-'Cash Flow'!H13/Assumptions!$B$7 -> 1.9282815 | I5: =-'Cash Flow'!I13/Assumptions!$B$7 -> 2.1723433
A6: BVPS (EGP) | B6: ='Balance Sheet'!B17/Assumptions!$B$7 -> 2.7142082 | C6: ='Balance Sheet'!C17/Assumptions!$B$7 -> 3.5713265 | D6: ='Balance Sheet'!D17/Assumptions!$B$7 -> 4.9284306 | E6: ='Balance Sheet'!E17/Assumptions!$B$7 -> 6.4337795 | F6: ='Balance Sheet'!F17/Assumptions!$B$7 -> 8.2305578 | G6: ='Balance Sheet'!G17/Assumptions!$B$7 -> 10.313838 | H6: ='Balance Sheet'!H17/Assumptions!$B$7 -> 12.670627 | I6: ='Balance Sheet'!I17/Assumptions!$B$7 -> 15.325713
A7: ROE (avg) | C7: ='Income Statement'!C17/(('Balance Sheet'!C17+'Balance Sheet'!B17)/2) -> 0.32168182 | D7: ='Income Statement'!D17/(('Balance Sheet'!D17+'Balance Sheet'!C17)/2) -> 0.41047059 | E7: ='Income Statement'!E17/(('Balance Sheet'!E17+'Balance Sheet'!D17)/2) -> 0.48177212 | F7: ='Income Statement'!F17/(('Balance Sheet'!F17+'Balance Sheet'!E17)/2) -> 0.44555298 | G7: ='Income Statement'!G17/(('Balance Sheet'!G17+'Balance Sheet'!F17)/2) -> 0.40850968 | H7: ='Income Statement'!H17/(('Balance Sheet'!H17+'Balance Sheet'!G17)/2) -> 0.37286663 | I7: ='Income Statement'!I17/(('Balance Sheet'!I17+'Balance Sheet'!H17)/2) -> 0.34486148
A8: Net debt / (cash) (EGP m) | B8: ='Balance Sheet'!B13+'Balance Sheet'!B14-'Balance Sheet'!B9 -> 1270.9 | C8: ='Balance Sheet'!C13+'Balance Sheet'!C14-'Balance Sheet'!C9 -> 2952.4 | D8: ='Balance Sheet'!D13+'Balance Sheet'!D14-'Balance Sheet'!D9 -> 504.9 | E8: ='Balance Sheet'!E13+'Balance Sheet'!E14-'Balance Sheet'!E9 -> -515.90427 | F8: ='Balance Sheet'!F13+'Balance Sheet'!F14-'Balance Sheet'!F9 -> -1871.2011 | G8: ='Balance Sheet'!G13+'Balance Sheet'!G14-'Balance Sheet'!G9 -> -3602.4538 | H8: ='Balance Sheet'!H13+'Balance Sheet'!H14-'Balance Sheet'!H9 -> -5794.6929 | I8: ='Balance Sheet'!I13+'Balance Sheet'!I14-'Balance Sheet'!I9 -> -8248.2047
A9: Net debt / EBITDA (x) | B9: =('Balance Sheet'!B13+'Balance Sheet'!B14-'Balance Sheet'!B9)/'Income Statement'!B10 -> 0.53721943 | C9: =('Balance Sheet'!C13+'Balance Sheet'!C14-'Balance Sheet'!C9)/'Income Statement'!C10 -> 1.1635074 | D9: =('Balance Sheet'!D13+'Balance Sheet'!D14-'Balance Sheet'!D9)/'Income Statement'!D10 -> 0.12587569 | E9: =('Balance Sheet'!E13+'Balance Sheet'!E14-'Balance Sheet'!E9)/'Income Statement'!E10 -> -0.098824492 | F9: =('Balance Sheet'!F13+'Balance Sheet'!F14-'Balance Sheet'!F9)/'Income Statement'!F10 -> -0.29077403 | G9: =('Balance Sheet'!G13+'Balance Sheet'!G14-'Balance Sheet'!G9)/'Income Statement'!G10 -> -0.47197465 | H9: =('Balance Sheet'!H13+'Balance Sheet'!H14-'Balance Sheet'!H9)/'Income Statement'!H10 -> -0.66016552 | I9: =('Balance Sheet'!I13+'Balance Sheet'!I14-'Balance Sheet'!I9)/'Income Statement'!I10 -> -0.83157878
A10: Gross margin | B10: ='Income Statement'!B8 -> 0.32372273 | C10: ='Income Statement'!C8 -> 0.30386152 | D10: ='Income Statement'!D8 -> 0.33877916 | E10: ='Income Statement'!E8 -> 0.34 | F10: ='Income Statement'!F8 -> 0.342 | G10: ='Income Statement'!G8 -> 0.343 | H10: ='Income Statement'!H8 -> 0.343 | I10: ='Income Statement'!I8 -> 0.343
A11: EBITDA margin | B11: ='Income Statement'!B11 -> 0.19510123 | C11: ='Income Statement'!C11 -> 0.1571548 | D11: ='Income Statement'!D11 -> 0.1917801 | E11: ='Income Statement'!E11 -> 0.192 | F11: ='Income Statement'!F11 -> 0.194 | G11: ='Income Statement'!G11 -> 0.195 | H11: ='Income Statement'!H11 -> 0.195 | I11: ='Income Statement'!I11 -> 0.195
A12: Net margin | B12: ='Income Statement'!B18 -> 0.12425055 | C12: ='Income Statement'!C18 -> 0.087659864 | D12: ='Income Statement'!D18 -> 0.11677209 | E12: ='Income Statement'!E18 -> 0.14093266 | F12: ='Income Statement'!F18 -> 0.13788249 | G12: ='Income Statement'!G18 -> 0.13548161 | H12: ='Income Statement'!H18 -> 0.13327706 | I12: ='Income Statement'!I18 -> 0.13287246
A13: P/E at spot (x) | B13: =Assumptions!$B$5/'Income Statement'!B19 -> 25.406275 | C13: =Assumptions!$B$5/'Income Statement'!C19 -> 27.043305 | D13: =Assumptions!$B$5/'Income Statement'!D19 -> 15.67256 | E13: =Assumptions!$B$5/'Income Statement'!E19 -> 9.9890462 | F13: =Assumptions!$B$5/'Income Statement'!F19 -> 8.3688678 | G13: =Assumptions!$B$5/'Income Statement'!G19 -> 7.2179431 | H13: =Assumptions!$B$5/'Income Statement'!H19 -> 6.3802924 | I13: =Assumptions!$B$5/'Income Statement'!I19 -> 5.6634695
A14: EV/EBITDA at spot (x) | B14: =(Assumptions!$B$5*Assumptions!$B$7-Assumptions!$B$8)/'Income Statement'!B10 -> 15.819332 | C14: =(Assumptions!$B$5*Assumptions!$B$7-Assumptions!$B$8)/'Income Statement'!C10 -> 14.748293 | D14: =(Assumptions!$B$5*Assumptions!$B$7-Assumptions!$B$8)/'Income Statement'!D10 -> 9.3300575 | E14: =(Assumptions!$B$5*Assumptions!$B$7-Assumptions!$B$8)/'Income Statement'!E10 -> 7.1687475 | F14: =(Assumptions!$B$5*Assumptions!$B$7-Assumptions!$B$8)/'Income Statement'!F10 -> 5.815445 | G14: =(Assumptions!$B$5*Assumptions!$B$7-Assumptions!$B$8)/'Income Statement'!G10 -> 4.9030696 | H14: =(Assumptions!$B$5*Assumptions!$B$7-Assumptions!$B$8)/'Income Statement'!H10 -> 4.2635388 | I14: =(Assumptions!$B$5*Assumptions!$B$7-Assumptions!$B$8)/'Income Statement'!I10 -> 3.7730432

Sheet Peer & Sector
A1: Peer set & sector structure
A3: Peer set: EGX consumer staples — Juhayna (dairy/juice), Obour Land (white cheese), Domty (cheese/juice/bakery entrant), Eastern Company (tobacco, cash-flow comp) — plus Almarai (Tadawul) as the regional quality benchmark. Multiples on the 'Relative & Normalized' sheet.
A5: Sector structure: Egyptian packaged snacks is a repertoire, price-point-led category. Edita holds leading positions across cakes (~half the market), croissants (dominant), rusks and wafers, with HTT brand ownership (HoHos, Twinkies, Tiger Tail) now extended across Africa (Jan-2026).
A7: Demand driver: per-capita packaged-snack consumption in Egypt remains far below EM peers; price-point migration (EGP 5 -> 10) is the volume-preserving inflation pass-through mechanism.
A9: Competition: Mondelez Egypt, PepsiCo (Chipsy adjacency), Corona/Bisco Misr in biscuits, plus informal bakery substitutes at the low end.
A11: Key sector risks: EGP devaluation resets imported input costs (c.80% of direct materials are imported or FX-linked); sugar/flour/cocoa/packaging cycles; purchasing-power shocks to the mass consumer; export logistics (Red Sea).
