Workbook

Sheet READ FIRST
B1: eXtra — United Electronics Company (Tadawul:4003)
B2: Testahil · Independent Valuation Study — Educational Analysis · Not investment advice
B4: READ FIRST
B5: • This model is an educational valuation framework, not investment advice and not a rating or price target.
B6: • Fair value is presented as a RANGE and a probability distribution — never a single point.
B7: • Primary lens: split-legs sum-of-the-parts — retail operating-co DCF + Tasheel captive consumer-finance book (68.75%-owned).
B8: • Blue cells = inputs (edit these). Black = formulas. Green = links to another sheet. Change any blue Assumption and the model reprices.
B9: • The near-term Monte Carlo is carry-anchored (≈ flat): eXtra pays its ~4.25% risk-free carry, and more, out as a ~6.9% dividend — an explained-flat median.
B10: • Step 0 calibration: PARITY (CRPS skill -0.050, 90% CI [-0.140,+0.007]) — clears the v3 gate at the honest parity tier.
B11: • The preparer may hold, and may in the future take or dispose of, a position in the security discussed in this report.
B13: Spot SAR 68.1 (2026-07-09) | Shares 80m | Mkt cap SAR 5448m | SOTP central ~SAR 81/sh

Sheet Summary
B1: Valuation summary — every read at a glance
C3: SAR / share | D3: vs spot
B4: FUNDAMENTAL
B5: Sum-of-the-parts (split legs) | C5: 90.384385 | D5: =Summary!C5/Assumptions!$C$5-1 -> 0.32723032
B6: Retail DCF component | C6: 65.176052 | D6: =Summary!C6/Assumptions!$C$5-1 -> -0.0429361
B7: Tasheel component (68.75%) | C7: 25.208333 | D7: =Summary!C7/Assumptions!$C$5-1 -> -0.62983358
B8: Relative (P/E 12x) | C8: 74.52 | D8: =Summary!C8/Assumptions!$C$5-1 -> 0.094273128
B9: MONTE CARLO
B10: T+60 median | C10: 67.61 | D10: =Summary!C10/Assumptions!$C$5-1 -> -0.007195301
B11: 25th / 75th band low | C11: 62 | D11: =Summary!C11/Assumptions!$C$5-1 -> -0.089574156
B12: 25th / 75th band high | C12: 73.79 | D12: =Summary!C12/Assumptions!$C$5-1 -> 0.083553598
B13: WEIGHTED CENTRAL
B14: Weighted central (SOTP 50 / rel 25 / MC 25) | C14: 80.724692 | D14: =Summary!C14/Assumptions!$C$5-1 -> 0.18538462
B16: Spot SAR 68.1 (2026-07-09)
B17: Fair-value range ~SAR 65–92/sh. Range, not a target. Step 0 PARITY.

Sheet Fundamental Valuation
B1: Fundamental valuation — lens map
B3: Primary | C3: Split-legs SOTP: retail operating-co DCF (net-cash, discounted at Ke) + Tasheel captive consumer-finance book (equity×justified P/B, at 68.75%).
B4: Cross-check | C4: Relative P/E (12x on group EPS). EV/EBITDA is N/M for the blended entity (finance-book earnings).
B5: Near-term | C5: Carry-anchored Monte Carlo (T+60) — explained-flat median (dividend yield ~ risk-free).
B6: Discipline | C6: Bottom-up sourced WACC; conservative growth (adopt machinery not broker optimism); fair value as a range.
B8: Build-up | C8: SAR mn | D8: SAR/share
B9: Retail equity (DCF) | C9: =DCF!C20 -> 5214.0841 | D9: =DCF!C21 -> 65.176052
B10: Tasheel (68.75%) | C10: =SOTP!C7 -> 2016.6667 | D10: =SOTP!D7 -> 25.208333
B11: SOTP | C11: =SUM(C9:C10) -> 7230.7508 | D11: =C11/Assumptions!$C$6 -> 90.384385

Sheet Assumptions
B1: Assumptions — single input layer
B2: Blue = input. Every downstream sheet links here.
B4: Market
B5: Spot price (SAR) | C5: 68.1 | D5: Tadawul close 2026-07-09
B6: Shares outstanding (mn) | C6: 80 | D6: SAR 800m cap / SAR 10 par (post-2022 60->80m)
B7: Effective zakat/tax rate | C7: 0.09 | D7: eXtra effective ~8-9% (Zakat-based)
B9: Cost of capital (bottom-up, sourced)
B10: Risk-free rf (SAR 10Y sukuk) | C10: 0.055 | D10: Derived; band 5.4-5.6% (Cost_of_Capital_Reference.md) FLAGGED
B11: ERP — rating-based (primary) | C11: 0.0501 | D11: Damodaran Jan-2026, Saudi Aa3 (CRP 0.78 + 4.23)
B12: ERP — CDS-based (alt) | C12: 0.0572 | D12: Damodaran Jan-2026, Saudi CDS 0.98
B13: Beta (base) | C13: 0.8 | D13: Regressed 0.55 (n=40,R2 8.8%) noisy short window -> carry 0.80 base
B14: Retail cost of equity Ke = rf + beta×ERP(rating) | C14: =Assumptions!$C$10+Assumptions!$C$13*Assumptions!$C$11 -> 0.09508
B15: Tasheel cost of equity | C15: 0.105 | D15: Leveraged consumer-finance lender
B16: Cost of debt Kd (pre-tax) | C16: 0.06 | D16: SAIBOR3M 4.79 + spread; Tasheel murabaha FLAGGED
B18: Retail DCF drivers
B19: Retail revenue FY2025 (SAR mn) | C19: 6950 | D19: Sales & Services segment
B20: Revenue growth FY2026 | C20: 0.055
B21: Revenue growth FY2027 | C21: 0.055
B22: Revenue growth FY2028 | C22: 0.05
B23: Revenue growth FY2029 | C23: 0.05
B24: Revenue growth FY2030 | C24: 0.045
B25: EBIT margin FY2026 | C25: 0.042
B26: EBIT margin FY2027 | C26: 0.044
B27: EBIT margin FY2028 | C27: 0.045
B28: EBIT margin FY2029 | C28: 0.046
B29: EBIT margin FY2030 | C29: 0.047
B30: D&A (% of revenue) | C30: 0.022 | D30: incl ROU depreciation
B31: Capex (% of revenue) | C31: 0.011 | D31: low; Panda funds Clix capex
B32: Lease payments (% of revenue) | C32: 0.013 | D32: offsets ROU deprec in FCFF
B33: ΔWorking capital (% of Δrev) | C33: 0.004
B34: Terminal growth g | C34: 0.03
B35: Retail standalone net cash (SAR mn) | C35: 388 | D35: Aljazira 2025E net debt -387.9
B37: Tasheel (captive consumer-finance, 68.75%)
B38: Tasheel equity book (SAR mn) | C38: 1200 | D38: FLAGGED estimate — segment equity not separately disclosed
B39: Tasheel net income (SAR mn) | C39: 230 | D39: segment NI (Q2-25 59.8m annualized, FY25 softer)
B40: Tasheel ROE (=NI/equity) | C40: =Assumptions!$C$39/Assumptions!$C$38 -> 0.19166667
B41: Tasheel terminal growth | C41: 0.045
B42: eXtra stake in Tasheel | C42: 0.6875 | D42: Aljazira-sourced (31.25% NCI)
B43: Tasheel justified P/B = (ROE-g)/(COE-g) | C43: =(Assumptions!$C$40-Assumptions!$C$41)/(Assumptions!$C$15-Assumptions!$C$41) -> 2.4444444
B45: Relative
...

Sheet SOTP
B1: Sum-of-the-parts (split legs) — primary lens
B2: Retail DCF + Tasheel captive-lender at eXtra’s 68.75% stake.
B4: Leg | C4: SAR mn | D4: SAR / share
B5: Retail operating-co (DCF) | C5: =DCF!C20 -> 5214.0841 | D5: =DCF!C21 -> 65.176052
B6: Tasheel 100% (equity×justified P/B) | C6: =Assumptions!$C$38*Assumptions!$C$43 -> 2933.3333
B7: Tasheel — eXtra 68.75% share | C7: =SOTP!C6*Assumptions!$C$42 -> 2016.6667 | D7: =SOTP!C7/Assumptions!$C$6 -> 25.208333
B9: SOTP equity value | C9: =DCF!C20+SOTP!C7 -> 7230.7508 | D9: =SOTP!C9/Assumptions!$C$6 -> 90.384385
B11: Cross-checks (SAR/share)
B12: Relative P/E (12x on EPS) | C12: 74.52
B13: Monte Carlo T+60 median | C13: 67.61
B14: Weighted central | C14: 80.724692
B15: Spot | C15: 68.1
B17: Fair value presented as a range across beta/WACC and the Tasheel multiple — see Sensitivity. Not a point target.

Sheet Segments
B1: Segment scorecard
B2: Retail (Sales & Services) vs Tasheel (Consumer Finance).
B4: SAR mn | C4: FY2023 | D4: FY2024 | E4: FY2025
B5: Retail revenue | C5: 5850 | D5: 6350 | E5: 6950
B6: Tasheel revenue | C6: 350.7 | D6: 431.2 | E6: 500
B7: Retail net income | C7: 239.5 | D7: 329.5 | E7: 267
B8: Tasheel net income | C8: 150 | D8: 205 | E8: 230
B9: Tasheel loan book | C9: 1850 | D9: 2407 | E9: 3036
B10: Tasheel equity (est) | C10: 900 | D10: 1050 | E10: 1200
B11: Group net income (incl NCI) | C11: 389.5 | D11: 534.5 | E11: 497
B12: Tasheel ROE | C12: =Segments!C6/Segments!C8 -> 2.338 | D12: =Segments!D6/Segments!D8 -> 2.1034146 | E12: =Segments!E6/Segments!E8 -> 2.173913
B14: Consumer finance is ~45–50% of group net income despite ~7% of revenue — high-margin lending vs thin-margin retail.

Sheet DCF
B1: Retail operating-co DCF (FCFF)
B2: Net-cash entity → discounted at retail Ke. Links to Assumptions.
B4: SAR mn | C4: FY2026 | D4: FY2027 | E4: FY2028 | F4: FY2029 | G4: FY2030
B5: Revenue | C5: =Assumptions!$C$19*(1+Assumptions!$C$20) -> 7332.25 | D5: =DCF!C5*(1+Assumptions!$C$21) -> 7735.5238 | E5: =DCF!D5*(1+Assumptions!$C$22) -> 8122.2999 | F5: =DCF!E5*(1+Assumptions!$C$23) -> 8528.4149 | G5: =DCF!F5*(1+Assumptions!$C$24) -> 8912.1936
B6: EBIT | C6: =DCF!C5*Assumptions!$C$25 -> 307.9545 | D6: =DCF!D5*Assumptions!$C$26 -> 340.36304 | E6: =DCF!E5*Assumptions!$C$27 -> 365.5035 | F6: =DCF!F5*Assumptions!$C$28 -> 392.30709 | G6: =DCF!G5*Assumptions!$C$29 -> 418.8731
B7: NOPAT = EBIT×(1−tax) | C7: =DCF!C6*(1-Assumptions!$C$7) -> 280.23859 | D7: =DCF!D6*(1-Assumptions!$C$7) -> 309.73037 | E7: =DCF!E6*(1-Assumptions!$C$7) -> 332.60818 | F7: =DCF!F6*(1-Assumptions!$C$7) -> 356.99945 | G7: =DCF!G6*(1-Assumptions!$C$7) -> 381.17452
B8: + D&A | C8: =DCF!C5*Assumptions!$C$30 -> 161.3095 | D8: =DCF!D5*Assumptions!$C$30 -> 170.18152 | E8: =DCF!E5*Assumptions!$C$30 -> 178.6906 | F8: =DCF!F5*Assumptions!$C$30 -> 187.62513 | G8: =DCF!G5*Assumptions!$C$30 -> 196.06826
B9: − Capex | C9: =-DCF!C5*Assumptions!$C$31 -> -80.65475 | D9: =-DCF!D5*Assumptions!$C$31 -> -85.090761 | E9: =-DCF!E5*Assumptions!$C$31 -> -89.345299 | F9: =-DCF!F5*Assumptions!$C$31 -> -93.812564 | G9: =-DCF!G5*Assumptions!$C$31 -> -98.03413
B10: − Lease payments | C10: =-DCF!C5*Assumptions!$C$32 -> -95.31925 | D10: =-DCF!D5*Assumptions!$C$32 -> -100.56181 | E10: =-DCF!E5*Assumptions!$C$32 -> -105.5899 | F10: =-DCF!F5*Assumptions!$C$32 -> -110.86939 | G10: =-DCF!G5*Assumptions!$C$32 -> -115.85852
B11: − ΔWorking capital | C11: =-(DCF!C5-Assumptions!$C$19)*Assumptions!$C$33 -> -1.529 | D11: =-(DCF!D5-DCF!C5)*Assumptions!$C$33 -> -1.613095 | E11: =-(DCF!E5-DCF!D5)*Assumptions!$C$33 -> -1.5471047 | F11: =-(DCF!F5-DCF!E5)*Assumptions!$C$33 -> -1.62446 | G11: =-(DCF!G5-DCF!F5)*Assumptions!$C$33 -> -1.5351147
B12: Free cash flow to firm | C12: =DCF!C7+DCF!C8+DCF!C9+DCF!C10+DCF!C11 -> 264.0451 | D12: =DCF!D7+DCF!D8+DCF!D9+DCF!D10+DCF!D11 -> 292.64623 | E12: =DCF!E7+DCF!E8+DCF!E9+DCF!E10+DCF!E11 -> 314.81648 | F12: =DCF!F7+DCF!F8+DCF!F9+DCF!F10+DCF!F11 -> 338.31816 | G12: =DCF!G7+DCF!G8+DCF!G9+DCF!G10+DCF!G11 -> 361.81502
B13: Discount factor | C13: =1/(1+Assumptions!$C$14)^1 -> 0.91317529 | D13: =1/(1+Assumptions!$C$14)^2 -> 0.83388912 | E13: =1/(1+Assumptions!$C$14)^3 -> 0.76148694 | F13: =1/(1+Assumptions!$C$14)^4 -> 0.69537106 | G13: =1/(1+Assumptions!$C$14)^5 -> 0.63499567
B14: PV of FCFF | C14: =DCF!C12*DCF!C13 -> 241.11946 | D14: =DCF!D12*DCF!D13 -> 244.0345 | E14: =DCF!E12*DCF!E13 -> 239.72864 | F14: =DCF!F12*DCF!F13 -> 235.25666 | G14: =DCF!G12*DCF!G13 -> 229.75097
B16: Terminal value = FCFF₅×(1+g)/(Ke−g) | C16: =DCF!G12*(1+Assumptions!$C$34)/(Assumptions!$C$14-Assumptions!$C$34) -> 5726.3287
B17: PV of terminal value | C17: =DCF!C16*DCF!G13 -> 3636.1939
B18: Enterprise value (retail) | C18: =SUM(DCF!C14:G14)+DCF!C17 -> 4826.0841
B19: + Retail net cash | C19: =Assumptions!$C$35 -> 388
B20: Retail equity value | C20: =DCF!C18+DCF!C19 -> 5214.0841
B21: Retail value per share (SAR) | C21: =DCF!C20/Assumptions!$C$6 -> 65.176052
B22: TV as % of enterprise value | C22: =DCF!C17/DCF!C18 -> 0.75344603

Sheet Income Statement
B1: Income Statement
B2: 3 historical + 5 forecast (SAR mn)
C4: FY2023 | D4: FY2024 | E4: FY2025 | F4: FY2026 | G4: FY2027 | H4: FY2028 | I4: FY2029 | J4: FY2030
B5: Revenue | C5: 6200.7 | D5: 6781.2 | E5: 7450 | F5: 7897 | G5: 8370.8 | H5: 8831.2 | I5: 9272.8 | J5: 9736.4
B6: COGS | C6: -4838.8 | D6: -5222.2 | E6: -5669
B7: Gross profit | C7: 1361.9 | D7: 1559 | E7: 1781 | F7: 1911.1 | G7: 2025.7 | H7: 2137.2 | I7: 2244 | J7: 2356.2
B8: SG&A | C8: -811 | D8: -857 | E8: -1000
B9: Impairment (CF provisions) | C9: -70 | D9: -93 | E9: -175
B10: EBIT | C10: 480.9 | D10: 639 | E10: 600 | F10: 647.6 | G10: 686.4 | H10: 724.2 | I10: 760.4 | J10: 798.4
B11: D&A | C11: 114 | D11: 119 | E11: 165
B12: EBITDA | C12: 595 | D12: 758 | E12: 765 | F12: 821.3 | G12: 870.6 | H12: 918.4 | I12: 964.4 | J12: 1012.6
B13: Finance charges | C13: -62 | D13: -60 | E13: -50
B14: Pre-tax profit | C14: 418 | D14: 579 | E14: 550
B15: Zakat/tax | C15: -29 | D15: -45 | E15: -53
B16: Net income (incl NCI) | C16: 389.5 | D16: 534.5 | E16: 497 | F16: 552.8 | G16: 586 | H16: 618.2 | I16: 649.1 | J16: 681.5
B17: EPS (SAR) | C17: 4.87 | D17: 6.68 | E17: 6.21 | F17: 6.91 | G17: 7.33 | H17: 7.73 | I17: 8.11 | J17: 8.52
B18: DPS (SAR) | C18: 3.3 | D18: 10 | E18: 4.72 | F18: 5.25 | G18: 5.57 | H18: 5.87 | I18: 6.17 | J18: 6.47

Sheet Balance Sheet
B1: Balance Sheet
B2: 3 historical + 5 forecast (SAR mn)
C4: FY2023 | D4: FY2024 | E4: FY2025 | F4: FY2026 | G4: FY2027 | H4: FY2028 | I4: FY2029 | J4: FY2030
B5: Cash & equivalents | C5: 158 | D5: 476 | E5: 660 | F5: 693 | G5: 728 | H5: 764 | I5: 802 | J5: 842
B6: Other current assets | C6: 2204 | D6: 2653 | E6: 2770 | F6: 2936 | G6: 3112 | H6: 3299 | I6: 3497 | J6: 3707
B7: PP&E | C7: 486 | D7: 486 | E7: 504 | F7: 519 | G7: 535 | H7: 551 | I7: 567 | J7: 584
B8: Right-of-use assets | C8: 451 | D8: 463 | E8: 483 | F8: 497 | G8: 512 | H8: 528 | I8: 544 | J8: 560
B9: Other non-current (finance rec.) | C9: 1142 | D9: 1324 | E9: 1763 | F9: 1975 | G9: 2212 | H9: 2477 | I9: 2774 | J9: 3107
B10: Total assets | C10: 4442 | D10: 5402 | E10: 6187 | F10: 6620 | G10: 7083 | H10: 7579 | I10: 8110 | J10: 8678
B11: Current liabilities | C11: 1679 | D11: 1662 | E11: 2070 | F11: 2194 | G11: 2326 | H11: 2465 | I11: 2613 | J11: 2770
B12: Non-current liabilities | C12: 1478 | D12: 1697 | E12: 1947 | F12: 2083 | G12: 2229 | H12: 2385 | I12: 2552 | J12: 2731
B13: Total equity (incl NCI) | C13: 1284 | D13: 2043 | E13: 2170 | F13: 2300 | G13: 2438 | H13: 2585 | I13: 2740 | J13: 2904

Sheet Cash Flow
B1: Cash Flow
B2: 3 historical + 5 forecast (SAR mn)
C4: FY2023 | D4: FY2024 | E4: FY2025 | F4: FY2026 | G4: FY2027 | H4: FY2028 | I4: FY2029 | J4: FY2030
B5: Cash from operations | C5: 300 | D5: 601 | E5: 609 | F5: 639 | G5: 671 | H5: 705 | I5: 740 | J5: 777
B6: Capex | C6: -59 | D6: -56 | E6: -76 | F6: -80 | G6: -84 | H6: -88 | I6: -92 | J6: -97
B7: Financing (incl dividends) | C7: -232 | D7: -226 | E7: -424 | F7: -445 | G7: -467 | H7: -491 | I7: -515 | J7: -541

Sheet Summary Financials
B1: Summary financials
B2: Every cell links to the statement sheets.
C4: FY2023 | D4: FY2024 | E4: FY2025 | F4: FY2026 | G4: FY2027 | H4: FY2028 | I4: FY2029 | J4: FY2030
B5: Revenue | C5: ='Income Statement'!C2 -> 0 | D5: ='Income Statement'!D2 -> 0 | E5: ='Income Statement'!E2 -> 0 | F5: ='Income Statement'!F2 -> 0 | G5: ='Income Statement'!G2 -> 0 | H5: ='Income Statement'!H2 -> 0 | I5: ='Income Statement'!I2 -> 0 | J5: ='Income Statement'!J2 -> 0
B6: EBITDA | C6: ='Income Statement'!C9 -> -70 | D6: ='Income Statement'!D9 -> -93 | E6: ='Income Statement'!E9 -> -175 | F6: ='Income Statement'!F9 -> 0 | G6: ='Income Statement'!G9 -> 0 | H6: ='Income Statement'!H9 -> 0 | I6: ='Income Statement'!I9 -> 0 | J6: ='Income Statement'!J9 -> 0
B7: Net income | C7: ='Income Statement'!C13 -> -62 | D7: ='Income Statement'!D13 -> -60 | E7: ='Income Statement'!E13 -> -50 | F7: ='Income Statement'!F13 -> 0 | G7: ='Income Statement'!G13 -> 0 | H7: ='Income Statement'!H13 -> 0 | I7: ='Income Statement'!I13 -> 0 | J7: ='Income Statement'!J13 -> 0
B8: Total assets | C8: ='Balance Sheet'!C7 -> 486 | D8: ='Balance Sheet'!D7 -> 486 | E8: ='Balance Sheet'!E7 -> 504 | F8: ='Balance Sheet'!F7 -> 519 | G8: ='Balance Sheet'!G7 -> 535 | H8: ='Balance Sheet'!H7 -> 551 | I8: ='Balance Sheet'!I7 -> 567 | J8: ='Balance Sheet'!J7 -> 584
B9: Total equity | C9: ='Balance Sheet'!C10 -> 4442 | D9: ='Balance Sheet'!D10 -> 5402 | E9: ='Balance Sheet'!E10 -> 6187 | F9: ='Balance Sheet'!F10 -> 6620 | G9: ='Balance Sheet'!G10 -> 7083 | H9: ='Balance Sheet'!H10 -> 7579 | I9: ='Balance Sheet'!I10 -> 8110 | J9: ='Balance Sheet'!J10 -> 8678
B10: Cash from operations | C10: ='Cash Flow'!C2 -> 0 | D10: ='Cash Flow'!D2 -> 0 | E10: ='Cash Flow'!E2 -> 0 | F10: ='Cash Flow'!F2 -> 0 | G10: ='Cash Flow'!G2 -> 0 | H10: ='Cash Flow'!H2 -> 0 | I10: ='Cash Flow'!I2 -> 0 | J10: ='Cash Flow'!J2 -> 0

Sheet Monte Carlo
B1: Monte Carlo — carry-anchored YZ-HAR-t
B2: 50,000 paths, seed 42. Values are simulation output (source: mc_v3 engine).
B4: The probability read (T+60)
B5: P(price above spot) | C5: 0.476
B6: P(+10%) vs P(−10%) | C6: 22% vs 22% (odds 0.97)
B7: Median level (SAR) / move | C7: 67.61 (-0.7%)
B8: 50% band (SAR) | C8: 62.0–73.79 (17% of spot)
B9: Touch +10% / −10% | C9: 40% / 39%
B11: Explained flat: expected total return ≈ rf (4.25%), delivered as a ~6.9% dividend; price median ≈ flat, slightly negative as q>rf.
B13: Percentile (SAR) | C13: T+20 | D13: T+60
B14: 5th | C14: 59.18 | D14: 53.25
B15: 10th | C15: 61.89 | D15: 57.62
B16: 25th | C16: 64.61 | D16: 62
B17: 50th | C17: 67.92 | D17: 67.61
B18: 75th | C18: 71.44 | D18: 73.79
B19: 90th | C19: 74.8 | D19: 80
B20: 95th | C20: 78.16 | D20: 86.21
B22: Engine: nu 5.0 (fitted), width_cal 1.3, anchor vol 31.6%, carry -0.60%/60d
B23: Step 0: PARITY (CRPS -0.050, CI [-0.140,+0.007]); PIT 0.48; cov50/80/90 0.72/0.89/1.00

Sheet Sensitivity
B1: Sensitivity — SOTP (SAR/share)
B2: Retail Ke × terminal g; and beta / Tasheel-multiple grids.
B4: Retail Ke | C4: g=2.0% | D4: g=3.0% | E4: g=4.0%
B5: 8.26% | C5: 95 | D5: 105 | E5: 119.7
B6: 9.51% | C6: 83.9 | D6: 90.4 | E6: 99.1
B7: 10.51% | C7: 77.4 | D7: 82.2 | E7: 88.4
B8: 11.22% | C8: 73.7 | D8: 77.6 | E8: 82.5
B10: SOTP by beta (rating ERP)
C11: 0.55 | D11: 0.7 | E11: 0.85 | F11: 1.0
B12: SAR/sh | C12: 105.1 | D12: 95.5 | E12: 88.1 | F12: 82.2
B14: SOTP by Tasheel P/B
C15: 1.6x | D15: 2.0x | E15: 2.4x | F15: 2.8x
B16: SAR/sh | C16: 81.7 | D16: 85.8 | E16: 89.9 | F16: 94.1

Sheet Per-Share & Ratios
B1: Per-share & ratio dashboard
B2: FY2025 actuals at spot.
C4: Value
B5: EPS (SAR) | C5: 6.21
B6: DPS (SAR, normalized) | C6: 4.72
B7: BVPS (SAR) | C7: 27.125
B8: P/E (x) | C8: 10.966184
B9: P/B (x) | C9: 2.5105991
B10: Dividend yield | C10: 0.069309838
B11: Payout ratio | C11: 0.76
B12: EV/EBITDA (group, x) | C12: 6.6143791
B13: Gross margin | C13: 0.239
B14: EBIT margin | C14: 0.080536913
B15: Net margin | C15: 0.066711409
B16: ROE (group) | C16: 0.22903226

Sheet Peer & Sector
B1: Peer set & sector
B2: Illustrative GCC/EM electronics retail + consumer-finance comparators.
C4: P/E (x) | D4: Div yield | E4: Note
B5: eXtra (4003) — subject | C5: 11 | D5: 0.069 | E5: 52-wk low; ~half of NI from finance
B6: Jarir Marketing (4190) | C6: 18.5 | D6: 0.054 | E6: Closest Saudi peer; ~9% net margin, re-rated
B7: Al Othaim Markets (4001) | C7: 16 | D7: 0.03 | E7: Saudi grocery + consumer retail
B8: Best Buy (BBY, approx.) | C8: 12 | D8: 0.045 | E8: US electronics retail (illustrative)
B9: Ceconomy/Currys (approx.) | C9: 10 | D9: 0.03 | E9: European electronics (illustrative)
