Workbook

Sheet READ FIRST
A1: Testahil — First Abu Dhabi Bank PJSC (ADX: FAB)
A2: Companion model · Independent Valuation Study · Educational analysis · Not investment advice
A5: What this workbook is. A transparent companion to the FAB valuation study. Every blue cell is an input; every
A6: black cell is a formula; green cells link across sheets. All inputs live on the Assumptions sheet — change one
A7: (the cost of equity, the terminal ROE, a loan-growth rate) and the whole model reprices.
A9: What it is not. It is not investment advice, a recommendation, a rating, or a price target. Values are model
A10: outputs shown as ranges. The preparer is not licensed by any securities regulator and may hold, and may in the
A11: future take or dispose of, a position in the security discussed.
A13: Lens. FAB is a bank; the primary lens is a dividend-discount / residual-income model (DDM), cross-checked by an
A14: FCFE (capital-generation) DCF, relative P/B–ROE and peer P/E, and a normalized-ROTE capitalization.
A16: Currency. AED billion unless stated; the dirham is pegged to the US dollar at USD/AED 3.6725. Per-share figures
A17: in AED. Spot AED 17.40 (3 Jul 2026). Shares outstanding 11.05bn.
... A23: Income Statement · Balance Sheet · Capital & Cash Flow · Summary Financials · Monte Carlo · Sensitivity · Per-Share & Ratios · Peer & Sector.

Sheet Summary
A1: Valuation summary — First Abu Dhabi Bank (ADX: FAB)
A2: Four-lens fair value vs spot. Base links live; bear/bull are scenario outputs (see study §1.5).
B3: Bear | C3: Base | D3: Bull | E3: Weight
A4: DDM (residual income) | B4: =DDM!B20 -> 16.869627 | C4: =DDM!$B$13 -> 19.814464 | D4: =DDM!D20 -> 22.7593 | E4: =Assumptions!$B$29 -> 0.4
A5: FCFE-DCF | B5: 17.2 | C5: ='FCFE-DCF'!B12 -> 20.695327 | D5: 21.5 | E5: =Assumptions!$B$30 -> 0.2
A6: Relative multiples | B6: 16 | C6: ='Relative & Normalized'!B12 -> 18.77744 | D6: 20.5 | E6: =Assumptions!$B$31 -> 0.15
A7: Normalized ROTE | B7: 18 | C7: ='Relative & Normalized'!B17 -> 19.923425 | D7: 23.5 | E7: =Assumptions!$B$32 -> 0.25
A8: Weighted central | B8: =SUMPRODUCT(B4:B7,$E$4:$E$7) -> 17.087851 | C8: =SUMPRODUCT(C4:C7,$E$4:$E$7) -> 19.862323 | D8: =SUMPRODUCT(D4:D7,$E$4:$E$7) -> 22.35372
A10: Spot price (AED) | C10: =Assumptions!$B$4 -> 17.4
A11: Upside to central base | C11: =C8/C10-1 -> 0.14151283
A13: Read: modestly undervalued; the swing factors are the sustainable ROE / cost of equity gap and the cost-of-risk
A14: normalization as Fed cuts compress FABs asset-sensitive margin.

Sheet Fundamental Valuation
A1: Fundamental valuation — football-field data
A2: Bear/base/bull per lens (links to Summary).
A3: Lens | B3: Bear | C3: Base | D3: Bull
A4: DDM | B4: =Summary!B4 -> 16.869627 | C4: =Summary!C4 -> 19.814464 | D4: =Summary!D4 -> 22.7593
A5: FCFE-DCF | B5: =Summary!B5 -> 17.2 | C5: =Summary!C5 -> 20.695327 | D5: =Summary!D5 -> 21.5
A6: Relative multiples | B6: =Summary!B6 -> 16 | C6: =Summary!C6 -> 18.77744 | D6: =Summary!D6 -> 20.5
A7: Normalized ROTE | B7: =Summary!B7 -> 18 | C7: =Summary!C7 -> 19.923425 | D7: =Summary!D7 -> 23.5
A8: Weighted central | B8: =Summary!B8 -> 17.087851 | C8: =Summary!C8 -> 19.862323 | D8: =Summary!D8 -> 22.35372
A9: Spot | C9: =Assumptions!$B$4 -> 17.4

Sheet Assumptions
A1: Assumptions — the single input layer
A2: All blue cells are inputs. Every other sheet links here.
A3: ANCHORS
A4: Spot price (AED/share) | B4: 17.4
A5: Shares outstanding (bn) | B5: 11.05
A6: USD/AED peg | B6: 3.6725
A7: Ordinary shareholders equity, FY25 (AED bn) | B7: 117
A8: Goodwill & intangibles (AED bn) | B8: 11
A9: Risk-weighted assets, FY25 (AED bn) | B9: 748
A10: Risk-free rate (rf) | B10: 0.045
A11: Equity risk premium (ERP) | B11: 0.065
A12: Beta | B12: 1
A13: Cost of equity (Ke = rf + β·ERP) | B13: =B10+B12*B11 -> 0.11
A14: Terminal growth (g) | B14: 0.045
A15: Effective tax rate | B15: 0.14
A16: CET1 target (capital build) | B16: 0.135
A18: DDM / RESIDUAL INCOME (primary)
A19: Terminal / sustainable ROE | B19: 0.155
A20: Justified terminal P/B = (ROE−g)/(Ke−g) | B20: =(B19-B14)/(B13-B14) -> 1.6923077
A22: RELATIVE & NORMALIZED
A23: Peer forward P/E (x) | B23: 9.5
A24: Justified-P/B basis ROE | B24: 0.165
A25: Sustainable ROTE (normalized) | B25: 0.18
A26: Relative-lens weight: P/B vs P/E | B26: 0.5
A28: SYNTHESIS WEIGHTS
A29: DDM weight | B29: 0.4
A30: FCFE-DCF weight | B30: 0.2
A31: Relative weight | B31: 0.15
A32: Normalized-ROTE weight | B32: 0.25
A34: BALANCE-SHEET STRUCTURE
A35: Interest-earning assets (% of total assets) | B35: 0.84
A36: AT1 capital, held flat (AED bn) | B36: 10.4
A38: FORECAST DRIVERS (FY26E–FY30E)
E39: FY26E | F39: FY27E | G39: FY28E | H39: FY29E | I39: FY30E
A40: Total-asset growth | E40: 0.08 | F40: 0.08 | G40: 0.07 | H40: 0.07 | I40: 0.06
A41: Net interest margin (model, on avg EA) | E41: 0.0172 | F41: 0.0168 | G41: 0.0166 | H41: 0.0166 | I41: 0.0167
A42: Non-interest income growth | E42: 0.06 | F42: 0.07 | G42: 0.07 | H42: 0.06 | I42: 0.06
A43: Cost-to-income ratio | E43: 0.22 | F43: 0.225 | G43: 0.23 | H43: 0.23 | I43: 0.23
A44: Cost of risk (bps on avg loans) | E44: 55 | F44: 60 | G44: 65 | H44: 65 | I44: 60
A45: Loan growth | E45: 0.1 | F45: 0.09 | G45: 0.08 | H45: 0.08 | I45: 0.07
...

Sheet DDM
A1: Dividend-discount / residual-income model (primary lens)
A2: PV of 5-year dividends + PV of terminal equity value (terminal BVPS × justified P/B). Discounted at Ke. Links to Assumptions.
E3: FY26E | F3: FY27E | G3: FY28E | H3: FY29E | I3: FY30E
A4: DPS (AED) | E4: ='Income Statement'!E18 -> 0.85298061 | F4: ='Income Statement'!F18 -> 0.90697546 | G4: ='Income Statement'!G18 -> 0.96789138 | H4: ='Income Statement'!H18 -> 1.0571308 | I4: ='Income Statement'!I18 -> 1.195063
A5: Discount factor @ Ke | E5: =1/(1+Assumptions!$B$13)^1 -> 0.9009009 | F5: =1/(1+Assumptions!$B$13)^2 -> 0.81162243 | G5: =1/(1+Assumptions!$B$13)^3 -> 0.73119138 | H5: =1/(1+Assumptions!$B$13)^4 -> 0.65873097 | I5: =1/(1+Assumptions!$B$13)^5 -> 0.59345133
A6: PV of DPS | E6: =E4*E5 -> 0.768451 | F6: =F4*F5 -> 0.73612163 | G6: =G4*G5 -> 0.70771384 | H6: =H4*H5 -> 0.69636482 | I6: =I4*I5 -> 0.70921175
A8: Σ PV of explicit dividends (AED) | B8: =SUM(E6:I6) -> 3.617863
A9: Terminal BVPS, end FY30 (AED) | B9: ='Balance Sheet'!I13/Assumptions!$B$5 -> 16.127218
A10: Justified terminal P/B (x) | B10: =Assumptions!$B$20 -> 1.6923077
A11: Terminal value per share (AED) | B11: =B9*B10 -> 27.292214
A12: PV of terminal value (AED) | B12: =B11*I5 -> 16.196601
A13: DDM fair value per share (AED) | B13: =B8+B12 -> 19.814464
A14: terminal as % of value | B14: =B12/B13 -> 0.81741302
A15: implied on FY26 EPS (P/E) | B15: =B13/'Income Statement'!E17 -> 10.453355
B16: bear | C16: base | D16: bull
A17: Scenario fair value (bear / base / bull)
A18: Terminal ROE | B18: 0.135 | C18: =Assumptions!$B$19 -> 0.155 | D18: 0.175
A19: Justified P/B | B19: =(B18-Assumptions!$B$14)/(Assumptions!$B$13-Assumptions!$B$14) -> 1.3846154 | C19: =(C18-Assumptions!$B$14)/(Assumptions!$B$13-Assumptions!$B$14) -> 1.6923077 | D19: =(D18-Assumptions!$B$14)/(Assumptions!$B$13-Assumptions!$B$14) -> 2
A20: Fair value per share (AED) | B20: =$B$8+$B$9*B19*$I$5 -> 16.869627 | C20: =$B$8+$B$9*C19*$I$5 -> 19.814464 | D20: =$B$8+$B$9*D19*$I$5 -> 22.7593

Sheet Segments
A1: Revenue composition
A2: Net interest income vs non-interest income, and mix (links to Income Statement).
B3: FY23 | C3: FY24 | D3: FY25 | E3: FY26E | F3: FY27E | G3: FY28E | H3: FY29E | I3: FY30E
A4: Net interest income | B4: ='Income Statement'!B5 -> 19.4 | C4: ='Income Statement'!C5 -> 19.5 | D4: ='Income Statement'!D5 -> 20.32 | E4: ='Income Statement'!E5 -> 21.036288 | F4: ='Income Statement'!F5 -> 22.190838 | G4: ='Income Statement'!G5 -> 23.566944 | H4: ='Income Statement'!H5 -> 25.21663 | I4: ='Income Statement'!I5 -> 27.013203
A5: Non-interest income | B5: ='Income Statement'!B6 -> 8.1 | C5: ='Income Statement'!C6 -> 12.1 | D5: ='Income Statement'!D6 -> 16.35 | E5: ='Income Statement'!E6 -> 17.331 | F5: ='Income Statement'!F6 -> 18.54417 | G5: ='Income Statement'!G6 -> 19.842262 | H5: ='Income Statement'!H6 -> 21.032798 | I5: ='Income Statement'!I6 -> 22.294765
A6: Total operating income | B6: ='Income Statement'!B7 -> 27.5 | C6: ='Income Statement'!C7 -> 31.6 | D6: ='Income Statement'!D7 -> 36.67 | E6: ='Income Statement'!E7 -> 38.367288 | F6: ='Income Statement'!F7 -> 40.735008 | G6: ='Income Statement'!G7 -> 43.409206 | H6: ='Income Statement'!H7 -> 46.249428 | I6: ='Income Statement'!I7 -> 49.307969
A7: Non-II as % of income | B7: =B5/B6 -> 0.29454545 | C7: =C5/C6 -> 0.38291139 | D7: =D5/D6 -> 0.44586856 | E7: =E5/E6 -> 0.45171293 | F7: =F5/F6 -> 0.45523914 | G7: =G5/G6 -> 0.45709802 | H7: =H5/H6 -> 0.45476882 | I7: =I5/I6 -> 0.4521534
A8: NII as % of income | B8: =B4/B6 -> 0.70545455 | C8: =C4/C6 -> 0.61708861 | D8: =D4/D6 -> 0.55413144 | E8: =E4/E6 -> 0.54828707 | F8: =F4/F6 -> 0.54476086 | G8: =G4/G6 -> 0.54290198 | H8: =H4/H6 -> 0.54523118 | I8: =I4/I6 -> 0.5478466
A10: Loans & advances (net) | B10: ='Balance Sheet'!B5 -> 485 | C10: ='Balance Sheet'!C5 -> 528 | D10: ='Balance Sheet'!D5 -> 616 | E10: ='Balance Sheet'!E5 -> 677.6 | F10: ='Balance Sheet'!F5 -> 738.584 | G10: ='Balance Sheet'!G5 -> 797.67072 | H10: ='Balance Sheet'!H5 -> 861.48438 | I10: ='Balance Sheet'!I5 -> 921.78828
A11: Customer deposits | B11: ='Balance Sheet'!B9 -> 758 | C11: ='Balance Sheet'!C9 -> 786 | D11: ='Balance Sheet'!D9 -> 841 | E11: ='Balance Sheet'!E9 -> 908.28 | F11: ='Balance Sheet'!F9 -> 971.8596 | G11: ='Balance Sheet'!G9 -> 1039.8898 | H11: ='Balance Sheet'!H9 -> 1102.2832 | I11: ='Balance Sheet'!I9 -> 1168.4201
A12: Loan-to-deposit ratio | B12: =B10/B11 -> 0.63984169 | C12: =C10/C11 -> 0.67175573 | D12: =D10/D11 -> 0.73246136 | E12: =E10/E11 -> 0.74602545 | F12: =F10/F11 -> 0.75996986 | G12: =G10/G11 -> 0.76707238 | H12: =H10/H11 -> 0.78154544 | I12: =I10/I11 -> 0.78891851

Sheet Relative & Normalized
A1: Relative multiples & normalized ROTE
A2: Justified P/B–ROE and peer forward P/E (relative); sustainable-ROTE capitalization (normalized). Links to Assumptions.
A4: Relative — justified P/B leg
A5: BVPS, FY25 (AED) | B5: =Assumptions!$B$7/Assumptions!$B$5 -> 10.588235
A6: Justified P/B on basis ROE | B6: =(Assumptions!$B$24-Assumptions!$B$14)/(Assumptions!$B$13-Assumptions!$B$14) -> 1.8461538
A7: Value per share — P/B leg (AED) | B7: =B5*B6 -> 19.547511
A8: Relative — peer P/E leg
A9: FY26 EPS (AED) | B9: ='Income Statement'!E17 -> 1.8955125
A10: Peer forward P/E (x) | B10: =Assumptions!$B$23 -> 9.5
A11: Value per share — P/E leg (AED) | B11: =B9*B10 -> 18.007368
A12: Relative fair value (blend) | B12: =Assumptions!$B$26*B7+(1-Assumptions!$B$26)*B11 -> 18.77744
A14: Normalized — sustainable ROTE
A15: TBVPS, FY25 (AED) | B15: =(Assumptions!$B$7-Assumptions!$B$8)/Assumptions!$B$5 -> 9.5927602
A16: Warranted P/TB = (ROTE−g)/(Ke−g) | B16: =(Assumptions!$B$25-Assumptions!$B$14)/(Assumptions!$B$13-Assumptions!$B$14) -> 2.0769231
A17: Normalized fair value (AED) | B17: =B15*B16 -> 19.923425

Sheet FCFE-DCF
A1: FCFE discounted cash-flow cross-check
A2: Explicit 5-year FCFE (capital-generation), terminal value via Gordon on FCFE, discounted at Ke. Links to Capital & Cash Flow.
E3: FY26E | F3: FY27E | G3: FY28E | H3: FY29E | I3: FY30E
A4: FCFE (AED bn) | E4: ='Capital & Cash Flow'!E7 -> 12.867013 | F4: ='Capital & Cash Flow'!F7 -> 13.062456 | G4: ='Capital & Cash Flow'!G7 -> 14.510929 | H4: ='Capital & Cash Flow'!H7 -> 15.51408 | I4: ='Capital & Cash Flow'!I7 -> 18.319903
A5: Discount factor @ Ke | E5: =1/(1+Assumptions!$B$13)^1 -> 0.9009009 | F5: =1/(1+Assumptions!$B$13)^2 -> 0.81162243 | G5: =1/(1+Assumptions!$B$13)^3 -> 0.73119138 | H5: =1/(1+Assumptions!$B$13)^4 -> 0.65873097 | I5: =1/(1+Assumptions!$B$13)^5 -> 0.59345133
A6: PV of FCFE | E6: =E4*E5 -> 11.591903 | F6: =F4*F5 -> 10.601782 | G6: =G4*G5 -> 10.610266 | H6: =H4*H5 -> 10.219605 | I6: =I4*I5 -> 10.871971
A8: Σ PV of explicit FCFE (AED bn) | B8: =SUM(E6:I6) -> 53.895528
A9: Terminal value (Gordon on FCFE) | B9: =I4*(1+Assumptions!$B$14)/(Assumptions!$B$13-Assumptions!$B$14) -> 294.52767
A10: PV of terminal value | B10: =B9*I5 -> 174.78784
A11: Equity value (AED bn) | B11: =B8+B10 -> 228.68337
A12: Fair value per share (AED) | B12: =B11/Assumptions!$B$5 -> 20.695327
A13: % terminal of equity value | B13: =B10/B11 -> 0.76432248

Sheet Income Statement
A1: Income statement (AED bn, consolidated)
A2: FY23–FY25 disclosed (blue); FY26–FY30 forecast (formulas linking to Assumptions). EPS after AT1 coupons.
B3: FY23 | C3: FY24 | D3: FY25 | E3: FY26E | F3: FY27E | G3: FY28E | H3: FY29E | I3: FY30E
A4: Interest-earning assets (avg, memo) | B4: =Assumptions!$B$35*'Balance Sheet'!B12 -> 983.64 | C4: =Assumptions!$B$35*('Balance Sheet'!C12+'Balance Sheet'!B12)/2 -> 1000.02 | D4: =Assumptions!$B$35*('Balance Sheet'!D12+'Balance Sheet'!C12)/2 -> 1096.2 | E4: =Assumptions!$B$35*('Balance Sheet'!E12+'Balance Sheet'!D12)/2 -> 1223.04 | F4: =Assumptions!$B$35*('Balance Sheet'!F12+'Balance Sheet'!E12)/2 -> 1320.8832 | G4: =Assumptions!$B$35*('Balance Sheet'!G12+'Balance Sheet'!F12)/2 -> 1419.6954 | H4: =Assumptions!$B$35*('Balance Sheet'!H12+'Balance Sheet'!G12)/2 -> 1519.0741 | I4: =Assumptions!$B$35*('Balance Sheet'!I12+'Balance Sheet'!H12)/2 -> 1617.5571
A5: Net interest income | B5: 19.4 | C5: 19.5 | D5: 20.32 | E5: =Assumptions!E41*E4 -> 21.036288 | F5: =Assumptions!F41*F4 -> 22.190838 | G5: =Assumptions!G41*G4 -> 23.566944 | H5: =Assumptions!H41*H4 -> 25.21663 | I5: =Assumptions!I41*I4 -> 27.013203
A6: Non-interest income | B6: 8.1 | C6: 12.1 | D6: 16.35 | E6: =D6*(1+Assumptions!E42) -> 17.331 | F6: =E6*(1+Assumptions!F42) -> 18.54417 | G6: =F6*(1+Assumptions!G42) -> 19.842262 | H6: =G6*(1+Assumptions!H42) -> 21.032798 | I6: =H6*(1+Assumptions!I42) -> 22.294765
A7: Total operating income | B7: =B5+B6 -> 27.5 | C7: =C5+C6 -> 31.6 | D7: =D5+D6 -> 36.67 | E7: =E5+E6 -> 38.367288 | F7: =F5+F6 -> 40.735008 | G7: =G5+G6 -> 43.409206 | H7: =H5+H6 -> 46.249428 | I7: =I5+I6 -> 49.307969
A8: Operating expenses | B8: -6.05 | C8: -6.9 | D8: -8 | E8: =-Assumptions!E43*E7 -> -8.4408034 | F8: =-Assumptions!F43*F7 -> -9.1653767 | G8: =-Assumptions!G43*G7 -> -9.9841174 | H8: =-Assumptions!H43*H7 -> -10.637368 | I8: =-Assumptions!I43*I7 -> -11.340833
A9: Pre-provision operating profit | B9: =B7+B8 -> 21.45 | C9: =C7+C8 -> 24.7 | D9: =D7+D8 -> 28.67 | E9: =E7+E8 -> 29.926485 | F9: =F7+F8 -> 31.569631 | G9: =G7+G8 -> 33.425089 | H9: =H7+H8 -> 35.612059 | I9: =I7+I8 -> 37.967136
A10: Impairment / cost of risk | B10: -3.2 | C10: -3.5 | D10: -3 | E10: =-Assumptions!E44/10000*('Balance Sheet'!E5+'Balance Sheet'!D5)/2 -> -3.5574 | F10: =-Assumptions!F44/10000*('Balance Sheet'!F5+'Balance Sheet'!E5)/2 -> -4.248552 | G10: =-Assumptions!G44/10000*('Balance Sheet'!G5+'Balance Sheet'!F5)/2 -> -4.9928278 | H10: =-Assumptions!H44/10000*('Balance Sheet'!H5+'Balance Sheet'!G5)/2 -> -5.3922541 | I10: =-Assumptions!I44/10000*('Balance Sheet'!I5+'Balance Sheet'!H5)/2 -> -5.349818
A11: Associates / other | B11: -0.65 | C11: -1.3 | D11: -1.28 | E11: =Assumptions!E49 -> -1.2 | F11: =Assumptions!F49 -> -1.15 | G11: =Assumptions!G49 -> -1.1 | H11: =Assumptions!H49 -> -1.05 | I11: =Assumptions!I49 -> -1
A12: Profit before tax | B12: =B9+B10+B11 -> 17.6 | C12: =C9+C10+C11 -> 19.9 | D12: =D9+D10+D11 -> 24.39 | E12: =E9+E10+E11 -> 25.169085 | F12: =F9+F10+F11 -> 26.171079 | G12: =G9+G10+G11 -> 27.332261 | H12: =H9+H10+H11 -> 29.169805 | I12: =I9+I10+I11 -> 31.617318
A13: Tax | B13: -1.2 | C13: -2.8 | D13: -3.3 | E13: =-E12*Assumptions!$B$15 -> -3.5236718 | F13: =-F12*Assumptions!$B$15 -> -3.6639511 | G13: =-G12*Assumptions!$B$15 -> -3.8265165 | H13: =-H12*Assumptions!$B$15 -> -4.0837727 | I13: =-I12*Assumptions!$B$15 -> -4.4264245
A14: Net profit (attributable to equity holders) | B14: =B12+B13 -> 16.4 | C14: =C12+C13 -> 17.1 | D14: =D12+D13 -> 21.09 | E14: =E12+E13 -> 21.645413 | F14: =F12+F13 -> 22.507128 | G14: =G12+G13 -> 23.505744 | H14: =H12+H13 -> 25.086033 | I14: =I12+I13 -> 27.190893
A15: less: AT1 coupons | B15: -0.55 | C15: -0.65 | D15: -0.67 | E15: =-Assumptions!E48 -> -0.7 | F15: =-Assumptions!F48 -> -0.72 | G15: =-Assumptions!G48 -> -0.75 | H15: =-Assumptions!H48 -> -0.75 | I15: =-Assumptions!I48 -> -0.78
A16: Profit attributable to ordinary shareholders | B16: =B14+B15 -> 15.85 | C16: =C14+C15 -> 16.45 | D16: =D14+D15 -> 20.42 | E16: =E14+E15 -> 20.945413 | F16: =F14+F15 -> 21.787128 | G16: =G14+G15 -> 22.755744 | H16: =H14+H15 -> 24.336033 | I16: =I14+I15 -> 26.410893
A17: EPS (AED) | B17: =B16/Assumptions!$B$5 -> 1.4343891 | C17: =C16/Assumptions!$B$5 -> 1.4886878 | D17: =D16/Assumptions!$B$5 -> 1.8479638 | E17: =E16/Assumptions!$B$5 -> 1.8955125 | F17: =F16/Assumptions!$B$5 -> 1.9716858 | G17: =G16/Assumptions!$B$5 -> 2.0593434 | H17: =H16/Assumptions!$B$5 -> 2.2023559 | I17: =I16/Assumptions!$B$5 -> 2.3901261
A18: DPS (AED) | B18: 0.71 | C18: 0.75 | D18: 0.8 | E18: =E17*Assumptions!E50 -> 0.85298061 | F18: =F17*Assumptions!F50 -> 0.90697546 | G18: =G17*Assumptions!G50 -> 0.96789138 | H18: =H17*Assumptions!H50 -> 1.0571308 | I18: =I17*Assumptions!I50 -> 1.195063
A19: Cost-to-income ratio | B19: =-B8/B7 -> 0.22 | C19: =-C8/C7 -> 0.21835443 | D19: =-D8/D7 -> 0.21816199 | E19: =-E8/E7 -> 0.22 | F19: =-F8/F7 -> 0.225 | G19: =-G8/G7 -> 0.23 | H19: =-H8/H7 -> 0.23 | I19: =-I8/I7 -> 0.23
A20: Net-profit growth (YoY) | C20: =C14/B14-1 -> 0.042682927 | D20: =D14/C14-1 -> 0.23333333 | E20: =E14/D14-1 -> 0.026335362 | F20: =F14/E14-1 -> 0.039810521 | G20: =G14/F14-1 -> 0.04436889 | H20: =H14/G14-1 -> 0.067229878 | I20: =I14/H14-1 -> 0.083905686
A22: Source: FAB FY2025 results (company disclosure). FY23–25 operating-income basis; some line items (opex, impairment,
A23: associates) apportioned to tie to disclosed PBT / net profit. Forecast = formulas linking to Assumptions.

Sheet Balance Sheet
A1: Balance sheet (AED bn, consolidated)
A2: Historical anchored to disclosed loans/deposits/equity/RWA; other-assets and other-liabilities plug to disclosed totals.
B3: FY23 | C3: FY24 | D3: FY25 | E3: FY26E | F3: FY27E | G3: FY28E | H3: FY29E | I3: FY30E
A4: Cash & balances with central banks | B4: 180 | C4: 175 | D4: 200 | E4: =D4*(1+Assumptions!E40) -> 216 | F4: =E4*(1+Assumptions!F40) -> 233.28 | G4: =F4*(1+Assumptions!G40) -> 249.6096 | H4: =G4*(1+Assumptions!H40) -> 267.08227 | I4: =H4*(1+Assumptions!I40) -> 283.10721
A5: Loans & advances (net) | B5: 485 | C5: 528 | D5: 616 | E5: =D5*(1+Assumptions!E45) -> 677.6 | F5: =E5*(1+Assumptions!F45) -> 738.584 | G5: =F5*(1+Assumptions!G45) -> 797.67072 | H5: =G5*(1+Assumptions!H45) -> 861.48438 | I5: =H5*(1+Assumptions!I45) -> 921.78828
A6: Investment securities | B6: 230 | C6: 240 | D6: 260 | E6: =D6*(1+Assumptions!E40) -> 280.8 | F6: =E6*(1+Assumptions!F40) -> 303.264 | G6: =F6*(1+Assumptions!G40) -> 324.49248 | H6: =G6*(1+Assumptions!H40) -> 347.20695 | I6: =H6*(1+Assumptions!I40) -> 368.03937
A7: Total assets | B7: 1171 | C7: 1210 | D7: 1400 | E7: =D7*(1+Assumptions!E40) -> 1512 | F7: =E7*(1+Assumptions!F40) -> 1632.96 | G7: =F7*(1+Assumptions!G40) -> 1747.2672 | H7: =G7*(1+Assumptions!H40) -> 1869.5759 | I7: =H7*(1+Assumptions!I40) -> 1981.7505
A8: Other assets (plug) | B8: =B7-B4-B5-B6 -> 276 | C8: =C7-C4-C5-C6 -> 267 | D8: =D7-D4-D5-D6 -> 324 | E8: =E7-E4-E5-E6 -> 337.6 | F8: =F7-F4-F5-F6 -> 357.832 | G8: =G7-G4-G5-G6 -> 375.4944 | H8: =H7-H4-H5-H6 -> 393.8023 | I8: =I7-I4-I5-I6 -> 408.8156
A9: Customer deposits | B9: 758 | C9: 786 | D9: 841 | E9: =D9*(1+Assumptions!E46) -> 908.28 | F9: =E9*(1+Assumptions!F46) -> 971.8596 | G9: =F9*(1+Assumptions!G46) -> 1039.8898 | H9: =G9*(1+Assumptions!H46) -> 1102.2832 | I9: =H9*(1+Assumptions!I46) -> 1168.4201
A10: Due to banks, repos & debt securities | B10: 240 | C10: 245 | D10: 310 | E10: =D10*(1+Assumptions!E46) -> 334.8 | F10: =E10*(1+Assumptions!F46) -> 358.236 | G10: =F10*(1+Assumptions!G46) -> 383.31252 | H10: =G10*(1+Assumptions!H46) -> 406.31127 | I10: =H10*(1+Assumptions!I46) -> 430.68995
A11: Other liabilities (plug) | B11: =B7-B9-B10-B16 -> 59 | C11: =C7-C9-C10-C16 -> 56.4 | D11: =D7-D9-D10-D16 -> 114 | E11: =E7-E9-E10-E16 -> 122.40002 | F11: =F7-F9-F10-F16 -> 144.57937 | G11: =G7-G9-G10-G16 -> 153.71934 | H11: =H7-H9-H10-H16 -> 177.98117 | I11: =I7-I9-I10-I16 -> 186.43461
A12: Total assets (memo, = row 7) | B12: =B7 -> 1171 | C12: =C7 -> 1210 | D12: =D7 -> 1400 | E12: =E7 -> 1512 | F12: =F7 -> 1632.96 | G12: =G7 -> 1747.2672 | H12: =H7 -> 1869.5759 | I12: =I7 -> 1981.7505
A13: Ordinary shareholders equity | B13: 102 | C13: 110 | D13: =Assumptions!$B$7 -> 117 | E13: =D13+'Income Statement'!E16-'Income Statement'!E18*Assumptions!$B$5 -> 128.51998 | F13: =E13+'Income Statement'!F16-'Income Statement'!F18*Assumptions!$B$5 -> 140.28503 | G13: =F13+'Income Statement'!G16-'Income Statement'!G18*Assumptions!$B$5 -> 152.34557 | H13: =G13+'Income Statement'!H16-'Income Statement'!H18*Assumptions!$B$5 -> 165.00031 | I13: =H13+'Income Statement'!I16-'Income Statement'!I18*Assumptions!$B$5 -> 178.20575
A14: AT1 capital | B14: 10 | C14: 10.2 | D14: 10.4 | E14: =Assumptions!$B$36 -> 10.4 | F14: =Assumptions!$B$36 -> 10.4 | G14: =Assumptions!$B$36 -> 10.4 | H14: =Assumptions!$B$36 -> 10.4 | I14: =Assumptions!$B$36 -> 10.4
A15: Non-controlling interests | B15: 2 | C15: 2.4 | D15: 7.6 | E15: =D15 -> 7.6 | F15: =E15 -> 7.6 | G15: =F15 -> 7.6 | H15: =G15 -> 7.6 | I15: =H15 -> 7.6
A16: Total equity | B16: =B13+B14+B15 -> 114 | C16: =C13+C14+C15 -> 122.6 | D16: =D13+D14+D15 -> 135 | E16: =E13+E14+E15 -> 146.51998 | F16: =F13+F14+F15 -> 158.28503 | G16: =G13+G14+G15 -> 170.34557 | H16: =H13+H14+H15 -> 183.00031 | I16: =I13+I14+I15 -> 196.20575
A17: Total liabilities & equity | B17: =B9+B10+B11+B16 -> 1171 | C17: =C9+C10+C11+C16 -> 1210 | D17: =D9+D10+D11+D16 -> 1400 | E17: =E9+E10+E11+E16 -> 1512 | F17: =F9+F10+F11+F16 -> 1632.96 | G17: =G9+G10+G11+G16 -> 1747.2672 | H17: =H9+H10+H11+H16 -> 1869.5759 | I17: =I9+I10+I11+I16 -> 1981.7505
A18: Balance check (assets − L&E) | B18: =B7-B17 -> 0 | C18: =C7-C17 -> 0 | D18: =D7-D17 -> 0 | E18: =E7-E17 -> 0 | F18: =F7-F17 -> 0 | G18: =G7-G17 -> 0 | H18: =H7-H17 -> 0 | I18: =I7-I17 -> 0
A19: Risk-weighted assets | B19: 680 | C19: 710 | D19: =Assumptions!$B$9 -> 748 | E19: =D19*(1+Assumptions!E47) -> 807.84 | F19: =E19*(1+Assumptions!F47) -> 872.4672 | G19: =F19*(1+Assumptions!G47) -> 933.5399 | H19: =G19*(1+Assumptions!H47) -> 998.8877 | I19: =H19*(1+Assumptions!I47) -> 1058.821
A20: CET1 capital (equity − goodwill) | B20: =B13-Assumptions!$B$8 -> 91 | C20: =C13-Assumptions!$B$8 -> 99 | D20: =D13-Assumptions!$B$8 -> 106 | E20: =E13-Assumptions!$B$8 -> 117.51998 | F20: =F13-Assumptions!$B$8 -> 129.28503 | G20: =G13-Assumptions!$B$8 -> 141.34557 | H20: =H13-Assumptions!$B$8 -> 154.00031 | I20: =I13-Assumptions!$B$8 -> 167.20575
A21: CET1 ratio | B21: =B20/B19 -> 0.13382353 | C21: =C20/C19 -> 0.13943662 | D21: =D20/D19 -> 0.14171123 | E21: =E20/E19 -> 0.14547432 | F21: =F20/F19 -> 0.14818325 | G21: =G20/G19 -> 0.15140817 | H21: =H20/H19 -> 0.15417179 | I21: =I20/I19 -> 0.15791693
A23: Source: FAB FY2025 disclosure (loans, deposits, equity, RWA anchored). Other-assets/other-liabilities are plugs so
A24: totals tie exactly to disclosed balance-sheet size; balance check = 0 by construction.

Sheet Capital & Cash Flow
A1: Capital generation & cash flow (AED bn, forecast)
A2: Bank FCFE = profit attributable to ordinary − capital retained for RWA growth (at target CET1). Ties to Balance Sheet.
E3: FY26E | F3: FY27E | G3: FY28E | H3: FY29E | I3: FY30E
A4: Profit attributable to ordinary | E4: ='Income Statement'!E16 -> 20.945413 | F4: ='Income Statement'!F16 -> 21.787128 | G4: ='Income Statement'!G16 -> 22.755744 | H4: ='Income Statement'!H16 -> 24.336033 | I4: ='Income Statement'!I16 -> 26.410893
A5: ΔRWA | E5: ='Balance Sheet'!E19-'Balance Sheet'!D19 -> 59.84 | F5: ='Balance Sheet'!F19-'Balance Sheet'!E19 -> 64.6272 | G5: ='Balance Sheet'!G19-'Balance Sheet'!F19 -> 61.072704 | H5: ='Balance Sheet'!H19-'Balance Sheet'!G19 -> 65.347793 | I5: ='Balance Sheet'!I19-'Balance Sheet'!H19 -> 59.933262
A6: Capital retained (ΔRWA × CET1 target) | E6: =-E5*Assumptions!$B$16 -> -8.0784 | F6: =-F5*Assumptions!$B$16 -> -8.724672 | G6: =-G5*Assumptions!$B$16 -> -8.244815 | H6: =-H5*Assumptions!$B$16 -> -8.8219521 | I6: =-I5*Assumptions!$B$16 -> -8.0909903
A7: Free cash flow to equity (FCFE) | E7: =E4+E6 -> 12.867013 | F7: =F4+F6 -> 13.062456 | G7: =G4+G6 -> 14.510929 | H7: =H4+H6 -> 15.51408 | I7: =I4+I6 -> 18.319903
A8: Dividends paid | E8: =-'Income Statement'!E18*Assumptions!$B$5 -> -9.4254358 | F8: =-'Income Statement'!F18*Assumptions!$B$5 -> -10.022079 | G8: =-'Income Statement'!G18*Assumptions!$B$5 -> -10.6952 | H8: =-'Income Statement'!H18*Assumptions!$B$5 -> -11.681296 | I8: =-'Income Statement'!I18*Assumptions!$B$5 -> -13.205447
A9: Retained for capital build | E9: ='Income Statement'!E16+E8 -> 11.519977 | F9: ='Income Statement'!F16+F8 -> 11.765049 | G9: ='Income Statement'!G16+G8 -> 12.060544 | H9: ='Income Statement'!H16+H8 -> 12.654737 | I9: ='Income Statement'!I16+I8 -> 13.205447
A10: Dividend payout ratio | E10: =-E8/'Income Statement'!E16 -> 0.45 | F10: =-F8/'Income Statement'!F16 -> 0.46 | G10: =-G8/'Income Statement'!G16 -> 0.47 | H10: =-H8/'Income Statement'!H16 -> 0.48 | I10: =-I8/'Income Statement'!I16 -> 0.5
A11: FCFE payout coverage (FCFE ÷ dividends) | E11: =E7/-E8 -> 1.3651372 | F11: =F7/-F8 -> 1.3033679 | G11: =G7/-G8 -> 1.3567703 | H11: =H7/-H8 -> 1.328113 | I11: =I7/-I8 -> 1.387299

Sheet Summary Financials
A1: Summary financials (AED bn)
A2: Every cell links to the statement sheets.
B3: FY23 | C3: FY24 | D3: FY25 | E3: FY26E | F3: FY27E | G3: FY28E | H3: FY29E | I3: FY30E
A4: Total operating income | B4: ='Income Statement'!B7 -> 27.5 | C4: ='Income Statement'!C7 -> 31.6 | D4: ='Income Statement'!D7 -> 36.67 | E4: ='Income Statement'!E7 -> 38.367288 | F4: ='Income Statement'!F7 -> 40.735008 | G4: ='Income Statement'!G7 -> 43.409206 | H4: ='Income Statement'!H7 -> 46.249428 | I4: ='Income Statement'!I7 -> 49.307969
A5: Pre-provision profit | B5: ='Income Statement'!B9 -> 21.45 | C5: ='Income Statement'!C9 -> 24.7 | D5: ='Income Statement'!D9 -> 28.67 | E5: ='Income Statement'!E9 -> 29.926485 | F5: ='Income Statement'!F9 -> 31.569631 | G5: ='Income Statement'!G9 -> 33.425089 | H5: ='Income Statement'!H9 -> 35.612059 | I5: ='Income Statement'!I9 -> 37.967136
A6: Net profit | B6: ='Income Statement'!B14 -> 16.4 | C6: ='Income Statement'!C14 -> 17.1 | D6: ='Income Statement'!D14 -> 21.09 | E6: ='Income Statement'!E14 -> 21.645413 | F6: ='Income Statement'!F14 -> 22.507128 | G6: ='Income Statement'!G14 -> 23.505744 | H6: ='Income Statement'!H14 -> 25.086033 | I6: ='Income Statement'!I14 -> 27.190893
A7: Attributable to ordinary | B7: ='Income Statement'!B16 -> 15.85 | C7: ='Income Statement'!C16 -> 16.45 | D7: ='Income Statement'!D16 -> 20.42 | E7: ='Income Statement'!E16 -> 20.945413 | F7: ='Income Statement'!F16 -> 21.787128 | G7: ='Income Statement'!G16 -> 22.755744 | H7: ='Income Statement'!H16 -> 24.336033 | I7: ='Income Statement'!I16 -> 26.410893
A8: Loans & advances | B8: ='Balance Sheet'!B5 -> 485 | C8: ='Balance Sheet'!C5 -> 528 | D8: ='Balance Sheet'!D5 -> 616 | E8: ='Balance Sheet'!E5 -> 677.6 | F8: ='Balance Sheet'!F5 -> 738.584 | G8: ='Balance Sheet'!G5 -> 797.67072 | H8: ='Balance Sheet'!H5 -> 861.48438 | I8: ='Balance Sheet'!I5 -> 921.78828
A9: Customer deposits | B9: ='Balance Sheet'!B9 -> 758 | C9: ='Balance Sheet'!C9 -> 786 | D9: ='Balance Sheet'!D9 -> 841 | E9: ='Balance Sheet'!E9 -> 908.28 | F9: ='Balance Sheet'!F9 -> 971.8596 | G9: ='Balance Sheet'!G9 -> 1039.8898 | H9: ='Balance Sheet'!H9 -> 1102.2832 | I9: ='Balance Sheet'!I9 -> 1168.4201
A10: Total assets | B10: ='Balance Sheet'!B7 -> 1171 | C10: ='Balance Sheet'!C7 -> 1210 | D10: ='Balance Sheet'!D7 -> 1400 | E10: ='Balance Sheet'!E7 -> 1512 | F10: ='Balance Sheet'!F7 -> 1632.96 | G10: ='Balance Sheet'!G7 -> 1747.2672 | H10: ='Balance Sheet'!H7 -> 1869.5759 | I10: ='Balance Sheet'!I7 -> 1981.7505
A11: Ordinary equity | B11: ='Balance Sheet'!B13 -> 102 | C11: ='Balance Sheet'!C13 -> 110 | D11: ='Balance Sheet'!D13 -> 117 | E11: ='Balance Sheet'!E13 -> 128.51998 | F11: ='Balance Sheet'!F13 -> 140.28503 | G11: ='Balance Sheet'!G13 -> 152.34557 | H11: ='Balance Sheet'!H13 -> 165.00031 | I11: ='Balance Sheet'!I13 -> 178.20575
A12: RWA | B12: ='Balance Sheet'!B19 -> 680 | C12: ='Balance Sheet'!C19 -> 710 | D12: ='Balance Sheet'!D19 -> 748 | E12: ='Balance Sheet'!E19 -> 807.84 | F12: ='Balance Sheet'!F19 -> 872.4672 | G12: ='Balance Sheet'!G19 -> 933.5399 | H12: ='Balance Sheet'!H19 -> 998.8877 | I12: ='Balance Sheet'!I19 -> 1058.821
A13: CET1 ratio | B13: ='Balance Sheet'!B21 -> 0.13382353 | C13: ='Balance Sheet'!C21 -> 0.13943662 | D13: ='Balance Sheet'!D21 -> 0.14171123 | E13: ='Balance Sheet'!E21 -> 0.14547432 | F13: ='Balance Sheet'!F21 -> 0.14818325 | G13: ='Balance Sheet'!G21 -> 0.15140817 | H13: ='Balance Sheet'!H21 -> 0.15417179 | I13: ='Balance Sheet'!I21 -> 0.15791693

Sheet Monte Carlo
A1: Monte Carlo — engine outputs
A2: 50,000 paths · 16 factors · seed 42 · YZ-HAR width · Student-t(5) · zero drift (international name). Values, not a sheet simulation.
A3: Percentile map (AED/share)
A4: Horizon | B4: p5 | C4: p25 | D4: p50 | E4: p75 | F4: p95
A5: T+20 sessions | B5: 14.97 | C5: 16.44 | D5: 17.32 | E5: 18.18 | F5: 19.75
A6: T+60 sessions | B6: 13.37 | C6: 15.53 | D6: 17.05 | E6: 18.59 | F6: 21.45
A8: Diffusion volatility (annualized) | D8: 0.3069
A9: Net 3-month drift | D9: 0
A10: Spot (AED) | D10: =Assumptions!$B$4 -> 17.4
A12: Level-touch ladder (probability price is reached)
A13: Level (AED) | B13: T+20 | C13: T+60
A14: 20 | B14: 0.059 | C14: 0.218
A15: 19 | B15: 0.177 | C15: 0.395
A16: 18.5 | B16: 0.304 | C16: 0.523
A17: 18 | B17: 0.505 | C17: 0.681
A18: 17.5 | B18: 0.805 | C18: 0.88
A19: 17 | B19: 0.639 | C19: 0.809
A20: 16.5 | B20: 0.401 | C20: 0.656
A21: 16 | B21: 0.24 | C21: 0.517
A22: 15 | B22: 0.077 | C22: 0.291

Sheet Sensitivity
A1: DDM sensitivity — the terminal-value swing
A2: DDM fair value (AED/share) by terminal ROE × cost of equity, holding g and the 5-year dividend path. Live off Assumptions.
A4: Ke \ term ROE | B4: 0.14 | C4: 0.15 | D4: 0.155 | E4: 0.16 | F4: 0.17 | G4: 0.18
A5: 0.1 | B5: =DDM!$B$8+DDM!$B$9*((B$4-Assumptions!$B$14)/($A5-Assumptions!$B$14))/(1+$A5)^5 -> 20.914311 | C5: =DDM!$B$8+DDM!$B$9*((C$4-Assumptions!$B$14)/($A5-Assumptions!$B$14))/(1+$A5)^5 -> 22.73499 | D5: =DDM!$B$8+DDM!$B$9*((D$4-Assumptions!$B$14)/($A5-Assumptions!$B$14))/(1+$A5)^5 -> 23.64533 | E5: =DDM!$B$8+DDM!$B$9*((E$4-Assumptions!$B$14)/($A5-Assumptions!$B$14))/(1+$A5)^5 -> 24.555669 | F5: =DDM!$B$8+DDM!$B$9*((F$4-Assumptions!$B$14)/($A5-Assumptions!$B$14))/(1+$A5)^5 -> 26.376348 | G5: =DDM!$B$8+DDM!$B$9*((G$4-Assumptions!$B$14)/($A5-Assumptions!$B$14))/(1+$A5)^5 -> 28.197027
A6: 0.105 | B6: =DDM!$B$8+DDM!$B$9*((B$4-Assumptions!$B$14)/($A6-Assumptions!$B$14))/(1+$A6)^5 -> 19.11746 | C6: =DDM!$B$8+DDM!$B$9*((C$4-Assumptions!$B$14)/($A6-Assumptions!$B$14))/(1+$A6)^5 -> 20.748997 | D6: =DDM!$B$8+DDM!$B$9*((D$4-Assumptions!$B$14)/($A6-Assumptions!$B$14))/(1+$A6)^5 -> 21.564765 | E6: =DDM!$B$8+DDM!$B$9*((E$4-Assumptions!$B$14)/($A6-Assumptions!$B$14))/(1+$A6)^5 -> 22.380533 | F6: =DDM!$B$8+DDM!$B$9*((F$4-Assumptions!$B$14)/($A6-Assumptions!$B$14))/(1+$A6)^5 -> 24.01207 | G6: =DDM!$B$8+DDM!$B$9*((G$4-Assumptions!$B$14)/($A6-Assumptions!$B$14))/(1+$A6)^5 -> 25.643606
A7: 0.11 | B7: =DDM!$B$8+DDM!$B$9*((B$4-Assumptions!$B$14)/($A7-Assumptions!$B$14))/(1+$A7)^5 -> 17.605837 | C7: =DDM!$B$8+DDM!$B$9*((C$4-Assumptions!$B$14)/($A7-Assumptions!$B$14))/(1+$A7)^5 -> 19.078255 | D7: =DDM!$B$8+DDM!$B$9*((D$4-Assumptions!$B$14)/($A7-Assumptions!$B$14))/(1+$A7)^5 -> 19.814464 | E7: =DDM!$B$8+DDM!$B$9*((E$4-Assumptions!$B$14)/($A7-Assumptions!$B$14))/(1+$A7)^5 -> 20.550673 | F7: =DDM!$B$8+DDM!$B$9*((F$4-Assumptions!$B$14)/($A7-Assumptions!$B$14))/(1+$A7)^5 -> 22.023091 | G7: =DDM!$B$8+DDM!$B$9*((G$4-Assumptions!$B$14)/($A7-Assumptions!$B$14))/(1+$A7)^5 -> 23.49551
A8: 0.115 | B8: =DDM!$B$8+DDM!$B$9*((B$4-Assumptions!$B$14)/($A8-Assumptions!$B$14))/(1+$A8)^5 -> 16.318066 | C8: =DDM!$B$8+DDM!$B$9*((C$4-Assumptions!$B$14)/($A8-Assumptions!$B$14))/(1+$A8)^5 -> 17.65493 | D8: =DDM!$B$8+DDM!$B$9*((D$4-Assumptions!$B$14)/($A8-Assumptions!$B$14))/(1+$A8)^5 -> 18.323362 | E8: =DDM!$B$8+DDM!$B$9*((E$4-Assumptions!$B$14)/($A8-Assumptions!$B$14))/(1+$A8)^5 -> 18.991793 | F8: =DDM!$B$8+DDM!$B$9*((F$4-Assumptions!$B$14)/($A8-Assumptions!$B$14))/(1+$A8)^5 -> 20.328657 | G8: =DDM!$B$8+DDM!$B$9*((G$4-Assumptions!$B$14)/($A8-Assumptions!$B$14))/(1+$A8)^5 -> 21.66552
A9: 0.12 | B9: =DDM!$B$8+DDM!$B$9*((B$4-Assumptions!$B$14)/($A9-Assumptions!$B$14))/(1+$A9)^5 -> 15.20915 | C9: =DDM!$B$8+DDM!$B$9*((C$4-Assumptions!$B$14)/($A9-Assumptions!$B$14))/(1+$A9)^5 -> 16.429286 | D9: =DDM!$B$8+DDM!$B$9*((D$4-Assumptions!$B$14)/($A9-Assumptions!$B$14))/(1+$A9)^5 -> 17.039354 | E9: =DDM!$B$8+DDM!$B$9*((E$4-Assumptions!$B$14)/($A9-Assumptions!$B$14))/(1+$A9)^5 -> 17.649421 | F9: =DDM!$B$8+DDM!$B$9*((F$4-Assumptions!$B$14)/($A9-Assumptions!$B$14))/(1+$A9)^5 -> 18.869557 | G9: =DDM!$B$8+DDM!$B$9*((G$4-Assumptions!$B$14)/($A9-Assumptions!$B$14))/(1+$A9)^5 -> 20.089692

Sheet Per-Share & Ratios
A1: Per-share & ratios
A2: The standardized dashboard — identical layout across studies. Links to statements / Assumptions.
B3: FY23 | C3: FY24 | D3: FY25 | E3: FY26E | F3: FY27E | G3: FY28E | H3: FY29E | I3: FY30E
A4: EPS (AED) | B4: ='Income Statement'!B17 -> 1.4343891 | C4: ='Income Statement'!C17 -> 1.4886878 | D4: ='Income Statement'!D17 -> 1.8479638 | E4: ='Income Statement'!E17 -> 1.8955125 | F4: ='Income Statement'!F17 -> 1.9716858 | G4: ='Income Statement'!G17 -> 2.0593434 | H4: ='Income Statement'!H17 -> 2.2023559 | I4: ='Income Statement'!I17 -> 2.3901261
A5: DPS (AED) | B5: ='Income Statement'!B18 -> 0.71 | C5: ='Income Statement'!C18 -> 0.75 | D5: ='Income Statement'!D18 -> 0.8 | E5: ='Income Statement'!E18 -> 0.85298061 | F5: ='Income Statement'!F18 -> 0.90697546 | G5: ='Income Statement'!G18 -> 0.96789138 | H5: ='Income Statement'!H18 -> 1.0571308 | I5: ='Income Statement'!I18 -> 1.195063
A6: BVPS (AED) | B6: ='Balance Sheet'!B13/Assumptions!$B$5 -> 9.2307692 | C6: ='Balance Sheet'!C13/Assumptions!$B$5 -> 9.9547511 | D6: ='Balance Sheet'!D13/Assumptions!$B$5 -> 10.588235 | E6: ='Balance Sheet'!E13/Assumptions!$B$5 -> 11.630767 | F6: ='Balance Sheet'!F13/Assumptions!$B$5 -> 12.695477 | G6: ='Balance Sheet'!G13/Assumptions!$B$5 -> 13.786929 | H6: ='Balance Sheet'!H13/Assumptions!$B$5 -> 14.932155 | I6: ='Balance Sheet'!I13/Assumptions!$B$5 -> 16.127218
A7: TBVPS (AED) | B7: =('Balance Sheet'!B13-Assumptions!$B$8)/Assumptions!$B$5 -> 8.2352941 | C7: =('Balance Sheet'!C13-Assumptions!$B$8)/Assumptions!$B$5 -> 8.959276 | D7: =('Balance Sheet'!D13-Assumptions!$B$8)/Assumptions!$B$5 -> 9.5927602 | E7: =('Balance Sheet'!E13-Assumptions!$B$8)/Assumptions!$B$5 -> 10.635292 | F7: =('Balance Sheet'!F13-Assumptions!$B$8)/Assumptions!$B$5 -> 11.700002 | G7: =('Balance Sheet'!G13-Assumptions!$B$8)/Assumptions!$B$5 -> 12.791454 | H7: =('Balance Sheet'!H13-Assumptions!$B$8)/Assumptions!$B$5 -> 13.936679 | I7: =('Balance Sheet'!I13-Assumptions!$B$8)/Assumptions!$B$5 -> 15.131742
A8: P/E (x) | B8: =Assumptions!$B$4/'Income Statement'!B17 -> 12.130599 | C8: =Assumptions!$B$4/'Income Statement'!C17 -> 11.688146 | D8: =Assumptions!$B$4/'Income Statement'!D17 -> 9.4157689 | E8: =Assumptions!$B$4/'Income Statement'!E17 -> 9.1795756 | F8: =Assumptions!$B$4/'Income Statement'!F17 -> 8.8249356 | G8: =Assumptions!$B$4/'Income Statement'!G17 -> 8.4492952 | H8: =Assumptions!$B$4/'Income Statement'!H17 -> 7.9006305 | I8: =Assumptions!$B$4/'Income Statement'!I17 -> 7.2799506
A9: P/B (x) | B9: =Assumptions!$B$4/('Balance Sheet'!B13/Assumptions!$B$5) -> 1.885 | C9: =Assumptions!$B$4/('Balance Sheet'!C13/Assumptions!$B$5) -> 1.7479091 | D9: =Assumptions!$B$4/('Balance Sheet'!D13/Assumptions!$B$5) -> 1.6433333 | E9: =Assumptions!$B$4/('Balance Sheet'!E13/Assumptions!$B$5) -> 1.496032 | F9: =Assumptions!$B$4/('Balance Sheet'!F13/Assumptions!$B$5) -> 1.3705668 | G9: =Assumptions!$B$4/('Balance Sheet'!G13/Assumptions!$B$5) -> 1.2620649 | H9: =Assumptions!$B$4/('Balance Sheet'!H13/Assumptions!$B$5) -> 1.1652706 | I9: =Assumptions!$B$4/('Balance Sheet'!I13/Assumptions!$B$5) -> 1.0789214
A10: Dividend yield | B10: ='Income Statement'!B18/Assumptions!$B$4 -> 0.040804598 | C10: ='Income Statement'!C18/Assumptions!$B$4 -> 0.043103448 | D10: ='Income Statement'!D18/Assumptions!$B$4 -> 0.045977011 | E10: ='Income Statement'!E18/Assumptions!$B$4 -> 0.049021874 | F10: ='Income Statement'!F18/Assumptions!$B$4 -> 0.052125027 | G10: ='Income Statement'!G18/Assumptions!$B$4 -> 0.055625942 | H10: ='Income Statement'!H18/Assumptions!$B$4 -> 0.060754645 | I10: ='Income Statement'!I18/Assumptions!$B$4 -> 0.068681784
A11: Payout ratio | B11: ='Income Statement'!B18/'Income Statement'!B17 -> 0.49498423 | C11: ='Income Statement'!C18/'Income Statement'!C17 -> 0.50379939 | D11: ='Income Statement'!D18/'Income Statement'!D17 -> 0.43290891 | E11: ='Income Statement'!E18/'Income Statement'!E17 -> 0.45 | F11: ='Income Statement'!F18/'Income Statement'!F17 -> 0.46 | G11: ='Income Statement'!G18/'Income Statement'!G17 -> 0.47 | H11: ='Income Statement'!H18/'Income Statement'!H17 -> 0.48 | I11: ='Income Statement'!I18/'Income Statement'!I17 -> 0.5
A12: ROE (on ordinary equity) | B12: ='Income Statement'!B16/'Balance Sheet'!B13 -> 0.15539216 | C12: ='Income Statement'!C16/'Balance Sheet'!C13 -> 0.14954545 | D12: ='Income Statement'!D16/'Balance Sheet'!D13 -> 0.17452991 | E12: ='Income Statement'!E16/'Balance Sheet'!E13 -> 0.16297398 | F12: ='Income Statement'!F16/'Balance Sheet'!F13 -> 0.15530615 | G12: ='Income Statement'!G16/'Balance Sheet'!G13 -> 0.14936925 | H12: ='Income Statement'!H16/'Balance Sheet'!H13 -> 0.14749083 | I12: ='Income Statement'!I16/'Balance Sheet'!I13 -> 0.14820449
A13: ROTE | B13: ='Income Statement'!B16/('Balance Sheet'!B13-Assumptions!$B$8) -> 0.17417582 | C13: ='Income Statement'!C16/('Balance Sheet'!C13-Assumptions!$B$8) -> 0.16616162 | D13: ='Income Statement'!D16/('Balance Sheet'!D13-Assumptions!$B$8) -> 0.19264151 | E13: ='Income Statement'!E16/('Balance Sheet'!E13-Assumptions!$B$8) -> 0.17822853 | F13: ='Income Statement'!F16/('Balance Sheet'!F13-Assumptions!$B$8) -> 0.16852012 | G13: ='Income Statement'!G16/('Balance Sheet'!G13-Assumptions!$B$8) -> 0.16099368 | H13: ='Income Statement'!H16/('Balance Sheet'!H13-Assumptions!$B$8) -> 0.15802587 | I13: ='Income Statement'!I16/('Balance Sheet'!I13-Assumptions!$B$8) -> 0.15795445
A14: Net interest margin (model) | B14: ='Income Statement'!B5/'Income Statement'!B4 -> 0.019722663 | C14: ='Income Statement'!C5/'Income Statement'!C4 -> 0.01949961 | D14: ='Income Statement'!D5/'Income Statement'!D4 -> 0.018536763 | E14: ='Income Statement'!E5/'Income Statement'!E4 -> 0.0172 | F14: ='Income Statement'!F5/'Income Statement'!F4 -> 0.0168 | G14: ='Income Statement'!G5/'Income Statement'!G4 -> 0.0166 | H14: ='Income Statement'!H5/'Income Statement'!H4 -> 0.0166 | I14: ='Income Statement'!I5/'Income Statement'!I4 -> 0.0167
A15: Cost-to-income | B15: =-'Income Statement'!B8/'Income Statement'!B7 -> 0.22 | C15: =-'Income Statement'!C8/'Income Statement'!C7 -> 0.21835443 | D15: =-'Income Statement'!D8/'Income Statement'!D7 -> 0.21816199 | E15: =-'Income Statement'!E8/'Income Statement'!E7 -> 0.22 | F15: =-'Income Statement'!F8/'Income Statement'!F7 -> 0.225 | G15: =-'Income Statement'!G8/'Income Statement'!G7 -> 0.23 | H15: =-'Income Statement'!H8/'Income Statement'!H7 -> 0.23 | I15: =-'Income Statement'!I8/'Income Statement'!I7 -> 0.23
A16: Cost of risk (bps) | B16: =-'Income Statement'!B10/'Balance Sheet'!B5*10000 -> 65.979381 | C16: =-'Income Statement'!C10/'Balance Sheet'!C5*10000 -> 66.287879 | D16: =-'Income Statement'!D10/'Balance Sheet'!D5*10000 -> 48.701299 | E16: =-'Income Statement'!E10/'Balance Sheet'!E5*10000 -> 52.5 | F16: =-'Income Statement'!F10/'Balance Sheet'!F5*10000 -> 57.522936 | G16: =-'Income Statement'!G10/'Balance Sheet'!G5*10000 -> 62.592593 | H16: =-'Income Statement'!H10/'Balance Sheet'!H5*10000 -> 62.592593 | I16: =-'Income Statement'!I10/'Balance Sheet'!I5*10000 -> 58.037383
A17: CET1 ratio | B17: ='Balance Sheet'!B21 -> 0.13382353 | C17: ='Balance Sheet'!C21 -> 0.13943662 | D17: ='Balance Sheet'!D21 -> 0.14171123 | E17: ='Balance Sheet'!E21 -> 0.14547432 | F17: ='Balance Sheet'!F21 -> 0.14818325 | G17: ='Balance Sheet'!G21 -> 0.15140817 | H17: ='Balance Sheet'!H21 -> 0.15417179 | I17: ='Balance Sheet'!I21 -> 0.15791693
A18: Loan-to-deposit | B18: ='Balance Sheet'!B5/'Balance Sheet'!B9 -> 0.63984169 | C18: ='Balance Sheet'!C5/'Balance Sheet'!C9 -> 0.67175573 | D18: ='Balance Sheet'!D5/'Balance Sheet'!D9 -> 0.73246136 | E18: ='Balance Sheet'!E5/'Balance Sheet'!E9 -> 0.74602545 | F18: ='Balance Sheet'!F5/'Balance Sheet'!F9 -> 0.75996986 | G18: ='Balance Sheet'!G5/'Balance Sheet'!G9 -> 0.76707238 | H18: ='Balance Sheet'!H5/'Balance Sheet'!H9 -> 0.78154544 | I18: ='Balance Sheet'!I5/'Balance Sheet'!I9 -> 0.78891851

Sheet Peer & Sector
A1: Peer set & sector
A2: GCC banking comparables (context only; not model inputs).
A3: Bank | B3: Market | C3: P/B (x) | D3: P/E (x) | E3: ROE
A4: First Abu Dhabi Bank | B4: UAE (ADX) | C4: 1.6 | D4: 9.4 | E4: 0.175
A5: Emirates NBD | B5: UAE (DFM) | C5: 1.1 | D5: 6.5 | E5: 0.19
A6: Abu Dhabi Commercial Bank | B6: UAE (ADX) | C6: 1.15 | D6: 8.5 | E6: 0.14
A7: Dubai Islamic Bank | B7: UAE (DFM) | C7: 1.2 | D7: 7 | E7: 0.17
A8: Abu Dhabi Islamic Bank | B8: UAE (ADX) | C8: 2.1 | D8: 9.5 | E8: 0.23
A9: Qatar National Bank | B9: Qatar (QSE) | C9: 1.6 | D9: 10 | E9: 0.17
A10: Al Rajhi Bank | B10: KSA (Tadawul) | C10: 3.6 | D10: 18 | E10: 0.19
A11: Saudi National Bank | B11: KSA (Tadawul) | C11: 1.5 | D11: 13 | E11: 0.11
A13: GCC banks trade P/B ~1.0–3.6x, P/E ~6.5–18x, ROE ~11–23%. FAB sits mid-pack on P/B (~1.6x) despite top-tier scale,
A14: asset quality (NPL ~2.8%, 100% coverage) and RoTE ~20%. Marks as of Jul 2026; illustrative, not model inputs.
