Workbook

Sheet READ FIRST
A1: Testahil — Infosys Limited (NSE: INFY)
A2: Companion model · Independent Valuation Study · Educational analysis · Not investment advice
A4: What this workbook is. A transparent companion to the Infosys valuation study. Every blue cell is an input;
A5: every black cell is a formula; green cells link across sheets. All inputs live on the Assumptions sheet —
A6: change one (the WACC, the terminal growth, an EBIT margin) and the whole model reprices.
A8: What it is not. It is not investment advice, a recommendation, or a price target. Values are model outputs
A9: shown as ranges. The preparer is not licensed by any securities regulator and may hold a position.
A11: Primary lens. Infosys is an asset-light, cash-generative IT-services franchise, so the anchor lens is a
A12: discounted-cash-flow (FCFF) model; a shareholder-yield cross-check, relative multiples and a normalized-
A13: earnings read complete the set. There is no SOTP: the business is a single operating franchise.
A15: Currency. ₹ crore unless stated; USD/INR 88 at study date. Spot ₹1,042.20 (6 Jul 2026).
A16: Historical financials are company IFRS-INR disclosure (FY26 results, 23 Apr 2026); some balance-sheet line
... A20: Income Statement · Balance Sheet · Cash Flow · Summary Financials · Monte Carlo · Sensitivity · Per-Share & Ratios · Peer & Sector.

Sheet Summary
A1: Valuation summary — Infosys (NSE: INFY)
A2: Four-lens fair value vs spot. Base links live; bear/bull are scenario outputs (study §1.5).
B3: Bear | C3: Base | D3: Bull | E3: Weight
A4: DCF (intrinsic FCFF) | B4: 941 | C4: =DCF!B19 | D4: 1474 | E4: =Assumptions!B24
A5: Owner earnings / yield | B5: 1050 | C5: ='Owner Earnings'!B8 | D5: 1620 | E5: =Assumptions!B25
A6: Relative multiples | B6: 920 | C6: ='Relative & Normalized'!C4 | D6: 1430 | E6: =Assumptions!B26
A7: Normalized earnings | B7: 1010 | C7: ='Relative & Normalized'!C6 | D7: 1720 | E7: =Assumptions!B27
A8: Weighted central | B8: =SUMPRODUCT(B4:B7,E4:E7) | C8: =SUMPRODUCT(C4:C7,E4:E7) | D8: =SUMPRODUCT(D4:D7,E4:E7)
A10: Spot price (₹) | C10: =Assumptions!B4
A11: Upside to central base | C11: =C8/C10-1
A13: Read: a quality, cash-generative franchise trading at a de-rated multiple; the swing factor is GenAI's
A14: effect on the labour-arbitrage revenue model and margin. Distributions, not a target.

Sheet Fundamental Valuation
A1: Fundamental valuation — football-field data
A2: Bear/base/bull per lens (links to Summary).
A3: Lens | B3: Bear | C3: Base | D3: Bull
A4: DCF (intrinsic FCFF) | B4: =Summary!B4 | C4: =Summary!C4 | D4: =Summary!D4
A5: Owner earnings / yield | B5: =Summary!B5 | C5: =Summary!C5 | D5: =Summary!D5
A6: Relative multiples | B6: =Summary!B6 | C6: =Summary!C6 | D6: =Summary!D6
A7: Normalized earnings | B7: =Summary!B7 | C7: =Summary!C7 | D7: =Summary!D7
A8: Weighted central | B8: =Summary!B8 | C8: =Summary!C8 | D8: =Summary!D8
A9: Spot | C9: =Assumptions!B4

Sheet Assumptions
A1: Assumptions — the single input layer
A2: All blue cells are inputs. Every other sheet links here.
A3: ANCHORS
A4: Spot price (₹/share) | B4: 1042.2
A5: Shares outstanding (cr) | B5: 414.2
A6: USD/INR | B6: 88
A7: Net cash (₹ cr) | B7: 43000
A8: WACC | B8: 0.12
A9: Terminal growth | B9: 0.045
A10: Tax rate | B10: 0.26
A11: Risk-free rate (India 10y) | B11: 0.065
A12: Equity risk premium | B12: 0.06
A13: Beta | B13: 0.9
A14: Cost of equity (rf + beta x ERP) | B14: =B11+B13*B12
A16: RELATIVE & NORMALIZED
A17: Relative EV/EBITDA multiple | B17: 11
A18: Normalized EPS (₹) | B18: 76
A19: Justified P/E | B19: 18
A20: Normalized FCF/share (₹) | B20: 80
A21: Required owner yield | B21: 0.06
A23: SYNTHESIS WEIGHTS
A24: DCF weight | B24: 0.4
A25: Owner-earnings weight | B25: 0.15
A26: Relative weight | B26: 0.25
A27: Normalized-earnings weight | B27: 0.2
A29: WORKING CAPITAL (% of revenue)
A30: Receivables | B30: 0.205
A31: Other current assets | B31: 0.11
A32: Payables & other CL | B32: 0.16
A34: MONTE CARLO
A35: Diffusion volatility (annualized, YZ-HAR) | B35: 0.2702
A36: Net 3-month factor drift | B36: 0.025
A37: Simulated path vol (annualized) | B37: 0.2952
A39: FORECAST DRIVERS (FY27E–FY31E)
E40: FY27E | F40: FY28E | G40: FY29E | H40: FY30E | I40: FY31E
A41: Revenue growth | E41: 0.05 | F41: 0.06 | G41: 0.07 | H41: 0.07 | I41: 0.065
A42: EBIT margin | E42: 0.21 | F42: 0.215 | G42: 0.22 | H42: 0.22 | I42: 0.22
A43: D&A (% of revenue) | E43: 0.027 | F43: 0.027 | G43: 0.027 | H43: 0.027 | I43: 0.027
A44: Other income (₹ cr) | E44: 3600 | F44: 3800 | G44: 4000 | H44: 4300 | I44: 4600
A45: Capex (₹ cr) | E45: 3400 | F45: 3700 | G45: 4000 | H45: 4300 | I45: 4600
...

Sheet DCF
A1: Discounted cash flow — explicit 5-year FCFF (primary lens)
A2: NOPAT + D&A − capex − ΔWC, discounted at WACC. Links to Income Statement / Balance Sheet / Assumptions.
B3: FY27E | C3: FY28E | D3: FY29E | E3: FY30E | F3: FY31E
A4: EBIT | B4: ='Income Statement'!E5 | C4: ='Income Statement'!F5 | D4: ='Income Statement'!G5 | E4: ='Income Statement'!H5 | F4: ='Income Statement'!I5
A5: NOPAT = EBIT×(1−tax) | B5: =B4*(1-Assumptions!B10) | C5: =C4*(1-Assumptions!B10) | D5: =D4*(1-Assumptions!B10) | E5: =E4*(1-Assumptions!B10) | F5: =F4*(1-Assumptions!B10)
A6: + D&A | B6: ='Income Statement'!E7 | C6: ='Income Statement'!F7 | D6: ='Income Statement'!G7 | E6: ='Income Statement'!H7 | F6: ='Income Statement'!I7
A7: − Capex | B7: =-Assumptions!E45 | C7: =-Assumptions!F45 | D7: =-Assumptions!G45 | E7: =-Assumptions!H45 | F7: =-Assumptions!I45
A8: − Increase in net WC | B8: =-(('Balance Sheet'!E6+'Balance Sheet'!E7-'Balance Sheet'!E12)-('Balance Sheet'!D6+'Balance Sheet'!D7-'Balance Sheet'!D12)) | C8: =-(('Balance Sheet'!F6+'Balance Sheet'!F7-'Balance Sheet'!F12)-('Balance Sheet'!E6+'Balance Sheet'!E7-'Balance Sheet'!E12)) | D8: =-(('Balance Sheet'!G6+'Balance Sheet'!G7-'Balance Sheet'!G12)-('Balance Sheet'!F6+'Balance Sheet'!F7-'Balance Sheet'!F12)) | E8: =-(('Balance Sheet'!H6+'Balance Sheet'!H7-'Balance Sheet'!H12)-('Balance Sheet'!G6+'Balance Sheet'!G7-'Balance Sheet'!G12)) | F8: =-(('Balance Sheet'!I6+'Balance Sheet'!I7-'Balance Sheet'!I12)-('Balance Sheet'!H6+'Balance Sheet'!H7-'Balance Sheet'!H12))
A9: Free cash flow to firm | B9: =B5+B6+B7+B8 | C9: =C5+C6+C7+C8 | D9: =D5+D6+D7+D8 | E9: =E5+E6+E7+E8 | F9: =F5+F6+F7+F8
A10: Discount factor | B10: =1/(1+Assumptions!B8)^1 | C10: =1/(1+Assumptions!B8)^2 | D10: =1/(1+Assumptions!B8)^3 | E10: =1/(1+Assumptions!B8)^4 | F10: =1/(1+Assumptions!B8)^5
A11: PV of FCFF | B11: =B9*B10 | C11: =C9*C10 | D11: =D9*D10 | E11: =E9*E10 | F11: =F9*F10
A13: Σ PV of explicit FCFF (FY27–31) | B13: =SUM(B11:F11)
A14: Terminal value (Gordon) | B14: =F9*(1+Assumptions!B9)/(Assumptions!B8-Assumptions!B9)
A15: PV of terminal value | B15: =B14/(1+Assumptions!B8)^5
A16: Enterprise value | B16: =B13+B15
A17: add: net cash | B17: =Assumptions!B7
A18: Equity value | B18: =B16+B17
A19: Fair value per share (₹) | B19: =B18/Assumptions!B5
A20: Terminal value as % of EV | B20: =B15/B16
A21: Implied FY27E P/E at fair value | B21: =B19/('Income Statement'!E14/Assumptions!B5)

Sheet Segments
A1: Segment view — revenue by geography and vertical
A2: FY26 disclosed mix applied to modelled revenue (links to Income Statement).
B3: FY24 | C3: FY25 | D3: FY26 | E3: FY27E | F3: FY28E | G3: FY29E | H3: FY30E | I3: FY31E
A4: Group revenue | B4: ='Income Statement'!B4 | C4: ='Income Statement'!C4 | D4: ='Income Statement'!D4 | E4: ='Income Statement'!E4 | F4: ='Income Statement'!F4 | G4: ='Income Statement'!G4 | H4: ='Income Statement'!H4 | I4: ='Income Statement'!I4
A5: North America (55.7%) | B5: =B4*0.557 | C5: =C4*0.557 | D5: =D4*0.557 | E5: =E4*0.557 | F5: =F4*0.557 | G5: =G4*0.557 | H5: =H4*0.557 | I5: =I4*0.557
A6: Europe (28.6%) | B6: =B4*0.286 | C6: =C4*0.286 | D6: =D4*0.286 | E6: =E4*0.286 | F6: =F4*0.286 | G6: =G4*0.286 | H6: =H4*0.286 | I6: =I4*0.286
A7: India (2.6%) | B7: =B4*0.026 | C7: =C4*0.026 | D7: =D4*0.026 | E7: =E4*0.026 | F7: =F4*0.026 | G7: =G4*0.026 | H7: =H4*0.026 | I7: =I4*0.026
A8: Rest of world (13.1%) | B8: =B4*0.131 | C8: =C4*0.131 | D8: =D4*0.131 | E8: =E4*0.131 | F8: =F4*0.131 | G8: =G4*0.131 | H8: =H4*0.131 | I8: =I4*0.131
A9: Financial Services (largest vertical, ~28%) | B9: =B4*0.28 | C9: =C4*0.28 | D9: =D4*0.28 | E9: =E4*0.28 | F9: =F4*0.28 | G9: =G4*0.28 | H9: =H4*0.28 | I9: =I4*0.28
A10: EBIT margin (group) | B10: ='Income Statement'!B6 | C10: ='Income Statement'!C6 | D10: ='Income Statement'!D6 | E10: ='Income Statement'!E6 | F10: ='Income Statement'!F6 | G10: ='Income Statement'!G6 | H10: ='Income Statement'!H6 | I10: ='Income Statement'!I6

Sheet Relative & Normalized
A1: Relative & normalized-earnings lenses
A2: Links to Assumptions.
A3: Lens | B3: Workings | C3: ₹/share
A4: Relative EV/EBITDA | B4: Norm EBITDA × mult + net cash, /sh | C4: =('Income Statement'!E8*Assumptions!B17+Assumptions!B7)/Assumptions!B5
A5: implied EV (₹ cr) | C5: ='Income Statement'!E8*Assumptions!B17
A6: Normalized earnings (P/E) | B6: Normalized EPS × justified P/E | C6: =Assumptions!B18*Assumptions!B19
A7: normalized EPS (₹) | C7: =Assumptions!B18
A8: Spot P/E (FY26) | C8: =Assumptions!B4/('Income Statement'!D14/Assumptions!B5)
A9: Spot EV/EBITDA (FY26) | C9: =(Assumptions!B4*Assumptions!B5-Assumptions!B7)/'Income Statement'!D8

Sheet Owner Earnings
A1: Owner earnings & shareholder yield — the cash-flow cross-check
A2: Capitalizes normalized free cash flow to owners; a reverse-DCF reads the growth the price implies.
A3: Normalized FCF/share (₹) | B3: =Assumptions!B20
A4: Required owner yield | B4: =Assumptions!B21
A5: Assumed long-run FCF growth | B5: 0.05
A6: Fair value = FCF/(yield) (perpetuity) | B6: =B3/B4
A7: Fair value = FCF×(1+g)/(WACC−g) | B7: =B3*(1+B5)/(Assumptions!B8-B5)
A8: Owner-earnings fair value (mid) | B8: =AVERAGE(B6:B7)
A10: Reverse-DCF — what the market price implies
A11: Spot FCF yield | B11: =Assumptions!B20/Assumptions!B4
A12: Implied return at spot (yield + g) | B12: =B11+B5
A13: Excess over WACC (value signal) | B13: =B12-Assumptions!B8
A14: Read: implied return above WACC ⇒ the price under-rewards the cash the franchise returns.

Sheet Income Statement
A1: Income statement (₹ cr, consolidated, IFRS)
A2: FY24–FY26 disclosed (blue); FY27–FY31 forecast (formulas linking to Assumptions)
B3: FY24 | C3: FY25 | D3: FY26 | E3: FY27E | F3: FY28E | G3: FY29E | H3: FY30E | I3: FY31E
A4: Revenue | B4: 153670 | C4: 162990 | D4: 178650 | E4: =D4*(1+Assumptions!E41) | F4: =E4*(1+Assumptions!F41) | G4: =F4*(1+Assumptions!G41) | H4: =G4*(1+Assumptions!H41) | I4: =H4*(1+Assumptions!I41)
A5: EBIT | B5: 31810 | C5: 34391 | D5: 36266 | E5: =E4*Assumptions!E42 | F5: =F4*Assumptions!F42 | G5: =G4*Assumptions!G42 | H5: =H4*Assumptions!H42 | I5: =I4*Assumptions!I42
A6: EBIT margin | B6: =B5/B4 | C6: =C5/C4 | D6: =D5/D4 | E6: =E5/E4 | F6: =F5/F4 | G6: =G5/G4 | H6: =H5/H4 | I6: =I5/I4
A7: D&A | B7: 4160 | C7: 4520 | D7: 4900 | E7: =E4*Assumptions!E43 | F7: =F4*Assumptions!F43 | G7: =G4*Assumptions!G43 | H7: =H4*Assumptions!H43 | I7: =I4*Assumptions!I43
A8: EBITDA | B8: =B5+B7 | C8: =C5+C7 | D8: =D5+D7 | E8: =E5+E7 | F8: =F5+F7 | G8: =G5+G7 | H8: =H5+H7 | I8: =I5+I7
A9: Other income (net) | B9: 3080 | C9: 3560 | D9: 3510 | E9: =Assumptions!E44 | F9: =Assumptions!F44 | G9: =Assumptions!G44 | H9: =Assumptions!H44 | I9: =Assumptions!I44
A10: PBT (before exceptionals) | B10: =B5+B9 | C10: =C5+C9 | D10: =D5+D9 | E10: =E5+E9 | F10: =F5+F9 | G10: =G5+G9 | H10: =H5+H9 | I10: =I5+I9
A11: Exceptional items | B11: 0 | C11: 0 | D11: -1289 | E11: 0 | F11: 0 | G11: 0 | H11: 0 | I11: 0
A12: PBT | B12: =B10+B11 | C12: =C10+C11 | D12: =D10+D11 | E12: =E10+E11 | F12: =F10+F11 | G12: =G10+G11 | H12: =H10+H11 | I12: =I10+I11
A13: Tax | B13: =B12-26233 | C13: =C12-26713 | D13: =D12-29440 | E13: =MAX(0,E12)*Assumptions!B10 | F13: =MAX(0,F12)*Assumptions!B10 | G13: =MAX(0,G12)*Assumptions!B10 | H13: =MAX(0,H12)*Assumptions!B10 | I13: =MAX(0,I12)*Assumptions!B10
A14: PAT (owners) | B14: 26233 | C14: 26713 | D14: 29440 | E14: =E12-E13 | F14: =F12-F13 | G14: =G12-G13 | H14: =H12-H13 | I14: =I12-I13
A16: Source: Infosys IFRS-INR press releases FY24–FY26 (SEC Form 6-K). Forecast = formulas linking to Assumptions.

Sheet Balance Sheet
A1: Balance sheet (₹ cr, consolidated)
A2: Historical anchored to disclosed equity / cash & investments / borrowings (zero debt); forecast rolls forward.
B3: FY24 | C3: FY25 | D3: FY26 | E3: FY27E | F3: FY28E | G3: FY29E | H3: FY30E | I3: FY31E
A4: PP&E + intangibles | B4: 24000 | C4: 24500 | D4: 25000 | E4: =D4+Assumptions!E45-'Income Statement'!E7 | F4: =E4+Assumptions!F45-'Income Statement'!F7 | G4: =F4+Assumptions!G45-'Income Statement'!G7 | H4: =G4+Assumptions!H45-'Income Statement'!H7 | I4: =H4+Assumptions!I45-'Income Statement'!I7
A5: Goodwill | B5: 7800 | C5: 7900 | D5: 8000 | E5: =D5 | F5: =E5 | G5: =F5 | H5: =G5 | I5: =H5
A6: Receivables | B6: ='Income Statement'!B4*Assumptions!B30 | C6: ='Income Statement'!C4*Assumptions!B30 | D6: ='Income Statement'!D4*Assumptions!B30 | E6: ='Income Statement'!E4*Assumptions!B30 | F6: ='Income Statement'!F4*Assumptions!B30 | G6: ='Income Statement'!G4*Assumptions!B30 | H6: ='Income Statement'!H4*Assumptions!B30 | I6: ='Income Statement'!I4*Assumptions!B30
A7: Other current assets | B7: ='Income Statement'!B4*Assumptions!B31 | C7: ='Income Statement'!C4*Assumptions!B31 | D7: ='Income Statement'!D4*Assumptions!B31 | E7: ='Income Statement'!E4*Assumptions!B31 | F7: ='Income Statement'!F4*Assumptions!B31 | G7: ='Income Statement'!G4*Assumptions!B31 | H7: ='Income Statement'!H4*Assumptions!B31 | I7: ='Income Statement'!I4*Assumptions!B31
A8: Cash & investments | B8: 46000 | C8: 47000 | D8: 43075 | E8: =D8+('Income Statement'!E14+'Income Statement'!E7-((E6+E7-E12)-(D6+D7-D12)))-Assumptions!E45-Assumptions!E46-Assumptions!E47 | F8: =E8+('Income Statement'!F14+'Income Statement'!F7-((F6+F7-F12)-(E6+E7-E12)))-Assumptions!F45-Assumptions!F46-Assumptions!F47 | G8: =F8+('Income Statement'!G14+'Income Statement'!G7-((G6+G7-G12)-(F6+F7-F12)))-Assumptions!G45-Assumptions!G46-Assumptions!G47 | H8: =G8+('Income Statement'!H14+'Income Statement'!H7-((H6+H7-H12)-(G6+G7-G12)))-Assumptions!H45-Assumptions!H46-Assumptions!H47 | I8: =H8+('Income Statement'!I14+'Income Statement'!I7-((I6+I7-I12)-(H6+H7-H12)))-Assumptions!I45-Assumptions!I46-Assumptions!I47
A9: Total assets | B9: =SUM(B4:B8) | C9: =SUM(C4:C8) | D9: =SUM(D4:D8) | E9: =SUM(E4:E8) | F9: =SUM(F4:F8) | G9: =SUM(G4:G8) | H9: =SUM(H4:H8) | I9: =SUM(I4:I8)
A11: Equity | B11: 86800 | C11: 88200 | D11: 90000 | E11: =D11+'Income Statement'!E14-Assumptions!E46-Assumptions!E47 | F11: =E11+'Income Statement'!F14-Assumptions!F46-Assumptions!F47 | G11: =F11+'Income Statement'!G14-Assumptions!G46-Assumptions!G47 | H11: =G11+'Income Statement'!H14-Assumptions!H46-Assumptions!H47 | I11: =H11+'Income Statement'!I14-Assumptions!I46-Assumptions!I47
A12: Payables & other CL | B12: ='Income Statement'!B4*Assumptions!B32 | C12: ='Income Statement'!C4*Assumptions!B32 | D12: ='Income Statement'!D4*Assumptions!B32 | E12: ='Income Statement'!E4*Assumptions!B32 | F12: ='Income Statement'!F4*Assumptions!B32 | G12: ='Income Statement'!G4*Assumptions!B32 | H12: ='Income Statement'!H4*Assumptions!B32 | I12: ='Income Statement'!I4*Assumptions!B32
A13: Borrowings | B13: 0 | C13: 0 | D13: 0 | E13: 0 | F13: 0 | G13: 0 | H13: 0 | I13: 0
A14: Other liabilities | B14: 25000 | C14: 25400 | D14: 25600 | E14: =D14 | F14: =E14 | G14: =F14 | H14: =G14 | I14: =H14
A15: Reserves / reconciling plug | B15: =B9-(B11+B12+B13+B14) | C15: =C9-(C11+C12+C13+C14) | D15: =D9-(D11+D12+D13+D14) | E15: =E9-(E11+E12+E13+E14) | F15: =F9-(F11+F12+F13+F14) | G15: =G9-(G11+G12+G13+G14) | H15: =H9-(H11+H12+H13+H14) | I15: =I9-(I11+I12+I13+I14)
A16: Total liabilities & equity | B16: =B11+B12+B13+B14+B15 | C16: =C11+C12+C13+C14+C15 | D16: =D11+D12+D13+D14+D15 | E16: =E11+E12+E13+E14+E15 | F16: =F11+F12+F13+F14+F15 | G16: =G11+G12+G13+G14+G15 | H16: =H11+H12+H13+H14+H15 | I16: =I11+I12+I13+I14+I15
A18: Balance check (assets − L&E) | B18: =B9-B16 | C18: =C9-C16 | D18: =D9-D16 | E18: =E9-E16 | F18: =F9-F16 | G18: =G9-G16 | H18: =H9-H16 | I18: =I9-I16
A19: Net cash (cash & inv − borrowings) | B19: =B8-B13 | C19: =C8-C13 | D19: =D8-D13 | E19: =E8-E13 | F19: =F8-F13 | G19: =G8-G13 | H19: =H8-H13 | I19: =I8-I13
A20: Note: 'Reserves / reconciling plug' balances the sheet to disclosed equity, cash and borrowings; Infosys carries no debt.

Sheet Cash Flow
A1: Cash flow (₹ cr, forecast)
A2: Derived from the Income Statement and Balance Sheet. Closing cash ties to the Balance Sheet.
B3: FY27E | C3: FY28E | D3: FY29E | E3: FY30E | F3: FY31E
A4: PAT | B4: ='Income Statement'!E14 | C4: ='Income Statement'!F14 | D4: ='Income Statement'!G14 | E4: ='Income Statement'!H14 | F4: ='Income Statement'!I14
A5: + D&A | B5: ='Income Statement'!E7 | C5: ='Income Statement'!F7 | D5: ='Income Statement'!G7 | E5: ='Income Statement'!H7 | F5: ='Income Statement'!I7
A6: − Increase in net working capital | B6: =-(('Balance Sheet'!E6+'Balance Sheet'!E7-'Balance Sheet'!E12)-('Balance Sheet'!D6+'Balance Sheet'!D7-'Balance Sheet'!D12)) | C6: =-(('Balance Sheet'!F6+'Balance Sheet'!F7-'Balance Sheet'!F12)-('Balance Sheet'!E6+'Balance Sheet'!E7-'Balance Sheet'!E12)) | D6: =-(('Balance Sheet'!G6+'Balance Sheet'!G7-'Balance Sheet'!G12)-('Balance Sheet'!F6+'Balance Sheet'!F7-'Balance Sheet'!F12)) | E6: =-(('Balance Sheet'!H6+'Balance Sheet'!H7-'Balance Sheet'!H12)-('Balance Sheet'!G6+'Balance Sheet'!G7-'Balance Sheet'!G12)) | F6: =-(('Balance Sheet'!I6+'Balance Sheet'!I7-'Balance Sheet'!I12)-('Balance Sheet'!H6+'Balance Sheet'!H7-'Balance Sheet'!H12))
A7: Operating cash flow | B7: =B4+B5+B6 | C7: =C4+C5+C6 | D7: =D4+D5+D6 | E7: =E4+E5+E6 | F7: =F4+F5+F6
A8: − Capex | B8: =-Assumptions!E45 | C8: =-Assumptions!F45 | D8: =-Assumptions!G45 | E8: =-Assumptions!H45 | F8: =-Assumptions!I45
A9: Free cash flow | B9: =B7+B8 | C9: =C7+C8 | D9: =D7+D8 | E9: =E7+E8 | F9: =F7+F8
A10: − Dividend | B10: =-Assumptions!E46 | C10: =-Assumptions!F46 | D10: =-Assumptions!G46 | E10: =-Assumptions!H46 | F10: =-Assumptions!I46
A11: − Buyback | B11: =-Assumptions!E47 | C11: =-Assumptions!F47 | D11: =-Assumptions!G47 | E11: =-Assumptions!H47 | F11: =-Assumptions!I47
A12: Net change in cash | B12: =B9+B10+B11 | C12: =C9+C10+C11 | D12: =D9+D10+D11 | E12: =E9+E10+E11 | F12: =F9+F10+F11
A13: Opening cash & investments | B13: ='Balance Sheet'!D8 | C13: ='Balance Sheet'!E8 | D13: ='Balance Sheet'!F8 | E13: ='Balance Sheet'!G8 | F13: ='Balance Sheet'!H8
A14: Closing cash & investments | B14: =B13+B12 | C14: =C13+C12 | D14: =D13+D12 | E14: =E13+E12 | F14: =F13+F12

Sheet Summary Financials
A1: Summary financials (₹ cr)
A2: Every cell links to the statement sheets.
B3: FY24 | C3: FY25 | D3: FY26 | E3: FY27E | F3: FY28E | G3: FY29E | H3: FY30E | I3: FY31E
A4: Revenue | B4: ='Income Statement'!B4 | C4: ='Income Statement'!C4 | D4: ='Income Statement'!D4 | E4: ='Income Statement'!E4 | F4: ='Income Statement'!F4 | G4: ='Income Statement'!G4 | H4: ='Income Statement'!H4 | I4: ='Income Statement'!I4
A5: EBITDA | B5: ='Income Statement'!B8 | C5: ='Income Statement'!C8 | D5: ='Income Statement'!D8 | E5: ='Income Statement'!E8 | F5: ='Income Statement'!F8 | G5: ='Income Statement'!G8 | H5: ='Income Statement'!H8 | I5: ='Income Statement'!I8
A6: EBIT | B6: ='Income Statement'!B5 | C6: ='Income Statement'!C5 | D6: ='Income Statement'!D5 | E6: ='Income Statement'!E5 | F6: ='Income Statement'!F5 | G6: ='Income Statement'!G5 | H6: ='Income Statement'!H5 | I6: ='Income Statement'!I5
A7: PAT | B7: ='Income Statement'!B14 | C7: ='Income Statement'!C14 | D7: ='Income Statement'!D14 | E7: ='Income Statement'!E14 | F7: ='Income Statement'!F14 | G7: ='Income Statement'!G14 | H7: ='Income Statement'!H14 | I7: ='Income Statement'!I14
A8: Total assets | B8: ='Balance Sheet'!B9 | C8: ='Balance Sheet'!C9 | D8: ='Balance Sheet'!D9 | E8: ='Balance Sheet'!E9 | F8: ='Balance Sheet'!F9 | G8: ='Balance Sheet'!G9 | H8: ='Balance Sheet'!H9 | I8: ='Balance Sheet'!I9
A9: Equity | B9: ='Balance Sheet'!B11 | C9: ='Balance Sheet'!C11 | D9: ='Balance Sheet'!D11 | E9: ='Balance Sheet'!E11 | F9: ='Balance Sheet'!F11 | G9: ='Balance Sheet'!G11 | H9: ='Balance Sheet'!H11 | I9: ='Balance Sheet'!I11
A10: Net cash | B10: ='Balance Sheet'!B19 | C10: ='Balance Sheet'!C19 | D10: ='Balance Sheet'!D19 | E10: ='Balance Sheet'!E19 | F10: ='Balance Sheet'!F19 | G10: ='Balance Sheet'!G19 | H10: ='Balance Sheet'!H19 | I10: ='Balance Sheet'!I19
A11: Free cash flow | E11: ='Cash Flow'!B9 | F11: ='Cash Flow'!C9 | G11: ='Cash Flow'!D9 | H11: ='Cash Flow'!E9 | I11: ='Cash Flow'!F9

Sheet Monte Carlo
A1: Monte Carlo — engine outputs
A2: 50,000 paths · YZ-HAR width · Student-t(5) · zero secular drift (international) · 16-factor overlay · seed 42.
A3: Percentile map (₹/share)
A4: Horizon | B4: p5 | C4: p25 | D4: p50 | E4: p75 | F4: p95
A5: T+20 sessions | B5: 918 | C5: 998 | D5: 1047 | E5: 1099 | F5: 1193
A6: T+60 sessions | B6: 845 | C6: 972 | D6: 1058 | E6: 1151 | F6: 1326
A8: Inputs (from Assumptions): σ | D8: =Assumptions!B35
A9: net 3-month factor drift | D9: =Assumptions!B36
A11: Probability read (T+60)
A12: P(price above spot) | B12: 0.548
A13: P(+10%) vs P(−10%) | B13: 0.26
A14: P(−10%) | B14: 0.171
A15: Median (₹) | B15: 1058.5
A16: Median move | B16: 0.0157
A17: 50% band low (₹) | B17: 972.4
A18: 50% band high (₹) | B18: 1150.8
A19: Touch +10% / −10% | B19: 0.443
A20: Touch −10% | B20: 0.327
A22: Level-touch ladder
A23: Level | B23: T+20 | C23: T+60
A24: 1250 | B24: 0.029 | C24: 0.171
A25: 1200 | B25: 0.07 | C25: 0.273
A26: 1150 | B26: 0.17 | C26: 0.43
A27: 1100 | B27: 0.403 | C27: 0.646
A28: 1050 | B28: 0.818 | C28: 0.902
A29: 1000 | B29: 0.451 | C29: 0.644
A30: 950 | B30: 0.164 | C30: 0.379
A31: 900 | B31: 0.051 | C31: 0.199

Sheet Sensitivity
A1: DCF sensitivity — WACC × terminal growth
A2: Fair value (₹/share) across WACC and terminal growth, holding operating drivers at base. Live off Assumptions.
A4: WACC \ g | B4: 0.035 | C4: 0.04 | D4: 0.045 | E4: 0.05 | F4: 0.055
A5: 0.11 | B5: =((DCF!B9/(1+$A5)^1+DCF!C9/(1+$A5)^2+DCF!D9/(1+$A5)^3+DCF!E9/(1+$A5)^4+DCF!F9/(1+$A5)^5)+DCF!F9*(1+B$4)/($A5-B$4)/(1+$A5)^5+Assumptions!B7)/Assumptions!B5 | C5: =((DCF!B9/(1+$A5)^1+DCF!C9/(1+$A5)^2+DCF!D9/(1+$A5)^3+DCF!E9/(1+$A5)^4+DCF!F9/(1+$A5)^5)+DCF!F9*(1+C$4)/($A5-C$4)/(1+$A5)^5+Assumptions!B7)/Assumptions!B5 | D5: =((DCF!B9/(1+$A5)^1+DCF!C9/(1+$A5)^2+DCF!D9/(1+$A5)^3+DCF!E9/(1+$A5)^4+DCF!F9/(1+$A5)^5)+DCF!F9*(1+D$4)/($A5-D$4)/(1+$A5)^5+Assumptions!B7)/Assumptions!B5 | E5: =((DCF!B9/(1+$A5)^1+DCF!C9/(1+$A5)^2+DCF!D9/(1+$A5)^3+DCF!E9/(1+$A5)^4+DCF!F9/(1+$A5)^5)+DCF!F9*(1+E$4)/($A5-E$4)/(1+$A5)^5+Assumptions!B7)/Assumptions!B5 | F5: =((DCF!B9/(1+$A5)^1+DCF!C9/(1+$A5)^2+DCF!D9/(1+$A5)^3+DCF!E9/(1+$A5)^4+DCF!F9/(1+$A5)^5)+DCF!F9*(1+F$4)/($A5-F$4)/(1+$A5)^5+Assumptions!B7)/Assumptions!B5
A6: 0.115 | B6: =((DCF!B9/(1+$A6)^1+DCF!C9/(1+$A6)^2+DCF!D9/(1+$A6)^3+DCF!E9/(1+$A6)^4+DCF!F9/(1+$A6)^5)+DCF!F9*(1+B$4)/($A6-B$4)/(1+$A6)^5+Assumptions!B7)/Assumptions!B5 | C6: =((DCF!B9/(1+$A6)^1+DCF!C9/(1+$A6)^2+DCF!D9/(1+$A6)^3+DCF!E9/(1+$A6)^4+DCF!F9/(1+$A6)^5)+DCF!F9*(1+C$4)/($A6-C$4)/(1+$A6)^5+Assumptions!B7)/Assumptions!B5 | D6: =((DCF!B9/(1+$A6)^1+DCF!C9/(1+$A6)^2+DCF!D9/(1+$A6)^3+DCF!E9/(1+$A6)^4+DCF!F9/(1+$A6)^5)+DCF!F9*(1+D$4)/($A6-D$4)/(1+$A6)^5+Assumptions!B7)/Assumptions!B5 | E6: =((DCF!B9/(1+$A6)^1+DCF!C9/(1+$A6)^2+DCF!D9/(1+$A6)^3+DCF!E9/(1+$A6)^4+DCF!F9/(1+$A6)^5)+DCF!F9*(1+E$4)/($A6-E$4)/(1+$A6)^5+Assumptions!B7)/Assumptions!B5 | F6: =((DCF!B9/(1+$A6)^1+DCF!C9/(1+$A6)^2+DCF!D9/(1+$A6)^3+DCF!E9/(1+$A6)^4+DCF!F9/(1+$A6)^5)+DCF!F9*(1+F$4)/($A6-F$4)/(1+$A6)^5+Assumptions!B7)/Assumptions!B5
A7: 0.12 | B7: =((DCF!B9/(1+$A7)^1+DCF!C9/(1+$A7)^2+DCF!D9/(1+$A7)^3+DCF!E9/(1+$A7)^4+DCF!F9/(1+$A7)^5)+DCF!F9*(1+B$4)/($A7-B$4)/(1+$A7)^5+Assumptions!B7)/Assumptions!B5 | C7: =((DCF!B9/(1+$A7)^1+DCF!C9/(1+$A7)^2+DCF!D9/(1+$A7)^3+DCF!E9/(1+$A7)^4+DCF!F9/(1+$A7)^5)+DCF!F9*(1+C$4)/($A7-C$4)/(1+$A7)^5+Assumptions!B7)/Assumptions!B5 | D7: =((DCF!B9/(1+$A7)^1+DCF!C9/(1+$A7)^2+DCF!D9/(1+$A7)^3+DCF!E9/(1+$A7)^4+DCF!F9/(1+$A7)^5)+DCF!F9*(1+D$4)/($A7-D$4)/(1+$A7)^5+Assumptions!B7)/Assumptions!B5 | E7: =((DCF!B9/(1+$A7)^1+DCF!C9/(1+$A7)^2+DCF!D9/(1+$A7)^3+DCF!E9/(1+$A7)^4+DCF!F9/(1+$A7)^5)+DCF!F9*(1+E$4)/($A7-E$4)/(1+$A7)^5+Assumptions!B7)/Assumptions!B5 | F7: =((DCF!B9/(1+$A7)^1+DCF!C9/(1+$A7)^2+DCF!D9/(1+$A7)^3+DCF!E9/(1+$A7)^4+DCF!F9/(1+$A7)^5)+DCF!F9*(1+F$4)/($A7-F$4)/(1+$A7)^5+Assumptions!B7)/Assumptions!B5
A8: 0.125 | B8: =((DCF!B9/(1+$A8)^1+DCF!C9/(1+$A8)^2+DCF!D9/(1+$A8)^3+DCF!E9/(1+$A8)^4+DCF!F9/(1+$A8)^5)+DCF!F9*(1+B$4)/($A8-B$4)/(1+$A8)^5+Assumptions!B7)/Assumptions!B5 | C8: =((DCF!B9/(1+$A8)^1+DCF!C9/(1+$A8)^2+DCF!D9/(1+$A8)^3+DCF!E9/(1+$A8)^4+DCF!F9/(1+$A8)^5)+DCF!F9*(1+C$4)/($A8-C$4)/(1+$A8)^5+Assumptions!B7)/Assumptions!B5 | D8: =((DCF!B9/(1+$A8)^1+DCF!C9/(1+$A8)^2+DCF!D9/(1+$A8)^3+DCF!E9/(1+$A8)^4+DCF!F9/(1+$A8)^5)+DCF!F9*(1+D$4)/($A8-D$4)/(1+$A8)^5+Assumptions!B7)/Assumptions!B5 | E8: =((DCF!B9/(1+$A8)^1+DCF!C9/(1+$A8)^2+DCF!D9/(1+$A8)^3+DCF!E9/(1+$A8)^4+DCF!F9/(1+$A8)^5)+DCF!F9*(1+E$4)/($A8-E$4)/(1+$A8)^5+Assumptions!B7)/Assumptions!B5 | F8: =((DCF!B9/(1+$A8)^1+DCF!C9/(1+$A8)^2+DCF!D9/(1+$A8)^3+DCF!E9/(1+$A8)^4+DCF!F9/(1+$A8)^5)+DCF!F9*(1+F$4)/($A8-F$4)/(1+$A8)^5+Assumptions!B7)/Assumptions!B5
A9: 0.13 | B9: =((DCF!B9/(1+$A9)^1+DCF!C9/(1+$A9)^2+DCF!D9/(1+$A9)^3+DCF!E9/(1+$A9)^4+DCF!F9/(1+$A9)^5)+DCF!F9*(1+B$4)/($A9-B$4)/(1+$A9)^5+Assumptions!B7)/Assumptions!B5 | C9: =((DCF!B9/(1+$A9)^1+DCF!C9/(1+$A9)^2+DCF!D9/(1+$A9)^3+DCF!E9/(1+$A9)^4+DCF!F9/(1+$A9)^5)+DCF!F9*(1+C$4)/($A9-C$4)/(1+$A9)^5+Assumptions!B7)/Assumptions!B5 | D9: =((DCF!B9/(1+$A9)^1+DCF!C9/(1+$A9)^2+DCF!D9/(1+$A9)^3+DCF!E9/(1+$A9)^4+DCF!F9/(1+$A9)^5)+DCF!F9*(1+D$4)/($A9-D$4)/(1+$A9)^5+Assumptions!B7)/Assumptions!B5 | E9: =((DCF!B9/(1+$A9)^1+DCF!C9/(1+$A9)^2+DCF!D9/(1+$A9)^3+DCF!E9/(1+$A9)^4+DCF!F9/(1+$A9)^5)+DCF!F9*(1+E$4)/($A9-E$4)/(1+$A9)^5+Assumptions!B7)/Assumptions!B5 | F9: =((DCF!B9/(1+$A9)^1+DCF!C9/(1+$A9)^2+DCF!D9/(1+$A9)^3+DCF!E9/(1+$A9)^4+DCF!F9/(1+$A9)^5)+DCF!F9*(1+F$4)/($A9-F$4)/(1+$A9)^5+Assumptions!B7)/Assumptions!B5
A11: Base case (WACC 12.0%, g 4.5%) shaded; cells near spot show how much recovery is priced.

Sheet Per-Share & Ratios
A1: Per-share & ratios
A2: Links to statements / Assumptions.
B3: FY24 | C3: FY25 | D3: FY26 | E3: FY27E | F3: FY28E | G3: FY29E | H3: FY30E | I3: FY31E
A4: EPS (₹) | B4: ='Income Statement'!B14/Assumptions!B5 | C4: ='Income Statement'!C14/Assumptions!B5 | D4: ='Income Statement'!D14/Assumptions!B5 | E4: ='Income Statement'!E14/Assumptions!B5 | F4: ='Income Statement'!F14/Assumptions!B5 | G4: ='Income Statement'!G14/Assumptions!B5 | H4: ='Income Statement'!H14/Assumptions!B5 | I4: ='Income Statement'!I14/Assumptions!B5
A5: DPS (₹) | B5: 46 | C5: 46 | D5: 48 | E5: =Assumptions!E46/Assumptions!B5 | F5: =Assumptions!F46/Assumptions!B5 | G5: =Assumptions!G46/Assumptions!B5 | H5: =Assumptions!H46/Assumptions!B5 | I5: =Assumptions!I46/Assumptions!B5
A6: Book value/share (₹) | B6: ='Balance Sheet'!B11/Assumptions!B5 | C6: ='Balance Sheet'!C11/Assumptions!B5 | D6: ='Balance Sheet'!D11/Assumptions!B5 | E6: ='Balance Sheet'!E11/Assumptions!B5 | F6: ='Balance Sheet'!F11/Assumptions!B5 | G6: ='Balance Sheet'!G11/Assumptions!B5 | H6: ='Balance Sheet'!H11/Assumptions!B5 | I6: ='Balance Sheet'!I11/Assumptions!B5
A7: EBIT margin | B7: ='Income Statement'!B5/'Income Statement'!B4 | C7: ='Income Statement'!C5/'Income Statement'!C4 | D7: ='Income Statement'!D5/'Income Statement'!D4 | E7: ='Income Statement'!E5/'Income Statement'!E4 | F7: ='Income Statement'!F5/'Income Statement'!F4 | G7: ='Income Statement'!G5/'Income Statement'!G4 | H7: ='Income Statement'!H5/'Income Statement'!H4 | I7: ='Income Statement'!I5/'Income Statement'!I4
A8: Net cash / EBITDA | B8: ='Balance Sheet'!B19/'Income Statement'!B8 | C8: ='Balance Sheet'!C19/'Income Statement'!C8 | D8: ='Balance Sheet'!D19/'Income Statement'!D8 | E8: ='Balance Sheet'!E19/'Income Statement'!E8 | F8: ='Balance Sheet'!F19/'Income Statement'!F8 | G8: ='Balance Sheet'!G19/'Income Statement'!G8 | H8: ='Balance Sheet'!H19/'Income Statement'!H8 | I8: ='Balance Sheet'!I19/'Income Statement'!I8
A9: Revenue YoY | C9: ='Income Statement'!C4/'Income Statement'!B4-1 | D9: ='Income Statement'!D4/'Income Statement'!C4-1 | E9: ='Income Statement'!E4/'Income Statement'!D4-1 | F9: ='Income Statement'!F4/'Income Statement'!E4-1 | G9: ='Income Statement'!G4/'Income Statement'!F4-1 | H9: ='Income Statement'!H4/'Income Statement'!G4-1 | I9: ='Income Statement'!I4/'Income Statement'!H4-1
A10: ROE | B10: ='Income Statement'!B14/'Balance Sheet'!B11 | C10: ='Income Statement'!C14/'Balance Sheet'!C11 | D10: ='Income Statement'!D14/'Balance Sheet'!D11 | E10: ='Income Statement'!E14/'Balance Sheet'!E11 | F10: ='Income Statement'!F14/'Balance Sheet'!F11 | G10: ='Income Statement'!G14/'Balance Sheet'!G11 | H10: ='Income Statement'!H14/'Balance Sheet'!H11 | I10: ='Income Statement'!I14/'Balance Sheet'!I11
A11: P/E on spot (×) | B11: =Assumptions!B4/('Income Statement'!B14/Assumptions!B5) | C11: =Assumptions!B4/('Income Statement'!C14/Assumptions!B5) | D11: =Assumptions!B4/('Income Statement'!D14/Assumptions!B5) | E11: =Assumptions!B4/('Income Statement'!E14/Assumptions!B5) | F11: =Assumptions!B4/('Income Statement'!F14/Assumptions!B5) | G11: =Assumptions!B4/('Income Statement'!G14/Assumptions!B5) | H11: =Assumptions!B4/('Income Statement'!H14/Assumptions!B5) | I11: =Assumptions!B4/('Income Statement'!I14/Assumptions!B5)

Sheet Peer & Sector
A1: Peer set & sector
A2: Indian IT-services majors + global bellwether.
A3: Peer | B3: Positioning | C3: Typical valuation
A4: Tata Consultancy Services | B4: Largest India IT; broad-based | C4: P/E ~22–26x; EV/EBITDA ~15–17x
A5: HCLTech | B5: IT + engineering + products | C5: P/E ~20–24x; EV/EBITDA ~12–14x
A6: Wipro | B6: Turnaround; consulting-heavy | C6: P/E ~18–22x; EV/EBITDA ~11–13x
A7: LTIMindtree | B7: Mid-cap growth | C7: P/E ~24–30x; EV/EBITDA ~15–18x
A8: Accenture | B8: Global consulting bellwether | C8: P/E ~22–28x; EV/EBITDA ~14–17x
A10: Analyst context (not model inputs): consensus targets cluster well above spot on a recovery-and-quality view;
A11: the bears cite GenAI deflation of the labour-arbitrage model. Testahil publishes ranges, not a rating.
