Workbook

Sheet READ FIRST
A1: Testahil — Ibnsina Pharma S.A.E. (EGX: ISPH)
A2: Companion model · Independent Valuation Study — Educational Analysis · reporting currency EGP
A4: What this workbook is. A transparent companion to the study. Blue cells are inputs; black cells are formulas; green cells link across sheets.
A5: Change one input on the Assumptions sheet (a growth rate, a margin, the WACC or terminal growth) and the whole model reprices.
A7: INDICATIVE — calibration note. The Monte-Carlo engine did NOT beat a zero-drift random-walk cone in the Step-0 backtest (CRPS skill < 0 on every scheme).
A8: The §3 / Monte Carlo sheet is therefore an honest probability map for illustration only — NOT a skill-validated forecast for this name. See study §3.
A10: What it is not. Not investment advice, no rating, no price target. Fair values are ranges; forward inputs are the preparer's judgments.
A11: Anchor: EGP 11.67 (07 Jul 2026 close) · 1,008 mn shares · market cap ~EGP 11.76 bn. Historical financials are the company's own disclosure (FY23–FY25).
A12: Some balance-sheet detail (net interest-bearing debt, working-capital splits) is estimated to tie to disclosed totals and is flagged.
A14: Sheets: READ FIRST · Summary · Fundamental Valuation · Assumptions · DCF (Primary) · Segments · Relative & Normalized · DCF Detail · Income Statement · Balance Sheet · Cash Flow · Summary Financials · Monte Carlo · Sensitivity · Per-Share & Ratios · Peer & Sector

Sheet Assumptions
A1: Assumptions — the single input layer (EGP mn unless stated)
A2: All blue cells are inputs. Every other sheet references these.
A4: ANCHORS
A5: Spot price (EGP/share) | B5: 11.67
A6: Shares outstanding (mn) | B6: 1008
A7: Net interest-bearing debt (EGP mn) | B7: 4500
A8: Tax rate | B8: 0.225
A10: DCF — cost of capital
A11: Risk-free rate (rf, EGP 10y) | B11: 0.235
A12: Equity risk premium (ERP) | B12: 0.06
A13: Beta | B13: 1.15
A14: Cost of equity Ke = rf + beta*ERP | B14: =$B$11+$B$13*$B$12 -> 0.304
A15: Pre-tax cost of debt (Kd) | B15: 0.26
A16: Debt weight | B16: 0.45
A17: Equity weight | B17: 0.55
A18: WACC | B18: =$B$17*$B$14+$B$16*$B$15*(1-$B$8) -> 0.257875
A19: Terminal growth (nominal EGP) | B19: 0.125
A21: REVENUE GROWTH (forecast)
A22: Revenue growth FY26E | B22: 0.2
A23: Revenue growth FY27E | B23: 0.16
A24: Revenue growth FY28E | B24: 0.14
A25: Revenue growth FY29E | B25: 0.12
A26: Revenue growth FY30E | B26: 0.11
A28: EBITDA MARGIN (forecast)
A29: EBITDA margin FY26E | B29: 0.051
A30: EBITDA margin FY27E | B30: 0.052
A31: EBITDA margin FY28E | B31: 0.053
A32: EBITDA margin FY29E | B32: 0.054
A33: EBITDA margin FY30E | B33: 0.055
A35: OTHER FORECAST DRIVERS (% of revenue)
A36: D&A % of revenue | B36: 0.0045
A37: Capex % of revenue | B37: 0.006
A38: Net working-capital build (% of ΔRevenue) | B38: 0.045
A39: Net finance cost (% of revenue, forecast) | B39: 0.03
A41: WORKING CAPITAL (days)
A42: Receivables days (of sales) | B42: 90
A43: Inventory days (of COGS) | B43: 30
A44: Payables days (of COGS) | B44: 119
A46: RELATIVE & NORMALIZED
A47: EV/EBITDA target multiple (x) | B47: 5.5
...

Sheet Income Statement
A1: Income statement (consolidated, EGP mn) — 3y historical + 5y forecast
A3: EGP mn | B3: FY23 | C3: FY24 | D3: FY25 | E3: FY26E | F3: FY27E | G3: FY28E | H3: FY29E | I3: FY30E
A4: Revenue | B4: 33949 | C4: 55842 | D4: 76597 | E4: =D4*(1+Assumptions!$B$22) -> 91916.4 | F4: =E4*(1+Assumptions!$B$23) -> 106623.02 | G4: =F4*(1+Assumptions!$B$24) -> 121550.25 | H4: =G4*(1+Assumptions!$B$25) -> 136136.28 | I4: =H4*(1+Assumptions!$B$26) -> 151111.27
A5: EBITDA margin | B5: =B6/B4 -> 0.04595128 | C5: =C6/C4 -> 0.04584363 | D5: =D6/D4 -> 0.050654725 | E5: =E6/E4 -> 0.051 | F5: =F6/F4 -> 0.052 | G5: =G6/G4 -> 0.053 | H5: =H6/H4 -> 0.054 | I5: =I6/I4 -> 0.055
A6: EBITDA | B6: 1560 | C6: 2560 | D6: 3880 | E6: =E4*Assumptions!$B$29 -> 4687.7364 | F6: =F4*Assumptions!$B$30 -> 5544.3972 | G6: =G4*Assumptions!$B$31 -> 6442.1631 | H6: =H4*Assumptions!$B$32 -> 7351.359 | I6: =I4*Assumptions!$B$33 -> 8311.1197
A7: D&A | B7: 170 | C7: 230 | D7: 300 | E7: =E4*Assumptions!$B$36 -> 413.6238 | F7: =F4*Assumptions!$B$36 -> 479.80361 | G7: =G4*Assumptions!$B$36 -> 546.97611 | H7: =H4*Assumptions!$B$36 -> 612.61325 | I7: =I4*Assumptions!$B$36 -> 680.0007
A8: EBIT | B8: =B6-B7 -> 1390 | C8: =C6-C7 -> 2330 | D8: =D6-D7 -> 3580 | E8: =E6-E7 -> 4274.1126 | F8: =F6-F7 -> 5064.5936 | G8: =G6-G7 -> 5895.187 | H8: =H6-H7 -> 6738.7457 | I8: =I6-I7 -> 7631.119
A9: Net finance cost | B9: -1120 | C9: -1650 | D9: -2650 | E9: =-E4*Assumptions!$B$39 -> -2757.492 | F9: =-F4*Assumptions!$B$39 -> -3198.6907 | G9: =-G4*Assumptions!$B$39 -> -3646.5074 | H9: =-H4*Assumptions!$B$39 -> -4084.0883 | I9: =-I4*Assumptions!$B$39 -> -4533.338
A10: PBT | B10: =B8+B9 -> 270 | C10: =C8+C9 -> 680 | D10: =D8+D9 -> 930 | E10: =E8+E9 -> 1516.6206 | F10: =F8+F9 -> 1865.9029 | G10: =G8+G9 -> 2248.6796 | H10: =H8+H9 -> 2654.6574 | I10: =I8+I9 -> 3097.781
A11: Tax | B11: -56 | C11: -65 | D11: 0 | E11: =-E10*Assumptions!$B$8 -> -341.23964 | F11: =-F10*Assumptions!$B$8 -> -419.82816 | G11: =-G10*Assumptions!$B$8 -> -505.9529 | H11: =-H10*Assumptions!$B$8 -> -597.29792 | I11: =-I10*Assumptions!$B$8 -> -697.00072
A12: Net profit (after NCI) | B12: 214 | C12: 615 | D12: 952 | E12: =E10+E11 -> 1175.381 | F12: =F10+F11 -> 1446.0748 | G12: =G10+G11 -> 1742.7267 | H12: =H10+H11 -> 2057.3595 | I12: =I10+I11 -> 2400.7803
A13: EPS (EGP) | B13: =B12/Assumptions!$B$6 -> 0.21230159 | C13: =C12/Assumptions!$B$6 -> 0.61011905 | D13: =D12/Assumptions!$B$6 -> 0.94444444 | E13: =E12/Assumptions!$B$6 -> 1.1660525 | F13: =F12/Assumptions!$B$6 -> 1.434598 | G13: =G12/Assumptions!$B$6 -> 1.7288955 | H13: =H12/Assumptions!$B$6 -> 2.0410312 | I13: =I12/Assumptions!$B$6 -> 2.3817265
A15: Source: Ibnsina Pharma consolidated earnings releases FY23–FY25 (EGX filings). Forecast rows = formulas from Assumptions. Finance cost / tax history estimated to tie to reported net profit.

Sheet Balance Sheet
A1: Balance sheet (consolidated, EGP mn) — working-capital markers
B3: FY23 | C3: FY24 | D3: FY25 | E3: FY26E | F3: FY27E | G3: FY28E | H3: FY29E | I3: FY30E
A5: Receivables | B5: ='Income Statement'!B4*90/365 -> 8370.9863 | C5: ='Income Statement'!C4*90/365 -> 13769.26 | D5: ='Income Statement'!D4*90/365 -> 18886.932 | E5: ='Income Statement'!E4*90/365 -> 22664.318 | F5: ='Income Statement'!F4*90/365 -> 26290.609 | G5: ='Income Statement'!G4*90/365 -> 29971.294 | H5: ='Income Statement'!H4*90/365 -> 33567.849 | I5: ='Income Statement'!I4*90/365 -> 37260.313
A6: Inventory | B6: ='Income Statement'!B4*0.92*30/365 -> 2567.1025 | C6: ='Income Statement'!C4*0.92*30/365 -> 4222.5732 | D6: ='Income Statement'!D4*0.92*30/365 -> 5791.9923 | E6: ='Income Statement'!E4*0.92*30/365 -> 6950.3908 | F6: ='Income Statement'!F4*0.92*30/365 -> 8062.4533 | G6: ='Income Statement'!G4*0.92*30/365 -> 9191.1968 | H6: ='Income Statement'!H4*0.92*30/365 -> 10294.14 | I6: ='Income Statement'!I4*0.92*30/365 -> 11426.496
A7: Trade payables | B7: ='Income Statement'!B4*0.92*119/365 -> 10182.84 | C7: ='Income Statement'!C4*0.92*119/365 -> 16749.54 | D7: ='Income Statement'!D4*0.92*119/365 -> 22974.903 | E7: ='Income Statement'!E4*0.92*119/365 -> 27569.883 | F7: ='Income Statement'!F4*0.92*119/365 -> 31981.065 | G7: ='Income Statement'!G4*0.92*119/365 -> 36458.414 | H7: ='Income Statement'!H4*0.92*119/365 -> 40833.424 | I7: ='Income Statement'!I4*0.92*119/365 -> 45325.1
A8: Net working capital | B8: =B5+B6-B7 -> 755.24899 | C8: =C5+C6-C7 -> 1242.2933 | D8: =D5+D6-D7 -> 1704.0209 | E8: =E5+E6-E7 -> 2044.8251 | F8: =F5+F6-F7 -> 2371.9971 | G8: =G5+G6-G7 -> 2704.0767 | H8: =H5+H6-H7 -> 3028.5659 | I8: =I5+I6-I7 -> 3361.7082
A9: Net interest-bearing debt | B9: 2100 | C9: 3200 | D9: 4500 | E9: =D9*(1+0.12) -> 5040 | F9: =E9*(1+0.12) -> 5644.8 | G9: =F9*(1+0.12) -> 6322.176 | H9: =G9*(1+0.12) -> 7080.8371 | I9: =H9*(1+0.12) -> 7930.5376
A10: Total equity | B10: 1400 | C10: 2100 | D10: 2900 | E10: =D10+'Income Statement'!E12*0.88 -> 3934.3352 | F10: =E10+'Income Statement'!F12*0.88 -> 5206.881 | G10: =F10+'Income Statement'!G12*0.88 -> 6740.4805 | H10: =G10+'Income Statement'!H12*0.88 -> 8550.9569 | I10: =H10+'Income Statement'!I12*0.88 -> 10663.643
A12: Receivables/inventory/payables = days × sales/COGS (Assumptions). Near-zero cash-conversion cycle: receivables ~90d + inventory ~30d − payables ~119d. Net debt & equity FY23–24 estimated; FY25 per disclosure.

Sheet Cash Flow
A1: Cash flow (EGP mn) — simplified
B3: FY23 | C3: FY24 | D3: FY25 | E3: FY26E | F3: FY27E | G3: FY28E | H3: FY29E | I3: FY30E
A4: Net profit | B4: ='Income Statement'!B12 -> 214 | C4: ='Income Statement'!C12 -> 615 | D4: ='Income Statement'!D12 -> 952 | E4: ='Income Statement'!E12 -> 1175.381 | F4: ='Income Statement'!F12 -> 1446.0748 | G4: ='Income Statement'!G12 -> 1742.7267 | H4: ='Income Statement'!H12 -> 2057.3595 | I4: ='Income Statement'!I12 -> 2400.7803
A5: + D&A | B5: ='Income Statement'!B7 -> 170 | C5: ='Income Statement'!C7 -> 230 | D5: ='Income Statement'!D7 -> 300 | E5: ='Income Statement'!E7 -> 413.6238 | F5: ='Income Statement'!F7 -> 479.80361 | G5: ='Income Statement'!G7 -> 546.97611 | H5: ='Income Statement'!H7 -> 612.61325 | I5: ='Income Statement'!I7 -> 680.0007
A6: − Increase in net WC | B6: 0 | C6: =-('Balance Sheet'!C8-'Balance Sheet'!B8) -> -487.04427 | D6: =-('Balance Sheet'!D8-'Balance Sheet'!C8) -> -461.72767 | E6: =-('Balance Sheet'!E8-'Balance Sheet'!D8) -> -340.80419 | F6: =-('Balance Sheet'!F8-'Balance Sheet'!E8) -> -327.17202 | G6: =-('Balance Sheet'!G8-'Balance Sheet'!F8) -> -332.0796 | H6: =-('Balance Sheet'!H8-'Balance Sheet'!G8) -> -324.48921 | I6: =-('Balance Sheet'!I8-'Balance Sheet'!H8) -> -333.14225
A7: − Capex | B7: =-'Income Statement'!B4*Assumptions!$B$37 -> -203.694 | C7: =-'Income Statement'!C4*Assumptions!$B$37 -> -335.052 | D7: =-'Income Statement'!D4*Assumptions!$B$37 -> -459.582 | E7: =-'Income Statement'!E4*Assumptions!$B$37 -> -551.4984 | F7: =-'Income Statement'!F4*Assumptions!$B$37 -> -639.73814 | G7: =-'Income Statement'!G4*Assumptions!$B$37 -> -729.30148 | H7: =-'Income Statement'!H4*Assumptions!$B$37 -> -816.81766 | I7: =-'Income Statement'!I4*Assumptions!$B$37 -> -906.66761
A8: Free cash flow to firm | B8: =B4+B5+B6+B7 -> 180.306 | C8: =C4+C5+C6+C7 -> 22.903726 | D8: =D4+D5+D6+D7 -> 330.69033 | E8: =E4+E5+E6+E7 -> 696.70218 | F8: =F4+F5+F6+F7 -> 958.96821 | G8: =G4+G5+G6+G7 -> 1228.3217 | H8: =H4+H5+H6+H7 -> 1528.6659 | I8: =I4+I5+I6+I7 -> 1840.9711

Sheet DCF (Primary)
A1: DCF (Primary lens) — valuation bridge (EGP mn)
A3: Σ PV of explicit FCFF (FY26–30) | B3: ='DCF Detail'!B20 -> 10037.892
A4: Terminal value (Gordon) | B4: ='DCF Detail'!B18 -> 45332.806
A5: PV of terminal value | B5: ='DCF Detail'!B19 -> 14395.448
A6: Enterprise value | B6: =B3+B5 -> 24433.34
A7: less: net interest-bearing debt | B7: =-Assumptions!$B$7 -> -4500
A8: Equity value | B8: =B6+B7 -> 19933.34
A9: Fair value per share (EGP) | B9: =B8/Assumptions!$B$6 -> 19.775139
A10: % terminal of EV | B10: =B5/B6 -> 0.58917232
A12: WACC (from Assumptions) | B12: =Assumptions!$B$18 -> 0.257875
A13: Ke = rf + beta×ERP | B13: =Assumptions!$B$14 -> 0.304
A14: Terminal growth | B14: =Assumptions!$B$19 -> 0.125
A16: Full 5-year FCFF waterfall on the DCF Detail sheet. Bear/base/bull via the Sensitivity (WACC × g) grid.

Sheet DCF Detail
A1: DCF Detail — explicit 5-year FCFF waterfall (EGP mn)
C3: FY26E | D3: FY27E | E3: FY28E | F3: FY29E | G3: FY30E
A4: Revenue | B4: ='Income Statement'!E4 -> 91916.4 | C4: ='Income Statement'!F4 -> 106623.02 | D4: ='Income Statement'!G4 -> 121550.25 | E4: ='Income Statement'!H4 -> 136136.28 | F4: ='Income Statement'!I4 -> 151111.27
A5: EBITDA | B5: ='Income Statement'!E6 -> 4687.7364 | C5: ='Income Statement'!F6 -> 5544.3972 | D5: ='Income Statement'!G6 -> 6442.1631 | E5: ='Income Statement'!H6 -> 7351.359 | F5: ='Income Statement'!I6 -> 8311.1197
A6: D&A | B6: ='Income Statement'!E7 -> 413.6238 | C6: ='Income Statement'!F7 -> 479.80361 | D6: ='Income Statement'!G7 -> 546.97611 | E6: ='Income Statement'!H7 -> 612.61325 | F6: ='Income Statement'!I7 -> 680.0007
A7: EBIT | B7: ='Income Statement'!E8 -> 4274.1126 | C7: ='Income Statement'!F8 -> 5064.5936 | D7: ='Income Statement'!G8 -> 5895.187 | E7: ='Income Statement'!H8 -> 6738.7457 | F7: ='Income Statement'!I8 -> 7631.119
A8: NOPAT = EBIT×(1−t) | B8: =B7*(1-Assumptions!$B$8) -> 3312.4373 | C8: =C7*(1-Assumptions!$B$8) -> 3925.0601 | D8: =D7*(1-Assumptions!$B$8) -> 4568.7699 | E8: =E7*(1-Assumptions!$B$8) -> 5222.5279 | F8: =F7*(1-Assumptions!$B$8) -> 5914.1172
A9: + D&A | B9: =B6 -> 413.6238 | C9: =C6 -> 479.80361 | D9: =D6 -> 546.97611 | E9: =E6 -> 612.61325 | F9: =F6 -> 680.0007
A10: − Capex | B10: ='Cash Flow'!E7 -> -551.4984 | C10: ='Cash Flow'!F7 -> -639.73814 | D10: ='Cash Flow'!G7 -> -729.30148 | E10: ='Cash Flow'!H7 -> -816.81766 | F10: ='Cash Flow'!I7 -> -906.66761
A11: − Increase in net WC | B11: ='Cash Flow'!E6 -> -340.80419 | C11: ='Cash Flow'!F6 -> -327.17202 | D11: ='Cash Flow'!G6 -> -332.0796 | E11: ='Cash Flow'!H6 -> -324.48921 | F11: ='Cash Flow'!I6 -> -333.14225
A12: Free cash flow to firm | B12: =B8+B9+B10+B11 -> 2833.7585 | C12: =C8+C9+C10+C11 -> 3437.9535 | D12: =D8+D9+D10+D11 -> 4054.365 | E12: =E8+E9+E10+E11 -> 4693.8343 | F12: =F8+F9+F10+F11 -> 5354.3081
A13: Discount factor | B13: =1/(1+Assumptions!$B$18)^1 -> 0.79499155 | C13: =1/(1+Assumptions!$B$18)^2 -> 0.63201157 | D13: =1/(1+Assumptions!$B$18)^3 -> 0.50244386 | E13: =1/(1+Assumptions!$B$18)^4 -> 0.39943862 | F13: =1/(1+Assumptions!$B$18)^5 -> 0.31755033 | H13: =SUM(B14:F14) -> 10037.892
A14: Free cash flow to firm | B14: =B12*B13 -> 2252.8141 | C14: =C12*C13 -> 2172.8264 | D14: =D12*D13 -> 2037.0908 | E14: =E12*E13 -> 1874.8987 | F14: =F12*F13 -> 1700.2623
A16: Σ PV explicit (H13→)
A17: Terminal value (B14 slot)
A18: Terminal value (Gordon) | B18: =F12*(1+Assumptions!$B$19)/(Assumptions!$B$18-Assumptions!$B$19) -> 45332.806
A19: PV of terminal value | B19: =B18/(1+Assumptions!$B$18)^5 -> 14395.448
A20: Σ PV of explicit FCFF | B20: =SUM(B14:F14) -> 10037.892

Sheet Relative & Normalized
A1: Relative multiples & normalized earnings (EGP)
A3: EV/EBITDA — FY25 (trailing) EBITDA
A4: Trailing EBITDA (EGP mn) | B4: ='Income Statement'!D6 -> 3880
A5: Target EV/EBITDA (x) | B5: =Assumptions!$B$47 -> 5.5
A6: Implied EV | B6: =B4*B5 -> 21340
A7: less: net debt | B7: =-Assumptions!$B$7 -> -4500
A8: Relative fair value / share | B8: =(B6+B7)/Assumptions!$B$6 -> 16.706349
A10: Normalized earnings power
A11: FY27E revenue | B11: ='Income Statement'!F4 -> 106623.02
A12: Normalized net margin | B12: =Assumptions!$B$48 -> 0.017
A13: Normalized net profit | B13: =B11*B12 -> 1812.5914
A14: Justified P/E (x) | B14: =Assumptions!$B$49 -> 10
A15: Normalized fair value / share | B15: =B13*B14/Assumptions!$B$6 -> 17.982058
A17: Multiple anchored on trailing EBITDA (the market prices ISPH at ~4.2x); a modest re-rating to the mid-single digits reflects margin/rate normalization.

Sheet Summary Financials
A1: Summary financials (every cell links to the statement sheets)
B3: FY23 | C3: FY24 | D3: FY25 | E3: FY26E | F3: FY27E | G3: FY28E | H3: FY29E | I3: FY30E
A4: Revenue | B4: ='Income Statement'!B4 -> 33949 | C4: ='Income Statement'!C4 -> 55842 | D4: ='Income Statement'!D4 -> 76597 | E4: ='Income Statement'!E4 -> 91916.4 | F4: ='Income Statement'!F4 -> 106623.02 | G4: ='Income Statement'!G4 -> 121550.25 | H4: ='Income Statement'!H4 -> 136136.28 | I4: ='Income Statement'!I4 -> 151111.27
A5: EBITDA | B5: ='Income Statement'!B6 -> 1560 | C5: ='Income Statement'!C6 -> 2560 | D5: ='Income Statement'!D6 -> 3880 | E5: ='Income Statement'!E6 -> 4687.7364 | F5: ='Income Statement'!F6 -> 5544.3972 | G5: ='Income Statement'!G6 -> 6442.1631 | H5: ='Income Statement'!H6 -> 7351.359 | I5: ='Income Statement'!I6 -> 8311.1197
A6: EBIT | B6: ='Income Statement'!B8 -> 1390 | C6: ='Income Statement'!C8 -> 2330 | D6: ='Income Statement'!D8 -> 3580 | E6: ='Income Statement'!E8 -> 4274.1126 | F6: ='Income Statement'!F8 -> 5064.5936 | G6: ='Income Statement'!G8 -> 5895.187 | H6: ='Income Statement'!H8 -> 6738.7457 | I6: ='Income Statement'!I8 -> 7631.119
A7: Net profit | B7: ='Income Statement'!B12 -> 214 | C7: ='Income Statement'!C12 -> 615 | D7: ='Income Statement'!D12 -> 952 | E7: ='Income Statement'!E12 -> 1175.381 | F7: ='Income Statement'!F12 -> 1446.0748 | G7: ='Income Statement'!G12 -> 1742.7267 | H7: ='Income Statement'!H12 -> 2057.3595 | I7: ='Income Statement'!I12 -> 2400.7803
A8: EPS (EGP) | B8: ='Income Statement'!B13 -> 0.21230159 | C8: ='Income Statement'!C13 -> 0.61011905 | D8: ='Income Statement'!D13 -> 0.94444444 | E8: ='Income Statement'!E13 -> 1.1660525 | F8: ='Income Statement'!F13 -> 1.434598 | G8: ='Income Statement'!G13 -> 1.7288955 | H8: ='Income Statement'!H13 -> 2.0410312 | I8: ='Income Statement'!I13 -> 2.3817265
A9: FCFF | B9: ='Cash Flow'!B8 -> 180.306 | C9: ='Cash Flow'!C8 -> 22.903726 | D9: ='Cash Flow'!D8 -> 330.69033 | E9: ='Cash Flow'!E8 -> 696.70218 | F9: ='Cash Flow'!F8 -> 958.96821 | G9: ='Cash Flow'!G8 -> 1228.3217 | H9: ='Cash Flow'!H8 -> 1528.6659 | I9: ='Cash Flow'!I8 -> 1840.9711
A10: Net working capital | B10: ='Balance Sheet'!B8 -> 755.24899 | C10: ='Balance Sheet'!C8 -> 1242.2933 | D10: ='Balance Sheet'!D8 -> 1704.0209 | E10: ='Balance Sheet'!E8 -> 2044.8251 | F10: ='Balance Sheet'!F8 -> 2371.9971 | G10: ='Balance Sheet'!G8 -> 2704.0767 | H10: ='Balance Sheet'!H8 -> 3028.5659 | I10: ='Balance Sheet'!I8 -> 3361.7082

Sheet Monte Carlo
A1: Monte Carlo — §3 outputs (INDICATIVE: engine failed Step-0 calibration)
A2: Illustrative only — CRPS skill < 0 vs random-walk. Not a skill-validated forecast.
A4: Percentile map (EGP/share)
B5: p5 | C5: p25 | D5: p50 | E5: p75 | F5: p95
A6: T+20 sessions | B6: 10.161564 | C6: 11.138563 | D6: 11.745663 | E6: 12.385542 | F6: 13.524969
A7: T+60 sessions | B7: 9.2880359 | C7: 10.846924 | D7: 11.908143 | E7: 13.055882 | F7: 15.178882
A9: Probability read (T+60)
A10: P(price above spot) | B10: 0.55996
A11: P(+10%) | B11: 0.29108
A12: P(−10%) | B12: 0.18552
A13: Odds ratio (up:down) | B13: 1.5689953
A14: Median (EGP) | B14: 11.908143
A15: Median move | B15: 0.020406399
A16: 50% band low | B16: 10.846924
A17: 50% band high | B17: 13.055882
A18: Touch +10% | B18: 0.48994
A19: Touch −10% | B19: 0.35756
A22: Engine: YZ-HAR width (annualised ~29%) × horizon variance-ratio 1.86; Student-t(5); drift OFF (near-even); 16-factor skew; 50,000 paths, seed 42. Presentation-only.

Sheet Sensitivity
A1: DCF sensitivity — fair value / share (EGP): WACC × terminal growth
A3: WACC \ g | B3: 0.105 | C3: 0.115 | D3: 0.125 | E3: 0.135 | F3: 0.145
A4: 0.29 | B4: =('DCF Detail'!B12/(1+0.29)^1+'DCF Detail'!C12/(1+0.29)^2+'DCF Detail'!D12/(1+0.29)^3+'DCF Detail'!E12/(1+0.29)^4+'DCF Detail'!F12/(1+0.29)^5+'DCF Detail'!F12*(1+0.105)/(0.29-0.105)/(1+0.29)^5-Assumptions!$B$7)/Assumptions!$B$6 -> 13.688176 | C4: =('DCF Detail'!B12/(1+0.29)^1+'DCF Detail'!C12/(1+0.29)^2+'DCF Detail'!D12/(1+0.29)^3+'DCF Detail'!E12/(1+0.29)^4+'DCF Detail'!F12/(1+0.29)^5+'DCF Detail'!F12*(1+0.115)/(0.29-0.115)/(1+0.29)^5-Assumptions!$B$7)/Assumptions!$B$6 -> 14.280657 | D4: =('DCF Detail'!B12/(1+0.29)^1+'DCF Detail'!C12/(1+0.29)^2+'DCF Detail'!D12/(1+0.29)^3+'DCF Detail'!E12/(1+0.29)^4+'DCF Detail'!F12/(1+0.29)^5+'DCF Detail'!F12*(1+0.125)/(0.29-0.125)/(1+0.29)^5-Assumptions!$B$7)/Assumptions!$B$6 -> 14.944954 | E4: =('DCF Detail'!B12/(1+0.29)^1+'DCF Detail'!C12/(1+0.29)^2+'DCF Detail'!D12/(1+0.29)^3+'DCF Detail'!E12/(1+0.29)^4+'DCF Detail'!F12/(1+0.29)^5+'DCF Detail'!F12*(1+0.135)/(0.29-0.135)/(1+0.29)^5-Assumptions!$B$7)/Assumptions!$B$6 -> 15.694966 | F4: =('DCF Detail'!B12/(1+0.29)^1+'DCF Detail'!C12/(1+0.29)^2+'DCF Detail'!D12/(1+0.29)^3+'DCF Detail'!E12/(1+0.29)^4+'DCF Detail'!F12/(1+0.29)^5+'DCF Detail'!F12*(1+0.145)/(0.29-0.145)/(1+0.29)^5-Assumptions!$B$7)/Assumptions!$B$6 -> 16.548428
A5: 0.27 | B5: =('DCF Detail'!B12/(1+0.27)^1+'DCF Detail'!C12/(1+0.27)^2+'DCF Detail'!D12/(1+0.27)^3+'DCF Detail'!E12/(1+0.27)^4+'DCF Detail'!F12/(1+0.27)^5+'DCF Detail'!F12*(1+0.105)/(0.27-0.105)/(1+0.27)^5-Assumptions!$B$7)/Assumptions!$B$6 -> 15.992484 | C5: =('DCF Detail'!B12/(1+0.27)^1+'DCF Detail'!C12/(1+0.27)^2+'DCF Detail'!D12/(1+0.27)^3+'DCF Detail'!E12/(1+0.27)^4+'DCF Detail'!F12/(1+0.27)^5+'DCF Detail'!F12*(1+0.115)/(0.27-0.115)/(1+0.27)^5-Assumptions!$B$7)/Assumptions!$B$6 -> 16.790869 | D5: =('DCF Detail'!B12/(1+0.27)^1+'DCF Detail'!C12/(1+0.27)^2+'DCF Detail'!D12/(1+0.27)^3+'DCF Detail'!E12/(1+0.27)^4+'DCF Detail'!F12/(1+0.27)^5+'DCF Detail'!F12*(1+0.125)/(0.27-0.125)/(1+0.27)^5-Assumptions!$B$7)/Assumptions!$B$6 -> 17.699376 | E5: =('DCF Detail'!B12/(1+0.27)^1+'DCF Detail'!C12/(1+0.27)^2+'DCF Detail'!D12/(1+0.27)^3+'DCF Detail'!E12/(1+0.27)^4+'DCF Detail'!F12/(1+0.27)^5+'DCF Detail'!F12*(1+0.135)/(0.27-0.135)/(1+0.27)^5-Assumptions!$B$7)/Assumptions!$B$6 -> 18.742476 | F5: =('DCF Detail'!B12/(1+0.27)^1+'DCF Detail'!C12/(1+0.27)^2+'DCF Detail'!D12/(1+0.27)^3+'DCF Detail'!E12/(1+0.27)^4+'DCF Detail'!F12/(1+0.27)^5+'DCF Detail'!F12*(1+0.145)/(0.27-0.145)/(1+0.27)^5-Assumptions!$B$7)/Assumptions!$B$6 -> 19.952473
A6: 0.258 | B6: =('DCF Detail'!B12/(1+0.258)^1+'DCF Detail'!C12/(1+0.258)^2+'DCF Detail'!D12/(1+0.258)^3+'DCF Detail'!E12/(1+0.258)^4+'DCF Detail'!F12/(1+0.258)^5+'DCF Detail'!F12*(1+0.105)/(0.258-0.105)/(1+0.258)^5-Assumptions!$B$7)/Assumptions!$B$6 -> 17.667274 | C6: =('DCF Detail'!B12/(1+0.258)^1+'DCF Detail'!C12/(1+0.258)^2+'DCF Detail'!D12/(1+0.258)^3+'DCF Detail'!E12/(1+0.258)^4+'DCF Detail'!F12/(1+0.258)^5+'DCF Detail'!F12*(1+0.115)/(0.258-0.115)/(1+0.258)^5-Assumptions!$B$7)/Assumptions!$B$6 -> 18.636651 | D6: =('DCF Detail'!B12/(1+0.258)^1+'DCF Detail'!C12/(1+0.258)^2+'DCF Detail'!D12/(1+0.258)^3+'DCF Detail'!E12/(1+0.258)^4+'DCF Detail'!F12/(1+0.258)^5+'DCF Detail'!F12*(1+0.125)/(0.258-0.125)/(1+0.258)^5-Assumptions!$B$7)/Assumptions!$B$6 -> 19.7518 | E6: =('DCF Detail'!B12/(1+0.258)^1+'DCF Detail'!C12/(1+0.258)^2+'DCF Detail'!D12/(1+0.258)^3+'DCF Detail'!E12/(1+0.258)^4+'DCF Detail'!F12/(1+0.258)^5+'DCF Detail'!F12*(1+0.135)/(0.258-0.135)/(1+0.258)^5-Assumptions!$B$7)/Assumptions!$B$6 -> 21.048273 | F6: =('DCF Detail'!B12/(1+0.258)^1+'DCF Detail'!C12/(1+0.258)^2+'DCF Detail'!D12/(1+0.258)^3+'DCF Detail'!E12/(1+0.258)^4+'DCF Detail'!F12/(1+0.258)^5+'DCF Detail'!F12*(1+0.145)/(0.258-0.145)/(1+0.258)^5-Assumptions!$B$7)/Assumptions!$B$6 -> 22.57421
A7: 0.24 | B7: =('DCF Detail'!B12/(1+0.24)^1+'DCF Detail'!C12/(1+0.24)^2+'DCF Detail'!D12/(1+0.24)^3+'DCF Detail'!E12/(1+0.24)^4+'DCF Detail'!F12/(1+0.24)^5+'DCF Detail'!F12*(1+0.105)/(0.24-0.105)/(1+0.24)^5-Assumptions!$B$7)/Assumptions!$B$6 -> 20.742884 | C7: =('DCF Detail'!B12/(1+0.24)^1+'DCF Detail'!C12/(1+0.24)^2+'DCF Detail'!D12/(1+0.24)^3+'DCF Detail'!E12/(1+0.24)^4+'DCF Detail'!F12/(1+0.24)^5+'DCF Detail'!F12*(1+0.115)/(0.24-0.115)/(1+0.24)^5-Assumptions!$B$7)/Assumptions!$B$6 -> 22.074295 | D7: =('DCF Detail'!B12/(1+0.24)^1+'DCF Detail'!C12/(1+0.24)^2+'DCF Detail'!D12/(1+0.24)^3+'DCF Detail'!E12/(1+0.24)^4+'DCF Detail'!F12/(1+0.24)^5+'DCF Detail'!F12*(1+0.125)/(0.24-0.125)/(1+0.24)^5-Assumptions!$B$7)/Assumptions!$B$6 -> 23.637256 | E7: =('DCF Detail'!B12/(1+0.24)^1+'DCF Detail'!C12/(1+0.24)^2+'DCF Detail'!D12/(1+0.24)^3+'DCF Detail'!E12/(1+0.24)^4+'DCF Detail'!F12/(1+0.24)^5+'DCF Detail'!F12*(1+0.135)/(0.24-0.135)/(1+0.24)^5-Assumptions!$B$7)/Assumptions!$B$6 -> 25.497925 | F7: =('DCF Detail'!B12/(1+0.24)^1+'DCF Detail'!C12/(1+0.24)^2+'DCF Detail'!D12/(1+0.24)^3+'DCF Detail'!E12/(1+0.24)^4+'DCF Detail'!F12/(1+0.24)^5+'DCF Detail'!F12*(1+0.145)/(0.24-0.145)/(1+0.24)^5-Assumptions!$B$7)/Assumptions!$B$6 -> 27.750312
A8: 0.22 | B8: =('DCF Detail'!B12/(1+0.22)^1+'DCF Detail'!C12/(1+0.22)^2+'DCF Detail'!D12/(1+0.22)^3+'DCF Detail'!E12/(1+0.22)^4+'DCF Detail'!F12/(1+0.22)^5+'DCF Detail'!F12*(1+0.105)/(0.22-0.105)/(1+0.22)^5-Assumptions!$B$7)/Assumptions!$B$6 -> 25.298536 | C8: =('DCF Detail'!B12/(1+0.22)^1+'DCF Detail'!C12/(1+0.22)^2+'DCF Detail'!D12/(1+0.22)^3+'DCF Detail'!E12/(1+0.22)^4+'DCF Detail'!F12/(1+0.22)^5+'DCF Detail'!F12*(1+0.115)/(0.22-0.115)/(1+0.22)^5-Assumptions!$B$7)/Assumptions!$B$6 -> 27.284249 | D8: =('DCF Detail'!B12/(1+0.22)^1+'DCF Detail'!C12/(1+0.22)^2+'DCF Detail'!D12/(1+0.22)^3+'DCF Detail'!E12/(1+0.22)^4+'DCF Detail'!F12/(1+0.22)^5+'DCF Detail'!F12*(1+0.125)/(0.22-0.125)/(1+0.22)^5-Assumptions!$B$7)/Assumptions!$B$6 -> 29.688006 | E8: =('DCF Detail'!B12/(1+0.22)^1+'DCF Detail'!C12/(1+0.22)^2+'DCF Detail'!D12/(1+0.22)^3+'DCF Detail'!E12/(1+0.22)^4+'DCF Detail'!F12/(1+0.22)^5+'DCF Detail'!F12*(1+0.135)/(0.22-0.135)/(1+0.22)^5-Assumptions!$B$7)/Assumptions!$B$6 -> 32.657353 | F8: =('DCF Detail'!B12/(1+0.22)^1+'DCF Detail'!C12/(1+0.22)^2+'DCF Detail'!D12/(1+0.22)^3+'DCF Detail'!E12/(1+0.22)^4+'DCF Detail'!F12/(1+0.22)^5+'DCF Detail'!F12*(1+0.145)/(0.22-0.145)/(1+0.22)^5-Assumptions!$B$7)/Assumptions!$B$6 -> 36.418526

Sheet Per-Share & Ratios
A1: Per-share & ratio dashboard
B3: FY23 | C3: FY24 | D3: FY25 | E3: FY26E | F3: FY27E | G3: FY28E | H3: FY29E | I3: FY30E
A4: EPS (EGP) | B4: ='Income Statement'!B13 -> 0.21230159 | C4: ='Income Statement'!C13 -> 0.61011905 | D4: ='Income Statement'!D13 -> 0.94444444 | E4: ='Income Statement'!E13 -> 1.1660525 | F4: ='Income Statement'!F13 -> 1.434598 | G4: ='Income Statement'!G13 -> 1.7288955 | H4: ='Income Statement'!H13 -> 2.0410312 | I4: ='Income Statement'!I13 -> 2.3817265
A5: Revenue growth | B5: =IF(ISNUMBER('Income Statement'!A4),'Income Statement'!B4/'Income Statement'!A4-1,"") | C5: =IF(ISNUMBER('Income Statement'!B4),'Income Statement'!C4/'Income Statement'!B4-1,"") -> 0.64487908 | D5: =IF(ISNUMBER('Income Statement'!C4),'Income Statement'!D4/'Income Statement'!C4-1,"") -> 0.37167365 | E5: =IF(ISNUMBER('Income Statement'!D4),'Income Statement'!E4/'Income Statement'!D4-1,"") -> 0.2 | F5: =IF(ISNUMBER('Income Statement'!E4),'Income Statement'!F4/'Income Statement'!E4-1,"") -> 0.16 | G5: =IF(ISNUMBER('Income Statement'!F4),'Income Statement'!G4/'Income Statement'!F4-1,"") -> 0.14 | H5: =IF(ISNUMBER('Income Statement'!G4),'Income Statement'!H4/'Income Statement'!G4-1,"") -> 0.12 | I5: =IF(ISNUMBER('Income Statement'!H4),'Income Statement'!I4/'Income Statement'!H4-1,"") -> 0.11
A6: EBITDA margin | B6: ='Income Statement'!B5 -> 0.04595128 | C6: ='Income Statement'!C5 -> 0.04584363 | D6: ='Income Statement'!D5 -> 0.050654725 | E6: ='Income Statement'!E5 -> 0.051 | F6: ='Income Statement'!F5 -> 0.052 | G6: ='Income Statement'!G5 -> 0.053 | H6: ='Income Statement'!H5 -> 0.054 | I6: ='Income Statement'!I5 -> 0.055
A7: Net margin | B7: ='Income Statement'!B12/'Income Statement'!B4 -> 0.006303573 | C7: ='Income Statement'!C12/'Income Statement'!C4 -> 0.011013216 | D7: ='Income Statement'!D12/'Income Statement'!D4 -> 0.012428685 | E7: ='Income Statement'!E12/'Income Statement'!E4 -> 0.0127875 | F7: ='Income Statement'!F12/'Income Statement'!F4 -> 0.0135625 | G7: ='Income Statement'!G12/'Income Statement'!G4 -> 0.0143375 | H7: ='Income Statement'!H12/'Income Statement'!H4 -> 0.0151125 | I7: ='Income Statement'!I12/'Income Statement'!I4 -> 0.0158875
A8: Net debt / EBITDA | B8: ='Balance Sheet'!B9/'Income Statement'!B6 -> 1.3461538 | C8: ='Balance Sheet'!C9/'Income Statement'!C6 -> 1.25 | D8: ='Balance Sheet'!D9/'Income Statement'!D6 -> 1.1597938 | E8: ='Balance Sheet'!E9/'Income Statement'!E6 -> 1.0751458 | F8: ='Balance Sheet'!F9/'Income Statement'!F6 -> 1.0181089 | G8: ='Balance Sheet'!G9/'Income Statement'!G6 -> 0.98137472 | H8: ='Balance Sheet'!H9/'Income Statement'!H6 -> 0.96320111 | I8: ='Balance Sheet'!I9/'Income Statement'!I6 -> 0.95420808
A9: ROE | B9: ='Income Statement'!B12/'Balance Sheet'!B10 -> 0.15285714 | C9: ='Income Statement'!C12/'Balance Sheet'!C10 -> 0.29285714 | D9: ='Income Statement'!D12/'Balance Sheet'!D10 -> 0.32827586 | E9: ='Income Statement'!E12/'Balance Sheet'!E10 -> 0.29874957 | F9: ='Income Statement'!F12/'Balance Sheet'!F10 -> 0.2777238 | G9: ='Income Statement'!G12/'Balance Sheet'!G10 -> 0.25854636 | H9: ='Income Statement'!H12/'Balance Sheet'!H10 -> 0.24059991 | I9: ='Income Statement'!I12/'Balance Sheet'!I10 -> 0.22513696
A10: P/E (x, at spot) | B10: =Assumptions!$B$5/'Income Statement'!B13 -> 54.968972 | C10: =Assumptions!$B$5/'Income Statement'!C13 -> 19.127415 | D10: =Assumptions!$B$5/'Income Statement'!D13 -> 12.356471 | E10: =Assumptions!$B$5/'Income Statement'!E13 -> 10.008125 | F10: =Assumptions!$B$5/'Income Statement'!F13 -> 8.1346831 | G10: =Assumptions!$B$5/'Income Statement'!G13 -> 6.7499742 | H10: =Assumptions!$B$5/'Income Statement'!H13 -> 5.7176979 | I10: =Assumptions!$B$5/'Income Statement'!I13 -> 4.899807
A11: EV/EBITDA (x, at spot) | B11: =(Assumptions!$B$5*Assumptions!$B$6+Assumptions!$B$7)/'Income Statement'!B6 -> 10.425231 | C11: =(Assumptions!$B$5*Assumptions!$B$6+Assumptions!$B$7)/'Income Statement'!C6 -> 6.352875 | D11: =(Assumptions!$B$5*Assumptions!$B$6+Assumptions!$B$7)/'Income Statement'!D6 -> 4.1915876 | E11: =(Assumptions!$B$5*Assumptions!$B$6+Assumptions!$B$7)/'Income Statement'!E6 -> 3.4693418 | F11: =(Assumptions!$B$5*Assumptions!$B$6+Assumptions!$B$7)/'Income Statement'!F6 -> 2.9332963 | G11: =(Assumptions!$B$5*Assumptions!$B$6+Assumptions!$B$7)/'Income Statement'!G6 -> 2.5245185 | H11: =(Assumptions!$B$5*Assumptions!$B$6+Assumptions!$B$7)/'Income Statement'!H6 -> 2.212293 | I11: =(Assumptions!$B$5*Assumptions!$B$6+Assumptions!$B$7)/'Income Statement'!I6 -> 1.9568194

Sheet Segments
A1: Segments — revenue channel split (FY23 disclosed)
A3: Channel | B3: FY23 % of revenue | C3: FY23 EGP mn (approx.)
A4: Retail (pharmacies) | B4: 0.464 | C4: =B4*'Income Statement'!B4 -> 15752.336
A5: Wholesale | B5: 0.333 | C5: =B5*'Income Statement'!B4 -> 11305.017
A6: Tenders & private hospitals | B6: 0.203 | C6: =B6*'Income Statement'!B4 -> 6891.647
A7: Total | B7: =SUM(B4:B6) -> 1 | C7: =SUM(C4:C6) -> 33949
A9: Source: Ibnsina Pharma FY23 earnings release. FY25 channel mix not separately disclosed; retail share had been declining as credit risk managed.

Sheet Fundamental Valuation
A1: Fundamental valuation — four lenses (EGP/share)
A3: Lens | B3: Bear | C3: Base | D3: Bull | E3: Weight
A4: DCF (primary) | B4: 13.703383 | C4: 19.794663 | D4: 23.735786 | E4: 0.45
A5: Relative EV/EBITDA | B5: 12.857143 | C5: ='Relative & Normalized'!B8 -> 16.706349 | D5: 22.480159 | E5: 0.25
A6: Normalized earnings | B6: 12.58744 | C6: ='Relative & Normalized'!B15 -> 17.982058 | D6: 25.386434 | E6: 0.2
A7: DDM / yield floor | B7: 9.5 | C7: 11 | D7: 13 | E7: 0.1
A8: Weighted central | B8: =B4*$E$4+B5*$E$5+B6*$E$6+B7*$E$7 -> 12.848296 | C8: =C4*$E$4+C5*$E$5+C6*$E$6+C7*$E$7 -> 17.780597 | D8: =D4*$E$4+D5*$E$5+D6*$E$6+D7*$E$7 -> 22.67843
A10: DCF/Relative/Normalized link to their sheets; DDM floor and weights are inputs. Football-field-plus-distribution replaces a single blended point (device A-8).

Sheet Summary
A1: Summary — Ibnsina Pharma (EGX: ISPH)
A4: Spot (EGP, 07 Jul 2026) | B4: =Assumptions!$B$5 -> 11.67
A5: Shares (mn) | B5: =Assumptions!$B$6 -> 1008
A6: Market cap (EGP mn) | B6: =Assumptions!$B$5*Assumptions!$B$6 -> 11763.36
A7: Net debt (EGP mn) | B7: =Assumptions!$B$7 -> 4500
A8: DCF fair value (EGP) | B8: ='DCF (Primary)'!B9 -> 19.775139
A9: Relative fair value (EGP) | B9: ='Relative & Normalized'!B8 -> 16.706349
A10: Normalized fair value (EGP) | B10: ='Relative & Normalized'!B15 -> 17.982058
A11: Weighted central (EGP) | B11: ='Fundamental Valuation'!C8 -> 17.780597
A12: Upside vs spot | B12: ='Fundamental Valuation'!C8/Assumptions!$B$5-1 -> 0.52361588
A14: Monte Carlo (§3) — INDICATIVE, calibration failed
A15: T+60 median (EGP) | B15: 11.908143
A16: T+60 p5–p95 (EGP) | B16: 9.29 – 15.18

Sheet Peer & Sector
A1: Peer set & sector structure
A3: Peer / comparable | B3: Market | C3: Type | D3: Typical EV/EBITDA
A4: Ibnsina Pharma (ISPH) | B4: Egypt (EGX) | C4: Pharma distribution #1/#2 | D4: ~4–5x
A5: Pharma Overseas / UCP | B5: Egypt (private) | C5: Pharma distribution | D5: n/a
A6: Cell. / MENA distributors | B6: MENA | C6: Healthcare distribution | D6: 5–8x
A7: EM pharma distributors | B7: Global EM | C7: Distribution / logistics | D7: 6–10x
A9: Egyptian pharma distribution is a scale/working-capital game: #1–2 players (Ibnsina, UCP/Pharma Overseas) hold most share; demand is defensive (population +2%/yr) with inflation re-pricing. High local rates compress multiples vs global distributors.
