Workbook

Sheet READ FIRST
A1: Testahil — Independent Valuation Study — Educational Analysis
A2: El Nasr Clothing & Textiles Co. (Kabo) · EGX: KABO · Valuation model · edition 06-07-2026
A4: NOT INVESTMENT ADVICE. This workbook is an educational valuation exercise, published free of charge. It is not, and must not be relied upon as,
A5: investment, financial, legal or tax advice, nor an offer or recommendation to buy, sell or hold any security. It contains no price target and no rating.
A7: The preparer is not licensed by any securities regulator, holds no brokerage authorisation, and manages no money. All values are model outputs
A8: presented as ranges. KABO is a thinly-covered small-cap: the share count is derived from market capitalisation, and several historical line items and
A9: the balance-sheet split are reconstructed on a fiscal-year (July-June) basis and flagged as estimates. The land-and-buildings re-mark that drives the
A10: primary (RNAV) lens is the preparer's own judgment, not a disclosed figure, and is sensitised rather than asserted.
A12: PRIMARY LENS: revalued net asset value (RNAV), going-concern. Cross-checked by a going-concern DCF, a price-to-book relative read, and a
A13: normalized-earnings read. Every downstream sheet links to the Assumptions tab — change one input there and the whole model reprices.
A15: MONTE CARLO: the engine FAILED its Step 0 calibration on KABO (CRPS skill -0.010 vs a zero-drift random-walk cone; interval skill -0.055).
A16: No probabilistic price forecast is published; the Monte Carlo tab is an ILLUSTRATIVE volatility map only. See the Monte Carlo tab and the study Appendix B.
... A19: time without notice. Figures in EGP; m = million. Spot and market data as of 06 July 2026 and change continuously.

Sheet Summary
A1: Valuation summary — every read at a glance
A3: Lens / read | B3: Output (EGP/sh) | C3: vs spot | D3: Note
A4: FUNDAMENTAL — what the business is worth
A5: RNAV (primary) | B5: ='Fundamental Valuation'!B4 -> 3.2770973 | C5: ='Fundamental Valuation'!B4/Assumptions!$B$5-1 -> -0.53184324 | D5: the anchor
A6: Going-concern DCF | B6: ='Fundamental Valuation'!B5 -> 0.54142725 | C6: ='Fundamental Valuation'!B5/Assumptions!$B$5-1 -> -0.92265325 | D6: floor of operations
A7: Relative (price-to-book) | B7: ='Fundamental Valuation'!B6 -> 2.6496071 | C7: ='Fundamental Valuation'!B6/Assumptions!$B$5-1 -> -0.6214847
A8: Normalized earnings | B8: ='Fundamental Valuation'!B7 -> 1.2389381 | C8: ='Fundamental Valuation'!B7/Assumptions!$B$5-1 -> -0.82300885
A9: Weighted central | B9: ='Fundamental Valuation'!D9 -> 2.4041504 | C9: ='Fundamental Valuation'!D9/Assumptions!$B$5-1 -> -0.65654995 | D9: blend 45/15/25/15
A10: TECHNICAL
A11: Trend / momentum | B11: Above all MAs | C11: RSI 78 | D11: overbought, all-time high
A12: MONTE CARLO — ILLUSTRATIVE ONLY (failed Step 0)
A13: CRPS skill vs random-walk | B13: -0.01 | C13: fails >0 | D13: no forecast published
A14: Illustrative T+60 median (EGP) | B14: 7.12 | D14: volatility map only
A15: EXPERT PANEL (closing appendix)
A16: Expert 1 — RNAV | B16: 3.1 | C16: =B16/Assumptions!$B$5-1 -> -0.55714286 | D16: anchor
A17: Expert 2 — normalized earnings | B17: 1.3 | C17: =B17/Assumptions!$B$5-1 -> -0.81428571 | D17: conservative on ops
A18: Expert 3 — scenario/policy | B18: 2.4 | C18: =B18/Assumptions!$B$5-1 -> -0.65714286 | D18: catalyst bet

Sheet Fundamental Valuation
A1: Fundamental valuation - four lenses, weighted
A3: Lens | B3: Base (EGP/sh) | C3: Weight | D3: Weighted (EGP/sh)
A4: RNAV (primary) | B4: =RNAV!B8/Assumptions!$B$6 -> 3.2770973 | C4: =Assumptions!$B$19 -> 0.45 | D4: =B4*C4 -> 1.4746938
A5: Going-concern DCF | B5: =DCF!B22 -> 0.54142725 | C5: =Assumptions!$B$20 -> 0.15 | D5: =B5*C5 -> 0.081214088
A6: Relative (price-to-book) | B6: ='Relative & Normalized'!C6 -> 2.6496071 | C6: =Assumptions!$B$21 -> 0.25 | D6: =B6*C6 -> 0.66240177
A7: Normalized earnings | B7: ='Relative & Normalized'!C12 -> 1.2389381 | C7: =Assumptions!$B$22 -> 0.15 | D7: =B7*C7 -> 0.18584071
A9: Weighted central fair value (EGP/sh) | B9: =B4*C4+B5*C5+B6*C6+B7*C7 -> 2.4041504 | D9: =SUM(D4:D7) -> 2.4041504
A10: vs spot | D10: =D9/Assumptions!$B$5-1 -> -0.65654995

Sheet Assumptions
A1: KABO — Assumptions (single input layer)
A2: Blue = hardcoded input · Black = formula · Green = cross-sheet link. Change an input here to reprice the whole model.
A4: Market & capital
A5: Spot price (EGP) | B5: 7 | C5: EGX close, 06 Jul 2026
A6: Shares outstanding (m) | B6: 565 | C6: mkt-cap-derived, flagged
A7: Book equity — net assets (EGP m) | B7: 1151.56 | C7: reviewed, ~Mar 2025
A8: Interest-bearing debt (EGP m) | B8: 559 | C8: D/E ~48.6%
A9: Cash & equivalents (EGP m) | B9: 189 | C9: estimate, flagged
A10: RNAV — primary lens
A11: Land & buildings re-mark, base (EGP m) | B11: 700 | C11: preparer estimate — the swing
A12: Brand value, off-B/S (EGP m) | B12: 50 | C12: conservative
A13: Working-capital realizability haircut (EGP m) | B13: 50
A14: Relative & normalized lenses
A15: Justified price-to-book (base) | B15: 1.3 | C15: vs distressed textile peers
A16: Mid-cycle net income (EGP m) | B16: 70 | C16: through-cycle, ex FX windfall
A17: Justified through-cycle P/E | B17: 10
A18: Lens weights (synthesis)
A19: RNAV weight | B19: 0.45
A20: Going-concern DCF weight | B20: 0.15
A21: Relative weight | B21: 0.25
A22: Normalized-earnings weight | B22: 0.15
A23: Cost of capital (Ke = rf + beta x ERP)
A24: Risk-free rate (EGP) | B24: 0.175
A25: Equity risk premium | B25: 0.06
A26: Beta (per-name, 0.8-1.3 band) | B26: 0.95
A27: Pre-tax cost of debt | B27: 0.2
A28: Tax rate | B28: 0.225
A29: Equity weight | B29: 0.88
A30: Debt weight | B30: 0.12
A31: Terminal growth (nominal EGP) | B31: 0.135
A32: WACC used for discounting (rounded) | B32: 0.22 | C32: component WACC rounds to ~22%
A33: Operating forecast (FY26-30, EGP m)
A34: (FY26-30 schedules →) | B34: 0.135 | C34: FY26e | D34: FY27e | E34: FY28e | F34: FY29e | G34: FY30e
A35: Revenue | C35: 1180 | D35: 1320 | E35: 1470 | F35: 1630 | G35: 1800
A36: D&A | C36: 45 | D36: 48 | E36: 51 | F36: 54 | G36: 57
A37: Capex | C37: 55 | D37: 58 | E37: 61 | F37: 64 | G37: 67
A38: Change in working capital | C38: 35 | D38: 30 | E38: 32 | F38: 34 | G38: 36
A39: Net finance cost (IS) | C39: 48 | D39: 44 | E39: 40 | F39: 36 | G39: 33
A40: Derived (formulas)
A41: Cost of equity Ke = rf + beta x ERP | B41: =B24+B26*B25 -> 0.232
...

Sheet RNAV
A1: RNAV — revalued net asset value (primary lens)
A3: Component (base) | B3: EGP m | C3: EGP/share
A4: Audited book equity (net assets) | B4: =Assumptions!$B$7 -> 1151.56 | C4: =B4/Assumptions!$B$6 -> 2.0381593
A5: + Land & buildings re-mark (estimate) | B5: =Assumptions!$B$11 -> 700 | C5: =B5/Assumptions!$B$6 -> 1.2389381
A6: + Brand value (off-B/S, estimate) | B6: =Assumptions!$B$12 -> 50 | C6: =B6/Assumptions!$B$6 -> 0.088495575
A7: - Working-capital realizability haircut | B7: =-Assumptions!$B$13 -> -50 | C7: =B7/Assumptions!$B$6 -> -0.088495575
A8: RNAV equity (base) | B8: =SUM(B4:B7) -> 1851.56 | C8: =B8/Assumptions!$B$6 -> 3.2770973
A10: Memo: price-implied land re-mark (EGP m) | B10: =Assumptions!$B$43-Assumptions!$B$7-Assumptions!$B$12+Assumptions!$B$13 -> 2803.44
A11: Memo: P/B at spot | B11: =Assumptions!$B$5/Assumptions!$B$45 -> 3.4344715

Sheet Segments
A1: Asset / segment scorecard
A3: Asset / segment | B3: Realizability | C3: Carrying vs market | D3: Role
A4: Land & buildings (Alexandria) | B4: Low — owner-occupied | C4: Likely well below market | D4: The entire swing
A5: Plant & machinery | B5: Low — specialised | C5: Near/below book | D5: Operating base
A6: Inventory & receivables | B6: Moderate | C6: Near book | D6: Working capital
A7: Brand (Kabo/Jil/Super Kabo) | B7: Low — not separable | C7: Off balance sheet | D7: Optionality

Sheet Relative & Normalized
A1: Relative (price-to-book) & normalized-earnings lenses
A3: Relative — price-to-book
A4: Basis | B4: Bear | C4: Base | D4: Bull
A5: Justified price-to-book | B5: 0.8 | C5: =Assumptions!$B$15 -> 1.3 | D5: 2
A6: Fair value = P/B x BVPS (EGP/sh) | B6: =B5*Assumptions!$B$45 -> 1.6305274 | C6: =C5*Assumptions!$B$45 -> 2.6496071 | D6: =D5*Assumptions!$B$45 -> 4.0763186
A8: Normalized earnings power
A9: Basis | B9: Bear | C9: Base | D9: Bull
A10: Mid-cycle net income (EGP m) | B10: 55 | C10: =Assumptions!$B$16 -> 70 | D10: 96
A11: Justified P/E | B11: 8 | C11: =Assumptions!$B$17 -> 10 | D11: 12
A12: Fair value = NI x P/E / shares (EGP/sh) | B12: =B10*B11/Assumptions!$B$6 -> 0.77876106 | C12: =C10*C11/Assumptions!$B$6 -> 1.2389381 | D12: =D10*D11/Assumptions!$B$6 -> 2.0389381

Sheet DCF
A1: Going-concern DCF — full waterfall
A2: Ke = rf + beta x ERP (shown on Assumptions). WACC used for discounting is rounded to ~22%.
A3: EGP m | B3: FY26e | C3: FY27e | D3: FY28e | E3: FY29e | F3: FY30e
A4: Revenue | B4: =Assumptions!$C$35 -> 1180 | C4: =Assumptions!$D$35 -> 1320 | D4: =Assumptions!$E$35 -> 1470 | E4: =Assumptions!$F$35 -> 1630 | F4: =Assumptions!$G$35 -> 1800
A5: EBITDA | B5: =B4*Assumptions!$B$34 -> 159.3 | C5: =C4*Assumptions!$B$34 -> 178.2 | D5: =D4*Assumptions!$B$34 -> 198.45 | E5: =E4*Assumptions!$B$34 -> 220.05 | F5: =F4*Assumptions!$B$34 -> 243
A6: - D&A | B6: =-Assumptions!$C$36 -> -45 | C6: =-Assumptions!$D$36 -> -48 | D6: =-Assumptions!$E$36 -> -51 | E6: =-Assumptions!$F$36 -> -54 | F6: =-Assumptions!$G$36 -> -57
A7: EBIT | B7: =B5+B6 -> 114.3 | C7: =C5+C6 -> 130.2 | D7: =D5+D6 -> 147.45 | E7: =E5+E6 -> 166.05 | F7: =F5+F6 -> 186
A8: NOPAT = EBIT x (1 - t) | B8: =B7*(1-Assumptions!$B$28) -> 88.5825 | C8: =C7*(1-Assumptions!$B$28) -> 100.905 | D8: =D7*(1-Assumptions!$B$28) -> 114.27375 | E8: =E7*(1-Assumptions!$B$28) -> 128.68875 | F8: =F7*(1-Assumptions!$B$28) -> 144.15
A9: + D&A | B9: =Assumptions!$C$36 -> 45 | C9: =Assumptions!$D$36 -> 48 | D9: =Assumptions!$E$36 -> 51 | E9: =Assumptions!$F$36 -> 54 | F9: =Assumptions!$G$36 -> 57
A10: - Capex | B10: =-Assumptions!$C$37 -> -55 | C10: =-Assumptions!$D$37 -> -58 | D10: =-Assumptions!$E$37 -> -61 | E10: =-Assumptions!$F$37 -> -64 | F10: =-Assumptions!$G$37 -> -67
A11: - Change in working capital | B11: =-Assumptions!$C$38 -> -35 | C11: =-Assumptions!$D$38 -> -30 | D11: =-Assumptions!$E$38 -> -32 | E11: =-Assumptions!$F$38 -> -34 | F11: =-Assumptions!$G$38 -> -36
A12: Free cash flow to firm | B12: =B8+B9+B10+B11 -> 43.5825 | C12: =C8+C9+C10+C11 -> 60.905 | D12: =D8+D9+D10+D11 -> 72.27375 | E12: =E8+E9+E10+E11 -> 84.68875 | F12: =F8+F9+F10+F11 -> 98.15
A13: Discount factor @ WACC | B13: =1/(1+Assumptions!$B$32)^1 -> 0.81967213 | C13: =1/(1+Assumptions!$B$32)^2 -> 0.6718624 | D13: =1/(1+Assumptions!$B$32)^3 -> 0.55070689 | E13: =1/(1+Assumptions!$B$32)^4 -> 0.45139909 | F13: =1/(1+Assumptions!$B$32)^5 -> 0.36999925
A14: PV of FCFF | B14: =B12*B13 -> 35.723361 | C14: =C12*C13 -> 40.91978 | D14: =D12*D13 -> 39.801652 | E14: =E12*E13 -> 38.228425 | F14: =F12*F13 -> 36.315427
A16: Sum PV of explicit FCFF (EGP m) | B16: =SUM(B14:F14) -> 190.98864
A17: Terminal value = FCFF5 x (1+g)/(WACC-g) | B17: =F12*(1+Assumptions!$B$31)/(Assumptions!$B$32-Assumptions!$B$31) -> 1310.5912
A18: PV of terminal value | B18: =B17*F13 -> 484.91776
A19: Enterprise value | B19: =B16+B18 -> 675.9064
A20: Terminal value as % of EV | B20: =B18/B19 -> 0.7174333
A21: - Net debt | B21: =-Assumptions!$B$44 -> -370
A22: Equity value per share (EGP) | B22: =(B19+B21)/Assumptions!$B$6 -> 0.54142725
A23: Equity value (EGP m) | B23: =B22*Assumptions!$B$6 -> 305.9064

Sheet Income Statement
A1: Income statement (consolidated, EGP m) — 3y history + 5y forecast
A2: History (FY23-25) = disclosure/reconstructed inputs; forecast (FY26-30) links to Assumptions.
A3: Line | B3: FY23 | C3: FY24 | D3: FY25e | E3: FY26e | F3: FY27e | G3: FY28e | H3: FY29e | I3: FY30e
A4: Revenue | B4: 593 | C4: 1020 | D4: 1050 | E4: =Assumptions!$C$35 -> 1180 | F4: =Assumptions!$D$35 -> 1320 | G4: =Assumptions!$E$35 -> 1470 | H4: =Assumptions!$F$35 -> 1630 | I4: =Assumptions!$G$35 -> 1800
A5: Gross profit | B5: 95 | C5: 194 | D5: 145 | E5: =E4*0.16 -> 188.8 | F5: =F4*0.16 -> 211.2 | G5: =G4*0.16 -> 235.2 | H5: =H4*0.16 -> 260.8 | I5: =I4*0.16 -> 288
A6: EBITDA | B6: 88 | C6: 180 | D6: 120 | E6: =E4*Assumptions!$B$34 -> 159.3 | F6: =F4*Assumptions!$B$34 -> 178.2 | G6: =G4*Assumptions!$B$34 -> 198.45 | H6: =H4*Assumptions!$B$34 -> 220.05 | I6: =I4*Assumptions!$B$34 -> 243
A7: - D&A | B7: -36 | C7: -40 | D7: -42 | E7: =-Assumptions!$C$36 -> -45 | F7: =-Assumptions!$D$36 -> -48 | G7: =-Assumptions!$E$36 -> -51 | H7: =-Assumptions!$F$36 -> -54 | I7: =-Assumptions!$G$36 -> -57
A8: EBIT | B8: 52 | C8: 140 | D8: 78 | E8: =E6+E7 -> 114.3 | F8: =F6+F7 -> 130.2 | G8: =G6+G7 -> 147.45 | H8: =H6+H7 -> 166.05 | I8: =I6+I7 -> 186
A9: Net finance cost | B9: -8 | C9: -18 | D9: -55 | E9: =-Assumptions!$C$39 -> -48 | F9: =-Assumptions!$D$39 -> -44 | G9: =-Assumptions!$E$39 -> -40 | H9: =-Assumptions!$F$39 -> -36 | I9: =-Assumptions!$G$39 -> -33
A10: Net FX / one-off | B10: 12 | C10: 45 | D10: -5 | E10: =0 -> 0 | F10: =0 -> 0 | G10: =0 -> 0 | H10: =0 -> 0 | I10: =0 -> 0
A11: PBT | B11: 56 | C11: 167 | D11: 18 | E11: =E8+E9+E10 -> 66.3 | F11: =F8+F9+F10 -> 86.2 | G11: =G8+G9+G10 -> 107.45 | H11: =H8+H9+H10 -> 130.05 | I11: =I8+I9+I10 -> 153
A12: Tax | B12: -4 | C12: -38 | D12: -2 | E12: =-E11*Assumptions!$B$28 -> -14.9175 | F12: =-F11*Assumptions!$B$28 -> -19.395 | G12: =-G11*Assumptions!$B$28 -> -24.17625 | H12: =-H11*Assumptions!$B$28 -> -29.26125 | I12: =-I11*Assumptions!$B$28 -> -34.425
A13: Net income (attributable) | B13: 52 | C13: 129 | D13: 16 | E13: =E11+E12 -> 51.3825 | F13: =F11+F12 -> 66.805 | G13: =G11+G12 -> 83.27375 | H13: =H11+H12 -> 100.78875 | I13: =I11+I12 -> 118.575

Sheet Balance Sheet
A1: Balance sheet (consolidated, EGP m) — 3y history + 5y forecast
A2: FY25 ties to reviewed accounts; PP&E rolls (capex-D&A), equity rolls (retained earnings, no dividend), other-liabilities is the balancing plug.
A3: Line | B3: FY23 | C3: FY24 | D3: FY25 | E3: FY26e | F3: FY27e | G3: FY28e | H3: FY29e | I3: FY30e
A4: Property, plant & equipment (net) | B4: 600 | C4: 720 | D4: 780 | E4: =D4+Assumptions!$C$37-Assumptions!$C$36 -> 790 | F4: =E4+Assumptions!$D$37-Assumptions!$D$36 -> 800 | G4: =F4+Assumptions!$E$37-Assumptions!$E$36 -> 810 | H4: =G4+Assumptions!$F$37-Assumptions!$F$36 -> 820 | I4: =H4+Assumptions!$G$37-Assumptions!$G$36 -> 830
A5: Inventory | B5: 350 | C5: 480 | D5: 500 | E5: 540 | F5: 585 | G5: 630 | H5: 680 | I5: 730
A6: Trade & other receivables | B6: 250 | C6: 340 | D6: 360 | E6: 390 | F6: 425 | G6: 460 | H6: 500 | I6: 540
A7: Cash & equivalents | B7: 90 | C7: 140 | D7: 150 | E7: ='Cash Flow'!E12 -> 137.3825 | F7: ='Cash Flow'!F12 -> 144.1875 | G7: ='Cash Flow'!G12 -> 165.46125 | H7: ='Cash Flow'!H12 -> 202.25 | I7: ='Cash Flow'!I12 -> 254.825
A8: Other assets | B8: 60 | C8: 80 | D8: 44 | E8: 45 | F8: 46 | G8: 47 | H8: 48 | I8: 49
A9: Total assets | B9: =SUM(B4:B8) -> 1350 | C9: =SUM(C4:C8) -> 1760 | D9: =SUM(D4:D8) -> 1834 | E9: =SUM(E4:E8) -> 1902.3825 | F9: =SUM(F4:F8) -> 2000.1875 | G9: =SUM(G4:G8) -> 2112.4612 | H9: =SUM(H4:H8) -> 2250.25 | I9: =SUM(I4:I8) -> 2403.825
A10: Interest-bearing debt | B10: 380 | C10: 520 | D10: 559 | E10: 540 | F10: 520 | G10: 500 | H10: 480 | I10: 460
A11: Total equity (attributable) | B11: 850 | C11: 1090 | D11: 1152 | E11: =D11+'Income Statement'!E13 -> 1203.3825 | F11: =E11+'Income Statement'!F13 -> 1270.1875 | G11: =F11+'Income Statement'!G13 -> 1353.4613 | H11: =G11+'Income Statement'!H13 -> 1454.25 | I11: =H11+'Income Statement'!I13 -> 1572.825
A12: Payables & other liabilities | B12: =B9-B10-B11 -> 120 | C12: =C9-C10-C11 -> 150 | D12: =D9-D10-D11 -> 123 | E12: =E9-E10-E11 -> 159 | F12: =F9-F10-F11 -> 210 | G12: =G9-G10-G11 -> 259 | H12: =H9-H10-H11 -> 316 | I12: =I9-I10-I11 -> 371
A13: Total liabilities | B13: =B10+B12 -> 500 | C13: =C10+C12 -> 670 | D13: =D10+D12 -> 682 | E13: =E10+E12 -> 699 | F13: =F10+F12 -> 730 | G13: =G10+G12 -> 759 | H13: =H10+H12 -> 796 | I13: =I10+I12 -> 831
A14: Check: assets - liab - equity | B14: =B9-B13-B11 -> 0 | C14: =C9-C13-C11 -> 0 | D14: =D9-D13-D11 -> 0 | E14: =E9-E13-E11 -> 0 | F14: =F9-F13-F11 -> 0 | G14: =G9-G13-G11 -> 0 | H14: =H9-H13-H11 -> 0 | I14: =I9-I13-I11 -> 0

Sheet Cash Flow
A1: Cash flow (consolidated, EGP m) — 3y history + 5y forecast
A3: Line | B3: FY23 | C3: FY24 | D3: FY25 | E3: FY26e | F3: FY27e | G3: FY28e | H3: FY29e | I3: FY30e
A4: Net income | B4: 52 | C4: 129 | D4: 16 | E4: ='Income Statement'!E13 -> 51.3825 | F4: ='Income Statement'!F13 -> 66.805 | G4: ='Income Statement'!G13 -> 83.27375 | H4: ='Income Statement'!H13 -> 100.78875 | I4: ='Income Statement'!I13 -> 118.575
A5: + D&A | B5: 36 | C5: 40 | D5: 42 | E5: =Assumptions!$C$36 -> 45 | F5: =Assumptions!$D$36 -> 48 | G5: =Assumptions!$E$36 -> 51 | H5: =Assumptions!$F$36 -> 54 | I5: =Assumptions!$G$36 -> 57
A6: - Change in working capital | B6: -40 | C6: -90 | D6: -35 | E6: =-Assumptions!$C$38 -> -35 | F6: =-Assumptions!$D$38 -> -30 | G6: =-Assumptions!$E$38 -> -32 | H6: =-Assumptions!$F$38 -> -34 | I6: =-Assumptions!$G$38 -> -36
A7: Operating cash flow | B7: =B4+B5+B6 -> 48 | C7: =C4+C5+C6 -> 79 | D7: =D4+D5+D6 -> 23 | E7: =E4+E5+E6 -> 61.3825 | F7: =F4+F5+F6 -> 84.805 | G7: =G4+G5+G6 -> 102.27375 | H7: =H4+H5+H6 -> 120.78875 | I7: =I4+I5+I6 -> 139.575
A8: - Capex | B8: -45 | C8: -60 | D8: -55 | E8: =-Assumptions!$C$37 -> -55 | F8: =-Assumptions!$D$37 -> -58 | G8: =-Assumptions!$E$37 -> -61 | H8: =-Assumptions!$F$37 -> -64 | I8: =-Assumptions!$G$37 -> -67
A9: Free cash flow | B9: =B7+B8 -> 3 | C9: =C7+C8 -> 19 | D9: =D7+D8 -> -32 | E9: =E7+E8 -> 6.3825 | F9: =F7+F8 -> 26.805 | G9: =G7+G8 -> 41.27375 | H9: =H7+H8 -> 56.78875 | I9: =I7+I8 -> 72.575
A10: Change in debt / financing | B10: 10 | C10: 31 | D10: 41 | E10: ='Balance Sheet'!E10-'Balance Sheet'!D10 -> -19 | F10: ='Balance Sheet'!F10-'Balance Sheet'!E10 -> -20 | G10: ='Balance Sheet'!G10-'Balance Sheet'!F10 -> -20 | H10: ='Balance Sheet'!H10-'Balance Sheet'!G10 -> -20 | I10: ='Balance Sheet'!I10-'Balance Sheet'!H10 -> -20
A11: Net change in cash | B11: =B9+B10 -> 13 | C11: =C9+C10 -> 50 | D11: =D9+D10 -> 9 | E11: =E9+E10 -> -12.6175 | F11: =F9+F10 -> 6.805 | G11: =G9+G10 -> 21.27375 | H11: =H9+H10 -> 36.78875 | I11: =I9+I10 -> 52.575
A12: Ending cash | B12: 90 | C12: 140 | D12: 150 | E12: =D12+E11 -> 137.3825 | F12: =E12+F11 -> 144.1875 | G12: =F12+G11 -> 165.46125 | H12: =G12+H11 -> 202.25 | I12: =H12+I11 -> 254.825

Sheet Summary Financials
A1: Summary financials (links to statement sheets)
A3: Line | B3: FY23 | C3: FY24 | D3: FY25 | E3: FY26e | F3: FY27e | G3: FY28e | H3: FY29e | I3: FY30e
A4: Revenue | B4: ='Income Statement'!B4 -> 593 | C4: ='Income Statement'!C4 -> 1020 | D4: ='Income Statement'!D4 -> 1050 | E4: ='Income Statement'!E4 -> 1180 | F4: ='Income Statement'!F4 -> 1320 | G4: ='Income Statement'!G4 -> 1470 | H4: ='Income Statement'!H4 -> 1630 | I4: ='Income Statement'!I4 -> 1800
A5: EBITDA | B5: ='Income Statement'!B6 -> 88 | C5: ='Income Statement'!C6 -> 180 | D5: ='Income Statement'!D6 -> 120 | E5: ='Income Statement'!E6 -> 159.3 | F5: ='Income Statement'!F6 -> 178.2 | G5: ='Income Statement'!G6 -> 198.45 | H5: ='Income Statement'!H6 -> 220.05 | I5: ='Income Statement'!I6 -> 243
A6: EBIT | B6: ='Income Statement'!B8 -> 52 | C6: ='Income Statement'!C8 -> 140 | D6: ='Income Statement'!D8 -> 78 | E6: ='Income Statement'!E8 -> 114.3 | F6: ='Income Statement'!F8 -> 130.2 | G6: ='Income Statement'!G8 -> 147.45 | H6: ='Income Statement'!H8 -> 166.05 | I6: ='Income Statement'!I8 -> 186
A7: Net income | B7: ='Income Statement'!B13 -> 52 | C7: ='Income Statement'!C13 -> 129 | D7: ='Income Statement'!D13 -> 16 | E7: ='Income Statement'!E13 -> 51.3825 | F7: ='Income Statement'!F13 -> 66.805 | G7: ='Income Statement'!G13 -> 83.27375 | H7: ='Income Statement'!H13 -> 100.78875 | I7: ='Income Statement'!I13 -> 118.575
A8: Total assets | B8: ='Balance Sheet'!B9 -> 1350 | C8: ='Balance Sheet'!C9 -> 1760 | D8: ='Balance Sheet'!D9 -> 1834 | E8: ='Balance Sheet'!E9 -> 1902.3825 | F8: ='Balance Sheet'!F9 -> 2000.1875 | G8: ='Balance Sheet'!G9 -> 2112.4612 | H8: ='Balance Sheet'!H9 -> 2250.25 | I8: ='Balance Sheet'!I9 -> 2403.825
A9: Total equity | B9: ='Balance Sheet'!B11 -> 850 | C9: ='Balance Sheet'!C11 -> 1090 | D9: ='Balance Sheet'!D11 -> 1152 | E9: ='Balance Sheet'!E11 -> 1203.3825 | F9: ='Balance Sheet'!F11 -> 1270.1875 | G9: ='Balance Sheet'!G11 -> 1353.4613 | H9: ='Balance Sheet'!H11 -> 1454.25 | I9: ='Balance Sheet'!I11 -> 1572.825
A10: Net debt (debt - cash) | B10: ='Balance Sheet'!B10 -> 380 | C10: ='Balance Sheet'!C10 -> 520 | D10: ='Balance Sheet'!D10 -> 559 | E10: ='Balance Sheet'!E10 -> 540 | F10: ='Balance Sheet'!F10 -> 520 | G10: ='Balance Sheet'!G10 -> 500 | H10: ='Balance Sheet'!H10 -> 480 | I10: ='Balance Sheet'!I10 -> 460
A11: Free cash flow | B11: ='Cash Flow'!B9 -> 3 | C11: ='Cash Flow'!C9 -> 19 | D11: ='Cash Flow'!D9 -> -32 | E11: ='Cash Flow'!E9 -> 6.3825 | F11: ='Cash Flow'!F9 -> 26.805 | G11: ='Cash Flow'!G9 -> 41.27375 | H11: ='Cash Flow'!H9 -> 56.78875 | I11: ='Cash Flow'!I9 -> 72.575
A13: EBITDA margin | B13: =B5/B4 -> 0.14839798 | C13: =C5/C4 -> 0.17647059 | D13: =D5/D4 -> 0.11428571 | E13: =E5/E4 -> 0.135 | F13: =F5/F4 -> 0.135 | G13: =G5/G4 -> 0.135 | H13: =H5/H4 -> 0.135 | I13: =I5/I4 -> 0.135
A14: Net margin | B14: =B7/B4 -> 0.087689713 | C14: =C7/C4 -> 0.12647059 | D14: =D7/D4 -> 0.015238095 | E14: =E7/E4 -> 0.043544492 | F14: =F7/F4 -> 0.050609848 | G14: =G7/G4 -> 0.05664881 | H14: =H7/H4 -> 0.061833589 | I14: =I7/I4 -> 0.065875

Sheet Monte Carlo
A1: Monte Carlo — ILLUSTRATIVE ONLY (failed Step 0; no forecast published)
A2: CRPS skill -0.010 vs a zero-drift random-walk cone (best config -0.007); interval (Winkler) skill -0.055; PIT mean 0.573. Under the house rule a forecast
A3: is published only if it beats the random-walk cone on CRPS with a roughly uniform PIT. KABO fails, so the numbers below describe dispersion only.
A5: Probability read (illustrative, T+60)
A6: P(price above spot) | B6: 53%
A7: P(+10%) vs P(-10%) · odds | B7: 36% vs 29% · 1.22x
A8: Median level · % move | B8: EGP 7.12 · +1.7%
A9: 50% band (25th-75th) · % of spot | B9: EGP 6.12-8.28 · ~31%
A10: Touch +10% / -10% by T+60 | B10: 63% / 55%
A12: Percentile map (illustrative, EGP/share)
A13: Horizon | B13: p5 | C13: p25 | D13: p50 | E13: p75 | F13: p95
A14: T+20 sessions | B14: 5.58 | C14: 6.46 | D14: 7.03 | E14: 7.67 | F14: 8.92
A15: T+60 sessions | B15: 4.79 | C15: 6.12 | D15: 7.12 | E15: 8.28 | F15: 10.68
A17: These figures summarise the same 50,000 illustrative paths; they are presentation-only and are NOT a probability forecast for KABO.

Sheet Sensitivity
A1: Sensitivity
A3: RNAV per share — land re-mark (rows) x applied discount (cols)
A4: Land re-mark (EGP m) / discount | B4: Par (0%) | C4: -20% | D4: -40%
A5: 0 | B5: =(Assumptions!$B$7+0+Assumptions!$B$12-Assumptions!$B$13)/Assumptions!$B$6 -> 2.0381593 | C5: =(Assumptions!$B$7+0+Assumptions!$B$12-Assumptions!$B$13)/Assumptions!$B$6*0.8 -> 1.6305274 | D5: =(Assumptions!$B$7+0+Assumptions!$B$12-Assumptions!$B$13)/Assumptions!$B$6*0.6 -> 1.2228956
A6: 700 (base) | B6: =(Assumptions!$B$7+700+Assumptions!$B$12-Assumptions!$B$13)/Assumptions!$B$6 -> 3.2770973 | C6: =(Assumptions!$B$7+700+Assumptions!$B$12-Assumptions!$B$13)/Assumptions!$B$6*0.8 -> 2.6216779 | D6: =(Assumptions!$B$7+700+Assumptions!$B$12-Assumptions!$B$13)/Assumptions!$B$6*0.6 -> 1.9662584
A7: 1,400 | B7: =(Assumptions!$B$7+1400+Assumptions!$B$12-Assumptions!$B$13)/Assumptions!$B$6 -> 4.5160354 | C7: =(Assumptions!$B$7+1400+Assumptions!$B$12-Assumptions!$B$13)/Assumptions!$B$6*0.8 -> 3.6128283 | D7: =(Assumptions!$B$7+1400+Assumptions!$B$12-Assumptions!$B$13)/Assumptions!$B$6*0.6 -> 2.7096212
A8: 2,100 | B8: =(Assumptions!$B$7+2100+Assumptions!$B$12-Assumptions!$B$13)/Assumptions!$B$6 -> 5.7549735 | C8: =(Assumptions!$B$7+2100+Assumptions!$B$12-Assumptions!$B$13)/Assumptions!$B$6*0.8 -> 4.6039788 | D8: =(Assumptions!$B$7+2100+Assumptions!$B$12-Assumptions!$B$13)/Assumptions!$B$6*0.6 -> 3.4529841
A9: 2,800 (~price-implied) | B9: =(Assumptions!$B$7+2800+Assumptions!$B$12-Assumptions!$B$13)/Assumptions!$B$6 -> 6.9939115 | C9: =(Assumptions!$B$7+2800+Assumptions!$B$12-Assumptions!$B$13)/Assumptions!$B$6*0.8 -> 5.5951292 | D9: =(Assumptions!$B$7+2800+Assumptions!$B$12-Assumptions!$B$13)/Assumptions!$B$6*0.6 -> 4.1963469
A11: Going-concern DCF per share — WACC (rows) x terminal g (cols)
A12: WACC / terminal g | B12: 12.5% | C12: 13.5% | D12: 14.5%
A13: 20% | B13: =((DCF!B12/(1+0.2)^1+DCF!C12/(1+0.2)^2+DCF!D12/(1+0.2)^3+DCF!E12/(1+0.2)^4+DCF!F12/(1+0.2)^5)+((DCF!F12*(1+0.125)/(0.2-0.125))/(1+0.2)^5)-Assumptions!$B$44)/Assumptions!$B$6 -> 0.74759102 | C13: =((DCF!B12/(1+0.2)^1+DCF!C12/(1+0.2)^2+DCF!D12/(1+0.2)^3+DCF!E12/(1+0.2)^4+DCF!F12/(1+0.2)^5)+((DCF!F12*(1+0.135)/(0.2-0.135))/(1+0.2)^5)-Assumptions!$B$44)/Assumptions!$B$6 -> 0.91943814 | D13: =((DCF!B12/(1+0.2)^1+DCF!C12/(1+0.2)^2+DCF!D12/(1+0.2)^3+DCF!E12/(1+0.2)^4+DCF!F12/(1+0.2)^5)+((DCF!F12*(1+0.145)/(0.2-0.145))/(1+0.2)^5)-Assumptions!$B$44)/Assumptions!$B$6 -> 1.1537751
A14: 22% | B14: =((DCF!B12/(1+0.22)^1+DCF!C12/(1+0.22)^2+DCF!D12/(1+0.22)^3+DCF!E12/(1+0.22)^4+DCF!F12/(1+0.22)^5)+((DCF!F12*(1+0.125)/(0.22-0.125))/(1+0.22)^5)-Assumptions!$B$44)/Assumptions!$B$6 -> 0.44431814 | C14: =((DCF!B12/(1+0.22)^1+DCF!C12/(1+0.22)^2+DCF!D12/(1+0.22)^3+DCF!E12/(1+0.22)^4+DCF!F12/(1+0.22)^5)+((DCF!F12*(1+0.135)/(0.22-0.135))/(1+0.22)^5)-Assumptions!$B$44)/Assumptions!$B$6 -> 0.54142725 | D14: =((DCF!B12/(1+0.22)^1+DCF!C12/(1+0.22)^2+DCF!D12/(1+0.22)^3+DCF!E12/(1+0.22)^4+DCF!F12/(1+0.22)^5)+((DCF!F12*(1+0.145)/(0.22-0.145))/(1+0.22)^5)-Assumptions!$B$44)/Assumptions!$B$6 -> 0.66443214
A15: 24% | B15: =((DCF!B12/(1+0.24)^1+DCF!C12/(1+0.24)^2+DCF!D12/(1+0.24)^3+DCF!E12/(1+0.24)^4+DCF!F12/(1+0.24)^5)+((DCF!F12*(1+0.125)/(0.24-0.125))/(1+0.24)^5)-Assumptions!$B$44)/Assumptions!$B$6 -> 0.2468746 | C15: =((DCF!B12/(1+0.24)^1+DCF!C12/(1+0.24)^2+DCF!D12/(1+0.24)^3+DCF!E12/(1+0.24)^4+DCF!F12/(1+0.24)^5)+((DCF!F12*(1+0.135)/(0.24-0.135))/(1+0.24)^5)-Assumptions!$B$44)/Assumptions!$B$6 -> 0.30772563 | D15: =((DCF!B12/(1+0.24)^1+DCF!C12/(1+0.24)^2+DCF!D12/(1+0.24)^3+DCF!E12/(1+0.24)^4+DCF!F12/(1+0.24)^5)+((DCF!F12*(1+0.145)/(0.24-0.145))/(1+0.24)^5)-Assumptions!$B$44)/Assumptions!$B$6 -> 0.38138741

Sheet Per-Share & Ratios
A1: Per-share & ratios (standardized dashboard)
A3: Metric | B3: FY23 | C3: FY24 | D3: FY25 | E3: FY26e | F3: FY27e | G3: FY28e | H3: FY29e | I3: FY30e
A4: EPS (EGP) | B4: ='Income Statement'!B13/Assumptions!$B$6 -> 0.092035398 | C4: ='Income Statement'!C13/Assumptions!$B$6 -> 0.22831858 | D4: ='Income Statement'!D13/Assumptions!$B$6 -> 0.028318584 | E4: ='Income Statement'!E13/Assumptions!$B$6 -> 0.090942478 | F4: ='Income Statement'!F13/Assumptions!$B$6 -> 0.11823894 | G4: ='Income Statement'!G13/Assumptions!$B$6 -> 0.14738717 | H4: ='Income Statement'!H13/Assumptions!$B$6 -> 0.17838717 | I4: ='Income Statement'!I13/Assumptions!$B$6 -> 0.20986726
A5: BVPS (EGP) | B5: ='Balance Sheet'!B11/Assumptions!$B$6 -> 1.5044248 | C5: ='Balance Sheet'!C11/Assumptions!$B$6 -> 1.9292035 | D5: ='Balance Sheet'!D11/Assumptions!$B$6 -> 2.0389381 | E5: ='Balance Sheet'!E11/Assumptions!$B$6 -> 2.1298805 | F5: ='Balance Sheet'!F11/Assumptions!$B$6 -> 2.2481195 | G5: ='Balance Sheet'!G11/Assumptions!$B$6 -> 2.3955066 | H5: ='Balance Sheet'!H11/Assumptions!$B$6 -> 2.5738938 | I5: ='Balance Sheet'!I11/Assumptions!$B$6 -> 2.7837611
A6: DPS (EGP) | B6: 0 | C6: 0 | D6: 0 | E6: 0 | F6: 0 | G6: 0 | H6: 0 | I6: 0
A7: P/E (x, at spot) | B7: =Assumptions!$B$5/B4 -> 76.057692 | C7: =Assumptions!$B$5/C4 -> 30.658915 | D7: =Assumptions!$B$5/D4 -> 247.1875 | E7: =Assumptions!$B$5/E4 -> 76.971732 | F7: =Assumptions!$B$5/F4 -> 59.202156 | G7: =Assumptions!$B$5/G4 -> 47.493958 | H7: =Assumptions!$B$5/H4 -> 39.240491 | I7: =Assumptions!$B$5/I4 -> 33.354417
A8: P/B (x, at spot) | B8: =Assumptions!$B$5/B5 -> 4.6529412 | C8: =Assumptions!$B$5/C5 -> 3.6284404 | D8: =Assumptions!$B$5/D5 -> 3.4331597 | E8: =Assumptions!$B$5/E5 -> 3.2865693 | F8: =Assumptions!$B$5/F5 -> 3.1137135 | G8: =Assumptions!$B$5/G5 -> 2.9221376 | H8: =Assumptions!$B$5/H5 -> 2.7196149 | I8: =Assumptions!$B$5/I5 -> 2.5145836
A9: EV/EBITDA (x) | B9: =(Assumptions!$B$43+'Balance Sheet'!B10-'Balance Sheet'!B7)/'Income Statement'!B6 -> 48.238636 | C9: =(Assumptions!$B$43+'Balance Sheet'!C10-'Balance Sheet'!C7)/'Income Statement'!C6 -> 24.083333 | D9: =(Assumptions!$B$43+'Balance Sheet'!D10-'Balance Sheet'!D7)/'Income Statement'!D6 -> 36.366667 | E9: =(Assumptions!$B$43+'Balance Sheet'!E10-'Balance Sheet'!E7)/'Income Statement'!E6 -> 27.354787 | F9: =(Assumptions!$B$43+'Balance Sheet'!F10-'Balance Sheet'!F7)/'Income Statement'!F6 -> 24.3031 | G9: =(Assumptions!$B$43+'Balance Sheet'!G10-'Balance Sheet'!G7)/'Income Statement'!G6 -> 21.615212 | H9: =(Assumptions!$B$43+'Balance Sheet'!H10-'Balance Sheet'!H7)/'Income Statement'!H6 -> 19.235401 | I9: =(Assumptions!$B$43+'Balance Sheet'!I10-'Balance Sheet'!I7)/'Income Statement'!I6 -> 17.120062
A10: Net margin | B10: ='Income Statement'!B13/'Income Statement'!B4 -> 0.087689713 | C10: ='Income Statement'!C13/'Income Statement'!C4 -> 0.12647059 | D10: ='Income Statement'!D13/'Income Statement'!D4 -> 0.015238095 | E10: ='Income Statement'!E13/'Income Statement'!E4 -> 0.043544492 | F10: ='Income Statement'!F13/'Income Statement'!F4 -> 0.050609848 | G10: ='Income Statement'!G13/'Income Statement'!G4 -> 0.05664881 | H10: ='Income Statement'!H13/'Income Statement'!H4 -> 0.061833589 | I10: ='Income Statement'!I13/'Income Statement'!I4 -> 0.065875
A11: ROE | B11: ='Income Statement'!B13/'Balance Sheet'!B11 -> 0.061176471 | C11: ='Income Statement'!C13/'Balance Sheet'!C11 -> 0.11834862 | D11: ='Income Statement'!D13/'Balance Sheet'!D11 -> 0.013888889 | E11: ='Income Statement'!E13/'Balance Sheet'!E11 -> 0.042698394 | F11: ='Income Statement'!F13/'Balance Sheet'!F11 -> 0.052594597 | G11: ='Income Statement'!G13/'Balance Sheet'!G11 -> 0.061526512 | H11: ='Income Statement'!H13/'Balance Sheet'!H11 -> 0.069306343 | I11: ='Income Statement'!I13/'Balance Sheet'!I11 -> 0.075389824
A12: Net debt / EBITDA (x) | B12: =('Balance Sheet'!B10-'Balance Sheet'!B7)/'Income Statement'!B6 -> 3.2954545 | C12: =('Balance Sheet'!C10-'Balance Sheet'!C7)/'Income Statement'!C6 -> 2.1111111 | D12: =('Balance Sheet'!D10-'Balance Sheet'!D7)/'Income Statement'!D6 -> 3.4083333 | E12: =('Balance Sheet'!E10-'Balance Sheet'!E7)/'Income Statement'!E6 -> 2.5274168 | F12: =('Balance Sheet'!F10-'Balance Sheet'!F7)/'Income Statement'!F6 -> 2.1089366 | G12: =('Balance Sheet'!G10-'Balance Sheet'!G7)/'Income Statement'!G6 -> 1.6857584 | H12: =('Balance Sheet'!H10-'Balance Sheet'!H7)/'Income Statement'!H6 -> 1.2622131 | I12: =('Balance Sheet'!I10-'Balance Sheet'!I7)/'Income Statement'!I6 -> 0.84434156
A13: FCF yield (at mkt cap) | B13: ='Cash Flow'!B9/Assumptions!$B$43 -> 0.0007585335 | C13: ='Cash Flow'!C9/Assumptions!$B$43 -> 0.0048040455 | D13: ='Cash Flow'!D9/Assumptions!$B$43 -> -0.008091024 | E13: ='Cash Flow'!E9/Assumptions!$B$43 -> 0.00161378 | F13: ='Cash Flow'!F9/Assumptions!$B$43 -> 0.0067774968 | G13: ='Cash Flow'!G9/Assumptions!$B$43 -> 0.010435841 | H13: ='Cash Flow'!H9/Assumptions!$B$43 -> 0.014358723 | I13: ='Cash Flow'!I9/Assumptions!$B$43 -> 0.01835019

Sheet Peer & Sector
A1: Peer set & sector
A3: Peer / comparator | B3: Market | C3: Note
A4: Oriental Weavers (ORWE) | B4: EGX | C4: Carpets; scaled exporter; ~1.0-1.6x book; dividend-paying
A5: Arab Cotton Ginning (ACGC) | B5: EGX | C5: Cotton processing; asset-heavy; cyclical
A6: Nile Cotton Ginning / spinning | B6: EGX | C6: Legacy textile; asset value vs weak earnings
A7: Distressed EM knitwear / apparel | B7: Global | C7: Typically 0.5-1.2x book on thin margins
