Workbook

Sheet READ FIRST
A1: Testahil — Orascom Investment Holding (EGX: OIH) · Companion model
A2: Companion model · Independent Valuation Study — Educational Analysis · Not investment advice · 03 July 2026
A4: What this workbook is. A transparent companion to the OIH valuation study. Every blue cell is an input; every black cell is a formula; green cells link across sheets. Change one input (the holdco discount, the OPE platform value, EGP/USD, any single mark) and the whole model reprices.
A6: What it is not. It is not investment advice, a recommendation, or a price target. Figures are educational estimates presented as ranges. The preparer is not licensed by the Egyptian FRA.
A8: Entity note. OIH is the Sawiris-family holding company (parent: Orascom TMT Investments S.a r.l.). Its economics are a holdco NAV story, not an earnings story: the crown asset is the Giza Pyramids plateau visitor-services concession (Orascom Pyramids Entertainment + Sound & Light), beside ~US$114m of cash trapped in North Korea (carried at 50% ECL), the 60% Koryolink associate (profits recognized then fully impaired), the Lighthouse Energy renewables fund, and an interest-free EUR/USD shareholder loan owed back to Koryolink.
A10: Currency. EGP millions unless stated. Audited historicals are the IFRS consolidated statements (KPMG Luxembourg, qualified opinion on Koryolink, DPRK cash and OTL Lebanon), presented in US$ '000 and converted here at the disclosed closing/average rates; FY2024 line items not separately disclosed are estimated to balance to disclosed totals (EAS total assets EGP 9,508m). FY2025E-FY2029E are Testahil estimates.
A12: Sheets: Summary · Fundamental Valuation · Assumptions · Holdco NAV · Segments · Relative & Normalized · DCF · Income Statement · Balance Sheet · Cash Flow · Summary Financials · Monte Carlo · Sensitivity · Per-Share & Ratios · Peer & Sector

Sheet Summary
A1: Valuation summary — Orascom Investment Holding (EGX: OIH)
A2: Four-lens fair value vs spot. Base linked; bear/bull are scenario inputs.
B3: Bear | C3: Base | D3: Bull | E3: Weight
A4: Holdco NAV | B4: 0.55 | C4: ='Holdco NAV'!C18 -> 0.8139389 | D4: 1.8 | E4: =Assumptions!$B$32 -> 0.45
A5: Consolidated DCF | B5: 0.45 | C5: =DCF!B17 -> 0.47797657 | D5: 1.55 | E5: =Assumptions!$B$33 -> 0.2
A6: Relative (P/NAV) | B6: 0.5 | C6: ='Relative & Normalized'!C3 -> 0.71818138 | D6: 1.35 | E6: =Assumptions!$B$34 -> 0.15
A7: Normalized earnings | B7: 0.6 | C7: ='Relative & Normalized'!C5 -> 1.0294165 | D7: 1.9 | E7: =Assumptions!$B$35 -> 0.2
A8: Weighted central | B8: =SUMPRODUCT(B4:B7,$E4:$E7) -> 0.5325 | C8: =SUMPRODUCT(C4:C7,$E4:$E7) -> 0.77547833 | D8: =SUMPRODUCT(D4:D7,$E4:$E7) -> 1.7025
A10: Spot price (EGP) | C10: =Assumptions!$B$4 -> 1.41
A11: Upside to central base | C11: =C8/C10-1 -> -0.45001537
A13: Read: the market trades OIH above its accountable base NAV — the premium is the price of the Pyramids ramp, DPRK optionality and the Sawiris platform. The swing input is the OPE platform value; the tail is the DPRK cash / Koryolink-loan pair.

Sheet Fundamental Valuation
A1: Fundamental valuation — the lenses at a glance
A3: Lens | B3: Fair value (EGP/sh) | C3: Basis | D3: Weight
A4: Holdco NAV (primary) | B4: ='Holdco NAV'!C18 -> 0.8139389 | C4: Asset-by-asset marks, DCF of OPE, less 15% holdco discount | D4: =Assumptions!$B$32 -> 0.45
A5: Consolidated DCF | B5: =DCF!B17 -> 0.47797657 | C5: FCFF of operating business + financial assets at marks | D5: =Assumptions!$B$33 -> 0.2
A6: Relative (P/NAV) | B6: ='Relative & Normalized'!C3 -> 0.71818138 | C6: Peer holdco P/NAV on pre-discount NAV | D6: =Assumptions!$B$34 -> 0.15
A7: Normalized earnings | B7: ='Relative & Normalized'!C5 -> 1.0294165 | C7: Mid-cycle earnings power × justified P/E | D7: =Assumptions!$B$35 -> 0.2
A8: Weighted central (base) | B8: =SUMPRODUCT(B4:B7,D4:D7) -> 0.77547833
A10: Two clocks: this weighted figure is the risk-adjusted ~12-month anchor; the DPRK-cash-recovered, OPE-at-maturity NAV is a multi-year ceiling and is never placed beside near-term figures. The Monte Carlo percentiles are the only genuine 3-month numbers in this workbook.

Sheet Assumptions
A1: Assumptions — the single input layer
A2: All blue cells are inputs. Every other sheet links here.
A3: ANCHORS
A4: Spot price (EGP/share) | B4: 1.41 | H4: Close 01-Jul-2026, uploaded OHLC (investing.com)
A5: Shares outstanding (m) | B5: 5245.69 | H5: Mubasher/EGX: 5,245,690,620 shares, paid-in EGP 577.0m
A6: EGP/USD | B6: 49.09 | H6: Mid-market 02-Jul-2026 (investing.com / Xe / Yahoo)
A7: WACC — EGP operating business | B7: 0.2 | H7: CBE corridor ~19-20%, CPI 14.9% Apr-26; EGP cost of equity build-up
A8: Terminal growth (EGP, nominal) | B8: 0.06 | H8: Long-run EGP nominal growth, below CPI
A9: Tax rate | B9: 0.225 | H9: Egypt corporate rate 22.5%
A11: HOLDCO NAV — base marks (US$ m unless noted)
A12: Cash & equivalents (ex-DPRK) | B12: 45.7 | H12: FY24 IFRS FS (KPMG, 23-Dec-25): cash 45,714k
A13: DPRK cash — gross | B13: 113.9 | H13: FY24 IFRS: $106m at Foreign Trade Bank of DPRK + $8m in hand
A14: DPRK cash — expected credit loss | B14: 0.5 | H14: Board ECL 50%; KPMG qualified (unable to verify recoverability)
A15: Koryolink 60% associate — carrying | B15: 12 | H15: FY24 IFRS: equity-accounted, profits recognized then fully impaired
A16: Lighthouse Energy Fund (FVTPL, L3) | B16: 28.5 | H16: FY24 IFRS: 28,522k; DCF marks, disc. 7.5-13.5%
A17: Brazil investment property (Sao Paulo) | B17: 8 | H17: FY22 IFRS carrying 8,166k; discontinued segment — est.
A18: Trade receivables + other assets, net of payables/provisions/tax | B18: 0 | H18: FY24 IFRS: TR 4.3 + other 12.9 + inv 0.1 - payables 4.9 - provisions ~7.3 - tax ~2.3 - other ~2.8 (est.)
A19: Loan from Koryolink (interest-free, EUR/USD) | B19: -90.5 | H19: FY24 IFRS: carrying 90,499k ($86m Aug-22 + EUR30m Dec-24); undisc. ~$116m
A20: Bank borrowings | B20: -8.6 | H20: FY24 IFRS: liabilities to banks 8,585k (saib facilities at OPE)
A21: Lease liabilities | B21: -8.8 | H21: FY24 IFRS: 8,806k
A22: OPE + Sound & Light platform (EGP m) | B22: 2900 | H22: Standalone OPE/S&L DCF ex-holdco costs; the 15% discount below proxies central costs + governance (never both capitalized costs and a discount)
A23: Holdco discount | B23: 0.15 | H23: Conglomerate/complexity + governance + late-filer discount
A25: RELATIVE & NORMALIZED
A26: Peer P/NAV multiple | B26: 0.75 | H26: EGX holdco range ~0.5-0.9x accountable NAV
A27: EV/EBITDA target (FY27E) | B27: 9 | H27: Tourism-infrastructure concession comps
A28: Normalized attributable earnings (EGP m) | B28: 450 | H28: Mid-cycle: OPE at ~40% margin + net financial carry, ex-FX/one-offs
A29: Justified P/E | B29: 12 | H29: Growth concession, holdco wrapper
A31: SYNTHESIS WEIGHTS
A32: Holdco NAV weight | B32: 0.45 | H32: Primary lens
A33: DCF weight | B33: 0.2
A34: Relative weight | B34: 0.15
A35: Normalized-earnings weight | B35: 0.2
A37: MONTE CARLO (engine outputs — see Monte Carlo sheet)
A38: Diffusion volatility (annualized) | B38: 0.3831 | H38: YZ-HAR pooled log-HAR on Yang-Zhang proxy, fit 01-Jul-26
A39: Net 3-month drift (total) | B39: 0.1184 | H39: Secular (expanding mean, drift ON per Step 0) + 16-factor net
A40: KVOL (calibration multiplier) | B40: 1 | H40: Retired in engine v2 (over-covered, cost CRPS)
A42: FORECAST DRIVERS (FY25E–FY29E)
B43: FY25E | C43: FY26E | D43: FY27E | E43: FY28E | F43: FY29E
A44: Entertainment revenue — FY25E level (EGP m) | B44: 590 | H44: 9M-25 consolidated rev EGP 441m annualized (Arab Finance 31-Dec-25)
A45: Entertainment revenue growth | C45: 0.9 | D45: 0.45 | E45: 0.3 | F45: 0.22 | H45: OPE ramp; plateau-area rev EGP 3-3.5bn 2026E, +20-25%/yr (EnterpriseAM 29-Jun-26)
...

Sheet Holdco NAV
A1: Holdco NAV (primary lens)
A2: Each asset marked on the basis that fits it; USD marks converted at EGP/USD; the OPE platform carried at its DCF value.
A3: Part | B3: Basis | C3: Value (EGP m)
A4: Cash & equivalents (ex-DPRK) | B4: Carrying | C4: =Assumptions!$B$12*Assumptions!$B$6 -> 2243.413 | E4: The DPRK block is deliberately shown net-of-ECL against the full KL loan: the market may treat the pair as a wash; we carry both at audited marks.
A5: DPRK cash, net of ECL | B5: Gross × (1 − 50% ECL) | C5: =Assumptions!$B$13*(1-Assumptions!$B$14)*Assumptions!$B$6 -> 2795.6755
A6: Koryolink 60% associate | B6: Carrying (profits fully impaired) | C6: =Assumptions!$B$15*Assumptions!$B$6 -> 589.08
A7: Lighthouse Energy Fund | B7: L3 fund mark (DCF) | C7: =Assumptions!$B$16*Assumptions!$B$6 -> 1399.065
A8: Brazil investment property | B8: Carrying, est. | C8: =Assumptions!$B$17*Assumptions!$B$6 -> 392.72
A9: Net working capital & other | B9: Receivables + other − payables/provisions/tax | C9: =Assumptions!$B$18*Assumptions!$B$6 -> 0
A10: OPE + Sound & Light platform | B10: DCF of the plateau concession | C10: =Assumptions!$B$22 -> 2900
A11: Loan from Koryolink | B11: Carrying (interest-free, unwinds to ~$116m) | C11: =Assumptions!$B$19*Assumptions!$B$6 -> -4442.645
A12: Bank borrowings | B12: Carrying | C12: =Assumptions!$B$20*Assumptions!$B$6 -> -422.174
A13: Lease liabilities | B13: Carrying | C13: =Assumptions!$B$21*Assumptions!$B$6 -> -431.992
A14: Σ NAV (pre-discount) | C14: =SUM(C4:C13) -> 5023.1425
A15: per share (EGP) | C15: =C14/Assumptions!$B$5 -> 0.95757517
A16: less: holdco discount | B16: applied | C16: =-C14*Assumptions!$B$23 -> -753.47137
A17: NAV equity value | C17: =C14+C16 -> 4269.6711
A18: NAV fair value per share (EGP) | C18: =C17/Assumptions!$B$5 -> 0.8139389
A20: Memo — DPRK cash at full recovery adds (EGP/share) | C20: =Assumptions!$B$13*Assumptions!$B$14*Assumptions!$B$6/Assumptions!$B$5 -> 0.53294714
A21: Memo — KL loan at undiscounted $116m costs (EGP/share) | C21: =-(116-ABS(Assumptions!$B$19))*Assumptions!$B$6/Assumptions!$B$5 -> -0.23863305

Sheet Segments
A1: Segments (EGP m)
A2: IFRS reportable segments: Entertainment (OPE + Sound & Light, Giza plateau) · Other (holdco & equity investments) · GSM-Lebanon (terminated) · Investment property (Brazil, discontinued).
B3: FY23 | C3: FY24 | D3: FY25E | E3: FY26E
A4: Entertainment revenue | B4: 150 | C4: 330 | D4: ='Income Statement'!E23-Assumptions!B$46 -> 590 | E4: ='Income Statement'!F23-Assumptions!C$46 -> 1121 | F4: FY23/FY24 split est. from IFRS segment note & receivable mix; entertainment is the bulk of consolidated revenue
A5: Other / rental revenue | B5: 26 | C5: 28 | D5: =Assumptions!B$46 -> 20 | E5: =Assumptions!C$46 -> 22
A6: GSM-Lebanon revenue | B6: 0 | C6: 0 | D6: 0 | E6: 0
A7: Total revenue | B7: ='Income Statement'!C23 -> 176.47518 | C7: ='Income Statement'!D23 -> 357.82785 | D7: ='Income Statement'!E23 -> 610 | E7: ='Income Statement'!F23 -> 1143
A9: Entertainment EBITDA margin | D9: =Assumptions!B$47 -> 0.18 | E9: =Assumptions!C$47 -> 0.32
A11: Plateau concession economics: 2018 protocol with the Supreme Council of Antiquities; strict 50-50 revenue share with the state (state minimum EGP 20m/yr); site ticket revenue stays with the state — OPE monetizes transport (e-buses), F&B, retail leases, events, sponsorship; cumulative investment heading to ~EGP 2bn; plateau-area revenue seen at EGP 3-3.5bn in 2026 (+20-25%/yr), 5m visitors targeted.
A12: Sources: EnterpriseAM 29-Jun-26; Egyptian Streets 29-Nov-24; Daily News Egypt 09-Oct-23.

Sheet Relative & Normalized
A1: Relative & normalized lenses
A3: Relative: peer P/NAV × accountable NAV (pre-discount) per share | C3: =Assumptions!$B$26*'Holdco NAV'!C14/Assumptions!$B$5 -> 0.71818138
A5: Normalized: mid-cycle attributable earnings × justified P/E, per share | C5: =Assumptions!$B$28*Assumptions!$B$29/Assumptions!$B$5 -> 1.0294165
A7: EV/EBITDA cross-read: FY27E EBITDA × target ÷ shares (equity ≈ EV + net fin. assets) | C7: =('Income Statement'!F26*Assumptions!$B$27+DCF!B15)/Assumptions!$B$5 -> 0.40597567
A9: Normalized earnings anatomy: OPE at maturity margin + net financial carry, excluding FX swings, DPRK ECL noise and Koryolink pass-through.

Sheet DCF
A1: Consolidated DCF (FCFF, EGP m) — cross-check lens
A2: Operating business (OPE-led) FCFF at EGP WACC + net financial assets at marks.
B3: FY25E | C3: FY26E | D3: FY27E | E3: FY28E | F3: FY29E
A4: EBITDA | B4: ='Income Statement'!E26 -> -223.8 | C4: ='Income Statement'!F26 -> 0.72 | D4: ='Income Statement'!G26 -> 231.671 | E4: ='Income Statement'!H26 -> 468.4957 | F4: ='Income Statement'!I26 -> 682.30403
A5: less: tax on EBIT | B5: =-MAX(0,'Income Statement'!E29)*Assumptions!$B$9 -> 0 | C5: =-MAX(0,'Income Statement'!F29)*Assumptions!$B$9 -> 0 | D5: =-MAX(0,'Income Statement'!G29)*Assumptions!$B$9 -> -22.435875 | E5: =-MAX(0,'Income Statement'!H29)*Assumptions!$B$9 -> -71.720944 | F5: =-MAX(0,'Income Statement'!I29)*Assumptions!$B$9 -> -112.47448
A6: less: capex | B6: =Assumptions!B$52 -> -450 | C6: =Assumptions!C$52 -> -500 | D6: =Assumptions!D$52 -> -300 | E6: =Assumptions!E$52 -> -200 | F6: =Assumptions!F$52 -> -150
A7: less: ΔWC | B7: =Assumptions!B$53 -> -30 | C7: =Assumptions!C$53 -> -40 | D7: =Assumptions!D$53 -> -40 | E7: =Assumptions!E$53 -> -35 | F7: =Assumptions!F$53 -> -30
A8: FCFF | B8: =SUM(B4:B7) -> -703.8 | C8: =SUM(C4:C7) -> -539.28 | D8: =SUM(D4:D7) -> -130.76487 | E8: =SUM(E4:E7) -> 161.77476 | F8: =SUM(F4:F7) -> 389.82955
A9: Discount factor | B9: =1/(1+Assumptions!$B$7)^1 -> 0.83333333 | C9: =1/(1+Assumptions!$B$7)^2 -> 0.69444444 | D9: =1/(1+Assumptions!$B$7)^3 -> 0.5787037 | E9: =1/(1+Assumptions!$B$7)^4 -> 0.48225309 | F9: =1/(1+Assumptions!$B$7)^5 -> 0.40187757
A10: PV of FCFF | B10: =B8*B9 -> -586.5 | C10: =C8*C9 -> -374.5 | D10: =D8*D9 -> -75.674117 | E10: =E8*E9 -> 78.016376 | F10: =F8*F9 -> 156.66375
A12: Terminal value (FY29E FCFF × (1+g) / (WACC−g)) | B12: =F8*(1+Assumptions!$B$8)/(Assumptions!$B$7-Assumptions!$B$8) -> 2951.5666
A13: PV of terminal value | B13: =B12*F9 -> 1186.1684
A14: Operating EV | B14: =SUM(B10:F10)+B13 -> 384.17443
A15: plus: net financial assets at marks (NAV ex-OPE, pre-discount) | B15: ='Holdco NAV'!C14-Assumptions!$B$22 -> 2123.1425
A16: DCF equity value | B16: =B14+B15 -> 2507.3169
A17: DCF fair value per share (EGP) | B17: =B16/Assumptions!$B$5 -> 0.47797657
A19: WACC 20% (EGP) reflects CBE corridor ~19-20% and an EGP equity build-up; g 6% nominal.

Sheet Income Statement
A1: Income statement (EGP m, consolidated, FY ends Dec)
A2: FY22–FY24 audited IFRS (US$ ’000 × disclosed avg FX, converted below); FY25E–FY29E Testahil estimates.
B3: FY22 | C3: FY23 | D3: FY24 | E3: FY25E | F3: FY26E | G3: FY27E | H3: FY28E | I3: FY29E
A4: Avg FX (EGP per USD) | B4: 19.19 | C4: 30.67 | D4: 45.45 | K4: IFRS FY23/FY24 FS: avg USD-per-EGP 0.0521 / 0.0326 / 0.0220 inverted
A5: — audited US$ ’000 (source block) —
A6: Revenue | B6: 5085 | C6: 5754 | D6: 7873 | K6: Source: OIH consolidated IFRS FS FY2023 (KPMG 10-Nov-25, incl. FY22 restated) & FY2024 (23-Dec-25), orascomih.com
A7: Other income | B7: 4843 | C7: 115 | D7: 2728
A8: Purchases, services & other opex | B8: -7071 | C8: -4986 | D8: -9132
A9: Personnel cost | B9: -5678 | C9: -9081 | D9: -6446
A10: Provisions | B10: -1718 | C10: -1487 | D10: -1670
A11: D&A | B11: -579 | C11: -1627 | D11: -1085
A12: Impairment of financial assets | B12: 614 | C12: -49448 | D12: -14000
A13: Finance income | B13: 23534 | C13: 4241 | D13: 17537
A14: FVTPL gains/(losses) | B14: 6467 | C14: -3956 | D14: 5943
A15: Finance expense | B15: -2013 | C15: -9611 | D15: -6918
A16: Net FX differences | B16: 24776 | C16: 19783 | D16: 1944
A17: Koryolink share of profit | B17: 26113 | C17: 18103 | D17: 8868
A18: Koryolink impairment | B18: -26113 | C18: -18103 | D18: -8868
... A20: Discontinued operations | B20: -620 | C20: 9434 | D20: 0
A22: — EGP m (converted / forecast) —
A23: Revenue | B23: =B6*B$4/1000 -> 97.58115 | C23: =C6*C$4/1000 -> 176.47518 | D23: =D6*D$4/1000 -> 357.82785 | E23: =Assumptions!B$44+Assumptions!B$46 -> 610 | F23: =(E23-Assumptions!B$46)*(1+Assumptions!C$45)+Assumptions!C$46 -> 1143 | G23: =(F23-Assumptions!C$46)*(1+Assumptions!D$45)+Assumptions!D$46 -> 1649.45 | H23: =(G23-Assumptions!D$46)*(1+Assumptions!E$45)+Assumptions!E$46 -> 2139.085 | I23: =(H23-Assumptions!E$46)*(1+Assumptions!F$45)+Assumptions!F$46 -> 2605.9637
A24: Other income | B24: =B7*B$4/1000 -> 92.93717 | C24: =C7*C$4/1000 -> 3.52705 | D24: =D7*D$4/1000 -> 123.9876 | E24: 0 | F24: 0 | G24: 0 | H24: 0 | I24: 0
A25: Opex (purchases, personnel, provisions) | B25: =(B8+B9+B10)*B$4/1000 -> -277.62173 | C25: =(C8+C9+C10)*C$4/1000 -> -477.04118 | D25: =(D8+D9+D10)*D$4/1000 -> -783.9216 | E25: =-((E23-Assumptions!B$46)*(1-Assumptions!B$47))+Assumptions!B$48 -> -833.8 | F25: =-((F23-Assumptions!C$46)*(1-Assumptions!C$47))+Assumptions!C$48 -> -1142.28 | G25: =-((G23-Assumptions!D$46)*(1-Assumptions!D$47))+Assumptions!D$48 -> -1417.779 | H25: =-((H23-Assumptions!E$46)*(1-Assumptions!E$47))+Assumptions!E$48 -> -1670.5893 | I25: =-((I23-Assumptions!F$46)*(1-Assumptions!F$47))+Assumptions!F$48 -> -1923.6597
A26: EBITDA | B26: =B23+B24+B25 -> -87.10341 | C26: =C23+C24+C25 -> -297.03895 | D26: =D23+D24+D25 -> -302.10615 | E26: =E23+E24+E25 -> -223.8 | F26: =F23+F24+F25 -> 0.72 | G26: =G23+G24+G25 -> 231.671 | H26: =H23+H24+H25 -> 468.4957 | I26: =I23+I24+I25 -> 682.30403
A27: EBITDA margin | B27: =B26/B23 -> -0.89262537 | C27: =C26/C23 -> -1.6831769 | D27: =D26/D23 -> -0.84427791 | E27: =E26/E23 -> -0.36688525 | F27: =F26/F23 -> 0.00062992126 | G27: =G26/G23 -> 0.14045348 | H27: =H26/H23 -> 0.21901687 | I27: =I26/I23 -> 0.26182407
A28: D&A | B28: =B11*B$4/1000 -> -11.11101 | C28: =C11*C$4/1000 -> -49.90009 | D28: =D11*D$4/1000 -> -49.31325 | E28: =-E23*Assumptions!B$49 -> -61 | F28: =-F23*Assumptions!C$49 -> -102.87 | G28: =-G23*Assumptions!D$49 -> -131.956 | H28: =-H23*Assumptions!E$49 -> -149.73595 | I28: =-I23*Assumptions!F$49 -> -182.41746
A29: EBIT | B29: =B26+B28 -> -98.21442 | C29: =C26+C28 -> -346.93904 | D29: =D26+D28 -> -351.4194 | E29: =E26+E28 -> -284.8 | F29: =F26+F28 -> -102.15 | G29: =G26+G28 -> 99.715 | H29: =H26+H28 -> 318.75975 | I29: =I26+I28 -> 499.88657
A30: Impairments & FX (incl. DPRK ECL) | B30: =(B12+B16)*B$4/1000 -> 487.2341 | C30: =(C12+C16)*C$4/1000 -> -909.82555 | D30: =(D12+D16)*D$4/1000 -> -547.9452 | E30: =Assumptions!B$51 -> -700 | F30: =Assumptions!C$51 -> 0 | G30: =Assumptions!D$51 -> 0 | H30: =Assumptions!E$51 -> 0 | I30: =Assumptions!F$51 -> 0
A31: Net finance result (incl. FVTPL) | B31: =(B13+B14+B15)*B$4/1000 -> 537.08972 | C31: =(C13+C14+C15)*C$4/1000 -> -286.02842 | D31: =(D13+D14+D15)*D$4/1000 -> 752.7429 | E31: =Assumptions!B$50 -> -160 | F31: =Assumptions!C$50 -> -120 | G31: =Assumptions!D$50 -> -80 | H31: =Assumptions!E$50 -> -40 | I31: =Assumptions!F$50 -> 0
A32: Koryolink share, net of impairment | B32: =(B17+B18)*B$4/1000 -> 0 | C32: =(C17+C18)*C$4/1000 -> 0 | D32: =(D17+D18)*D$4/1000 -> 0 | E32: 0 | F32: 0 | G32: 0 | H32: 0 | I32: 0
A33: PBT | B33: =SUM(B29,B30:B32) -> 926.1094 | C33: =SUM(C29,C30:C32) -> -1542.793 | D33: =SUM(D29,D30:D32) -> -146.6217 | E33: =SUM(E29,E30:E32) -> -1144.8 | F33: =SUM(F29,F30:F32) -> -222.15 | G33: =SUM(G29,G30:G32) -> 19.715 | H33: =SUM(H29,H30:H32) -> 278.75975 | I33: =SUM(I29,I30:I32) -> 499.88657
A34: Income tax | B34: =B19*B$4/1000 -> -191.84243 | C34: =C19*C$4/1000 -> 48.05989 | D34: =D19*D$4/1000 -> -142.0767 | E34: =-MAX(0,E33)*Assumptions!$B$9 -> 0 | F34: =-MAX(0,F33)*Assumptions!$B$9 -> 0 | G34: =-MAX(0,G33)*Assumptions!$B$9 -> -4.435875 | H34: =-MAX(0,H33)*Assumptions!$B$9 -> -62.720944 | I34: =-MAX(0,I33)*Assumptions!$B$9 -> -112.47448
A35: Discontinued operations | B35: =B20*B$4/1000 -> -11.8978 | C35: =C20*C$4/1000 -> 289.34078 | D35: =D20*D$4/1000 -> 0 | E35: 0 | F35: 0 | G35: 0 | H35: 0 | I35: 0
A36: Net profit / (loss) | B36: =B33+B34+B35 -> 722.36917 | C36: =C33+C34+C35 -> -1205.3923 | D36: =D33+D34+D35 -> -288.6984 | E36: =E33+E34+E35 -> -1144.8 | F36: =F33+F34+F35 -> -222.15 | G36: =G33+G34+G35 -> 15.279125 | H36: =H33+H34+H35 -> 216.03881 | I36: =I33+I34+I35 -> 387.41209
A38: FY25E check: 9M-25 consolidated net loss EGP -806m (Arab Finance/Zawya, 31-Dec-25/02-Jan-26); model FY25E lands in the same zone.

Sheet Balance Sheet
A1: Balance sheet (EGP m, consolidated, 31 Dec)
A2: FY22–FY24 audited IFRS (US$ ’000 × closing FX); FY24 lines not separately disclosed are estimated to balance to EAS total assets EGP 9,508m. FY25E–FY29E Testahil.
B3: FY22 | C3: FY23 | D3: FY24 | E3: FY25E | F3: FY26E | G3: FY27E | H3: FY28E | I3: FY29E
A4: Closing FX (EGP per USD) | B4: 24.75 | C4: 30.86 | D4: 51.02 | E4: =Assumptions!$B$6 -> 49.09 | F4: =Assumptions!$B$6 -> 49.09 | G4: =Assumptions!$B$6 -> 49.09 | H4: =Assumptions!$B$6 -> 49.09 | I4: =Assumptions!$B$6 -> 49.09
A5: — audited US$ ’000 (source block; FY24 P&E, payables split, DTL/tax/provisions est. to balance) —
A6: Property & equipment (incl. ROU) | B6: 18600 | C6: 31558 | D6: 26022
A7: Investment property | B7: 8166 | C7: 0 | D7: 0
A8: Equity-accounted investees (Koryolink) | B8: 24803 | C8: 19858 | D8: 12000
A9: Financial assets at amortized cost (DPRK cash, net) | B9: 90471 | C9: 47975 | D9: 56967
A10: Financial assets at FVTPL (Lighthouse) | B10: 27504 | C10: 24332 | D10: 28522
A11: Inventories | B11: 0 | C11: 35 | D11: 50
A12: Trade receivables | B12: 10921 | C12: 5208 | D12: 4302
A13: Other assets | B13: 2918 | C13: 2057 | D13: 12869
A14: Cash & cash equivalents | B14: 66880 | C14: 73583 | D14: 45714
A15: Borrowings (incl. KL loan & leases) | B15: -79872 | C15: -103395 | D15: -107890
A16: Trade payables & other liabilities | B16: -19973 | C16: -15593 | D16: -5584
A17: Deferred tax liabilities | B17: -12363 | C17: -9396 | D17: -9000
... A19: Provisions | B19: -8702 | C19: -7280 | D19: -7300
A21: — EGP m —
A22: Property & equipment (incl. ROU) | B22: =B6*B$4/1000 -> 460.35 | C22: =C6*C$4/1000 -> 973.87988 | D22: =D6*D$4/1000 -> 1327.6424 | E22: =D22-Assumptions!B$52+'Income Statement'!E28 -> 1716.6424 | F22: =E22-Assumptions!C$52+'Income Statement'!F28 -> 2113.7724 | G22: =F22-Assumptions!D$52+'Income Statement'!G28 -> 2281.8164 | H22: =G22-Assumptions!E$52+'Income Statement'!H28 -> 2332.0805 | I22: =H22-Assumptions!F$52+'Income Statement'!I28 -> 2299.663
A23: Investment property | B23: =B7*B$4/1000 -> 202.1085 | C23: =C7*C$4/1000 -> 0 | D23: =D7*D$4/1000 -> 0 | E23: =D23 -> 0 | F23: =E23 -> 0 | G23: =F23 -> 0 | H23: =G23 -> 0 | I23: =H23 -> 0
A24: Koryolink (equity-accounted) | B24: =B8*B$4/1000 -> 613.87425 | C24: =C8*C$4/1000 -> 612.81788 | D24: =D8*D$4/1000 -> 612.24 | E24: =D24 -> 612.24 | F24: =E24 -> 612.24 | G24: =F24 -> 612.24 | H24: =G24 -> 612.24 | I24: =H24 -> 612.24
A25: DPRK cash (net of 50% ECL) | B25: =B9*B$4/1000 -> 2239.1573 | C25: =C9*C$4/1000 -> 1480.5085 | D25: =D9*D$4/1000 -> 2906.4563 | E25: =D25*Assumptions!$B$6/D$4 -> 2796.51 | F25: =E25 -> 2796.51 | G25: =F25 -> 2796.51 | H25: =G25 -> 2796.51 | I25: =H25 -> 2796.51
A26: Lighthouse Energy Fund (FVTPL) | B26: =B10*B$4/1000 -> 680.724 | C26: =C10*C$4/1000 -> 750.88552 | D26: =D10*D$4/1000 -> 1455.1924 | E26: =D26 -> 1455.1924 | F26: =E26 -> 1455.1924 | G26: =F26 -> 1455.1924 | H26: =G26 -> 1455.1924 | I26: =H26 -> 1455.1924
A27: Inventories | B27: =B11*B$4/1000 -> 0 | C27: =C11*C$4/1000 -> 1.0801 | D27: =D11*D$4/1000 -> 2.551 | E27: =D27 -> 2.551 | F27: =E27 -> 2.551 | G27: =F27 -> 2.551 | H27: =G27 -> 2.551 | I27: =H27 -> 2.551
A28: Trade receivables | B28: =B12*B$4/1000 -> 270.29475 | C28: =C12*C$4/1000 -> 160.71888 | D28: =D12*D$4/1000 -> 219.48804 | E28: =D28-Assumptions!B$53*0.6 -> 237.48804 | F28: =E28-Assumptions!C$53*0.6 -> 261.48804 | G28: =F28-Assumptions!D$53*0.6 -> 285.48804 | H28: =G28-Assumptions!E$53*0.6 -> 306.48804 | I28: =H28-Assumptions!F$53*0.6 -> 324.48804
A29: Other assets | B29: =B13*B$4/1000 -> 72.2205 | C29: =C13*C$4/1000 -> 63.47902 | D29: =D13*D$4/1000 -> 656.57638 | E29: =D29-Assumptions!B$53*0.4 -> 668.57638 | F29: =E29-Assumptions!C$53*0.4 -> 684.57638 | G29: =F29-Assumptions!D$53*0.4 -> 700.57638 | H29: =G29-Assumptions!E$53*0.4 -> 714.57638 | I29: =H29-Assumptions!F$53*0.4 -> 726.57638
A30: Cash & cash equivalents | B30: =B14*B$4/1000 -> 1655.28 | C30: =C14*C$4/1000 -> 2270.7714 | D30: =D14*D$4/1000 -> 2332.3283 | E30: ='Cash Flow'!E23 -> 1368.5283 | F30: ='Cash Flow'!F23 -> 749.24828 | G30: ='Cash Flow'!G23 -> 596.4834 | H30: ='Cash Flow'!H23 -> 767.25816 | I30: ='Cash Flow'!I23 -> 1197.0877
A31: Total assets | B31: =SUM(B22:B30) -> 6194.0093 | C31: =SUM(C22:C30) -> 6314.1412 | D31: =SUM(D22:D30) -> 9512.4749 | E31: =SUM(E22:E30) -> 8857.7286 | F31: =SUM(F22:F30) -> 8675.5786 | G31: =SUM(G22:G30) -> 8730.8577 | H31: =SUM(H22:H30) -> 8986.8965 | I31: =SUM(I22:I30) -> 9414.3086
A32: Borrowings (incl. KL loan & leases) | B32: =B15*B$4/1000 -> -1976.832 | C32: =C15*C$4/1000 -> -3190.7697 | D32: =D15*D$4/1000 -> -5504.5478 | E32: =D32+40 -> -5464.5478 | F32: =E32+40 -> -5424.5478 | G32: =F32+40 -> -5384.5478 | H32: =G32+40 -> -5344.5478 | I32: =H32+40 -> -5304.5478
A33: Trade payables & other liabilities | B33: =B16*B$4/1000 -> -494.33175 | C33: =C16*C$4/1000 -> -481.19998 | D33: =D16*D$4/1000 -> -284.89568 | E33: =D33 -> -284.89568 | F33: =E33 -> -284.89568 | G33: =F33 -> -284.89568 | H33: =G33 -> -284.89568 | I33: =H33 -> -284.89568
A34: Deferred tax liabilities | B34: =B17*B$4/1000 -> -305.98425 | C34: =C17*C$4/1000 -> -289.96056 | D34: =D17*D$4/1000 -> -459.18 | E34: =D34 -> -459.18 | F34: =E34 -> -459.18 | G34: =F34 -> -459.18 | H34: =G34 -> -459.18 | I34: =H34 -> -459.18
A35: Income tax liabilities | B35: =B18*B$4/1000 -> -102.48975 | C35: =C18*C$4/1000 -> -71.84208 | D35: =D18*D$4/1000 -> -117.346 | E35: =D35 -> -117.346 | F35: =E35 -> -117.346 | G35: =F35 -> -117.346 | H35: =G35 -> -117.346 | I35: =H35 -> -117.346
A36: Provisions | B36: =B19*B$4/1000 -> -215.3745 | C36: =C19*C$4/1000 -> -224.6608 | D36: =D19*D$4/1000 -> -372.446 | E36: =D36 -> -372.446 | F36: =E36 -> -372.446 | G36: =F36 -> -372.446 | H36: =G36 -> -372.446 | I36: =H36 -> -372.446
A37: Total liabilities | B37: =-SUM(B32:B36) -> 3095.0123 | C37: =-SUM(C32:C36) -> 4258.4331 | D37: =-SUM(D32:D36) -> 6738.4155 | E37: =-SUM(E32:E36) -> 6698.4155 | F37: =-SUM(F32:F36) -> 6658.4155 | G37: =-SUM(G32:G36) -> 6618.4155 | H37: =-SUM(H32:H36) -> 6578.4155 | I37: =-SUM(I32:I36) -> 6538.4155
A38: Total equity | B38: =B31-B37 -> 3098.997 | C38: =C31-C37 -> 2055.708 | D38: =D31-D37 -> 2774.0594 | E38: =D38+'Income Statement'!E36+E41 -> 2159.3131 | F38: =E38+'Income Statement'!F36+F41 -> 2017.1631 | G38: =F38+'Income Statement'!G36+G41 -> 2112.4423 | H38: =G38+'Income Statement'!H36+H41 -> 2408.4811 | I38: =H38+'Income Statement'!I36+I41 -> 2875.8932
A39: Check: assets − liabilities − equity | B39: =B31-B37-B38 -> 0 | C39: =C31-C37-C38 -> 0 | D39: =D31-D37-D38 -> 0 | E39: =E31-E37-E38 -> 0 | F39: =F31-F37-F38 -> 0 | G39: =G31-G37-G38 -> 0 | H39: =H31-H37-H38 -> 0 | I39: =I31-I37-I38 -> 0
A41: FX translation & other equity movements (balancing, est.) | E41: =E31-E37-D38-'Income Statement'!E36 -> 530.05369 | F41: =F31-F37-E38-'Income Statement'!F36 -> 80 | G41: =G31-G37-F38-'Income Statement'!G36 -> 80 | H41: =H31-H37-G38-'Income Statement'!H36 -> 80 | I41: =I31-I37-H38-'Income Statement'!I36 -> 80
A43: Source: FY23 IFRS FS incl. FY22 restated (RNS 1069H, 11-Nov-25); FY24 IFRS FS (23-Dec-25); EAS total assets EGP 9,508m end-24 / 9,509m Sep-25 (Zawya 02-Jan-26).

Sheet Cash Flow
A1: Cash flow (EGP m, consolidated)
A2: FY22–FY24 audited IFRS × avg FX; FY25E–FY29E: NP + D&A − capex − ΔWC + financing.
B3: FY22 | C3: FY23 | D3: FY24 | E3: FY25E | F3: FY26E | G3: FY27E | H3: FY28E | I3: FY29E
A4: Avg FX (EGP per USD) | B4: ='Income Statement'!B4 -> 19.19 | C4: ='Income Statement'!C4 -> 30.67 | D4: ='Income Statement'!D4 -> 45.45 | E4: =Assumptions!$B$6 -> 49.09 | F4: =Assumptions!$B$6 -> 49.09 | G4: =Assumptions!$B$6 -> 49.09 | H4: =Assumptions!$B$6 -> 49.09 | I4: =Assumptions!$B$6 -> 49.09
A5: — audited US$ ’000 —
A6: Operating cash flow | B6: -10877 | C6: -7783 | D6: -33650
A7: Investing cash flow | B7: -1070 | C7: 12885 | D7: -21126
A8: Financing cash flow | B8: 9153 | C8: 2966 | D8: 27833
A9: Discontinued & FX on cash | B9: -5354 | C9: -1365 | D9: -1364
A11: — EGP m —
A12: Net profit / (loss) | E12: ='Income Statement'!E36 -> -1144.8 | F12: ='Income Statement'!F36 -> -222.15 | G12: ='Income Statement'!G36 -> 15.279125 | H12: ='Income Statement'!H36 -> 216.03881 | I12: ='Income Statement'!I36 -> 387.41209
A13: add back: D&A | E13: =-'Income Statement'!E28 -> 61 | F13: =-'Income Statement'!F28 -> 102.87 | G13: =-'Income Statement'!G28 -> 131.956 | H13: =-'Income Statement'!H28 -> 149.73595 | I13: =-'Income Statement'!I28 -> 182.41746
A14: add back: non-cash impairments & FX | E14: =-'Income Statement'!E30*0.8 -> 560 | F14: =-'Income Statement'!F30*0.8 -> 0 | G14: =-'Income Statement'!G30*0.8 -> 0 | H14: =-'Income Statement'!H30*0.8 -> 0 | I14: =-'Income Statement'!I30*0.8 -> 0
A15: Working-capital change | E15: =Assumptions!B$53 -> -30 | F15: =Assumptions!C$53 -> -40 | G15: =Assumptions!D$53 -> -40 | H15: =Assumptions!E$53 -> -35 | I15: =Assumptions!F$53 -> -30
A16: Operating cash flow | B16: =B6*B$4/1000 -> -208.72963 | C16: =C6*C$4/1000 -> -238.70461 | D16: =D6*D$4/1000 -> -1529.3925 | E16: =SUM(E12:E15) -> -553.8 | F16: =SUM(F12:F15) -> -159.28 | G16: =SUM(G12:G15) -> 107.23512 | H16: =SUM(H12:H15) -> 330.77476 | I16: =SUM(I12:I15) -> 539.82955
A17: Capex | E17: =Assumptions!B$52 -> -450 | F17: =Assumptions!C$52 -> -500 | G17: =Assumptions!D$52 -> -300 | H17: =Assumptions!E$52 -> -200 | I17: =Assumptions!F$52 -> -150
A18: Investing cash flow | B18: =B7*B$4/1000 -> -20.5333 | C18: =C7*C$4/1000 -> 395.18295 | D18: =D7*D$4/1000 -> -960.1767 | E18: =E17 -> -450 | F18: =F17 -> -500 | G18: =G17 -> -300 | H18: =H17 -> -200 | I18: =I17 -> -150
A19: Net borrowings & other financing | E19: 40 | F19: 40 | G19: 40 | H19: 40 | I19: 40
A20: Financing cash flow | B20: =B8*B$4/1000 -> 175.64607 | C20: =C8*C$4/1000 -> 90.96722 | D20: =D8*D$4/1000 -> 1265.0098 | E20: =E19 -> 40 | F20: =F19 -> 40 | G20: =G19 -> 40 | H20: =H19 -> 40 | I20: =I19 -> 40
A21: Net change in cash | B21: =(B6+B7+B8+B9)*B$4/1000 -> -156.36012 | C21: =(C6+C7+C8+C9)*C$4/1000 -> 205.58101 | D21: =(D6+D7+D8+D9)*D$4/1000 -> -1286.5531 | E21: =E16+E18+E20 -> -963.8 | F21: =F16+F18+F20 -> -619.28 | G21: =G16+G18+G20 -> -152.76487 | H21: =H16+H18+H20 -> 170.77476 | I21: =I16+I18+I20 -> 429.82955
A22: Opening cash | E22: ='Balance Sheet'!D30 -> 2332.3283 | F22: =E23 -> 1368.5283 | G22: =F23 -> 749.24828 | H22: =G23 -> 596.4834 | I22: =H23 -> 767.25816
A23: Closing cash | E23: =E22+E21 -> 1368.5283 | F23: =F22+F21 -> 749.24828 | G23: =G22+G21 -> 596.4834 | H23: =H22+H21 -> 767.25816 | I23: =I22+I21 -> 1197.0877
A25: Source: FY23 IFRS FS incl. FY22 (RNS 1069H); FY24 IFRS FS: CFO −33,650 / CFI −21,126 / CFF +27,833, cash end 45,714 (US$ ’000).

Sheet Summary Financials
A1: Summary financials (EGP m) — every cell links to the statement sheets
B3: FY22 | C3: FY23 | D3: FY24 | E3: FY25E | F3: FY26E | G3: FY27E | H3: FY28E | I3: FY29E
A4: Revenue | B4: ='Income Statement'!B23 -> 97.58115 | C4: ='Income Statement'!C23 -> 176.47518 | D4: ='Income Statement'!D23 -> 357.82785 | E4: ='Income Statement'!E23 -> 610 | F4: ='Income Statement'!F23 -> 1143 | G4: ='Income Statement'!G23 -> 1649.45 | H4: ='Income Statement'!H23 -> 2139.085 | I4: ='Income Statement'!I23 -> 2605.9637
A5: EBITDA | B5: ='Income Statement'!B26 -> -87.10341 | C5: ='Income Statement'!C26 -> -297.03895 | D5: ='Income Statement'!D26 -> -302.10615 | E5: ='Income Statement'!E26 -> -223.8 | F5: ='Income Statement'!F26 -> 0.72 | G5: ='Income Statement'!G26 -> 231.671 | H5: ='Income Statement'!H26 -> 468.4957 | I5: ='Income Statement'!I26 -> 682.30403
A6: EBIT | B6: ='Income Statement'!B29 -> -98.21442 | C6: ='Income Statement'!C29 -> -346.93904 | D6: ='Income Statement'!D29 -> -351.4194 | E6: ='Income Statement'!E29 -> -284.8 | F6: ='Income Statement'!F29 -> -102.15 | G6: ='Income Statement'!G29 -> 99.715 | H6: ='Income Statement'!H29 -> 318.75975 | I6: ='Income Statement'!I29 -> 499.88657
A7: Net profit / (loss) | B7: ='Income Statement'!B36 -> 722.36917 | C7: ='Income Statement'!C36 -> -1205.3923 | D7: ='Income Statement'!D36 -> -288.6984 | E7: ='Income Statement'!E36 -> -1144.8 | F7: ='Income Statement'!F36 -> -222.15 | G7: ='Income Statement'!G36 -> 15.279125 | H7: ='Income Statement'!H36 -> 216.03881 | I7: ='Income Statement'!I36 -> 387.41209
A8: Total assets | B8: ='Balance Sheet'!B31 -> 6194.0093 | C8: ='Balance Sheet'!C31 -> 6314.1412 | D8: ='Balance Sheet'!D31 -> 9512.4749 | E8: ='Balance Sheet'!E31 -> 8857.7286 | F8: ='Balance Sheet'!F31 -> 8675.5786 | G8: ='Balance Sheet'!G31 -> 8730.8577 | H8: ='Balance Sheet'!H31 -> 8986.8965 | I8: ='Balance Sheet'!I31 -> 9414.3086
A9: Total equity | B9: ='Balance Sheet'!B38 -> 3098.997 | C9: ='Balance Sheet'!C38 -> 2055.708 | D9: ='Balance Sheet'!D38 -> 2774.0594 | E9: ='Balance Sheet'!E38 -> 2159.3131 | F9: ='Balance Sheet'!F38 -> 2017.1631 | G9: ='Balance Sheet'!G38 -> 2112.4423 | H9: ='Balance Sheet'!H38 -> 2408.4811 | I9: ='Balance Sheet'!I38 -> 2875.8932
A10: Cash (closing) | B10: ='Balance Sheet'!B30 -> 1655.28 | C10: ='Balance Sheet'!C30 -> 2270.7714 | D10: ='Balance Sheet'!D30 -> 2332.3283 | E10: ='Balance Sheet'!E30 -> 1368.5283 | F10: ='Balance Sheet'!F30 -> 749.24828 | G10: ='Balance Sheet'!G30 -> 596.4834 | H10: ='Balance Sheet'!H30 -> 767.25816 | I10: ='Balance Sheet'!I30 -> 1197.0877
A11: Borrowings | B11: ='Balance Sheet'!B32 -> -1976.832 | C11: ='Balance Sheet'!C32 -> -3190.7697 | D11: ='Balance Sheet'!D32 -> -5504.5478 | E11: ='Balance Sheet'!E32 -> -5464.5478 | F11: ='Balance Sheet'!F32 -> -5424.5478 | G11: ='Balance Sheet'!G32 -> -5384.5478 | H11: ='Balance Sheet'!H32 -> -5344.5478 | I11: ='Balance Sheet'!I32 -> -5304.5478

Sheet Monte Carlo
A1: Monte Carlo — engine outputs
A2: 50,000 paths · 16 factors (7 continuous + 9 discrete) · seed 42 · YZ-HAR width, unit-variance t5 innovations, secular drift ON (Step 0). Paths diffuse from spot; the §1 value gap is kept out of the drift.
A3: Percentile map (EGP/share)
A4: Horizon | B4: p5 | C4: p25 | D4: p50 | E4: p75 | F4: p95 | H4: Factor set = egx_holdco adapted to OIH (tourism/DPRK/FX-long); calibrated=False pending red-pen sign-off; net factor contribution +1.9%.
A5: T+20 sessions | B5: 1.176 | C5: 1.352 | D5: 1.462 | E5: 1.579 | F5: 1.801
A6: T+60 sessions | B6: 1.093 | C6: 1.364 | D6: 1.57 | E6: 1.799 | F6: 2.226
A8: Inputs (from Assumptions): σ (ann.) | E8: =Assumptions!$B$38 -> 0.3831
A9: net 3-month drift | E9: =Assumptions!$B$39 -> 0.1184
A10: KVOL (calibration) | E10: =Assumptions!$B$40 -> 1
A12: Level-touch ladder
A13: Level | B13: T+20 | C13: T+60
A14: 2.2 | B14: 0.005 | C14: 0.084
A15: 2 | B15: 0.017 | C15: 0.178
A16: 1.8 | B16: 0.071 | C16: 0.363
A17: 1.6 | B17: 0.309 | C17: 0.659
A18: 1.5 | B18: 0.594 | C18: 0.826
A19: 1.3 | B19: 0.297 | C19: 0.458
A20: 1.2 | B20: 0.113 | C20: 0.249
A21: 1.1 | B21: 0.037 | C21: 0.121
A22: 1 | B22: 0.01 | C22: 0.054
A23: 0.9 | B23: 0.003 | C23: 0.022
A25: T+60 probability zones
A26: Zone (EGP) | B26: Probability
A27: 0.00-1.00 | B27: 0.025
A28: 1.00-1.20 | B28: 0.08
A29: 1.20-1.41 | B29: 0.198
A30: 1.41-1.60 | B30: 0.234
A31: 1.60-1.80 | B31: 0.214
A32: 1.80-2.10 | B32: 0.168
A33: 2.10+ | B33: 0.081

Sheet Sensitivity
A1: Sensitivity — NAV fair value per share (EGP)
A2: Holdco discount (rows) × OPE + S&L platform value (columns, EGP m). All else at base marks.
A3: Discount \ OPE | B3: 2000 | C3: 3000 | D3: 3450 | E3: 4500 | F3: 6000
A4: 0 | B4: =(('Holdco NAV'!C14-Assumptions!$B$22+B$3)*(1-$A4))/Assumptions!$B$5 -> 0.78600575 | C4: =(('Holdco NAV'!C14-Assumptions!$B$22+C$3)*(1-$A4))/Assumptions!$B$5 -> 0.97663844 | D4: =(('Holdco NAV'!C14-Assumptions!$B$22+D$3)*(1-$A4))/Assumptions!$B$5 -> 1.0624232 | E4: =(('Holdco NAV'!C14-Assumptions!$B$22+E$3)*(1-$A4))/Assumptions!$B$5 -> 1.2625875 | F4: =(('Holdco NAV'!C14-Assumptions!$B$22+F$3)*(1-$A4))/Assumptions!$B$5 -> 1.5485365
A5: 0.1 | B5: =(('Holdco NAV'!C14-Assumptions!$B$22+B$3)*(1-$A5))/Assumptions!$B$5 -> 0.70740517 | C5: =(('Holdco NAV'!C14-Assumptions!$B$22+C$3)*(1-$A5))/Assumptions!$B$5 -> 0.8789746 | D5: =(('Holdco NAV'!C14-Assumptions!$B$22+D$3)*(1-$A5))/Assumptions!$B$5 -> 0.95618084 | E5: =(('Holdco NAV'!C14-Assumptions!$B$22+E$3)*(1-$A5))/Assumptions!$B$5 -> 1.1363287 | F5: =(('Holdco NAV'!C14-Assumptions!$B$22+F$3)*(1-$A5))/Assumptions!$B$5 -> 1.3936829
A6: 0.15 | B6: =(('Holdco NAV'!C14-Assumptions!$B$22+B$3)*(1-$A6))/Assumptions!$B$5 -> 0.66810489 | C6: =(('Holdco NAV'!C14-Assumptions!$B$22+C$3)*(1-$A6))/Assumptions!$B$5 -> 0.83014267 | D6: =(('Holdco NAV'!C14-Assumptions!$B$22+D$3)*(1-$A6))/Assumptions!$B$5 -> 0.90305968 | E6: =(('Holdco NAV'!C14-Assumptions!$B$22+E$3)*(1-$A6))/Assumptions!$B$5 -> 1.0731994 | F6: =(('Holdco NAV'!C14-Assumptions!$B$22+F$3)*(1-$A6))/Assumptions!$B$5 -> 1.316256
A7: 0.2 | B7: =(('Holdco NAV'!C14-Assumptions!$B$22+B$3)*(1-$A7))/Assumptions!$B$5 -> 0.6288046 | C7: =(('Holdco NAV'!C14-Assumptions!$B$22+C$3)*(1-$A7))/Assumptions!$B$5 -> 0.78131075 | D7: =(('Holdco NAV'!C14-Assumptions!$B$22+D$3)*(1-$A7))/Assumptions!$B$5 -> 0.84993852 | E7: =(('Holdco NAV'!C14-Assumptions!$B$22+E$3)*(1-$A7))/Assumptions!$B$5 -> 1.01007 | F7: =(('Holdco NAV'!C14-Assumptions!$B$22+F$3)*(1-$A7))/Assumptions!$B$5 -> 1.2388292
A8: 0.3 | B8: =(('Holdco NAV'!C14-Assumptions!$B$22+B$3)*(1-$A8))/Assumptions!$B$5 -> 0.55020402 | C8: =(('Holdco NAV'!C14-Assumptions!$B$22+C$3)*(1-$A8))/Assumptions!$B$5 -> 0.68364691 | D8: =(('Holdco NAV'!C14-Assumptions!$B$22+D$3)*(1-$A8))/Assumptions!$B$5 -> 0.74369621 | E8: =(('Holdco NAV'!C14-Assumptions!$B$22+E$3)*(1-$A8))/Assumptions!$B$5 -> 0.88381123 | F8: =(('Holdco NAV'!C14-Assumptions!$B$22+F$3)*(1-$A8))/Assumptions!$B$5 -> 1.0839756
A11: DPRK swing (memo): full recovery of the ECL adds; KL-loan unwinding to $116m costs — see Holdco NAV memo rows.

Sheet Per-Share & Ratios
A1: Per-share & ratios
B3: FY22 | C3: FY23 | D3: FY24 | E3: FY25E | F3: FY26E | G3: FY27E | H3: FY28E | I3: FY29E
A4: Revenue / share (EGP) | B4: ='Income Statement'!B23/Assumptions!$B$5 -> 0.018602157 | C4: ='Income Statement'!C23/Assumptions!$B$5 -> 0.033641938 | D4: ='Income Statement'!D23/Assumptions!$B$5 -> 0.068213686 | E4: ='Income Statement'!E23/Assumptions!$B$5 -> 0.11628594 | F4: ='Income Statement'!F23/Assumptions!$B$5 -> 0.21789317 | G4: ='Income Statement'!G23/Assumptions!$B$5 -> 0.31443909 | H4: ='Income Statement'!H23/Assumptions!$B$5 -> 0.40777953 | I4: ='Income Statement'!I23/Assumptions!$B$5 -> 0.49678187
A5: EPS (EGP) | B5: ='Income Statement'!B36/Assumptions!$B$5 -> 0.13770718 | C5: ='Income Statement'!C36/Assumptions!$B$5 -> -0.22978719 | D5: ='Income Statement'!D36/Assumptions!$B$5 -> -0.055035353 | E5: ='Income Statement'!E36/Assumptions!$B$5 -> -0.2182363 | F5: ='Income Statement'!F36/Assumptions!$B$5 -> -0.042349052 | G5: ='Income Statement'!G36/Assumptions!$B$5 -> 0.0029127007 | H5: ='Income Statement'!H36/Assumptions!$B$5 -> 0.041184059 | I5: ='Income Statement'!I36/Assumptions!$B$5 -> 0.073853409
A6: Book value / share (EGP) | B6: ='Balance Sheet'!B38/Assumptions!$B$5 -> 0.59077014 | C6: ='Balance Sheet'!C38/Assumptions!$B$5 -> 0.39188516 | D6: ='Balance Sheet'!D38/Assumptions!$B$5 -> 0.52882642 | E6: ='Balance Sheet'!E38/Assumptions!$B$5 -> 0.41163567 | F6: ='Balance Sheet'!F38/Assumptions!$B$5 -> 0.38453724 | G6: ='Balance Sheet'!G38/Assumptions!$B$5 -> 0.40270055 | H6: ='Balance Sheet'!H38/Assumptions!$B$5 -> 0.45913523 | I6: ='Balance Sheet'!I38/Assumptions!$B$5 -> 0.54823925
A7: P/BV at spot | B7: =Assumptions!$B$4/('Balance Sheet'!B38/Assumptions!$B$5) -> 2.3867151 | C7: =Assumptions!$B$4/('Balance Sheet'!C38/Assumptions!$B$5) -> 3.5979929 | D7: =Assumptions!$B$4/('Balance Sheet'!D38/Assumptions!$B$5) -> 2.6662813 | E7: =Assumptions!$B$4/('Balance Sheet'!E38/Assumptions!$B$5) -> 3.4253591 | F7: =Assumptions!$B$4/('Balance Sheet'!F38/Assumptions!$B$5) -> 3.666745 | G7: =Assumptions!$B$4/('Balance Sheet'!G38/Assumptions!$B$5) -> 3.501361 | H7: =Assumptions!$B$4/('Balance Sheet'!H38/Assumptions!$B$5) -> 3.0709907 | I7: =Assumptions!$B$4/('Balance Sheet'!I38/Assumptions!$B$5) -> 2.5718699
A8: EBITDA margin | B8: ='Income Statement'!B27 -> -0.89262537 | C8: ='Income Statement'!C27 -> -1.6831769 | D8: ='Income Statement'!D27 -> -0.84427791 | E8: ='Income Statement'!E27 -> -0.36688525 | F8: ='Income Statement'!F27 -> 0.00062992126 | G8: ='Income Statement'!G27 -> 0.14045348 | H8: ='Income Statement'!H27 -> 0.21901687 | I8: ='Income Statement'!I27 -> 0.26182407
A10: NAV / share (base, post-discount) | B10: ='Holdco NAV'!C18 -> 0.8139389
A11: P/NAV at spot | B11: =Assumptions!$B$4/'Holdco NAV'!C18 -> 1.7323168
A12: Market cap (EGP m) | B12: =Assumptions!$B$4*Assumptions!$B$5 -> 7396.4229

Sheet Peer & Sector
A1: Peer set & sector structure — EGX listed holdcos
A3: Name (EGX) | B3: Focus | C3: Discount narrative | D3: Comparability to OIH
A4: OIH — subject | B4: Pyramids concession, DPRK telecom legacy, renewables fund | C4: Trades ABOVE accountable NAV on OPE ramp + retail flow | D4: —
A5: Qalaa Holdings (CCAP) | B5: Energy/refining (ERC), infrastructure | C5: Deep P/NAV discount, leverage at subs | D5: Closest listed holdco; opposite discount regime
A6: B Investments (BINV) | B6: PE-style stakes, consumer & fintech | C6: Modest discount, cash-rich | D6: Cleaner book, no concession/DPRK tails
A7: EK Holding (EKHO) | B7: Gas, fertilizers, NBFC, USD-quoted | C7: Near NAV; USD line reduces FX drag | D7: USD-asset overlap parallels OIH FX-long book
A8: Odin Investments (ODIN) | B8: Brokerage-linked micro-holdco | C8: Illiquid, wide bands | D8: Size/retail-liquidity comparator only
A10: Sector structure: EGX holdcos habitually trade at 10–50% P/NAV discounts; OIH is the outlier premium name because its swing asset (the plateau concession) is ramping and its NAV is dominated by hard-to-verify marks (DPRK cash at 50% ECL, an L3 fund, an equity-method associate under sanctions). Key risks: concession terms, EGP path (OIH is net-long USD), DPRK writedown/recovery, late statutory filings (FY23 IFRS authorized Nov-25), governance/related-party flows.
