Workbook

Sheet READ FIRST
A1: Testahil — Pioneers Properties for Urban Development (EGX: PRDC)
A2: Companion model · Independent Valuation Study · Educational analysis · Not investment advice
A4: What this workbook is. A transparent companion to the PRDC valuation study. Every blue cell is an input;
A5: every black cell is a formula; green cells link across sheets. All inputs live on the Assumptions sheet —
A6: change one (the holdco discount, a development-NAV mark, a growth rate) and the whole model reprices.
A8: What it is not. It is not investment advice, a recommendation, or a price target. Values are model outputs
A9: shown as ranges. The preparer is not licensed by any securities regulator and may hold a position.
A11: Entity note. PRDC (PRE Group) demerged from Pioneers Holding in Oct-2021; it houses the group's real-estate
A12: development, contracting, leasing and El Kahera Housing (majority-owned) operations — a 360° developer-contractor.
A13: Primary lens: split-leg sum-of-the-parts / RNAV (development legs carry NO terminal value; recurring legs
A14: get cap-rate treatment); consolidated FCFF DCF and relative multiples cross-check.
A16: Currency. EGP million unless stated. Spot EGP 8.28 (6 Jul 2026 close). Shares 1,047.2 mn.
... A21: Income Statement · Balance Sheet · Cash Flow · Summary Financials · Monte Carlo · Sensitivity · Per-Share & Ratios · Peer & Sector.

Sheet Summary
A1: Valuation summary — Pioneers Properties (EGX: PRDC)
A2: Five-lens fair value vs spot. Base links live; bear/bull are scenario outputs (study §1.5).
A3: Lens | B3: Bear | C3: Base | D3: Bull | E3: Weight
A4: Sum-of-the-parts / RNAV | B4: 6.3 | C4: =SOTP!C15 | D4: 12 | E4: =Assumptions!B33
A5: Consolidated DCF | B5: 5.37 | C5: =DCF!B21 | D5: 11.56 | E5: =Assumptions!B34
A6: Relative multiples | B6: 4.5 | C6: ='Relative & Normalized'!C7 | D6: 8.8 | E6: =Assumptions!B35
A7: Property-cycle earnings | B7: 6.6 | C7: =Assumptions!B30 | D7: 12.3 | E7: =Assumptions!B36
A8: Weighted central | B8: =SUMPRODUCT(B4:B7,$E$4:$E$7) | C8: =SUMPRODUCT(C4:C7,$E$4:$E$7) | D8: =SUMPRODUCT(D4:D7,$E$4:$E$7)
A10: Spot price (EGP) | C10: =Assumptions!B4
A11: Upside to central base | C11: =C8/C10-1
A13: Read: broadly fairly valued after the 2026 re-rating closed the deep NAV discount; the swing factor is
A14: land monetisation and the holdco / minority discount, with the contracting-margin cycle behind it.

Sheet Fundamental Valuation
A1: Fundamental valuation — five lenses
A3: Lens | B3: Base (EGP) | C3: Weight | D3: Contribution
A4: Sum-of-the-parts / RNAV | B4: =Summary!C4 | C4: =Summary!E4 | D4: =B4*C4
A5: Consolidated DCF | B5: =Summary!C5 | C5: =Summary!E5 | D5: =B5*C5
A6: Relative multiples | B6: =Summary!C6 | C6: =Summary!E6 | D6: =B6*C6
A7: Property-cycle earnings | B7: =Summary!C7 | C7: =Summary!E7 | D7: =B7*C7
A8: Weighted central fair value | D8: =SUM(D4:D7)
A9: Spot | D9: =Assumptions!B4

Sheet Assumptions
A1: Assumptions — the single input layer
A2: All blue cells are inputs. Every other sheet links here.
A3: ANCHORS
A4: Spot price (EGP/share) | B4: 8.28
A5: Shares outstanding (mn) | B5: 1047.2
A6: Consolidated net debt (EGP mn) | B6: 5000 | C6: house estimate
A7: Minority interest (EGP mn) | B7: 3000 | C7: house estimate
A8: Risk-free rate (rf) | B8: 0.15
A9: Equity risk premium (ERP) | B9: 0.065
A10: Beta | B10: 1
A11: Cost of equity (Ke = rf + beta*ERP) | B11: =B8+B10*B9
A12: WACC (debt-blended) | B12: 0.185
A13: Terminal growth | B13: 0.1
A14: Tax rate | B14: 0.225
A16: SOTP — base marks (EGP mn, 100% basis)
A17: Development NAV (no terminal value) | B17: 15000
A18: Contracting arm | B18: 1500
A19: Rental / leasing portfolio | B19: 1500
A20: Retail & other | B20: 300
A21: Holdco / complexity discount | B21: 0.1 | C21: fair; market-implied ~16%
A23: RELATIVE & NORMALIZED
A24: Book value / share (EGP) | B24: 13.85
A25: Attributable EPS TTM (EGP) | B25: 0.35
A26: EBITDA TTM (EGP mn) | B26: 1400
A27: Target P/B (x) | B27: 0.55
A28: Target P/E (x) | B28: 8
A29: Target EV/EBITDA (x) | B29: 7
A30: Property-cycle fair value (EGP) | B30: 9.2
A32: SYNTHESIS WEIGHTS
A33: RNAV / SOTP weight | B33: 0.4
A34: DCF weight | B34: 0.2
A35: Relative weight | B35: 0.15
A36: Property-cycle weight | B36: 0.25
A38: FORECAST DRIVERS (FY26E–FY30E)
C39: FY26E | D39: FY27E | E39: FY28E | F39: FY29E | G39: FY30E
A40: Revenue growth | C40: 0.1 | D40: 0.15 | E40: 0.15 | F40: 0.15 | G40: 0.15
A41: EBITDA margin | C41: 0.24 | D41: 0.24 | E41: 0.24 | F41: 0.24 | G41: 0.24
A42: D&A (% of revenue) | C42: 0.02 | D42: 0.02 | E42: 0.02 | F42: 0.02 | G42: 0.02
A43: Capex (% of revenue) | C43: 0.03 | D43: 0.03 | E43: 0.03 | F43: 0.03 | G43: 0.03
A44: Δ working capital (% of Δrevenue) | C44: -0.03 | D44: -0.03 | E44: -0.03 | F44: -0.03 | G44: -0.03
...

Sheet SOTP
A1: Sum-of-the-parts / RNAV (primary lens)
A2: Split-leg: development legs carry NO terminal value; recurring legs get cap-rate. Links to Assumptions.
A3: Part | B3: Basis | C3: Value (EGP mn)
A4: Real-estate development (IVOIRE, Second Home, land bank) | B4: RNAV — PV of net development profit; no TV | C4: =Assumptions!B17
A5: Contracting arm | B5: Normalised earnings × multiple | C5: =Assumptions!B18
A6: Rental / leasing portfolio | B6: NOI / cap-rate (recurring) | C6: =Assumptions!B19
A7: Retail & other | B7: Book / residual | C7: =Assumptions!B20
A8: Σ Asset (enterprise) value | C8: =SUM(C4:C7)
A9: less: consolidated net debt | C9: =-Assumptions!B6
A10: less: minority interest | C10: =-Assumptions!B7
A11: Attributable NAV (pre-discount) | C11: =C8+C9+C10
A12: per share (EGP) | C12: =C11/Assumptions!B5
A13: less: holdco / complexity discount | C13: =-C11*Assumptions!B21
A14: RNAV equity value | C14: =C11+C13
A15: RNAV fair value per share (EGP) | C15: =C14/Assumptions!B5

Sheet Segments
A1: Segments — revenue mix (EGP mn)
A2: Contracting is the largest revenue line (~57% H1-24); real-estate sales ~37%, rental ~5%, retail ~1%.
A3: Segment | B3: FY24 rev | C3: % of rev | D3: Basis in SOTP
A4: Contracting | B4: 2850 | C4: 57% | D4: Going concern
A5: Real-estate sales | B5: 1850 | C5: 37% | D5: RNAV (dev leg)
A6: Rental / leasing | B6: 250 | C6: 5% | D6: Cap-rate
A7: Retail & other | B7: 50 | C7: 1% | D7: Book/residual
A8: Total | B8: =SUM(B4:B7)

Sheet Relative & Normalized
A1: Relative multiples
A2: P/B is the reliable anchor for an asset-heavy developer below book; P/E is depressed (mark the floor).
A3: Basis | B3: Multiple | C3: Implied EGP/share
A4: P/B on book value | B4: =Assumptions!B27 | C4: =Assumptions!B27*Assumptions!B24
A5: P/E on attributable EPS | B5: =Assumptions!B28 | C5: =Assumptions!B28*Assumptions!B25
A6: EV/EBITDA (net of debt & minority) | B6: =Assumptions!B29 | C6: =(Assumptions!B29*Assumptions!B26-Assumptions!B6-Assumptions!B7)/Assumptions!B5
A7: Blended relative (P/B-weighted) | C7: =0.70*C4+0.15*C5+0.15*MAX(C6,0)

Sheet DCF
A1: Discounted cash flow — explicit 5-year FCFF
A2: NOPAT + D&A − Capex − ΔWC, discounted at WACC. Ke shown as rf+ERP on Assumptions. Links to statements.
B3: FY26E | C3: FY27E | D3: FY28E | E3: FY29E | F3: FY30E
A4: EBIT | B4: ='Income Statement'!E10 | C4: ='Income Statement'!F10 | D4: ='Income Statement'!G10 | E4: ='Income Statement'!H10 | F4: ='Income Statement'!I10
A5: NOPAT = EBIT×(1−tax) | B5: =B4*(1-Assumptions!B14) | C5: =C4*(1-Assumptions!B14) | D5: =D4*(1-Assumptions!B14) | E5: =E4*(1-Assumptions!B14) | F5: =F4*(1-Assumptions!B14)
A6: + D&A | B6: =-'Income Statement'!E9 | C6: =-'Income Statement'!F9 | D6: =-'Income Statement'!G9 | E6: =-'Income Statement'!H9 | F6: =-'Income Statement'!I9
A7: − Capex | B7: =-'Income Statement'!E4*Assumptions!C43 | C7: =-'Income Statement'!F4*Assumptions!D43 | D7: =-'Income Statement'!G4*Assumptions!E43 | E7: =-'Income Statement'!H4*Assumptions!F43 | F7: =-'Income Statement'!I4*Assumptions!G43
A8: − Increase in net working capital | B8: =-('Income Statement'!E4-'Income Statement'!D4)*Assumptions!C44 | C8: =-('Income Statement'!F4-'Income Statement'!E4)*Assumptions!D44 | D8: =-('Income Statement'!G4-'Income Statement'!F4)*Assumptions!E44 | E8: =-('Income Statement'!H4-'Income Statement'!G4)*Assumptions!F44 | F8: =-('Income Statement'!I4-'Income Statement'!H4)*Assumptions!G44
A9: FCFF | B9: =B5+B6+B7+B8 | C9: =C5+C6+C7+C8 | D9: =D5+D6+D7+D8 | E9: =E5+E6+E7+E8 | F9: =F5+F6+F7+F8
A10: Discount factor | B10: =1/(1+Assumptions!B12)^1 | C10: =1/(1+Assumptions!B12)^2 | D10: =1/(1+Assumptions!B12)^3 | E10: =1/(1+Assumptions!B12)^4 | F10: =1/(1+Assumptions!B12)^5
A11: PV of FCFF | B11: =B9*B10 | C11: =C9*C10 | D11: =D9*D10 | E11: =E9*E10 | F11: =F9*F10
A13: Σ PV of explicit FCFF (FY26–30) | B13: =SUM(B11:F11)
A14: Terminal value (Gordon) | B14: =F9*(1+Assumptions!B13)/(Assumptions!B12-Assumptions!B13)
A15: PV of terminal value | B15: =B14/(1+Assumptions!B12)^5
A16: Enterprise value | B16: =B13+B15
A17: TV as % of EV | B17: =B15/B16
A18: less: consolidated net debt | B18: =-Assumptions!B6
A19: less: minority interest | B19: =-Assumptions!B7
A20: Equity value | B20: =B16+B18+B19
A21: DCF fair value per share (EGP) | B21: =B20/Assumptions!B5

Sheet Income Statement
A1: Income statement (consolidated, EGP mn)
A2: FY2023–FY2025 as reported (EGX filings, company releases); FY26E–FY30E link to Assumptions drivers.
B3: FY23 | C3: FY24 | D3: FY25 | E3: FY26E | F3: FY27E | G3: FY28E | H3: FY29E | I3: FY30E
A4: Revenue | B4: 5780 | C4: 5000 | D4: 6400 | E4: =D4*(1+Assumptions!C40) | F4: =E4*(1+Assumptions!D40) | G4: =F4*(1+Assumptions!E40) | H4: =G4*(1+Assumptions!F40) | I4: =H4*(1+Assumptions!G40)
A5: COGS | B5: =-B4*0.70 | C5: =-C4*0.70 | D5: =-D4*0.70 | E5: =-E4*(1-0.30) | F5: =-F4*(1-0.30) | G5: =-G4*(1-0.30) | H5: =-H4*(1-0.30) | I5: =-I4*(1-0.30)
A6: Gross profit | B6: =B4+B5 | C6: =C4+C5 | D6: =D4+D5 | E6: =E4+E5 | F6: =F4+F5 | G6: =G4+G5 | H6: =H4+H5 | I6: =I4+I5
A7: SG&A & other opex | B7: =-B4*0.08 | C7: =-C4*0.08 | D7: =-D4*0.08 | E7: =-E4*0.08 | F7: =-F4*0.08 | G7: =-G4*0.08 | H7: =-H4*0.08 | I7: =-I4*0.08
A8: EBITDA | B8: =B6+B7 | C8: =C6+C7 | D8: =D6+D7 | E8: =E4*Assumptions!C41 | F8: =F4*Assumptions!D41 | G8: =G4*Assumptions!E41 | H8: =H4*Assumptions!F41 | I8: =I4*Assumptions!G41
A9: D&A | B9: =-B4*0.02 | C9: =-C4*0.02 | D9: =-D4*0.02 | E9: =-E4*Assumptions!C42 | F9: =-F4*Assumptions!D42 | G9: =-G4*Assumptions!E42 | H9: =-H4*Assumptions!F42 | I9: =-I4*Assumptions!G42
A10: EBIT | B10: =B8+B9 | C10: =C8+C9 | D10: =D8+D9 | E10: =E8+E9 | F10: =F8+F9 | G10: =G8+G9 | H10: =H8+H9 | I10: =I8+I9
A11: Net finance cost | B11: -900 | C11: -1050 | D11: -1200 | E11: =-E4*0.13 | F11: =-F4*0.13 | G11: =-G4*0.13 | H11: =-H4*0.13 | I11: =-I4*0.13
A12: Other income / associates | B12: 600 | C12: 1900 | D12: 650 | E12: 300 | F12: 300 | G12: 300 | H12: 300 | I12: 300
A13: Pre-tax profit | B13: =B10+B11+B12 | C13: =C10+C11+C12 | D13: =D10+D11+D12 | E13: =E10+E11+E12 | F13: =F10+F11+F12 | G13: =G10+G11+G12 | H13: =H10+H11+H12 | I13: =I10+I11+I12
A14: Tax | B14: =-B13*Assumptions!B14 | C14: =-C13*Assumptions!B14 | D14: =-D13*Assumptions!B14 | E14: =-E13*Assumptions!B14 | F14: =-F13*Assumptions!B14 | G14: =-G13*Assumptions!B14 | H14: =-H13*Assumptions!B14 | I14: =-I13*Assumptions!B14
A15: Net profit after tax (consolidated) | B15: =B13+B14 | C15: =C13+C14 | D15: =D13+D14 | E15: =E13+E14 | F15: =F13+F14 | G15: =G13+G14 | H15: =H13+H14 | I15: =I13+I14
A16: less: minority interest | B16: -257 | C16: 10 | D16: -312 | E16: =-E15*0.30 | F16: =-F15*0.30 | G16: =-G15*0.30 | H16: =-H15*0.30 | I16: =-I15*0.30
A17: Attributable to parent | B17: =B15+B16 | C17: =C15+C16 | D17: =D15+D16 | E17: =E15+E16 | F17: =F15+F16 | G17: =G15+G16 | H17: =H15+H16 | I17: =I15+I16
A19: Reported NPAT (consolidated), disclosed | B19: 557 | C19: 1260 | D19: 674

Sheet Balance Sheet
A1: Balance sheet (consolidated, EGP mn)
A2: Selected lines; several splits are house estimates to balance to disclosed totals (assets ~54bn, equity attr. ~13.5bn H1-24).
B3: FY23 | C3: FY24 | D3: FY25 | E3: FY26E | F3: FY27E | G3: FY28E | H3: FY29E | I3: FY30E
A4: Cash & equivalents | B4: 4200 | C4: 5000 | D4: 5600 | E4: 6000 | F4: 6500 | G4: 7000 | H4: 7600 | I4: 8300
A5: Trade & installment receivables | B5: 8000 | C5: 9500 | D5: 11000 | E5: 12200 | F5: 13900 | G5: 15900 | H5: 18100 | I5: 20700
A6: Development inventory / WIP & land | B6: 26000 | C6: 30000 | D6: 33000 | E6: 35000 | F6: 37500 | G6: 40000 | H6: 42500 | I6: 45000
A7: Investment property & PP&E | B7: 4500 | C7: 5000 | D7: 5300 | E7: 5500 | F7: 5700 | G7: 5900 | H7: 6100 | I7: 6300
A8: Other assets | B8: 4300 | C8: 4500 | D8: 4600 | E8: 4700 | F8: 4800 | G8: 4900 | H8: 5000 | I8: 5100
A9: Total assets | B9: =B4+B5+B6+B7+B8 | C9: =C4+C5+C6+C7+C8 | D9: =D4+D5+D6+D7+D8 | E9: =E4+E5+E6+E7+E8 | F9: =F4+F5+F6+F7+F8 | G9: =G4+G5+G6+G7+G8 | H9: =H4+H5+H6+H7+H8 | I9: =I4+I5+I6+I7+I8
A10: Borrowings (financial debt) | B10: 9000 | C10: 10000 | D10: 10600 | E10: 11200 | F10: 11700 | G10: 12100 | H10: 12300 | I10: 12400
A11: Customer advances / deferred revenue | B11: 16000 | C11: 19000 | D11: 21000 | E11: 22800 | F11: 25000 | G11: 27400 | H11: 30000 | I11: 32800
A12: Trade payables & provisions | B12: 9500 | C12: 11000 | D12: 11800 | E12: 12300 | F12: 12900 | G12: 13500 | H12: 14100 | I12: 14700
A13: Total liabilities | B13: =B10+B11+B12 | C13: =C10+C11+C12 | D13: =D10+D11+D12 | E13: =E10+E11+E12 | F13: =F10+F11+F12 | G13: =G10+G11+G12 | H13: =H10+H11+H12 | I13: =I10+I11+I12
A14: Minority interest | B14: 6000 | C14: 6800 | D14: 7000 | E14: 7100 | F14: 7200 | G14: 7300 | H14: 7400 | I14: 7500
A15: Equity attributable to parent | B15: =B9-B13-B14 | C15: =C9-C13-C14 | D15: =D9-D13-D14 | E15: =E9-E13-E14 | F15: =F9-F13-F14 | G15: =G9-G13-G14 | H15: =H9-H13-H14 | I15: =I9-I13-I14

Sheet Cash Flow
A1: Cash flow (consolidated, EGP mn)
A2: Indirect method; forecast links to Income Statement, Balance Sheet and Assumptions.
B3: FY26E | C3: FY27E | D3: FY28E | E3: FY29E | F3: FY30E
A4: NOPAT (EBIT×(1−t)) | B4: ='Income Statement'!E10*(1-Assumptions!B14) | C4: ='Income Statement'!F10*(1-Assumptions!B14) | D4: ='Income Statement'!G10*(1-Assumptions!B14) | E4: ='Income Statement'!H10*(1-Assumptions!B14) | F4: ='Income Statement'!I10*(1-Assumptions!B14)
A5: + D&A | B5: =-'Income Statement'!E9 | C5: =-'Income Statement'!F9 | D5: =-'Income Statement'!G9 | E5: =-'Income Statement'!H9 | F5: =-'Income Statement'!I9
A6: − Capex | B6: =-'Income Statement'!E4*Assumptions!C43 | C6: =-'Income Statement'!F4*Assumptions!D43 | D6: =-'Income Statement'!G4*Assumptions!E43 | E6: =-'Income Statement'!H4*Assumptions!F43 | F6: =-'Income Statement'!I4*Assumptions!G43
A7: − Δ working capital | B7: =-('Income Statement'!E4-'Income Statement'!D4)*Assumptions!C44 | C7: =-('Income Statement'!F4-'Income Statement'!E4)*Assumptions!D44 | D7: =-('Income Statement'!G4-'Income Statement'!F4)*Assumptions!E44 | E7: =-('Income Statement'!H4-'Income Statement'!G4)*Assumptions!F44 | F7: =-('Income Statement'!I4-'Income Statement'!H4)*Assumptions!G44
A8: Free cash flow to firm | B8: =B4+B5+B6+B7 | C8: =C4+C5+C6+C7 | D8: =D4+D5+D6+D7 | E8: =E4+E5+E6+E7 | F8: =F4+F5+F6+F7

Sheet Summary Financials
A1: Summary financials (links to statement sheets, EGP mn)
B3: FY23 | C3: FY24 | D3: FY25 | E3: FY26E | F3: FY27E | G3: FY28E | H3: FY29E | I3: FY30E
A4: Revenue | B4: ='Income Statement'!B4 | C4: ='Income Statement'!C4 | D4: ='Income Statement'!D4 | E4: ='Income Statement'!E4 | F4: ='Income Statement'!F4 | G4: ='Income Statement'!G4 | H4: ='Income Statement'!H4 | I4: ='Income Statement'!I4
A5: EBITDA | B5: ='Income Statement'!B8 | C5: ='Income Statement'!C8 | D5: ='Income Statement'!D8 | E5: ='Income Statement'!E8 | F5: ='Income Statement'!F8 | G5: ='Income Statement'!G8 | H5: ='Income Statement'!H8 | I5: ='Income Statement'!I8
A6: EBIT | B6: ='Income Statement'!B10 | C6: ='Income Statement'!C10 | D6: ='Income Statement'!D10 | E6: ='Income Statement'!E10 | F6: ='Income Statement'!F10 | G6: ='Income Statement'!G10 | H6: ='Income Statement'!H10 | I6: ='Income Statement'!I10
A7: Net profit (consolidated) | B7: ='Income Statement'!B15 | C7: ='Income Statement'!C15 | D7: ='Income Statement'!D15 | E7: ='Income Statement'!E15 | F7: ='Income Statement'!F15 | G7: ='Income Statement'!G15 | H7: ='Income Statement'!H15 | I7: ='Income Statement'!I15
A8: Attributable to parent | B8: ='Income Statement'!B17 | C8: ='Income Statement'!C17 | D8: ='Income Statement'!D17 | E8: ='Income Statement'!E17 | F8: ='Income Statement'!F17 | G8: ='Income Statement'!G17 | H8: ='Income Statement'!H17 | I8: ='Income Statement'!I17
A9: Total assets | B9: ='Balance Sheet'!B9 | C9: ='Balance Sheet'!C9 | D9: ='Balance Sheet'!D9 | E9: ='Balance Sheet'!E9 | F9: ='Balance Sheet'!F9 | G9: ='Balance Sheet'!G9 | H9: ='Balance Sheet'!H9 | I9: ='Balance Sheet'!I9
A10: Equity attributable | B10: ='Balance Sheet'!B15 | C10: ='Balance Sheet'!C15 | D10: ='Balance Sheet'!D15 | E10: ='Balance Sheet'!E15 | F10: ='Balance Sheet'!F15 | G10: ='Balance Sheet'!G15 | H10: ='Balance Sheet'!H15 | I10: ='Balance Sheet'!I15

Sheet Monte Carlo
A1: Monte Carlo — probabilistic price map (illustrative)
A2: YZ-HAR width · unit-variance t(5) · EGX-developer secular drift (floored) · 16 factors · 50k paths · seed 42.
A3: Step 0 is marginal (see study Appendix B); this section is presented as an illustrative map, not a calibrated forecast.
A5: Probability read (T+60, same 50,000 paths)
A6: P(price > spot) | B6: 0.609
A7: P(+10%) vs P(−10%) | B7: 44% vs 23% (odds 1.89)
A8: Median level / move | B8: EGP 8.81 (+6.4%)
A9: 50% band (25th–75th) | B9: EGP 7.55 – 10.25 (-9% / +24%)
A10: Touch(+10%) / Touch(−10%) | B10: 70% / 50%
A12: Percentile map (EGP/share)
A13: Horizon | B13: p5 | C13: p25 | D13: p50 | E13: p75 | F13: p95
A14: T+20 | B14: 6.63 | C14: 7.74 | D14: 8.45 | E14: 9.24 | F14: 10.68
A15: T+60 | B15: 5.86 | C15: 7.55 | D15: 8.81 | E15: 10.25 | F15: 13.17

Sheet Sensitivity
A1: Sensitivity
A2: RNAV to development-leg NAV × holdco discount; and DCF fair value to WACC × terminal growth.
A4: RNAV (EGP/share) — development NAV (EGP bn, cols) × discount (rows)
B5: 11 | C5: 13 | D5: 15 | E5: 17 | F5: 19
A6: 20% | B6: 4.81 | C6: 6.34 | D6: 7.87 | E6: 9.4 | F6: 10.92
A7: 15% | B7: 5.11 | C7: 6.74 | D7: 8.36 | E7: 9.98 | F7: 11.61
A8: 10% | B8: 5.41 | C8: 7.13 | D8: 8.85 | E8: 10.57 | F8: 12.29
A9: 5% | B9: 5.72 | C9: 7.53 | D9: 9.34 | E9: 11.16 | F9: 12.97
A10: 0% | B10: 6.02 | C10: 7.93 | D10: 9.84 | E10: 11.75 | F10: 13.66
A12: DCF (EGP/share) — WACC (rows) × terminal g (cols)
B13: 8% | C13: 9% | D13: 10% | E13: 11% | F13: 12%
A14: 16.5% | B14: 8.42 | C14: 10.07 | D14: 12.22 | E14: 15.16 | F14: 19.4
A15: 18.0% | B15: 5.93 | C15: 7.04 | D15: 8.42 | E15: 10.2 | F15: 12.58
A16: 18.5% | B16: 5.26 | C16: 6.24 | D16: 7.46 | E16: 8.99 | F16: 11.01
A17: 19.0% | B17: 4.65 | C17: 5.53 | D17: 6.6 | E17: 7.94 | F17: 9.66
A18: 20.5% | B18: 3.11 | C18: 3.75 | D18: 4.51 | E18: 5.43 | F18: 6.57

Sheet Per-Share & Ratios
A1: Per-Share & Ratios — the standardized dashboard
A3: Metric | B3: Value
A4: Spot (EGP) | B4: =Assumptions!B4
A5: Weighted central fair value (EGP) | B5: ='Fundamental Valuation'!D8
A6: Upside to central | B6: =B5/B4-1
A7: RNAV / share (EGP) | B7: =SOTP!C15
A8: BVPS (EGP) | B8: =Assumptions!B24
A9: P/B (x) | B9: =B4/B8
A10: Attributable EPS TTM (EGP) | B10: =Assumptions!B25
A11: P/E (x) | B11: =B4/B10
A12: EV/EBITDA (x) | B12: =(B4*Assumptions!B5+Assumptions!B6+Assumptions!B7)/Assumptions!B26
A13: Cost of equity Ke | B13: =Assumptions!B8+Assumptions!B10*Assumptions!B9
A14: WACC | B14: =Assumptions!B12
A15: Net debt / EBITDA (x) | B15: =Assumptions!B6/Assumptions!B26
A16: Dividend / share | B16: 0.00 (no dividend)

Sheet Peer & Sector
A1: Peer set & sector
A3: Peer (EGX developer) | B3: Typical valuation basis | C3: Note
A4: TMG Holding (TMGH) | B4: P/NAV, presales-driven | C4: Sector bellwether
A5: Palm Hills (PHDC) | B5: RNAV / P/B | C5: Mid-cap developer
A6: Emaar Misr (EMFD) | B6: RNAV / cap-rate mix | C6: Recurring + development
A7: Heliopolis Housing (HELI) | B7: Land-monetisation NAV | C7: Land-rich
A8: SODIC (OCDI) | B8: RNAV | C8: New-Cairo/coast developer
A10: Sector: EGX developers are in an inflation-driven presales boom; PRDC blends development + a large
A11: contracting arm + a majority-owned listed subsidiary; principal risks are rates, EGP, and the holdco/minority discount.
