Workbook

Sheet READ FIRST
A1: READ FIRST — DISCLOSURE & DISCLAIMER (educational valuation study — not investment advice)
A2: NATURE OF THIS WORKBOOK
A3: This workbook is an educational valuation exercise and an expression of the preparer's personal analytical opinion, based exclusively on publicly available information and on the assumptions stated in the text and this model. It is published free of charge to demonstrate methodology and to invite scrutiny of that methodology.
A5: NO ADVICE, NO RECOMMENDATION, NO SOLICITATION
A6: Nothing here constitutes investment advice, financial consultancy, securities analysis, a research recommendation, a rating, a price target, an offer, or a solicitation to buy, sell or hold any security. No statement is directed at the objectives, situation or needs of any person.
A8: NO LICENSED ACTIVITY
A9: The preparer is not licensed or registered with any securities regulator, carries on no regulated activity, manages no money, and accepts no clients, fees or funds.
A11: ESTIMATES AND UNCERTAINTY
A12: All values are model outputs resting on explicit, subjective assumptions; they are illustrative, highly uncertain and likely to prove wrong in material respects. Qalaa's reported financials are company disclosure; the FORWARD assumptions — the holding-company discount, the marks on unlisted subsidiaries (Qalaa Entertainment, Qalaa Mobility), the value of the core QalaaTalk platform, and the multiples applied — are the preparer's judgments. Presented as ranges and distributions because no single number should be relied on.
A14: NO LIABILITY / READER'S RESPONSIBILITY
A15: To the maximum extent permitted by law, the preparer accepts no liability for any decision, action or loss in reliance on this workbook. Any person considering an investment decision should conduct their own assessment and consult a licensed advisor.
A17: HOLDINGS DISCLOSURE
... A21: Blue cells are hardcoded inputs (edit to your own view); black cells are formulas; green cells link across sheets. The valuation is a holding-company sum-of-the-parts: listed stakes at market value, unlisted subsidiaries at transaction-implied marks, the core QalaaTalk operating business on a multiple, plus parent net cash, less a holding-company discount — cross-checked against a consolidated DCF, relative multiples and normalized earnings. Currency is KRW unless stated; valuation in KRW trillion, per-share in KRW.

Sheet Summary
A1: QALAA HOLDINGS (EGX: CCAP) — VALUATION SUMMARY
A2: Holding-company SOTP (economic stakes) + DCF cross-check + relative + normalized + 16-factor Monte Carlo.
A4: HEADLINE — VALUE PER SHARE (EGP)
A5: Weighted central fundamental | B5: ='Fundamental Valuation'!B11 -> 5.8886877
A6: SOTP base (30% discount) | B6: =SOTP!B17 -> 5.93792
A7: SOTP bull (18% discount) | B7: =SOTP!C17 -> 8.5989886
A8: SOTP bear (45% discount) | B8: =SOTP!D17 -> 3.2946755
A9: Consolidated DCF (FCFF) | B9: =DCF!B24 -> 4.0601082
A10: Market price (30-Jun-26) | B10: =Assumptions!B5 -> 4.77
A11: Spot discount to central | B11: =B10/B5-1 -> -0.18997233
A13: WHAT THE NUMBER RESTS ON (edit on Assumptions)
A14: Gross NAV per share (EGP) | B14: =SOTP!B15 -> 8.4827429
A15: Base holdco discount | B15: =Assumptions!B29 -> 0.3
A16: Implied discount to NAV at spot | B16: =Assumptions!B5/B14-1 -> -0.43768188
A17: DCF WACC | B17: =Assumptions!B50 -> 0.2
A19: METHODOLOGY
A20: - Holding-company SOTP on ECONOMIC-INTEREST basis — ERC at Qalaa 13.14%, not consolidated (avoids the minority overstatement).
A21: - The holding-company discount is the dominant swing factor; base 30%, bull 18%, bear 45%.
A22: - Consolidated DCF (FCFF) is a deliberately narrow cross-check on attributable operating cash; it lands below SOTP/spot.
A23: - Relative & normalized on attributable (ex-minority) net, since consolidated EBITDA is ~87% ERC minority.
A24: - Spot sits ~24% below the weighted central — the wide discount to NAV is the whole debate.
A25: - Reported financials are company disclosure (qualified FY2024 audit, going-concern emphasis); marks & discount are the preparer judgments.
A26: - Monte Carlo (16 factors, 50k paths, seed 42) maps the 3-month price; median ~flat, very wide cone (~47% realized vol).

Sheet Fundamental Valuation
A1: FUNDAMENTAL VALUATION — FIVE METHODS
A2: Holding-company SOTP (primary, economic-interest) + DCF cross-check + relative + normalized.
A4: THE METHODS — value per share (EGP)
A5: Method | B5: EGP/sh | C5: vs spot | D5: Weight | E5: Note
A6: SOTP — base (30% discount) | B6: =SOTP!B17 -> 5.93792 | C6: =B6/Assumptions!$B$5-1 -> 0.24484696 | D6: =Assumptions!B43 -> 0.3 | E6: primary lens
A7: SOTP — bull (18% discount) | B7: =SOTP!C17 -> 8.5989886 | C7: =B7/Assumptions!$B$5-1 -> 0.80272297 | D7: =Assumptions!B44 -> 0.12 | E7: ceiling if discount compresses
A8: Consolidated DCF (FCFF) | B8: =DCF!B24 -> 4.0601082 | C8: =B8/Assumptions!$B$5-1 -> -0.14882428 | D8: =Assumptions!B45 -> 0.13 | E8: narrow cash-flow cross-check
A9: Relative multiples | B9: ='Relative & Normalized'!B7 -> 5 | C9: =B9/Assumptions!$B$5-1 -> 0.048218029 | D9: =Assumptions!B46 -> 0.2 | E9: attributable net × multiple
A10: Normalized earnings power | B10: ='Relative & Normalized'!B12 -> 6.1904762 | C10: =B10/Assumptions!$B$5-1 -> 0.29779375 | D10: =Assumptions!B47 -> 0.25 | E10: through-cycle discipline
A11: WEIGHTED CENTRAL FUNDAMENTAL VALUE | B11: =SUMPRODUCT(B6:B10,D6:D10) -> 5.8886877 | C11: =B11/Assumptions!$B$5-1 -> 0.23452573 | D11: =SUM(D6:D10) -> 1
A12: Memo: spot price (30-Jun-26) | B12: =Assumptions!B5 -> 4.77
A13: Spot discount to central | B13: =B12/B11-1 -> -0.18997233 | E13: market prices a wide holdco discount to NAV
A15: RANGE: bear (wide discount) → bull (discount compression)
A16: Bear / wide-discount floor (SOTP bear) | B16: =SOTP!D17 -> 3.2946755
A17: Bull / discount-compression ceiling (SOTP bull) | B17: =SOTP!C17 -> 8.5989886

Sheet Assumptions
A1: QALAA HOLDINGS (EGX: CCAP) — ASSUMPTIONS
A2: All blue cells are inputs. EGP billion unless noted. SOTP on ECONOMIC-INTEREST basis (Qalaa share of each asset).
A4: GLOBAL & CORPORATE
A5: Spot price (EGP, 30-Jun-26 close) | B5: 4.77
A6: Shares outstanding (bn, post Oct-25 increase) | B6: 4.2
A7: Tax rate (effective) | B7: 0.225
A8: USD/EGP | B8: 49
A10: SOTP — ENERGY PLATFORM (economic stakes, EGP bn)
A11: Item | B11: Stake % | C11: Base | D11: Bull | E11: Bear
A12: ERC EV (refinery) | C12: 107.8 | D12: 125 | E12: 86.6
A13: ERC net debt | C13: 41 | D13: 41 | E13: 41
A14: ERC economic stake % | B14: 0.1314
A15: TAQA Arabia EBITDA | C15: 5 | D15: 5.4 | E15: 4.5
A16: TAQA EV/EBITDA (x) | C16: 5 | D16: 5.3 | E16: 4.7
A17: TAQA net debt | C17: 8 | D17: 7.7 | E17: 8.3
A18: TAQA stake % | B18: 0.55
A20: SOTP — OTHER PLATFORMS (attributable equity, EGP bn)
A21: Platform | C21: Base | D21: Bull | E21: Bear
A22: ASCOM / GlassRock (mining) | C22: 6 | D22: 6.8 | E22: 5
A23: ASEC / cement (Al-Takamol, Zahana) | C23: 5 | D23: 5.7 | E23: 4
A24: Dina Farms / agrifoods | C24: 7 | D24: 8 | E24: 5.8
A25: Transport & Logistics (CCTO/NRPMC) | C25: 3.5 | D25: 4 | E25: 2.8
A26: Other / smaller platforms | C26: 2 | D26: 2.5 | E26: 1.5
A28: HOLDCO DISCOUNT & RECOURSE DEBT (EGP bn)
A29: Holdco discount — base | B29: 0.3
A30: Holdco discount — bull | B30: 0.18
A31: Holdco discount — bear | B31: 0.45
A32: Holdco recourse net debt — base | B32: 6
A33: Holdco recourse net debt — bull | B33: 5.5
A34: Holdco recourse net debt — bear | B34: 7
A36: RELATIVE & NORMALIZED (EGP bn)
A37: Normalized attributable net (relative) | B37: 3.5
A38: Relative P/E (x) | B38: 6
A39: Normalized through-cycle net | B39: 4
A40: Normalized justified P/E (x) | B40: 6.5
A42: FIVE-METHOD WEIGHTS
A43: SOTP — base | B43: 0.3
A44: SOTP — bull | B44: 0.12
A45: Consolidated DCF (FCFF) | B45: 0.13
A46: Relative multiples | B46: 0.2
...

Sheet SOTP
A1: SUM-OF-THE-PARTS — holding-company NAV (economic-interest basis; base / bull / bear)
A2: ERC & TAQA at Qalaa economic stake net of their own debt; platforms at attributable equity; less holdco recourse debt, less discount.
A4: Asset | B4: Base (bn) | C4: Bull (bn) | D4: Bear (bn) | E4: Basis
A5: ERC — 13.14% economic | B5: =(Assumptions!C12-Assumptions!C13)*Assumptions!$B$14 -> 8.77752 | C5: =(Assumptions!D12-Assumptions!C13)*Assumptions!$B$14 -> 11.0376 | D5: =(Assumptions!E12-Assumptions!C13)*Assumptions!$B$14 -> 5.99184 | E5: unlisted; refinery net of ERC debt
A6: TAQA Arabia — 55% (associate) | B6: =(Assumptions!C15*Assumptions!C16-Assumptions!C17)*Assumptions!$B$18 -> 9.35 | C6: =(Assumptions!D15*Assumptions!D16-Assumptions!D17)*Assumptions!$B$18 -> 11.506 | D6: =(Assumptions!E15*Assumptions!E16-Assumptions!E17)*Assumptions!$B$18 -> 7.0675 | E6: equity-method; energy distribution
A7: ASCOM / GlassRock (mining) | B7: =Assumptions!C22 -> 6 | C7: =Assumptions!D22 -> 6.8 | D7: =Assumptions!E22 -> 5 | E7: attributable equity mark
A8: ASEC / cement (Al-Takamol, Zahana) | B8: =Assumptions!C23 -> 5 | C8: =Assumptions!D23 -> 5.7 | D8: =Assumptions!E23 -> 4 | E8: attributable equity mark
A9: Dina Farms / agrifoods | B9: =Assumptions!C24 -> 7 | C9: =Assumptions!D24 -> 8 | D9: =Assumptions!E24 -> 5.8 | E9: attributable equity mark
A10: Transport & Logistics (CCTO/NRPMC) | B10: =Assumptions!C25 -> 3.5 | C10: =Assumptions!D25 -> 4 | D10: =Assumptions!E25 -> 2.8 | E10: attributable equity mark
A11: Other / smaller platforms | B11: =Assumptions!C26 -> 2 | C11: =Assumptions!D26 -> 2.5 | D11: =Assumptions!E26 -> 1.5 | E11: attributable equity mark
A12: Gross asset value (EGP bn) | B12: =SUM(B5:B11) -> 41.62752 | C12: =SUM(C5:C11) -> 49.5436 | D12: =SUM(D5:D11) -> 32.15934
A13: (−) Holdco recourse net debt | B13: =-Assumptions!B32 -> -6 | C13: =-Assumptions!B33 -> -5.5 | D13: =-Assumptions!B34 -> -7
A14: NAV (EGP bn) | B14: =B12+B13 -> 35.62752 | C14: =C12+C13 -> 44.0436 | D14: =D12+D13 -> 25.15934
A15: NAV / share (EGP) | B15: =B14/Assumptions!$B$6 -> 8.4827429 | C15: =C14/Assumptions!$B$6 -> 10.486571 | D15: =D14/Assumptions!$B$6 -> 5.990319
A16: (−) Holdco discount | B16: =Assumptions!B29 -> 0.3 | C16: =Assumptions!B30 -> 0.18 | D16: =Assumptions!B31 -> 0.45
A17: VALUE / SHARE (EGP) | B17: =B15*(1-B16) -> 5.93792 | C17: =C15*(1-C16) -> 8.5989886 | D17: =D15*(1-D16) -> 3.2946755
A18: vs spot | B18: =B17/Assumptions!$B$5-1 -> 0.24484696 | C18: =C17/Assumptions!$B$5-1 -> 0.80272297 | D18: =D17/Assumptions!$B$5-1 -> -0.30929235
A19: Base = 30% holdco discount on economic-stake NAV; discount is the swing factor. ERC carried at 13.14% economic interest, not consolidated.

Sheet Segments
A1: SEGMENTS / PLATFORMS
A2: Energy (ERC consolidated + TAQA associate) dominates; smaller platforms in mining, cement, agrifoods, transport.
A4: Platform | B4: Treatment | C4: Qalaa stake | D4: Note
A5: ERC (refining) | B5: fully consolidated (IFRS 10) | C5: 13.14% economic | D5: ~91% of consolidated revenue; minority ~87%
A6: TAQA Arabia | B6: equity-method associate | C6: ~55% | D6: deconsolidated end-2023; energy distribution
A7: ASCOM / GlassRock | B7: consolidated | C7: majority | D7: mining, quarrying, glass
A8: ASEC / cement | B8: consolidated | C8: ~99% | D8: Al-Takamol (Sudan), Zahana
A9: Dina Farms / agrifoods | B9: consolidated | C9: majority | D9: dairy, farms, ICDP
A10: Transport & Logistics | B10: consolidated | C10: ~92-93% | D10: CCTO, NRPMC, river barges
A11: Printing & Packaging | B11: discontinued (2024) | C11: — | D11: deconsolidated; ~9.9bn one-off gain
A12: The split that matters for valuation: ERC is "gross" (consolidated, minority deducted below the line) while TAQA is "net" (only Qalaa share via associate income). The SOTP carries both at economic stake.

Sheet Relative & Normalized
A1: RELATIVE MULTIPLES & NORMALIZED EARNINGS POWER
A2: On attributable (ex-minority) metrics — consolidated EBITDA is ~87% ERC minority, so attributable basis is used.
A4: RELATIVE MULTIPLES (EGP bn unless noted)
A5: Normalized attributable net (EGP bn) | B5: =Assumptions!B37 -> 3.5
A6: Relative P/E (x) | B6: =Assumptions!B38 -> 6
A7: RELATIVE VALUE / SHARE (EGP) | B7: =B5*B6/Assumptions!$B$6 -> 5
A9: NORMALIZED THROUGH-CYCLE EARNINGS POWER
A10: Normalized net profit (EGP bn) | B10: =Assumptions!B39 -> 4
A11: Justified P/E (x) | B11: =Assumptions!B40 -> 6.5
A12: NORMALIZED VALUE / SHARE (EGP) | B12: =B10*B11/Assumptions!$B$6 -> 6.1904762
A14: Relative blends a modest 6x P/E on normalized attributable net; normalized lens lifts the multiple to 6.5x. Both deliberately exclude the asset-mark uplift the SOTP captures.

Sheet DCF
A1: CONSOLIDATED DCF — bottom-up unlevered FCFF from the projected statements (cross-check)
A2: FCFF = EBIT×(1−tax) + D&A − capex − ΔWC, built line-by-line from the Income Statement & Cash Flow forecast columns (2026e-2030e), discounted at the EGP WACC. Deliberately excludes the SOTP asset-mark uplift, so it lands below SOTP/spot. Attributable basis.
A4: EGP bn | B4: 2026 | C4: 2027 | D4: 2028 | E4: 2029 | F4: 2030
A5: Operating profit (EBIT, consolidated) | B5: ='Income Statement'!E11 -> 11 | C5: ='Income Statement'!F11 -> 14 | D5: ='Income Statement'!G11 -> 17 | E5: ='Income Statement'!H11 -> 19.5 | F5: ='Income Statement'!I11 -> 22
A6: attributable factor (Qalaa economic share, blended) | B6: 0.15 | C6: 0.15 | D6: 0.15 | E6: 0.15 | F6: 0.15
A7: Attributable EBIT | B7: =B5*B6 -> 1.65 | C7: =C5*C6 -> 2.1 | D7: =D5*D6 -> 2.55 | E7: =E5*E6 -> 2.925 | F7: =F5*F6 -> 3.3
A8: (−) Tax @ DCF rate | B8: =-B7*Assumptions!$B$54 -> -0.37125 | C8: =-C7*Assumptions!$B$54 -> -0.4725 | D8: =-D7*Assumptions!$B$54 -> -0.57375 | E8: =-E7*Assumptions!$B$54 -> -0.658125 | F8: =-F7*Assumptions!$B$54 -> -0.7425
A9: NOPAT (attributable) | B9: =B7+B8 -> 1.27875 | C9: =C7+C8 -> 1.6275 | D9: =D7+D8 -> 1.97625 | E9: =E7+E8 -> 2.266875 | F9: =F7+F8 -> 2.5575
A10: (+) D&A (attributable share) | B10: =-'Income Statement'!E10*B6 -> 1.95 | C10: =-'Income Statement'!F10*C6 -> 2.025 | D10: =-'Income Statement'!G10*D6 -> 2.1 | E10: =-'Income Statement'!H10*E6 -> 2.175 | F10: =-'Income Statement'!I10*F6 -> 2.25
A11: (−) Capex (attributable share) | B11: ='Cash Flow'!E6*B6 -> -1.35 | C11: ='Cash Flow'!F6*C6 -> -1.425 | D11: ='Cash Flow'!G6*D6 -> -1.5 | E11: ='Cash Flow'!H6*E6 -> -1.575 | F11: ='Cash Flow'!I6*F6 -> -1.65
A12: (−) Δ Working capital | B12: -0.3 | C12: -0.3 | D12: -0.3 | E12: -0.3 | F12: -0.3
A13: Unlevered FCFF (attributable) | B13: =B9+B10+B11+B12 -> 1.57875 | C13: =C9+C10+C11+C12 -> 1.9275 | D13: =D9+D10+D11+D12 -> 2.27625 | E13: =E9+E10+E11+E12 -> 2.566875 | F13: =F9+F10+F11+F12 -> 2.8575
A14: Discount factor @ WACC | B14: =1/(1+Assumptions!$B$50)^1 -> 0.83333333 | C14: =1/(1+Assumptions!$B$50)^2 -> 0.69444444 | D14: =1/(1+Assumptions!$B$50)^3 -> 0.5787037 | E14: =1/(1+Assumptions!$B$50)^4 -> 0.48225309 | F14: =1/(1+Assumptions!$B$50)^5 -> 0.40187757
A15: PV of FCFF | B15: =B13*B14 -> 1.315625 | C15: =C13*C14 -> 1.3385417 | D15: =D13*D14 -> 1.3172743 | E15: =E13*E14 -> 1.2378834 | F15: =F13*F14 -> 1.1483652
A17: PV of explicit FCFF (2026e-2030e) | B17: =SUM(B15:F15) -> 6.3576895
A18: Terminal value (Gordon, normalized FCFF) | B18: =F13*(1+Assumptions!B51)/(Assumptions!B50-Assumptions!B51) -> 21.635357
A19: PV of terminal value | B19: =B18/(1+Assumptions!B50)^5 -> 8.6947648
A20: Enterprise value (operating) | B20: =B17+B19 -> 15.052454
A21: (+) Parent net cash | B21: =Assumptions!B53 -> 2
A22: Equity value (EGP bn) | B22: =B20+B21 -> 17.052454
A23: Shares (bn) | B23: =Assumptions!B6 -> 4.2
A24: VALUE / SHARE (EGP) | B24: =B22/B23 -> 4.0601082
A25: vs spot | B25: =B24/Assumptions!B5-1 -> -0.14882428

Sheet Income Statement
A1: QALAA HOLDINGS — CONSOLIDATED INCOME STATEMENT (EGP bn)
A2: 2023a-2024a are Qalaa consolidated disclosure (FY2024 qualified). 2025e = 9M2025 limited-review ACTUALS + Q4 2025 estimate (NOT audited full-year). 2026e-2030e illustrative as ERC de-levers and refining margins normalise. Blue = input.
A4: Income statement | B4: 2023a | C4: 2024a | D4: 2025e | E4: 2026e | F4: 2027e | G4: 2028e | H4: 2029e | I4: 2030e
A5: Revenue (consolidated, incl. ERC) | B5: 97.1 | C5: 148.9 | D5: 140.6 | E5: 150 | F5: 162 | G5: 174 | H5: 186 | I5: 198
A6: of which ERC | B6: 87 | C6: 134.9 | D6: 127 | E6: 134 | F6: 143 | G6: 152 | H6: 161 | I6: 170
A7: of which other platforms | B7: =B5-B6 -> 10.1 | C7: =C5-C6 -> 14 | D7: =D5-D6 -> 13.6 | E7: =E5-E6 -> 16 | F7: =F5-F6 -> 19 | G7: =G5-G6 -> 22 | H7: =H5-H6 -> 25 | I7: =I5-I6 -> 28
A8: Recurring EBITDA | B8: 22.7 | C8: 21.4 | D8: 19.4 | E8: 24 | F8: 27.5 | G8: 31 | H8: 34 | I8: 37
A9: EBITDA margin | B9: =B8/B5 -> 0.23377961 | C9: =C8/C5 -> 0.14372062 | D9: =D8/D5 -> 0.13798009 | E9: =E8/E5 -> 0.16 | F9: =F8/F5 -> 0.16975309 | G9: =G8/G5 -> 0.17816092 | H9: =H8/H5 -> 0.1827957 | I9: =I8/I5 -> 0.18686869
A10: (−) Depreciation & amortization | B10: -9 | C10: -10.5 | D10: -13.8 | E10: -13 | F10: -13.5 | G10: -14 | H10: -14.5 | I10: -15
A11: Operating profit (EBIT) | B11: =B8+B10 -> 13.7 | C11: =C8+C10 -> 10.9 | D11: =D8+D10 -> 5.6 | E11: =E8+E10 -> 11 | F11: =F8+F10 -> 14 | G11: =G8+G10 -> 17 | H11: =H8+H10 -> 19.5 | I11: =I8+I10 -> 22
A12: operating margin | B12: =B11/B5 -> 0.14109166 | C12: =C11/C5 -> 0.073203492 | D12: =D11/D5 -> 0.039829303 | E12: =E11/E5 -> 0.073333333 | F12: =F11/F5 -> 0.086419753 | G12: =G11/G5 -> 0.097701149 | H12: =H11/H5 -> 0.10483871 | I12: =I11/I5 -> 0.11111111
A13: (−) Net finance cost | B13: -12 | C13: -14 | D13: -8.4 | E13: -11 | F13: -9.5 | G13: -8.5 | H13: -8 | I13: -7.5
A14: (+) Discontinued ops / one-offs | B14: 0 | C14: 9.9 | D14: 0 | E14: 0 | F14: 0 | G14: 0 | H14: 0 | I14: 0
A15: (+) Share of associates (TAQA etc.) | B15: 0.3 | C15: 0.4 | D15: 0.2 | E15: 0.5 | F15: 0.7 | G15: 0.9 | H15: 1.1 | I15: 1.3
A16: Pre-tax profit/(loss) | B16: =B11+B13+B14+B15 -> 2 | C16: =C11+C13+C14+C15 -> 7.2 | D16: =D11+D13+D14+D15 -> -2.6 | E16: =E11+E13+E14+E15 -> 0.5 | F16: =F11+F13+F14+F15 -> 5.2 | G16: =G11+G13+G14+G15 -> 9.4 | H16: =H11+H13+H14+H15 -> 12.6 | I16: =I11+I13+I14+I15 -> 15.8
A17: (−) Income tax | B17: -0.5 | C17: -1.5 | D17: -1.6 | E17: -1.2 | F17: -2 | G17: -2.7 | H17: -3.4 | I17: -4
A18: Net profit/(loss) incl. minority | B18: =B16+B17 -> 1.5 | C18: =C16+C17 -> 5.7 | D18: =D16+D17 -> -4.2 | E18: =E16+E17 -> -0.7 | F18: =F16+F17 -> 3.2 | G18: =G16+G17 -> 6.7 | H18: =H16+H17 -> 9.2 | I18: =I16+I17 -> 11.8
A19: (−) Attributable to NCI | B19: 5.3 | C19: 1.8 | D19: -3.1 | E19: 2.5 | F19: 4 | G19: 5.5 | H19: 7 | I19: 8.5
A20: Net profit/(loss) attributable to parent | B20: =B18-B19 -> -3.8 | C20: =C18-C19 -> 3.9 | D20: =D18-D19 -> -1.1 | E20: =E18-E19 -> -3.2 | F20: =F18-F19 -> -0.8 | G20: =G18-G19 -> 1.2 | H20: =H18-H19 -> 2.2 | I20: =I18-I19 -> 3.3
A21: EPS attributable (EGP) | B21: =B20/Assumptions!$B$6 -> -0.9047619 | C21: =C20/Assumptions!$B$6 -> 0.92857143 | D21: =D20/Assumptions!$B$6 -> -0.26190476 | E21: =E20/Assumptions!$B$6 -> -0.76190476 | F21: =F20/Assumptions!$B$6 -> -0.19047619 | G21: =G20/Assumptions!$B$6 -> 0.28571429 | H21: =H20/Assumptions!$B$6 -> 0.52380952 | I21: =I20/Assumptions!$B$6 -> 0.78571429

Sheet Balance Sheet
A1: QALAA HOLDINGS — CONSOLIDATED BALANCE SHEET (EGP bn)
A2: FY2024 audited (qualified). 2025e anchored on 9M2025 limited-review balance sheet (30-Sep-25) + Q4 roll. Parent equity REMAINS NEGATIVE end-2025 (~−4.5bn) — management cites +3.4bn standalone/pro-forma, NOT the consolidated figure. Blue = input.
A4: Balance sheet | B4: 2023a | C4: 2024a | D4: 2025e | E4: 2026e | F4: 2027e | G4: 2028e | H4: 2029e | I4: 2030e
A5: Cash & equivalents | B5: 12 | C5: 2.7 | D5: 4.5 | E5: 6 | F5: 8 | G5: 10 | H5: 12 | I5: 14
A6: Other current assets (balancing) | B6: =B14+B17-B5-B8-B9-B10 -> 80.1 | C6: =C14+C17-C5-C8-C9-C10 -> 44.6 | D6: =D14+D17-D5-D8-D9-D10 -> 25.4 | E6: =E14+E17-E5-E8-E9-E10 -> 21 | F6: =F14+F17-F5-F8-F9-F10 -> 24.5 | G6: =G14+G17-G5-G8-G9-G10 -> 28 | H6: =H14+H17-H5-H8-H9-H10 -> 33 | I6: =I14+I17-I5-I8-I9-I10 -> 39
A7: Total current assets | B7: =B5+B6 -> 92.1 | C7: =C5+C6 -> 47.3 | D7: =D5+D6 -> 29.9 | E7: =E5+E6 -> 27 | F7: =F5+F6 -> 32.5 | G7: =G5+G6 -> 38 | H7: =H5+H6 -> 45 | I7: =I5+I6 -> 53
A8: PP&E & refinery assets | B8: 95 | C8: 163.1 | D8: 142 | E8: 140 | F8: 138 | G8: 136 | H8: 134 | I8: 132
A9: Investments in associates (TAQA etc.) | B9: 8 | C9: 6.8 | D9: 7 | E9: 8 | F9: 9 | G9: 10 | H9: 11 | I9: 12
A10: Other non-current assets | B10: 5.6 | C10: 11.3 | D10: 12 | E10: 11 | F10: 10 | G10: 10 | H10: 10 | I10: 10
A11: Total assets | B11: =B7+B8+B9+B10 -> 200.7 | C11: =C7+C8+C9+C10 -> 228.5 | D11: =D7+D8+D9+D10 -> 190.9 | E11: =E7+E8+E9+E10 -> 186 | F11: =F7+F8+F9+F10 -> 189.5 | G11: =G7+G8+G9+G10 -> 194 | H11: =H7+H8+H9+H10 -> 200 | I11: =I7+I8+I9+I10 -> 207
A12: Total borrowings | B12: 100 | C12: 111.4 | D12: 72.4 | E12: 62 | F12: 56 | G12: 51 | H12: 47 | I12: 43
A13: Other liabilities | B13: 60.7 | C13: 50.1 | D13: 51 | E13: 52 | F13: 53 | G13: 54 | H13: 55 | I13: 56
A14: Total liabilities | B14: =B12+B13 -> 160.7 | C14: =C12+C13 -> 161.5 | D14: =D12+D13 -> 123.4 | E14: =E12+E13 -> 114 | F14: =F12+F13 -> 109 | G14: =G12+G13 -> 105 | H14: =H12+H13 -> 102 | I14: =I12+I13 -> 99
A15: Non-controlling interest | B15: 47.1 | C15: 80.7 | D15: 72 | E15: 74 | F15: 77 | G15: 80 | H15: 83 | I15: 86
A16: Equity attributable to parent | B16: -7.1 | C16: -13.7 | D16: -4.5 | E16: -2 | F16: 3.5 | G16: 9 | H16: 15 | I16: 22
A17: Total equity | B17: =B15+B16 -> 40 | C17: =C15+C16 -> 67 | D17: =D15+D16 -> 67.5 | E17: =E15+E16 -> 72 | F17: =F15+F16 -> 80.5 | G17: =G15+G16 -> 89 | H17: =H15+H16 -> 98 | I17: =I15+I16 -> 108
A18: Check: assets − liab − equity (≈0) | B18: =B11-B14-B17 -> 0 | C18: =C11-C14-C17 -> 0 | D18: =D11-D14-D17 -> 0 | E18: =E11-E14-E17 -> 0 | F18: =F11-F14-F17 -> 0 | G18: =G11-G14-G17 -> 0 | H18: =H11-H14-H17 -> 0 | I18: =I11-I14-I17 -> 0
A19: BVPS — attributable (EGP) | B19: =B16/Assumptions!$B$6 -> -1.6904762 | C19: =C16/Assumptions!$B$6 -> -3.2619048 | D19: =D16/Assumptions!$B$6 -> -1.0714286 | E19: =E16/Assumptions!$B$6 -> -0.47619048 | F19: =F16/Assumptions!$B$6 -> 0.83333333 | G19: =G16/Assumptions!$B$6 -> 2.1428571 | H19: =H16/Assumptions!$B$6 -> 3.5714286 | I19: =I16/Assumptions!$B$6 -> 5.2380952

Sheet Cash Flow
A1: QALAA HOLDINGS — CONSOLIDATED CASH FLOW (EGP bn)
A2: 2025e = 9M2025 limited-review ACTUALS + Q4 roll. ERC repaid USD 574.4m of senior debt in 2025; total consolidated debt cut ~EGP 39bn. Blue = input; FCF & net change are formulas.
A4: Cash flow | B4: 2023a | C4: 2024a | D4: 2025e | E4: 2026e | F4: 2027e | G4: 2028e | H4: 2029e | I4: 2030e
A5: Operating cash flow | B5: 18 | C5: 20 | D5: 20.1 | E5: 22 | F5: 24 | G5: 26 | H5: 28 | I5: 30
A6: (−) Capex | B6: -8 | C6: -9 | D6: -9 | E6: -9 | F6: -9.5 | G6: -10 | H6: -10.5 | I6: -11
A7: Free cash flow | B7: =B5+B6 -> 10 | C7: =C5+C6 -> 11 | D7: =D5+D6 -> 11.1 | E7: =E5+E6 -> 13 | F7: =F5+F6 -> 14.5 | G7: =G5+G6 -> 16 | H7: =H5+H6 -> 17.5 | I7: =I5+I6 -> 19
A8: (−) Debt repayment (incl. ERC senior) | B8: -6 | C8: -28 | D8: -39 | E8: -10 | F8: -7 | G8: -6 | H8: -5 | I8: -5
A9: Net cash flow after financing | B9: =B7+B8 -> 4 | C9: =C7+C8 -> -17 | D9: =D7+D8 -> -27.9 | E9: =E7+E8 -> 3 | F9: =F7+F8 -> 7.5 | G9: =G7+G8 -> 10 | H9: =H7+H8 -> 12.5 | I9: =I7+I8 -> 14

Sheet Summary Financials
A1: SUMMARY FINANCIALS — every cell links to the statement sheets
A2: No hard-codes; pulls from Income Statement / Balance Sheet / Cash Flow. 2025e blends 9M2025 actuals + Q4 estimate.
A4: EGP bn | B4: 2023a | C4: 2024a | D4: 2025e | E4: 2026e | F4: 2027e | G4: 2028e | H4: 2029e | I4: 2030e
A5: Revenue | B5: ='Income Statement'!B5 -> 97.1 | C5: ='Income Statement'!C5 -> 148.9 | D5: ='Income Statement'!D5 -> 140.6 | E5: ='Income Statement'!E5 -> 150 | F5: ='Income Statement'!F5 -> 162 | G5: ='Income Statement'!G5 -> 174 | H5: ='Income Statement'!H5 -> 186 | I5: ='Income Statement'!I5 -> 198
A6: Recurring EBITDA | B6: ='Income Statement'!B8 -> 22.7 | C6: ='Income Statement'!C8 -> 21.4 | D6: ='Income Statement'!D8 -> 19.4 | E6: ='Income Statement'!E8 -> 24 | F6: ='Income Statement'!F8 -> 27.5 | G6: ='Income Statement'!G8 -> 31 | H6: ='Income Statement'!H8 -> 34 | I6: ='Income Statement'!I8 -> 37
A7: Operating profit (EBIT) | B7: ='Income Statement'!B11 -> 13.7 | C7: ='Income Statement'!C11 -> 10.9 | D7: ='Income Statement'!D11 -> 5.6 | E7: ='Income Statement'!E11 -> 11 | F7: ='Income Statement'!F11 -> 14 | G7: ='Income Statement'!G11 -> 17 | H7: ='Income Statement'!H11 -> 19.5 | I7: ='Income Statement'!I11 -> 22
A8: Net profit attributable | B8: ='Income Statement'!B20 -> -3.8 | C8: ='Income Statement'!C20 -> 3.9 | D8: ='Income Statement'!D20 -> -1.1 | E8: ='Income Statement'!E20 -> -3.2 | F8: ='Income Statement'!F20 -> -0.8 | G8: ='Income Statement'!G20 -> 1.2 | H8: ='Income Statement'!H20 -> 2.2 | I8: ='Income Statement'!I20 -> 3.3
A9: EPS attributable (EGP) | B9: ='Income Statement'!B21 -> -0.9047619 | C9: ='Income Statement'!C21 -> 0.92857143 | D9: ='Income Statement'!D21 -> -0.26190476 | E9: ='Income Statement'!E21 -> -0.76190476 | F9: ='Income Statement'!F21 -> -0.19047619 | G9: ='Income Statement'!G21 -> 0.28571429 | H9: ='Income Statement'!H21 -> 0.52380952 | I9: ='Income Statement'!I21 -> 0.78571429
A10: Total assets | B10: ='Balance Sheet'!B11 -> 200.7 | C10: ='Balance Sheet'!C11 -> 228.5 | D10: ='Balance Sheet'!D11 -> 190.9 | E10: ='Balance Sheet'!E11 -> 186 | F10: ='Balance Sheet'!F11 -> 189.5 | G10: ='Balance Sheet'!G11 -> 194 | H10: ='Balance Sheet'!H11 -> 200 | I10: ='Balance Sheet'!I11 -> 207
A11: Total borrowings | B11: ='Balance Sheet'!B12 -> 100 | C11: ='Balance Sheet'!C12 -> 111.4 | D11: ='Balance Sheet'!D12 -> 72.4 | E11: ='Balance Sheet'!E12 -> 62 | F11: ='Balance Sheet'!F12 -> 56 | G11: ='Balance Sheet'!G12 -> 51 | H11: ='Balance Sheet'!H12 -> 47 | I11: ='Balance Sheet'!I12 -> 43
A12: Parent equity | B12: ='Balance Sheet'!B16 -> -7.1 | C12: ='Balance Sheet'!C16 -> -13.7 | D12: ='Balance Sheet'!D16 -> -4.5 | E12: ='Balance Sheet'!E16 -> -2 | F12: ='Balance Sheet'!F16 -> 3.5 | G12: ='Balance Sheet'!G16 -> 9 | H12: ='Balance Sheet'!H16 -> 15 | I12: ='Balance Sheet'!I16 -> 22
A13: Free cash flow | B13: ='Cash Flow'!B7 -> 10 | C13: ='Cash Flow'!C7 -> 11 | D13: ='Cash Flow'!D7 -> 11.1 | E13: ='Cash Flow'!E7 -> 13 | F13: ='Cash Flow'!F7 -> 14.5 | G13: ='Cash Flow'!G7 -> 16 | H13: ='Cash Flow'!H7 -> 17.5 | I13: ='Cash Flow'!I7 -> 19

Sheet Monte Carlo
A1: MONTE CARLO — ONE 16-FACTOR MODEL (50,000 paths, seed 42)
A2: Seven continuous factors compound daily; nine discrete events fire with probability. Paths diffuse from spot; the §1 NAV gap is kept OUT of the drift.
A4: CORE INPUTS
A5: Anchor price (EGP, 30-Jun-26) | B5: 4.77
A6: Horizon T+20 (sessions) | B6: 20
A7: Horizon T+60 (sessions) | B7: 60
A8: Realized 3M volatility (idiosyncratic) | B8: 0.23
A9: 52-week low reference (EGP) | B9: 2.39
A10: Round / support level (EGP) | B10: 4.5
A11: SMA50 / structure (EGP) | B11: 4.87
A12: 52-week high reference (EGP) | B12: 5.7
A14: SEVEN CONTINUOUS FACTORS
A15: Factor | B15: 3M drift | C15: 3M vol | H15: Channel
A16: ERC refining margin & utilization | B16: 0.015 | C16: 0.07 | H16: master energy driver
A17: ERC senior-debt retirement / de-levering (1Q26) | B17: 0.012 | C17: 0.04 | H17: de-levering tailwind
A18: TAQA Arabia & energy-distribution earnings | B18: 0.006 | C18: 0.04 | H18: distribution earnings
A19: EGX flows / EGP carry & rate path | B19: 0.004 | C19: 0.06 | H19: market liquidity
A20: EGP devaluation translation (ERC USD-functional) | B20: 0.005 | C20: 0.05 | H20: FX translation lift
A21: Holdco-debt write-off progress (2030/2033) | B21: 0.003 | C21: 0.03 | H21: parent de-gearing
A22: Realized price momentum (carried, not extrapolated) | B22: -0.004 | C22: 0.05 | H22: momentum, de-weighted
A24: NINE DISCRETE EVENTS
A25: Event | B25: Prob | C25: Impact mu | D25: Impact sigma | H25: Channel
A26: ERC dividend resumption (post senior debt) | B26: 0.35 | C26: 0.08 | D26: 0.04 | H26: pivotal upside catalyst
A27: Holdco-discount compression / re-rating | B27: 0.3 | C27: 0.06 | D27: 0.04 | H27: discount narrows
A28: Platform crystallization (TAQA stake-up / sale) | B28: 0.25 | C28: 0.06 | D28: 0.04 | H28: portfolio crystallization
A29: EGP step devaluation (nominal lift, USD assets) | B29: 0.25 | C29: 0.05 | D29: 0.05 | H29: FX step, two-edged
A30: Quarterly results surprise (two-sided) | B30: 0.4 | C30: 0 | D30: 0.06 | H30: two-sided
A31: Refining-margin / oil-price disappointment | B31: 0.3 | C31: -0.06 | D31: 0.04 | H31: demand left-tail
A32: Going-concern / qualified-audit overhang flare | B32: 0.2 | C32: -0.07 | D32: 0.05 | H32: balance-sheet risk
A33: EGX / EM risk-off, EGP pressure | B33: 0.25 | C33: -0.06 | D33: 0.04 | H33: market risk-off
A34: Regulatory / energy-subsidy / FX-access shock | B34: 0.2 | C34: -0.05 | D34: 0.04 | H34: policy shock
A36: FACTOR MOMENTS (live)
A37: Expected 3M log-return mu | B37: =SUM(B16:B22)+SUMPRODUCT(B26:B34,C26:C34) -> 0.0575
A38: 3M variance | B38: =SUMPRODUCT(C16:C22,C16:C22)+SUMPRODUCT(B26:B34,D26:D34,D26:D34) -> 0.022805
A39: 3M volatility sigma | B39: =SQRT(B38) -> 0.15101324
A40: Annualized vol (x2) | B40: =B39*2 -> 0.30202649 | H40: engine total 3M vol ~27%; ann ~54%
A42: PERCENTILES (EGP/share)
A43: Horizon | B43: 5% | C43: 25% | D43: Median | E43: 75% | F43: 95% | G43: Source
A44: T+20 — engine (simulated) | B44: 3.771 | C44: 4.36 | D44: 4.809 | E44: 5.312 | F44: 6.126 | G44: 50k paths · seed 42
A45: T+20 — closed-form (live) | B45: =$B$5*EXP($B$37*20/60+(-1.6449)*$B$39*SQRT(20/60)) -> 4.2126765 | C45: =$B$5*EXP($B$37*20/60+(-0.6745)*$B$39*SQRT(20/60)) -> 4.5846097 | D45: =$B$5*EXP($B$37*20/60+(0)*$B$39*SQRT(20/60)) -> 4.8623068 | E45: =$B$5*EXP($B$37*20/60+(0.6745)*$B$39*SQRT(20/60)) -> 5.1568244 | F45: =$B$5*EXP($B$37*20/60+(1.6449)*$B$39*SQRT(20/60)) -> 5.6121155
...

Sheet Sensitivity
A1: SENSITIVITY — value/share (EGP)
A2: Top: SOTP holdco discount × ERC EV (the two biggest swing factors). Bottom: DCF WACC × terminal growth.
A4: SOTP: Holdco discount (down) / ERC EV in EGP bn (right)
A5: disc / ERC EV | B5: 88 | C5: 98 | D5: 108 | E5: 118 | F5: 128
A6: 0.45 | B6: =((32.85+(88-41)*0.1314)-6)/Assumptions!$B$6*(1-0.45) -> 4.3248071 | C6: =((32.85+(98-41)*0.1314)-6)/Assumptions!$B$6*(1-0.45) -> 4.4968786 | D6: =((32.85+(108-41)*0.1314)-6)/Assumptions!$B$6*(1-0.45) -> 4.66895 | E6: =((32.85+(118-41)*0.1314)-6)/Assumptions!$B$6*(1-0.45) -> 4.8410214 | F6: =((32.85+(128-41)*0.1314)-6)/Assumptions!$B$6*(1-0.45) -> 5.0130929
A7: 0.38 | B7: =((32.85+(88-41)*0.1314)-6)/Assumptions!$B$6*(1-0.38) -> 4.8752371 | C7: =((32.85+(98-41)*0.1314)-6)/Assumptions!$B$6*(1-0.38) -> 5.0692086 | D7: =((32.85+(108-41)*0.1314)-6)/Assumptions!$B$6*(1-0.38) -> 5.26318 | E7: =((32.85+(118-41)*0.1314)-6)/Assumptions!$B$6*(1-0.38) -> 5.4571514 | F7: =((32.85+(128-41)*0.1314)-6)/Assumptions!$B$6*(1-0.38) -> 5.6511229
A8: 0.3 | B8: =((32.85+(88-41)*0.1314)-6)/Assumptions!$B$6*(1-0.3) -> 5.5043 | C8: =((32.85+(98-41)*0.1314)-6)/Assumptions!$B$6*(1-0.3) -> 5.7233 | D8: =((32.85+(108-41)*0.1314)-6)/Assumptions!$B$6*(1-0.3) -> 5.9423 | E8: =((32.85+(118-41)*0.1314)-6)/Assumptions!$B$6*(1-0.3) -> 6.1613 | F8: =((32.85+(128-41)*0.1314)-6)/Assumptions!$B$6*(1-0.3) -> 6.3803
A9: 0.24 | B9: =((32.85+(88-41)*0.1314)-6)/Assumptions!$B$6*(1-0.24) -> 5.9760971 | C9: =((32.85+(98-41)*0.1314)-6)/Assumptions!$B$6*(1-0.24) -> 6.2138686 | D9: =((32.85+(108-41)*0.1314)-6)/Assumptions!$B$6*(1-0.24) -> 6.45164 | E9: =((32.85+(118-41)*0.1314)-6)/Assumptions!$B$6*(1-0.24) -> 6.6894114 | F9: =((32.85+(128-41)*0.1314)-6)/Assumptions!$B$6*(1-0.24) -> 6.9271829
A10: 0.18 | B10: =((32.85+(88-41)*0.1314)-6)/Assumptions!$B$6*(1-0.18) -> 6.4478943 | C10: =((32.85+(98-41)*0.1314)-6)/Assumptions!$B$6*(1-0.18) -> 6.7044371 | D10: =((32.85+(108-41)*0.1314)-6)/Assumptions!$B$6*(1-0.18) -> 6.96098 | E10: =((32.85+(118-41)*0.1314)-6)/Assumptions!$B$6*(1-0.18) -> 7.2175229 | F10: =((32.85+(128-41)*0.1314)-6)/Assumptions!$B$6*(1-0.18) -> 7.4740657
A12: DCF: WACC (down) / terminal growth g (right)
A13: WACC / g | B13: 0.04 | C13: 0.05 | D13: 0.06 | E13: 0.07 | F13: 0.08
A14: 0.16 | B14: =(SUMPRODUCT(DCF!$B$13:$F$13,(1+0.16)^-{1,2,3,4,5})+DCF!$F$13*(1+0.04)/(0.16-0.04)/(1+0.16)^5+Assumptions!$B$53)/Assumptions!$B$6 -> 4.9573402 | C14: =(SUMPRODUCT(DCF!$B$13:$F$13,(1+0.16)^-{1,2,3,4,5})+DCF!$F$13*(1+0.05)/(0.16-0.05)/(1+0.16)^5+Assumptions!$B$53)/Assumptions!$B$6 -> 5.2420032 | D14: =(SUMPRODUCT(DCF!$B$13:$F$13,(1+0.16)^-{1,2,3,4,5})+DCF!$F$13*(1+0.06)/(0.16-0.06)/(1+0.16)^5+Assumptions!$B$53)/Assumptions!$B$6 -> 5.5835989 | E14: =(SUMPRODUCT(DCF!$B$13:$F$13,(1+0.16)^-{1,2,3,4,5})+DCF!$F$13*(1+0.07)/(0.16-0.07)/(1+0.16)^5+Assumptions!$B$53)/Assumptions!$B$6 -> 6.0011046 | F14: =(SUMPRODUCT(DCF!$B$13:$F$13,(1+0.16)^-{1,2,3,4,5})+DCF!$F$13*(1+0.08)/(0.16-0.08)/(1+0.16)^5+Assumptions!$B$53)/Assumptions!$B$6 -> 6.5229868
A15: 0.18 | B15: =(SUMPRODUCT(DCF!$B$13:$F$13,(1+0.18)^-{1,2,3,4,5})+DCF!$F$13*(1+0.04)/(0.18-0.04)/(1+0.18)^5+Assumptions!$B$53)/Assumptions!$B$6 -> 4.2760012 | C15: =(SUMPRODUCT(DCF!$B$13:$F$13,(1+0.18)^-{1,2,3,4,5})+DCF!$F$13*(1+0.05)/(0.18-0.05)/(1+0.18)^5+Assumptions!$B$53)/Assumptions!$B$6 -> 4.4688148 | D15: =(SUMPRODUCT(DCF!$B$13:$F$13,(1+0.18)^-{1,2,3,4,5})+DCF!$F$13*(1+0.06)/(0.18-0.06)/(1+0.18)^5+Assumptions!$B$53)/Assumptions!$B$6 -> 4.6937639 | E15: =(SUMPRODUCT(DCF!$B$13:$F$13,(1+0.18)^-{1,2,3,4,5})+DCF!$F$13*(1+0.07)/(0.18-0.07)/(1+0.18)^5+Assumptions!$B$53)/Assumptions!$B$6 -> 4.9596129 | F15: =(SUMPRODUCT(DCF!$B$13:$F$13,(1+0.18)^-{1,2,3,4,5})+DCF!$F$13*(1+0.08)/(0.18-0.08)/(1+0.18)^5+Assumptions!$B$53)/Assumptions!$B$6 -> 5.2786316
A16: 0.2 | B16: =(SUMPRODUCT(DCF!$B$13:$F$13,(1+0.2)^-{1,2,3,4,5})+DCF!$F$13*(1+0.04)/(0.2-0.04)/(1+0.2)^5+Assumptions!$B$53)/Assumptions!$B$6 -> 3.7671579 | C16: =(SUMPRODUCT(DCF!$B$13:$F$13,(1+0.2)^-{1,2,3,4,5})+DCF!$F$13*(1+0.05)/(0.2-0.05)/(1+0.2)^5+Assumptions!$B$53)/Assumptions!$B$6 -> 3.903868 | D16: =(SUMPRODUCT(DCF!$B$13:$F$13,(1+0.2)^-{1,2,3,4,5})+DCF!$F$13*(1+0.06)/(0.2-0.06)/(1+0.2)^5+Assumptions!$B$53)/Assumptions!$B$6 -> 4.0601082 | E16: =(SUMPRODUCT(DCF!$B$13:$F$13,(1+0.2)^-{1,2,3,4,5})+DCF!$F$13*(1+0.07)/(0.2-0.07)/(1+0.2)^5+Assumptions!$B$53)/Assumptions!$B$6 -> 4.2403853 | F16: =(SUMPRODUCT(DCF!$B$13:$F$13,(1+0.2)^-{1,2,3,4,5})+DCF!$F$13*(1+0.08)/(0.2-0.08)/(1+0.2)^5+Assumptions!$B$53)/Assumptions!$B$6 -> 4.4507086
A17: 0.22 | B17: =(SUMPRODUCT(DCF!$B$13:$F$13,(1+0.22)^-{1,2,3,4,5})+DCF!$F$13*(1+0.04)/(0.22-0.04)/(1+0.22)^5+Assumptions!$B$53)/Assumptions!$B$6 -> 3.3731582 | C17: =(SUMPRODUCT(DCF!$B$13:$F$13,(1+0.22)^-{1,2,3,4,5})+DCF!$F$13*(1+0.05)/(0.22-0.05)/(1+0.22)^5+Assumptions!$B$53)/Assumptions!$B$6 -> 3.4735218 | D17: =(SUMPRODUCT(DCF!$B$13:$F$13,(1+0.22)^-{1,2,3,4,5})+DCF!$F$13*(1+0.06)/(0.22-0.06)/(1+0.22)^5+Assumptions!$B$53)/Assumptions!$B$6 -> 3.5864308 | E17: =(SUMPRODUCT(DCF!$B$13:$F$13,(1+0.22)^-{1,2,3,4,5})+DCF!$F$13*(1+0.07)/(0.22-0.07)/(1+0.22)^5+Assumptions!$B$53)/Assumptions!$B$6 -> 3.7143944 | F17: =(SUMPRODUCT(DCF!$B$13:$F$13,(1+0.22)^-{1,2,3,4,5})+DCF!$F$13*(1+0.08)/(0.22-0.08)/(1+0.22)^5+Assumptions!$B$53)/Assumptions!$B$6 -> 3.8606385
A18: 0.24 | B18: =(SUMPRODUCT(DCF!$B$13:$F$13,(1+0.24)^-{1,2,3,4,5})+DCF!$F$13*(1+0.04)/(0.24-0.04)/(1+0.24)^5+Assumptions!$B$53)/Assumptions!$B$6 -> 3.0594243 | C18: =(SUMPRODUCT(DCF!$B$13:$F$13,(1+0.24)^-{1,2,3,4,5})+DCF!$F$13*(1+0.05)/(0.24-0.05)/(1+0.24)^5+Assumptions!$B$53)/Assumptions!$B$6 -> 3.1351541 | D18: =(SUMPRODUCT(DCF!$B$13:$F$13,(1+0.24)^-{1,2,3,4,5})+DCF!$F$13*(1+0.06)/(0.24-0.06)/(1+0.24)^5+Assumptions!$B$53)/Assumptions!$B$6 -> 3.2192983 | E18: =(SUMPRODUCT(DCF!$B$13:$F$13,(1+0.24)^-{1,2,3,4,5})+DCF!$F$13*(1+0.07)/(0.24-0.07)/(1+0.24)^5+Assumptions!$B$53)/Assumptions!$B$6 -> 3.3133418 | F18: =(SUMPRODUCT(DCF!$B$13:$F$13,(1+0.24)^-{1,2,3,4,5})+DCF!$F$13*(1+0.08)/(0.24-0.08)/(1+0.24)^5+Assumptions!$B$53)/Assumptions!$B$6 -> 3.4191407
A20: SOTP grid flexes the holdco discount and ERC EV — the two factors that move the answer most. The DCF grid stays well below the SOTP across the space, by construction.

Sheet Per-Share & Ratios
A1: PER-SHARE & RATIOS (at spot)
A2: Drivers link to Income Statement / Balance Sheet / SOTP.
A5: Share price (EGP, 30-Jun-26) | B5: =Assumptions!B5 -> 4.77
A6: Shares outstanding (bn) | B6: =Assumptions!B6 -> 4.2
A7: Market cap (EGP bn) | B7: =Assumptions!B5*Assumptions!B6 -> 20.034
A8: 2025e EPS attributable (EGP) | B8: ='Income Statement'!D21 -> -0.26190476
A9: Normalized EPS (EGP) | B9: =Assumptions!B39/Assumptions!B6 -> 0.95238095
A10: BVPS attributable (EGP) | B10: ='Balance Sheet'!D19 -> -1.0714286
A12: P/E on 2025e (x) | B12: =IF(B8>0,B5/B8,"n.m. (loss)") -> n.m. (loss)
A13: P/E normalized (x) | B13: =B5/B9 -> 5.0085
A14: P/B attributable (x) | B14: =IF(B10>0,B5/B10,"n.m. (neg. equity)") -> n.m. (neg. equity)
A15: Gross NAV per share (EGP) | B15: =SOTP!B15 -> 8.4827429
A16: Discount to gross NAV at spot | B16: =B5/B15-1 -> -0.43768188
A18: Qalaa parent equity remains NEGATIVE through end-2025 (management cites +3.4bn standalone, not consolidated); 2025e shows a net loss to parent. P/E and P/B are not meaningful — discount-to-NAV is the gauge.

Sheet Peer & Sector
A1: PEER & SECTOR
A2: Egyptian investment holding companies and the energy/diversified comparable set.
A4: Peer / arena | B4: Note | C4: Relevance
A5: EGX holdco discount norms | B5: Egyptian holdcos trade at wide NAV discounts | C5: sets the base discount
A6: ERC (refining) | B6: single-asset refinery; margin & utilization cyclical | C6: dominant value driver
A7: TAQA Arabia | B7: energy distribution; steadier earnings | C7: associate cross-check
A8: Going-concern / audit | B8: qualified FY2024 opinion, going-concern emphasis | C8: widens the discount
A9: EGP / macro | B9: devaluation lifts USD-functional ERC nominally | C9: two-edged translation
A10: Value-up / disclosure | B10: crystallization (TAQA stake-up, asset sale) narrows discount | C10: upside catalyst
