Workbook

Sheet READ FIRST
B2: RAYA — READ FIRST
B6: What this document is, and is not.
B9: This workbook is a valuation exercise and an expression of personal analytical opinion, published free of charge for educational purposes. It shows how one analyst applies a holding-company sum-of-the-parts, a DCF cross-check, relative and normalized reads, and a Monte-Carlo simulation to a listed company, and invites scrutiny of that methodology.
B12: It is NOT investment advice, NOT a recommendation or solicitation to buy, sell or hold any security, and NOT directed at the circumstances of any reader. The preparer is not licensed by any securities regulator, holds no brokerage authorisation, manages no money, and accepts no fees or clients.
B15: All values are model outputs presented as ranges and distributions because no single number should be relied upon. Reported financials are the company's own disclosure (FY2025 results, 8 March 2026); forward-looking inputs — the segment marks, multiples, the holdco discount, the DCF and the Monte-Carlo factor probabilities — are the preparer's judgments and are flagged in Assumptions.
B18: The preparer may hold, and may in the future take or dispose of, a position in the security discussed in this report. Consult a licensed financial advisor before any investment decision.

Sheet Summary
B2: RAYA — Valuation summary
B3: Raya Holding for Financial Investments (EGX: RAYA) · Independent Valuation Study — Educational Analysis · not investment advice.
B6: Every read at a glance (EGP/share)
B7: Lens | C7: Value | D7: vs spot
B8: Spot (01 Jul 2026) | C8: =Assumptions!C6 -> 7.7
B9: Holdco SOTP (primary) | C9: =SOTP!J27 -> 5.0085269 | D9: =C9/Assumptions!C6-1 -> -0.34954196
B10: DCF (cross-check) | C10: =DCF!C24 -> 4.7742567 | D10: =C10/Assumptions!C6-1 -> -0.37996666
B11: Relative multiples | C11: ='Relative & Normalized'!C17 -> 6.1285156 | D11: =C11/Assumptions!C6-1 -> -0.20408889
B12: Normalized earnings | C12: ='Relative & Normalized'!C23 -> 8.2218061 | D12: =C12/Assumptions!C6-1 -> 0.067767023
B13: Expert panel | C13: =Assumptions!C117 -> 6.2 | D13: =C13/Assumptions!C6-1 -> -0.19480519
B14: Weighted central fair value | C14: ='Fundamental Valuation'!C11 -> 5.5584329 | D14: =C14/Assumptions!C6-1 -> -0.2781256
B16: 3-month Monte Carlo (drift off)
B17: T+60 median (EGP) | C17: 7.79
B18: T+60 50% IQR band | C18: 6.4 | E18: 9.45
B19: T+60 5–95% band | C19: 4.6 | E19: 13.06
B21: Verdict (educational — no recommendation)
B22: The re-rating has outrun a conservative sum-of-the-parts. On the primary holdco NAV the shares screen expensive: weighted central fair value ~EGP 5.6 vs spot 7.70 (~27% above fair). Spot is only justified at the bull end — Aman at a full fintech multiple, RIT compounding its 70% growth, and no conglomerate discount. Technically the tape is strong (near the all-time high, above every moving average, RSI ~67); the Monte Carlo, with the secular drift off, is centred near spot with a wide 50% band of roughly EGP 6.4–9.5 over three months. The value gap of §1 is deliberately kept out of the MC drift. This is an educational valuation exercise, not advice; no buy/sell/hold.

Sheet Fundamental Valuation
B2: RAYA — Fundamental valuation synthesis
B3: Five lenses, weighted to a central fair value. Each value links to its own sheet; weights live in Assumptions.
B5: Lens (EGP/share) | C5: Value/sh | D5: Weight | E5: Contribution
B6: Holdco SOTP (primary) | C6: =SOTP!J27 -> 5.0085269 | D6: =Assumptions!C112 -> 0.4 | E6: =C6*D6 -> 2.0034108
B7: DCF (FCFF cross-check) | C7: =DCF!C24 -> 4.7742567 | D7: =Assumptions!C113 -> 0.25 | E7: =C7*D7 -> 1.1935642
B8: Relative multiples | C8: ='Relative & Normalized'!C17 -> 6.1285156 | D8: =Assumptions!C114 -> 0.15 | E8: =C8*D8 -> 0.91927733
B9: Normalized earnings | C9: ='Relative & Normalized'!C23 -> 8.2218061 | D9: =Assumptions!C115 -> 0.1 | E9: =C9*D9 -> 0.82218061
B10: Expert panel | C10: =Assumptions!C117 -> 6.2 | D10: =Assumptions!C116 -> 0.1 | E10: =C10*D10 -> 0.62
B11: Weighted central fair value | C11: =SUM(E6:E10) -> 5.5584329 | D11: =SUM(D6:D10) -> 1
B12: Spot | C12: =Assumptions!C6 -> 7.7
B13: Upside / (downside) to fair | C13: =C11/Assumptions!C6-1 -> -0.2781256

Sheet Assumptions
B2: RAYA — Assumptions
B3: Single blue-cell input layer. Blue = input/judgment (editable); every other sheet links here. Marks & multiples are the preparer's judgments, flagged.
B5: Market (as of 01 Jul 2026)
B6: Spot price | C6: 7.7 | D6: EGP | E6: Attached daily history, 01 Jul 2026 close
B7: Shares outstanding | C7: 4281.2978 | D7: mn | E7: Company fact sheet 1Q2025 (4,281,297,768)
B8: Market capitalisation | C8: =C6*C7 -> 32965.993 | D8: EGP mn | E8: spot x shares
B9: Group actuals — FY2025 (consolidated)
B10: Group revenue FY2025 | C10: 63829 | D10: EGP mn | E10: Raya FY2025 results, 8 Mar 2026 (EGP 63.83bn)
B11: Group EBITDA FY2025 | C11: 7800 | D11: EGP mn | E11: FY2025 results (EGP 7.8bn, +60%)
B12: NPAT after minority FY2025 | C12: 2588 | D12: EGP mn | E12: FY2025 results (EGP 2.588bn, +53%)
B13: Segment revenue — FY2025 (EGP mn)
B14: Raya IT | C14: 18400 | E14: FY2025 release (EGP 18.4bn, +70%)
B15: Aman Holding (fintech) | C15: 9600 | E15: FY2025 release (EGP 9.6bn, +49%)
B16: Raya Trade (distribution) | C16: 23800 | E16: FY2025 release (EGP 23.8bn)
B17: Raya Customer Experience (RACC) | C17: 2440 | E17: Est. from 1Q25 mix (listed EGX:RACC)
B18: Raya FMCG | C18: 2900 | E18: Est. from 1Q25 segment mix
B19: Ostool (logistics) | C19: 2200 | E19: Est. from 1Q25 segment mix
B20: Raya Foods | C20: 2050 | E20: Est. from 1Q25 segment mix
B21: Raya Auto | C21: 1300 | E21: Est. from 1Q25 segment mix
B22: Raya Electric (Haier/LG JV) | C22: 700 | E22: Est. from 1Q25 segment mix
B23: Raya Smart Buildings | C23: 250 | E23: Est. from 1Q25 segment mix
B24: Raya Restaurants | C24: 200 | E24: Est. from 1Q25 segment mix
B25: Segment EBITDA margins (preparer judgment)
B26: EBITDA margin — Raya IT | C26: 0.075 | E26: judgment by business type
B27: EBITDA margin — Raya Trade | C27: 0.04 | E27: judgment by business type
B28: EBITDA margin — Raya FMCG | C28: 0.05 | E28: judgment by business type
B29: EBITDA margin — RCX | C29: 0.18 | E29: judgment by business type
B30: EBITDA margin — Ostool | C30: 0.09 | E30: judgment by business type
B31: EBITDA margin — Raya Foods | C31: 0.11 | E31: judgment by business type
B32: EBITDA margin — Raya Auto | C32: 0.04 | E32: judgment by business type
B33: EBITDA margin — Raya Electric | C33: 0.06 | E33: judgment by business type
B34: EBITDA margin — Smart Buildings | C34: 0.2 | E34: judgment by business type
B35: EBITDA margin — Restaurants | C35: 0.08 | E35: judgment by business type
B36: Segment EV/EBITDA multiples (base case, judgment)
B37: EV/EBITDA — Raya IT | C37: 9 | E37: base-case multiple
B38: EV/EBITDA — Raya Trade | C38: 5.5 | E38: base-case multiple
B39: EV/EBITDA — Raya FMCG | C39: 6 | E39: base-case multiple
B40: EV/EBITDA — Ostool | C40: 5.5 | E40: base-case multiple
B41: EV/EBITDA — Raya Foods | C41: 6.5 | E41: base-case multiple
B42: EV/EBITDA — Raya Auto | C42: 5 | E42: base-case multiple
...

Sheet SOTP
B2: RAYA — Holdco Sum-of-the-Parts (primary lens)
B3: Each stake valued on an instrument-appropriate basis; Aman on P/E, RACC at the Aug-2025 tender-implied equity, operating cos on EV/EBITDA. All inputs live in Assumptions.
B5: Segment (EGP mn) | C5: Revenue | D5: EBITDA / NI | E5: Mult | F5: EV / Eq | G5: Net debt | H5: Equity | I5: Own % | J5: Attrib.
B6: Raya IT | C6: =Assumptions!C14 -> 18400 | D6: =C6*Assumptions!C26 -> 1380 | E6: =Assumptions!C37 -> 9 | F6: =D6*E6 -> 12420 | G6: =Assumptions!C63 -> 1500 | H6: =F6-G6 -> 10920 | I6: =Assumptions!C51 -> 1 | J6: =H6*I6 -> 10920
B7: Aman Holding (P/E on NI) | C7: =Assumptions!C15 -> 9600 | D7: =C7*Assumptions!C45 -> 864 | E7: =Assumptions!C46 -> 14 | F7: =D7*E7 -> 12096 | G7: 0 | H7: =F7-G7 -> 12096 | I7: =Assumptions!C52 -> 0.76 | J7: =H7*I7 -> 9192.96
B8: Raya Trade | C8: =Assumptions!C16 -> 23800 | D8: =C8*Assumptions!C27 -> 952 | E8: =Assumptions!C38 -> 5.5 | F8: =D8*E8 -> 5236 | G8: =Assumptions!C64 -> 2500 | H8: =F8-G8 -> 2736 | I8: =Assumptions!C53 -> 1 | J8: =H8*I8 -> 2736
B9: Raya Customer Experience (RACC, listed) | C9: =Assumptions!C17 -> 2440 | F9: =Assumptions!C47 -> 1880 | G9: 0 | H9: =F9 -> 1880 | I9: =Assumptions!C54 -> 0.868 | J9: =H9*I9 -> 1631.84
B10: Raya FMCG | C10: =Assumptions!C18 -> 2900 | D10: =C10*Assumptions!C28 -> 145 | E10: =Assumptions!C39 -> 6 | F10: =D10*E10 -> 870 | G10: =Assumptions!C65 -> 300 | H10: =F10-G10 -> 570 | I10: =Assumptions!C55 -> 1 | J10: =H10*I10 -> 570
B11: Ostool (logistics) | C11: =Assumptions!C19 -> 2200 | D11: =C11*Assumptions!C30 -> 198 | E11: =Assumptions!C40 -> 5.5 | F11: =D11*E11 -> 1089 | G11: =Assumptions!C66 -> 500 | H11: =F11-G11 -> 589 | I11: =Assumptions!C56 -> 1 | J11: =H11*I11 -> 589
B12: Raya Foods | C12: =Assumptions!C20 -> 2050 | D12: =C12*Assumptions!C31 -> 225.5 | E12: =Assumptions!C41 -> 6.5 | F12: =D12*E12 -> 1465.75 | G12: =Assumptions!C67 -> 400 | H12: =F12-G12 -> 1065.75 | I12: =Assumptions!C57 -> 1 | J12: =H12*I12 -> 1065.75
B13: Raya Auto | C13: =Assumptions!C21 -> 1300 | D13: =C13*Assumptions!C32 -> 52 | E13: =Assumptions!C42 -> 5 | F13: =D13*E13 -> 260 | G13: =Assumptions!C68 -> 200 | H13: =F13-G13 -> 60 | I13: =Assumptions!C58 -> 1 | J13: =H13*I13 -> 60
B14: Raya Electric | C14: =Assumptions!C22 -> 700 | D14: =C14*Assumptions!C33 -> 42 | E14: =Assumptions!C43 -> 5 | F14: =D14*E14 -> 210 | G14: =Assumptions!C69 -> 200 | H14: =F14-G14 -> 10 | I14: =Assumptions!C59 -> 1 | J14: =H14*I14 -> 10
B15: Raya Smart Buildings (asset NAV) | C15: =Assumptions!C23 -> 250 | F15: =Assumptions!C48 -> 500 | G15: =Assumptions!C70 -> 100 | H15: =F15-G15 -> 400 | I15: =Assumptions!C60 -> 1 | J15: =H15*I15 -> 400
B16: Raya Restaurants (EV/Sales) | C16: =Assumptions!C24 -> 200 | E16: =Assumptions!C49 -> 1 | F16: =C16*E16 -> 200 | G16: =Assumptions!C71 -> 50 | H16: =F16-G16 -> 150 | I16: =Assumptions!C61 -> 1 | J16: =H16*I16 -> 150
B17: Sum of attributable equity | J17: =SUM(J6:J16) -> 27325.55
B19: Holdco bridge
B20: Gross portfolio equity | J20: =J17 -> 27325.55
B21: less: parent / holdco net debt | J21: =-Assumptions!C73 -> -2000
B22: less: capitalised central cost | J22: =-Assumptions!C74 -> -1500
B23: Gross NAV | J23: =J20-Assumptions!C73-Assumptions!C74 -> 23825.55
B24: Holdco (conglomerate) discount | J24: =Assumptions!C75 -> 0.1
B25: Post-discount NAV | J25: =J23*(1-Assumptions!C75) -> 21442.995
B26: Shares (mn) | J26: =Assumptions!C7 -> 4281.2978
B27: NAV per share (EGP) | J27: =J25/Assumptions!C7 -> 5.0085269
B28: vs spot | J28: =J27/Assumptions!C6-1 -> -0.34954196

Sheet Segments
B2: RAYA — Segment revenue & scorecard
B3: FY2025 revenue by portfolio company (disclosed for Trade/RIT/Aman; others estimated from the 1Q2025 mix). Contribution and qualitative scorecard.
B5: Segment (EGP mn) | C5: FY25 Rev | D5: % of grp | E5: Note
B6: Raya Trade (distribution) | C6: =Assumptions!C16 -> 23800 | D6: =C6/C17 -> 0.37280702 | E6: Consumer-electronics distribution; thin margin, high turnover
B7: Raya IT (RIT) | C7: =Assumptions!C14 -> 18400 | D7: =C7/C17 -> 0.28822055 | E7: Systems integration + data centres; +70% FY25, KSA Vision-2030
B8: Aman Holding (fintech/NBFC) | C8: =Assumptions!C15 -> 9600 | D8: =C8/C17 -> 0.15037594 | E8: Consumer finance, microfinance, e-payments; crown jewel
B9: Raya FMCG | C9: =Assumptions!C18 -> 2900 | D9: =C9/C17 -> 0.045426065 | E9: FMCG distribution
B10: Raya Customer Experience (RACC) | C10: =Assumptions!C17 -> 2440 | D10: =C10/C17 -> 0.038220551 | E10: Listed BPO; Raya moving to full ownership
B11: Ostool (logistics) | C11: =Assumptions!C19 -> 2200 | D11: =C11/C17 -> 0.034461153 | E11: Land transport & logistics
B12: Raya Foods | C12: =Assumptions!C20 -> 2050 | D12: =C12/C17 -> 0.032111529 | E12: Frozen fruit/veg exports
B13: Raya Auto | C13: =Assumptions!C21 -> 1300 | D13: =C13/C17 -> 0.020363409 | E13: XPeng/EV distribution; Alturki KSA JV
B14: Raya Electric | C14: =Assumptions!C22 -> 700 | D14: =C14/C17 -> 0.010964912 | E14: Haier/LG appliance JV
B15: Raya Smart Buildings | C15: =Assumptions!C23 -> 250 | D15: =C15/C17 -> 0.0039160401 | E15: Smart offices; Riyadh EIC
B16: Raya Restaurants | C16: =Assumptions!C24 -> 200 | D16: =C16/C17 -> 0.0031328321 | E16: Ovio, Loris, Lebanese Bakery
B17: Total | C17: =SUM(C6:C16) -> 63840

Sheet Relative & Normalized
B2: RAYA — Relative & Normalized reads
B3: Cross-checks on the SOTP: peer-multiple (floor) and normalized-earnings (ceiling).
B6: Relative multiples
B7: FY2025 NPAT attributable | C7: ='Income Statement'!E18 -> 2588
B8: Peer median P/E | C8: =Assumptions!C101 -> 9
B9: Implied equity (P/E) | C9: =C7*C8 -> 23292
B10: Implied value / share (P/E) | C10: =C9/Assumptions!C7 -> 5.4404065
B11: FY2025 EBITDA | C11: ='Income Statement'!E9 -> 7800
B12: Peer median EV/EBITDA | C12: =Assumptions!C102 -> 6
B13: Implied EV | C13: =C11*C12 -> 46800
B14: less net debt (FY25) | C14: =-('Balance Sheet'!E7-'Balance Sheet'!E14) -> -12000
B15: less minority (est.) | C15: =-C13*Assumptions!C94 -> -5616
B16: Implied value / share (EV/EBITDA) | C16: =(C13+C14+C15)/Assumptions!C7 -> 6.8166247
B17: Relative central (avg) | C17: =AVERAGE(C10,C16) -> 6.1285156
B19: Normalized earnings power
B20: Normalized attributable earnings | C20: =Assumptions!C110 -> 3200
B21: Normalized fair P/E | C21: =Assumptions!C111 -> 11
B22: Implied equity | C22: =C20*C21 -> 35200
B23: Normalized value / share | C23: =C22/Assumptions!C7 -> 8.2218061

Sheet DCF
B2: RAYA — Group FCFF DCF (cross-check)
B3: 5-year explicit FCFF + Gordon terminal. Caveat: Aman is a financial whose funding flows distort consolidated FCFF; treat as a cross-check on the SOTP, not the primary lens.
B5: EGP mn | C5: FY2026E | D5: FY2027E | E5: FY2028E | F5: FY2029E | G5: FY2030E
B6: Revenue | C6: ='Income Statement'!F6 -> 82977.7 | D6: ='Income Statement'!G6 -> 102892.35 | E6: ='Income Statement'!H6 -> 123470.82 | F6: ='Income Statement'!I6 -> 144460.86 | G6: ='Income Statement'!J6 -> 164685.38
B7: EBIT | C7: ='Income Statement'!F12 -> 8795.6362 | D7: ='Income Statement'!G12 -> 11318.158 | E7: ='Income Statement'!H12 -> 13828.732 | F7: ='Income Statement'!I12 -> 16468.538 | G7: ='Income Statement'!J12 -> 18938.818
B8: NOPAT = EBIT x (1-tax) | C8: =C7*(1-Assumptions!C79) -> 6596.7271 | D8: =D7*(1-Assumptions!C79) -> 8488.6187 | E8: =E7*(1-Assumptions!C79) -> 10371.549 | F8: =F7*(1-Assumptions!C79) -> 12351.403 | G8: =G7*(1-Assumptions!C79) -> 14204.114
B9: add: D&A | C9: =-'Income Statement'!F11 -> 1659.554 | D9: =-'Income Statement'!G11 -> 2057.847 | E9: =-'Income Statement'!H11 -> 2469.4164 | F9: =-'Income Statement'!I11 -> 2889.2171 | G9: =-'Income Statement'!J11 -> 3293.7075
B10: less: Capex | C10: =-'Income Statement'!F6*Assumptions!C92 -> -1991.4648 | D10: =-'Income Statement'!G6*Assumptions!C92 -> -2469.4164 | E10: =-'Income Statement'!H6*Assumptions!C92 -> -2963.2996 | F10: =-'Income Statement'!I6*Assumptions!C92 -> -3467.0606 | G10: =-'Income Statement'!J6*Assumptions!C92 -> -3952.449
B11: less: Δ NWC | C11: =-('Income Statement'!F6-'Income Statement'!E6)*Assumptions!C93 -> -4212.714 | D11: =-('Income Statement'!G6-'Income Statement'!F6)*Assumptions!C93 -> -4381.2226 | E11: =-('Income Statement'!H6-'Income Statement'!G6)*Assumptions!C93 -> -4527.2633 | F11: =-('Income Statement'!I6-'Income Statement'!H6)*Assumptions!C93 -> -4617.8086 | G11: =-('Income Statement'!J6-'Income Statement'!I6)*Assumptions!C93 -> -4449.3944
B12: FCFF | C12: =C8+C9+C10+C11 -> 2052.1024 | D12: =D8+D9+D10+D11 -> 3695.8268 | E12: =E8+E9+E10+E11 -> 5350.4021 | F12: =F8+F9+F10+F11 -> 7155.7512 | G12: =G8+G9+G10+G11 -> 9095.9778
B13: Period (t) | C13: 1 | D13: 2 | E13: 3 | F13: 4 | G13: 5
B14: Discount factor | C14: =1/(1+Assumptions!C77)^C13 -> 0.8097166 | D14: =1/(1+Assumptions!C77)^D13 -> 0.65564097 | E14: =1/(1+Assumptions!C77)^E13 -> 0.53088338 | F14: =1/(1+Assumptions!C77)^F13 -> 0.42986508 | G14: =1/(1+Assumptions!C77)^G13 -> 0.34806889
B15: PV of FCFF | C15: =C12*C14 -> 1661.6213 | D15: =D12*D14 -> 2423.1354 | E15: =E12*E14 -> 2840.4395 | F15: =F12*F14 -> 3076.0076 | G15: =G12*G14 -> 3166.0269
B17: Sum PV (explicit) | C17: =SUM(C15:G15) -> 13167.231
B18: Terminal value (Gordon) | C18: =G12*(1+Assumptions!C78)/(Assumptions!C77-Assumptions!C78) -> 63378.426
B19: PV of terminal value | C19: =C18*G14 -> 22060.059
B20: Enterprise value | C20: =C17+C19 -> 35227.289
B21: less: net debt (FY25) | C21: =-('Balance Sheet'!E7-'Balance Sheet'!E14) -> -12000
B22: Equity value | C22: =C20+C21 -> 23227.289
B23: Attributable (x (1-minority)) | C23: =C22*(1-Assumptions!C94) -> 20440.015
B24: DCF value / share (EGP) | C24: =C23/Assumptions!C7 -> 4.7742567

Sheet Income Statement
B2: RAYA — Consolidated Income Statement
B3: 3 years historical (sourced) + 5-year forecast (formula-driven from Assumptions). Historical interest/tax split estimated to reconcile to reported NPAT.
B5: EGP mn | C5: FY2023 | D5: FY2024 | E5: FY2025 | F5: FY2026E | G5: FY2027E | H5: FY2028E | I5: FY2029E | J5: FY2030E
B6: Revenue | C6: 31300 | D6: 45119 | E6: 63829 | F6: =E6*(1+Assumptions!C80) -> 82977.7 | G6: =F6*(1+Assumptions!C81) -> 102892.35 | H6: =G6*(1+Assumptions!C82) -> 123470.82 | I6: =H6*(1+Assumptions!C83) -> 144460.86 | J6: =I6*(1+Assumptions!C84) -> 164685.38
B7: Gross profit | C7: 6260 | D7: 9430 | E7: 13700 | F7: =F6*Assumptions!C85 -> 18255.094 | G7: =G6*Assumptions!C85 -> 22636.317 | H7: =H6*Assumptions!C85 -> 27163.58 | I7: =I6*Assumptions!C85 -> 31781.388 | J7: =J6*Assumptions!C85 -> 36230.783
B8: Gross margin | C8: =C7/C6 -> 0.2 | D8: =D7/D6 -> 0.20900286 | E8: =E7/E6 -> 0.21463598 | F8: =F7/F6 -> 0.22 | G8: =G7/G6 -> 0.22 | H8: =H7/H6 -> 0.22 | I8: =I7/I6 -> 0.22 | J8: =J7/J6 -> 0.22
B9: EBITDA | C9: 2974 | D9: 4875 | E9: 7800 | F9: =F6*Assumptions!C86 -> 10455.19 | G9: =G6*Assumptions!C87 -> 13376.005 | H9: =H6*Assumptions!C88 -> 16298.148 | I9: =I6*Assumptions!C89 -> 19357.755 | J9: =J6*Assumptions!C90 -> 22232.526
B10: EBITDA margin | C10: =C9/C6 -> 0.095015974 | D10: =D9/D6 -> 0.10804761 | E10: =E9/E6 -> 0.12220151 | F10: =F9/F6 -> 0.126 | G10: =G9/G6 -> 0.13 | H10: =H9/H6 -> 0.132 | I10: =I9/I6 -> 0.134 | J10: =J9/J6 -> 0.135
B11: Depreciation & amortisation | C11: -400 | D11: -620 | E11: -1250 | F11: =-F6*Assumptions!C91 -> -1659.554 | G11: =-G6*Assumptions!C91 -> -2057.847 | H11: =-H6*Assumptions!C91 -> -2469.4164 | I11: =-I6*Assumptions!C91 -> -2889.2171 | J11: =-J6*Assumptions!C91 -> -3293.7075
B12: EBIT | C12: =C9+C11 -> 2574 | D12: =D9+D11 -> 4255 | E12: =E9+E11 -> 6550 | F12: =F9+F11 -> 8795.6362 | G12: =G9+G11 -> 11318.158 | H12: =H9+H11 -> 13828.732 | I12: =I9+I11 -> 16468.538 | J12: =J9+J11 -> 18938.818
B13: Net finance cost (incl. FX) | C13: -1822 | D13: -1735 | E13: -2643 | F13: =-F6*Assumptions!C105 -> -2738.2641 | G13: =-G6*Assumptions!C105 -> -3395.4475 | H13: =-H6*Assumptions!C105 -> -4074.537 | I13: =-I6*Assumptions!C105 -> -4767.2083 | J13: =-J6*Assumptions!C105 -> -5434.6174
B14: Profit before tax | C14: =C12+C13 -> 752 | D14: =D12+D13 -> 2520 | E14: =E12+E13 -> 3907 | F14: =F12+F13 -> 6057.3721 | G14: =G12+G13 -> 7922.7108 | H14: =H12+H13 -> 9754.1946 | I14: =I12+I13 -> 11701.329 | J14: =J12+J13 -> 13504.201
B15: Income tax | C15: -188 | D15: -630 | E15: -977 | F15: =-F14*Assumptions!C79 -> -1514.343 | G15: =-G14*Assumptions!C79 -> -1980.6777 | H15: =-H14*Assumptions!C79 -> -2438.5486 | I15: =-I14*Assumptions!C79 -> -2925.3323 | J15: =-J14*Assumptions!C79 -> -3376.0502
B16: NPAT (incl. minority) | C16: =C14+C15 -> 564 | D16: =D14+D15 -> 1890 | E16: =E14+E15 -> 2930 | F16: =F14+F15 -> 4543.0291 | G16: =G14+G15 -> 5942.0331 | H16: =H14+H15 -> 7315.6459 | I16: =I14+I15 -> 8775.997 | J16: =J14+J15 -> 10128.151
B17: Minority interest | C17: -74 | D17: -202 | E17: -342 | F17: =-F16*Assumptions!C94 -> -545.16349 | G17: =-G16*Assumptions!C94 -> -713.04397 | H17: =-H16*Assumptions!C94 -> -877.87751 | I17: =-I16*Assumptions!C94 -> -1053.1196 | J17: =-J16*Assumptions!C94 -> -1215.3781
B18: NPAT attributable | C18: =C16+C17 -> 490 | D18: =D16+D17 -> 1688 | E18: =E16+E17 -> 2588 | F18: =F16+F17 -> 3997.8656 | G18: =G16+G17 -> 5228.9891 | H18: =H16+H17 -> 6437.7684 | I18: =I16+I17 -> 7722.8774 | J18: =J16+J17 -> 8912.7726
B19: EPS (EGP) | C19: =C18/Assumptions!C7 -> 0.11445128 | D19: =D18/Assumptions!C7 -> 0.39427297 | E19: =E18/Assumptions!C7 -> 0.60448961 | F19: =F18/Assumptions!C7 -> 0.9337976 | G19: =G18/Assumptions!C7 -> 1.2213561 | H19: =H18/Assumptions!C7 -> 1.5036956 | I19: =I18/Assumptions!C7 -> 1.8038636 | J19: =J18/Assumptions!C7 -> 2.0817923

Sheet Balance Sheet
B2: RAYA — Consolidated Balance Sheet
B3: 3y historical (sourced) + 5y forecast. Forecast built on the accounting identity (assets = equity + liabilities); cash is the residual.
B5: EGP mn | C5: FY2023 | D5: FY2024 | E5: FY2025 | F5: FY2026E | G5: FY2027E | H5: FY2028E | I5: FY2029E | J5: FY2030E
B6: Total equity (incl. minority) | C6: 3500 | D6: 4752 | E6: 7500 | F6: =E6+'Income Statement'!F16-Assumptions!C106*'Income Statement'!F18 -> 11763.178 | G6: =F6+'Income Statement'!G16-Assumptions!C106*'Income Statement'!G18 -> 17339.182 | H6: =G6+'Income Statement'!H16-Assumptions!C106*'Income Statement'!H18 -> 24204.184 | I6: =H6+'Income Statement'!I16-Assumptions!C106*'Income Statement'!I18 -> 32439.58 | J6: =I6+'Income Statement'!J16-Assumptions!C106*'Income Statement'!J18 -> 41943.837
B7: Total debt | C7: 10000 | D7: 13362 | E7: 15000 | F7: =E7*(1+Assumptions!C107*Assumptions!C80) -> 17700 | G7: =F7*(1+Assumptions!C107*Assumptions!C81) -> 20248.8 | H7: =G7*(1+Assumptions!C107*Assumptions!C82) -> 22678.656 | I7: =H7*(1+Assumptions!C107*Assumptions!C83) -> 24991.879 | J7: =I7*(1+Assumptions!C107*Assumptions!C84) -> 27091.197
B8: Trade & other payables | C8: 14500 | D8: 20998 | E8: 28180 | F8: ='Income Statement'!F6*Assumptions!C108 -> 36510.188 | G8: ='Income Statement'!G6*Assumptions!C108 -> 45272.633 | H8: ='Income Statement'!H6*Assumptions!C108 -> 54327.16 | I8: ='Income Statement'!I6*Assumptions!C108 -> 63562.777 | J8: ='Income Statement'!J6*Assumptions!C108 -> 72461.566
B9: Total liabilities | C9: =C7+C8 -> 24500 | D9: =D7+D8 -> 34360 | E9: =E7+E8 -> 43180 | F9: =F7+F8 -> 54210.188 | G9: =G7+G8 -> 65521.433 | H9: =H7+H8 -> 77005.816 | I9: =I7+I8 -> 88554.656 | J9: =J7+J8 -> 99552.762
B10: Total assets | C10: 28000 | D10: 39112 | E10: 50680 | F10: =F6+F9 -> 65973.366 | G10: =G6+G9 -> 82860.615 | H10: =H6+H9 -> 101210 | I10: =I6+I9 -> 120994.24 | J10: =J6+J9 -> 141496.6
B11: Non-current assets | C11: 4000 | D11: 5185 | E11: 5300 | F11: =E11+'Income Statement'!F6*Assumptions!C92+'Income Statement'!F11 -> 5631.9108 | G11: =F11+'Income Statement'!G6*Assumptions!C92+'Income Statement'!G11 -> 6043.4802 | H11: =G11+'Income Statement'!H6*Assumptions!C92+'Income Statement'!H11 -> 6537.3635 | I11: =H11+'Income Statement'!I6*Assumptions!C92+'Income Statement'!I11 -> 7115.2069 | J11: =I11+'Income Statement'!J6*Assumptions!C92+'Income Statement'!J11 -> 7773.9484
B12: Current assets | C12: =C10-C11 -> 24000 | D12: =D10-D11 -> 33927 | E12: =E10-E11 -> 45380 | F12: =F10-F11 -> 60341.456 | G12: =G10-G11 -> 76817.135 | H12: =H10-H11 -> 94672.637 | I12: =I10-I11 -> 113879.03 | J12: =J10-J11 -> 133722.65
B13: Receivables & inventory | C13: 21500 | D13: 29915 | E13: 42380 | F13: ='Income Statement'!F6*Assumptions!C109 -> 54765.282 | G13: ='Income Statement'!G6*Assumptions!C109 -> 67908.95 | H13: ='Income Statement'!H6*Assumptions!C109 -> 81490.74 | I13: ='Income Statement'!I6*Assumptions!C109 -> 95344.165 | J13: ='Income Statement'!J6*Assumptions!C109 -> 108692.35
B14: Cash & equivalents | C14: 2500 | D14: 4012 | E14: 3000 | F14: =F12-F13 -> 5576.1737 | G14: =G12-G13 -> 8908.1856 | H14: =H12-H13 -> 13181.897 | I14: =I12-I13 -> 18534.864 | J14: =J12-J13 -> 25030.302
B15: Check: A − L − E (=0) | C15: =C10-C9-C6 -> 0 | D15: =D10-D9-D6 -> 0 | E15: =E10-E9-E6 -> 0 | F15: =F10-F9-F6 -> 0 | G15: =G10-G9-G6 -> 0 | H15: =H10-H9-H6 -> 0 | I15: =I10-I9-I6 -> 0 | J15: =J10-J9-J6 -> 0

Sheet Cash Flow
B2: RAYA — Consolidated Cash Flow
B3: Indirect method, derived from the IS/BS so it always ties to the balance-sheet cash movement. FY2023 deltas n/a (no prior year).
B5: EGP mn | C5: FY2023 | D5: FY2024 | E5: FY2025 | F5: FY2026E | G5: FY2027E | H5: FY2028E | I5: FY2029E | J5: FY2030E
B6: NPAT (incl. minority) | D6: ='Income Statement'!D16 -> 1890 | E6: ='Income Statement'!E16 -> 2930 | F6: ='Income Statement'!F16 -> 4543.0291 | G6: ='Income Statement'!G16 -> 5942.0331 | H6: ='Income Statement'!H16 -> 7315.6459 | I6: ='Income Statement'!I16 -> 8775.997 | J6: ='Income Statement'!J16 -> 10128.151
B7: add: D&A | D7: =-'Income Statement'!D11 -> 620 | E7: =-'Income Statement'!E11 -> 1250 | F7: =-'Income Statement'!F11 -> 1659.554 | G7: =-'Income Statement'!G11 -> 2057.847 | H7: =-'Income Statement'!H11 -> 2469.4164 | I7: =-'Income Statement'!I11 -> 2889.2171 | J7: =-'Income Statement'!J11 -> 3293.7075
B8: less: Δ receivables & inventory | D8: =-(D13-C13) -> 1082.856 | E8: =-(E13-D13) -> 449.04 | F8: =-(F13-E13) -> 459.5688 | G8: =-(G13-F13) -> 477.95155 | H8: =-(H13-G13) -> 493.88327 | I8: =-(I13-H13) -> 503.76094 | J8: =-(J13-I13) -> 485.38848
B9: add: Δ payables | D9: =D8-C8 -> 1082.856 | E9: =E8-D8 -> -633.816 | F9: =F8-E8 -> 10.5288 | G9: =G8-F8 -> 18.382752 | H9: =H8-G8 -> 15.931718 | I9: =I8-H8 -> 9.8776654 | J9: =J8-I8 -> -18.372458
B10: Other / non-cash & FX (net) | D10: =(D14-C14)-(D6+D7+D8+D9)-(-'Income Statement'!D6*Assumptions!C92)-((D7-C7)-Assumptions!C106*'Income Statement'!D18) -> -3474.696 | E10: =(E14-D14)-(E6+E7+E8+E9)-(-'Income Statement'!E6*Assumptions!C92)-((E7-D7)-Assumptions!C106*'Income Statement'!E18) -> -2902.168 | F10: =(F14-E14)-(F6+F7+F8+F9)-(-'Income Statement'!F6*Assumptions!C92)-((F7-E7)-Assumptions!C106*'Income Statement'!F18) -> -5031.3653 | G10: =(G14-F14)-(G6+G7+G8+G9)-(-'Income Statement'!G6*Assumptions!C92)-((G7-F7)-Assumptions!C106*'Income Statement'!G18) -> -6070.3228 | H10: =(H14-G14)-(H6+H7+H8+H9)-(-'Income Statement'!H6*Assumptions!C92)-((H7-G7)-Assumptions!C106*'Income Statement'!H18) -> -7279.2268 | I10: =(I14-H14)-(I6+I7+I8+I9)-(-'Income Statement'!I6*Assumptions!C92)-((I7-H7)-Assumptions!C106*'Income Statement'!I18) -> -8582.7602 | J10: =(J14-I14)-(J6+J7+J8+J9)-(-'Income Statement'!J6*Assumptions!C92)-((J7-I7)-Assumptions!C106*'Income Statement'!J18) -> -9732.3319
B11: Cash flow from operations | D11: =SUM(D6:D10) -> 1201.016 | E11: =SUM(E6:E10) -> 1093.056 | F11: =SUM(F6:F10) -> 1641.3154 | G11: =SUM(G6:G10) -> 2425.8916 | H11: =SUM(H6:H10) -> 3015.6505 | I11: =SUM(I6:I10) -> 3596.0926 | J11: =SUM(J6:J10) -> 4156.5423
B12: Capex | D12: =-'Income Statement'!D6*Assumptions!C92 -> -1082.856 | E12: =-'Income Statement'!E6*Assumptions!C92 -> -1531.896 | F12: =-'Income Statement'!F6*Assumptions!C92 -> -1991.4648 | G12: =-'Income Statement'!G6*Assumptions!C92 -> -2469.4164 | H12: =-'Income Statement'!H6*Assumptions!C92 -> -2963.2996 | I12: =-'Income Statement'!I6*Assumptions!C92 -> -3467.0606 | J12: =-'Income Statement'!J6*Assumptions!C92 -> -3952.449
B13: Cash flow from investing | D13: =D12 -> -1082.856 | E13: =E12 -> -1531.896 | F13: =F12 -> -1991.4648 | G13: =G12 -> -2469.4164 | H13: =H12 -> -2963.2996 | I13: =I12 -> -3467.0606 | J13: =J12 -> -3952.449
B14: Δ debt | D14: =D7-C7 -> 620 | E14: =E7-D7 -> 630 | F14: =F7-E7 -> 409.554 | G14: =G7-F7 -> 398.29296 | H14: =H7-G7 -> 411.56939 | I14: =I7-H7 -> 419.80078 | J14: =J7-I7 -> 404.4904
B15: Dividends | D15: =-Assumptions!C106*'Income Statement'!D18 -> -118.16 | E15: =-Assumptions!C106*'Income Statement'!E18 -> -181.16 | F15: =-Assumptions!C106*'Income Statement'!F18 -> -279.85059 | G15: =-Assumptions!C106*'Income Statement'!G18 -> -366.02924 | H15: =-Assumptions!C106*'Income Statement'!H18 -> -450.64379 | I15: =-Assumptions!C106*'Income Statement'!I18 -> -540.60142 | J15: =-Assumptions!C106*'Income Statement'!J18 -> -623.89408
B16: Cash flow from financing | D16: =D14+D15 -> 501.84 | E16: =E14+E15 -> 448.84 | F16: =F14+F15 -> 129.70341 | G16: =G14+G15 -> 32.263721 | H16: =H14+H15 -> -39.074398 | I16: =I14+I15 -> -120.80064 | J16: =J14+J15 -> -219.40368
B17: Net change in cash | D17: =D11+D13+D16 -> 620 | E17: =E11+E13+E16 -> 10 | F17: =F11+F13+F16 -> -220.446 | G17: =G11+G13+G16 -> -11.26104 | H17: =H11+H13+H16 -> 13.276432 | I17: =I11+I13+I16 -> 8.2313878 | J17: =J11+J13+J16 -> -15.310381
B18: Closing cash (ties to BS) | D18: =D14 -> 620 | E18: =E14 -> 630 | F18: =F14 -> 409.554 | G18: =G14 -> 398.29296 | H18: =H14 -> 411.56939 | I18: =I14 -> 419.80078 | J18: =J14 -> 404.4904

Sheet Summary Financials
B2: RAYA — Summary Financials
B3: Every cell links to the Income Statement / Balance Sheet / Cash Flow sheets.
B5: EGP mn | C5: FY2023 | D5: FY2024 | E5: FY2025 | F5: FY2026E | G5: FY2027E | H5: FY2028E | I5: FY2029E | J5: FY2030E
B6: Revenue | C6: ='Income Statement'!C6 -> 31300 | D6: ='Income Statement'!D6 -> 45119 | E6: ='Income Statement'!E6 -> 63829 | F6: ='Income Statement'!F6 -> 82977.7 | G6: ='Income Statement'!G6 -> 102892.35 | H6: ='Income Statement'!H6 -> 123470.82 | I6: ='Income Statement'!I6 -> 144460.86 | J6: ='Income Statement'!J6 -> 164685.38
B7: EBITDA | C7: ='Income Statement'!C9 -> 2974 | D7: ='Income Statement'!D9 -> 4875 | E7: ='Income Statement'!E9 -> 7800 | F7: ='Income Statement'!F9 -> 10455.19 | G7: ='Income Statement'!G9 -> 13376.005 | H7: ='Income Statement'!H9 -> 16298.148 | I7: ='Income Statement'!I9 -> 19357.755 | J7: ='Income Statement'!J9 -> 22232.526
B8: EBIT | C8: ='Income Statement'!C12 -> 2574 | D8: ='Income Statement'!D12 -> 4255 | E8: ='Income Statement'!E12 -> 6550 | F8: ='Income Statement'!F12 -> 8795.6362 | G8: ='Income Statement'!G12 -> 11318.158 | H8: ='Income Statement'!H12 -> 13828.732 | I8: ='Income Statement'!I12 -> 16468.538 | J8: ='Income Statement'!J12 -> 18938.818
B9: NPAT attributable | C9: ='Income Statement'!C18 -> 490 | D9: ='Income Statement'!D18 -> 1688 | E9: ='Income Statement'!E18 -> 2588 | F9: ='Income Statement'!F18 -> 3997.8656 | G9: ='Income Statement'!G18 -> 5228.9891 | H9: ='Income Statement'!H18 -> 6437.7684 | I9: ='Income Statement'!I18 -> 7722.8774 | J9: ='Income Statement'!J18 -> 8912.7726
B10: EPS (EGP) | C10: ='Income Statement'!C19 -> 0.11445128 | D10: ='Income Statement'!D19 -> 0.39427297 | E10: ='Income Statement'!E19 -> 0.60448961 | F10: ='Income Statement'!F19 -> 0.9337976 | G10: ='Income Statement'!G19 -> 1.2213561 | H10: ='Income Statement'!H19 -> 1.5036956 | I10: ='Income Statement'!I19 -> 1.8038636 | J10: ='Income Statement'!J19 -> 2.0817923
B11: Total assets | C11: ='Balance Sheet'!C10 -> 28000 | D11: ='Balance Sheet'!D10 -> 39112 | E11: ='Balance Sheet'!E10 -> 50680 | F11: ='Balance Sheet'!F10 -> 65973.366 | G11: ='Balance Sheet'!G10 -> 82860.615 | H11: ='Balance Sheet'!H10 -> 101210 | I11: ='Balance Sheet'!I10 -> 120994.24 | J11: ='Balance Sheet'!J10 -> 141496.6
B12: Total equity | C12: ='Balance Sheet'!C6 -> 3500 | D12: ='Balance Sheet'!D6 -> 4752 | E12: ='Balance Sheet'!E6 -> 7500 | F12: ='Balance Sheet'!F6 -> 11763.178 | G12: ='Balance Sheet'!G6 -> 17339.182 | H12: ='Balance Sheet'!H6 -> 24204.184 | I12: ='Balance Sheet'!I6 -> 32439.58 | J12: ='Balance Sheet'!J6 -> 41943.837
B13: Net debt | C13: ='Balance Sheet'!C7-'Balance Sheet'!C14 -> 7500 | D13: ='Balance Sheet'!D7-'Balance Sheet'!D14 -> 9350 | E13: ='Balance Sheet'!E7-'Balance Sheet'!E14 -> 12000 | F13: ='Balance Sheet'!F7-'Balance Sheet'!F14 -> 12123.826 | G13: ='Balance Sheet'!G7-'Balance Sheet'!G14 -> 11340.614 | H13: ='Balance Sheet'!H7-'Balance Sheet'!H14 -> 9496.7588 | I13: ='Balance Sheet'!I7-'Balance Sheet'!I14 -> 6457.0152 | J13: ='Balance Sheet'!J7-'Balance Sheet'!J14 -> 2060.8945
B14: Cash flow from operations | C14: n/a | D14: ='Cash Flow'!D11 -> 1201.016 | E14: ='Cash Flow'!E11 -> 1093.056 | F14: ='Cash Flow'!F11 -> 1641.3154 | G14: ='Cash Flow'!G11 -> 2425.8916 | H14: ='Cash Flow'!H11 -> 3015.6505 | I14: ='Cash Flow'!I11 -> 3596.0926 | J14: ='Cash Flow'!J11 -> 4156.5423

Sheet Monte Carlo
B2: RAYA — Monte Carlo (YZ-HAR engine, drift OFF)
B3: Distribution outputs from mc_v2.py (50,000 paths, seed 42). Width = pooled log-HAR on a gap-aware Yang-Zhang proxy; Student-t(5) body; secular drift OFF; 16-factor overlay. Paths diffuse from spot — the §1 value gap is kept out of the drift.
B6: Engine inputs
B7: Spot (EGP) | C7: =Assumptions!C6 -> 7.7
B8: YZ-HAR annualised vol | C8: =Assumptions!C96 -> 0.63100986
B9: Net 3-month factor drift | C9: =Assumptions!C97 -> 0.0195
B10: Horizon (days) | C10: =Assumptions!C98 -> 60
B11: Paths | C11: =Assumptions!C99 -> 50000
B13: Percentile table (EGP)
B14: Percentile | C14: T+20 | D14: move | E14: T+60 | F14: move
B15: P5 | C15: 5.68 | D15: =C15/Assumptions!C6-1 -> -0.26233766 | E15: 4.6 | F15: =E15/Assumptions!C6-1 -> -0.4025974
B16: P25 | C16: 6.9 | D16: =C16/Assumptions!C6-1 -> -0.1038961 | E16: 6.4 | F16: =E16/Assumptions!C6-1 -> -0.16883117
B17: P50 | C17: 7.74 | D17: =C17/Assumptions!C6-1 -> 0.0051948052 | E17: 7.79 | F17: =E17/Assumptions!C6-1 -> 0.011688312
B18: P75 | C18: 8.66 | D18: =C18/Assumptions!C6-1 -> 0.12467532 | E18: 9.45 | F18: =E18/Assumptions!C6-1 -> 0.22727273
B19: P95 | C19: 10.48 | D19: =C19/Assumptions!C6-1 -> 0.36103896 | E19: 13.06 | F19: =E19/Assumptions!C6-1 -> 0.6961039
B21: 50% IQR band T+20 | C21: 6.9 | E21: 8.66
B22: 50% IQR band T+60 | C22: 6.4 | E22: 9.45
B24: Touch probabilities (by T+60)
B25: Direction | C25: Level | D25: P(touch)
B26: Upside 10.01 | C26: 10.01 | D26: 0.346
B27: Upside 9.24 | C27: 9.24 | D27: 0.497
B28: Upside 8.85 | C28: 8.85 | D28: 0.592
B29: Upside 8.47 | C29: 8.47 | D29: 0.697
B30: Upside 8.09 | C30: 8.09 | D30: 0.815
B31: Downside 7.31 | C31: 7.31 | D31: 0.784
B32: Downside 6.93 | C32: 6.93 | D32: 0.648
B33: Downside 6.54 | C33: 6.54 | D33: 0.512
B34: Downside 6.16 | C34: 6.16 | D34: 0.394
B35: Downside 5.39 | C35: 5.39 | D35: 0.206

Sheet Sensitivity
B2: RAYA — Sensitivity: NAV/share vs Aman P/E and holdco discount
B3: Two-way grid recomputing the SOTP NAV per share. Every cell links to the SOTP portfolio ex-Aman and the Aman NI in Assumptions/SOTP.
B6: Portfolio ex-Aman (attrib.) | C6: =SOTP!J17-SOTP!J7 -> 18132.59
B7: Aman NI x ownership | C7: =SOTP!D7*SOTP!I7 -> 656.64
B9: Aman P/E ↓ / Discount → | C9: 0 | D9: 0.05 | E9: 0.1 | F9: 0.15 | G9: 0.2 | H9: 0.25
B10: 8.0x | C10: =((C6+C7*8)-Assumptions!C73-Assumptions!C74)*(1-C9)/Assumptions!C7 -> 4.6447855 | D10: =((C6+C7*8)-Assumptions!C73-Assumptions!C74)*(1-D9)/Assumptions!C7 -> 4.4125463 | E10: =((C6+C7*8)-Assumptions!C73-Assumptions!C74)*(1-E9)/Assumptions!C7 -> 4.180307 | F10: =((C6+C7*8)-Assumptions!C73-Assumptions!C74)*(1-F9)/Assumptions!C7 -> 3.9480677 | G10: =((C6+C7*8)-Assumptions!C73-Assumptions!C74)*(1-G9)/Assumptions!C7 -> 3.7158284 | H10: =((C6+C7*8)-Assumptions!C73-Assumptions!C74)*(1-H9)/Assumptions!C7 -> 3.4835892
B11: 10.0x | C11: =((C6+C7*10)-Assumptions!C73-Assumptions!C74)*(1-C9)/Assumptions!C7 -> 4.9515337 | D11: =((C6+C7*10)-Assumptions!C73-Assumptions!C74)*(1-D9)/Assumptions!C7 -> 4.703957 | E11: =((C6+C7*10)-Assumptions!C73-Assumptions!C74)*(1-E9)/Assumptions!C7 -> 4.4563803 | F11: =((C6+C7*10)-Assumptions!C73-Assumptions!C74)*(1-F9)/Assumptions!C7 -> 4.2088036 | G11: =((C6+C7*10)-Assumptions!C73-Assumptions!C74)*(1-G9)/Assumptions!C7 -> 3.9612269 | H11: =((C6+C7*10)-Assumptions!C73-Assumptions!C74)*(1-H9)/Assumptions!C7 -> 3.7136502
B12: 12.0x | C12: =((C6+C7*12)-Assumptions!C73-Assumptions!C74)*(1-C9)/Assumptions!C7 -> 5.2582818 | D12: =((C6+C7*12)-Assumptions!C73-Assumptions!C74)*(1-D9)/Assumptions!C7 -> 4.9953677 | E12: =((C6+C7*12)-Assumptions!C73-Assumptions!C74)*(1-E9)/Assumptions!C7 -> 4.7324536 | F12: =((C6+C7*12)-Assumptions!C73-Assumptions!C74)*(1-F9)/Assumptions!C7 -> 4.4695395 | G12: =((C6+C7*12)-Assumptions!C73-Assumptions!C74)*(1-G9)/Assumptions!C7 -> 4.2066254 | H12: =((C6+C7*12)-Assumptions!C73-Assumptions!C74)*(1-H9)/Assumptions!C7 -> 3.9437113
B13: 14.0x | C13: =((C6+C7*14)-Assumptions!C73-Assumptions!C74)*(1-C9)/Assumptions!C7 -> 5.5650299 | D13: =((C6+C7*14)-Assumptions!C73-Assumptions!C74)*(1-D9)/Assumptions!C7 -> 5.2867784 | E13: =((C6+C7*14)-Assumptions!C73-Assumptions!C74)*(1-E9)/Assumptions!C7 -> 5.0085269 | F13: =((C6+C7*14)-Assumptions!C73-Assumptions!C74)*(1-F9)/Assumptions!C7 -> 4.7302754 | G13: =((C6+C7*14)-Assumptions!C73-Assumptions!C74)*(1-G9)/Assumptions!C7 -> 4.4520239 | H13: =((C6+C7*14)-Assumptions!C73-Assumptions!C74)*(1-H9)/Assumptions!C7 -> 4.1737724
B14: 16.0x | C14: =((C6+C7*16)-Assumptions!C73-Assumptions!C74)*(1-C9)/Assumptions!C7 -> 5.871778 | D14: =((C6+C7*16)-Assumptions!C73-Assumptions!C74)*(1-D9)/Assumptions!C7 -> 5.5781891 | E14: =((C6+C7*16)-Assumptions!C73-Assumptions!C74)*(1-E9)/Assumptions!C7 -> 5.2846002 | F14: =((C6+C7*16)-Assumptions!C73-Assumptions!C74)*(1-F9)/Assumptions!C7 -> 4.9910113 | G14: =((C6+C7*16)-Assumptions!C73-Assumptions!C74)*(1-G9)/Assumptions!C7 -> 4.6974224 | H14: =((C6+C7*16)-Assumptions!C73-Assumptions!C74)*(1-H9)/Assumptions!C7 -> 4.4038335
B15: 18.0x | C15: =((C6+C7*18)-Assumptions!C73-Assumptions!C74)*(1-C9)/Assumptions!C7 -> 6.1785261 | D15: =((C6+C7*18)-Assumptions!C73-Assumptions!C74)*(1-D9)/Assumptions!C7 -> 5.8695998 | E15: =((C6+C7*18)-Assumptions!C73-Assumptions!C74)*(1-E9)/Assumptions!C7 -> 5.5606735 | F15: =((C6+C7*18)-Assumptions!C73-Assumptions!C74)*(1-F9)/Assumptions!C7 -> 5.2517472 | G15: =((C6+C7*18)-Assumptions!C73-Assumptions!C74)*(1-G9)/Assumptions!C7 -> 4.9428209 | H15: =((C6+C7*18)-Assumptions!C73-Assumptions!C74)*(1-H9)/Assumptions!C7 -> 4.6338946
B17: Spot (reference) | C17: =Assumptions!C6 -> 7.7

Sheet Per-Share & Ratios
B2: RAYA — Per-share & ratios
B3: Linked to the statements and Assumptions (spot, shares). P/E and P/B use the current spot against each year's figure.
C5: FY2023 | D5: FY2024 | E5: FY2025 | F5: FY2026E | G5: FY2027E | H5: FY2028E | I5: FY2029E | J5: FY2030E
B6: EPS (EGP) | C6: ='Income Statement'!C19 -> 0.11445128 | D6: ='Income Statement'!D19 -> 0.39427297 | E6: ='Income Statement'!E19 -> 0.60448961 | F6: ='Income Statement'!F19 -> 0.9337976 | G6: ='Income Statement'!G19 -> 1.2213561 | H6: ='Income Statement'!H19 -> 1.5036956 | I6: ='Income Statement'!I19 -> 1.8038636 | J6: ='Income Statement'!J19 -> 2.0817923
B7: BVPS (EGP) | C7: ='Balance Sheet'!C6/Assumptions!C7 -> 0.81750913 | D7: ='Balance Sheet'!D6/Assumptions!C7 -> 1.1099438 | E7: ='Balance Sheet'!E6/Assumptions!C7 -> 1.7518053 | F7: ='Balance Sheet'!F6/Assumptions!C7 -> 2.7475731 | G7: ='Balance Sheet'!G6/Assumptions!C7 -> 4.0499828 | H7: ='Balance Sheet'!H6/Assumptions!C7 -> 5.6534691 | I7: ='Balance Sheet'!I6/Assumptions!C7 -> 7.5770437 | J7: ='Balance Sheet'!J6/Assumptions!C7 -> 9.7969912
B8: P/E (spot) | C8: =Assumptions!C6/'Income Statement'!C19 -> 67.277536 | D8: =Assumptions!C6/'Income Statement'!D19 -> 19.529617 | E8: =Assumptions!C6/'Income Statement'!E19 -> 12.738019 | F8: =Assumptions!C6/'Income Statement'!F19 -> 8.2458982 | G8: =Assumptions!C6/'Income Statement'!G19 -> 6.3044677 | H8: =Assumptions!C6/'Income Statement'!H19 -> 5.1207174 | I8: =Assumptions!C6/'Income Statement'!I19 -> 4.2686153 | J8: =Assumptions!C6/'Income Statement'!J19 -> 3.698736
B9: P/B (spot) | C9: =Assumptions!C6*Assumptions!C7/'Balance Sheet'!C6 -> 9.4188551 | D9: =Assumptions!C6*Assumptions!C7/'Balance Sheet'!D6 -> 6.9372881 | E9: =Assumptions!C6*Assumptions!C7/'Balance Sheet'!E6 -> 4.3954657 | F9: =Assumptions!C6*Assumptions!C7/'Balance Sheet'!F6 -> 2.8024732 | G9: =Assumptions!C6*Assumptions!C7/'Balance Sheet'!G6 -> 1.9012426 | H9: =Assumptions!C6*Assumptions!C7/'Balance Sheet'!H6 -> 1.3619956 | I9: =Assumptions!C6*Assumptions!C7/'Balance Sheet'!I6 -> 1.0162275 | J9: =Assumptions!C6*Assumptions!C7/'Balance Sheet'!J6 -> 0.78595559
B10: EV/EBITDA (spot) | C10: =(Assumptions!C6*Assumptions!C7+'Balance Sheet'!C7-'Balance Sheet'!C14)/'Income Statement'!C9 -> 13.606588 | D10: =(Assumptions!C6*Assumptions!C7+'Balance Sheet'!D7-'Balance Sheet'!D14)/'Income Statement'!D9 -> 8.6802037 | E10: =(Assumptions!C6*Assumptions!C7+'Balance Sheet'!E7-'Balance Sheet'!E14)/'Income Statement'!E9 -> 5.7648709 | F10: =(Assumptions!C6*Assumptions!C7+'Balance Sheet'!F7-'Balance Sheet'!F14)/'Income Statement'!F9 -> 4.3126733 | G10: =(Assumptions!C6*Assumptions!C7+'Balance Sheet'!G7-'Balance Sheet'!G14)/'Income Statement'!G9 -> 3.3123946 | H10: =(Assumptions!C6*Assumptions!C7+'Balance Sheet'!H7-'Balance Sheet'!H14)/'Income Statement'!H9 -> 2.6053728 | I10: =(Assumptions!C6*Assumptions!C7+'Balance Sheet'!I7-'Balance Sheet'!I14)/'Income Statement'!I9 -> 2.0365486 | J10: =(Assumptions!C6*Assumptions!C7+'Balance Sheet'!J7-'Balance Sheet'!J14)/'Income Statement'!J9 -> 1.5754794
B11: ROE | C11: ='Income Statement'!C18/'Balance Sheet'!C6 -> 0.14 | D11: ='Income Statement'!D18/'Balance Sheet'!D6 -> 0.35521886 | E11: ='Income Statement'!E18/'Balance Sheet'!E6 -> 0.34506667 | F11: ='Income Statement'!F18/'Balance Sheet'!F6 -> 0.3398627 | G11: ='Income Statement'!G18/'Balance Sheet'!G6 -> 0.30157069 | H11: ='Income Statement'!H18/'Balance Sheet'!H6 -> 0.2659775 | I11: ='Income Statement'!I18/'Balance Sheet'!I6 -> 0.23806959 | J11: ='Income Statement'!J18/'Balance Sheet'!J6 -> 0.21249302
B12: Net debt / EBITDA | C12: =('Balance Sheet'!C7-'Balance Sheet'!C14)/'Income Statement'!C9 -> 2.5218561 | D12: =('Balance Sheet'!D7-'Balance Sheet'!D14)/'Income Statement'!D9 -> 1.9179487 | E12: =('Balance Sheet'!E7-'Balance Sheet'!E14)/'Income Statement'!E9 -> 1.5384615 | F12: =('Balance Sheet'!F7-'Balance Sheet'!F14)/'Income Statement'!F9 -> 1.1595988 | G12: =('Balance Sheet'!G7-'Balance Sheet'!G14)/'Income Statement'!G9 -> 0.84783268 | H12: =('Balance Sheet'!H7-'Balance Sheet'!H14)/'Income Statement'!H9 -> 0.58268945 | I12: =('Balance Sheet'!I7-'Balance Sheet'!I14)/'Income Statement'!I9 -> 0.3335622 | J12: =('Balance Sheet'!J7-'Balance Sheet'!J14)/'Income Statement'!J9 -> 0.092697274
B13: Revenue growth | C13: n/a | D13: ='Income Statement'!D6/'Income Statement'!C6-1 -> 0.4415016 | E13: ='Income Statement'!E6/'Income Statement'!D6-1 -> 0.41468118 | F13: ='Income Statement'!F6/'Income Statement'!E6-1 -> 0.3 | G13: ='Income Statement'!G6/'Income Statement'!F6-1 -> 0.24 | H13: ='Income Statement'!H6/'Income Statement'!G6-1 -> 0.2 | I13: ='Income Statement'!I6/'Income Statement'!H6-1 -> 0.17 | J13: ='Income Statement'!J6/'Income Statement'!I6-1 -> 0.14

Sheet Peer & Sector
B2: RAYA — Peer & sector
B3: Egyptian diversified holdcos / distributors. Peer multiples are indicative (aggregator/market data); Raya's own multiples link to this model.
B5: Company | C5: P/E | D5: EV/EBITDA | E5: Note
B6: Qalaa Holdings (CCAP) | C6: 6.5 | D6: 5.5 | E6: Diversified holdco (energy-tilted)
B7: EFG Holding (HRHO) | C7: 7.5 | D7: 6 | E7: Financial services holdco
B8: B Investments (BINV) | C8: 6 | E8: Investment holdco
B9: Egyptian Financial & Ind. peers | C9: 8 | D9: 6.5 | E9: Distributors / industrials
B10: Peer median (Assumptions) | C10: =Assumptions!C101 -> 9 | D10: =Assumptions!C102 -> 6
B11: RAYA (this model, spot) | C11: =Assumptions!C6/'Income Statement'!E19 -> 12.738019 | D11: =(Assumptions!C6*Assumptions!C7+'Balance Sheet'!E7-'Balance Sheet'!E14)/'Income Statement'!E9 -> 5.7648709
