Workbook

Sheet READ FIRST
A1: SALIK COMPANY PJSC (DFM: SALIK) — Testahil valuation model · 11 July 2026
A4: WHAT THIS IS
B5: An educational valuation exercise published free of charge by Testahil. It is NOT investment advice, NOT a
B6: recommendation, and NOT a price target. The preparer is not licensed by any securities regulator.
B7: Every output is a RANGE or a DISTRIBUTION because no single number should be relied on.
A9: HOW TO USE THIS FILE
B10: BLUE cells are the only hard-coded inputs. Everything else is a live formula. Change a blue cell and the
B11: DCF, the lenses, the football field and the sensitivity grids all recalculate.
B12: The Assumptions sheet is the single source of truth for every driver.
A14: WHAT IS COMPANY-SOURCED AND WHAT IS OURS
B15: SOURCED (Salik earnings releases, AR2024, Dubai Media Office, DFM filings): all FY2023-FY2025 and Q1-2026
B16: line items; the concession terms; the dividends declared; the credit ratings; the toll tariffs.
B17: OURS (judgment, flagged throughout): the FY2026-FY2030 trip, tariff, margin and ancillary paths; the cost of
B18: capital; terminal growth; the peer multiple band; the Monte-Carlo horizon.
A20: THE ONE THING TO UNDERSTAND BEFORE READING ANY NUMBER
B21: Our weighted central fair value is AED 4.62 against a spot of AED 5.70.
B22: That gap is NOT an earnings disagreement. Our FY2026E EPS is within 1.4% of FY2025 actual and ABOVE the
B23: Q1-2026 run-rate. The gap is a COST-OF-EQUITY disagreement — and unlike v1, we can now MEASURE it.
B25: v1 of this study defaulted beta to 1.00 because a DFMGI regression failed a sample-size gate (n=19).
B26: v2 rebuilt the market portfolio from the 14 UAE names the MC engine itself uses, and the regression now
B27: PASSES: weekly beta 0.637, n=195, t=6.1, R2 16.2%.
B28: We publish the Blume-adjusted 0.76 (conservative). Fair value moved AED 3.67 -> 4.49.
B30: AND THE CRUX: SALIK's beta was 0.47 BEFORE the war and 1.00 DURING it.
B31: Spot implies 0.52 — inside our measured 95% CI, and almost exactly the
B32: PRE-WAR reading. The same war that cut Q1 traffic 7.7% also DOUBLED the beta. It attacks the numerator
B33: AND the denominator. At spot, the market is pricing both to reverse. See sheet 5.
A35: THE OTHER FINDING — TWO GROWTH ENGINES (sheet 6)
B36: The 8 gates Salik was HANDED at the IPO earn 32% ROIC. The 2 gates the RTA SOLD it in
B37: 2024 earn 9.5% — against a 8.1% WACC. Growth by ACQUIRING gates is not free
B38: growth, and the RTA — grantor, regulator, 75.1% shareholder — is the vendor. Our DCF models ZERO new gates.
A40: AND ONE MORE (sheet 7)
B41: 84% of FY2025's +35.1% toll-revenue growth came from TWO one-off events:
B42: the gate count going 8->10, and the tariff going flat->variable. Only 12% was organic. FY2026 has neither.
A44: CALIBRATION
B45: the calibration back-test (5-yr walk-forward, h=60, carry-anchored benchmark): 11 non-overlapping windows,
B46: verdict PARITY, robust across bootstrap block sizes 2/3/4. SALIK listed 29-Sep-2022, so the panel is short.
B47: The cone is OVER-covered (every realised outcome fell inside the 90% band). Treat the bands as generous.
B49: Full disclosure & disclaimer: see the Word study.

Sheet Summary
A1: SUMMARY — every read at a glance
A3: ANCHOR
A4: Spot (10 Jul 2026 close) | B4: 5.7
A5: Shares outstanding (mn) | B5: 7500
A6: Market cap (AED mn) | B6: 42750
A7: Net debt, Q1-2026 (AED mn) | B7: 4226.4
A8: Enterprise value (AED mn) | B8: =B6+B7
A9: Free float | B9: 0.249
A11: FUNDAMENTAL LENSES — AED per share
A12: Lens | B12: Bear | C12: Central | D12: Bull | E12: Weight | F12: Contribution
A13: FCFF DCF (primary) | B13: 2.8603134 | C13: 4.4899091 | D13: 8.1545327 | E13: 0.45 | F13: =C13*E13
A14: Normalized earnings | B14: 4.1717358 | C14: 5.4413945 | D14: 6.6657083 | E14: 0.2 | F14: =C14*E14
A15: Relative — P/E (=1/yield) | B15: 4.0773307 | C15: 4.8927968 | D15: 5.708263 | E15: 0.2 | F15: =C15*E15
A16: Dividend discount (floor) | B16: 2.5526385 | C16: 3.5468831 | D16: 6.0690825 | E16: 0.15 | F16: =C16*E16
A17: WEIGHTED CENTRAL | B17: =SUMPRODUCT(B13:B16,$E$13:$E$16) | C17: =SUMPRODUCT(C13:C16,$E$13:$E$16) | D17: =SUMPRODUCT(D13:D16,$E$13:$E$16) | E17: =SUM(E13:E16)
A18: Spot | C18: =B4
A19: Weighted central vs spot | C19: =C17/C18-1
A20: Sanity check — concession ends 2071, no perpetuity | C20: 4.0431327 | D20: NOT weighted — a nice-to-know
A22: MONTE CARLO — engine v3, carry-anchored YZ-HAR-t
A23: Horizon | B23: 5% | C23: 25% | D23: Median | E23: 75% | F23: 95% | G23: P(up) | H23: 90% band
A24: T+20 · 7 Aug 2026 | B24: 4.9423603 | C24: 5.3956489 | D24: 5.6963955 | E24: 6.0190742 | F24: 6.5712658 | G24: 0.49658 | H24: 0.2857729
A25: T+60 · 2 Oct 2026 | B25: 4.4227389 | C25: 5.1691432 | D25: 5.692234 | E25: 6.2778367 | F25: 7.3376188 | G25: 0.49588 | H25: 0.51138244
A26: the calibration back-test verdict: PARITY (robust, blocks 2/3/4) · 11 windows · cone OVER-covered

Sheet Fundamental Valuation
A1: FUNDAMENTAL VALUATION — the four lenses, and what drives each
A3: LENS | B3: Bear | C3: Central | D3: Bull | E3: Weight | F3: What it is most sensitive to
A4: FCFF DCF (primary) | B4: 2.8603134 | C4: 4.4899091 | D4: 8.1545327 | E4: 0.45 | F4: Beta -> WACC. See Sensitivity.
A5: Normalized earnings power | B5: 4.1717358 | C5: 5.4413945 | D5: 6.6657083 | E5: 0.2 | F5: The multiple applied to a non-conflict year.
A6: Relative — P/E (= 1/yield) | B6: 4.0773307 | C6: 4.8927968 | D6: 5.708263 | E6: 0.2 | F6: The peer P/E band. 100% payout -> P/E = 1/yield.
A7: Dividend discount (floor) | B7: 2.5526385 | C7: 3.5468831 | D7: 6.0690825 | E7: 0.15 | F7: Ke - g. Structurally a FLOOR: see note below.
A8: WEIGHTED | B8: =SUMPRODUCT(B4:B7,$E$4:$E$7) | C8: =SUMPRODUCT(C4:C7,$E$4:$E$7) | D8: =SUMPRODUCT(D4:D7,$E$4:$E$7)
A10: WHY THE DDM IS ONLY A FLOOR FOR SALIK
A11: Salik pays out 100% of NET PROFIT — not 100% of free cash flow.
A12: D&A is AED 146mn/yr (concession intangible AED 6,934mn / 49 yrs).
A13: Capex is ~AED 30mn/yr — the RTA bears 100% of the road capex and maintenance.
A14: That leaves ~AED 116mn/yr of cash the dividend never sees. It deleverages the
A15: balance sheet and accrues to equity as a rising share of a constant EV. A DDM cannot see it.
A16: This is not a modelling quirk; it is the whole point of an asset-light concession.
A18: THE FINITE-LIFE CHECK (nice-to-know, NOT weighted)
A19: Concession expires 2071. Valuing FY2031-2071 as a growing annuity with NO terminal value:
A20: Fair value on a finite 2071 life | B20: 4.0431327
A21: Fair value on a perpetuity (the headline DCF) | B21: 4.4899091
A22: The perpetuity assumption is worth | B22: =B21/B20-1
A23: Read: only ~7% of the DCF depends on assuming the concession is renewed. The 45 remaining
A24: years already capture essentially all of the perpetuity's value. Finite life is NOT the crux.

Sheet Assumptions
A1: ASSUMPTIONS — blue cells are the ONLY hard-coded inputs in this workbook
A3: ANCHOR
A4: Spot, AED | B4: 5.7
A5: Shares outstanding, mn | B5: 7500
A6: Net debt (Q1-2026 reported), AED mn | B6: 4226.4
A7: Corporate tax rate (UAE) | B7: 0.09
A8: COST OF CAPITAL — bottom-up
A9: Risk-free rate, AED 10Y | B9: 0.047 | G9: UST10Y 4.56% (10-Jul-26) + the UAE MoF's OWN 14bp AED-over-UST pricing spread (May-2026
G10: T-Bond auction, YTM 4.03% Sep-27 / 4.30% Jan-31). DERIVED, not a screen quote —
G11: no free live AED 10Y exists. NOT a UST shortcut: the peg does not equate the curves.
A12: ERP — rating-based (Damodaran) | B12: 0.0487 | G12: ctryprem.html, "Last updated: January 5, 2026". UAE Aa2: CRP 0.64% + mature 4.23%.
A13: ERP — CDS-based (Damodaran) | B13: 0.0493 | G13: Same file, Abu Dhabi row (sovereign CDS 0.46%) — the only UAE CDS quoted. Proxy, flagged.
A14: Equity beta — PUBLISHED | B14: 0.758 | G14: MEASURED, not assumed. Weekly regression vs a 14-name equal-weighted UAE market portfolio
G15: (both exchanges): beta=0.637, n=195, SE=0.104, t=6.1, R2=16.2%. Gate: PASS.
G16: Published figure is Blume-adjusted (2/3 raw + 1/3 x 1.0) = 0.758 — the CONSERVATIVE direction for a low-beta name. Full detail on sheet 5.
A17: Cost of debt, pre-tax | B17: 0.055 | G17: Triangulated: (a) Q1-26 net finance cost annualised / avg net debt = 5.77%; (b) AED rf 4.70%
G18: + 83bp (ENBD's inaugural AED bond over UAE Treasuries, a comparable A-rated UAE credit)
G19: -> 5.53%; (c) 3M EIBOR 3.76% + 150-175bp IG term margin = 5.26-5.51%.
A20: Terminal growth g | B20: 0.025 | G20: Conservative. Dubai population 4.0mn -> 5.8mn by 2040 (2040 Urban Master Plan) is ~2.5%/yr
G21: on its own, before any tariff escalation. Sensitised 1.5%-3.5%.
A22: Cost of equity (rating ERP) | B22: =B9+B14*B12
A23: Cost of equity (CDS ERP) | B23: =B9+B14*B13
A24: After-tax cost of debt | B24: =B17*(1-B7)
A25: Weight of equity | B25: =B4*B5/(B4*B5+B6)
A26: Weight of debt | B26: =B6/(B4*B5+B6)
A27: WACC (rating ERP) — PRIMARY | B27: =B22*B25+B24*B26
A28: WACC (CDS ERP) | B28: =B23*B25+B24*B26
A30: CONCESSION — the contract (AR2024 + IPO prospectus + RTA confirmation 3-Apr-2024)
A31: Concession term, years | B31: 49 | G31: Effective 1-Jul-2022, expires 2071.
A32: Upfront paid — the 8 original gates, AED mn | B32: 4200 | G32: Debt-funded.
A33: Upfront paid — the 2 new gates (Nov-24), AED mn | B33: 2734 | G33: Semi-annual instalments to RTA.
A34: Concession intangible, gross AED mn | B34: =B32+B33
A35: Straight-line amortisation, AED mn/yr | B35: =B34/B31 | G35: Reconciles to the D&A derived from Q1-26 (AED 145mn/yr).
A36: Concession fee — CURRENT, % of TOLL revenue | B36: 0.225 | G36: Cut 25.0% -> 22.5% on 1-Apr-2024.
A37: Concession fee — CAP | B37: 0.25 | G37: If a higher-than-standard tariff rise IS approved, the fee rises.
A38: Concession fee — FLOOR | B38: 0.15 | G38: If a tariff rise is REJECTED, the RTA CUTS the fee instead.
G39: This is a two-sided contractual inflation hedge. It is the reason the 25%->22.5% cut happened.
A40: Fee base | G40: TOLL USAGE REVENUE ONLY. Fines, tag fees and ancillary are 100% retained by Salik.
A42: FORWARD DRIVERS — the preparer's judgment, logged to the our forecast-assumptions log
A43: Year | B43: 2026 | C43: 2027 | D43: 2028 | E43: 2029 | F43: 2030
...

Sheet Beta & Cost of Capital
A1: BETA — MEASURED, NOT ASSUMED. This is the fix to v1 of this study.
A3: WHY v1 GOT THIS WRONG, AND WHAT WE DID ABOUT IT
A4: v1 regressed SALIK against the DFM General Index and could only obtain 19 sessions of DFMGI history.
A5: n=19 < the 24-observation usability floor, so the gate FAILED and our standing rule forced beta = 1.00.
A6: That single fallback drove the whole answer: it put fair value at AED 3.67 and the study at -27% vs spot.
A7: THE FIX: a market portfolio does not have to be an exchange index. We rebuilt one from the 14 UAE names
A8: the Testahil MC engine itself uses to calibrate this market — equal-weighted, spanning BOTH exchanges,
A9: every constituent through the same the data-quality check. The regression now PASSES comfortably.
A11: THE 14-NAME UAE MARKET PORTFOLIO (equal-weighted)
A12: ADCB, ADIB, ADNOCGAS, AGTHIA, ALDAR, ALPHADHABI, DIB, EAND, EMAAR, EMAARDEV, ENBD, FAB, IHC, TWOPOINTZERO
A14: Specification | B14: n | C14: beta | D14: SE | E14: t | F14: R^2 | G14: Usability test
A15: WEEKLY log returns, full history since IPO | B15: 195 | C15: 0.63658978 | D15: 0.10432886 | E15: 6.1017613 | F15: 0.16171328 | G15: PASS
A16: DAILY log returns, full history since IPO | B16: 940 | C16: 0.57806307 | D16: 0.051615372 | E16: 11.199436 | F16: 0.11794634 | G16: PASS
A17: WEEKLY, PRE-WAR only (to 27-Feb-2026) | B17: 177 | C17: 0.47452162 | D17: 0.11955016 | E17: 3.9692263 | F17: 0.082591689 | G17: PASS
A18: WEEKLY, WAR PERIOD only (from 28-Feb-2026) | B18: 18 | C18: 1.0008778 | D18: 0.25114754 | E18: 3.9852185 | F18: 0.49814889 | G18: FAIL (n<24)
A20: THE WAR DOUBLED THE BETA: 0.475 pre-war -> 1.001 during. That is what a crisis does —
A21: correlations go to one. It also explains v1's 0.89: that 19-session window sat INSIDE the war.
A23: PUBLISHED BETA
A24: Raw measured weekly beta | B24: 0.6366
A25: Blume weight on 1.0 (the convention) | B25: 0.33333333
A26: PUBLISHED BETA (Blume-adjusted) | B26: =B24*(1-B25)+1*B25
A27: For a LOW-beta stock the Blume shrink RAISES the discount rate and LOWERS fair value.
A28: It is therefore the CONSERVATIVE choice, and we make it deliberately.
A30: THE VOLATILITY PARADOX, RESOLVED
A31: SALIK annualised vol (daily) | B31: 0.25809189 | G31: HIGH. Not a sleepy utility.
A32: UAE market portfolio vol | B32: 0.15333503
A33: Correlation | B33: 0.34343317 | G33: LOW.
A34: Share of SALIK variance that is IDIOSYNCRATIC | B34: 0.88205366 | G34: THE resolution: a 26%-vol stock CAN carry a 0.64 beta because ~9/10 of its risk is its own.
A35: Asset (unlevered) beta | B35: 0.58404582 | G35: Barely levered, so the asset beta and the equity beta are nearly the same number.
A37: Beta | B37: Cost of equity | C37: WACC | D37: Fair value AED | E37: vs spot | F37: What this beta IS
A38: 1 | B38: 0.0957 | C38: 0.091592934 | D38: 3.6647773 | E38: -0.35705661 | F38: what v1 used, on a FAILED gate — void
A39: 0.841 | B39: 0.0879567 | C39: 0.084546288 | D39: 4.1733648 | E39: -0.26783074 | F39: upper bound of the 95% CI on the measured beta
A40: 0.76 | B40: 0.084012 | C40: 0.080956487 | D40: 4.4817914 | E40: -0.2137208 | F40: PUBLISHED — Blume-adjusted (2/3 x 0.637 + 1/3 x 1.0)
A41: 0.64 | B41: 0.078168 | C41: 0.075638263 | D41: 5.0192207 | E41: -0.11943496 | F41: RAW measured weekly beta, n=195, t=6.10
A42: 0.47 | B42: 0.069889 | C42: 0.068104113 | D42: 6.0078904 | E42: 0.054015851 | F42: measured PRE-WAR only (n=177) — the peacetime beta
A43: 0.432 | B43: 0.0680384 | C43: 0.066420009 | D43: 6.2781219 | E43: 0.10142489 | F43: lower bound of the 95% CI on the measured beta
A45: Spot implies beta | B45: 0.51724842 | C45: INSIDE the measured 95% CI
A46: Measured 95% CI on beta | B46: 0.43210522 | C46: 0.84107434
A47: THE CRUX: spot implies a beta almost exactly equal to SALIK's PRE-WAR beta.
A48: The market is pricing Salik as though the war is already over. It may be right.

Sheet Concession & Unit Econ
A1: THE CONCESSION — and the two growth engines, only one of which is free
A3: THE TARIFF MECHANISM (this is what protects the margin)
A4: Salik may RECOMMEND an annual toll increase under an inflation-linked formula.
A5: The RTA reviews it; The Executive Council (TEC) decides.
A6: If the TEC REJECTS the increase -> the RTA COMPENSATES Salik by CUTTING the concession fee.
A7: If a higher-than-standard increase IS approved -> the concession fee RISES.
A8: Bounded: the fee cannot exceed 25% of toll revenue, nor fall below 15%.
A9: It already fired: 25.0% -> 22.5% effective 1-Apr-2024 (RTA confirmation, 3-Apr-2024).
A10: Salik is hedged on BOTH sides of the inflation question. That is unusual, and it is contractual.
A12: THE CUSHION, IN REAL MONEY
A13: Concession fee today | B13: 0.225
A14: Contractual FLOOR | B14: 0.15
A15: Headroom, pp | B15: =B13-B14
A16: FY2026E toll usage revenue, AED mn | B16: 2554.955
A17: Value of the headroom, AED mn/yr | B17: =B15*B16
A18: FY2026E EBITDA, AED mn | B18: 2078.2187
A19: Headroom as % of FY2026E EBITDA | B19: =B17/B18
A21: TWO GROWTH ENGINES — AND ONLY ONE OF THEM IS FREE
B22: The ORIGINAL 8 gates | C22: The 2 gates the RTA SOLD Salik
A23: When | B23: Handed over at the Sep-2022 IPO | C23: Bought 24-Nov-2024
A24: Price paid to the RTA, AED mn | B24: 4200 | C24: 2734
A25: of which Business Bay Crossing | C25: 2265
A26: of which Al Safa South | C26: 469
A27: Incremental chargeable trips, mn | B27: 498.1 | C27: 111
A28: Incremental toll revenue, AED mn | B28: 1992.5 | C28: 474.15115
A29: less concession fee @22.5% | C29: -106.68401
A30: less incremental opex @5% | C30: -23.707558
A31: EBITDA, AED mn | B31: 1579.1 | C31: 343.75958
A32: Amortisation life, years | B32: 49 | C32: 46.67
A33: less D&A, AED mn | B33: -85.714286 | C33: -58.58153
A34: NOPAT (x 0.91), AED mn | B34: 1353.8551 | C34: 259.51203
A35: Invested capital, AED mn | B35: 4200 | C35: 2700
A36: RETURN ON INVESTED CAPITAL | B36: 0.32234646 | C36: 0.094920274
A37: ... against a WACC of | B37: 0.08086785 | C37: 0.08086785
A38: SPREAD | B38: 0.24147861 | C38: 0.014052424
A39: Value created by the 2-gate deal, AED mn | B39: 475.08778
A40: THE FINDING. The RTA priced the first 8 gates to make an IPO work. It priced the next 2
A41: at FAIR VALUE. The RTA is grantor, regulator, 75.1% shareholder AND vendor — and Salik's
A42: Chairman is its Director-General. Growth by ACQUIRING gates is NOT free growth.
A44: ROBUSTNESS — does the finding survive the assumption box?
...

Sheet Revenue & FY25 Bridge
A1: REVENUE BUILD — and what ACTUALLY drove FY2025's +35.1%
A3: THE FY2025 TOLL-REVENUE BRIDGE — 88% of the growth cannot repeat
A4: Component | B4: AED mn | C4: Share of growth | D4: Can it repeat?
A5: FY2024 toll revenue (8 gates, flat AED 4.000) | B5: 1992.5
A6: + organic trip growth (30.0mn x AED 4.000) | B6: 120.00602 | C6: 0.16272003 | D6: YES - this is the real business
A7: + TWO NEW GATES (111.0mn x AED 4.000) | B7: 444.02228 | C7: 0.60206411 | D7: NO - the gate count went 8->10 once
A8: + VARIABLE PRICING (639.1mn x AED +0.272) | B8: 173.47169 | C8: 0.23521585 | D8: NO - the tariff went flat->variable once
A9: FY2025 toll revenue (REBUILT) | B9: 2730
A10: FY2025 toll revenue (REPORTED) | B10: 2730 | C10: =B9/B10-1 | D10: rebuild error ->
A11: ONE-OFF SHARE OF THE GROWTH (new gates + variable pricing) | C11: =(B7+B8)/(B10-B5)
A12: ORGANIC SHARE OF THE GROWTH | C12: =B6/(B10-B5)
A13: Anyone extrapolating 35% growth from FY2025 is extrapolating an artefact.
A15: THE ELASTICITY TEST — variable pricing raised the price 6.8%. What did it cost?
B16: FY2024 | C16: FY2025 (ex-new-gates) | D16: Change
A17: Chargeable trips on the SAME 8 gates, mn | B17: 498.1 | C17: 528.1 | D17: =C17/B17-1
A18: Effective realised toll, AED | B18: 4.0002008 | C18: 4.271632 | D18: =C18/B18-1
A19: Implied demand response | D19: NONE
A20: Price +6.8%, volume +4.4% on the SAME gates. ZERO demand destruction. Dubai's tolled
A21: commute is price-INELASTIC — a tariff rise is nearly pure margin. The strongest bull fact.
A22: It also explains the free 01:00-06:00 window: pricing did NOT reduce congestion, so the RTA
A23: had to buy the reduction another way. The RTA's objective was never the revenue.
A25: THE FORWARD REVENUE BUILD
A26: AED mn unless stated | B26: FY2023 | C26: FY2024 | D26: FY2025 | E26: FY2026E | F26: FY2027E | G26: FY2028E | H26: FY2029E | I26: FY2030E
A27: Chargeable trips, mn | B27: 461.4 | C27: 498.1 | D27: 639.1 | E27: 595.135 | F27: 621.91607 | G27: 646.79272 | H27: 669.43046 | I27: 689.51338
A28: Effective realised toll, AED/trip | B28: 4.0006502 | C28: 4.0002008 | D28: 4.271632 | E28: 4.2930679 | F28: 4.357464 | G28: 4.4228259 | H28: 4.4891683 | I28: 4.5565058
A29: Toll usage fees | B29: 1845.9 | C29: 1992.5 | D29: 2730 | E29: 2554.955 | F29: 2709.9769 | G29: 2860.6516 | H29: 3005.186 | I29: 3141.7717
A30: Fines (NO concession fee - 1.34x the EBITDA) | B30: 224.1 | C30: 236.1 | D30: 280.6 | E30: 276.73777 | F30: 289.19097 | G30: 300.75861 | H30: 311.28517 | I30: 320.62372
A31: Tag activation fees | E31: 49.3 | F31: 51.8 | G31: 54.4 | H31: 57.1 | I31: 59.9
A32: Ancillary | E32: 44 | F32: 61.6 | G32: 86.2 | H32: 116.4 | I32: 151.3
A33: Other | B33: =B35-B29-B30 | C33: =C35-C29-C30 | D33: =D35-D29-D30 | E33: 56 | F33: 57.1 | G33: 58.3 | H33: 59.4 | I33: 60.6
A34: TOTAL REVENUE (build) | B34: =SUM(B29:B33) | C34: =SUM(C29:C33) | D34: =SUM(D29:D33) | E34: =SUM(E29:E33) | F34: =SUM(F29:F33) | G34: =SUM(G29:G33) | H34: =SUM(H29:H33) | I34: =SUM(I29:I33)
A35: Reported / forecast revenue | B35: 2109 | C35: 2292 | D35: 3096.9 | E35: 2980.9928 | F35: 3169.6679 | G35: 3360.3102 | H35: 3549.3712 | I35: 3734.1954
A36: Delta (must be 0) | B36: =B35-B34 | C36: =C35-C34 | D36: =D35-D34 | E36: =E35-E34 | F36: =F35-F34 | G36: =G35-G34 | H36: =H35-H34 | I36: =I35-I34
A37: FY23-25 tag/ancillary are not separately disclosed; shown as a live residual (italic).

Sheet Relative & Normalized
A1: RELATIVE & NORMALIZED — one earnings multiple, and a non-conflict year
A3: WHY EV/EBITDA IS NOT USED AS A VALUE DRIVER HERE
A4: The RTA bears 100% of Salik's road capex and maintenance. Salik converts ~90% of EBITDA to free cash flow.
A5: A conventional toll road converts ~50-60%. An EV/EBITDA multiple drawn from that peer set would understate
A6: Salik by construction. We DISCLOSE the multiple below; we do not value on it.
A8: EV at spot, AED mn | B8: 46976.4
A9: EV / FY2026E EBITDA | B9: 22.604166
A10: EV / FY2026E FCFF | B10: 25.060641
A11: FCFF / EBITDA conversion | B11: 0.90197874
A13: THE ONE MULTIPLE WE DO USE: P/E — and it IS the dividend yield (100% payout)
B14: Low | C14: Mid | D14: High
A15: Peer P/E | B15: 20 | C15: 24 | D15: 28
A16: Implied dividend yield | B16: =1/B15 | C16: =1/C15 | D16: =1/D15
A17: FY2026E EPS = DPS, AED | B17: 0.20386653
A18: Fair value, AED/share | B18: =B15*$B$17 | C18: =C15*$B$17 | D18: =D15*$B$17
A20: SALIK at spot — P/E on FY2025 actual | B20: 27.520278
A21: SALIK at spot — P/E on our FY2026E | B21: 27.959469
A22: SALIK trailing dividend yield (declared) | B22: 0.03885731
A23: Parkin (DFM) — RTA 49-yr parking concession, ~100% payout | B23: 24.9
A24: Parkin dividend yield | B24: 0.042
A25: Parkin figures as at Apr-2026 (investing.com quoting the company). Flagged as ~3 months stale.
A27: NORMALIZED EARNINGS POWER — what does a NON-conflict year earn?
A28: Chargeable trips, mn (FY25 +2% underlying) | B28: 651.882
A29: Revenue, AED mn | B29: 3254.2583
A30: EBITDA, AED mn | B30: 2266.6108
A31: EBITDA margin | B31: 0.69650611
A32: Net profit, AED mn | B32: 1700.4358
A33: Normalized EPS = DPS, AED | B33: 0.22672477
A34: vs our FY2026E net profit | B34: 0.11212354
A35: P/E applied (mid of the band) | B35: 24
A36: Fair value, AED/share | B36: 5.4413945

Sheet DCF
A1: DCF — the FULL FCFF waterfall, no step skipped
A3: AED mn | B3: 2026 | C3: 2027 | D3: 2028 | E3: 2029 | F3: 2030
A4: Revenue | B4: 2980.9928 | C4: 3169.6679 | D4: 3360.3102 | E4: 3549.3712 | F4: 3734.1954
A5: less: concession fee (22.5% of TOLL revenue) | B5: -574.86487 | C5: -609.7448 | D5: -643.64661 | E5: -676.16686 | F5: -706.89864
A6: less: other opex | B6: -327.9092 | C6: -345.4938 | D6: -362.9135 | E6: -379.78272 | F6: -392.09052
A7: EBITDA | B7: 2078.2187 | C7: 2214.4293 | D7: 2353.7501 | E7: 2493.4216 | F7: 2635.2063
A8: EBITDA margin | B8: 0.69715657 | C8: 0.69863133 | D8: 0.70045619 | E8: 0.70249672 | F8: 0.70569587
A9: less: D&A | B9: -146 | C9: -146 | D9: -146 | E9: -146 | F9: -146
A10: EBIT | B10: 1932.2187 | C10: 2068.4293 | D10: 2207.7501 | E10: 2347.4216 | F10: 2489.2063
A11: less: tax @ 9% | B11: -173.89968 | C11: -186.15863 | D11: -198.69751 | E11: -211.26795 | F11: -224.02857
A12: NOPAT | B12: 1758.319 | C12: 1882.2706 | D12: 2009.0526 | E12: 2136.1537 | F12: 2265.1777
A13: add back: D&A | B13: 146 | C13: 146 | D13: 146 | E13: 146 | F13: 146
A14: less: capex | B14: -29.809928 | C14: -31.696679 | D14: -33.603102 | E14: -35.493712 | F14: -37.341954
... A16: FCFF | B16: 1874.5091 | C16: 1996.574 | D16: 2121.4495 | E16: 2246.66 | F16: 2373.8358
A17: Discount factor @ WACC | B17: =1/(1+Assumptions!$B$27)^1 | C17: =1/(1+Assumptions!$B$27)^2 | D17: =1/(1+Assumptions!$B$27)^3 | E17: =1/(1+Assumptions!$B$27)^4 | F17: =1/(1+Assumptions!$B$27)^5
A18: PV of FCFF | B18: =B16*B17 | C18: =C16*C17 | D18: =D16*D17 | E18: =E16*E17 | F18: =F16*F17
A19: Sum of PV(FCFF), FY26-30 | B19: =SUM(B18:F18)
A20: Terminal value = FCFF(2030) x (1+g) / (WACC - g) | B20: =F16*(1+Assumptions!$B$20)/(Assumptions!$B$27-Assumptions!$B$20)
A21: PV of terminal value | B21: =B20*F17
A22: Terminal value as % of EV | B22: =B21/B23
A23: ENTERPRISE VALUE | B23: =B19+B21
A24: less: net debt (Q1-2026 reported) | B24: -4226.4
A25: EQUITY VALUE | B25: =B23+B24
A26: Shares outstanding, mn | B26: 7500
A27: FAIR VALUE, AED / SHARE | B27: =B25/B26
A28: Spot | B28: 5.7
A29: vs spot | B29: =B27/B28-1
A31: Bear case (see Sensitivity for the drivers) | B31: 2.8603134
A32: Bull case | B32: 8.1545327

Sheet Income Statement
A1: INCOME STATEMENT — 3 historical (company-sourced) + 5 forecast
A3: AED mn | B3: FY2023 | C3: FY2024 | D3: FY2025 | E3: FY2026E | F3: FY2027E | G3: FY2028E | H3: FY2029E | I3: FY2030E
A4: Revenue | B4: 2109 | C4: 2292 | D4: 3096.9 | E4: 2980.9928 | F4: 3169.6679 | G4: 3360.3102 | H4: 3549.3712 | I4: 3734.1954
A5: Concession fee to RTA | B5: -461.2 | C5: -460.6 | D5: -614.3 | E5: -574.86487 | F5: -609.7448 | G5: -643.64661 | H5: -676.16686 | I5: -706.89864
A6: Other operating costs | B6: -257.7 | C6: -252.3 | D6: -338.7 | E6: -327.9092 | F6: -345.4938 | G6: -362.9135 | H6: -379.78272 | I6: -392.09052
A7: EBITDA | B7: 1390.1 | C7: 1579.1 | D7: 2143.9 | E7: 2078.2187 | F7: 2214.4293 | G7: 2353.7501 | H7: 2493.4216 | I7: 2635.2063
A8: EBITDA margin | B8: 0.65912755 | C8: 0.68896161 | D8: 0.69227292 | E8: 0.69715657 | F8: 0.69863133 | G8: 0.70045619 | H8: 0.70249672 | I8: 0.70569587
A9: D&A | B9: -146 | C9: -146 | D9: -146 | E9: -146 | F9: -146 | G9: -146 | H9: -146 | I9: -146
A10: EBIT | B10: 1244.1 | C10: 1433.1 | D10: 1997.9 | E10: 1932.2187 | F10: 2068.4293 | G10: 2207.7501 | H10: 2347.4216 | I10: 2489.2063
A11: Net finance costs | D11: -290.9 | E11: -252 | F11: -245.49336 | G11: -238.98671 | H11: -232.48007 | I11: -225.97342
A12: Profit before tax | C12: 1279.7 | D12: 1707 | E12: 1680.2187 | F12: 1822.9359 | G12: 1968.7634 | H12: 2114.9415 | I12: 2263.2329
A13: Tax (UAE CT, 9% from 2024) | B13: 0 | C13: -115.2 | D13: -153.6 | E13: -151.21968 | F13: -164.06423 | G13: -177.18871 | H13: -190.34474 | I13: -203.69096
A14: NET PROFIT | B14: 1098 | C14: 1164.5 | D14: 1553.4 | E14: 1528.999 | F14: 1658.8717 | G14: 1791.5747 | H14: 1924.5968 | I14: 2059.5419
A15: net margin | B15: 0.52062589 | C15: 0.50807155 | D15: 0.50159837 | E15: 0.51291604 | F15: 0.5233582 | G15: 0.53315753 | H15: 0.54223599 | I15: 0.55153565
A16: EPS, AED | B16: 0.1464 | C16: 0.15526667 | D16: 0.20712 | E16: 0.20386653 | F16: 0.22118289 | G16: 0.23887662 | H16: 0.25661291 | I16: 0.27460559
A17: DPS, AED (100% payout) | B17: 0.1464 | C17: 0.15526667 | D17: 0.22148667 | E17: 0.20386653 | F17: 0.22118289 | G17: 0.23887662 | H17: 0.25661291 | I17: 0.27460559
A19: FY23/24 D&A and FY23 net finance are DERIVED (EBITDA-EBIT-NPBT identity), not disclosed lines.
A20: FY2025 DPS AED 0.2215 exceeds FY2025 EPS AED 0.2071: the H2 dividend covered 100% of H2 net
A21: profit (AED 782.5mn) PLUS exceptional gains of AED 107.8mn. Both framings are stated.

Sheet Balance Sheet
A1: BALANCE SHEET — sourced anchors, derived bridge (flagged)
A3: AED mn | B3: FY2024 | C3: FY2025 | D3: Q1-2026
A4: Total assets [SOURCED] | B4: 7980 | C4: 7870
A5: of which: concession intangible, gross | B5: 6900 | C5: 6900 | D5: 6900
A6: less accumulated amortisation (derived) | B6: -352 | C6: -498 | D6: -534
A7: concession intangible, net (derived) | B7: 6548 | C7: 6402 | D7: 6366
A8: Net debt [SOURCED] | B8: 5198.6 | C8: 4799.2 | D8: 4226.4
A9: Net working capital [SOURCED] | B9: -536.8 | C9: -674 | D9: -846
A10: Net debt / EBITDA (T12M) [SOURCED] | B10: 3.29 | C10: 2.24 | D10: 1.98
A11: Debt covenant | B11: 5 | C11: 5 | D11: 5
A12: Headroom to covenant | B12: 1.71 | C12: 2.76 | D12: 3.02
A14: HONEST FLAG. Salik does not publish a full quarterly balance sheet in its earnings release.
A15: Total assets, net debt, NWC and leverage ARE disclosed. Equity, gross debt and cash are NOT.
A16: The intangible bridge above is DERIVED from the AED 4.2bn + AED 2.7bn upfront payments and a
A17: 49-year straight line. It reconciles to the D&A implied by Q1-2026 (AED 145mn/yr vs 141 modelled).
A18: The DCF uses NET DEBT (disclosed) and never needs book equity, so nothing in the valuation
A19: depends on a derived line. Logged to the our forecast-assumptions log.

Sheet Cash Flow
A1: CASH FLOW — why FCF exceeds EBITDA in some quarters
A3: AED mn | B3: FY2024 | C3: FY2025 | D3: Q1-2026 | E3: FY2026E | F3: FY2027E | G3: FY2028E | H3: FY2029E
A4: EBITDA | B4: 1579.1 | C4: 2143.9 | D4: 507.2 | E4: 2078.2187 | F4: 2214.4293 | G4: 2353.7501 | H4: 2493.4216
A5: less: cash tax | B5: -115.2 | C5: -153.6 | D5: -36.5 | E5: -151.21968 | F5: -164.06423 | G5: -177.18871 | H5: -190.34474
A6: +/- change in working capital | D6: 172 | E6: 0 | F6: 0 | G6: 0 | H6: 0
A7: less: capex | D7: -6.2 | E7: -29.809928 | F7: -31.696679 | G7: -33.603102 | H7: -35.493712
A8: FREE CASH FLOW [FY24 & Q1-26 SOURCED] | B8: 1457.3 | D8: 636.5 | E8: 1874.5091 | F8: 1996.574 | G8: 2121.4495 | H8: 2246.66
A9: FCF margin | B9: 0.636 | D9: 0.873 | E9: 0.62882041 | F9: 0.62990005 | G9: 0.63132549 | H9: 0.63297408
A10: Dividends paid | B10: -1094.7 | D10: 0 | E10: -1528.999 | F10: -1658.8717 | G10: -1791.5747 | H10: -1924.5968
A12: Q1-2026 FCF (AED 636.5mn) EXCEEDED EBITDA (AED 507.2mn). That is not an error: the negative
A13: working capital deepened by AED 172mn (prepaid e-wallet float grows; the RTA toll-rights
A14: instalment falls in other quarters). Our DCF sets dWC to ZERO, which is deliberately conservative.

Sheet Summary Financials
A1: SUMMARY FINANCIALS
A3: AED mn | B3: FY2023 | C3: FY2024 | D3: FY2025 | E3: FY2026E | F3: FY2027E | G3: FY2028E | H3: FY2029E | I3: FY2030E
A4: Revenue | B4: 2109 | C4: 2292 | D4: 3096.9 | E4: 2980.9928 | F4: 3169.6679 | G4: 3360.3102 | H4: 3549.3712 | I4: 3734.1954
A5: EBITDA | B5: 1390.1 | C5: 1579.1 | D5: 2143.9 | E5: 2078.2187 | F5: 2214.4293 | G5: 2353.7501 | H5: 2493.4216 | I5: 2635.2063
A6: EBITDA margin | B6: 0.65912755 | C6: 0.68896161 | D6: 0.69227292 | E6: 0.69715657 | F6: 0.69863133 | G6: 0.70045619 | H6: 0.70249672 | I6: 0.70569587
A7: Net profit | B7: 1098 | C7: 1164.5 | D7: 1553.4 | E7: 1528.999 | F7: 1658.8717 | G7: 1791.5747 | H7: 1924.5968 | I7: 2059.5419
A8: FCFF | E8: 1874.5091 | F8: 1996.574 | G8: 2121.4495 | H8: 2246.66 | I8: 2373.8358
A9: EPS, AED | B9: 0.1464 | C9: 0.15526667 | D9: 0.20712 | E9: 0.20386653 | F9: 0.22118289 | G9: 0.23887662 | H9: 0.25661291 | I9: 0.27460559
A10: Chargeable trips, mn | B10: 461.4 | C10: 498.1 | D10: 639.1 | E10: 595.135 | F10: 621.91607 | G10: 646.79272 | H10: 669.43046 | I10: 689.51338
A11: Revenue growth | C11: 0.0868 | D11: 0.3512 | E11: -0.037426856 | F11: 0.063292704 | G11: 0.060145846 | H11: 0.056262952 | I11: 0.052072395

Sheet Monte Carlo
A1: MONTE CARLO — engine v3 "carry-anchored YZ-HAR-t", read live from the repo
A3: ENGINE CONFIG (our calibration engine is the single source of truth)
A4: Market profile | B4: UAE (ADX/DFM)
A5: Tail parameter nu (fitted, per-market) | B5: 10
A6: Cone-width calibration (fitted) | B6: 1.049
A7: Signal active? | B7: NO — carry-only (ablated OFF on evidence)
A8: Carry: risk-free (Fed/CBUAE, AED is pegged) | B8: 0.0363
A9: Carry: dividend yield q (trailing declared DPS / spot) | B9: 0.03885731
A10: Drift over 60 sessions = [ln(1+rf) - ln(1+q)] x 60/252 | B10: -0.0005868313
A11: Paths | B11: 50000
A12: Seed | B12: 42
A13: nu is WEAKLY IDENTIFIED. Never quote it as precise: the (nu, the cone-width calibration) PAIR is what is
A14: fitted, and the honest object is the cone they jointly produce.
A16: THE PROBABILITY READ
A17: Statement | B17: T+20 · 7 Aug 2026 | C17: T+60 · 2 Oct 2026
A18: Median (the engine's central price) | B18: 5.6963955 | C18: 5.692234
A19: P(price above today's AED 5.70) | B19: 0.49658 | C19: 0.49588
A20: 5th percentile — a bad-but-not-extreme outcome | B20: 4.9423603 | C20: 4.4227389
A21: 95th percentile | B21: 6.5712658 | C21: 7.3376188
A22: Width of the 90% band, % of spot | B22: 0.2857729 | C22: 0.51138244
A24: Percentile | B24: T+20 AED | C24: T+60 AED | D24: T+60 vs spot
A25: 5% | B25: 4.9423603 | C25: 4.4227389 | D25: =C25/5.7-1
A26: 10% | B26: 5.120687 | C26: 4.7103045 | D26: =C26/5.7-1
A27: 25% | B27: 5.3956489 | C27: 5.1691432 | D27: =C27/5.7-1
A28: 50% | B28: 5.6963955 | C28: 5.692234 | D28: =C28/5.7-1
A29: 75% | B29: 6.0190742 | C29: 6.2778367 | D29: =C29/5.7-1
A30: 90% | B30: 6.3482312 | C30: 6.9008716 | D30: =C30/5.7-1
A31: 95% | B31: 6.5712658 | C31: 7.3376188 | D31: =C31/5.7-1
A33: Level, AED | B33: vs spot | C33: Probability
A34: 4.5 | B34: =A34/5.7-1 | C34: 0.09855
A35: 5 | B35: =A35/5.7-1 | C35: 0.3323
A36: 5.25 | B36: =A36/5.7-1 | C36: 0.51975
A37: 5.5 | B37: =A37/5.7-1 | C37: 0.74665
A38: 6 | B38: =A38/5.7-1 | C38: 0.6671
A39: 6.25 | B39: =A39/5.7-1 | C39: 0.47205
A40: 6.5 | B40: =A40/5.7-1 | C40: 0.32365
A41: 7 | B41: =A41/5.7-1 | C41: 0.14315
A43: CALIBRATION BACK-TEST (the pass/fail check; full numbers publish to the public Ledger, not to the study)
A44: Windows (h=60, non-overlapping) | B44: 11
A45: Verdict | B45: PARITY — robust across bootstrap blocks 2/3/4
...

Sheet Sensitivity
A1: SENSITIVITY — read the beta grid FIRST. It is the whole study.
A3: FAIR VALUE ACROSS BETA x TERMINAL GROWTH — AED/share (gold cells reach spot AED 5.70)
A4: beta \ terminal g | B4: 0.015 | C4: 0.02 | D4: 0.025 | E4: 0.03 | F4: 0.035
A5: 1 | B5: 3.2277288 | C5: 3.4309914 | D5: 3.6647773 | E5: 3.9365198 | F5: 4.2562793
A6: 0.9 | B6: 3.4660481 | C6: 3.6998043 | D6: 3.9711654 | E6: 4.2899995 | F6: 4.6699586
A7: 0.8 | B7: 3.73565 | C7: 4.0066903 | D7: 4.3246809 | E7: 4.7029778 | F7: 5.1605337
A8: 0.76 | B8: 3.8536628 | C8: 4.1419658 | D8: 4.4817914 | E8: 4.8883065 | F8: 5.3832781
A9: 0.64 | B9: 4.2492063 | C9: 4.5996144 | D9: 5.0192207 | E9: 5.5307689 | F9: 6.1681955
A10: 0.5 | B10: 4.8085843 | C10: 5.2582125 | D10: 5.8090316 | E10: 6.4995331 | F10: 7.3905655
A12: PUBLISHED beta 0.758 = Blume-adjusted. RAW MEASURED weekly beta 0.637 (n=195, t=6.1, R2 16.2%) — the gate PASSES. See sheet 5.
A13: PRE-WAR beta 0.475. WAR-PERIOD beta 1.001. The war DOUBLED it.
A14: Spot implies beta 0.52 — INSIDE the measured 95% CI [0.43,0.84], and almost exactly the PRE-WAR reading. That is the crux.
A16: Beta | B16: Cost of equity | C16: WACC | D16: Fair value AED | E16: vs spot | F16: What this beta means
A17: 1 | B17: 0.0957 | C17: 0.091592934 | D17: 3.6647773 | E17: -0.35705661 | F17: what v1 used, on a FAILED gate — void
A18: 0.841 | B18: 0.0879567 | C18: 0.084546288 | D18: 4.1733648 | E18: -0.26783074 | F18: upper bound of the 95% CI on the measured beta
A19: 0.76 | B19: 0.084012 | C19: 0.080956487 | D19: 4.4817914 | E19: -0.2137208 | F19: PUBLISHED — Blume-adjusted (2/3 x 0.637 + 1/3 x 1.0)
A20: 0.64 | B20: 0.078168 | C20: 0.075638263 | D20: 5.0192207 | E20: -0.11943496 | F20: RAW measured weekly beta, n=195, t=6.10
A21: 0.47 | B21: 0.069889 | C21: 0.068104113 | D21: 6.0078904 | E21: 0.054015851 | F21: measured PRE-WAR only (n=177) — the peacetime beta
A22: 0.432 | B22: 0.0680384 | C22: 0.066420009 | D22: 6.2781219 | E22: 0.10142489 | F22: lower bound of the 95% CI on the measured beta
A24: WACC x TERMINAL g (beta held at our 1.00)
A25: WACC \ g | B25: 0.015 | C25: 0.02 | D25: 0.025 | E25: 0.03 | F25: 0.035
A26: 0.06586785 | B26: 5.1919301 | C26: 5.7174561 | D26: 6.3715736 | E26: 7.2080599 | F26: 8.3155357
A27: 0.07336785 | B27: 4.4400732 | C27: 4.8228201 | D27: 5.2846995 | E27: 5.8530816 | F27: 6.5696039
A28: 0.08086785 | B28: 3.8597306 | C28: 4.1489368 | D28: 4.4899091 | E28: 4.8979124 | F28: 5.3948676
A29: 0.08836785 | B29: 3.398294 | C29: 3.6231471 | D29: 3.883484 | E29: 4.1884237 | F29: 4.5505026
A30: 0.09586785 | B30: 3.0226719 | C30: 3.2015235 | D30: 3.4056126 | E30: 3.6406862 | F30: 3.9143802
A32: SEPARATE STRESS: the FY2026 traffic trough (the derived/judgment driver)
A33: Q2-26 trips at 75% of Q2-25 | B33: 4.0544801
A34: Q2-26 trips at 80% of Q2-25 | B34: 4.2365977
A35: Q2-26 trips at 85% of Q2-25 | B35: 4.4187153
A36: Q2-26 trips at 90% of Q2-25 | B36: 4.6008329
A37: Q2-26 trips at 95% of Q2-25 | B37: 4.7829504
A38: Even a 25% Q2-2026 trip collapse moves fair value LESS than a single 0.10 step in beta does.
A39: That is the finding: this is a discount-rate story, not a traffic story.
A41: THE 0.80 BETA FLOOR — a challenged standing rule, priced
A42: A fact-check asserted that Testahil mandates a 0.80 beta floor and that our 0.76 is a breach.
A43: The our published research standards says the OPPOSITE: attempt the regression; fall back to 1.0 ONLY
A44: on a usability-gate FAILURE (n>=24, R2>=5%, SE<|b|). Ours passes all three. our cost-of-capital module has
A45: NO floor. The 0.8-1.3 band belongs to the EFG-Hermes portable lessons, and the standing rule on
A46: those is: adopt EFG's machinery, NOT their optimistic assumptions. We priced it anyway:
...

Sheet Per-Share & Ratios
A1: PER-SHARE & RATIOS
B3: FY2024 | C3: FY2025 | D3: FY2026E | E3: FY2027E | F3: FY2028E | G3: FY2029E | H3: FY2030E
A4: EPS, AED | B4: 0.15526667 | C4: 0.20712 | D4: 0.20386653 | E4: 0.22118289 | F4: 0.23887662 | G4: 0.25661291 | H4: 0.27460559
A5: DPS, AED | B5: 0.15526667 | C5: 0.22148667 | D5: 0.20386653 | E5: 0.22118289 | F5: 0.23887662 | G5: 0.25661291 | H5: 0.27460559
A6: FCFF per share, AED | D6: 0.24993454 | E6: 0.26620986 | F6: 0.28285993 | G6: 0.29955466 | H6: 0.31651144
A7: P/E at spot AED 5.70 | B7: 36.711035 | C7: 27.520278 | D7: 27.959469 | E7: 25.770529 | F7: 23.86169 | G7: 22.212445 | H7: 20.757043
A8: Dividend yield at spot | B8: 0.027239766 | C8: 0.03885731 | D8: 0.035766059 | E8: 0.038804016 | F8: 0.04190818 | G8: 0.045019808 | H8: 0.048176419
A9: EBITDA margin | B9: 0.68896161 | C9: 0.69227292 | D9: 0.69715657 | E9: 0.69863133 | F9: 0.70045619 | G9: 0.70249672 | H9: 0.70569587
A10: Net margin | B10: 0.50807155 | C10: 0.50159837 | D10: 0.51291604 | E10: 0.5233582 | F10: 0.53315753 | G10: 0.54223599 | H10: 0.55153565
A11: FCFF / EBITDA conversion | D11: 0.90197874 | E11: 0.90162011 | F11: 0.90130617 | G11: 0.90103492 | H11: 0.90081592
A12: Net debt / EBITDA | B12: 3.29 | C12: 2.24 | D12: 2.1653159 | E12: 1.9796568 | F12: 1.8131151 | G12: 1.664953 | H12: 1.5312804
A14: DUAL FRAMING — the FY2025 dividend
A15: On NET PROFIT (AED 1,553.4mn): | B15: 0.20712 | C15: yield | D15: 0.036336842
A16: On DECLARED dividends (incl. AED 107.8mn exceptional gains): | B16: 0.22148667 | C16: yield | D16: 0.03885731
A17: Both are true. We state both everywhere the figure appears.

Sheet Peer & Sweep
A1: PEER SET, AND THE RESEARCH REGISTER
A3: PEER SET
A4: Name | B4: P/E | C4: Div yield | D4: As at
A5: Parkin (DFM) — RTA 49-yr parking concession, Dubai | B5: 24.9 | C5: 0.042 | D5: Apr-2026
A6: SALIK at spot — on our FY2026E | B6: 27.959469 | C6: 0.035766059 | D6: 10-Jul-2026
A7: SALIK at spot — on FY2025 actual | B7: 27.520278 | C7: 0.03885731 | D7: 10-Jul-2026
A8: Global toll-road concessions — indicative range | D8: indicative 18-24x
A9: Dubai utilities (DEWA, Empower) — indicative range | D9: indicative 15-19x
A10: Parkin is the only true structural comparable: same emirate, same grantor (RTA), same
A11: 49-year term, same ~100% payout, same Dubai Investment Fund parent. It trades at ~24.9x.
A13: RESEARCH REGISTER — four rings, run BEFORE any driver was set
A14: Ring | B14: Mandatory category | C14: Cls | D14: Finding | E14: Effect on a driver
A15: GLOBAL | B15: rate cycle & FX regime | C15: D | D15: UST 10Y 4.56%; CBUAE base 3.65%; AED pegged. Fed HIKE priced. | E15: Anchors rf 4.70% + the MC carry. A hiking cycle RAISES WACC.
A16: GLOBAL | B16: commodity complex | C16: C | D16: Brent ~US$91. IEA: largest oil supply disruption in history. | E16: Two-sided. Funds Dubai support; raises living costs.
A17: GLOBAL | B17: trade / sanctions / supply chains | C17: B | D17: US-Israel-Iran war from 28-Feb-26. Hormuz 138/day -> <10. Truce "over" 7-Jul, walked back 8-Jul. | E17: Root cause of the Q1-26 traffic fall. Sets the FY26 trip path.
A18: GLOBAL | B18: global sector demand | C18: S | D18: Emirates 96% of network; flydubai 80%. Travel warnings still live. | E18: Supports Q3-26 at 95% / Q4-26 at 100% - and caps it.
A19: COUNTRY | B19: sovereign macro | C19: D | D19: UAE MoF: AED prices at UST+14bp. Damodaran UAE Aa2, ERP 4.87% / CDS 4.93%. | E19: rf 4.70%; ERP 4.87%. Peg rule respected - NOT a UST shortcut.
A20: COUNTRY | B20: regulatory environment | C20: B | D20: Concession fee CUT 25.0%->22.5% (1-Apr-24). Cap 25% / FLOOR 15%. CT 9%. | E20: Fee = 22.5% of toll rev. The 15% floor = 9.2% of FY26E EBITDA.
A21: COUNTRY | B21: fiscal / political | C21: C | D21: Dubai AED 2.5bn support package. Reported departure of foreign residents. | E21: Package supports recovery. Population risk NOT modelled - declared.
A22: INDUSTRY | B22: demand & capacity balance | C22: B | D22: Dubai pop 4.0mn -> 5.8mn by 2040. Trips 4.3% CAGR 2013-23. RTA is ADDING road capacity. | E22: Underpins 4.5%->3.0% trend growth and the 2.5% terminal.
A23: INDUSTRY | B23: pricing | C23: S | D23: Variable pricing 31-Jan-25. Realised toll AED 4.000 -> 4.293. Free window = 11% of trips. | E23: Toll driver: AED 4.293 flat FY26, +1.5%/yr after.
A24: INDUSTRY | B24: new entrants (named) | C24: NEG | D24: NOTHING FOUND - and there cannot be. Exclusive to 2071. | E24: Evidence of absence, recorded.
A25: INDUSTRY | B25: technology substitution | C25: C | D25: METRO BLUE LINE: AED 20.5bn, 30km, 14 stations, OPENS 2029, 200k->320k pax/day. Plus Joby air taxis, WeRide robotaxis (live), Etihad Rail, RTA 25%-driverless-by-2030. | E25: THE material catch. Dated INSIDE the forecast. Why terminal g is capped at 2.5%.
... A33: COMPANY | B33: official financial statements | C33: D | D33: FY23-25 audited. FY24 toll rev / trips = EXACTLY AED 4.000. No full quarterly balance sheet published. | E33: The 3-yr history and the DCF bridge (through NET debt).
A35: Class: B = base-case driver | S = scenario/upside | D = data input | C = caveat/risk | NEG = searched, nothing found
A36: VALIDATED by our research register: PASS - 4/4 rings, 21 findings, 13 driver-gate rows, 0 errors, 0 warnings.
A37: Every MANDATORY category in every ring is CLOSED with a finding or a DATED NEGATIVE SEARCH. The sweep ran BEFORE any driver was set.
A38: It caught the Metro Blue Line (2029) - a substitution threat inside the forecast period that we would otherwise have missed.
