Workbook

Sheet READ FIRST
A1: Palm Hills Developments — valuation workbook
A2: Edition of 2 September 2026. Supersedes 30 August 2026.
A4: This workbook is for information and education. It is not investment advice and carries no rating and no price target.
A6: BLUE cells are inputs and live on the Assumptions sheet. BLACK cells are formulas. Change a blue cell and the statements, the discounted cash flow and the value per share all recompute.
A8: Reported history comes only from the company's own audited statements and its own results releases. Where a figure the valuation needs is not disclosed, it is absent and named on the Assumptions sheet rather than estimated.
A10: The single most important number in this workbook is cash conversion — the share of revenue that reaches operating cash flow. The company does not disclose its collection terms, so it is measured from the three published cash-flow statements and it spans 3.9% to 17.9%. The Sensitivity sheet shows what that does to the answer.

Sheet Summary
A1: Summary
A2: Every figure recomputes from Assumptions.
A4: Lens | B4: Bear | C4: Base | D4: Full value | E4: Weight
A5: Discounted cash flow | B5: 3.08 | C5: 14.54 | D5: 37.3 | E5: 0.45
A6: Book value of equity | B6: 5.97 | C6: 6.63 | D6: 8.62 | E6: 0.15
A7: Earnings multiple on own history | B7: 7.45 | C7: 11.17 | D7: 17.37 | E7: 0.2
A8: Normalised earnings power | B8: 7.26 | C8: 8.39 | D8: 9.94 | E8: 0.2
A9: Weighted central | B9: 5.22 | C9: 11.45 | D9: 23.54 | E9: 1
A11: Valuation | B11: Per share (EGP) | C11: Equity (EGP mn) | D11: Enterprise value
A12: Weak cash conversion (3.9%) | B12: 4.46 | C12: 12747 | D12: 31759
A13: Average cash conversion (8.7%) | B13: 14.54 | C13: 41571 | D13: 61999
A14: Strong cash conversion (17.9%) | B14: 33.86 | C14: 96831 | D14: 119975
A15: Average, alternative country-risk basis | B15: 16.29 | C15: 46600 | D15: 67276
A17: Market price, 23 Aug 2026 | B17: 15.2
A18: Book value of equity per share | B18: 6.63
A19: Cash conversion implied by the market price | B19: 0.0903
A21: Cost of capital
A22: Weighted average, rating basis | B22: 0.26250009
A23: Weighted average, swap basis | B23: 0.25237862
A24: 11 June 2026 edition used | B24: 0.18

Sheet Fundamental Valuation
A1: Fundamental valuation — bridge to equity
A2: All formulas; drivers live on Assumptions.
A4: Present value of the explicit five years | B4: 23030.2
A5: Present value of the terminal value | B5: 38969.3
A6: Enterprise value | B6: =B4+B5
A7: less net debt, 31 March 2026 | B7: =-Assumptions!B13
A8: plus investments in associates | B8: =Assumptions!B14
A9: plus investment property | B9: =Assumptions!B15
A10: Equity value before minority interests | B10: =B6+B7+B8+B9
A11: less minority interests at their share of value | B11: =-B10*Assumptions!B16
A12: Equity value attributable to shareholders | B12: =B10+B11
A13: Shares outstanding (mn) | B13: =Assumptions!B17
A14: Value per share (EGP) | B14: =B12/B13
A16: Terminal value as a share of enterprise value | B16: =B5/B6

Sheet Assumptions
A1: Assumptions — every blue cell is an input
A2: Change one and the whole workbook recomputes.
A4: Driver | B4: Value | C4: Source
A5: Cash conversion — central | B5: 0.087136637 | C5: mean of the three published cash-flow statements
A6: Cash conversion — weak | B6: 0.039375935 | C6: 2023 and 2025 outcome
A7: Cash conversion — strong | B7: 0.17870013 | C7: 2024 outcome
A8: Gross margin | B8: 0.38322372 | C8: average of FY2025 and 1Q2026 as reported
A9: Overheads as a share of revenue | B9: 0.17599456 | C9: FY2025 as reported
A10: Price escalation | B10: 0.252 | C10: Egyptian consumer price inflation, three-year mean
A11: Terminal growth | B11: 0.12 | C11: below nominal growth, stated
A12: Cost of capital | B12: 0.26250009 | C12: built on the Fundamental Valuation and Peer sheets
A13: Net debt (EGP mn) | B13: 23244.719 | C13: gross borrowings less cash, 31 March 2026 reviewed balance sheet
A14: Investments in associates (EGP mn) | B14: 3838.6972 | C14: 31 March 2026 reviewed balance sheet
A15: Investment property (EGP mn) | B15: 1020.4749 | C15: 31 March 2026 reviewed balance sheet
A16: Minority interests, share of equity value | B16: 0.04683756 | C16: the minority's filed share of FY2025 profit after tax, as its share of value
... A23: Maintenance capital expenditure, share of revenue | B23: 0.01 | C23: the building itself is inventory and sits in operating cash
A25: NOT DISCLOSED — absent by design, never estimated
A26: cash flow statement detail | C26: The FY2025 cash-flow statement is published in its three totals only (operating EGP 1,424.2mn, investing EGP -4,031.7mn, financing EGP 5,628.8mn); no line-by-line statement is post
A27: fy2025 results release | C27: PHD has published FY2025 consolidated statements but NO FY2025 full-year results release. The release is where units sold, new sales, deliveries and construction spend are disclose
A28: h1 2026 results | C28: As at this build date (30-Aug-2026) no 2Q/H1-2026 statements or release are posted to the result centre; the newest disclosure of any kind is 1Q2026 (posted 25-Jun-2026). The study
A29: securitisation pricing | C29: The EGP 2.015bn securitisation of 4-Feb-2026 discloses tranche sizes, tenors and national-scale ratings but NO coupon on any tranche, so the company's own marginal cost of debt can
A30: per project pricing | C30: The company does not disclose per-project unit mix, average unit area, price per square metre or construction cost per square metre. The 11-Jun-2026 edition carried a full per-proj
A31: backlog cost to complete | C31: Remaining construction cost against the EGP 263bn backlog is not disclosed as a single figure. It is inferred in the model from the realised gross margin and flagged where used.

Sheet SOTP Bridge
A1: Bridge from enterprise value to equity
A2: A developer is one business; the bridge is the parts that sit outside the operating cash flows.
A4: Operating business, discounted cash flow | B4: 61999.5
A5: Investments in associates, 31 March 2026 | B5: 3838.7
A6: Investment property, 31 March 2026 | B6: 1020.5
A7: Cash, 31 March 2026 | B7: 9125.1
A8: Gross borrowings, 31 March 2026 | B8: -32369.8
A9: Minority interests at their share of value | B9: =-(B4+B5+B6+B7+B8)*Assumptions!B16
A10: Equity value attributable to shareholders | B10: =B4+B5+B6+B7+B8+B9
A11: Per share (EGP) | B11: =B10/Assumptions!B17

Sheet Segments
A1: Units and prices by region — the forecast's drivers
A2: New sales value and unit counts are both disclosed per region; the price per unit is one divided by the other.
A4: North Coast & Alexandria
A5: Year | B5: 2020 | C5: 2021 | D5: 2022 | E5: 2023 | F5: 2024
A6: New sales (EGP mn) | B6: 4205 | C6: 7139 | D6: 5627 | E6: 13900 | F6: 95082
A7: Units sold | B7: 726 | C7: 1552 | D7: 800 | E7: 1231 | F7: 4192
A8: Price per unit (EGP mn) | B8: 5.792011 | C8: 4.5998711 | D8: 7.03375 | E8: 11.291633 | F8: 22.681775
A9: carried forward at 2074 units, price 22.68, escalated
A11: West Cairo & Badya
A12: Year | B12: 2020 | C12: 2021 | D12: 2022 | E12: 2023 | F12: 2024
A13: New sales (EGP mn) | B13: 6627 | C13: 7258 | D13: 13118 | E13: 32332 | F13: 44570
A14: Units sold | B14: 858 | C14: 1416 | D14: 2039 | E14: 2950 | F14: 2839
A15: Price per unit (EGP mn) | B15: 7.7237762 | C15: 5.1257062 | D15: 6.4335459 | E15: 10.96 | F15: 15.69919
A16: carried forward at 2609 units, price 15.70, escalated
A18: East Cairo
A19: Year | B19: 2020 | C19: 2021 | D19: 2022 | E19: 2023 | F19: 2024
A20: New sales (EGP mn) | B20: 1947 | C20: 2892 | D20: 7265 | E20: 13270 | F20: 11364
A21: Units sold | B21: 256 | C21: 382 | D21: 1194 | E21: 1200 | F21: 453
A22: Price per unit (EGP mn) | B22: 7.6054688 | C22: 7.5706806 | D22: 6.0845896 | E22: 11.058333 | F22: 25.086093
A23: carried forward at 949 units, price 25.09, escalated
A25: Disclosed group drivers
A26: Disclosed driver | B26: Value | C26: Note
A27: New sales, 1Q2026 (EGP mn) | B27: 52000 | C27: includes EGP 24,000mn from one land-plot launch
A28: New sales, FY2024 (EGP mn) | B28: 151016 | C28: chart series
A29: Order book, 31 Mar 2026 (EGP mn) | B29: 263000 | C29: units sold and not yet delivered
A30: Order book, FY2024 (EGP mn) | B30: 147000
A31: Units sold, FY2023 | B31: 5300 | C31: the last year the company disclosed a unit count
A32: Units delivered, FY2023 | B32: 1500
A33: Construction spend, FY2024 (EGP mn) | B33: 8500
A34: Cash collections, FY2024 (EGP mn) | B34: 25400
A35: Land bank (mn sqm) | B35: 33
A37: Build level: SEGMENT, not unit.
A38: The company discloses no per-project unit mix, unit area, price per square metre or construction cost per square metre. The forecast is built at the finest level the disclosure supports and the limit is stated rather than filled.

Sheet Relative & Normalized
A1: Relative and normalised measures
B4: 2023 | C4: 2024 | D4: 2025
A5: Revenue | B5: 17462.1 | C5: 27167.3 | D5: 36169.3
A6: Cash from operations | B6: 756.7 | C6: 4854.8 | D6: 1424.2
A7: Cash conversion | B7: =B6/B5 | C7: =C6/C5 | D7: =D6/D5
A9: Price to book (market) | B9: =15.2000/6.6281
A10: Book value per share (EGP) | B10: 6.63
A11: Return on equity, 2025 | B11: =4216.7/((18765.8+14624.7)/2)

Sheet DCF
A1: Discounted cash flow — central case
A2: Units delivered times revenue per delivered unit, then every row a formula. Change a blue cell on Assumptions and this recomputes.
A4: EGP million | B4: 2026 | C4: 2027 | D4: 2028 | E4: 2029 | F4: 2030
A5: Units delivered | B5: =Assumptions!$B$20 | C5: =B5*(1+Assumptions!$B$21) | D5: =C5*(1+Assumptions!$B$21) | E5: =D5*(1+Assumptions!$B$21) | F5: =E5*(1+Assumptions!$B$21)
A6: Revenue per delivered unit | B6: =Assumptions!$B$22 | C6: =B6*(1+Assumptions!$B$10) | D6: =C6*(1+Assumptions!$B$10) | E6: =D6*(1+Assumptions!$B$10) | F6: =E6*(1+Assumptions!$B$10)
A7: Revenue | B7: =B5*B6 | C7: =C5*C6 | D7: =D5*D6 | E7: =E5*E6 | F7: =F5*F6
A8: Gross profit | B8: =B7*Assumptions!$B$8 | C8: =C7*Assumptions!$B$8 | D8: =D7*Assumptions!$B$8 | E8: =E7*Assumptions!$B$8 | F8: =F7*Assumptions!$B$8
A9: Overheads | B9: =-B7*Assumptions!$B$9 | C9: =-C7*Assumptions!$B$9 | D9: =-D7*Assumptions!$B$9 | E9: =-E7*Assumptions!$B$9 | F9: =-F7*Assumptions!$B$9
A10: Operating cash flow | B10: =B7*Assumptions!$B$5 | C10: =C7*Assumptions!$B$5 | D10: =D7*Assumptions!$B$5 | E10: =E7*Assumptions!$B$5 | F10: =F7*Assumptions!$B$5
A11: Maintenance capital expenditure | B11: =-B7*Assumptions!$B$23 | C11: =-C7*Assumptions!$B$23 | D11: =-D7*Assumptions!$B$23 | E11: =-E7*Assumptions!$B$23 | F11: =-F7*Assumptions!$B$23
A12: plus finance cost, after tax | B12: 2594.3 | C12: 2594.3 | D12: 2594.3 | E12: 2594.3 | F12: 2594.3
A13: Free cash flow to the firm | B13: =B10+B12+B11 | C13: =C10+C12+C11 | D13: =D10+D12+D11 | E13: =E10+E12+E11 | F13: =F10+F12+F11
A14: Discount factor | B14: =1/(1+Assumptions!$B$12)^1 | C14: =1/(1+Assumptions!$B$12)^2 | D14: =1/(1+Assumptions!$B$12)^3 | E14: =1/(1+Assumptions!$B$12)^4 | F14: =1/(1+Assumptions!$B$12)^5
A15: Present value | B15: =B13*B14 | C15: =C13*C14 | D15: =D13*D14 | E15: =E13*E14 | F15: =F13*F14
A17: Sum of the explicit years | B17: =SUM(B15:F15)
A18: Terminal value, discounted | B18: 38969.3
A19: Enterprise value | B19: =B17+B18

Sheet Income Statement
A1: Income statement — built from units and prices
A2: Gross margin is an OUTPUT of price per unit against cost per unit.
A4: EGP mn unless stated | B4: 2026 | C4: 2027 | D4: 2028 | E4: 2029 | F4: 2030
A5: Units sold | B5: 5632.6667 | C5: 5632.6667 | D5: 5632.6667 | E5: 5632.6667 | F5: 5632.6667
A6: New sales | B6: 139999.49 | C6: 175279.37 | D6: 219449.77 | E6: 274751.11 | F6: 343988.39
A7: Units delivered | B7: 1885.5495 | C7: 2168.3819 | D7: 2493.6392 | E7: 2867.6851 | F7: 3297.8379
A8: Revenue per delivered unit | B8: 21.2924 | C8: 26.6581 | D8: 33.376 | E8: 41.7867 | F8: 52.317
A9: Revenue | B9: 40147.923 | C9: 57804.98 | D9: 83227.61 | E9: 119831.11 | F9: 172532.84
A10: Cost per delivered unit | B10: 13.1327 | C10: 16.4421 | D10: 20.5855 | E10: 25.773 | F10: 32.2679
A11: Cost of revenue | B11: 24762.286 | C11: 35652.74 | D11: 51332.815 | E11: 73908.987 | F11: 106414.16
A12: Gross profit | B12: 15385.637 | C12: 22152.24 | D12: 31894.794 | E12: 45922.125 | F12: 66118.676
A13: Gross margin | B13: 0.3832 | C13: 0.3832 | D13: 0.3832 | E13: 0.3832 | F13: 0.3832
A14: Overheads | B14: 7065.816 | C14: 10173.362 | D14: 14647.606 | E14: 21089.624 | F14: 30364.84
A15: Operating profit | B15: 7927.2136 | C15: 11413.602 | D15: 16433.304 | E15: 23660.672 | F15: 34066.635
... A20: Order book, closing | B20: 362851.57 | C20: 480325.96 | D20: 616548.12 | E20: 771468.12 | F20: 942923.67

Sheet Balance Sheet
A1: Balance sheet — as reported, then forecast both ways
A2: EGP million. Assets equal liabilities plus shareholders' funds in every reported and every forecast year.
A4: AS REPORTED | B4: 2025 | C4: 2024
A5: Non-current assets | B5: 65900.2 | C5: 54166.4
A6: Current assets | B6: 106229.6 | C6: 69270.9
A7: Total assets | B7: 172129.8 | C7: 123437.3
A8: Current liabilities | B8: 105099 | C8: 74496.9
A9: Non-current liabilities | B9: 48265.1 | C9: 34315.7
A10: Total liabilities | B10: 153364.1 | C10: 108812.6
A11: Shareholders' funds | B11: 18765.8 | C11: 14624.7
A12: Check: assets less liabilities and equity | B12: =B7-B10-B11 | C12: =C7-C10-C11
A14: FORECAST — IF CASH CONVERSION HOLDS
A15: EGP mn unless stated | B15: 2026 | C15: 2027 | D15: 2028 | E15: 2029 | F15: 2030
A16: Trade and notes receivable | B16: 104247.54 | C16: 107203.17 | D16: 113353.7 | E16: 124104.24 | F16: 141477.88
A17: Work in progress | B17: 17695.945 | C17: 18197.661 | D17: 19241.708 | E17: 21066.605 | F17: 24015.768
A18: Other receivables and prepayments | B18: 13013.96 | C18: 13382.933 | D18: 14150.747 | E18: 15492.813 | F18: 17661.688
A19: Advances to suppliers | B19: 9120.6492 | C19: 9379.2381 | D19: 9917.3497 | E19: 10857.918 | F19: 12377.943
A20: Cash and equivalents | B20: 12516.376 | C20: 16975.257 | D20: 23395.156 | E20: 32638.524 | F20: 45947.127
A21: Property and equipment | B21: 4530.8722 | C21: 4543.6465 | D21: 4562.0388 | E21: 4588.5201 | F21: 4626.6479
A22: Other assets, held at the 2025 level | B22: 15128.3 | C22: 15128.3 | D22: 15128.3 | E22: 15128.3 | F22: 15128.3
A23: TOTAL ASSETS | B23: 176253.65 | C23: 184810.21 | D23: 199749 | E23: 223876.92 | F23: 261235.35
A24: Customer advances | B24: 69847.664 | C24: 71827.987 | D24: 75948.948 | E24: 83151.996 | F24: 94792.637
A25: Suppliers | B25: 3834.0928 | C25: 3942.7972 | D25: 4169.0058 | E25: 4564.3971 | F25: 5203.3776
A26: Other creditors | B26: 5158.149 | C26: 5304.393 | D26: 5608.72 | E26: 6140.6547 | F26: 7000.2991
... A39: as a multiple of revenue | B39: 1.5634 | C39: 1.1166 | D39: 0.82 | E39: 0.6236 | F39: 0.4937
A41: FORECAST — IF THE COLLECTION CYCLE HOLDS
A42: EGP mn unless stated | B42: 2026 | C42: 2027 | D42: 2028 | E42: 2029 | F42: 2030
A43: Trade and notes receivable | B43: 114897.1 | C43: 165428.84 | D43: 238184.45 | E43: 342937.97 | F43: 493762.09
A44: Work in progress | B44: 19503.699 | C44: 28081.426 | D44: 40431.637 | E44: 58213.471 | F44: 83815.755
A45: Other receivables and prepayments | B45: 14343.42 | C45: 20651.656 | D45: 29734.254 | E45: 42811.38 | F45: 61639.824
A46: Advances to suppliers | B46: 10052.382 | C46: 14473.42 | D46: 20838.829 | E46: 30003.747 | F46: 43199.395
A47: Cash and equivalents | B47: 6104.3208 | C47: 2354.875 | D47: 2354.875 | E47: 2354.875 | F47: 2354.875
A48: Property and equipment | B48: 4530.8722 | C48: 4543.6465 | D48: 4562.0388 | E48: 4588.5201 | F48: 4626.6479
A49: Other assets, held at the 2025 level | B49: 15128.3 | C49: 15128.3 | D49: 15128.3 | E49: 15128.3 | F49: 15128.3
A50: TOTAL ASSETS | B50: 184560.09 | C50: 250662.17 | D50: 351234.38 | E50: 496038.26 | F50: 704526.88
A51: Customer advances | B51: 76983.051 | C51: 110840.2 | D51: 159587.72 | E51: 229774.39 | F51: 330829.17
A52: Suppliers | B52: 4225.77 | C52: 6084.2636 | D52: 8760.1228 | E52: 12612.825 | F52: 18159.945
A53: Other creditors | B53: 5685.087 | C53: 8185.3883 | D53: 11785.322 | E53: 16968.507 | F53: 24431.256
... A66: as a multiple of revenue | B66: 1.7231 | C66: 1.7231 | D66: 1.7231 | E66: 1.7231 | F66: 1.7231
A68: The cycle as reported, both audited years
...

Sheet Cash Flow
A1: Cash flow — forecast, both readings
A2: The audited balance sheet and the audited cash-flow statement disagree about 2025 by EGP 16,938 million, and that difference cannot be split from what is disclosed. So the forecast is published two ways and neither is averaged into the other.
A4: IF CASH CONVERSION HOLDS — the basis of the valuation
A5: EGP mn unless stated | B5: 2026 | C5: 2027 | D5: 2028 | E5: 2029 | F5: 2030
A6: Net profit | B6: 3549.278 | C6: 6251.2292 | D6: 10141.498 | E6: 15742.708 | F6: 23807.33
A7: Depreciation and amortisation | B7: 392.607 | C7: 565.2756 | D7: 813.8837 | E7: 1171.8298 | F7: 1687.2006
A8: Change in working capital, cash effect | B8: -443.53 | C8: -1779.5732 | D8: -3703.2081 | E8: -6472.8577 | F8: -10460.599
A9: Cash from operations | B9: 3498.355 | C9: 5036.9315 | D9: 7252.174 | E9: 10441.68 | F9: 15033.931
A10: as a share of revenue | B10: 0.0871 | C10: 0.0871 | D10: 0.0871 | E10: 0.0871 | F10: 0.0871
A11: Capital expenditure | B11: -401.4792 | C11: -578.0498 | D11: -832.2761 | E11: -1198.3111 | F11: -1725.3284
A12: New borrowing drawn | B12: 0 | C12: 0 | D12: 0 | E12: 0 | F12: 0
A13: Cash from financing | B13: 0 | C13: 0 | D13: 0 | E13: 0 | F13: 0
A14: Closing cash | B14: 12516.376 | C14: 16975.257 | D14: 23395.156 | E14: 32638.524 | F14: 45947.127
A15: Cumulative new borrowing | B15: 0 | C15: 0 | D15: 0 | E15: 0 | F15: 0
A17: IF THE COLLECTION CYCLE HOLDS
A18: EGP mn unless stated | B18: 2026 | C18: 2027 | D18: 2028 | E18: 2029 | F18: 2030
A19: Net profit | B19: 3549.278 | C19: 6251.2292 | D19: 10141.498 | E19: 15742.708 | F19: 23807.33
A20: Depreciation and amortisation | B20: 392.607 | C20: 565.2756 | D20: 813.8837 | E20: 1171.8298 | F20: 1687.2006
A21: Change in working capital, cash effect | B21: -6855.585 | C21: -30424.962 | D21: -43805.86 | E21: -63071.677 | F21: -90810.6
A22: Cash from operations | B22: -2913.7 | C22: -23608.457 | D22: -32850.478 | E22: -46157.139 | F22: -65316.07
A23: as a share of revenue | B23: -0.0726 | C23: -0.4084 | D23: -0.3947 | E23: -0.3852 | F23: -0.3786
A24: Capital expenditure | B24: -401.4792 | C24: -578.0498 | D24: -832.2761 | E24: -1198.3111 | F24: -1725.3284
A25: New borrowing drawn | B25: 0 | C25: 20437.061 | D25: 33682.754 | E25: 47355.45 | F25: 67041.398
A26: Cash from financing | B26: 0 | C26: 20437.061 | D26: 33682.754 | E26: 47355.45 | F26: 67041.398
A27: Closing cash | B27: 6104.3208 | C27: 2354.875 | D27: 2354.875 | E27: 2354.875 | F27: 2354.875
A28: Cumulative new borrowing | B28: 0 | C28: 20437.061 | D28: 54119.815 | E28: 101475.26 | F28: 168516.66
A30: Cash conversion, the three published years
A31: FY2023 | B31: 0.043334
A32: FY2024 | B32: 0.1787
A33: FY2025 | B33: 0.039376
A34: mean, carried above | B34: 0.087137

Sheet Summary Financials
A1: Summary financials, as reported
A4: EGP million | B4: 2023 | C4: 2024 | D4: 2025
A5: Revenue | B5: 17462.1 | C5: 27167.3 | D5: 36169.3
A6: Cost of revenue | B6: -11907.2 | C6: -17739.9 | D6: -21118.9
A7: Gross profit | B7: 5507.6 | C7: 9330.1 | D7: 14887.6
A8: Overheads | B8: -2060.5 | C8: -3435.8 | D8: -6365.6
A9: Finance cost | C9: -2311.4 | D9: -3347.5
A10: Pre-tax profit | B10: 2300.7 | C10: 4320.6 | D10: 6251.1
A11: Tax | B11: -567.3 | C11: -917.1 | D11: -1827.2
A12: Profit after tax and minority | B12: 1581.5 | C12: 3254.9 | D12: 4216.7
A13: Cash from operations | B13: 756.7 | C13: 4854.8 | D13: 1424.2
A14: Cash from operations, share of revenue | B14: =B14/B5 | C14: =C14/C5 | D14: =D14/D5

Sheet Monte Carlo
A1: Price distribution — published output, reproduced not re-derived
A2: This is the price engine's distribution, independent of the valuation.
A4: Percentile | B4: One month | C4: Three months
A5: 5th | B5: 13.08 | C5: 11.98
A6: 25th | B6: 14.67 | C6: 14.61
A7: 50th | B7: 15.64 | C7: 16.34
A8: 75th | B8: 16.68 | C8: 18.27
A9: 95th | B9: 18.71 | C9: 22.26
A11: Resolved three-month tests | B11: 57
A12: Inside the 90% band | B12: 0.9123
A13: Inside the middle band | B13: 0.5088
A14: Band width vs a random walk | B14: 1.469

Sheet Sensitivity
A1: Value per share against the two things that move it
A2: Read down a column: cash conversion moves value more than the discount rate does.
A4: Cash conversion | B4: 0.22250009 | C4: 0.24250009 | D4: 0.26250009 | E4: 0.28250009 | F4: 0.30250009
A5: 0.039375935 | B5: 8.85 | C5: 6.29 | D5: 4.46 | E5: 3.08 | F5: 2.01
A6: 0.06 | B6: 15.2 | C6: 11.47 | D6: 8.81 | E6: 6.81 | F6: 5.26
A7: 0.087136637 | B7: 23.56 | C7: 18.3 | D7: 14.54 | E7: 11.72 | F7: 9.54
A8: 0.12 | B8: 33.68 | C8: 26.56 | D8: 21.47 | E8: 17.66 | F8: 14.71
A9: 0.17870013 | B9: 51.77 | C9: 41.32 | D9: 33.86 | E9: 28.28 | F9: 23.96

Sheet Per-Share & Ratios
A1: Per share and ratios
A4: Shares outstanding (mn) | B4: 2859.92
A5: Market price (EGP) | B5: 15.2
A6: Book value per share (EGP) | B6: 6.6281
A7: Price to book | B7: 2.2933
A8: Earnings per share, 2025 (EGP) | B8: 1.4744
A9: Net debt per share, 31 March 2026 (EGP) | B9: 8.1278
A10: Order book per share (EGP) | B10: 91.9606
A11: Gross margin, 2025 | B11: 0.4116
A12: Cash conversion, 2025 | B12: 0.0394

Sheet Peer & Sector
A1: Egyptian listed developers
A2: Every measure on the same window, the same cleaning and the same index.
A4: Code | B4: Company | C4: Beta | D4: R-squared | E4: Std error | F4: Volatility | G4: Worst fall
A5: TMGH | B5: Talaat Moustafa Group Holding | C5: 1.4718 | D5: 0.3261 | E5: 0.1848 | F5: 0.4394 | G5: -0.4419
A6: PHDC | B6: Palm Hills Developments | C6: 1.0493 | D6: 0.2988 | E6: 0.1823 | F6: 0.4391 | G6: -0.4866
A7: ORHD | B7: Orascom Development Egypt | C7: 0.8837 | D7: 0.321 | E7: 0.173 | F7: 0.4636 | G7: -0.4293
A8: HELI | B8: Heliopolis Housing and Development | C8: 0.7653 | D8: 0.2884 | E8: 0.1815 | F8: 0.444 | G8: -0.3958
A9: EMFD | B9: Emaar Misr for Development | C9: 0.7388 | D9: 0.2441 | E9: 0.1692 | F9: 0.4106 | G9: -0.4712
A10: PRDC | B10: Pioneers Properties for Urban Development | C10: 0.7067 | D10: 0.2576 | E10: 0.1864 | F10: 0.4217 | G10: -0.5199
A11: OCDI | B11: Sixth of October Development & Investment (SODIC) | C11: 0.4938 | D11: 0.1033 | E11: 0.2237 | F11: 0.4713 | G11: -0.4658
A13: Earnings and book multiples are not published for the peer group: no peer discloses statements this study can obtain on a consistent basis, and an inconsistent multiple would mislead.
