Workbook

Sheet READ FIRST
A1: Testahil — GB Corp S.A.E. (EGX: GBCO)
A3: Companion model · Independent Valuation Study · Educational analysis · Not investment advice
A5: What this workbook is. A transparent companion to the GB Corp valuation study. Every blue cell is an input; every
A6: black cell is a formula; green cells link across sheets. All inputs live on the Assumptions sheet — change one (a
A7: volume growth rate, the Auto gross margin, the lender's return on equity, the mark on the associate) and the whole
A8: model reprices, both answers with it.
A10: THE ANSWER HAS TWO SIDES, AND THAT IS THE FINDING RATHER THAN AN EVASION. GB Corp's largest single component is a
A11: minority interest in an unlisted company, and the two bases on which the company itself puts a number on it differ
A12: by EGP 11.9bn — about a quarter of the answer. One is the equity-accounted carrying value in its own reviewed
A13: statements at 30 June 2026; the other is its stated stake applied to the primary round it announced in June 2026.
A14: Both are the company's own disclosures and the filings do not decide between them, so neither does this workbook:
A15: the two are carried side by side to the last cell. NO FIGURE BETWEEN THEM IS PRESENTED AS AN ANSWER
... A40: Sheets: Summary · Fundamental Valuation · Assumptions · SOTP Bridge · Segments · Relative & Normalized · DCF · Income Statement · Balance Sheet · Cash Flow · Summary Financials · Monte Carlo · Sensitivity · Per-Share & Ratios · Peer & Sector

Sheet Summary
A1: Valuation summary — GB Corp (EGX: GBCO)
A2: One class primary, published on both of its sides; the other reads are cross-checks beside it. Every cell here is a link — nothing on this sheet is typed.
A5: Read | B5: Basis | C5: EGP/share | D5: vs the price
A6: Sum of the parts — MNT-Halan at its reviewed carrying value | B6: THE PRIMARY, branch B | C6: ='SOTP Bridge'!C11 | D6: =C6/Assumptions!$B$5-1
A7: Sum of the parts — MNT-Halan at the June-2026 round price | B7: THE PRIMARY, branch A | C7: ='SOTP Bridge'!D11 | D7: =C7/Assumptions!$B$5-1
A8: Relative multiple on the company's own history | B8: cross-check, never weighted | C8: ='Relative & Normalized'!B15 | D8: =C8/Assumptions!$B$5-1
A9: Book value per share | B9: a DISCLOSED FLOOR — outside the envelope below, and never weighted | C9: ='Relative & Normalized'!B21 | D9: =C9/Assumptions!$B$5-1
A11: Envelope — low | B11: the RANGE of the present-value reads on one clock, never an average and never a spread invented around a central | C11: =MIN(C6:C8) | D11: =C11/Assumptions!$B$5-1
A12: Envelope — high | C12: =MAX(C6:C8) | D12: =C12/Assumptions!$B$5-1
A14: Latest known price (EGP), 2026-09-03 | C14: =Assumptions!$B$5
A16: THERE IS NO CENTRAL, AND THAT IS THE ANSWER RATHER THAN AN OMISSION. There is no central. The primary is two-sided and the two branches are published side by side; a figure between them would be the average the dual-framing rule forbids. The two branches differ by the mark on one minority stake in an unlisted company, and the filings do not decide between them. Both are well above the price, so the reading the two share is that the market is paying less than either of the company's own disclosures on that stake would support — which is a claim about the mark, and the workbook prices it across its whole range on the SOTP Bridge sheet rather than resolving it.

Sheet Fundamental Valuation
A1: Fundamental valuation — the football-field data
A2: Every read this study publishes, with the scenario span the study's own record carries for the primary. Links to Summary; no weights and no central.
A5: Read | B5: Low | C5: Published | D5: High | E5: Note
A6: Sum of the parts — MNT-Halan at its reviewed carrying value | C6: =Summary!C6 | E6: the primary, branch B
A7: Sum of the parts — MNT-Halan at the June-2026 round price | B7: 30.3773 | C7: =Summary!C7 | D7: 96.1336 | E7: the primary, branch A. The low and high are the study's committed scenario reads: a gross-margin shift, the WHOLE cost-of-capital ladder moved together, a terminal growth shifted in REAL terms, and the marks on the lender and the associates moved with them — a stress on the model at once rather than one driver at a time, which is why they are read from the record and not rebuilt in a cell here.
A8: Relative multiple on the company's own history | C8: =Summary!C8 | E8: cross-check; one value, because the multiple is a median of three observations and a bear/bull around it would be invented.
A9: Book value per share | C9: =Summary!C9 | E9: a disclosed floor, outside the envelope and never weighted.
A10: Envelope | B10: =Summary!C11 | D10: =Summary!C12 | E10: the range of the present-value reads; there is no figure between the two branches anywhere in this workbook.
A11: Latest known price | C11: =Assumptions!$B$5
A12: GB Capital operating equity per share | C12: =Assumptions!$B$43 | E12: memo only: the lender leg's own book, to show what the residual-income multiple does to it.

Sheet Assumptions
A1: Assumptions — the single input layer
A2: All blue cells are inputs. Every other sheet links here.
A4: ANCHORS
A5: Price (EGP/share) | B5: 28.98 | C5: the LATEST KNOWN price, 2026-09-03 close, read from the committed supplied-price record rather than from this workbook's own memory.
A6: Shares outstanding (mn) | B6: 1085.5
A7: Tax rate | B7: 0.28
A8: COST OF CAPITAL — the schedule is built by the house module; this is its first year
A9: Normalised risk-free rate rf* (Egypt 10Y less this sovereign's own default spread) | B9: 0.1959 | C9: observed 23.00% less a default spread of 3.41%, so country risk is counted EXACTLY ONCE, inside the equity risk premium below.
A10: Equity beta — own-stock weekly regression against the published EGX30 index | B10: 0.89068225 | C10: a conforming tier-1 regression: 251 weekly observations to 2026-07-16, R-squared 0.2430, standard error 0.2041.
A11: Equity risk premium — Egypt, market basis (adopted) | B11: 0.0941 | C11: the sovereign's own row on the market basis; the rating basis of 13.94% is published beside it below and in the study.
A12: of which the mature equity premium — beta applies to THIS leg | B12: 0.042268 | C12: the total premium less the country premium below. Beta measures how much more than the market this company moves; it is not a measure of how risky the country is, and multiplying the two charges the sovereign twice over for a cyclical name.
A13: of which the country premium — charged FLAT, once | B13: 0.051832 | C13: Egypt at 5.18% weighted by the 100% of operations that are here.
A14: Cost of equity Ke = rf* + beta x mature premium + country premium | B14: =B9+B10*B12+B13 | C14: reproduces the committed schedule to the basis point.
A15: Pre-tax cost of debt | B15: 0.2653 | C15: the company's own effective borrowing rate, computed on the borrowings that actually bear the interest; the book is entirely local-currency on the disclosed facility note.
A16: After-tax cost of debt | B16: =B15*(1-B7)
A17: Debt weight D/(D+E) — market-value equity | B17: 0.57451403 | C17: market capitalisation against disclosed borrowings; never book equity.
A18: WACC — first forecast year | B18: =(1-B17)*B14+B17*B16 | C18: the schedule GLIDES to a norm-built terminal of 13.45%; the DCF sheet carries one forward rate per year rather than this rate held for ever.
A19: Terminal growth (nominal EGP, DERIVED) | B19: 0.07 | C19: stored as a REAL rate of 0.0% on the house Egyptian inflation path and recomputed to this nominal figure; a typed nominal rate is unfalsifiable.
A20: LEG 1 — GB AUTO: the cash-flow model's own bridge (the DCF sheet builds the leg)
A21: GB Auto net debt (30 June 2026, reviewed) | B21: 14623.7 | C21: the bridge stands on the LATEST disclosed balance sheet and on the AUTO segment's own net debt, not the prior year end and not the group total.
A22: GB Auto non-controlling interests (30 June 2026) | B22: 590.7 | C22: that leg's own minority, deducted from EQUITY value and never from enterprise value.
A23: LEG 2 — GB CAPITAL: residual income, not book times one
A24: GB Capital shareholders' equity before NCI, 30 June 2026 | B24: 22497.8 | C24: 2Q26 earnings release, segmented balance sheet, GB Capital column.
A25: less: associates carried inside that segment, 30 June 2026 | B25: 16230.465 | C25: the reviewed consolidated interim balance sheet's own associates line. Taking it out is what stops the stake funding this leg AND being added back at its own mark.
A26: GB Capital operating equity | B26: =B24-B25 | C26: an identity off two disclosed figures, so nothing here is chosen.
A27: 1H2026 GB Capital net profit after NCI | B27: 649.6 | C27: 2Q26 earnings release, segment income statement.
A28: 1H2026 GB Capital investment gains from associates | B28: 426.2 | C28: same table; taken out of the numerator because it is taken out of the base.
A29: GB Capital equity before NCI, 31 December 2025 | B29: 18312.6 | C29: 4Q25 earnings release, segmented balance sheet, GB Capital column.
A30: less: associates carried inside it, 31 December 2025 | B30: 15732.426 | C30: the reviewed balance sheet's own comparative column, which note 34 foots to.
A31: GB Capital operating equity, 31 December 2025 | B31: =B29-B30
A32: Return on operating equity — 1H2026 annualised (ADOPTED) | B32: =(B27-B28)*2/((B31+B26)/2) | C32: a near-term reviewed actual outranks a stale full-year rate.
A33: FY2025 GB Capital net profit after NCI | B33: 1365.9
A34: FY2025 GB Capital investment gains from associates | B34: 986.4
A35: Return on operating equity — FY2025 framing | B35: =(B33-B34)/B31 | C35: the OTHER framing of a contested judgement worth more than 5% of the answer, published beside the adopted one rather than averaged with it.
A36: Terminal risk-free rate | B36: 0.105 | C36: from the house macro path: terminal inflation plus the real-rate convention, derived and never quoted.
A37: Terminal equity risk premium | B37: 0.07
A38: of which the terminal country premium — charged FLAT, once | B38: 0.027732 | C38: the terminal premium splits the same way the explicit one does; a country premium that stops being multiplied by beta in year five and starts again in perpetuity would be two views of one sovereign.
A39: Terminal cost of equity Ke(T) = rf(T) + beta x mature premium + country premium | B39: =B36+B10*(B37-B38)+B38 | C39: the same beta as the explicit window, on the mature leg only; the construction is named, not assumed.
A40: Justified price-to-book = (ROE - g) / (Ke(T) - g) | B40: =(B32-B19)/(B39-B19) | C40: the residual-income identity in its terminal form. THE TERMINAL Ke IS THE GENEROUS END and it is used deliberately: the explicit-window Ke would put this leg at a fraction of the figure below.
A41: GB Capital lending leg (EGP mn) | B41: =B26*B40
...

Sheet SOTP Bridge
A1: Sum of the parts — the class primary, and it IS the answer
A2: Three legs, and the third has two bases the company itself discloses. Both are carried to the end; nothing between them is computed anywhere in this workbook.
A5: Leg | B5: Basis | C5: MNT-Halan at its reviewed carrying value | D5: MNT-Halan at the June-2026 round price
A6: GB Auto operating leg | B6: five-year cash-flow model: enterprise value less the segment's own net debt and minority | C6: =DCF!$B$27 | D6: =DCF!$B$27
A7: GB Capital lending leg | B7: operating equity x a justified price-to-book of (ROE - g) / (Ke - g) | C7: =Assumptions!$B$41 | D7: =Assumptions!$B$41
A8: Associates (MNT-Halan, Bedaya, Kaf) | B8: the contested judgement: the reviewed carrying value against the June-2026 round price | C8: =Assumptions!$B$52 | D8: =Assumptions!$B$51
A9: Equity value (EGP mn) | C9: =SUM(C6:C8) | D9: =SUM(D6:D8)
A10: Shares in issue (mn) | C10: =Assumptions!$B$6 | D10: =Assumptions!$B$6
A11: FAIR VALUE PER SHARE (EGP) | C11: =C9/C10 | D11: =D9/D10
A12: Latest known price (EGP) | C12: =Assumptions!$B$5 | D12: =Assumptions!$B$5
A13: Difference against the price | C13: =C11/C12-1 | D13: =D11/D12-1
A15: memo: MNT-Halan alone (EGP mn) | C15: =Assumptions!$B$49 | D15: =Assumptions!$B$48
A16: memo: MNT-Halan alone, per share (EGP) | C16: =C15/C10 | D16: =D15/D10
A17: memo: MNT-Halan as a share of the equity value | C17: =C15/C9 | D17: =D15/D9
A18: memo: the distance between the two branches, per share (EGP) | B18: the whole of it is the associate mark; the auto leg and the lender leg are identical in both branches, to the pound. | D18: =D11-C11
A20: WHY THERE IS NO SINGLE NUMBER HERE. GB Corp's largest single component is a minority interest in an unlisted company, and the two bases on which the company itself puts a number on it differ by EGP 11.9bn -- 27% of this answer. Both are GB Corp's own disclosures and the filings do not decide between them, so neither does this study. The low end is the equity-accounted carrying value in the reviewed consolidated interim statements at 30 June 2026; the review conclusion on those statements is QUALIFIED at exactly that line, because the reviewers were not provided with the associate's own financial statements — so the conservative branch is not a safe harbour either, and this workbook says so rather than resting on it. The high end is the stake the company states applied to the primary round it announced on 9 June 2026. A primary round prices new money with whatever preferences ride with it, and GB Corp holds an ordinary equity-accounted minority: it is a mark, not a realisable price.
A22: THE MARK, PRICED ACROSS ITS OWN RANGE
A23: MNT-Halan carried at (EGP mn) | B23: as a multiple of the reviewed carrying value | C23: Fair value per share (EGP)
A24: =Assumptions!$B$48*0.5 | B24: =A24/Assumptions!$B$49 | C24: =(DCF!$B$27+Assumptions!$B$41+A24+Assumptions!$B$50)/Assumptions!$B$6 | D24: the round price haircut to 0.5x — this study's own expert panel's stated sensitivity on a private mark held by a minority holder
A25: =Assumptions!$B$49 | B25: =A25/Assumptions!$B$49 | C25: =(DCF!$B$27+Assumptions!$B$41+A25+Assumptions!$B$50)/Assumptions!$B$6 | D25: MNT-Halan at its reviewed carrying value
A26: =Assumptions!$B$48*0.75 | B26: =A26/Assumptions!$B$49 | C26: =(DCF!$B$27+Assumptions!$B$41+A26+Assumptions!$B$50)/Assumptions!$B$6 | D26: the round price haircut to 0.75x — this study's own expert panel's stated sensitivity on a private mark held by a minority holder
A27: =Assumptions!$B$48 | B27: =A27/Assumptions!$B$49 | C27: =(DCF!$B$27+Assumptions!$B$41+A27+Assumptions!$B$50)/Assumptions!$B$6 | D27: MNT-Halan at the June-2026 round price
A29: The two branch rows here ARE the two branches above, recomputed from the legs rather than copied — which is what makes this table a check on the bridge and not a restatement of it. The rungs are not sorted into a line between the branches on purpose: this prices a mark, it does not interpolate an answer.

Sheet Segments
A1: Segment view — the units x ASP build
A2: Volumes and average selling prices per line of business, FY23-FY30E. The forecast links to the drivers on Assumptions; nothing on this sheet is a hardcoded forecast.
B4: FY23 | C4: FY24 | D4: FY25 | E4: FY26E | F4: FY27E | G4: FY28E | H4: FY29E | I4: FY30E
A6: PC volume (units) | B6: 26994 | C6: 42043 | D6: 56548 | E6: =D6*(1+Assumptions!$C$68) | F6: =E6*(1+Assumptions!$D$68) | G6: =F6*(1+Assumptions!$E$68) | H6: =G6*(1+Assumptions!$F$68) | I6: =H6*(1+Assumptions!$G$68)
A7: PC revenue | B7: 16544.3 | C7: 36533.4 | D7: 52827.3 | E7: =E6*E8 | F7: =F6*F8 | G7: =G6*G8 | H7: =H6*H8 | I7: =I6*I8
A8: PC ASP (EGP mn/unit) | B8: =B7/B6 | C8: =C7/C6 | D8: =D7/D6 | E8: =D8*(1+Assumptions!$C$69) | F8: =E8*(1+Assumptions!$D$69) | G8: =F8*(1+Assumptions!$E$69) | H8: =G8*(1+Assumptions!$F$69) | I8: =H8*(1+Assumptions!$G$69)
A9: CV&CE volume (units) | B9: 2273 | C9: 2096 | D9: 3404 | E9: =D9*(1+Assumptions!$C$70) | F9: =E9*(1+Assumptions!$D$70) | G9: =F9*(1+Assumptions!$E$70) | H9: =G9*(1+Assumptions!$F$70) | I9: =H9*(1+Assumptions!$G$70)
A10: CV&CE revenue | B10: 2323 | C10: 3984.5 | D10: 5956.8 | E10: =D10*(1+Assumptions!$C$70)*(1+Assumptions!$C$71) | F10: =E10*(1+Assumptions!$D$70)*(1+Assumptions!$D$71) | G10: =F10*(1+Assumptions!$E$70)*(1+Assumptions!$E$71) | H10: =G10*(1+Assumptions!$F$70)*(1+Assumptions!$F$71) | I10: =H10*(1+Assumptions!$G$70)*(1+Assumptions!$G$71)
A11: Light-Mobility volume (units) | B11: 13610 | C11: 20189 | D11: 33906 | E11: =D11*(1+Assumptions!$C$72) | F11: =E11*(1+Assumptions!$D$72) | G11: =F11*(1+Assumptions!$E$72) | H11: =G11*(1+Assumptions!$F$72) | I11: =H11*(1+Assumptions!$G$72)
A12: Light-Mobility revenue | B12: 854.2 | C12: 1378.2 | D12: 2203.8 | E12: =D12*(1+Assumptions!$C$72)*(1+Assumptions!$C$73) | F12: =E12*(1+Assumptions!$D$72)*(1+Assumptions!$D$73) | G12: =F12*(1+Assumptions!$E$72)*(1+Assumptions!$E$73) | H12: =G12*(1+Assumptions!$F$72)*(1+Assumptions!$F$73) | I12: =H12*(1+Assumptions!$G$72)*(1+Assumptions!$G$73)
A13: Trading revenue (tires + parts) | B13: 2506.8 | C13: 3815.5 | D13: 4242.8 | E13: =D13*(1+Assumptions!$C$74) | F13: =E13*(1+Assumptions!$D$74) | G13: =F13*(1+Assumptions!$E$74) | H13: =G13*(1+Assumptions!$F$74) | I13: =H13*(1+Assumptions!$G$74)
A14: Other Auto / after-sales & regional adj. | B14: =B15-B7-B10-B12-B13 | C14: =C15-C7-C10-C12-C13 | D14: =D15-D7-D10-D12-D13 | E14: =0 | F14: =0 | G14: =0 | H14: =0 | I14: =0
A15: GB Auto total revenue | B15: 23854 | C15: 47065 | D15: 66358.3 | E15: =E7+E10+E12+E13+E14 | F15: =F7+F10+F12+F13+F14 | G15: =G7+G10+G12+G13+G14 | H15: =H7+H10+H12+H13+H14 | I15: =I7+I10+I12+I13+I14
A16: GB Capital revenue | B16: 4950.9 | C16: 7383.6 | D16: 14743 | E16: =D16*(1+Assumptions!$C$75) | F16: =E16*(1+Assumptions!$D$75) | G16: =F16*(1+Assumptions!$E$75) | H16: =G16*(1+Assumptions!$F$75) | I16: =H16*(1+Assumptions!$G$75)
A17: Intercompany eliminations | B17: =B18-B15-B16 | C17: =C18-C15-C16 | D17: =D18-D15-D16 | E17: =-(E15+E16)*Assumptions!$C$98 | F17: =-(F15+F16)*Assumptions!$D$98 | G17: =-(G15+G16)*Assumptions!$E$98 | H17: =-(H15+H16)*Assumptions!$F$98 | I17: =-(I15+I16)*Assumptions!$G$98
A18: Group revenue | B18: 28317.2 | C18: 53969.5 | D18: 80229.8 | E18: =E15+E16+E17 | F18: =F15+F16+F17 | G18: =G15+G16+G17 | H18: =H15+H16+H17 | I18: =I15+I16+I17
A20: Auto gross profit | B20: 5813.1 | C20: 9057.4 | D20: 9837.1 | E20: =E15*Assumptions!$C$77 | F20: =F15*Assumptions!$D$77 | G20: =G15*Assumptions!$E$77 | H20: =H15*Assumptions!$F$77 | I20: =I15*Assumptions!$G$77
A21: Auto gross margin | B21: =B20/B15 | C21: =C20/C15 | D21: =D20/D15 | E21: =E20/E15 | F21: =F20/F15 | G21: =G20/G15 | H21: =H20/H15 | I21: =I20/I15
A22: Auto EBIT (operating profit) | B22: 3460.9 | C22: 5564.9 | D22: 5830.9 | E22: =E20-E15*Assumptions!$C$78+E15*Assumptions!$C$79+E15*Assumptions!$C$80 | F22: =F20-F15*Assumptions!$D$78+F15*Assumptions!$D$79+F15*Assumptions!$D$80 | G22: =G20-G15*Assumptions!$E$78+G15*Assumptions!$E$79+G15*Assumptions!$E$80 | H22: =H20-H15*Assumptions!$F$78+H15*Assumptions!$F$79+H15*Assumptions!$F$80 | I22: =I20-I15*Assumptions!$G$78+I15*Assumptions!$G$79+I15*Assumptions!$G$80
A23: Auto D&A | B23: 374.3 | C23: 525.7 | D23: 683.3 | E23: =E15*Assumptions!$C$81 | F23: =F15*Assumptions!$D$81 | G23: =G15*Assumptions!$E$81 | H23: =H15*Assumptions!$F$81 | I23: =I15*Assumptions!$G$81
A24: Auto EBITDA | B24: =B22+B23 | C24: =C22+C23 | D24: =D22+D23 | E24: =E22+E23 | F24: =F22+F23 | G24: =G22+G23 | H24: =H22+H23 | I24: =I22+I23
A25: Auto EBITDA margin | B25: =B24/B15 | C25: =C24/C15 | D25: =D24/D15 | E25: =E24/E15 | F25: =F24/F15 | G25: =G24/G15 | H25: =H24/H15 | I25: =I24/I15
A26: GB Capital operating profit | B26: 243.7 | C26: 380.1 | D26: 788.5
A27: GB Capital net profit (after NCI) | B27: 1207.6 | C27: 1091.5 | D27: 1365.9
A28: GB Capital on-book loan portfolio | B28: 8980.5 | C28: 13183.4 | D28: 19495.2
A30: GB Auto 1H2026 reviewed gross margin — the forecast anchor | B30: 0.14297565 | C30: The latest reviewed period, from the segment income statement in the 2Q26 release: revenue 40,021.5 and gross profit 5,722.1. The forecast OPENS BELOW it, at 13.80%, and the gap is 3.5% relative — inside the 5% materiality line, so no mechanism is claimed for it.
A31: Source: GB Corp 4Q23 / 4Q24 / 4Q25 earnings releases. "Other Auto" is the residual against the disclosed segment total, so each historical column foots to the revenue the company published; it is set to zero in the forecast, which is conservative. Historical eliminations are likewise the residual against disclosed group revenue.

Sheet Relative & Normalized
A1: The cross-checks — a relative multiple off the company's own history, and the disclosed floor
A2: Published beside the primary and never averaged into it. There is no normalised-earnings lens for this class, and the reason is at the foot of this sheet.
A5: GB Corp's OWN trailing price-to-earnings, at its last three year-end closes | B5: Close (EGP) | C5: Net profit attributable | D5: EPS (EGP) | E5: Trailing P/E
A6: FY2023 year-end | B6: =Assumptions!$B$54 | C6: =Assumptions!$B$55 | D6: =C6/Assumptions!$B$6 | E6: =B6/D6
A7: FY2024 year-end | B7: =Assumptions!$B$56 | C7: =Assumptions!$B$57 | D7: =C7/Assumptions!$B$6 | E7: =B7/D7
A8: FY2025 year-end | B8: =Assumptions!$B$58 | C8: =Assumptions!$B$59 | D8: =C8/Assumptions!$B$6 | E8: =B8/D8
A9: Adopted multiple — the MEDIAN of those three | E9: =MEDIAN(E6:E8) | F9: THREE OBSERVATIONS IS THIN, and the count is published with the median for exactly that reason.
A10: Observations behind it | E10: 3
A12: THE RELATIVE READ
A13: FY26E group net profit attributable (EGP mn) | B13: ='Income Statement'!E26 | C13: READ from this model's own consolidated forecast rather than typed.
A14: FY26E earnings per share (EGP) | B14: =B13/Assumptions!$B$6
A15: Relative multiple read (EGP/share) | B15: =B14*E9
A16: Difference against the price | B16: =B15/Assumptions!$B$5-1
A17: memo: the multiple the shares ALREADY trade at, on the same forward earnings | B17: =Assumptions!$B$5*Assumptions!$B$6/B13 | C17: committed so the non-circularity claim is arithmetic rather than prose: a lens whose multiple IS the traded one values the company at what it already trades at. This row is NOT an input to anything.
A19: THE DISCLOSED FLOOR
A20: Shareholders' equity before NCI, 30 June 2026 (EGP mn) | B20: =Assumptions!$B$60
A21: Book value per share (EGP) | B21: =B20/Assumptions!$B$6
A22: Price to book, at the latest known price | B22: =Assumptions!$B$5/B21 | C22: A DISCLOSED FLOOR, published as such and carrying no weight in any answer above. It is worth printing because the shares trade BELOW it.
A24: NORMALISED EARNINGS POWER — ABSENT, AND HERE IS WHY
A25: The superseded edition carried a normalised-earnings lens at a fifth of a weighted blend, on six typed figures — three mid-cycle profit levels and three through-cycle multiples — sourced to nothing. It is removed rather than re-sourced, and with this issuer's own numbers behind the decision: group earnings carry investment gains from associates that ran 451.6, 294.6 and 131.6 across three consecutive quarters, plus a revaluation on deconsolidating an associate that the company itself strips out of its own return measure. Normalising earnings that swing on associate marks normalises noise. The sheet keeps its name because the model report's sheet list is the standard and a study does not rename the standard to fit itself.

Sheet DCF
A1: DCF — GB Auto operating leg, explicit five-year free cash flow to the firm
A2: Revenue -> EBITDA -> D&A -> EBIT -> NOPAT -> +D&A -> -capex -> -change in working capital -> FCFF -> discount factor -> present value. Links to Segments, the Balance Sheet and Assumptions.
B4: FY26E | C4: FY27E | D4: FY28E | E4: FY29E | F4: FY30E
A6: Auto revenue | B6: =Segments!E15 | C6: =Segments!F15 | D6: =Segments!G15 | E6: =Segments!H15 | F6: =Segments!I15
A7: EBITDA | B7: =Segments!E24 | C7: =Segments!F24 | D7: =Segments!G24 | E7: =Segments!H24 | F7: =Segments!I24
A8: D&A | B8: =-Segments!E23 | C8: =-Segments!F23 | D8: =-Segments!G23 | E8: =-Segments!H23 | F8: =-Segments!I23
A9: EBIT | B9: =Segments!E22 | C9: =Segments!F22 | D9: =Segments!G22 | E9: =Segments!H22 | F9: =Segments!I22
A10: NOPAT = EBIT x (1 - tax) | B10: =B9*(1-Assumptions!$B$7) | C10: =C9*(1-Assumptions!$B$7) | D10: =D9*(1-Assumptions!$B$7) | E10: =E9*(1-Assumptions!$B$7) | F10: =F9*(1-Assumptions!$B$7)
A11: + D&A | B11: =Segments!E23 | C11: =Segments!F23 | D11: =Segments!G23 | E11: =Segments!H23 | F11: =Segments!I23
A12: - Capex | B12: =-Assumptions!$C$82 | C12: =-Assumptions!$D$82 | D12: =-Assumptions!$E$82 | E12: =-Assumptions!$F$82 | F12: =-Assumptions!$G$82
A13: - Increase in net working capital | B13: =-'Balance Sheet'!E32 | C13: =-'Balance Sheet'!F32 | D13: =-'Balance Sheet'!G32 | E13: =-'Balance Sheet'!H32 | F13: =-'Balance Sheet'!I32
A14: FCFF | B14: =SUM(B10:B13) | C14: =SUM(C10:C13) | D14: =SUM(D10:D13) | E14: =SUM(E10:E13) | F14: =SUM(F10:F13)
A15: Cost of capital — this year's forward rate | B15: 0.23116628 | C15: 0.19665745 | D15: 0.16905038 | E15: 0.14834508 | F15: 0.13454154
A16: Discount factor (cumulative on the schedule) | B16: =1/(1+B15) | C16: =B16/(1+C15) | D16: =C16/(1+D15) | E16: =D16/(1+E15) | F16: =E16/(1+F15)
A17: PV of FCFF | B17: =B14*B16 | C17: =C14*C16 | D17: =D14*D16 | E17: =E14*E16 | F17: =F14*F16
A19: Sum of the present values, FY26-30E | B19: =SUM(B17:F17)
A20: Cost of capital — terminal (norm-built) | B20: 0.13454154 | C20: the norm-built terminal rate the schedule glides to; the terminal is brought home on the SAME cumulative factor as the last explicit year — one date, one price of time.
A21: Terminal value (on the terminal rate) | B21: =F14*(1+Assumptions!$B$19)/(B20-Assumptions!$B$19)
A22: PV of the terminal value | B22: =B21*F16
A23: Enterprise value — GB Auto leg | B23: =B19+B22
A24: Terminal share of enterprise value | B24: =B22/B23
A25: less: GB Auto net debt (30 June 2026) | B25: =-Assumptions!$B$21
A26: less: GB Auto non-controlling interests | B26: =-Assumptions!$B$22
A27: GB Auto equity value | B27: =B23-Assumptions!$B$21-Assumptions!$B$22
A29: check: year-1 forward rate less the WACC built on Assumptions | B29: =B15-Assumptions!$B$18 | C29: ZERO by construction: the schedule's first year and rf* + beta x ERP blended with after-tax debt are the same rate, and this row is what says so.
A30: Enterprise value per +1pp of Auto gross margin (helper) | B30: =0.01*(1-Assumptions!$B$7)*(SUMPRODUCT(B6:F6,B16:F16)+F6*(1+Assumptions!$B$19)/(B20-Assumptions!$B$19)*F16) | C30: EXACT rather than approximate: a margin shift moves cost only, so it moves every year's free cash flow by revenue x shift x (1 - tax) and nothing else. The Sensitivity sheet is built on this row.
A32: The discount factors are the cost-of-capital schedule's own cumulative factors. The terminal growth rate on the Assumptions sheet is stored as a REAL rate on the house Egyptian inflation path and recomputed to its nominal value.

Sheet Income Statement
A1: Income statement (EGP mn, consolidated)
A2: FY23-FY25 as reported (blue, read from the study record); FY26E-FY30E formulas linking to Segments and to the drivers on Assumptions.
B4: FY23 | C4: FY24 | D4: FY25 | E4: FY26E | F4: FY27E | G4: FY28E | H4: FY29E | I4: FY30E
A6: GB Auto revenue | B6: =Segments!B15 | C6: =Segments!C15 | D6: =Segments!D15 | E6: =Segments!E15 | F6: =Segments!F15 | G6: =Segments!G15 | H6: =Segments!H15 | I6: =Segments!I15
A7: GB Capital revenue | B7: =Segments!B16 | C7: =Segments!C16 | D7: =Segments!D16 | E7: =Segments!E16 | F7: =Segments!F16 | G7: =Segments!G16 | H7: =Segments!H16 | I7: =Segments!I16
A8: Intercompany eliminations | B8: =Segments!B17 | C8: =Segments!C17 | D8: =Segments!D17 | E8: =Segments!E17 | F8: =Segments!F17 | G8: =Segments!G17 | H8: =Segments!H17 | I8: =Segments!I17
A9: Total revenue | B9: =SUM(B6:B8) | C9: =SUM(C6:C8) | D9: =SUM(D6:D8) | E9: =SUM(E6:E8) | F9: =SUM(F6:F8) | G9: =SUM(G6:G8) | H9: =SUM(H6:H8) | I9: =SUM(I6:I8)
A10: Gross profit | B10: 6884.5 | C10: 10514.6 | D10: 12431.1 | E10: =Segments!E20+Segments!E16*Assumptions!$C$92+Segments!E17*0.2 | F10: =Segments!F20+Segments!F16*Assumptions!$D$92+Segments!F17*0.2 | G10: =Segments!G20+Segments!G16*Assumptions!$E$92+Segments!G17*0.2 | H10: =Segments!H20+Segments!H16*Assumptions!$F$92+Segments!H17*0.2 | I10: =Segments!I20+Segments!I16*Assumptions!$G$92+Segments!I17*0.2
A11: Gross profit margin | B11: =B10/B9 | C11: =C10/C9 | D11: =D10/D9 | E11: =E10/E9 | F11: =F10/F9 | G11: =G10/G9 | H11: =H10/H9 | I11: =I10/I9
A12: Selling, marketing & administration | B12: -3430.8 | C12: -4843.6 | D12: -6547.3 | E12: =-E9*Assumptions!$C$89 | F12: =-F9*Assumptions!$D$89 | G12: =-G9*Assumptions!$E$89 | H12: =-H9*Assumptions!$F$89 | I12: =-I9*Assumptions!$G$89
A13: Other operating income | B13: 523.2 | C13: 505.6 | D13: 912.2 | E13: =E9*Assumptions!$C$90 | F13: =F9*Assumptions!$D$90 | G13: =G9*Assumptions!$E$90 | H13: =H9*Assumptions!$F$90 | I13: =I9*Assumptions!$G$90
A14: Provisions (net) | B14: -268.9 | C14: -355.7 | D14: -165.1 | E14: =E9*Assumptions!$C$91 | F14: =F9*Assumptions!$D$91 | G14: =G9*Assumptions!$E$91 | H14: =H9*Assumptions!$F$91 | I14: =I9*Assumptions!$G$91
A15: Operating profit | B15: =B10+SUM(B12:B14) | C15: =C10+SUM(C12:C14) | D15: =D10+SUM(D12:D14) | E15: =E10+SUM(E12:E14) | F15: =F10+SUM(F12:F14) | G15: =G10+SUM(G12:G14) | H15: =H10+SUM(H12:H14) | I15: =I10+SUM(I12:I14)
A16: Investment gains from associates | B16: 1061.7 | C16: 867.6 | D16: 974.8 | E16: =Assumptions!$C$93 | F16: =Assumptions!$D$93 | G16: =Assumptions!$E$93 | H16: =Assumptions!$F$93 | I16: =Assumptions!$G$93
A17: EBIT | B17: =B15+B16 | C17: =C15+C16 | D17: =D15+D16 | E17: =E15+E16 | F17: =F15+F16 | G17: =G15+G16 | H17: =H15+H16 | I17: =I15+I16
A18: Group D&A | D18: 999.3 | E18: =Segments!E23+Assumptions!$C$84 | F18: =Segments!F23+Assumptions!$D$84 | G18: =Segments!G23+Assumptions!$E$84 | H18: =Segments!H23+Assumptions!$F$84 | I18: =Segments!I23+Assumptions!$G$84
A19: EBITDA (EBIT + D&A) | D19: =D17+D18 | E19: =E17+E18 | F19: =F17+F18 | G19: =G17+G18 | H19: =H17+H18 | I19: =I17+I18
A20: Foreign exchange gains (losses) | B20: -1499.2 | C20: -291.6 | D20: -37.1 | E20: =0 | F20: =0 | G20: =0 | H20: =0 | I20: =0
A21: Net finance cost | B21: -965.8 | C21: -2397.8 | D21: -3702.1 | E21: =Assumptions!$C$94 | F21: =Assumptions!$D$94 | G21: =Assumptions!$E$94 | H21: =Assumptions!$F$94 | I21: =Assumptions!$G$94
A22: Earnings before tax | B22: =B17+B20+B21 | C22: =C17+C20+C21 | D22: =D17+D20+D21 | E22: =E17+E20+E21 | F22: =F17+F20+F21 | G22: =G17+G20+G21 | H22: =H17+H20+H21 | I22: =I17+I20+I21
A23: Income taxes | B23: -493.2 | C23: -939.2 | D23: -1086.1 | E23: =-E22*Assumptions!$B$7 | F23: =-F22*Assumptions!$B$7 | G23: =-G22*Assumptions!$B$7 | H23: =-H22*Assumptions!$B$7 | I23: =-I22*Assumptions!$B$7
A24: Net profit before minority interest | B24: =B22+B23 | C24: =C22+C23 | D24: =D22+D23 | E24: =E22+E23 | F24: =F22+F23 | G24: =G22+G23 | H24: =H22+H23 | I24: =I22+I23
A25: Minority interest | B25: 79.3 | C25: -131.8 | D25: 99.6 | E25: =E24*Assumptions!$C$95 | F25: =F24*Assumptions!$D$95 | G25: =G24*Assumptions!$E$95 | H25: =H24*Assumptions!$F$95 | I25: =I24*Assumptions!$G$95
A26: Net profit (attributable) | B26: =B24+B25 | C26: =C24+C25 | D26: =D24+D25 | E26: =E24+E25 | F26: =F24+F25 | G26: =G24+G25 | H26: =H24+H25 | I26: =I24+I25
A27: Net profit margin | B27: =B26/B9 | C27: =C26/C9 | D27: =D26/D9 | E27: =E26/E9 | F27: =F26/F9 | G27: =G26/G9 | H27: =H26/H9 | I27: =I26/I9
A29: Source: GB Corp 4Q23 / 4Q24 / 4Q25 earnings releases, group income statement and the segment income statement, read from this study's committed record. Operating profit is computed AFTER provisions in all three years so that the column foots on one definition; the company's own FY2023 and FY2024 captions state it before provisions, which is why its printed figure for those two years is higher by the provisions line directly above. Group depreciation for FY2023 and FY2024 is not carried in the study's record and is left empty rather than estimated.

Sheet Balance Sheet
A1: Balance sheet (EGP mn, consolidated)
A2: FY23-FY25 grouped from the disclosed segment balance sheets to a house layout (blue). The forecast rolls forward and the check row is zero by clean-surplus construction.
B4: FY23 | C4: FY24 | D4: FY25 | E4: FY26E | F4: FY27E | G4: FY28E | H4: FY29E | I4: FY30E
A6: PP&E, intangibles, right-of-use & investment property | B6: 6937.4 | C6: 10360.6 | D6: 13389.1 | E6: =D6+Assumptions!$C$82+Assumptions!$C$83-'Income Statement'!E18 | F6: =E6+Assumptions!$D$82+Assumptions!$D$83-'Income Statement'!F18 | G6: =F6+Assumptions!$E$82+Assumptions!$E$83-'Income Statement'!G18 | H6: =G6+Assumptions!$F$82+Assumptions!$F$83-'Income Statement'!H18 | I6: =H6+Assumptions!$G$82+Assumptions!$G$83-'Income Statement'!I18
A7: Investments in associates (MNT-Halan, Bedaya, Kaf) | B7: 10732.4 | C7: 11743.6 | D7: 13689.5 | E7: =D7+Assumptions!$C$93 | F7: =E7+Assumptions!$D$93 | G7: =F7+Assumptions!$E$93 | H7: =G7+Assumptions!$F$93 | I7: =H7+Assumptions!$G$93
A8: GB Capital loan book (on balance sheet) | B8: 7681.4 | C8: 11483 | D8: 17518.3 | E8: =D8*(1+Assumptions!$C$76) | F8: =E8*(1+Assumptions!$D$76) | G8: =F8*(1+Assumptions!$E$76) | H8: =G8*(1+Assumptions!$F$76) | I8: =H8*(1+Assumptions!$G$76)
A9: Inventories | B9: 6366.1 | C9: 21134.3 | D9: 24649.7 | E9: =Segments!E15*Assumptions!$C$85 | F9: =Segments!F15*Assumptions!$D$85 | G9: =Segments!G15*Assumptions!$E$85 | H9: =Segments!H15*Assumptions!$F$85 | I9: =Segments!I15*Assumptions!$G$85
A10: Trade receivables — Auto | B10: 1743.5 | C10: 3708.7 | D10: 5316.9 | E10: =Segments!E15*Assumptions!$C$86 | F10: =Segments!F15*Assumptions!$D$86 | G10: =Segments!G15*Assumptions!$E$86 | H10: =Segments!H15*Assumptions!$F$86 | I10: =Segments!I15*Assumptions!$G$86
A11: Advances, debtors & other current | B11: 1039.1 | C11: 2942.2 | D11: 4670.6 | E11: =Segments!E15*Assumptions!$C$87 | F11: =Segments!F15*Assumptions!$D$87 | G11: =Segments!G15*Assumptions!$E$87 | H11: =Segments!H15*Assumptions!$F$87 | I11: =Segments!I15*Assumptions!$G$87
A12: Cash & cash equivalents | B12: 4504.2 | C12: 7420.9 | D12: 9523.6 | E12: ='Cash Flow'!E18 | F12: ='Cash Flow'!F18 | G12: ='Cash Flow'!G18 | H12: ='Cash Flow'!H18 | I12: ='Cash Flow'!I18
A13: Other assets (deferred tax, held-for-sale, miscellaneous) | B13: 3581.4 | C13: 3931.9 | D13: 2601.3 | E13: =D13 | F13: =E13 | G13: =F13 | H13: =G13 | I13: =H13
A14: TOTAL ASSETS | B14: =SUM(B6:B13) | C14: =SUM(C6:C13) | D14: =SUM(D6:D13) | E14: =SUM(E6:E13) | F14: =SUM(F6:F13) | G14: =SUM(G6:G13) | H14: =SUM(H6:H13) | I14: =SUM(I6:I13)
A16: Equity attributable to shareholders | B16: 19838.8 | C16: 25438.5 | D16: 28788.7 | E16: =D16+'Income Statement'!E26+'Cash Flow'!E15 | F16: =E16+'Income Statement'!F26+'Cash Flow'!F15 | G16: =F16+'Income Statement'!G26+'Cash Flow'!G15 | H16: =G16+'Income Statement'!H26+'Cash Flow'!H15 | I16: =H16+'Income Statement'!I26+'Cash Flow'!I15
A17: Non-controlling interests | B17: 1363 | C17: 1978.4 | D17: 1801.4 | E17: =D17-'Income Statement'!E25 | F17: =E17-'Income Statement'!F25 | G17: =F17-'Income Statement'!G25 | H17: =G17-'Income Statement'!H25 | I17: =H17-'Income Statement'!I25
A18: Total equity | B18: =B16+B17 | C18: =C16+C17 | D18: =D16+D17 | E18: =E16+E17 | F18: =F16+F17 | G18: =G16+G17 | H18: =H16+H17 | I18: =I16+I17
A19: Borrowings (loans, overdrafts & bonds) | B19: 12517.7 | C19: 22608.7 | D19: 38041.4 | E19: =D19+Assumptions!$C$96 | F19: =E19+Assumptions!$D$96 | G19: =F19+Assumptions!$E$96 | H19: =G19+Assumptions!$F$96 | I19: =H19+Assumptions!$G$96
A20: Trade & notes payables | B20: 7398.7 | C20: 19717.6 | D20: 18436.5 | E20: =Segments!E15*Assumptions!$C$88+$B$30 | F20: =Segments!F15*Assumptions!$D$88+$B$30 | G20: =Segments!G15*Assumptions!$E$88+$B$30 | H20: =Segments!H15*Assumptions!$F$88+$B$30 | I20: =Segments!I15*Assumptions!$G$88+$B$30
A21: Lease obligations | B21: 371.3 | C21: 1123.8 | D21: 1554.3 | E21: =D21 | F21: =E21 | G21: =F21 | H21: =G21 | I21: =H21
A22: Provisions | B22: 347.7 | C22: 709.9 | D22: 794.9 | E22: =D22 | F22: =E22 | G22: =F22 | H22: =G22 | I22: =H22
A23: Other liabilities | B23: 415.2 | C23: 746.2 | D23: 1178.2 | E23: =D23 | F23: =E23 | G23: =F23 | H23: =G23 | I23: =H23
A24: Deferred tax liabilities | B24: 333.1 | C24: 402 | D24: 763.5 | E24: =D24 | F24: =E24 | G24: =F24 | H24: =G24 | I24: =H24
A25: TOTAL EQUITY & LIABILITIES | B25: =B18+SUM(B19:B24) | C25: =C18+SUM(C19:C24) | D25: =D18+SUM(D19:D24) | E25: =E18+SUM(E19:E24) | F25: =F18+SUM(F19:F24) | G25: =G18+SUM(G19:G24) | H25: =H18+SUM(H19:H24) | I25: =I18+SUM(I19:I24)
A27: Balance check (assets less equity & liabilities) — constant, never growing | B27: =B14-B25 | C27: =C14-C25 | D27: =D14-D25 | E27: =E14-E25 | F27: =F14-F25 | G27: =G14-G25 | H27: =H14-H25 | I27: =I14-I25
A28: Group net debt (borrowings less cash) | B28: =B19-B12 | C28: =C19-C12 | D28: =D19-D12 | E28: =E19-E12 | F28: =F19-F12 | G28: =G19-G12 | H28: =H19-H12 | I28: =I19-I12
A30: memo: non-Auto trade payables, held flat across the forecast | B30: 2716.3 | C30: the payables block that does not move with Auto revenue; held flat, which is conservative for working capital.
A31: Net Auto working capital (inventory + receivables + advances less payables) | B31: =B9+B10+B11-(B20-$B$30) | C31: =C9+C10+C11-(C20-$B$30) | D31: =D9+D10+D11-(D20-$B$30) | E31: =E9+E10+E11-(E20-$B$30) | F31: =F9+F10+F11-(F20-$B$30) | G31: =G9+G10+G11-(G20-$B$30) | H31: =H9+H10+H11-(H20-$B$30) | I31: =I9+I10+I11-(I20-$B$30)
A32: Increase in net Auto working capital | E32: =E31-D31 | F32: =F31-E31 | G32: =G31-F31 | H32: =H31-G31 | I32: =I31-H31
A34: Historic mapping note: lines grouped from the disclosed 4Q23 / 4Q24 / 4Q25 segment balance sheets to one house layout. "GB Capital loan book (on balance sheet)" is notes receivable plus GB Capital trade receivables net of eliminations; the portfolio metric the company reports differs by provisions and presentation. Cash at 31-Dec-2025 and borrowings at 31-Dec-2025 are read from the study's committed input register.

Sheet Cash Flow
A1: Cash flow (EGP mn, forecast)
A2: Derived from the Income Statement and the Balance Sheet. Closing cash ties back to the Balance Sheet, and every balance-sheet movement is captured, so the balance check on that sheet is zero.
E4: FY26E | F4: FY27E | G4: FY28E | H4: FY29E | I4: FY30E
A6: Net profit before minority interest | E6: ='Income Statement'!E24 | F6: ='Income Statement'!F24 | G6: ='Income Statement'!G24 | H6: ='Income Statement'!H24 | I6: ='Income Statement'!I24
A7: + D&A | E7: ='Income Statement'!E18 | F7: ='Income Statement'!F18 | G7: ='Income Statement'!G18 | H7: ='Income Statement'!H18 | I7: ='Income Statement'!I18
A8: - Associates income (non-cash) | E8: =-'Income Statement'!E16 | F8: =-'Income Statement'!F16 | G8: =-'Income Statement'!G16 | H8: =-'Income Statement'!H16 | I8: =-'Income Statement'!I16
A9: - Increase in net Auto working capital | E9: =-'Balance Sheet'!E32 | F9: =-'Balance Sheet'!F32 | G9: =-'Balance Sheet'!G32 | H9: =-'Balance Sheet'!H32 | I9: =-'Balance Sheet'!I32
A10: - Increase in the GB Capital loan book | E10: =-('Balance Sheet'!E8-'Balance Sheet'!D8) | F10: =-('Balance Sheet'!F8-'Balance Sheet'!E8) | G10: =-('Balance Sheet'!G8-'Balance Sheet'!F8) | H10: =-('Balance Sheet'!H8-'Balance Sheet'!G8) | I10: =-('Balance Sheet'!I8-'Balance Sheet'!H8)
A11: Operating cash flow | E11: =SUM(E6:E10) | F11: =SUM(F6:F10) | G11: =SUM(G6:G10) | H11: =SUM(H6:H10) | I11: =SUM(I6:I10)
A12: - Capex (Auto + rental fleet) | E12: =-Assumptions!$C$82-Assumptions!$C$83 | F12: =-Assumptions!$D$82-Assumptions!$D$83 | G12: =-Assumptions!$E$82-Assumptions!$E$83 | H12: =-Assumptions!$F$82-Assumptions!$F$83 | I12: =-Assumptions!$G$82-Assumptions!$G$83
A13: Free cash flow | E13: =E11+E12 | F13: =F11+F12 | G13: =G11+G12 | H13: =H11+H12 | I13: =I11+I12
A14: + Increase in borrowings (net) | E14: =Assumptions!$C$96 | F14: =Assumptions!$D$96 | G14: =Assumptions!$E$96 | H14: =Assumptions!$F$96 | I14: =Assumptions!$G$96
A15: - Dividends paid | E15: =-'Income Statement'!E26*Assumptions!$C$97 | F15: =-'Income Statement'!F26*Assumptions!$D$97 | G15: =-'Income Statement'!G26*Assumptions!$E$97 | H15: =-'Income Statement'!H26*Assumptions!$F$97 | I15: =-'Income Statement'!I26*Assumptions!$G$97
A16: Net change in cash | E16: =E13+E14+E15 | F16: =F13+F14+F15 | G16: =G13+G14+G15 | H16: =H13+H14+H15 | I16: =I13+I14+I15
A17: Opening cash | E17: ='Balance Sheet'!D12 | F17: =E18 | G17: =F18 | H17: =G18 | I17: =H18
A18: Closing cash | E18: =E17+E16 | F18: =F17+F16 | G18: =G17+G16 | H18: =H17+H16 | I18: =I17+I16
A20: Historical group cash-flow statements are published per segment in the company's own releases; the forecast here is the consolidated clean-surplus build, which is what the balance check on the previous sheet tests.

Sheet Summary Financials
A1: Summary financials (EGP mn)
A2: Every cell links to a statement sheet.
B4: FY23 | C4: FY24 | D4: FY25 | E4: FY26E | F4: FY27E | G4: FY28E | H4: FY29E | I4: FY30E
A6: Revenue | B6: ='Income Statement'!B9 | C6: ='Income Statement'!C9 | D6: ='Income Statement'!D9 | E6: ='Income Statement'!E9 | F6: ='Income Statement'!F9 | G6: ='Income Statement'!G9 | H6: ='Income Statement'!H9 | I6: ='Income Statement'!I9
A7: EBITDA | D7: ='Income Statement'!D19 | E7: ='Income Statement'!E19 | F7: ='Income Statement'!F19 | G7: ='Income Statement'!G19 | H7: ='Income Statement'!H19 | I7: ='Income Statement'!I19
A8: EBIT | B8: ='Income Statement'!B17 | C8: ='Income Statement'!C17 | D8: ='Income Statement'!D17 | E8: ='Income Statement'!E17 | F8: ='Income Statement'!F17 | G8: ='Income Statement'!G17 | H8: ='Income Statement'!H17 | I8: ='Income Statement'!I17
A9: Net profit (attributable) | B9: ='Income Statement'!B26 | C9: ='Income Statement'!C26 | D9: ='Income Statement'!D26 | E9: ='Income Statement'!E26 | F9: ='Income Statement'!F26 | G9: ='Income Statement'!G26 | H9: ='Income Statement'!H26 | I9: ='Income Statement'!I26
A10: Total assets | B10: ='Balance Sheet'!B14 | C10: ='Balance Sheet'!C14 | D10: ='Balance Sheet'!D14 | E10: ='Balance Sheet'!E14 | F10: ='Balance Sheet'!F14 | G10: ='Balance Sheet'!G14 | H10: ='Balance Sheet'!H14 | I10: ='Balance Sheet'!I14
A11: Total equity | B11: ='Balance Sheet'!B18 | C11: ='Balance Sheet'!C18 | D11: ='Balance Sheet'!D18 | E11: ='Balance Sheet'!E18 | F11: ='Balance Sheet'!F18 | G11: ='Balance Sheet'!G18 | H11: ='Balance Sheet'!H18 | I11: ='Balance Sheet'!I18
A12: Group net debt | B12: ='Balance Sheet'!B28 | C12: ='Balance Sheet'!C28 | D12: ='Balance Sheet'!D28 | E12: ='Balance Sheet'!E28 | F12: ='Balance Sheet'!F28 | G12: ='Balance Sheet'!G28 | H12: ='Balance Sheet'!H28 | I12: ='Balance Sheet'!I28
A13: Free cash flow (forecast) | E13: ='Cash Flow'!E13 | F13: ='Cash Flow'!F13 | G13: ='Cash Flow'!G13 | H13: ='Cash Flow'!H13 | I13: ='Cash Flow'!I13
A14: GB Auto free cash flow to the firm (the DCF leg) | E14: =DCF!B14 | F14: =DCF!C14 | G14: =DCF!D14 | H14: =DCF!E14 | I14: =DCF!F14
A16: EBITDA for FY2023 and FY2024 is not shown because the group depreciation line for those two years is not carried in this study's committed record; it is left empty rather than estimated.

Sheet Monte Carlo
A1: Monte Carlo — the price engine's own lens, on its own clock
A2: 50,000 paths, seed 42, computed by the Testahil price engine. It is a SEPARATE LENS from the valuation on the sheets before this one: no output of either is an input to the other, which is what makes agreement between them information rather than an echo.
A5: The probability read (three months)
A6: Probability the price is above the anchor | B6: 0.58104
A7: P(+10%) against P(-10%) — odds | B7: 39% vs 24% · 1.7:1
A8: Median level (EGP) and move | B8: 30.69 (+4.0%)
A9: 50% band (25th to 75th percentile) | B9: 26.8 - 35.2 (-9% / +19%)
A10: Touch(+10%) / touch(-10%) | B10: 65% / 49%
A12: Percentile map (EGP/share)
A13: Horizon | B13: p5 | C13: p25 | D13: p50 | E13: p75 | F13: p95
A14: 1 month | B14: 24.0317 | C14: 27.6392 | D14: 29.9082 | E14: 32.3718 | F14: 37.3098
A15: 3 months | B15: 21.0045 | C15: 26.8046 | D15: 30.6895 | E15: 35.1844 | F15: 44.8885
A17: Engine inputs (from Assumptions)
A18: Anchor volatility (HAR, annualised) | B18: =Assumptions!$B$62
A19: Secular drift (daily) | B19: =Assumptions!$B$63
A20: Net factor drift per quarter | B20: =Assumptions!$B$64
A22: Level-touch ladder (probability of touching by the horizon)
A23: Level (EGP) | B23: 1 month | C23: 3 months
A24: 40 | B24: 0.0347 | C24: 0.1821
A25: 38 | B25: 0.06214 | C25: 0.25656
A26: 36 | B26: 0.11672 | C26: 0.36168
A27: 34 | B27: 0.23456 | C27: 0.50962
A28: 32 | B28: 0.45508 | C28: 0.69446
A29: 30 | B29: 0.8072 | C29: 0.9008
A30: 28 | B30: 0.52576 | C30: 0.6845
A31: 26 | B31: 0.22022 | C31: 0.4228
A33: The cone is anchored on the last real session the exchange library holds, EGP 29.51 on 2026-08-23; the valuation is struck against the latest known price of EGP 28.98 on 2026-09-03. Two clocks, both published with their own dates.

Sheet Sensitivity
A1: Sensitivity — the two things the answer actually turns on
A2: The mark on the associate, and the price of time. There is no complexity-discount axis: the superseded edition sensitised the answer across a discount it also applied, and that discount is gone.
A4: GRID 1 — Auto gross-margin shift against the MNT-Halan mark
A5: Gross-margin shift \ mark (EGP mn) | B5: =Assumptions!$B$48*0.5 | C5: =Assumptions!$B$49 | D5: =Assumptions!$B$48*0.75 | E5: =Assumptions!$B$48
A6: -0.02 | B6: =(DCF!$B$23+$A6*100*DCF!$B$30-Assumptions!$B$21-Assumptions!$B$22+Assumptions!$B$41+B$5+Assumptions!$B$50)/Assumptions!$B$6 | C6: =(DCF!$B$23+$A6*100*DCF!$B$30-Assumptions!$B$21-Assumptions!$B$22+Assumptions!$B$41+C$5+Assumptions!$B$50)/Assumptions!$B$6 | D6: =(DCF!$B$23+$A6*100*DCF!$B$30-Assumptions!$B$21-Assumptions!$B$22+Assumptions!$B$41+D$5+Assumptions!$B$50)/Assumptions!$B$6 | E6: =(DCF!$B$23+$A6*100*DCF!$B$30-Assumptions!$B$21-Assumptions!$B$22+Assumptions!$B$41+E$5+Assumptions!$B$50)/Assumptions!$B$6
A7: -0.01 | B7: =(DCF!$B$23+$A7*100*DCF!$B$30-Assumptions!$B$21-Assumptions!$B$22+Assumptions!$B$41+B$5+Assumptions!$B$50)/Assumptions!$B$6 | C7: =(DCF!$B$23+$A7*100*DCF!$B$30-Assumptions!$B$21-Assumptions!$B$22+Assumptions!$B$41+C$5+Assumptions!$B$50)/Assumptions!$B$6 | D7: =(DCF!$B$23+$A7*100*DCF!$B$30-Assumptions!$B$21-Assumptions!$B$22+Assumptions!$B$41+D$5+Assumptions!$B$50)/Assumptions!$B$6 | E7: =(DCF!$B$23+$A7*100*DCF!$B$30-Assumptions!$B$21-Assumptions!$B$22+Assumptions!$B$41+E$5+Assumptions!$B$50)/Assumptions!$B$6
A8: 0 | B8: =(DCF!$B$23+$A8*100*DCF!$B$30-Assumptions!$B$21-Assumptions!$B$22+Assumptions!$B$41+B$5+Assumptions!$B$50)/Assumptions!$B$6 | C8: =(DCF!$B$23+$A8*100*DCF!$B$30-Assumptions!$B$21-Assumptions!$B$22+Assumptions!$B$41+C$5+Assumptions!$B$50)/Assumptions!$B$6 | D8: =(DCF!$B$23+$A8*100*DCF!$B$30-Assumptions!$B$21-Assumptions!$B$22+Assumptions!$B$41+D$5+Assumptions!$B$50)/Assumptions!$B$6 | E8: =(DCF!$B$23+$A8*100*DCF!$B$30-Assumptions!$B$21-Assumptions!$B$22+Assumptions!$B$41+E$5+Assumptions!$B$50)/Assumptions!$B$6
A9: 0.01 | B9: =(DCF!$B$23+$A9*100*DCF!$B$30-Assumptions!$B$21-Assumptions!$B$22+Assumptions!$B$41+B$5+Assumptions!$B$50)/Assumptions!$B$6 | C9: =(DCF!$B$23+$A9*100*DCF!$B$30-Assumptions!$B$21-Assumptions!$B$22+Assumptions!$B$41+C$5+Assumptions!$B$50)/Assumptions!$B$6 | D9: =(DCF!$B$23+$A9*100*DCF!$B$30-Assumptions!$B$21-Assumptions!$B$22+Assumptions!$B$41+D$5+Assumptions!$B$50)/Assumptions!$B$6 | E9: =(DCF!$B$23+$A9*100*DCF!$B$30-Assumptions!$B$21-Assumptions!$B$22+Assumptions!$B$41+E$5+Assumptions!$B$50)/Assumptions!$B$6
A10: 0.02 | B10: =(DCF!$B$23+$A10*100*DCF!$B$30-Assumptions!$B$21-Assumptions!$B$22+Assumptions!$B$41+B$5+Assumptions!$B$50)/Assumptions!$B$6 | C10: =(DCF!$B$23+$A10*100*DCF!$B$30-Assumptions!$B$21-Assumptions!$B$22+Assumptions!$B$41+C$5+Assumptions!$B$50)/Assumptions!$B$6 | D10: =(DCF!$B$23+$A10*100*DCF!$B$30-Assumptions!$B$21-Assumptions!$B$22+Assumptions!$B$41+D$5+Assumptions!$B$50)/Assumptions!$B$6 | E10: =(DCF!$B$23+$A10*100*DCF!$B$30-Assumptions!$B$21-Assumptions!$B$22+Assumptions!$B$41+E$5+Assumptions!$B$50)/Assumptions!$B$6
A11: Two of these columns ARE the two published branches, at a zero margin shift, and the other two are haircuts on the round price that this study's own expert panel argues for. A margin shift moves cost only, so it moves each year's free cash flow by revenue x shift x (1 - tax) — the helper row on the DCF sheet is that arithmetic exactly, not an approximation of it.
A13: GRID 2 — the price of time: a shift in the WHOLE cost-of-capital ladder against terminal growth
A14: Ladder shift \ terminal growth | B14: =Assumptions!$B$19+-0.02 | C14: =Assumptions!$B$19+-0.01 | D14: =Assumptions!$B$19+0.0 | E14: =Assumptions!$B$19+0.01 | F14: =Assumptions!$B$19+0.02
A15: -0.02 | B15: =(SUMPRODUCT(DCF!$B$14:$F$14,$B$23:$F$23)+DCF!$F$14*(1+B$14)/($G$23-B$14)*$F$23-Assumptions!$B$21-Assumptions!$B$22+Assumptions!$B$41+Assumptions!$B$51)/Assumptions!$B$6 | C15: =(SUMPRODUCT(DCF!$B$14:$F$14,$B$23:$F$23)+DCF!$F$14*(1+C$14)/($G$23-C$14)*$F$23-Assumptions!$B$21-Assumptions!$B$22+Assumptions!$B$41+Assumptions!$B$51)/Assumptions!$B$6 | D15: =(SUMPRODUCT(DCF!$B$14:$F$14,$B$23:$F$23)+DCF!$F$14*(1+D$14)/($G$23-D$14)*$F$23-Assumptions!$B$21-Assumptions!$B$22+Assumptions!$B$41+Assumptions!$B$51)/Assumptions!$B$6 | E15: =(SUMPRODUCT(DCF!$B$14:$F$14,$B$23:$F$23)+DCF!$F$14*(1+E$14)/($G$23-E$14)*$F$23-Assumptions!$B$21-Assumptions!$B$22+Assumptions!$B$41+Assumptions!$B$51)/Assumptions!$B$6 | F15: =(SUMPRODUCT(DCF!$B$14:$F$14,$B$23:$F$23)+DCF!$F$14*(1+F$14)/($G$23-F$14)*$F$23-Assumptions!$B$21-Assumptions!$B$22+Assumptions!$B$41+Assumptions!$B$51)/Assumptions!$B$6
A16: -0.01 | B16: =(SUMPRODUCT(DCF!$B$14:$F$14,$B$24:$F$24)+DCF!$F$14*(1+B$14)/($G$24-B$14)*$F$24-Assumptions!$B$21-Assumptions!$B$22+Assumptions!$B$41+Assumptions!$B$51)/Assumptions!$B$6 | C16: =(SUMPRODUCT(DCF!$B$14:$F$14,$B$24:$F$24)+DCF!$F$14*(1+C$14)/($G$24-C$14)*$F$24-Assumptions!$B$21-Assumptions!$B$22+Assumptions!$B$41+Assumptions!$B$51)/Assumptions!$B$6 | D16: =(SUMPRODUCT(DCF!$B$14:$F$14,$B$24:$F$24)+DCF!$F$14*(1+D$14)/($G$24-D$14)*$F$24-Assumptions!$B$21-Assumptions!$B$22+Assumptions!$B$41+Assumptions!$B$51)/Assumptions!$B$6 | E16: =(SUMPRODUCT(DCF!$B$14:$F$14,$B$24:$F$24)+DCF!$F$14*(1+E$14)/($G$24-E$14)*$F$24-Assumptions!$B$21-Assumptions!$B$22+Assumptions!$B$41+Assumptions!$B$51)/Assumptions!$B$6 | F16: =(SUMPRODUCT(DCF!$B$14:$F$14,$B$24:$F$24)+DCF!$F$14*(1+F$14)/($G$24-F$14)*$F$24-Assumptions!$B$21-Assumptions!$B$22+Assumptions!$B$41+Assumptions!$B$51)/Assumptions!$B$6
A17: 0 | B17: =(SUMPRODUCT(DCF!$B$14:$F$14,$B$25:$F$25)+DCF!$F$14*(1+B$14)/($G$25-B$14)*$F$25-Assumptions!$B$21-Assumptions!$B$22+Assumptions!$B$41+Assumptions!$B$51)/Assumptions!$B$6 | C17: =(SUMPRODUCT(DCF!$B$14:$F$14,$B$25:$F$25)+DCF!$F$14*(1+C$14)/($G$25-C$14)*$F$25-Assumptions!$B$21-Assumptions!$B$22+Assumptions!$B$41+Assumptions!$B$51)/Assumptions!$B$6 | D17: =(SUMPRODUCT(DCF!$B$14:$F$14,$B$25:$F$25)+DCF!$F$14*(1+D$14)/($G$25-D$14)*$F$25-Assumptions!$B$21-Assumptions!$B$22+Assumptions!$B$41+Assumptions!$B$51)/Assumptions!$B$6 | E17: =(SUMPRODUCT(DCF!$B$14:$F$14,$B$25:$F$25)+DCF!$F$14*(1+E$14)/($G$25-E$14)*$F$25-Assumptions!$B$21-Assumptions!$B$22+Assumptions!$B$41+Assumptions!$B$51)/Assumptions!$B$6 | F17: =(SUMPRODUCT(DCF!$B$14:$F$14,$B$25:$F$25)+DCF!$F$14*(1+F$14)/($G$25-F$14)*$F$25-Assumptions!$B$21-Assumptions!$B$22+Assumptions!$B$41+Assumptions!$B$51)/Assumptions!$B$6
A18: 0.01 | B18: =(SUMPRODUCT(DCF!$B$14:$F$14,$B$26:$F$26)+DCF!$F$14*(1+B$14)/($G$26-B$14)*$F$26-Assumptions!$B$21-Assumptions!$B$22+Assumptions!$B$41+Assumptions!$B$51)/Assumptions!$B$6 | C18: =(SUMPRODUCT(DCF!$B$14:$F$14,$B$26:$F$26)+DCF!$F$14*(1+C$14)/($G$26-C$14)*$F$26-Assumptions!$B$21-Assumptions!$B$22+Assumptions!$B$41+Assumptions!$B$51)/Assumptions!$B$6 | D18: =(SUMPRODUCT(DCF!$B$14:$F$14,$B$26:$F$26)+DCF!$F$14*(1+D$14)/($G$26-D$14)*$F$26-Assumptions!$B$21-Assumptions!$B$22+Assumptions!$B$41+Assumptions!$B$51)/Assumptions!$B$6 | E18: =(SUMPRODUCT(DCF!$B$14:$F$14,$B$26:$F$26)+DCF!$F$14*(1+E$14)/($G$26-E$14)*$F$26-Assumptions!$B$21-Assumptions!$B$22+Assumptions!$B$41+Assumptions!$B$51)/Assumptions!$B$6 | F18: =(SUMPRODUCT(DCF!$B$14:$F$14,$B$26:$F$26)+DCF!$F$14*(1+F$14)/($G$26-F$14)*$F$26-Assumptions!$B$21-Assumptions!$B$22+Assumptions!$B$41+Assumptions!$B$51)/Assumptions!$B$6
A19: 0.02 | B19: =(SUMPRODUCT(DCF!$B$14:$F$14,$B$27:$F$27)+DCF!$F$14*(1+B$14)/($G$27-B$14)*$F$27-Assumptions!$B$21-Assumptions!$B$22+Assumptions!$B$41+Assumptions!$B$51)/Assumptions!$B$6 | C19: =(SUMPRODUCT(DCF!$B$14:$F$14,$B$27:$F$27)+DCF!$F$14*(1+C$14)/($G$27-C$14)*$F$27-Assumptions!$B$21-Assumptions!$B$22+Assumptions!$B$41+Assumptions!$B$51)/Assumptions!$B$6 | D19: =(SUMPRODUCT(DCF!$B$14:$F$14,$B$27:$F$27)+DCF!$F$14*(1+D$14)/($G$27-D$14)*$F$27-Assumptions!$B$21-Assumptions!$B$22+Assumptions!$B$41+Assumptions!$B$51)/Assumptions!$B$6 | E19: =(SUMPRODUCT(DCF!$B$14:$F$14,$B$27:$F$27)+DCF!$F$14*(1+E$14)/($G$27-E$14)*$F$27-Assumptions!$B$21-Assumptions!$B$22+Assumptions!$B$41+Assumptions!$B$51)/Assumptions!$B$6 | F19: =(SUMPRODUCT(DCF!$B$14:$F$14,$B$27:$F$27)+DCF!$F$14*(1+F$14)/($G$27-F$14)*$F$27-Assumptions!$B$21-Assumptions!$B$22+Assumptions!$B$41+Assumptions!$B$51)/Assumptions!$B$6
A22: helper — the shifted discount factors, one forward rate per year moved together | B22: FY26E | C22: FY27E | D22: FY28E | E22: FY29E | F22: FY30E | G22: terminal rate
A23: -0.02 | B23: =1/(1+DCF!B15+$A23) | C23: =B23/(1+DCF!C15+$A23) | D23: =C23/(1+DCF!D15+$A23) | E23: =D23/(1+DCF!E15+$A23) | F23: =E23/(1+DCF!F15+$A23) | G23: =DCF!$B$20+$A23
A24: -0.01 | B24: =1/(1+DCF!B15+$A24) | C24: =B24/(1+DCF!C15+$A24) | D24: =C24/(1+DCF!D15+$A24) | E24: =D24/(1+DCF!E15+$A24) | F24: =E24/(1+DCF!F15+$A24) | G24: =DCF!$B$20+$A24
A25: 0 | B25: =1/(1+DCF!B15+$A25) | C25: =B25/(1+DCF!C15+$A25) | D25: =C25/(1+DCF!D15+$A25) | E25: =D25/(1+DCF!E15+$A25) | F25: =E25/(1+DCF!F15+$A25) | G25: =DCF!$B$20+$A25
A26: 0.01 | B26: =1/(1+DCF!B15+$A26) | C26: =B26/(1+DCF!C15+$A26) | D26: =C26/(1+DCF!D15+$A26) | E26: =D26/(1+DCF!E15+$A26) | F26: =E26/(1+DCF!F15+$A26) | G26: =DCF!$B$20+$A26
A27: 0.02 | B27: =1/(1+DCF!B15+$A27) | C27: =B27/(1+DCF!C15+$A27) | D27: =C27/(1+DCF!D15+$A27) | E27: =D27/(1+DCF!E15+$A27) | F27: =E27/(1+DCF!F15+$A27) | G27: =DCF!$B$20+$A27
A29: Grid 2 is read on branch A — MNT-Halan at the June-2026 round price. Branch B is the same grid shifted DOWN by exactly the distance between the two marks per share, which the SOTP Bridge sheet prints; the price of time does not touch the associate mark, so the shift is a constant and there is nothing to recompute. The whole ladder moves together — moving one forward rate and leaving the others would price two different economies in one model.
A30: the constant to subtract for branch B (EGP/share) | B30: ='SOTP Bridge'!D11-'SOTP Bridge'!C11

Sheet Per-Share & Ratios
A1: Per share and ratios — the standing dashboard
A2: Links to the statements and to Assumptions; nothing here is typed.
B4: FY23 | C4: FY24 | D4: FY25 | E4: FY26E | F4: FY27E | G4: FY28E | H4: FY29E | I4: FY30E
A6: EPS (EGP) | B6: ='Income Statement'!B26/Assumptions!$B$6 | C6: ='Income Statement'!C26/Assumptions!$B$6 | D6: ='Income Statement'!D26/Assumptions!$B$6 | E6: ='Income Statement'!E26/Assumptions!$B$6 | F6: ='Income Statement'!F26/Assumptions!$B$6 | G6: ='Income Statement'!G26/Assumptions!$B$6 | H6: ='Income Statement'!H26/Assumptions!$B$6 | I6: ='Income Statement'!I26/Assumptions!$B$6
A7: DPS (EGP) | E7: ='Income Statement'!E26*Assumptions!C$97/Assumptions!$B$6 | F7: ='Income Statement'!F26*Assumptions!D$97/Assumptions!$B$6 | G7: ='Income Statement'!G26*Assumptions!E$97/Assumptions!$B$6 | H7: ='Income Statement'!H26*Assumptions!F$97/Assumptions!$B$6 | I7: ='Income Statement'!I26*Assumptions!G$97/Assumptions!$B$6
A8: Book value per share (EGP) | B8: ='Balance Sheet'!B16/Assumptions!$B$6 | C8: ='Balance Sheet'!C16/Assumptions!$B$6 | D8: ='Balance Sheet'!D16/Assumptions!$B$6 | E8: ='Balance Sheet'!E16/Assumptions!$B$6 | F8: ='Balance Sheet'!F16/Assumptions!$B$6 | G8: ='Balance Sheet'!G16/Assumptions!$B$6 | H8: ='Balance Sheet'!H16/Assumptions!$B$6 | I8: ='Balance Sheet'!I16/Assumptions!$B$6
A9: P/E at the latest known price | B9: =Assumptions!$B$5/('Income Statement'!B26/Assumptions!$B$6) | C9: =Assumptions!$B$5/('Income Statement'!C26/Assumptions!$B$6) | D9: =Assumptions!$B$5/('Income Statement'!D26/Assumptions!$B$6) | E9: =Assumptions!$B$5/('Income Statement'!E26/Assumptions!$B$6) | F9: =Assumptions!$B$5/('Income Statement'!F26/Assumptions!$B$6) | G9: =Assumptions!$B$5/('Income Statement'!G26/Assumptions!$B$6) | H9: =Assumptions!$B$5/('Income Statement'!H26/Assumptions!$B$6) | I9: =Assumptions!$B$5/('Income Statement'!I26/Assumptions!$B$6)
A10: P/B at the latest known price | B10: =Assumptions!$B$5/('Balance Sheet'!B16/Assumptions!$B$6) | C10: =Assumptions!$B$5/('Balance Sheet'!C16/Assumptions!$B$6) | D10: =Assumptions!$B$5/('Balance Sheet'!D16/Assumptions!$B$6) | E10: =Assumptions!$B$5/('Balance Sheet'!E16/Assumptions!$B$6) | F10: =Assumptions!$B$5/('Balance Sheet'!F16/Assumptions!$B$6) | G10: =Assumptions!$B$5/('Balance Sheet'!G16/Assumptions!$B$6) | H10: =Assumptions!$B$5/('Balance Sheet'!H16/Assumptions!$B$6) | I10: =Assumptions!$B$5/('Balance Sheet'!I16/Assumptions!$B$6)
A11: Dividend yield at the latest known price | E11: =E7/Assumptions!$B$5 | F11: =F7/Assumptions!$B$5 | G11: =G7/Assumptions!$B$5 | H11: =H7/Assumptions!$B$5 | I11: =I7/Assumptions!$B$5
A12: EBITDA margin | D12: ='Income Statement'!D19/'Income Statement'!D9 | E12: ='Income Statement'!E19/'Income Statement'!E9 | F12: ='Income Statement'!F19/'Income Statement'!F9 | G12: ='Income Statement'!G19/'Income Statement'!G9 | H12: ='Income Statement'!H19/'Income Statement'!H9 | I12: ='Income Statement'!I19/'Income Statement'!I9
A13: Net margin | B13: ='Income Statement'!B26/'Income Statement'!B9 | C13: ='Income Statement'!C26/'Income Statement'!C9 | D13: ='Income Statement'!D26/'Income Statement'!D9 | E13: ='Income Statement'!E26/'Income Statement'!E9 | F13: ='Income Statement'!F26/'Income Statement'!F9 | G13: ='Income Statement'!G26/'Income Statement'!G9 | H13: ='Income Statement'!H26/'Income Statement'!H9 | I13: ='Income Statement'!I26/'Income Statement'!I9
A14: Return on average equity (attributable) | B14: ='Income Statement'!B26/'Balance Sheet'!B16 | C14: ='Income Statement'!C26/'Balance Sheet'!C16 | D14: ='Income Statement'!D26/'Balance Sheet'!D16 | E14: ='Income Statement'!E26/'Balance Sheet'!E16 | F14: ='Income Statement'!F26/'Balance Sheet'!F16 | G14: ='Income Statement'!G26/'Balance Sheet'!G16 | H14: ='Income Statement'!H26/'Balance Sheet'!H16 | I14: ='Income Statement'!I26/'Balance Sheet'!I16
A15: Group net debt / EBITDA | D15: ='Balance Sheet'!D28/'Income Statement'!D19 | E15: ='Balance Sheet'!E28/'Income Statement'!E19 | F15: ='Balance Sheet'!F28/'Income Statement'!F19 | G15: ='Balance Sheet'!G28/'Income Statement'!G19 | H15: ='Balance Sheet'!H28/'Income Statement'!H19 | I15: ='Balance Sheet'!I28/'Income Statement'!I19
A16: Revenue year on year | C16: ='Income Statement'!C9/'Income Statement'!B9-1 | D16: ='Income Statement'!D9/'Income Statement'!C9-1 | E16: ='Income Statement'!E9/'Income Statement'!D9-1 | F16: ='Income Statement'!F9/'Income Statement'!E9-1 | G16: ='Income Statement'!G9/'Income Statement'!F9-1 | H16: ='Income Statement'!H9/'Income Statement'!G9-1 | I16: ='Income Statement'!I9/'Income Statement'!H9-1
A17: EPS year on year | C17: ='Income Statement'!C26/'Income Statement'!B26-1 | D17: ='Income Statement'!D26/'Income Statement'!C26-1 | E17: ='Income Statement'!E26/'Income Statement'!D26-1 | F17: ='Income Statement'!F26/'Income Statement'!E26-1 | G17: ='Income Statement'!G26/'Income Statement'!F26-1 | H17: ='Income Statement'!H26/'Income Statement'!G26-1 | I17: ='Income Statement'!I26/'Income Statement'!H26-1
