Workbook

Sheet READ FIRST
A1: Testahil — Saudi Telecom Company (Tadawul: 7010)
A3: Companion model · Independent Valuation Study · Educational analysis · Not investment advice
A5: What this workbook is. A transparent companion to the stc valuation study. Every blue cell is an input; every
A6: black cell is a formula; green cells link across sheets. All inputs live on the Assumptions sheet — change one
A7: (the EBITDA margin path, capex intensity, the beta, terminal growth, a stake mark) and the whole model reprices.
A9: What it is not. It is not investment advice, a recommendation, or a price target. Values are model outputs shown
A10: as ranges. The preparer is not licensed by any securities regulator and may hold a position in the security.
A12: Entity note. Saudi Telecom Company (stc Group) is the Kingdom’s incumbent operator: stc KSA (consumer,
A13: enterprise, wholesale) plus subsidiaries — solutions by stc (79%, listed 7202), stc bank (85%, SAMA-licensed
A14: Jan-2025), stc Kuwait (51.8%), stc Bahrain (100%), center3 (data centres), sirar, iot squared (50% PIF JV) —
A15: and minority stakes: 43.06% of Digital Infrastructure Co (TAWAL+GLIC towers, PIF-controlled) and 9.97% of
A16: Telefónica. House lens: going-concern FCFF DCF (primary), cross-checked by the dividend-policy DDM,
... A26: Per-Share & Ratios · Peer & Sector.

Sheet Summary
A1: Valuation summary — Saudi Telecom Company (Tadawul: 7010)
A2: The class primary is the central; the other lenses sit beside it as cross-checks and are never weighted into it. Base links live; bear and bull are the same model on one driver’s own filed range (study §1.5).
B5: Bear | C5: Base | D5: Bull | E5: Role
A6: Discounted cash flow | B6: 35.3 | C6: ='SOTP Bridge'!C14 | D6: 37 | E6: THE CENTRAL
A7: Dividend discount | B7: 28.2 | C7: ='SOTP Bridge'!C23 | D7: 47.3 | E7: cross-check
A8: Enterprise multiple on own history | B8: 45.8 | C8: ='Relative & Normalized'!C6 | D8: 49.9 | E8: cross-check
A9: Normalised earnings power | B9: 36.8 | C9: ='Relative & Normalized'!C9 | D9: 50.2 | E9: cross-check
A10: Book value per share — a DISCLOSED FLOOR, never weighted | C10: 17.02 | E10: floor
A12: THE CENTRAL — the class primary, not an average of the rows above | C12: =C6
A13: Published range — the span of the present-value reads | B13: 35.29 | D13: 48.08
A15: Spot price (SAR) | B15: Assumptions!$B$5
A16: Central against spot | B16: =C12/Assumptions!$B$5-1
A18: The retired four-lens blend at typed weights is recorded on Assumptions so nothing here can quietly rebuild it. A number produced by averaging several methods is not more robust than the best of them: it is a new method with free parameters nobody tested, and it imports every weakness of the weakest lens at whatever weight somebody typed.

Sheet Fundamental Valuation
A1: Fundamental valuation — football-field data
A2: Bear/base/bull per lens (links to Summary).
A5: Lens | B5: Bear | C5: Base | D5: Bull
A6: Cash-flow model (the class primary) | B6: =Summary!B6 | C6: =Summary!C6 | D6: =Summary!D6
A7: Dividend discount | B7: =Summary!B7 | C7: =Summary!C7 | D7: =Summary!D7
A8: Enterprise multiple on own history | B8: =Summary!B8 | C8: =Summary!C8 | D8: =Summary!D8
A9: Normalised earnings power | B9: =Summary!B9 | C9: =Summary!C9 | D9: =Summary!D9
A10: Book value — a disclosed floor, never weighted into an answer | B10: =Summary!B10 | C10: =Summary!C10 | D10: =Summary!D10
A11: Spot | B11: =Assumptions!$B$5

Sheet Assumptions
A1: Assumptions — the single input layer
A2: All blue cells are inputs. Every other sheet links here.
A4: ANCHORS
A5: Spot price (SAR/share) | B5: 43.86 | C5: the latest known close, 2026-09-03, and the price the published gap is measured against
A6: Shares outstanding (mn) | B6: 4993.024 | C6: issued capital divided by par, less treasury, FOOTED against the count note 17 of the reviewed interim itself states
A7: Effective zakat rate ON EBIT (used for after-tax operating profit) | B7: 0.080345259 | C7: three filed years together, with the disclosed prior-year reversal of 1,324,787 put back. Carrying that reversal forward would read 5.02%.
A8: Effective zakat rate on profit before zakat (income statement) | B8: 0.082668546 | C8: the same charge on the base the income statement applies it to
A9: COST OF CAPITAL — the sanctioned schedule, not built on this sheet
A10: Risk-free rate, normalised by the sovereign default spread | B10: 0.0454 | C10: the observed sovereign yield of 5.52% less this sovereign's OWN default spread of 0.98%. Country risk enters ONCE, through the premium; the raw yield plus a premium already carrying it would count it twice.
A11: Equity beta — own-stock weekly regression vs the published index | B11: 0.70925813 | C11: against the index of the exchange the stock is listed on, through the sanctioned resolver. The delivered study used a 40-session DAILY regression at 0.48, which is not one of the three tiers and may stand only as a flagged interim.
A12: Equity risk premium (market basis, central) | B12: 0.0572 | C12: both bases are published; the swap basis is central because it is the market's own live pricing of the sovereign's credit against an agency judgement updated in steps
A13: of which the MATURE premium — beta applies to this leg only | B13: 0.042304 | C13: Damodaran's identity: the total premium less the country leg below
A14: Country premium — charged FLAT, once, never multiplied by beta | B14: 0.014896 | C14: the sovereign default spread scaled to equity volatility. Country risk is a charge on being here, not a charge that scales with a stock's covariance
A15: Cost of equity Ke = rf* + beta x MATURE premium + country premium, flat | B15: =B10+B11*B13+B14 | C15: reproduces the schedule's own 9.030% from the three cells above it
A16: Pre-tax cost of debt — the company's own latest issue | B16: 0.048602896 | C16: the January 2026 sukuk in two tranches, weighted. Held against an effective rate computed independently over two periods from the finance cost on the borrowings that actually bear it.
A17: After-tax Kd | B17: =B16*(1-0.200000)
A18: Debt weight D/(D+E) — MARKET-VALUE equity, never book | B18: =23536.554/(B5*B6+23536.554) | C18: gross borrowings from the LATEST DISCLOSED balance sheet
A19: WACC — FLAT, because the riyal is pegged and today is already the terminal | B19: =(1-B18)*B15+B18*B17 | C19: the module returns a flat ladder here rather than manufacturing a glide the peg forbids; explicit 8.531% and terminal 8.531%
A20: Terminal growth — DERIVED, terminal inflation + stated real growth | B20: 0.02 | C20: real growth of 0.0% on the house terminal inflation. A typed nominal rate is unfalsifiable: nobody can tell whether 2.5% meant inflation plus half a point or something else.
A21: EV -> EQUITY BRIDGE — every line from the committed bridge record
A22: Investments in associates and joint ventures | B22: 12909.648 | C22: the FILED carrying value. The delivered study carried 4,641 — a figure from before the towers business was contributed to DIIC in February 2025 — and correcting it raised the answer by 3.55%.
A23: Listed equity investment at its disclosed fair value | B23: 8513.43 | C23: marked at the disclosed fair value, not at cost
A24: Investment funds and unlisted equity investments, at fair value | B24: 5163.516 | C24: note 9.1, outside the operating cash flows this model discounts
A25: Net debt | B25: 8375.407 | C25: borrowings 23537 + leases 2259 + spectrum licences 3443 less cash 12940, murabahas 1062, sukuk 6368 and treasury bills 492. THE SPECTRUM LICENCE LIABILITY is consideration owed for licences already capitalised and it is disclosed OUTSIDE borrowings, so a bridge reading the borrowings lines does not see it.
A26: Non-controlling interests, at their share of equity value | B26: 3713.0961 | C26: the model capitalises 100% of subsidiary cash flow, so the minority's claim is worth its SHARE OF THAT VALUE and not its historical cost. Book is 2726 and is published beside it so a reader sees the choice.
A27: DDM (the locked SAR 0.55/quarter policy)
A28: DPS path FY26E–FY30E (SAR) | C28: 2.2 | D28: 2.2 | E28: 2.3 | F28: 2.4 | G28: 2.55
A29: DDM terminal dividend growth | B29: 0.03 | C29: post-policy (2027+) payout growth ≈ EPS growth at ~75% payout
A30: Minority share of equity value (proportional) | B30: 0.020206296 | C30: the minority's own share of profit, which is how the cross-check lenses apply it: proportionally to the whole equity value including the stakes, rather than as a fixed deduction
A31: CROSS-CHECKS — published beside the central, never averaged into it
A32: EV/EBITDA — the company's own trailing multiple, three year ends | B32: 8.762062 | C32: bear 8.316x to bull 9.131x, the range its own three year ends span. NOT a peer band and NOT the current multiple.
A33: FY26E net profit for the relative cross-check | B33: 14503.305 | C33: from the projected income statement, not aligned by hand
A34: Normalized PAT (ex one-offs) | B34: 13232.646
A35: Justified through-cycle P/E | B35: 15 | C35: a stated judgement rather than a measurement, and it is a CROSS-CHECK: it carries no weight in the central
A36: THE RETIRED BLEND — recorded so nothing here can quietly rebuild it
A37: Former weights: cash flow 35%, dividend discount 25%, relative 20%, normalised earnings 20% | C37: RETIRED. Two of those four lenses are not permitted cross-checks for this class at all and between them carried 45% of a central.
A38: THE PRICE MAP — the production engine, reproduced (outputs on the Monte Carlo sheet)
A39: Forward volatility over three months (annualised) | B39: 0.1653 | C39: Projected from this stock’s own recent, medium and longer-run variation
A40: Tail parameter and width calibration | B40: 15.0 / 1.056 | C40: The market panel’s fitted pair. Neither is quoted alone: they trade off, and the honest object is the cone they jointly produce
A41: Momentum lean applied over three months | B41: 0.002404 | C41: Direction call UP (reading +0.30 against a 0.25 threshold); capped at the strength measured
...

Sheet SOTP Bridge
A1: Valuation bridge — FCFF DCF (primary) + the dividend-policy DDM
A2: Core-operations EV from the DCF sheet; stakes marked separately; DDM = the locked SAR 0.55/quarter policy. Links to DCF / Assumptions.
A5: Component | B5: Basis | C5: Value (SAR mn)
A6: Core operations enterprise value | B6: FCFF DCF (§1.1): Σ PV FCFF + PV terminal | C6: =DCF!B27
A7: of which terminal value | B7: % of core enterprise value | C7: =DCF!B28
A8: + Investments in associates & JVs | B8: 43.06% DIIC/TAWAL at carrying value | C8: =Assumptions!$B$22
A9: + Telefónica 9.97% | B9: Market mark on the disclosed stake | C9: =Assumptions!$B$23
A10: + Investment funds and unlisted equity investments | B10: At fair value | C10: =Assumptions!$B$24
A11: − Net debt | B11: Total borrowings less cash, on the 30 June 2026 reviewed sheet | C11: =-Assumptions!$B$25
A12: − Non-controlling interests | B12: At the minority’s share of equity value, not at book | C12: =-Assumptions!$B$26
A13: Equity value | C13: =C6+Assumptions!$B$22+Assumptions!$B$23+Assumptions!$B$24-Assumptions!$B$25-Assumptions!$B$26
A14: DCF fair value per share (SAR) | C14: =C13/Assumptions!$B$6
A15: Upside / (downside) vs spot | C15: =C14/Assumptions!$B$5-1
A17: DDM — the locked dividend policy as a lens
A18: DPS (SAR) | C18: =Assumptions!C28 | D18: =Assumptions!D28 | E18: =Assumptions!E28 | F18: =Assumptions!F28 | G18: =Assumptions!G28
A19: PV of DPS @ Ke | C19: =C18/(1+Assumptions!$B$15)^1 | D19: =D18/(1+Assumptions!$B$15)^2 | E19: =E18/(1+Assumptions!$B$15)^3 | F19: =F18/(1+Assumptions!$B$15)^4 | G19: =G18/(1+Assumptions!$B$15)^5
A20: Σ PV of explicit DPS (FY26–30E) | C20: =SUM(C19:G19)
A21: Terminal value = DPS30 × (1+g) / (Ke − g) | C21: =G18*(1+Assumptions!$B$29)/(Assumptions!$B$15-Assumptions!$B$29)
A22: PV of terminal value | C22: =C21/(1+Assumptions!$B$15)^5
A23: DDM fair value per share (SAR) | C23: =C20+C22
A24: terminal as a share of the dividend-model value | C24: =C22/C23
A26: What the market is paying, read off this sheet: at the spot price the market values the whole equity above what these lines add to, and the difference is the disagreement section 4 of the study takes apart. The regular dividend is covered 1.06 to 1.24 times by first-year model free cash flow across the range of capital intensity this company own three filed years actually ran — covered throughout that range, so the question is whether the data-centre build takes intensity above anything it has yet run.

Sheet Segments
A1: Operating segments — the 12 the company discloses
A2: Note 9 of the audited statements, three filed years, each segment grown on ITS OWN measured real rate times the house Saudi inflation ladder. This sheet used to carry four BUSINESS UNITS with their historicals typed in — consumer, enterprise, wholesale and a subsidiaries residual — none of which the company reports and none of which the model is built on.
B4: FY23 | C4: FY24 | D4: FY25 | E4: FY26E | F4: FY27E | G4: FY28E | H4: FY29E | I4: FY30E
A6: stc | B6: 49218.179 | C6: 49643.893 | D6: 51119.024 | E6: =D6*(1+Assumptions!$C$56)*(1+Assumptions!$C$58)*Assumptions!$C$57 | F6: =E6*(1+Assumptions!$D$56)*(1+Assumptions!$D$58)*Assumptions!$D$57 | G6: =F6*(1+Assumptions!$E$56)*(1+Assumptions!$E$58)*Assumptions!$E$57 | H6: =G6*(1+Assumptions!$F$56)*(1+Assumptions!$F$58)*Assumptions!$F$57 | I6: =H6*(1+Assumptions!$G$56)*(1+Assumptions!$G$58)*Assumptions!$G$57
A7: Channels | B7: 14194.21 | C7: 15110.606 | D7: 14085.195 | E7: =D7*(1+Assumptions!$C$53)*(1+Assumptions!$C$58)*Assumptions!$C$57 | F7: =E7*(1+Assumptions!$D$53)*(1+Assumptions!$D$58)*Assumptions!$D$57 | G7: =F7*(1+Assumptions!$E$53)*(1+Assumptions!$E$58)*Assumptions!$E$57 | H7: =G7*(1+Assumptions!$F$53)*(1+Assumptions!$F$58)*Assumptions!$F$57 | I7: =H7*(1+Assumptions!$G$53)*(1+Assumptions!$G$58)*Assumptions!$G$57
A8: Solutions | B8: 11040.493 | C8: 12063.897 | D8: 12730.189 | E8: =D8*(1+Assumptions!$C$48)*(1+Assumptions!$C$58)*Assumptions!$C$57 | F8: =E8*(1+Assumptions!$D$48)*(1+Assumptions!$D$58)*Assumptions!$D$57 | G8: =F8*(1+Assumptions!$E$48)*(1+Assumptions!$E$58)*Assumptions!$E$57 | H8: =G8*(1+Assumptions!$F$48)*(1+Assumptions!$F$58)*Assumptions!$F$57 | I8: =H8*(1+Assumptions!$G$48)*(1+Assumptions!$G$58)*Assumptions!$G$57
A9: stc Kuwait | B9: 3986.034 | C9: 4105.483 | D9: 4179.842 | E9: =D9*(1+Assumptions!$C$54)*(1+Assumptions!$C$58)*Assumptions!$C$57 | F9: =E9*(1+Assumptions!$D$54)*(1+Assumptions!$D$58)*Assumptions!$D$57 | G9: =F9*(1+Assumptions!$E$54)*(1+Assumptions!$E$58)*Assumptions!$E$57 | H9: =G9*(1+Assumptions!$F$54)*(1+Assumptions!$F$58)*Assumptions!$F$57 | I9: =H9*(1+Assumptions!$G$54)*(1+Assumptions!$G$58)*Assumptions!$G$57
A10: stc Bahrain | B10: 1913.287 | C10: 1927.967 | D10: 1967.83 | E10: =D10*(1+Assumptions!$C$55)*(1+Assumptions!$C$58)*Assumptions!$C$57 | F10: =E10*(1+Assumptions!$D$55)*(1+Assumptions!$D$58)*Assumptions!$D$57 | G10: =F10*(1+Assumptions!$E$55)*(1+Assumptions!$E$58)*Assumptions!$E$57 | H10: =G10*(1+Assumptions!$F$55)*(1+Assumptions!$F$58)*Assumptions!$F$57 | I10: =H10*(1+Assumptions!$G$55)*(1+Assumptions!$G$58)*Assumptions!$G$57
A11: Center 3 | B11: 1089.218 | C11: 1911.716 | D11: 1961.666 | E11: =D11*(1+Assumptions!$C$49)*(1+Assumptions!$C$58)*Assumptions!$C$57 | F11: =E11*(1+Assumptions!$D$49)*(1+Assumptions!$D$58)*Assumptions!$D$57 | G11: =F11*(1+Assumptions!$E$49)*(1+Assumptions!$E$58)*Assumptions!$E$57 | H11: =G11*(1+Assumptions!$F$49)*(1+Assumptions!$F$58)*Assumptions!$F$57 | I11: =H11*(1+Assumptions!$G$49)*(1+Assumptions!$G$58)*Assumptions!$G$57
A12: stc Bank | B12: 1063.006 | C12: 1261.646 | D12: 1401.027 | E12: =D12*(1+Assumptions!$C$46)*(1+Assumptions!$C$58)*Assumptions!$C$57 | F12: =E12*(1+Assumptions!$D$46)*(1+Assumptions!$D$58)*Assumptions!$D$57 | G12: =F12*(1+Assumptions!$E$46)*(1+Assumptions!$E$58)*Assumptions!$E$57 | H12: =G12*(1+Assumptions!$F$46)*(1+Assumptions!$F$58)*Assumptions!$F$57 | I12: =H12*(1+Assumptions!$G$46)*(1+Assumptions!$G$58)*Assumptions!$G$57
A13: Sirar | B13: 588.606 | C13: 732.675 | D13: 826.545 | E13: =D13*(1+Assumptions!$C$45)*(1+Assumptions!$C$58)*Assumptions!$C$57 | F13: =E13*(1+Assumptions!$D$45)*(1+Assumptions!$D$58)*Assumptions!$D$57 | G13: =F13*(1+Assumptions!$E$45)*(1+Assumptions!$E$58)*Assumptions!$E$57 | H13: =G13*(1+Assumptions!$F$45)*(1+Assumptions!$F$58)*Assumptions!$F$57 | I13: =H13*(1+Assumptions!$G$45)*(1+Assumptions!$G$58)*Assumptions!$G$57
A14: Specialized | B14: 397.492 | C14: 371.763 | D14: 355.306 | E14: =D14*(1+Assumptions!$C$47)*(1+Assumptions!$C$58)*Assumptions!$C$57 | F14: =E14*(1+Assumptions!$D$47)*(1+Assumptions!$D$58)*Assumptions!$D$57 | G14: =F14*(1+Assumptions!$E$47)*(1+Assumptions!$E$58)*Assumptions!$E$57 | H14: =G14*(1+Assumptions!$F$47)*(1+Assumptions!$F$58)*Assumptions!$F$57 | I14: =H14*(1+Assumptions!$G$47)*(1+Assumptions!$G$58)*Assumptions!$G$57
A15: iot2 | B15: 72.539 | C15: 301.434 | D15: 321.668 | E15: =D15*(1+Assumptions!$C$50)*(1+Assumptions!$C$58)*Assumptions!$C$57 | F15: =E15*(1+Assumptions!$D$50)*(1+Assumptions!$D$58)*Assumptions!$D$57 | G15: =F15*(1+Assumptions!$E$50)*(1+Assumptions!$E$58)*Assumptions!$E$57 | H15: =G15*(1+Assumptions!$F$50)*(1+Assumptions!$F$58)*Assumptions!$F$57 | I15: =H15*(1+Assumptions!$G$50)*(1+Assumptions!$G$58)*Assumptions!$G$57
A16: SCCC | B16: 72.15 | C16: 187.904 | D16: 303.969 | E16: =D16*(1+Assumptions!$C$51)*(1+Assumptions!$C$58)*Assumptions!$C$57 | F16: =E16*(1+Assumptions!$D$51)*(1+Assumptions!$D$58)*Assumptions!$D$57 | G16: =F16*(1+Assumptions!$E$51)*(1+Assumptions!$E$58)*Assumptions!$E$57 | H16: =G16*(1+Assumptions!$F$51)*(1+Assumptions!$F$58)*Assumptions!$F$57 | I16: =H16*(1+Assumptions!$G$51)*(1+Assumptions!$G$58)*Assumptions!$G$57
A17: Other operating segments | B17: 709.843 | C17: 729.345 | D17: 65.059 | E17: =D17*(1+Assumptions!$C$52)*(1+Assumptions!$C$58)*Assumptions!$C$57 | F17: =E17*(1+Assumptions!$D$52)*(1+Assumptions!$D$58)*Assumptions!$D$57 | G17: =F17*(1+Assumptions!$E$52)*(1+Assumptions!$E$58)*Assumptions!$E$57 | H17: =G17*(1+Assumptions!$F$52)*(1+Assumptions!$F$58)*Assumptions!$F$57 | I17: =H17*(1+Assumptions!$G$52)*(1+Assumptions!$G$58)*Assumptions!$G$57
A18: Gross segment revenue | B18: =SUM(B6:B17) | C18: =SUM(C6:C17) | D18: =SUM(D6:D17) | E18: =SUM(E6:E17) | F18: =SUM(F6:F17) | G18: =SUM(G6:G17) | H18: =SUM(H6:H17) | I18: =SUM(I6:I17)
A19: Eliminations / adjustments | B19: -12567.896 | C19: -12454.916 | D19: -11498.645 | E19: =E18*Assumptions!$C$59 | F19: =F18*Assumptions!$D$59 | G19: =G18*Assumptions!$E$59 | H19: =H18*Assumptions!$F$59 | I19: =I18*Assumptions!$G$59
A20: Group revenue | B20: =B18+B19 | C20: =C18+C19 | D20: =D18+D19 | E20: =E18+E19 | F20: =F18+F19 | G20: =G18+G19 | H20: =H18+H19 | I20: =I18+I19
A22: Group EBITDA | B22: 22445 | C22: 23951 | D22: 24469 | E22: =E20*Assumptions!$C$60 | F22: =F20*Assumptions!$D$60 | G22: =G20*Assumptions!$E$60 | H22: =H20*Assumptions!$F$60 | I22: =I20*Assumptions!$G$60
A23: EBITDA margin | B23: =B22/B20 | C23: =C22/C20 | D23: =D22/D20 | E23: =E22/E20 | F23: =F22/F20 | G23: =G22/G20 | H23: =H22/H20 | I23: =I22/I20
A26: Every forecast cell above is a formula: the prior year times one plus the segment's own real rate times one plus the house inflation ladder, both read from Assumptions. Move a rate there and this sheet moves.

Sheet Relative & Normalized
A1: Relative & normalized-earnings lenses
A2: Links to Assumptions, DCF and the Income Statement.
A5: Lens | B5: Workings | C5: SAR/share
A6: Relative EV/EBITDA | B6: FY26E EBITDA × justified multiple + stakes − net debt − NCI, /sh | C6: =(DCF!B7*Assumptions!$B$32+Assumptions!$B$22+Assumptions!$B$23+Assumptions!$B$24-Assumptions!$B$25)*(1-Assumptions!$B$30)/Assumptions!$B$6
A7: implied P/E cross-check at that value | C7: =C6*Assumptions!$B$6/Assumptions!$B$33
A8: IS-build FY26E EPS, for reference | C8: ='Income Statement'!E21
A9: Normalized earnings power | B9: Normalized PAT (ex one-offs) × through-cycle P/E, /sh | C9: =Assumptions!$B$34*Assumptions!$B$35/Assumptions!$B$6
A10: normalized EPS (SAR) | C10: =Assumptions!$B$34/Assumptions!$B$6
A12: P/B cross-check: spot / FY25 BVPS | C12: =Assumptions!$B$5/('Balance Sheet'!D14/Assumptions!$B$6)
A13: Dividend yield — two framings: regular declared 2.20/sh = 5.0%; cash paid during 2025 (incl. the SAR 2.00 special for FY24) 4.20/sh = 9.6%.

Sheet DCF
A1: DCF — going-concern FCFF, explicit 5 years
A2: Revenue → EBITDA → D&A → EBIT → NOPAT → +D&A → −Capex → −ΔWC → FCFF → discount factor → PV. WACC built bottom-up on Assumptions (rf + β×ERP, both ERP bases published).
B4: FY26E | C4: FY27E | D4: FY28E | E4: FY29E | F4: FY30E
A6: Group revenue | B6: =Segments!E20 | C6: =Segments!F20 | D6: =Segments!G20 | E6: =Segments!H20 | F6: =Segments!I20
A7: EBITDA | B7: =Segments!E22 | C7: =Segments!F22 | D7: =Segments!G22 | E7: =Segments!H22 | F7: =Segments!I22
A8: D&A | B8: =-B6*Assumptions!$C$61 | C8: =-C6*Assumptions!$D$61 | D8: =-D6*Assumptions!$E$61 | E8: =-E6*Assumptions!$F$61 | F8: =-F6*Assumptions!$G$61
A9: EBIT | B9: =B7+B8 | C9: =C7+C8 | D9: =D7+D8 | E9: =E7+E8 | F9: =F7+F8
A10: NOPAT = EBIT × (1 − zakat/tax) | B10: =B9*(1-Assumptions!$B$7) | C10: =C9*(1-Assumptions!$B$7) | D10: =D9*(1-Assumptions!$B$7) | E10: =E9*(1-Assumptions!$B$7) | F10: =F9*(1-Assumptions!$B$7)
A11: + D&A | B11: =-B8 | C11: =-C8 | D11: =-D8 | E11: =-E8 | F11: =-F8
A12: − Capex | B12: =-B6*Assumptions!$C$62 | C12: =-C6*Assumptions!$D$62 | D12: =-D6*Assumptions!$E$62 | E12: =-E6*Assumptions!$F$62 | F12: =-F6*Assumptions!$G$62
A13: − Increase in net working capital | B13: =-B6*Assumptions!$C$63 | C13: =-C6*Assumptions!$D$63 | D13: =-D6*Assumptions!$E$63 | E13: =-E6*Assumptions!$F$63 | F13: =-F6*Assumptions!$G$63
A14: FCFF | B14: =SUM(B10:B13) | C14: =SUM(C10:C13) | D14: =SUM(D10:D13) | E14: =SUM(E10:E13) | F14: =SUM(F10:F13)
A15: Discount factor | B15: =1/(1+Assumptions!$B$19)^1 | C15: =1/(1+Assumptions!$B$19)^2 | D15: =1/(1+Assumptions!$B$19)^3 | E15: =1/(1+Assumptions!$B$19)^4 | F15: =1/(1+Assumptions!$B$19)^5
A16: PV of FCFF | B16: =B14*B15 | C16: =C14*C15 | D16: =D14*D15 | E16: =E14*E15 | F16: =F14*F15
A18: Σ PV of explicit FCFF (FY26–30E) | B18: =SUM(B16:F16)
A19: Terminal NOPAT | B19: 15407.078
A20: + book depreciation added back | B20: 11436.603
A21: - maintenance at current cost (disclosed life 15.23 years) | B21: -15461.021
A22: - capital that real growth needs | B22: 0
A23: - inflation on working capital | B23: -271.10088
A24: Terminal free cash flow | B24: =SUM(B19:B23)
A25: Terminal value | B25: =B24*(1+Assumptions!$B$20)/(Assumptions!$B$19-Assumptions!$B$20)
A26: PV of terminal value | B26: =B25*F15
A27: Enterprise value — core operations | B27: =B18+B26
A28: % terminal of enterprise value | B28: =B26/B27
A29: + Investments in associates (DIIC/TAWAL 43.06%) | B29: =Assumptions!$B$22
A30: + Telefónica 9.97% (market mark) | B30: =Assumptions!$B$23
A31: − Net debt, on the 30 June 2026 reviewed sheet | B31: =-Assumptions!$B$25
A32: − Non-controlling interests | B32: =-Assumptions!$B$26
A33: + Investment funds and unlisted equity investments | B33: =Assumptions!$B$24
A34: Equity value | B34: =B27+Assumptions!$B$22+Assumptions!$B$23+Assumptions!$B$24-Assumptions!$B$25-Assumptions!$B$26
A35: DCF fair value per share (SAR) | B35: =B34/Assumptions!$B$6
A36: Upside / (downside) vs spot | B36: =B35/Assumptions!$B$5-1
A38: WACC is built on Assumptions as Ke = rf + β×ERP blended with after-tax Kd (§3.5-G); the alternative CDS-based WACC is on Assumptions row 88. Terminal value is disclosed as a share of enterprise value above rather than blended away.

Sheet Income Statement
A1: Income statement (SAR mn, consolidated, continuing operations)
A2: FY23–FY25 as disclosed in stc IR releases, restated continuing-ops basis (blue); FY26E–FY30E formulas linked to Segments and Assumptions.
B4: FY23 | C4: FY24 | D4: FY25 | E4: FY26E | F4: FY27E | G4: FY28E | H4: FY29E | I4: FY30E
A6: Total revenue | B6: 71777 | C6: 75893 | D6: 77819 | E6: =Segments!E20 | F6: =Segments!F20 | G6: =Segments!G20 | H6: =Segments!H20 | I6: =Segments!I20
A7: Gross profit | B7: 34740 | C7: 37326 | D7: 37700 | E7: =E6*0.485 | F7: =F6*0.485 | G7: =G6*0.485 | H7: =H6*0.485 | I7: =I6*0.485
A8: Gross margin | B8: =B7/B6 | C8: =C7/C6 | D8: =D7/D6 | E8: =E7/E6 | F8: =F7/F6 | G8: =G7/G6 | H8: =H7/H6 | I8: =I7/I6
A9: EBITDA | B9: 22445 | C9: 23951 | D9: 24469 | E9: =Segments!E22 | F9: =Segments!F22 | G9: =Segments!G22 | H9: =Segments!H22 | I9: =Segments!I22
A10: EBITDA margin | B10: =B9/B6 | C10: =C9/C6 | D10: =D9/D6 | E10: =E9/E6 | F10: =F9/F6 | G10: =G9/G6 | H10: =H9/H6 | I10: =I9/I6
A11: Depreciation, amortisation & impairment | B11: -9284 | C11: -9525 | D11: -10031 | E11: =-E6*Assumptions!$C$61 | F11: =-F6*Assumptions!$D$61 | G11: =-G6*Assumptions!$E$61 | H11: =-H6*Assumptions!$F$61 | I11: =-I6*Assumptions!$G$61
A12: Operating profit (EBIT) | B12: 13161 | C12: 14426 | D12: 14438 | E12: =E9+E11 | F12: =F9+F11 | G12: =G9+G11 | H12: =H9+H11 | I12: =I9+I11
A13: Share of associates & JVs + net finance & other | B13: 1461 | C13: 899 | D13: 285 | E13: =Assumptions!$C$64+Assumptions!$C$65+Assumptions!$C$66 | F13: =Assumptions!$D$64+Assumptions!$D$65+Assumptions!$D$66 | G13: =Assumptions!$E$64+Assumptions!$E$65+Assumptions!$E$66 | H13: =Assumptions!$F$64+Assumptions!$F$65+Assumptions!$F$66 | I13: =Assumptions!$G$64+Assumptions!$G$65+Assumptions!$G$66
A14: Profit before zakat & income tax | B14: 14622 | C14: 15325 | D14: 14723 | E14: =E12+E13 | F14: =F12+F13 | G14: =G12+G13 | H14: =H12+H13 | I14: =I12+I13
A15: Zakat & income tax | B15: -1327 | C15: -1192 | D15: 466 | E15: =-E14*Assumptions!$B$7 | F15: =-F14*Assumptions!$B$7 | G15: =-G14*Assumptions!$B$7 | H15: =-H14*Assumptions!$B$7 | I15: =-I14*Assumptions!$B$7
A16: Profit from continuing operations | B16: 12660 | C16: 10942 | D16: 15189 | E16: =E14+E15 | F16: =F14+F15 | G16: =G14+G15 | H16: =H14+H15 | I16: =I14+I15
A17: Profit from discontinued operations | B17: 759 | C17: 13973 | D17: 0 | E17: =0 | F17: =0 | G17: =0 | H17: =0 | I17: =0
A18: Non-controlling interests | B18: -124 | C18: -226 | D18: -361 | E18: =-(E16)*0.020206295602669237 | F18: =-(F16)*0.020206295602669237 | G18: =-(G16)*0.020206295602669237 | H18: =-(H16)*0.020206295602669237 | I18: =-(I16)*0.020206295602669237
A19: Net profit (attributable) | B19: 13295 | C19: 24689 | D19: 14828 | E19: =E16+E17+E18 | F19: =F16+F17+F18 | G19: =G16+G17+G18 | H19: =H16+H17+H18 | I19: =I16+I17+I18
A20: Net margin (attributable) | B20: =B19/B6 | C20: =C19/C6 | D20: =D19/D6 | E20: =E19/E6 | F20: =F19/F6 | G20: =G19/G6 | H20: =H19/H6 | I20: =I19/I6
A21: EPS (SAR) | B21: =B19/Assumptions!$B$6 | C21: =C19/Assumptions!$B$6 | D21: =D19/Assumptions!$B$6 | E21: =E19/Assumptions!$B$6 | F21: =F19/Assumptions!$B$6 | G21: =G19/Assumptions!$B$6 | H21: =H19/Assumptions!$B$6 | I21: =I19/Assumptions!$B$6
A23: Sources — the filings every figure above was read out of: audited consolidated financial statements for the year ended 31 December 2024; audited consolidated financial statements for the year ended 31 December 2025; reviewed condensed consolidated interim financial statements for the six months ended 30 June 2026; fourth-quarter and full-year 2025 earnings presentation; second-quarter and half-year 2026 earnings presentation — every one fetched from the company's own investor-relations archive. FY23/FY24 restated to continuing operations (TAWAL + Digital Infrastructure Co reclassified as discontinued; FY24 discontinued profit 13,973 incl. the SAR 12,885mn disposal gain). One-offs: FY23 AlKhobar land gain +1,296, WHT reversal +724, ERP −863; FY24 WHT reversal +1,500, ERP −2,577, BGSM impairment −764; FY25 zakat credit +466, ERP ≈ −824. "Share of associates + net finance & other" is the residual bridging disclosed EBIT to disclosed profit before zakat — stc does not publish those lines separately in the IR release layout; the FY25 annual FS carries the full detail.

Sheet Balance Sheet
A1: Balance sheet (SAR mn, consolidated)
A2: FY23–FY25 grouped from the company's own statements into one layout (blue). Forecast rolls forward clean-surplus; the check row is zero by construction.
B4: FY23 | C4: FY24 | D4: FY25 | E4: FY26E | F4: FY27E | G4: FY28E | H4: FY29E | I4: FY30E
A6: PP&E, ROU, intangibles & inv. property | B6: 92000 | C6: 95500 | D6: 126436 | E6: =D6+Segments!E20*Assumptions!$C$62+'Income Statement'!E11 | F6: =E6+Segments!F20*Assumptions!$D$62+'Income Statement'!F11 | G6: =F6+Segments!G20*Assumptions!$E$62+'Income Statement'!G11 | H6: =G6+Segments!H20*Assumptions!$F$62+'Income Statement'!H11 | I6: =H6+Segments!I20*Assumptions!$G$62+'Income Statement'!I11
A7: Investments in associates & JVs | B7: 3800 | C7: 4200 | D7: 4641 | E7: =D7 | F7: =E7 | G7: =F7 | H7: =G7 | I7: =H7
A8: Financial assets (incl. Telefónica 9.97%) | B8: 22000 | C8: 23500 | D8: 24893 | E8: =D8 | F8: =E8 | G8: =F8 | H8: =G8 | I8: =H8
A9: Trade receivables, net | B9: 24500 | C9: 25800 | D9: 26727 | E9: =D9+Segments!E20*Assumptions!$C$63 | F9: =E9+Segments!F20*Assumptions!$D$63 | G9: =F9+Segments!G20*Assumptions!$E$63 | H9: =G9+Segments!H20*Assumptions!$F$63 | I9: =H9+Segments!I20*Assumptions!$G$63
A10: Cash, equivalents & short-term murabahas | B10: 28138 | C10: 30755 | D10: 15108 | E10: ='Cash Flow'!E20 | F10: ='Cash Flow'!F20 | G10: ='Cash Flow'!G20 | H10: ='Cash Flow'!H20 | I10: ='Cash Flow'!I20
A11: Other assets | B11: =159646-B6-B7-B8-B9-B10 | C11: =160638-C6-C7-C8-C9-C10 | D11: 2952 | E11: =D11 | F11: =E11 | G11: =F11 | H11: =G11 | I11: =H11
A12: TOTAL ASSETS | B12: 159646 | C12: 160638 | D12: =SUM(D6:D11) | E12: =SUM(E6:E11) | F12: =SUM(F6:F11) | G12: =SUM(G6:G11) | H12: =SUM(H6:H11) | I12: =SUM(I6:I11)
A14: Equity attributable to shareholders | B14: 78985 | C14: 89417 | D14: 83414 | E14: =D14+'Income Statement'!E19-Assumptions!$C$68*Assumptions!$B$6 | F14: =E14+'Income Statement'!F19-Assumptions!$D$68*Assumptions!$B$6 | G14: =F14+'Income Statement'!G19-Assumptions!$E$68*Assumptions!$B$6 | H14: =G14+'Income Statement'!H19-Assumptions!$F$68*Assumptions!$B$6 | I14: =H14+'Income Statement'!I19-Assumptions!$G$68*Assumptions!$B$6
A15: Non-controlling interests | B15: 2530 | C15: 3069 | D15: 3482 | E15: =D15-'Income Statement'!E18 | F15: =E15-'Income Statement'!F18 | G15: =F15-'Income Statement'!G18 | H15: =G15-'Income Statement'!H18 | I15: =H15-'Income Statement'!I18
A16: Total equity | B16: =B14+B15 | C16: =C14+C15 | D16: =D14+D15 | E16: =E14+E15 | F16: =F14+F15 | G16: =G14+G15 | H16: =H14+H15 | I16: =I14+I15
A17: Borrowings & sukuk (excl. leases) | B17: 21958 | C17: 15132 | D17: 15191 | E17: =D17+7284 | F17: =E17 | G17: =F17 | H17: =G17 | I17: =H17
A18: Lease liabilities | B18: 6985 | C18: 4580 | D18: 2253 | E18: =D18 | F18: =E18 | G18: =F18 | H18: =G18 | I18: =H18
A19: Trade payables & financial liabilities | B19: 26000 | C19: 27500 | D19: 29610 | E19: =D19 | F19: =E19 | G19: =F19 | H19: =G19 | I19: =H19
A20: Zakat payable, provisions & other liabilities | B20: =159646-B16-B17-B18-B19 | C20: =160638-C16-C17-C18-C19 | D20: 14876 | E20: =D20 | F20: =E20 | G20: =F20 | H20: =G20 | I20: =H20
A21: TOTAL EQUITY & LIABILITIES | B21: =B16+B17+B18+B19+B20 | C21: =C16+C17+C18+C19+C20 | D21: =D16+D17+D18+D19+D20 | E21: =E16+E17+E18+E19+E20 | F21: =F16+F17+F18+F19+F20 | G21: =G16+G17+G18+G19+G20 | H21: =H16+H17+H18+H19+H20 | I21: =I16+I17+I18+I19+I20
A23: Balance check (assets − L&E) | B23: =B12-B21 | C23: =C12-C21 | D23: =D12-D21 | E23: =E12-E21 | F23: =F12-F21 | G23: =G12-G21 | H23: =H12-H21 | I23: =I12-I21
A24: Net debt — IR basis (borrowings − cash, group def.) | B24: =B17-B10 | C24: =C17-C10 | D24: =D17-D10 | E24: =E17-E10 | F24: =F17-F10 | G24: =G17-G10 | H24: =H17-H10 | I24: =I17-I10
A26: Historic mapping: the FY2025 line detail is grouped from that year's own audited statements (property and equipment, right-of-use assets, intangibles and investment property into one line; cash and short-term murabahas into another). FY23/FY24 detail lines are groupings that reconcile to the disclosed totals (blue totals are as disclosed); "Other" lines are the balancing items against those totals, shown as formulas so a reader can see them close. FY26E borrowings step up SAR +7,284mn = the Jan-2026 $2bn sukuk (net of FY26 amortisation) — thereafter gross debt held flat. Two cash framings exist (FS 21,442 incl. stc bank vs IR 15,412 core): the model rolls the FS-basis cash from FY25’s 15,108 (cash + murabaha) and states the IR basis in the net-debt memo.

Sheet Cash Flow
A1: Cash flow (SAR mn, forecast)
A2: Derived from the Income Statement and Balance Sheet; closing cash ties to the Balance Sheet, so the check row is zero.
E4: FY26E | F4: FY27E | G4: FY28E | H4: FY29E | I4: FY30E
A6: Profit for the period (incl. NCI) | E6: ='Income Statement'!E16 | F6: ='Income Statement'!F16 | G6: ='Income Statement'!G16 | H6: ='Income Statement'!H16 | I6: ='Income Statement'!I16
A7: + D&A | E7: =-'Income Statement'!E11 | F7: =-'Income Statement'!F11 | G7: =-'Income Statement'!G11 | H7: =-'Income Statement'!H11 | I7: =-'Income Statement'!I11
A8: − Increase in trade receivables (ΔWC) | E8: =-(('Balance Sheet'!E9)-('Balance Sheet'!D9)) | F8: =-(('Balance Sheet'!F9)-('Balance Sheet'!E9)) | G8: =-(('Balance Sheet'!G9)-('Balance Sheet'!F9)) | H8: =-(('Balance Sheet'!H9)-('Balance Sheet'!G9)) | I8: =-(('Balance Sheet'!I9)-('Balance Sheet'!H9))
A9: Operating cash flow | E9: =SUM(E6:E8) | F9: =SUM(F6:F8) | G9: =SUM(G6:G8) | H9: =SUM(H6:H8) | I9: =SUM(I6:I8)
A10: − Capex | E10: =-Segments!E20*Assumptions!$C$62 | F10: =-Segments!F20*Assumptions!$D$62 | G10: =-Segments!G20*Assumptions!$E$62 | H10: =-Segments!H20*Assumptions!$F$62 | I10: =-Segments!I20*Assumptions!$G$62
A11: Free cash flow | E11: =E9+E10 | F11: =F9+F10 | G11: =G9+G10 | H11: =H9+H10 | I11: =I9+I10
A12: + Increase in borrowings (net) | E12: =7284 | F12: =0 | G12: =0 | H12: =0 | I12: =0
A13: − Dividends paid (attributable) | E13: =-Assumptions!$C$68*Assumptions!$B$6 | F13: =-Assumptions!$D$68*Assumptions!$B$6 | G13: =-Assumptions!$E$68*Assumptions!$B$6 | H13: =-Assumptions!$F$68*Assumptions!$B$6 | I13: =-Assumptions!$G$68*Assumptions!$B$6
A14: Net change in cash | E14: =E11+E12+E13 | F14: =F11+F12+F13 | G14: =G11+G12+G13 | H14: =H11+H12+H13 | I14: =I11+I12+I13
A15: Opening cash | E15: ='Balance Sheet'!D10 | F15: =E16 | G15: =F16 | H15: =G16 | I15: =H16
A16: Closing cash | E16: =E15+E14 | F16: =F15+F14 | G16: =G15+G14 | H16: =H15+H14 | I16: =I15+I14
A18: NCI profit is retained (no NCI dividend modelled — solutions’ minority dividend leakage is inside "net finance & other"). Historical group cash flows: OCF 22,418 / 19,885 / 18,283 and FCF 12,628 / 7,959 / 6,488 (FY23/24/25, stc IR releases; restated). The FY26E borrowings line is the Jan-2026 sukuk already completed.

Sheet Summary Financials
A1: Summary financials (SAR mn)
A2: Every cell links to the statement sheets.
B4: FY23 | C4: FY24 | D4: FY25 | E4: FY26E | F4: FY27E | G4: FY28E | H4: FY29E | I4: FY30E
A6: Revenue | B6: ='Income Statement'!B6 | C6: ='Income Statement'!C6 | D6: ='Income Statement'!D6 | E6: ='Income Statement'!E6 | F6: ='Income Statement'!F6 | G6: ='Income Statement'!G6 | H6: ='Income Statement'!H6 | I6: ='Income Statement'!I6
A7: EBITDA | B7: ='Income Statement'!B9 | C7: ='Income Statement'!C9 | D7: ='Income Statement'!D9 | E7: ='Income Statement'!E9 | F7: ='Income Statement'!F9 | G7: ='Income Statement'!G9 | H7: ='Income Statement'!H9 | I7: ='Income Statement'!I9
A8: EBIT | B8: ='Income Statement'!B12 | C8: ='Income Statement'!C12 | D8: ='Income Statement'!D12 | E8: ='Income Statement'!E12 | F8: ='Income Statement'!F12 | G8: ='Income Statement'!G12 | H8: ='Income Statement'!H12 | I8: ='Income Statement'!I12
A9: Net profit (attributable) | B9: ='Income Statement'!B19 | C9: ='Income Statement'!C19 | D9: ='Income Statement'!D19 | E9: ='Income Statement'!E19 | F9: ='Income Statement'!F19 | G9: ='Income Statement'!G19 | H9: ='Income Statement'!H19 | I9: ='Income Statement'!I19
A10: Total assets | B10: ='Balance Sheet'!B12 | C10: ='Balance Sheet'!C12 | D10: ='Balance Sheet'!D12 | E10: ='Balance Sheet'!E12 | F10: ='Balance Sheet'!F12 | G10: ='Balance Sheet'!G12 | H10: ='Balance Sheet'!H12 | I10: ='Balance Sheet'!I12
A11: Total equity | B11: ='Balance Sheet'!B16 | C11: ='Balance Sheet'!C16 | D11: ='Balance Sheet'!D16 | E11: ='Balance Sheet'!E16 | F11: ='Balance Sheet'!F16 | G11: ='Balance Sheet'!G16 | H11: ='Balance Sheet'!H16 | I11: ='Balance Sheet'!I16
A12: Net debt (IR basis) | B12: ='Balance Sheet'!B24 | C12: ='Balance Sheet'!C24 | D12: ='Balance Sheet'!D24 | E12: ='Balance Sheet'!E24 | F12: ='Balance Sheet'!F24 | G12: ='Balance Sheet'!G24 | H12: ='Balance Sheet'!H24 | I12: ='Balance Sheet'!I24
A13: Free cash flow (forecast) | E13: ='Cash Flow'!E11 | F13: ='Cash Flow'!F11 | G13: ='Cash Flow'!G11 | H13: ='Cash Flow'!H11 | I13: ='Cash Flow'!I11
A14: Free cash flow (historical, disclosed) | B14: 12628 | C14: 7959 | D14: 6488

Sheet Monte Carlo
A1: Monte Carlo — the price cone as the engine struck it
A2: 50,000 paths, seed 42, computed by the engine itself rather than simulated in this sheet. The distribution carries a live momentum lean, upward, worth 0.13% at one month and 0.24% at three.
A5: The probability read (3 months)
A6: P(price above spot) | B6: 0.56274
A7: P(+10%) vs P(−10%) — odds | B7: 16% vs 8% · 2.0:1
A8: Median level (SAR) and % move | B8: 45.30 (+1.3%)
A9: 50% band (25th–75th) | B9: 42.9 – 47.9 (-4.2% / +7.0%)
A10: Touch(+10%) / touch(−10%) | B10: 27% / 16%
A12: Percentile map (SAR/share)
A13: Horizon | B13: p5 | C13: p25 | D13: p50 | E13: p75 | F13: p95
A14: 1 month | B14: 41.7 | C14: 43.6 | D14: 44.9 | E14: 46.3 | F14: 48.5
A15: 3 months | B15: 39.3 | C15: 42.9 | D15: 45.3 | E15: 47.9 | F15: 52.2
A17: Engine inputs (from Assumptions)
A18: Forward volatility over three months (annualised) | B18: =Assumptions!$B$39
A19: Momentum lean applied over three months | B19: =Assumptions!$B$41
A21: Level-touch ladder (probability of touching by horizon)
A22: Level (SAR) | B22: 1 month | C22: 3 months
A23: 50 | B23: 0.01846 | C23: 0.20038
A24: 48 | B24: 0.11476 | C24: 0.40734
A25: 46 | B25: 0.48074 | C25: 0.72196
A26: 44 | B26: 0.59512 | C26: 0.75416
A27: 42 | B27: 0.11542 | C27: 0.35908
A28: 40 | B28: 0.01328 | C28: 0.13696
A29: 38 | B29: 0.00128 | C29: 0.04186
A30: 36 | B30: 0.00018 | C30: 0.01182

Sheet Sensitivity
A1: DCF sensitivity — WACC × terminal growth (live formulas)
A2: Fair value per share (SAR). Recomputes the full FCFF stream off the DCF sheet; the centre cell is the base case.
A5: WACC \ terminal g | B5: 0.015 | C5: 0.02 | D5: 0.025 | E5: 0.03 | F5: 0.035
A6: 0.075310546 | B6: =(SUMPRODUCT(DCF!$B$14:$F$14,1/(1+$A6)^{1,2,3,4,5})+DCF!$F$14*(1+B$5)/($A6-B$5)/(1+$A6)^5+Assumptions!$B$22+Assumptions!$B$23-Assumptions!$B$25-Assumptions!$B$26)/Assumptions!$B$6 | C6: =(SUMPRODUCT(DCF!$B$14:$F$14,1/(1+$A6)^{1,2,3,4,5})+DCF!$F$14*(1+C$5)/($A6-C$5)/(1+$A6)^5+Assumptions!$B$22+Assumptions!$B$23-Assumptions!$B$25-Assumptions!$B$26)/Assumptions!$B$6 | D6: =(SUMPRODUCT(DCF!$B$14:$F$14,1/(1+$A6)^{1,2,3,4,5})+DCF!$F$14*(1+D$5)/($A6-D$5)/(1+$A6)^5+Assumptions!$B$22+Assumptions!$B$23-Assumptions!$B$25-Assumptions!$B$26)/Assumptions!$B$6 | E6: =(SUMPRODUCT(DCF!$B$14:$F$14,1/(1+$A6)^{1,2,3,4,5})+DCF!$F$14*(1+E$5)/($A6-E$5)/(1+$A6)^5+Assumptions!$B$22+Assumptions!$B$23-Assumptions!$B$25-Assumptions!$B$26)/Assumptions!$B$6 | F6: =(SUMPRODUCT(DCF!$B$14:$F$14,1/(1+$A6)^{1,2,3,4,5})+DCF!$F$14*(1+F$5)/($A6-F$5)/(1+$A6)^5+Assumptions!$B$22+Assumptions!$B$23-Assumptions!$B$25-Assumptions!$B$26)/Assumptions!$B$6
A7: 0.080310546 | B7: =(SUMPRODUCT(DCF!$B$14:$F$14,1/(1+$A7)^{1,2,3,4,5})+DCF!$F$14*(1+B$5)/($A7-B$5)/(1+$A7)^5+Assumptions!$B$22+Assumptions!$B$23-Assumptions!$B$25-Assumptions!$B$26)/Assumptions!$B$6 | C7: =(SUMPRODUCT(DCF!$B$14:$F$14,1/(1+$A7)^{1,2,3,4,5})+DCF!$F$14*(1+C$5)/($A7-C$5)/(1+$A7)^5+Assumptions!$B$22+Assumptions!$B$23-Assumptions!$B$25-Assumptions!$B$26)/Assumptions!$B$6 | D7: =(SUMPRODUCT(DCF!$B$14:$F$14,1/(1+$A7)^{1,2,3,4,5})+DCF!$F$14*(1+D$5)/($A7-D$5)/(1+$A7)^5+Assumptions!$B$22+Assumptions!$B$23-Assumptions!$B$25-Assumptions!$B$26)/Assumptions!$B$6 | E7: =(SUMPRODUCT(DCF!$B$14:$F$14,1/(1+$A7)^{1,2,3,4,5})+DCF!$F$14*(1+E$5)/($A7-E$5)/(1+$A7)^5+Assumptions!$B$22+Assumptions!$B$23-Assumptions!$B$25-Assumptions!$B$26)/Assumptions!$B$6 | F7: =(SUMPRODUCT(DCF!$B$14:$F$14,1/(1+$A7)^{1,2,3,4,5})+DCF!$F$14*(1+F$5)/($A7-F$5)/(1+$A7)^5+Assumptions!$B$22+Assumptions!$B$23-Assumptions!$B$25-Assumptions!$B$26)/Assumptions!$B$6
A8: 0.085310546 | B8: =(SUMPRODUCT(DCF!$B$14:$F$14,1/(1+$A8)^{1,2,3,4,5})+DCF!$F$14*(1+B$5)/($A8-B$5)/(1+$A8)^5+Assumptions!$B$22+Assumptions!$B$23-Assumptions!$B$25-Assumptions!$B$26)/Assumptions!$B$6 | C8: =(SUMPRODUCT(DCF!$B$14:$F$14,1/(1+$A8)^{1,2,3,4,5})+DCF!$F$14*(1+C$5)/($A8-C$5)/(1+$A8)^5+Assumptions!$B$22+Assumptions!$B$23-Assumptions!$B$25-Assumptions!$B$26)/Assumptions!$B$6 | D8: =(SUMPRODUCT(DCF!$B$14:$F$14,1/(1+$A8)^{1,2,3,4,5})+DCF!$F$14*(1+D$5)/($A8-D$5)/(1+$A8)^5+Assumptions!$B$22+Assumptions!$B$23-Assumptions!$B$25-Assumptions!$B$26)/Assumptions!$B$6 | E8: =(SUMPRODUCT(DCF!$B$14:$F$14,1/(1+$A8)^{1,2,3,4,5})+DCF!$F$14*(1+E$5)/($A8-E$5)/(1+$A8)^5+Assumptions!$B$22+Assumptions!$B$23-Assumptions!$B$25-Assumptions!$B$26)/Assumptions!$B$6 | F8: =(SUMPRODUCT(DCF!$B$14:$F$14,1/(1+$A8)^{1,2,3,4,5})+DCF!$F$14*(1+F$5)/($A8-F$5)/(1+$A8)^5+Assumptions!$B$22+Assumptions!$B$23-Assumptions!$B$25-Assumptions!$B$26)/Assumptions!$B$6
A9: 0.090310546 | B9: =(SUMPRODUCT(DCF!$B$14:$F$14,1/(1+$A9)^{1,2,3,4,5})+DCF!$F$14*(1+B$5)/($A9-B$5)/(1+$A9)^5+Assumptions!$B$22+Assumptions!$B$23-Assumptions!$B$25-Assumptions!$B$26)/Assumptions!$B$6 | C9: =(SUMPRODUCT(DCF!$B$14:$F$14,1/(1+$A9)^{1,2,3,4,5})+DCF!$F$14*(1+C$5)/($A9-C$5)/(1+$A9)^5+Assumptions!$B$22+Assumptions!$B$23-Assumptions!$B$25-Assumptions!$B$26)/Assumptions!$B$6 | D9: =(SUMPRODUCT(DCF!$B$14:$F$14,1/(1+$A9)^{1,2,3,4,5})+DCF!$F$14*(1+D$5)/($A9-D$5)/(1+$A9)^5+Assumptions!$B$22+Assumptions!$B$23-Assumptions!$B$25-Assumptions!$B$26)/Assumptions!$B$6 | E9: =(SUMPRODUCT(DCF!$B$14:$F$14,1/(1+$A9)^{1,2,3,4,5})+DCF!$F$14*(1+E$5)/($A9-E$5)/(1+$A9)^5+Assumptions!$B$22+Assumptions!$B$23-Assumptions!$B$25-Assumptions!$B$26)/Assumptions!$B$6 | F9: =(SUMPRODUCT(DCF!$B$14:$F$14,1/(1+$A9)^{1,2,3,4,5})+DCF!$F$14*(1+F$5)/($A9-F$5)/(1+$A9)^5+Assumptions!$B$22+Assumptions!$B$23-Assumptions!$B$25-Assumptions!$B$26)/Assumptions!$B$6
A10: 0.095310546 | B10: =(SUMPRODUCT(DCF!$B$14:$F$14,1/(1+$A10)^{1,2,3,4,5})+DCF!$F$14*(1+B$5)/($A10-B$5)/(1+$A10)^5+Assumptions!$B$22+Assumptions!$B$23-Assumptions!$B$25-Assumptions!$B$26)/Assumptions!$B$6 | C10: =(SUMPRODUCT(DCF!$B$14:$F$14,1/(1+$A10)^{1,2,3,4,5})+DCF!$F$14*(1+C$5)/($A10-C$5)/(1+$A10)^5+Assumptions!$B$22+Assumptions!$B$23-Assumptions!$B$25-Assumptions!$B$26)/Assumptions!$B$6 | D10: =(SUMPRODUCT(DCF!$B$14:$F$14,1/(1+$A10)^{1,2,3,4,5})+DCF!$F$14*(1+D$5)/($A10-D$5)/(1+$A10)^5+Assumptions!$B$22+Assumptions!$B$23-Assumptions!$B$25-Assumptions!$B$26)/Assumptions!$B$6 | E10: =(SUMPRODUCT(DCF!$B$14:$F$14,1/(1+$A10)^{1,2,3,4,5})+DCF!$F$14*(1+E$5)/($A10-E$5)/(1+$A10)^5+Assumptions!$B$22+Assumptions!$B$23-Assumptions!$B$25-Assumptions!$B$26)/Assumptions!$B$6 | F10: =(SUMPRODUCT(DCF!$B$14:$F$14,1/(1+$A10)^{1,2,3,4,5})+DCF!$F$14*(1+F$5)/($A10-F$5)/(1+$A10)^5+Assumptions!$B$22+Assumptions!$B$23-Assumptions!$B$25-Assumptions!$B$26)/Assumptions!$B$6
A12: The cost-of-capital axis centres on the sourced bottom-up build — a normalised risk-free rate of 4.54% plus a beta of 0.7093 times the 5.72% premium this study names as central, blended with an after-tax cost of debt of 3.89% at a 9.7% debt weight. On the alternative premium basis, published beside the central one rather than chosen silently, the same build gives 8.31%. At a beta of 1.00 the rate is 9.64%, which sits off this grid deliberately and is priced in the beta grid below.
A14: Beta sensitivity — the regression gives 0.7093 and the grid prices the answer either side of it
A15: beta | B15: Cost of equity (central premium basis) | C15: Cost of capital | D15: DCF value/sh
A16: 0.3 | B16: =Assumptions!$B$10+A16*Assumptions!$B$12 | C16: =(1-Assumptions!$B$18)*B16+Assumptions!$B$18*Assumptions!$B$17 | D16: =(SUMPRODUCT(DCF!$B$14:$F$14,1/(1+C16)^{1,2,3,4,5})+DCF!$F$14*(1+Assumptions!$B$20)/(C16-Assumptions!$B$20)/(1+C16)^5+Assumptions!$B$22+Assumptions!$B$23-Assumptions!$B$25-Assumptions!$B$26)/Assumptions!$B$6
A17: 0.5 | B17: =Assumptions!$B$10+A17*Assumptions!$B$12 | C17: =(1-Assumptions!$B$18)*B17+Assumptions!$B$18*Assumptions!$B$17 | D17: =(SUMPRODUCT(DCF!$B$14:$F$14,1/(1+C17)^{1,2,3,4,5})+DCF!$F$14*(1+Assumptions!$B$20)/(C17-Assumptions!$B$20)/(1+C17)^5+Assumptions!$B$22+Assumptions!$B$23-Assumptions!$B$25-Assumptions!$B$26)/Assumptions!$B$6
A18: 0.70925813 | B18: =Assumptions!$B$10+A18*Assumptions!$B$12 | C18: =(1-Assumptions!$B$18)*B18+Assumptions!$B$18*Assumptions!$B$17 | D18: =(SUMPRODUCT(DCF!$B$14:$F$14,1/(1+C18)^{1,2,3,4,5})+DCF!$F$14*(1+Assumptions!$B$20)/(C18-Assumptions!$B$20)/(1+C18)^5+Assumptions!$B$22+Assumptions!$B$23-Assumptions!$B$25-Assumptions!$B$26)/Assumptions!$B$6 | E18: <- the adopted regression beta
A19: 0.85 | B19: =Assumptions!$B$10+A19*Assumptions!$B$12 | C19: =(1-Assumptions!$B$18)*B19+Assumptions!$B$18*Assumptions!$B$17 | D19: =(SUMPRODUCT(DCF!$B$14:$F$14,1/(1+C19)^{1,2,3,4,5})+DCF!$F$14*(1+Assumptions!$B$20)/(C19-Assumptions!$B$20)/(1+C19)^5+Assumptions!$B$22+Assumptions!$B$23-Assumptions!$B$25-Assumptions!$B$26)/Assumptions!$B$6
A20: 1 | B20: =Assumptions!$B$10+A20*Assumptions!$B$12 | C20: =(1-Assumptions!$B$18)*B20+Assumptions!$B$18*Assumptions!$B$17 | D20: =(SUMPRODUCT(DCF!$B$14:$F$14,1/(1+C20)^{1,2,3,4,5})+DCF!$F$14*(1+Assumptions!$B$20)/(C20-Assumptions!$B$20)/(1+C20)^5+Assumptions!$B$22+Assumptions!$B$23-Assumptions!$B$25-Assumptions!$B$26)/Assumptions!$B$6 | E20: <- the fallback this desk would have used had the regression not been usable
A21: 1.2 | B21: =Assumptions!$B$10+A21*Assumptions!$B$12 | C21: =(1-Assumptions!$B$18)*B21+Assumptions!$B$18*Assumptions!$B$17 | D21: =(SUMPRODUCT(DCF!$B$14:$F$14,1/(1+C21)^{1,2,3,4,5})+DCF!$F$14*(1+Assumptions!$B$20)/(C21-Assumptions!$B$20)/(1+C21)^5+Assumptions!$B$22+Assumptions!$B$23-Assumptions!$B$25-Assumptions!$B$26)/Assumptions!$B$6

Sheet Per-Share & Ratios
A1: Per-share & ratios
A2: Every line links to the statements and the assumptions behind them.
B4: FY23 | C4: FY24 | D4: FY25 | E4: FY26E | F4: FY27E | G4: FY28E | H4: FY29E | I4: FY30E
A6: EPS (SAR) | B6: ='Income Statement'!B19/Assumptions!$B$6 | C6: ='Income Statement'!C19/Assumptions!$B$6 | D6: ='Income Statement'!D19/Assumptions!$B$6 | E6: ='Income Statement'!E19/Assumptions!$B$6 | F6: ='Income Statement'!F19/Assumptions!$B$6 | G6: ='Income Statement'!G19/Assumptions!$B$6 | H6: ='Income Statement'!H19/Assumptions!$B$6 | I6: ='Income Statement'!I19/Assumptions!$B$6
A7: DPS declared (SAR) | B7: 1.6 | C7: 3.75 | D7: 2.2 | E7: =Assumptions!C28 | F7: =Assumptions!D28 | G7: =Assumptions!E28 | H7: =Assumptions!F28 | I7: =Assumptions!G28
A8: Book value / share (SAR) | B8: ='Balance Sheet'!B14/Assumptions!$B$6 | C8: ='Balance Sheet'!C14/Assumptions!$B$6 | D8: ='Balance Sheet'!D14/Assumptions!$B$6 | E8: ='Balance Sheet'!E14/Assumptions!$B$6 | F8: ='Balance Sheet'!F14/Assumptions!$B$6 | G8: ='Balance Sheet'!G14/Assumptions!$B$6 | H8: ='Balance Sheet'!H14/Assumptions!$B$6 | I8: ='Balance Sheet'!I14/Assumptions!$B$6
A9: P/E at spot (×)f | B9: =Assumptions!$B$5/('Income Statement'!B19/Assumptions!$B$6) | C9: =Assumptions!$B$5/('Income Statement'!C19/Assumptions!$B$6) | D9: =Assumptions!$B$5/('Income Statement'!D19/Assumptions!$B$6) | E9: =Assumptions!$B$5/('Income Statement'!E19/Assumptions!$B$6) | F9: =Assumptions!$B$5/('Income Statement'!F19/Assumptions!$B$6) | G9: =Assumptions!$B$5/('Income Statement'!G19/Assumptions!$B$6) | H9: =Assumptions!$B$5/('Income Statement'!H19/Assumptions!$B$6) | I9: =Assumptions!$B$5/('Income Statement'!I19/Assumptions!$B$6)
A10: P/B at spot (×)f | B10: =Assumptions!$B$5/('Balance Sheet'!B14/Assumptions!$B$6) | C10: =Assumptions!$B$5/('Balance Sheet'!C14/Assumptions!$B$6) | D10: =Assumptions!$B$5/('Balance Sheet'!D14/Assumptions!$B$6) | E10: =Assumptions!$B$5/('Balance Sheet'!E14/Assumptions!$B$6) | F10: =Assumptions!$B$5/('Balance Sheet'!F14/Assumptions!$B$6) | G10: =Assumptions!$B$5/('Balance Sheet'!G14/Assumptions!$B$6) | H10: =Assumptions!$B$5/('Balance Sheet'!H14/Assumptions!$B$6) | I10: =Assumptions!$B$5/('Balance Sheet'!I14/Assumptions!$B$6)
A11: Dividend yield at spot (declared) | B11: =B7/Assumptions!$B$5 | C11: =C7/Assumptions!$B$5 | D11: =D7/Assumptions!$B$5 | E11: =E7/Assumptions!$B$5 | F11: =F7/Assumptions!$B$5 | G11: =G7/Assumptions!$B$5 | H11: =H7/Assumptions!$B$5 | I11: =I7/Assumptions!$B$5
A12: Payout (of attributable NP)f | B12: =B7*Assumptions!$B$6/'Income Statement'!B19 | C12: =C7*Assumptions!$B$6/'Income Statement'!C19 | D12: =D7*Assumptions!$B$6/'Income Statement'!D19 | E12: =E7*Assumptions!$B$6/'Income Statement'!E19 | F12: =F7*Assumptions!$B$6/'Income Statement'!F19 | G12: =G7*Assumptions!$B$6/'Income Statement'!G19 | H12: =H7*Assumptions!$B$6/'Income Statement'!H19 | I12: =I7*Assumptions!$B$6/'Income Statement'!I19
A13: EBITDA margin | B13: ='Income Statement'!B9/'Income Statement'!B6 | C13: ='Income Statement'!C9/'Income Statement'!C6 | D13: ='Income Statement'!D9/'Income Statement'!D6 | E13: ='Income Statement'!E9/'Income Statement'!E6 | F13: ='Income Statement'!F9/'Income Statement'!F6 | G13: ='Income Statement'!G9/'Income Statement'!G6 | H13: ='Income Statement'!H9/'Income Statement'!H6 | I13: ='Income Statement'!I9/'Income Statement'!I6
A14: Net margin | B14: ='Income Statement'!B19/'Income Statement'!B6 | C14: ='Income Statement'!C19/'Income Statement'!C6 | D14: ='Income Statement'!D19/'Income Statement'!D6 | E14: ='Income Statement'!E19/'Income Statement'!E6 | F14: ='Income Statement'!F19/'Income Statement'!F6 | G14: ='Income Statement'!G19/'Income Statement'!G6 | H14: ='Income Statement'!H19/'Income Statement'!H6 | I14: ='Income Statement'!I19/'Income Statement'!I6
A15: ROAE (attributable) | B15: ='Income Statement'!B19/'Balance Sheet'!B14 | C15: ='Income Statement'!C19/'Balance Sheet'!C14 | D15: ='Income Statement'!D19/'Balance Sheet'!D14 | E15: ='Income Statement'!E19/'Balance Sheet'!E14 | F15: ='Income Statement'!F19/'Balance Sheet'!F14 | G15: ='Income Statement'!G19/'Balance Sheet'!G14 | H15: ='Income Statement'!H19/'Balance Sheet'!H14 | I15: ='Income Statement'!I19/'Balance Sheet'!I14
A16: Net debt (IR) / EBITDA (×) | B16: ='Balance Sheet'!B24/'Income Statement'!B9 | C16: ='Balance Sheet'!C24/'Income Statement'!C9 | D16: ='Balance Sheet'!D24/'Income Statement'!D9 | E16: ='Balance Sheet'!E24/'Income Statement'!E9 | F16: ='Balance Sheet'!F24/'Income Statement'!F9 | G16: ='Balance Sheet'!G24/'Income Statement'!G9 | H16: ='Balance Sheet'!H24/'Income Statement'!H9 | I16: ='Balance Sheet'!I24/'Income Statement'!I9
A17: Capex intensity (% of revenue) | B17: 0.136 | C17: 0.157 | D17: 0.152 | E17: =-'Cash Flow'!E10/'Income Statement'!E6 | F17: =-'Cash Flow'!F10/'Income Statement'!F6 | G17: =-'Cash Flow'!G10/'Income Statement'!G6 | H17: =-'Cash Flow'!H10/'Income Statement'!H6 | I17: =-'Cash Flow'!I10/'Income Statement'!I6
A18: FCF yield at spot (forecast) | E18: ='Cash Flow'!E11/(Assumptions!$B$5*Assumptions!$B$6) | F18: ='Cash Flow'!F11/(Assumptions!$B$5*Assumptions!$B$6) | G18: ='Cash Flow'!G11/(Assumptions!$B$5*Assumptions!$B$6) | H18: ='Cash Flow'!H11/(Assumptions!$B$5*Assumptions!$B$6) | I18: ='Cash Flow'!I11/(Assumptions!$B$5*Assumptions!$B$6)
A19: Revenue YoY | C19: ='Income Statement'!C6/'Income Statement'!B6-1 | D19: ='Income Statement'!D6/'Income Statement'!C6-1 | E19: ='Income Statement'!E6/'Income Statement'!D6-1 | F19: ='Income Statement'!F6/'Income Statement'!E6-1 | G19: ='Income Statement'!G6/'Income Statement'!F6-1 | H19: ='Income Statement'!H6/'Income Statement'!G6-1 | I19: ='Income Statement'!I6/'Income Statement'!H6-1
A20: EPS YoY | C20: =('Income Statement'!C19/'Income Statement'!B19)-1 | D20: =('Income Statement'!D19/'Income Statement'!C19)-1 | E20: =('Income Statement'!E19/'Income Statement'!D19)-1 | F20: =('Income Statement'!F19/'Income Statement'!E19)-1 | G20: =('Income Statement'!G19/'Income Statement'!F19)-1 | H20: =('Income Statement'!H19/'Income Statement'!G19)-1 | I20: =('Income Statement'!I19/'Income Statement'!H19)-1
A22: FY24 EPS/DPS carry the TAWAL disposal gain and the SAR 2.00 special dividend — the payout row prints >100% on the cash-paid framing (141% LTM per stc). Declared-regular vs cash-paid framings both stated (house rule).

Sheet Peer & Sector
A1: Peer set & sector
A2: GCC/regional telecoms; multiples approximate, as-of dates flagged (context, not model inputs).
A5: Name | B5: Mkt | C5: P/E (t) | D5: EV/EBITDA | E5: Div yield | F5: Note
A6: stc (7010) | B6: KSA | C6: 14.7× | D6: 9.5× | E6: 5.0% (9.6% incl. special) | F6: Incumbent; ~57% mobile share; net debt ~0
A7: Mobily (7020) | B7: KSA | C7: 13.5× | D7: ~7.4× | E7: 4.5% | F7: No.2; e& anchor shareholder; fastest sub growth
A8: Zain KSA (7030) | B8: KSA | C8: 12.8× | D8: n/a | E8: 4.9% | F8: No.3; tower-light; higher leverage
A9: e& (EAND) | B9: UAE | C9: 13.2× | D9: n/a | E9: 5.1% | F9: UAE incumbent + international portfolio
A10: Ooredoo (ORDS) | B10: Qatar | C10: 10.7× | D10: n/a | E10: 5.7% | F10: Multi-market; data-centre pivot
A11: du (DU) | B11: UAE | C11: 17.6× | D11: n/a | E11: 5.5% | F11: No.2 UAE; hyperscale DC momentum
A12: Omantel / Beyon / ETEL | B12: Oman/Bah/Egy | C12: 11.5× / 11.1× / 8.8× | D12: n/a | E12: 3.9% / 7.1% / 1.5% | F12: Regional context
A14: Sector: KSA mobile ≈ 57/27/16 stc/Mobily/Zain; Nov-2024 CST spectrum auction (stc: 600MHz + 3.8GHz); 10,800+ stc 5G sites, 63% populated coverage; FTTH 3.75mn; FWA one of the highest-adoption markets globally; center3–HUMAIN 1GW AI-DC ambition; SilkLink Syria fibre corridor (SAR 3bn, Feb-2026). Peer P/E band 10.7–17.6×; stc premium tracks its share, balance sheet and yield.
