Workbook

Sheet READ FIRST
A1: Testahil — Borouge plc (ADX: BOROUGE)
A4: Companion model · Independent Valuation Study · Educational analysis · Not investment advice
A6: What this workbook is. A transparent companion to the Borouge valuation study. Every blue cell is an
A7: input; every black cell is a formula; green cells link across sheets. Amounts are USD million unless a
A8: row says otherwise — Borouge reports in US dollars and its shares trade in dirhams, so per-share figures
A9: are converted at the pegged rate held on Assumptions.
A11: IT IS FORMULA-DRIVEN, AND THAT CLAIM IS TESTED. Every figure derivable from a driver is a live formula,
A12: so you can change a blue cell on Assumptions and watch the model reprice. The cost of equity is built
A13: from the risk-free rate NET of the sovereign default spread, beta and the premium rather than pasted;
A14: the cost of debt is taxed in the sheet; the weights come from net debt and market capitalisation; the
A15: terminal rate is built from its own components; the discount factors compound; the DCF waterfall chains
A16: from revenue through EBITDA, EBIT, NOPAT and free cash flow to the firm to present value; the terminal
... A59: SHEET GUIDE
A60: Summary | C60: the headline: four lenses, both betas, and the terminal-value share
A61: Fundamental Valuation | C61: the cost of capital built line by line, and the lenses assembled
A62: Assumptions | C62: every driver. Blue cells here are what you change
A63: SOTP Bridge | C63: enterprise value to equity, with the Borouge 4 fee stream separate
A64: Segments | C64: the unit build: tonnes, prices and cost per tonne, by product
A65: Relative & Normalized | C65: the through-cycle triangulation and normalised earnings power
A66: DCF | C66: the waterfall and the terminal block, both constructions
A67: Income Statement | C67: three audited years and five forecast years
A68: Balance Sheet | C68: three audited years and five forecast years, rolled forward
A69: Cash Flow | C69: linked to the waterfall, not restated
A70: Summary Financials | C70: the compact view
A71: Monte Carlo | C71: the probability map for the traded price (a re-run, not a formula)
... A74: Peer & Sector | C74: the eleven listed peers and why the naive median is rejected

Sheet Summary
A1: Summary valuation
A2: Value per share in AED. Every figure on this sheet is a live link or formula.
A4: THE FOUR LENSES, ACROSS THE BETA THE STUDY CONTESTS
A5: Lens | B5: Sector bottom-up beta | C5: Own-stock beta | D5: Terminal value % of EV
A6: Discounted cash flow — normalisation | B6: ='Fundamental Valuation'!$B$34 | C6: ='Fundamental Valuation'!$C$34 | D6: ='DCF'!$E$68
A7: Discounted cash flow — prolonged disruption | B7: ='Fundamental Valuation'!$B$35 | C7: ='Fundamental Valuation'!$C$35 | D7: ='DCF'!$E$70
A8: Book value and sustainable return | B8: ='Fundamental Valuation'!$B$39 | C8: ='Fundamental Valuation'!$C$39
A9: Normalised earnings power | B9: ='Fundamental Valuation'!$B$40 | C9: ='Fundamental Valuation'!$C$40
A10: Relative multiples (independent of beta) | B10: ='Fundamental Valuation'!$B$41 | C10: ='Fundamental Valuation'!$C$41
A12: THE ANSWER AGAINST THE MARKET
A13: Navigation normalises during 2026 | B13: ='Fundamental Valuation'!$B$44
A14: Disruption persists into 2027 | B14: ='Fundamental Valuation'!$B$45
A15: Closing price, 3 September 2026 | B15: =Assumptions!$B$5
A16: Navigation normalises, against the close | B16: =B13/B15-1
A17: Disruption persists, against the close | B17: =B14/B15-1
A18: Cross-checks span (AED) | B18: ='Fundamental Valuation'!$B$52 | C18: ='Fundamental Valuation'!$B$53
A20: THE COST OF CAPITAL BEHIND IT
A21: Weighted average cost of capital — own-stock beta | B21: ='Fundamental Valuation'!$B$29
A22: Weighted average cost of capital — sector bottom-up beta | B22: ='Fundamental Valuation'!$C$29
A23: Normalised risk-free rate | B23: ='Fundamental Valuation'!$B$7
A24: Equity risk premium (rating basis) | B24: ='Fundamental Valuation'!$B$12
A25: Terminal growth rate | B25: =Assumptions!$B$51
A27: THE PROBABILITY MAP FOR THE TRADED PRICE
A28: Horizon | B28: 5th | C28: Median | D28: 95th | E28: Above the close
A29: One month | B29: ='Monte Carlo'!C14 | C29: ='Monte Carlo'!E14 | D29: ='Monte Carlo'!G14 | E29: ='Monte Carlo'!H14
A30: Three months | B30: ='Monte Carlo'!C15 | C30: ='Monte Carlo'!E15 | D30: ='Monte Carlo'!G15 | E30: ='Monte Carlo'!H15
A32: The two constructions and the two betas are shown side by side and are never averaged. The spread between them is the honest width of the answer.

Sheet Fundamental Valuation
A1: Fundamental valuation — the cost of capital, built line by line
A2: Nothing on this sheet is pasted. Every rate is assembled from the inputs on Assumptions.
A4: RISK-FREE RATE, NORMALISED
A5: US 10-year Treasury yield | B5: =Assumptions!$B$10
A6: Less: US adjusted default spread | B6: =-Assumptions!$B$11
A7: Normalised risk-free rate | B7: =B5+B6 | C7: Country risk is charged once, in the premium below — never twice
A9: EQUITY RISK PREMIUM (BOTH BASES PUBLISHED)
A10: Mature-market equity risk premium | B10: =Assumptions!$B$12
A11: Plus: UAE country risk premium (rating basis) | B11: =Assumptions!$B$13
A12: Equity risk premium — rating basis | B12: =B10+B11
A13: Equity risk premium — default-spread basis | B13: =B10+Assumptions!$B$14 | C13: Published alongside: no sovereign credit-default-swap quote exists for this sovereign
A15: BETA — THE STUDY'S CENTRAL CONTESTED JUDGEMENT
A16: The share's own five-year weekly regression beta | B16: =Assumptions!$B$15 | C16: R-squared 0.094 on 215 weekly observations — statistically weak
A17: Sector unlevered beta (global chemicals) | B17: =Assumptions!$B$16
A18: Re-levered at the company's debt-to-equity and tax rate | B18: =B17*(1+(1-Assumptions!$B$19)*Assumptions!$B$17)
A20: COST OF EQUITY, COST OF DEBT AND THE WEIGHTS
B21: Own-stock beta | C21: Sector bottom-up beta
A22: Cost of equity = risk-free rate + beta x premium | B22: =$B7+B16*$B12 | C22: =$B7+B18*$B12
A23: Pre-tax cost of debt (marginal) | B23: =Assumptions!$B$18 | C23: =Assumptions!$B$18
A24: After-tax cost of debt | B24: =B23*(1-Assumptions!$B$19) | C24: =C23*(1-Assumptions!$B$19)
A25: Market capitalisation (USD million) | B25: =Assumptions!$B$5/Assumptions!$B$6*Assumptions!$B$7
A26: Net debt (USD million) | B26: =Assumptions!$B$53
A27: Equity weight | B27: =B25/(B25+B26)
A28: Debt weight | B28: =1-B27
A29: Weighted average cost of capital | B29: =B22*$B27+B24*$B28 | C29: =C22*$B27+C24*$B28
A30: The two columns are the study's central contested judgement. They are carried side by side to a value per share everywhere they appear and are never averaged into one number.
A32: THE FOUR LENSES ASSEMBLED
A33: Lens | B33: Sector bottom-up beta | C33: Own-stock beta
A34: Discounted cash flow — normalisation | B34: ='DCF'!$F$69 | C34: ='DCF'!$F$68
A35: Discounted cash flow — prolonged disruption | B35: ='DCF'!$F$71 | C35: ='DCF'!$F$70
A36: Book value per share (USD) | B36: =Assumptions!$B$44/Assumptions!$B$7
A37: Sustainable return on equity (three audited years) | B37: =AVERAGE(Assumptions!$B$45,Assumptions!$B$46,Assumptions!$B$47)
A38: Justified price to book = (return - growth) / (cost of equity - growth) | B38: =(B37-Assumptions!$B$51)/(C22-Assumptions!$B$51) | C38: =(B37-Assumptions!$B$51)/(B22-Assumptions!$B$51)
A39: Book value lens — value per share (AED) | B39: =B38*B36*Assumptions!$B$6 | C39: =C38*B36*Assumptions!$B$6
A40: Normalised earnings power — value per share (AED) | B40: ='Relative & Normalized'!$B$48 | C40: ='Relative & Normalized'!$B$47
A41: Relative multiples — value per share (AED), independent of beta | B41: ='Relative & Normalized'!$B$23 | C41: ='Relative & Normalized'!$B$23
A43: THE ANSWER — the cash-flow lens, both sides of the shipping-lane judgement
A44: Navigation normalises during 2026 (AED) | B44: =C34
A45: Disruption persists into 2027 (AED) | B45: =C35
A46: The judgement is worth (AED a share) | B46: =$B$44-$B$45
...

Sheet Assumptions
A1: Assumptions — every driver in the model
A2: Blue = input. Change a blue cell and the whole workbook reprices. Amounts in USD million unless stated.
A4: MARKET AND SHARE COUNT
A5: Closing price, 7 August 2026 | B5: 2.35 | C5: AED per share
A6: Dirham per US dollar (pegged since November 1997) | B6: 3.6725 | C6: AED/USD
A7: Ordinary shares in issue | B7: 30057.692 | C7: million
A9: COST OF CAPITAL — INPUTS; THE BUILD IS ON FUNDAMENTAL VALUATION
A10: US 10-year Treasury yield | B10: 0.0465 | C10: the dollar risk-free anchor
A11: US adjusted default spread | B11: 0.0023 | C11: subtracted to normalise the risk-free rate
A12: Mature-market equity risk premium | B12: 0.0423
A13: UAE country risk premium | B13: 0.0064 | C13: country risk enters ONCE, here
A14: UAE adjusted default spread | B14: 0.0042 | C14: the alternative premium basis
A15: Beta — the share's own five-year weekly regression | B15: 0.4152894 | C15: weak: R-squared 8.8%
A16: Beta — sector bottom-up, unlevered | B16: 0.9101 | C16: Chemical (Diversified) — the SAME industry row the EV/EBITDA anchor uses
A17: Debt to equity at market value | B17: 0.1702745 | C17: for re-levering the sector beta
A18: Marginal pre-tax cost of debt | B18: 0.0555 | C18: long dollar rate plus an arm's-length margin
A19: Effective tax rate | B19: 0.2873604 | C19: the company's own three-year mean, not the 9% headline
A21: CAPACITY AND THE UNIT BUILD
A22: Polyethylene nameplate capacity | B22: 2750 | C22: kt a year
A23: Polypropylene nameplate capacity | B23: 2230 | C23: kt a year
A24: Sales over production (partner sourcing) | B24: 1.0295633 | C24: sales exceed production because Borouge sources from partners — measured from the audited record and held flat
A25: Realisation residual — polyethylene | B25: 1.0675777 | C25: three-year mean; computed on Segments
A26: Realisation residual — polypropylene | B26: 1.0321065 | C26: three-year mean; computed on Segments
A27: Other production cost — fixed leg | B27: 789.79084 | C27: PASTED CLASS 2: least squares across three audited years
A28: Other production cost — per tonne of production | B28: 0.20063485 | C28: PASTED CLASS 2: USD million per kt, same regression
A29: Feedstock cost per tonne, FY2025 actual | B29: 256.182 | C29: USD per tonne produced — the base both legs escalate from
A30: Polypropylene benchmark, FY2025 actual | B30: 851 | C30: the traded leg escalates on THIS, not on consumer inflation
A31: Contracted ethane real escalation | B31: 0 | C31: zero: the pricing formula is not disclosed, so none is invented
A32: UAE consumer inflation | B32: 0.021 | C32: escalates the DOMESTIC fixed cost leg only
A34: FIXED COSTS, WORKING CAPITAL AND CAPITAL SPEND
A35: General and administrative, FY2025 excluding depreciation | B35: 188 | C35: USD million
A36: Other income, FY2025 | B36: 26.321 | C36: USD million
A37: Other revenue, FY2025 | B37: 44 | C37: USD million, run off at 10% a year
A38: Days sales outstanding | B38: 50.89129 | C38: days, from the audited statements
A39: Days inventory | B39: 61.830887 | C39: days
A40: Days payable | B40: 92.496089 | C40: days
A41: Capital expenditure guide, 2026 | B41: 300 | C41: USD million
A42: Maintenance capital expenditure, steady state | B42: 320 | C42: USD million a year
A43: Property, plant and equipment, opening | B43: 6082.232 | C43: USD million at 31 December 2025
A44: Equity attributable to owners, 30 June 2026 | B44: 3725.997 | C44: USD million — the book-value lens reads this, on the SAME date as the bridge
...

Sheet SOTP Bridge
A1: Enterprise value to equity value
A2: Borouge is one operating business plus one operator fee stream. The fee stream is valued separately and never consolidated as owned capacity.
A4: THE BOROUGE 4 FEE STREAM — QUANTIFIED TWO WAYS, THE LOWER CARRIED
A5: From the disclosed three-year cumulative net profit | B5: =Assumptions!$B$57/1.0
A6: From the disclosed post-ramp-up earnings accretion | B6: =Assumptions!$B$56*AVERAGE('DCF'!B16:F16)
A7: Steady-state fee carried — the LOWER of the two | B7: =MIN(B5,B6) | C7: The sponsors' two figures do not agree; the study does not average them
B9: 2026 | C9: 2027 | D9: 2028 | E9: 2029 | F9: 2030
A10: Ramp-up fraction | B10: 0.1 | C10: 0.3 | D10: 0.6 | E10: 1 | F10: 1
A11: Fee to Borouge plc (USD million) | B11: =$B7*B10 | C11: =$B7*C10 | D11: =$B7*D10 | E11: =$B7*E10 | F11: =$B7*F10
A12: Present value of the fee | B12: =B11*'DCF'!B$22 | C12: =C11*'DCF'!C$22 | D12: =D11*'DCF'!D$22 | E12: =E11*'DCF'!E$22 | F12: =F11*'DCF'!F$22
A14: Present value of the explicit fee years | B14: =SUM(B12:F12)
A15: Present value of the fee beyond the forecast | B15: =$B7*0 | C15: NIL by construction: the Asset Usage Agreement runs only until the assets are acquired by the parent group, which the company says is not anticipated before 2029. A stream that ends cannot carry a perpetuity
A16: Value of the Borouge 4 fee stream | B16: =B14+B15
A18: THE BRIDGE — BOTH CONSTRUCTIONS, BOTH BETAS
B19: Normalisation, own beta | C19: Normalisation, sector beta | D19: Prolonged, own beta | E19: Prolonged, sector beta
A20: Enterprise value | B20: ='DCF'!$B$68 | C20: ='DCF'!$B$69 | D20: ='DCF'!$B$70 | E20: ='DCF'!$B$71
A21: Less: net debt | B21: =-Assumptions!$B$53 | C21: =-Assumptions!$B$53 | D21: =-Assumptions!$B$53 | E21: =-Assumptions!$B$53
A22: Less: lease liabilities | B22: =-Assumptions!$B$54 | C22: =-Assumptions!$B$54 | D22: =-Assumptions!$B$54 | E22: =-Assumptions!$B$54
A23: Less: non-controlling interests | B23: =-Assumptions!$B$55 | C23: =-Assumptions!$B$55 | D23: =-Assumptions!$B$55 | E23: =-Assumptions!$B$55
A24: Equity value | B24: =SUM(B20:B23) | C24: =SUM(C20:C23) | D24: =SUM(D20:D23) | E24: =SUM(E20:E23)
A25: Shares in issue (million) | B25: =Assumptions!$B$7 | C25: =Assumptions!$B$7 | D25: =Assumptions!$B$7 | E25: =Assumptions!$B$7
A26: Value per share (USD) | B26: =B24/B25 | C26: =C24/C25 | D26: =D24/D25 | E26: =E24/E25
A27: Value per share (AED) | B27: =B26*Assumptions!$B$6 | C27: =C26*Assumptions!$B$6 | D27: =D26*Assumptions!$B$6 | E27: =E26*Assumptions!$B$6
A28: Terminal value as a share of enterprise value | B28: ='DCF'!$E$68 | C28: ='DCF'!$E$69 | D28: ='DCF'!$E$70 | E28: ='DCF'!$E$71
A29: The terminal value share is shown in the bridge itself, live, so a reader can see at a glance how much of each answer rests on the years beyond the forecast rather than inside it.

Sheet Segments
A1: Segments — the unit build, tonnes and dollars per tonne
A2: Borouge reports as one operating segment. Volume and price are disclosed by product; cost is allocated on the disclosed physical drivers.
A4: DISCLOSED HISTORY (PASTED — THE PRIMARY RECORD)
B5: FY2023 | C5: FY2024 | D5: FY2025
A6: Polyethylene sold (kt) | B6: 2715 | C6: 3072 | D6: 3053
A7: Polypropylene sold (kt) | B7: 2285 | C7: 2253 | D7: 2322
A8: Total production (kt) | B8: 5116 | C8: 5216 | D8: 5055
A9: Polyethylene benchmark (USD/t) | B9: 914 | C9: 898 | D9: 822
A10: Polypropylene benchmark (USD/t) | B10: 891 | C10: 897 | D10: 851
A11: Polyethylene premium (USD/t) | B11: 215 | C11: 197 | D11: 224
A12: Polypropylene premium (USD/t) | B12: 125 | C12: 150 | D12: 134
A13: Polyethylene revenue (USD m) | B13: 3276 | C13: 3559 | D13: 3436
A14: Polypropylene revenue (USD m) | B14: 2402 | C14: 2421 | D14: 2368
A15: Feedstock (USD per tonne produced) | B15: 265.24629 | C15: 246.93252 | D15: 256.182
A16: Selling and distribution (USD per tonne sold) | B16: 78.087373 | C16: 88.465417 | D16: 77.213808
A18: THE REALISATION RESIDUAL, COMPUTED FROM THAT HISTORY
B19: FY2023 | C19: FY2024 | D19: FY2025 | E19: Three-year mean
A20: Polyethylene: revenue per tonne / (benchmark + premium) | B20: =B13*1000/B6/(B9+B11) | C20: =C13*1000/C6/(C9+C11) | D20: =D13*1000/D6/(D9+D11) | E20: =AVERAGE(B20:D20)
A21: Polypropylene: revenue per tonne / (benchmark + premium) | B21: =B14*1000/B7/(B10+B12) | C21: =C14*1000/C7/(C10+C12) | D21: =D14*1000/D7/(D10+D12) | E21: =AVERAGE(B21:D21)
A22: The residual is the bridge from a published benchmark to the company's own printed top line. It is computed here from disclosed revenue, volume, benchmark and premium — not assumed.
A24: THE FORECAST UNIT BUILD — NORMALISATION CONSTRUCTION
B25: 2026 | C25: 2027 | D25: 2028 | E25: 2029 | F25: 2030
A26: Polyethylene volume (kt) = capacity x utilisation | B26: =Assumptions!$B$22*Assumptions!B$61 | C26: =Assumptions!$B$22*Assumptions!C$61 | D26: =Assumptions!$B$22*Assumptions!D$61 | E26: =Assumptions!$B$22*Assumptions!E$61 | F26: =Assumptions!$B$22*Assumptions!F$61
A27: Polypropylene volume (kt) = capacity x utilisation | B27: =Assumptions!$B$23*Assumptions!B$62 | C27: =Assumptions!$B$23*Assumptions!C$62 | D27: =Assumptions!$B$23*Assumptions!D$62 | E27: =Assumptions!$B$23*Assumptions!E$62 | F27: =Assumptions!$B$23*Assumptions!F$62
A28: Total volume (kt) | B28: =B26+B27 | C28: =C26+C27 | D28: =D26+D27 | E28: =E26+E27 | F28: =F26+F27
A29: Polyethylene realised price (USD/t) | B29: =(Assumptions!B$63+Assumptions!B$65)*Assumptions!$B$25 | C29: =(Assumptions!C$63+Assumptions!C$65)*Assumptions!$B$25 | D29: =(Assumptions!D$63+Assumptions!D$65)*Assumptions!$B$25 | E29: =(Assumptions!E$63+Assumptions!E$65)*Assumptions!$B$25 | F29: =(Assumptions!F$63+Assumptions!F$65)*Assumptions!$B$25
A30: Polypropylene realised price (USD/t) | B30: =(Assumptions!B$64+Assumptions!B$66)*Assumptions!$B$26 | C30: =(Assumptions!C$64+Assumptions!C$66)*Assumptions!$B$26 | D30: =(Assumptions!D$64+Assumptions!D$66)*Assumptions!$B$26 | E30: =(Assumptions!E$64+Assumptions!E$66)*Assumptions!$B$26 | F30: =(Assumptions!F$64+Assumptions!F$66)*Assumptions!$B$26
A31: Feedstock (USD per tonne produced) | B31: =(1-Assumptions!B$68)*(Assumptions!$B$29*(1+Assumptions!$B$31)^1)+Assumptions!B$68*(Assumptions!$B$29*Assumptions!B$64/Assumptions!$B$30) | C31: =(1-Assumptions!C$68)*(Assumptions!$B$29*(1+Assumptions!$B$31)^2)+Assumptions!C$68*(Assumptions!$B$29*Assumptions!C$64/Assumptions!$B$30) | D31: =(1-Assumptions!D$68)*(Assumptions!$B$29*(1+Assumptions!$B$31)^3)+Assumptions!D$68*(Assumptions!$B$29*Assumptions!D$64/Assumptions!$B$30) | E31: =(1-Assumptions!E$68)*(Assumptions!$B$29*(1+Assumptions!$B$31)^4)+Assumptions!E$68*(Assumptions!$B$29*Assumptions!E$64/Assumptions!$B$30) | F31: =(1-Assumptions!F$68)*(Assumptions!$B$29*(1+Assumptions!$B$31)^5)+Assumptions!F$68*(Assumptions!$B$29*Assumptions!F$64/Assumptions!$B$30)
A33: THE FORECAST UNIT BUILD — PROLONGED-DISRUPTION CONSTRUCTION
B34: 2026 | C34: 2027 | D34: 2028 | E34: 2029 | F34: 2030
A35: Polyethylene volume (kt) = capacity x utilisation | B35: =Assumptions!$B$22*Assumptions!B$72 | C35: =Assumptions!$B$22*Assumptions!C$72 | D35: =Assumptions!$B$22*Assumptions!D$72 | E35: =Assumptions!$B$22*Assumptions!E$72 | F35: =Assumptions!$B$22*Assumptions!F$72
A36: Polypropylene volume (kt) = capacity x utilisation | B36: =Assumptions!$B$23*Assumptions!B$73 | C36: =Assumptions!$B$23*Assumptions!C$73 | D36: =Assumptions!$B$23*Assumptions!D$73 | E36: =Assumptions!$B$23*Assumptions!E$73 | F36: =Assumptions!$B$23*Assumptions!F$73
A37: Total volume (kt) | B37: =B35+B36 | C37: =C35+C36 | D37: =D35+D36 | E37: =E35+E36 | F37: =F35+F36
A38: Polyethylene realised price (USD/t) | B38: =(Assumptions!B$74+Assumptions!B$76)*Assumptions!$B$25 | C38: =(Assumptions!C$74+Assumptions!C$76)*Assumptions!$B$25 | D38: =(Assumptions!D$74+Assumptions!D$76)*Assumptions!$B$25 | E38: =(Assumptions!E$74+Assumptions!E$76)*Assumptions!$B$25 | F38: =(Assumptions!F$74+Assumptions!F$76)*Assumptions!$B$25
A39: Polypropylene realised price (USD/t) | B39: =(Assumptions!B$75+Assumptions!B$77)*Assumptions!$B$26 | C39: =(Assumptions!C$75+Assumptions!C$77)*Assumptions!$B$26 | D39: =(Assumptions!D$75+Assumptions!D$77)*Assumptions!$B$26 | E39: =(Assumptions!E$75+Assumptions!E$77)*Assumptions!$B$26 | F39: =(Assumptions!F$75+Assumptions!F$77)*Assumptions!$B$26
A40: Feedstock (USD per tonne produced) | B40: =(1-Assumptions!B$79)*(Assumptions!$B$29*(1+Assumptions!$B$31)^1)+Assumptions!B$79*(Assumptions!$B$29*Assumptions!B$75/Assumptions!$B$30) | C40: =(1-Assumptions!C$79)*(Assumptions!$B$29*(1+Assumptions!$B$31)^2)+Assumptions!C$79*(Assumptions!$B$29*Assumptions!C$75/Assumptions!$B$30) | D40: =(1-Assumptions!D$79)*(Assumptions!$B$29*(1+Assumptions!$B$31)^3)+Assumptions!D$79*(Assumptions!$B$29*Assumptions!D$75/Assumptions!$B$30) | E40: =(1-Assumptions!E$79)*(Assumptions!$B$29*(1+Assumptions!$B$31)^4)+Assumptions!E$79*(Assumptions!$B$29*Assumptions!E$75/Assumptions!$B$30) | F40: =(1-Assumptions!F$79)*(Assumptions!$B$29*(1+Assumptions!$B$31)^5)+Assumptions!F$79*(Assumptions!$B$29*Assumptions!F$75/Assumptions!$B$30)
A42: Two escalators, because there are two physically different inputs: contracted ethane escalates on its own terms, purchased propylene on the propylene benchmark. A single blended cost index across both would manufacture a margin trend out of arithmetic.

Sheet Relative & Normalized
A1: Relative multiples and normalised earnings power
A2: The multiple is triangulated on the sheet from three through-cycle anchors, and averaged here rather than asserted.
A4: WHY THE PEER MEDIAN IS REJECTED
A5: Listed peers observed | B5: =11
A6: Of which loss-making on trailing net income | B6: 9
A7: Of which enterprise value to EBITDA is undefined | B7: 2
A8: Naive median of whatever prints | B8: 13.39 | C8: Rejected: a median across collapsed denominators measures the trough, not the multiple
A10: THE THROUGH-CYCLE TRIANGULATION
A11: LyondellBasell ten-year median EV/EBITDA | B11: 7.18
A12: Industries Qatar current EV/EBITDA | B12: 9.9
A13: Damodaran global Chemical (Diversified) sector EV/EBITDA | B13: 8.655
A14: Adopted multiple — the median of the three anchors | B14: =MEDIAN(B11:B13)
A16: THE RELATIVE LENS
A17: Mid-cycle EBITDA (USD million) | B17: =AVERAGE('DCF'!D12,'DCF'!D43) | C17: The third forecast year of each construction, averaged — the mid-point of the cycle the study models
A18: Enterprise value = multiple x mid-cycle EBITDA | B18: =B14*B17
A19: Add: the Borouge 4 fee stream, on the same basis as the cash-flow lens | B19: ='SOTP Bridge'!$B$16 | C19: The same separable asset the cash-flow lens carries. Omitting it here valued three different companies under three lenses
A20: Enterprise value including the fee stream | B20: =B18+B19
A21: Less: net debt, leases and non-controlling interests | B21: =-Assumptions!$B$53-Assumptions!$B$54-Assumptions!$B$55
A22: Equity value | B22: =B20+B21
A23: Relative lens — value per share (AED) | B23: =B22/Assumptions!$B$7*Assumptions!$B$6
A25: NORMALISED EARNINGS POWER
A26: Mid-cycle is DERIVED from the audited record, not asserted: utilisation is the mean of the two most recent audited years and the benchmark is the mean of the three audited annual averages. Both therefore contain a turnaround year and a soft-price year, and neither contains the 2026 disruption.
A27: Mid-cycle polyethylene utilisation | B27: 1.06
A28: Mid-cycle polypropylene utilisation | B28: 0.99
A29: Mid-cycle polyethylene benchmark (USD/t) | B29: 878
A30: Mid-cycle polypropylene benchmark (USD/t) | B30: 879.66667
A31: Through-the-cycle polyethylene premium (USD/t) | B31: 200
A32: Through-the-cycle polypropylene premium (USD/t) | B32: 140
A33: Mid-cycle selling and distribution (USD/t) | B33: 81.255533
A34: Mid-cycle depreciation and amortisation (USD m) | B34: 400
A35: Mid-cycle polyethylene volume (kt) | B35: =B27*Assumptions!$B$22
A36: Mid-cycle polypropylene volume (kt) | B36: =B28*Assumptions!$B$23
A37: Mid-cycle volume (kt) | B37: =B35+B36
A38: Mid-cycle revenue (USD million) | B38: =(B35*(B29+B31)*Assumptions!$B$25+B36*(B30+B32)*Assumptions!$B$26)/1000
A39: Less: feedstock | B39: =Assumptions!$B$29*B37/1000
A40: Less: other production cost | B40: =Assumptions!$B$27+Assumptions!$B$28*B37
A41: Less: selling and distribution | B41: =B33*B37/1000
A42: Less: general and administrative | B42: =Assumptions!$B$35
A43: Mid-cycle EBITDA | B43: =B38-B39-B40-B41-B42
A44: Mid-cycle EBIT | B44: =B43-B34
...

Sheet DCF
A1: Discounted cash flow — the waterfall and the terminal block
A2: USD million. Both constructions. Every cell below is a formula.
A4: WATERFALL — NORMALISATION CONSTRUCTION
B5: 2026 | C5: 2027 | D5: 2028 | E5: 2029 | F5: 2030
A6: Revenue | B6: =(Segments!B$26*Segments!B$29+Segments!B$27*Segments!B$30)/1000*Assumptions!$B$24+Assumptions!$B$37*(1-0.1)^1 | C6: =(Segments!C$26*Segments!C$29+Segments!C$27*Segments!C$30)/1000*Assumptions!$B$24+Assumptions!$B$37*(1-0.1)^2 | D6: =(Segments!D$26*Segments!D$29+Segments!D$27*Segments!D$30)/1000*Assumptions!$B$24+Assumptions!$B$37*(1-0.1)^3 | E6: =(Segments!E$26*Segments!E$29+Segments!E$27*Segments!E$30)/1000*Assumptions!$B$24+Assumptions!$B$37*(1-0.1)^4 | F6: =(Segments!F$26*Segments!F$29+Segments!F$27*Segments!F$30)/1000*Assumptions!$B$24+Assumptions!$B$37*(1-0.1)^5
A7: Less: feedstock | B7: =Segments!B$31*Segments!B$28/1000 | C7: =Segments!C$31*Segments!C$28/1000 | D7: =Segments!D$31*Segments!D$28/1000 | E7: =Segments!E$31*Segments!E$28/1000 | F7: =Segments!F$31*Segments!F$28/1000
A8: Less: other production cost | B8: =Assumptions!$B$27*(1+Assumptions!$B$32)^1+Assumptions!$B$28*Segments!B$28 | C8: =Assumptions!$B$27*(1+Assumptions!$B$32)^2+Assumptions!$B$28*Segments!C$28 | D8: =Assumptions!$B$27*(1+Assumptions!$B$32)^3+Assumptions!$B$28*Segments!D$28 | E8: =Assumptions!$B$27*(1+Assumptions!$B$32)^4+Assumptions!$B$28*Segments!E$28 | F8: =Assumptions!$B$27*(1+Assumptions!$B$32)^5+Assumptions!$B$28*Segments!F$28
A9: Less: selling and distribution | B9: =Assumptions!B$67*Segments!B$28*Assumptions!$B$24/1000 | C9: =Assumptions!C$67*Segments!C$28*Assumptions!$B$24/1000 | D9: =Assumptions!D$67*Segments!D$28*Assumptions!$B$24/1000 | E9: =Assumptions!E$67*Segments!E$28*Assumptions!$B$24/1000 | F9: =Assumptions!F$67*Segments!F$28*Assumptions!$B$24/1000
A10: Less: general and administrative | B10: =Assumptions!$B$35*(1+Assumptions!$B$32)^1 | C10: =Assumptions!$B$35*(1+Assumptions!$B$32)^2 | D10: =Assumptions!$B$35*(1+Assumptions!$B$32)^3 | E10: =Assumptions!$B$35*(1+Assumptions!$B$32)^4 | F10: =Assumptions!$B$35*(1+Assumptions!$B$32)^5
A11: Add: other income | B11: =Assumptions!$B$36*(1+Assumptions!$B$32)^1 | C11: =Assumptions!$B$36*(1+Assumptions!$B$32)^2 | D11: =Assumptions!$B$36*(1+Assumptions!$B$32)^3 | E11: =Assumptions!$B$36*(1+Assumptions!$B$32)^4 | F11: =Assumptions!$B$36*(1+Assumptions!$B$32)^5
A12: EBITDA | B12: =B6-B7-B8-B9-B10+B11 | C12: =C6-C7-C8-C9-C10+C11 | D12: =D6-D7-D8-D9-D10+D11 | E12: =E6-E7-E8-E9-E10+E11 | F12: =F6-F7-F8-F9-F10+F11
A13: EBITDA margin = EBITDA / revenue | B13: =B12/B6 | C13: =C12/C6 | D13: =D12/D6 | E13: =E12/E6 | F13: =F12/F6
A14: Less: depreciation and amortisation | B14: =Assumptions!$B$43*Assumptions!$B$48 | C14: =(Assumptions!$B$43+SUM(B18:B18)-SUM(B14:B14))*Assumptions!$B$48 | D14: =(Assumptions!$B$43+SUM(B18:C18)-SUM(B14:C14))*Assumptions!$B$48 | E14: =(Assumptions!$B$43+SUM(B18:D18)-SUM(B14:D14))*Assumptions!$B$48 | F14: =(Assumptions!$B$43+SUM(B18:E18)-SUM(B14:E14))*Assumptions!$B$48
A15: EBIT = EBITDA less depreciation and amortisation | B15: =B12-B14 | C15: =C12-C14 | D15: =D12-D14 | E15: =E12-E14 | F15: =F12-F14
A16: NOPAT = EBIT x (1 - tax rate) | B16: =B15*(1-Assumptions!$B$19) | C16: =C15*(1-Assumptions!$B$19) | D16: =D15*(1-Assumptions!$B$19) | E16: =E15*(1-Assumptions!$B$19) | F16: =F15*(1-Assumptions!$B$19)
A17: Add back: depreciation and amortisation | B17: =B14 | C17: =C14 | D17: =D14 | E17: =E14 | F17: =F14
A18: Less: capital expenditure | B18: =Assumptions!$B$41 | C18: =Assumptions!$B$42 | D18: =Assumptions!$B$42 | E18: =Assumptions!$B$42 | F18: =Assumptions!$B$42
A19: Less: increase in working capital | B19: =(B6*Assumptions!$B$38/365+(B7+B8)*Assumptions!$B$39/365-(B7+B8)*Assumptions!$B$40/365)-(5847.773*Assumptions!$B$38/365+3099*Assumptions!$B$39/365-3099*Assumptions!$B$40/365) | C19: =(C6*Assumptions!$B$38/365+(C7+C8)*Assumptions!$B$39/365-(C7+C8)*Assumptions!$B$40/365)-(B6*Assumptions!$B$38/365+(B7+B8)*Assumptions!$B$39/365-(B7+B8)*Assumptions!$B$40/365) | D19: =(D6*Assumptions!$B$38/365+(D7+D8)*Assumptions!$B$39/365-(D7+D8)*Assumptions!$B$40/365)-(C6*Assumptions!$B$38/365+(C7+C8)*Assumptions!$B$39/365-(C7+C8)*Assumptions!$B$40/365) | E19: =(E6*Assumptions!$B$38/365+(E7+E8)*Assumptions!$B$39/365-(E7+E8)*Assumptions!$B$40/365)-(D6*Assumptions!$B$38/365+(D7+D8)*Assumptions!$B$39/365-(D7+D8)*Assumptions!$B$40/365) | F19: =(F6*Assumptions!$B$38/365+(F7+F8)*Assumptions!$B$39/365-(F7+F8)*Assumptions!$B$40/365)-(E6*Assumptions!$B$38/365+(E7+E8)*Assumptions!$B$39/365-(E7+E8)*Assumptions!$B$40/365)
A20: Free cash flow to the firm | B20: =B16+B17-B18-B19 | C20: =C16+C17-C18-C19 | D20: =D16+D17-D18-D19 | E20: =E16+E17-E18-E19 | F20: =F16+F17-F18-F19
A21: Discount rate applied | B21: ='Fundamental Valuation'!$B$29 | C21: ='Fundamental Valuation'!$B$29 | D21: ='Fundamental Valuation'!$B$29 | E21: ='Fundamental Valuation'!$B$29 | F21: ='Fundamental Valuation'!$B$29
A22: Discount factor | B22: =1/(1+B21)^1 | C22: =1/(1+C21)^2 | D22: =1/(1+D21)^3 | E22: =1/(1+E21)^4 | F22: =1/(1+F21)^5
A23: Present value of free cash flow to the firm | B23: =B20*B22 | C23: =C20*C22 | D23: =D20*D22 | E23: =E20*E22 | F23: =F20*F22
A25: TERMINAL BLOCK — NORMALISATION
A26: Final-year NOPAT | B26: =F16
A27: Terminal NOPAT = final-year NOPAT x (1 + growth) | B27: =B26*(1+Assumptions!$B$51)
A28: Reinvestment rate = growth / return on capital | B28: =Assumptions!$B$51/Assumptions!$B$52
A29: Terminal free cash flow = NOPAT x (1 - reinvestment rate) | B29: =B27*(1-B28)
A30: Terminal value = terminal cash flow / (cost of capital - growth) | B30: =B29/(F21-Assumptions!$B$51)
A31: Present value of the terminal value | B31: =B30*F22
A32: Present value of the explicit five years | B32: =SUM(B23:F23)
A33: Enterprise value of the owned business | B33: =B32+B31
A35: WATERFALL — PROLONGED-DISRUPTION CONSTRUCTION
B36: 2026 | C36: 2027 | D36: 2028 | E36: 2029 | F36: 2030
A37: Revenue | B37: =(Segments!B$35*Segments!B$38+Segments!B$36*Segments!B$39)/1000*Assumptions!$B$24+Assumptions!$B$37*(1-0.1)^1 | C37: =(Segments!C$35*Segments!C$38+Segments!C$36*Segments!C$39)/1000*Assumptions!$B$24+Assumptions!$B$37*(1-0.1)^2 | D37: =(Segments!D$35*Segments!D$38+Segments!D$36*Segments!D$39)/1000*Assumptions!$B$24+Assumptions!$B$37*(1-0.1)^3 | E37: =(Segments!E$35*Segments!E$38+Segments!E$36*Segments!E$39)/1000*Assumptions!$B$24+Assumptions!$B$37*(1-0.1)^4 | F37: =(Segments!F$35*Segments!F$38+Segments!F$36*Segments!F$39)/1000*Assumptions!$B$24+Assumptions!$B$37*(1-0.1)^5
A38: Less: feedstock | B38: =Segments!B$40*Segments!B$37/1000 | C38: =Segments!C$40*Segments!C$37/1000 | D38: =Segments!D$40*Segments!D$37/1000 | E38: =Segments!E$40*Segments!E$37/1000 | F38: =Segments!F$40*Segments!F$37/1000
A39: Less: other production cost | B39: =Assumptions!$B$27*(1+Assumptions!$B$32)^1+Assumptions!$B$28*Segments!B$37 | C39: =Assumptions!$B$27*(1+Assumptions!$B$32)^2+Assumptions!$B$28*Segments!C$37 | D39: =Assumptions!$B$27*(1+Assumptions!$B$32)^3+Assumptions!$B$28*Segments!D$37 | E39: =Assumptions!$B$27*(1+Assumptions!$B$32)^4+Assumptions!$B$28*Segments!E$37 | F39: =Assumptions!$B$27*(1+Assumptions!$B$32)^5+Assumptions!$B$28*Segments!F$37
A40: Less: selling and distribution | B40: =Assumptions!B$78*Segments!B$37*Assumptions!$B$24/1000 | C40: =Assumptions!C$78*Segments!C$37*Assumptions!$B$24/1000 | D40: =Assumptions!D$78*Segments!D$37*Assumptions!$B$24/1000 | E40: =Assumptions!E$78*Segments!E$37*Assumptions!$B$24/1000 | F40: =Assumptions!F$78*Segments!F$37*Assumptions!$B$24/1000
A41: Less: general and administrative | B41: =Assumptions!$B$35*(1+Assumptions!$B$32)^1 | C41: =Assumptions!$B$35*(1+Assumptions!$B$32)^2 | D41: =Assumptions!$B$35*(1+Assumptions!$B$32)^3 | E41: =Assumptions!$B$35*(1+Assumptions!$B$32)^4 | F41: =Assumptions!$B$35*(1+Assumptions!$B$32)^5
A42: Add: other income | B42: =Assumptions!$B$36*(1+Assumptions!$B$32)^1 | C42: =Assumptions!$B$36*(1+Assumptions!$B$32)^2 | D42: =Assumptions!$B$36*(1+Assumptions!$B$32)^3 | E42: =Assumptions!$B$36*(1+Assumptions!$B$32)^4 | F42: =Assumptions!$B$36*(1+Assumptions!$B$32)^5
A43: EBITDA | B43: =B37-B38-B39-B40-B41+B42 | C43: =C37-C38-C39-C40-C41+C42 | D43: =D37-D38-D39-D40-D41+D42 | E43: =E37-E38-E39-E40-E41+E42 | F43: =F37-F38-F39-F40-F41+F42
...

Sheet Income Statement
A1: Income statement — three audited years and five forecast years
A2: USD million. Historical columns are the audited figures; forecast columns are formulas from the waterfall.
B4: FY2023 | C4: FY2024 | D4: FY2025 | E4: 2026 | F4: 2027 | G4: 2028 | H4: 2029 | I4: 2030
A5: Revenue | B5: 5791.345 | C5: 6026.123 | D5: 5847.773 | E5: ='DCF'!B6 | F5: ='DCF'!C6 | G5: ='DCF'!D6 | H5: ='DCF'!E6 | I5: ='DCF'!F6
A6: Cost of sales | B6: 3627.383 | C6: 3490.989 | D6: 3565.985 | E6: ='DCF'!B7+'DCF'!B8+'DCF'!B14 | F6: ='DCF'!C7+'DCF'!C8+'DCF'!C14 | G6: ='DCF'!D7+'DCF'!D8+'DCF'!D14 | H6: ='DCF'!E7+'DCF'!E8+'DCF'!E14 | I6: ='DCF'!F7+'DCF'!F8+'DCF'!F14
A7: Gross profit | B7: 2163.962 | C7: 2535.134 | D7: 2281.788 | E7: =E5-E6 | F7: =F5-F6 | G7: =G5-G6 | H7: =H5-H6 | I7: =I5-I6
A8: Selling and distribution | B8: 399.495 | C8: 471.963 | D8: 416.028 | E8: ='DCF'!B9 | F8: ='DCF'!C9 | G8: ='DCF'!D9 | H8: ='DCF'!E9 | I8: ='DCF'!F9
A9: General and administrative | B9: 182.915 | C9: 193.121 | D9: 196.577 | E9: ='DCF'!B10 | F9: ='DCF'!C10 | G9: ='DCF'!D10 | H9: ='DCF'!E10 | I9: ='DCF'!F10
A10: Other income | B10: 17.35 | C10: 53.951 | D10: 26.321 | E10: ='DCF'!B11 | F10: ='DCF'!C11 | G10: ='DCF'!D11 | H10: ='DCF'!E11 | I10: ='DCF'!F11
A11: Operating profit (EBIT) | B11: 1597.171 | C11: 1920.919 | D11: 1694.063 | E11: =E7-E8-E9+E10 | F11: =F7-F8-F9+F10 | G11: =G7-G8-G9+G10 | H11: =H7-H8-H9+H10 | I11: =I7-I8-I9+I10
A12: Depreciation and amortisation | B12: 572.169 | C12: 552.65 | D12: 476.314 | E12: ='DCF'!B14 | F12: ='DCF'!C14 | G12: ='DCF'!D14 | H12: ='DCF'!E14 | I12: ='DCF'!F14
A13: EBITDA | B13: 2169.34 | C13: 2473.569 | D13: 2170.377 | E13: =E11+E12 | F13: =F11+F12 | G13: =G11+G12 | H13: =H11+H12 | I13: =I11+I12
A14: Net finance cost | B14: 196.168 | C14: 175.61 | D14: 154.219 | E14: =Assumptions!$B$53*Assumptions!$B$18 | F14: =Assumptions!$B$53*Assumptions!$B$18 | G14: =Assumptions!$B$53*Assumptions!$B$18 | H14: =Assumptions!$B$53*Assumptions!$B$18 | I14: =Assumptions!$B$53*Assumptions!$B$18
A15: Profit before tax | B15: 1401.003 | C15: 1745.309 | D15: 1539.844 | E15: =E11-E14 | F15: =F11-F14 | G15: =G11-G14 | H15: =H11-H14 | I15: =I11-I14
A16: Tax | B16: 400.333 | C16: 506.361 | D16: 440.714 | E16: =E15*Assumptions!$B$19 | F16: =F15*Assumptions!$B$19 | G16: =G15*Assumptions!$B$19 | H16: =H15*Assumptions!$B$19 | I16: =I15*Assumptions!$B$19
A17: Profit after tax | B17: 1000.67 | C17: 1238.948 | D17: 1099.13 | E17: =E15-E16 | F17: =F15-F16 | G17: =G15-G16 | H17: =H15-H16 | I17: =I15-I16
A19: The forecast operating lines are the same cells as the cash-flow waterfall, linked rather than restated. The finance cost below EBIT is the net debt balance at the marginal cost of debt — it does not enter free cash flow to the firm, which is computed before financing.

Sheet Balance Sheet
A1: Balance sheet — three audited years and five forecast years
A2: USD million. The forecast rolls property, working capital and net debt forward from the drivers; nothing is plugged.
B4: FY2023 | C4: FY2024 | D4: FY2025 | E4: 2026 | F4: 2027 | G4: 2028 | H4: 2029 | I4: 2030
A5: Property, plant and equipment | B5: 6677.355 | C5: 6292.502 | D5: 6082.232 | E5: =D5+'DCF'!B18-'DCF'!B14 | F5: =E5+'DCF'!C18-'DCF'!C14 | G5: =F5+'DCF'!D18-'DCF'!D14 | H5: =G5+'DCF'!E18-'DCF'!E14 | I5: =H5+'DCF'!F18-'DCF'!F14
A6: Trade receivables | B6: ='Income Statement'!B5*50.21094926998823/365 | C6: ='Income Statement'!C5*52.015254252194985/365 | D6: ='Income Statement'!D5*50.44766700075396/365 | E6: ='Income Statement'!E5*Assumptions!$B$38/365 | F6: ='Income Statement'!F5*Assumptions!$B$38/365 | G6: ='Income Statement'!G5*Assumptions!$B$38/365 | H6: ='Income Statement'!H5*Assumptions!$B$38/365 | I6: ='Income Statement'!I5*Assumptions!$B$38/365
A7: Inventory | B7: 645.184 | C7: 640.505 | D7: 523.702 | E7: =('DCF'!B7+'DCF'!B8)*Assumptions!$B$39/365 | F7: =('DCF'!C7+'DCF'!C8)*Assumptions!$B$39/365 | G7: =('DCF'!D7+'DCF'!D8)*Assumptions!$B$39/365 | H7: =('DCF'!E7+'DCF'!E8)*Assumptions!$B$39/365 | I7: =('DCF'!F7+'DCF'!F8)*Assumptions!$B$39/365
A8: Cash and equivalents | B8: 353.921 | C8: 418.506 | D8: 426.901 | E8: =E11-E14 | F8: =F11-F14 | G8: =G11-G14 | H8: =H11-H14 | I8: =I11-I14
A9: Total assets (memo: audited) | B9: 8943.896 | C9: 8707.465 | D9: 8489.104 | E9: =E5+E6+E7+E8 | F9: =F5+F6+F7+F8 | G9: =G5+G6+G7+G8 | H9: =H5+H6+H7+H8 | I9: =I5+I6+I7+I8
A10: Trade payables | B10: ='Income Statement'!B6*88.08249776767437/365 | C10: ='Income Statement'!C6*91.68628145204697/365 | D10: ='Income Statement'!D6*97.71948844428678/365 | E10: =('DCF'!B7+'DCF'!B8)*Assumptions!$B$40/365 | F10: =('DCF'!C7+'DCF'!C8)*Assumptions!$B$40/365 | G10: =('DCF'!D7+'DCF'!D8)*Assumptions!$B$40/365 | H10: =('DCF'!E7+'DCF'!E8)*Assumptions!$B$40/365 | I10: =('DCF'!F7+'DCF'!F8)*Assumptions!$B$40/365
A11: Borrowings | B11: 3140.725 | C11: 2944.1 | D11: 2957.73 | E11: ='Balance Sheet'!D11 | F11: ='Balance Sheet'!D11 | G11: ='Balance Sheet'!D11 | H11: ='Balance Sheet'!D11 | I11: ='Balance Sheet'!D11
A12: Equity | B12: 4532.482 | C12: 4462.726 | D12: 4088.85 | E12: =D12+'Income Statement'!E17-0.044111640571817566*Assumptions!$B$7 | F12: =E12+'Income Statement'!F17-0.044111640571817566*Assumptions!$B$7 | G12: =F12+'Income Statement'!G17-0.044111640571817566*Assumptions!$B$7 | H12: =G12+'Income Statement'!H17-0.044111640571817566*Assumptions!$B$7 | I12: =H12+'Income Statement'!I17-0.044111640571817566*Assumptions!$B$7
A13: Net working capital | B13: =B6+B7-B10 | C13: =C6+C7-C10 | D13: =D6+D7-D10 | E13: =E6+E7-E10 | F13: =F6+F7-F10 | G13: =G6+G7-G10 | H13: =H6+H7-H10 | I13: =I6+I7-I10
A14: Net debt | B14: =B11-B8 | C14: =C11-C8 | D14: =D11-D8 | E14: =D14-('DCF'!B20-Assumptions!$B$53*Assumptions!$B$18*(1-Assumptions!$B$19))+0.044111640571817566*Assumptions!$B$7 | F14: =E14-('DCF'!C20-Assumptions!$B$53*Assumptions!$B$18*(1-Assumptions!$B$19))+0.044111640571817566*Assumptions!$B$7 | G14: =F14-('DCF'!D20-Assumptions!$B$53*Assumptions!$B$18*(1-Assumptions!$B$19))+0.044111640571817566*Assumptions!$B$7 | H14: =G14-('DCF'!E20-Assumptions!$B$53*Assumptions!$B$18*(1-Assumptions!$B$19))+0.044111640571817566*Assumptions!$B$7 | I14: =H14-('DCF'!F20-Assumptions!$B$53*Assumptions!$B$18*(1-Assumptions!$B$19))+0.044111640571817566*Assumptions!$B$7
A16: Receivables, inventory and payables are projected from the days the audited statements themselves show — fifty-one days of sales, sixty-two days of inventory, ninety-two days of payables. Nothing on this sheet is a balancing figure.

Sheet Cash Flow
A1: Cash flow — linked to the waterfall, not restated
A2: USD million. The forecast columns are the same cells the valuation discounts.
B4: FY2023 | C4: FY2024 | D4: FY2025 | E4: 2026 | F4: 2027 | G4: 2028 | H4: 2029 | I4: 2030
A5: EBITDA | B5: 2169.34 | C5: 2473.569 | D5: 2170.377 | E5: ='DCF'!B12 | F5: ='DCF'!C12 | G5: ='DCF'!D12 | H5: ='DCF'!E12 | I5: ='DCF'!F12
A6: Less: increase in working capital | E6: ='DCF'!B19 | F6: ='DCF'!C19 | G6: ='DCF'!D19 | H6: ='DCF'!E19 | I6: ='DCF'!F19
A7: Less: tax on operating profit | B7: 400.333 | C7: 506.361 | D7: 440.714 | E7: ='DCF'!B15*Assumptions!$B$19 | F7: ='DCF'!C15*Assumptions!$B$19 | G7: ='DCF'!D15*Assumptions!$B$19 | H7: ='DCF'!E15*Assumptions!$B$19 | I7: ='DCF'!F15*Assumptions!$B$19
A8: Cash from operations | B8: 1768.72 | C8: 1913.152 | D8: 1920.976 | E8: =E5-E6-E7 | F8: =F5-F6-F7 | G8: =G5-G6-G7 | H8: =H5-H6-H7 | I8: =I5-I6-I7
A9: Less: capital expenditure | B9: 198.78 | C9: 167.383 | D9: 308.233 | E9: ='DCF'!B18 | F9: ='DCF'!C18 | G9: ='DCF'!D18 | H9: ='DCF'!E18 | I9: ='DCF'!F18
A10: Free cash flow to the firm | B10: =B8-B9 | C10: =C8-C9 | D10: =D8-D9 | E10: =E8-E9 | F10: =F8-F9 | G10: =G8-G9 | H10: =H8-H9 | I10: =I8-I9
A11: Less: net finance cost after tax | E11: =Assumptions!$B$53*Assumptions!$B$18*(1-Assumptions!$B$19) | F11: =Assumptions!$B$53*Assumptions!$B$18*(1-Assumptions!$B$19) | G11: =Assumptions!$B$53*Assumptions!$B$18*(1-Assumptions!$B$19) | H11: =Assumptions!$B$53*Assumptions!$B$18*(1-Assumptions!$B$19) | I11: =Assumptions!$B$53*Assumptions!$B$18*(1-Assumptions!$B$19)
A12: Less: dividend | E12: =0.044111640571817566*Assumptions!$B$7 | F12: =0.044111640571817566*Assumptions!$B$7 | G12: =0.044111640571817566*Assumptions!$B$7 | H12: =0.044111640571817566*Assumptions!$B$7 | I12: =0.044111640571817566*Assumptions!$B$7
A13: Free cash flow to equity | E13: =E10-E11-E12 | F13: =F10-F11-F12 | G13: =G10-G11-G12 | H13: =H10-H11-H12 | I13: =I10-I11-I12
A15: Cash from operations reconciles to free cash flow to the firm through capital expenditure alone, because the working-capital movement and the tax on operating profit are already inside it. The dividend is the company's own stated intention of 16.2 fils a share.

Sheet Summary Financials
A1: Summary financials
A2: USD million. Every cell is a link or a formula.
B4: FY2023 | C4: FY2024 | D4: FY2025 | E4: 2026 | F4: 2027 | G4: 2028 | H4: 2029 | I4: 2030
A5: Revenue | B5: ='Income Statement'!B5 | C5: ='Income Statement'!C5 | D5: ='Income Statement'!D5 | E5: ='Income Statement'!E5 | F5: ='Income Statement'!F5 | G5: ='Income Statement'!G5 | H5: ='Income Statement'!H5 | I5: ='Income Statement'!I5
A6: EBITDA | B6: ='Income Statement'!B13 | C6: ='Income Statement'!C13 | D6: ='Income Statement'!D13 | E6: ='Income Statement'!E13 | F6: ='Income Statement'!F13 | G6: ='Income Statement'!G13 | H6: ='Income Statement'!H13 | I6: ='Income Statement'!I13
A7: EBITDA margin | B7: =B6/B5 | C7: =C6/C5 | D7: =D6/D5 | E7: =E6/E5 | F7: =F6/F5 | G7: =G6/G5 | H7: =H6/H5 | I7: =I6/I5
A8: EBIT | B8: ='Income Statement'!B11 | C8: ='Income Statement'!C11 | D8: ='Income Statement'!D11 | E8: ='Income Statement'!E11 | F8: ='Income Statement'!F11 | G8: ='Income Statement'!G11 | H8: ='Income Statement'!H11 | I8: ='Income Statement'!I11
A9: Profit after tax | B9: ='Income Statement'!B17 | C9: ='Income Statement'!C17 | D9: ='Income Statement'!D17 | E9: ='Income Statement'!E17 | F9: ='Income Statement'!F17 | G9: ='Income Statement'!G17 | H9: ='Income Statement'!H17 | I9: ='Income Statement'!I17
A10: Free cash flow to the firm | B10: ='Cash Flow'!B10 | C10: ='Cash Flow'!C10 | D10: ='Cash Flow'!D10 | E10: ='Cash Flow'!E10 | F10: ='Cash Flow'!F10 | G10: ='Cash Flow'!G10 | H10: ='Cash Flow'!H10 | I10: ='Cash Flow'!I10
A11: Capital expenditure | B11: ='Cash Flow'!B9 | C11: ='Cash Flow'!C9 | D11: ='Cash Flow'!D9 | E11: ='Cash Flow'!E9 | F11: ='Cash Flow'!F9 | G11: ='Cash Flow'!G9 | H11: ='Cash Flow'!H9 | I11: ='Cash Flow'!I9
A12: Net debt | B12: ='Balance Sheet'!B14 | C12: ='Balance Sheet'!C14 | D12: ='Balance Sheet'!D14 | E12: ='Balance Sheet'!E14 | F12: ='Balance Sheet'!F14 | G12: ='Balance Sheet'!G14 | H12: ='Balance Sheet'!H14 | I12: ='Balance Sheet'!I14
A13: Net debt to EBITDA | B13: =B12/B6 | C13: =C12/C6 | D13: =D12/D6 | E13: =E12/E6 | F13: =F12/F6 | G13: =G12/G6 | H13: =H12/H6 | I13: =I12/I6

Sheet Monte Carlo
A1: Probability map for the traded price
A2: Each figure is the outcome of a 50,000-path simulation on the cleaned price history — a complete re-run, not a formula. THIS MAP DOES NOT REDRAW WHEN A DRIVER CHANGES.
A4: THE SIMULATION AS IT WAS RUN
A5: Anchor close (AED) | B5: 2.4
A6: Anchor date | B6: 2026-08-07
A7: Paths | B7: 50000
A8: Risk-free rate | B8: 0.0365
A9: Dividend yield (16.2 fils on the close) | B9: 0.0675
A10: Net carry a year | B10: -0.031
A12: PERCENTILE MAP (AED PER SHARE)
A13: Horizon | B13: Ends | C13: 5th | D13: 25th | E13: Median | F13: 75th | G13: 95th | H13: Above the close
A14: One month | B14: 2026-09-07 | C14: 2.2216485 | D14: 2.3262837 | E14: 2.3940115 | F14: 2.4640703 | G14: 2.5766702 | H14: 0.47704
A15: Three months | B15: 2026-11-09 | C15: 2.0743744 | D15: 2.2598068 | E15: 2.3835515 | F15: 2.5136178 | G15: 2.7407693 | H15: 0.46466
A17: LEVEL-TOUCH LADDER — CHANCE THE PRICE TRADES THROUGH A LEVEL AT ANY POINT
A18: Move from the close | B18: Level (AED) | C18: One month | D18: Three months
A19: Up 5% | B19: =$B$5*(1+0.05) | C19: 0.20246 | D19: 0.46392
A20: Down 5% | B20: =$B$5*(1-0.05) | C20: 0.21098 | D20: 0.5035
A21: Up 10% | B21: =$B$5*(1+0.1) | C21: 0.02956 | D21: 0.19616
A22: Down 10% | B22: =$B$5*(1-0.1) | C22: 0.0238 | D22: 0.19478
A23: Up 15% | B23: =$B$5*(1+0.15) | C23: 0.0044 | D23: 0.07742
A24: Down 15% | B24: =$B$5*(1-0.15) | C24: 0.00194 | D24: 0.05896
A25: Up 20% | B25: =$B$5*(1+0.2) | C25: 0.00072 | D25: 0.02966
A26: Down 20% | B26: =$B$5*(1-0.2) | C26: 0.0002 | D26: 0.0155
A28: The percentile map and the touch ladder are simulation output. The level column beside them is a live formula off the close, so the ladder's rungs move if the anchor changes even though the probabilities beside them do not.

Sheet Sensitivity
A1: Sensitivity — each cell is a complete revaluation
A2: THESE GRIDS DO NOT REDRAW WHEN A DRIVER CHANGES. Value per share in AED, normalisation construction, own-stock beta.
A4: COST OF CAPITAL AGAINST TERMINAL GROWTH
A5: Cost of capital \ growth | B5: 1.0% | C5: 1.5% | D5: 2.0% | E5: 2.5% | F5: 3.0%
A6: 0.050805568 | B6: 2.8989602 | C6: 3.1427895 | D6: 3.4642107 | E6: 3.9083255 | F6: 4.5635915
A7: 0.055805568 | B7: 2.5490234 | C7: 2.7237956 | D7: 2.9460693 | E7: 3.238974 | F7: 3.6435657
A8: 0.060805568 | B8: 2.267628 | C8: 2.3958156 | D8: 2.5542948 | E8: 2.7557557 | F8: 3.0211271
A9: 0.065805568 | B9: 2.0363605 | C9: 2.1319915 | D9: 2.2475232 | E9: 2.3902712 | F9: 2.571637
A10: 0.070805568 | B10: 1.8428637 | C10: 1.9150904 | D10: 2.0006731 | E10: 2.1039854 | F10: 2.2315447
A12: REALISED PREMIUM OVER THE BENCHMARK (USD PER TONNE)
A13: Shift | B13: Normalisation | C13: Prolonged disruption
A14: -100 | B14: 1.6136522 | C14: 1.4284498
A15: -50 | B15: 2.0839735 | C15: 1.8904206
A16: +0 | B16: 2.5542948 | C16: 2.3523913
A17: +50 | B17: 3.0246162 | C17: 2.8143621
A18: +100 | B18: 3.4949375 | C18: 3.2763328
A20: UTILISATION
A21: Shift | B21: Normalisation | C21: Prolonged disruption
A22: -10% | B22: 2.0303368 | C22: 1.8395588
A23: -5% | B23: 2.2923158 | C23: 2.0959751
A24: +0% | B24: 2.5542948 | C24: 2.3523913
A25: +5% | B25: 2.8162738 | C25: 2.6088076
A26: +10% | B26: 3.0782528 | C26: 2.8652238
A28: Every cell above is the whole valuation solved again at that pair of inputs. That is why they are values rather than formulas, and why they are named as a pasted class on READ FIRST.

Sheet Per-Share & Ratios
A1: Per-share figures and returns
A2: Every cell is a formula.
B4: FY2023 | C4: FY2024 | D4: FY2025 | E4: 2026 | F4: 2027 | G4: 2028 | H4: 2029 | I4: 2030
A5: Earnings per share (USD) | B5: ='Income Statement'!B17/Assumptions!$B$7 | C5: ='Income Statement'!C17/Assumptions!$B$7 | D5: ='Income Statement'!D17/Assumptions!$B$7 | E5: ='Income Statement'!E17/Assumptions!$B$7 | F5: ='Income Statement'!F17/Assumptions!$B$7 | G5: ='Income Statement'!G17/Assumptions!$B$7 | H5: ='Income Statement'!H17/Assumptions!$B$7 | I5: ='Income Statement'!I17/Assumptions!$B$7
A6: Earnings per share (AED) | B6: =B5*Assumptions!$B$6 | C6: =C5*Assumptions!$B$6 | D6: =D5*Assumptions!$B$6 | E6: =E5*Assumptions!$B$6 | F6: =F5*Assumptions!$B$6 | G6: =G5*Assumptions!$B$6 | H6: =H5*Assumptions!$B$6 | I6: =I5*Assumptions!$B$6
A7: Book value per share (AED) | B7: ='Balance Sheet'!B12/Assumptions!$B$7*Assumptions!$B$6 | C7: ='Balance Sheet'!C12/Assumptions!$B$7*Assumptions!$B$6 | D7: ='Balance Sheet'!D12/Assumptions!$B$7*Assumptions!$B$6 | E7: ='Balance Sheet'!E12/Assumptions!$B$7*Assumptions!$B$6 | F7: ='Balance Sheet'!F12/Assumptions!$B$7*Assumptions!$B$6 | G7: ='Balance Sheet'!G12/Assumptions!$B$7*Assumptions!$B$6 | H7: ='Balance Sheet'!H12/Assumptions!$B$7*Assumptions!$B$6 | I7: ='Balance Sheet'!I12/Assumptions!$B$7*Assumptions!$B$6
A8: Return on equity | B8: ='Income Statement'!B17/'Balance Sheet'!B12 | C8: ='Income Statement'!C17/'Balance Sheet'!C12 | D8: ='Income Statement'!D17/'Balance Sheet'!D12 | E8: ='Income Statement'!E17/'Balance Sheet'!E12 | F8: ='Income Statement'!F17/'Balance Sheet'!F12 | G8: ='Income Statement'!G17/'Balance Sheet'!G12 | H8: ='Income Statement'!H17/'Balance Sheet'!H12 | I8: ='Income Statement'!I17/'Balance Sheet'!I12
A9: Return on invested capital | B9: ='Income Statement'!B11*(1-Assumptions!$B$19)/('Balance Sheet'!B5+'Balance Sheet'!B13) | C9: ='Income Statement'!C11*(1-Assumptions!$B$19)/('Balance Sheet'!C5+'Balance Sheet'!C13) | D9: ='Income Statement'!D11*(1-Assumptions!$B$19)/('Balance Sheet'!D5+'Balance Sheet'!D13) | E9: ='Income Statement'!E11*(1-Assumptions!$B$19)/('Balance Sheet'!E5+'Balance Sheet'!E13) | F9: ='Income Statement'!F11*(1-Assumptions!$B$19)/('Balance Sheet'!F5+'Balance Sheet'!F13) | G9: ='Income Statement'!G11*(1-Assumptions!$B$19)/('Balance Sheet'!G5+'Balance Sheet'!G13) | H9: ='Income Statement'!H11*(1-Assumptions!$B$19)/('Balance Sheet'!H5+'Balance Sheet'!H13) | I9: ='Income Statement'!I11*(1-Assumptions!$B$19)/('Balance Sheet'!I5+'Balance Sheet'!I13)
A10: EBITDA margin | B10: ='Summary Financials'!B7 | C10: ='Summary Financials'!C7 | D10: ='Summary Financials'!D7 | E10: ='Summary Financials'!E7 | F10: ='Summary Financials'!F7 | G10: ='Summary Financials'!G7 | H10: ='Summary Financials'!H7 | I10: ='Summary Financials'!I7
A11: Net debt to EBITDA | B11: ='Balance Sheet'!B14/'Income Statement'!B13 | C11: ='Balance Sheet'!C14/'Income Statement'!C13 | D11: ='Balance Sheet'!D14/'Income Statement'!D13 | E11: ='Balance Sheet'!E14/'Income Statement'!E13 | F11: ='Balance Sheet'!F14/'Income Statement'!F13 | G11: ='Balance Sheet'!G14/'Income Statement'!G13 | H11: ='Balance Sheet'!H14/'Income Statement'!H13 | I11: ='Balance Sheet'!I14/'Income Statement'!I13
A12: Dividend per share (AED) | B12: =0.162 | C12: =0.162 | D12: =0.162 | E12: =0.162 | F12: =0.162 | G12: =0.162 | H12: =0.162 | I12: =0.162
A13: Payout ratio | B13: =B12/B6 | C13: =C12/C6 | D13: =D12/D6 | E13: =E12/E6 | F13: =F12/F6 | G13: =G12/G6 | H13: =H12/H6 | I13: =I12/I6
A15: The dividend per share is the company's own stated annual intention of 16.2 fils. It is held flat rather than grown, because the company states an intention, not a policy formula.

Sheet Peer & Sector
A1: Listed peers — a cross-check, never a source
A2: Observed 9 August 2026. Shown to explain why the naive median is rejected, not to set the multiple.
A4: Company | B4: EV / EBITDA | C4: Forward P/E | D4: Price to book | E4: Dividend yield | F4: EBITDA margin | G4: Net margin | H4: Loss-making
A5: SABIC (Tadawul 2010) | B5: 10.83 | C5: 24.65 | D5: 1.02 | E5: 0.0435 | F5: 0.1393 | G5: -0.1974 | H5: yes
A6: Saudi Kayan (2350) | B6: 32.52 | C6: - | D6: 0.99 | E6: 0 | F6: 0.0604 | G6: -0.3014 | H6: yes
A7: Yansab (2290) | B7: 12.24 | C7: 33.04 | D7: 1.61 | E7: 0.0669 | F7: 0.2035 | G7: 0.0494 | H7: no
A8: Industries Qatar (IQCD) | B8: 9.9 | C8: 17.04 | D8: 1.86 | E8: 0.0638 | F8: - | G8: - | H8: no
A9: LyondellBasell (LYB) | B9: 12.96 | C9: 7.42 | D9: 1.8 | E9: 0.0463 | F9: 0.0765 | G9: -0.0113 | H9: yes
A10: Dow Inc (DOW) | B10: 13.39 | C10: 13.74 | D10: 1.34 | E10: 0.0477 | F10: 0.0658 | G10: -0.0313 | H10: yes
A11: Formosa Plastics (1301) | B11: 55.97 | C11: 14.8 | D11: 0.91 | E11: 0.009 | F11: 0.0157 | G11: -0.0401 | H11: yes
A12: LG Chem (051910) | B12: 13.39 | C12: 15.48 | D12: 0.43 | E12: 0.0072 | F12: 0.1003 | G12: -0.0452 | H12: yes
A13: Petronas Chemicals (PCHEM) | B13: 22.92 | C13: 21.18 | D13: 0.97 | E13: 0.0156 | F13: 0.0512 | G13: -0.0642 | H13: yes
A14: Westlake (WLK) | B14: - | C14: 20.34 | D14: 1.14 | E14: 0.0274 | F14: -0.0066 | G14: -0.1094 | H14: yes
A15: Braskem (BAK) | B15: - | C15: - | D15: - | E15: - | F15: -0.0006 | G15: -0.1368 | H15: yes
A16: Median of the multiples that print | B16: =MEDIAN(B5:B13) | C16: REJECTED — see Relative & Normalized
A18: BOROUGE ON THE SAME BASIS, FOR CONTRAST
A19: EV / EBITDA | B19: 12.02
A20: Forward P/E | B20: 9.19
A21: Dividend yield | B21: 0.0675
A22: EBITDA margin | B22: 0.3305
A24: Borouge earns an EBITDA margin roughly three times the peer group's while nine of the eleven are loss-making. That is the advantaged-feedstock position, and it is the reason a peer median cannot be applied to it directly.
