Workbook

Sheet READ FIRST
A1: ADNOC Distribution — valuation model | B1: Abu Dhabi National Oil Company for Distribution PJSC · Abu Dhabi Securities Exchange · AED · study date 2026-08-09 · price date 2026-08-07
A3: THIS WORKBOOK CALCULATES | B3: Everything that can be derived from a driver is a live formula. Change a driver on the Assumptions sheet and the cost of capital, the glide, the discount factors, the cash-flow waterfall, the terminal block, the statements and every ratio all move.
A4: BLUE IS AN INPUT, BLACK IS A FORMULA | B4: That is the whole colour code. A blue cell is a number that came from somewhere; a black one is computed by the sheet from cells above it.
A5: ONLY THREE KINDS OF CELL ARE PASTED — 1. AUDITED AND DISCLOSED HISTORY | B5: The FY2023, FY2024 and FY2025 statement columns and the disclosed operating figures (volumes, station counts, segment gross profit). Where a line is both disclosed and derivable, the DISCLOSED figure is carried, because that is what the company reported.
A6: 2. THE OUTPUT OF THE UNIT BUILD | B6: The opening volumes, prices and margins per litre that the forecast grows from. Flattening the reconciliation behind them into this grid would make it unreadable.
A7: 3. WHOLE-MODEL RE-RUNS | B7: The probability map on the Monte Carlo sheet and the grids on the Sensitivity sheet. Each of those cells is a COMPLETE revaluation of the entire model at a different setting. THEY DO NOT REDRAW WHEN A DRIVER CHANGES. Every other number here does.
A8: THE CONTESTED JUDGEMENT IS CARRIED BOTH WAYS | B8: Inventory movements were AED 254m in FY2024, AED 335m in FY2025 and AED 762m in the first half of 2026 alone, against fuel volume growth of 1.6% in that half. Frame A normalises them to zero from FY2027; Frame B carries the FY2024-FY2025 average. Both run all the way through to a value per share and they are NEVER averaged together.
A9: WHERE TO START | B9: Summary for the answer, Assumptions for every driver, Segments for the volume and margin build, DCF for the waterfall and the terminal block, SOTP Bridge for the enterprise-to-equity walk and the terminal share of value.

Sheet Summary
A1: Summary valuation | B1: Frame A (AED) | C1: Frame B (AED) | D1: Note
A2: Discounted cash flow | B2: ='Fundamental Valuation'!B2 | C2: ='Fundamental Valuation'!C2 | D2: the cash the business generates
A3: Normalised earnings power | B3: ='Fundamental Valuation'!B3 | C3: ='Fundamental Valuation'!C3 | D3: structural gross profit only
A4: Relative multiples | B4: ='Fundamental Valuation'!B4 | C4: ='Fundamental Valuation'!C4 | D4: triangulated on the company’s own history
A5: Book value and sustainable return | B5: ='Fundamental Valuation'!B5 | C5: ='Fundamental Valuation'!C5 | D5: return on a deliberately thin equity base
A6: TERMINAL VALUE AS A PERCENTAGE OF ENTERPRISE VALUE, beside the cash-flow reading | B6: ='SOTP Bridge'!B5 | C6: ='SOTP Bridge'!C5 | D6: it is high, and it is stated here rather than buried
A7: WEIGHTED CENTRE | B7: ='Fundamental Valuation'!B7 | C7: ='Fundamental Valuation'!C7 | D7: the two frames are published side by side, never averaged
A8: Dividend capitalisation (unweighted fifth reading) | B8: ='Relative & Normalized'!B23
A9: Market price (AED) | B9: =Assumptions!$C$3

Sheet Fundamental Valuation
A1: The four lenses | B1: Frame A (AED) | C1: Frame B (AED) | D1: Weight | E1: Note
A2: Discounted cash flow | B2: ='SOTP Bridge'!B10 | C2: ='SOTP Bridge'!C10 | D2: 0.4 | E2: the cash the business generates
A3: Normalised earnings power | B3: ='Relative & Normalized'!B18 | C3: ='Relative & Normalized'!B18 | D3: 0.25 | E3: structural gross profit only
A4: Relative multiples | B4: ='Relative & Normalized'!B9 | C4: ='Relative & Normalized'!B11 | D4: 0.2 | E4: triangulated on the company’s own history
A5: Book value and sustainable return | B5: ='Relative & Normalized'!B22 | C5: ='Relative & Normalized'!B22 | D5: 0.15 | E5: return on a deliberately thin equity base
A6: SUM OF WEIGHTS (must be one) | D6: =SUM(D2:D5)
A7: WEIGHTED CENTRE | B7: =B2*D2+B3*D3+B4*D4+B5*D5 | C7: =C2*D2+C3*D3+C4*D4+C5*D5 | E7: the two frames are NEVER averaged into one number
A8: Market price (AED) | B8: =Assumptions!$C$3
A9: Difference against the market price | B9: =B7/B8-1 | C9: =C7/B8-1

Sheet Assumptions
A1: Assumption | B1: Basis | C1: FY2026E | D1: FY2027E | E1: FY2028E | F1: FY2029E | G1: FY2030E
A2: Market
A3: Share price (AED) | B3: close of 2026-08-07 | C3: 4.02
A4: Shares in issue (millions) | B4: issued capital note | C4: 12500
A5: Market capitalisation (AED m) | B5: calculated | C5: =Assumptions!$C$3*Assumptions!$C$4
A6: Cost of capital
A7: Government bond yield, local currency | B7: federal Treasury Bond auction, Jul-2026 | C7: 0.0448
A8: Sovereign default spread | B8: published country-risk file, Jan-2026 | C8: 0.0004
A9: Normalised risk-free rate = yield less sovereign spread | B9: calculated | C9: =Assumptions!$C$7-Assumptions!$C$8
A10: Total equity risk premium | B10: published country-risk file, Jan-2026 | C10: 0.0487
A11: Beta | B11: own five-year weekly regression against the published index of its own exchange | C11: 0.6494
A12: Cost of equity = normalised risk-free + beta x premium | B12: calculated | C12: =Assumptions!$C$9+Assumptions!$C$11*Assumptions!$C$10
A13: Credit margin over the sovereign | B13: company's own disclosed loan margin | C13: 0.006
A14: Cost of debt before tax = government yield + credit margin | B14: calculated | C14: =Assumptions!$C$7+Assumptions!$C$13
A15: Statutory tax rate | B15: federal corporate tax | C15: 0.09
A16: Effective tax rate applied to cash flows | B16: audited tax reconciliation, FY2025 | C16: 0.1017
A17: Cost of debt after tax = before tax x (1 less statutory rate) | B17: calculated | C17: =Assumptions!$C$14*(1-Assumptions!$C$15)
A18: Net debt excluding leases (AED m) | B18: disclosure, FY2025 balance sheet | C18: 2985.121
A19: Equity weight = market capitalisation / (market capitalisation + net debt) | B19: calculated | C19: =Assumptions!$C$5/(Assumptions!$C$5+Assumptions!$C$18)
A20: Debt weight = 1 less the equity weight | B20: calculated | C20: =1-Assumptions!$C$19
A21: Cost of capital, first forecast year | B21: calculated | C21: =Assumptions!$C$19*Assumptions!$C$12+Assumptions!$C$20*Assumptions!$C$17
A22: Terminal beta = the measured beta (flat, pegged market) | B22: calculated | C22: =Assumptions!$C$11
A23: Terminal cost of equity = normalised risk-free + terminal beta x premium | B23: calculated | C23: =Assumptions!$C$9+Assumptions!$C$22*Assumptions!$C$10
A24: Terminal debt weight = today's weight (flat, pegged market) | B24: calculated | C24: =Assumptions!$C$20
A25: Terminal cost of capital = terminal equity and debt weights on their costs | B25: calculated | C25: =(1-Assumptions!$C$24)*Assumptions!$C$23+Assumptions!$C$24*Assumptions!$C$17
A26: Long-run growth after the forecast period | B26: below domestic inflation | C26: 0.015
A27: Terminal return on invested capital | B27: fade from the realised return | C27: 0.25
A28: Volume and price drivers — built bottom-up
A29: Service-station network growth | B29: network +11.3% y/y to June 2026 | C29: 0.025 | D29: 0.045 | E29: 0.04 | F29: 0.035 | G29: 0.03
A30: Growth in litres sold per station | B30: realised MINUS 9.3% y/y to June 2026 | C30: -0.01 | D30: -0.025 | E30: -0.02 | F30: -0.01 | G30: -0.005
A31: Corporate fuel volume growth | B31: realised MINUS 2.6% in the first half | C31: 0 | D31: 0.005 | E31: 0.01 | F31: 0.01 | G31: 0.01
A32: Aviation fuel volume growth | B32: realised PLUS 53.9% in the first half, faded | C32: 0 | D32: 0.04 | E32: 0.03 | F32: 0.025 | G32: 0.02
A33: Realised retail price per litre (AED) | B33: crude-linked price path | C33: 2.42 | D33: 2.34 | E33: 2.363 | F33: 2.387 | G33: 2.411
A34: Realised corporate price per litre (AED) | B34: crude-linked price path | C34: 3.05 | D34: 2.95 | E34: 2.98 | F34: 3.01 | G34: 3.04
A35: Realised aviation price per litre (AED) | B35: crude-linked; jet prices ~50% above | C35: 4.55 | D35: 4.4 | E35: 4.44 | F35: 4.49 | G35: 4.53
A36: Retail margin per litre, escalation | B36: domestic escalator | C36: 0.02 | D36: 0.02 | E36: 0.02 | F36: 0.02 | G36: 0.02
A37: Commercial margin per litre, escalation | B37: realised step then domestic escalator | C37: 0.17 | D37: 0.02 | E37: 0.02 | F37: 0.02 | G37: 0.02
A38: Fuel transaction growth | B38: realised +4.9% in the first half | C38: 0.01 | D38: 0.025 | E38: 0.022 | F38: 0.02 | G38: 0.018
A39: Growth in the non-fuel conversion rate | B39: FELL from 27.0% to 26.2% y/y | C39: -0.005 | D39: -0.01 | E39: 0 | F39: 0.005 | G39: 0.005
A40: Growth in the average non-fuel basket | B40: domestic escalator plus food service | C40: 0.015 | D40: 0.035 | E40: 0.03 | F40: 0.03 | G40: 0.03
...

Sheet SOTP Bridge
A1: Enterprise value to equity value | B1: Frame A (AED m) | C1: Frame B (AED m)
A2: Present value of five years of free cash flow | B2: =DCF!G14 | C2: =DCF!G24
A3: Present value of the terminal value | B3: =DCF!B30 | C3: =DCF!B38
A4: ENTERPRISE VALUE | B4: =B2+B3 | C4: =C2+C3
A5: TERMINAL VALUE AS A PERCENTAGE OF ENTERPRISE VALUE | B5: =B3/B4 | C5: =C3/C4
A6: Less net debt excluding leases | B6: =-Assumptions!$C$18 | C6: =-Assumptions!$C$18
A7: Less lease liabilities | B7: =-Assumptions!$C$80 | C7: =-Assumptions!$C$80
A8: Less non-controlling interests | B8: =-Assumptions!$C$78 | C8: =-Assumptions!$C$78
A9: EQUITY VALUE | B9: =B4+B6+B7+B8 | C9: =C4+C6+C7+C8
A10: VALUE PER SHARE (AED) | B10: =B9/Assumptions!$C$4 | C10: =C9/Assumptions!$C$4

Sheet Segments
A1: The unit build — every forecast cell is a formula | B1: Anchor | C1: FY2026E | D1: FY2027E | E1: FY2028E | F1: FY2029E
A2: The anchor column is the ANNUALISED DISCLOSED FIRST HALF of 2026, not FY2025: two quarters of the study year are already on the public record. The first forecast column therefore carries the second-half shape on that realised run rate, and growth proper begins in FY2027.
A3: Service stations | B3: 1045 | C3: =Assumptions!$C$59*(1+Assumptions!C$29) | D3: =C3*(1+Assumptions!D$29) | E3: =D3*(1+Assumptions!E$29) | F3: =E3*(1+Assumptions!F$29) | G3: =F3*(1+Assumptions!G$29)
A4: Litres sold per station (million) | B4: 10.288995 | C4: =Assumptions!$C$61*(1+Assumptions!C$30) | D4: =C4*(1+Assumptions!D$30) | E4: =D4*(1+Assumptions!E$30) | F4: =E4*(1+Assumptions!F$30) | G4: =F4*(1+Assumptions!G$30)
A5: RETAIL FUEL VOLUME = stations x litres per station | B5: 10752 | C5: =C3*C4 | D5: =D3*D4 | E5: =E3*E4 | F5: =F3*F4 | G5: =G3*G4
A6: Corporate fuel volume (million litres) | B6: 4030 | C6: =Assumptions!$C$62*(1+Assumptions!C$31) | D6: =C6*(1+Assumptions!D$31) | E6: =D6*(1+Assumptions!E$31) | F6: =E6*(1+Assumptions!F$31) | G6: =F6*(1+Assumptions!G$31)
A7: Aviation fuel volume (million litres) | B7: 714 | C7: =Assumptions!$C$63*(1+Assumptions!C$32) | D7: =C7*(1+Assumptions!D$32) | E7: =D7*(1+Assumptions!E$32) | F7: =E7*(1+Assumptions!F$32) | G7: =F7*(1+Assumptions!G$32)
A8: Commercial fuel volume = corporate + aviation | B8: 4744 | C8: =C6+C7 | D8: =D6+D7 | E8: =E6+E7 | F8: =F6+F7 | G8: =G6+G7
A9: TOTAL FUEL VOLUME | B9: 15496 | C9: =C5+C8 | D9: =D5+D8 | E9: =E5+E8 | F9: =F5+F8 | G9: =G5+G8
A10: Realised retail price per litre (AED) | B10: 2.4497703 | C10: =Assumptions!C$33 | D10: =Assumptions!D$33 | E10: =Assumptions!E$33 | F10: =Assumptions!F$33 | G10: =Assumptions!G$33
A11: Realised corporate price per litre (AED) | B11: 3.1178045 | C11: =Assumptions!C$34 | D11: =Assumptions!D$34 | E11: =Assumptions!E$34 | F11: =Assumptions!F$34 | G11: =Assumptions!G$34
A12: Realised aviation price per litre (AED) | B12: 4.6365322 | C12: =Assumptions!C$35 | D12: =Assumptions!D$35 | E12: =Assumptions!E$35 | F12: =Assumptions!F$35 | G12: =Assumptions!G$35
A13: Retail fuel revenue = volume x price | B13: 26339.93 | C13: =C5*C10 | D13: =D5*D10 | E13: =E5*E10 | F13: =F5*F10 | G13: =G5*G10
A14: Corporate revenue = volume x price | B14: 12564.752 | C14: =C6*C11 | D14: =D6*D11 | E14: =E6*E11 | F14: =F6*F11 | G14: =G6*G11
A15: Aviation revenue = volume x price | B15: 3310.484 | C15: =C7*C12 | D15: =D7*D12 | E15: =E7*E12 | F15: =F7*F12 | G15: =G7*G12
A16: Commercial revenue = corporate + aviation | B16: 15875.236 | C16: =C14+C15 | D16: =D14+D15 | E16: =E14+E15 | F16: =F14+F15 | G16: =G14+G15
A17: Blended commercial price per litre — AN OUTPUT of the mix | B17: 3.346382 | C17: =C16/C8 | D17: =D16/D8 | E17: =E16/E8 | F17: =F16/F8 | G17: =G16/G8
A18: Fuel transactions (million) | B18: 201.8 | C18: =Assumptions!$C$64*(1+Assumptions!C$38) | D18: =C18*(1+Assumptions!D$38) | E18: =D18*(1+Assumptions!E$38) | F18: =E18*(1+Assumptions!F$38) | G18: =F18*(1+Assumptions!G$38)
A19: Non-fuel conversion rate | B19: 0.26164519 | C19: =Assumptions!$C$65*(1+Assumptions!C$39) | D19: =C19*(1+Assumptions!D$39) | E19: =D19*(1+Assumptions!E$39) | F19: =E19*(1+Assumptions!F$39) | G19: =F19*(1+Assumptions!G$39)
A20: Non-fuel transactions = fuel transactions x conversion | B20: 52.8 | C20: =C18*C19 | D20: =D18*D19 | E20: =E18*E19 | F20: =F18*F19 | G20: =G18*G19
A21: Average non-fuel basket (AED) | B21: 35.129583 | C21: =Assumptions!$C$66*(1+Assumptions!C$40) | D21: =C21*(1+Assumptions!D$40) | E21: =D21*(1+Assumptions!E$40) | F21: =E21*(1+Assumptions!F$40) | G21: =F21*(1+Assumptions!G$40)
A22: Non-fuel revenue = transactions x basket | B22: 1854.842 | C22: =C20*C21 | D22: =D20*D21 | E22: =E20*E21 | F22: =F20*F21 | G22: =G20*G21
A23: TOTAL REVENUE | B23: 44070.008 | C23: =C13+C16+C22 | D23: =D13+D16+D22 | E23: =E13+E16+E22 | F23: =F13+F16+F22 | G23: =G13+G16+G22
A24: Retail margin per litre (AED) | B24: 0.35974702 | C24: =Assumptions!$C$70*(1+Assumptions!C$36) | D24: =C24*(1+Assumptions!D$36) | E24: =D24*(1+Assumptions!E$36) | F24: =E24*(1+Assumptions!F$36) | G24: =F24*(1+Assumptions!G$36)
A25: Commercial margin per litre (AED) — blended, split NOT disclosed | B25: 0.43634064 | C25: =Assumptions!$C$71*(1+Assumptions!C$37) | D25: =C25*(1+Assumptions!D$37) | E25: =D25*(1+Assumptions!E$37) | F25: =E25*(1+Assumptions!F$37) | G25: =F25*(1+Assumptions!G$37)
A26: Retail fuel gross profit = volume x margin | B26: 3868 | C26: =C5*C24 | D26: =D5*D24 | E26: =E5*E24 | F26: =F5*F24 | G26: =G5*G24
A27: Commercial gross profit = volume x margin | B27: 2070 | C27: =C8*C25 | D27: =D8*D25 | E27: =E8*E25 | F27: =F8*F25 | G27: =G8*G25
A28: Non-fuel gross profit = revenue x margin | B28: 1044 | C28: =C22*Assumptions!C$41 | D28: =D22*Assumptions!D$41 | E28: =E22*Assumptions!E$41 | F28: =F22*Assumptions!F$41 | G28: =G22*Assumptions!G$41
A29: STRUCTURAL GROSS PROFIT | B29: 6980.204 | C29: =C26+C27+C28 | D29: =D26+D27+D28 | E29: =E26+E27+E28 | F29: =F26+F27+F28 | G29: =G26+G27+G28
A30: Inventory movement — Frame A, normalised | B30: 762 | C30: =Assumptions!C$42 | D30: =Assumptions!D$42 | E30: =Assumptions!E$42 | F30: =Assumptions!F$42 | G30: =Assumptions!G$42
A31: Inventory movement — Frame B, through-cycle | B31: 762 | C31: =Assumptions!C$43 | D31: =Assumptions!D$43 | E31: =Assumptions!E$43 | F31: =Assumptions!F$43 | G31: =Assumptions!G$43
A32: GROSS PROFIT — Frame A | B32: 8504.204 | C32: =C29+C30 | D32: =D29+D30 | E32: =E29+E30 | F32: =F29+F30 | G32: =G29+G30
A33: GROSS PROFIT — Frame B | B33: 8504.204 | C33: =C29+C31 | D33: =D29+D31 | E33: =E29+E31 | F33: =F29+F31 | G33: =G29+G31
A34: The asset base, rolled — depreciation and capital spending are outputs of it, not pasted arrays
A35: Opening fixed and right-of-use base | C35: =Assumptions!$C$75 | D35: =C41 | E35: =D41 | F35: =E41 | G35: =F41
A36: Depreciation = opening base x the measured rate | C36: =C35*Assumptions!$C$50 | D36: =D35*Assumptions!$C$50 | E36: =E35*Assumptions!$C$50 | F36: =F35*Assumptions!$C$50 | G36: =G35*Assumptions!$C$50
A37: Maintenance capital spending = opening base x the maintenance rate | C37: =C35*Assumptions!$C$51 | D37: =D35*Assumptions!$C$51 | E37: =E35*Assumptions!$C$51 | F37: =F35*Assumptions!$C$51 | G37: =G35*Assumptions!$C$51
A38: Stations added | C38: =C3-Assumptions!$C$60 | D38: =D3-C3 | E38: =E3-D3 | F38: =F3-E3 | G38: =G3-F3
A39: Growth capital spending = stations added x cost per station | C39: =C38*Assumptions!$C$52 | D39: =D38*Assumptions!$C$52 | E39: =E38*Assumptions!$C$52 | F39: =F38*Assumptions!$C$52 | G39: =G38*Assumptions!$C$52
A40: TOTAL CAPITAL SPENDING = maintenance + growth | C40: =C37+C39 | D40: =D37+D39 | E40: =E37+E39 | F40: =F37+F39 | G40: =G37+G39
...

Sheet Relative & Normalized
A1: Relative multiples and normalised earnings power | B1: Frame A | C1: Frame B | D1: Basis
A2: Triangulation: the reference multiple is the AVERAGE of three independently-derived readings, taken on the sheet rather than asserted.
A3: Own trailing multiple today | B3: =Assumptions!$C$3/'Income Statement'!D19 | D3: traded price over the FY2025 audited earnings per share
A4: Own three-year average multiple | B4: =(Assumptions!$C$3/'Income Statement'!B19+Assumptions!$C$3/'Income Statement'!C19+Assumptions!$C$3/'Income Statement'!D19)/3 | D4: traded price against each audited year, averaged
A5: Retention the growth rate requires = growth / return on equity | B5: =Assumptions!$C$26/0.8077013806 | D5: the sustainable-growth identity g = retention x ROE
A6: Payout consistent with that growth = 1 less the retention | B6: =1-B5
A7: REFERENCE MULTIPLE — what the company’s own economics justify | B7: =B6*(1+Assumptions!$C$26)/(Assumptions!$C$12-Assumptions!$C$26) | D7: payout x (1 + growth) / (cost of equity less growth), on the payout the growth rate itself implies — NOT the realised payout and NOT the policy floor, either of which breaks the identity
A8: Reference multiple carried into the lens | B8: =B7 | D8: the fundamentals leg ALONE. The two traded multiples above are published as context and are deliberately NOT averaged in: both are the traded price divided by earnings, so averaging them would anchor the lens to the price it is being compared against
A9: RELATIVE MULTIPLES READING (AED a share) | B9: =B8*'Income Statement'!E19 | D9: reference multiple on the first forecast year
A10: First forecast year earnings per share — Frame B (AED) | B10: =(DCF!B18+Assumptions!$C$84-Assumptions!$C$83)*(1-Assumptions!$C$16)/Assumptions!$C$4-Assumptions!$C$85/Assumptions!$C$4 | D10: the same construction as the income statement, on Frame B earnings
A11: RELATIVE MULTIPLES READING — Frame B (AED a share) | B11: =B8*B10 | D11: the same reference multiple on Frame B earnings
A12: Normalised EBITDA — structural gross profit only, no inventory movement | B12: =Segments!C29+'Income Statement'!E5+'Income Statement'!E6+'Income Statement'!E7
A13: Normalised EBIT | B13: =B12-Assumptions!C$48
A14: Normalised NOPAT | B14: =B13*(1-Assumptions!$C$16)
A15: Reinvestment this perpetuity must fund = growth / return on capital | B15: =Assumptions!$C$26/Assumptions!$C$27
A16: Normalised enterprise value = NOPAT x (1 less reinvestment) / (cost of capital less growth) | B16: =B14*(1-B15)/(Assumptions!$C$21-Assumptions!$C$26) | D16: the identity g = ROIC x reinvestment governs EVERY perpetuity, not only the cash-flow model terminal block. This lens previously credited growth for free
A17: Normalised equity value | B17: =B16-Assumptions!$C$18-Assumptions!$C$80-Assumptions!$C$78
A18: NORMALISED EARNINGS POWER READING (AED a share) | B18: =B17/Assumptions!$C$4
A19: Book value per share (AED) | B19: =Assumptions!$C$77/Assumptions!$C$4
A20: Sustainable return on equity — the three-year mean | B20: =('Income Statement'!B18/3472.066+'Income Statement'!C18/2991.839+'Income Statement'!D18/3230.423)/3
A21: Justified multiple of book = (return less growth) / (cost of equity less growth) | B21: =(B20-Assumptions!$C$26)/(Assumptions!$C$12-Assumptions!$C$26)
A22: BOOK VALUE AND SUSTAINABLE RETURN READING (AED a share) | B22: =B19*B21
A23: DIVIDEND CAPITALISATION READING (AED a share, unweighted) | B23: =Assumptions!$C$56/Assumptions!$C$12 | D23: the dividend is a FIXED commitment held flat from 2024 through 2030, so it is valued flat. Growing it credited growth the policy does not promise

Sheet DCF
A1: The discounted cash flow | B1: FY2026E | C1: FY2027E | D1: FY2028E | E1: FY2029E | F1: FY2030E | G1: Total
A2: Glide fraction toward the terminal cost of capital | B2: =(1)/5 | C2: =(2)/5 | D2: =(3)/5 | E2: =(4)/5 | F2: =(5)/5
A3: Discount rate = first-year rate + glide x (terminal less first-year) | B3: =Assumptions!$C$21+B2*(Assumptions!$C$25-Assumptions!$C$21) | C3: =Assumptions!$C$21+C2*(Assumptions!$C$25-Assumptions!$C$21) | D3: =Assumptions!$C$21+D2*(Assumptions!$C$25-Assumptions!$C$21) | E3: =Assumptions!$C$21+E2*(Assumptions!$C$25-Assumptions!$C$21) | F3: =Assumptions!$C$21+F2*(Assumptions!$C$25-Assumptions!$C$21)
A4: Discount factor (compounding) | B4: =1/(1+B3) | C4: =B4/(1+C3) | D4: =C4/(1+D3) | E4: =D4/(1+E3) | F4: =E4/(1+F3)
A5: FRAME A — inventory movements normalised to zero from FY2027
A6: EBITDA — Frame A | B6: =Segments!C32-Assumptions!$C$73*0+'Income Statement'!E5+'Income Statement'!E6+'Income Statement'!E7 | C6: =Segments!D32-Assumptions!$C$73*0+'Income Statement'!F5+'Income Statement'!F6+'Income Statement'!F7 | D6: =Segments!E32-Assumptions!$C$73*0+'Income Statement'!G5+'Income Statement'!G6+'Income Statement'!G7 | E6: =Segments!F32-Assumptions!$C$73*0+'Income Statement'!H5+'Income Statement'!H6+'Income Statement'!H7 | F6: =Segments!G32-Assumptions!$C$73*0+'Income Statement'!I5+'Income Statement'!I6+'Income Statement'!I7
A7: Less depreciation and amortisation | B7: =-Assumptions!C$48 | C7: =-Assumptions!D$48 | D7: =-Assumptions!E$48 | E7: =-Assumptions!F$48 | F7: =-Assumptions!G$48
A8: EBIT — Frame A | B8: =B6+B7 | C8: =C6+C7 | D8: =D6+D7 | E8: =E6+E7 | F8: =F6+F7
A9: NOPAT = EBIT x (1 less the tax rate) | B9: =B8*(1-Assumptions!$C$16) | C9: =C8*(1-Assumptions!$C$16) | D9: =D8*(1-Assumptions!$C$16) | E9: =E8*(1-Assumptions!$C$16) | F9: =F8*(1-Assumptions!$C$16)
A10: Add back depreciation and amortisation | B10: =Assumptions!C$48 | C10: =Assumptions!D$48 | D10: =Assumptions!E$48 | E10: =Assumptions!F$48 | F10: =Assumptions!G$48
A11: Less capital expenditure | B11: =-Assumptions!C$49 | C11: =-Assumptions!D$49 | D11: =-Assumptions!E$49 | E11: =-Assumptions!F$49 | F11: =-Assumptions!G$49
A12: Less increase in working capital | B12: ='Cash Flow'!E7 | C12: ='Cash Flow'!F7 | D12: ='Cash Flow'!G7 | E12: ='Cash Flow'!H7 | F12: ='Cash Flow'!I7
A13: FREE CASH FLOW TO THE FIRM — Frame A | B13: =B9+B10+B11+B12 | C13: =C9+C10+C11+C12 | D13: =D9+D10+D11+D12 | E13: =E9+E10+E11+E12 | F13: =F9+F10+F11+F12
A14: PRESENT VALUE of free cash flow | B14: =B13*B4 | C14: =C13*C4 | D14: =D13*D4 | E14: =E13*E4 | F14: =F13*F4 | G14: =SUM(B14:F14)
A15: FRAME B — inventory movements carried at the through-cycle average
A16: EBITDA — Frame B | B16: =Segments!C33-Assumptions!$C$73*0+'Income Statement'!E5+'Income Statement'!E6+'Income Statement'!E7 | C16: =Segments!D33-Assumptions!$C$73*0+'Income Statement'!F5+'Income Statement'!F6+'Income Statement'!F7 | D16: =Segments!E33-Assumptions!$C$73*0+'Income Statement'!G5+'Income Statement'!G6+'Income Statement'!G7 | E16: =Segments!F33-Assumptions!$C$73*0+'Income Statement'!H5+'Income Statement'!H6+'Income Statement'!H7 | F16: =Segments!G33-Assumptions!$C$73*0+'Income Statement'!I5+'Income Statement'!I6+'Income Statement'!I7
A17: Less depreciation and amortisation | B17: =-Assumptions!C$48 | C17: =-Assumptions!D$48 | D17: =-Assumptions!E$48 | E17: =-Assumptions!F$48 | F17: =-Assumptions!G$48
A18: EBIT — Frame B | B18: =B16+B17 | C18: =C16+C17 | D18: =D16+D17 | E18: =E16+E17 | F18: =F16+F17
A19: NOPAT = EBIT x (1 less the tax rate) | B19: =B18*(1-Assumptions!$C$16) | C19: =C18*(1-Assumptions!$C$16) | D19: =D18*(1-Assumptions!$C$16) | E19: =E18*(1-Assumptions!$C$16) | F19: =F18*(1-Assumptions!$C$16)
A20: Add back depreciation and amortisation | B20: =Assumptions!C$48 | C20: =Assumptions!D$48 | D20: =Assumptions!E$48 | E20: =Assumptions!F$48 | F20: =Assumptions!G$48
A21: Less capital expenditure | B21: =-Assumptions!C$49 | C21: =-Assumptions!D$49 | D21: =-Assumptions!E$49 | E21: =-Assumptions!F$49 | F21: =-Assumptions!G$49
A22: Less increase in working capital | B22: ='Cash Flow'!E7 | C22: ='Cash Flow'!F7 | D22: ='Cash Flow'!G7 | E22: ='Cash Flow'!H7 | F22: ='Cash Flow'!I7
A23: FREE CASH FLOW TO THE FIRM — Frame B | B23: =B19+B20+B21+B22 | C23: =C19+C20+C21+C22 | D23: =D19+D20+D21+D22 | E23: =E19+E20+E21+E22 | F23: =F19+F20+F21+F22
A24: PRESENT VALUE of free cash flow | B24: =B23*B4 | C24: =C23*C4 | D24: =D23*D4 | E24: =E23*E4 | F24: =F23*F4 | G24: =SUM(B24:F24)
A25: TERMINAL BLOCK — Frame A
A26: Reinvestment rate = long-run growth / terminal return on capital | B26: =Assumptions!$C$26/Assumptions!$C$27
A27: Terminal NOPAT = final-year NOPAT x (1 + growth) | B27: =F9*(1+Assumptions!$C$26)
A28: Terminal free cash flow = terminal NOPAT x (1 less reinvestment) | B28: =B27*(1-B26)
A29: Terminal value = terminal free cash flow / (terminal rate less growth) | B29: =B28/(Assumptions!$C$25-Assumptions!$C$26)
A30: Present value of the terminal value | B30: =B29*F4
A31: ENTERPRISE VALUE | B31: =G14+B30
A32: TERMINAL VALUE AS A PERCENTAGE OF ENTERPRISE VALUE | B32: =B30/B31
A33: TERMINAL BLOCK — Frame B
A34: Reinvestment rate = long-run growth / terminal return on capital | B34: =Assumptions!$C$26/Assumptions!$C$27
A35: Terminal NOPAT = final-year NOPAT x (1 + growth) | B35: =F19*(1+Assumptions!$C$26)
A36: Terminal free cash flow = terminal NOPAT x (1 less reinvestment) | B36: =B35*(1-B34)
A37: Terminal value = terminal free cash flow / (terminal rate less growth) | B37: =B36/(Assumptions!$C$25-Assumptions!$C$26)
A38: Present value of the terminal value | B38: =B37*F4
A39: ENTERPRISE VALUE | B39: =G24+B38
A40: TERMINAL VALUE AS A PERCENTAGE OF ENTERPRISE VALUE | B40: =B38/B39

Sheet Income Statement
A1: AED million | B1: FY2023 | C1: FY2024 | D1: FY2025 | E1: FY2026E | F1: FY2027E | G1: FY2028E | H1: FY2029E | I1: FY2030E
A2: Revenue | B2: 34629.178 | C2: 35453.716 | D2: 35896.617 | E2: =Segments!C23 | F2: =Segments!D23 | G2: =Segments!E23 | H2: =Segments!F23 | I2: =Segments!G23
A3: Gross profit — Frame A | B3: 5836.285 | C3: 6216.032 | D3: 6945.79 | E3: =Segments!C32 | F3: =Segments!D32 | G3: =Segments!E32 | H3: =Segments!F32 | I3: =Segments!G32
A4: Gross margin | B4: 0.16853663 | C4: 0.17532808 | D4: 0.19349428 | E4: =E3/E2 | F4: =F3/F2 | G4: =G3/G2 | H4: =H3/H2 | I4: =I3/I2
A5: Cash operating expenses | B5: -2219.973 | C5: -2409.135 | D5: -2547.6 | E5: =-Assumptions!$C$73*(1+Assumptions!C$45) | F5: =E5*(1+Assumptions!D$45) | G5: =F5*(1+Assumptions!E$45) | H5: =G5*(1+Assumptions!F$45) | I5: =H5*(1+Assumptions!G$45)
A6: Other income | B6: 145.645 | C6: 138.059 | D6: 167.665 | E6: =Assumptions!$C$74*(1+Assumptions!C$46) | F6: =E6*(1+Assumptions!D$46) | G6: =F6*(1+Assumptions!E$46) | H6: =G6*(1+Assumptions!F$46) | I6: =H6*(1+Assumptions!G$46)
A7: Impairments and other operating expenses | B7: -82.143 | C7: -90.254 | D7: -284.305 | E7: =-Assumptions!C$47 | F7: =-Assumptions!D$47 | G7: =-Assumptions!E$47 | H7: =-Assumptions!F$47 | I7: =-Assumptions!G$47
A8: EBITDA | B8: 3679.814 | C8: 3854.702 | D8: 4281.55 | E8: =E3+E5+E6+E7 | F8: =F3+F5+F6+F7 | G8: =G3+G5+G6+G7 | H8: =H3+H5+H6+H7 | I8: =I3+I5+I6+I7
A9: EBITDA margin | B9: 0.10626339 | C9: 0.10872491 | D9: 0.11927447 | E9: =E8/E2 | F9: =F8/F2 | G9: =G8/G2 | H9: =H8/H2 | I9: =I8/I2
A10: Depreciation and amortisation | B10: -696.565 | C10: -785.807 | D10: -775.946 | E10: =-Assumptions!C$48 | F10: =-Assumptions!D$48 | G10: =-Assumptions!E$48 | H10: =-Assumptions!F$48 | I10: =-Assumptions!G$48
A11: EBIT | B11: 2983.249 | C11: 3068.895 | D11: 3505.604 | E11: =E8+E10 | F11: =F8+F10 | G11: =G8+G10 | H11: =H8+H10 | I11: =I8+I10
A12: Interest income | B12: 98.834 | C12: 143.893 | D12: 71.274 | E12: =Assumptions!$C$84 | F12: =Assumptions!$C$84 | G12: =Assumptions!$C$84 | H12: =Assumptions!$C$84 | I12: =Assumptions!$C$84
A13: Finance costs | B13: -432.757 | C13: -457.111 | D13: -402.945 | E13: =-Assumptions!$C$83 | F13: =-Assumptions!$C$83 | G13: =-Assumptions!$C$83 | H13: =-Assumptions!$C$83 | I13: =-Assumptions!$C$83
A14: Profit before tax | B14: 2649.326 | C14: 2755.677 | D14: 3173.933 | E14: =E11+E12+E13 | F14: =F11+F12+F13 | G14: =G11+G12+G13 | H14: =H11+H12+H13 | I14: =I11+I12+I13
A15: Income tax | B15: -18.837 | C15: -283.394 | D15: -322.891 | E15: =-E14*Assumptions!$C$16 | F15: =-F14*Assumptions!$C$16 | G15: =-G14*Assumptions!$C$16 | H15: =-H14*Assumptions!$C$16 | I15: =-I14*Assumptions!$C$16
A16: Profit for the year | B16: 2630.489 | C16: 2472.283 | D16: 2851.042 | E16: =E14+E15 | F16: =F14+F15 | G16: =G14+G15 | H16: =H14+H15 | I16: =I14+I15
A17: Non-controlling interests | B17: -29.068 | C17: -52.008 | D17: -57.042 | E17: =-Assumptions!$C$85 | F17: =-Assumptions!$C$85 | G17: =-Assumptions!$C$85 | H17: =-Assumptions!$C$85 | I17: =-Assumptions!$C$85
A18: Profit attributable to owners | B18: 2601.421 | C18: 2420.275 | D18: 2794 | E18: =E16+E17 | F18: =F16+F17 | G18: =G16+G17 | H18: =H16+H17 | I18: =I16+I17
A19: Earnings per share (AED) | B19: 0.208 | C19: 0.194 | D19: 0.224 | E19: =E18/Assumptions!$C$4 | F19: =F18/Assumptions!$C$4 | G19: =G18/Assumptions!$C$4 | H19: =H18/Assumptions!$C$4 | I19: =I18/Assumptions!$C$4
A20: Dividend — the fixed policy commitment | E20: =Assumptions!$C$56*Assumptions!$C$4 | F20: =Assumptions!$C$56*Assumptions!$C$4 | G20: =Assumptions!$C$56*Assumptions!$C$4 | H20: =Assumptions!$C$56*Assumptions!$C$4 | I20: =Assumptions!$C$56*Assumptions!$C$4
A21: Dividend — the 75% of profit minimum | E21: =Assumptions!$C$57*E18 | F21: =Assumptions!$C$57*F18 | G21: =Assumptions!$C$57*G18 | H21: =Assumptions!$C$57*H18 | I21: =Assumptions!$C$57*I18
A22: DIVIDEND PAID = the higher of the two | E22: =MAX(E20,E21) | F22: =MAX(F20,F21) | G22: =MAX(G20,G21) | H22: =MAX(H20,H21) | I22: =MAX(I20,I21)

Sheet Balance Sheet
A1: AED million | B1: FY2023 | C1: FY2024 | D1: FY2025 | E1: FY2026E | F1: FY2027E | G1: FY2028E | H1: FY2029E | I1: FY2030E
A2: Fixed and right-of-use assets | B2: 8968.079 | C2: 9278.529 | D2: 9478.001 | E2: =Assumptions!$C$75+Assumptions!C$49-Assumptions!C$48 | F2: =E2+Assumptions!D$49-Assumptions!D$48 | G2: =F2+Assumptions!E$49-Assumptions!E$48 | H2: =G2+Assumptions!F$49-Assumptions!F$48 | I2: =H2+Assumptions!G$49-Assumptions!G$48
A3: Goodwill, intangibles and other non-current | B3: 1109.994 | C3: 661.41 | D3: 671.273 | E3: =Assumptions!$C$76 | F3: =Assumptions!$C$76 | G3: =Assumptions!$C$76 | H3: =Assumptions!$C$76 | I3: =Assumptions!$C$76
A4: Inventories | B4: 1294.423 | C4: 1619.887 | D4: 1574.254 | E4: =Assumptions!$C$54/365*('Income Statement'!E2-'Income Statement'!E3) | F4: =Assumptions!$C$54/365*('Income Statement'!F2-'Income Statement'!F3) | G4: =Assumptions!$C$54/365*('Income Statement'!G2-'Income Statement'!G3) | H4: =Assumptions!$C$54/365*('Income Statement'!H2-'Income Statement'!H3) | I4: =Assumptions!$C$54/365*('Income Statement'!I2-'Income Statement'!I3)
A5: Receivables including related parties | B5: 4324.971 | C5: 3686.705 | D5: 3390.983 | E5: =Assumptions!$C$53/365*'Income Statement'!E2 | F5: =Assumptions!$C$53/365*'Income Statement'!F2 | G5: =Assumptions!$C$53/365*'Income Statement'!G2 | H5: =Assumptions!$C$53/365*'Income Statement'!H2 | I5: =Assumptions!$C$53/365*'Income Statement'!I2
A6: Cash and term deposits | B6: 3194.162 | C6: 2934.263 | D6: 2560.854 | E6: =E8+E9+E10+E11+E12+E13-E2-E3-E4-E5 | F6: =F8+F9+F10+F11+F12+F13-F2-F3-F4-F5 | G6: =G8+G9+G10+G11+G12+G13-G2-G3-G4-G5 | H6: =H8+H9+H10+H11+H12+H13-H2-H3-H4-H5 | I6: =I8+I9+I10+I11+I12+I13-I2-I3-I4-I5
A7: TOTAL ASSETS | B7: 18891.629 | C7: 18180.794 | D7: 17675.365 | E7: =E2+E3+E4+E5+E6 | F7: =F2+F3+F4+F5+F6 | G7: =G2+G3+G4+G5+G6 | H7: =H2+H3+H4+H5+H6 | I7: =I2+I3+I4+I5+I6
A8: Equity attributable to owners | B8: 3472.066 | C8: 2991.839 | D8: 3230.423 | E8: =Assumptions!$C$77+'Income Statement'!E18-'Income Statement'!E22 | F8: =E8+'Income Statement'!F18-'Income Statement'!F22 | G8: =F8+'Income Statement'!G18-'Income Statement'!G22 | H8: =G8+'Income Statement'!H18-'Income Statement'!H22 | I8: =H8+'Income Statement'!I18-'Income Statement'!I22
A9: Non-controlling interests | B9: 323.767 | C9: 189.437 | D9: 230.374 | E9: =Assumptions!$C$78+Assumptions!$C$85 | F9: =E9+Assumptions!$C$85 | G9: =F9+Assumptions!$C$85 | H9: =G9+Assumptions!$C$85 | I9: =H9+Assumptions!$C$85
A10: Borrowings | B10: 5492.28 | C10: 5590.644 | D10: 5545.975 | E10: =Assumptions!$C$79 | F10: =Assumptions!$C$79 | G10: =Assumptions!$C$79 | H10: =Assumptions!$C$79 | I10: =Assumptions!$C$79
A11: Lease liabilities | B11: 1747.264 | C11: 1722.622 | D11: 1446.327 | E11: =Assumptions!$C$80 | F11: =Assumptions!$C$80 | G11: =Assumptions!$C$80 | H11: =Assumptions!$C$80 | I11: =Assumptions!$C$80
A12: Provisions, deferred tax and other | D12: 460.12 | E12: =Assumptions!$C$81 | F12: =Assumptions!$C$81 | G12: =Assumptions!$C$81 | H12: =Assumptions!$C$81 | I12: =Assumptions!$C$81
A13: Payables including related parties | B13: 7368.986 | C13: 7236.399 | D13: 6762.146 | E13: =Assumptions!$C$55/365*('Income Statement'!E2-'Income Statement'!E3) | F13: =Assumptions!$C$55/365*('Income Statement'!F2-'Income Statement'!F3) | G13: =Assumptions!$C$55/365*('Income Statement'!G2-'Income Statement'!G3) | H13: =Assumptions!$C$55/365*('Income Statement'!H2-'Income Statement'!H3) | I13: =Assumptions!$C$55/365*('Income Statement'!I2-'Income Statement'!I3)
A14: TOTAL EQUITY AND LIABILITIES | B14: 18891.629 | C14: 18180.794 | D14: 17675.365 | E14: =E8+E9+E10+E11+E12+E13 | F14: =F8+F9+F10+F11+F12+F13 | G14: =G8+G9+G10+G11+G12+G13 | H14: =H8+H9+H10+H11+H12+H13 | I14: =I8+I9+I10+I11+I12+I13
A15: BALANCE CHECK (must be zero) | B15: 0 | C15: 0 | D15: 0 | E15: =E7-E14 | F15: =F7-F14 | G15: =G7-G14 | H15: =H7-H14 | I15: =I7-I14
A16: Net debt excluding leases | B16: 2298.118 | C16: 2656.381 | D16: 2985.121 | E16: =E10-E6 | F16: =F10-F6 | G16: =G10-G6 | H16: =H10-H6 | I16: =I10-I6
A17: Book value per share (AED) | B17: 0.27776528 | C17: 0.23934712 | D17: 0.25843384 | E17: =E8/Assumptions!$C$4 | F17: =F8/Assumptions!$C$4 | G17: =G8/Assumptions!$C$4 | H17: =H8/Assumptions!$C$4 | I17: =I8/Assumptions!$C$4

Sheet Cash Flow
A1: AED million | B1: FY2023 | C1: FY2024 | D1: FY2025 | E1: FY2026E | F1: FY2027E | G1: FY2028E | H1: FY2029E | I1: FY2030E
A2: EBIT | B2: 2983.249 | C2: 3068.895 | D2: 3505.604 | E2: ='Income Statement'!E11 | F2: ='Income Statement'!F11 | G2: ='Income Statement'!G11 | H2: ='Income Statement'!H11 | I2: ='Income Statement'!I11
A3: Tax rate applied to EBIT | B3: 0.0071101103 | C3: 0.10284006 | D3: 0.10173214 | E3: =Assumptions!$C$16 | F3: =Assumptions!$C$16 | G3: =Assumptions!$C$16 | H3: =Assumptions!$C$16 | I3: =Assumptions!$C$16
A4: NOPAT = EBIT x (1 less the tax rate) | B4: 2962.0378 | C4: 2753.2896 | D4: 3148.9714 | E4: =E2*(1-E3) | F4: =F2*(1-F3) | G4: =G2*(1-G3) | H4: =H2*(1-H3) | I4: =I2*(1-I3)
A5: Add back depreciation and amortisation | B5: 696.565 | C5: 785.807 | D5: 775.946 | E5: =Assumptions!C$48 | F5: =Assumptions!D$48 | G5: =Assumptions!E$48 | H5: =Assumptions!F$48 | I5: =Assumptions!G$48
A6: Less capital expenditure | B6: -1032.241 | C6: -1179.233 | D6: -1207.394 | E6: =-Assumptions!C$49 | F6: =-Assumptions!D$49 | G6: =-Assumptions!E$49 | H6: =-Assumptions!F$49 | I6: =-Assumptions!G$49
A7: Less increase in working capital | E7: =-('Balance Sheet'!E5+'Balance Sheet'!E4-'Balance Sheet'!E13-'Balance Sheet'!D5-'Balance Sheet'!D4+'Balance Sheet'!D13) | F7: =-('Balance Sheet'!F5+'Balance Sheet'!F4-'Balance Sheet'!F13-'Balance Sheet'!E5-'Balance Sheet'!E4+'Balance Sheet'!E13) | G7: =-('Balance Sheet'!G5+'Balance Sheet'!G4-'Balance Sheet'!G13-'Balance Sheet'!F5-'Balance Sheet'!F4+'Balance Sheet'!F13) | H7: =-('Balance Sheet'!H5+'Balance Sheet'!H4-'Balance Sheet'!H13-'Balance Sheet'!G5-'Balance Sheet'!G4+'Balance Sheet'!G13) | I7: =-('Balance Sheet'!I5+'Balance Sheet'!I4-'Balance Sheet'!I13-'Balance Sheet'!H5-'Balance Sheet'!H4+'Balance Sheet'!H13)
A8: FREE CASH FLOW TO THE FIRM | E8: =E4+E5+E6+E7 | F8: =F4+F5+F6+F7 | G8: =G4+G5+G6+G7 | H8: =H4+H5+H6+H7 | I8: =I4+I5+I6+I7
A9: Dividends paid | B9: -2622.89 | C9: -2613.7 | D9: -2599.146 | E9: =-'Income Statement'!E22 | F9: =-'Income Statement'!F22 | G9: =-'Income Statement'!G22 | H9: =-'Income Statement'!H22 | I9: =-'Income Statement'!I22

Sheet Summary Financials
A1: AED million | B1: FY2023 | C1: FY2024 | D1: FY2025 | E1: FY2026E | F1: FY2027E | G1: FY2028E | H1: FY2029E | I1: FY2030E
A2: Revenue | B2: 34629.178 | C2: 35453.716 | D2: 35896.617 | E2: ='Income Statement'!E2 | F2: ='Income Statement'!F2 | G2: ='Income Statement'!G2 | H2: ='Income Statement'!H2 | I2: ='Income Statement'!I2
A3: Gross profit | B3: 5836.285 | C3: 6216.032 | D3: 6945.79 | E3: ='Income Statement'!E3 | F3: ='Income Statement'!F3 | G3: ='Income Statement'!G3 | H3: ='Income Statement'!H3 | I3: ='Income Statement'!I3
A4: EBITDA | B4: 3679.814 | C4: 3854.702 | D4: 4281.55 | E4: ='Income Statement'!E8 | F4: ='Income Statement'!F8 | G4: ='Income Statement'!G8 | H4: ='Income Statement'!H8 | I4: ='Income Statement'!I8
A5: EBIT | B5: 2983.249 | C5: 3068.895 | D5: 3505.604 | E5: ='Income Statement'!E11 | F5: ='Income Statement'!F11 | G5: ='Income Statement'!G11 | H5: ='Income Statement'!H11 | I5: ='Income Statement'!I11
A6: Profit attributable to owners | B6: 2601.421 | C6: 2420.275 | D6: 2794 | E6: ='Income Statement'!E18 | F6: ='Income Statement'!F18 | G6: ='Income Statement'!G18 | H6: ='Income Statement'!H18 | I6: ='Income Statement'!I18
A7: Free cash flow to the firm | E7: ='Cash Flow'!E8 | F7: ='Cash Flow'!F8 | G7: ='Cash Flow'!G8 | H7: ='Cash Flow'!H8 | I7: ='Cash Flow'!I8

Sheet Monte Carlo
A1: Probability map | B1: One month | C1: Three months | D1: Note
A2: THESE CELLS ARE A WHOLE-MODEL RE-RUN — 50,000 simulated price paths each. They do NOT redraw when a driver on the Assumptions sheet changes.
A3: 5th percentile (AED) | B3: 3.6921834 | C3: 3.3906147
A4: 25th percentile (AED) | B4: 3.9175865 | C4: 3.7878802
A5: 50th percentile (AED) | B5: 4.0650549 | C5: 4.0584241
A6: 75th percentile (AED) | B6: 4.2188664 | C6: 4.3472742
A7: 95th percentile (AED) | B7: 4.4687106 | C7: 4.8622613
A8: Probability of finishing above the anchor | B8: 0.49132 | C8: 0.48872
A9: Probability of finishing 10% higher | B9: 0.04742 | C9: 0.17202
A10: Probability of finishing 10% lower | B10: 0.03952 | C10: 0.16112
A11: Probability of TOUCHING 10% higher | B11: 0.0768 | C11: 0.31482
A12: Probability of TOUCHING 10% lower | B12: 0.06074 | C12: 0.28772

Sheet Sensitivity
A1: Value per share (AED), Frame A | B1: 0.5% growth | C1: 1.0% growth | D1: 1.5% growth | E1: 2.0% growth | F1: 2.5% growth
A2: EACH CELL IS A COMPLETE REVALUATION of the whole model. These grids do NOT redraw when a driver changes.
A3: Terminal cost of capital 6.44% | B3: 5.0396248 | C3: 5.3472548 | D3: 5.7162136 | E3: 6.1672414 | F3: 6.7316188
A4: Terminal cost of capital 6.94% | B4: 4.6602911 | C4: 4.911618 | D4: 5.2082866 | E4: 5.5640769 | F4: 5.998983
A5: Terminal cost of capital 7.44% | B5: 4.3354363 | C5: 4.5434198 | D5: 4.7856344 | E5: 5.0715265 | F5: 5.4143707
A6: Terminal cost of capital 7.94% | B6: 4.0540722 | C6: 4.2280773 | D6: 4.4283843 | E6: 4.6616402 | F6: 4.9369377
A7: Terminal cost of capital 8.44% | B7: 3.8079801 | C7: 3.95493 | D7: 4.1223941 | E7: 4.315154 | F7: 4.5396023
A9: Single-driver sensitivity | B9: Input | C9: Value per share
A10: Terminal cost of capital | B10: 0.064354891 | C10: 5.7162136
A11: Terminal cost of capital | B11: 0.069354891 | C11: 5.2082866
A12: Terminal cost of capital | B12: 0.074354891 | C12: 4.7856344
A13: Terminal cost of capital | B13: 0.079354891 | C13: 4.4283843
A14: Terminal cost of capital | B14: 0.084354891 | C14: 4.1223941
A15: Long-run growth | B15: 0.005 | C15: 4.3354363
A16: Long-run growth | B16: 0.01 | C16: 4.5434198
A17: Long-run growth | B17: 0.015 | C17: 4.7856344
A18: Long-run growth | B18: 0.02 | C18: 5.0715265
A19: Long-run growth | B19: 0.025 | C19: 5.4143707
A20: Beta | B20: 0.45 | C20: 5.7232129
A21: Beta | B21: 0.55 | C21: 5.2138083
... A49: Capital expenditure | B49: 0.2 | C49: 4.7214104

Sheet Per-Share & Ratios
A1: Per share and ratios | B1: FY2023 | C1: FY2024 | D1: FY2025 | E1: FY2026E | F1: FY2027E | G1: FY2028E | H1: FY2029E | I1: FY2030E
A2: Earnings per share (AED) | B2: 0.208 | C2: 0.194 | D2: 0.224 | E2: ='Income Statement'!E19 | F2: ='Income Statement'!F19 | G2: ='Income Statement'!G19 | H2: ='Income Statement'!H19 | I2: ='Income Statement'!I19
A3: Book value per share (AED) | B3: 0.27776528 | C3: 0.23934712 | D3: 0.25843384 | E3: ='Balance Sheet'!E17 | F3: ='Balance Sheet'!F17 | G3: ='Balance Sheet'!G17 | H3: ='Balance Sheet'!H17 | I3: ='Balance Sheet'!I17
A4: Dividend per share (AED) | B4: 0.2098312 | C4: 0.209096 | D4: 0.20793168 | E4: =Assumptions!$C$56 | F4: =Assumptions!$C$56 | G4: =Assumptions!$C$56 | H4: =Assumptions!$C$56 | I4: =Assumptions!$C$56
A5: EBITDA margin | B5: 0.10626339 | C5: 0.10872491 | D5: 0.11927447 | E5: ='Income Statement'!E9 | F5: ='Income Statement'!F9 | G5: ='Income Statement'!G9 | H5: ='Income Statement'!H9 | I5: ='Income Statement'!I9
A6: Return on equity | B6: 0.74924296 | C6: 0.80895897 | D6: 0.86490221 | E6: ='Income Statement'!E18/'Balance Sheet'!E8 | F6: ='Income Statement'!F18/'Balance Sheet'!F8 | G6: ='Income Statement'!G18/'Balance Sheet'!G8 | H6: ='Income Statement'!H18/'Balance Sheet'!H8 | I6: ='Income Statement'!I18/'Balance Sheet'!I8
A7: Net debt to EBITDA | B7: 0.62452015 | C7: 0.68912746 | D7: 0.69720568 | E7: ='Balance Sheet'!E16/'Income Statement'!E8 | F7: ='Balance Sheet'!F16/'Income Statement'!F8 | G7: ='Balance Sheet'!G16/'Income Statement'!G8 | H7: ='Balance Sheet'!H16/'Income Statement'!H8 | I7: ='Balance Sheet'!I16/'Income Statement'!I8
A8: Return on capital employed | B8: 0.48954266 | C8: 0.52570663 | D8: 0.54384868 | E8: ='Income Statement'!E11/('Balance Sheet'!E8+'Balance Sheet'!E9+'Balance Sheet'!E16) | F8: ='Income Statement'!F11/('Balance Sheet'!F8+'Balance Sheet'!F9+'Balance Sheet'!F16) | G8: ='Income Statement'!G11/('Balance Sheet'!G8+'Balance Sheet'!G9+'Balance Sheet'!G16) | H8: ='Income Statement'!H11/('Balance Sheet'!H8+'Balance Sheet'!H9+'Balance Sheet'!H16) | I8: ='Income Statement'!I11/('Balance Sheet'!I8+'Balance Sheet'!I9+'Balance Sheet'!I16)

Sheet Peer & Sector
A1: Peer and sector evidence | B1: EV / EBITDA | C1: Role | D1: Note
A2: Peer observations are a CROSS-CHECK. They are not the source of any number in this valuation: the reference multiple is triangulated from the company’s own history on the Relative & Normalized sheet.
A3: Aldrees Petroleum and Transport Services | B3: 12.89 | C3: cross-check
A4: Saudi Automotive Services Company / SASCO | B4: 12.28 | C4: cross-check
A5: Alimentation Couche-Tard | B5: 10.66 | C5: cross-check
A6: Casey's General Stores | B6: 22.41 | C6: cross-check
A7: Murphy USA | B7: 10.03 | C7: cross-check
A8: OMV Petrom | B8: 9.91 | C8: cross-check
A9: Vibra Energia | B9: 7.7 | C9: cross-check
A10: Ultrapar Participacoes | B10: 6.8 | C10: cross-check
A11: PEER AVERAGE (context only) | B11: =AVERAGE(B3:B10) | C11: not used | D11: the spread across these names is more than three to one, across different fuel-pricing regimes
A12: This company, on the traded price | B12: =(Assumptions!$C$5+Assumptions!$C$18+Assumptions!$C$80)/'Income Statement'!D8 | C12: the subject
