Workbook

Sheet READ FIRST
A1: Testahil — Modon Holding PSC (ADX: MODON)
A3: Companion model · Independent Valuation Study · Educational analysis · Not investment advice
A5: What this workbook is. A transparent companion to the MODON valuation study. Every blue cell is an input;
A6: every black cell is a formula; green cells link across sheets.
A8: IT IS FORMULA-DRIVEN. Every figure that can be derived arithmetically from a driver is a live formula, so
A9: you can change a blue cell on Assumptions and watch the model reprice: the cost of capital is built from
A10: the AED government yield net of the sovereign spread, beta and the premium rather than pasted; the
A11: development backlog rolls forward in front of you (opening backlog + new sales − recognised revenue);
A12: the DCF waterfall chains EBITDA → EBIT → NOPAT → free cash flow → present value; the terminal block
A13: derives its reinvestment rate from growth over return on capital; and the income statement, balance
A14: sheet, cash flow, ratios and all four lenses chain off the same cells.
A16: THREE THINGS ARE PASTED VALUES, and it is worth knowing exactly which. First, audited and disclosed
... A54: Sensitivity · Per-Share & Ratios · Peer & Sector.

Sheet Summary
A1: Summary — valuation at a glance
A2: All values link live to their source sheets
A4: Lens | B4: Bear | C4: Base | D4: Bull | E4: Weight | F4: Contribution | G4: vs spot
A5: Discounted cash flow (primary) | B5: 4.1793912 | C5: =DCF!C54 | D5: 7.3934302 | E5: =Assumptions!$C$57 | F5: =C5*E5 | G5: =C5/$C$14-1
A6: Relative multiples | B6: ='Relative & Normalized'!C12 | C6: ='Relative & Normalized'!C11 | D6: ='Relative & Normalized'!D12 | E6: =Assumptions!$C$58 | F6: =C6*E6 | G6: =C6/$C$14-1
A7: Normalised earnings power | B7: ='Relative & Normalized'!E28 | C7: ='Relative & Normalized'!C28 | D7: ='Relative & Normalized'!F28 | E7: =Assumptions!$C$59 | F7: =C7*E7 | G7: =C7/$C$14-1
A8: Book value and sustainable return | B8: ='Relative & Normalized'!E36 | C8: ='Relative & Normalized'!C36 | D8: ='Relative & Normalized'!F36 | E8: =Assumptions!$C$60 | F8: =C8*E8 | G8: =C8/$C$14-1
A9: Weighted central | B9: =MIN(B5:B8) | C9: =SUM(F5:F8) | D9: =MAX(D5:D8) | E9: =SUM(E5:E8) | G9: =C9/$C$14-1
A11: The contested judgement, both ways: DCF base vs backlog run-off | C11: =DCF!C54 | D11: 4.1793912
A12: Terminal value share of DCF enterprise value | C12: =DCF!C42
A13: Expert panel median | C13: 3.9232109
A14: Market price (anchor, 7-Aug-2026) | C14: =Assumptions!$C$4
A16: Key figure | B16: Value
A17: Market capitalisation (AED mn) | C17: =Assumptions!$C$4*Assumptions!$C$5
A18: Net cash, strict basis (cash − debt, FY2025) | C18: =Assumptions!$C$42-Assumptions!$C$43
A19: Net cash, company definition (disclosed) | C19: 1800
A20: FY2025 revenue (AED mn) | C20: ='Income Statement'!D5
A21: FY2025 EBITDA (AED mn) | C21: ='Income Statement'!D7
A22: FY2025 attributable profit (AED mn) | C22: ='Income Statement'!D17
A23: Cost of capital (explicit window) | C23: =DCF!C30
A24: Cost of capital (terminal) | C24: =DCF!C31
A25: Terminal growth | C25: =Assumptions!$C$38
A27: Monte Carlo price map (engine re-run, pasted) | B27: 1 month | C27: 3 months
A28: 5th percentile | B28: 2.537068 | C28: 2.3199657
A29: 25th percentile | B29: 2.718596 | C29: 2.6379757
A30: Median | B30: 2.8383089 | C30: 2.8576479
A31: 75th percentile | B31: 2.9639422 | C31: 3.0947734
A32: 95th percentile | B32: 3.1696329 | C32: 3.5237234

Sheet Fundamental Valuation
A1: Fundamental valuation — four lenses, the contested judgement and the stress readings
A4: Lens / step | B4: Basis | C4: AED per share
A5: Discounted cash flow (primary) | B5: links to the DCF sheet | C5: =DCF!C54
A6: backlog run-off alternative | B6: new sales halve and fade; margins compress (engine re-run) | C6: 4.1793912
A7: growth-hold alternative | B7: sales hold at AED 30bn; margins hold (engine re-run) | C7: 7.3934302
A8: Egypt-risk stress | B8: non-UAE revenue share carries the Egypt country premium (engine re-run) | C8: 5.0866767
A9: Relative multiples | B9: justified P/E and EV/EBITDA against the UAE developer set | C9: ='Relative & Normalized'!C11
A10: Normalised earnings power | B10: through-cycle sales and margin at a through-cycle multiple | C10: ='Relative & Normalized'!C28
A11: Book value and sustainable return | B11: justified price-to-book on sustainable return on equity | C11: ='Relative & Normalized'!C36
A13: Weighted central (links to Summary) | C13: =Summary!C9
A15: What the market price implies | B15: cost-of-equity adder that reconciles the base DCF to spot (engine solve) | C15: 0.11409083
A17: Expert panel (engine re-runs, worked in Appendix C) | B17: Method | C17: AED per share
A18: Expert 1 | B18: asset value (RNAV) | C18: 3.9232109
A19: Expert 2 | B19: owner cash flow, run-off basis | C19: 4.0580923
A20: Expert 3 | B20: peer-multiple convergence | C20: 1.7374382
A21: Panel median | C21: =MEDIAN(C18:C20)

Sheet Assumptions
A1: Assumptions — every blue cell reprices the model
A2: Vectors run FY2026E..FY2030E across columns C..G
A3: Driver | C3: FY26E / value | D3: FY27E | E3: FY28E | F3: FY29E | G3: FY30E
A4: Spot price (AED, 7-Aug-2026 close) | C4: 2.83
A5: Shares outstanding (mn) | C5: 16347.08
A6: Backlog conversion rate on opening development backlog | C6: 0.24 | D6: 0.27 | E6: 0.29 | F6: 0.31 | G6: 0.33
A7: New development sales (AED mn) | C7: 26000 | D7: 24000 | E7: 22000 | F7: 20500 | G7: 19000
A8: Land and plot sales revenue (AED mn) | C8: 1800 | D8: 1600 | E8: 1400 | F8: 1200 | G8: 1000
A9: Development gross margin | C9: 0.41 | D9: 0.4 | E9: 0.39 | F9: 0.385 | G9: 0.38
A10: Asset & investment management revenue growth | C10: 0.1 | D10: 0.085 | E10: 0.085 | F10: 0.08 | G10: 0.08
A11: Asset & investment management gross margin | C11: 0.64 | D11: 0.64 | E11: 0.64 | F11: 0.64 | G11: 0.64
A12: Hospitality revenue growth | C12: 0.06 | D12: 0.07 | E12: 0.07 | F12: 0.06 | G12: 0.06
A13: Hospitality gross margin | C13: 0.27 | D13: 0.28 | E13: 0.29 | F13: 0.3 | G13: 0.3
A14: Events, catering & tourism revenue growth | C14: 0.118 | D14: 0.045 | E14: 0.043 | F14: 0.041 | G14: 0.039
A15: Events, catering & tourism gross margin | C15: 0.265 | D15: 0.27 | E15: 0.275 | F15: 0.28 | G15: 0.28
A16: Others / eliminations revenue (AED mn) | C16: -30
A17: Others gross loss (AED mn) | C17: -120
A18: General & administrative / revenue | C18: 0.088 | D18: 0.088 | E18: 0.087 | F18: 0.086 | G18: 0.085
A19: Selling & marketing / revenue | C19: 0.018 | D19: 0.018 | E19: 0.017 | F19: 0.017 | G19: 0.016
A20: Investment and other income, recurring (AED mn) | C20: 160 | D20: 165 | E20: 170 | F20: 175 | G20: 180
A21: Depreciation & amortisation / revenue | C21: 0.042
A22: Capital expenditure (AED mn) | C22: 1400 | D22: 1500 | E22: 1550 | F22: 1600 | G22: 1650
A23: Working-capital release, negative = absorption (AED mn) | C23: -1500 | D23: 800 | E23: 1200 | F23: 1400 | G23: 1400
A24: Effective tax rate (DMTT floor + foreign uplift) | C24: 0.155
A25: NCI share of profit | C25: 0.02
A26: Associate income FY2026E base (AED mn) | C26: 200
A27: Associate income growth | C27: 0.08
A28: Gross debt path incl. related-party loan (AED mn) | C28: 9700 | D28: 9900 | E28: 9200 | F28: 8300 | G28: 7400
A29: Yield on cash balances | C29: 0.035
A30: Cost of capital build
A31: AED government bond yield (Jan-2031 T-Bond auction) | C31: 0.0448
A32: UAE sovereign default spread (rating basis, netted out) | C32: 0.0042
A33: Equity risk premium (UAE row, rating basis) | C33: 0.0487
A34: Beta (tier-3 fallback, flagged; sensitised 0.8-1.2) | C34: 1
A35: 6-month EIBOR | C35: 0.0371
A36: Marginal debt margin over 6M EIBOR | C36: 0.0165
A37: Terminal debt weight D/(D+E) | C37: 0.15
A38: Terminal growth | C38: 0.025
A39: Terminal return on invested capital | C39: 0.085
A40: Days from 31-Dec-2025 valuation date to the 7-Aug-2026 anchor | C40: 219
...

Sheet SOTP Bridge
A1: SOTP bridge — segment EV split and the EV → equity walk
A2: The four legs share one AED discount rate; the Egypt stress prices the cross-border leg separately
A4: Enterprise value by segment | B4: Weight base (FY2025 GP less corporate load) | C4: AED mn
A5: Real Estate Development | B5: 2261.93 | C5: =MAX(B5,0)/3372.324009*DCF!C41
A6: Asset & Investment Management | B6: 335.22314 | C6: =MAX(B6,0)/3372.324009*DCF!C41
A7: Hospitality | B7: 107.05047 | C7: =MAX(B7,0)/3372.324009*DCF!C41
A8: Events, Catering & Tourism | B8: 668.1204 | C8: =MAX(B8,0)/3372.324009*DCF!C41
A9: Enterprise value (links to DCF) | C9: =DCF!C41
A10: Terminal value share of enterprise value | C10: =DCF!C42
A11: + Cash and bank balances | C11: =Assumptions!$C$42
A12: − Gross debt incl. related-party loan | C12: =-Assumptions!$C$43
A13: − Lease liabilities | C13: =-Assumptions!$C$44
A14: + Associates & JVs | C14: =Assumptions!$C$45
A15: + Financial assets | C15: =Assumptions!$C$46
A16: − Non-controlling interests (book) | C16: =-Assumptions!$C$47
A17: Equity attributable → per share → at anchor | C17: =C9+SUM(C11:C16)
A18: per share, 31-Dec-2025 | C18: =C17/Assumptions!$C$5
A19: per share at the 7-Aug-2026 anchor | C19: =C18*DCF!C53
A21: NCI alternative framing (capitalised at share of profit, engine) | C21: 5.9583244

Sheet Segments
A1: Segments — the four disclosed legs, FY2025 base and forecast build
A2: FY2025 base pasted from IFRS 8 note 33 (audited); every forecast cell is a formula off Assumptions
A4: FY2025 base (audited) | B4: Revenue | C4: Gross profit | D4: GP margin | E4: PBT | F4: Assets
A5: Real Estate Development | B5: 7403.313 | C5: 3232.891 | D5: =C5/B5 | E5: 2547.573 | F5: 55738.581
A6: Asset & Investment Management | B6: 654.658 | C6: 421.083 | D6: =C6/B6 | E6: 685.082 | F6: 11095.849
A7: Hospitality | B7: 791.771 | C7: 210.893 | D7: =C7/B7 | E7: -69.15 | F7: 4601.757
A8: Events, Catering & Tourism | B8: 5008.749 | C8: 1325.029 | D8: =C8/B8 | E8: 1061.602 | F8: 14118.268
A9: Others / eliminations | B9: -29.622 | C9: -164.637
A10: Group FY2025 | B10: =SUM(B5:B9) | C10: =SUM(C5:C9)
A12: Development build | B12: FY26E | C12: FY27E | D12: FY28E | E12: FY29E | F12: FY30E
A13: Opening development backlog | B13: =Assumptions!$C$49 | C13: =B16 | D13: =C16 | E13: =D16 | F13: =E16
A14: New development sales | B14: =Assumptions!$C$7 | C14: =Assumptions!$D$7 | D14: =Assumptions!$E$7 | E14: =Assumptions!$F$7 | F14: =Assumptions!$G$7
A15: Development revenue recognised (conv × opening) | B15: =Assumptions!$C$6*B13 | C15: =Assumptions!$D$6*C13 | D15: =Assumptions!$E$6*D13 | E15: =Assumptions!$F$6*E13 | F15: =Assumptions!$G$6*F13
A16: Closing backlog | B16: =B13+B14-B15 | C16: =C13+C14-C15 | D16: =D13+D14-D15 | E16: =E13+E14-E15 | F16: =F13+F14-F15
A17: Land and plot sales | B17: =Assumptions!$C$8 | C17: =Assumptions!$D$8 | D17: =Assumptions!$E$8 | E17: =Assumptions!$F$8 | F17: =Assumptions!$G$8
A18: Real Estate Development revenue | B18: =B15+B17 | C18: =C15+C17 | D18: =D15+D17 | E18: =E15+E17 | F18: =F15+F17
A20: Segment revenue forecast | B20: FY26E | C20: FY27E | D20: FY28E | E20: FY29E | F20: FY30E
A21: Real Estate Development | B21: =B18 | C21: =C18 | D21: =D18 | E21: =E18 | F21: =F18
A22: Asset & Investment Management | B22: =B6*(1+Assumptions!$C$10) | C22: =B22*(1+Assumptions!$D$10) | D22: =C22*(1+Assumptions!$E$10) | E22: =D22*(1+Assumptions!$F$10) | F22: =E22*(1+Assumptions!$G$10)
A23: Hospitality | B23: =B7*(1+Assumptions!$C$12) | C23: =B23*(1+Assumptions!$D$12) | D23: =C23*(1+Assumptions!$E$12) | E23: =D23*(1+Assumptions!$F$12) | F23: =E23*(1+Assumptions!$G$12)
A24: Events, Catering & Tourism | B24: =B8*(1+Assumptions!$C$14) | C24: =B24*(1+Assumptions!$D$14) | D24: =C24*(1+Assumptions!$E$14) | E24: =D24*(1+Assumptions!$F$14) | F24: =E24*(1+Assumptions!$G$14)
A25: Others / eliminations | B25: =Assumptions!$C$16 | C25: =Assumptions!$C$16 | D25: =Assumptions!$C$16 | E25: =Assumptions!$C$16 | F25: =Assumptions!$C$16
A26: Group revenue | B26: =SUM(B21:B25) | C26: =SUM(C21:C25) | D26: =SUM(D21:D25) | E26: =SUM(E21:E25) | F26: =SUM(F21:F25)
A28: Gross profit build (margin × revenue) | B28: FY26E | C28: FY27E | D28: FY28E | E28: FY29E | F28: FY30E
A29: Real Estate Development | B29: =B21*Assumptions!$C$9 | C29: =C21*Assumptions!$D$9 | D29: =D21*Assumptions!$E$9 | E29: =E21*Assumptions!$F$9 | F29: =F21*Assumptions!$G$9
A30: Asset & Investment Management | B30: =B22*Assumptions!$C$11 | C30: =C22*Assumptions!$D$11 | D30: =D22*Assumptions!$E$11 | E30: =E22*Assumptions!$F$11 | F30: =F22*Assumptions!$G$11
A31: Hospitality | B31: =B23*Assumptions!$C$13 | C31: =C23*Assumptions!$D$13 | D31: =D23*Assumptions!$E$13 | E31: =E23*Assumptions!$F$13 | F31: =F23*Assumptions!$G$13
A32: Events, Catering & Tourism | B32: =B24*Assumptions!$C$15 | C32: =C24*Assumptions!$D$15 | D32: =D24*Assumptions!$E$15 | E32: =E24*Assumptions!$F$15 | F32: =F24*Assumptions!$G$15
A33: Others | B33: =Assumptions!$C$17 | C33: =Assumptions!$C$17 | D33: =Assumptions!$C$17 | E33: =Assumptions!$C$17 | F33: =Assumptions!$C$17
A34: Group gross profit | B34: =SUM(B29:B33) | C34: =SUM(C29:C33) | D34: =SUM(D29:D33) | E34: =SUM(E29:E33) | F34: =SUM(F29:F33)
A35: Group gross margin (output) | B35: =B34/B26 | C35: =C34/C26 | D35: =D34/D26 | E35: =E34/E26 | F35: =F34/F26

Sheet Relative & Normalized
A1: Relative multiples · normalised earnings power · book value
A2: Peer figures are cross-checks from the peers' own releases (pasted, labelled); every implied value is a formula
A4: Relative multiples | B4: Value
A5: FY2026E attributable profit (AED mn) | C5: ='Income Statement'!E17
A6: Justified P/E × FY2026E EPS | C6: =Assumptions!$C$51*C5/Assumptions!$C$5
A7: FY2026E EBITDA (AED mn) | C7: =DCF!B13
A8: Justified EV/EBITDA → EV | C8: =Assumptions!$C$52*C7
A9: → equity per share through the same bridge | C9: =(C8+Assumptions!$C$42-Assumptions!$C$43-Assumptions!$C$44+Assumptions!$C$45+Assumptions!$C$46-Assumptions!$C$47)/Assumptions!$C$5
A11: Relative lens (mean of the two) | C11: =AVERAGE(C6,C9)
A12: bear / bull (blended lens scaled to the 4.08x floor · 9.5x ceiling) | C12: =C11*4.08/Assumptions!$C$51 | D12: =C11*9.5/Assumptions!$C$51
A14: Trailing cross-checks (formulas on disclosed figures) | B14: Value
A15: Trailing P/E on FY2025 profit | C15: =DCF!C27/3925.705
A16: Trailing EV/EBITDA (EV = mktcap + net debt) | C16: =(DCF!C27+Assumptions!$C$43-Assumptions!$C$42)/4895.552000000001
A18: Normalised earnings power | B18: Value
A19: Through-cycle development sales → recognised revenue (85%) | C19: =Assumptions!$C$53*0.85+(654.658+791.771+5008.749)*1.15
A20: Through-cycle net margin | C20: =Assumptions!$C$54
A21: Normalised net profit | C21: =C19*C20
A22: Normalised EPS | C22: =C21/Assumptions!$C$5
A28: Normalised lens = EPS × through-cycle P/E | C28: =C22*Assumptions!$C$55 | E28: =C22*6 | F28: =C22*10.5
A30: Book value & sustainable return | B30: Value
A31: Book value per share (audited FY2025 attributable equity) | C31: =Assumptions!$C$48/Assumptions!$C$5
A32: Justified P/B = (ROE − g)/(Ke − g) | C32: =(Assumptions!$C$56-Assumptions!$C$38)/(DCF!C24-Assumptions!$C$38)
A36: Book lens = BVPS × justified P/B | C36: =C31*C32 | E36: =C31*((0.055-Assumptions!$C$38)/(DCF!C24-Assumptions!$C$38)) | F36: =C31*((0.095-Assumptions!$C$38)/(DCF!C24-Assumptions!$C$38))

Sheet DCF
A1: DCF — waterfall, cost of capital build, terminal block, bridge to per-share
A2: Chains live off Segments and Assumptions; the three engine alternatives are labelled pastes
A4: Waterfall (AED mn) | B4: FY26E | C4: FY27E | D4: FY28E | E4: FY29E | F4: FY30E
A5: Revenue | B5: =Segments!B26 | C5: =Segments!C26 | D5: =Segments!D26 | E5: =Segments!E26 | F5: =Segments!F26
A6: Gross profit | B6: =Segments!B34 | C6: =Segments!C34 | D6: =Segments!D34 | E6: =Segments!E34 | F6: =Segments!F34
A7: General & administrative | B7: =-Assumptions!$C$18*B5 | C7: =-Assumptions!$D$18*C5 | D7: =-Assumptions!$E$18*D5 | E7: =-Assumptions!$F$18*E5 | F7: =-Assumptions!$G$18*F5
A8: Selling & marketing | B8: =-Assumptions!$C$19*B5 | C8: =-Assumptions!$D$19*C5 | D8: =-Assumptions!$E$19*D5 | E8: =-Assumptions!$F$19*E5 | F8: =-Assumptions!$G$19*F5
A9: Investment and other income | B9: =Assumptions!$C$20 | C9: =Assumptions!$D$20 | D9: =Assumptions!$E$20 | E9: =Assumptions!$F$20 | F9: =Assumptions!$G$20
A10: EBIT (post-D&A, ex-fair-value items) | B10: =SUM(B6:B9) | C10: =SUM(C6:C9) | D10: =SUM(D6:D9) | E10: =SUM(E6:E9) | F10: =SUM(F6:F9)
A11: EBITDA margin (output) | B11: =(B10+B12)/B5 | C11: =(C10+C12)/C5 | D11: =(D10+D12)/D5 | E11: =(E10+E12)/E5 | F11: =(F10+F12)/F5
A12: Depreciation & amortisation | B12: =Assumptions!$C$21*B5 | C12: =Assumptions!$C$21*C5 | D12: =Assumptions!$C$21*D5 | E12: =Assumptions!$C$21*E5 | F12: =Assumptions!$C$21*F5
A13: EBITDA | B13: =B10+B12 | C13: =C10+C12 | D13: =D10+D12 | E13: =E10+E12 | F13: =F10+F12
A14: NOPAT = EBIT × (1 − t) | B14: =B10*(1-Assumptions!$C$24) | C14: =C10*(1-Assumptions!$C$24) | D14: =D10*(1-Assumptions!$C$24) | E14: =E10*(1-Assumptions!$C$24) | F14: =F10*(1-Assumptions!$C$24)
A15: + D&A | B15: =B12 | C15: =C12 | D15: =D12 | E15: =E12 | F15: =F12
A16: − Capital expenditure | B16: =-Assumptions!$C$22 | C16: =-Assumptions!$D$22 | D16: =-Assumptions!$E$22 | E16: =-Assumptions!$F$22 | F16: =-Assumptions!$G$22
A17: − Δ working capital (release enters +) | B17: =Assumptions!$C$23 | C17: =Assumptions!$D$23 | D17: =Assumptions!$E$23 | E17: =Assumptions!$F$23 | F17: =Assumptions!$G$23
A18: Free cash flow to firm | B18: =SUM(B14:B17) | C18: =SUM(C14:C17) | D18: =SUM(D14:D17) | E18: =SUM(E14:E17) | F18: =SUM(F14:F17)
A19: Discount factor | B19: =1/(1+$C$30)^1 | C19: =1/(1+$C$30)^2 | D19: =1/(1+$C$30)^3 | E19: =1/(1+$C$30)^4 | F19: =1/(1+$C$30)^5
A20: PV of FCFF | B20: =B18*B19 | C20: =C18*C19 | D20: =D18*D19 | E20: =E18*E19 | F20: =F18*F19
A22: Cost of capital — built on the sheet, never pasted
A23: Normalised risk-free rate rf* = AED yield − sovereign spread | C23: =Assumptions!$C$31-Assumptions!$C$32
A24: Cost of equity Ke = rf* + β × ERP | C24: =C23+Assumptions!$C$34*Assumptions!$C$33
A25: Marginal cost of debt Kd = 6M EIBOR + margin | C25: =Assumptions!$C$35+Assumptions!$C$36
A26: Kd after tax | C26: =C25*(1-Assumptions!$C$24)
A27: Market capitalisation (spot × shares) | C27: =Assumptions!$C$4*Assumptions!$C$5
A28: Equity weight E/(E+D) | C28: =C27/(C27+Assumptions!$C$43)
A29: Debt weight D/(E+D), book debt at market | C29: =1-C28
A30: Cost of capital (explicit window) | C30: =C28*C24+C29*C26
A31: Terminal cost of capital (terminal weights) | C31: =(1-Assumptions!$C$37)*C24+Assumptions!$C$37*C25*(1-Assumptions!$C$24)
A33: Terminal block — reinvestment derived, never typed
A34: Terminal growth g | C34: =Assumptions!$C$38
A35: Terminal return on invested capital | C35: =Assumptions!$C$39
A36: Reinvestment rate = g / ROIC | C36: =C34/C35
A37: Terminal NOPAT = FY2030E NOPAT × (1+g) | C37: =F14*(1+C34)
A38: Terminal value = NOPAT × (1−RR) / (WACCterm − g) | C38: =C37*(1-C36)/(C31-C34)
A39: PV of terminal value (year-5 factor) | C39: =C38*F19
A40: PV of explicit years | C40: =SUM(B20:F20)
A41: Enterprise value | C41: =C39+C40
A42: Terminal value share of enterprise value | C42: =C39/C41
A44: EV → equity bridge (31-Dec-2025, audited anchors)
...

Sheet Income Statement
A1: Income statement — 3 years audited + 5 years forecast
A2: FY2023 is the Q Holding perimeter; FY2024 contains the AED 9,192mn bargain-purchase gain (dual-framed)
B4: FY2023 | C4: FY2024 | D4: FY2025 | E4: FY26E | F4: FY27E | G4: FY28E | H4: FY29E | I4: FY30E
A5: Revenue | B5: 994.293 | C5: 6511.182 | D5: 13828.869 | E5: =DCF!B5 | F5: =DCF!C5 | G5: =DCF!D5 | H5: =DCF!E5 | I5: =DCF!F5
A6: Gross profit | B6: 599.559 | C6: 2316.507 | D6: 5025.259 | E6: =DCF!B6 | F6: =DCF!C6 | G6: =DCF!D6 | H6: =DCF!E6 | I6: =DCF!F6
A7: EBITDA (house) | B7: 673.353 | C7: 9794.942 | D7: 4895.552 | E7: =DCF!B13 | F7: =DCF!C13 | G7: =DCF!D13 | H7: =DCF!E13 | I7: =DCF!F13
A8: EBITDA margin | B8: =B7/B5 | C8: =C7/C5 | D8: =D7/D5 | E8: =E7/E5 | F8: =F7/F5 | G8: =G7/G5 | H8: =H7/H5 | I8: =I7/I5
A9: Depreciation & amortisation | B9: 27.719 | C9: 265.122 | D9: 610.483 | E9: =DCF!B12 | F9: =DCF!C12 | G9: =DCF!D12 | H9: =DCF!E12 | I9: =DCF!F12
A10: EBIT | B10: =B7-B9 | C10: =C7-C9 | D10: =D7-D9 | E10: =E7-E9 | F10: =F7-F9 | G10: =G7-G9 | H10: =H7-H9 | I10: =I7-I9
A11: Net finance result | B11: 8.518 | C11: -156.667 | D11: -127.466 | E11: =Assumptions!$C$29*'Balance Sheet'!D9-(DCF!$C$25*(Assumptions!$C$43+Assumptions!$C$28)/2+35) | F11: =Assumptions!$C$29*'Balance Sheet'!E9-(DCF!$C$25*(Assumptions!$C$28+Assumptions!$D$28)/2+35) | G11: =Assumptions!$C$29*'Balance Sheet'!F9-(DCF!$C$25*(Assumptions!$D$28+Assumptions!$E$28)/2+35) | H11: =Assumptions!$C$29*'Balance Sheet'!G9-(DCF!$C$25*(Assumptions!$E$28+Assumptions!$F$28)/2+35) | I11: =Assumptions!$C$29*'Balance Sheet'!H9-(DCF!$C$25*(Assumptions!$F$28+Assumptions!$G$28)/2+35)
A12: Associates & JVs | B12: -0.697 | C12: 115.114 | D12: 263.592 | E12: =Assumptions!$C$26*(1+Assumptions!$C$27)^0 | F12: =Assumptions!$C$26*(1+Assumptions!$C$27)^1 | G12: =Assumptions!$C$26*(1+Assumptions!$C$27)^2 | H12: =Assumptions!$C$26*(1+Assumptions!$C$27)^3 | I12: =Assumptions!$C$26*(1+Assumptions!$C$27)^4
A13: Profit before tax | B13: =B10+B11+B12 | C13: =C10+C11+C12 | D13: =D10+D11+D12 | E13: =E10+E11+E12 | F13: =F10+F11+F12 | G13: =G10+G11+G12 | H13: =H10+H11+H12 | I13: =I10+I11+I12
A14: Income tax | B14: -79.504 | C14: -98.815 | D14: -495.49 | E14: =-E13*Assumptions!$C$24 | F14: =-F13*Assumptions!$C$24 | G14: =-G13*Assumptions!$C$24 | H14: =-H13*Assumptions!$C$24 | I14: =-I13*Assumptions!$C$24
A15: Profit for the year | B15: =B13+B14 | C15: =C13+C14 | D15: =D13+D14 | E15: =E13+E14 | F15: =F13+F14 | G15: =G13+G14 | H15: =H13+H14 | I15: =I13+I14
A16: Non-controlling interests | B16: 112.682 | C16: -33.739 | D16: -94.397 | E16: =E15*Assumptions!$C$25 | F16: =F15*Assumptions!$C$25 | G16: =G15*Assumptions!$C$25 | H16: =H15*Assumptions!$C$25 | I16: =I15*Assumptions!$C$25
A17: Attributable profit | B17: =B15-B16 | C17: =C15-C16 | D17: =D15-D16 | E17: =E15-E16 | F17: =F15-F16 | G17: =G15-G16 | H17: =H15-H16 | I17: =I15-I16

Sheet Balance Sheet
A1: Balance sheet — 3 years audited + 5-year roll-forward
A2: Forecast: equity rolls on retained profit (no dividend); debt is the drawn path; cash balances derive
B4: FY2023 | C4: FY2024 | D4: FY2025 | E4: FY26E | F4: FY27E | G4: FY28E | H4: FY29E | I4: FY30E
A5: Property, plant & equipment | B5: 789.463 | C5: 7593.191 | D5: 8812.397 | E5: - | F5: - | G5: - | H5: - | I5: -
A6: Investment properties | B6: 7536.858 | C6: 9336.725 | D6: 9461.777 | E6: - | F6: - | G6: - | H6: - | I6: -
A7: Inventories (land bank) | B7: 2246.917 | C7: 29586.274 | D7: 27297.588 | E7: - | F7: - | G7: - | H7: - | I7: -
A8: Development work-in-progress | B8: 0 | C8: 2461.672 | D8: 6111.794 | E8: - | F8: - | G8: - | H8: - | I8: -
A9: Cash and bank balances | B9: 2259.902 | C9: 7009.67 | D9: 12641.987 | E9: =D9+DCF!B18+'Income Statement'!E11-('Income Statement'!E13-DCF!B10)*Assumptions!$C$24+(Assumptions!$C$28-Assumptions!$C$43) | F9: =E9+DCF!C18+'Income Statement'!F11-('Income Statement'!F13-DCF!C10)*Assumptions!$C$24+(Assumptions!$D$28-Assumptions!$C$28) | G9: =F9+DCF!D18+'Income Statement'!G11-('Income Statement'!G13-DCF!D10)*Assumptions!$C$24+(Assumptions!$E$28-Assumptions!$D$28) | H9: =G9+DCF!E18+'Income Statement'!H11-('Income Statement'!H13-DCF!E10)*Assumptions!$C$24+(Assumptions!$F$28-Assumptions!$E$28) | I9: =H9+DCF!F18+'Income Statement'!I11-('Income Statement'!I13-DCF!F10)*Assumptions!$C$24+(Assumptions!$G$28-Assumptions!$F$28)
A10: Total assets (audited) | B10: 21311.081 | C10: 75925.281 | D10: 87030.985 | E10: - | F10: - | G10: - | H10: - | I10: -
A11: Gross debt incl. related-party loan | B11: 1976.135 | C11: 5364.11 | D11: 6789.086 | E11: =Assumptions!$C$28 | F11: =Assumptions!$D$28 | G11: =Assumptions!$E$28 | H11: =Assumptions!$F$28 | I11: =Assumptions!$G$28
A12: Net working capital (house) | B12: - | C12: 26861.838 | D12: 26942.91 | E12: =26942.910-Assumptions!$C$23 | F12: =E12-Assumptions!$D$23 | G12: =F12-Assumptions!$E$23 | H12: =G12-Assumptions!$F$23 | I12: =H12-Assumptions!$G$23
A13: Equity attributable to owners | B13: 13769.094 | C13: 49676.408 | D13: 53902.504 | E13: =D13+'Income Statement'!E17 | F13: =E13+'Income Statement'!F17 | G13: =F13+'Income Statement'!G17 | H13: =G13+'Income Statement'!H17 | I13: =H13+'Income Statement'!I17
A14: Non-controlling interests | B14: 1149.566 | C14: 1186.183 | D14: 847.48 | E14: =D14+'Income Statement'!E16 | F14: =E14+'Income Statement'!F16 | G14: =F14+'Income Statement'!G16 | H14: =G14+'Income Statement'!H16 | I14: =H14+'Income Statement'!I16
A15: Net debt (− = net cash) | B15: =B11-B9 | C15: =C11-C9 | D15: =D11-D9 | E15: =E11-E9 | F15: =F11-F9 | G15: =G11-G9 | H15: =H11-H9 | I15: =I11-I9
A16: Net debt / EBITDA | B16: =(B11-B9)/673.3530000000001 | C16: =(C11-C9)/9794.942 | D16: =(D11-D9)/4895.552000000001 | E16: =(E11-E9)/DCF!B13 | F16: =(F11-F9)/DCF!C13 | G16: =(G11-G9)/DCF!D13 | H16: =(H11-H9)/DCF!E13 | I16: =(I11-I9)/DCF!F13

Sheet Cash Flow
A1: Cash flow — history (audited) and the forecast free-cash-flow chain
A2: Forecast rows link to the DCF waterfall; history is the audited record
B4: FY2024 | C4: FY2025 | D4: FY26E | E4: FY27E | F4: FY28E | G4: FY29E | H4: FY30E
A5: Net cash from operating activities (audited) | B5: 3231.447 | C5: 3860.373
A6: Capital expenditure (PP&E + intangibles + IP, audited) | B6: 1247 | C6: 1260.566
A7: H1-2026 operating cash flow (reviewed interim) | B7: -3921.027
A9: Forecast chain (links to the DCF waterfall)
A10: NOPAT | D10: =DCF!B14 | E10: =DCF!C14 | F10: =DCF!D14 | G10: =DCF!E14 | H10: =DCF!F14
A11: + D&A | D11: =DCF!B15 | E11: =DCF!C15 | F11: =DCF!D15 | G11: =DCF!E15 | H11: =DCF!F15
A12: − Capex | D12: =DCF!B16 | E12: =DCF!C16 | F12: =DCF!D16 | G12: =DCF!E16 | H12: =DCF!F16
A13: − Δ working capital | D13: =DCF!B17 | E13: =DCF!C17 | F13: =DCF!D17 | G13: =DCF!E17 | H13: =DCF!F17
A14: Free cash flow to firm | D14: =DCF!B18 | E14: =DCF!C18 | F14: =DCF!D18 | G14: =DCF!E18 | H14: =DCF!F18
A16: Forecast years run FY2026E..FY2030E in columns D..H

Sheet Summary Financials
A1: Summary financials — the model in one table
A2: Every row links live
B4: FY2023 | C4: FY2024 | D4: FY2025 | E4: FY26E | F4: FY27E | G4: FY28E | H4: FY29E | I4: FY30E
A5: Revenue | B5: ='Income Statement'!B5 | C5: ='Income Statement'!C5 | D5: ='Income Statement'!D5 | E5: ='Income Statement'!E5 | F5: ='Income Statement'!F5 | G5: ='Income Statement'!G5 | H5: ='Income Statement'!H5 | I5: ='Income Statement'!I5
A6: EBITDA | B6: ='Income Statement'!B7 | C6: ='Income Statement'!C7 | D6: ='Income Statement'!D7 | E6: ='Income Statement'!E7 | F6: ='Income Statement'!F7 | G6: ='Income Statement'!G7 | H6: ='Income Statement'!H7 | I6: ='Income Statement'!I7
A7: EBITDA margin | B7: ='Income Statement'!B8 | C7: ='Income Statement'!C8 | D7: ='Income Statement'!D8 | E7: ='Income Statement'!E8 | F7: ='Income Statement'!F8 | G7: ='Income Statement'!G8 | H7: ='Income Statement'!H8 | I7: ='Income Statement'!I8
A8: Attributable profit | B8: ='Income Statement'!B17 | C8: ='Income Statement'!C17 | D8: ='Income Statement'!D17 | E8: ='Income Statement'!E17 | F8: ='Income Statement'!F17 | G8: ='Income Statement'!G17 | H8: ='Income Statement'!H17 | I8: ='Income Statement'!I17
A9: Free cash flow to firm | B9: - | C9: - | D9: - | E9: ='Cash Flow'!D14 | F9: ='Cash Flow'!E14 | G9: ='Cash Flow'!F14 | H9: ='Cash Flow'!G14 | I9: ='Cash Flow'!H14
A10: Net debt (− = net cash) | B10: ='Balance Sheet'!B15 | C10: ='Balance Sheet'!C15 | D10: ='Balance Sheet'!D15 | E10: ='Balance Sheet'!E15 | F10: ='Balance Sheet'!F15 | G10: ='Balance Sheet'!G15 | H10: ='Balance Sheet'!H15 | I10: ='Balance Sheet'!I15
A11: Equity attributable | B11: ='Balance Sheet'!B13 | C11: ='Balance Sheet'!C13 | D11: ='Balance Sheet'!D13 | E11: ='Balance Sheet'!E13 | F11: ='Balance Sheet'!F13 | G11: ='Balance Sheet'!G13 | H11: ='Balance Sheet'!H13 | I11: ='Balance Sheet'!I13
A13: Invested capital (FY2025 base + cumulative capex − D&A + ΔWC) | E13: =48897.083+DCF!B16*-1-DCF!B12-DCF!B17 | F13: =48897.083+DCF!B16*-1-DCF!B12-DCF!B17+DCF!C16*-1-DCF!C12-DCF!C17 | G13: =48897.083+DCF!B16*-1-DCF!B12-DCF!B17+DCF!C16*-1-DCF!C12-DCF!C17+DCF!D16*-1-DCF!D12-DCF!D17 | H13: =48897.083+DCF!B16*-1-DCF!B12-DCF!B17+DCF!C16*-1-DCF!C12-DCF!C17+DCF!D16*-1-DCF!D12-DCF!D17+DCF!E16*-1-DCF!E12-DCF!E17 | I13: =48897.083+DCF!B16*-1-DCF!B12-DCF!B17+DCF!C16*-1-DCF!C12-DCF!C17+DCF!D16*-1-DCF!D12-DCF!D17+DCF!E16*-1-DCF!E12-DCF!E17+DCF!F16*-1-DCF!F12-DCF!F17

Sheet Monte Carlo
A1: Monte Carlo price map — engine re-run (pasted, does not reprice)
A2: Struck 2026-08-07 at spot 2.83; 50,000 paths, seed 42; grade dates are calendar-resolved
B4: 1 month | C4: 3 months
A5: Sessions in window | B5: 20 | C5: 63
A6: Grade date | B6: 2026-09-07 | C6: 2026-11-09
A7: Annualised anchor volatility | B7: 0.25166322 | C7: 0.26372485
A8: 5th percentile | B8: 2.537068 | C8: 2.3199657
A9: 25th percentile | B9: 2.718596 | C9: 2.6379757
A10: Median | B10: 2.8383089 | C10: 2.8576479
A11: 75th percentile | B11: 2.9639422 | C11: 3.0947734
A12: 95th percentile | B12: 3.1696329 | C12: 3.5237234
A13: P(close above spot) | B13: 0.51874 | C13: 0.53302
A14: P(≥ +10%) | B14: 0.08014 | C14: 0.23496
A15: P(≤ −10%) | B15: 0.05528 | C15: 0.16866
A16: P(touch +5% at any point) | B16: 0.3935 | C16: 0.6544
A17: P(touch −5% at any point) | B17: 0.34584 | C17: 0.589
A19: Calibration evidence (walk-forward, this name)
A20: Windows scored (post-break) | B20: 17
A21: CRPS skill vs carry-anchored random walk | B21: 0.042398909
A22: Verdict | B22: PASS
A23: Coverage of the 80% band | B23: 0.94117647
A24: Coverage of the 90% band | B24: 0.94117647
A25: PIT mean (0.5 = centred) | B25: 0.43918529

Sheet Sensitivity
A1: Sensitivity — each cell is a complete engine revaluation (pasted)
A2: Rows: cost of capital; columns: terminal growth. Additional one-way strips below
A4: WACC \ g | B4: 1.5% | C4: 2.0% | D4: 2.5% | E4: 3.0% | F4: 3.5%
A5: 7.37% | B5: 6.8164525 | C5: 6.9098734 | D5: 7.0185434 | E5: 7.1477006 | F5: 7.3052922
A6: 7.87% | B6: 6.3278518 | C6: 6.3809286 | D6: 6.4403987 | E6: 6.5082326 | F6: 6.5873031
A7: 8.37% | B7: 5.9098382 | C7: 5.9342274 | D7: 5.9596482 | E7: 5.9863892 | F7: 6.0148571
A8: 8.87% | B8: 5.548061 | C8: 5.5518342 | D8: 5.5533856 | E8: 5.5521472 | F8: 5.5473391
A9: 9.37% | B9: 5.2318171 | C9: 5.2206819 | D9: 5.2053747 | E9: 5.1849127 | F9: 5.1579777
A11: Beta | B11: 0.8 | C11: 0.9 | D11: 1.0 | E11: 1.1 | F11: 1.2
A12: DCF per share | B12: 6.8666793 | C12: 6.4131695 | D12: 6.0242361 | E12: 5.6869275 | F12: 5.3915419
A14: Development margin shift | B14: -0.04 | C14: -0.02 | D14: 0.0 | E14: 0.02 | F14: 0.04
A15: DCF per share | B15: 5.4324057 | C15: 5.7283209 | D15: 6.0242361 | E15: 6.3201514 | F15: 6.6160666
A17: Conversion-rate shift | B17: -0.06 | C17: -0.03 | D17: 0.0 | E17: 0.03 | F17: 0.06
A18: DCF per share | B18: 5.6830575 | C18: 5.8696179 | D18: 6.0242361 | E18: 6.1511218 | F18: 6.2541076
A20: New-sales multiple | B20: 0.5 | C20: 0.75 | D20: 1.0 | E20: 1.25 | F20: 1.5
A21: DCF per share | B21: 4.4678059 | C21: 5.246021 | D21: 6.0242361 | E21: 6.8024513 | F21: 7.5806664
A23: Working-capital release shift (AED mn/yr) | B23: -1000.0 | C23: -500.0 | D23: 0.0 | E23: 500.0 | F23: 1000.0
A24: DCF per share | B24: 5.7695945 | C24: 5.8969153 | D24: 6.0242361 | E24: 6.151557 | F24: 6.2788778
A26: Cost-of-equity adder | B26: 0.0 | C26: 0.005 | D26: 0.01 | E26: 0.015 | F26: 0.02
A27: DCF per share | B27: 6.0242361 | C27: 5.6785352 | D27: 5.3767996 | E27: 5.1110872 | F27: 4.8752629

Sheet Per-Share & Ratios
A1: Per-share figures and ratios — all formulas
B4: FY2023 | C4: FY2024 | D4: FY2025 | E4: FY26E | F4: FY27E | G4: FY28E | H4: FY29E | I4: FY30E
A5: EPS (attributable) | B5: ='Income Statement'!B17/Assumptions!$C$5 | C5: ='Income Statement'!C17/Assumptions!$C$5 | D5: ='Income Statement'!D17/Assumptions!$C$5 | E5: ='Income Statement'!E17/Assumptions!$C$5 | F5: ='Income Statement'!F17/Assumptions!$C$5 | G5: ='Income Statement'!G17/Assumptions!$C$5 | H5: ='Income Statement'!H17/Assumptions!$C$5 | I5: ='Income Statement'!I17/Assumptions!$C$5
A6: Book value per share | B6: ='Balance Sheet'!B13/Assumptions!$C$5 | C6: ='Balance Sheet'!C13/Assumptions!$C$5 | D6: ='Balance Sheet'!D13/Assumptions!$C$5 | E6: ='Balance Sheet'!E13/Assumptions!$C$5 | F6: ='Balance Sheet'!F13/Assumptions!$C$5 | G6: ='Balance Sheet'!G13/Assumptions!$C$5 | H6: ='Balance Sheet'!H13/Assumptions!$C$5 | I6: ='Balance Sheet'!I13/Assumptions!$C$5
A7: Return on attributable equity (avg) | B7: - | C7: ='Income Statement'!C17/(('Balance Sheet'!C13+'Balance Sheet'!B13)/2) | D7: ='Income Statement'!D17/(('Balance Sheet'!D13+'Balance Sheet'!C13)/2) | E7: ='Income Statement'!E17/(('Balance Sheet'!E13+'Balance Sheet'!D13)/2) | F7: ='Income Statement'!F17/(('Balance Sheet'!F13+'Balance Sheet'!E13)/2) | G7: ='Income Statement'!G17/(('Balance Sheet'!G13+'Balance Sheet'!F13)/2) | H7: ='Income Statement'!H17/(('Balance Sheet'!H13+'Balance Sheet'!G13)/2) | I7: ='Income Statement'!I17/(('Balance Sheet'!I13+'Balance Sheet'!H13)/2)
A8: Return on invested capital (fwd, avg base) | B8: - | C8: - | D8: - | E8: 0.086471737 | F8: 0.11116316 | G8: 0.12880101 | H8: 0.14192055 | I8: 0.15025329
A9: P/E at spot | B9: =Assumptions!$C$4/B5 | C9: =Assumptions!$C$4/C5 | D9: =Assumptions!$C$4/D5 | E9: =Assumptions!$C$4/E5 | F9: =Assumptions!$C$4/F5 | G9: =Assumptions!$C$4/G5 | H9: =Assumptions!$C$4/H5 | I9: =Assumptions!$C$4/I5
A10: P/B at spot | B10: =Assumptions!$C$4/B6 | C10: =Assumptions!$C$4/C6 | D10: =Assumptions!$C$4/D6 | E10: =Assumptions!$C$4/E6 | F10: =Assumptions!$C$4/F6 | G10: =Assumptions!$C$4/G6 | H10: =Assumptions!$C$4/H6 | I10: =Assumptions!$C$4/I6

Sheet Peer & Sector
A1: Peer & sector — cross-checks only, never build sources
A2: Peer fundamentals from each company's own FY2025 release; prices/multiples from stockanalysis.com 07-Aug-2026 (aggregator, labelled)
A4: Peer | B4: Spot | C4: Mkt cap (AED mn) | D4: FY2025 NP (AED mn) | E4: Trailing P/E | F4: FY2025 revenue | G4: Backlog
A5: Aldar Properties (ADX) | B5: 7.78 | C5: 61170 | D5: 8800 | E5: 7.54 | F5: 33800 | G5: 66500
A6: Emaar Properties (DFM) | B6: 11.5 | C6: 101650 | D6: - | E6: 5.3 | F6: 49600 | G6: 155000
A7: Emaar Development (DFM) | B7: 13.38 | C7: 53520 | D7: 11320 | E7: 4.08 | F7: 27490 | G7: 134300
A8: Modon Holding (this study) | B8: =Assumptions!$C$4 | C8: =Assumptions!$C$4*Assumptions!$C$5 | D8: 3925.705 | E8: =C8/D8 | F8: ='Income Statement'!D5 | G8: 46000
A10: Sector context (ADREC 2025, regulator): AED 142bn transactions (+44%); residential AED 76bn (+67%); off-plan 71% of residential deals; foreign buyers 62% of growth.
