Workbook

Sheet READ FIRST
A1: Palm Hills Developments — valuation workbook
A2: Edition of 10 September 2026. Supersedes 3 September 2026.
A4: This workbook is for information and education. It is not investment advice and carries no rating and no price target.
A6: BLUE cells are inputs and live on the Assumptions sheet. BLACK cells are formulas. Change a blue cell and the statements, the discounted cash flow and the value per share all recompute.
A8: Reported history comes only from the company's own audited statements and its own results releases. Where a figure the valuation needs is not disclosed, it is absent and named on the Assumptions sheet rather than estimated.
A10: The single most important number in this workbook is cash conversion — the share of revenue that reaches operating cash flow. The company does not disclose its collection terms, so it is measured from the three published cash-flow statements and it spans 3.9% to 17.9%. The Sensitivity sheet shows what that does to the answer.

Sheet Summary
A1: Summary
A2: Every figure recomputes from Assumptions.
A4: Lens | B4: Bear | C4: Base | D4: Full value | E4: Weight
A5: Discounted cash flow | B5: 4.98 | C5: 21.09 | D5: 55.07
A6: Earnings multiple on own history | B6: 5.59 | C6: 8.39 | D6: 13.05
A7: Book value of equity — a disclosed floor | B7: 5.97 | C7: 6.63 | D7: 8.62
A8: Weighted central | B8: 4.98 | C8: 21.09 | D8: 55.07 | E8: 1
A10: Valuation | B10: Per share (EGP) | C10: Equity (EGP mn) | D10: Enterprise value
A11: Weak cash conversion (3.9%) | B11: 7.65 | C11: 21883 | D11: 41344
A12: Average cash conversion (8.7%) | B12: 21.09 | C12: 60315 | D12: 81664
A13: Strong cash conversion (17.9%) | B13: 46.85 | C13: 133993 | D13: 158963
A14: Average, alternative country-risk basis | B14: 20.7 | C14: 59192 | D14: 80486
A16: Market price, 23 Aug 2026 | B16: 14.4
A17: Book value of equity per share | B17: 6.63
A18: Cash conversion implied by the market price | B18: 0.0634
A20: Cost of capital
A21: Weighted average, rating basis | B21: 0.25830684
A22: Weighted average, swap basis | B22: 0.24964724
A23: 11 June 2026 edition used | B23: 0.18

Sheet Fundamental Valuation
A1: Fundamental valuation — bridge to equity
A2: All formulas; drivers live on Assumptions.
A4: Present value of the explicit five years | B4: 52181.7
A5: Present value of the terminal value | B5: 29482.4
A6: Enterprise value | B6: =B4+B5
A7: less net debt, 31 March 2026 | B7: =-Assumptions!B14
A8: plus investments in associates | B8: =Assumptions!B15
A9: plus investment property | B9: =Assumptions!B16
A10: Equity value before minority interests | B10: =B6+B7+B8+B9
A11: less minority interests at their share of value | B11: =-B10*Assumptions!B17
A12: Equity value attributable to shareholders | B12: =B10+B11
A13: Shares outstanding (mn) | B13: =Assumptions!B18
A14: Value per share (EGP) | B14: =B12/B13
A16: Terminal value as a share of enterprise value | B16: =B5/B6

Sheet Assumptions
A1: Assumptions — every blue cell is an input
A2: Change one and the whole workbook recomputes.
A4: Driver | B4: Value | C4: Source
A5: Cash conversion — central | B5: 0.087136637 | C5: mean of the three published cash-flow statements
A6: Cash conversion — weak | B6: 0.039375935 | C6: 2023 and 2025 outcome
A7: Cash conversion — strong | B7: 0.17870013 | C7: 2024 outcome
A8: Gross margin | B8: 0.35483871 | C8: the first quarter of 2026 on its own, the latest disclosure; NOT an average (FY2025 was 41.16%, 1Q2026 35.48%)
A9: Overheads as a share of revenue | B9: 0.17599456 | C9: FY2025 as reported
A10: Price escalation | B10: 0.252 | C10: Egyptian consumer price inflation, three-year mean
A11: Terminal growth | B11: 0.07 | C11: the terminal growth this model runs, read from the valuation module
A12: Cost of capital — ADOPTED (traded default-swap basis) | B12: 0.24964724 | C12: the rate this model discounts at; section 1.8 marks it adopted
A13: Cost of capital — alternative (credit-rating basis), not used | B13: 0.25830684 | C13: published for comparison only; no cell on this sheet reads it
A14: Net debt (EGP mn) | B14: 23244.719 | C14: gross borrowings less cash, 31 March 2026 reviewed balance sheet
A15: Investments in associates (EGP mn) | B15: 3838.6972 | C15: 31 March 2026 reviewed balance sheet
A16: Investment property (EGP mn) | B16: 1020.4749 | C16: 31 March 2026 reviewed balance sheet
... A24: Maintenance capital expenditure, share of revenue | B24: 0.01 | C24: the building itself is inventory and sits in operating cash
A26: NOT DISCLOSED — absent by design, never estimated
A27: cash flow statement detail | C27: The FY2025 cash-flow statement is published in its three totals only (operating EGP 1,424.2mn, investing EGP -4,031.7mn, financing EGP 5,628.8mn); no line-by-line statement is post
A28: fy2025 results release | C28: PHD has published FY2025 consolidated statements but NO FY2025 full-year results release. The release is where units sold, new sales, deliveries and construction spend are disclose
A29: h1 2026 results | C29: A half-year 2026 release of 18-Aug-2026 is REPORTED in the trade press — an order book of EGP 284bn at 30 June, 40% up on the year, and a further EGP 75bn sold at Hacienda Ras El H
A30: securitisation pricing | C30: The EGP 2.015bn securitisation of 4-Feb-2026 discloses tranche sizes, tenors and national-scale ratings but NO coupon on any tranche, so the company's own marginal cost of debt can
A31: per project pricing | C31: The company does not disclose per-project unit mix, average unit area, price per square metre or construction cost per square metre. The 11-Jun-2026 edition carried a full per-proj
A32: backlog cost to complete | C32: Remaining construction cost against the EGP 263bn backlog is not disclosed as a single figure. It is inferred in the model from the realised gross margin and flagged where used.

Sheet SOTP Bridge
A1: Bridge from enterprise value to equity
A2: A developer is one business; the bridge is the parts that sit outside the operating cash flows.
A4: Operating business, discounted cash flow | B4: 81664.1
A5: Investments in associates, 31 March 2026 | B5: 3838.7
A6: Investment property, 31 March 2026 | B6: 1020.5
A7: Cash, 31 March 2026 | B7: 9125.1
A8: Gross borrowings, 31 March 2026 | B8: -32369.8
A9: Minority interests at their share of value | B9: =-(B4+B5+B6+B7+B8)*Assumptions!B17
A10: Equity value attributable to shareholders | B10: =B4+B5+B6+B7+B8+B9
A11: Per share (EGP) | B11: =B10/Assumptions!B18

Sheet Segments
A1: Units and prices by region — the forecast's drivers
A2: New sales value and unit counts are both disclosed per region; the price per unit is one divided by the other.
A4: North Coast & Alexandria
A5: Year | B5: 2020 | C5: 2021 | D5: 2022 | E5: 2023 | F5: 2024
A6: New sales (EGP mn) | B6: 4205 | C6: 7139 | D6: 5627 | E6: 13900 | F6: 95082
A7: Units sold | B7: 726 | C7: 1552 | D7: 800 | E7: 1231 | F7: 4192
A8: Price per unit (EGP mn) | B8: 5.792011 | C8: 4.5998711 | D8: 7.03375 | E8: 11.291633 | F8: 22.681775
A9: carried forward at 2074 units, price 22.68, escalated
A11: West Cairo & Badya
A12: Year | B12: 2020 | C12: 2021 | D12: 2022 | E12: 2023 | F12: 2024
A13: New sales (EGP mn) | B13: 6627 | C13: 7258 | D13: 13118 | E13: 32332 | F13: 44570
A14: Units sold | B14: 858 | C14: 1416 | D14: 2039 | E14: 2950 | F14: 2839
A15: Price per unit (EGP mn) | B15: 7.7237762 | C15: 5.1257062 | D15: 6.4335459 | E15: 10.96 | F15: 15.69919
A16: carried forward at 2609 units, price 15.70, escalated
A18: East Cairo
A19: Year | B19: 2020 | C19: 2021 | D19: 2022 | E19: 2023 | F19: 2024
A20: New sales (EGP mn) | B20: 1947 | C20: 2892 | D20: 7265 | E20: 13270 | F20: 11364
A21: Units sold | B21: 256 | C21: 382 | D21: 1194 | E21: 1200 | F21: 453
A22: Price per unit (EGP mn) | B22: 7.6054688 | C22: 7.5706806 | D22: 6.0845896 | E22: 11.058333 | F22: 25.086093
A23: carried forward at 949 units, price 25.09, escalated
A25: Disclosed group drivers
A26: Disclosed driver | B26: Value | C26: Note
A27: New sales, 1Q2026 (EGP mn) | B27: 52000 | C27: includes EGP 24,000mn from one land-plot launch
A28: New sales, FY2024 (EGP mn) | B28: 151016 | C28: chart series
A29: Order book, 31 Mar 2026 (EGP mn) | B29: 263000 | C29: units sold and not yet delivered
A30: Order book, FY2024 (EGP mn) | B30: 147000
A31: Units sold, FY2023 | B31: 5300 | C31: the last year the company disclosed a unit count
A32: Units delivered, FY2023 | B32: 1500
A33: Construction spend, FY2024 (EGP mn) | B33: 8500
A34: Cash collections, FY2024 (EGP mn) | B34: 25400
A35: Land bank (mn sqm) | B35: 33
A37: Build level: SEGMENT, not unit.
A38: The company discloses no per-project unit mix, unit area, price per square metre or construction cost per square metre. The forecast is built at the finest level the disclosure supports and the limit is stated rather than filled.

Sheet Relative & Normalized
A1: Relative and normalised measures
B4: 2023 | C4: 2024 | D4: 2025
A5: Revenue | B5: 17462.1 | C5: 27167.3 | D5: 36169.3
A6: Cash from operations | B6: 756.7 | C6: 4854.8 | D6: 1424.2
A7: Cash conversion | B7: =B6/B5 | C7: =C6/C5 | D7: =D6/D5
A9: Price to book (market) | B9: =14.4000/6.6281
A10: Book value per share (EGP) | B10: 6.63
A11: Return on equity, 2025 | B11: =4216.7/((18765.8+14624.7)/2)

Sheet DCF
A1: Discounted cash flow — central case
A2: Units delivered times revenue per delivered unit, then every row a formula. Change a blue cell on Assumptions and this recomputes.
A4: EGP million | B4: 2026 | C4: 2027 | D4: 2028 | E4: 2029 | F4: 2030 | G4: 2031 | H4: 2032 | I4: 2033 | J4: 2034 | K4: 2035 | L4: 2036 | M4: 2037 | N4: 2038 | O4: 2039 | P4: 2040
A5: Price and cost escalation | B5: 0.16 | C5: 0.12 | D5: 0.09 | E5: 0.075 | F5: 0.07 | G5: 0.07 | H5: 0.07 | I5: 0.07 | J5: 0.07 | K5: 0.07 | L5: 0.07 | M5: 0.07 | N5: 0.07 | O5: 0.07 | P5: 0.07 | Q5: the house inflation path
A6: Growth in units delivered | B6: 0 | C6: 0.15 | D6: 0.135 | E6: 0.12 | F6: 0.105 | G6: 0.09 | H6: 0.075 | I6: 0.06 | J6: 0.045 | K6: 0.03 | L6: 0.015 | M6: 0 | N6: 0 | O6: 0 | P6: 0 | Q6: the disclosed run, fading to nothing
A7: Units delivered | B7: =Assumptions!$B$21 | C7: =B7*(1+C6) | D7: =C7*(1+D6) | E7: =D7*(1+E6) | F7: =E7*(1+F6) | G7: =F7*(1+G6) | H7: =G7*(1+H6) | I7: =H7*(1+I6) | J7: =I7*(1+J6) | ... P7: =O7*(1+P6)
A8: Revenue per delivered unit | B8: =Assumptions!$B$23 | C8: =B8*(1+C5) | D8: =C8*(1+D5) | E8: =D8*(1+E5) | F8: =E8*(1+F5) | G8: =F8*(1+G5) | H8: =G8*(1+H5) | I8: =H8*(1+I5) | J8: =I8*(1+J5) | ... P8: =O8*(1+P5)
A9: Revenue | B9: =B7*B8 | C9: =C7*C8 | D9: =D7*D8 | E9: =E7*E8 | F9: =F7*F8 | G9: =G7*G8 | H9: =H7*H8 | I9: =I7*I8 | ... P9: =P7*P8
A10: Gross profit | B10: =B9*Assumptions!$B$8 | C10: =C9*Assumptions!$B$8 | D10: =D9*Assumptions!$B$8 | E10: =E9*Assumptions!$B$8 | F10: =F9*Assumptions!$B$8 | G10: =G9*Assumptions!$B$8 | H10: =H9*Assumptions!$B$8 | I10: =I9*Assumptions!$B$8 | ... P10: =P9*Assumptions!$B$8
A11: Overheads | B11: =-B9*Assumptions!$B$9 | C11: =-C9*Assumptions!$B$9 | D11: =-D9*Assumptions!$B$9 | E11: =-E9*Assumptions!$B$9 | F11: =-F9*Assumptions!$B$9 | G11: =-G9*Assumptions!$B$9 | H11: =-H9*Assumptions!$B$9 | I11: =-I9*Assumptions!$B$9 | ... P11: =-P9*Assumptions!$B$9
A12: Operating cash flow | B12: =B9*Assumptions!$B$5 | C12: =C9*Assumptions!$B$5 | D12: =D9*Assumptions!$B$5 | E12: =E9*Assumptions!$B$5 | F12: =F9*Assumptions!$B$5 | G12: =G9*Assumptions!$B$5 | H12: =H9*Assumptions!$B$5 | I12: =I9*Assumptions!$B$5 | ... P12: =P9*Assumptions!$B$5
A13: Maintenance capital expenditure | B13: =-B9*Assumptions!$B$24 | C13: =-C9*Assumptions!$B$24 | D13: =-D9*Assumptions!$B$24 | E13: =-E9*Assumptions!$B$24 | F13: =-F9*Assumptions!$B$24 | G13: =-G9*Assumptions!$B$24 | H13: =-H9*Assumptions!$B$24 | I13: =-I9*Assumptions!$B$24 | ... P13: =-P9*Assumptions!$B$24
A14: plus finance cost, after tax | B14: 2594.3 | C14: 2594.3 | D14: 2594.3 | E14: 2594.3 | F14: 2594.3 | G14: 2594.3 | H14: 2594.3 | I14: 2594.3 | J14: 2594.3 | K14: 2594.3 | L14: 2594.3 | M14: 2594.3 | N14: 2594.3 | O14: 2594.3 | P14: 2594.3
A15: Free cash flow to the firm | B15: =B12+B14+B13 | C15: =C12+C14+C13 | D15: =D12+D14+D13 | E15: =E12+E14+E13 | F15: =F12+F14+F13 | G15: =G12+G14+G13 | H15: =H12+H14+H13 | I15: =I12+I14+I13 | ... P15: =P12+P14+P13
A16: Cost of capital, that year | B16: 0.249647 | C16: 0.213967 | D16: 0.185423 | E16: 0.164015 | F16: 0.149743 | G16: 0.149743 | H16: 0.149743 | I16: 0.149743 | J16: 0.149743 | K16: 0.149743 | L16: 0.149743 | M16: 0.149743 | N16: 0.149743 | O16: 0.149743 | P16: 0.149743
A17: Discount factor | B17: =1/(1+B16) | C17: =B17/(1+C16) | D17: =C17/(1+D16) | E17: =D17/(1+E16) | F17: =E17/(1+F16) | G17: =F17/(1+G16) | H17: =G17/(1+H16) | I17: =H17/(1+I16) | J17: =I17/(1+J16) | ... P17: =O17/(1+P16)
A18: Present value | B18: =B15*B17 | C18: =C15*C17 | D18: =D15*D17 | E18: =E15*E17 | F18: =F15*F17 | G18: =G15*G17 | H18: =H15*H17 | I18: =I15*I17 | ... P18: =P15*P17
A20: Sum of the explicit years | B20: =SUM(B18:P18)
A21: Terminal value, discounted | B21: 29482.4
A22: Enterprise value | B22: =B20+B21

Sheet Income Statement
A1: Income statement — built from units and prices
A2: Gross margin is an OUTPUT of price per unit against cost per unit.
A4: EGP mn unless stated | B4: 2026 | C4: 2027 | D4: 2028 | E4: 2029 | F4: 2030 | G4: 2031 | H4: 2032 | I4: 2033 | J4: 2034 | K4: 2035 | L4: 2036 | M4: 2037 | N4: 2038 | O4: 2039 | P4: 2040
A5: Units sold | B5: 5632.6667 | C5: 5632.6667 | D5: 5632.6667 | E5: 5632.6667 | F5: 5632.6667 | G5: 5632.6667 | H5: 5632.6667 | I5: 5632.6667 | J5: 5632.6667 | K5: 5632.6667 | L5: 5632.6667 | M5: 5632.6667 | N5: 5632.6667 | O5: 5632.6667 | P5: 5632.6667
A6: New sales | B6: 129711.99 | C6: 145277.43 | D6: 158352.4 | E6: 170228.83 | F6: 182144.85 | G6: 194894.99 | H6: 208537.64 | I6: 223135.27 | J6: 238754.74 | K6: 255467.57 | L6: 273350.3 | M6: 292484.82 | N6: 312958.76 | O6: 334865.87 | P6: 358306.49
A7: Units delivered | B7: 2035.0931 | C7: 2340.3571 | D7: 2656.3053 | E7: 2975.0619 | F7: 3287.4434 | G7: 3583.3133 | H7: 3852.0618 | I7: 4083.1855 | J7: 4266.9289 | K7: 4394.9367 | L7: 4460.8608 | M7: 4460.8608 | N7: 4460.8608 | O7: 4460.8608 | P7: 4460.8608
A8: Revenue per delivered unit | B8: 19.7278 | C8: 22.0951 | D8: 24.0837 | E8: 25.89 | F8: 27.7023 | G8: 29.6414 | H8: 31.7163 | I8: 33.9365 | J8: 36.312 | K8: 38.8539 | L8: 41.5737 | M8: 44.4838 | N8: 47.5977 | O8: 50.9295 | P8: 54.4946
A9: Revenue | B9: 40147.923 | C9: 51710.525 | D9: 63973.676 | E9: 77024.306 | F9: 91069.688 | G9: 106214.58 | H9: 122173.32 | I9: 138568.98 | J9: 154940.9 | K9: 170760.37 | L9: 185454.3 | M9: 198436.1 | N9: 212326.62 | O9: 227189.49 | P9: 243092.75
A10: Cost per delivered unit | B10: 12.7276 | C10: 14.2549 | D10: 15.5379 | E10: 16.7032 | F10: 17.8724 | G10: 19.1235 | H10: 20.4622 | I10: 21.8945 | J10: 23.4271 | K10: 25.067 | L10: 26.8217 | M10: 28.6992 | N10: 30.7082 | O10: 32.8578 | P10: 35.1578
A11: Cost of revenue | B11: 25901.886 | C11: 33361.629 | D11: 41273.339 | E11: 49693.1 | F11: 58754.637 | G11: 68525.534 | H11: 78821.495 | I11: 89399.34 | J11: 99961.871 | K11: 110167.98 | L11: 119647.93 | M11: 128023.29 | N11: 136984.92 | O11: 146573.86 | P11: 156834.03
A12: Gross profit | B12: 14246.037 | C12: 18348.896 | D12: 22700.337 | E12: 27331.205 | F12: 32315.051 | G12: 37689.043 | H12: 43351.822 | I12: 49169.637 | J12: 54979.029 | K12: 60592.388 | L12: 65806.363 | M12: 70412.809 | N12: 75341.705 | O12: 80615.625 | P12: 86258.718
A13: Gross margin | B13: 0.3548 | C13: 0.3548 | D13: 0.3548 | E13: 0.3548 | F13: 0.3548 | G13: 0.3548 | H13: 0.3548 | I13: 0.3548 | J13: 0.3548 | K13: 0.3548 | L13: 0.3548 | M13: 0.3548 | N13: 0.3548 | O13: 0.3548 | P13: 0.3548
A14: Overheads | B14: 7065.816 | C14: 9100.771 | D14: 11259.019 | E14: 13555.859 | F14: 16027.77 | G14: 18693.188 | H14: 21501.839 | I14: 24387.386 | J14: 27268.755 | K14: 30052.895 | L14: 32638.947 | M14: 34923.673 | N14: 37368.33 | O14: 39984.114 | P14: 42783.002
A15: Operating profit | B15: 6787.6142 | C15: 8742.4471 | D15: 10815.718 | E15: 13022.125 | F15: 15396.709 | G15: 17957.182 | H15: 20655.249 | I15: 23427.183 | J15: 26195.105 | K15: 28869.625 | L15: 31353.856 | M15: 33548.626 | N15: 35897.03 | O15: 38409.822 | P15: 41098.51
... A20: Order book, closing | B20: 352564.07 | C20: 446130.98 | D20: 540509.7 | E20: 633714.22 | F20: 724789.38 | G20: 813469.8 | H20: 899834.12 | I20: 984400.41 | J20: 1068214.2 | K20: 1152921.5 | L20: 1240817.5 | M20: 1334866.2 | N20: 1435498.3 | O20: 1543174.7 | P20: 1658388.4

Sheet Balance Sheet
A1: Balance sheet — as reported, then forecast both ways
A2: EGP million. Assets equal liabilities plus shareholders' funds in every reported and every forecast year.
A4: AS REPORTED | B4: 2025 | C4: 2024
A5: Non-current assets | B5: 65900.2 | C5: 54166.4
A6: Current assets | B6: 106229.6 | C6: 69270.9
A7: Total assets | B7: 172129.8 | C7: 123437.3
A8: Current liabilities | B8: 105099 | C8: 74496.9
A9: Non-current liabilities | B9: 48265.1 | C9: 34315.7
A10: Total liabilities | B10: 153364.1 | C10: 108812.6
A11: Shareholders' funds | B11: 18765.8 | C11: 14624.7
A12: Check: assets less liabilities and equity | B12: =B7-B10-B11 | C12: =C7-C10-C11
A14: FORECAST — IF CASH CONVERSION HOLDS
A15: EGP mn unless stated | B15: 2026 | C15: 2027 | D15: 2028 | E15: 2029 | F15: 2030 | G15: 2031 | H15: 2032 | I15: 2033 | J15: 2034 | K15: 2035 | L15: 2036 | M15: 2037 | N15: 2038 | O15: 2039 | P15: 2040
A16: Trade and notes receivable | B16: 102780.69 | C16: 103081.1 | D16: 104474.6 | E16: 107031.36 | F16: 110840.06 | G16: 115998.7 | H16: 122579.82 | I16: 130622.37 | J16: 140124.24 | K16: 151036.17 | L16: 163257.84 | M16: 176636.65 | N16: 191253.59 | O16: 207195.34 | P16: 224554.62
A17: Work in progress | B17: 17446.946 | C17: 17497.942 | D17: 17734.487 | E17: 18168.496 | F17: 18815.02 | G17: 19690.695 | H17: 20807.836 | I17: 22173.053 | J17: 23785.987 | K17: 25638.28 | L17: 27712.9 | M17: 29983.943 | N17: 32465.158 | O17: 35171.258 | P17: 38117.983
A18: Other receivables and prepayments | B18: 12830.842 | C18: 12868.345 | D18: 13042.305 | E18: 13361.484 | F18: 13836.951 | G18: 14480.941 | H18: 15302.509 | I18: 16306.517 | J18: 17492.702 | K18: 18854.916 | L18: 20380.635 | M18: 22050.806 | N18: 23875.543 | O18: 25865.664 | P18: 28032.746
A19: Advances to suppliers | B19: 8992.3133 | C19: 9018.5969 | D19: 9140.5142 | E19: 9364.2062 | F19: 9697.4304 | G19: 10148.761 | H19: 10724.546 | I19: 11428.191 | J19: 12259.512 | K19: 13214.2 | L19: 14283.478 | M19: 15453.994 | N19: 16732.835 | O19: 18127.583 | P19: 19646.352
A20: Cash and equivalents | B20: 12516.376 | C20: 16505.152 | D20: 21439.866 | E20: 27381.262 | F20: 34406.071 | G20: 42599.107 | H20: 52023.146 | I20: 62711.89 | J20: 74663.511 | K20: 87835.391 | L20: 102140.71 | M20: 117447.4 | N20: 133825.57 | O20: 151350.2 | P20: 170101.56
A21: Property and equipment | B21: 4530.8722 | C21: 4542.2997 | D21: 4556.4371 | E21: 4573.4586 | F21: 4593.584 | G21: 4617.0562 | H21: 4644.0551 | I21: 4674.6772 | J21: 4708.9174 | K21: 4746.6534 | L21: 4787.6367 | M21: 4831.4888 | N21: 4878.4106 | O21: 4928.6168 | P21: 4982.3375
A22: Other assets, held at the 2025 level | B22: 15128.3 | C22: 15128.3 | D22: 15128.3 | E22: 15128.3 | F22: 15128.3 | G22: 15128.3 | H22: 15128.3 | I22: 15128.3 | J22: 15128.3 | K22: 15128.3 | L22: 15128.3 | M22: 15128.3 | N22: 15128.3 | O22: 15128.3 | P22: 15128.3
A23: TOTAL ASSETS | B23: 174226.33 | C23: 178641.74 | D23: 185516.51 | E23: 195008.57 | F23: 207317.42 | G23: 222663.56 | H23: 241210.21 | I23: 263045 | J23: 288163.16 | K23: 316453.91 | L23: 347691.5 | M23: 381532.59 | N23: 418159.41 | O23: 457766.96 | P23: 500563.9
A24: Customer advances | B24: 68864.843 | C24: 69066.129 | D24: 69999.794 | E24: 71712.87 | F24: 74264.765 | G24: 77721.143 | H24: 82130.609 | I24: 87519.257 | J24: 93885.67 | K24: 101196.85 | L24: 109385.59 | M24: 118349.62 | N24: 128143.23 | O24: 138824.47 | P24: 150455.49
A25: Suppliers | B25: 3780.1436 | C25: 3791.1926 | D25: 3842.4436 | E25: 3936.4781 | F25: 4076.5572 | G25: 4266.2855 | H25: 4508.3308 | I25: 4804.1257 | J25: 5153.5922 | K25: 5554.9192 | L25: 6004.417 | M25: 6496.4727 | N25: 7034.0653 | O25: 7620.3825 | P25: 8258.8349
A26: Other creditors | B26: 5085.5691 | C26: 5100.4337 | D26: 5169.3836 | E26: 5295.8918 | F26: 5484.3455 | G26: 5739.594 | H26: 6065.2267 | I26: 6463.1706 | J26: 6933.321 | K26: 7473.2413 | L26: 8077.9675 | M26: 8739.9485 | N26: 9463.1921 | O26: 10251.987 | P26: 11110.921
... A39: as a multiple of revenue | B39: 1.5414 | C39: 1.2002 | D39: 0.9833 | E39: 0.8367 | F39: 0.7328 | G39: 0.6576 | H39: 0.6041 | I39: 0.5676 | J39: 0.5445 | K39: 0.5325 | L39: 0.53 | M39: 0.536 | N39: 0.5423 | O39: 0.5491 | P39: 0.5562
A41: FORECAST — IF THE COLLECTION CYCLE HOLDS
A42: EGP mn unless stated | B42: 2026 | C42: 2027 | D42: 2028 | E42: 2029 | F42: 2030 | G42: 2031 | H42: 2032 | I42: 2033 | J42: 2034 | K42: 2035 | L42: 2036 | M42: 2037 | N42: 2038 | O42: 2039 | P42: 2040
A43: Trade and notes receivable | B43: 114897.1 | C43: 147987.46 | D43: 183082.69 | E43: 220431.56 | F43: 260627.25 | G43: 303969.57 | H43: 349640.99 | I43: 396562.82 | J43: 443416.71 | K43: 488689.56 | L43: 530741.29 | M43: 567893.19 | N43: 607645.71 | O43: 650180.91 | P43: 695693.57
A44: Work in progress | B44: 19503.699 | C44: 25120.764 | D44: 31078.154 | E44: 37418.097 | F44: 44241.287 | G44: 51598.613 | H44: 59351.304 | I44: 67316.25 | J44: 75269.664 | K44: 82954.697 | L44: 90092.949 | M44: 96399.455 | N44: 103147.42 | O44: 110367.74 | P44: 118093.48
A45: Other receivables and prepayments | B45: 14343.42 | C45: 18474.325 | D45: 22855.511 | E45: 27518.035 | F45: 32535.949 | G45: 37946.677 | H45: 43648.166 | I45: 49505.75 | J45: 55354.854 | K45: 61006.584 | L45: 66256.201 | M45: 70894.135 | N45: 75856.725 | O45: 81166.695 | P45: 86848.364
A46: Advances to suppliers | B46: 10052.382 | C46: 12947.468 | D46: 16017.96 | E46: 19285.624 | F46: 22802.357 | G46: 26594.39 | H46: 30590.196 | I46: 34695.401 | J46: 38794.662 | K46: 42755.598 | L46: 46434.717 | M46: 49685.147 | N46: 53163.107 | O46: 56884.525 | P46: 60866.441
A47: Cash and equivalents | B47: 5221.1313 | C47: 2354.875 | D47: 2354.875 | E47: 2354.875 | F47: 2354.875 | G47: 2354.875 | H47: 2354.875 | I47: 2354.875 | J47: 2354.875 | K47: 2354.875 | L47: 2354.875 | M47: 3347.8907 | N47: 4592.0193 | O47: 6104.8389 | P47: 7905.1577
A48: Property and equipment | B48: 4530.8722 | C48: 4542.2997 | D48: 4556.4371 | E48: 4573.4586 | F48: 4593.584 | G48: 4617.0562 | H48: 4644.0551 | I48: 4674.6772 | J48: 4708.9174 | K48: 4746.6534 | L48: 4787.6367 | M48: 4831.4888 | N48: 4878.4106 | O48: 4928.6168 | P48: 4982.3375
A49: Other assets, held at the 2025 level | B49: 15128.3 | C49: 15128.3 | D49: 15128.3 | E49: 15128.3 | F49: 15128.3 | G49: 15128.3 | H49: 15128.3 | I49: 15128.3 | J49: 15128.3 | K49: 15128.3 | L49: 15128.3 | M49: 15128.3 | N49: 15128.3 | O49: 15128.3 | P49: 15128.3
A50: TOTAL ASSETS | B50: 183676.9 | C50: 226555.5 | D50: 275073.93 | E50: 326709.95 | F50: 382283.61 | G50: 442209.48 | H50: 505357.89 | I50: 570238.07 | J50: 635027.99 | K50: 697636.27 | L50: 755795.97 | M50: 808179.6 | N50: 864411.69 | O50: 924761.62 | P50: 989517.65
A51: Customer advances | B51: 76983.051 | C51: 99154.17 | D51: 122668.58 | E51: 147692.97 | F51: 174624.78 | G51: 203664.89 | H51: 234265.54 | I51: 265703.97 | J51: 297096.89 | K51: 327430.49 | L51: 355605.88 | M51: 380498.29 | N51: 407133.17 | O51: 435632.5 | P51: 466126.77
A52: Suppliers | B52: 4225.77 | C52: 5442.7918 | D52: 6733.5498 | E52: 8107.194 | F52: 9585.5408 | G52: 11179.616 | H52: 12859.354 | I52: 14585.079 | J52: 16308.306 | K52: 17973.384 | L52: 19519.994 | M52: 20886.393 | N52: 22348.441 | O52: 23912.832 | P52: 25586.73
A53: Other creditors | B53: 5685.087 | C53: 7322.3921 | D53: 9058.8973 | E53: 10906.912 | F53: 12895.788 | G53: 15040.357 | H53: 17300.171 | I53: 19621.854 | J53: 21940.176 | K53: 24180.268 | L53: 26260.98 | M53: 28099.249 | N53: 30066.196 | O53: 32170.83 | P53: 34422.788
... A66: as a multiple of revenue | B66: 1.7231 | C66: 1.7231 | D66: 1.7231 | E66: 1.7231 | F66: 1.7231 | G66: 1.7231 | H66: 1.7231 | I66: 1.7231 | J66: 1.7231 | K66: 1.7231 | L66: 1.7231 | M66: 1.7231 | N66: 1.7231 | O66: 1.7231 | P66: 1.7231
A68: The cycle as reported, both audited years
...

Sheet Cash Flow
A1: Cash flow — forecast, both readings
A2: The audited balance sheet and the audited cash-flow statement disagree about 2025 by EGP 16,938 million, and that difference cannot be split from what is disclosed. So the forecast is published two ways and neither is averaged into the other.
A4: IF CASH CONVERSION HOLDS — the basis of the valuation
A5: EGP mn unless stated | B5: 2026 | C5: 2027 | D5: 2028 | E5: 2029 | F5: 2030 | G5: 2031 | H5: 2032 | I5: 2033 | J5: 2034 | K5: 2035 | L5: 2036 | M5: 2037 | N5: 2038 | O5: 2039 | P5: 2040
A6: Net profit | B6: 2666.0885 | C6: 4181.084 | D6: 5787.8693 | E6: 7497.8343 | F6: 9338.1373 | G6: 11322.504 | H6: 13413.505 | I6: 15561.754 | J6: 17706.894 | K6: 19779.647 | L6: 21704.926 | M6: 23405.873 | N6: 25225.886 | O6: 27173.3 | P6: 29257.033
A7: Depreciation and amortisation | B7: 392.607 | C7: 505.6778 | D7: 625.5993 | E7: 753.2216 | F7: 890.5715 | G7: 1038.6736 | H7: 1194.7343 | I7: 1355.0676 | J7: 1515.1688 | K7: 1669.8676 | L7: 1813.5597 | M7: 1940.5089 | N7: 2076.3445 | O7: 2221.6886 | P7: 2377.2068
A8: Change in working capital, cash effect | B8: 439.6595 | C8: -180.8806 | D8: -839.0176 | E8: -1539.4169 | F8: -2293.2025 | G8: -3105.9962 | H8: -3962.4676 | I8: -4842.3875 | J8: -5721.0336 | K8: -6570.0305 | L8: -7358.6222 | M8: -8055.3276 | N8: -8800.8024 | O8: -9598.4604 | P8: -10451.954
A9: Cash from operations | B9: 3498.355 | C9: 4505.8812 | D9: 5574.451 | E9: 6711.639 | F9: 7935.5064 | G9: 9255.1811 | H9: 10645.772 | I9: 12074.435 | J9: 13501.029 | K9: 14879.484 | L9: 16159.864 | M9: 17291.054 | N9: 18501.428 | O9: 19796.528 | P9: 21182.285
A10: as a share of revenue | B10: 0.0871 | C10: 0.0871 | D10: 0.0871 | E10: 0.0871 | F10: 0.0871 | G10: 0.0871 | H10: 0.0871 | I10: 0.0871 | J10: 0.0871 | K10: 0.0871 | L10: 0.0871 | M10: 0.0871 | N10: 0.0871 | O10: 0.0871 | P10: 0.0871
A11: Capital expenditure | B11: -401.4792 | C11: -517.1052 | D11: -639.7368 | E11: -770.2431 | F11: -910.6969 | G11: -1062.1458 | H11: -1221.7332 | I11: -1385.6898 | J11: -1549.409 | K11: -1707.6037 | L11: -1854.543 | M11: -1984.361 | N11: -2123.2662 | O11: -2271.8949 | P11: -2430.9275
A12: New borrowing drawn | B12: 0 | C12: 0 | D12: 0 | E12: 0 | F12: 0 | G12: 0 | H12: 0 | I12: 0 | J12: 0 | K12: 0 | L12: 0 | M12: 0 | N12: 0 | O12: 0 | P12: 0
A13: Cash from financing | B13: 0 | C13: 0 | D13: 0 | E13: 0 | F13: 0 | G13: 0 | H13: 0 | I13: 0 | J13: 0 | K13: 0 | L13: 0 | M13: 0 | N13: 0 | O13: 0 | P13: 0
A14: Closing cash | B14: 12516.376 | C14: 16505.152 | D14: 21439.866 | E14: 27381.262 | F14: 34406.071 | G14: 42599.107 | H14: 52023.146 | I14: 62711.89 | J14: 74663.511 | K14: 87835.391 | L14: 102140.71 | M14: 117447.4 | N14: 133825.57 | O14: 151350.2 | P14: 170101.56
A15: Cumulative new borrowing | B15: 0 | C15: 0 | D15: 0 | E15: 0 | F15: 0 | G15: 0 | H15: 0 | I15: 0 | J15: 0 | K15: 0 | L15: 0 | M15: 0 | N15: 0 | O15: 0 | P15: 0
A17: IF THE COLLECTION CYCLE HOLDS
A18: EGP mn unless stated | B18: 2026 | C18: 2027 | D18: 2028 | E18: 2029 | F18: 2030 | G18: 2031 | H18: 2032 | I18: 2033 | J18: 2034 | K18: 2035 | L18: 2036 | M18: 2037 | N18: 2038 | O18: 2039 | P18: 2040
A19: Net profit | B19: 2666.0885 | C19: 4181.084 | D19: 5787.8693 | E19: 7497.8343 | F19: 9338.1373 | G19: 11322.504 | H19: 13413.505 | I19: 15561.754 | J19: 17706.894 | K19: 19779.647 | L19: 21704.926 | M19: 23405.873 | N19: 25225.886 | O19: 27173.3 | P19: 29257.033
A20: Depreciation and amortisation | B20: 392.607 | C20: 505.6778 | D20: 625.5993 | E20: 753.2216 | F20: 890.5715 | G20: 1038.6736 | H20: 1194.7343 | I20: 1355.0676 | J20: 1515.1688 | K20: 1669.8676 | L20: 1813.5597 | M20: 1940.5089 | N20: 2076.3445 | O20: 2221.6886 | P20: 2377.2068
A21: Change in working capital, cash effect | B21: -6855.585 | C21: -19923.576 | D21: -21130.696 | E21: -22487.605 | F21: -24201.667 | G21: -26096.233 | H21: -27498.584 | I21: -28251.442 | J21: -28210.544 | K21: -27258.6 | L21: -25319.183 | M21: -22369.005 | N21: -23934.836 | O21: -25610.274 | P21: -27402.993
A22: Cash from operations | B22: -3796.8895 | C22: -15236.815 | D22: -14717.228 | E22: -14236.549 | F22: -13972.959 | G22: -13735.056 | H22: -12890.345 | I22: -11334.619 | J22: -8988.4816 | K22: -5809.0856 | L22: -1800.6969 | M22: 2977.3767 | N22: 3367.3949 | O22: 3784.7144 | P22: 4231.2463
A23: as a share of revenue | B23: -0.0946 | C23: -0.2947 | D23: -0.2301 | E23: -0.1848 | F23: -0.1534 | G23: -0.1293 | H23: -0.1055 | I23: -0.0818 | J23: -0.058 | K23: -0.034 | L23: -0.0097 | M23: 0.015 | N23: 0.0159 | O23: 0.0167 | P23: 0.0174
A24: Capital expenditure | B24: -401.4792 | C24: -517.1052 | D24: -639.7368 | E24: -770.2431 | F24: -910.6969 | G24: -1062.1458 | H24: -1221.7332 | I24: -1385.6898 | J24: -1549.409 | K24: -1707.6037 | L24: -1854.543 | M24: -1984.361 | N24: -2123.2662 | O24: -2271.8949 | P24: -2430.9275
A25: New borrowing drawn | B25: 0 | C25: 12887.664 | D25: 15356.964 | E25: 15006.792 | F25: 14883.656 | G25: 14797.202 | H25: 14112.078 | I25: 12720.309 | J25: 10537.891 | K25: 7516.6892 | L25: 3655.2398 | M25: 0 | N25: 0 | O25: 0 | P25: 0
A26: Cash from financing | B26: 0 | C26: 12887.664 | D26: 15356.964 | E26: 15006.792 | F26: 14883.656 | G26: 14797.202 | H26: 14112.078 | I26: 12720.309 | J26: 10537.891 | K26: 7516.6892 | L26: 3655.2398 | M26: 0 | N26: 0 | O26: 0 | P26: 0
A27: Closing cash | B27: 5221.1313 | C27: 2354.875 | D27: 2354.875 | E27: 2354.875 | F27: 2354.875 | G27: 2354.875 | H27: 2354.875 | I27: 2354.875 | J27: 2354.875 | K27: 2354.875 | L27: 2354.875 | M27: 3347.8907 | N27: 4592.0193 | O27: 6104.8389 | P27: 7905.1577
A28: Cumulative new borrowing | B28: 0 | C28: 12887.664 | D28: 28244.628 | E28: 43251.42 | F28: 58135.076 | G28: 72932.277 | H28: 87044.355 | I28: 99764.664 | J28: 110302.55 | K28: 117819.24 | L28: 121474.48 | M28: 121474.48 | N28: 121474.48 | O28: 121474.48 | P28: 121474.48
A30: Cash conversion, the three published years
A31: FY2023 | B31: 0.043334
A32: FY2024 | B32: 0.1787
A33: FY2025 | B33: 0.039376
A34: mean, carried above | B34: 0.087137

Sheet Summary Financials
A1: Summary financials, as reported
A4: EGP million | B4: 2023 | C4: 2024 | D4: 2025
A5: Revenue | B5: 17462.1 | C5: 27167.3 | D5: 36169.3
A6: Cost of revenue | B6: -11907.2 | C6: -17739.9 | D6: -21118.9
A7: Gross profit | B7: 5507.6 | C7: 9330.1 | D7: 14887.6
A8: Overheads | B8: -2060.5 | C8: -3435.8 | D8: -6365.6
A9: Finance cost | C9: -2311.4 | D9: -3347.5
A10: Pre-tax profit | B10: 2300.7 | C10: 4320.6 | D10: 6251.1
A11: Tax | B11: -567.3 | C11: -917.1 | D11: -1827.2
A12: Profit after tax and minority | B12: 1581.5 | C12: 3254.9 | D12: 4216.7
A13: Cash from operations | B13: 756.7 | C13: 4854.8 | D13: 1424.2
A14: Cash from operations, share of revenue | B14: =B14/B5 | C14: =C14/C5 | D14: =D14/D5

Sheet Monte Carlo
A1: Price distribution — published output, reproduced not re-derived
A2: This is the price engine's distribution, independent of the valuation.
A4: Percentile | B4: One month | C4: Three months
A5: 5th | B5: 13.08 | C5: 11.98
A6: 25th | B6: 14.67 | C6: 14.61
A7: 50th | B7: 15.64 | C7: 16.34
A8: 75th | B8: 16.68 | C8: 18.27
A9: 95th | B9: 18.71 | C9: 22.26
A11: Resolved three-month tests | B11: 57
A12: Inside the 90% band | B12: 0.9123
A13: Inside the middle band | B13: 0.5088
A14: Band width vs a random walk | B14: 1.469

Sheet Sensitivity
A1: Value per share against the two things that move it
A2: Read down a column: cash conversion moves value more than the discount rate does.
A4: Cash conversion | B4: 0.20964724 | C4: 0.22964724 | D4: 0.24964724 | E4: 0.26964724 | F4: 0.28964724
A5: 0.039375935 | B5: 20.9 | C5: 12.08 | D5: 7.65 | E5: 4.98 | F5: 3.19
A6: 0.06 | B6: 33.33 | C6: 20.07 | D6: 13.45 | E6: 9.49 | F6: 6.85
A7: 0.087136637 | B7: 49.69 | C7: 30.59 | D7: 21.09 | E7: 15.42 | F7: 11.66
A8: 0.12 | B8: 69.5 | C8: 43.32 | D8: 30.34 | E8: 22.6 | F8: 17.48
A9: 0.17870013 | B9: 104.89 | C9: 66.07 | D9: 46.85 | E9: 35.43 | F9: 27.89

Sheet Per-Share & Ratios
A1: Per share and ratios
A4: Shares outstanding (mn) | B4: 2859.92
A5: Market price (EGP) | B5: 14.4
A6: Book value per share (EGP) | B6: 6.6281
A7: Price to book | B7: 2.1726
A8: Earnings per share, 2025 (EGP) | B8: 1.4744
A9: Net debt per share, 31 March 2026 (EGP) | B9: 8.1278
A10: Order book per share (EGP) | B10: 91.9606
A11: Gross margin, 2025 | B11: 0.4116
A12: Cash conversion, 2025 | B12: 0.0394

Sheet Peer & Sector
A1: Egyptian listed developers
A2: Every measure on the same window, the same cleaning and the same index.
A4: Code | B4: Company | C4: Beta | D4: R-squared | E4: Std error | F4: Volatility | G4: Worst fall
A5: TMGH | B5: Talaat Moustafa Group Holding | C5: 1.4687 | D5: 0.3252 | E5: 0.1833 | F5: 0.4394 | G5: -0.4419
A6: PHDC | B6: Palm Hills Developments | C6: 1.0481 | D6: 0.2997 | E6: 0.1808 | F6: 0.4391 | G6: -0.4866
A7: ORHD | B7: Orascom Development Egypt | C7: 0.8817 | D7: 0.3251 | E7: 0.1727 | F7: 0.4619 | G7: -0.4293
A8: HELI | B8: Heliopolis Housing and Development | C8: 0.7648 | D8: 0.2874 | E8: 0.1803 | F8: 0.444 | G8: -0.3958
A9: EMFD | B9: Emaar Misr for Development | C9: 0.7349 | D9: 0.2423 | E9: 0.1693 | F9: 0.412 | G9: -0.4712
A10: PRDC | B10: Pioneers Properties for Urban Development | C10: 0.7006 | D10: 0.2565 | E10: 0.1854 | F10: 0.4217 | G10: -0.5199
A11: OCDI | B11: Sixth of October Development & Investment (SODIC) | C11: 0.4949 | D11: 0.1018 | E11: 0.2275 | F11: 0.4755 | G11: -0.4658
A13: Earnings and book multiples are not published for the peer group: no peer discloses statements this study can obtain on a consistent basis, and an inconsistent multiple would mislead.
