Workbook

Sheet READ FIRST
A1: Read this first
A5: THE RULE
A6: IT CALCULATES. IT DOES NOT STORE.
A8: Exactly ONE class of cell is pasted in this workbook: a figure read off an audited or disclosed filing, or a stated house judgement. Those are the blue cells on Assumptions, and the blue lever cells that define each sensitivity grid point. Everything else is a live formula.
A10: The previous edition also pasted its sensitivity grids, its beta sweep and its bear and bull columns, on the grounds that each is a whole-model re-run and a re-run cannot be written inside a grid. That was 27.6% of the file, and it was the part a reader would most want to interrogate. Three of those pasted rows turned out not to reproduce.
A12: The Sensitivity sheet now writes the entire forecast engine out again, in formulas, once for every grid point. Change any driver on Assumptions and every sensitivity cell in the file moves with it.
A14: WHAT IS AUDITED AND WHAT IS NOT
A15: The base year is the twelve months to 30 June 2026. The first half of it — July to December 2025 — is AUDITED by Crowe with an unqualified opinion. The second half — January to June 2026 — is REPORTED: a disclosure to the Egyptian Exchange dated 29-30 July 2026, not a filing. Half of this base year is a press release and the study says so wherever it uses it.
A17: The gross profit of that reported half is NOT used as released. Run through the company's own first-quarter expense run rates the released figure implies a profit after tax about 12.6% above the profit the same release reports. The gross profit used here is solved from the profit line, which passes two independent coherence tests. Base Year rows 13 to 17 show the whole test.
A19: THE ONE OPERATING INPUT THAT IS NOT READ OFF A FILING
A20: Note 15-A discloses the cost stack for the company and not by line. The processing-intensity weights on Assumptions are therefore a judgement, and the per-line margins depend on them. They are registered, dated and sensitised like every other input rather than hidden inside a formula.

Sheet Summary
A1: Summary — the answer, and every lens behind it
A2: Nothing on this sheet is typed. Every figure points at the sheet that computed it, so a driver changed on Assumptions moves this page too.
B5: Bear | C5: Base | D5: Bull | E5: Weight
A6: Discounted cash flow | B6: 1.6731381 | C6: ='Fundamental Valuation'!B10 | D6: 23.927095 | E6: =Assumptions!$B$189
A7: Relative multiples | B7: 9.8774947 | C7: ='Fundamental Valuation'!C11 | D7: 15.299898 | E7: =Assumptions!$B$190
A8: Normalised earnings power | B8: 9.8828031 | C8: ='Fundamental Valuation'!D12 | D8: 16.086867 | E8: =Assumptions!$B$191
A9: Book value and sustainable return | B9: 4.7388314 | C9: ='Fundamental Valuation'!E13 | D9: 7.1228739 | E9: =Assumptions!$B$192
A10: CENTRAL — the cash-flow lens | B10: =B6 | C10: =C6 | D10: =D6
A12: Market price at the valuation date | B12: =Assumptions!$B$7
A13: Central against price | B13: =C10/B12-1
A14: Shares in issue, millions | B14: =Assumptions!$B$8
A15: Market capitalisation at the valuation date | B15: =B14*Assumptions!$B$7
A17: WHERE THE VALUE SITS
A18: Present value of the explicit five years | B18: =DCF!B52
A19: Present value of the terminal block | B19: =DCF!B56
A20: Terminal share of enterprise value | B20: =B19/(B18+B19)
A21: Net cash added in the bridge | B21: =DCF!B58
A23: The bear and bull columns of each lens are the blue cells here and the only pasted figures on the sheet: each is a complete re-run of the model at that scenario, computed in compute.py and reproduced in formulas on the Sensitivity sheet. The central row is a live formula across them, because the defect being closed was a sheet that labelled a row weighted and then took the minimum and maximum across four lenses.

Sheet Fundamental Valuation
A1: Four lenses, one bridge, one valuation date
A2: Lens 2 is on the TRAILING metric so it borrows no discount factor from lens 1. Lens 3 is forward-dated and is therefore DISCOUNTED to the valuation date at the cost of equity, with net cash added at face outside the multiple. Lens 4 uses the same cost-of-equity glide lens 1 uses. All formulas.
A5: Base-year EBITDA | B5: ='Income Statement'!B20-'Income Statement'!B28-'Income Statement'!B29-'Income Statement'!B30-'Income Statement'!B31+'Income Statement'!B32
A6: Enterprise value at spot | B6: =Assumptions!$B$7*Assumptions!$B$8+(Assumptions!$B$103+Assumptions!$B$104-Assumptions!$B$100)/10^6
A7: The company's OWN trailing EV/EBITDA | B7: =B6/B5
A8: Justified multiple = trailing x (1 + re-rating) | B8: =B7*(1+Assumptions!$B$113)
A10: LENS 1 — discounted cash flow | B10: =DCF!B65
A11: LENS 2 — relative multiples, on the trailing metric | B11: =(B8*B5-(Assumptions!$B$103+Assumptions!$B$104-Assumptions!$B$100)/10^6)*(1-'Income Statement'!B41)-(Assumptions!$B$99+Assumptions!$B$98-Assumptions!$B$102-Assumptions!$B$101)/10^6 | C11: =B11/Assumptions!$B$8
A12: LENS 3 — normalised earnings power, DISCOUNTED | B12: =DCF!E41 | C12: =B12*(1-Assumptions!$B$108)*(1-'Income Statement'!B40)*(1-'Income Statement'!B41)/Assumptions!$B$8 | D12: =C12*Assumptions!$B$112/(1+DCF!B10)^2.4+((Assumptions!$B$100-Assumptions!$B$103-Assumptions!$B$104-Assumptions!$B$99-Assumptions!$B$98)/10^6)/Assumptions!$B$8
A13: LENS 4 — book value and sustainable return | B13: =Assumptions!$B$105/10^6/Assumptions!$B$8 | C13: =0.2283705826 | D13: =(Assumptions!$B$111-Assumptions!$B$110)/(C13-Assumptions!$B$110) | E13: =B13*D13
A15: CENTRAL — the cash-flow lens | B15: =B10
A16: against spot | B16: =B15/Assumptions!$B$7-1
A17: the retired 45/20/20/15 blend, published beside the answer and unused | B17: =B10*Assumptions!$B$189+C11*Assumptions!$B$190+D12*Assumptions!$B$191+E13*Assumptions!$B$192
A19: ONE CLASS PRIMARY IS THE CENTRAL. The cash-flow lens is the answer; the relative, normalised-earnings and book rows are cross-checks and the range across them is an ENVELOPE, not a spread around a weighted estimate. The blend on the row above is kept visible and unused: three of the four lenses value a refiner on reported earnings and historical-cost book, and averaging them into the answer imports every weakness of the weakest at a weight nobody tested out of sample. An earlier edition labelled a row "weighted central" and then took the minimum and maximum across all four lenses, both of which came from the cash-flow lens alone, so the word "weighted" applied to the centre and not to the ends and the published spread was about two and a half times too wide.

Sheet Assumptions
A1: Assumptions — every driver, with the filing it was read from
A2: Blue cells are the ONLY pasted values in this workbook. Every one is a figure read off an audited or disclosed filing, or a stated house judgement. There is no third class: the previous edition also pasted its sensitivity grids and its bear and bull columns because each is a whole-model re-run; those re-runs are now written out as live formula blocks on the Sensitivity sheet, so a reader can change a driver here and watch every one of them move.
A5: Driver | B5: Value | C5: Ring | D5: Date | E5: Source
A6: MARKET AND CAPITAL
A7: Spot price, EGP | B7: 13.5 | C7: Company | D7: 2026-09-03 | E7: AMOC closing price on the Egyptian Exchange, 3 September 2026
A8: Shares outstanding, mn | B8: 1291.5 | C8: Company | D8: 2025-12-31 | E8: Issued and paid-up capital EGP 1,291,500,000 at EGP 1 par = 1,291,500,000 shares (note 18-L, share split to EGP 1 par recorded in the Commercial Register 24-Jan-2018)
A9: THE TWELVE MONTHS TO 30 JUNE 2026 — the base year
A10: Net sales, 6M to 31-Dec-2025 (AUDITED) | B10: 20735725812 | C10: Company | D10: 2025-12-31 | E10: Net sales, six months to 31-Dec-2025. Audited consolidated FS, transition period 1-Jul-2025 to 31-Dec-2025, Crowe unqualified, 18-Feb-2026
A11: Cost of sales, 6M to 31-Dec-2025 (AUDITED) | B11: 19461550746 | C11: Company | D11: 2025-12-31 | E11: Cost of sales, six months to 31-Dec-2025. Audited consolidated FS, transition period 1-Jul-2025 to 31-Dec-2025, Crowe unqualified, 18-Feb-2026
A12: Net sales, 6M to 30-Jun-2026 (FILED) | B12: 26223032454 | C12: Company | D12: 2026-06-30 | E12: Net sales, six months to 30-Jun-2026. Reviewed consolidated financial statements, six months to 30-Jun-2026, limited review report attached (note 14-A / 15-A)
A13: Cost of sales, 6M to 30-Jun-2026 (FILED) | B13: 22964084821 | C13: Company | D13: 2026-06-30 | E13: Cost of sales, six months to 30-Jun-2026. Reviewed consolidated financial statements, six months to 30-Jun-2026, limited review report attached (note 14-A / 15-A)
A14: Gross profit, 6M to 30-Jun-2026 (FILED) | B14: 3258947633 | C14: Company | D14: 2026-06-30 | E14: Gross profit, six months to 30-Jun-2026 — 12.43% of net sales. Reviewed consolidated financial statements, six months to 30-Jun-2026, limited review report attached (note 14-A / 15-A)
A15: General and administrative, 6M to 30-Jun-2026 (FILED) | B15: 675083735 | C15: Company | D15: 2026-06-30 | E15: General and administrative expenses, six months to 30-Jun-2026. Reviewed consolidated financial statements, six months to 30-Jun-2026, limited review report attached (note 14-A / 15-A)
A16: Marketing and selling, 6M to 30-Jun-2026 (FILED) | B16: 125019700 | C16: Company | D16: 2026-06-30 | E16: Marketing and selling expenses, six months to 30-Jun-2026. Reviewed consolidated financial statements, six months to 30-Jun-2026, limited review report attached (note 14-A / 15-A)
A17: Other expenses, 6M to 30-Jun-2026 (FILED) | B17: 2599294 | C17: Company | D17: 2026-06-30 | E17: Other expenses, six months to 30-Jun-2026. Reviewed consolidated financial statements, six months to 30-Jun-2026, limited review report attached (note 14-A / 15-A)
A18: Formed provisions, 6M to 30-Jun-2026 (FILED) | B18: 96672167 | C18: Company | D18: 2026-06-30 | E18: Formed provisions, six months to 30-Jun-2026. Reviewed consolidated financial statements, six months to 30-Jun-2026, limited review report attached (note 14-A / 15-A)
A19: Expected credit losses, 6M to 30-Jun-2026 (FILED) | B19: 48692230 | C19: Company | D19: 2026-06-30 | E19: Expected credit losses formed, six months to 30-Jun-2026. Reviewed consolidated financial statements, six months to 30-Jun-2026, limited review report attached (note 14-A / 15-A)
A20: Finance expenses, 6M to 30-Jun-2026 (FILED) | B20: 1938539 | C20: Company | D20: 2026-06-30 | E20: Finance expenses, six months to 30-Jun-2026. Reviewed consolidated financial statements, six months to 30-Jun-2026, limited review report attached (note 14-A / 15-A)
A21: Other income, 6M to 30-Jun-2026 (FILED) | B21: 196526615 | C21: Company | D21: 2026-06-30 | E21: Other operating income, six months to 30-Jun-2026, of which credit interest 134,944,385. Reviewed consolidated financial statements, six months to 30-Jun-2026, limited review report attached (note 14-A / 15-A)
... A65: Finance cost, 6M to 31-Dec-2025 | B65: 1892108 | C65: Company | D65: 2025-12-31 | E65: Finance expenses, six months to 31-Dec-2025 (note 15-E): loan interest and charges 1,130,556, lease interest 761,552. Audited consolidated FS, transition period 1-Jul-2025 to 31-Dec-2025, Crowe unqualified, 18-Feb-2026
A66: NOTE 14-A — the audited product table, 6M to 31-Dec-2025
A67: Base and special oils — tonnes sold | B67: 118475.64 | C67: Company | D67: 2026-06-30 | E67: Tonnes sold by product line, TWELVE months to 30-Jun-2026 — the audited transition half (note 14-A, Audited consolidated FS, transition period 1-Jul-2025 to 31-Dec-2025, Crowe unqualified, 18-Feb-2026) plus the reviewed half (Reviewed consolidated financial statements, six months to 30-Jun-2026, limited review report attached (note 14-A / 15-A)). Both halves are filed; nothing is annualised.
A68: Paraffin wax — tonnes sold | B68: 82805.74 | C68: Company | D68: 2026-06-30 | E68: Tonnes sold by product line, TWELVE months to 30-Jun-2026 — the audited transition half (note 14-A, Audited consolidated FS, transition period 1-Jul-2025 to 31-Dec-2025, Crowe unqualified, 18-Feb-2026) plus the reviewed half (Reviewed consolidated financial statements, six months to 30-Jun-2026, limited review report attached (note 14-A / 15-A)). Both halves are filed; nothing is annualised.
A69: Gas oil — tonnes sold | B69: 346720.79 | C69: Company | D69: 2026-06-30 | E69: Tonnes sold by product line, TWELVE months to 30-Jun-2026 — the audited transition half (note 14-A, Audited consolidated FS, transition period 1-Jul-2025 to 31-Dec-2025, Crowe unqualified, 18-Feb-2026) plus the reviewed half (Reviewed consolidated financial statements, six months to 30-Jun-2026, limited review report attached (note 14-A / 15-A)). Both halves are filed; nothing is annualised.
A70: Naphtha — tonnes sold | B70: 80543.106 | C70: Company | D70: 2026-06-30 | E70: Tonnes sold by product line, TWELVE months to 30-Jun-2026 — the audited transition half (note 14-A, Audited consolidated FS, transition period 1-Jul-2025 to 31-Dec-2025, Crowe unqualified, 18-Feb-2026) plus the reviewed half (Reviewed consolidated financial statements, six months to 30-Jun-2026, limited review report attached (note 14-A / 15-A)). Both halves are filed; nothing is annualised.
A71: Liquefied petroleum gas — tonnes sold | B71: 47938.789 | C71: Company | D71: 2026-06-30 | E71: Tonnes sold by product line, TWELVE months to 30-Jun-2026 — the audited transition half (note 14-A, Audited consolidated FS, transition period 1-Jul-2025 to 31-Dec-2025, Crowe unqualified, 18-Feb-2026) plus the reviewed half (Reviewed consolidated financial statements, six months to 30-Jun-2026, limited review report attached (note 14-A / 15-A)). Both halves are filed; nothing is annualised.
A72: Fuel oil (mix) — tonnes sold | B72: 799642.26 | C72: Company | D72: 2026-06-30 | E72: Tonnes sold by product line, TWELVE months to 30-Jun-2026 — the audited transition half (note 14-A, Audited consolidated FS, transition period 1-Jul-2025 to 31-Dec-2025, Crowe unqualified, 18-Feb-2026) plus the reviewed half (Reviewed consolidated financial statements, six months to 30-Jun-2026, limited review report attached (note 14-A / 15-A)). Both halves are filed; nothing is annualised.
A73: Heavy fuel oil — tonnes sold | B73: 26181.62 | C73: Company | D73: 2026-06-30 | E73: Tonnes sold by product line, TWELVE months to 30-Jun-2026 — the audited transition half (note 14-A, Audited consolidated FS, transition period 1-Jul-2025 to 31-Dec-2025, Crowe unqualified, 18-Feb-2026) plus the reviewed half (Reviewed consolidated financial statements, six months to 30-Jun-2026, limited review report attached (note 14-A / 15-A)). Both halves are filed; nothing is annualised.
A74: Waste — tonnes sold | B74: 16.66 | C74: Company | D74: 2026-06-30 | E74: Tonnes sold by product line, TWELVE months to 30-Jun-2026 — the audited transition half (note 14-A, Audited consolidated FS, transition period 1-Jul-2025 to 31-Dec-2025, Crowe unqualified, 18-Feb-2026) plus the reviewed half (Reviewed consolidated financial statements, six months to 30-Jun-2026, limited review report attached (note 14-A / 15-A)). Both halves are filed; nothing is annualised.
A75: Base and special oils — sales value, EGP | B75: 6910344291 | C75: Company | D75: 2026-06-30 | E75: Sales value by product line, EGP, TWELVE months to 30-Jun-2026 — the audited transition half (note 14-A, Audited consolidated FS, transition period 1-Jul-2025 to 31-Dec-2025, Crowe unqualified, 18-Feb-2026) plus the reviewed half (Reviewed consolidated financial statements, six months to 30-Jun-2026, limited review report attached (note 14-A / 15-A)). Foots to disclosed twelve-month net sales with no scalar.
A76: Paraffin wax — sales value, EGP | B76: 4652865956 | C76: Company | D76: 2026-06-30 | E76: Sales value by product line, EGP, TWELVE months to 30-Jun-2026 — the audited transition half (note 14-A, Audited consolidated FS, transition period 1-Jul-2025 to 31-Dec-2025, Crowe unqualified, 18-Feb-2026) plus the reviewed half (Reviewed consolidated financial statements, six months to 30-Jun-2026, limited review report attached (note 14-A / 15-A)). Foots to disclosed twelve-month net sales with no scalar.
A77: Gas oil — sales value, EGP | B77: 13032962579 | C77: Company | D77: 2026-06-30 | E77: Sales value by product line, EGP, TWELVE months to 30-Jun-2026 — the audited transition half (note 14-A, Audited consolidated FS, transition period 1-Jul-2025 to 31-Dec-2025, Crowe unqualified, 18-Feb-2026) plus the reviewed half (Reviewed consolidated financial statements, six months to 30-Jun-2026, limited review report attached (note 14-A / 15-A)). Foots to disclosed twelve-month net sales with no scalar.
A78: Naphtha — sales value, EGP | B78: 2237624310 | C78: Company | D78: 2026-06-30 | E78: Sales value by product line, EGP, TWELVE months to 30-Jun-2026 — the audited transition half (note 14-A, Audited consolidated FS, transition period 1-Jul-2025 to 31-Dec-2025, Crowe unqualified, 18-Feb-2026) plus the reviewed half (Reviewed consolidated financial statements, six months to 30-Jun-2026, limited review report attached (note 14-A / 15-A)). Foots to disclosed twelve-month net sales with no scalar.
... A82: Waste — sales value, EGP | B82: 192200 | C82: Company | D82: 2026-06-30 | E82: Sales value by product line, EGP, TWELVE months to 30-Jun-2026 — the audited transition half (note 14-A, Audited consolidated FS, transition period 1-Jul-2025 to 31-Dec-2025, Crowe unqualified, 18-Feb-2026) plus the reviewed half (Reviewed consolidated financial statements, six months to 30-Jun-2026, limited review report attached (note 14-A / 15-A)). Foots to disclosed twelve-month net sales with no scalar.
A83: NOTE 15-A — the audited cost stack, 6M to 31-Dec-2025
A84: Raw materials | B84: 17650102725 | C84: Company | D84: 2025-12-31 | E84: Cost of sales — RAW MATERIALS, six months to 31-Dec-2025 (note 15-A). 90.7% of cost of sales and 85.1% of revenue: this single line is what the company is. Audited consolidated FS, transition period 1-Jul-2025 to 31-Dec-2025, Crowe unqualified, 18-Feb-2026
A85: Salaries | B85: 881019497 | C85: Company | D85: 2025-12-31 | E85: Cost of sales — salaries, six months to 31-Dec-2025 (note 15-A). Audited consolidated FS, transition period 1-Jul-2025 to 31-Dec-2025, Crowe unqualified, 18-Feb-2026
A86: Other expenses | B86: 807146755 | C86: Company | D86: 2025-12-31 | E86: Cost of sales — other expenses, six months to 31-Dec-2025 (note 15-A): natural gas, operating electricity, operating water, spare parts, maintenance, and the operating management and technical support contract with the Egyptian Projects Operations & Maintenance Company (EPROM). Audited consolidated FS, transition period 1-Jul-2025 to 31-Dec-2025, Crowe unqualified, 18-Feb-2026
A87: Supporting materials (chemicals and additives) | B87: 64533723 | C87: Company | D87: 2025-12-31 | E87: Cost of sales — supporting materials (chemicals and additives), six months to 31-Dec-2025 (note 15-A). The previous edition estimated this charge at roughly five times the disclosed figure
A88: Depreciation | B88: 58748046 | C88: Company | D88: 2025-12-31 | E88: Cost of sales — depreciation, six months to 31-Dec-2025 (note 15-A). Audited consolidated FS, transition period 1-Jul-2025 to 31-Dec-2025, Crowe unqualified, 18-Feb-2026
...

Sheet SOTP Bridge
A1: Enterprise value to equity — every step
A2: AMOC is a single operating company: one refinery, eight product lines off one crude slate, no stakes to sum. There are no parts to break out, so this sheet is the full enterprise-to-equity walk rather than a sum of pieces, and it says so rather than inventing segments to fill the shape.
A5: Present value of the explicit window | B5: =DCF!B52
A6: Terminal value | B6: =DCF!B55
A7: Present value of the terminal block | B7: =DCF!B56
A8: ENTERPRISE VALUE | B8: =DCF!B57
A9: plus net cash | B9: =DCF!B58
A10: Enterprise value including cash | B10: =DCF!B59
A11: less minority interest, on the whole enterprise | B11: =DCF!B60
A12: less the tax-disputes provision | B12: =DCF!B61
A13: less dividends declared and payable | B13: =DCF!B62
A14: plus non-operating investments and pledged deposits | B14: =DCF!B63
A15: EQUITY ATTRIBUTABLE TO THE PARENT | B15: =DCF!B64
A16: VALUE PER SHARE, EGP | B16: =B15/Assumptions!$B$8
A18: THE SAME WALK, PER SHARE
A19: Enterprise value | B19: =DCF!B57/Assumptions!$B$8
A20: Net cash | B20: =DCF!B58/Assumptions!$B$8
A21: Minority interest | B21: =DCF!B60/Assumptions!$B$8*-1
A22: Provisions, dividends payable and investments | B22: =(DCF!B63-DCF!B61-DCF!B62)/Assumptions!$B$8
A23: VALUE PER SHARE, EGP | B23: =SUM(B19:B22)
A25: The minority is taken on the WHOLE enterprise, cash included, because the subsidiary that carries it holds its share of the cash as well as of the plant. Taking it on the operating enterprise alone and then adding the group cash at face would credit the parent with cash it does not wholly own.

Sheet Segments
A1: The eight disclosed product lines — revenue AND cost, per line
A2: Note 14-A gives tonnes and value per line. Note 15-A gives the cost stack for the company and NOT by line, so conversion is allocated on the registered processing-intensity weights and feedstock is then allocated on NET REALISABLE VALUE — the standard joint-product method. Every cell here is a formula.
A5: Line | B5: Tonnes, 6M | C5: Value, EGP 6M | D5: Realisation EGP/t | E5: Base tonnes mn | F5: Base realisation | G5: Conversion EGP/t | H5: Feedstock EGP/t | I5: Spread EGP/t
A6: Base and special oils | B6: =Assumptions!$B$67 | C6: =Assumptions!$B$75 | D6: =C6/B6 | E6: =B6/10^6 | F6: =D6*$B$16 | G6: =$B$22*H6/$B$23 | H6: =Assumptions!$B$114 | I6: =F6-G6
A7: Paraffin wax | B7: =Assumptions!$B$68 | C7: =Assumptions!$B$76 | D7: =C7/B7 | E7: =B7/10^6 | F7: =D7*$B$16 | G7: =$B$22*H7/$B$23 | H7: =Assumptions!$B$115 | I7: =F7-G7
A8: Gas oil | B8: =Assumptions!$B$69 | C8: =Assumptions!$B$77 | D8: =C8/B8 | E8: =B8/10^6 | F8: =D8*$B$16 | G8: =$B$22*H8/$B$23 | H8: =Assumptions!$B$116 | I8: =F8-G8
A9: Naphtha | B9: =Assumptions!$B$70 | C9: =Assumptions!$B$78 | D9: =C9/B9 | E9: =B9/10^6 | F9: =D9*$B$16 | G9: =$B$22*H9/$B$23 | H9: =Assumptions!$B$117 | I9: =F9-G9
A10: Liquefied petroleum gas | B10: =Assumptions!$B$71 | C10: =Assumptions!$B$79 | D10: =C10/B10 | E10: =B10/10^6 | F10: =D10*$B$16 | G10: =$B$22*H10/$B$23 | H10: =Assumptions!$B$118 | I10: =F10-G10
A11: Fuel oil (mix) | B11: =Assumptions!$B$72 | C11: =Assumptions!$B$80 | D11: =C11/B11 | E11: =B11/10^6 | F11: =D11*$B$16 | G11: =$B$22*H11/$B$23 | H11: =Assumptions!$B$119 | I11: =F11-G11
A12: Heavy fuel oil | B12: =Assumptions!$B$73 | C12: =Assumptions!$B$81 | D12: =C12/B12 | E12: =B12/10^6 | F12: =D12*$B$16 | G12: =$B$22*H12/$B$23 | H12: =Assumptions!$B$120 | I12: =F12-G12
A13: Waste | B13: =Assumptions!$B$74 | C13: =Assumptions!$B$82 | D13: =C13/B13 | E13: =B13/10^6 | F13: =D13*$B$16 | G13: =$B$22*H13/$B$23 | H13: =Assumptions!$B$121 | I13: =F13-G13
A14: TOTAL | B14: =SUM(B6:B13) | C14: =SUM(C6:C13) | E14: =SUM(E6:E13) | F14: =SUMPRODUCT(E6:E13,F6:F13)
A15: Revenue at the disclosed realisations, twelve months as filed | B15: =SUMPRODUCT(E6:E13,D6:D13)
A16: REALISATION INDEX — solved so the base year foots | B16: ='Income Statement'!B19/B15
A18: COST ALLOCATION
A19: Cost of sales, base year | B19: ='Income Statement'!B21
A20: Feedstock share of cost (note 15-A) | B20: =Assumptions!$B$26/(Assumptions!$B$26+Assumptions!$B$25+Assumptions!$B$29+Assumptions!$B$27+Assumptions!$B$28)
A21: Feedstock total | B21: =B19*B20
A22: Conversion total | B22: =B19-B21
A23: Processing-weighted tonnage | B23: =SUMPRODUCT(E6:E13,H6:H13)
A24: Net realisable value weighted tonnage | B24: =SUMPRODUCT(E6:E13,I6:I13)
A26: Line | B26: Conversion EGP/t | C26: Net realisable EGP/t | D26: Feedstock EGP/t | E26: Total cost EGP/t | F26: Realisation EGP/t | G26: Spread EGP/t | H26: Gross margin
A27: Base and special oils | B27: =G6 | C27: =I6 | D27: =$B$21*I6/$B$24 | E27: =D27+B27 | F27: =F6 | G27: =F27-E27 | H27: =G27/F27
A28: Paraffin wax | B28: =G7 | C28: =I7 | D28: =$B$21*I7/$B$24 | E28: =D28+B28 | F28: =F7 | G28: =F28-E28 | H28: =G28/F28
A29: Gas oil | B29: =G8 | C29: =I8 | D29: =$B$21*I8/$B$24 | E29: =D29+B29 | F29: =F8 | G29: =F29-E29 | H29: =G29/F29
A30: Naphtha | B30: =G9 | C30: =I9 | D30: =$B$21*I9/$B$24 | E30: =D30+B30 | F30: =F9 | G30: =F30-E30 | H30: =G30/F30
A31: Liquefied petroleum gas | B31: =G10 | C31: =I10 | D31: =$B$21*I10/$B$24 | E31: =D31+B31 | F31: =F10 | G31: =F31-E31 | H31: =G31/F31
A32: Fuel oil (mix) | B32: =G11 | C32: =I11 | D32: =$B$21*I11/$B$24 | E32: =D32+B32 | F32: =F11 | G32: =F32-E32 | H32: =G32/F32
A33: Heavy fuel oil | B33: =G12 | C33: =I12 | D33: =$B$21*I12/$B$24 | E33: =D33+B33 | F33: =F12 | G33: =F33-E33 | H33: =G33/F33
A34: Waste | B34: =G13 | C34: =I13 | D34: =$B$21*I13/$B$24 | E34: =D34+B34 | F34: =F13 | G34: =F34-E34 | H34: =G34/F34
A35: Cost of sales rebuilt from the per-line allocation | B35: =SUMPRODUCT(E6:E13,E27:E34)
A36: must equal the base-year cost of sales — difference | B36: =B35-'Income Statement'!B21
A38: Row 36 is the footing test: the eight per-line costs must rebuild the disclosed cost of sales exactly. Feedstock allocated flat per tonne would make fuel oil sell below the cost of its own feed; feedstock allocated on relative sales value would make base oils and paraffin wax — the products this plant exists for — loss-making. Net realisable value is the standard joint-product method and the only one of the three that leaves every disclosed line with a positive spread.

Sheet Relative & Normalized
A1: Lens 2 and lens 3, in full
A2: Lens 2 is struck on the TRAILING metric so it borrows no discount factor from the cash-flow lens. Lens 3 is forward-dated and is therefore discounted back to the valuation date, with net cash added at face outside the multiple.
A5: LENS 2 — RELATIVE MULTIPLES
A6: Base-year EBITDA | B6: ='Fundamental Valuation'!B5
A7: Enterprise value at the market price | B7: ='Fundamental Valuation'!B6
A8: The company's own trailing enterprise value / EBITDA | B8: ='Fundamental Valuation'!B7
A9: Re-rating applied | B9: =Assumptions!$B$113
A10: Justified multiple | B10: ='Fundamental Valuation'!B8
A11: Equity on that multiple | B11: ='Fundamental Valuation'!B11
A12: LENS 2, EGP PER SHARE | B12: ='Fundamental Valuation'!C11
A14: LENS 3 — NORMALISED EARNINGS POWER
A15: Normalised EBIT, 2028E | B15: ='Fundamental Valuation'!B12
A16: Normalised earnings per share | B16: ='Fundamental Valuation'!C12
A17: Justified price / earnings | B17: =Assumptions!$B$112
A18: Discounted back at the explicit cost of equity | B18: =(1+DCF!B10)^2.4
A19: LENS 3, EGP PER SHARE | B19: ='Fundamental Valuation'!D12
A21: LENS 4 — BOOK VALUE AND SUSTAINABLE RETURN
A22: Book value per share attributable to the parent | B22: ='Fundamental Valuation'!B13
A23: Sustainable return on equity | B23: =Assumptions!$B$111
A24: Cost of equity used | B24: ='Fundamental Valuation'!C13
A25: Justified price / book | B25: ='Fundamental Valuation'!D13
A26: LENS 4, EGP PER SHARE | B26: ='Fundamental Valuation'!E13

Sheet DCF
A1: Discounted cash flow — the forecast engine — eight lines by five years, all formulas
A2: This is the block the Sensitivity sheet replicates twenty-five times, once per grid point, so that every sensitivity cell in this workbook is a live re-run rather than a pasted number.
A5: Levers for this block — the base case sets them all neutral
A6: Volume growth added a year | B6: 0
A7: Gross-margin shift | B7: 0
A8: Realisation-path multiplier | B8: 1
A9: Working-capital cycle multiplier | B9: 1
A10: Explicit cost of capital | B10: =Assumptions!$B$173-Assumptions!$B$174+Assumptions!$B$176*Assumptions!$B$175
A11: Gross borrowings as a share of the capital structure | B11: =(Assumptions!$B$103+Assumptions!$B$104)/10^6/(Assumptions!$B$7*Assumptions!$B$8)
A12: Equity weight — unlevered | B12: =1-B11
A13: After-tax cost of net debt (shown; not used to discount operations) | B13: =(Assumptions!$B$178*(Assumptions!$B$103+Assumptions!$B$104)/10^6-Assumptions!$B$177*Assumptions!$B$100/10^6)/((Assumptions!$B$103+Assumptions!$B$104-Assumptions!$B$100)/10^6)*(1-0.22118761296853667)
A14: OPERATING DISCOUNT RATE — unlevered; the cash is added in the bridge | B14: =B10
A15: Terminal risk-free — DERIVED from the target in force | B15: =Assumptions!$B$179+Assumptions!$B$180
A16: Terminal cost of equity | B16: =B15+Assumptions!$B$176*Assumptions!$B$181
A17: WACC — terminal | B17: =(1-Assumptions!$B$183)*B16+Assumptions!$B$183*Assumptions!$B$182*(1-0.22118761296853667)
A19: BASE CASE | B19: 2026E | C19: 2027E | D19: 2028E | E19: 2029E | F19: 2030E
A20: Inflation index, cumulative | C20: =Assumptions!$B$167 | D20: =C20*Assumptions!$B$168 | E20: =D20*Assumptions!$B$169 | F20: =E20*Assumptions!$B$170 | G20: =F20*Assumptions!$B$171
A21: Realisation index, cumulative | C21: =(1+Assumptions!$B$122*$B$8) | D21: =C21*(1+Assumptions!$B$123*$B$8) | E21: =D21*(1+Assumptions!$B$124*$B$8) | F21: =E21*(1+Assumptions!$B$125*$B$8) | G21: =F21*(1+Assumptions!$B$126*$B$8)
A22: Volume — Base and special oils, mn t | C22: ='Segments'!E6*(1+Assumptions!$B$127+$B$6) | D22: =C22*(1+Assumptions!$B$128+$B$6) | E22: =D22*(1+Assumptions!$B$129+$B$6) | F22: =E22*(1+Assumptions!$B$130+$B$6) | G22: =F22*(1+Assumptions!$B$131+$B$6)
A23: Volume — Paraffin wax, mn t | C23: ='Segments'!E7*(1+Assumptions!$B$132+$B$6) | D23: =C23*(1+Assumptions!$B$133+$B$6) | E23: =D23*(1+Assumptions!$B$134+$B$6) | F23: =E23*(1+Assumptions!$B$135+$B$6) | G23: =F23*(1+Assumptions!$B$136+$B$6)
A24: Volume — Gas oil, mn t | C24: ='Segments'!E8*(1+Assumptions!$B$137+$B$6) | D24: =C24*(1+Assumptions!$B$138+$B$6) | E24: =D24*(1+Assumptions!$B$139+$B$6) | F24: =E24*(1+Assumptions!$B$140+$B$6) | G24: =F24*(1+Assumptions!$B$141+$B$6)
A25: Volume — Naphtha, mn t | C25: ='Segments'!E9*(1+Assumptions!$B$142+$B$6) | D25: =C25*(1+Assumptions!$B$143+$B$6) | E25: =D25*(1+Assumptions!$B$144+$B$6) | F25: =E25*(1+Assumptions!$B$145+$B$6) | G25: =F25*(1+Assumptions!$B$146+$B$6)
A26: Volume — Liquefied petroleum gas, mn t | C26: ='Segments'!E10*(1+Assumptions!$B$147+$B$6) | D26: =C26*(1+Assumptions!$B$148+$B$6) | E26: =D26*(1+Assumptions!$B$149+$B$6) | F26: =E26*(1+Assumptions!$B$150+$B$6) | G26: =F26*(1+Assumptions!$B$151+$B$6)
A27: Volume — Fuel oil (mix), mn t | C27: ='Segments'!E11*(1+Assumptions!$B$152+$B$6) | D27: =C27*(1+Assumptions!$B$153+$B$6) | E27: =D27*(1+Assumptions!$B$154+$B$6) | F27: =E27*(1+Assumptions!$B$155+$B$6) | G27: =F27*(1+Assumptions!$B$156+$B$6)
A28: Volume — Heavy fuel oil, mn t | C28: ='Segments'!E12*(1+Assumptions!$B$157+$B$6) | D28: =C28*(1+Assumptions!$B$158+$B$6) | E28: =D28*(1+Assumptions!$B$159+$B$6) | F28: =E28*(1+Assumptions!$B$160+$B$6) | G28: =F28*(1+Assumptions!$B$161+$B$6)
A29: Volume — Waste, mn t | C29: ='Segments'!E13*(1+Assumptions!$B$162+$B$6) | D29: =C29*(1+Assumptions!$B$163+$B$6) | E29: =D29*(1+Assumptions!$B$164+$B$6) | F29: =E29*(1+Assumptions!$B$165+$B$6) | G29: =F29*(1+Assumptions!$B$166+$B$6)
A30: Total volume, mn t | C30: =SUM(C22:C29) | D30: =SUM(D22:D29) | E30: =SUM(E22:E29) | F30: =SUM(F22:F29) | G30: =SUM(G22:G29)
A31: REVENUE | C31: =C22*'Segments'!$F$6*C21+C23*'Segments'!$F$7*C21+C24*'Segments'!$F$8*C21+C25*'Segments'!$F$9*C21+C26*'Segments'!$F$10*C21+C27*'Segments'!$F$11*C21+C28*'Segments'!$F$12*C21+C29*'Segments'!$F$13*C21 | D31: =D22*'Segments'!$F$6*D21+D23*'Segments'!$F$7*D21+D24*'Segments'!$F$8*D21+D25*'Segments'!$F$9*D21+D26*'Segments'!$F$10*D21+D27*'Segments'!$F$11*D21+D28*'Segments'!$F$12*D21+D29*'Segments'!$F$13*D21 | E31: =E22*'Segments'!$F$6*E21+E23*'Segments'!$F$7*E21+E24*'Segments'!$F$8*E21+E25*'Segments'!$F$9*E21+E26*'Segments'!$F$10*E21+E27*'Segments'!$F$11*E21+E28*'Segments'!$F$12*E21+E29*'Segments'!$F$13*E21 | F31: =F22*'Segments'!$F$6*F21+F23*'Segments'!$F$7*F21+F24*'Segments'!$F$8*F21+F25*'Segments'!$F$9*F21+F26*'Segments'!$F$10*F21+F27*'Segments'!$F$11*F21+F28*'Segments'!$F$12*F21+F29*'Segments'!$F$13*F21 | G31: =G22*'Segments'!$F$6*G21+G23*'Segments'!$F$7*G21+G24*'Segments'!$F$8*G21+G25*'Segments'!$F$9*G21+G26*'Segments'!$F$10*G21+G27*'Segments'!$F$11*G21+G28*'Segments'!$F$12*G21+G29*'Segments'!$F$13*G21
A32: Cost of sales | C32: =C22*('Segments'!$D$27*C21*Assumptions!$B$109+'Segments'!$B$27*(0.4983251709*C21+0.4357405005*C21+0.0330936548*C21+0.0328406739))+C23*('Segments'!$D$28*C21*Assumptions!$B$109+'Segments'!$B$28*(0.4983251709*C21+0.4357405005*C21+0.0330936548*C21+0.0328406739))+C24*('Segments'!$D$29*C21*Assumptions!$B$109+'Segments'!$B$29*(0.4983251709*C21+0.4357405005*C21+0.0330936548*C21+0.0328406739))+C25*('Segments'!$D$30*C21*Assumptions!$B$109+'Segments'!$B$30*(0.4983251709*C21+0.4357405005*C21+0.0330936548*C21+0.0328406739))+C26*('Segments'!$D$31*C21*Assumptions!$B$109+'Segments'!$B$31*(0.4983251709*C21+0.4357405005*C21+0.0330936548*C21+0.0328406739))+C27*('Segments'!$D$32*C21*Assumptions!$B$109+'Segments'!$B$32*(0.4983251709*C21+0.4357405005*C21+0.0330936548*C21+0.0328406739))+C28*('Segments'!$D$33*C21*Assumptions!$B$109+'Segments'!$B$33*(0.4983251709*C21+0.4357405005*C21+0.0330936548*C21+0.0328406739))+C29*('Segments'!$D$34*C21*Assumptions!$B$109+'Segments'!$B$34*(0.4983251709*C21+0.4357405005*C21+0.0330936548*C21+0.0328406739)) | D32: =D22*('Segments'!$D$27*D21*Assumptions!$B$109+'Segments'!$B$27*(0.4983251709*D21+0.4357405005*D21+0.0330936548*D21+0.0328406739))+D23*('Segments'!$D$28*D21*Assumptions!$B$109+'Segments'!$B$28*(0.4983251709*D21+0.4357405005*D21+0.0330936548*D21+0.0328406739))+D24*('Segments'!$D$29*D21*Assumptions!$B$109+'Segments'!$B$29*(0.4983251709*D21+0.4357405005*D21+0.0330936548*D21+0.0328406739))+D25*('Segments'!$D$30*D21*Assumptions!$B$109+'Segments'!$B$30*(0.4983251709*D21+0.4357405005*D21+0.0330936548*D21+0.0328406739))+D26*('Segments'!$D$31*D21*Assumptions!$B$109+'Segments'!$B$31*(0.4983251709*D21+0.4357405005*D21+0.0330936548*D21+0.0328406739))+D27*('Segments'!$D$32*D21*Assumptions!$B$109+'Segments'!$B$32*(0.4983251709*D21+0.4357405005*D21+0.0330936548*D21+0.0328406739))+D28*('Segments'!$D$33*D21*Assumptions!$B$109+'Segments'!$B$33*(0.4983251709*D21+0.4357405005*D21+0.0330936548*D21+0.0328406739))+D29*('Segments'!$D$34*D21*Assumptions!$B$109+'Segments'!$B$34*(0.4983251709*D21+0.4357405005*D21+0.0330936548*D21+0.0328406739)) | E32: =E22*('Segments'!$D$27*E21*Assumptions!$B$109+'Segments'!$B$27*(0.4983251709*E21+0.4357405005*E21+0.0330936548*E21+0.0328406739))+E23*('Segments'!$D$28*E21*Assumptions!$B$109+'Segments'!$B$28*(0.4983251709*E21+0.4357405005*E21+0.0330936548*E21+0.0328406739))+E24*('Segments'!$D$29*E21*Assumptions!$B$109+'Segments'!$B$29*(0.4983251709*E21+0.4357405005*E21+0.0330936548*E21+0.0328406739))+E25*('Segments'!$D$30*E21*Assumptions!$B$109+'Segments'!$B$30*(0.4983251709*E21+0.4357405005*E21+0.0330936548*E21+0.0328406739))+E26*('Segments'!$D$31*E21*Assumptions!$B$109+'Segments'!$B$31*(0.4983251709*E21+0.4357405005*E21+0.0330936548*E21+0.0328406739))+E27*('Segments'!$D$32*E21*Assumptions!$B$109+'Segments'!$B$32*(0.4983251709*E21+0.4357405005*E21+0.0330936548*E21+0.0328406739))+E28*('Segments'!$D$33*E21*Assumptions!$B$109+'Segments'!$B$33*(0.4983251709*E21+0.4357405005*E21+0.0330936548*E21+0.0328406739))+E29*('Segments'!$D$34*E21*Assumptions!$B$109+'Segments'!$B$34*(0.4983251709*E21+0.4357405005*E21+0.0330936548*E21+0.0328406739)) | F32: =F22*('Segments'!$D$27*F21*Assumptions!$B$109+'Segments'!$B$27*(0.4983251709*F21+0.4357405005*F21+0.0330936548*F21+0.0328406739))+F23*('Segments'!$D$28*F21*Assumptions!$B$109+'Segments'!$B$28*(0.4983251709*F21+0.4357405005*F21+0.0330936548*F21+0.0328406739))+F24*('Segments'!$D$29*F21*Assumptions!$B$109+'Segments'!$B$29*(0.4983251709*F21+0.4357405005*F21+0.0330936548*F21+0.0328406739))+F25*('Segments'!$D$30*F21*Assumptions!$B$109+'Segments'!$B$30*(0.4983251709*F21+0.4357405005*F21+0.0330936548*F21+0.0328406739))+F26*('Segments'!$D$31*F21*Assumptions!$B$109+'Segments'!$B$31*(0.4983251709*F21+0.4357405005*F21+0.0330936548*F21+0.0328406739))+F27*('Segments'!$D$32*F21*Assumptions!$B$109+'Segments'!$B$32*(0.4983251709*F21+0.4357405005*F21+0.0330936548*F21+0.0328406739))+F28*('Segments'!$D$33*F21*Assumptions!$B$109+'Segments'!$B$33*(0.4983251709*F21+0.4357405005*F21+0.0330936548*F21+0.0328406739))+F29*('Segments'!$D$34*F21*Assumptions!$B$109+'Segments'!$B$34*(0.4983251709*F21+0.4357405005*F21+0.0330936548*F21+0.0328406739)) | G32: =G22*('Segments'!$D$27*G21*Assumptions!$B$109+'Segments'!$B$27*(0.4983251709*G21+0.4357405005*G21+0.0330936548*G21+0.0328406739))+G23*('Segments'!$D$28*G21*Assumptions!$B$109+'Segments'!$B$28*(0.4983251709*G21+0.4357405005*G21+0.0330936548*G21+0.0328406739))+G24*('Segments'!$D$29*G21*Assumptions!$B$109+'Segments'!$B$29*(0.4983251709*G21+0.4357405005*G21+0.0330936548*G21+0.0328406739))+G25*('Segments'!$D$30*G21*Assumptions!$B$109+'Segments'!$B$30*(0.4983251709*G21+0.4357405005*G21+0.0330936548*G21+0.0328406739))+G26*('Segments'!$D$31*G21*Assumptions!$B$109+'Segments'!$B$31*(0.4983251709*G21+0.4357405005*G21+0.0330936548*G21+0.0328406739))+G27*('Segments'!$D$32*G21*Assumptions!$B$109+'Segments'!$B$32*(0.4983251709*G21+0.4357405005*G21+0.0330936548*G21+0.0328406739))+G28*('Segments'!$D$33*G21*Assumptions!$B$109+'Segments'!$B$33*(0.4983251709*G21+0.4357405005*G21+0.0330936548*G21+0.0328406739))+G29*('Segments'!$D$34*G21*Assumptions!$B$109+'Segments'!$B$34*(0.4983251709*G21+0.4357405005*G21+0.0330936548*G21+0.0328406739))
A33: GROSS PROFIT | C33: =C31-C32+$B$7*C31 | D33: =D31-D32+$B$7*D31 | E33: =E31-E32+$B$7*E31 | F33: =F31-F32+$B$7*F31 | G33: =G31-G32+$B$7*G31
A34: Gross margin | C34: =C33/C31 | D34: =D33/D31 | E34: =E33/E31 | F34: =F33/F31 | G34: =G33/G31
A35: Operating expense | C35: =('Income Statement'!$B$28*C20)+('Income Statement'!$B$29*C20*C30/'Segments'!$E$14)+('Income Statement'!$B$30*C20)+('Income Statement'!$B$31*C20) | D35: =('Income Statement'!$B$28*D20)+('Income Statement'!$B$29*D20*D30/'Segments'!$E$14)+('Income Statement'!$B$30*D20)+('Income Statement'!$B$31*D20) | E35: =('Income Statement'!$B$28*E20)+('Income Statement'!$B$29*E20*E30/'Segments'!$E$14)+('Income Statement'!$B$30*E20)+('Income Statement'!$B$31*E20) | F35: =('Income Statement'!$B$28*F20)+('Income Statement'!$B$29*F20*F30/'Segments'!$E$14)+('Income Statement'!$B$30*F20)+('Income Statement'!$B$31*F20) | G35: =('Income Statement'!$B$28*G20)+('Income Statement'!$B$29*G20*G30/'Segments'!$E$14)+('Income Statement'!$B$30*G20)+('Income Statement'!$B$31*G20)
A36: EBITDA | C36: =C33-C35 | D36: =D33-D35 | E36: =E33-E35 | F36: =F33-F35 | G36: =G33-G35
A37: Capital expenditure — maintenance + growth | C37: ='Income Statement'!$B$43*C20+MAX(C30-'Segments'!$E$14,0)*2100.379938*C20 | D37: ='Income Statement'!$B$43*D20+MAX(D30-C30,0)*2100.379938*D20 | E37: ='Income Statement'!$B$43*E20+MAX(E30-D30,0)*2100.379938*E20 | F37: ='Income Statement'!$B$43*F20+MAX(F30-E30,0)*2100.379938*F20 | G37: ='Income Statement'!$B$43*G20+MAX(G30-F30,0)*2100.379938*G20
A38: Fixed assets at cost, closing | C38: =(Assumptions!$B$91+Assumptions!$B$92)/10^6+C37 | D38: =C38+D37 | E38: =D38+E37 | F38: =E38+F37 | G38: =F38+G37
A39: Depreciation — rolls off the asset register | C39: =(Assumptions!$B$91+Assumptions!$B$92)/10^6/'Income Statement'!$B$42 | D39: =C38/'Income Statement'!$B$42 | E39: =D38/'Income Statement'!$B$42 | F39: =E38/'Income Statement'!$B$42 | G39: =F38/'Income Statement'!$B$42
A40: Fixed assets, net book, closing | C40: =(Assumptions!$B$90+Assumptions!$B$92)/10^6+C37-C39 | D40: =C40+D37-D39 | E40: =D40+E37-E39 | F40: =E40+F37-F39 | G40: =F40+G37-G39
A41: EBIT | C41: =C36-C39 | D41: =D36-D39 | E41: =E36-E39 | F41: =F36-F39 | G41: =G36-G39
A42: NOPAT before the profit share | C42: =C41*(1-Assumptions!$B$108) | D42: =D41*(1-Assumptions!$B$108) | E42: =E41*(1-Assumptions!$B$108) | F42: =F41*(1-Assumptions!$B$108) | G42: =G41*(1-Assumptions!$B$108)
A43: less employees' profit share and board bonuses | C43: =MAX(C42,0)*'Income Statement'!$B$40 | D43: =MAX(D42,0)*'Income Statement'!$B$40 | E43: =MAX(E42,0)*'Income Statement'!$B$40 | F43: =MAX(F42,0)*'Income Statement'!$B$40 | G43: =MAX(G42,0)*'Income Statement'!$B$40
...

Sheet Income Statement
A1: Base year — twelve contiguous months to 30 June 2026
A2: The gross profit of the reported half is NOT taken as released. It is solved from the release's own profit line, and the released figure is shown beside it with the profit it would have implied. Every cell below is a formula.
B5: EGP | C5: Check
A6: Administrative + selling + other, 3M to 31-Mar-2026 | B6: =Assumptions!$B$38+Assumptions!$B$39+Assumptions!$B$40
A7: Scaled to the half (x2) | B7: =B6*2
A8: Other revenue, half | B8: =Assumptions!$B$41*2
A9: Provisions and expected credit losses, half | B9: =(Assumptions!$B$42+Assumptions!$B$43)*2
A10: Finance cost, half | B10: =Assumptions!$B$44*2
A11: Effective tax rate, nine months (for the solve only) | B11: =(Assumptions!$B$59-Assumptions!$B$60+Assumptions!$B$61-Assumptions!$B$62)/((Assumptions!$B$59-Assumptions!$B$60+Assumptions!$B$61-Assumptions!$B$62)/0.22118761296853667)
A13: GROSS PROFIT, 6M to 30-Jun-2026 — AS FILED | B13: =Assumptions!$B$14
A14: Gross profit as the press release stated it | B14: =Assumptions!$B$35
A15: Profit after tax, 6M to 30-Jun-2026 — AS FILED | B15: =Assumptions!$B$22
A16: against the profit the press release reported | B16: =Assumptions!$B$34
A17: Release against filing, gross profit | B17: =B13/B14-1
A19: BASE-YEAR REVENUE — twelve months to 30-Jun-2026 | B19: =(Assumptions!$B$10+Assumptions!$B$12)/10^6
A20: BASE-YEAR GROSS PROFIT | B20: =(Assumptions!$B$10-Assumptions!$B$11+B13)/10^6
A21: BASE-YEAR COST OF SALES | B21: =B19-B20
A22: BASE-YEAR GROSS MARGIN | B22: =B20/B19
A24: Alternative base: nine audited months x 4/3 | B24: =(Assumptions!$B$10+Assumptions!$B$36)/10^6*4/3
A25: its gross margin | B25: =(Assumptions!$B$10+Assumptions!$B$36-Assumptions!$B$11-Assumptions!$B$37)/(Assumptions!$B$10+Assumptions!$B$36)
A27: Operating lines, SAME twelve months
A28: Administrative expense | B28: =(Assumptions!$B$45+Assumptions!$B$15)/10^6
A29: Selling expense | B29: =(Assumptions!$B$46+Assumptions!$B$16)/10^6
A30: Other operating expense | B30: =(Assumptions!$B$47+Assumptions!$B$17)/10^6
A31: Provisions and credit losses | B31: =(Assumptions!$B$48+Assumptions!$B$18+Assumptions!$B$19)/10^6
A32: Depreciation | B32: =(Assumptions!$B$30)/10^6
A33: Cash capital expenditure | B33: =(Assumptions!$B$31)/10^6
A34: Credit interest | B34: =(Assumptions!$B$53+Assumptions!$B$32)/10^6
A35: Employees' profit share | B35: =(Assumptions!$B$55*2)/10^6
A37: Every operating line is struck on the SAME twelve months as revenue and gross profit. The previous edition built revenue from the six-month product table doubled while taking cost of sales from the nine months scaled by four thirds, so its base-year gross margin of 7.081% corresponded to no filed period at all. One period, both sides, or the margin is an artefact of the scalars.
A39: RATES — solved, not assumed
A40: Employees' profit share, % of profit after tax | B40: =B35/((Assumptions!$B$56+Assumptions!$B$22)/10^6)
A41: Minority interest, % of OPERATING profit, whole base year | B41: =((Assumptions!$B$57+Assumptions!$B$23)/10^6)/((Assumptions!$B$56+Assumptions!$B$22)/10^6-B34*(1-0.22118761296853667))
A42: Implied asset life, years = fixed assets at cost / depreciation | B42: =Assumptions!$B$91/10^6/B32
A43: Maintenance capital expenditure at cost over that life | B43: =Assumptions!$B$91/10^6/B42
A44: Inventory days of cost of sales | B44: =Assumptions!$B$93/10^6/B21*365
A45: Receivable days of revenue | B45: =(Assumptions!$B$94+Assumptions!$B$95)/10^6/B19*365
A46: Operating payable days of cost of sales — dividends payable REMOVED | B46: =(Assumptions!$B$96+Assumptions!$B$97-Assumptions!$B$98)/10^6/B21*365

Sheet Balance Sheet
A1: Balance sheet — as filed, and the lines the forecast projects
A2: The filed column is the blue class: figures read off the statement. Everything to the right is projected from the working-capital days and the asset register on the Income Statement sheet, through the same engine the cash flow runs on.
A5: EGP mn | B5: As filed | C5: 2026E | D5: 2027E | E5: 2028E | F5: 2029E | G5: 2030E
A6: Fixed assets at cost | B6: =(Assumptions!$B$91+Assumptions!$B$92)/10^6 | C6: =DCF!C38 | D6: =DCF!D38 | E6: =DCF!E38 | F6: =DCF!F38 | G6: =DCF!G38
A7: Accumulated depreciation | B7: =-(Assumptions!$B$91-Assumptions!$B$90)/10^6
A8: Fixed assets, net book | B8: =(Assumptions!$B$90+Assumptions!$B$92)/10^6 | C8: =DCF!C40 | D8: =DCF!D40 | E8: =DCF!E40 | F8: =DCF!F40 | G8: =DCF!G40
A9: Inventory | B9: =Assumptions!$B$93/10^6
A10: Trade and other receivables | B10: =(Assumptions!$B$94+Assumptions!$B$95)/10^6
A11: Cash and bank | B11: =Assumptions!$B$100/10^6
A12: Financial investments and pledged deposits | B12: =(Assumptions!$B$102+Assumptions!$B$101)/10^6
A13: Trade and other payables | B13: =-(Assumptions!$B$96+Assumptions!$B$97)/10^6
A14: Dividends declared and payable | B14: =-Assumptions!$B$98/10^6
A15: Borrowings | B15: =-(Assumptions!$B$103+Assumptions!$B$104)/10^6
A16: Provisions | B16: =-Assumptions!$B$99/10^6
A17: Equity attributable to the parent, as filed | B17: =Assumptions!$B$105/10^6
A18: Minority interest, as filed | B18: =Assumptions!$B$106/10^6
A20: PROJECTED WORKING CAPITAL AND INVESTED CAPITAL
A21: Net working capital — on the filed days | C21: =DCF!C45 | D21: =DCF!D45 | E21: =DCF!E45 | F21: =DCF!F45 | G21: =DCF!G45
A22: change in the year | C22: =DCF!C46 | D22: =DCF!D46 | E22: =DCF!E46 | F22: =DCF!F46 | G22: =DCF!G46
A23: Invested capital at replacement cost | C23: =DCF!C52 | D23: =DCF!D52 | E23: =DCF!E52 | F23: =DCF!F52 | G23: =DCF!G52
A25: Working capital is projected on inventory, receivable and payable DAYS solved off the filed balance sheet, with dividends declared removed from payables first — leaving them in would have the company financing itself out of a distribution it has already committed to pay.

Sheet Cash Flow
A1: Free cash flow to the firm — the full waterfall, year by year
A2: This is the flow the discounted cash flow discounts, taken line by line from the engine on the DCF sheet. It stops at present value, not at free cash flow.
A5: EGP mn | B5: 2026E | C5: 2027E | D5: 2028E | E5: 2029E | F5: 2030E
A6: Revenue | C6: =DCF!C31 | D6: =DCF!D31 | E6: =DCF!E31 | F6: =DCF!F31 | G6: =DCF!G31
A7: Cost of sales | C7: =DCF!C32 | D7: =DCF!D32 | E7: =DCF!E32 | F7: =DCF!F32 | G7: =DCF!G32
A8: GROSS PROFIT | C8: =DCF!C33 | D8: =DCF!D33 | E8: =DCF!E33 | F8: =DCF!F33 | G8: =DCF!G33
A9: Operating expense | C9: =DCF!C35 | D9: =DCF!D35 | E9: =DCF!E35 | F9: =DCF!F35 | G9: =DCF!G35
A10: EBITDA | C10: =DCF!C36 | D10: =DCF!D36 | E10: =DCF!E36 | F10: =DCF!F36 | G10: =DCF!G36
A11: Depreciation | C11: =DCF!C39 | D11: =DCF!D39 | E11: =DCF!E39 | F11: =DCF!F39 | G11: =DCF!G39
A12: EBIT | C12: =DCF!C41 | D12: =DCF!D41 | E12: =DCF!E41 | F12: =DCF!F41 | G12: =DCF!G41
A13: NOPAT before the profit share | C13: =DCF!C42 | D13: =DCF!D42 | E13: =DCF!E42 | F13: =DCF!F42 | G13: =DCF!G42
A14: Employees' profit share and board bonuses | C14: =DCF!C43 | D14: =DCF!D43 | E14: =DCF!E43 | F14: =DCF!F43 | G14: =DCF!G43
A15: NOPAT | C15: =DCF!C44 | D15: =DCF!D44 | E15: =DCF!E44 | F15: =DCF!F44 | G15: =DCF!G44
A16: add back depreciation | C16: =DCF!C39 | D16: =DCF!D39 | E16: =DCF!E39 | F16: =DCF!F39 | G16: =DCF!G39
A17: less capital expenditure | C17: =DCF!C37 | D17: =DCF!D37 | E17: =DCF!E37 | F17: =DCF!F37 | G17: =DCF!G37
A18: less the change in working capital | C18: =DCF!C46 | D18: =DCF!D46 | E18: =DCF!E46 | F18: =DCF!F46 | G18: =DCF!G46
A19: FREE CASH FLOW TO THE FIRM | C19: =DCF!C47 | D19: =DCF!D47 | E19: =DCF!E47 | F19: =DCF!F47 | G19: =DCF!G47
A20: Forward cost of capital | C20: =DCF!C49 | D20: =DCF!D49 | E20: =DCF!E49 | F20: =DCF!F49 | G20: =DCF!G49
A21: Cumulative discount factor | C21: =DCF!C50 | D21: =DCF!D50 | E21: =DCF!E50 | F21: =DCF!F50 | G21: =DCF!G50
A22: PRESENT VALUE | C22: =DCF!C51 | D22: =DCF!D51 | E22: =DCF!E51 | F22: =DCF!F51 | G22: =DCF!G51
A24: PV of the explicit window | B24: =DCF!B52
A25: PV of the terminal block | B25: =DCF!B56
A27: Two lines are shown as they are computed rather than as a conventional waterfall would order them: tax is struck on EBIT at the statutory rate before the profit share, and the employees' share is then taken off the taxed figure, which is the order the company's own statements follow.

Sheet Summary Financials
A1: Summary financials — the base year and the five forecast years
A2: The base column is the twelve months to 30 June 2026 built on the Income Statement sheet; the five forecast columns are the engine. Margins are outputs of the volume, price and cost-per-unit build, never inputs.
A5: EGP mn | B5: Base year | C5: 2026E | D5: 2027E | E5: 2028E | F5: 2029E | G5: 2030E
A6: Revenue | B6: ='Income Statement'!B19 | C6: =DCF!C31 | D6: =DCF!D31 | E6: =DCF!E31 | F6: =DCF!F31 | G6: =DCF!G31
A7: Gross profit | B7: ='Income Statement'!B20 | C7: =DCF!C33 | D7: =DCF!D33 | E7: =DCF!E33 | F7: =DCF!F33 | G7: =DCF!G33
A8: Gross margin | B8: ='Income Statement'!B22 | C8: =DCF!C34 | D8: =DCF!D34 | E8: =DCF!E34 | F8: =DCF!F34 | G8: =DCF!G34
A9: EBITDA | B9: ='Fundamental Valuation'!B5 | C9: =DCF!C36 | D9: =DCF!D36 | E9: =DCF!E36 | F9: =DCF!F36 | G9: =DCF!G36
A10: EBIT | B10: ='Fundamental Valuation'!B5-'Income Statement'!B32 | C10: =DCF!C41 | D10: =DCF!D41 | E10: =DCF!E41 | F10: =DCF!F41 | G10: =DCF!G41
A11: NOPAT | C11: =DCF!C44 | D11: =DCF!D44 | E11: =DCF!E44 | F11: =DCF!F44 | G11: =DCF!G44
A12: Capital expenditure | B12: ='Income Statement'!B33 | C12: =DCF!C37 | D12: =DCF!D37 | E12: =DCF!E37 | F12: =DCF!F37 | G12: =DCF!G37
A13: Free cash flow to the firm | C13: =DCF!C47 | D13: =DCF!D47 | E13: =DCF!E47 | F13: =DCF!F47 | G13: =DCF!G47
A15: PER TONNE, EGP — the unit the plant actually runs on
A16: Volume, million tonnes | C16: =DCF!C30 | D16: =DCF!D30 | E16: =DCF!E30 | F16: =DCF!F30 | G16: =DCF!G30
A17: Revenue per tonne | C17: =DCF!C31/DCF!C30 | D17: =DCF!D31/DCF!D30 | E17: =DCF!E31/DCF!E30 | F17: =DCF!F31/DCF!F30 | G17: =DCF!G31/DCF!G30
A18: Gross profit per tonne | C18: =DCF!C33/DCF!C30 | D18: =DCF!D33/DCF!D30 | E18: =DCF!E33/DCF!E30 | F18: =DCF!F33/DCF!F30 | G18: =DCF!G33/DCF!G30
A19: EBITDA per tonne | C19: =DCF!C36/DCF!C30 | D19: =DCF!D36/DCF!D30 | E19: =DCF!E36/DCF!E30 | F19: =DCF!F36/DCF!F30 | G19: =DCF!G36/DCF!G30

Sheet Monte Carlo
A1: The price distribution, and how often its bands have held
A2: This is the price engine, not the valuation: an independent lens, shown beside the fundamental answer and never fed into it. The percentiles are produced by the engine and are read in here, like a figure off a filing.
A5: Anchor date | B5: 2026-08-06
A6: Anchor price, EGP | B6: 9.1
A7: Live risk-free used by the engine | B7: 0.195
A8: Dividend yield used by the engine | B8: 0.0879
A9: Tail parameter and width calibration (per-market fit) | B9: 6 | C9: 0.951
A10: Per-name width overlay applied | B10: 0.98772961
A12: THE DISTRIBUTION, EGP PER SHARE
A13: Horizon | B13: p5 | C13: p25 | D13: p50 | E13: p75 | F13: p95
A14: 1M — grade date 2026-09-06 | B14: 7.7095612 | C14: 8.598973 | D14: 9.1709726 | E14: 9.785587 | F14: 10.913622
A15: 3M — grade date 2026-11-08 | B15: 6.9017095 | C15: 8.3442309 | D15: 9.3294301 | E15: 10.41935 | F15: 12.604538
A17: HOW OFTEN THE BANDS HAVE HELD, ON THIS NAME
A18: Resolved three-month windows scored | B18: 17
A19: First origin | B19: 2022-04-05
A20: Last origin | B20: 2026-04-12
A21: Inside the 50 per cent band | B21: 0.52941176
A22: Inside the 80 per cent band | B22: 0.88235294
A23: Inside the 90 per cent band | B23: 0.94117647
A24: Mean probability-integral transform (0.5 is centred) | B24: 0.4612
A26: These bands are a record of what happened, not a forecast of the fundamental value. The fundamental study, this price distribution and the technical read are independent lenses: no output of one is an input to another, and they are shown side by side so that agreement between them is information rather than an echo.

Sheet Sensitivity
A1: Sensitivity — every grid point is the whole engine, again, in formulas
A2: The previous edition pasted these rows because each point is a whole-model re-run and its builder could not express a re-run inside a grid. Three of the pasted rows turned out not to reproduce: a working-capital row whose grid was never sorted, a beta row whose centre did not return the base case, and a volume row whose label described a different scenario from the one it ran. None of that can happen here, because there is nothing to paste.
A4: Summary — every cell points at its own live block below
A5: Gross margin, shifted on every forecast year
A6: grid point 1: -1.0% | C6: -0.01 | I6: =B95
A7: grid point 2: -0.5% | C7: -0.005 | I7: =B144
A8: grid point 3: +0.0% | C8: 0 | I8: =B193 | J8: =B193-DCF!B65
A9: grid point 4: +0.5% | C9: 0.005 | I9: =B242
A10: grid point 5: +1.0% | C10: 0.01 | I10: =B291
A12: Volume growth path, as a multiple of the assumed path
A13: grid point 1: -6.0% | B13: -0.06 | I13: =B340
A14: grid point 2: -3.0% | B14: -0.03 | I14: =B389
A15: grid point 3: +0.0% | B15: 0 | I15: =B438 | J15: =B438-DCF!B65
A16: grid point 4: +3.0% | B16: 0.03 | I16: =B487
A17: grid point 5: +6.0% | B17: 0.06 | I17: =B536
A19: Realisation path, as a multiple of the assumed path
A20: grid point 1: 0.90x | D20: 0.9 | I20: =B585
A21: grid point 2: 0.95x | D21: 0.95 | I21: =B634
A22: grid point 3: 1.00x | D22: 1 | I22: =B683 | J22: =B683-DCF!B65
A23: grid point 4: 1.05x | D23: 1.05 | I23: =B732
A24: grid point 5: 1.10x | D24: 1.1 | I24: =B781
A26: Beta
A27: grid point 1: 0.6000 | F27: 0.24556 | G27: 0.16198219 | I27: =B830
A28: grid point 2: 0.8000 | F28: 0.26438 | G28: 0.17458219 | I28: =B879
A29: grid point 3: 0.9063 | F29: 0.2743872 | G29: 0.18128201 | I29: =B928 | J29: =B928-DCF!B65
A30: grid point 4: 1.1500 | F30: 0.297315 | G30: 0.19663219 | I30: =B977
A31: grid point 5: 1.3000 | F31: 0.31143 | G31: 0.20608219 | I31: =B1026
A33: Working-capital cycle, as a multiple of the solved days
A34: grid point 1: 0.50x | E34: 0.5 | I34: =B1075
A35: grid point 2: 0.75x | E35: 0.75 | I35: =B1124
A36: grid point 3: 1.00x | E36: 1 | I36: =B1173 | J36: =B1173-DCF!B65
A37: grid point 4: 1.25x | E37: 1.25 | I37: =B1222
A38: grid point 5: 1.50x | E38: 1.5 | I38: =B1271
A40: Terminal growth
A41: grid point 1: 3.0% | H41: 0.03 | I41: =B1320
A42: grid point 2: 4.0% | H42: 0.04 | I42: =B1369
A43: grid point 3: 5.0% | H43: 0.05 | I43: =B1418
A44: grid point 4: 6.0% | H44: 0.06 | I44: =B1467
A45: grid point 5: 7.0% | H45: 0.07 | I45: =B1516 | J45: =B1516-DCF!B65
A47: GATE — every row must return the base case at its own base point
...

Sheet Per-Share & Ratios
A1: Per share, and the multiples the answer implies
A2: What the central and the market price each imply, on the same base-year figures. Every cell is a formula off the Summary and Income Statement sheets.
A5: Central, EGP | B5: =Summary!C10
A6: Market price, EGP | B6: =Assumptions!$B$7
A7: Book value per share, EGP | B7: ='Fundamental Valuation'!B13
A8: Base-year revenue per share, EGP | B8: ='Income Statement'!B19/Assumptions!$B$8
A9: Base-year EBITDA per share, EGP | B9: ='Fundamental Valuation'!B5/Assumptions!$B$8
A10: Dividend declared and payable, per share, EGP | B10: =Assumptions!$B$98/10^6/Assumptions!$B$8
A12: Multiple | B12: At the central | C12: At the market price
A13: Price / book | B13: =B$5/'Fundamental Valuation'!B13 | C13: =Assumptions!$B$7/'Fundamental Valuation'!B13
A14: Enterprise value / base-year EBITDA | B14: =(B$5*Assumptions!$B$8+(Assumptions!$B$103+Assumptions!$B$104-Assumptions!$B$100)/10^6)/'Fundamental Valuation'!B5 | C14: ='Fundamental Valuation'!B6/'Fundamental Valuation'!B5
A15: Enterprise value / base-year revenue | B15: =(B$5*Assumptions!$B$8+(Assumptions!$B$103+Assumptions!$B$104-Assumptions!$B$100)/10^6)/'Income Statement'!B19 | C15: ='Fundamental Valuation'!B6/'Income Statement'!B19
A16: Yield on the dividend already declared and payable | B16: =Assumptions!$B$98/10^6/Assumptions!$B$8/B$5 | C16: =Assumptions!$B$98/10^6/Assumptions!$B$8/Assumptions!$B$7
A18: RETURNS
A19: Trailing return on equity | B19: =Assumptions!$B$111
A20: Terminal return on invested capital, at replacement cost | B20: =DCF!B53
A21: Required reinvestment rate in the terminal year | B21: =DCF!B54
A22: Terminal growth | B22: =Assumptions!$B$110

Sheet Peer & Sector
A1: Sector context — a refiner and lubricant base-oil producer
A2: The comparator basis is the company's OWN traded multiple and a stated re-rating, not a peer set: no Egyptian listed refiner discloses a comparable base-oil split, and importing a foreign multiple into an EGP valuation would price a different cost of capital. That is a gap and it is named as one rather than filled.
A5: Comparator basis | B5: Multiple | C5: Applied to (EGP mn) | D5: Implied EGP/share
A6: The company's own trailing enterprise value / EBITDA | B6: ='Fundamental Valuation'!B7 | C6: ='Fundamental Valuation'!B5 | D6: =(B6*C6-(Assumptions!$B$103+Assumptions!$B$104-Assumptions!$B$100)/10^6)*(1-'Income Statement'!B41)/Assumptions!$B$8
A7: Justified multiple, after the stated re-rating | B7: ='Fundamental Valuation'!B8 | C7: ='Fundamental Valuation'!B5 | D7: =(B7*C7-(Assumptions!$B$103+Assumptions!$B$104-Assumptions!$B$100)/10^6)*(1-'Income Statement'!B41)/Assumptions!$B$8
A9: WHAT ACTUALLY DRIVES A PROCESSOR
A10: Indicator | B10: 2026E | C10: 2027E | D10: 2028E | E10: 2029E | F10: 2030E
A11: Throughput, million tonnes | C11: =DCF!C30 | D11: =DCF!D30 | E11: =DCF!E30 | F11: =DCF!F30 | G11: =DCF!G30
A12: Gross profit per tonne, EGP | C12: =DCF!C33/DCF!C30 | D12: =DCF!D33/DCF!D30 | E12: =DCF!E33/DCF!E30 | F12: =DCF!F33/DCF!F30 | G12: =DCF!G33/DCF!G30
A13: EBITDA per tonne, EGP | C13: =DCF!C36/DCF!C30 | D13: =DCF!D36/DCF!D30 | E13: =DCF!E36/DCF!E30 | F13: =DCF!F36/DCF!F30 | G13: =DCF!G36/DCF!G30
A14: Gross margin | C14: =DCF!C34 | D14: =DCF!D34 | E14: =DCF!E34 | F14: =DCF!F34 | G14: =DCF!G34
A15: Capital expenditure as a share of revenue | C15: =DCF!C37/DCF!C31 | D15: =DCF!D37/DCF!D31 | E15: =DCF!E37/DCF!E31 | F15: =DCF!F37/DCF!F31 | G15: =DCF!G37/DCF!G31
A17: The crude slate is bought from a single counterparty at a disclosed formula and the refined product is sold into a market whose price is set outside the company, so what a reader can actually compare across the sector is the spread per tonne and how much of the plant is running — not a price/earnings ratio struck on a different tax regime and a different currency.
