Workbook

Sheet READ FIRST
A1: Testahil — Arabian Cement Company S.A.E. (EGX: ARCC)
A4: Companion model · Independent Valuation Study · Educational analysis · Not investment advice
A6: What this workbook is. A transparent companion to the Arabian Cement valuation study. Every blue cell is an
A7: input; every black cell is a formula; green cells link across sheets.
A9: IT IS FORMULA-DRIVEN, AND THAT CLAIM IS TESTED. Every figure derivable from a driver is a live formula, so
A10: you can change a blue cell on Assumptions and watch the model reprice. The cost of equity is BUILT from the
A11: risk-free rate NET of the sovereign default spread, beta and the premium rather than pasted; the cost of debt
A12: is taxed in the sheet; the capital-structure weights come from debt and market capitalisation; the terminal
A13: rate is built from its own components; the glide fractions are visibly derived from the cost-of-debt path;
A14: the discount factors compound through that path; the cash-flow waterfall chains from margin through EBITDA,
A15: D&A, EBIT, NOPAT, capital expenditure and working capital to free cash flow and present value; the terminal
A16: block chains from reinvestment = growth / return on capital; the statements roll property, working capital,
... A65: No rating and no price target. Fair-value ranges and distributions only.

Sheet Assumptions
A1: Assumptions — every driver, including the whole cost stack
A2: Blue cells are inputs. Nothing below a driver is typed.
A4: MARKET
A5: Spot price | B5: 59 | C5: EGP, close 06-Aug-2026
A6: Shares outstanding | B6: 374.87 | C6: mn
A7: Statutory tax rate | B7: 0.225
A8: USD/EGP at the valuation date | B8: 50.3
A9: Beta (own-stock weekly regression) | B9: 0.62807983
A11: PLANT — PHYSICAL
A12: Cement capacity | B12: 5 | C12: Mt/yr
A13: Kiln clinker capacity | B13: 3.6 | C13: Mt/yr
A14: Clinker factor | B14: 0.72 | C14: t clinker / t cement
A16: COST STACK — PHYSICAL AND MARKET DRIVERS
A17: Specific thermal energy | B17: 3.3 | C17: GJ/t clinker
A18: Fossil fuel price | B18: 4 | C18: USD/GJ
A19: Alternative fuel price | B19: 1.8 | C19: USD/GJ
A20: Specific electrical energy | B20: 100 | C20: kWh/t cement
A21: Industrial electricity tariff | B21: 2.6 | C21: EGP/kWh
A22: Raw materials and quarrying | B22: 195 | C22: EGP/t cement
A23: Packaging | B23: 55 | C23: EGP/t bagged
A24: Bagged share of despatches | B24: 0.7
A25: Distribution and selling | B25: 190 | C25: EGP/t cement
A26: Fixed cash cost | B26: 15.7583 | C26: USD/t of capacity
A28: PATHS — FY2025A then FY2026E to FY2030E
B29: FY2025A | C29: FY2026E | D29: FY2027E | E29: FY2028E | F29: FY2029E | G29: FY2030E
A30: Kiln utilisation | B30: 0.72 | C30: 0.768 | D30: 0.79 | E30: 0.805 | F30: 0.815 | G30: 0.822
A31: Alternative-fuel substitution rate | B31: 0.52 | C31: 0.55 | D31: 0.58 | E31: 0.6 | F31: 0.62 | G31: 0.64
A32: Domestic share of despatches | B32: 0.88 | C32: 0.88 | D32: 0.87 | E32: 0.86 | F32: 0.85 | G32: 0.84
A33: Domestic realised price | B33: 3512.24 | C33: 3600 | D33: 3780 | E33: 3950 | F33: 4128 | G33: 4293 | I33: EGP/t
A34: Export price | B34: 62 | C34: 60 | D34: 58.5 | E34: 57.5 | F34: 56.5 | G34: 55.5 | I34: USD/t
A35: USD/EGP path | B35: 49.3 | C35: 50.6 | D35: 53.1 | E35: 55.8 | F35: 58.6 | G35: 61.5
A36: Local cost-inflation index | B36: 1 | C36: 1.115 | D36: 1.226 | E36: 1.336 | F36: 1.443 | G36: 1.544 | I36: FY2025 = 1.000
A38: CAPITAL INTENSITY AND DISTRIBUTION — FY2026E to FY2030E
B39: FY2026E | C39: FY2027E | D39: FY2028E | E39: FY2029E | F39: FY2030E
A40: Depreciation as % of revenue | B40: 0.025 | C40: 0.028 | D40: 0.031 | E40: 0.034 | F40: 0.036
A41: Cost-of-debt path | B41: 0.215 | C41: 0.19 | D41: 0.17 | E41: 0.158 | F41: 0.15
A42: Yield earned on cash | B42: 0.185 | C42: 0.16 | D42: 0.145 | E42: 0.135 | F42: 0.13
A43: Maintenance capital expenditure | B43: 4 | C43: USD/t of capacity
A44: Change in working capital / change in revenue | B44: 0.12
A45: Dividend payout ratio | B45: 0.56
...

Sheet Unit Build
A1: Bottom-up build — physical units in, EBITDA out
A2: EBITDA is a RESULT of this sheet, never an input.
B4: FY2025A | C4: FY2026E | D4: FY2027E | E4: FY2028E | F4: FY2029E | G4: FY2030E
A5: Kiln clinker capacity (Mt/yr) | B5: =Assumptions!$B$13 | C5: =Assumptions!$B$13 | D5: =Assumptions!$B$13 | E5: =Assumptions!$B$13 | F5: =Assumptions!$B$13 | G5: =Assumptions!$B$13
A6: Kiln utilisation | B6: =Assumptions!$B$30 | C6: =Assumptions!$C$30 | D6: =Assumptions!$D$30 | E6: =Assumptions!$E$30 | F6: =Assumptions!$F$30 | G6: =Assumptions!$G$30
A7: Clinker produced (Mt) | B7: =B5*B6 | C7: =C5*C6 | D7: =D5*D6 | E7: =E5*E6 | F7: =F5*F6 | G7: =G5*G6
A8: Cement capacity (Mt/yr) | B8: =Assumptions!$B$12 | C8: =Assumptions!$B$12 | D8: =Assumptions!$B$12 | E8: =Assumptions!$B$12 | F8: =Assumptions!$B$12 | G8: =Assumptions!$B$12
A9: Clinker factor (t clinker / t cement) | B9: =Assumptions!$B$14 | C9: =Assumptions!$B$14 | D9: =Assumptions!$B$14 | E9: =Assumptions!$B$14 | F9: =Assumptions!$B$14 | G9: =Assumptions!$B$14
A10: Cement produced (Mt) | B10: =B7/B9 | C10: =C7/C9 | D10: =D7/D9 | E10: =E7/E9 | F10: =F7/F9 | G10: =G7/G9
A11: Domestic share | B11: =Assumptions!$B$32 | C11: =Assumptions!$C$32 | D11: =Assumptions!$D$32 | E11: =Assumptions!$E$32 | F11: =Assumptions!$F$32 | G11: =Assumptions!$G$32
A12: Domestic volume (Mt) | B12: =B10*B11 | C12: =C10*C11 | D12: =D10*D11 | E12: =E10*E11 | F12: =F10*F11 | G12: =G10*G11
A13: Export volume (Mt) | B13: =B10-B12 | C13: =C10-C12 | D13: =D10-D12 | E13: =E10-E12 | F13: =F10-F12 | G13: =G10-G12
A14: Domestic price (EGP/t) | B14: =Assumptions!$B$33 | C14: =Assumptions!$C$33 | D14: =Assumptions!$D$33 | E14: =Assumptions!$E$33 | F14: =Assumptions!$F$33 | G14: =Assumptions!$G$33
A15: Export price (USD/t) | B15: =Assumptions!$B$34 | C15: =Assumptions!$C$34 | D15: =Assumptions!$D$34 | E15: =Assumptions!$E$34 | F15: =Assumptions!$F$34 | G15: =Assumptions!$G$34
A16: USD/EGP | B16: =Assumptions!$B$35 | C16: =Assumptions!$C$35 | D16: =Assumptions!$D$35 | E16: =Assumptions!$E$35 | F16: =Assumptions!$F$35 | G16: =Assumptions!$G$35
A17: Domestic revenue (EGP mn) | B17: =B12*B14 | C17: =C12*C14 | D17: =D12*D14 | E17: =E12*E14 | F17: =F12*F14 | G17: =G12*G14
A18: Export revenue (EGP mn) | B18: =B13*B15*B16 | C18: =C13*C15*C16 | D18: =D13*D15*D16 | E18: =E13*E15*E16 | F18: =F13*F15*F16 | G18: =G13*G15*G16
A19: REVENUE (EGP mn) | B19: =B17+B18 | C19: =C17+C18 | D19: =D17+D18 | E19: =E17+E18 | F19: =F17+F18 | G19: =G17+G18
A20: Blended realised price (EGP/t) | B20: =B19/B10 | C20: =C19/C10 | D20: =D19/D10 | E20: =E19/E10 | F20: =F19/F10 | G20: =G19/G10
A22: COST STACK — EGP PER TONNE OF CEMENT
A23: Alternative-fuel substitution rate | B23: =Assumptions!$B$31 | C23: =Assumptions!$C$31 | D23: =Assumptions!$D$31 | E23: =Assumptions!$E$31 | F23: =Assumptions!$F$31 | G23: =Assumptions!$G$31
A24: Blended fuel price (USD/GJ) | B24: =B23*Assumptions!$B$19+(1-B23)*Assumptions!$B$18 | C24: =C23*Assumptions!$B$19+(1-C23)*Assumptions!$B$18 | D24: =D23*Assumptions!$B$19+(1-D23)*Assumptions!$B$18 | E24: =E23*Assumptions!$B$19+(1-E23)*Assumptions!$B$18 | F24: =F23*Assumptions!$B$19+(1-F23)*Assumptions!$B$18 | G24: =G23*Assumptions!$B$19+(1-G23)*Assumptions!$B$18
A25: Thermal fuel | B25: =Assumptions!$B$17*B9*B24*B16 | C25: =Assumptions!$B$17*C9*C24*C16 | D25: =Assumptions!$B$17*D9*D24*D16 | E25: =Assumptions!$B$17*E9*E24*E16 | F25: =Assumptions!$B$17*F9*F24*F16 | G25: =Assumptions!$B$17*G9*G24*G16
A26: Electrical power | B26: =Assumptions!$B$20*Assumptions!$B$21*Assumptions!$B$36 | C26: =Assumptions!$B$20*Assumptions!$B$21*Assumptions!$C$36 | D26: =Assumptions!$B$20*Assumptions!$B$21*Assumptions!$D$36 | E26: =Assumptions!$B$20*Assumptions!$B$21*Assumptions!$E$36 | F26: =Assumptions!$B$20*Assumptions!$B$21*Assumptions!$F$36 | G26: =Assumptions!$B$20*Assumptions!$B$21*Assumptions!$G$36
A27: Raw materials and quarrying | B27: =Assumptions!$B$22*Assumptions!$B$36 | C27: =Assumptions!$B$22*Assumptions!$C$36 | D27: =Assumptions!$B$22*Assumptions!$D$36 | E27: =Assumptions!$B$22*Assumptions!$E$36 | F27: =Assumptions!$B$22*Assumptions!$F$36 | G27: =Assumptions!$B$22*Assumptions!$G$36
A28: Packaging | B28: =Assumptions!$B$23*Assumptions!$B$24*Assumptions!$B$36 | C28: =Assumptions!$B$23*Assumptions!$B$24*Assumptions!$C$36 | D28: =Assumptions!$B$23*Assumptions!$B$24*Assumptions!$D$36 | E28: =Assumptions!$B$23*Assumptions!$B$24*Assumptions!$E$36 | F28: =Assumptions!$B$23*Assumptions!$B$24*Assumptions!$F$36 | G28: =Assumptions!$B$23*Assumptions!$B$24*Assumptions!$G$36
A29: Distribution and selling | B29: =Assumptions!$B$25*Assumptions!$B$36 | C29: =Assumptions!$B$25*Assumptions!$C$36 | D29: =Assumptions!$B$25*Assumptions!$D$36 | E29: =Assumptions!$B$25*Assumptions!$E$36 | F29: =Assumptions!$B$25*Assumptions!$F$36 | G29: =Assumptions!$B$25*Assumptions!$G$36
A30: TOTAL VARIABLE (EGP/t) | B30: =SUM(B25:B29) | C30: =SUM(C25:C29) | D30: =SUM(D25:D29) | E30: =SUM(E25:E29) | F30: =SUM(F25:F29) | G30: =SUM(G25:G29)
A32: PROFIT AND LOSS — EGP MILLION
A33: Revenue | B33: =B19 | C33: =C19 | D33: =D19 | E33: =E19 | F33: =F19 | G33: =G19
A34: Variable cost | B34: =B30*B10 | C34: =C30*C10 | D34: =D30*D10 | E34: =E30*E10 | F34: =F30*F10 | G34: =G30*G10
A35: Fixed cost | B35: =Assumptions!$B$26*B8*Assumptions!$B$35*Assumptions!$B$36 | C35: =Assumptions!$B$26*C8*Assumptions!$B$35*Assumptions!$C$36 | D35: =Assumptions!$B$26*D8*Assumptions!$B$35*Assumptions!$D$36 | E35: =Assumptions!$B$26*E8*Assumptions!$B$35*Assumptions!$E$36 | F35: =Assumptions!$B$26*F8*Assumptions!$B$35*Assumptions!$F$36 | G35: =Assumptions!$B$26*G8*Assumptions!$B$35*Assumptions!$G$36
A36: EBITDA (AN OUTPUT) | B36: =B33-B34-B35 | C36: =C33-C34-C35 | D36: =D33-D34-D35 | E36: =E33-E34-E35 | F36: =F33-F34-F35 | G36: =G33-G34-G35
A37: EBITDA margin | B37: =B36/B33 | C37: =C36/C33 | D37: =D36/D33 | E37: =E36/E33 | F37: =F36/F33 | G37: =G36/G33
A38: EBITDA per tonne (EGP) | B38: =B36/B10 | C38: =C36/C10 | D38: =D36/D10 | E38: =E36/E10 | F38: =F36/F10 | G38: =G36/G10
A40: DEPRECIATION — THREE METHODS, AVERAGED HERE
A41: Method 1 — Q4-2025 EBITDA margin applied to FY2025 revenue, less disclosed EBIT | B41: =Assumptions!$B$68/Assumptions!$B$67*Assumptions!$B$62-Assumptions!$B$66
A42: Method 2 — peer depreciation per tonne times FY2025 despatched volume | B42: =Assumptions!$B$89*B10
A43: Cost of sales implied by the disclosed gross margin | B43: =Assumptions!$B$62*(1-Assumptions!$B$69)
A44: Inventory implied by inventory days | B44: =B43*Assumptions!$B$90/365
...

Sheet DCF
A1: Discounted cash flow — the primary lens
A2: Cost of capital built here, never pasted.
B4: FY2026E | C4: FY2027E | D4: FY2028E | E4: FY2029E | F4: FY2030E
A5: Revenue | B5: ='Unit Build'!C33 | C5: ='Unit Build'!D33 | D5: ='Unit Build'!E33 | E5: ='Unit Build'!F33 | F5: ='Unit Build'!G33
A6: EBITDA margin | B6: =B7/B5 | C6: =C7/C5 | D6: =D7/D5 | E6: =E7/E5 | F6: =F7/F5
A7: EBITDA | B7: ='Unit Build'!C36 | C7: ='Unit Build'!D36 | D7: ='Unit Build'!E36 | E7: ='Unit Build'!F36 | F7: ='Unit Build'!G36
A8: Depreciation and amortisation | B8: =B5*Assumptions!$B$40 | C8: =C5*Assumptions!$C$40 | D8: =D5*Assumptions!$D$40 | E8: =E5*Assumptions!$E$40 | F8: =F5*Assumptions!$F$40
A9: EBIT | B9: =B7-B8 | C9: =C7-C8 | D9: =D7-D8 | E9: =E7-E8 | F9: =F7-F8
A10: Tax rate (effective) | B10: =$C$47 | C10: =$C$47 | D10: =$C$47 | E10: =$C$47 | F10: =$C$47
A11: NOPAT (EBIT × (1 − t)) | B11: =B9*(1-B10) | C11: =C9*(1-C10) | D11: =D9*(1-D10) | E11: =E9*(1-E10) | F11: =F9*(1-F10)
A12: Plus depreciation | B12: =B8 | C12: =C8 | D12: =D8 | E12: =E8 | F12: =F8
A13: Less capital expenditure | B13: =-Assumptions!$B$12*Assumptions!$B$43*Assumptions!$C$35 | C13: =-Assumptions!$B$12*Assumptions!$B$43*Assumptions!$D$35 | D13: =-Assumptions!$B$12*Assumptions!$B$43*Assumptions!$E$35 | E13: =-Assumptions!$B$12*Assumptions!$B$43*Assumptions!$F$35 | F13: =-Assumptions!$B$12*Assumptions!$B$43*Assumptions!$G$35
A14: Less change in working capital | B14: =-(B5-Assumptions!$B$62)*Assumptions!$B$44 | C14: =-(C5-B5)*Assumptions!$B$44 | D14: =-(D5-C5)*Assumptions!$B$44 | E14: =-(E5-D5)*Assumptions!$B$44 | F14: =-(F5-E5)*Assumptions!$B$44
A15: FREE CASH FLOW TO THE FIRM | B15: =(B11+B12+B13+B14)*(1-Assumptions!$B$57) | C15: =C11+C12+C13+C14 | D15: =D11+D12+D13+D14 | E15: =E11+E12+E13+E14 | F15: =F11+F12+F13+F14
A16: Glide fraction | B16: =(Assumptions!$B$41-Assumptions!$B$41)/(Assumptions!$B$41-Assumptions!$F$41) | C16: =(Assumptions!$B$41-Assumptions!$C$41)/(Assumptions!$B$41-Assumptions!$F$41) | D16: =(Assumptions!$B$41-Assumptions!$D$41)/(Assumptions!$B$41-Assumptions!$F$41) | E16: =(Assumptions!$B$41-Assumptions!$E$41)/(Assumptions!$B$41-Assumptions!$F$41) | F16: =(Assumptions!$B$41-Assumptions!$F$41)/(Assumptions!$B$41-Assumptions!$F$41)
A17: Forward cost of capital | B17: =$C$40-($C$40-$C$46)*B16 | C17: =$C$40-($C$40-$C$46)*C16 | D17: =$C$40-($C$40-$C$46)*D16 | E17: =$C$40-($C$40-$C$46)*E16 | F17: =$C$40-($C$40-$C$46)*F16
A18: Discount factor | B18: =1/(1+B17)^((1-Assumptions!$B$57)/2) | C18: =1/(1+B17)^(1-Assumptions!$B$57+0.5) | D18: =1/((1+B17)*(1+C17)^(1-Assumptions!$B$57+0.5)) | E18: =1/((1+B17)*(1+C17)*(1+D17)^(1-Assumptions!$B$57+0.5)) | F18: =1/((1+B17)*(1+C17)*(1+D17)*(1+E17)^(1-Assumptions!$B$57+0.5))
A19: PRESENT VALUE OF FCFF | B19: =B15*B18 | C19: =C15*C18 | D19: =D15*D18 | E19: =E15*E18 | F19: =F15*F18
A21: TERMINAL BLOCK
A22: Replacement-cost invested capital (EGP mn) | B22: =Assumptions!$B$12*Assumptions!$B$93*Assumptions!$B$8
A23: Terminal NOPAT (year 5 NOPAT grown at g) | B23: =F11*(1+Assumptions!$B$56)
A24: Terminal return on invested capital | B24: =B23/B22
A25: Reinvestment rate (g ÷ return on capital) | B25: =Assumptions!$B$56/B24
A26: Terminal value | B26: =B23*(1-B25)/($C$46-Assumptions!$B$56)
A27: Present value of terminal value | B27: =B26*F18
A29: ENTERPRISE TO EQUITY BRIDGE
A30: Present value of explicit years (FY2026E-FY2030E) | B30: =SUM(B19:F19)
A31: Present value of terminal value | B31: =B27
A32: Enterprise value | B32: =B30+B31
A33: TERMINAL VALUE AS % OF ENTERPRISE VALUE | B33: =B31/B32
A34: Cash at the valuation date | B34: =Assumptions!$B$71+B15/(1-Assumptions!$B$57)*Assumptions!$B$57
A35: Less gross debt | B35: =-Assumptions!$B$72
A36: Risk-free rate (observed EGP 10-year) | B36: =B34+B35 | C36: =Assumptions!$B$48
A37: Less sovereign default spread | B37: =-Assumptions!$B$75 | C37: =-Assumptions!$B$49
A38: Normalised risk-free rate | B38: =B32+B36+B37 | C38: =C36+C37
A39: Cost of equity (rf* + beta × premium) | B39: =Assumptions!$B$6 | C39: =C38+Assumptions!$B$9*Assumptions!$B$50
A40: WACC — explicit window | B40: =B38/B39 | C40: =(1-C43)*C39+C43*C41
A41: Cost of debt after tax | C41: =Assumptions!$B$51*(1-Assumptions!$B$7)
A42: Market capitalisation | C42: =Assumptions!$B$5*Assumptions!$B$6
A43: Debt weight D/(D+E) | C43: =Assumptions!$B$72/(Assumptions!$B$72+C42)
...

Sheet EV Bridge
A1: Enterprise value to equity bridge
B4: EGP mn | C4: Per share (EGP)
A5: Present value of explicit free cash flow | B5: =DCF!B30 | C5: =B5/Assumptions!$B$6
A6: Present value of terminal value | B6: =DCF!B31 | C6: =B6/Assumptions!$B$6
A7: Enterprise value | B7: =DCF!B32 | C7: =B7/Assumptions!$B$6
A8: Plus net cash | B8: =DCF!B36 | C8: =B8/Assumptions!$B$6
A9: Less non-controlling interests | B9: =DCF!B37 | C9: =B9/Assumptions!$B$6
A10: Equity value | B10: =DCF!B38 | C10: =B10/Assumptions!$B$6
A12: TERMINAL VALUE AS % OF ENTERPRISE VALUE | B12: =DCF!B33
A13: Memo: spot price | C13: =Assumptions!$B$5
A14: Fair value less spot | C14: =C10-C13
A15: Upside / (downside) to the cash-flow lens | C15: =C10/C13-1
A16: Memo: enterprise value per annual tonne of capacity (USD) | C16: =B7/Assumptions!$B$12/Assumptions!$B$8
A18: Terminal value share is linked live to the DCF sheet — never typed. The company is net cash, so
A19: the bridge ADDS cash and DEDUCTS minority interests; both signs are asserted in the build.

Sheet Income Statement
A1: Income statement — 3 years historical + 5-year forecast
A2: EGP mn
B4: FY2023 | C4: FY2024 | D4: FY2025 | E4: FY2026E | F4: FY2027E | G4: FY2028E | H4: FY2029E | I4: FY2030E
A5: Revenue | B5: =Assumptions!$B$60 | C5: =Assumptions!$B$61 | D5: =Assumptions!$B$62 | E5: =DCF!B5 | F5: =DCF!C5 | G5: =DCF!D5 | H5: =DCF!E5 | I5: =DCF!F5
A6: EBITDA | B6: =B9+B8 | C6: =C9+C8 | D6: =D9+D8 | E6: =DCF!B7 | F6: =DCF!C7 | G6: =DCF!D7 | H6: =DCF!E7 | I6: =DCF!F7
A7: EBITDA margin | B7: =B6/B5 | C7: =C6/C5 | D7: =D6/D5 | E7: =E6/E5 | F7: =F6/F5 | G7: =G6/G5 | H7: =H6/H5 | I7: =I6/I5
A8: Depreciation and amortisation | B8: ='Unit Build'!$B$50*B16 | C8: ='Unit Build'!$B$50*C16 | D8: ='Unit Build'!$B$50*D16 | E8: =DCF!B8 | F8: =DCF!C8 | G8: =DCF!D8 | H8: =DCF!E8 | I8: =DCF!F8
A9: EBIT | B9: =Assumptions!$B$63/(1-DCF!$C$47) | C9: =Assumptions!$B$64/(1-DCF!$C$47) | D9: =Assumptions!$B$66 | E9: =E6-E8 | F9: =F6-F8 | G9: =G6-G8 | H9: =H6-H8 | I9: =I6-I8
A10: Net finance income | B10: =0 | C10: =0 | D10: =DCF!$C$48 | E10: =Assumptions!$B$71*Assumptions!$B$42-Assumptions!$B$72*Assumptions!$B$41 | F10: ='Balance Sheet'!E7*Assumptions!$C$42-Assumptions!$B$72*Assumptions!$C$41 | G10: ='Balance Sheet'!F7*Assumptions!$D$42-Assumptions!$B$72*Assumptions!$D$41 | H10: ='Balance Sheet'!G7*Assumptions!$E$42-Assumptions!$B$72*Assumptions!$E$41 | I10: ='Balance Sheet'!H7*Assumptions!$F$42-Assumptions!$B$72*Assumptions!$F$41
A11: Profit before tax | B11: =B9+B10 | C11: =C9+C10 | D11: =D9+D10 | E11: =E9+E10 | F11: =F9+F10 | G11: =G9+G10 | H11: =H9+H10 | I11: =I9+I10
A12: Tax | B12: =B11-B13 | C12: =C11-C13 | D12: =D11-D13 | E12: =E11*DCF!$C$47 | F12: =F11*DCF!$C$47 | G12: =G11*DCF!$C$47 | H12: =H11*DCF!$C$47 | I12: =I11*DCF!$C$47
A13: Profit after tax | B13: =Assumptions!$B$63 | C13: =Assumptions!$B$64 | D13: =Assumptions!$B$65 | E13: =E11-E12 | F13: =F11-F12 | G13: =G11-G12 | H13: =H11-H12 | I13: =I11-I12
A14: Earnings per share (EGP) | B14: =B13/Assumptions!$B$6 | C14: =C13/Assumptions!$B$6 | D14: =D13/Assumptions!$B$6 | E14: =E13/Assumptions!$B$6 | F14: =F13/Assumptions!$B$6 | G14: =G13/Assumptions!$B$6 | H14: =H13/Assumptions!$B$6 | I14: =I13/Assumptions!$B$6
A15: Dividends declared (disclosed) | C15: 1100 | D15: 2000 | E15: =E13*Assumptions!$B$45 | F15: =F13*Assumptions!$B$45 | G15: =G13*Assumptions!$B$45 | H15: =H13*Assumptions!$B$45 | I15: =I13*Assumptions!$B$45
A16: Memo: despatched volume (Mt) | B16: =Assumptions!$B$13*Assumptions!$B$80/Assumptions!$B$14 | C16: =Assumptions!$B$13*Assumptions!$B$81/Assumptions!$B$14 | D16: =Assumptions!$B$13*Assumptions!$B$30/Assumptions!$B$14 | E16: ='Unit Build'!C10 | F16: ='Unit Build'!D10 | G16: ='Unit Build'!E10 | H16: ='Unit Build'!F10 | I16: ='Unit Build'!G10
A17: Memo: blended realised price (EGP/t) | B17: =B5/B16 | C17: =C5/C16 | D17: =D5/D16 | E17: =E5/E16 | F17: =F5/F16 | G17: =G5/G16 | H17: =H5/H16 | I17: =I5/I16
A18: Dividend per share (EGP) | C18: =C15/Assumptions!$B$6 | D18: =D15/Assumptions!$B$6 | E18: =E15/Assumptions!$B$6 | F18: =F15/Assumptions!$B$6 | G18: =G15/Assumptions!$B$6 | H18: =H15/Assumptions!$B$6 | I18: =I15/Assumptions!$B$6
A20: Revenue and profit after tax for FY2023-FY2025 and FY2025 operating income are DISCLOSED and
A21: pasted on Assumptions. Every other historical line is DERIVED by closing the disclosed profit at
A22: the effective tax rate built on the DCF sheet, and is a formula here. FY2023 and FY2024 net
A23: finance income is set to zero: the cash pile that produces it was built during FY2025.

Sheet Balance Sheet
A1: Balance sheet — 3 years historical + 5-year forecast
A2: EGP mn
B4: FY2023 | C4: FY2024 | D4: FY2025 | E4: FY2026E | F4: FY2027E | G4: FY2028E | H4: FY2029E | I4: FY2030E
A5: Net property, plant and equipment | D5: ='Unit Build'!B46 | E5: =D5-DCF!B8-DCF!B13 | F5: =E5-DCF!C8-DCF!C13 | G5: =F5-DCF!D8-DCF!D13 | H5: =G5-DCF!E8-DCF!E13 | I5: =H5-DCF!F8-DCF!F13
A6: Working capital (inventory + receivables) | D6: ='Unit Build'!B44+'Unit Build'!B45 | E6: =D6-DCF!B14 | F6: =E6-DCF!C14 | G6: =F6-DCF!D14 | H6: =G6-DCF!E14 | I6: =H6-DCF!F14
A7: Cash and equivalents | D7: =Assumptions!$B$71 | E7: =D7+'Income Statement'!E13+DCF!B8+DCF!B13+DCF!B14-'Income Statement'!E15 | F7: =E7+'Income Statement'!F13+DCF!C8+DCF!C13+DCF!C14-'Income Statement'!F15 | G7: =F7+'Income Statement'!G13+DCF!D8+DCF!D13+DCF!D14-'Income Statement'!G15 | H7: =G7+'Income Statement'!H13+DCF!E8+DCF!E13+DCF!E14-'Income Statement'!H15 | I7: =H7+'Income Statement'!I13+DCF!F8+DCF!F13+DCF!F14-'Income Statement'!I15
A8: TOTAL ASSETS | D8: =Assumptions!$B$70 | E8: =E5+E6+E7 | F8: =F5+F6+F7 | G8: =G5+G6+G7 | H8: =H5+H6+H7 | I8: =I5+I6+I7
A9: Total debt | D9: =Assumptions!$B$72 | E9: =Assumptions!$B$72 | F9: =Assumptions!$B$72 | G9: =Assumptions!$B$72 | H9: =Assumptions!$B$72 | I9: =Assumptions!$B$72
A10: Other liabilities | D10: =D11-D9 | E10: =D10 | F10: =D10 | G10: =D10 | H10: =D10 | I10: =D10
A11: Total liabilities | D11: =D8-D12 | E11: =E9+E10 | F11: =F9+F10 | G11: =G9+G10 | H11: =H9+H10 | I11: =I9+I10
A12: Total equity | D12: =Assumptions!$B$73 | E12: =D12+'Income Statement'!E13-'Income Statement'!E15 | F12: =E12+'Income Statement'!F13-'Income Statement'!F15 | G12: =F12+'Income Statement'!G13-'Income Statement'!G15 | H12: =G12+'Income Statement'!H13-'Income Statement'!H15 | I12: =H12+'Income Statement'!I13-'Income Statement'!I15
A13: Net (cash) / debt | D13: =D9-D7 | E13: =E9-E7 | F13: =F9-F7 | G13: =G9-G7 | H13: =H9-H7 | I13: =I9-I7
A14: Book value per share (EGP) | D14: =D12/Assumptions!$B$6 | E14: =E12/Assumptions!$B$6 | F14: =F12/Assumptions!$B$6 | G14: =G12/Assumptions!$B$6 | H14: =H12/Assumptions!$B$6 | I14: =I12/Assumptions!$B$6
A15: Return on equity | D15: =Assumptions!$B$65/D12 | E15: ='Income Statement'!E13/E12 | F15: ='Income Statement'!F13/F12 | G15: ='Income Statement'!G13/G12 | H15: ='Income Statement'!H13/H12 | I15: ='Income Statement'!I13/I12
A17: BALANCE-SHEET TRIANGULATION — THE DISAGREEMENT IS SHOWN, NOT SMOOTHED
A18: Total assets, as reported | B18: =Assumptions!$B$70
A19: Total equity, as reported | B19: =Assumptions!$B$73
A20: Total liabilities DERIVED as assets less equity — carried | B20: =B18-B19
A21: Total liabilities as printed by a second aggregation | B21: =Assumptions!$B$74
A22: Gap between the two | B22: =B20-B21
A23: Gap as a share of total assets | B23: =B22/B18
A25: FY2023 and FY2024 balance sheets are not retrievable at the evidentiary standard used elsewhere
A26: and are therefore left blank rather than reconstructed. The FY2025 column is the disclosed
A27: position; property and working capital within it are the estimates built on the Unit Build sheet,
A28: and they sum to total assets by construction because cash and total assets are both disclosed.

Sheet Cash Flow
A1: Cash flow — linked to the valuation waterfall
A2: EGP mn
B4: FY2026E | C4: FY2027E | D4: FY2028E | E4: FY2029E | F4: FY2030E
A5: Profit after tax | B5: ='Income Statement'!E13 | C5: ='Income Statement'!F13 | D5: ='Income Statement'!G13 | E5: ='Income Statement'!H13 | F5: ='Income Statement'!I13
A6: Add back depreciation | B6: =DCF!B8 | C6: =DCF!C8 | D6: =DCF!D8 | E6: =DCF!E8 | F6: =DCF!F8
A7: Less change in working capital | B7: =DCF!B14 | C7: =DCF!C14 | D7: =DCF!D14 | E7: =DCF!E14 | F7: =DCF!F14
A8: Cash from operations | B8: =B5+B6+B7 | C8: =C5+C6+C7 | D8: =D5+D6+D7 | E8: =E5+E6+E7 | F8: =F5+F6+F7
A9: Capital expenditure | B9: =DCF!B13 | C9: =DCF!C13 | D9: =DCF!D13 | E9: =DCF!E13 | F9: =DCF!F13
A10: Free cash flow to equity | B10: =B8+B9 | C10: =C8+C9 | D10: =D8+D9 | E10: =E8+E9 | F10: =F8+F9
A11: Dividends paid | B11: =-'Income Statement'!E15 | C11: =-'Income Statement'!F15 | D11: =-'Income Statement'!G15 | E11: =-'Income Statement'!H15 | F11: =-'Income Statement'!I15
A12: Net change in cash | B12: =B10+B11 | C12: =C10+C11 | D12: =D10+D11 | E12: =E10+E11 | F12: =F10+F11
A13: Closing cash | B13: ='Balance Sheet'!E7 | C13: ='Balance Sheet'!F7 | D13: ='Balance Sheet'!G7 | E13: ='Balance Sheet'!H7 | F13: ='Balance Sheet'!I7
A14: Memo: free cash flow to the firm (from the DCF sheet) | B14: =DCF!B15 | C14: =DCF!C15 | D14: =DCF!D15 | E14: =DCF!E15 | F14: =DCF!F15
A16: The cash flow does not restate the model — it LINKS to it. Every line here points at the DCF or
A17: Income Statement sheet, so the statement and the valuation cannot disagree by construction.
A18: Free cash flow to the FIRM excludes treasury income; free cash flow to EQUITY includes it through
A19: profit after tax. The cash balance is the one on the balance sheet, and closes to it exactly.

Sheet Summary Financials
A1: Summary financials — eight years on one screen
A2: EGP mn
B4: FY2023 | C4: FY2024 | D4: FY2025 | E4: FY2026E | F4: FY2027E | G4: FY2028E | H4: FY2029E | I4: FY2030E
A5: Revenue | B5: ='Income Statement'!B5 | C5: ='Income Statement'!C5 | D5: ='Income Statement'!D5 | E5: ='Income Statement'!E5 | F5: ='Income Statement'!F5 | G5: ='Income Statement'!G5 | H5: ='Income Statement'!H5 | I5: ='Income Statement'!I5
A6: EBITDA | B6: ='Income Statement'!B6 | C6: ='Income Statement'!C6 | D6: ='Income Statement'!D6 | E6: ='Income Statement'!E6 | F6: ='Income Statement'!F6 | G6: ='Income Statement'!G6 | H6: ='Income Statement'!H6 | I6: ='Income Statement'!I6
A7: EBITDA margin | B7: ='Income Statement'!B7 | C7: ='Income Statement'!C7 | D7: ='Income Statement'!D7 | E7: ='Income Statement'!E7 | F7: ='Income Statement'!F7 | G7: ='Income Statement'!G7 | H7: ='Income Statement'!H7 | I7: ='Income Statement'!I7
A8: EBIT | B8: ='Income Statement'!B9 | C8: ='Income Statement'!C9 | D8: ='Income Statement'!D9 | E8: ='Income Statement'!E9 | F8: ='Income Statement'!F9 | G8: ='Income Statement'!G9 | H8: ='Income Statement'!H9 | I8: ='Income Statement'!I9
A9: Profit after tax | B9: ='Income Statement'!B13 | C9: ='Income Statement'!C13 | D9: ='Income Statement'!D13 | E9: ='Income Statement'!E13 | F9: ='Income Statement'!F13 | G9: ='Income Statement'!G13 | H9: ='Income Statement'!H13 | I9: ='Income Statement'!I13
A10: Earnings per share (EGP) | B10: ='Income Statement'!B14 | C10: ='Income Statement'!C14 | D10: ='Income Statement'!D14 | E10: ='Income Statement'!E14 | F10: ='Income Statement'!F14 | G10: ='Income Statement'!G14 | H10: ='Income Statement'!H14 | I10: ='Income Statement'!I14
A11: Despatched volume (Mt) | B11: ='Income Statement'!B16 | C11: ='Income Statement'!C16 | D11: ='Income Statement'!D16 | E11: ='Income Statement'!E16 | F11: ='Income Statement'!F16 | G11: ='Income Statement'!G16 | H11: ='Income Statement'!H16 | I11: ='Income Statement'!I16
A12: Realised price (EGP/t) | B12: ='Income Statement'!B17 | C12: ='Income Statement'!C17 | D12: ='Income Statement'!D17 | E12: ='Income Statement'!E17 | F12: ='Income Statement'!F17 | G12: ='Income Statement'!G17 | H12: ='Income Statement'!H17 | I12: ='Income Statement'!I17
A14: GROWTH
A15: Revenue growth | C15: =C5/B5-1 | D15: =D5/C5-1 | E15: =E5/D5-1 | F15: =F5/E5-1 | G15: =G5/F5-1 | H15: =H5/G5-1 | I15: =I5/H5-1
A16: EBITDA growth | C16: =C6/B6-1 | D16: =D6/C6-1 | E16: =E6/D6-1 | F16: =F6/E6-1 | G16: =G6/F6-1 | H16: =H6/G6-1 | I16: =I6/H6-1
A17: Profit growth | C17: =C9/B9-1 | D17: =D9/C9-1 | E17: =E9/D9-1 | F17: =F9/E9-1 | G17: =G9/F9-1 | H17: =H9/G9-1 | I17: =I9/H9-1
A20: Every cell on this sheet is a link or a formula. Nothing is restated.

Sheet Per-Share & Ratios
A1: Per-share figures and ratios — all formulas
B4: FY2023 | C4: FY2024 | D4: FY2025 | E4: FY2026E | F4: FY2027E | G4: FY2028E | H4: FY2029E | I4: FY2030E
A5: Earnings per share (EGP) | B5: ='Income Statement'!B14 | C5: ='Income Statement'!C14 | D5: ='Income Statement'!D14 | E5: ='Income Statement'!E14 | F5: ='Income Statement'!F14 | G5: ='Income Statement'!G14 | H5: ='Income Statement'!H14 | I5: ='Income Statement'!I14
A6: Dividend per share (EGP) | C6: ='Income Statement'!C18 | D6: ='Income Statement'!D18 | E6: ='Income Statement'!E18 | F6: ='Income Statement'!F18 | G6: ='Income Statement'!G18 | H6: ='Income Statement'!H18 | I6: ='Income Statement'!I18
A7: Book value per share (EGP) | D7: ='Balance Sheet'!D14 | E7: ='Balance Sheet'!E14 | F7: ='Balance Sheet'!F14 | G7: ='Balance Sheet'!G14 | H7: ='Balance Sheet'!H14 | I7: ='Balance Sheet'!I14
A8: Price / earnings (at spot) | B8: =Assumptions!$B$5/B5 | C8: =Assumptions!$B$5/C5 | D8: =Assumptions!$B$5/D5 | E8: =Assumptions!$B$5/E5 | F8: =Assumptions!$B$5/F5 | G8: =Assumptions!$B$5/G5 | H8: =Assumptions!$B$5/H5 | I8: =Assumptions!$B$5/I5
A9: Dividend yield (at spot) | C9: =C6/Assumptions!$B$5 | D9: =D6/Assumptions!$B$5 | E9: =E6/Assumptions!$B$5 | F9: =F6/Assumptions!$B$5 | G9: =G6/Assumptions!$B$5 | H9: =H6/Assumptions!$B$5 | I9: =I6/Assumptions!$B$5
A10: Price / book (at spot) | D10: =Assumptions!$B$5/D7 | E10: =Assumptions!$B$5/E7 | F10: =Assumptions!$B$5/F7 | G10: =Assumptions!$B$5/G7 | H10: =Assumptions!$B$5/H7 | I10: =Assumptions!$B$5/I7
A11: EBITDA per tonne (EGP) | B11: ='Income Statement'!B6/'Income Statement'!B16 | C11: ='Income Statement'!C6/'Income Statement'!C16 | D11: ='Income Statement'!D6/'Income Statement'!D16 | E11: ='Income Statement'!E6/'Income Statement'!E16 | F11: ='Income Statement'!F6/'Income Statement'!F16 | G11: ='Income Statement'!G6/'Income Statement'!G16 | H11: ='Income Statement'!H6/'Income Statement'!H16 | I11: ='Income Statement'!I6/'Income Statement'!I16
A12: Net (cash) / EBITDA | D12: ='Balance Sheet'!D13/'Income Statement'!D6 | E12: ='Balance Sheet'!E13/'Income Statement'!E6 | F12: ='Balance Sheet'!F13/'Income Statement'!F6 | G12: ='Balance Sheet'!G13/'Income Statement'!G6 | H12: ='Balance Sheet'!H13/'Income Statement'!H6 | I12: ='Balance Sheet'!I13/'Income Statement'!I6
A13: Return on equity | D13: ='Balance Sheet'!D15 | E13: ='Balance Sheet'!E15 | F13: ='Balance Sheet'!F15 | G13: ='Balance Sheet'!G15 | H13: ='Balance Sheet'!H15 | I13: ='Balance Sheet'!I15
A15: Historical book value, net cash and return on equity are shown only for FY2025, the one year
A16: with a retrievable balance sheet. Ratios at spot use the 06-Aug-2026 close on Assumptions.
A18: RECONCILIATIONS — THE SHARE COUNT, THE EARNINGS PER SHARE, AND THE RUN RATE
A19: Shares implied by the FY2024 distribution (total / per share) | B19: =Assumptions!$B$78/Assumptions!$B$76
A20: Shares implied by the FY2025 distribution (total / per share) | B20: =Assumptions!$B$79/Assumptions!$B$77
A21: Shares as quoted — ADOPTED | B21: =Assumptions!$B$6
A22: Spread between the widest and narrowest route | B22: =MAX(B19:B21)/MIN(B19:B21)-1
A23: Attributable profit implied by the disclosed earnings per share | B23: =Assumptions!$B$86*Assumptions!$B$6
A24: Attributable profit as disclosed | B24: =Assumptions!$B$65
A25: Difference — the employees' and directors' statutory profit share | B25: =B24-B23
A26: as a share of attributable profit | B26: =B25/B24
A27: Q1-2026 revenue growth on Q1-2025 | B27: =Assumptions!$B$83/Assumptions!$B$84-1
A28: FY2026 revenue implied by holding that growth rate | B28: =Assumptions!$B$62*Assumptions!$B$83/Assumptions!$B$84
A29: FY2026 revenue this model forecasts | B29: =DCF!B5
A30: The forecast against the run rate | B30: =B29/B28-1
A31: Q1-2026 attributable profit, annualised at four times | B31: =4*Assumptions!$B$85
A32: FY2026 profit this model forecasts | B32: ='Income Statement'!E13
A33: The forecast against the annualised first quarter | B33: =B32/B31-1
A35: Three independent routes to the share count agree to within a fifth of one percent, which is why
A36: the count is treated as known rather than estimated. The first-quarter run rate is shown because a
A37: forecast that cannot be reconciled with the most recent actual quarter is not a forecast.

Sheet Relative & Normalized
A1: Relative multiples and normalised earnings power
A4: NORMALISED EARNINGS BASE
A5: FY2025 revenue (the cyclical peak) | B5: =Assumptions!$B$62
A6: Haircut to the revenue base | B6: =Assumptions!$B$98
A7: Normalised revenue | B7: =B5*B6
A8: Mid-cycle EBITDA margin | B8: =Assumptions!$B$97
A9: Normalised EBITDA | B9: =B7*B8
A10: Less depreciation | B10: =-'Unit Build'!B48
A11: Normalised EBIT | B11: =B9+B10
A12: Normalised NOPAT | B12: =B11*(1-DCF!$C$47)
A13: Memo: FY2025 EBITDA margin actually earned | B13: ='Unit Build'!B37
A15: RELATIVE LENS — EV/EBITDA ON NORMALISED EARNINGS
A16: Justified EV/EBITDA | B16: =Assumptions!$B$95
A17: Implied enterprise value | B17: =B9*B16
A18: Plus net cash | B18: =DCF!B36
A19: Less non-controlling interests | B19: =DCF!B37
A20: Equity value | B20: =B17+B18+B19
A21: Value per share (EGP) | B21: =B20/Assumptions!$B$6
A23: NORMALISED-EARNINGS LENS
A24: Justified price / earnings | B24: =Assumptions!$B$96
A25: Capitalised operating earnings | B25: =B12*B24
A26: Plus net cash, at FACE | B26: =DCF!B36
A27: Less non-controlling interests | B27: =DCF!B37
A28: Equity value | B28: =B25+B26+B27
A29: Value per share (EGP) | B29: =B28/Assumptions!$B$6
A31: Cash is added at FACE in both lenses rather than capitalised at the operating multiple. Cash is
A32: worth cash; capitalising it at seven times would value a pound of treasury at a discount to itself.

Sheet Fundamental Valuation
A1: Asset lens, and the choices that were contested
A4: ASSET / REPLACEMENT-COST LENS
A5: Cement capacity (Mt/yr) | B5: =Assumptions!$B$12
A6: Replacement cost per annual tonne (USD) | B6: =Assumptions!$B$93
A7: Justified enterprise value per annual tonne (USD) | B7: =Assumptions!$B$94
A8: Discount to replacement cost | B8: =B7/B6-1
A9: Implied enterprise value (EGP mn) | B9: =B7*B5*Assumptions!$B$8
A10: Plus net cash | B10: =DCF!B36
A11: Less non-controlling interests | B11: =DCF!B37
A12: Equity value | B12: =B9+B10+B11
A13: Value per share (EGP) | B13: =B12/Assumptions!$B$6
A14: Memo: what the MARKET is paying per annual tonne (USD) | B14: =(Assumptions!$B$5*Assumptions!$B$6-DCF!B36+Assumptions!$B$75)/Assumptions!$B$12/Assumptions!$B$8
A16: CONTESTED CHOICES — EACH COMPUTED, NOT ARGUED
A17: Choice | B17: Adopted | C17: Alternative | D17: Fair value adopted | E17: Fair value alternative | F17: Effect
A18: Beta: contemporaneous regression (adopted) vs Dimson lead-lag sum-beta | B18: 0.628 | C18: 0.919 | D18: =DCF!$B$40 | E18: 44.583526 | F18: =E18/D18-1
A19: Capital-structure weights: gross debt (adopted) vs net debt | B19: 4.47% | C19: -12.31% | D19: =DCF!$B$40 | E19: 48.559605 | F19: =E19/D19-1
A20: Minority interests: EGP 150mn deducted (adopted) vs none | B20: 150 | C20: 0 | D20: =DCF!$B$40 | E20: 49.688676 | F20: =E20/D20-1
A21: Capex: economic maintenance in dollars per tonne (adopted) vs book depreciation | B21: USD 4.00/t | C21: book depreciation | D21: =DCF!$B$40 | E21: 54.279675 | F21: =E21/D21-1
A23: The alternative fair values in column E are whole-model re-runs — class 3 pasted cells. Each one
A24: is a complete revaluation at a different assumption and cannot be a formula in a grid. The EFFECT
A25: column is a live formula against the adopted value, so it moves when the model does.
A27: TERMINAL-GROWTH RECONCILIATION
A28: Profit growth achieved since FY2022 (compound) | B28: 1.1562736
A29: FY2025 revenue as a share of Egyptian nominal output | B29: =Assumptions!$B$62/18000000.0
A30: Years until that growth rate equals the whole economy | B30: 12.070069
A31: Terminal return on invested capital | B31: =DCF!B24
A32: Terminal rate | B32: =DCF!$C$46
A33: Reinvestment rate that terminal growth requires | B33: =DCF!B25
A34: Terminal growth adopted | B34: =Assumptions!$B$56
A36: Terminal return on capital sits BELOW the terminal rate, so faster terminal growth LOWERS the
A37: valuation rather than raising it. That is visible in the growth column of the Sensitivity sheet.

Sheet Summary
A1: Summary valuation table
A2: Every value linked live from its own sheet.
A4: Lens | B4: Value per share (EGP) | C4: Weight | D4: Weighted contribution | E4: Versus spot | F4: Terminal value % of EV
A5: DCF (cash flow) | B5: =DCF!B40 | C5: =Assumptions!$B$99 | D5: =B5*C5 | E5: =B5/Assumptions!$B$5-1 | F5: =DCF!B33
A6: Relative multiples | B6: ='Relative & Normalized'!B21 | C6: =Assumptions!$B$100 | D6: =B6*C6 | E6: =B6/Assumptions!$B$5-1 | F6: —
A7: Normalised earnings | B7: ='Relative & Normalized'!B29 | C7: =Assumptions!$B$101 | D7: =B7*C7 | E7: =B7/Assumptions!$B$5-1 | F7: —
A8: Asset / replacement cost | B8: ='Fundamental Valuation'!B13 | C8: =Assumptions!$B$102 | D8: =B8*C8 | E8: =B8/Assumptions!$B$5-1 | F8: —
A9: WEIGHTED CENTRAL FAIR VALUE | B9: =SUMPRODUCT(B5:B8,C5:C8) | C9: =SUM(C5:C8) | D9: =SUM(D5:D8) | E9: =B9/Assumptions!$B$5-1
A10: Lowest lens | B10: =MIN(B5:B8) | E10: =B10/Assumptions!$B$5-1
A11: Highest lens | B11: =MAX(B5:B8) | E11: =B11/Assumptions!$B$5-1
A12: Market price, 6 August 2026 | B12: =Assumptions!$B$5
A13: Market capitalisation (EGP mn) | B13: =DCF!C42
A15: THE THREE-PANEL VALUATIONS
B16: Low (EGP) | C16: Central (EGP) | D16: High (EGP) | E16: Versus spot
A17: Expert 1 — Replacement-cost industrialist | B17: 63.61941 | C17: 73.682899 | D17: 83.746388 | E17: =C17/Assumptions!$B$5-1
A18: Expert 2 — Mid-cycle earnings-power analyst | B18: 47.250245 | C18: 53.467374 | D18: 59.684503 | E18: =C18/Assumptions!$B$5-1
A19: Expert 3 — Cash-return and distribution investor | B19: 44.045991 | C19: 48.917208 | D19: 55.412164 | E19: =C19/Assumptions!$B$5-1
A20: Panel median | C20: =MEDIAN(C17:C19) | E20: =C20/Assumptions!$B$5-1
A22: Terminal value as a percentage of enterprise value is shown beside the cash-flow lens and links
A23: live to the DCF sheet — it is never typed. The three panel valuations are whole-model re-runs on
A24: different methods and are pasted; the versus-spot column beside them is a formula.

Sheet Monte Carlo
A1: Probabilistic price map — ILLUSTRATIVE ONLY
A2: Percentiles are the output of a 50,000-path simulation: pasted, class 2.
A3: This map is NOT a valuation. It is a distribution of where the SHARE PRICE could sit, drawn from
A4: the price history alone. It does not redraw when a valuation driver changes.
B6: One month | C6: Three months
A7: 5th percentile | B7: 50.444111 | C7: 43.922515
A8: 25th percentile | B8: 55.934078 | C8: 53.711182
A9: Median | B9: 59.448465 | C9: 60.456482
A10: 75th percentile | B10: 63.21157 | C10: 67.968663
A11: 95th percentile | B11: 70.085724 | C11: 83.168398
A12: Spot | B12: =Assumptions!$B$5 | C12: =Assumptions!$B$5
A14: Probability of finishing above spot | B14: 0.53378 | C14: 0.55584
A15: Probability of finishing 10% or more above | B15: 0.16972 | C15: 0.33954
A16: Probability of finishing 10% or more below | B16: 0.11564 | C16: 0.2301
A17: Probability of TOUCHING +10% at any point | B17: 0.2777 | C17: 0.57952
A18: Probability of TOUCHING -10% at any point | B18: 0.19752 | C18: 0.45536
A20: Median versus spot | B20: =B9/B12-1 | C20: =C9/C12-1
A21: Width of the 5th-95th band, as % of spot | B21: =(B11-B7)/B12 | C21: =(C11-C7)/C12
A23: HOW WELL CALIBRATED IS THIS MAP? — MEASURED, NOT ASSERTED
A24: Windows scored | B24: 16
A25: Skill against a random walk | B25: -0.01779057
A26: Coverage of the 50% band (nominal 50%) | B26: 0.5625
A27: Coverage of the 80% band (nominal 80%) | B27: 1
A28: Coverage of the 90% band (nominal 90%) | B28: 1
A29: Cone width against the benchmark | B29: 1.2342923
A31: The bands cover MORE than their nominal share, so the map is too wide rather than mis-centred.
A32: It is carried as illustrative only and no valuation conclusion rests on it.

Sheet Sensitivity
A1: Sensitivity — whole-model re-runs (class 3, pasted)
A2: Each cell is a complete revaluation. THESE GRIDS DO NOT REDRAW.
A4: Fair value per share (EGP): explicit-window cost of capital against terminal growth
B5: g = 3% | C5: g = 4% | D5: g = 5% | E5: g = 6% | F5: g = 7%
A6: 0.21455485 | B6: 53.818676 | C6: 52.504947 | D6: 50.963214 | E6: 49.128479 | F6: 46.908446
A7: 0.22955485 | B7: 52.896342 | C7: 51.615449 | D7: 50.112251 | E7: 48.323374 | F7: 46.158829
A8: 0.24455485 | B8: 52.003652 | C8: 50.754494 | D8: 49.288537 | E8: 47.54398 | F8: 45.433062
A9: 0.25955485 | B9: 51.139368 | C9: 49.920889 | D9: 48.490936 | E9: 46.789226 | F9: 44.730152
A10: 0.27455485 | B10: 50.302312 | C10: 49.113502 | D10: 47.718368 | E10: 46.058094 | F10: 44.049157
A12: Fair value per share (EGP): explicit-window rate against TERMINAL rate
B13: terminal 14.5% | C13: terminal 15.5% | D13: terminal 16.5% | E13: terminal 17.5% | F13: terminal 18.5%
A14: 0.21455485 | B14: 56.255082 | C14: 53.362751 | D14: 50.963214 | E14: 48.93862 | F14: 47.20597
A15: 0.22955485 | B15: 55.26823 | C15: 52.450175 | D15: 50.112251 | E15: 48.139634 | F15: 46.451457
A16: 0.24455485 | B16: 54.313282 | C16: 51.566959 | D16: 49.288537 | E16: 47.366117 | F16: 45.720891
A17: 0.25955485 | B17: 53.3889 | C17: 50.711874 | D17: 48.490936 | E17: 46.617011 | F17: 45.013279
A18: 0.27455485 | B18: 52.493813 | C18: 49.883755 | D18: 47.718368 | E18: 45.891307 | F18: 44.327675
A20: Fair value per share (EGP): beta
B21: 0.60 | C21: 0.80 | D21: 1.00 | E21: 1.15 | F21: 1.30
A22: Fair value | B22: 49.824727 | C22: 46.339866 | D22: 43.495664 | E22: 41.680938 | F22: 40.082835
A24: Fair value per share (EGP): shift in the EBITDA margin, every forecast year
B25: -4% | C25: -2% | D25: +0% | E25: +2% | F25: +4%
A26: Fair value | B26: 40.269675 | C26: 44.779106 | D26: 49.288537 | E26: 53.797968 | F26: 58.307399
A28: Fair value per share (EGP): net cash at the valuation date (EGP mn)
B29: 2,379 | C29: 3,129 | D29: 3,879 | E29: 4,629 | F29: 5,379
A30: Fair value | B30: 45.28715 | C30: 47.287844 | D30: 49.288537 | E30: 51.289231 | F30: 53.289924
A32: Note the growth column of the first grid: HIGHER terminal growth gives a LOWER value, because the
A33: terminal return on capital sits below the terminal rate. That is the model being consistent, not a
A34: sign error. Beta is varied over the fixed comparability anchors 0.60 / 0.80 / 1.00 / 1.15 / 1.30,
A35: which span the regression's own confidence interval.

Sheet Peer & Sector
A1: Peer set and the Egyptian cement balance
B4: Revenue (EGP mn) | C4: Profit (EGP mn) | D4: Market cap (EGP mn) | E4: Price / earnings | F4: Price / sales | G4: Net margin
A5: Arabian Cement (ARCC) | B5: =Assumptions!$B$62 | C5: =Assumptions!$B$65 | D5: =DCF!C42 | E5: =D5/C5 | F5: =D5/B5 | G5: =C5/B5
A6: Sinai Cement (SCEM) | B6: =Assumptions!$B$110 | C6: =Assumptions!$B$111 | D6: =Assumptions!$B$112 | E6: =D6/C6 | F6: =D6/B6 | G6: =C6/B6
A7: Misr Beni Suef Cement (MBSC) | B7: =Assumptions!$B$113 | C7: =Assumptions!$B$114 | D7: =Assumptions!$B$115 | E7: =D7/C7 | F7: =D7/B7 | G7: =C7/B7
A9: Peer average price / earnings (excluding the subject) | E9: =AVERAGE(E6:E7)
A10: Subject premium / (discount) to the peer average | E10: =E5/E9-1
A12: THE EGYPTIAN CEMENT BALANCE
A13: Nameplate capacity (Mt) | B13: =Assumptions!$B$105
A14: Production 2025 (Mt) | B14: =Assumptions!$B$106
A15: Domestic consumption 2025 (Mt) | B15: =Assumptions!$B$107
A16: Exports 2025 (Mt) | B16: =Assumptions!$B$108
A17: Dormant capacity under revival (Mt) | B17: =Assumptions!$B$109
A18: Sector utilisation | B18: =B14/B13
A19: The subject as a share of national capacity | B19: =Assumptions!$B$12/B13
A20: Revival capacity as a share of consumption | B20: =B17/B15
A22: The Egyptian peer set is thin and its published multiples do not reconcile against the market
A23: capitalisations printed beside them, which is why the relative lens carries only 20% of the weight.
A24: Every multiple on this sheet is RECOMPUTED from revenue, profit and market capitalisation rather
A25: than quoted.
