Workbook

Sheet READ FIRST
A1: Testahil — Fertiglobe plc (ADX: FERTIGLB)
A3: Companion model · Independent valuation study · Educational analysis · Not investment advice
A5: What this workbook is. A transparent companion to the Fertiglobe valuation study. Blue cells are
A6: inputs; black cells are formulas; green cells link to another sheet in this workbook.
A8: IT CALCULATES, IT DOES NOT STORE. Every figure that can be derived from a driver is a live formula,
A9: so you can change a blue cell on Assumptions and watch the model reprice. The cost of capital is
A10: built in the sheet — the Abu Dhabi US dollar sovereign yield less its own default spread gives the
A11: normalised risk-free rate, beta times the equity risk premium gives the cost of equity, the cost of
A12: debt is taken after tax, and the weights come from net debt and market capitalisation. The glide
A13: fractions are shown as they are derived and the discount factors compound, each one the year before
A14: divided by one plus that year's cost of capital. The unit build multiplies volume by price and by
A15: cost per tonne. The balance sheet rolls property forward as prior plus capital expenditure less
... A65: Monte Carlo · Sensitivity · Per-Share & Ratios · Peer & Sector.

Sheet Summary
A1: Summary — valuation at a glance
A2: Every value links live to the sheet that computes it
A4: Lens | B4: AED per share | C4: Role | D4: Against the market price | E4: Terminal value share
A5: Cash flow — framing A, marginal-cost anchor | B5: ='Fundamental Valuation'!B5 | C5: THE ANSWER | D5: =B5/$B$12-1 | E5: ='SOTP Bridge'!B14
A6: Cash flow — framing B, tightness persists | B6: ='Fundamental Valuation'!B6 | C6: THE ANSWER | D6: =B6/$B$12-1 | E6: ='SOTP Bridge'!C14
A7: Relative multiples | B7: ='Fundamental Valuation'!B7 | C7: Cross-check | D7: =B7/$B$12-1
A8: Book value | B8: ='Fundamental Valuation'!B8 | C8: Floor | D8: =B8/$B$12-1
A9: NOT AVERAGED — the midpoint neither framing supports | B9: ='Fundamental Valuation'!B9
A10: The envelope — the two present-value reads | B10: ='Fundamental Valuation'!B10 | C10: ='Fundamental Valuation'!C10
A11: Median of the three panel methods | B11: ='Fundamental Valuation'!D25
A12: Market price (AED per share) | B12: =Assumptions!$C$5
A14: Key figure | B14: Value
A15: Ordinary shares outstanding (mn) | B15: =Assumptions!$C$7
A16: Market capitalisation ($m) | B16: =DCF!C84
A17: Net debt at 30 June 2026 ($m) | B17: =Assumptions!$C$70
A18: FY2025 revenue ($m) | B18: ='Income Statement'!D5
A19: FY2025 EBITDA ($m) | B19: ='Income Statement'!D11
A20: FY2025 profit to owners ($m) | B20: ='Income Statement'!D21
A21: Realisation against the blended benchmark | B21: =Assumptions!$C$24
A22: Cost pass-through, share of each incremental dollar | B22: =Assumptions!$C$25
A23: Forecast tax rate | B23: =DCF!C106
A24: Cost of capital — explicit window | B24: =DCF!C88
A25: Cost of capital — terminal | B25: =DCF!C91
A26: Terminal growth | B26: =Assumptions!$C$74
A28: Values are model outputs shown as a range and a weighted central figure. They are not a recommendation and not a target.

Sheet Fundamental Valuation
A1: Fundamental valuation — four lenses, and the judgement carried both ways
A4: Lens | B4: AED per share | C4: Role | D4: Against the market price
A5: Cash flow — framing A, normalisation to a marginal-cost anchor | B5: ='SOTP Bridge'!B13 | C5: THE ANSWER | D5: =B5/Assumptions!$C$5-1
A6: Cash flow — framing B, the current tightness persists | B6: ='SOTP Bridge'!C13 | C6: THE ANSWER | D6: =B6/Assumptions!$C$5-1
A7: Relative multiples — mid-cycle EBITDA on a peer-anchored multiple | B7: ='Relative & Normalized'!C9 | C7: Cross-check | D7: =B7/Assumptions!$C$5-1
A8: Book value marked to the sustainable return on that equity | B8: ='Relative & Normalized'!C34 | C8: Floor | D8: =B8/Assumptions!$C$5-1
A9: NOT AVERAGED — the midpoint is a number neither framing supports | B9: =AVERAGE(B5:B6) | C9: shown only to be refused
A10: The envelope — the two present-value reads | B10: =MIN(B5:B6) | C10: =MAX(B5:B6)
A12: THE CONTESTED JUDGEMENT — COMPUTED BOTH WAYS, PUBLISHED SIDE BY SIDE | B12: Framing A | C12: Framing B
A13: Urea price assumed in FY2030E ($/t) | B13: =Assumptions!$F$17 | C13: =Assumptions!$F$19
A14: FY2030E EBITDA ($m) | B14: =DCF!F7 | C14: =DCF!F26
A15: Enterprise value ($m) | B15: ='SOTP Bridge'!B7 | C15: ='SOTP Bridge'!C7
A16: Terminal value as a share of enterprise value | B16: ='SOTP Bridge'!B14 | C16: ='SOTP Bridge'!C14
A17: Value per share (AED) | B17: ='SOTP Bridge'!B13 | C17: ='SOTP Bridge'!C13
A18: NEITHER IS AVERAGED INTO THE OTHER — both are the answer
A20: THE PANEL — THREE METHODS, WORKED SEPARATELY
A21: Method | B21: Input | C21: Enterprise value ($m) | D21: AED per share
A22: Mid-cycle multiple on through-the-cycle EBITDA | B22: 6.4 | C22: =B22*'Relative & Normalized'!C5 | D22: =(C22-Assumptions!$C$70)*(1-Assumptions!$C$78)/Assumptions!$C$7*Assumptions!$C$6
A23: Discounted cash flow with an explicit gas pass-through | B23: =Assumptions!$C$25 | C23: ='SOTP Bridge'!B7 | D23: ='SOTP Bridge'!B13
A24: Replacement cost of installed nitrogen capacity | B24: =Assumptions!$C$76 | C24: =(Assumptions!$C$10+Assumptions!$C$11)*B24/1000 | D24: =(C24-Assumptions!$C$70)*(1-Assumptions!$C$78)/Assumptions!$C$7*Assumptions!$C$6
A25: Median of the three | D25: =MEDIAN(D22:D24)
A27: The three do not agree, and the disagreement is the point: the multiple method prices the cycle the peers are in, the cash-flow method prices the gas contracts, and the replacement method prices the steel. They bracket the same answer from three directions.

Sheet Assumptions
A1: Assumptions — the driver register
A2: Blue cells are inputs: change one and the model reprices. Green cells are computed elsewhere in the workbook and shown here so every driver the model consumes is visible in one place.
A3: Driver | B3: FY2026E | C3: FY2027E | D3: FY2028E | E3: FY2029E | F3: FY2030E
A4: Market and share count
A5: Market price (AED per share) | C5: 2.67
A6: Dirhams per US dollar (Central Bank peg) | C6: 3.6725
A7: Ordinary shares outstanding (mn) | C7: 8249.6
A9: Capacity and utilisation
A10: Urea production capacity (kt) | C10: 5100
A11: Merchant ammonia capacity (kt) | C11: 1500
A12: Urea capacity utilisation | B12: 0.823 | C12: 0.853 | D12: 0.873 | E12: 0.883 | F12: 0.888
A13: Merchant ammonia capacity utilisation | B13: 0.715 | C13: 0.8 | D13: 0.827 | E13: 0.84 | F13: 0.847
A14: Third-party traded volume (kt) | B14: 1150 | C14: 1200 | D14: 1250 | E14: 1300 | F14: 1350
A16: Price paths — the contested judgement, carried both ways
A17: Framing A — urea benchmark, Egypt free on board ($/t) | B17: 590 | C17: 480 | D17: 440 | E17: 435 | F17: 435
A18: Framing A — ammonia benchmark, Middle East ($/t) | B18: 560 | C18: 460 | D18: 420 | E18: 415 | F18: 415
A19: Framing B — urea benchmark, Egypt free on board ($/t) | B19: 590 | C19: 560 | D19: 550 | E19: 550 | F19: 555
A20: Framing B — ammonia benchmark, Middle East ($/t) | B20: 560 | C20: 540 | D20: 530 | E20: 530 | F20: 535
A21: Third-party traded price ($/t) | B21: 600 | C21: 520 | D21: 490 | E21: 490 | F21: 492
A23: Cost and margin drivers
A24: Realisation against the blended benchmark | C24: =Segments!B19
A25: Cost pass-through — share of each incremental dollar of realised price | C25: =Segments!B28
A26: Cost pass-through — fixed cash cost intercept ($/t) | C26: =Segments!B29
A27: Third-party trading EBITDA margin | C27: 0.075
A28: Corporate and other segment EBITDA ($m) | B28: -82 | C28: -78 | D28: -76 | E28: -76 | F28: -77
A30: Capital intensity
A31: Depreciation and amortisation ($m) | B31: 305 | C31: 315 | D31: 325 | E31: 333 | F31: 340
A32: Capital expenditure ($m) | B32: 175 | C32: 240 | D32: 285 | E32: 315 | F32: 335
A34: Working-capital cycle (measured on the Balance Sheet sheet)
A35: Days sales outstanding | C35: ='Balance Sheet'!D27
A36: Days inventory outstanding | C36: ='Balance Sheet'!D28
A37: Days payables outstanding, excluding the gas accrual | C37: ='Balance Sheet'!D32
A38: Working capital at FY2025, excluding the gas accrual ($m) | C38: ='Balance Sheet'!D34
A40: Tax — three sourced estimates, averaged on the DCF sheet
A41: Statutory corporate tax rate — United Arab Emirates | C41: 0.09
A42: Statutory corporate tax rate — Egypt | C42: 0.225
A43: Statutory corporate tax rate — Algeria | C43: 0.1007
A44: Share of non-current assets in Egypt | C44: 0.311
A45: Share of non-current assets in Algeria | C45: 0.161
A46: Income tax charge, FY2022 ($m) | C46: 239.2
...

Sheet SOTP Bridge
A1: Enterprise value to equity — the bridge, and where the value sits
A2: A single-class nitrogen producer, so this is the bridge from enterprise value to the shareholder plus the split of that value between the two operating legs — not a holding-company sum of parts.
A4: Step | B4: Framing A | C4: Framing B
A5: Present value of the five explicit years ($m) | B5: =DCF!C60 | C5: =DCF!D60
A6: Present value of the terminal value ($m) | B6: =DCF!C61 | C6: =DCF!D61
A7: Enterprise value ($m) | B7: =B5+B6 | C7: =C5+C6
A8: Less net debt ($m) | B8: =Assumptions!$C$70 | C8: =Assumptions!$C$70
A9: Equity value before minority interests ($m) | B9: =B7-B8 | C9: =C7-C8
A10: Less minority interests at their share of group profit ($m) | B10: =B9*Assumptions!$C$78 | C10: =C9*Assumptions!$C$78
A11: Equity attributable to owners ($m) | B11: =B9-B10 | C11: =C9-C10
A12: Value per share ($) | B12: =B11/Assumptions!$C$7 | C12: =C11/Assumptions!$C$7
A13: Value per share (AED) | B13: =B12*Assumptions!$C$6 | C13: =C12*Assumptions!$C$6
A14: Terminal value as a share of enterprise value | B14: =B6/B7 | C14: =C6/C7
A16: NOT AVERAGED — the midpoint of the two framings, which neither supports (AED per share) | B16: =AVERAGE(B13:C13)
A18: THE MINORITY INTERESTS ON THE OTHER BASIS — BOTH ARE SHOWN, NEITHER IS AVERAGED
A19: Less minority interests at their book carrying value ($m) | B19: =Assumptions!$C$79 | C19: =Assumptions!$C$79
A20: Equity attributable to owners, book basis ($m) | B20: =B9-B19 | C20: =C9-C19
A21: Value per share, book basis (AED) | B21: =B20/Assumptions!$C$7*Assumptions!$C$6 | C21: =C20/Assumptions!$C$7*Assumptions!$C$6
A23: Egypt Basic Industries is a quarter owned outside the group and Sorfert almost half, so the minority deduction is the single largest step in this bridge. Deducting the minorities at their share of the profit they actually earn takes out roughly five times what their historical book carrying value would; the model runs on the earnings basis and shows the book basis beside it rather than splitting the difference.
A25: WHERE THE VALUE SITS — THE TWO OPERATING LEGS
A26: Leg | B26: Mid-cycle EBITDA ($m) | C26: Share | D26: Enterprise value ($m) | E26: AED per share
A27: Mid-cycle enterprise value, the average of the two framings ($m) | B27: =(DCF!C62+DCF!D62)/2
A28: Own-produced production and marketing | B28: =(SUM(Segments!D50:F50)+SUM(Segments!D82:F82))/6 | C28: =B28/$B$31 | D28: =C28*$B$27 | E28: =D28/Assumptions!$C$7*Assumptions!$C$6
A29: Third-party trading | B29: =(SUM(Segments!D54:F54)+SUM(Segments!D86:F86))/6 | C29: =B29/$B$31 | D29: =C29*$B$27 | E29: =D29/Assumptions!$C$7*Assumptions!$C$6
A30: Corporate and other | B30: =(SUM(Segments!D55:F55)+SUM(Segments!D87:F87))/6 | C30: =B30/$B$31 | D30: =C30*$B$27 | E30: =D30/Assumptions!$C$7*Assumptions!$C$6
A31: Total mid-cycle EBITDA ($m) | B31: =SUM(B28:B30) | C31: =SUM(C28:C30) | D31: =SUM(D28:D30)
A33: The legs are separated on the enterprise value they earn, before net debt and before the minority deduction, because both of those attach to the group rather than to either leg. Trading is a real business but a thin one: it moves a sixth of the tonnes for a twentieth of the profit, and the corporate load costs more than the whole of it.

Sheet Segments
A1: Segments — the unit build
A2: Volume times price, and cost per tonne regressed on the realised price. Both the realisation factor and the cost pass-through are measured here from the three reported periods, not assumed.
A4: Reported period | B4: FY2024 | C4: FY2025 | D4: First half 2026
A5: Urea sales volume (kt) | B5: 4225 | C5: 4228 | D5: 2045
A6: Merchant ammonia sales volume (kt) | B6: 1119 | C6: 1267 | D6: 523
A7: Own-produced sales volume, total (kt) | B7: 5345 | C7: 5498 | D7: 2571
A8: Own-produced segment revenue ($m) | B8: 1896.2 | C8: 2332.4 | D8: 1597
A9: Own-produced segment EBITDA ($m) | B9: 697.5 | C9: 1059.9 | D9: 709.6
A10: Urea benchmark, Egypt free on board ($/t) | B10: 357 | C10: 440 | D10: 637
A11: Ammonia benchmark, Middle East ($/t) | B11: 349 | C11: 343 | D11: 594
A12: Realised price ($/t) | B12: =B8*1000/B7 | C12: =C8*1000/C7 | D12: =D8*1000/D7
A13: Volume-weighted benchmark price ($/t) | B13: =(B5*B10+B6*B11)/(B5+B6) | C13: =(C5*C10+C6*C11)/(C5+C6) | D13: =(D5*D10+D6*D11)/(D5+D6)
A14: Realisation against the benchmark | B14: =B12/B13 | C14: =C12/C13 | D14: =D12/D13
A15: Cash cost, total ($m) | B15: =B8-B9 | C15: =C8-C9 | D15: =D8-D9
A16: Cash cost per tonne ($/t) | B16: =B15*1000/B7 | C16: =C15*1000/C7 | D16: =D15*1000/D7
A17: Own-produced EBITDA margin | B17: =B9/B8 | C17: =C9/C8 | D17: =D9/D8
A19: Realisation factor applied to the forecast (average of the three) | B19: =AVERAGE(B14:D14)
A21: Cost pass-through — least squares of cash cost per tonne on realised price
A22: Realised price, the explanatory variable ($/t) | B22: =B12 | C22: =C12 | D22: =D12
A23: Cash cost per tonne, the dependent variable ($/t) | B23: =B16 | C23: =C16 | D23: =D16
A24: Mean realised price ($/t) | B24: =AVERAGE(B22:D22)
A25: Mean cash cost per tonne ($/t) | B25: =AVERAGE(B23:D23)
A26: Sum of cross products | B26: =(B22-$B$24)*(B23-$B$25)+(C22-$B$24)*(C23-$B$25)+(D22-$B$24)*(D23-$B$25)
A27: Sum of squared deviations in price | B27: =(B22-$B$24)^2+(C22-$B$24)^2+(D22-$B$24)^2
A28: Slope — the pass-through | B28: =B26/B27
A29: Intercept — fixed cash cost per tonne ($/t) | B29: =B25-B28*B24
A30: Sum of squared residuals | B30: =(B23-($B$29+$B$28*B22))^2+(C23-($B$29+$B$28*C22))^2+(D23-($B$29+$B$28*D22))^2
A31: Total sum of squares | B31: =(B23-$B$25)^2+(C23-$B$25)^2+(D23-$B$25)^2
A32: Share of the variation explained | B32: =1-B30/B31
A34: The Egyptian and Algerian gas contracts are product-linked, so the cost side moves with the price side. The slope above is how much of each incremental dollar of realised price comes straight back out as cash cost; the intercept is what is left when the price side is stripped away. Both are measured, not assumed.
A36: FRAMING A — normalisation to a marginal-cost anchor
A37: $m unless stated | B37: FY2026E | C37: FY2027E | D37: FY2028E | E37: FY2029E | F37: FY2030E
A38: Urea capacity utilisation | B38: =Assumptions!$B$12 | C38: =Assumptions!$C$12 | D38: =Assumptions!$D$12 | E38: =Assumptions!$E$12 | F38: =Assumptions!$F$12
A39: Merchant ammonia capacity utilisation | B39: =Assumptions!$B$13 | C39: =Assumptions!$C$13 | D39: =Assumptions!$D$13 | E39: =Assumptions!$E$13 | F39: =Assumptions!$F$13
A40: Urea volume (kt) | B40: =Assumptions!$C$10*B38 | C40: =Assumptions!$C$10*C38 | D40: =Assumptions!$C$10*D38 | E40: =Assumptions!$C$10*E38 | F40: =Assumptions!$C$10*F38
A41: Merchant ammonia volume (kt) | B41: =Assumptions!$C$11*B39 | C41: =Assumptions!$C$11*C39 | D41: =Assumptions!$C$11*D39 | E41: =Assumptions!$C$11*E39 | F41: =Assumptions!$C$11*F39
A42: Own-produced volume (kt) | B42: =B40+B41 | C42: =C40+C41 | D42: =D40+D41 | E42: =E40+E41 | F42: =F40+F41
A43: Urea benchmark price ($/t) | B43: =Assumptions!$B$17 | C43: =Assumptions!$C$17 | D43: =Assumptions!$D$17 | E43: =Assumptions!$E$17 | F43: =Assumptions!$F$17
A44: Ammonia benchmark price ($/t) | B44: =Assumptions!$B$18 | C44: =Assumptions!$C$18 | D44: =Assumptions!$D$18 | E44: =Assumptions!$E$18 | F44: =Assumptions!$F$18
A45: Volume-weighted benchmark price ($/t) | B45: =(B40*B43+B41*B44)/(B40+B41) | C45: =(C40*C43+C41*C44)/(C40+C41) | D45: =(D40*D43+D41*D44)/(D40+D41) | E45: =(E40*E43+E41*E44)/(E40+E41) | F45: =(F40*F43+F41*F44)/(F40+F41)
...

Sheet Relative & Normalized
A1: Relative multiples, normalised earnings power, and book value
A2: The three lenses that do not discount a cash flow. Each is built from the same forecast.
A4: Relative multiples | B4: Value
A5: Mid-cycle EBITDA — the average of FY2028E to FY2030E on both framings ($m) | C5: =(SUM(DCF!D7:F7)+SUM(DCF!D26:F26))/6
A6: Justified enterprise value / EBITDA | C6: =Assumptions!$C$83
A7: Implied enterprise value ($m) | C7: =C5*C6
A8: Less net debt, giving equity before minorities ($m) | C8: =C7-Assumptions!$C$70
A9: Implied value per share (AED) | C9: =C8*(1-Assumptions!$C$78)/Assumptions!$C$7*Assumptions!$C$6
A11: Trailing market check | B11: Value
A12: Market capitalisation ($m) | C12: =DCF!C84
A13: Trailing enterprise value ($m) | C13: =C12+Assumptions!$C$70
A14: Trailing enterprise value / EBITDA (first half annualised) | C14: =C13/(Assumptions!$C$85*2)
A15: Trailing price / earnings (first half annualised) | C15: =C12/(Assumptions!$C$86*2)
A17: Normalised earnings power | B17: Value
A18: Mid-cycle EBITDA margin — the average of FY2023 to FY2025 | C18: =AVERAGE('Income Statement'!B24:D24)
A19: Mid-cycle revenue — the average of FY2028E to FY2030E on both framings ($m) | C19: =(SUM(DCF!D6:F6)+SUM(DCF!D25:F25))/6
A20: Normalised EBITDA ($m) | C20: =C19*C18
A21: Less depreciation, giving normalised EBIT ($m) | C21: =C20-Assumptions!$D$31
A22: Less interest on net debt ($m) | C22: =Assumptions!$C$71*Assumptions!$C$70
A23: Normalised profit to owners, after tax and minorities ($m) | C23: =(C21-C22)*(1-DCF!$C$106)*(1-Assumptions!$C$78)
A24: Normalised earnings per share ($) | C24: =C23/Assumptions!$C$7
A25: Justified price / earnings | C25: =Assumptions!$C$84
A26: Implied value per share (AED) | C26: =C24*C25*Assumptions!$C$6
A28: Book value and the sustainable return | B28: Value
A29: Book value per share ($) | C29: ='Balance Sheet'!D18/Assumptions!$C$7
A30: Return on equity, trailing | C30: ='Income Statement'!D21/'Balance Sheet'!D18
A31: Sustainable return on equity — the average of the three audited years | C31: =('Income Statement'!B21/'Balance Sheet'!B18+'Income Statement'!C21/'Balance Sheet'!C18+'Income Statement'!D21/'Balance Sheet'!D18)/3
A32: Cost of equity, the average of the two premium bases | C32: =DCF!C80
A33: Justified price to book — return less growth, over cost of equity less growth | C33: =(C31-Assumptions!$C$74)/(C32-Assumptions!$C$74)
A34: Implied value per share (AED) | C34: =C29*C33*Assumptions!$C$6
A36: The book lens is the weakest of the four here and is weighted accordingly. A nitrogen producer's plants are carried at depreciated historical cost in a currency that has been stable, so book equity understates what the same capacity would cost to build — but it is the one lens that does not need a forecast at all, which is why it is kept.

Sheet DCF
A1: Discounted cash flow — the full waterfall, both framings
A2: Every line is a live formula. The cost of capital is built at the foot of the sheet, the glide fractions are derived in front of you, and the discount factors compound one from the next.
A4: $m unless stated | B4: FY2026E | C4: FY2027E | D4: FY2028E | E4: FY2029E | F4: FY2030E
A5: FRAMING A — normalisation to a marginal-cost anchor
A6: Revenue | B6: =Segments!B56 | C6: =Segments!C56 | D6: =Segments!D56 | E6: =Segments!E56 | F6: =Segments!F56
A7: EBITDA | B7: =Segments!B57 | C7: =Segments!C57 | D7: =Segments!D57 | E7: =Segments!E57 | F7: =Segments!F57
A8: EBITDA margin (EBITDA / revenue) | B8: =B7/B6 | C8: =C7/C6 | D8: =D7/D6 | E8: =E7/E6 | F8: =F7/F6
A9: Depreciation and amortisation | B9: =Assumptions!$B$31 | C9: =Assumptions!$C$31 | D9: =Assumptions!$D$31 | E9: =Assumptions!$E$31 | F9: =Assumptions!$F$31
A10: EBIT (EBITDA less depreciation and amortisation) | B10: =B7-B9 | C10: =C7-C9 | D10: =D7-D9 | E10: =E7-E9 | F10: =F7-F9
A11: Net operating profit after tax (EBIT times one less the tax rate) | B11: =B10*(1-$C$106) | C11: =C10*(1-$C$106) | D11: =D10*(1-$C$106) | E11: =E10*(1-$C$106) | F11: =F10*(1-$C$106)
A12: Add back depreciation and amortisation | B12: =B9 | C12: =C9 | D12: =D9 | E12: =E9 | F12: =F9
A13: Less capital expenditure | B13: =Assumptions!$B$32 | C13: =Assumptions!$C$32 | D13: =Assumptions!$D$32 | E13: =Assumptions!$E$32 | F13: =Assumptions!$F$32
A14: Trade and other receivables (days sales outstanding) | B14: =Assumptions!$C$35*B6/365 | C14: =Assumptions!$C$35*C6/365 | D14: =Assumptions!$C$35*D6/365 | E14: =Assumptions!$C$35*E6/365 | F14: =Assumptions!$C$35*F6/365
A15: Inventories (days inventory outstanding) | B15: =Assumptions!$C$36*(B6-B7)/365 | C15: =Assumptions!$C$36*(C6-C7)/365 | D15: =Assumptions!$C$36*(D6-D7)/365 | E15: =Assumptions!$C$36*(E6-E7)/365 | F15: =Assumptions!$C$36*(F6-F7)/365
A16: Trade and other payables (days payables outstanding) | B16: =Assumptions!$C$37*(B6-B7)/365 | C16: =Assumptions!$C$37*(C6-C7)/365 | D16: =Assumptions!$C$37*(D6-D7)/365 | E16: =Assumptions!$C$37*(E6-E7)/365 | F16: =Assumptions!$C$37*(F6-F7)/365
A17: Net working capital | B17: =B14+B15-B16 | C17: =C14+C15-C16 | D17: =D14+D15-D16 | E17: =E14+E15-E16 | F17: =F14+F15-F16
A18: Less change in net working capital | B18: =B17-Assumptions!$C$38 | C18: =C17-B17 | D18: =D17-C17 | E18: =E17-D17 | F18: =F17-E17
A19: Free cash flow to the firm | B19: =B11+B12-B13-B18 | C19: =C11+C12-C13-C18 | D19: =D11+D12-D13-D18 | E19: =E11+E12-E13-E18 | F19: =F11+F12-F13-F18
A20: Forward cost of capital | B20: =$C$88+($C$91-$C$88)*B96 | C20: =$C$88+($C$91-$C$88)*C96 | D20: =$C$88+($C$91-$C$88)*D96 | E20: =$C$88+($C$91-$C$88)*E96 | F20: =$C$88+($C$91-$C$88)*F96
A21: Discount factor (each one the year before, divided by one plus that year's rate) | B21: =1/(1+B20) | C21: =B21/(1+C20) | D21: =C21/(1+D20) | E21: =D21/(1+E20) | F21: =E21/(1+F20)
A22: Present value of free cash flow | B22: =B19*B21 | C22: =C19*C21 | D22: =D19*D21 | E22: =E19*E21 | F22: =F19*F21
A24: FRAMING B — a structurally tight market
A25: Revenue | B25: =Segments!B88 | C25: =Segments!C88 | D25: =Segments!D88 | E25: =Segments!E88 | F25: =Segments!F88
A26: EBITDA | B26: =Segments!B89 | C26: =Segments!C89 | D26: =Segments!D89 | E26: =Segments!E89 | F26: =Segments!F89
A27: EBITDA margin (EBITDA / revenue) | B27: =B26/B25 | C27: =C26/C25 | D27: =D26/D25 | E27: =E26/E25 | F27: =F26/F25
A28: Depreciation and amortisation | B28: =Assumptions!$B$31 | C28: =Assumptions!$C$31 | D28: =Assumptions!$D$31 | E28: =Assumptions!$E$31 | F28: =Assumptions!$F$31
A29: EBIT (EBITDA less depreciation and amortisation) | B29: =B26-B28 | C29: =C26-C28 | D29: =D26-D28 | E29: =E26-E28 | F29: =F26-F28
A30: Net operating profit after tax (EBIT times one less the tax rate) | B30: =B29*(1-$C$106) | C30: =C29*(1-$C$106) | D30: =D29*(1-$C$106) | E30: =E29*(1-$C$106) | F30: =F29*(1-$C$106)
A31: Add back depreciation and amortisation | B31: =B28 | C31: =C28 | D31: =D28 | E31: =E28 | F31: =F28
A32: Less capital expenditure | B32: =Assumptions!$B$32 | C32: =Assumptions!$C$32 | D32: =Assumptions!$D$32 | E32: =Assumptions!$E$32 | F32: =Assumptions!$F$32
A33: Trade and other receivables (days sales outstanding) | B33: =Assumptions!$C$35*B25/365 | C33: =Assumptions!$C$35*C25/365 | D33: =Assumptions!$C$35*D25/365 | E33: =Assumptions!$C$35*E25/365 | F33: =Assumptions!$C$35*F25/365
A34: Inventories (days inventory outstanding) | B34: =Assumptions!$C$36*(B25-B26)/365 | C34: =Assumptions!$C$36*(C25-C26)/365 | D34: =Assumptions!$C$36*(D25-D26)/365 | E34: =Assumptions!$C$36*(E25-E26)/365 | F34: =Assumptions!$C$36*(F25-F26)/365
A35: Trade and other payables (days payables outstanding) | B35: =Assumptions!$C$37*(B25-B26)/365 | C35: =Assumptions!$C$37*(C25-C26)/365 | D35: =Assumptions!$C$37*(D25-D26)/365 | E35: =Assumptions!$C$37*(E25-E26)/365 | F35: =Assumptions!$C$37*(F25-F26)/365
A36: Net working capital | B36: =B33+B34-B35 | C36: =C33+C34-C35 | D36: =D33+D34-D35 | E36: =E33+E34-E35 | F36: =F33+F34-F35
A37: Less change in net working capital | B37: =B36-Assumptions!$C$38 | C37: =C36-B36 | D37: =D36-C36 | E37: =E36-D36 | F37: =F36-E36
A38: Free cash flow to the firm | B38: =B30+B31-B32-B37 | C38: =C30+C31-C32-C37 | D38: =D30+D31-D32-D37 | E38: =E30+E31-E32-E37 | F38: =F30+F31-F32-F37
A39: Forward cost of capital | B39: =$C$88+($C$91-$C$88)*B96 | C39: =$C$88+($C$91-$C$88)*C96 | D39: =$C$88+($C$91-$C$88)*D96 | E39: =$C$88+($C$91-$C$88)*E96 | F39: =$C$88+($C$91-$C$88)*F96
A40: Discount factor (each one the year before, divided by one plus that year's rate) | B40: =1/(1+B39) | C40: =B40/(1+C39) | D40: =C40/(1+D39) | E40: =D40/(1+E39) | F40: =E40/(1+F39)
A41: Present value of free cash flow | B41: =B38*B40 | C41: =C38*C40 | D41: =D38*D40 | E41: =E38*E40 | F41: =F38*F40
A43: TERMINAL BLOCK AND ENTERPRISE VALUE | C43: Framing A | D43: Framing B
...

Sheet Income Statement
A1: Income statement — three years audited, five years forecast
A2: $m, consolidated. The disclosed lines are carried as reported; every subtotal is a formula that has to reconcile to them, and every forecast column is a formula.
A4: $m | B4: FY2023 | C4: FY2024 | D4: FY2025 | E4: FY2026E | F4: FY2027E | G4: FY2028E | H4: FY2029E | I4: FY2030E
A5: Revenue | B5: 2416.2 | C5: 2009.2 | D5: 2827.4 | E5: =DCF!B6 | F5: =DCF!C6 | G5: =DCF!D6 | H5: =DCF!E6 | I5: =DCF!F6
A6: Cost of sales | B6: 1564.2 | C6: 1512.9 | D6: 1942 | E6: - | F6: - | G6: - | H6: - | I6: -
A7: Gross profit | B7: =B5-B6 | C7: =C5-C6 | D7: =D5-D6 | E7: - | F7: - | G7: - | H7: - | I7: -
A8: Selling, general and administrative expenses | B8: 144.5 | C8: 150.2 | D8: 158.1 | E8: - | F8: - | G8: - | H8: - | I8: -
A9: Other income, net | B9: 2.6 | C9: 3 | D9: 0 | E9: - | F9: - | G9: - | H9: - | I9: -
A10: Depreciation and amortisation | B10: 279.3 | C10: 279.5 | D10: 297.6 | E10: =DCF!B9 | F10: =DCF!C9 | G10: =DCF!D9 | H10: =DCF!E9 | I10: =DCF!F9
A11: EBITDA | B11: =B7-B8+B9+B10 | C11: =C7-C8+C9+C10 | D11: =D7-D8+D9+D10 | E11: =DCF!B7 | F11: =DCF!C7 | G11: =DCF!D7 | H11: =DCF!E7 | I11: =DCF!F7
A12: Operating profit (EBIT) | B12: =B11-B10 | C12: =C11-C10 | D12: =D11-D10 | E12: =E11-E10 | F12: =F11-F10 | G12: =G11-G10 | H12: =H11-H10 | I12: =I11-I10
A13: Finance income | B13: 16.3 | C13: 17.1 | D13: 13.6 | E13: - | F13: - | G13: - | H13: - | I13: -
A14: Finance costs | B14: 119.4 | C14: 135.6 | D14: 115.8 | E14: =Assumptions!$C$71*MAX(Assumptions!$C$70,0) | F14: =Assumptions!$C$71*MAX('Balance Sheet'!E22,0) | G14: =Assumptions!$C$71*MAX('Balance Sheet'!F22,0) | H14: =Assumptions!$C$71*MAX('Balance Sheet'!G22,0) | I14: =Assumptions!$C$71*MAX('Balance Sheet'!H22,0)
A15: Net foreign exchange gain and loss | B15: -19.6 | C15: -1.3 | D15: -11.6 | E15: - | F15: - | G15: - | H15: - | I15: -
A16: Net finance result | B16: =B13-B14+B15 | C16: =C13-C14+C15 | D16: =D13-D14+D15 | E16: =E13-E14+E15 | F16: =F13-F14+F15 | G16: =G13-G14+G15 | H16: =H13-H14+H15 | I16: =I13-I14+I15
A17: Profit before tax | B17: =B12+B16 | C17: =C12+C16 | D17: =D12+D16 | E17: =E12+E16 | F17: =F12+F16 | G17: =G12+G16 | H17: =H12+H16 | I17: =I12+I16
A18: Income tax expense | B18: 82.4 | C18: 15.7 | D18: 25 | E18: =E17*DCF!$C$106 | F18: =F17*DCF!$C$106 | G18: =G17*DCF!$C$106 | H18: =H17*DCF!$C$106 | I18: =I17*DCF!$C$106
A19: Profit for the year | B19: =B17-B18 | C19: =C17-C18 | D19: =D17-D18 | E19: =E17-E18 | F19: =F17-F18 | G19: =G17-G18 | H19: =H17-H18 | I19: =I17-I18
A20: Non-controlling interests | B20: 156.1 | C20: 53.7 | D20: 154.6 | E20: =E19*Assumptions!$C$78 | F20: =F19*Assumptions!$C$78 | G20: =G19*Assumptions!$C$78 | H20: =H19*Assumptions!$C$78 | I20: =I19*Assumptions!$C$78
A21: Profit attributable to owners | B21: =B19-B20 | C21: =C19-C20 | D21: =D19-D20 | E21: =E19-E20 | F21: =F19-F20 | G21: =G19-G20 | H21: =H19-H20 | I21: =I19-I20
A22: Earnings per share ($) | B22: =B21/Assumptions!$C$7 | C22: =C21/Assumptions!$C$7 | D22: =D21/Assumptions!$C$7 | E22: =E21/Assumptions!$C$7 | F22: =F21/Assumptions!$C$7 | G22: =G21/Assumptions!$C$7 | H22: =H21/Assumptions!$C$7 | I22: =I21/Assumptions!$C$7
A23: Earnings per share (AED) | B23: =B22*Assumptions!$C$6 | C23: =C22*Assumptions!$C$6 | D23: =D22*Assumptions!$C$6 | E23: =E22*Assumptions!$C$6 | F23: =F22*Assumptions!$C$6 | G23: =G22*Assumptions!$C$6 | H23: =H22*Assumptions!$C$6 | I23: =I22*Assumptions!$C$6
A24: EBITDA margin | B24: =B11/B5 | C24: =C11/C5 | D24: =D11/D5 | E24: =E11/E5 | F24: =F11/F5 | G24: =G11/G5 | H24: =H11/H5 | I24: =I11/I5
A25: Effective tax rate | B25: =B18/B17 | C25: =C18/C17 | D25: =D18/D17 | E25: =E18/E17 | F25: =F18/F17 | G25: =G18/G17 | H25: =H18/H17 | I25: =I18/I17
A27: The forecast is built at the EBITDA line from the unit build, so cost of sales and the administrative and other lines are not split out in the forecast columns; the total cash cost that replaces them is on the Segments sheet. The finance charge is computed on the net debt the business is actually carrying that year, so profit is struck after financing and differs from the pre-financing cash-flow waterfall by construction.

Sheet Balance Sheet
A1: Balance sheet — audited history and a rolled-forward forecast
A2: $m, consolidated. FY2023 to FY2025 are the audited closing figures; the forecast rolls property, working capital, equity and net debt forward from them.
A4: $m | B4: FY2023 | C4: FY2024 | D4: FY2025 | E4: FY2026E | F4: FY2027E | G4: FY2028E | H4: FY2029E | I4: FY2030E
A5: Property, plant and equipment | B5: 2699.6 | C5: 2596.8 | D5: 2499 | E5: =D5+DCF!B13-DCF!B9 | F5: =E5+DCF!C13-DCF!C9 | G5: =F5+DCF!D13-DCF!D9 | H5: =G5+DCF!E13-DCF!E9 | I5: =H5+DCF!F13-DCF!F9
A6: Right-of-use assets | B6: 74.9 | C6: 68.6 | D6: 139.4
A7: Goodwill and intangible assets | B7: 614.5 | C7: 626.8 | D7: 656.9
A8: Inventories | B8: 133.6 | C8: 164 | D8: 335.5 | E8: =DCF!B15 | F8: =DCF!C15 | G8: =DCF!D15 | H8: =DCF!E15 | I8: =DCF!F15
A9: Trade and other receivables | B9: 314.3 | C9: 290.7 | D9: 493.1 | E9: =DCF!B14 | F9: =DCF!C14 | G9: =DCF!D14 | H9: =DCF!E14 | I9: =DCF!F14
A10: Cash and cash equivalents | B10: 759.8 | C10: 633.9 | D10: 735.1
A11: Total assets | B11: 4625.8 | C11: 4410.6 | D11: 4949.5
A12: Trade and other payables | B12: 326.7 | C12: 481 | D12: 820.3 | E12: =DCF!B16 | F12: =DCF!C16 | G12: =DCF!D16 | H12: =DCF!E16 | I12: =DCF!F16
A13: Loans and borrowings — non-current | B13: 1490.2 | C13: 1425.5 | D13: 1398.6
A14: Loans and borrowings — current | B14: 174.9 | C14: 256.7 | D14: 342
A15: Lease liabilities | B15: 90.6 | C15: 86.9 | D15: 158.4
A16: Deferred tax liabilities | B16: 344.9 | C16: 310 | D16: 273.1
A17: Income tax payable | B17: 270.4 | C17: 254.4 | D17: 112.9
A18: Equity attributable to owners | B18: 1444.7 | C18: 1241.8 | D18: 1356.5 | E18: =D18+'Income Statement'!E21*(1-Assumptions!$C$80) | F18: =E18+'Income Statement'!F21*(1-Assumptions!$C$80) | G18: =F18+'Income Statement'!G21*(1-Assumptions!$C$80) | H18: =G18+'Income Statement'!H21*(1-Assumptions!$C$80) | I18: =H18+'Income Statement'!I21*(1-Assumptions!$C$80)
A19: Non-controlling interests | B19: 425 | C19: 295.9 | D19: 443.3
A20: Total equity | B20: =B18+B19 | C20: =C18+C19 | D20: =D18+D19
A21: Gross interest-bearing debt | B21: =B13+B14 | C21: =C13+C14 | D21: =D13+D14
A22: Net debt (debt and leases less cash) | B22: =B21+B15-B10 | C22: =C21+C15-C10 | D22: =D21+D15-D10 | E22: =Assumptions!$C$70-(DCF!B19+'Income Statement'!E16*(1-DCF!$C$106))+Assumptions!$C$80*'Income Statement'!E21+'Income Statement'!E20 | F22: =E22-(DCF!C19+'Income Statement'!F16*(1-DCF!$C$106))+Assumptions!$C$80*'Income Statement'!F21+'Income Statement'!F20 | G22: =F22-(DCF!D19+'Income Statement'!G16*(1-DCF!$C$106))+Assumptions!$C$80*'Income Statement'!G21+'Income Statement'!G20 | H22: =G22-(DCF!E19+'Income Statement'!H16*(1-DCF!$C$106))+Assumptions!$C$80*'Income Statement'!H21+'Income Statement'!H20 | I22: =H22-(DCF!F19+'Income Statement'!I16*(1-DCF!$C$106))+Assumptions!$C$80*'Income Statement'!I21+'Income Statement'!I20
A23: Net working capital (inventories and receivables less payables) | B23: =B8+B9-B12 | C23: =C8+C9-C12 | D23: =D8+D9-D12 | E23: =E8+E9-E12 | F23: =F8+F9-F12 | G23: =G8+G9-G12 | H23: =H8+H9-H12 | I23: =I8+I9-I12
A24: Invested capital (property plus net working capital) | B24: =B5+B23 | C24: =C5+C23 | D24: =D5+D23 | E24: =E5+E23 | F24: =F5+F23 | G24: =G5+G23 | H24: =H5+H23 | I24: =I5+I23
A26: THE ASSET-CONVERSION CYCLE — MEASURED, THEN PROJECTED
A27: Days sales outstanding (receivables over revenue) | C27: =365*C9/'Income Statement'!C5 | D27: =365*D9/'Income Statement'!D5
A28: Days inventory outstanding (inventories over cost of sales) | C28: =365*C8/'Income Statement'!C6 | D28: =365*D8/'Income Statement'!D6
A29: Days payables outstanding (payables over cost of sales) | C29: =365*C12/'Income Statement'!C6 | D29: =365*D12/'Income Statement'!D6
A30: Cash conversion cycle (days) | C30: =C27+C28-C29 | D30: =D27+D28-D29
A31: Gas accrual carried inside payables at FY2025 ($m) | D31: 386.3
A32: Days payables outstanding, excluding that accrual | D32: =365*(D12-D31)/'Income Statement'!D6
A33: Cash conversion cycle, excluding that accrual (days) | D33: =D27+D28-D32
A34: Net working capital at FY2025, excluding that accrual ($m) | D34: =D8+D9-(D12-D31)
A36: The gas accrual is a retrospective true-up on a disputed supply contract, not a trade payable in the ordinary course. Leaving it inside payables would make the company look as though it were financing itself on its suppliers to the tune of a full quarter of cost of sales. The forecast therefore runs on the cycle excluding it, and the 2026 change in working capital is measured against the same adjusted base.
A38: This is a condensed layout and does not foot to zero: other liabilities, provisions and related-party balances are not shown separately. Every historical line above is the audited closing figure.

Sheet Cash Flow
A1: Cash flow — audited markers and the forecast waterfall
A2: $m. The forecast waterfall is the same one the discounted cash flow runs on, shown here against the reported history.
A4: $m | B4: FY2023 | C4: FY2024 | D4: FY2025 | E4: FY2026E | F4: FY2027E | G4: FY2028E | H4: FY2029E | I4: FY2030E
A5: Net cash from operating activities (reported) | B5: 797.6 | C5: 607.7 | D5: 734.2
A6: Purchase of property, plant and equipment (reported) | B6: 114.6 | C6: 168.3 | D6: 191.3
A7: Income taxes paid (reported) | B7: 67.4 | C7: 56.7 | D7: 205.1
A8: Dividends paid to owners and to minorities (reported) | D8: ='Balance Sheet'!D18*0+250.0+61.3
A9: Cash conversion — operating cash flow over EBITDA | B9: =B5/'Income Statement'!B11 | C9: =C5/'Income Statement'!C11 | D9: =D5/'Income Statement'!D11
A11: THE FORECAST WATERFALL — FRAMING A
A12: Net operating profit after tax | E12: =DCF!B11 | F12: =DCF!C11 | G12: =DCF!D11 | H12: =DCF!E11 | I12: =DCF!F11
A13: Add back depreciation and amortisation | E13: =DCF!B9 | F13: =DCF!C9 | G13: =DCF!D9 | H13: =DCF!E9 | I13: =DCF!F9
A14: Less capital expenditure | E14: =DCF!B13 | F14: =DCF!C13 | G14: =DCF!D13 | H14: =DCF!E13 | I14: =DCF!F13
A15: Less change in net working capital | E15: =DCF!B18 | F15: =DCF!C18 | G15: =DCF!D18 | H15: =DCF!E18 | I15: =DCF!F18
A16: Free cash flow to the firm | E16: =E12+E13-E14-E15 | F16: =F12+F13-F14-F15 | G16: =G12+G13-G14-G15 | H16: =H12+H13-H14-H15 | I16: =I12+I13-I14-I15
A17: Less interest after tax | E17: ='Income Statement'!E14*(1-DCF!$C$106) | F17: ='Income Statement'!F14*(1-DCF!$C$106) | G17: ='Income Statement'!G14*(1-DCF!$C$106) | H17: ='Income Statement'!H14*(1-DCF!$C$106) | I17: ='Income Statement'!I14*(1-DCF!$C$106)
A18: Less dividends to owners | E18: =Assumptions!$C$80*'Income Statement'!E21 | F18: =Assumptions!$C$80*'Income Statement'!F21 | G18: =Assumptions!$C$80*'Income Statement'!G21 | H18: =Assumptions!$C$80*'Income Statement'!H21 | I18: =Assumptions!$C$80*'Income Statement'!I21
A19: Less profit accruing to minorities | E19: ='Income Statement'!E20 | F19: ='Income Statement'!F20 | G19: ='Income Statement'!G20 | H19: ='Income Statement'!H20 | I19: ='Income Statement'!I20
A20: Movement in net debt | E20: =-E16+E17+E18+E19 | F20: =-F16+F17+F18+F19 | G20: =-G16+G17+G18+G19 | H20: =-H16+H17+H18+H19 | I20: =-I16+I17+I18+I19
A21: Closing net debt | E21: ='Balance Sheet'!E22 | F21: ='Balance Sheet'!F22 | G21: ='Balance Sheet'!G22 | H21: ='Balance Sheet'!H22 | I21: ='Balance Sheet'!I22
A23: The reported cash flow and the forecast waterfall are not the same object and are not meant to reconcile line for line: the reported figure is after interest, tax and the working-capital swing the gas accrual causes, while the waterfall is struck before financing so that it can be discounted at a cost of capital that already prices the debt.

Sheet Summary Financials
A1: Summary financials — the eight-year picture
A2: $m unless stated. Every cell on this sheet is a link or a ratio; nothing is typed twice.
A4: $m | B4: FY2023 | C4: FY2024 | D4: FY2025 | E4: FY2026E | F4: FY2027E | G4: FY2028E | H4: FY2029E | I4: FY2030E
A5: Revenue | B5: ='Income Statement'!B5 | C5: ='Income Statement'!C5 | D5: ='Income Statement'!D5 | E5: ='Income Statement'!E5 | F5: ='Income Statement'!F5 | G5: ='Income Statement'!G5 | H5: ='Income Statement'!H5 | I5: ='Income Statement'!I5
A6: Revenue growth | B6: - | C6: =C5/B5-1 | D6: =D5/C5-1 | E6: =E5/D5-1 | F6: =F5/E5-1 | G6: =G5/F5-1 | H6: =H5/G5-1 | I6: =I5/H5-1
A7: EBITDA | B7: ='Income Statement'!B11 | C7: ='Income Statement'!C11 | D7: ='Income Statement'!D11 | E7: ='Income Statement'!E11 | F7: ='Income Statement'!F11 | G7: ='Income Statement'!G11 | H7: ='Income Statement'!H11 | I7: ='Income Statement'!I11
A8: EBITDA margin | B8: =B7/B5 | C8: =C7/C5 | D8: =D7/D5 | E8: =E7/E5 | F8: =F7/F5 | G8: =G7/G5 | H8: =H7/H5 | I8: =I7/I5
A9: EBIT | B9: ='Income Statement'!B12 | C9: ='Income Statement'!C12 | D9: ='Income Statement'!D12 | E9: ='Income Statement'!E12 | F9: ='Income Statement'!F12 | G9: ='Income Statement'!G12 | H9: ='Income Statement'!H12 | I9: ='Income Statement'!I12
A10: Profit attributable to owners | B10: ='Income Statement'!B21 | C10: ='Income Statement'!C21 | D10: ='Income Statement'!D21 | E10: ='Income Statement'!E21 | F10: ='Income Statement'!F21 | G10: ='Income Statement'!G21 | H10: ='Income Statement'!H21 | I10: ='Income Statement'!I21
A11: Free cash flow to the firm | B11: - | C11: - | D11: - | E11: ='Cash Flow'!E16 | F11: ='Cash Flow'!F16 | G11: ='Cash Flow'!G16 | H11: ='Cash Flow'!H16 | I11: ='Cash Flow'!I16
A12: Net debt | B12: ='Balance Sheet'!B22 | C12: ='Balance Sheet'!C22 | D12: ='Balance Sheet'!D22 | E12: ='Balance Sheet'!E22 | F12: ='Balance Sheet'!F22 | G12: ='Balance Sheet'!G22 | H12: ='Balance Sheet'!H22 | I12: ='Balance Sheet'!I22
A13: Invested capital | B13: ='Balance Sheet'!B24 | C13: ='Balance Sheet'!C24 | D13: ='Balance Sheet'!D24 | E13: ='Balance Sheet'!E24 | F13: ='Balance Sheet'!F24 | G13: ='Balance Sheet'!G24 | H13: ='Balance Sheet'!H24 | I13: ='Balance Sheet'!I24
A14: Return on invested capital | B14: - | C14: - | D14: - | E14: =DCF!B11/E13 | F14: =DCF!C11/F13 | G14: =DCF!D11/G13 | H14: =DCF!E11/H13 | I14: =DCF!F11/I13
A15: Net debt / EBITDA | B15: =B12/B7 | C15: =C12/C7 | D15: =D12/D7 | E15: =E12/E7 | F15: =F12/F7 | G15: =G12/G7 | H15: =H12/H7 | I15: =I12/I7
A17: The forecast columns are framing A. Framing B differs only in the price path; its revenue, EBITDA and cash flow are on the DCF sheet beside framing A's, and both reach a value on the SOTP Bridge sheet.

Sheet Monte Carlo
A1: Probabilistic price map
A2: A map of price dispersion around the market price. It carries no view on value and is never blended with the valuation. Each figure is a complete engine re-run, so nothing on this sheet redraws when a driver is changed.
A4: Horizon | B4: 5th | C4: 25th | D4: Median | E4: 75th | F4: 95th | G4: Above the market price
A5: One month — to 2026-09-07 | B5: 2.2367439 | C5: 2.4168955 | D5: 2.5365056 | E5: 2.6626885 | F5: 2.8706685 | G5: 0.49222
A6: Three months — to 2026-11-09 | B6: 2.0137177 | C6: 2.3190403 | D6: 2.5321162 | E6: 2.7639458 | F6: 3.1877242 | G6: 0.4906
A8: Level event | B8: One month | C8: Three months
A9: Finishes 10% or more above the market price | B9: 0.09364 | C9: 0.22516
A10: Finishes 10% or more below the market price | B10: 0.0813 | C10: 0.21646
A11: Touches 10% above the market price at any point | B11: 0.15724 | C11: 0.4185
A12: Touches 10% below the market price at any point | B12: 0.1323 | C12: 0.39122
A13: Touches 20% above the market price at any point | B13: 0.01782 | C13: 0.1556
A14: Touches 20% below the market price at any point | B14: 0.00652 | C14: 0.09616
A16: Setting | B16: Value
A17: Simulated paths | C17: 50000
A18: Annualised volatility at the three-month anchor | C18: 0.28982114
A19: Market price (AED) | C19: =Assumptions!$C$5
A20: Anchor date | C20: 2026-08-07
A22: How the map has behaved out of sample: across 14 non-overlapping three-month windows on this stock, the interval that should contain nine outcomes in ten contained 100% of them and the interval that should contain four in five contained 79%. The average position of the realised price inside the distribution was 0.43, against a half for a perfectly centred map. Against a carry-adjusted random walk the map scored -0.0015, which is inside the confidence interval either way — it is honest about dispersion, not a forecast of direction.

Sheet Sensitivity
A1: Sensitivity — what the valuation needs the world to do
A2: AED per share, framing A. Each cell is a complete re-run of the whole model, including the unit build, so these grids are engine outputs rather than formulas and do NOT redraw when a driver is changed.
A4: Terminal cost of capital (rows) against terminal growth (columns)
B5: 0.0% | C5: 0.2% | D5: 0.5% | E5: 0.8% | F5: 1.0%
A6: 10.11% | B6: 1.9930728 | C6: 1.9834569 | D6: 1.9729096 | E6: 1.9613339 | F6: 1.9486187
A7: 10.61% | B7: 1.8960321 | C7: 1.8848238 | D7: 1.872645 | E7: 1.859401 | F7: 1.8449843
A8: 11.11% | B8: 1.809469 | C8: 1.7971382 | D8: 1.78383 | E8: 1.7694549 | F8: 1.7539118
A9: 11.61% | B9: 1.7317499 | C9: 1.7186467 | D9: 1.7045796 | E9: 1.6894654 | F9: 1.6732106
A10: 12.11% | B10: 1.6615644 | C10: 1.6479519 | D10: 1.6334016 | E10: 1.6178367 | F10: 1.6011719
A12: Single-driver sensitivities — five complete re-runs per row
A13: Driver (the grid it is run over) | G13: Swing
A14: Cost pass-through (0.300 / 0.400 / 0.481 / 0.550 / 0.650) | B14: 3.0668143 | C14: 2.3716972 | D14: 1.809469 | E14: 1.3290216 | F14: 0.63390455 | G14: =MAX(B14:F14)-MIN(B14:F14)
A15: Nitrogen price path, multiplicative (-20% / -10% / +0% / +10% / +20%) | B15: 1.0730619 | C15: 1.4412655 | D15: 1.809469 | E15: 2.1776726 | F15: 2.5458761 | G15: =MAX(B15:F15)-MIN(B15:F15)
A16: Beta (0.465 / 0.400 / 0.931 / 0.600 / 1.398) | B16: 2.7747986 | C16: 2.9984669 | D16: 1.809469 | E16: 2.4052426 | F16: 1.3356925 | G16: =MAX(B16:F16)-MIN(B16:F16)
A17: Tax rate (8.0% / 11.0% / 13.1% / 16.0% / 20.0%) | B17: 1.9333567 | C17: 1.8610399 | D17: 1.809469 | E17: 1.7405117 | F17: 1.6440892 | G17: =MAX(B17:F17)-MIN(B17:F17)
A18: Terminal growth, at the base cost of capital (0.0% / 0.2% / 0.5% / 0.8% / 1.0%) | B18: 1.809469 | C18: 1.7971382 | D18: 1.78383 | E18: 1.7694549 | F18: 1.7539118 | G18: =MAX(B18:F18)-MIN(B18:F18)
A20: The pass-through row is the one that matters. Every other driver moves the answer by less than the width of the range the four lenses already span; the pass-through moves it by more than the whole of that range, which is why it is measured on the Segments sheet from the company's own reported periods rather than assumed.

Sheet Per-Share & Ratios
A1: Per-share and ratio analysis
A2: The indicator set for a merchant nitrogen producer. Every ratio is a formula off the statements.
A4: Measure | B4: FY2023 | C4: FY2024 | D4: FY2025 | E4: FY2026E | F4: FY2027E | G4: FY2028E | H4: FY2029E | I4: FY2030E
A5: Earnings per share ($) | B5: ='Income Statement'!B22 | C5: ='Income Statement'!C22 | D5: ='Income Statement'!D22 | E5: ='Income Statement'!E22 | F5: ='Income Statement'!F22 | G5: ='Income Statement'!G22 | H5: ='Income Statement'!H22 | I5: ='Income Statement'!I22
A6: Earnings per share (AED) | B6: ='Income Statement'!B23 | C6: ='Income Statement'!C23 | D6: ='Income Statement'!D23 | E6: ='Income Statement'!E23 | F6: ='Income Statement'!F23 | G6: ='Income Statement'!G23 | H6: ='Income Statement'!H23 | I6: ='Income Statement'!I23
A7: Book value per share ($) | B7: ='Balance Sheet'!B18/Assumptions!$C$7 | C7: ='Balance Sheet'!C18/Assumptions!$C$7 | D7: ='Balance Sheet'!D18/Assumptions!$C$7 | E7: ='Balance Sheet'!E18/Assumptions!$C$7 | F7: ='Balance Sheet'!F18/Assumptions!$C$7 | G7: ='Balance Sheet'!G18/Assumptions!$C$7 | H7: ='Balance Sheet'!H18/Assumptions!$C$7 | I7: ='Balance Sheet'!I18/Assumptions!$C$7
A8: Free cash flow per share ($) | B8: - | C8: - | D8: - | E8: ='Summary Financials'!E11/Assumptions!$C$7 | F8: ='Summary Financials'!F11/Assumptions!$C$7 | G8: ='Summary Financials'!G11/Assumptions!$C$7 | H8: ='Summary Financials'!H11/Assumptions!$C$7 | I8: ='Summary Financials'!I11/Assumptions!$C$7
A9: Dividend per share ($) | B9: - | C9: - | D9: - | E9: =Assumptions!$C$80*'Income Statement'!E21/Assumptions!$C$7 | F9: =Assumptions!$C$80*'Income Statement'!F21/Assumptions!$C$7 | G9: =Assumptions!$C$80*'Income Statement'!G21/Assumptions!$C$7 | H9: =Assumptions!$C$80*'Income Statement'!H21/Assumptions!$C$7 | I9: =Assumptions!$C$80*'Income Statement'!I21/Assumptions!$C$7
A10: Gross margin | B10: ='Income Statement'!B7/'Income Statement'!B5 | C10: ='Income Statement'!C7/'Income Statement'!C5 | D10: ='Income Statement'!D7/'Income Statement'!D5 | E10: - | F10: - | G10: - | H10: - | I10: -
A11: EBITDA margin | B11: ='Income Statement'!B24 | C11: ='Income Statement'!C24 | D11: ='Income Statement'!D24 | E11: ='Income Statement'!E24 | F11: ='Income Statement'!F24 | G11: ='Income Statement'!G24 | H11: ='Income Statement'!H24 | I11: ='Income Statement'!I24
A12: EBIT margin | B12: ='Income Statement'!B12/'Income Statement'!B5 | C12: ='Income Statement'!C12/'Income Statement'!C5 | D12: ='Income Statement'!D12/'Income Statement'!D5 | E12: ='Income Statement'!E12/'Income Statement'!E5 | F12: ='Income Statement'!F12/'Income Statement'!F5 | G12: ='Income Statement'!G12/'Income Statement'!G5 | H12: ='Income Statement'!H12/'Income Statement'!H5 | I12: ='Income Statement'!I12/'Income Statement'!I5
A13: Net margin, attributable | B13: ='Income Statement'!B21/'Income Statement'!B5 | C13: ='Income Statement'!C21/'Income Statement'!C5 | D13: ='Income Statement'!D21/'Income Statement'!D5 | E13: ='Income Statement'!E21/'Income Statement'!E5 | F13: ='Income Statement'!F21/'Income Statement'!F5 | G13: ='Income Statement'!G21/'Income Statement'!G5 | H13: ='Income Statement'!H21/'Income Statement'!H5 | I13: ='Income Statement'!I21/'Income Statement'!I5
A14: Return on equity, on opening equity | B14: - | C14: ='Income Statement'!C21/'Balance Sheet'!B18 | D14: ='Income Statement'!D21/'Balance Sheet'!C18 | E14: ='Income Statement'!E21/'Balance Sheet'!D18 | F14: ='Income Statement'!F21/'Balance Sheet'!E18 | G14: ='Income Statement'!G21/'Balance Sheet'!F18 | H14: ='Income Statement'!H21/'Balance Sheet'!G18 | I14: ='Income Statement'!I21/'Balance Sheet'!H18
A15: Return on invested capital | B15: - | C15: - | D15: - | E15: ='Summary Financials'!E14 | F15: ='Summary Financials'!F14 | G15: ='Summary Financials'!G14 | H15: ='Summary Financials'!H14 | I15: ='Summary Financials'!I14
A16: Net debt / EBITDA | B16: ='Summary Financials'!B15 | C16: ='Summary Financials'!C15 | D16: ='Summary Financials'!D15 | E16: ='Summary Financials'!E15 | F16: ='Summary Financials'!F15 | G16: ='Summary Financials'!G15 | H16: ='Summary Financials'!H15 | I16: ='Summary Financials'!I15
A17: Interest cover (EBIT over the net finance charge) | B17: =-'Income Statement'!B12/'Income Statement'!B16 | C17: =-'Income Statement'!C12/'Income Statement'!C16 | D17: =-'Income Statement'!D12/'Income Statement'!D16 | E17: =-'Income Statement'!E12/'Income Statement'!E16 | F17: =-'Income Statement'!F12/'Income Statement'!F16 | G17: =-'Income Statement'!G12/'Income Statement'!G16 | H17: =-'Income Statement'!H12/'Income Statement'!H16 | I17: =-'Income Statement'!I12/'Income Statement'!I16
A18: Net working capital / revenue | B18: ='Balance Sheet'!B23/'Income Statement'!B5 | C18: ='Balance Sheet'!C23/'Income Statement'!C5 | D18: ='Balance Sheet'!D23/'Income Statement'!D5 | E18: ='Balance Sheet'!E23/'Income Statement'!E5 | F18: ='Balance Sheet'!F23/'Income Statement'!F5 | G18: ='Balance Sheet'!G23/'Income Statement'!G5 | H18: ='Balance Sheet'!H23/'Income Statement'!H5 | I18: ='Balance Sheet'!I23/'Income Statement'!I5
A19: Capital expenditure / revenue | B19: ='Cash Flow'!B6/'Income Statement'!B5 | C19: ='Cash Flow'!C6/'Income Statement'!C5 | D19: ='Cash Flow'!D6/'Income Statement'!D5 | E19: =DCF!B13/'Income Statement'!E5 | F19: =DCF!C13/'Income Statement'!F5 | G19: =DCF!D13/'Income Statement'!G5 | H19: =DCF!E13/'Income Statement'!H5 | I19: =DCF!F13/'Income Statement'!I5
A20: Cash cost per tonne of own product ($/t) | B20: - | C20: =Segments!B16 | D20: =Segments!C16 | E20: =Segments!B48 | F20: =Segments!C48 | G20: =Segments!D48 | H20: =Segments!E48 | I20: =Segments!F48
A21: Realised price per tonne of own product ($/t) | B21: - | C21: =Segments!B12 | D21: =Segments!C12 | E21: =Segments!B46 | F21: =Segments!C46 | G21: =Segments!D46 | H21: =Segments!E46 | I21: =Segments!F46
A23: The forecast columns are framing A. Return on equity is struck on opening equity rather than an average because the forecast equity balance is itself a roll-forward, and averaging a roll against itself flatters the early years.

Sheet Peer & Sector
A1: Peer frame and sector context
A2: A sanity check on the multiple, not an independent valuation. No listed nitrogen producer carries the same gas position.
A4: Company | B4: Market | C4: Enterprise value / EBITDA | D4: Why it is and is not comparable
A5: Nutrien | B5: US | C5: 7.4 | D5: diversified nutrient, retail attached
A6: CF Industries | B6: US | C6: 6.1 | D6: pure nitrogen, Henry Hub advantaged
A7: Yara International | B7: NO | C7: 5.2 | D7: nitrogen, European gas cost
A8: OCI Global | B8: NL | C8: 5.6 | D8: nitrogen and methanol
A9: Industries Qatar | B9: QA | C9: 9.1 | D9: Gulf petrochemical and fertiliser
A10: SABIC Agri-Nutrients | B10: SA | C10: 10.4 | D10: Gulf nitrogen, Tadawul rating
A11: Peer median | C11: =MEDIAN(C5:C10)
A12: Peer average | C12: =AVERAGE(C5:C10)
A13: Applied in the relative lens | C13: ='Relative & Normalized'!C6
A15: The company on its own multiples | B15: Value
A16: Trailing enterprise value / EBITDA | C16: ='Relative & Normalized'!C14
A17: Trailing price / earnings | C17: ='Relative & Normalized'!C15
A18: Trailing price / book | C18: =Assumptions!$C$5/Assumptions!$C$6/'Relative & Normalized'!C29
A19: Terminal value implied enterprise value / EBITDA, framing A | C19: =DCF!C64
A20: Terminal value implied enterprise value / EBITDA, framing B | C20: =DCF!D64
A22: The two Gulf names trade where they do because of who owns them and where they list, not because their nitrogen assets are worth more per tonne; the two American names sit on a gas position that is structurally cheaper than anything in this group. The applied multiple sits below the peer median for that reason.
