Workbook

Sheet READ FIRST
A1: Testahil — ACWA Power Company (Tadawul: 2082)
A2: Companion model · Independent Valuation Study · Educational analysis · Not investment advice
A4: What this workbook is. A transparent companion to the ACWA Power valuation study. Every blue cell is an input;
A5: every black cell is a formula; green cells link across sheets. All inputs live on the Assumptions sheet — change
A6: one (the holdco discount analogue, an operating-portfolio mark, WACC, terminal growth) and the whole model reprices.
A8: What it is not. It is not investment advice, a recommendation, or a price target. Values are model outputs shown
A9: as ranges. The preparer is not licensed by any securities regulator and may hold a position in the security.
A11: Structure note. ACWA Power is a Develop–Invest–Operate–Optimize infrastructure platform: it takes equity stakes in
A12: power & water project companies on 20–30-year offtake contracts, and earns development, construction-management and
A13: O&M (NOMAC) fees. Much of its economic cash arrives via equity-accounted associates and development fees, so
A14: consolidated revenue understates scale and a pure consolidated FCFF understates value. The primary lens is therefore
A15: a sum-of-the-parts / NAV of the portfolio; the DCF is a normalized attributable-cash cross-check (see DCF sheet note).
... A22: Income Statement · Balance Sheet · Cash Flow · Summary Financials · Monte Carlo · Sensitivity · Per-Share & Ratios · Peer & Sector.

Sheet Summary
A1: Valuation summary — ACWA Power (Tadawul: 2082)
A2: Four-lens fair value vs spot. Base links live; bear/bull are scenario outputs (see study §1.5).
B3: Bear | C3: Base | D3: Bull | E3: Weight
A4: Sum-of-the-parts / NAV | B4: 140 | C4: =SOTP!C12 -> 215.26419 | D4: 320 | E4: =Assumptions!$B$34 -> 0.4
A5: Consolidated DCF | B5: 120 | C5: =DCF!B19 -> 184.21618 | D5: 285 | E5: =Assumptions!$B$35 -> 0.25
A6: Relative multiples | B6: 115 | C6: ='Relative & Normalized'!C7 -> 158.05501 | D6: 235 | E6: =Assumptions!$B$36 -> 0.15
A7: Pipeline-maturation earnings | B7: 130 | C7: ='Relative & Normalized'!C9 -> 197.11073 | D7: 320 | E7: =Assumptions!$B$37 -> 0.2
A8: Weighted central | B8: =SUMPRODUCT(B4:B7,$E$4:$E$7) -> 129.25 | C8: =SUMPRODUCT(C4:C7,$E$4:$E$7) -> 195.29012 | D8: =SUMPRODUCT(D4:D7,$E$4:$E$7) -> 298.5
A10: Spot price (SAR) | C10: =Assumptions!$B$4 -> 193.9
A11: Upside to central base | C11: =C8/C10-1 -> 0.0071692507
A12: Read: fairly valued; the swing is whether Vision-2030 growth capital earns above its cost, and the multiple on the development platform.

Sheet Fundamental Valuation
A1: Fundamental valuation — football field data
A2: Bear/base/bull per lens (links to Summary).
A3: Lens | B3: Bear | C3: Base | D3: Bull
A4: =Summary!A4 -> Sum-of-the-parts / NAV | B4: =Summary!B4 -> 140 | C4: =Summary!C4 -> 215.26419 | D4: =Summary!D4 -> 320
A5: =Summary!A5 -> Consolidated DCF | B5: =Summary!B5 -> 120 | C5: =Summary!C5 -> 184.21618 | D5: =Summary!D5 -> 285
A6: =Summary!A6 -> Relative multiples | B6: =Summary!B6 -> 115 | C6: =Summary!C6 -> 158.05501 | D6: =Summary!D6 -> 235
A7: =Summary!A7 -> Pipeline-maturation earnings | B7: =Summary!B7 -> 130 | C7: =Summary!C7 -> 197.11073 | D7: =Summary!D7 -> 320
A8: Weighted central | B8: =Summary!B8 -> 129.25 | C8: =Summary!C8 -> 195.29012 | D8: =Summary!D8 -> 298.5
A9: Spot | C9: =Assumptions!$B$4 -> 193.9

Sheet Assumptions
A1: Assumptions — the single input layer
A2: All blue cells are inputs. Every other sheet links here.
A3: ANCHORS
A4: Spot price (SAR/share) | B4: 193.9
A5: Shares outstanding (m) | B5: 766.5
A6: SAR/USD (peg) | B6: 3.75
A7: Holdco / corporate net debt (SAR m) | B7: 25000
A8: WACC | B8: 0.0875
A9: Risk-free rate (rf) | B9: 0.0475
A10: Equity risk premium (ERP) | B10: 0.06
A11: Beta | B11: 0.85
A12: Cost of equity Ke = rf + beta*ERP | B12: =B9+B11*B10 -> 0.0985
A13: Terminal growth | B13: 0.035
A14: Zakat & effective tax rate | B14: 0.1
A16: SOTP — base marks (SAR bn, attributable equity)
A17: Operating power & water portfolio | B17: 115
A18: Under-construction portfolio (equity + uplift) | B18: 42
A19: Advanced development pipeline (risk-weighted) | B19: 10
A20: NOMAC + development / services platform | B20: 23
A21: Holdco discount on gross NAV (structure/liquidity) | B21: 0
A23: RELATIVE & NORMALIZED
A24: FY2026E EPS for P/E lens (SAR) | B24: 2.7
A25: Justified P/E (growth infra) | B25: 55
A26: Book value per share (SAR) | B26: 37
A27: Justified P/B | B27: 4.5
A28: Normalized EBITDA for EV/EBITDA (SAR m) | B28: 4900
A29: EV/EBITDA target multiple | B29: 30
A30: 2030 run-rate net profit (SAR m) | B30: 5500
A31: Pipeline-maturation justified P/E | B31: 40
A33: SYNTHESIS WEIGHTS
A34: SOTP / NAV weight | B34: 0.4
A35: DCF weight | B35: 0.25
A36: Relative weight | B36: 0.15
A37: Pipeline-maturation weight | B37: 0.2
A39: WORKING CAPITAL (% of revenue)
A40: Receivables | B40: 0.28
A41: Payables | B41: 0.22
A43: MONTE CARLO
A44: Diffusion volatility (annualized, YZ-HAR) | B44: 0.4116
A45: Net 3-month drift (near zero, international) | B45: 0.019
...

Sheet SOTP
A1: Sum-of-the-parts / NAV (primary lens)
A2: Attributable equity value by leg (non-recourse project debt already netted within each leg). Links to Assumptions. SAR bn except per-share.
A3: Part | B3: Basis | C3: Value (SAR bn)
A4: Operating power & water portfolio | B4: Capitalized attributable distributions / EV-per-MW | C4: =Assumptions!$B$17 -> 115
A5: Under-construction portfolio | B5: Invested equity + development uplift (to COD) | C5: =Assumptions!$B$18 -> 42
A6: Advanced development pipeline | B6: Risk-weighted optionality | C6: =Assumptions!$B$19 -> 10
A7: NOMAC + development / services | B7: Fee-stream DCF (super-senior, stable) | C7: =Assumptions!$B$20 -> 23
A8: Σ Gross asset value (attributable equity) | C8: =SUM(C4:C7) -> 190
A9: less: holdco / corporate net debt | C9: =-Assumptions!$B$7/1000 -> -25
A10: less: holdco structure/liquidity discount | C10: =-C8*Assumptions!$B$21 -> 0
A11: SOTP equity value (SAR bn) | C11: =C8+C9+C10 -> 165
A12: SOTP fair value per share (SAR) | C12: =C11*1000/Assumptions!$B$5 -> 215.26419
A13: Implied gross NAV per share (pre-net-debt) | C13: =C8*1000/Assumptions!$B$5 -> 247.87997

Sheet Segments
A1: Segment / capacity view
A2: Portfolio capacity and operating mix (company disclosure, year-end 2025 / latest).
A3: Metric | B3: FY2023 | C3: FY2024 | D3: FY2025 | E3: Latest
A4: Gross power capacity (GW) | C4: 69.2 | D4: 93 | E4: 98
A5: of which renewable (GW) | D5: 52.3
A6: Renewable share | C6: 0.504 | D6: 0.562
A7: Desalination capacity (m³/day, m) | C7: 8.1 | D7: 9.2 | E7: 9.7
A8: BESS (GWh) | C8: 5.3 | D8: 5.6
A9: Operating power (GW) | D9: 43
A10: Projects (count) | C10: 94 | D10: 108 | E10: 111
A11: Investment value / AUM (SAR bn) | C11: 364 | D11: 437 | E11: 466
A12: Countries | D12: 15 | E12: 16
A14: Source: ACWA Power FY2024/FY2025 results and investor overview (mid-2026). USD 97bn (2024) / 117bn (2025) / 125bn (latest) at SAR/USD 3.75.

Sheet Relative & Normalized
A1: Relative & pipeline-maturation lenses
A2: Links to Assumptions. SAR/share.
A3: Lens | B3: Workings | C3: SAR/share
A4: P/E on FY2026E EPS | B4: EPS × justified P/E | C4: =Assumptions!$B$24*Assumptions!$B$25 -> 148.5
A5: P/B on book value | B5: BVPS × justified P/B | C5: =Assumptions!$B$26*Assumptions!$B$27 -> 166.5
A6: EV/EBITDA | B6: EBITDA × mult − holdco net debt, /sh | C6: =(Assumptions!$B$28*Assumptions!$B$29-Assumptions!$B$7)/Assumptions!$B$5 -> 159.16504
A7: Relative lens (blend of the three) | C7: =AVERAGE(C4:C6) -> 158.05501
A9: Pipeline-maturation earnings power | B9: 2030 run-rate NP × P/E, discounted to today at Ke | C9: =(Assumptions!$B$30*Assumptions!$B$31/Assumptions!$B$5)/(1+(Assumptions!$B$9+Assumptions!$B$11*Assumptions!$B$10))^4 -> 197.11073
A10: 2030 implied value/share (undiscounted) | C10: =Assumptions!$B$30*Assumptions!$B$31/Assumptions!$B$5 -> 287.01892

Sheet DCF
A1: Discounted cash flow — normalized attributable FCFF, explicit 5-year
A2: NOPAT + D&A − capex − ΔWC on a NORMALIZED ATTRIBUTABLE EBIT (captures equity-accounted associate cash the consolidated P&L omits). Cross-check to the SOTP. WACC and Ke link to Assumptions.
B3: FY2026E | C3: FY2027E | D3: FY2028E | E3: FY2029E | F3: FY2030E
A4: Normalized attributable EBIT | B4: =Assumptions!E55 -> 7000 | C4: =Assumptions!F55 -> 8200 | D4: =Assumptions!G55 -> 9500 | E4: =Assumptions!H55 -> 10900 | F4: =Assumptions!I55 -> 12600
A5: NOPAT = EBIT × (1 − tax) | B5: =B4*(1-Assumptions!$B$14) -> 6300 | C5: =C4*(1-Assumptions!$B$14) -> 7380 | D5: =D4*(1-Assumptions!$B$14) -> 8550 | E5: =E4*(1-Assumptions!$B$14) -> 9810 | F5: =F4*(1-Assumptions!$B$14) -> 11340
A6: + D&A | B6: =Assumptions!E56 -> 1300 | C6: =Assumptions!F56 -> 1450 | D6: =Assumptions!G56 -> 1600 | E6: =Assumptions!H56 -> 1750 | F6: =Assumptions!I56 -> 1900
A7: − Capex (attributable growth) | B7: =-Assumptions!E57 -> -2000 | C7: =-Assumptions!F57 -> -2100 | D7: =-Assumptions!G57 -> -2200 | E7: =-Assumptions!H57 -> -2300 | F7: =-Assumptions!I57 -> -2400
A8: − Increase in net working capital | B8: =-Assumptions!E58 -> -300 | C8: =-Assumptions!F58 -> -300 | D8: =-Assumptions!G58 -> -300 | E8: =-Assumptions!H58 -> -300 | F8: =-Assumptions!I58 -> -300
A9: Free cash flow to firm (FCFF) | B9: =B5+B6+B7+B8 -> 5300 | C9: =C5+C6+C7+C8 -> 6430 | D9: =D5+D6+D7+D8 -> 7650 | E9: =E5+E6+E7+E8 -> 8960 | F9: =F5+F6+F7+F8 -> 10540
A10: Discount factor | B10: =1/(1+Assumptions!$B$8)^1 -> 0.91954023 | C10: =1/(1+Assumptions!$B$8)^2 -> 0.84555423 | D10: =1/(1+Assumptions!$B$8)^3 -> 0.77752114 | E10: =1/(1+Assumptions!$B$8)^4 -> 0.71496196 | F10: =1/(1+Assumptions!$B$8)^5 -> 0.65743629
A11: PV of FCFF | B11: =B9*B10 -> 4873.5632 | C11: =C9*C10 -> 5436.9137 | D11: =D9*D10 -> 5948.0367 | E11: =E9*E10 -> 6406.0592 | F11: =F9*F10 -> 6929.3785
A13: Σ PV of explicit FCFF (FY2026–30) | B13: =SUM(B11:F11) -> 29593.951
A14: Terminal value (Gordon) | B14: =F9*(1+Assumptions!$B$13)/(Assumptions!$B$8-Assumptions!$B$13) -> 207788.57
A15: PV of terminal value | B15: =B14/(1+Assumptions!$B$8)^5 -> 136607.75
A16: Enterprise value | B16: =B13+B15 -> 166201.7
A17: less: holdco / corporate net debt | B17: =-Assumptions!$B$7 -> -25000
A18: Equity value | B18: =B16+B17 -> 141201.7
A19: Fair value per share (SAR) | B19: =B18/Assumptions!$B$5 -> 184.21618
A20: Terminal value as % of EV | B20: =B15/B16 -> 0.82193954
A21: Cost of equity Ke (rf + β·ERP), memo | B21: =Assumptions!$B$9+Assumptions!$B$11*Assumptions!$B$10 -> 0.0985
A23: Note: normalized attributable EBIT sits above consolidated EBIT because it includes ACWA's share of equity-accounted project cash and development fees that do not flow through consolidated revenue. The DCF is a cross-check; the SOTP is the primary lens. Terminal-heavy by nature (long-life 20–30-yr contracted assets) — see TV % of EV and the WACC × g grid on Sensitivity.

Sheet Income Statement
A1: Income statement (SAR m, consolidated)
A2: FY2023–FY2025 disclosed (blue); FY2026E–FY2030E forecast (formulas linking to Assumptions). EBIT ≈ operating income before impairment, incl. equity-accounted associate & development-fee income.
B3: FY2023 | C3: FY2024 | D3: FY2025 | E3: FY2026E | F3: FY2027E | G3: FY2028E | H3: FY2029E | I3: FY2030E
A4: Consolidated revenue | B4: 6080 | C4: 6280 | D4: 7410 | E4: =D4*(1+Assumptions!E50) -> 8521.5 | F4: =E4*(1+Assumptions!F50) -> 10055.37 | G4: =F4*(1+Assumptions!G50) -> 11664.229 | H4: =G4*(1+Assumptions!H50) -> 13297.221 | I4: =H4*(1+Assumptions!I50) -> 14892.888
A5: EBIT (operating income before impairment) | B5: 2984 | C5: 2983 | D5: 3600 | E5: =E4*Assumptions!E51 -> 4260.75 | F5: =F4*Assumptions!F51 -> 5128.2387 | G5: =G4*Assumptions!G51 -> 6007.078 | H5: =H4*Assumptions!H51 -> 6914.5551 | I5: =I4*Assumptions!I51 -> 7818.7661
A6: D&A (memo; estimated pre-2026) | B6: 1050 | C6: 1150 | D6: 1300 | E6: =E4*Assumptions!E52 -> 1278.225 | F6: =F4*Assumptions!F52 -> 1508.3055 | G6: =G4*Assumptions!G52 -> 1749.6344 | H6: =H4*Assumptions!H52 -> 1994.5832 | I6: =I4*Assumptions!I52 -> 2233.9332
A7: EBITDA (= EBIT + D&A) | B7: =B5+B6 -> 4034 | C7: =C5+C6 -> 4133 | D7: =D5+D6 -> 4900 | E7: =E5+E6 -> 5538.975 | F7: =F5+F6 -> 6636.5442 | G7: =G5+G6 -> 7756.7124 | H7: =H5+H6 -> 8909.1383 | I7: =I5+I6 -> 10052.699
A8: Net finance cost | B8: 1050 | C8: 1000 | D8: 1400 | E8: =Assumptions!E53 -> 1600 | F8: =Assumptions!F53 -> 1750 | G8: =Assumptions!G53 -> 1850 | H8: =Assumptions!H53 -> 1950 | I8: =Assumptions!I53 -> 2050
A9: PBT (= EBIT − finance cost) | B9: =B5-B8 -> 1934 | C9: =C5-C8 -> 1983 | D9: =D5-D8 -> 2200 | E9: =E5-E8 -> 2660.75 | F9: =F5-F8 -> 3378.2387 | G9: =G5-G8 -> 4157.078 | H9: =H5-H8 -> 4964.5551 | I9: =I5-I8 -> 5768.7661
A10: Zakat & tax | B10: 130 | C10: 100 | D10: 231 | E10: =MAX(0,E9)*Assumptions!$B$14 -> 266.075 | F10: =MAX(0,F9)*Assumptions!$B$14 -> 337.82387 | G10: =MAX(0,G9)*Assumptions!$B$14 -> 415.7078 | H10: =MAX(0,H9)*Assumptions!$B$14 -> 496.45551 | I10: =MAX(0,I9)*Assumptions!$B$14 -> 576.87661
A11: Minority interest | B11: 142 | C11: 126 | D11: 117 | E11: =Assumptions!E54 -> 130 | F11: =Assumptions!F54 -> 150 | G11: =Assumptions!G54 -> 170 | H11: =Assumptions!H54 -> 190 | I11: =Assumptions!I54 -> 210
A12: Net profit (attributable to parent) | B12: =B9-B10-B11 -> 1662 | C12: =C9-C10-C11 -> 1757 | D12: =D9-D10-D11 -> 1852 | E12: =E9-E10-E11 -> 2264.675 | F12: =F9-F10-F11 -> 2890.4148 | G12: =G9-G10-G11 -> 3571.3702 | H12: =H9-H10-H11 -> 4278.0996 | I12: =I9-I10-I11 -> 4981.8895
A13: EBIT margin | B13: =B5/B4 -> 0.49078947 | C13: =C5/C4 -> 0.475 | D13: =D5/D4 -> 0.48582996 | E13: =E5/E4 -> 0.5 | F13: =F5/F4 -> 0.51 | G13: =G5/G4 -> 0.515 | H13: =H5/H4 -> 0.52 | I13: =I5/I4 -> 0.525
A15: Source: ACWA Power FY2023–FY2025 results (KPMG-audited); revenue, operating income and net profit disclosed. D&A, finance cost, minority estimated to tie. Forecast = formulas.

Sheet Balance Sheet
A1: Balance sheet (SAR m, consolidated)
A2: Historical anchored to disclosed equity/borrowings/cash; other lines estimated to balance. Consolidated (incl. majority-owned SPVs & non-recourse project debt). Forecast rolls forward.
B3: FY2023 | C3: FY2024 | D3: FY2025 | E3: FY2026E | F3: FY2027E | G3: FY2028E | H3: FY2029E | I3: FY2030E
A4: PP&E + project assets + intangibles | B4: 78000 | C4: 86000 | D4: 95000 | E4: =D4+Assumptions!E57*4-'Income Statement'!E6 -> 101721.77 | F4: =E4+Assumptions!F57*4-'Income Statement'!F6 -> 108613.47 | G4: =F4+Assumptions!G57*4-'Income Statement'!G6 -> 115663.84 | H4: =G4+Assumptions!H57*4-'Income Statement'!H6 -> 122869.25 | I4: =H4+Assumptions!I57*4-'Income Statement'!I6 -> 130235.32
A5: Equity-accounted investments | B5: 9000 | C5: 10500 | D5: 12500 | E5: =D5*1.08 -> 13500 | F5: =E5*1.08 -> 14580 | G5: =F5*1.08 -> 15746.4 | H5: =G5*1.08 -> 17006.112 | I5: =H5*1.08 -> 18366.601
A6: Receivables & contract assets | B6: ='Income Statement'!B4*Assumptions!$B$40 -> 1702.4 | C6: ='Income Statement'!C4*Assumptions!$B$40 -> 1758.4 | D6: ='Income Statement'!D4*Assumptions!$B$40 -> 2074.8 | E6: ='Income Statement'!E4*Assumptions!$B$40 -> 2386.02 | F6: ='Income Statement'!F4*Assumptions!$B$40 -> 2815.5036 | G6: ='Income Statement'!G4*Assumptions!$B$40 -> 3265.9842 | H6: ='Income Statement'!H4*Assumptions!$B$40 -> 3723.222 | I6: ='Income Statement'!I4*Assumptions!$B$40 -> 4170.0086
A7: Cash & equivalents | B7: 5000 | C7: 5600 | D7: 7830 | E7: =D7+'Cash Flow'!E12 -> 10402.9 | F7: =E7+'Cash Flow'!F12 -> 13811.62 | G7: =F7+'Cash Flow'!G12 -> 17722.625 | H7: =G7+'Cash Flow'!H12 -> 22165.308 | I7: =H7+'Cash Flow'!I12 -> 27131.13
A8: Other assets | B8: 12000 | C8: 13000 | D8: 14000 | E8: =D8 -> 14000 | F8: =E8 -> 14000 | G8: =F8 -> 14000 | H8: =G8 -> 14000 | I8: =H8 -> 14000
A9: Total assets | B9: =SUM(B4:B8) -> 105702.4 | C9: =SUM(C4:C8) -> 116858.4 | D9: =SUM(D4:D8) -> 131404.8 | E9: =SUM(E4:E8) -> 142010.7 | F9: =SUM(F4:F8) -> 153820.59 | G9: =SUM(G4:G8) -> 166398.84 | H9: =SUM(H4:H8) -> 179763.89 | I9: =SUM(I4:I8) -> 193903.06
A11: Equity attributable to parent | B11: 22000 | C11: 24000 | D11: 28000 | E11: =D11+'Income Statement'!E12-Assumptions!E59 -> 30264.675 | F11: =E11+'Income Statement'!F12-Assumptions!F59 -> 33155.09 | G11: =F11+'Income Statement'!G12-Assumptions!G59 -> 36326.46 | H11: =G11+'Income Statement'!H12-Assumptions!H59 -> 39804.56 | I11: =H11+'Income Statement'!I12-Assumptions!I59 -> 43586.449
A12: Non-controlling interests | B12: 13000 | C12: 14500 | D12: 16500 | E12: =D12+'Income Statement'!E11 -> 16630 | F12: =E12+'Income Statement'!F11 -> 16780 | G12: =F12+'Income Statement'!G11 -> 16950 | H12: =G12+'Income Statement'!H11 -> 17140 | I12: =H12+'Income Statement'!I11 -> 17350
A13: Borrowings (corporate + non-recourse) | B13: 28800 | C13: 32500 | D13: 37200 | E13: =D13+Assumptions!E57*3 -> 43200 | F13: =E13+Assumptions!F57*3 -> 49500 | G13: =F13+Assumptions!G57*3 -> 56100 | H13: =G13+Assumptions!H57*3 -> 63000 | I13: =H13+Assumptions!I57*3 -> 70200
A14: Payables, provisions & other liabilities (bal.) | B14: =B9-B11-B12-B13 -> 41902.4 | C14: =C9-C11-C12-C13 -> 45858.4 | D14: =D9-D11-D12-D13 -> 49704.8 | E14: =E9-E11-E12-E13 -> 51916.02 | F14: =F9-F11-F12-F13 -> 54385.504 | G14: =G9-G11-G12-G13 -> 57022.384 | H14: =H9-H11-H12-H13 -> 59819.334 | I14: =I9-I11-I12-I13 -> 62766.61
A15: Total equity & liabilities | B15: =B11+B12+B13+B14 -> 105702.4 | C15: =C11+C12+C13+C14 -> 116858.4 | D15: =D11+D12+D13+D14 -> 131404.8 | E15: =E11+E12+E13+E14 -> 142010.7 | F15: =F11+F12+F13+F14 -> 153820.59 | G15: =G11+G12+G13+G14 -> 166398.84 | H15: =H11+H12+H13+H14 -> 179763.89 | I15: =I11+I12+I13+I14 -> 193903.06
A17: Balance check (assets − E&L) | B17: =B9-B15 -> 0 | C17: =C9-C15 -> 0 | D17: =D9-D15 -> 0 | E17: =E9-E15 -> 0 | F17: =F9-F15 -> 0 | G17: =G9-G15 -> 0 | H17: =H9-H15 -> 0 | I17: =I9-I15 -> 0
A18: Holdco / corporate net debt (memo) | B18: =Assumptions!$B$7 -> 25000
A20: Non-recourse project debt sits inside each project's equity value; only holdco/corporate net debt is deducted in the SOTP. Balance-sheet plug lines flagged; not all consolidated detail is disclosed.

Sheet Cash Flow
A1: Cash flow (SAR m, forecast)
A2: Derived from the Income Statement and Balance Sheet. Closing cash ties to the Balance Sheet.
B3: FY2023 | C3: FY2024 | D3: FY2025 | E3: FY2026E | F3: FY2027E | G3: FY2028E | H3: FY2029E | I3: FY2030E
A4: Net profit (attributable) | E4: ='Income Statement'!E12 -> 2264.675 | F4: ='Income Statement'!F12 -> 2890.4148 | G4: ='Income Statement'!G12 -> 3571.3702 | H4: ='Income Statement'!H12 -> 4278.0996 | I4: ='Income Statement'!I12 -> 4981.8895
A5: + Minority interest | E5: ='Income Statement'!E11 -> 130 | F5: ='Income Statement'!F11 -> 150 | G5: ='Income Statement'!G11 -> 170 | H5: ='Income Statement'!H11 -> 190 | I5: ='Income Statement'!I11 -> 210
A6: + D&A | E6: ='Income Statement'!E6 -> 1278.225 | F6: ='Income Statement'!F6 -> 1508.3055 | G6: ='Income Statement'!G6 -> 1749.6344 | H6: ='Income Statement'!H6 -> 1994.5832 | I6: ='Income Statement'!I6 -> 2233.9332
A7: − Increase in net working capital | E7: =-Assumptions!E58 -> -300 | F7: =-Assumptions!F58 -> -300 | G7: =-Assumptions!G58 -> -300 | H7: =-Assumptions!H58 -> -300 | I7: =-Assumptions!I58 -> -300
A8: Operating cash flow | E8: =E4+E5+E6+E7 -> 3372.9 | F8: =F4+F5+F6+F7 -> 4248.7203 | G8: =G4+G5+G6+G7 -> 5191.0046 | H8: =H4+H5+H6+H7 -> 6162.6828 | I8: =I4+I5+I6+I7 -> 7125.8227
A9: − Growth capex (attributable) | E9: =-Assumptions!E57 -> -2000 | F9: =-Assumptions!F57 -> -2100 | G9: =-Assumptions!G57 -> -2200 | H9: =-Assumptions!H57 -> -2300 | I9: =-Assumptions!I57 -> -2400
A10: − Dividend | E10: =-Assumptions!E59 -> 0 | F10: =-Assumptions!F59 -> 0 | G10: =-Assumptions!G59 -> -400 | H10: =-Assumptions!H59 -> -800 | I10: =-Assumptions!I59 -> -1200
A11: + Net new borrowing (est.) | E11: =Assumptions!E57*0.6 -> 1200 | F11: =Assumptions!F57*0.6 -> 1260 | G11: =Assumptions!G57*0.6 -> 1320 | H11: =Assumptions!H57*0.6 -> 1380 | I11: =Assumptions!I57*0.6 -> 1440
A12: Net change in cash | E12: =E8+E9+E10+E11 -> 2572.9 | F12: =F8+F9+F10+F11 -> 3408.7203 | G12: =G8+G9+G10+G11 -> 3911.0046 | H12: =H8+H9+H10+H11 -> 4442.6828 | I12: =I8+I9+I10+I11 -> 4965.8227
A13: Closing cash (ties to Balance Sheet) | E13: ='Balance Sheet'!E7 -> 10402.9 | F13: ='Balance Sheet'!F7 -> 13811.62 | G13: ='Balance Sheet'!G7 -> 17722.625 | H13: ='Balance Sheet'!H7 -> 22165.308 | I13: ='Balance Sheet'!I7 -> 27131.13

Sheet Summary Financials
A1: Summary financials (SAR m)
A2: Every cell links to the statement sheets.
B3: FY2023 | C3: FY2024 | D3: FY2025 | E3: FY2026E | F3: FY2027E | G3: FY2028E | H3: FY2029E | I3: FY2030E
A4: Revenue | B4: ='Income Statement'!B4 -> 6080 | C4: ='Income Statement'!C4 -> 6280 | D4: ='Income Statement'!D4 -> 7410 | E4: ='Income Statement'!E4 -> 8521.5 | F4: ='Income Statement'!F4 -> 10055.37 | G4: ='Income Statement'!G4 -> 11664.229 | H4: ='Income Statement'!H4 -> 13297.221 | I4: ='Income Statement'!I4 -> 14892.888
A5: EBITDA | B5: ='Income Statement'!B7 -> 4034 | C5: ='Income Statement'!C7 -> 4133 | D5: ='Income Statement'!D7 -> 4900 | E5: ='Income Statement'!E7 -> 5538.975 | F5: ='Income Statement'!F7 -> 6636.5442 | G5: ='Income Statement'!G7 -> 7756.7124 | H5: ='Income Statement'!H7 -> 8909.1383 | I5: ='Income Statement'!I7 -> 10052.699
A6: EBIT | B6: ='Income Statement'!B5 -> 2984 | C6: ='Income Statement'!C5 -> 2983 | D6: ='Income Statement'!D5 -> 3600 | E6: ='Income Statement'!E5 -> 4260.75 | F6: ='Income Statement'!F5 -> 5128.2387 | G6: ='Income Statement'!G5 -> 6007.078 | H6: ='Income Statement'!H5 -> 6914.5551 | I6: ='Income Statement'!I5 -> 7818.7661
A7: Net profit (attrib.) | B7: ='Income Statement'!B12 -> 1662 | C7: ='Income Statement'!C12 -> 1757 | D7: ='Income Statement'!D12 -> 1852 | E7: ='Income Statement'!E12 -> 2264.675 | F7: ='Income Statement'!F12 -> 2890.4148 | G7: ='Income Statement'!G12 -> 3571.3702 | H7: ='Income Statement'!H12 -> 4278.0996 | I7: ='Income Statement'!I12 -> 4981.8895
A8: Total assets | B8: ='Balance Sheet'!B9 -> 105702.4 | C8: ='Balance Sheet'!C9 -> 116858.4 | D8: ='Balance Sheet'!D9 -> 131404.8 | E8: ='Balance Sheet'!E9 -> 142010.7 | F8: ='Balance Sheet'!F9 -> 153820.59 | G8: ='Balance Sheet'!G9 -> 166398.84 | H8: ='Balance Sheet'!H9 -> 179763.89 | I8: ='Balance Sheet'!I9 -> 193903.06
A9: Equity (attrib.) | B9: ='Balance Sheet'!B11 -> 22000 | C9: ='Balance Sheet'!C11 -> 24000 | D9: ='Balance Sheet'!D11 -> 28000 | E9: ='Balance Sheet'!E11 -> 30264.675 | F9: ='Balance Sheet'!F11 -> 33155.09 | G9: ='Balance Sheet'!G11 -> 36326.46 | H9: ='Balance Sheet'!H11 -> 39804.56 | I9: ='Balance Sheet'!I11 -> 43586.449
A10: Holdco net debt (memo) | D10: =Assumptions!$B$7 -> 25000

Sheet Monte Carlo
A1: Monte Carlo — engine outputs (mc_v2, YZ-HAR)
A2: 50,000 paths · 16 factors · seed 42 · Student-t(5) · zero secular drift (international). Values computed by the engine, not a sheet simulation.
A3: Percentile map (SAR/share)
A4: Horizon | B4: p5 | C4: p25 | D4: p50 | E4: p75 | F4: p95
A5: T+20 sessions | B5: 158.5 | C5: 180.4 | D5: 194.1 | E5: 208.7 | F5: 235.2
A6: T+60 sessions | B6: 136.9 | C6: 171 | D6: 194.2 | E6: 220 | F6: 268.4
A8: Diffusion σ (annualized, YZ-HAR) | D8: =Assumptions!$B$44 -> 0.4116
A9: Net 3-month drift | D9: =Assumptions!$B$45 -> 0.019
A10: Student-t df | D10: =Assumptions!$B$46 -> 5
A12: Level-touch ladder (by horizon)
A13: Level | B13: T+20 | C13: T+60
A14: 150 | B14: 0.135 | C14: 0.352
A15: 165 | B15: 0.316 | C15: 0.52
A16: 180 | B16: 0.632 | C16: 0.741
A17: 195 | B17: 0.485 | C17: 0.66
A18: 210 | B18: 0.3 | C18: 0.52
A19: 230 | B19: 0.13 | C19: 0.335
A20: 250 | B20: 0.05 | C20: 0.19

Sheet Sensitivity
A1: DCF sensitivity — WACC × terminal growth
A2: Fair value (SAR/share) by WACC and terminal growth, holding the normalized FCFF ramp. Live off Assumptions/DCF.
A4: g \ WACC | B4: 0.075 | C4: 0.0825 | D4: 0.0875 | E4: 0.095 | F4: 0.1025
A5: 0.025 | B5: =((DCF!B9/(1+B$4)^1+DCF!C9/(1+B$4)^2+DCF!D9/(1+B$4)^3+DCF!E9/(1+B$4)^4+DCF!F9/(1+B$4)^5)+(DCF!F9*(1+$A5)/(B$4-$A5)/(1+B$4)^5)-Assumptions!$B$7)/Assumptions!$B$5 -> 203.79475 | C5: =((DCF!B9/(1+C$4)^1+DCF!C9/(1+C$4)^2+DCF!D9/(1+C$4)^3+DCF!E9/(1+C$4)^4+DCF!F9/(1+C$4)^5)+(DCF!F9*(1+$A5)/(C$4-$A5)/(1+C$4)^5)-Assumptions!$B$7)/Assumptions!$B$5 -> 171.47191 | D5: =((DCF!B9/(1+D$4)^1+DCF!C9/(1+D$4)^2+DCF!D9/(1+D$4)^3+DCF!E9/(1+D$4)^4+DCF!F9/(1+D$4)^5)+(DCF!F9*(1+$A5)/(D$4-$A5)/(1+D$4)^5)-Assumptions!$B$7)/Assumptions!$B$5 -> 154.25409 | E5: =((DCF!B9/(1+E$4)^1+DCF!C9/(1+E$4)^2+DCF!D9/(1+E$4)^3+DCF!E9/(1+E$4)^4+DCF!F9/(1+E$4)^5)+(DCF!F9*(1+$A5)/(E$4-$A5)/(1+E$4)^5)-Assumptions!$B$7)/Assumptions!$B$5 -> 133.06652 | F5: =((DCF!B9/(1+F$4)^1+DCF!C9/(1+F$4)^2+DCF!D9/(1+F$4)^3+DCF!E9/(1+F$4)^4+DCF!F9/(1+F$4)^5)+(DCF!F9*(1+$A5)/(F$4-$A5)/(1+F$4)^5)-Assumptions!$B$7)/Assumptions!$B$5 -> 116.00837
A6: 0.03 | B6: =((DCF!B9/(1+B$4)^1+DCF!C9/(1+B$4)^2+DCF!D9/(1+B$4)^3+DCF!E9/(1+B$4)^4+DCF!F9/(1+B$4)^5)+(DCF!F9*(1+$A6)/(B$4-$A6)/(1+B$4)^5)-Assumptions!$B$7)/Assumptions!$B$5 -> 226.67612 | C6: =((DCF!B9/(1+C$4)^1+DCF!C9/(1+C$4)^2+DCF!D9/(1+C$4)^3+DCF!E9/(1+C$4)^4+DCF!F9/(1+C$4)^5)+(DCF!F9*(1+$A6)/(C$4-$A6)/(1+C$4)^5)-Assumptions!$B$7)/Assumptions!$B$5 -> 188.0586 | D6: =((DCF!B9/(1+D$4)^1+DCF!C9/(1+D$4)^2+DCF!D9/(1+D$4)^3+DCF!E9/(1+D$4)^4+DCF!F9/(1+D$4)^5)+(DCF!F9*(1+$A6)/(D$4-$A6)/(1+D$4)^5)-Assumptions!$B$7)/Assumptions!$B$5 -> 167.93243 | E6: =((DCF!B9/(1+E$4)^1+DCF!C9/(1+E$4)^2+DCF!D9/(1+E$4)^3+DCF!E9/(1+E$4)^4+DCF!F9/(1+E$4)^5)+(DCF!F9*(1+$A6)/(E$4-$A6)/(1+E$4)^5)-Assumptions!$B$7)/Assumptions!$B$5 -> 143.57719 | F6: =((DCF!B9/(1+F$4)^1+DCF!C9/(1+F$4)^2+DCF!D9/(1+F$4)^3+DCF!E9/(1+F$4)^4+DCF!F9/(1+F$4)^5)+(DCF!F9*(1+$A6)/(F$4-$A6)/(1+F$4)^5)-Assumptions!$B$7)/Assumptions!$B$5 -> 124.29054
A7: 0.035 | B7: =((DCF!B9/(1+B$4)^1+DCF!C9/(1+B$4)^2+DCF!D9/(1+B$4)^3+DCF!E9/(1+B$4)^4+DCF!F9/(1+B$4)^5)+(DCF!F9*(1+$A7)/(B$4-$A7)/(1+B$4)^5)-Assumptions!$B$7)/Assumptions!$B$5 -> 255.27784 | C7: =((DCF!B9/(1+C$4)^1+DCF!C9/(1+C$4)^2+DCF!D9/(1+C$4)^3+DCF!E9/(1+C$4)^4+DCF!F9/(1+C$4)^5)+(DCF!F9*(1+$A7)/(C$4-$A7)/(1+C$4)^5)-Assumptions!$B$7)/Assumptions!$B$5 -> 208.13723 | D7: =((DCF!B9/(1+D$4)^1+DCF!C9/(1+D$4)^2+DCF!D9/(1+D$4)^3+DCF!E9/(1+D$4)^4+DCF!F9/(1+D$4)^5)+(DCF!F9*(1+$A7)/(D$4-$A7)/(1+D$4)^5)-Assumptions!$B$7)/Assumptions!$B$5 -> 184.21618 | E7: =((DCF!B9/(1+E$4)^1+DCF!C9/(1+E$4)^2+DCF!D9/(1+E$4)^3+DCF!E9/(1+E$4)^4+DCF!F9/(1+E$4)^5)+(DCF!F9*(1+$A7)/(E$4-$A7)/(1+E$4)^5)-Assumptions!$B$7)/Assumptions!$B$5 -> 155.83965 | F7: =((DCF!B9/(1+F$4)^1+DCF!C9/(1+F$4)^2+DCF!D9/(1+F$4)^3+DCF!E9/(1+F$4)^4+DCF!F9/(1+F$4)^5)+(DCF!F9*(1+$A7)/(F$4-$A7)/(1+F$4)^5)-Assumptions!$B$7)/Assumptions!$B$5 -> 133.79971
A8: 0.04 | B8: =((DCF!B9/(1+B$4)^1+DCF!C9/(1+B$4)^2+DCF!D9/(1+B$4)^3+DCF!E9/(1+B$4)^4+DCF!F9/(1+B$4)^5)+(DCF!F9*(1+$A8)/(B$4-$A8)/(1+B$4)^5)-Assumptions!$B$7)/Assumptions!$B$5 -> 292.05147 | C8: =((DCF!B9/(1+C$4)^1+DCF!C9/(1+C$4)^2+DCF!D9/(1+C$4)^3+DCF!E9/(1+C$4)^4+DCF!F9/(1+C$4)^5)+(DCF!F9*(1+$A8)/(C$4-$A8)/(1+C$4)^5)-Assumptions!$B$7)/Assumptions!$B$5 -> 232.94023 | D8: =((DCF!B9/(1+D$4)^1+DCF!C9/(1+D$4)^2+DCF!D9/(1+D$4)^3+DCF!E9/(1+D$4)^4+DCF!F9/(1+D$4)^5)+(DCF!F9*(1+$A8)/(D$4-$A8)/(1+D$4)^5)-Assumptions!$B$7)/Assumptions!$B$5 -> 203.92808 | E8: =((DCF!B9/(1+E$4)^1+DCF!C9/(1+E$4)^2+DCF!D9/(1+E$4)^3+DCF!E9/(1+E$4)^4+DCF!F9/(1+E$4)^5)+(DCF!F9*(1+$A8)/(E$4-$A8)/(1+E$4)^5)-Assumptions!$B$7)/Assumptions!$B$5 -> 170.33164 | F8: =((DCF!B9/(1+F$4)^1+DCF!C9/(1+F$4)^2+DCF!D9/(1+F$4)^3+DCF!E9/(1+F$4)^4+DCF!F9/(1+F$4)^5)+(DCF!F9*(1+$A8)/(F$4-$A8)/(1+F$4)^5)-Assumptions!$B$7)/Assumptions!$B$5 -> 144.83033
A9: 0.045 | B9: =((DCF!B9/(1+B$4)^1+DCF!C9/(1+B$4)^2+DCF!D9/(1+B$4)^3+DCF!E9/(1+B$4)^4+DCF!F9/(1+B$4)^5)+(DCF!F9*(1+$A9)/(B$4-$A9)/(1+B$4)^5)-Assumptions!$B$7)/Assumptions!$B$5 -> 341.08299 | C9: =((DCF!B9/(1+C$4)^1+DCF!C9/(1+C$4)^2+DCF!D9/(1+C$4)^3+DCF!E9/(1+C$4)^4+DCF!F9/(1+C$4)^5)+(DCF!F9*(1+$A9)/(C$4-$A9)/(1+C$4)^5)-Assumptions!$B$7)/Assumptions!$B$5 -> 264.35737 | D9: =((DCF!B9/(1+D$4)^1+DCF!C9/(1+D$4)^2+DCF!D9/(1+D$4)^3+DCF!E9/(1+D$4)^4+DCF!F9/(1+D$4)^5)+(DCF!F9*(1+$A9)/(D$4-$A9)/(1+D$4)^5)-Assumptions!$B$7)/Assumptions!$B$5 -> 228.27807 | E9: =((DCF!B9/(1+E$4)^1+DCF!C9/(1+E$4)^2+DCF!D9/(1+E$4)^3+DCF!E9/(1+E$4)^4+DCF!F9/(1+E$4)^5)+(DCF!F9*(1+$A9)/(E$4-$A9)/(1+E$4)^5)-Assumptions!$B$7)/Assumptions!$B$5 -> 187.72202 | F9: =((DCF!B9/(1+F$4)^1+DCF!C9/(1+F$4)^2+DCF!D9/(1+F$4)^3+DCF!E9/(1+F$4)^4+DCF!F9/(1+F$4)^5)+(DCF!F9*(1+$A9)/(F$4-$A9)/(1+F$4)^5)-Assumptions!$B$7)/Assumptions!$B$5 -> 157.77933
A11: Shaded cell = base case (WACC 8.75%, g 3.5%). Terminal-heavy: small WACC/g moves swing the value materially — the honest warning on a long-life-asset DCF.

Sheet Per-Share & Ratios
A1: Per-share & ratios (the Data Miner)
A2: Links to statements / Assumptions.
B3: FY2023 | C3: FY2024 | D3: FY2025 | E3: FY2026E | F3: FY2027E | G3: FY2028E | H3: FY2029E | I3: FY2030E
A4: EPS (SAR) | B4: ='Income Statement'!B12/Assumptions!$B$5 -> 2.1682975 | C4: ='Income Statement'!C12/Assumptions!$B$5 -> 2.2922374 | D4: ='Income Statement'!D12/Assumptions!$B$5 -> 2.4161774 | E4: ='Income Statement'!E12/Assumptions!$B$5 -> 2.9545662 | F4: ='Income Statement'!F12/Assumptions!$B$5 -> 3.7709261 | G4: ='Income Statement'!G12/Assumptions!$B$5 -> 4.6593219 | H4: ='Income Statement'!H12/Assumptions!$B$5 -> 5.5813432 | I4: ='Income Statement'!I12/Assumptions!$B$5 -> 6.4995297
A5: BVPS (SAR) | B5: ='Balance Sheet'!B11/Assumptions!$B$5 -> 28.701892 | C5: ='Balance Sheet'!C11/Assumptions!$B$5 -> 31.311155 | D5: ='Balance Sheet'!D11/Assumptions!$B$5 -> 36.52968 | E5: ='Balance Sheet'!E11/Assumptions!$B$5 -> 39.484247 | F5: ='Balance Sheet'!F11/Assumptions!$B$5 -> 43.255173 | G5: ='Balance Sheet'!G11/Assumptions!$B$5 -> 47.392642 | H5: ='Balance Sheet'!H11/Assumptions!$B$5 -> 51.93028 | I5: ='Balance Sheet'!I11/Assumptions!$B$5 -> 56.864252
A6: P/E (x) | B6: =Assumptions!$B$4/(B4) -> 89.425 | C6: =Assumptions!$B$4/(C4) -> 84.589841 | D6: =Assumptions!$B$4/(D4) -> 80.250729 | E6: =Assumptions!$B$4/(E4) -> 65.627231 | F6: =Assumptions!$B$4/(F4) -> 51.41973 | G6: =Assumptions!$B$4/(G4) -> 41.615498 | H6: =Assumptions!$B$4/(H4) -> 34.740741 | I6: =Assumptions!$B$4/(I4) -> 29.832928
A7: P/B (x) | B7: =Assumptions!$B$4/(B5) -> 6.7556523 | C7: =Assumptions!$B$4/(C5) -> 6.1926812 | D7: =Assumptions!$B$4/(D5) -> 5.3080125 | E7: =Assumptions!$B$4/(E5) -> 4.9108193 | F7: =Assumptions!$B$4/(F5) -> 4.4827009 | G7: =Assumptions!$B$4/(G5) -> 4.0913524 | H7: =Assumptions!$B$4/(H5) -> 3.7338524 | I7: =Assumptions!$B$4/(I5) -> 3.4098752
A8: EBIT margin | B8: ='Income Statement'!B5/'Income Statement'!B4 -> 0.49078947 | C8: ='Income Statement'!C5/'Income Statement'!C4 -> 0.475 | D8: ='Income Statement'!D5/'Income Statement'!D4 -> 0.48582996 | E8: ='Income Statement'!E5/'Income Statement'!E4 -> 0.5 | F8: ='Income Statement'!F5/'Income Statement'!F4 -> 0.51 | G8: ='Income Statement'!G5/'Income Statement'!G4 -> 0.515 | H8: ='Income Statement'!H5/'Income Statement'!H4 -> 0.52 | I8: ='Income Statement'!I5/'Income Statement'!I4 -> 0.525
A9: Net margin | B9: ='Income Statement'!B12/'Income Statement'!B4 -> 0.27335526 | C9: ='Income Statement'!C12/'Income Statement'!C4 -> 0.27977707 | D9: ='Income Statement'!D12/'Income Statement'!D4 -> 0.24993252 | E9: ='Income Statement'!E12/'Income Statement'!E4 -> 0.26576014 | F9: ='Income Statement'!F12/'Income Statement'!F4 -> 0.28744987 | G9: ='Income Statement'!G12/'Income Statement'!G4 -> 0.30618142 | H9: ='Income Statement'!H12/'Income Statement'!H4 -> 0.32172884 | I9: ='Income Statement'!I12/'Income Statement'!I4 -> 0.33451467
A10: ROE (on attrib. equity) | B10: ='Income Statement'!B12/'Balance Sheet'!B11 -> 0.075545455 | C10: ='Income Statement'!C12/'Balance Sheet'!C11 -> 0.073208333 | D10: ='Income Statement'!D12/'Balance Sheet'!D11 -> 0.066142857 | E10: ='Income Statement'!E12/'Balance Sheet'!E11 -> 0.074828988 | F10: ='Income Statement'!F12/'Balance Sheet'!F11 -> 0.087178616 | G10: ='Income Statement'!G12/'Balance Sheet'!G11 -> 0.098313192 | H10: ='Income Statement'!H12/'Balance Sheet'!H11 -> 0.10747763 | I10: ='Income Statement'!I12/'Balance Sheet'!I11 -> 0.11429904
A11: Revenue YoY | C11: ='Income Statement'!C4/'Income Statement'!B4-1 -> 0.032894737 | D11: ='Income Statement'!D4/'Income Statement'!C4-1 -> 0.17993631 | E11: ='Income Statement'!E4/'Income Statement'!D4-1 -> 0.15 | F11: ='Income Statement'!F4/'Income Statement'!E4-1 -> 0.18 | G11: ='Income Statement'!G4/'Income Statement'!F4-1 -> 0.16 | H11: ='Income Statement'!H4/'Income Statement'!G4-1 -> 0.14 | I11: ='Income Statement'!I4/'Income Statement'!H4-1 -> 0.12
A12: Holdco net debt / EBITDA (x) | B12: =Assumptions!$B$7/'Income Statement'!B7 -> 6.1973228 | C12: =Assumptions!$B$7/'Income Statement'!C7 -> 6.0488749 | D12: =Assumptions!$B$7/'Income Statement'!D7 -> 5.1020408 | E12: =Assumptions!$B$7/'Income Statement'!E7 -> 4.5134705 | F12: =Assumptions!$B$7/'Income Statement'!F7 -> 3.7670208 | G12: =Assumptions!$B$7/'Income Statement'!G7 -> 3.2230149 | H12: =Assumptions!$B$7/'Income Statement'!H7 -> 2.8061075 | I12: =Assumptions!$B$7/'Income Statement'!I7 -> 2.4868942

Sheet Peer & Sector
A1: Peer set & sector
A2: Global IPPs, developers and Gulf utilities; ACWA is a growth developer-owner-operator, not a regulated utility.
A3: Peer / metric | B3: Descriptor | C3: Typical valuation
A4: Global renewables IPPs | B4: NextEra, Iberdrola, EDPR, Ørsted | C4: EV/EBITDA ~9–13x; growth-quality premium
A5: Gulf / MENA utilities | B5: SEC, TAQA, Nomac peers | C5: EV/EBITDA ~7–11x; contracted
A6: Water desalination | B6: Veolia, developer peers | C6: Scarce; ACWA ~25% of global capacity
A7: Development platform | B7: Project developers | C7: EV/GW; pipeline optionality
A8: ACWA on reported earnings | B8: P/E ~78x trailing / ~55x fwd | C8: Reflects pipeline capitalization, not steady-state
A10: Analyst context (not model inputs): Al Rajhi Capital (Feb-2024) TP SAR 257 (Neutral), DCF SAR 241 (7.37% WACC, 5% g), EV/GW SAR 272; current consensus SAR ~100–205 (de-rated with the stock). Shown for context only.
