Workbook

Sheet READ FIRST
A1: Testahil — Abu Dhabi Commercial Bank (ADX: ADCB)
A3: Companion model · Independent Valuation Study · Educational analysis · Not investment advice
A5: What this workbook is. A transparent companion to the ADCB valuation study. Every blue cell is an input; every
A6: black cell is a formula; green cells link across sheets. All inputs live on the Assumptions sheet — change one
A7: (the NIM path, loan growth, cost of risk, the Ke build, terminal growth) and the whole model reprices.
A9: What it is not. It is not investment advice, a recommendation, or a price target. Values are model outputs shown
A10: as ranges. The preparer is not licensed by any securities regulator and may hold a position in the security.
A12: Entity note. ADCB is the UAE’s third-largest bank by assets (AED 809bn, Mar-2026): retail, corporate & investment
A13: banking, private banking and treasury, plus Al Hilal Bank (digital Islamic), ADCB Egypt and ADCB Securities.
A14: Mubadala Investment Company holds 60.69%. A completed AED 6.1bn rights issue (Dec-2025; 592.2mn new shares
A15: at AED 10.30; capital to 7,912.2mn shares) is the base-changer every per-share figure in this model reflects.
A17: Valuation approach for a bank: dividend discount model (primary), cross-checked by an equity DCF (profit less capital retained for
... A28: Carlo percentiles on the Monte Carlo sheet. Never read one clock as another.

Sheet Summary
A1: Summary — five lenses, weights, weighted central
A3: Lens | B3: AED/share | C3: Weight | D3: Weighted
A4: DDM (primary) | B4: =DDM!B13 -> 21.159407 | C4: =Assumptions!E47 -> 0.3 | D4: =B4*C4 -> 6.347822
A5: Residual income | B5: ='Residual Income'!B16 -> 22.744122 | C5: =Assumptions!F47 -> 0.2 | D5: =B5*C5 -> 4.5488244
A6: FCFE (equity DCF) | B6: =DCF!B14 -> 23.349008 | C6: =Assumptions!G47 -> 0.15 | D6: =B6*C6 -> 3.5023511
A7: Relative multiples | B7: ='Relative & Normalized'!B6 -> 15.938805 | C7: =Assumptions!H47 -> 0.2 | D7: =B7*C7 -> 3.1877609
A8: Normalized value (through-cycle) | B8: ='Relative & Normalized'!B11 -> 14.346038 | C8: =Assumptions!I47 -> 0.15 | D8: =B8*C8 -> 2.1519057
A9: Weighted central | B9: =SUM(D4:D8) -> 19.738664
A10: Spot | B10: =Assumptions!$B$5 -> 15.1
A11: Upside / (downside) vs spot | B11: =B9/B10-1 -> 0.3071963
A13: Two clocks (never conflate)
A14: Risk-adjusted fair value (~12-month anchor) | B14: =B9 -> 19.738664
A15: Strategy-delivered ceiling (base-Ke, AED 20bn credited — multi-year) | B15: 23
A16: 3-month figures = Monte Carlo percentiles only (see Monte Carlo sheet)

Sheet Fundamental Valuation
A1: Fundamental valuation — the five-lens summary and the headline range
A3: Lens | B3: AED/share | C3: Weight | D3: Contribution
A4: DDM (primary) | B4: =Summary!B4 -> 21.159407 | C4: =Summary!C4 -> 0.3 | D4: =Summary!D4 -> 6.347822
A5: Residual income | B5: =Summary!B5 -> 22.744122 | C5: =Summary!C5 -> 0.2 | D5: =Summary!D5 -> 4.5488244
A6: DCF — equity FCFE | B6: =Summary!B6 -> 23.349008 | C6: =Summary!C6 -> 0.15 | D6: =Summary!D6 -> 3.5023511
A7: Relative multiples | B7: =Summary!B7 -> 15.938805 | C7: =Summary!C7 -> 0.2 | D7: =Summary!D7 -> 3.1877609
A8: Normalized value (through-cycle) | B8: =Summary!B8 -> 14.346038 | C8: =Summary!C8 -> 0.15 | D8: =Summary!D8 -> 2.1519057
A9: Weighted central | B9: =Summary!B9 -> 19.738664
A11: HEADLINE RANGE (the three numbers on the study and the site)
A12: Bear — normalized through-cycle floor | B12: ='Relative & Normalized'!B11 -> 14.346038
A13: Base — weighted central | B13: =Summary!B9 -> 19.738664
A14: Bull — equity DCF (FCFE) ceiling | B14: =DCF!B14 -> 23.349008
A15: Spot | B15: =Assumptions!$B$5 -> 15.1
A16: Upside to weighted central | B16: =B13/B15-1 -> 0.3071963
A18: The DCF family (DDM/RI/DCF, 21-23) and the market family (Relative/Normalized, 14-16) do not overlap —
A19: so they are not blended into a single point estimate dressed up as precision. See study §1.7.

Sheet Assumptions
A1: Assumptions — the single blue-input layer
A2: Every input in the model lives here. Blue = change me.
A4: MARKET
A5: Spot (AED, 03-Jul-2026 close) | B5: 15.1
A6: Shares outstanding (mn, post-rights) | B6: 7912.1757
A7: Market cap (AED bn) | B7: =Assumptions!$B$5*Assumptions!$B$6/1000 -> 119.47385
A8: FY25 DPS (AED) — trailing yield anchor | B8: 0.63
A10: COST OF EQUITY (Ke)
A11: Risk-free (AED 10Y, constructed: UST10Y 4.58% + ~12bp AED T-Bond spread) | B11: 0.047
A12: ERP — rating-based (Damodaran Jan-2026, UAE Aa2) | B12: 0.0487
A13: ERP — CDS-based (Abu Dhabi row, cross-check) | B13: 0.0493
A14: Beta (regression on ADX index not available → set to 1.00; band 0.8–1.3) | B14: 1
A15: Conflict-risk adder (2026 Iran war; sensitized to 0 on de-escalation) | B15: 0.01
A16: Ke = rf + β·ERP + adder | B16: =Assumptions!$B$11+Assumptions!$B$14*Assumptions!$B$12+Assumptions!$B$15 -> 0.1057
A17: Terminal growth g | B17: 0.04
A18: Terminal ROE | B18: 0.15
A20: DRIVER PATHS (FY26E–FY30E) | E20: FY26E | F20: FY27E | G20: FY28E | H20: FY29E | I20: FY30E
A21: Net loan growth % | E21: 0.16 | F21: 0.12 | G21: 0.1 | H21: 0.09 | I21: 0.08
A22: Net interest margin % (avg NIEA) | E22: 0.023 | F22: 0.0226 | G22: 0.0228 | H22: 0.023 | I22: 0.0232
A23: Non-interest income growth % | E23: 0.11 | F23: 0.09 | G23: 0.09 | H23: 0.09 | I23: 0.09
A24: Cost-to-income % | E24: 0.27 | F24: 0.26 | G24: 0.255 | H24: 0.25 | I24: 0.245
A25: Cost of risk (bp on avg loans) | E25: 55 | F25: 50 | G25: 48 | H25: 46 | I25: 45
A26: Effective tax rate (IAE 9% → DMTT 15%) | E26: 0.11 | F26: 0.15 | G26: 0.15 | H26: 0.15 | I26: 0.15
A27: Dividend payout % | E27: 0.38 | F27: 0.37 | G27: 0.36 | H27: 0.34 | I27: 0.33
A28: RWA growth % | E28: 0.13 | F28: 0.11 | G28: 0.095 | H28: 0.085 | I28: 0.075
A29: CET1 target % | E29: 0.136 | F29: 0.134 | G29: 0.132 | H29: 0.13 | I29: 0.1275
A30: NIEA / net loans multiple (Dec-2025 anchor) | B30: 1.6
A31: RWA, Dec-2025 (AED mn — DERIVED from CET1 13.82% at density ~62%; FLAGGED, ledger row) | B31: 500000
A32: CET1 capital, Mar-2026 (AED mn = 13.82% × RWA) | B32: =0.1382*Assumptions!$B$31 -> 69100
A34: EQUITY SPLIT (derived to disclosed Mar-2026 total; FLAGGED)
A35: Total shareholders’ equity, Mar-2026 (disclosed) | B35: 86000
A36: Total shareholders’ equity, Dec-2025 (derived) | B36: 84500
A37: Tier-1 capital notes within equity (est., FLAGGED) | B37: 6000
A38: Common equity, Dec-2025 = total − T1 notes | B38: =B36-B37 -> 78500
A39: Goodwill & intangibles (est., merger vintage; FLAGGED) | B39: 7500
A40: BVPS (common) / TBVPS | B40: =Assumptions!$B$38/Assumptions!$B$6 -> 9.9214177 | C40: =(Assumptions!$B$38-B39)/Assumptions!$B$6 -> 8.9735115
A42: RELATIVE & FLOOR
A43: Sector P/B (UAE large banks) | B43: 1.55
A44: Forward P/E (peer read) | B44: 9.5
A45: Through-cycle ROE % (floor) | B45: 0.135
...

Sheet Driver Build
A1: Driver Build — rate-path NIM bridge, DuPont, CET1 schedule
A2: Rate-path margin bridge, DuPont, and the capital schedule. Black cells compute from Assumptions.
A3: AED mn | C3: FY25A | D3: link | E3: FY26E | F3: FY27E | G3: FY28E | H3: FY29E | I3: FY30E
A4: Net loans (close) | C4: 405967 | E4: =C4*(1+Assumptions!E21) -> 470921.72 | F4: =E4*(1+Assumptions!F21) -> 527432.33 | G4: =F4*(1+Assumptions!G21) -> 580175.56 | H4: =G4*(1+Assumptions!H21) -> 632391.36 | I4: =H4*(1+Assumptions!I21) -> 682982.67
A5: Avg NIEA | E5: =(C4*Assumptions!$B$30+E4*Assumptions!$B$30)/2 -> 701510.98 | F5: =(E4*Assumptions!$B$30+F4*Assumptions!$B$30)/2 -> 798683.24 | G5: =(F4*Assumptions!$B$30+G4*Assumptions!$B$30)/2 -> 886086.31 | H5: =(G4*Assumptions!$B$30+H4*Assumptions!$B$30)/2 -> 970053.53 | I5: =(H4*Assumptions!$B$30+I4*Assumptions!$B$30)/2 -> 1052299.2
A6: Net interest income | E6: =E5*Assumptions!E22 -> 16134.752 | F6: =F5*Assumptions!F22 -> 18050.241 | G6: =G5*Assumptions!G22 -> 20202.768 | H6: =H5*Assumptions!H22 -> 22311.231 | I6: =I5*Assumptions!I22 -> 24413.342
A7: Non-interest income | E7: =7495*(1+Assumptions!E23) -> 8319.45 | F7: =E7*(1+Assumptions!F23) -> 9068.2005 | G7: =F7*(1+Assumptions!G23) -> 9884.3385 | H7: =G7*(1+Assumptions!H23) -> 10773.929 | I7: =H7*(1+Assumptions!I23) -> 11743.583
A8: Operating income | E8: =E6+E7 -> 24454.202 | F8: =F6+F7 -> 27118.442 | G8: =G6+G7 -> 30087.106 | H8: =H6+H7 -> 33085.16 | I8: =I6+I7 -> 36156.925
A9: Operating expenses | E9: =-E8*Assumptions!E24 -> -6602.6347 | F9: =-F8*Assumptions!F24 -> -7050.7948 | G9: =-G8*Assumptions!G24 -> -7672.2121 | H9: =-H8*Assumptions!H24 -> -8271.2901 | I9: =-I8*Assumptions!I24 -> -8858.4465
A10: Pre-provision operating profit | E10: =E8+E9 -> 17851.568 | F10: =F8+F9 -> 20067.647 | G10: =G8+G9 -> 22414.894 | H10: =H8+H9 -> 24813.87 | I10: =I8+I9 -> 27298.478
A11: Impairment charge | E11: =-(C4+E4)/2*Assumptions!E25/10000 -> -2411.444 | F11: =-(E4+F4)/2*Assumptions!F25/10000 -> -2495.8851 | G11: =-(F4+G4)/2*Assumptions!G25/10000 -> -2658.2589 | H11: =-(G4+H4)/2*Assumptions!H25/10000 -> -2788.9039 | I11: =-(H4+I4)/2*Assumptions!I25/10000 -> -2959.5916
A12: Profit before tax | E12: =E10+E11 -> 15440.124 | F12: =F10+F11 -> 17571.762 | G12: =G10+G11 -> 19756.635 | H12: =H10+H11 -> 22024.966 | I12: =I10+I11 -> 24338.886
A13: Tax | E13: =-E12*Assumptions!E26 -> -1698.4136 | F13: =-F12*Assumptions!F26 -> -2635.7643 | G13: =-G12*Assumptions!G26 -> -2963.4953 | H13: =-H12*Assumptions!H26 -> -3303.7449 | I13: =-I12*Assumptions!I26 -> -3650.833
A14: Net profit after tax | E14: =E12+E13 -> 13741.71 | F14: =F12+F13 -> 14935.997 | G14: =G12+G13 -> 16793.14 | H14: =H12+H13 -> 18721.221 | I14: =I12+I13 -> 20688.054
A15: EPS (AED) | E15: =E14/Assumptions!$B$6 -> 1.7367802 | F15: =F14/Assumptions!$B$6 -> 1.8877232 | G15: =G14/Assumptions!$B$6 -> 2.1224428 | H15: =H14/Assumptions!$B$6 -> 2.3661281 | I15: =I14/Assumptions!$B$6 -> 2.6147111
A16: DPS (AED) | E16: =E15*Assumptions!E27 -> 0.65997648 | F16: =F15*Assumptions!F27 -> 0.69845757 | G16: =G15*Assumptions!G27 -> 0.76407939 | H16: =H15*Assumptions!H27 -> 0.80448356 | I16: =I15*Assumptions!I27 -> 0.86285466
A17: Dividends (total) | E17: =E16*Assumptions!$B$6 -> 5221.8499 | F17: =F16*Assumptions!$B$6 -> 5526.3191 | G17: =G16*Assumptions!$B$6 -> 6045.5304 | H17: =H16*Assumptions!$B$6 -> 6365.2153 | I17: =I16*Assumptions!$B$6 -> 6827.0577
A18: Opening common equity | E18: =Assumptions!$B$38 -> 78500 | F18: =E19 -> 87019.86 | G18: =F19 -> 96429.539 | H18: =G19 -> 107177.15 | I18: =H19 -> 119533.15
A19: Closing common equity | E19: =E18+E14-E17 -> 87019.86 | F19: =F18+F14-F17 -> 96429.539 | G19: =G18+G14-G17 -> 107177.15 | H19: =H18+H14-H17 -> 119533.15 | I19: =I18+I14-I17 -> 133394.15
A20: ROE % | E20: =E14/((E18+E19)/2) -> 0.16604304 | F20: =F14/((F18+F19)/2) -> 0.16283507 | G20: =G14/((G18+G19)/2) -> 0.16495666 | H20: =H14/((H18+H19)/2) -> 0.16515545 | I20: =I14/((I18+I19)/2) -> 0.16358893
A22: CET1 / RWA schedule (FCFE leg)
A23: RWA (close) | C23: =Assumptions!$B$31 -> 500000 | E23: =C23*(1+Assumptions!E28) -> 565000 | F23: =E23*(1+Assumptions!F28) -> 627150 | G23: =F23*(1+Assumptions!G28) -> 686729.25 | H23: =G23*(1+Assumptions!H28) -> 745101.24 | I23: =H23*(1+Assumptions!I28) -> 800983.83
A24: Required CET1 capital = target × RWA | E24: =E23*Assumptions!E29 -> 76840 | F24: =F23*Assumptions!F29 -> 84038.1 | G24: =G23*Assumptions!G29 -> 90648.261 | H24: =H23*Assumptions!H29 -> 96863.161 | I24: =I23*Assumptions!I29 -> 102125.44
A25: Δ CET1 capital retained | E25: =E24-Assumptions!$B$32 -> 7740 | F25: =F24-E24 -> 7198.1 | G25: =G24-F24 -> 6610.161 | H25: =H24-G24 -> 6214.8997 | I25: =I24-H24 -> 5262.2775
A26: FCFE = NPAT − Δ CET1 retained | E26: =E14-E25 -> 6001.7102 | F26: =F14-F25 -> 7737.8975 | G26: =G14-G25 -> 10182.979 | H26: =H14-H25 -> 12506.322 | I26: =I14-I25 -> 15425.776
A28: DuPont — return on average assets, decomposed
A29: (avg total assets = avg-of-open/close net loans ÷ 0.525, the Dec-25 loans/assets mix — same proxy used in Appendix A)
A30: Avg total assets (proxy) | E30: =(405967/0.525+E4/0.525)/2 -> 835132.11 | F30: =(E4/0.525+F4/0.525)/2 -> 950813.38 | G30: =(F4/0.525+G4/0.525)/2 -> 1054864.7 | H30: =(G4/0.525+H4/0.525)/2 -> 1154825.6 | I30: =(H4/0.525+I4/0.525)/2 -> 1252737.2
A31: Net interest income / avg assets | E31: =E6/E30 -> 0.01932 | F31: =F6/F30 -> 0.018984 | G31: =G6/G30 -> 0.019152 | H31: =H6/H30 -> 0.01932 | I31: =I6/I30 -> 0.019488
A32: + Non-interest income / avg assets | E32: =E7/E30 -> 0.009961837 | F32: =F7/F30 -> 0.0095373085 | G32: =G7/G30 -> 0.0093702434 | H32: =H7/H30 -> 0.0093294855 | I32: =I7/I30 -> 0.0093743388
A33: − Operating expense / avg assets | E33: =E9/E30 -> -0.007906096 | F33: =F9/F30 -> -0.0074155402 | G33: =G9/G30 -> -0.0072731721 | H33: =H9/H30 -> -0.0071623714 | I33: =I9/I30 -> -0.007071273
A34: − Impairment charge / avg assets | E34: =E11/E30 -> -0.0028875 | F34: =F11/F30 -> -0.002625 | G34: =G11/G30 -> -0.00252 | H34: =H11/H30 -> -0.002415 | I34: =I11/I30 -> -0.0023625
A35: − Tax / avg assets | E35: =E13/E30 -> -0.0020337065 | F35: =F13/F30 -> -0.0027721152 | G35: =G13/G30 -> -0.0028093607 | H35: =H13/H30 -> -0.0028608171 | I35: =I13/I30 -> -0.0029142849
A36: Return on average assets (RoAA) | E36: =E14/E30 -> 0.016454535 | F36: =F14/F30 -> 0.015708653 | G36: =G14/G30 -> 0.015919711 | H36: =H14/H30 -> 0.016211297 | I36: =I14/I30 -> 0.016514281
A37: × Equity multiplier (avg assets / avg common equity) | E37: =E30/((Assumptions!$B$38+E19)/2) -> 10.09102 | F37: =F30/((E19+F19)/2) -> 10.365947 | G37: =G30/((F19+G19)/2) -> 10.361788 | H37: =H30/((G19+H19)/2) -> 10.187677 | I37: =I30/((H19+I19)/2) -> 9.9059069
A38: Return on average equity (ROE) — ties to the ROE row above | E38: =E36*E37 -> 0.16604304 | F38: =F36*F37 -> 0.16283507 | G38: =G36*G37 -> 0.16495666 | H38: =H36*H37 -> 0.16515545 | I38: =I36*I37 -> 0.16358893
A40: Read: the margin (NII/assets) and efficiency (opex/assets) lines carry the operating story; leverage (the equity
A41: multiplier) is held roughly flat by the CET1 floor — so ROE moves mainly on RoAA, not on balance-sheet leverage.

Sheet DDM
A1: Dividend discount model — the primary lens
A2: DPS from the Driver Build; Gordon terminal at g on terminal payout 1−g/ROE.
A3: AED / share | E3: FY26E | F3: FY27E | G3: FY28E | H3: FY29E | I3: FY30E
A4: DPS | E4: ='Driver Build'!E16 -> 0.65997648 | F4: ='Driver Build'!F16 -> 0.69845757 | G4: ='Driver Build'!G16 -> 0.76407939 | H4: ='Driver Build'!H16 -> 0.80448356 | I4: ='Driver Build'!I16 -> 0.86285466
A5: Discount factor = 1/(1+Ke)^t | E5: =1/POWER(1+Assumptions!$B$16,1) -> 0.90440445 | F5: =1/POWER(1+Assumptions!$B$16,2) -> 0.81794741 | G5: =1/POWER(1+Assumptions!$B$16,3) -> 0.73975528 | H5: =1/POWER(1+Assumptions!$B$16,4) -> 0.66903796 | I5: =1/POWER(1+Assumptions!$B$16,5) -> 0.60508091
A6: PV of dividend | E6: =E4*E5 -> 0.59688566 | F6: =F4*F5 -> 0.57130156 | G6: =G4*G5 -> 0.56523176 | H6: =H4*H5 -> 0.53823004 | I6: =I4*I5 -> 0.52209688
A8: Σ PV of explicit dividends (FY26–30) | B8: =SUM(E6:I6) -> 2.7937459
A9: Terminal payout = 1 − g/ROE_terminal | B9: =1-Assumptions!$B$17/Assumptions!$B$18 -> 0.73333333
A10: Terminal DPS (FY31) = EPS30 × (1+g) × terminal payout | B10: ='Driver Build'!I15*(1+Assumptions!$B$17)*B9 -> 1.994153
A11: Terminal value at Ke − g | B11: =B10/(Assumptions!$B$16-Assumptions!$B$17) -> 30.352405
A12: PV of terminal value | B12: =B11*I5 -> 18.365661
A13: DDM fair value | B13: =B8+B12 -> 21.159407
A14: Terminal value as % of DDM (dependency disclosure) | B14: =B12/B13 -> 0.86796672
A15: vs spot | B15: =B13/Assumptions!$B$5-1 -> 0.4012852

Sheet Segments
A1: Segments — operating-income mix and the two disclosed subsidiaries
A2: ADCB reports one consolidated P&L; segment and subsidiary detail below is applied top-down to the group build.
A3: OPERATING-INCOME MIX (Q1’26, ADCB investor materials — the latest disclosed split)
A4: Segment | B4: Q1’26 mix | E4: FY26E | F4: FY27E | G4: FY28E | H4: FY29E | I4: FY30E
A5: Corporate & Investment Banking | B5: 0.36 | E5: =$B5*'Driver Build'!E8 -> 8803.5129 | F5: =$B5*'Driver Build'!F8 -> 9762.639 | G5: =$B5*'Driver Build'!G8 -> 10831.358 | H5: =$B5*'Driver Build'!H8 -> 11910.658 | I5: =$B5*'Driver Build'!I8 -> 13016.493
A6: Retail (Consumer) Banking | B6: 0.33 | E6: =$B6*'Driver Build'!E8 -> 8069.8868 | F6: =$B6*'Driver Build'!F8 -> 8949.0857 | G6: =$B6*'Driver Build'!G8 -> 9928.7451 | H6: =$B6*'Driver Build'!H8 -> 10918.103 | I6: =$B6*'Driver Build'!I8 -> 11931.785
A7: Treasury & Investments | B7: 0.25 | E7: =$B7*'Driver Build'!E8 -> 6113.5506 | F7: =$B7*'Driver Build'!F8 -> 6779.6104 | G7: =$B7*'Driver Build'!G8 -> 7521.7766 | H7: =$B7*'Driver Build'!H8 -> 8271.2901 | I7: =$B7*'Driver Build'!I8 -> 9039.2311
A8: Private Banking & Wealth | B8: 0.06 | E8: =$B8*'Driver Build'!E8 -> 1467.2521 | F8: =$B8*'Driver Build'!F8 -> 1627.1065 | G8: =$B8*'Driver Build'!G8 -> 1805.2264 | H8: =$B8*'Driver Build'!H8 -> 1985.1096 | I8: =$B8*'Driver Build'!I8 -> 2169.4155
A9: Total operating income (check) | E9: =SUM(E5:E8) -> 24454.202 | F9: =SUM(F5:F8) -> 27118.442 | G9: =SUM(G5:G8) -> 30087.106 | H9: =SUM(H5:H8) -> 33085.16 | I9: =SUM(I5:I8) -> 36156.925
A11: The mix is applied flat across FY26E–30E (no segment-level forward guidance disclosed — negative search,
A12: logged in the Fundamental Driver Ledger); Al Hilal Bank (Islamic banking) is not broken out as a separate P&L
A13: line in captured disclosures — also a negative search, consolidated within Retail/CIB on a product basis.
A15: SUBSIDIARY: ADCB EGYPT (EGP, IFRS, disclosed separately each quarter)
A16: Q1’26 net profit (EGP mn) | B16: 1100
A17: Q1’26 return on equity | B17: 0.24
A18: Net loans, Q1’26 (EGP mn, +28% YoY) | B18: 77600
A19: Customer deposits, Q1’26 (EGP mn, +27% YoY) | B19: 158000
A20: Source: ADCB Q1 2026 results release (23-Apr-2026), reproduced on wire services — EGP figures not
A21: material to the AED group model (ADCB Egypt is ~1% of group net profit) and shown for context only.

Sheet Relative & Normalized
A1: Relative multiples & the normalized through-cycle value
A3: Relative read
A4: Sector P/B × BVPS | B4: =Assumptions!$B$43*Assumptions!$B$40 -> 15.378197
A5: Forward P/E × FY26E EPS | B5: =Assumptions!$B$44*'Driver Build'!E15 -> 16.499412
A6: Relative blend (average) | B6: =(B4+B5)/2 -> 15.938805
A8: Normalized value (through-cycle)
A9: Through-cycle ROE × BVPS = normalized EPS | B9: =Assumptions!$B$45*Assumptions!$B$40 -> 1.3393914
A10: Justified P/B = (ROE_tc − g)/(Ke − g) | B10: =(Assumptions!$B$45-Assumptions!$B$17)/(Assumptions!$B$16-Assumptions!$B$17) -> 1.4459665
A11: Normalized value = justified P/B × BVPS | B11: =B10*Assumptions!$B$40 -> 14.346038
A12: Implied through-cycle P/E (memo) = value ÷ normalized EPS | B12: =B11/B9 -> 10.710863
A13: Terminal justified P/B = (ROE_terminal − g)/(Ke − g) (cross-check) | B13: =(Assumptions!$B$18-Assumptions!$B$17)/(Assumptions!$B$16-Assumptions!$B$17) -> 1.674277
A14: Market P/B at spot | B14: =Assumptions!$B$5/Assumptions!$B$40 -> 1.5219599

Sheet DCF
A1: DCF — equity free cash flow (FCFE), profit less capital retained for RWA growth
A2: What is genuinely distributable, whether or not paid. Canonical DCF slot: for a bank, the cash-flow cross-check is FCFE, not FCFF (deposits are an operating input, not financing).
A3: AED mn | E3: FY26E | F3: FY27E | G3: FY28E | H3: FY29E | I3: FY30E
A4: Net profit after tax | E4: ='Driver Build'!E14 -> 13741.71 | F4: ='Driver Build'!F14 -> 14935.997 | G4: ='Driver Build'!G14 -> 16793.14 | H4: ='Driver Build'!H14 -> 18721.221 | I4: ='Driver Build'!I14 -> 20688.054
A5: − Δ CET1 capital retained | E5: ='Driver Build'!E25 -> 7740 | F5: ='Driver Build'!F25 -> 7198.1 | G5: ='Driver Build'!G25 -> 6610.161 | H5: ='Driver Build'!H25 -> 6214.8997 | I5: ='Driver Build'!I25 -> 5262.2775
A6: FCFE (NPAT less retention) | E6: ='Driver Build'!E26 -> 6001.7102 | F6: ='Driver Build'!F26 -> 7737.8975 | G6: ='Driver Build'!G26 -> 10182.979 | H6: ='Driver Build'!H26 -> 12506.322 | I6: ='Driver Build'!I26 -> 15425.776
A7: Discount factor | E7: =1/POWER(1+Assumptions!$B$16,1) -> 0.90440445 | F7: =1/POWER(1+Assumptions!$B$16,2) -> 0.81794741 | G7: =1/POWER(1+Assumptions!$B$16,3) -> 0.73975528 | H7: =1/POWER(1+Assumptions!$B$16,4) -> 0.66903796 | I7: =1/POWER(1+Assumptions!$B$16,5) -> 0.60508091
A8: PV of FCFE | E8: =E6*E7 -> 5427.9734 | F8: =F6*F7 -> 6329.1932 | G8: =G6*G7 -> 7532.9125 | H8: =H6*H7 -> 8367.204 | I8: =I6*I7 -> 9333.8426
A10: Σ PV of explicit FCFE | B10: =SUM(E8:I8) -> 36991.126
A11: Terminal FCFE (FY31, +g) / (Ke−g) | B11: =I6*(1+Assumptions!$B$17)/(Assumptions!$B$16-Assumptions!$B$17) -> 244182.76
A12: PV of terminal FCFE | B12: =B11*I7 -> 147750.32
A13: Equity value | B13: =B10+B12 -> 184741.45
A14: FCFE value / share | B14: =B13/Assumptions!$B$6 -> 23.349008
A15: PV of terminal as % of equity value | B15: =B12/B13 -> 0.79976813

Sheet Residual Income
A1: Residual income — book value plus PV of excess returns
A2: RI = NPAT − Ke × opening common equity.
A3: AED mn | E3: FY26E | F3: FY27E | G3: FY28E | H3: FY29E | I3: FY30E
A4: Opening common equity | E4: ='Driver Build'!E18 -> 78500 | F4: ='Driver Build'!F18 -> 87019.86 | G4: ='Driver Build'!G18 -> 96429.539 | H4: ='Driver Build'!H18 -> 107177.15 | I4: ='Driver Build'!I18 -> 119533.15
A5: Net profit after tax | E5: ='Driver Build'!E14 -> 13741.71 | F5: ='Driver Build'!F14 -> 14935.997 | G5: ='Driver Build'!G14 -> 16793.14 | H5: ='Driver Build'!H14 -> 18721.221 | I5: ='Driver Build'!I14 -> 20688.054
A6: − equity charge (Ke × opening BV) | E6: =-Assumptions!$B$16*E4 -> -8297.45 | F6: =-Assumptions!$B$16*F4 -> -9197.9992 | G6: =-Assumptions!$B$16*G4 -> -10192.602 | H6: =-Assumptions!$B$16*H4 -> -11328.625 | I6: =-Assumptions!$B$16*I4 -> -12634.654
A7: Residual income (NPAT less charge) | E7: =E5+E6 -> 5444.2602 | F7: =F5+F6 -> 5737.9982 | G7: =G5+G6 -> 6600.5378 | H7: =H5+H6 -> 7392.5968 | I7: =I5+I6 -> 8053.3991
A8: Discount factor | E8: =1/POWER(1+Assumptions!$B$16,1) -> 0.90440445 | F8: =1/POWER(1+Assumptions!$B$16,2) -> 0.81794741 | G8: =1/POWER(1+Assumptions!$B$16,3) -> 0.73975528 | H8: =1/POWER(1+Assumptions!$B$16,4) -> 0.66903796 | I8: =1/POWER(1+Assumptions!$B$16,5) -> 0.60508091
A9: PV of residual income | E9: =E7*E8 -> 4923.8131 | F9: =F7*F8 -> 4693.3808 | G9: =G7*G8 -> 4882.7826 | H9: =H7*H8 -> 4945.9279 | I9: =I7*I8 -> 4872.9581
A11: Common book value, Dec-2025 (starting equity) | B11: =Assumptions!$B$38 -> 78500
A12: Σ PV of explicit residual income | B12: =SUM(E9:I9) -> 24318.863
A13: Terminal RI (FY31, +g) / (Ke−g) | B13: =I7*(1+Assumptions!$B$17)/(Assumptions!$B$16-Assumptions!$B$17) -> 127481.51
A14: PV of terminal RI | B14: =B13*I8 -> 77136.627
A15: Equity value | B15: =B11+B12+B14 -> 179955.49
A16: Residual-income value / share | B16: =B15/Assumptions!$B$6 -> 22.744122
A17: Implied exit multiple on Dec-2025 common book | B17: =B15/B11 -> 2.2924266

Sheet Income Statement
A1: Income statement — 3yr history + 5yr forecast (AED mn)
A2: History from ADCB results releases (IR); forecast links to the Driver Build.
A3: AED mn | C3: FY23 | D3: FY24 | E3: FY25 | F3: FY26E | G3: FY27E | H3: FY28E | I3: FY29E | J3: FY30E
A4: Net interest income | C4: 12370 | D4: 13232 | E4: 14688 | F4: ='Driver Build'!E6 -> 16134.752 | G4: ='Driver Build'!F6 -> 18050.241 | H4: ='Driver Build'!G6 -> 20202.768 | I4: ='Driver Build'!H6 -> 22311.231 | J4: ='Driver Build'!I6 -> 24413.342
A5: Non-interest income | C5: 4490 | D5: 6227 | E5: 7495 | F5: ='Driver Build'!E7 -> 8319.45 | G5: ='Driver Build'!F7 -> 9068.2005 | H5: ='Driver Build'!G7 -> 9884.3385 | I5: ='Driver Build'!H7 -> 10773.929 | J5: ='Driver Build'!I7 -> 11743.583
A6: Operating income | C6: 16860 | D6: 19459 | E6: 22183 | F6: ='Driver Build'!E8 -> 24454.202 | G6: ='Driver Build'!F8 -> 27118.442 | H6: ='Driver Build'!G8 -> 30087.106 | I6: ='Driver Build'!H8 -> 33085.16 | J6: ='Driver Build'!I8 -> 36156.925
A7: Operating expenses | C7: -5176 | D7: -6032 | E7: -6256 | F7: ='Driver Build'!E9 -> -6602.6347 | G7: ='Driver Build'!F9 -> -7050.7948 | H7: ='Driver Build'!G9 -> -7672.2121 | I7: ='Driver Build'!H9 -> -8271.2901 | J7: ='Driver Build'!I9 -> -8858.4465
A8: Pre-provision operating profit | C8: =C6+C7 -> 11684 | D8: =D6+D7 -> 13427 | E8: =E6+E7 -> 15927 | F8: ='Driver Build'!E10 -> 17851.568 | G8: ='Driver Build'!F10 -> 20067.647 | H8: ='Driver Build'!G10 -> 22414.894 | I8: ='Driver Build'!H10 -> 24813.87 | J8: ='Driver Build'!I10 -> 27298.478
A9: Impairment charge | C9: -3477 | D9: -2842 | E9: -3084 | F9: ='Driver Build'!E11 -> -2411.444 | G9: ='Driver Build'!F11 -> -2495.8851 | H9: ='Driver Build'!G11 -> -2658.2589 | I9: ='Driver Build'!H11 -> -2788.9039 | J9: ='Driver Build'!I11 -> -2959.5916
A10: Profit before tax | C10: 8207 | D10: 10585 | E10: 12843 | F10: ='Driver Build'!E12 -> 15440.124 | G10: ='Driver Build'!F12 -> 17571.762 | H10: ='Driver Build'!G12 -> 19756.635 | I10: ='Driver Build'!H12 -> 22024.966 | J10: ='Driver Build'!I12 -> 24338.886
A11: Tax | C11: 0 | D11: -1166 | E11: -1398 | F11: ='Driver Build'!E13 -> -1698.4136 | G11: ='Driver Build'!F13 -> -2635.7643 | H11: ='Driver Build'!G13 -> -2963.4953 | I11: ='Driver Build'!H13 -> -3303.7449 | J11: ='Driver Build'!I13 -> -3650.833
A12: Net profit after tax | C12: 8207 | D12: 9419 | E12: 11445 | F12: ='Driver Build'!E14 -> 13741.71 | G12: ='Driver Build'!F14 -> 14935.997 | H12: ='Driver Build'!G14 -> 16793.14 | I12: ='Driver Build'!H14 -> 18721.221 | J12: ='Driver Build'!I14 -> 20688.054
A14: Memo: NIM % (as reported / model) | C14: 0.0283 | D14: 0.0258 | E14: 0.0245 | F14: =Assumptions!E22 -> 0.023 | G14: =Assumptions!F22 -> 0.0226 | H14: =Assumptions!G22 -> 0.0228 | I14: =Assumptions!H22 -> 0.023 | J14: =Assumptions!I22 -> 0.0232
A15: Memo: cost-to-income % | C15: 0.307 | D15: 0.31 | E15: 0.282 | F15: =Assumptions!E24 -> 0.27 | G15: =Assumptions!F24 -> 0.26 | H15: =Assumptions!G24 -> 0.255 | I15: =Assumptions!H24 -> 0.25 | J15: =Assumptions!I24 -> 0.245
A17: FY23 is pre-UAE-CIT (9% from FY24, DMTT/IAE from FY25) and includes the ADCP one-off gain of AED 490mn;
A18: FY23 ex-one-off net profit AED 7,717mn (dual framing). FY24 opex/impairment derived from disclosed CIR/PBT (flagged).

Sheet Balance Sheet
A1: Balance sheet — key lines (AED mn)
A2: FY23 assets and FY24 deposits derived from disclosed growth rates (flagged blue-with-note).
A3: AED mn | C3: FY23 | D3: FY24 | E3: FY25 | F3: FY26E | G3: FY27E | H3: FY28E | I3: FY29E | J3: FY30E
A4: Total assets | C4: 567000 | D4: 650130 | E4: 773654 | F4: =F5/0.525 -> 896993.75 | G4: =G5/0.525 -> 1004633 | H4: =H5/0.525 -> 1105096.3 | I4: =I5/0.525 -> 1204555 | J4: =J5/0.525 -> 1300919.4
A5: Net loans and advances | C5: 301700 | D5: 349972 | E5: 405967 | F5: ='Driver Build'!E4 -> 470921.72 | G5: ='Driver Build'!F4 -> 527432.33 | H5: ='Driver Build'!G4 -> 580175.56 | I5: ='Driver Build'!H4 -> 632391.36 | J5: ='Driver Build'!I4 -> 682982.67
A6: Customer deposits | C6: 363000 | D6: 421000 | E6: 499775 | F6: =F5/0.812 -> 579952.86 | G6: =G5/0.812 -> 649547.2 | H6: =H5/0.812 -> 714501.92 | I6: =I5/0.812 -> 778807.09 | J6: =J5/0.812 -> 841111.66
A8: Common equity (close) | C8: — | D8: — | E8: =Assumptions!$B$38 -> 78500 | F8: ='Driver Build'!E19 -> 87019.86 | G8: ='Driver Build'!F19 -> 96429.539 | H8: ='Driver Build'!G19 -> 107177.15 | I8: ='Driver Build'!H19 -> 119533.15 | J8: ='Driver Build'!I19 -> 133394.15
A9: RWA (close) | F9: ='Driver Build'!E23 -> 565000 | G9: ='Driver Build'!F23 -> 627150 | H9: ='Driver Build'!G23 -> 686729.25 | I9: ='Driver Build'!H23 -> 745101.24 | J9: ='Driver Build'!I23 -> 800983.83
A10: CET1 % (target path) | F10: =Assumptions!E29 -> 0.136 | G10: =Assumptions!F29 -> 0.134 | H10: =Assumptions!G29 -> 0.132 | I10: =Assumptions!H29 -> 0.13 | J10: =Assumptions!I29 -> 0.1275
A12: Reported anchors: Mar-2026 assets 808,857 · loans 425,720 · deposits 523,095 · NIEA 679,794 · total equity 86,000
A13: CET1 13.82% · CAR 16.95% · LCR 124.2% · LDR 81.4% · CASA 46.9% · NPL 1.76% · coverage 151.8% (ADCB Q1-26 MD&A).

Sheet Cash Flow
A1: Equity cash walk — retention vs distribution (AED mn)
A2: For a bank the meaningful cash statement is the capital walk.
E3: FY26E | F3: FY27E | G3: FY28E | H3: FY29E | I3: FY30E
A4: Net profit after tax | E4: ='Driver Build'!E14 -> 13741.71 | F4: ='Driver Build'!F14 -> 14935.997 | G4: ='Driver Build'!G14 -> 16793.14 | H4: ='Driver Build'!H14 -> 18721.221 | I4: ='Driver Build'!I14 -> 20688.054
A5: Dividends paid | E5: =-'Driver Build'!E17 -> -5221.8499 | F5: =-'Driver Build'!F17 -> -5526.3191 | G5: =-'Driver Build'!G17 -> -6045.5304 | H5: =-'Driver Build'!H17 -> -6365.2153 | I5: =-'Driver Build'!I17 -> -6827.0577
A6: Retained into common equity | E6: =E4+E5 -> 8519.8603 | F6: =F4+F5 -> 9409.6784 | G6: =G4+G5 -> 10747.61 | H6: =H4+H5 -> 12356.006 | I6: =I4+I5 -> 13860.996
A7: Δ CET1 required for RWA growth | E7: ='Driver Build'!E25 -> 7740 | F7: ='Driver Build'!F25 -> 7198.1 | G7: ='Driver Build'!G25 -> 6610.161 | H7: ='Driver Build'!H25 -> 6214.8997 | I7: ='Driver Build'!I25 -> 5262.2775
A8: Surplus / (call) vs requirement | E8: =E6-E7 -> 779.86032 | F8: =F6-F7 -> 2211.5784 | G8: =G6-G7 -> 4137.4486 | H8: =H6-H7 -> 6141.1064 | I8: =I6-I7 -> 8598.7184
A10: A positive bottom row funds buffer rebuild / optionality; a negative one forces payout or growth to give.

Sheet Summary Financials
A1: Summary financials — the one-page numbers block (AED mn)
C3: FY23 | D3: FY24 | E3: FY25 | F3: FY26E | G3: FY27E | H3: FY28E | I3: FY29E | J3: FY30E
A4: Operating income | C4: 16860 | D4: 19459 | E4: 22183 | F4: ='Driver Build'!E8 -> 24454.202 | G4: ='Driver Build'!F8 -> 27118.442 | H4: ='Driver Build'!G8 -> 30087.106 | I4: ='Driver Build'!H8 -> 33085.16 | J4: ='Driver Build'!I8 -> 36156.925
A5: Net profit after tax | C5: 8207 | D5: 9419 | E5: 11445 | F5: ='Driver Build'!E14 -> 13741.71 | G5: ='Driver Build'!F14 -> 14935.997 | H5: ='Driver Build'!G14 -> 16793.14 | I5: ='Driver Build'!H14 -> 18721.221 | J5: ='Driver Build'!I14 -> 20688.054
A6: Net loans | C6: 301700 | D6: 349972 | E6: 405967 | F6: ='Driver Build'!E4 -> 470921.72 | G6: ='Driver Build'!F4 -> 527432.33 | H6: ='Driver Build'!G4 -> 580175.56 | I6: ='Driver Build'!H4 -> 632391.36 | J6: ='Driver Build'!I4 -> 682982.67
A7: Customer deposits | C7: 363000 | D7: 421000 | E7: 499775 | F7: ='Balance Sheet'!F6 -> 579952.86 | G7: ='Balance Sheet'!G6 -> 649547.2 | H7: ='Balance Sheet'!H6 -> 714501.92 | I7: ='Balance Sheet'!I6 -> 778807.09 | J7: ='Balance Sheet'!J6 -> 841111.66
A8: DPS (AED) | C8: 0.56 | D8: 0.59 | E8: 0.63 | F8: ='Driver Build'!E16 -> 0.65997648 | G8: ='Driver Build'!F16 -> 0.69845757 | H8: ='Driver Build'!G16 -> 0.76407939 | I8: ='Driver Build'!H16 -> 0.80448356 | J8: ='Driver Build'!I16 -> 0.86285466
A10: Weighted central AED 19.7 vs spot 15.1 (+31%) · backtest PASS · MC T+60 median 15.09

Sheet Monte Carlo
A1: Monte Carlo — 50,000 simulated price paths
A2: Summary of the simulation; values, not formulas.
A3: Probability read (T+60)
A4: P(above spot) | B4: 49.7%
A5: P(+10%) vs P(−10%) | B5: 20.8% vs 18.9% (odds 1.1x)
A6: Median (move) | B6: AED 15.09 (-0.1%)
A7: 50% band (25th–75th) | B7: AED 13.95 – 16.32
A8: Touch ±10% within horizon | B8: 37.6% up · 34.3% down
A10: Percentiles (AED) | B10: T+20 | C10: T+60
A11: 5th | B11: 13.28 | C11: 12.04
A12: 25th | B12: 14.43 | C12: 13.95
A13: 50th | B13: 15.09 | C13: 15.09
A14: 75th | B14: 15.79 | C14: 16.32
A15: 95th | B15: 17.2 | C15: 18.87
A17: Median components: carry = ln(1+rf 3.65%) − ln(1+q 4.17%) ≈ -0.12% over 60d — carry ≈ 0 for this dividend-payer: total return ≈ rf, delivered as dividend.
A18: Volatility (60-day, log) 0.150 · fat-tailed shape (t, 4 d.o.f.) · calibration 1.07 — fitted on a 9-name UAE panel (this bank plus its ADX/DFM peers), so shape and width reflect the market, not one stock.
A20: Five-year backtest (walk-forward, 60-day horizon, non-overlapping; history from 2022 on a consistent trading calendar)
A21: Windows 14 · CRPS skill +0.0232 · pinball-0.5 +0.0019 · Winkler-90 +0.0780
A22: Coverage 50/80/90: 0.64/0.86/0.86 · PIT mean 0.54
A23: Bootstrap CI by block: 2→[0.004, 0.035] · 3→[0.002, 0.04] · 4→[0.003, 0.032] → ROBUST VERDICT: PASS
A24: PASS: the distribution is calibrated (coverage near nominal, PIT centred) AND beats the naive benchmark, with the skill margin holding above zero across every resampling scheme — a modest demonstrated edge.
A25: The simulation is centred on carry alone; the fundamental value gap from Section 1 is deliberately kept out of it.

Sheet Sensitivity
A1: Sensitivity — weighted central on Ke × terminal g; DDM grid; crux swings
A3: Weighted central (AED/share) | B3: g 3.0% | C3: g 3.5% | D3: g 4.0% | E3: g 4.5%
A4: Ke 9.6% | B4: 21.2 | C4: 22 | D4: 22.9 | E4: 24
A5: Ke 10.1% | B5: 19.8 | C5: 20.4 | D5: 21.2 | E5: 22
A6: Ke 10.6% | B6: 18.6 | C6: 19.1 | D6: 19.7 | E6: 20.3
A7: Ke 11.1% | B7: 17.5 | C7: 17.9 | D7: 18.4 | E7: 18.9
A8: Ke 11.6% | B8: 16.5 | C8: 16.9 | D8: 17.3 | E8: 17.7
A9: Ke 12.1% | B9: 15.7 | C9: 16 | D9: 16.3 | E9: 16.6
A11: DDM alone (AED/share) | B11: g 3.0% | C11: g 3.5% | D11: g 4.0% | E11: g 4.5%
A12: Ke 9.6% | B12: 23.5 | C12: 24.4 | D12: 25.4 | E12: 26.6
A13: Ke 10.1% | B13: 21.6 | C13: 22.3 | D13: 23 | E13: 23.9
A14: Ke 10.6% | B14: 19.9 | C14: 20.4 | D14: 21 | E14: 21.7
A15: Ke 11.1% | B15: 18.5 | C15: 18.9 | D15: 19.3 | E15: 19.9
A16: Ke 11.6% | B16: 17.2 | C16: 17.5 | D16: 17.9 | E16: 18.3
A17: Ke 12.1% | B17: 16.1 | C17: 16.3 | D17: 16.6 | E17: 16.9
A19: Crux swings in real units
A20: NIM path ±10bp across FY26–30 | B20: ≈ ±AED 0.9–1.1/sh on the central (NII ≈ avg NIEA × NIM; ~AED 0.9bn NPAT/yr per 10bp by FY28)
A21: Cost of risk ±10bp | B21: ≈ ∓AED 0.5/sh (≈ AED 0.5–0.6bn pre-tax per year on ~AED 550bn avg loans mid-path)
A22: Tax: IAE 9% persists vs DMTT 15% from FY27 | B22: +AED 1.3–1.5/sh if 9% persists through FY28 (sensitized; lapse date undisclosed)
A23: Conflict adder 0 ↔ 2.0pt on Ke | B23: central 23.0 (0pt) ↔ ~16.3 (Ke ~12.1%)
A24: Loan growth −4pt across the path | B24: ≈ −AED 1.5/sh via NII and FCFE; partially offset by lower ΔCET1 retention

Sheet Per-Share & Ratios
A1: Per-share & ratios dashboard (standardized panel)
C3: FY23 | D3: FY24 | E3: FY25 | F3: FY26E | G3: FY27E | H3: FY28E | I3: FY29E | J3: FY30E
A4: EPS (AED) | C4: 1.12 | D4: 1.29 | E4: 1.45 | F4: ='Driver Build'!E15 -> 1.7367802 | G4: ='Driver Build'!F15 -> 1.8877232 | H4: ='Driver Build'!G15 -> 2.1224428 | I4: ='Driver Build'!H15 -> 2.3661281 | J4: ='Driver Build'!I15 -> 2.6147111
A5: DPS (AED) | C5: 0.56 | D5: 0.59 | E5: 0.63 | F5: ='Driver Build'!E16 -> 0.65997648 | G5: ='Driver Build'!F16 -> 0.69845757 | H5: ='Driver Build'!G16 -> 0.76407939 | I5: ='Driver Build'!H16 -> 0.80448356 | J5: ='Driver Build'!I16 -> 0.86285466
A6: BVPS (AED) | C6: — | D6: — | E6: — | F6: ='Driver Build'!E19/Assumptions!$B$6 -> 10.998221 | G6: ='Driver Build'!F19/Assumptions!$B$6 -> 12.187487 | H6: ='Driver Build'!G19/Assumptions!$B$6 -> 13.54585 | I6: ='Driver Build'!H19/Assumptions!$B$6 -> 15.107495 | J6: ='Driver Build'!I19/Assumptions!$B$6 -> 16.859351
A7: P/E at spot | C7: =Assumptions!$B$5/C4 -> 13.482143 | D7: =Assumptions!$B$5/D4 -> 11.705426 | E7: =Assumptions!$B$5/E4 -> 10.413793 | F7: =Assumptions!$B$5/F4 -> 8.6942492 | G7: =Assumptions!$B$5/G4 -> 7.9990542 | H7: =Assumptions!$B$5/H4 -> 7.1144439 | I7: =Assumptions!$B$5/I4 -> 6.3817339 | J7: =Assumptions!$B$5/J4 -> 5.7750166
A8: P/B at spot | C8: — | D8: — | E8: — | F8: =Assumptions!$B$5/F6 -> 1.3729493 | G8: =Assumptions!$B$5/G6 -> 1.2389757 | H8: =Assumptions!$B$5/H6 -> 1.1147325 | I8: =Assumptions!$B$5/I6 -> 0.99950389 | J8: =Assumptions!$B$5/J6 -> 0.89564537
A9: Dividend yield | C9: =C5/Assumptions!$B$5 -> 0.037086093 | D9: =D5/Assumptions!$B$5 -> 0.039072848 | E9: =E5/Assumptions!$B$5 -> 0.041721854 | F9: =F5/Assumptions!$B$5 -> 0.043707052 | G9: =G5/Assumptions!$B$5 -> 0.046255469 | H9: =H5/Assumptions!$B$5 -> 0.050601284 | I9: =I5/Assumptions!$B$5 -> 0.053277057 | J9: =J5/Assumptions!$B$5 -> 0.057142693
A10: ROE % | C10: — | D10: 0.14 | E10: 0.153 | F10: ='Driver Build'!E20 -> 0.16604304 | G10: ='Driver Build'!F20 -> 0.16283507 | H10: ='Driver Build'!G20 -> 0.16495666 | I10: ='Driver Build'!H20 -> 0.16515545 | J10: ='Driver Build'!I20 -> 0.16358893
A11: CIR % | C11: 0.307 | D11: 0.31 | E11: 0.282 | F11: =Assumptions!E24 -> 0.27 | G11: =Assumptions!F24 -> 0.26 | H11: =Assumptions!G24 -> 0.255 | I11: =Assumptions!H24 -> 0.25 | J11: =Assumptions!I24 -> 0.245
A12: NIM % | C12: 0.0283 | D12: 0.0258 | E12: 0.0245 | F12: =Assumptions!E22 -> 0.023 | G12: =Assumptions!F22 -> 0.0226 | H12: =Assumptions!G22 -> 0.0228 | I12: =Assumptions!H22 -> 0.023 | J12: =Assumptions!I22 -> 0.0232
A13: NPL % | C13: 0.0373 | D13: 0.0304 | E13: 0.0183 | F13: — | G13: — | H13: — | I13: — | J13: —
A15: FY23/FY24 EPS on the pre-rights 7,319.9mn count; forecasts on 7,912.2mn (the rights base-changer).

Sheet Peer & Sector
A1: Peer set — UAE large-cap banks
A3: Name | B3: Latest sourced print | C3: Read
A4: First Abu Dhabi Bank (FAB) | B4: Q1-26 net income AED 4.75bn; EPS 0.43 (beat); next results 29-Jul-26 | C4: Largest peer; sets the sector multiple ceiling
A5: Emirates NBD (ENBD) | B5: Not re-sourced this session (DFM-listed) | C5: Dubai flagship; row to refresh at publish
A6: Dubai Islamic Bank (DIB) | B6: Not re-sourced this session | C6: Largest Islamic peer
A7: Abu Dhabi Islamic Bank (ADIB) | B7: FY24 NPAT AED 6.1bn (+16%); DPS 0.83 | C7: Islamic AD peer; premium ROE franchise
A8: ADCB (this study) | B8: Q1-26 NPAT AED 3.361bn; RoAE 16.3%; NPL 1.76% | C8: #3 by assets; 19 straight quarters of PBT growth
A10: Sector: UAE bank assets AED 4.97tn (Jun-25); system credit demand robust; deposit competition keeps funding sticky as
A11: rates fall; AI adoption is the cost-curve battleground. Sector P/B input on Assumptions (1.55×) reflects the large-cap band.
