Workbook

Sheet READ FIRST
A1: Abu Dhabi Islamic Bank PJSC (ADX: ADIB) — valuation model
A2: Testahil · Independent Valuation Study — Educational Analysis · Not investment advice · 11 July 2026
A5: WHAT THIS IS. A working model, not a recommendation. It contains no rating and no price target. It produces fair-value ranges and probability distributions — distributions, not tips.
A7: WHO WE ARE NOT. The preparer is not licensed by the FRA, the SCA or any securities regulator, holds no CFA charter, and this workbook has not been reviewed by any authority.
A9: HOW TO USE IT. Every input in the model lives once, in blue, on the Assumptions sheet. Every other cell on every other sheet is a formula. Change one blue cell and the whole model reprices — that is the point of it. If you disagree with a driver, edit it and watch the answer move.
A11: THE TWO CLOCKS. The weighted central (AED 21.23) is a risk-adjusted ~12-month anchor built from five independent lenses. The only genuinely 3-month figures are the Monte Carlo percentiles on the Monte Carlo sheet. Never read one clock as the other.
A13: PROVENANCE. Every historical figure is taken from ADIB's own filings — the FY2023, FY2024 and FY2025 Management Discussion & Analysis, the FY2025 earnings presentation, and the Q1-2026 MD&A. No aggregator was used for any financial-statement line. Market prices, index levels and yields are market data and are sourced as such.
A15: CALIBRATION. Step 0 verdict for ADIB: PARITY, on a CRPS skill of +0.0093 against a carry-anchored random walk across 14 walk-forward windows. The tail and width parameters are NOT chosen — they are read live from the engine registry, where they are fitted to a 14-name UAE panel. The distribution is honestly calibrated and validated on that panel, but on ADIB's own 14 windows the confidence interval spans zero, so no single-name forecasting edge has been demonstrated. Read it as a base rate, not a promise.
A17: CRUX. ADIB trades at 3.31x book against a sector at 1.55x. Its 28.8% return on equity earns most of that premium — but not all of it. Everything in this model turns on how long a ~25% ROE lasts.
A20: Colour key: BLUE = a hard-coded input you may edit · BLACK = a formula · GREEN = a link to another sheet.

Sheet Summary
A1: Summary — the whole answer in one view
A2: Every figure below is a live link. Nothing on this sheet is typed.
A4: THE BOTTOM LINE
A5: Spot (AED, 03-Jul-2026 close) | B5: =Assumptions!$B$5 -> 21.76
A6: FAIR-VALUE RANGE — the primary object (see §1.7)
A7: Market-anchored family (relative / normalized) | B7: =_xlfn.CONCAT(TEXT('Relative & Normalized'!$B$14,"0.00")," – ",TEXT('Relative & Normalized'!$B$24,"0.00")) -> 17.94 – 19.00
A8: Cash-flow family (DDM / residual income / FCFE) | B8: =_xlfn.CONCAT(TEXT(DDM!$B$14,"0.00")," – ",TEXT(FCFE!$B$13,"0.00")) -> 22.54 – 23.48
A9: Weighted central (a probability-weighted SUMMARY — not a target) | B9: ='Relative & Normalized'!$B$30 -> 21.230906
A10: Implied gap to central | B10: =B9/B5-1 -> -0.024314977
A12: THE FIVE LENSES
A13: Dividend discount model (primary) | B13: =DDM!$B$14 -> 22.541783
A14: Free cash flow to equity (equity DCF) | B14: =FCFE!$B$13 -> 23.481366
A15: Residual income | B15: ='Residual Income'!$B$14 -> 22.541783
A16: Relative multiples (ROE-adjusted) | B16: ='Relative & Normalized'!$B$14 -> 17.9374
A17: Normalized / through-cycle | B17: ='Relative & Normalized'!$B$24 -> 19.002198
A19: WHAT THE PRICE IMPLIES
A20: Price / book (latest reported, Q1-26) | B20: =Assumptions!$B$5/'Per-Share & Ratios'!$B$5 -> 3.3116413
A21: Price / book (last audited FY, Dec-25) | B21: =Assumptions!$B$5/'Per-Share & Ratios'!$B$6 -> 3.0318917
A22: Forward P/E (FY26E) | B22: =Assumptions!$B$5/'Driver Build'!$E$15 -> 11.85008
A23: Perpetual ROE the price implies at Ke | B23: =Assumptions!$B$17+B20*(Assumptions!$B$16-Assumptions!$B$17) -> 0.25757483
A24: ADIB actual ROE — FY25 reported | B24: =Assumptions!$B$45 -> 0.288
A25: ADIB target ROE — management 2030 | B25: =Assumptions!$B$46 -> 0.25
A26: UAE bank sector ROE | B26: =Assumptions!$B$36 -> 0.183
A28: THREE-MONTH VIEW (Monte Carlo — the only 3-month figures here)
A29: P(price above spot) at T+60 | B29: ='Monte Carlo'!$B$18 -> 0.4955
A30: Median outcome at T+60 | B30: ='Monte Carlo'!$B$20 -> 21.727
A31: 50% band (25th–75th) | B31: =_xlfn.CONCAT(TEXT('Monte Carlo'!$C$11,"0.00")," – ",TEXT('Monte Carlo'!$E$11,"0.00")) -> 19.81 – 23.84

Sheet Assumptions
A1: Assumptions — the single blue-input layer
A2: Every input in the model lives here, once, in blue. Every other cell in this workbook is a formula.
A4: MARKET
A5: Spot (AED, 03-Jul-2026 close) | B5: 21.76 | K5: Last close in the OHLC series used for the Monte Carlo. Market data.
A6: Shares outstanding (mn) | B6: 3632 | K6: Share capital AED 3,632mn at AED 1 par — ADIB FY25 MD&A balance sheet.
A7: Market cap (AED bn) | B7: =B5*B6/1000 -> 79.03232
A8: FY25 DPS (AED) — the carry anchor's dividend yield | B8: 0.9705 | K8: 97.05 fils, AGM-approved 04-Mar-2026 (ADIB FY25 MD&A: total payout AED 3,525mn = 50% of net profit).
A10: COST OF EQUITY (Ke)
A11: Risk-free (AED 10Y — constructed, flagged) | B11: 0.047 | K11: UST 10Y 4.58% + ~12bp AED T-bond spread (UAE MoF May-2026 auctions). FLAGGED estimate: no live AED long-curve screen exists. House peg rule: never shortcut rf to the US Treasury yield.
A12: ERP — rating-based | B12: 0.0487 | K12: Damodaran ORIGINAL ctryprem.html, 5-Jan-2026 vintage, ABU DHABI row: Aa2, CRP 0.64% + mature-market 4.23%.
A13: ERP — CDS-based (the "more current" alternative) | B13: 0.0493 | K13: Same row, sovereign CDS 0.46% -> CDS-based ERP 4.93%. Both bases published, per house rule.
A14: Beta | B14: 1 | K14: ASSUMED 1.00. A regression against the FTSE ADX General Index was genuinely attempted; only a 21-observation stale window was obtainable, failing RegressionBetaAttempt.is_usable() (n>=24). Sensitized 0.8-1.3 on the Sensitivity sheet. Never a foreign sector-peer beta.
A15: Regional-conflict adder | B15: 0.01 | K15: 2026 Iran/Hormuz conflict. Same 1.0pt adder as the ADCB study (same market, same week). The ceasefire frayed on ~10-Jul-2026 — see Sensitivity for the 0 <-> 2.5pt map.
A16: Ke = rf + beta x ERP + adder | B16: =B11+B14*B12+B15 -> 0.1057
A17: Terminal growth g | B17: 0.04 | K17: UAE nominal GDP ~7% (real 5.3% + inflation 1.8%, ADIB FY25 deck). A bank does not outgrow nominal GDP in perpetuity. Sensitized 3.0-4.5%.
A18: Terminal ROE | B18: 0.2 | K18: LEDGER ROW. Deliberate fade from management's ~25% 2030 target toward — but still above — the 18.3% sector average. THE crux: see the Sensitivity sheet's Ke x terminal-ROE grid.
A20: DRIVER PATHS (FY26E–FY30E) | E20: FY26E | F20: FY27E | G20: FY28E | H20: FY29E | I20: FY30E
A21: Gross financing growth % | E21: 0.13 | F21: 0.12 | G21: 0.11 | H21: 0.1 | I21: 0.09 | K21: FY26 guidance 12-14% (ADIB FY25 earnings presentation, Outlook & Guidance). Glide to 9% by FY30. Implies total assets ~1.68x FY25 by 2030 vs management's 1.7-1.9x target — at/below the bottom of the range.
A22: Net profit margin % (on avg earning assets) | E22: 0.039 | F22: 0.0382 | G22: 0.0376 | H22: 0.0372 | I22: 0.037 | K22: FY26 guidance 3.8-4.0%; Q1-26 printed 3.91%. The grind to 3.70% is MIX (retail 56%->55%, GRE 24%->26%), not rates — the Fed is now expected to hold or hike, which is supportive.
A23: Non-funded income growth % | E23: 0.04 | F23: 0.08 | G23: 0.08 | H23: 0.08 | I23: 0.08 | K23: Q1-26 ran +4% YoY on softer transaction activity (official). FY26 held at +4%; recovery to +8% after.
A24: Cost-to-income ratio % | E24: 0.294 | F24: 0.29 | G24: 0.285 | H24: 0.28 | I24: 0.275 | K24: FY26 guidance <30%; Q1-26 printed 29.6%. Lands at 27.5% in FY30 — the TOP of the 26-28% 2030 target band.
A25: Cost of risk % (on avg GROSS financing) | E25: 0.0046 | F25: 0.0046 | G25: 0.0044 | H25: 0.0043 | I25: 0.0042 | K25: DUAL-FRAMED: on this basis FY25 actual = 0.41%. On ADIB's own stated basis these map to ~50/50/48/46/45bp — mid-guidance (40-60bp), above the FY25 print of 44bp.
A26: Effective tax rate % | E26: 0.13 | F26: 0.16 | G26: 0.16 | H26: 0.16 | I26: 0.16 | K26: CRUX. FY23 4.0% -> FY24 11.2% -> FY25 12.7% -> Q1-26 12.9%. The step to 16% from FY27 is the CONSERVATIVE placement of the UAE DMTT 15% top-up on the UAE leg, net of the substance-based income exclusion. ADIB has NOT disclosed its Pillar Two position (negative search, Sweep F24). Sensitized 13% <-> 17.3%.
A27: Dividend payout % | E27: 0.5 | F27: 0.5 | G27: 0.51 | H27: 0.52 | I27: 0.53 | K27: A policy, not a whim: 48.5 / 49.2 / 49.4 / 49.7 / 49.9% over FY21-25 (official). Drifts up as growth slows.
A29: BALANCE-SHEET & CAPITAL MECHANICS
A30: Avg earning assets / avg net financing (x) | B30: 1.12 | K30: LEDGER ROW. Disclosed trend 1.221 (FY23) -> 1.172 (FY24) -> 1.134 (FY25): financing is outgrowing the other earning assets. One notch further down, then held flat.
A31: Net / gross financing (x) | B31: 0.978 | K31: FY25 97.7%, Q1-26 97.9% (official). Held at 97.8%.
A32: Credit RWA / gross financing (x) | B32: 0.88 | K32: FY25: credit RWA 163.5bn / gross financing 185.6bn = 88.1% (FY25 earnings presentation p.27). Reproduces FY25 total RWA to within 0.06%.
A33: CET1 target % | B33: 0.12 | K33: Held flat at the 12.0% level management has actually run for four straight years (12.23 / 12.07 / 12.02 / 12.0%).
A34: AT1 sukuk coupon (AED mn, annual) | B34: 353 | K34: USD 750mn perpetual Mudaraba sukuk @7.25% (= AED 2,754mn) -> AED 199.7mn, plus the AED 2,000mn Abu Dhabi Government Tier 1 sukuk -> AED 153.3mn. Ties to the AED 4,754mn AT1 on the balance sheet.
A35: Non-controlling interests FY25 (AED mn) | B35: 376 | K35: DERIVED, LEDGER ROW: PAT 7,070 - AT1 353 - attributable (EPS 1.746 x 3,632 shares) = 376. Mostly ADIB Egypt (~47% minority). Grown 8%/yr.
A36: UAE bank sector ROE | B36: 0.183 | K36: Alvarez & Marsal UAE Banking Pulse FY2025 (top-10 listed banks, built from public filings): sector RoE 18.3%.
A37: SECTOR MARKS (relative lens) & BENCHMARKS
A38: UAE bank sector P/B (large-cap band) | B38: 1.55 | K38: Same mark used in the ADCB study (10-Jul-2026). Cross-check: A&M puts the top-10 at 1.64x P/TBV.
A39: UAE bank sector P/TBV (cross-check) | B39: 1.64 | K39: Alvarez & Marsal UAE Banking Pulse FY2025.
A40: UAE bank sector forward P/E | B40: 9 | K40: UAE banks industry average forward P/E (~9x).
A41: Normalized / through-cycle ROE | B41: 0.23 | K41: LEDGER ROW. Below management's 25% 2030 target, above the FY21-25 average of 23.8%. The FY21-22 ROEs (14% / 21%) carried a legacy NPA problem since fixed (NPA 8.9% -> 2.8%), so a flat 5-year average understates it.
A43: BENCHMARKS (memo only — no formula depends on these)
A45: ADIB FY25 ROAE — reported | B45: 0.288 | K45: ADIB FY25 MD&A: ROAE 28.8%.
A46: ADIB 2030 ROE target — management | B46: 0.25 | K46: ADIB FY25 earnings presentation, "Five-Year Strategy as part of 2035 Vision": ROE ~25%.

Sheet Driver Build
A1: Driver build — every forward line, from the drivers on Assumptions
A2: Nothing here is typed. Column D is the FY25 actual (linked from the Income Statement); E–I are formulas.
D3: FY25A | E3: FY26E | F3: FY27E | G3: FY28E | H3: FY29E | I3: FY30E
A4: Gross customer financing | D4: ='Balance Sheet'!D5 -> 185600 | E4: =D4*(1+Assumptions!E$21) -> 209728 | F4: =E4*(1+Assumptions!F$21) -> 234895.36 | G4: =F4*(1+Assumptions!G$21) -> 260733.85 | H4: =G4*(1+Assumptions!H$21) -> 286807.23 | I4: =H4*(1+Assumptions!I$21) -> 312619.89
A5: Net customer financing | D5: ='Balance Sheet'!D6 -> 181376 | E5: =E4*Assumptions!$B$31 -> 205113.98 | F5: =F4*Assumptions!$B$31 -> 229727.66 | G5: =G4*Assumptions!$B$31 -> 254997.7 | H5: =H4*Assumptions!$B$31 -> 280497.48 | I5: =I4*Assumptions!$B$31 -> 305742.25
A6: Average net financing | E6: =AVERAGE(D5,E5) -> 193244.99 | F6: =AVERAGE(E5,F5) -> 217420.82 | G6: =AVERAGE(F5,G5) -> 242362.68 | H6: =AVERAGE(G5,H5) -> 267747.59 | I6: =AVERAGE(H5,I5) -> 293119.86
A7: Average gross financing | E7: =AVERAGE(D4,E4) -> 197664 | F7: =AVERAGE(E4,F4) -> 222311.68 | G7: =AVERAGE(F4,G4) -> 247814.6 | H7: =AVERAGE(G4,H4) -> 273770.54 | I7: =AVERAGE(H4,I4) -> 299713.56
A8: Average earning assets (NIEA) | E8: =E6*Assumptions!$B$30 -> 216434.39 | F8: =F6*Assumptions!$B$30 -> 243511.32 | G8: =G6*Assumptions!$B$30 -> 271446.21 | H8: =H6*Assumptions!$B$30 -> 299877.3 | I8: =I6*Assumptions!$B$30 -> 328294.25
A9: Funded income = NPM x NIEA | D9: ='Income Statement'!D4 -> 7553 | E9: =E8*Assumptions!E$22 -> 8440.9413 | F9: =F8*Assumptions!F$22 -> 9302.1325 | G9: =G8*Assumptions!G$22 -> 10206.377 | H9: =H8*Assumptions!H$22 -> 11155.436 | I9: =I8*Assumptions!I$22 -> 12146.887
A10: Non-funded income | D10: ='Income Statement'!D5 -> 4751 | E10: =D10*(1+Assumptions!E$23) -> 4941.04 | F10: =E10*(1+Assumptions!F$23) -> 5336.3232 | G10: =F10*(1+Assumptions!G$23) -> 5763.2291 | H10: =G10*(1+Assumptions!H$23) -> 6224.2874 | I10: =H10*(1+Assumptions!I$23) -> 6722.2304
A11: Total operating income | D11: =D9+D10 -> 12304 | E11: =E9+E10 -> 13381.981 | F11: =F9+F10 -> 14638.456 | G11: =G9+G10 -> 15969.606 | H11: =H9+H10 -> 17379.723 | I11: =I9+I10 -> 18869.117
A12: Operating expenses = − CIR x operating income | D12: ='Income Statement'!D7 -> -3525 | E12: =-E11*Assumptions!E$24 -> -3934.3025 | F12: =-F11*Assumptions!F$24 -> -4245.1522 | G12: =-G11*Assumptions!G$24 -> -4551.3378 | H12: =-H11*Assumptions!H$24 -> -4866.3224 | I12: =-I11*Assumptions!I$24 -> -5189.0073
A13: Impairment = − CoR x avg gross financing | D13: ='Income Statement'!D9 -> -678 | E13: =-E7*Assumptions!E$25 -> -909.2544 | F13: =-F7*Assumptions!F$25 -> -1022.6337 | G13: =-G7*Assumptions!G$25 -> -1090.3843 | H13: =-H7*Assumptions!H$25 -> -1177.2133 | I13: =-I7*Assumptions!I$25 -> -1258.797
A14: Profit before tax | D14: =D11+D12+D13 -> 8101 | E14: =E11+E12+E13 -> 8538.4244 | F14: =F11+F12+F13 -> 9370.6698 | G14: =G11+G12+G13 -> 10327.884 | H14: =H11+H12+H13 -> 11336.187 | I14: =I11+I12+I13 -> 12421.313
A15: EPS (AED) — attributable to ordinary shareholders | D15: ='Income Statement'!D16 -> 1.74587 | E15: ='Income Statement'!E16 -> 1.8362746 | F15: ='Income Statement'!F16 -> 1.9492831 | G15: ='Income Statement'!G16 -> 2.1610053 | H15: ='Income Statement'!H16 -> 2.3837702 | I15: ='Income Statement'!I16 -> 2.623468
A16: DPS (AED) = payout x EPS | D16: =Assumptions!$B$8 -> 0.9705 | E16: =E15*Assumptions!E$27 -> 0.91813728 | F16: =F15*Assumptions!F$27 -> 0.97464155 | G16: =G15*Assumptions!G$27 -> 1.1021127 | H16: =H15*Assumptions!H$27 -> 1.2395605 | I16: =I15*Assumptions!I$27 -> 1.390438
A17: RWA = credit + market + operational | D17: ='Balance Sheet'!D22 -> 183637 | E17: =E4*Assumptions!$B$32+2000+18200*(E11/$D$11) -> 206355.18 | F17: =F4*Assumptions!$B$32+2000+18200*(F11/$D$11) -> 230361.03 | G17: =G4*Assumptions!$B$32+2000+18200*(G11/$D$11) -> 255067.93 | H17: =H4*Assumptions!$B$32+2000+18200*(H11/$D$11) -> 280098.34 | I17: =I4*Assumptions!$B$32+2000+18200*(I11/$D$11) -> 305016.58
A18: Change in RWA | E18: =E17-D17 -> 22718.183 | F18: =F17-E17 -> 24005.846 | G18: =G17-F17 -> 24706.901 | H18: =H17-G17 -> 25030.414 | I18: =I17-H17 -> 24918.236
A19: Equity retained for RWA growth = ΔRWA x CET1 target | E19: =E18*Assumptions!$B$33 -> 2726.182 | F19: =F18*Assumptions!$B$33 -> 2880.7015 | G19: =G18*Assumptions!$B$33 -> 2964.8281 | H19: =H18*Assumptions!$B$33 -> 3003.6497 | I19: =I18*Assumptions!$B$33 -> 2990.1883
A20: Free cash flow to equity = attributable − equity retained | E20: ='Income Statement'!E15-E19 -> 3943.1672 | F20: ='Income Statement'!F15-F19 -> 4199.0947 | G20: ='Income Statement'!G15-G19 -> 4883.943 | H20: ='Income Statement'!H15-H19 -> 5654.2037 | I20: ='Income Statement'!I15-I19 -> 6538.2474
A22: Note — market RWA (AED 2,000mn, held flat) and operational RWA (AED 18,200mn FY25, grown with operating income) are taken from ADIB's FY25 earnings presentation p.27. The credit-RWA density reproduces FY25 total RWA (183,637) to within 0.06%.

Sheet DDM
A1: Dividend discount model — the primary lens
A2: For a bank, deposits are an operating input, not a financing choice — everything discounts at Ke. ADIB's payout has not left 48.5–49.9% in five years, so the policy is the cash flow.
E3: FY26E | F3: FY27E | G3: FY28E | H3: FY29E | I3: FY30E
A4: DPS (AED) | E4: ='Driver Build'!E16 -> 0.91813728 | F4: ='Driver Build'!F16 -> 0.97464155 | G4: ='Driver Build'!G16 -> 1.1021127 | H4: ='Driver Build'!H16 -> 1.2395605 | I4: ='Driver Build'!I16 -> 1.390438
A5: Discount factor = 1/(1+Ke)^t | E5: =1/POWER(1+Assumptions!$B$16,1) -> 0.90440445 | F5: =1/POWER(1+Assumptions!$B$16,2) -> 0.81794741 | G5: =1/POWER(1+Assumptions!$B$16,3) -> 0.73975528 | H5: =1/POWER(1+Assumptions!$B$16,4) -> 0.66903796 | I5: =1/POWER(1+Assumptions!$B$16,5) -> 0.60508091
A6: PV of dividend | E6: =E4*E5 -> 0.83036744 | F6: =F4*F5 -> 0.79720553 | G6: =G4*G5 -> 0.81529367 | H6: =H4*H5 -> 0.82931304 | I6: =I4*I5 -> 0.84132751
A8: TERMINAL BLOCK — one steady state, shared with FCFE and Residual Income
A9: Closing common equity FY30 (AED mn) | B9: ='Balance Sheet'!I17 -> 45421.605
A10: Terminal payout = 1 − g / terminal ROE | B10: =1-Assumptions!$B$17/Assumptions!$B$18 -> 0.8
A11: Terminal earnings (FY31) = terminal ROE x FY30 closing book | B11: =Assumptions!$B$18*B9 -> 9084.321
A12: Terminal dividend (FY31) = terminal payout x terminal earnings | B12: =B10*B11 -> 7267.4568
A13: Terminal value at (Ke − g), AED mn | B13: =B12/(Assumptions!$B$16-Assumptions!$B$17) -> 110615.78
A14: DDM FAIR VALUE (AED / share) | B14: =SUM(E6:I6)+B13*I5/Assumptions!$B$6 -> 22.541783
A15: of which: Σ PV of explicit dividends FY26–30 | B15: =SUM(E6:I6) -> 4.1135072
A16: of which: PV of terminal value | B16: =B13*I5/Assumptions!$B$6 -> 18.428276
A17: Terminal value as % of DDM (dependency disclosure) | B17: =B16/B14 -> 0.81751633
A18: vs spot | B18: =B14/Assumptions!$B$5-1 -> 0.035927524
A20: Terminal-value dependency: the terminal block carries most of this number, which is normal for a bank growing at 11–13% on a ~50% payout — but it means the DDM is a claim about ADIB's STEADY STATE (the terminal ROE on Assumptions!B18), not about the next five dividends. The Sensitivity sheet stresses exactly that claim.

Sheet FCFE
A1: Equity DCF (FCFE) — what the bank COULD pay after funding its own growth
A2: The full build: revenue -> costs -> provisions -> tax -> profit -> less the fresh equity RWA growth consumes -> free cash flow to equity -> discount factor -> PV. Shown inline, never output-only.
E3: FY26E | F3: FY27E | G3: FY28E | H3: FY29E | I3: FY30E
A4: Net revenue from funds (funded income) | E4: ='Driver Build'!E9 -> 8440.9413 | F4: ='Driver Build'!F9 -> 9302.1325 | G4: ='Driver Build'!G9 -> 10206.377 | H4: ='Driver Build'!H9 -> 11155.436 | I4: ='Driver Build'!I9 -> 12146.887
A5: Non-funded income | E5: ='Driver Build'!E10 -> 4941.04 | F5: ='Driver Build'!F10 -> 5336.3232 | G5: ='Driver Build'!G10 -> 5763.2291 | H5: ='Driver Build'!H10 -> 6224.2874 | I5: ='Driver Build'!I10 -> 6722.2304
A6: Total operating income | E6: ='Driver Build'!E11 -> 13381.981 | F6: ='Driver Build'!F11 -> 14638.456 | G6: ='Driver Build'!G11 -> 15969.606 | H6: ='Driver Build'!H11 -> 17379.723 | I6: ='Driver Build'!I11 -> 18869.117
A7: Operating expenses | E7: ='Driver Build'!E12 -> -3934.3025 | F7: ='Driver Build'!F12 -> -4245.1522 | G7: ='Driver Build'!G12 -> -4551.3378 | H7: ='Driver Build'!H12 -> -4866.3224 | I7: ='Driver Build'!I12 -> -5189.0073
A8: Pre-provision operating profit | E8: =E6+E7 -> 9447.6788 | F8: =F6+F7 -> 10393.304 | G8: =G6+G7 -> 11418.269 | H8: =H6+H7 -> 12513.401 | I8: =I6+I7 -> 13680.11
A9: Impairment charge | E9: ='Driver Build'!E13 -> -909.2544 | F9: ='Driver Build'!F13 -> -1022.6337 | G9: ='Driver Build'!G13 -> -1090.3843 | H9: ='Driver Build'!H13 -> -1177.2133 | I9: ='Driver Build'!I13 -> -1258.797
A10: Profit before tax | E10: =E8+E9 -> 8538.4244 | F10: =F8+F9 -> 9370.6698 | G10: =G8+G9 -> 10327.884 | H10: =H8+H9 -> 11336.187 | I10: =I8+I9 -> 12421.313
A11: Tax | E11: ='Income Statement'!E11 -> -1109.9952 | F11: ='Income Statement'!F11 -> -1499.3072 | G11: ='Income Statement'!G11 -> -1652.4615 | H11: ='Income Statement'!H11 -> -1813.79 | I11: ='Income Statement'!I11 -> -1987.4101
A12: Profit after tax | E12: =E10+E11 -> 7428.4292 | F12: =F10+F11 -> 7871.3626 | G12: =G10+G11 -> 8675.4228 | H12: =H10+H11 -> 9522.3973 | I12: =I10+I11 -> 10433.903
A13: FCFE FAIR VALUE (AED / share) | B13: =B27/B28 -> 23.481366
A14: less: AT1 sukuk coupon | E14: ='Income Statement'!E13 -> -353 | F14: ='Income Statement'!F13 -> -353 | G14: ='Income Statement'!G13 -> -353 | H14: ='Income Statement'!H13 -> -353 | I14: ='Income Statement'!I13 -> -353
A15: less: non-controlling interests | E15: ='Income Statement'!E14 -> -406.08 | F15: ='Income Statement'!F14 -> -438.5664 | G15: ='Income Statement'!G14 -> -473.65171 | H15: ='Income Statement'!H14 -> -511.54385 | I15: ='Income Statement'!I14 -> -552.46736
A16: Attributable to ordinary shareholders | E16: =E12+E14+E15 -> 6669.3492 | F16: =F12+F14+F15 -> 7079.7962 | G16: =G12+G14+G15 -> 7848.7711 | H16: =H12+H14+H15 -> 8657.8534 | I16: =I12+I14+I15 -> 9528.4357
A17: less: equity retained for RWA growth | E17: =-'Driver Build'!E19 -> -2726.182 | F17: =-'Driver Build'!F19 -> -2880.7015 | G17: =-'Driver Build'!G19 -> -2964.8281 | H17: =-'Driver Build'!H19 -> -3003.6497 | I17: =-'Driver Build'!I19 -> -2990.1883
A18: FREE CASH FLOW TO EQUITY | E18: =E16+E17 -> 3943.1672 | F18: =F16+F17 -> 4199.0947 | G18: =G16+G17 -> 4883.943 | H18: =H16+H17 -> 5654.2037 | I18: =I16+I17 -> 6538.2474
A19: Discount factor at Ke | E19: =1/POWER(1+Assumptions!$B$16,1) -> 0.90440445 | F19: =1/POWER(1+Assumptions!$B$16,2) -> 0.81794741 | G19: =1/POWER(1+Assumptions!$B$16,3) -> 0.73975528 | H19: =1/POWER(1+Assumptions!$B$16,4) -> 0.66903796 | I19: =1/POWER(1+Assumptions!$B$16,5) -> 0.60508091
A20: PV of FCFE | E20: =E18*E19 -> 3566.218 | F20: =F18*F19 -> 3434.6387 | G20: =G18*G19 -> 3612.9226 | H20: =H18*H19 -> 3782.8769 | I20: =I18*I19 -> 3956.1687
A22: TERMINAL VALUE & BRIDGE TO PER-SHARE
A23: Σ PV of explicit FCFE (FY26–30) | B23: =SUM(E20:I20) -> 18352.825
A24: Terminal FCFE (FY31) = steady-state payout x terminal earnings | B24: =DDM!$B$12 -> 7267.4568
A25: Terminal value = terminal FCFE / (Ke − g) | B25: =DDM!$B$13 -> 110615.78
A26: PV of terminal value | B26: =B25*I19 -> 66931.497
A27: Equity value (AED mn) | B27: =B23+B26 -> 85284.322
A28: ÷ shares outstanding (mn) | B28: =Assumptions!$B$6 -> 3632
A29: Terminal value as % of equity value | B29: =B26/B27 -> 0.78480424
A30: vs spot | B30: =B13/Assumptions!$B$5-1 -> 0.079106905
A32: RECONCILIATION: why FCFE exceeds the DDM
A33: Surplus capital generated FY26–30 (retained earnings above RWA needs), PV per share | B33: =B13-DDM!$B$14 -> 0.93958335
A34: The two lenses share ONE terminal steady state, so they can differ only inside the explicit window. FCFE counts the surplus capital ADIB generates as growth slows; the DDM only collects it later, through a bigger terminal book. B33 is that difference, and it is the whole of it.

Sheet Residual Income
A1: Residual income — book value plus the value of returns above the cost of equity
A2: The lens least dependent on a terminal assumption: more than half the answer is already on the balance sheet. Under clean surplus this MUST reconcile to the DDM — see row 16.
E3: FY26E | F3: FY27E | G3: FY28E | H3: FY29E | I3: FY30E
A4: Opening common equity | E4: ='Balance Sheet'!E16 -> 26067 | F4: ='Balance Sheet'!F16 -> 29401.675 | G4: ='Balance Sheet'!G16 -> 32941.573 | H4: ='Balance Sheet'!H16 -> 36787.471 | I4: ='Balance Sheet'!I16 -> 40943.24
A5: Equity charge = Ke x opening equity | E5: =-E4*Assumptions!$B$16 -> -2755.2819 | F5: =-F4*Assumptions!$B$16 -> -3107.757 | G5: =-G4*Assumptions!$B$16 -> -3481.9242 | H5: =-H4*Assumptions!$B$16 -> -3888.4356 | I5: =-I4*Assumptions!$B$16 -> -4327.7005
A6: Attributable profit | E6: ='Income Statement'!E15 -> 6669.3492 | F6: ='Income Statement'!F15 -> 7079.7962 | G6: ='Income Statement'!G15 -> 7848.7711 | H6: ='Income Statement'!H15 -> 8657.8534 | I6: ='Income Statement'!I15 -> 9528.4357
A7: Residual income | E7: =E6+E5 -> 3914.0673 | F7: =F6+F5 -> 3972.0392 | G7: =G6+G5 -> 4366.8469 | H7: =H6+H5 -> 4769.4178 | I7: =I6+I5 -> 5200.7352
A8: Discount factor | E8: =1/POWER(1+Assumptions!$B$16,1) -> 0.90440445 | F8: =1/POWER(1+Assumptions!$B$16,2) -> 0.81794741 | G8: =1/POWER(1+Assumptions!$B$16,3) -> 0.73975528 | H8: =1/POWER(1+Assumptions!$B$16,4) -> 0.66903796 | I8: =1/POWER(1+Assumptions!$B$16,5) -> 0.60508091
A9: PV of residual income | E9: =E7*E8 -> 3539.8999 | F9: =F7*F8 -> 3248.9192 | G9: =G7*G8 -> 3230.398 | H9: =H7*H8 -> 3190.9216 | I9: =I7*I8 -> 3146.8656
A11: Opening book value (FY25 common equity, AED mn) | B11: ='Balance Sheet'!D16 -> 26067
A12: Σ PV of explicit residual income | B12: =SUM(E9:I9) -> 16357.004
A13: PV of terminal RI = FY30 book x (terminal ROE − Ke) / (Ke − g) | B13: ='Balance Sheet'!I17*(Assumptions!$B$18-Assumptions!$B$16)/(Assumptions!$B$16-Assumptions!$B$17)*I8 -> 39447.751
A14: RESIDUAL-INCOME FAIR VALUE (AED / share) | B14: =(B11+B12+B13)/Assumptions!$B$6 -> 22.541783
A15: Implied P/B on current book | B15: =(B11+B12+B13)/B11 -> 3.14082
A16: CHECK: RI minus DDM (must be ~0 under clean surplus) | B16: =B14-DDM!$B$14 -> 0
A17: vs spot | B17: =B14/Assumptions!$B$5-1 -> 0.035927524

Sheet Relative & Normalized
A1: Relative multiples (ROE-adjusted) and the normalized through-cycle value
A2: A bank's justified P/B is LINEAR in (ROE − g), not proportional to ROE. So the sector mark tells us what one point of ROE is worth today, and ADIB's premium must be earned on that scale.
A4: RELATIVE — what the sector pays for this ROE
A5: UAE bank sector P/B | B5: =Assumptions!$B$38 -> 1.55
A6: UAE bank sector ROE | B6: =Assumptions!$B$36 -> 0.183
A7: ADIB ROE (FY25 reported — like-for-like with the sector mark) | B7: =Assumptions!$B$45 -> 0.288
A8: ROE-justified premium = (ROE_ADIB − g) / (ROE_sector − g) | B8: =(B7-Assumptions!$B$17)/(B6-Assumptions!$B$17) -> 1.7342657
A9: Justified P/B = sector P/B x premium | B9: =B5*B8 -> 2.6881119
A10: BVPS — latest reported (Q1-26) | B10: ='Per-Share & Ratios'!$B$5 -> 6.5707599
A11: Value on the P/B route (AED) | B11: =B9*B10 -> 17.662938
A12: Justified forward P/E = sector P/E x premium x (ROE_sector / ROE_ADIB) | B12: =Assumptions!$B$40*B8*(B6/B7) -> 9.9178322
A13: Value on the P/E route (AED) = justified P/E x FY26E EPS | B13: =B12*'Driver Build'!$E$15 -> 18.211863
A14: RELATIVE FAIR VALUE (AED / share) — average of the two routes | B14: =AVERAGE(B11,B13) -> 17.9374
A15: DUAL FRAME — same lens on the A&M 1.64x P/TBV mark instead | B15: =AVERAGE(D15,B13) -> 18.450195 | C15: =Assumptions!$B$39*B8 -> 2.8441958 | D15: =C15*B10 -> 18.688528
A16: WHERE IT ACTUALLY TRADES
A17: ADIB P/B now (on the latest reported book) | B17: =Assumptions!$B$5/B10 -> 3.3116413
A18: Premium OVER its own ROE-justified P/B | B18: =B17/B9-1 -> 0.23195814
A19: ADIB forward P/E now | B19: =Assumptions!$B$5/'Driver Build'!$E$15 -> 11.85008
A21: NORMALIZED / THROUGH-CYCLE
A22: Through-cycle ROE | B22: =Assumptions!$B$41 -> 0.23
A23: Justified P/B = (ROE_n − g) / (Ke − g) | B23: =(B22-Assumptions!$B$17)/(Assumptions!$B$16-Assumptions!$B$17) -> 2.891933
A24: NORMALIZED FAIR VALUE (AED / share) | B24: =B23*B10 -> 19.002198
A25: Normalized EPS = ROE_n x BVPS | B25: =B22*B10 -> 1.5112748
A26: Implied P/E on normalized earnings | B26: =B24/B25 -> 12.573622
A28: THE FIVE-LENS SYNTHESIS | C28: Value (AED) | D28: Weight | E28: Contribution
A29: Lens
A30: Dividend discount model (primary) | B30: =SUM(E30:E34) -> 21.230906 | C30: =DDM!$B$14 -> 22.541783 | D30: 0.3 | E30: =C30*D30 -> 6.7625349
A31: Residual income | C31: ='Residual Income'!$B$14 -> 22.541783 | D31: 0.2 | E31: =C31*D31 -> 4.5083566
A32: FCFE (equity DCF) | C32: =FCFE!$B$13 -> 23.481366 | D32: 0.15 | E32: =C32*D32 -> 3.5222049
A33: Relative multiples (ROE-adjusted) | C33: =B14 -> 17.9374 | D33: 0.2 | E33: =C33*D33 -> 3.5874801
A34: Normalized (through-cycle) | C34: =B24 -> 19.002198 | D34: 0.15 | E34: =C34*D34 -> 2.8503296
A35: WEIGHTED CENTRAL (AED / share) | C35: =SUM(D30:D34) -> 1 | E35: =SUM(E30:E34) -> 21.230906
A36: vs spot | E36: =E35/Assumptions!$B$5-1 -> -0.024314977
A37: Weighted central under the 1.64x P/TBV sector mark (dual frame) | E37: =E35+(B15-B14)*D33 -> 21.333465
A39: THE CENTRAL IS NOT A TARGET. The two lens families do not overlap: the cash-flow family (rows 30-32) prices a bank that keeps out-earning its cost of equity for a long time; the market family (rows 33-34) prices what a buyer will actually pay for that today. The RANGE is the primary object and the football field carries it. The weighted central is a probability-weighted summary ACROSS those two regimes — not a claim that the truth sits politely between them, and not a price at which we expect the stock to trade. Note also how little the sector mark matters: swapping the 1.55x P/B for A&M's 1.64x P/TBV moves the central by about ten fils (row 37).

Sheet Income Statement
A1: Income statement — 3 years reported + 5 years modelled (AED mn)
A2: FY23/24/25 are OFFICIAL: ADIB Management Discussion & Analysis, FY2023 / FY2024 / FY2025. No aggregator was used for any line. FY26E–FY30E are formulas off the Driver Build.
B3: FY23A | C3: FY24A | D3: FY25A | E3: FY26E | F3: FY27E | G3: FY28E | H3: FY29E | I3: FY30E
A4: Net revenue from funds (funded income) | B4: 6122 | C4: 6566 | D4: 7553 | E4: ='Driver Build'!E9 -> 8440.9413 | F4: ='Driver Build'!F9 -> 9302.1325 | G4: ='Driver Build'!G9 -> 10206.377 | H4: ='Driver Build'!H9 -> 11155.436 | I4: ='Driver Build'!I9 -> 12146.887
A5: Non-funded income | B5: 3172 | C5: 4066 | D5: 4751 | E5: ='Driver Build'!E10 -> 4941.04 | F5: ='Driver Build'!F10 -> 5336.3232 | G5: ='Driver Build'!G10 -> 5763.2291 | H5: ='Driver Build'!H10 -> 6224.2874 | I5: ='Driver Build'!I10 -> 6722.2304
A6: Total operating income | B6: 9294 | C6: 10632 | D6: 12304 | E6: ='Driver Build'!E11 -> 13381.981 | F6: ='Driver Build'!F11 -> 14638.456 | G6: ='Driver Build'!G11 -> 15969.606 | H6: ='Driver Build'!H11 -> 17379.723 | I6: ='Driver Build'!I11 -> 18869.117
A7: Total operating expenses | B7: -3061 | C7: -3145 | D7: -3525 | E7: ='Driver Build'!E12 -> -3934.3025 | F7: ='Driver Build'!F12 -> -4245.1522 | G7: ='Driver Build'!G12 -> -4551.3378 | H7: ='Driver Build'!H12 -> -4866.3224 | I7: ='Driver Build'!I12 -> -5189.0073
A8: Pre-provision operating profit | B8: =B6+B7 -> 6233 | C8: =C6+C7 -> 7487 | D8: =D6+D7 -> 8779 | E8: =E6+E7 -> 9447.6788 | F8: =F6+F7 -> 10393.304 | G8: =G6+G7 -> 11418.269 | H8: =H6+H7 -> 12513.401 | I8: =I6+I7 -> 13680.11
A9: Provision for impairment | B9: -760 | C9: -620 | D9: -678 | E9: ='Driver Build'!E13 -> -909.2544 | F9: ='Driver Build'!F13 -> -1022.6337 | G9: ='Driver Build'!G13 -> -1090.3843 | H9: ='Driver Build'!H13 -> -1177.2133 | I9: ='Driver Build'!I13 -> -1258.797
A10: Profit before tax | B10: 5472 | C10: 6868 | D10: 8101 | E10: =E6+E7+E9 -> 8538.4244 | F10: =F6+F7+F9 -> 9370.6698 | G10: =G6+G7+G9 -> 10327.884 | H10: =H6+H7+H9 -> 11336.187 | I10: =I6+I7+I9 -> 12421.313
A11: Tax | B11: -221 | C11: -766 | D11: -1031 | E11: =-E10*Assumptions!E$26 -> -1109.9952 | F11: =-F10*Assumptions!F$26 -> -1499.3072 | G11: =-G10*Assumptions!G$26 -> -1652.4615 | H11: =-H10*Assumptions!H$26 -> -1813.79 | I11: =-I10*Assumptions!I$26 -> -1987.4101
A12: Profit after tax | B12: =B10+B11 -> 5251 | C12: =C10+C11 -> 6102 | D12: =D10+D11 -> 7070 | E12: =E10+E11 -> 7428.4292 | F12: =F10+F11 -> 7871.3626 | G12: =G10+G11 -> 8675.4228 | H12: =H10+H11 -> 9522.3973 | I12: =I10+I11 -> 10433.903
A13: less: AT1 sukuk coupon | B13: =-Assumptions!$B$34 -> -353 | C13: =-Assumptions!$B$34 -> -353 | D13: =-Assumptions!$B$34 -> -353 | E13: =-Assumptions!$B$34 -> -353 | F13: =-Assumptions!$B$34 -> -353 | G13: =-Assumptions!$B$34 -> -353 | H13: =-Assumptions!$B$34 -> -353 | I13: =-Assumptions!$B$34 -> -353
A14: less: non-controlling interests | B14: -234.512 | C14: -336.32 | D14: =-Assumptions!$B$35 -> -376 | E14: =-Assumptions!$B$35*POWER(1+0.08,1) -> -406.08 | F14: =-Assumptions!$B$35*POWER(1+0.08,2) -> -438.5664 | G14: =-Assumptions!$B$35*POWER(1+0.08,3) -> -473.65171 | H14: =-Assumptions!$B$35*POWER(1+0.08,4) -> -511.54385 | I14: =-Assumptions!$B$35*POWER(1+0.08,5) -> -552.46736
A15: Attributable to ordinary shareholders | B15: =B12+B13+B14 -> 4663.488 | C15: =C12+C13+C14 -> 5412.68 | D15: =D12+D13+D14 -> 6341 | E15: =E12+E13+E14 -> 6669.3492 | F15: =F12+F13+F14 -> 7079.7962 | G15: =G12+G13+G14 -> 7848.7711 | H15: =H12+H13+H14 -> 8657.8534 | I15: =I12+I13+I14 -> 9528.4357
A16: EPS (AED) | B16: =B15/Assumptions!$B$6 -> 1.284 | C16: =C15/Assumptions!$B$6 -> 1.4902753 | D16: =D15/Assumptions!$B$6 -> 1.74587 | E16: =E15/Assumptions!$B$6 -> 1.8362746 | F16: =F15/Assumptions!$B$6 -> 1.9492831 | G16: =G15/Assumptions!$B$6 -> 2.1610053 | H16: =H15/Assumptions!$B$6 -> 2.3837702 | I16: =I15/Assumptions!$B$6 -> 2.623468
A17: DPS (AED) | B17: 0.715 | C17: 0.834 | D17: 0.9705 | E17: ='Driver Build'!E16 -> 0.91813728 | F17: ='Driver Build'!F16 -> 0.97464155 | G17: ='Driver Build'!G16 -> 1.1021127 | H17: ='Driver Build'!H16 -> 1.2395605 | I17: ='Driver Build'!I16 -> 1.390438
A19: MEMO — key ratios
A20: Net profit margin % | B20: 0.045 | C20: 0.0435 | D20: 0.0411 | E20: =Assumptions!E$22 -> 0.039 | F20: =Assumptions!F$22 -> 0.0382 | G20: =Assumptions!G$22 -> 0.0376 | H20: =Assumptions!H$22 -> 0.0372 | I20: =Assumptions!I$22 -> 0.037
A21: Cost-to-income % | B21: =-B7/B6 -> 0.32935227 | C21: =-C7/C6 -> 0.29580512 | D21: =-D7/D6 -> 0.2864922 | E21: =-E7/E6 -> 0.294 | F21: =-F7/F6 -> 0.29 | G21: =-G7/G6 -> 0.285 | H21: =-H7/H6 -> 0.28 | I21: =-I7/I6 -> 0.275
A22: Effective tax rate % | B22: =-B11/B10 -> 0.040387427 | C22: =-C11/C10 -> 0.11153174 | D22: =-D11/D10 -> 0.12726824 | E22: =-E11/E10 -> 0.13 | F22: =-F11/F10 -> 0.16 | G22: =-G11/G10 -> 0.16 | H22: =-H11/H10 -> 0.16 | I22: =-I11/I10 -> 0.16
A23: Payout ratio % | B23: =B17/B16 -> 0.55685358 | C23: =C17/C16 -> 0.55962813 | D23: =D17/D16 -> 0.5558833 | E23: =E17/E16 -> 0.5 | F23: =F17/F16 -> 0.5 | G23: =G17/G16 -> 0.51 | H23: =H17/H16 -> 0.52 | I23: =I17/I16 -> 0.53
A25: EPS check — FY25: attributable AED 6,341mn / 3,632mn shares = AED 1.746, matching ADIB's reported EPS of AED 1.746 exactly. The AT1 coupon (AED 353mn) and the non-controlling interest (AED 376mn, derived as the residual) are the bridge from PAT to what an ordinary shareholder owns.

Sheet Balance Sheet
A1: Balance sheet and capital — 3 years reported + 5 years modelled (AED mn)
A2: FY23/24/25 OFFICIAL (ADIB MD&A). Q1-26 column is the latest reported actual. FY26E–FY30E are formulas.
B3: FY23A | C3: FY24A | D3: FY25A | E3: FY26E | F3: FY27E | G3: FY28E | H3: FY29E | I3: FY30E | J3: Q1-26A
A4: Total assets | B4: 192827 | C4: 225910 | D4: 280753 | E4: ='Driver Build'!E5/($D$6/$D$4) -> 317497.17 | F4: ='Driver Build'!F5/($D$6/$D$4) -> 355596.83 | G4: ='Driver Build'!G5/($D$6/$D$4) -> 394712.48 | H4: ='Driver Build'!H5/($D$6/$D$4) -> 434183.73 | I4: ='Driver Build'!I5/($D$6/$D$4) -> 473260.26 | J4: 287065
A5: Gross customer financing | B5: 120169 | C5: 147100 | D5: 185600 | E5: ='Driver Build'!E4 -> 209728 | F5: ='Driver Build'!F4 -> 234895.36 | G5: ='Driver Build'!G4 -> 260733.85 | H5: ='Driver Build'!H4 -> 286807.23 | I5: ='Driver Build'!I4 -> 312619.89 | J5: 198000
A6: Customer financing, net | B6: 115002 | C6: 142611 | D6: 181376 | E6: ='Driver Build'!E5 -> 205113.98 | F6: ='Driver Build'!F5 -> 229727.66 | G6: ='Driver Build'!G5 -> 254997.7 | H6: ='Driver Build'!H5 -> 280497.48 | I6: ='Driver Build'!I5 -> 305742.25 | J6: 193809
A7: Investments | B7: 24483 | C7: 29286 | D7: 31621 | E7: =$D$7*(E4/$D$4) -> 35759.468 | F7: =$D$7*(F4/$D$4) -> 40050.604 | G7: =$D$7*(G4/$D$4) -> 44456.171 | H7: =$D$7*(H4/$D$4) -> 48901.788 | I7: =$D$7*(I4/$D$4) -> 53302.949
A8: Customer deposits | B8: 157067 | C8: 182675 | D8: 229096 | E8: ='Driver Build'!E5/($D$6/$D$8) -> 259079.44 | F8: ='Driver Build'!F5/($D$6/$D$8) -> 290168.98 | G8: ='Driver Build'!G5/($D$6/$D$8) -> 322087.57 | H8: ='Driver Build'!H5/($D$6/$D$8) -> 354296.32 | I8: ='Driver Build'!I5/($D$6/$D$8) -> 386182.99 | J8: 239335
A10: EQUITY & CAPITAL
A11: Share capital | B11: 3632 | C11: 3632 | D11: 3632 | E11: =$D$11 -> 3632 | F11: =$D$11 -> 3632 | G11: =$D$11 -> 3632 | H11: =$D$11 -> 3632 | I11: =$D$11 -> 3632 | J11: 3632
A12: Tier 1 sukuk (AT1) | B12: 4754 | C12: 4754 | D12: 4754 | E12: =$D$12 -> 4754 | F12: =$D$12 -> 4754 | G12: =$D$12 -> 4754 | H12: =$D$12 -> 4754 | I12: =$D$12 -> 4754 | J12: 4754
A13: Non-controlling interests | B13: 1114 | C13: 972 | D13: 1548 | E13: =D13-'Income Statement'!E14 -> 1954.08 | F13: =E13-'Income Statement'!F14 -> 2392.6464 | G13: =F13-'Income Statement'!G14 -> 2866.2981 | H13: =G13-'Income Statement'!H14 -> 3377.842 | I13: =H13-'Income Statement'!I14 -> 3930.3093 | J13: 1462
A15: Opening common equity (ordinary shareholders) | E15: =D17 -> 26067 | F15: =E17 -> 29401.675 | G15: =F17 -> 32941.573 | H15: =G17 -> 36787.471 | I15: =H17 -> 40943.24
A16: Opening common equity — link for Residual Income | D16: =D17 -> 26067 | E16: =E15 -> 26067 | F16: =F15 -> 29401.675 | G16: =G15 -> 32941.573 | H16: =H15 -> 36787.471 | I16: =I15 -> 40943.24
A17: Closing common equity (attributable to shareholders) | B17: 20374 | C17: 22591 | D17: 26067 | E17: =E15+'Income Statement'!E15-'Income Statement'!E17*Assumptions!$B$6 -> 29401.675 | F17: =F15+'Income Statement'!F15-'Income Statement'!F17*Assumptions!$B$6 -> 32941.573 | G17: =G15+'Income Statement'!G15-'Income Statement'!G17*Assumptions!$B$6 -> 36787.471 | H17: =H15+'Income Statement'!H15-'Income Statement'!H17*Assumptions!$B$6 -> 40943.24 | I17: =I15+'Income Statement'!I15-'Income Statement'!I17*Assumptions!$B$6 -> 45421.605 | J17: 23865
A18: Total equity (incl. AT1 and NCI) | B18: =B17+B12+B13 -> 26242 | C18: =C17+C12+C13 -> 28317 | D18: =D17+D12+D13 -> 32369 | E18: =E17+E12+E13 -> 36109.755 | F18: =F17+F12+F13 -> 40088.219 | G18: =G17+G12+G13 -> 44407.769 | H18: =H17+H12+H13 -> 49075.082 | I18: =I17+I12+I13 -> 54105.914 | J18: =J17+J12+J13 -> 30081
A19: BVPS (AED) | B19: =B17/Assumptions!$B$6 -> 5.6095815 | C19: =C17/Assumptions!$B$6 -> 6.219989 | D19: =D17/Assumptions!$B$6 -> 7.1770374 | E19: =E17/Assumptions!$B$6 -> 8.0951747 | F19: =F17/Assumptions!$B$6 -> 9.0698163 | G19: =G17/Assumptions!$B$6 -> 10.128709 | H19: =H17/Assumptions!$B$6 -> 11.272919 | I19: =I17/Assumptions!$B$6 -> 12.505949 | J19: =J17/Assumptions!$B$6 -> 6.5707599
A21: RISK-WEIGHTED ASSETS & CAPITAL
A22: Risk-weighted assets | B22: 138211 | C22: 159983 | D22: 183637 | E22: ='Driver Build'!E17 -> 206355.18 | F22: ='Driver Build'!F17 -> 230361.03 | G22: ='Driver Build'!G17 -> 255067.93 | H22: ='Driver Build'!H17 -> 280098.34 | I22: ='Driver Build'!I17 -> 305016.58 | J22: 193748
A23: CET1 capital | D23: 22100 | E23: =D23+'Income Statement'!E15-'Income Statement'!E17*Assumptions!$B$6 -> 25434.675 | F23: =E23+'Income Statement'!F15-'Income Statement'!F17*Assumptions!$B$6 -> 28974.573 | G23: =F23+'Income Statement'!G15-'Income Statement'!G17*Assumptions!$B$6 -> 32820.471 | H23: =G23+'Income Statement'!H15-'Income Statement'!H17*Assumptions!$B$6 -> 36976.24 | I23: =H23+'Income Statement'!I15-'Income Statement'!I17*Assumptions!$B$6 -> 41454.605
A24: CET1 ratio % | B24: 0.1223 | C24: 0.1207 | D24: 0.1202 | E24: =E23/E22 -> 0.12325678 | F24: =F23/F22 -> 0.12577897 | G24: =G23/G22 -> 0.12867345 | H24: =H23/H22 -> 0.13201163 | I24: =I23/I22 -> 0.13590935 | J24: 0.12
A25: Capital adequacy ratio % (reported) | B25: 0.168 | C25: 0.1621 | D25: 0.1571 | J25: 0.155
A26: NPA ratio % (reported) | B26: 0.061 | C26: 0.04 | D26: 0.028 | J26: 0.026
A27: NPA coverage % incl. collateral (reported) | B27: 1.395 | C27: 1.574 | D27: 1.725 | J27: 1.783
A29: CHECK — FY25 capital equation
A30: Retained attributable earnings FY25 (AED mn) | B30: =1.746*Assumptions!$B$6-3525 -> 2816.472
A31: Capital FY25 RWA growth consumed at 12.0% CET1 | B31: =(D22-C22)*Assumptions!$B$33 -> 2838.48
A32: Difference (a ~50% payout EXACTLY funded FY25 growth) | B32: =B30-B31 -> -22.008
A34: Balance-sheet scaffolding: FY26E+ total assets, investments and deposits are held at their FY25 ratios to net financing — presentation only, not drivers. Nothing in the valuation depends on them. The lines that DO drive value — financing, RWA, common equity and CET1 — are all built from Assumptions.

Sheet Cash Flow
A1: Cash flow to the ordinary shareholder (AED mn)
A2: For a bank the meaningful cash-flow statement is the equity one: what the business earns, what growth consumes, and what is left to distribute.
E3: FY26E | F3: FY27E | G3: FY28E | H3: FY29E | I3: FY30E
A4: Profit after tax | E4: ='Income Statement'!E12 -> 7428.4292 | F4: ='Income Statement'!F12 -> 7871.3626 | G4: ='Income Statement'!G12 -> 8675.4228 | H4: ='Income Statement'!H12 -> 9522.3973 | I4: ='Income Statement'!I12 -> 10433.903
A5: less: AT1 sukuk coupon | E5: ='Income Statement'!E13 -> -353 | F5: ='Income Statement'!F13 -> -353 | G5: ='Income Statement'!G13 -> -353 | H5: ='Income Statement'!H13 -> -353 | I5: ='Income Statement'!I13 -> -353
A6: less: non-controlling interests | E6: ='Income Statement'!E14 -> -406.08 | F6: ='Income Statement'!F14 -> -438.5664 | G6: ='Income Statement'!G14 -> -473.65171 | H6: ='Income Statement'!H14 -> -511.54385 | I6: ='Income Statement'!I14 -> -552.46736
A7: Attributable to ordinary shareholders | E7: =E4+E5+E6 -> 6669.3492 | F7: =F4+F5+F6 -> 7079.7962 | G7: =G4+G5+G6 -> 7848.7711 | H7: =H4+H5+H6 -> 8657.8534 | I7: =I4+I5+I6 -> 9528.4357
A8: less: equity retained for RWA growth | E8: =-'Driver Build'!E19 -> -2726.182 | F8: =-'Driver Build'!F19 -> -2880.7015 | G8: =-'Driver Build'!G19 -> -2964.8281 | H8: =-'Driver Build'!H19 -> -3003.6497 | I8: =-'Driver Build'!I19 -> -2990.1883
A9: FREE CASH FLOW TO EQUITY | E9: =E7+E8 -> 3943.1672 | F9: =F7+F8 -> 4199.0947 | G9: =G7+G8 -> 4883.943 | H9: =H7+H8 -> 5654.2037 | I9: =I7+I8 -> 6538.2474
A11: Dividend declared | E11: =-'Income Statement'!E17*Assumptions!$B$6 -> -3334.6746 | F11: =-'Income Statement'!F17*Assumptions!$B$6 -> -3539.8981 | G11: =-'Income Statement'!G17*Assumptions!$B$6 -> -4002.8733 | H11: =-'Income Statement'!H17*Assumptions!$B$6 -> -4502.0838 | I11: =-'Income Statement'!I17*Assumptions!$B$6 -> -5050.0709
A12: Surplus / (deficit) after the declared dividend | E12: =E9+E11 -> 608.49262 | F12: =F9+F11 -> 659.19661 | G12: =G9+G11 -> 881.06976 | H12: =H9+H11 -> 1152.1199 | I12: =I9+I11 -> 1488.1765
A14: Memo: retained earnings (attributable − dividend) | E14: =E7+E11 -> 3334.6746 | F14: =F7+F11 -> 3539.8981 | G14: =G7+G11 -> 3845.8978 | H14: =H7+H11 -> 4155.7696 | I14: =I7+I11 -> 4478.3648
A15: Memo: change in RWA | E15: ='Driver Build'!E18 -> 22718.183 | F15: ='Driver Build'!F18 -> 24005.846 | G15: ='Driver Build'!G18 -> 24706.901 | H15: ='Driver Build'!H18 -> 25030.414 | I15: ='Driver Build'!I18 -> 24918.236
A16: Memo: closing CET1 ratio | E16: ='Balance Sheet'!E24 -> 0.12325678 | F16: ='Balance Sheet'!F24 -> 0.12577897 | G16: ='Balance Sheet'!G24 -> 0.12867345 | H16: ='Balance Sheet'!H24 -> 0.13201163 | I16: ='Balance Sheet'!I24 -> 0.13590935

Sheet Monte Carlo
A1: Monte Carlo — the 3-month distribution (the ONLY 3-month figures in this workbook)
A2: v3 engine: carry-anchored drift, gap-aware Yang-Zhang / HAR width, fitted t(4) shape. 50,000 paths, seed 42. The §1 value gap NEVER enters the drift (lens independence).
A4: ENGINE
A5: Spot (AED, 03-Jul-2026) | B5: 21.76
A6: Risk-free (3M EIBOR, CBUAE fixings) | B6: 0.039
A7: Dividend yield q = FY25 DPS / spot | B7: 0.0446
A8: Carry (60d) = [ln(1+rf) − ln(1+q)] x 60/252 | B8: -0.002014
A9: Anchor volatility (annualized, x width_cal) | B9: 0.3066
A10: Tail parameter nu (UAE 9-name panel fit) | B10: 10
A11: Width calibration (UAE 9-name panel fit) | B11: 1.049 | C11: 19.806 | E11: 23.842
A13: PERCENTILES | B13: 5th | C13: 25th | D13: 50th | E13: 75th | F13: 95th
A14: T+20 (AED) | B14: 18.911 | C14: 20.609 | D14: 21.744 | E14: 22.949 | F14: 24.947
A15: T+60 (AED) | B15: 17.101 | C15: 19.806 | D15: 21.727 | E15: 23.842 | F15: 27.699
A17: THE PROBABILITY READ (T+60)
A18: P(price above spot) | B18: 0.4955
A19: P(+10% or better) vs P(−10% or worse) | B19: 0.2413 | C19: 0.2251
A20: Median path (AED) | B20: 21.727
A21: Median move | B21: -0.0015
A22: Touch +10% at any point in the horizon | B22: 0.4431
A23: Touch −10% at any point in the horizon | B23: 0.4111
A25: STEP 0.0 — DATA-QUALITY GATE (mandatory before any calibration)
A26: ADX daily price limit ±15% → artifact threshold |1-day log move| | B26: 0.211
A27: Rows in / out after the gate | B27: 1367 | C27: 1365
A28: What the gate removed | D28: dropped 2 interior stale/no-trade rows
A30: STEP 0 — the five-year backtest, in the open
A31: Windows (non-overlapping, h=60d, post-2022 break) | B31: 14
A32: CRPS skill vs the carry-anchored RW — SCALE-NORMALIZED (the gate) | B32: 0.0093
A33: CRPS skill on the retired raw-price basis (for reconciliation only) | B33: 0.0104
A34: Pinball-0.50 skill | B34: 0.0024
A35: Winkler-90 interval skill | B35: -0.1093
A36: Coverage 50 / 80 / 90 | B36: 0.429 | C36: 0.786 | D36: 1
A37: PIT mean | B37: 0.618
A38: Bootstrap CI, window-block 2 / 3 / 4 | B38: [-0.014, +0.030] PARITY | C38: [-0.017, +0.032] PARITY | D38: [-0.017, +0.032] PARITY
A39: ROBUST NAME-LEVEL VERDICT (all block sizes agree) | B39: PARITY
A41: THE STANDING GATE — the UAE market panel (not this one name)
A42: Panel: names / windows | B42: 14 | C42: 237
A43: Panel fitted (nu, width_cal) — read LIVE from the engine registry | B43: 10 | C43: 1.049
A44: Panel CRPS skill and 90% CI | B44: 0.0049 | C44: [-0.004, +0.015]
A45: PANEL VERDICT | B45: PARITY
A47: PARITY means exactly what it says. The distribution is honestly calibrated — every realized close fell inside the 90% band, coverage at 80% is 0.79 against a 0.80 target, and the CRPS skill is POSITIVE at +0.0093 — and it is validated on the 14-name UAE panel, which is the standing gate. But on ADIB's own 14 windows the confidence interval spans zero at every block size, so no single-name forecasting EDGE has been demonstrated. The PIT mean above 0.5 says the model UNDER-called ADIB's rise rather than over-calling it — which is exactly what a carry-anchored engine should do to a stock that quadrupled: it refuses to extrapolate a trend, and pays for that refusal in a rising market. We keep the refusal. Read the distribution as a base rate, not a promise.

Sheet Sensitivity
A1: Sensitivity — the crux, in the units that actually move it
A2: Live grids. Every cell recomputes the weighted central from the Assumptions sheet.
A4: GRID 1 — Ke x terminal growth g (weighted central, AED)
B5: g 3.0% | C5: g 3.5% | D5: g 4.0% | E5: g 4.5%
A6: Ke 9.57% | B6: 22.7 | C6: 23.59 | D6: 24.63 | E6: 25.87
A7: Ke 10.07% | B7: 21.23 | C7: 21.95 | D7: 22.79 | E7: 23.77
A8: Ke 10.57% | B8: 19.95 | C8: 20.55 | D8: 21.23 | E8: 22.02
A9: Ke 11.07% | B9: 18.84 | C9: 19.33 | D9: 19.9 | E9: 20.54
A10: Ke 11.57% | B10: 17.86 | C10: 18.27 | D10: 18.74 | E10: 19.27
A11: Ke 12.07% | B11: 16.98 | C11: 17.33 | D11: 17.73 | E11: 18.17
A13: GRID 2 — Ke x TERMINAL ROE (the crux). Weighted central, AED.
B14: ROE 18% | C14: ROE 20% | D14: ROE 22% | E14: ROE 25% | F14: ROE 28%
A15: Ke 9.57% | B15: 22.78 | C15: 24.63 | D15: 26.48 | E15: 29.25 | F15: 32.02
A16: Ke 10.07% | B16: 21.13 | C16: 22.79 | D16: 24.45 | E16: 26.93 | F16: 29.42
A17: Ke 10.57% | B17: 19.73 | C17: 21.23 | D17: 22.73 | E17: 24.97 | F17: 27.22
A18: Ke 11.07% | B18: 18.54 | C18: 19.9 | D18: 21.26 | E18: 23.3 | F18: 25.34
A19: Ke 11.57% | B19: 17.5 | C19: 18.74 | D19: 19.98 | E19: 21.84 | F19: 23.71
A20: Ke 12.07% | B20: 16.59 | C20: 17.73 | D20: 18.87 | E20: 20.58 | F20: 22.29
A22: Shaded = combinations that reproduce today's AED 21.76 price. Cream = the base case.
A24: GRID 3 — beta (assumed 1.00; the regression failed its usability gate)
B25: Beta | C25: Ke | D25: Weighted central (AED)
B26: 0.8 | C26: =Assumptions!$B$11+B26*Assumptions!$B$12+Assumptions!$B$15 -> 0.09596 | D26: 24.52
B27: 0.9 | C27: =Assumptions!$B$11+B27*Assumptions!$B$12+Assumptions!$B$15 -> 0.10083 | D27: 22.74
B28: 1 | C28: =Assumptions!$B$11+B28*Assumptions!$B$12+Assumptions!$B$15 -> 0.1057 | D28: 21.23
B29: 1.1 | C29: =Assumptions!$B$11+B29*Assumptions!$B$12+Assumptions!$B$15 -> 0.11057 | D29: 19.93
B30: 1.2 | C30: =Assumptions!$B$11+B30*Assumptions!$B$12+Assumptions!$B$15 -> 0.11544 | D30: 18.8
B31: 1.3 | C31: =Assumptions!$B$11+B31*Assumptions!$B$12+Assumptions!$B$15 -> 0.12031 | D31: 17.8
A33: THE CRUX IN REAL UNITS — swing on the weighted central (AED/share)
B34: Effect on central
A35: NPM +10bp across path | B35: 0.21
A36: NPM -10bp across path | B36: -0.21
A37: Tax held at 13% (no DMTT step) | B37: 0.27
A38: Tax full 15% UAE top-up (17.3%) | B38: -0.12
A39: CoR +10bp | B39: -0.27
A40: Financing growth -3pt across path | B40: -0.26
A41: CIR held flat at 29.6% (Q1-26) | B41: -0.17
A42: Payout to 60% by FY30 | B42: -0.27
A43: Terminal ROE 18% (the sector level) | B43: -1.5
A44: Terminal ROE 25% (management's 2030 target) | B44: 3.74
A45: Conflict adder 0pt — peace-time Ke 9.57% | B45: 3.4
...

Sheet Per-Share & Ratios
A1: Per-share and ratio dashboard — the standard panel, identical across every Testahil study
A2: The house "Data Miner" page. Everything is a formula.
A4: BOOK VALUE
A5: BVPS — latest reported (Q1-26) | B5: ='Balance Sheet'!J17/Assumptions!$B$6 -> 6.5707599
A6: BVPS — last audited FY (Dec-25) | B6: ='Balance Sheet'!D17/Assumptions!$B$6 -> 7.1770374
A7: DUAL FRAMING: the Dec-25 book still contains the AED 3,525mn dividend that was proposed then and paid after the 04-Mar-2026 AGM; the Q1-26 book is after that payment. Both P/B framings are shown everywhere they appear.
B9: FY23A | C9: FY24A | D9: FY25A | E9: FY26E | F9: FY27E | G9: FY28E | H9: FY29E | I9: FY30E
A10: EPS (AED) | B10: ='Income Statement'!B16 -> 1.284 | C10: ='Income Statement'!C16 -> 1.4902753 | D10: ='Income Statement'!D16 -> 1.74587 | E10: ='Income Statement'!E16 -> 1.8362746 | F10: ='Income Statement'!F16 -> 1.9492831 | G10: ='Income Statement'!G16 -> 2.1610053 | H10: ='Income Statement'!H16 -> 2.3837702 | I10: ='Income Statement'!I16 -> 2.623468
A11: DPS (AED) | B11: ='Income Statement'!B17 -> 0.715 | C11: ='Income Statement'!C17 -> 0.834 | D11: ='Income Statement'!D17 -> 0.9705 | E11: ='Income Statement'!E17 -> 0.91813728 | F11: ='Income Statement'!F17 -> 0.97464155 | G11: ='Income Statement'!G17 -> 1.1021127 | H11: ='Income Statement'!H17 -> 1.2395605 | I11: ='Income Statement'!I17 -> 1.390438
A12: BVPS (AED) | B12: ='Balance Sheet'!B19 -> 5.6095815 | C12: ='Balance Sheet'!C19 -> 6.219989 | D12: ='Balance Sheet'!D19 -> 7.1770374 | E12: ='Balance Sheet'!E19 -> 8.0951747 | F12: ='Balance Sheet'!F19 -> 9.0698163 | G12: ='Balance Sheet'!G19 -> 10.128709 | H12: ='Balance Sheet'!H19 -> 11.272919 | I12: ='Balance Sheet'!I19 -> 12.505949
A13: P/E (x, at spot) | B13: =Assumptions!$B$5/'Income Statement'!B16 -> 16.94704 | C13: =Assumptions!$B$5/'Income Statement'!C16 -> 14.601329 | D13: =Assumptions!$B$5/'Income Statement'!D16 -> 12.4637 | E13: =Assumptions!$B$5/'Income Statement'!E16 -> 11.85008 | F13: =Assumptions!$B$5/'Income Statement'!F16 -> 11.163078 | G13: =Assumptions!$B$5/'Income Statement'!G16 -> 10.069388 | H13: =Assumptions!$B$5/'Income Statement'!H16 -> 9.1283966 | I13: =Assumptions!$B$5/'Income Statement'!I16 -> 8.2943646
A14: P/B (x, at spot) | B14: =Assumptions!$B$5/'Balance Sheet'!B19 -> 3.8790773 | C14: =Assumptions!$B$5/'Balance Sheet'!C19 -> 3.4983985 | D14: =Assumptions!$B$5/'Balance Sheet'!D19 -> 3.0318917 | E14: =Assumptions!$B$5/'Balance Sheet'!E19 -> 2.688021 | F14: =Assumptions!$B$5/'Balance Sheet'!F19 -> 2.3991666 | G14: =Assumptions!$B$5/'Balance Sheet'!G19 -> 2.1483488 | H14: =Assumptions!$B$5/'Balance Sheet'!H19 -> 1.9302898 | I14: =Assumptions!$B$5/'Balance Sheet'!I19 -> 1.739972
A15: Dividend yield (at spot) | B15: ='Income Statement'!B17/Assumptions!$B$5 -> 0.032858456 | C15: ='Income Statement'!C17/Assumptions!$B$5 -> 0.038327206 | D15: ='Income Statement'!D17/Assumptions!$B$5 -> 0.044600184 | E15: ='Income Statement'!E17/Assumptions!$B$5 -> 0.042193809 | F15: ='Income Statement'!F17/Assumptions!$B$5 -> 0.044790513 | G15: ='Income Statement'!G17/Assumptions!$B$5 -> 0.050648561 | H15: ='Income Statement'!H17/Assumptions!$B$5 -> 0.056965097 | I15: ='Income Statement'!I17/Assumptions!$B$5 -> 0.063898807
A16: Payout ratio | B16: ='Income Statement'!B23 -> 0.55685358 | C16: ='Income Statement'!C23 -> 0.55962813 | D16: ='Income Statement'!D23 -> 0.5558833 | E16: ='Income Statement'!E23 -> 0.5 | F16: ='Income Statement'!F23 -> 0.5 | G16: ='Income Statement'!G23 -> 0.51 | H16: ='Income Statement'!H23 -> 0.52 | I16: ='Income Statement'!I23 -> 0.53
A17: Return on equity (attributable) | B17: ='Income Statement'!B15/'Balance Sheet'!B17 -> 0.22889408 | C17: ='Income Statement'!C15/'Balance Sheet'!C17 -> 0.23959453 | D17: ='Income Statement'!D15/'Balance Sheet'!D17 -> 0.24325776 | E17: ='Income Statement'!E15/'Balance Sheet'!E17 -> 0.22683569 | F17: ='Income Statement'!F15/'Balance Sheet'!F17 -> 0.2149198 | G17: ='Income Statement'!G15/'Balance Sheet'!G17 -> 0.21335447 | H17: ='Income Statement'!H15/'Balance Sheet'!H17 -> 0.2114599 | I17: ='Income Statement'!I15/'Balance Sheet'!I17 -> 0.20977761
A18: Net profit margin | B18: ='Income Statement'!B20 -> 0.045 | C18: ='Income Statement'!C20 -> 0.0435 | D18: ='Income Statement'!D20 -> 0.0411 | E18: ='Income Statement'!E20 -> 0.039 | F18: ='Income Statement'!F20 -> 0.0382 | G18: ='Income Statement'!G20 -> 0.0376 | H18: ='Income Statement'!H20 -> 0.0372 | I18: ='Income Statement'!I20 -> 0.037
A19: Cost-to-income | B19: ='Income Statement'!B21 -> 0.32935227 | C19: ='Income Statement'!C21 -> 0.29580512 | D19: ='Income Statement'!D21 -> 0.2864922 | E19: ='Income Statement'!E21 -> 0.294 | F19: ='Income Statement'!F21 -> 0.29 | G19: ='Income Statement'!G21 -> 0.285 | H19: ='Income Statement'!H21 -> 0.28 | I19: ='Income Statement'!I21 -> 0.275
A20: Effective tax rate | B20: ='Income Statement'!B22 -> 0.040387427 | C20: ='Income Statement'!C22 -> 0.11153174 | D20: ='Income Statement'!D22 -> 0.12726824 | E20: ='Income Statement'!E22 -> 0.13 | F20: ='Income Statement'!F22 -> 0.16 | G20: ='Income Statement'!G22 -> 0.16 | H20: ='Income Statement'!H22 -> 0.16 | I20: ='Income Statement'!I22 -> 0.16
A21: CET1 ratio | B21: ='Balance Sheet'!B24 -> 0.1223 | C21: ='Balance Sheet'!C24 -> 0.1207 | D21: ='Balance Sheet'!D24 -> 0.1202 | E21: ='Balance Sheet'!E24 -> 0.12325678 | F21: ='Balance Sheet'!F24 -> 0.12577897 | G21: ='Balance Sheet'!G24 -> 0.12867345 | H21: ='Balance Sheet'!H24 -> 0.13201163 | I21: ='Balance Sheet'!I24 -> 0.13590935
A22: RWA density (RWA / total assets) | B22: ='Balance Sheet'!B22/'Balance Sheet'!B4 -> 0.71676166 | C22: ='Balance Sheet'!C22/'Balance Sheet'!C4 -> 0.7081714 | D22: ='Balance Sheet'!D22/'Balance Sheet'!D4 -> 0.6540874 | E22: ='Balance Sheet'!E22/'Balance Sheet'!E4 -> 0.64994338 | F22: ='Balance Sheet'!F22/'Balance Sheet'!F4 -> 0.6478152 | G22: ='Balance Sheet'!G22/'Balance Sheet'!G4 -> 0.64621197 | H22: ='Balance Sheet'!H22/'Balance Sheet'!H4 -> 0.64511479 | I22: ='Balance Sheet'!I22/'Balance Sheet'!I4 -> 0.64450072
A23: Financing / deposits | B23: ='Balance Sheet'!B6/'Balance Sheet'!B8 -> 0.73218435 | C23: ='Balance Sheet'!C6/'Balance Sheet'!C8 -> 0.78068154 | D23: ='Balance Sheet'!D6/'Balance Sheet'!D8 -> 0.79170304 | E23: ='Balance Sheet'!E6/'Balance Sheet'!E8 -> 0.79170304 | F23: ='Balance Sheet'!F6/'Balance Sheet'!F8 -> 0.79170304 | G23: ='Balance Sheet'!G6/'Balance Sheet'!G8 -> 0.79170304 | H23: ='Balance Sheet'!H6/'Balance Sheet'!H8 -> 0.79170304 | I23: ='Balance Sheet'!I6/'Balance Sheet'!I8 -> 0.79170304
A25: COST DECOMPOSITION (opex as % of operating income)
A26: Total operating expenses / operating income | B26: =-'Income Statement'!B7/'Income Statement'!B6 -> 0.32935227 | C26: =-'Income Statement'!C7/'Income Statement'!C6 -> 0.29580512 | D26: =-'Income Statement'!D7/'Income Statement'!D6 -> 0.2864922 | E26: =-'Income Statement'!E7/'Income Statement'!E6 -> 0.294 | F26: =-'Income Statement'!F7/'Income Statement'!F6 -> 0.29 | G26: =-'Income Statement'!G7/'Income Statement'!G6 -> 0.285 | H26: =-'Income Statement'!H7/'Income Statement'!H6 -> 0.28 | I26: =-'Income Statement'!I7/'Income Statement'!I6 -> 0.275
A27: Impairment / operating income | B27: =-'Income Statement'!B9/'Income Statement'!B6 -> 0.081773187 | C27: =-'Income Statement'!C9/'Income Statement'!C6 -> 0.058314522 | D27: =-'Income Statement'!D9/'Income Statement'!D6 -> 0.055104031 | E27: =-'Income Statement'!E9/'Income Statement'!E6 -> 0.067946172 | F27: =-'Income Statement'!F9/'Income Statement'!F6 -> 0.0698594 | G27: =-'Income Statement'!G9/'Income Statement'!G6 -> 0.068278719 | H27: =-'Income Statement'!H9/'Income Statement'!H6 -> 0.067734873 | I27: =-'Income Statement'!I9/'Income Statement'!I6 -> 0.066712021

Sheet Peer & Sector
A1: Peer set and sector marks
A2: Company financials from each bank's own results releases. Prices and multiples are market data.
B4: Latest sourced print | C4: Read vs ADIB
A5: Dubai Islamic Bank (DFM: DIB) | B5: FY25 revenue AED 13.3bn (+3%), pre-tax AED 9.0bn (+20%), assets AED 416bn (+21%); EPS 0.98; DPS 0.35. NET PROFIT MARGIN 2.6% ACTUAL in FY25, guided DOWN to 2.3% for 2026 by the Group CEO on the FY25 results call — a guide that explicitly assumes THREE more Fed cuts. Also guided: financing +10%, cost of risk ~50bp. Effective tax rate went 9% (2024) → 15% (2025). NO fixed dividend policy. | C5: The only true like-for-like. ADIB's 4.11% margin is 151bp above DIB's 2.6% on the SAME metric. DIB's 2.3% guide rests on rate cuts the June-26 dot plot no longer supports — which makes ADIB's CASA defence look more structural, not less. And DIB is ALREADY paying the 15% DMTT floor: the strongest single piece of evidence that ADIB's tax step is coming.
A6: Abu Dhabi Commercial Bank (ADX: ADCB) | B6: FY25 NPAT AED 11.4bn (+22%); Q1-26 RoAE 16.3%; CET1 13.82%; DPS 0.63 (44% payout). Testahil study 10-Jul-2026: P/B 1.52x. | C6: The conventional Abu Dhabi comparator. Bigger, cheaper, and earns ~12 points less on equity. It sits almost exactly ON the ROE-justified line — ADIB sits above it.
A7: First Abu Dhabi Bank (ADX: FAB) | B7: Largest UAE bank. Q1-26 net income AED 4.75bn, EPS 0.43 (beat). FY25 payout ~43%. | C7: The sector ceiling on scale, not on returns.
A8: Emirates NBD (DFM: ENBD) | B8: Dubai flagship. Q1-26 NIM 3.37% (−19bp QoQ). | C8: The most rate-sensitive large peer; ADIB's 64–67% CASA is the structural defence ENBD lacks.
A9: UAE bank sector (top-10 listed) | B9: FY25: NIM 2.48% (−19bp), RoE 18.3% (−63bp), RoA 2.0%, NPL 2.4%, CoR 0.47%; 8.8x P/E, 1.64x P/TBV. Q1-26 sector NIM 2.37%. [Alvarez & Marsal UAE Banking Pulse, built from public filings] | C9: ADIB's 4.11% net profit margin is 163bp above the sector NIM, and its 28.8% RoE is 10.5 points above. That gap is the entire investment case — and the entire risk.
A12: THE ROE-JUSTIFIED LINE (the relative lens, in one table)
B13: ROE | C13: P/B where it trades | D13: P/B the ROE justifies
A14: UAE sector | B14: =Assumptions!$B$36 -> 0.183 | C14: =Assumptions!$B$38 -> 1.55 | D14: =Assumptions!$B$38 -> 1.55
A15: ADCB | B15: 0.163 | C15: 1.52 | D15: =Assumptions!$B$38*(0.163-Assumptions!$B$17)/(Assumptions!$B$36-Assumptions!$B$17) -> 1.3332168
A16: ADIB | B16: =Assumptions!$B$45 -> 0.288 | C16: ='Relative & Normalized'!$B$17 -> 3.3116413 | D16: ='Relative & Normalized'!$B$9 -> 2.6881119
A17: ADIB premium over its own ROE-justified P/B | B17: ='Relative & Normalized'!$B$18 -> 0.23195814

Sheet Earnings Drivers
A1: Earnings drivers — how each assumption was set, and what it rests on
A2: The per-driver gate table. Bottom-up is the default wherever the sweep cleared it; top-down where the bank reports blended outcomes rather than the components.
B4: Mode | C4: Justification, and the sweep line that carries it
