Workbook

Sheet READ FIRST
A1: Testahil — ADNOC Logistics & Services plc (ADX: ADNOCLS)
A3: Companion model · Independent Valuation Study · Educational analysis · Not investment advice
A5: What this workbook is. A transparent companion to the ADNOC L&S valuation study. Every blue cell is an
A6: input; every black cell is a formula; green cells link across sheets.
A8: IT IS FORMULA-DRIVEN. Every figure that can be derived arithmetically from a driver is a live formula, so
A9: you can change a blue cell on Assumptions and watch the model reprice. The cost of equity is built from the
A10: normalised risk-free rate, the beta and the equity risk premium — and the normalised rate is itself a
A11: formula, the observed government bond yield less the sovereign default spread. The cost of debt is built
A12: three separate ways on the sheet — the parent facility at the overnight financing rate plus its margin, a
A13: weighted blend of the instruments the company actually has outstanding, and the disclosed third-party
A14: bank-loan midpoint — and the three are averaged in a cell. The discount factors compound year on year off
A15: the cost-of-capital glide, with a three-quarter stub for 2026 because the valuation date is 31 March 2026.
... A115: Sensitivity · Per-Share & Ratios · Peer & Sector.

Sheet Summary
A1: Summary — valuation at a glance
A2: All values link live to their source sheets. AED per share unless stated.
A4: Lens | B4: Bear | C4: Base | D4: Bull | E4: Weight | F4: Contribution | G4: vs spot | H4: Terminal value share
A5: Discounted cash flow (own regressed beta) | B5: ='Fundamental Valuation'!$C$6 | C5: =DCF!$C$62 | D5: ='Fundamental Valuation'!$C$7 | E5: =Assumptions!$C$170 | F5: =C5*E5 | G5: =C5/$C$16-1 | H5: =DCF!$C$48
A6: Relative multiples | B6: ='Relative & Normalized'!$C$26 | C6: ='Relative & Normalized'!$C$21 | D6: ='Relative & Normalized'!$D$26 | E6: =Assumptions!$C$171 | F6: =C6*E6 | G6: =C6/$C$16-1
A7: Normalised earnings power | B7: ='Relative & Normalized'!$C$58 | C7: ='Relative & Normalized'!$C$53 | D7: ='Relative & Normalized'!$D$58 | E7: =Assumptions!$C$172 | F7: =C7*E7 | G7: =C7/$C$16-1
A8: Book value and sustainable return | B8: ='Relative & Normalized'!$C$102 | C8: ='Relative & Normalized'!$C$80 | D8: ='Relative & Normalized'!$D$102 | E8: =Assumptions!$C$173 | F8: =C8*E8 | G8: =C8/$C$16-1
A9: WEIGHTED CENTRAL | B9: =B5*E5+B6*E6+B7*E7+B8*E8 | C9: =SUM(F5:F8) | D9: =D5*E5+D6*E6+D7*E7+D8*E8 | E9: =SUM(E5:E8) | G9: =C9/$C$16-1
A11: THE CONTESTED JUDGEMENT — PUBLISHED BOTH WAYS, NEVER AVERAGED
A12: Discounted cash flow (composite-index beta of 0.705) | B12: =B5 | C12: =DCF!$C$141 | D12: =D5 | E12: =E5 | F12: =C12*E12 | G12: =C12/$C$16-1 | H12: =DCF!$C$136
A13: Weighted central on the composite-index beta | C13: =F12+F6+F7+F8 | G13: =C13/$C$16-1
A15: Expert panel average | C15: ='Fundamental Valuation'!$C$34 | G15: =C15/$C$16-1
A16: Market price (AED, anchor) | C16: =Assumptions!$C$5
A18: Key figure | C18: Value
A19: Shares outstanding (mn) | C19: =Assumptions!$C$6
A20: Market capitalisation (USD 000) | C20: =DCF!$C$97
A21: Enterprise value at the anchor price (USD 000) | C21: ='Relative & Normalized'!$C$32
A22: Net debt at 31 March 2026, including the deferred consideration and the eleven vessels bought on 7 August 2026 (USD 000) | C22: ='Relative & Normalized'!$C$31
A23: The eleven vessels bought on 7 August 2026, at the announced price (USD 000) | C23: =Assumptions!$C$82
A24: FY2025 revenue (USD 000) | C24: ='Income Statement'!D5
A25: FY2025 EBITDA as reported (USD 000) | C25: ='Income Statement'!D16
A26: FY2025 profit attributable to shareholders (USD 000) | C26: ='Income Statement'!D28
A27: Cost of equity — published-index beta (primary) | C27: =DCF!$C$69
A28: Cost of equity — composite-index beta (alternative) | C28: =DCF!$C$115
A29: Cost of equity at the lower 90% confidence bound on the primary beta | C29: =DCF!$C$123
A30: Cost of equity at the upper 90% confidence bound on the primary beta | C30: =DCF!$C$124
A31: Cost of debt — the three constructions averaged (a simple average, not a weighted figure) | C31: =DCF!$C$92
A32: Cost of debt — the balance-weighted construction alone, published beside the average rather than in place of it | C32: =DCF!$C$93
A33: Cost of capital — explicit window | C33: =DCF!$C$105
A34: Cost of capital — terminal | C34: =DCF!$C$111
A35: Terminal growth | C35: =DCF!$C$39
A36: Sum-of-the-parts cross-check (AED per share) | C36: ='SOTP Bridge'!$C$43
A38: The terminal value share beside the discounted-cash-flow row is a live formula — the present value of the terminal value over the enterprise value of operations — and it is shown again in the equity bridge on the SOTP Bridge sheet. It is high, as it is for any long-lived asset owner whose fleet outlives the forecast window, and it is the reason the terminal cost of capital and the terminal growth rate carry more of this valuation than any single trading year.

Sheet Fundamental Valuation
A1: Fundamental valuation — the four lenses and the contested judgement
A4: Lens / step | B4: Basis | C4: AED per share
A5: Discounted cash flow (own regressed beta) | B5: links to the DCF sheet — five explicit years plus a capitalised terminal value | C5: =DCF!$C$62
A6: bear | B6: beta 1.412 — the TOP of the regression's own 90% confidence interval, not a round number picked by hand — with the rate anchor at 0.85x and capital expenditure at 1.10x. A whole-model re-run | C6: 4.0250073
A7: bull | B7: beta 0.758 — the BOTTOM of the same interval — with the rate anchor at 1.15x and capital expenditure at 0.95x. Taking both bounds from the interval means the published range is the range the estimate itself supports. A whole-model re-run | C7: 10.132159
A8: Relative multiples | B8: blended enterprise and earnings multiples on 2026 earnings | C8: ='Relative & Normalized'!$C$21
A9: Normalised earnings power | B9: the same multiples on the five-year average of the forecast | C9: ='Relative & Normalized'!$C$53
A10: Book value and sustainable return | B10: the book the company already has, plus the present value of earning more than the cost of equity on it while that lasts, plus a fading remainder — a residual income build, not a justified multiple | C10: ='Relative & Normalized'!$C$80
A12: Weighted central | C12: =Summary!$C$9
A14: THE CONTESTED JUDGEMENT — TWO INDEX CONSTRUCTIONS, BOTH CARRIED THROUGH IN FULL
A15: Beta — weekly regression against the published index of its own exchange (primary) | B15: 161 weekly observations, R-squared 15.8%, standard error 0.199, 90% confidence interval 0.758 to 1.412 — the usability gate is passed, and this is the index the method asks for | C15: =Assumptions!$C$14
A16: Cost of equity on the published-index beta | B16: normalised risk-free rate plus beta times the equity risk premium | C16: =DCF!$C$69
A17: Cost of capital on the published-index beta | B17: explicit window, market-value weights | C17: =DCF!$C$105
A18: Fair value per share — published-index beta (AED) | B18: the primary reading | C18: =DCF!$C$62
A19: Weighted central — published-index beta (AED) | B19: all four lenses | C19: =Summary!$C$9
A20: Beta — the same regression against an equal-weight composite of the same exchange's names (alternative) | B20: the published index is weighted by size and is dominated by the same large-capitalisation group this company belongs to; the composite gives the exchange's smallest names the same say as its largest. Only the measure of the market changes | C20: =Assumptions!$C$15
A21: Cost of equity on the composite-index beta | B21: the same construction, the same premium, the composite beta | C21: =DCF!$C$115
A22: Cost of capital on the composite-index beta | B22: explicit window, market-value weights | C22: =DCF!$C$117
A23: Fair value per share — composite-index beta (AED) | B23: the alternative reading | C23: =DCF!$C$141
A24: Weighted central — composite-index beta (AED) | B24: all four lenses, the discounted-cash-flow leg swapped | C24: =Summary!$C$13
A25: Beta — lower bound of the 90% confidence interval on the primary regression | B25: the bull-case beta; the bear and bull cases take the two ends of this interval rather than round numbers picked by hand | C25: =Assumptions!$C$16
A26: Beta — upper bound of the 90% confidence interval on the primary regression | B26: the bear-case beta; the published range is therefore the range the estimate itself supports | C26: =Assumptions!$C$17
A27: These two readings are published side by side and are never averaged into a single number. They are the same regression of the same weekly returns; what differs is how the market itself is measured. The published index of the exchange is what the beta method asks for and is the primary reading. The equal-weight composite is what an earlier construction of this study used, and it is kept in view because a difference of this size is a property of index construction rather than a fact about the company. The regression passes its usability gate, but the history is only three years long and the 90% interval shown above spans more than half the point estimate, so the alternative is not a stress case — it is a second legitimate answer to the same question.
A29: EXPERT PANEL — THREE METHODS, WORKED INDEPENDENTLY
A30: Expert | B30: Method | C30: Base (AED per share) | D30: Low | E30: High
A31: Expert 1 | B31: mid-cycle earnings power | C31: 7.3089016 | D31: 5.4816762 | E31: 9.136127
A32: Expert 2 | B32: owner cash earnings | C32: 6.3021038 | D32: 4.6121737 | E32: 8.8564341
A33: Expert 3 | B33: cash returns against the cost of capital | C33: 4.8929387 | D33: 3.4814178 | E33: 5.9965206
A34: Panel average | C34: =AVERAGE(C31:C33)

Sheet Assumptions
A1: Assumptions — every input in the model
A2: Blue cells are inputs. Change one and the model reprices: everything downstream is a formula.
A4: Market and share anchors
A5: Share price (AED, Abu Dhabi Securities Exchange close) | C5: 6.16
A6: Shares outstanding (mn) | C6: 7398.4988
A7: Dirhams per US dollar (fixed parity, unchanged since 1997) | C7: 3.6725
A8: Stub year fraction — 31 March 2026 valuation date to 31 December 2026 | C8: 0.75
A9: First-quarter 2026 free cash flow, already inside net debt at the valuation date (USD 000) | C9: 130000
A11: Cost of capital
A12: Observed government bond yield (dirham tranche maturing January 2031) | C12: 0.0448
A13: Sovereign default spread (netted out of the risk-free rate) | C13: 0.0042
A14: Beta — own-stock weekly regression against the published index of its own exchange | C14: 1.085
A15: Beta — the same regression against an equal-weight composite of that exchange's names (the disclosed alternative) | C15: 0.705
A16: Beta — lower bound of the regression's 90% confidence interval (the bull-case beta) | C16: 0.758
A17: Beta — upper bound of the regression's 90% confidence interval (the bear-case beta) | C17: 1.412
A18: Beta — lead-lag sum beta from the same series, one lead and two lags | C18: 1.164
A19: Equity risk premium (mature premium plus country risk) | C19: 0.0487 | H19: No sovereign credit-default-swap entry exists for the United Arab Emirates in the country risk file, so the alternative rating-versus-swap premium basis cannot be built for this country; one basis is published rather than two.
A20: Terminal risk-free rate | C20: 0.0325
A21: Statutory corporate tax rate | C21: 0.09
A23: Cost of debt — the evidence behind the three constructions
A24: Secured overnight financing rate | C24: 0.0365 | H24: The Central Bank base rate of 3.65% was maintained at the 29 July 2026 decision; the last change was a 25 basis point cut from 3.90% on 10 December 2025.
A25: Parent revolving credit facility margin | C25: 0.008
A26: Third-party bank loans — low end of the disclosed range | C26: 0.0711
A27: Third-party bank loans — high end of the disclosed range | C27: 0.0755
A28: Other third-party borrowings — low end of the disclosed range | C28: 0.0436
A29: Other third-party borrowings — high end of the disclosed range | C29: 0.0831
A30: Lease interest charged in 2025 (USD 000) | C30: 12719
A31: Lease liabilities, opening balance 2025 (USD 000) | C31: 170274
A32: Lease liabilities, closing balance 2025 (USD 000) | C32: 223153
A33: Shareholder loan at 31 March 2026 (USD 000) | C33: 500000
A34: Third-party borrowings at 31 March 2026 (USD 000) | C34: 402763
A35: Lease liabilities at 31 March 2026 (USD 000) | C35: 212449
A37: Tanker fleet — vessel counts by class | B37: Handysize | C37: Medium range | D37: Long range 1 | E37: Long range 2 | F37: Very large crude carrier
A38: Vessels owned at 31 December 2025 | B38: 2 | C38: 16 | D38: 9 | E38: 17 | F38: 9
A39: Less vessels sold between the year end and the valuation date | B39: 0 | C39: 0 | D39: 0 | E39: 0 | F39: 1
A41: Tanker rates — the published blended rate by class and quarter (USD per day). It is a BLEND across the whole class, charters out included; the spot rate is solved out of it on the Segments sheet, never read off it | B41: First quarter | C41: Second quarter | D41: Third quarter | E41: Fourth quarter
A42: Long range 1 — 2024 | B42: 51645 | C42: 49424 | D42: 31911 | E42: 27640
A43: Long range 2 — 2024 | B43: 60038 | C43: 63734 | D43: 36237 | E43: 32034
A44: Very large crude carrier — 2024 | B44: 54580 | C44: 46097 | D44: 39681 | E44: 33167
A45: Medium range — 2025 | B45: 23459 | C45: 25161 | D45: 23391 | E45: 24547 | H45: The handysize class is not broken out in the disclosure, so the medium-range rate stands in for it — SCALED by the disclosed relative move, because the company said handysize rates fell 21% while medium range rose 29%, and an unadjusted substitution therefore had the sign wrong. The gap is still flagged. The 2024 quarterly rates for the medium-range class are not disclosed either, so its 2025 average stands in on both sides of the mid-cycle average.
...

Sheet SOTP Bridge
A1: Enterprise value to equity — the bridge, and the sum-of-the-parts cross-check
A2: USD thousand unless stated. Per-share figures in dirhams at the fixed parity.
A4: Step | C4: USD 000 | D4: AED per share
A5: Present value of the five forecast years | C5: =DCF!$C$45 | D5: =C5/Assumptions!$C$6/1000*Assumptions!$C$7
A6: Present value of the terminal value | C6: =DCF!$C$46 | D6: =C6/Assumptions!$C$6/1000*Assumptions!$C$7
A7: Enterprise value of operations | C7: =C5+C6 | D7: =C7/Assumptions!$C$6/1000*Assumptions!$C$7
A8: Terminal value as a share of enterprise value | C8: =C6/C7
A9: Plus joint ventures and associates at carrying value | C9: =Assumptions!$C$157 | D9: =C9/Assumptions!$C$6/1000*Assumptions!$C$7
A10: Enterprise value | C10: =C7+C9 | D10: =C10/Assumptions!$C$6/1000*Assumptions!$C$7
A11: Less net debt at 31 March 2026 | C11: =-Assumptions!$C$150 | D11: =C11/Assumptions!$C$6/1000*Assumptions!$C$7
A12: Less deferred consideration on acquisitions | C12: =-Assumptions!$C$151 | D12: =C12/Assumptions!$C$6/1000*Assumptions!$C$7
A13: Less the eleven vessels bought on 7 August 2026, at the announced price | C13: =-Assumptions!$C$82 | D13: =C13/Assumptions!$C$6/1000*Assumptions!$C$7
A14: Less perpetual capital securities at carrying value | C14: =-Assumptions!$C$152 | D14: =C14/Assumptions!$C$6/1000*Assumptions!$C$7
A15: Equity value before the minorities | C15: =C10+C11+C12+C13+C14 | D15: =C15/Assumptions!$C$6/1000*Assumptions!$C$7
A16: Less non-controlling interests — the contracted slice at its contracted price, the rest at the greater of book and value | C16: =DCF!$C$59 | D16: =C16/Assumptions!$C$6/1000*Assumptions!$C$7
A17: Equity attributable to ordinary shareholders | C17: =C15+C16 | D17: =C17/Assumptions!$C$6/1000*Assumptions!$C$7
A18: Fair value per share (USD) | C18: =C17/Assumptions!$C$6/1000
A19: Fair value per share (AED) | C19: =C18*Assumptions!$C$7
A21: THE SUM-OF-THE-PARTS CROSS-CHECK — EACH LEG ON ITS OWN MULTIPLE | C21: 2026E EBITDA | D21: Multiple | E21: Enterprise value | F21: Basis
A22: Integrated Logistics | B22: =Segments!B204 | C22: =C28 | D22: =B22*C22 | E22: a contracted-fleet multiple, because this leg earns under long-term contracts
A23: Shipping | B23: =Segments!B205 | C23: =C31 | D23: =B23*C23 | E23: a blend of the contracted and spot multiples, weighted by the company's own disclosed share of earnings exposed to spot rates
A24: Services | B24: =Segments!B206 | C24: =C28 | D24: =B24*C24 | E24: a contracted-fleet multiple, because this leg earns under long-term contracts
A25: Enterprise value of the operating legs | D25: =SUM(D22:D24)
A27: THE SHIPPING MULTIPLE, BUILT — NOT PASTED
A28: Contracted-fleet multiple (long-term contracted gas shipping peer) | C28: ='Peer & Sector'!$C$10
A29: Spot-tanker multiple (average of the two spot-tanker peers) | C29: ='Peer & Sector'!$C$11
A30: Share of 2026 earnings exposed to spot rates, as disclosed | C30: =Assumptions!$C$167
A31: Shipping multiple — the two weighted by that share | C31: =(1-C30)*C28+C30*C29
A33: THE SUM-OF-THE-PARTS BRIDGE TO EQUITY
A34: Enterprise value of the operating legs | C34: =D25
A35: Plus joint ventures and associates at carrying value | C35: =Assumptions!$C$157
A36: Enterprise value | C36: =C34+C35
A37: Less net debt at 31 March 2026 | C37: =-Assumptions!$C$150
A38: Less deferred consideration on acquisitions | C38: =-Assumptions!$C$151
A39: Less the eleven vessels bought on 7 August 2026, at the announced price | C39: =-Assumptions!$C$82
A40: Less perpetual capital securities at carrying value | C40: =-Assumptions!$C$152
A41: Less non-controlling interests at carrying value | C41: =-Assumptions!$C$154
A42: Equity attributable to ordinary shareholders | C42: =C36+C37+C38+C39+C40+C41
A43: Sum-of-the-parts fair value per share (AED) | C43: =C42/Assumptions!$C$6/1000*Assumptions!$C$7
A45: The sum-of-the-parts is a cross-check on the discounted cash flow, not a fifth lens: it prices each business unit's 2026 earnings on the multiple the market is paying for that kind of earnings stream, and the Shipping leg is the only one that carries spot exposure, which is why its multiple is a weighted blend rather than a single peer figure.

Sheet Segments
A1: Segments — the disclosed record and the unit build
A2: USD thousand unless stated. The tanker fleet is built vessel by vessel; every forecast figure below is a formula.
A4: Segment revenue — as disclosed (USD 000) | B4: FY2023 | C4: FY2024 | D4: FY2025
A5: Offshore Contracting | B5: 974525 | C5: 1108200 | D5: 1368875
A6: Offshore Services | B6: 500751 | C6: 552790 | D6: 628915
A7: Offshore Projects | B7: 157146 | C7: 619930 | D7: 531333
A8: Tankers | B8: 407370 | C8: 516530 | D8: 1719714
A9: Gas Carriers | B9: 173550 | C9: 152650 | D9: 179794
A10: Dry-Bulk and Containers | B10: 257900 | C10: 286820 | D10: 225048
A11: Services | B11: 283910 | C11: 312410 | D11: 362433
A12: Total revenue | B12: =SUM(B5:B11) | C12: =SUM(C5:C11) | D12: =SUM(D5:D11)
A14: Segment EBITDA — as disclosed (USD 000) | B14: FY2023 | C14: FY2024 | D14: FY2025
A15: Offshore Contracting | B15: 424419 | C15: 497703 | D15: 623065
A16: Offshore Services | B16: 92741 | C16: 134880 | D16: 178369
A17: Offshore Projects | B17: 10439 | C17: 54240 | D17: 28024
A18: Tankers | B18: 159260 | C18: 239700 | D18: 451220
A19: Gas Carriers | B19: 101022 | C19: 87308 | D19: 129547
A20: Dry-Bulk and Containers | B20: 60280 | C20: 69440 | D20: 37862
A21: Services | B21: 44488 | C21: 56000 | D21: 60273
A22: Total segment EBITDA | B22: =SUM(B15:B21) | C22: =SUM(C15:C21) | D22: =SUM(D15:D21)
A23: Segment EBITDA margin | B23: =B22/B12 | C23: =C22/C12 | D23: =D22/D12
A25: TANKERS — THE UNIT BUILD, VESSEL BY VESSEL | B25: Handysize | C25: Medium range | D25: Long range 1 | E25: Long range 2 | F25: Very large crude carrier
A26: Vessels owned at 31 December 2025 | B26: =Assumptions!$B$38 | C26: =Assumptions!$C$38 | D26: =Assumptions!$D$38 | E26: =Assumptions!$E$38 | F26: =Assumptions!$F$38
A27: Less vessels sold between the year end and the valuation date | B27: =Assumptions!$B$39 | C27: =Assumptions!$C$39 | D27: =Assumptions!$D$39 | E27: =Assumptions!$E$39 | F27: =Assumptions!$F$39
A28: Vessels owned at the 31 March 2026 valuation date | B28: =B26-B27 | C28: =C26-C27 | D28: =D26-D27 | E28: =E26-E27 | F28: =F26-F27
A29: Vessels bought in the purchase announced 7 August 2026 | B29: =0 | C29: =0 | D29: =0 | E29: =0 | F29: =Assumptions!$B$83
A30: Their delivery date — they earn nothing before it and at the implied spot rate after it | B30: =0 | C30: =0 | D30: =0 | E30: =0 | F30: =Assumptions!$C$83
A32: THE PUBLISHED BLEND, CONVERTED TO A SPOT RATE — WINDOW BY WINDOW. The company publishes ONE rate per class and states it is a blend across the whole class, charters out included, so the spot rate is SOLVED out of it here | B32: Q1 2025 | C32: Q2 2025 | D32: Q3 2025 | E32: Q4 2025 | F32: Q1 2026 | G32: Q2 2026 | H32: Mid-cycle anchor
A33: Window begins | B33: =Assumptions!$B$74 | C33: =Assumptions!$C$74 | D33: =Assumptions!$D$74 | E33: =Assumptions!$E$74 | F33: =Assumptions!$F$74 | G33: =Assumptions!$G$74 | H33: =B33
A34: Window ends | B34: =Assumptions!$B$75 | C34: =Assumptions!$C$75 | D34: =Assumptions!$D$75 | E34: =Assumptions!$E$75 | F34: =Assumptions!$F$75 | G34: =Assumptions!$G$75 | H34: =B34
A35: Days in the window | B35: =B34-B33 | C35: =C34-C33 | D35: =D34-D33 | E35: =E34-E33 | F35: =F34-F33 | G35: =G34-G33 | H35: =H34-H33
A37: Published blended rate by class (USD per day)
A38: Handysize | B38: =AVERAGE(Assumptions!$B$45:$E$45)*Assumptions!$C$57 | C38: =AVERAGE(Assumptions!$B$45:$E$45)*Assumptions!$C$57 | D38: =AVERAGE(Assumptions!$B$45:$E$45)*Assumptions!$C$57 | E38: =AVERAGE(Assumptions!$B$45:$E$45)*Assumptions!$C$57 | F38: =Assumptions!$B$51*Assumptions!$C$57 | G38: =Assumptions!$C$51*Assumptions!$C$57 | H38: =AVERAGE(Assumptions!$B$45:$E$45)*Assumptions!$C$57
A39: Medium range | B39: =Assumptions!$B$45 | C39: =Assumptions!$C$45 | D39: =Assumptions!$D$45 | E39: =Assumptions!$E$45 | F39: =Assumptions!$B$51 | G39: =Assumptions!$C$51 | H39: =AVERAGE(Assumptions!$B$45:$E$45)
A40: Long range 1 | B40: =Assumptions!$B$46 | C40: =Assumptions!$C$46 | D40: =Assumptions!$D$46 | E40: =Assumptions!$E$46 | F40: =Assumptions!$B$52 | G40: =Assumptions!$C$52 | H40: =(AVERAGE(Assumptions!$B$42:$E$42)+AVERAGE(Assumptions!$B$46:$E$46))/2
A41: Long range 2 | B41: =Assumptions!$B$47 | C41: =Assumptions!$C$47 | D41: =Assumptions!$D$47 | E41: =Assumptions!$E$47 | F41: =Assumptions!$B$53 | G41: =Assumptions!$C$53 | H41: =(AVERAGE(Assumptions!$B$43:$E$43)+AVERAGE(Assumptions!$B$47:$E$47))/2
A42: Very large crude carrier | B42: =Assumptions!$B$48 | C42: =Assumptions!$C$48 | D42: =Assumptions!$D$48 | E42: =Assumptions!$E$48 | F42: =Assumptions!$B$54 | G42: =Assumptions!$C$54 | H42: =(AVERAGE(Assumptions!$B$44:$E$44)+AVERAGE(Assumptions!$B$48:$E$48))/2
A44: Class vessel-days in the window — vessels owned x days
A45: Handysize | B45: =$B$26*B$35 | C45: =$B$26*C$35 | D45: =$B$26*D$35 | E45: =$B$26*E$35 | F45: =$B$28*F$35 | G45: =$B$28*G$35 | H45: =$B$26*H$35
A46: Medium range | B46: =$C$26*B$35 | C46: =$C$26*C$35 | D46: =$C$26*D$35 | E46: =$C$26*E$35 | F46: =$C$28*F$35 | G46: =$C$28*G$35 | H46: =$C$26*H$35
...

Sheet Relative & Normalized
A1: Relative multiples, normalised earnings power and the book lens
A2: USD thousand unless stated. Per-share figures in dirhams.
A4: Relative lens | C4: Value
A5: FY2026E group EBITDA | C5: =DCF!B6
A6: Blended enterprise multiple | C6: ='Peer & Sector'!$C$13
A7: Implied enterprise value | C7: =C5*C6
A8: Plus joint ventures and associates at carrying value | C8: =Assumptions!$C$157
A9: Less net debt at 31 March 2026 | C9: =-Assumptions!$C$150
A10: Less deferred consideration on acquisitions | C10: =-Assumptions!$C$151
A11: Less the eleven vessels bought on 7 August 2026, at the announced price | C11: =-Assumptions!$C$82
A12: Less perpetual capital securities at carrying value | C12: =-Assumptions!$C$152
A13: Implied equity value before the minorities | C13: =C7+C8+C9+C10+C11+C12
A14: Less non-controlling interests — the contracted slice at its contracted price, the rest at the greater of book and value | C14: =-(DCF!$C$56+MAX(DCF!$C$57,C13*DCF!$C$58))
A15: Implied equity attributable to ordinary shareholders | C15: =C13+C14
A16: Value per share on the enterprise multiple (AED) | C16: =C15/Assumptions!$C$6/1000*Assumptions!$C$7
A17: Blended FORWARD price/earnings — applied to forward earnings below, so the multiple and the earnings are on the same basis | C17: ='Peer & Sector'!$C$16
A18: FY2026E earnings attributable to ordinary shareholders | C18: ='Income Statement'!E30
A19: Value per share on the earnings multiple (AED) | C19: =C18*C17/Assumptions!$C$6/1000*Assumptions!$C$7
A20: Weight on the enterprise multiple | C20: =Assumptions!$C$169
A21: RELATIVE LENS — value per share (AED) | C21: =C20*C16+(1-C20)*C19
A22: Bear and bull — enterprise value on the spot-tanker multiple (C) / on the contracted multiple (D) | C22: =C5*'Peer & Sector'!$C$11 | D22: =C5*'Peer & Sector'!$C$10
A23: Equity value before the minorities | C23: =C22+Assumptions!$C$157-Assumptions!$C$150-Assumptions!$C$151-Assumptions!$C$82-Assumptions!$C$152 | D23: =D22+Assumptions!$C$157-Assumptions!$C$150-Assumptions!$C$151-Assumptions!$C$82-Assumptions!$C$152
A24: Less non-controlling interests — the same two-part deduction | C24: =-(DCF!$C$56+MAX(DCF!$C$57,C23*DCF!$C$58)) | D24: =-(DCF!$C$56+MAX(DCF!$C$57,D23*DCF!$C$58))
A25: Equity attributable to ordinary shareholders | C25: =C23+C24 | D25: =D23+D24
A26: Bear on the spot multiple (C) / bull on the contracted multiple (D), same construction | C26: =C25/Assumptions!$C$6/1000*Assumptions!$C$7 | D26: =D25/Assumptions!$C$6/1000*Assumptions!$C$7
A28: THE COMPANY'S OWN MULTIPLES AT THE ANCHOR PRICE
A29: Share price (USD) | C29: =Assumptions!$C$5/Assumptions!$C$7
A30: Market capitalisation (USD 000) | C30: =C29*Assumptions!$C$6*1000
A31: Net debt including the deferred consideration and the vessels bought on 7 August 2026 (USD 000) | C31: =Assumptions!$C$150+Assumptions!$C$151+Assumptions!$C$82
A32: Enterprise value (USD 000) | C32: =C30+C31
A33: Enterprise value / 2025 reported EBITDA | C33: =C32/'Income Statement'!D16
A34: Enterprise value / FY2026E EBITDA | C34: =C32/C5
A35: Price / 2025 earnings attributable to ordinary shareholders — the TRAILING basis | C35: =C30/'Income Statement'!D30
A36: Price / FY2026E earnings attributable to ordinary shareholders — the FORWARD basis, the one the peer multiples are quoted on | C36: =C30/C18
A37: Price / book at 31 March 2026 | C37: =C30/(Assumptions!$C$158+Assumptions!$C$152)
A38: Dividend yield on the 2026 distribution | C38: =Assumptions!$C$162/C30
A39: Enterprise value on the equity bridge's own convention — adding the perpetual capital securities and the minorities (USD 000) | C39: =C32+Assumptions!$C$152+Assumptions!$C$154
A40: Enterprise value / 2025 reported EBITDA — bridge convention | C40: =C39/'Income Statement'!D16
A41: Enterprise value / FY2026E EBITDA — bridge convention | C41: =C39/C5
A42: The two multiples immediately above are the company's own on the SAME enterprise value the equity bridge uses. The three rows before them use the narrower market-capitalisation-plus-net-debt convention, because that is the convention the peer figures are published on and the comparison has to be like for like. Both are shown rather than one chosen.
...

Sheet DCF
A1: Discounted cash flow — the full waterfall
A2: USD thousand. Every line is a live formula: the cost of capital is built below from its own components, the discount factors compound year on year off the glide, and 2026 is a three-quarter stub because the valuation date is 31 March 2026.
A4: USD 000 | B4: FY2026E | C4: FY2027E | D4: FY2028E | E4: FY2029E | F4: FY2030E
A5: Revenue | B5: =Segments!B187 | C5: =Segments!C187 | D5: =Segments!D187 | E5: =Segments!E187 | F5: =Segments!F187
A6: EBITDA | B6: =Segments!B197 | C6: =Segments!C197 | D6: =Segments!D197 | E6: =Segments!E197 | F6: =Segments!F197
A7: EBITDA margin | B7: =B6/B5 | C7: =C6/C5 | D7: =D6/D5 | E7: =E6/E5 | F7: =F6/F5
A8: Less depreciation and amortisation | B8: =-'Balance Sheet'!B39 | C8: =-'Balance Sheet'!C39 | D8: =-'Balance Sheet'!D39 | E8: =-'Balance Sheet'!E39 | F8: =-'Balance Sheet'!F39
A9: EBIT | B9: =B6+B8 | C9: =C6+C8 | D9: =D6+D8 | E9: =E6+E8 | F9: =F6+F8
A10: Less tax on operating profit — the business-unit mix below | B10: =-B35 | C10: =-C35 | D10: =-D35 | E10: =-E35 | F10: =-F35
A11: NOPAT | B11: =B9+B10 | C11: =C9+C10 | D11: =D9+D10 | E11: =E9+E10 | F11: =F9+F10
A12: Add back depreciation and amortisation | B12: =-B8 | C12: =-C8 | D12: =-D8 | E12: =-E8 | F12: =-F8
A13: Less capital expenditure | B13: =-Assumptions!$B$120 | C13: =-Assumptions!$C$120 | D13: =-Assumptions!$D$120 | E13: =-Assumptions!$E$120 | F13: =-Assumptions!$F$120
A14: Less change in working capital | B14: =-'Balance Sheet'!B50 | C14: =-'Balance Sheet'!C50 | D14: =-'Balance Sheet'!D50 | E14: =-'Balance Sheet'!E50 | F14: =-'Balance Sheet'!F50
A15: Free cash flow to the firm | B15: =B11+B12+B13+B14 | C15: =C11+C12+C13+C14 | D15: =D11+D12+D13+D14 | E15: =E11+E12+E13+E14 | F15: =F11+F12+F13+F14
A16: Less first-quarter 2026 free cash flow, already inside net debt at the valuation date | B16: =-Assumptions!$C$9 | C16: =0 | D16: =0 | E16: =0 | F16: =0
A17: Free cash flow discounted from 31 March 2026 | B17: =B15+B16 | C17: =C15+C16 | D17: =D15+D16 | E17: =E15+E16 | F17: =F15+F16
A18: Forward cost of capital — the glide from current to terminal | B18: =$C$105+($C$111-$C$105)*1/5 | C18: =$C$105+($C$111-$C$105)*2/5 | D18: =$C$105+($C$111-$C$105)*3/5 | E18: =$C$105+($C$111-$C$105)*4/5 | F18: =$C$105+($C$111-$C$105)*5/5
A19: Discount factor — each year compounded onto the last | B19: =1/(1+B18)^Assumptions!$C$8 | C19: =B19/(1+C18) | D19: =C19/(1+D18) | E19: =D19/(1+E18) | F19: =E19/(1+F18)
A20: Present value of free cash flow | B20: =B17*B19 | C20: =C17*C19 | D20: =D17*D19 | E20: =E17*E19 | F20: =F17*F19
A22: THE TAX MIX — EACH BUSINESS UNIT AT ITS OWN DISCLOSED RATE | B22: FY2026E | C22: FY2027E | D22: FY2028E | E22: FY2029E | F22: FY2030E
A23: Integrated Logistics — EBITDA | B23: =Segments!B204 | C23: =Segments!C204 | D23: =Segments!D204 | E23: =Segments!E204 | F23: =Segments!F204
A24: Shipping — EBITDA | B24: =Segments!B205 | C24: =Segments!C205 | D24: =Segments!D205 | E24: =Segments!E205 | F24: =Segments!F205
A25: Services — EBITDA | B25: =Segments!B206 | C25: =Segments!C206 | D25: =Segments!D206 | E25: =Segments!E206 | F25: =Segments!F206
A26: Integrated Logistics — share of depreciation and amortisation | B26: =-B8*(Assumptions!$C$141+Assumptions!$C$142+Assumptions!$C$143)/(Assumptions!$C$141+Assumptions!$C$142+Assumptions!$C$143+Assumptions!$C$144+Assumptions!$C$145+Assumptions!$C$146+Assumptions!$C$147) | C26: =-C8*(Assumptions!$C$141+Assumptions!$C$142+Assumptions!$C$143)/(Assumptions!$C$141+Assumptions!$C$142+Assumptions!$C$143+Assumptions!$C$144+Assumptions!$C$145+Assumptions!$C$146+Assumptions!$C$147) | D26: =-D8*(Assumptions!$C$141+Assumptions!$C$142+Assumptions!$C$143)/(Assumptions!$C$141+Assumptions!$C$142+Assumptions!$C$143+Assumptions!$C$144+Assumptions!$C$145+Assumptions!$C$146+Assumptions!$C$147) | E26: =-E8*(Assumptions!$C$141+Assumptions!$C$142+Assumptions!$C$143)/(Assumptions!$C$141+Assumptions!$C$142+Assumptions!$C$143+Assumptions!$C$144+Assumptions!$C$145+Assumptions!$C$146+Assumptions!$C$147) | F26: =-F8*(Assumptions!$C$141+Assumptions!$C$142+Assumptions!$C$143)/(Assumptions!$C$141+Assumptions!$C$142+Assumptions!$C$143+Assumptions!$C$144+Assumptions!$C$145+Assumptions!$C$146+Assumptions!$C$147)
A27: Shipping — share of depreciation and amortisation | B27: =-B8*(Assumptions!$C$144+Assumptions!$C$145+Assumptions!$C$146)/(Assumptions!$C$141+Assumptions!$C$142+Assumptions!$C$143+Assumptions!$C$144+Assumptions!$C$145+Assumptions!$C$146+Assumptions!$C$147) | C27: =-C8*(Assumptions!$C$144+Assumptions!$C$145+Assumptions!$C$146)/(Assumptions!$C$141+Assumptions!$C$142+Assumptions!$C$143+Assumptions!$C$144+Assumptions!$C$145+Assumptions!$C$146+Assumptions!$C$147) | D27: =-D8*(Assumptions!$C$144+Assumptions!$C$145+Assumptions!$C$146)/(Assumptions!$C$141+Assumptions!$C$142+Assumptions!$C$143+Assumptions!$C$144+Assumptions!$C$145+Assumptions!$C$146+Assumptions!$C$147) | E27: =-E8*(Assumptions!$C$144+Assumptions!$C$145+Assumptions!$C$146)/(Assumptions!$C$141+Assumptions!$C$142+Assumptions!$C$143+Assumptions!$C$144+Assumptions!$C$145+Assumptions!$C$146+Assumptions!$C$147) | F27: =-F8*(Assumptions!$C$144+Assumptions!$C$145+Assumptions!$C$146)/(Assumptions!$C$141+Assumptions!$C$142+Assumptions!$C$143+Assumptions!$C$144+Assumptions!$C$145+Assumptions!$C$146+Assumptions!$C$147)
A28: Services — share of depreciation and amortisation | B28: =-B8*(Assumptions!$C$147)/(Assumptions!$C$141+Assumptions!$C$142+Assumptions!$C$143+Assumptions!$C$144+Assumptions!$C$145+Assumptions!$C$146+Assumptions!$C$147) | C28: =-C8*(Assumptions!$C$147)/(Assumptions!$C$141+Assumptions!$C$142+Assumptions!$C$143+Assumptions!$C$144+Assumptions!$C$145+Assumptions!$C$146+Assumptions!$C$147) | D28: =-D8*(Assumptions!$C$147)/(Assumptions!$C$141+Assumptions!$C$142+Assumptions!$C$143+Assumptions!$C$144+Assumptions!$C$145+Assumptions!$C$146+Assumptions!$C$147) | E28: =-E8*(Assumptions!$C$147)/(Assumptions!$C$141+Assumptions!$C$142+Assumptions!$C$143+Assumptions!$C$144+Assumptions!$C$145+Assumptions!$C$146+Assumptions!$C$147) | F28: =-F8*(Assumptions!$C$147)/(Assumptions!$C$141+Assumptions!$C$142+Assumptions!$C$143+Assumptions!$C$144+Assumptions!$C$145+Assumptions!$C$146+Assumptions!$C$147)
A29: Integrated Logistics — taxable profit | B29: =MAX(B23-B26,0) | C29: =MAX(C23-C26,0) | D29: =MAX(D23-D26,0) | E29: =MAX(E23-E26,0) | F29: =MAX(F23-F26,0)
A30: Shipping — taxable profit | B30: =MAX(B24-B27,0) | C30: =MAX(C24-C27,0) | D30: =MAX(D24-D27,0) | E30: =MAX(E24-E27,0) | F30: =MAX(F24-F27,0)
A31: Services — taxable profit | B31: =MAX(B25-B28,0) | C31: =MAX(C25-C28,0) | D31: =MAX(D25-D28,0) | E31: =MAX(E25-E28,0) | F31: =MAX(F25-F28,0)
A32: Integrated Logistics — tax charge at 9% | B32: =B29*Assumptions!$C$138 | C32: =C29*Assumptions!$C$138 | D32: =D29*Assumptions!$C$138 | E32: =E29*Assumptions!$C$138 | F32: =F29*Assumptions!$C$138
A33: Shipping — tax charge at 1% | B33: =B30*Assumptions!$C$139 | C33: =C30*Assumptions!$C$139 | D33: =D30*Assumptions!$C$139 | E33: =E30*Assumptions!$C$139 | F33: =F30*Assumptions!$C$139
A34: Services — tax charge at 4% | B34: =B31*Assumptions!$C$140 | C34: =C31*Assumptions!$C$140 | D34: =D31*Assumptions!$C$140 | E34: =E31*Assumptions!$C$140 | F34: =F31*Assumptions!$C$140
A35: Tax on operating profit | B35: =SUM(B32:B34) | C35: =SUM(C32:C34) | D35: =SUM(D32:D34) | E35: =SUM(E32:E34) | F35: =SUM(F32:F34)
A36: Effective tax rate on operating profit | B36: =B35/B9 | C36: =C35/C9 | D36: =D35/D9 | E36: =E35/E9 | F36: =F35/F9
A38: TERMINAL VALUE AND THE BRIDGE TO EQUITY
A39: Terminal growth | C39: =Assumptions!$C$164
A40: Terminal invested capital | C40: ='Balance Sheet'!I26
A41: Terminal return on invested capital | C41: =F11/C40
A42: Required reinvestment rate — terminal growth over the return on invested capital | C42: =C39/C41
A43: Terminal-year NOPAT grown one year | C43: =F11*(1+C39)
...

Sheet Income Statement
A1: Income statement — three years audited, five years forecast
A2: USD thousand, consolidated. History is the audited record; every forecast line is a formula.
A4: USD 000 | B4: FY2023 | C4: FY2024 | D4: FY2025 | E4: FY2026E | F4: FY2027E | G4: FY2028E | H4: FY2029E | I4: FY2030E
A5: Revenue | B5: =Segments!B12 | C5: =Segments!C12 | D5: =Segments!D12 | E5: =DCF!B5 | F5: =DCF!C5 | G5: =DCF!D5 | H5: =DCF!E5 | I5: =DCF!F5
A6: Direct costs | B6: -2003225 | C6: -2608784 | D6: -3908236 | E6: - | F6: - | G6: - | H6: - | I6: -
A7: Gross profit | B7: =B5+B6 | C7: =C5+C6 | D7: =D5+D6 | E7: - | F7: - | G7: - | H7: - | I7: -
A8: General and administrative expenses | B8: -146436 | C8: -141522 | D8: -204983 | E8: - | F8: - | G8: - | H8: - | I8: -
A9: Expected credit losses | B9: -2672 | C9: 2649 | D9: -9590 | E9: - | F9: - | G9: - | H9: - | I9: -
A10: Other income | B10: 10865 | C10: 19896 | D10: 50459 | E10: - | F10: - | G10: - | H10: - | I10: -
A11: Other expenses | B11: 0 | C11: -4310 | D11: 0 | E11: - | F11: - | G11: - | H11: - | I11: -
A12: Operating profit | B12: =B7+B8+B9+B10+B11 | C12: =C7+C8+C9+C10+C11 | D12: =D7+D8+D9+D10+D11 | E12: =E14-E13 | F12: =F14-F13 | G12: =G14-G13 | H12: =H14-H13 | I12: =I14-I13
A13: Depreciation and amortisation | B13: 248526 | C13: 317339 | D13: 524809 | E13: ='Balance Sheet'!B39 | F13: ='Balance Sheet'!C39 | G13: ='Balance Sheet'!D39 | H13: ='Balance Sheet'!E39 | I13: ='Balance Sheet'!F39
A14: EBITDA (operating) | B14: =B12+B13 | C14: =C12+C13 | D14: =D12+D13 | E14: =DCF!B6 | F14: =DCF!C6 | G14: =DCF!D6 | H14: =DCF!E6 | I14: =DCF!F6
A15: Add share of joint ventures and one-off gains carried in reported EBITDA | B15: =B19+B20+B21 | C15: =C19+C20+C21 | D15: =D19+D20+D21 | E15: - | F15: - | G15: - | H15: - | I15: -
A16: EBITDA as reported | B16: =B14+B15 | C16: =C14+C15 | D16: =D14+D15 | E16: =E14 | F16: =F14 | G16: =G14 | H16: =H14 | I16: =I14
A17: Total operating costs | B17: =B5-B14 | C17: =C5-C14 | D17: =D5-D14 | E17: =E5-E14 | F17: =F5-F14 | G17: =G5-G14 | H17: =H5-H14 | I17: =I5-I14
A18: EBITDA margin (operating) | B18: =B14/B5 | C18: =C14/C5 | D18: =D14/D5 | E18: =E14/E5 | F18: =F14/F5 | G18: =G14/G5 | H18: =H14/H5 | I18: =I14/I5
A19: Share of joint ventures and associates | B19: 14071 | C19: 14198 | D19: 37392 | E19: - | F19: - | G19: - | H19: - | I19: -
A20: Gain on bargain purchase | B20: 0 | C20: 0 | D20: 12056 | E20: - | F20: - | G20: - | H20: - | I20: -
A21: Loss on the previously held interest | B21: 0 | C21: 0 | D21: -3398 | E21: - | F21: - | G21: - | H21: - | I21: -
A22: Finance income | B22: 9785 | C22: 15594 | D22: 18959 | E22: =Assumptions!$C$24*Assumptions!$C$159 | F22: =Assumptions!$C$24*Assumptions!$C$159 | G22: =Assumptions!$C$24*Assumptions!$C$159 | H22: =Assumptions!$C$24*Assumptions!$C$159 | I22: =Assumptions!$C$24*Assumptions!$C$159
A23: Finance costs | B23: -15098 | C23: -18034 | D23: -87143 | E23: =-DCF!$C$92*'Balance Sheet'!B54 | F23: =-DCF!$C$92*'Balance Sheet'!C54 | G23: =-DCF!$C$92*'Balance Sheet'!D54 | H23: =-DCF!$C$92*'Balance Sheet'!E54 | I23: =-DCF!$C$92*'Balance Sheet'!F54
A24: Profit before tax | B24: =B12+B19+B20+B21+B22+B23 | C24: =C12+C19+C20+C21+C22+C23 | D24: =D12+D19+D20+D21+D22+D23 | E24: =E12+E22+E23 | F24: =F12+F22+F23 | G24: =G12+G22+G23 | H24: =H12+H22+H23 | I24: =I12+I22+I23
A25: Income tax | B25: -2283 | C25: -72847 | D25: -58781 | E25: =-E24*DCF!B36 | F25: =-F24*DCF!C36 | G25: =-G24*DCF!D36 | H25: =-H24*DCF!E36 | I25: =-I24*DCF!F36
A26: Profit for the year | B26: =B24+B25 | C26: =C24+C25 | D26: =D24+D25 | E26: =E24+E25 | F26: =F24+F25 | G26: =G24+G25 | H26: =H24+H25 | I26: =I24+I25
A27: Non-controlling interests | B27: 0 | C27: 0 | D27: -24306 | E27: =-E26*Assumptions!$C$156 | F27: =-F26*Assumptions!$C$156 | G27: =-G26*Assumptions!$C$156 | H27: =-H26*Assumptions!$C$156 | I27: =-I26*Assumptions!$C$156
A28: Profit attributable to shareholders | B28: =B26+B27 | C28: =C26+C27 | D28: =D26+D27 | E28: =E26+E27 | F28: =F26+F27 | G28: =G26+G27 | H28: =H26+H27 | I28: =I26+I27
A29: Perpetual capital securities coupon | B29: 0 | C29: 0 | D29: -61333 | E29: =-Assumptions!$C$152*(Assumptions!$C$24+Assumptions!$C$153) | F29: =-Assumptions!$C$152*(Assumptions!$C$24+Assumptions!$C$153) | G29: =-Assumptions!$C$152*(Assumptions!$C$24+Assumptions!$C$153) | H29: =-Assumptions!$C$152*(Assumptions!$C$24+Assumptions!$C$153) | I29: =-Assumptions!$C$152*(Assumptions!$C$24+Assumptions!$C$153)
A30: Earnings attributable to ordinary shareholders, AFTER the perpetual capital securities coupon | B30: =B28+B29 | C30: =C28+C29 | D30: =D28+D29 | E30: =E28+E29 | F30: =F28+F29 | G30: =G28+G29 | H30: =H28+H29 | I30: =I28+I29
A31: Earnings per ordinary share, AFTER the perpetual coupon (USD) — the coupon ranks ahead of the ordinary shares, so it comes out of the numerator | B31: =B30/Assumptions!$C$6/1000 | C31: =C30/Assumptions!$C$6/1000 | D31: =D30/Assumptions!$C$6/1000 | E31: =E30/Assumptions!$C$6/1000 | F31: =F30/Assumptions!$C$6/1000 | G31: =G30/Assumptions!$C$6/1000 | H31: =H30/Assumptions!$C$6/1000 | I31: =I30/Assumptions!$C$6/1000
A32: Earnings per ordinary share, AFTER the perpetual coupon (AED) | B32: =B31*Assumptions!$C$7 | C32: =C31*Assumptions!$C$7 | D32: =D31*Assumptions!$C$7 | E32: =E31*Assumptions!$C$7 | F32: =F31*Assumptions!$C$7 | G32: =G31*Assumptions!$C$7 | H32: =H31*Assumptions!$C$7 | I32: =I31*Assumptions!$C$7
A33: Memorandum — earnings per share BEFORE the perpetual coupon (USD), on attributable profit; shown so the two are never confused | B33: =B28/Assumptions!$C$6/1000 | C33: =C28/Assumptions!$C$6/1000 | D33: =D28/Assumptions!$C$6/1000 | E33: =E28/Assumptions!$C$6/1000 | F33: =F28/Assumptions!$C$6/1000 | G33: =G28/Assumptions!$C$6/1000 | H33: =H28/Assumptions!$C$6/1000 | I33: =I28/Assumptions!$C$6/1000
A35: Every FY2023-25 line above is the audited figure. In the forecast the company's own disclosure-only lines — direct costs, gross profit, the general and administrative split, the share of joint ventures and the two 2025 acquisition items — are not projected, because the forecast is built at the business-unit level on earnings before depreciation rather than on a cost-line split the filings do not support forward. The finance charge is computed on gross borrowings, which move with the net-debt roll, so profit is struck after interest and differs from the pre-financing discounted-cash-flow waterfall by construction.

Sheet Balance Sheet
A1: Balance sheet — condensed, and the rolls that drive it
A2: USD thousand, consolidated. Every FY2023-25 line is the audited closing figure; every forecast line is rolled forward from a driver.
A4: USD 000 | B4: FY2023 | C4: FY2024 | D4: FY2025 | E4: FY2026E | F4: FY2027E | G4: FY2028E | H4: FY2029E | I4: FY2030E
A5: Property, plant and equipment | B5: 3806543 | C5: 4543335 | D5: 6884178 | E5: =B37 | F5: =C37 | G5: =D37 | H5: =E37 | I5: =F37
A6: Right-of-use assets | B6: 148146 | C6: 161691 | D6: 225292 | E6: - | F6: - | G6: - | H6: - | I6: -
A7: Intangible assets | B7: 11440 | C7: 11078 | D7: 19434 | E7: =Assumptions!$C$160 | F7: =Assumptions!$C$160 | G7: =Assumptions!$C$160 | H7: =Assumptions!$C$160 | I7: =Assumptions!$C$160
A8: Goodwill | B8: 51368 | C8: 51368 | D8: 51368 | E8: =Assumptions!$C$161 | F8: =Assumptions!$C$161 | G8: =Assumptions!$C$161 | H8: =Assumptions!$C$161 | I8: =Assumptions!$C$161
A9: Investment properties | B9: 95269 | C9: 92501 | D9: 89154 | E9: - | F9: - | G9: - | H9: - | I9: -
A10: Investments in joint ventures and associates | B10: 76712 | C10: 267775 | D10: 577769 | E10: =Assumptions!$C$157 | F10: =Assumptions!$C$157 | G10: =Assumptions!$C$157 | H10: =Assumptions!$C$157 | I10: =Assumptions!$C$157
A11: Inventories | B11: 120720 | C11: 132687 | D11: 137108 | E11: =B47 | F11: =C47 | G11: =D47 | H11: =E47 | I11: =F47
A12: Trade and other receivables, including amounts due from related parties | B12: 1131167 | C12: 1284889 | D12: 1489668 | E12: =B46 | F12: =C46 | G12: =D46 | H12: =E46 | I12: =F46
A13: Cash and cash equivalents | B13: 215709 | C13: 198919 | D13: 337794 | E13: =Assumptions!$C$159 | F13: =Assumptions!$C$159 | G13: =Assumptions!$C$159 | H13: =Assumptions!$C$159 | I13: =Assumptions!$C$159
A14: Total assets | B14: 5745668 | C14: 7003326 | D14: 9965153 | E14: - | F14: - | G14: - | H14: - | I14: -
A15: Trade and other payables, including amounts due to related parties | B15: 962048 | C15: 1227680 | D15: 1280361 | E15: =B48 | F15: =C48 | G15: =D48 | H15: =E48 | I15: =F48
A16: Net working capital | B16: =B12+B11-B15 | C16: =C12+C11-C15 | D16: =D12+D11-D15 | E16: =E12+E11-E15 | F16: =F12+F11-F15 | G16: =G12+G11-G15 | H16: =H12+H11-H15 | I16: =I12+I11-I15
A17: Gross borrowings | B17: 289554 | C17: 739301 | D17: 1031879 | E17: =B54 | F17: =C54 | G17: =D54 | H17: =E54 | I17: =F54
A18: Net debt | B18: =B17-B13 | C18: =C17-C13 | D18: =D17-D13 | E18: =B62 | F18: =C62 | G18: =D62 | H18: =E62 | I18: =F62
A19: Perpetual capital securities | B19: 0 | C19: 0 | D19: 1978619 | E19: =Assumptions!$C$152 | F19: =Assumptions!$C$152 | G19: =Assumptions!$C$152 | H19: =Assumptions!$C$152 | I19: =Assumptions!$C$152
A20: Non-controlling interests | B20: 0 | C20: 0 | D20: 264512 | E20: =Assumptions!$C$154 | F20: =Assumptions!$C$154 | G20: =Assumptions!$C$154 | H20: =Assumptions!$C$154 | I20: =Assumptions!$C$154
A21: Equity attributable to shareholders | B21: 4405982 | C21: 4894627 | D21: 4981987 | E21: =B69 | F21: =C69 | G21: =D69 | H21: =E69 | I21: =F69
A22: Total equity | B22: =B21+B19+B20 | C22: =C21+C19+C20 | D22: =D21+D19+D20 | E22: =E21+E19+E20 | F22: =F21+F19+F20 | G22: =G21+G19+G20 | H22: =H21+H19+H20 | I22: =I21+I19+I20
A23: Net debt / EBITDA | B23: =B18/'Income Statement'!B14 | C23: =C18/'Income Statement'!C14 | D23: =D18/'Income Statement'!D14 | E23: =E18/'Income Statement'!E14 | F23: =F18/'Income Statement'!F14 | G23: =G18/'Income Statement'!G14 | H23: =H18/'Income Statement'!H14 | I23: =I18/'Income Statement'!I14
A24: Book value per share (USD) | B24: =B21/Assumptions!$C$6/1000 | C24: =C21/Assumptions!$C$6/1000 | D24: =D21/Assumptions!$C$6/1000 | E24: =E21/Assumptions!$C$6/1000 | F24: =F21/Assumptions!$C$6/1000 | G24: =G21/Assumptions!$C$6/1000 | H24: =H21/Assumptions!$C$6/1000 | I24: =I21/Assumptions!$C$6/1000
A25: Book value per share (AED) | B25: =B24*Assumptions!$C$7 | C25: =C24*Assumptions!$C$7 | D25: =D24*Assumptions!$C$7 | E25: =E24*Assumptions!$C$7 | F25: =F24*Assumptions!$C$7 | G25: =G24*Assumptions!$C$7 | H25: =H24*Assumptions!$C$7 | I25: =I24*Assumptions!$C$7
A26: Invested capital | B26: =B5+B16+B7+B8 | C26: =C5+C16+C7+C8 | D26: =D5+D16+D7+D8 | E26: =E5+E16+E7+E8 | F26: =F5+F16+F7+F8 | G26: =G5+G16+G7+G8 | H26: =H5+H16+H7+H8 | I26: =I5+I16+I7+I8
A27: Return on invested capital | B27: - | C27: - | D27: - | E27: =DCF!B11/E26 | F27: =DCF!C11/F26 | G27: =DCF!D11/G26 | H27: =DCF!E11/H26 | I27: =DCF!F11/I26
A28: Return on equity (profit over average equity) | B28: - | C28: ='Income Statement'!C28/((B21+C21)/2) | D28: ='Income Statement'!D28/((C21+D21)/2) | E28: ='Income Statement'!E28/((Assumptions!$C$158+E21)/2) | F28: ='Income Statement'!F28/((E21+F21)/2) | G28: ='Income Statement'!G28/((F21+G21)/2) | H28: ='Income Statement'!H28/((G21+H21)/2) | I28: ='Income Statement'!I28/((H21+I21)/2)
A30: THE PROPERTY, PLANT AND EQUIPMENT ROLL | B30: FY2026E | C30: FY2027E | D30: FY2028E | E30: FY2029E | F30: FY2030E
A31: Opening property, plant and equipment | B31: =D5 | C31: =B37 | D31: =C37 | E31: =D37 | F31: =E37
A32: Capital expenditure | B32: =Assumptions!$B$120 | C32: =Assumptions!$C$120 | D32: =Assumptions!$D$120 | E32: =Assumptions!$E$120 | F32: =Assumptions!$F$120
A33: Vessels acquired in the purchase announced 7 August 2026 — the same price that is carried in net debt below | B33: =Assumptions!$C$82 | C33: =0 | D33: =0 | E33: =0 | F33: =0
A34: Depreciation rate on property, plant and equipment | B34: =Assumptions!$C$121 | C34: =Assumptions!$C$121 | D34: =Assumptions!$C$121 | E34: =Assumptions!$C$121 | F34: =Assumptions!$C$121
A35: First-pass depreciation, on the opening balance plus the full additions | B35: =B34*(B31+(B31+B32+B33))/2 | C35: =C34*(C31+(C31+C32+C33))/2 | D35: =D34*(D31+(D31+D32+D33))/2 | E35: =E34*(E31+(E31+E32+E33))/2 | F35: =F34*(F31+(F31+F32+F33))/2
A36: Depreciation on property, plant and equipment — on the average of opening and closing | B36: =B34*(B31+(B31+B32+B33-B35))/2 | C36: =C34*(C31+(C31+C32+C33-C35))/2 | D36: =D34*(D31+(D31+D32+D33-D35))/2 | E36: =E34*(E31+(E31+E32+E33-E35))/2 | F36: =F34*(F31+(F31+F32+F33-F35))/2
A37: Closing property, plant and equipment | B37: =B31+B32+B33-B36 | C37: =C31+C32+C33-C36 | D37: =D31+D32+D33-D36 | E37: =E31+E32+E33-E36 | F37: =F31+F32+F33-F36
A38: Other depreciation and amortisation, escalated | B38: =Assumptions!$C$122*(1+Assumptions!$C$92)^1 | C38: =Assumptions!$C$122*(1+Assumptions!$C$92)^2 | D38: =Assumptions!$C$122*(1+Assumptions!$C$92)^3 | E38: =Assumptions!$C$122*(1+Assumptions!$C$92)^4 | F38: =Assumptions!$C$122*(1+Assumptions!$C$92)^5
A39: Total depreciation and amortisation | B39: =B36+B38 | C39: =C36+C38 | D39: =D36+D38 | E39: =E36+E38 | F39: =F36+F38
A40: THE WORKING-CAPITAL ROLL FROM THE DAYS RATIOS | B40: FY2026E | C40: FY2027E | D40: FY2028E | E40: FY2029E | F40: FY2030E
A41: Revenue | B41: =DCF!B5 | C41: =DCF!C5 | D41: =DCF!D5 | E41: =DCF!E5 | F41: =DCF!F5
A42: Total operating costs | B42: =B41-DCF!B6 | C42: =C41-DCF!C6 | D42: =D41-DCF!D6 | E42: =E41-DCF!E6 | F42: =F41-DCF!F6
...

Sheet Cash Flow
A1: Cash flow — the audited record and the forecast waterfall
A2: USD thousand.
A4: USD 000 | B4: FY2023 | C4: FY2024 | D4: FY2025 | E4: FY2026E | F4: FY2027E | G4: FY2028E | H4: FY2029E | I4: FY2030E
A5: EBITDA (operating) | B5: ='Income Statement'!B14 | C5: ='Income Statement'!C14 | D5: ='Income Statement'!D14 | E5: ='Income Statement'!E14 | F5: ='Income Statement'!F14 | G5: ='Income Statement'!G14 | H5: ='Income Statement'!H14 | I5: ='Income Statement'!I14
A6: Operating cash flow, as reported | B6: 822648 | C6: 1068865 | D6: 1370729 | E6: - | F6: - | G6: - | H6: - | I6: -
A7: Capital expenditure | B7: -774015 | C7: -810851 | D7: -1106529 | E7: =DCF!B13 | F7: =DCF!C13 | G7: =DCF!D13 | H7: =DCF!E13 | I7: =DCF!F13
A8: Free cash flow, as reported | B8: =B6+B7 | C8: =C6+C7 | D8: =D6+D7 | E8: - | F8: - | G8: - | H8: - | I8: -
A10: THE FORECAST WATERFALL — LINKED TO THE DISCOUNTED-CASH-FLOW SHEET | E10: FY2026E | F10: FY2027E | G10: FY2028E | H10: FY2029E | I10: FY2030E
A11: NOPAT | B11: - | C11: - | D11: - | E11: =DCF!B11 | F11: =DCF!C11 | G11: =DCF!D11 | H11: =DCF!E11 | I11: =DCF!F11
A12: Add back depreciation and amortisation | B12: - | C12: - | D12: - | E12: =DCF!B12 | F12: =DCF!C12 | G12: =DCF!D12 | H12: =DCF!E12 | I12: =DCF!F12
A13: Less capital expenditure | B13: - | C13: - | D13: - | E13: =DCF!B13 | F13: =DCF!C13 | G13: =DCF!D13 | H13: =DCF!E13 | I13: =DCF!F13
A14: Less change in working capital | B14: - | C14: - | D14: - | E14: =DCF!B14 | F14: =DCF!C14 | G14: =DCF!D14 | H14: =DCF!E14 | I14: =DCF!F14
A15: Free cash flow to the firm | B15: - | C15: - | D15: - | E15: =E11+E12+E13+E14 | F15: =F11+F12+F13+F14 | G15: =G11+G12+G13+G14 | H15: =H11+H12+H13+H14 | I15: =I11+I12+I13+I14
A16: Less interest after tax | B16: - | C16: - | D16: - | E16: ='Balance Sheet'!B57 | F16: ='Balance Sheet'!C57 | G16: ='Balance Sheet'!D57 | H16: ='Balance Sheet'!E57 | I16: ='Balance Sheet'!F57
A17: Plus finance income after tax | B17: - | C17: - | D17: - | E17: ='Balance Sheet'!B58 | F17: ='Balance Sheet'!C58 | G17: ='Balance Sheet'!D58 | H17: ='Balance Sheet'!E58 | I17: ='Balance Sheet'!F58
A18: Less perpetual capital securities coupon | B18: - | C18: - | D18: - | E18: ='Balance Sheet'!B59 | F18: ='Balance Sheet'!C59 | G18: ='Balance Sheet'!D59 | H18: ='Balance Sheet'!E59 | I18: ='Balance Sheet'!F59
A19: Free cash flow to equity | B19: - | C19: - | D19: - | E19: =E15+E16+E17+E18 | F19: =F15+F16+F17+F18 | G19: =G15+G16+G17+G18 | H19: =H15+H16+H17+H18 | I19: =I15+I16+I17+I18
A20: Less ordinary dividends | B20: - | C20: - | D20: - | E20: ='Balance Sheet'!B61 | F20: ='Balance Sheet'!C61 | G20: ='Balance Sheet'!D61 | H20: ='Balance Sheet'!E61 | I20: ='Balance Sheet'!F61
A21: Movement in net debt (a fall is a negative) | B21: - | C21: - | D21: - | E21: =-E19-E20 | F21: =-F19-F20 | G21: =-G19-G20 | H21: =-H19-H20 | I21: =-I19-I20
A22: Cash conversion — free cash flow to the firm over EBITDA | B22: - | C22: - | D22: - | E22: =E15/E5 | F22: =F15/F5 | G22: =G15/G5 | H22: =H15/H5 | I22: =I15/I5
A24: Cash conversion is the crux of an asset-heavy fleet owner: in 2026 the newbuild programme absorbs more than the whole of the operating cash the business generates, and only as that programme delivers does free cash flow to the firm turn materially positive.

Sheet Summary Financials
A1: Summary financials — the eight-year picture
A2: USD thousand unless stated. Every cell on this sheet is a link or a ratio; nothing is typed twice.
A4: USD 000 | B4: FY2023 | C4: FY2024 | D4: FY2025 | E4: FY2026E | F4: FY2027E | G4: FY2028E | H4: FY2029E | I4: FY2030E
A5: Revenue | B5: ='Income Statement'!B5 | C5: ='Income Statement'!C5 | D5: ='Income Statement'!D5 | E5: ='Income Statement'!E5 | F5: ='Income Statement'!F5 | G5: ='Income Statement'!G5 | H5: ='Income Statement'!H5 | I5: ='Income Statement'!I5
A6: Revenue growth | B6: - | C6: =C5/B5-1 | D6: =D5/C5-1 | E6: =E5/D5-1 | F6: =F5/E5-1 | G6: =G5/F5-1 | H6: =H5/G5-1 | I6: =I5/H5-1
A7: EBITDA (operating) | B7: ='Income Statement'!B14 | C7: ='Income Statement'!C14 | D7: ='Income Statement'!D14 | E7: ='Income Statement'!E14 | F7: ='Income Statement'!F14 | G7: ='Income Statement'!G14 | H7: ='Income Statement'!H14 | I7: ='Income Statement'!I14
A8: EBITDA margin | B8: ='Income Statement'!B18 | C8: ='Income Statement'!C18 | D8: ='Income Statement'!D18 | E8: ='Income Statement'!E18 | F8: ='Income Statement'!F18 | G8: ='Income Statement'!G18 | H8: ='Income Statement'!H18 | I8: ='Income Statement'!I18
A9: EBIT | B9: ='Income Statement'!B12 | C9: ='Income Statement'!C12 | D9: ='Income Statement'!D12 | E9: ='Income Statement'!E12 | F9: ='Income Statement'!F12 | G9: ='Income Statement'!G12 | H9: ='Income Statement'!H12 | I9: ='Income Statement'!I12
A10: Depreciation and amortisation | B10: ='Income Statement'!B13 | C10: ='Income Statement'!C13 | D10: ='Income Statement'!D13 | E10: ='Income Statement'!E13 | F10: ='Income Statement'!F13 | G10: ='Income Statement'!G13 | H10: ='Income Statement'!H13 | I10: ='Income Statement'!I13
A11: Profit attributable to shareholders | B11: ='Income Statement'!B28 | C11: ='Income Statement'!C28 | D11: ='Income Statement'!D28 | E11: ='Income Statement'!E28 | F11: ='Income Statement'!F28 | G11: ='Income Statement'!G28 | H11: ='Income Statement'!H28 | I11: ='Income Statement'!I28
A12: Earnings attributable to ordinary shareholders | B12: ='Income Statement'!B30 | C12: ='Income Statement'!C30 | D12: ='Income Statement'!D30 | E12: ='Income Statement'!E30 | F12: ='Income Statement'!F30 | G12: ='Income Statement'!G30 | H12: ='Income Statement'!H30 | I12: ='Income Statement'!I30
A13: Earnings per ordinary share (AED) | B13: ='Income Statement'!B32 | C13: ='Income Statement'!C32 | D13: ='Income Statement'!D32 | E13: ='Income Statement'!E32 | F13: ='Income Statement'!F32 | G13: ='Income Statement'!G32 | H13: ='Income Statement'!H32 | I13: ='Income Statement'!I32
A14: Free cash flow to the firm | B14: - | C14: - | D14: - | E14: ='Cash Flow'!E15 | F14: ='Cash Flow'!F15 | G14: ='Cash Flow'!G15 | H14: ='Cash Flow'!H15 | I14: ='Cash Flow'!I15
A15: Capital expenditure | B15: ='Cash Flow'!B7 | C15: ='Cash Flow'!C7 | D15: ='Cash Flow'!D7 | E15: ='Cash Flow'!E7 | F15: ='Cash Flow'!F7 | G15: ='Cash Flow'!G7 | H15: ='Cash Flow'!H7 | I15: ='Cash Flow'!I7
A16: Capital expenditure / revenue | B16: =-B15/B5 | C16: =-C15/C5 | D16: =-D15/D5 | E16: =-E15/E5 | F16: =-F15/F5 | G16: =-G15/G5 | H16: =-H15/H5 | I16: =-I15/I5
A17: Net working capital | B17: ='Balance Sheet'!B16 | C17: ='Balance Sheet'!C16 | D17: ='Balance Sheet'!D16 | E17: ='Balance Sheet'!E16 | F17: ='Balance Sheet'!F16 | G17: ='Balance Sheet'!G16 | H17: ='Balance Sheet'!H16 | I17: ='Balance Sheet'!I16
A18: Net working capital / revenue | B18: =B17/B5 | C18: =C17/C5 | D18: =D17/D5 | E18: =E17/E5 | F18: =F17/F5 | G18: =G17/G5 | H18: =H17/H5 | I18: =I17/I5
A19: Net debt | B19: ='Balance Sheet'!B18 | C19: ='Balance Sheet'!C18 | D19: ='Balance Sheet'!D18 | E19: ='Balance Sheet'!E18 | F19: ='Balance Sheet'!F18 | G19: ='Balance Sheet'!G18 | H19: ='Balance Sheet'!H18 | I19: ='Balance Sheet'!I18
A20: Net debt / EBITDA | B20: ='Balance Sheet'!B23 | C20: ='Balance Sheet'!C23 | D20: ='Balance Sheet'!D23 | E20: ='Balance Sheet'!E23 | F20: ='Balance Sheet'!F23 | G20: ='Balance Sheet'!G23 | H20: ='Balance Sheet'!H23 | I20: ='Balance Sheet'!I23
A21: Equity attributable to shareholders | B21: ='Balance Sheet'!B21 | C21: ='Balance Sheet'!C21 | D21: ='Balance Sheet'!D21 | E21: ='Balance Sheet'!E21 | F21: ='Balance Sheet'!F21 | G21: ='Balance Sheet'!G21 | H21: ='Balance Sheet'!H21 | I21: ='Balance Sheet'!I21
A22: Invested capital | B22: ='Balance Sheet'!B26 | C22: ='Balance Sheet'!C26 | D22: ='Balance Sheet'!D26 | E22: ='Balance Sheet'!E26 | F22: ='Balance Sheet'!F26 | G22: ='Balance Sheet'!G26 | H22: ='Balance Sheet'!H26 | I22: ='Balance Sheet'!I26
A23: Return on invested capital | B23: - | C23: - | D23: - | E23: ='Balance Sheet'!E27 | F23: ='Balance Sheet'!F27 | G23: ='Balance Sheet'!G27 | H23: ='Balance Sheet'!H27 | I23: ='Balance Sheet'!I27
A24: Return on equity | B24: - | C24: ='Balance Sheet'!C28 | D24: ='Balance Sheet'!D28 | E24: ='Balance Sheet'!E28 | F24: ='Balance Sheet'!F28 | G24: ='Balance Sheet'!G28 | H24: ='Balance Sheet'!H28 | I24: ='Balance Sheet'!I28
A26: Return on invested capital is the discounted-cash-flow sheet's NOPAT over the same year's invested capital, which is why the audited years carry capital but no return: their tax charge is struck on a post-financing basis and is not comparable with the pre-financing NOPAT the forecast uses.

Sheet Monte Carlo
A1: Probabilistic price map
A2: A map of price dispersion over the next one and three months. It carries no view on value and is never blended with the valuation. Each figure is a complete engine re-run, so it is a pasted value and does NOT redraw when a driver is changed.
A4: Horizon (AED) | B4: 5th | C4: 25th | D4: Median | E4: 75th | F4: 95th | G4: Probability above spot
A5: One month — graded 2026-09-07 | B5: 5.4740089 | C5: 5.8893332 | D5: 6.164121 | E5: 6.4532251 | F5: 6.9280856 | G5: 0.50406
A6: Three months — graded 2026-11-09 | B6: 4.945078 | C6: 5.6724641 | D6: 6.1784801 | E6: 6.7276859 | F6: 7.7283701 | G6: 0.5092
A8: Level event | B8: One month | C8: Three months
A9: Finishes 10% or more above spot | B9: 0.08632 | C9: 0.23286
A10: Finishes 10% or more below spot | B10: 0.06752 | C10: 0.19752
A11: Touches 10% above spot at any point | B11: 0.14278 | C11: 0.42208
A12: Touches 10% below spot at any point | B12: 0.11002 | C12: 0.3644
A14: Engine setting | C14: Value
A15: Simulated paths | C15: 50000
A16: Annualised volatility (three-month anchor) | C16: 0.28173247
A17: Spot price (AED) | C17: =Summary!$C$16
A18: Anchor date | C18: 2026-08-07
A19: Calibration verdict on the five-year walk-forward | C19: PARITY
A21: The price map is a dispersion forecast from the price series alone. It is deliberately not reconciled to the valuation lenses: one is a statement about what a price could do over weeks, the other about what a business is worth.

Sheet Sensitivity
A1: Sensitivity — what the valuation needs the world to do
A2: AED per share. Each cell is a complete re-run of the whole model, including the fleet build, so these grids are engine outputs rather than formulas and do NOT redraw when a driver is changed.
A4: Beta (rows) x terminal growth (columns)
A5: Beta | B5: 1.0% | C5: 1.5% | D5: 2.0% | E5: 2.5%
A6: 0.705 | B6: 8.3749443 | C6: 8.8225319 | D6: 9.3704688 | E6: 10.058871
A7: 0.900 | B7: 7.0705809 | C7: 7.3541289 | D7: 7.6902194 | E7: 8.0963184
A8: 1.085 | B8: 6.1042118 | C8: 6.2903658 | D8: 6.505577 | E8: 6.7581734
A9: 1.250 | B9: 5.4009352 | C9: 5.5286387 | D9: 5.6733875 | E9: 5.8395323
A10: 1.412 | B10: 4.8197249 | C10: 4.906776 | D10: 5.0036095 | E10: 5.1124798
