Workbook

Sheet READ FIRST
A1: Testahil — ADNOC Gas plc (ADX: ADNOCGAS)
A2: Companion model · Independent Valuation Study — Educational Analysis · Not investment advice
A5: WHAT THIS WORKBOOK IS. The companion model to the ADNOC Gas valuation study. Reporting currency is US dollars
A6: (the company reports in USD); the share price and all per-share fair values are in AED (peg 3.6725).
A8: COLOUR CODE. Blue = a hardcoded input you can change. Black = a formula/calculation. Green = a link pulling
A9: from another sheet. Every forecast and valuation cell links back to the Assumptions sheet — change one blue input
A10: there (WACC, a margin, the dividend growth rate) and the whole model reprices.
A12: LENS. Primary lens = discounted cash flow (FCFF) on a 5-year forecast. Cross-checks: a dividend-discount model
A13: (DDM) on the board-committed 5%-growth dividend, discounted at a lower sovereign-backed rate; and relative
A14: multiples (EV/EBITDA, justified P/E, dividend yield). The five lenses are weighted on the Summary sheet.
A16: MONTE CARLO. Width from the YZ-HAR engine (pooled log-HAR on a Yang-Zhang variance proxy); Student-t(5)
A17: innovations; drift OFF (international name — paths diffuse from spot); 16 factors (7 continuous + 9 discrete);
... A24: NOT A RATING. Testahil publishes fair-value ranges and probability distributions — never a buy/sell/hold or a price target.

Sheet Summary
A1: Valuation summary — ADNOC Gas (ADX: ADNOCGAS)
A2: Five-lens fair value versus spot. Bear/bull are judgment ranges; base links to the lens sheets.
A3: Lens | B3: Bear | C3: Base | D3: Bull | E3: Weight
A4: DCF (FCFF) | B4: 4 | C4: =DCF!B21 -> 4.5000656 | D4: 5.1 | E4: =Assumptions!B30 -> 0.2
A5: DDM (dividend stream) | B5: 3.1 | C5: =DDM!B14 -> 3.4086197 | D5: 3.7 | E5: =Assumptions!B31 -> 0.35
A6: Relative EV/EBITDA | B6: 3.55 | C6: ='Relative & Normalized'!C4 -> 3.8334291 | D6: 4.05 | E6: =Assumptions!B32 -> 0.15
A7: Justified P/E | B7: 3.3 | C7: ='Relative & Normalized'!C5 -> 3.6151398 | D7: 3.95 | E7: =Assumptions!B33 -> 0.15
A8: Dividend yield | B8: 3.6 | C8: ='Relative & Normalized'!C6 -> 3.8317702 | D8: 4 | E8: =Assumptions!B34 -> 0.15
A10: Weighted fair value (base) | C10: =SUMPRODUCT(C4:C8,E4:E8) -> 3.7850809
A11: Spot | C11: =Assumptions!B4 -> 3.44
A12: Upside / (downside) to fair | C12: =C10/C11-1 -> 0.10031421
A13: Fair-value range (bear–bull) | C13: =MIN(B4:B8) -> 3.1 | D13: =MAX(D4:D8) -> 5.1

Sheet Fundamental Valuation
A1: Fundamental valuation — bear/base/bull per lens
A2: All figures link to the Summary sheet.
A3: Lens | B3: Bear | C3: Base | D3: Bull
A4: =Summary!A4 -> DCF (FCFF) | B4: =Summary!B4 -> 4 | C4: =Summary!C4 -> 4.5000656 | D4: =Summary!D4 -> 5.1
A5: =Summary!A5 -> DDM (dividend stream) | B5: =Summary!B5 -> 3.1 | C5: =Summary!C5 -> 3.4086197 | D5: =Summary!D5 -> 3.7
A6: =Summary!A6 -> Relative EV/EBITDA | B6: =Summary!B6 -> 3.55 | C6: =Summary!C6 -> 3.8334291 | D6: =Summary!D6 -> 4.05
A7: =Summary!A7 -> Justified P/E | B7: =Summary!B7 -> 3.3 | C7: =Summary!C7 -> 3.6151398 | D7: =Summary!D7 -> 3.95
A8: =Summary!A8 -> Dividend yield | B8: =Summary!B8 -> 3.6 | C8: =Summary!C8 -> 3.8317702 | D8: =Summary!D8 -> 4
A10: Weighted fair value | C10: =Summary!C10 -> 3.7850809

Sheet Assumptions
A1: Assumptions — the single input layer
A2: All blue cells are inputs. Black cells are formulas. USD m unless noted; per-share in AED.
A3: ANCHORS
A4: Spot price (AED/share) | B4: 3.44
A5: Shares outstanding (m) | B5: 76740
A6: AED/USD peg | B6: 3.6725
A7: Net cash (USD m) | B7: 4780
A9: DCF — COST OF CAPITAL
A10: Risk-free rate (UAE USD sovereign) | B10: 0.045
A11: Beta | B11: 1
A12: Equity risk premium | B12: 0.055
A13: Cost of equity Ke = rf + β·ERP | B13: =B10+B11*B12 -> 0.1
A14: WACC (net cash → = Ke) | B14: =B13 -> 0.1
A15: Terminal growth | B15: 0.025
A16: Effective tax rate (blended) | B16: 0.16
A18: DDM — DIVIDEND STREAM
A19: Cost of equity (dividend, split-Ke) | B19: 0.0825
A20: Dividend growth (board policy) | B20: 0.05
A21: DDM terminal growth | B21: 0.025
A22: FY2025 total dividend (USD m) | B22: 3584
A24: RELATIVE & YIELD
A25: EV/EBITDA target multiple | B25: 8.5
A26: Justified P/E | B26: 13.5
A27: Fair dividend yield | B27: 0.047
A29: SYNTHESIS WEIGHTS
A30: DCF weight | B30: 0.2
A31: DDM weight | B31: 0.35
A32: Relative EV/EBITDA weight | B32: 0.15
A33: Justified P/E weight | B33: 0.15
A34: Dividend yield weight | B34: 0.15
A35: sum of weights (check) | B35: =SUM(B30:B34) -> 1
A37: FORECAST DRIVERS (FY2026E–FY2030E)
C38: 2026E | D38: 2027E | E38: 2028E | F38: 2029E | G38: 2030E
A39: Revenue (USD m) | C39: 23950 | D39: 25100 | E39: 26900 | F39: 28400 | G39: 29600
A40: EBITDA margin | C40: 0.37 | D40: 0.375 | E40: 0.378 | F40: 0.382 | G40: 0.385
A41: D&A (USD m) | C41: 2000 | D41: 2250 | E41: 2550 | F41: 2750 | G41: 2900
A42: Net finance cost (USD m) | C42: 200 | D42: 150 | E42: 150 | F42: 100 | G42: 100
A43: Capex (USD m) | C43: 3300 | D43: 3000 | E43: 3400 | F43: 1700 | G43: 2000
A44: Δ Working capital (USD m) | C44: 150 | D44: 150 | E44: 200 | F44: 150 | G44: 150
A46: MONTE CARLO
...

Sheet DDM
A1: Dividend discount model — committed dividend
A2: 5% policy growth to 2030, then terminal g; discounted at the split-Ke (sovereign-backed dividend).
B3: 2026E | C3: 2027E | D3: 2028E | E3: 2029E | F3: 2030E
A4: Total dividend (USD m) | B4: ='Income Statement'!E14 -> 3763.2 | C4: ='Income Statement'!F14 -> 3951.36 | D4: ='Income Statement'!G14 -> 4148.928 | E4: ='Income Statement'!H14 -> 4356.3744 | F4: ='Income Statement'!I14 -> 4574.1931
A5: DPS (USD) | B5: =B4/Assumptions!$B$5 -> 0.049038311 | C5: =C4/Assumptions!$B$5 -> 0.051490227 | D5: =D4/Assumptions!$B$5 -> 0.054064738 | E5: =E4/Assumptions!$B$5 -> 0.056767975 | F5: =F4/Assumptions!$B$5 -> 0.059606374
A6: Discount factor @ Ke_ddm | B6: =1/(1+Assumptions!$B$19)^1 -> 0.92378753 | C6: =1/(1+Assumptions!$B$19)^2 -> 0.8533834 | D6: =1/(1+Assumptions!$B$19)^3 -> 0.78834494 | E6: =1/(1+Assumptions!$B$19)^4 -> 0.72826322 | F6: =1/(1+Assumptions!$B$19)^5 -> 0.67276048
A7: PV of DPS (USD) | B7: =B5*B6 -> 0.04530098 | C7: =C5*C6 -> 0.043940905 | D7: =D5*D6 -> 0.042621663 | E7: =E5*E6 -> 0.041342029 | F7: =F5*F6 -> 0.040100813
A9: Sum PV of explicit DPS | B9: =SUM(B7:F7) -> 0.21330639
A10: Terminal DPS (2031, USD) | B10: =F5*(1+Assumptions!$B$21) -> 0.061096533
A11: Terminal value (USD) | B11: =B10/(Assumptions!$B$19-Assumptions!$B$21) -> 1.0625484
A12: PV of terminal value (USD) | B12: =B11*F6 -> 0.71484058
A13: Value per share (USD) | B13: =B9+B12 -> 0.92814697
A14: Value per share (AED) | B14: =B13*Assumptions!$B$6 -> 3.4086197

Sheet Segments
A1: Segment view (USD m)
A2: Illustrative split of the two revenue legs — domestic take-or-pay vs liquids/LNG exports.
A3: 2023 | B3: 2024 | C3: 2025 | D3: 2026E | E3: 2027E | F3: 2028E | G3: 2029E | H3: 2030E
A4: Domestic gas (~60%, take-or-pay) | B4: ='Income Statement'!B4*0.6 -> 13698 | C4: ='Income Statement'!C4*0.6 -> 14656.8 | D4: ='Income Statement'!D4*0.6 -> 14083.8 | E4: ='Income Statement'!E4*0.6 -> 14370 | F4: ='Income Statement'!F4*0.6 -> 15060 | G4: ='Income Statement'!G4*0.6 -> 16140 | H4: ='Income Statement'!H4*0.6 -> 17040 | I4: ='Income Statement'!I4*0.6 -> 17760
A5: Liquids / LNG / condensate (~40%) | B5: ='Income Statement'!B4*0.4 -> 9132 | C5: ='Income Statement'!C4*0.4 -> 9771.2 | D5: ='Income Statement'!D4*0.4 -> 9389.2 | E5: ='Income Statement'!E4*0.4 -> 9580 | F5: ='Income Statement'!F4*0.4 -> 10040 | G5: ='Income Statement'!G4*0.4 -> 10760 | H5: ='Income Statement'!H4*0.4 -> 11360 | I5: ='Income Statement'!I4*0.4 -> 11840
A6: Total revenue | B6: =B4+B5 -> 22830 | C6: =C4+C5 -> 24428 | D6: =D4+D5 -> 23473 | E6: =E4+E5 -> 23950 | F6: =F4+F5 -> 25100 | G6: =G4+G5 -> 26900 | H6: =H4+H5 -> 28400 | I6: =I4+I5 -> 29600
A7: Group EBITDA | B7: ='Income Statement'!B5 -> 7586 | C7: ='Income Statement'!C5 -> 8648 | D7: ='Income Statement'!D5 -> 8636 | E7: ='Income Statement'!E5 -> 8861.5 | F7: ='Income Statement'!F5 -> 9412.5 | G7: ='Income Statement'!G5 -> 10168.2 | H7: ='Income Statement'!H5 -> 10848.8 | I7: ='Income Statement'!I5 -> 11396
A8: EBITDA margin | B8: =B7/B6 -> 0.33228208 | C8: =C7/C6 -> 0.35401998 | D8: =D7/D6 -> 0.36791207 | E8: =E7/E6 -> 0.37 | F8: =F7/F6 -> 0.375 | G8: =G7/G6 -> 0.378 | H8: =H7/H6 -> 0.382 | I8: =I7/I6 -> 0.385
A10: Note | B10: Segment split illustrative (60/40); ADNOC Gas does not disclose per-segment volume×price — top-down basis.

Sheet Relative & Normalized
A1: Relative & yield lenses
A2: Applied to FY2026E figures. Links to Assumptions and the income statement.
A3: Lens | B3: Workings | C3: AED/share
A4: Relative EV/EBITDA | B4: target × FY26 EBITDA + net cash, ÷ shares | C4: =(Assumptions!$B$25*'Income Statement'!E5+Assumptions!$B$7)/Assumptions!$B$5*Assumptions!$B$6 -> 3.8334291
A5: Justified P/E | B5: justified P/E × FY26 EPS (AED) | C5: =Assumptions!$B$26*'Income Statement'!E13 -> 3.6151398
A6: Dividend yield | B6: FY26 DPS (AED) ÷ fair yield | C6: ='Income Statement'!E15/Assumptions!$B$27 -> 3.8317702
A8: Implied EV at target (USD m) | C8: =Assumptions!$B$25*'Income Statement'!E5 -> 75322.75
A9: FY26 EPS (AED) | C9: ='Income Statement'!E13 -> 0.26778813
A10: FY26 DPS (AED) | C10: ='Income Statement'!E15 -> 0.1800932

Sheet DCF
A1: Discounted cash flow — FCFF (USD m)
A2: NOPAT + D&A − capex − Δ working capital, discounted at WACC. Value per share in AED.
B3: 2026E | C3: 2027E | D3: 2028E | E3: 2029E | F3: 2030E
A4: EBIT | B4: ='Income Statement'!E8 -> 6861.5 | C4: ='Income Statement'!F8 -> 7162.5 | D4: ='Income Statement'!G8 -> 7618.2 | E4: ='Income Statement'!H8 -> 8098.8 | F4: ='Income Statement'!I8 -> 8496
A5: NOPAT = EBIT×(1−tax) | B5: =B4*(1-Assumptions!$B$16) -> 5763.66 | C5: =C4*(1-Assumptions!$B$16) -> 6016.5 | D5: =D4*(1-Assumptions!$B$16) -> 6399.288 | E5: =E4*(1-Assumptions!$B$16) -> 6802.992 | F5: =F4*(1-Assumptions!$B$16) -> 7136.64
A6: + D&A | B6: ='Income Statement'!E7 -> 2000 | C6: ='Income Statement'!F7 -> 2250 | D6: ='Income Statement'!G7 -> 2550 | E6: ='Income Statement'!H7 -> 2750 | F6: ='Income Statement'!I7 -> 2900
A7: − Capex | B7: =-Assumptions!C43 -> -3300 | C7: =-Assumptions!D43 -> -3000 | D7: =-Assumptions!E43 -> -3400 | E7: =-Assumptions!F43 -> -1700 | F7: =-Assumptions!G43 -> -2000
A8: − Δ working capital | B8: =-Assumptions!C44 -> -150 | C8: =-Assumptions!D44 -> -150 | D8: =-Assumptions!E44 -> -200 | E8: =-Assumptions!F44 -> -150 | F8: =-Assumptions!G44 -> -150
A9: Free cash flow to firm | B9: =B5+B6+B7+B8 -> 4313.66 | C9: =C5+C6+C7+C8 -> 5116.5 | D9: =D5+D6+D7+D8 -> 5349.288 | E9: =E5+E6+E7+E8 -> 7702.992 | F9: =F5+F6+F7+F8 -> 7886.64
A10: Discount factor @ WACC | B10: =1/(1+Assumptions!$B$14)^1 -> 0.90909091 | C10: =1/(1+Assumptions!$B$14)^2 -> 0.82644628 | D10: =1/(1+Assumptions!$B$14)^3 -> 0.7513148 | E10: =1/(1+Assumptions!$B$14)^4 -> 0.68301346 | F10: =1/(1+Assumptions!$B$14)^5 -> 0.62092132
A11: PV of FCFF | B11: =B9*B10 -> 3921.5091 | C11: =C9*C10 -> 4228.5124 | D11: =D9*D10 -> 4018.9992 | E11: =E9*E10 -> 5261.2472 | F11: =F9*F10 -> 4896.9829
A13: Sum PV of explicit FCFF | B13: =SUM(B11:F11) -> 22327.251
A14: Terminal value (2031) | B14: =F9*(1+Assumptions!$B$15)/(Assumptions!$B$14-Assumptions!$B$15) -> 107784.08
A15: PV of terminal value | B15: =B14*F10 -> 66925.434
A16: Enterprise value | B16: =B13+B15 -> 89252.684
A17: Terminal value as % of EV | B17: =B15/B16 -> 0.74984225
A18: + Net cash | B18: =Assumptions!$B$7 -> 4780
A19: Equity value | B19: =B16+B18 -> 94032.684
A20: Value per share (USD) | B20: =B19/Assumptions!$B$5 -> 1.2253412
A21: Value per share (AED) | B21: =B20*Assumptions!$B$6 -> 4.5000656

Sheet Income Statement
A1: Income statement (USD m; per-share AED)
A2: FY2023–25 anchored to disclosed adjusted results; FY2026E–30E driven by Assumptions.
A3: 2023 | B3: 2024 | C3: 2025 | D3: 2026E | E3: 2027E | F3: 2028E | G3: 2029E | H3: 2030E
A4: Revenue | B4: 22830 | C4: 24428 | D4: 23473 | E4: =Assumptions!C39 -> 23950 | F4: =Assumptions!D39 -> 25100 | G4: =Assumptions!E39 -> 26900 | H4: =Assumptions!F39 -> 28400 | I4: =Assumptions!G39 -> 29600
A5: EBITDA | B5: 7586 | C5: 8648 | D5: 8636 | E5: =E4*Assumptions!C40 -> 8861.5 | F5: =F4*Assumptions!D40 -> 9412.5 | G5: =G4*Assumptions!E40 -> 10168.2 | H5: =H4*Assumptions!F40 -> 10848.8 | I5: =I4*Assumptions!G40 -> 11396
A6: EBITDA margin | B6: =B5/B4 -> 0.33228208 | C6: =C5/C4 -> 0.35401998 | D6: =D5/D4 -> 0.36791207 | E6: =E5/E4 -> 0.37 | F6: =F5/F4 -> 0.375 | G6: =G5/G4 -> 0.378 | H6: =H5/H4 -> 0.382 | I6: =I5/I4 -> 0.385
A7: Depreciation & amortization | B7: 1300 | C7: 1600 | D7: 1900 | E7: =Assumptions!C41 -> 2000 | F7: =Assumptions!D41 -> 2250 | G7: =Assumptions!E41 -> 2550 | H7: =Assumptions!F41 -> 2750 | I7: =Assumptions!G41 -> 2900
A8: EBIT | B8: =B5-B7 -> 6286 | C8: =C5-C7 -> 7048 | D8: =D5-D7 -> 6736 | E8: =E5-E7 -> 6861.5 | F8: =F5-F7 -> 7162.5 | G8: =G5-G7 -> 7618.2 | H8: =H5-H7 -> 8098.8 | I8: =I5-I7 -> 8496
A9: Net finance cost | B9: 1017 | C9: 1094 | D9: 586 | E9: =Assumptions!C42 -> 200 | F9: =Assumptions!D42 -> 150 | G9: =Assumptions!E42 -> 150 | H9: =Assumptions!F42 -> 100 | I9: =Assumptions!G42 -> 100
A10: Profit before tax | B10: =B8-B9 -> 5269 | C10: =C8-C9 -> 5954 | D10: =D8-D9 -> 6150 | E10: =E8-E9 -> 6661.5 | F10: =F8-F9 -> 7012.5 | G10: =G8-G9 -> 7468.2 | H10: =H8-H9 -> 7998.8 | I10: =I8-I9 -> 8396
A11: Tax | B11: =B10*Assumptions!$B$16 -> 843.04 | C11: =C10*Assumptions!$B$16 -> 952.64 | D11: =D10*Assumptions!$B$16 -> 984 | E11: =E10*Assumptions!$B$16 -> 1065.84 | F11: =F10*Assumptions!$B$16 -> 1122 | G11: =G10*Assumptions!$B$16 -> 1194.912 | H11: =H10*Assumptions!$B$16 -> 1279.808 | I11: =I10*Assumptions!$B$16 -> 1343.36
A12: Net income | B12: =B10-B11 -> 4425.96 | C12: =C10-C11 -> 5001.36 | D12: =D10-D11 -> 5166 | E12: =E10-E11 -> 5595.66 | F12: =F10-F11 -> 5890.5 | G12: =G10-G11 -> 6273.288 | H12: =H10-H11 -> 6718.992 | I12: =I10-I11 -> 7052.64
A13: EPS (AED) | B13: =B12/Assumptions!$B$5*Assumptions!$B$6 -> 0.2118105 | C13: =C12/Assumptions!$B$5*Assumptions!$B$6 -> 0.23934708 | D13: =D12/Assumptions!$B$5*Assumptions!$B$6 -> 0.24722615 | E13: =E12/Assumptions!$B$5*Assumptions!$B$6 -> 0.26778813 | F13: =F12/Assumptions!$B$5*Assumptions!$B$6 -> 0.28189811 | G13: =G12/Assumptions!$B$5*Assumptions!$B$6 -> 0.30021697 | H13: =H12/Assumptions!$B$5*Assumptions!$B$6 -> 0.32154676 | I13: =I12/Assumptions!$B$5*Assumptions!$B$6 -> 0.33751395
A14: Total dividend (USD m) | B14: 3250 | C14: 3412 | D14: 3584 | E14: =D14*(1+Assumptions!$B$20) -> 3763.2 | F14: =E14*(1+Assumptions!$B$20) -> 3951.36 | G14: =F14*(1+Assumptions!$B$20) -> 4148.928 | H14: =G14*(1+Assumptions!$B$20) -> 4356.3744 | I14: =H14*(1+Assumptions!$B$20) -> 4574.1931
A15: DPS (AED) | B15: =B14/Assumptions!$B$5*Assumptions!$B$6 -> 0.15553329 | C15: =C14/Assumptions!$B$5*Assumptions!$B$6 -> 0.16328603 | D15: =D14/Assumptions!$B$5*Assumptions!$B$6 -> 0.17151733 | E15: =E14/Assumptions!$B$5*Assumptions!$B$6 -> 0.1800932 | F15: =F14/Assumptions!$B$5*Assumptions!$B$6 -> 0.18909786 | G15: =G14/Assumptions!$B$5*Assumptions!$B$6 -> 0.19855275 | H15: =H14/Assumptions!$B$5*Assumptions!$B$6 -> 0.20848039 | I15: =I14/Assumptions!$B$5*Assumptions!$B$6 -> 0.21890441
A16: Payout ratio | B16: =B14/B12 -> 0.73430397 | C16: =C14/C12 -> 0.68221444 | D16: =D14/D12 -> 0.69376694 | E16: =E14/E12 -> 0.6725212 | F16: =F14/F12 -> 0.67080214 | G16: =G14/G12 -> 0.66136418 | H16: =H14/H12 -> 0.64836726 | I16: =I14/I12 -> 0.64857885

Sheet Balance Sheet
A1: Balance sheet (USD m)
A2: Anchored to disclosed equity, cash, debt and net cash; line detail below those anchors estimated.
A3: 2023 | B3: 2024 | C3: 2025 | D3: 2026E | E3: 2027E | F3: 2028E | G3: 2029E | H3: 2030E
A4: Cash & equivalents | B4: 3500 | C4: 4200 | D4: 5060 | E4: ='Cash Flow'!E14 -> 5442.46 | F4: ='Cash Flow'!F14 -> 6481.6 | G4: ='Cash Flow'!G14 -> 7555.96 | H4: ='Cash Flow'!H14 -> 10818.578 | I4: ='Cash Flow'!I14 -> 14047.024
A5: Trade & other receivables | B5: 2500 | C5: 2700 | D5: 2600 | E5: ='Income Statement'!E4*($D$5/'Income Statement'!$D$4) -> 2652.8352 | F5: ='Income Statement'!F4*($D$5/'Income Statement'!$D$4) -> 2780.2156 | G5: ='Income Statement'!G4*($D$5/'Income Statement'!$D$4) -> 2979.5936 | H5: ='Income Statement'!H4*($D$5/'Income Statement'!$D$4) -> 3145.7419 | I5: ='Income Statement'!I4*($D$5/'Income Statement'!$D$4) -> 3278.6606
A6: Inventory | B6: 300 | C6: 320 | D6: 300 | E6: ='Income Statement'!E4*($D$6/'Income Statement'!$D$4) -> 306.09637 | F6: ='Income Statement'!F4*($D$6/'Income Statement'!$D$4) -> 320.7941 | G6: ='Income Statement'!G4*($D$6/'Income Statement'!$D$4) -> 343.79926 | H6: ='Income Statement'!H4*($D$6/'Income Statement'!$D$4) -> 362.97022 | I6: ='Income Statement'!I4*($D$6/'Income Statement'!$D$4) -> 378.30699
A7: Investments in JV/associates | B7: 5600 | C7: 5800 | D7: 6000 | E7: =D7 -> 6000 | F7: =E7 -> 6000 | G7: =F7 -> 6000 | H7: =G7 -> 6000 | I7: =H7 -> 6000
A8: PP&E & intangibles | B8: 14980 | C8: 16300 | D8: 18040 | E8: =D8+Assumptions!C43-Assumptions!C41 -> 19340 | F8: =E8+Assumptions!D43-Assumptions!D41 -> 20090 | G8: =F8+Assumptions!E43-Assumptions!E41 -> 20940 | H8: =G8+Assumptions!F43-Assumptions!F41 -> 19890 | I8: =H8+Assumptions!G43-Assumptions!G41 -> 18990
A9: Total assets | B9: =SUM(B4:B8) -> 26880 | C9: =SUM(C4:C8) -> 29320 | D9: =SUM(D4:D8) -> 32000 | E9: =SUM(E4:E8) -> 33741.392 | F9: =SUM(F4:F8) -> 35672.61 | G9: =SUM(G4:G8) -> 37819.353 | H9: =SUM(H4:H8) -> 40217.29 | I9: =SUM(I4:I8) -> 42693.992
A11: Debt | B11: 320 | C11: 300 | D11: 280 | E11: =D11 -> 280 | F11: =E11 -> 280 | G11: =F11 -> 280 | H11: =G11 -> 280 | I11: =H11 -> 280
A12: Decommissioning & provisions | B12: 3300 | C12: 3400 | D12: 3500 | E12: =D12 -> 3500 | F12: =E12 -> 3500 | G12: =F12 -> 3500 | H12: =G12 -> 3500 | I12: =H12 -> 3500
A13: Trade & other payables | B13: 2980 | C13: 3150 | D13: 3170 | E13: ='Income Statement'!E4*($D$13/'Income Statement'!$D$4) -> 3234.4183 | F13: ='Income Statement'!F4*($D$13/'Income Statement'!$D$4) -> 3389.7244 | G13: ='Income Statement'!G4*($D$13/'Income Statement'!$D$4) -> 3632.8122 | H13: ='Income Statement'!H4*($D$13/'Income Statement'!$D$4) -> 3835.3853 | I13: ='Income Statement'!I4*($D$13/'Income Statement'!$D$4) -> 3997.4439
A14: Other liabilities (balancing) | B14: 400 | C14: 1000 | D14: 2000 | E14: =E9-E11-E12-E13-E16 -> 1844.5133 | F14: =F9-F11-F12-F13-F16 -> 1681.2853 | G14: =G9-G11-G12-G13-G16 -> 1460.5807 | H14: =H9-H11-H12-H13-H16 -> 1293.3268 | I14: =I9-I11-I12-I13-I16 -> 1129.5237
A15: Total liabilities | B15: =SUM(B11:B14) -> 7000 | C15: =SUM(C11:C14) -> 7850 | D15: =SUM(D11:D14) -> 8950 | E15: =SUM(E11:E14) -> 8858.9315 | F15: =SUM(F11:F14) -> 8851.0097 | G15: =SUM(G11:G14) -> 8873.3928 | H15: =SUM(H11:H14) -> 8908.7121 | I15: =SUM(I11:I14) -> 8906.9676
A16: Total equity | B16: 19880 | C16: 21470 | D16: 23050 | E16: =D16+'Income Statement'!E12-'Income Statement'!E14 -> 24882.46 | F16: =E16+'Income Statement'!F12-'Income Statement'!F14 -> 26821.6 | G16: =F16+'Income Statement'!G12-'Income Statement'!G14 -> 28945.96 | H16: =G16+'Income Statement'!H12-'Income Statement'!H14 -> 31308.578 | I16: =H16+'Income Statement'!I12-'Income Statement'!I14 -> 33787.024
A17: Total liab. & equity | B17: =B15+B16 -> 26880 | C17: =C15+C16 -> 29320 | D17: =D15+D16 -> 32000 | E17: =E15+E16 -> 33741.392 | F17: =F15+F16 -> 35672.61 | G17: =G15+G16 -> 37819.353 | H17: =H15+H16 -> 40217.29 | I17: =I15+I16 -> 42693.992
A18: Net cash / (net debt) | B18: =B4-B11 -> 3180 | C18: =C4-C11 -> 3900 | D18: =D4-D11 -> 4780 | E18: =E4-E11 -> 5162.46 | F18: =F4-F11 -> 6201.6 | G18: =G4-G11 -> 7275.96 | H18: =H4-H11 -> 10538.578 | I18: =I4-I11 -> 13767.024

Sheet Cash Flow
A1: Cash flow (USD m, forecast)
A2: Derived from the income statement and Assumptions drivers.
D3: 2026E | E3: 2027E | F3: 2028E | G3: 2029E | H3: 2030E
A4: Net income | E4: ='Income Statement'!E12 -> 5595.66 | F4: ='Income Statement'!F12 -> 5890.5 | G4: ='Income Statement'!G12 -> 6273.288 | H4: ='Income Statement'!H12 -> 6718.992 | I4: ='Income Statement'!I12 -> 7052.64
A5: + D&A | E5: ='Income Statement'!E7 -> 2000 | F5: ='Income Statement'!F7 -> 2250 | G5: ='Income Statement'!G7 -> 2550 | H5: ='Income Statement'!H7 -> 2750 | I5: ='Income Statement'!I7 -> 2900
A6: − Δ working capital | E6: =-Assumptions!C44 -> -150 | F6: =-Assumptions!D44 -> -150 | G6: =-Assumptions!E44 -> -200 | H6: =-Assumptions!F44 -> -150 | I6: =-Assumptions!G44 -> -150
A7: Operating cash flow | E7: =E4+E5+E6 -> 7445.66 | F7: =F4+F5+F6 -> 7990.5 | G7: =G4+G5+G6 -> 8623.288 | H7: =H4+H5+H6 -> 9318.992 | I7: =I4+I5+I6 -> 9802.64
A8: − Capex | E8: =-Assumptions!C43 -> -3300 | F8: =-Assumptions!D43 -> -3000 | G8: =-Assumptions!E43 -> -3400 | H8: =-Assumptions!F43 -> -1700 | I8: =-Assumptions!G43 -> -2000
A9: Free cash flow | E9: =E7+E8 -> 4145.66 | F9: =F7+F8 -> 4990.5 | G9: =G7+G8 -> 5223.288 | H9: =H7+H8 -> 7618.992 | I9: =I7+I8 -> 7802.64
A10: − Dividends | E10: =-'Income Statement'!E14 -> -3763.2 | F10: =-'Income Statement'!F14 -> -3951.36 | G10: =-'Income Statement'!G14 -> -4148.928 | H10: =-'Income Statement'!H14 -> -4356.3744 | I10: =-'Income Statement'!I14 -> -4574.1931
A11: + Δ debt | E11: 0 | F11: 0 | G11: 0 | H11: 0 | I11: 0
A12: Net change in cash | E12: =E9+E10+E11 -> 382.46 | F12: =F9+F10+F11 -> 1039.14 | G12: =G9+G10+G11 -> 1074.36 | H12: =H9+H10+H11 -> 3262.6176 | I12: =I9+I10+I11 -> 3228.4469
A13: Opening cash | E13: ='Balance Sheet'!D4 -> 5060 | F13: =E14 -> 5442.46 | G13: =F14 -> 6481.6 | H13: =G14 -> 7555.96 | I13: =H14 -> 10818.578
A14: Closing cash | E14: ='Balance Sheet'!$D$4+SUM($E$12:E12) -> 5442.46 | F14: ='Balance Sheet'!$D$4+SUM($E$12:F12) -> 6481.6 | G14: ='Balance Sheet'!$D$4+SUM($E$12:G12) -> 7555.96 | H14: ='Balance Sheet'!$D$4+SUM($E$12:H12) -> 10818.578 | I14: ='Balance Sheet'!$D$4+SUM($E$12:I12) -> 14047.024

Sheet Summary Financials
A1: Summary financials (USD m)
A2: Every cell links to the statement sheets.
A3: 2023 | B3: 2024 | C3: 2025 | D3: 2026E | E3: 2027E | F3: 2028E | G3: 2029E | H3: 2030E
A4: Revenue | B4: ='Income Statement'!B4 -> 22830 | C4: ='Income Statement'!C4 -> 24428 | D4: ='Income Statement'!D4 -> 23473 | E4: ='Income Statement'!E4 -> 23950 | F4: ='Income Statement'!F4 -> 25100 | G4: ='Income Statement'!G4 -> 26900 | H4: ='Income Statement'!H4 -> 28400 | I4: ='Income Statement'!I4 -> 29600
A5: EBITDA | B5: ='Income Statement'!B5 -> 7586 | C5: ='Income Statement'!C5 -> 8648 | D5: ='Income Statement'!D5 -> 8636 | E5: ='Income Statement'!E5 -> 8861.5 | F5: ='Income Statement'!F5 -> 9412.5 | G5: ='Income Statement'!G5 -> 10168.2 | H5: ='Income Statement'!H5 -> 10848.8 | I5: ='Income Statement'!I5 -> 11396
A6: EBIT | B6: ='Income Statement'!B8 -> 6286 | C6: ='Income Statement'!C8 -> 7048 | D6: ='Income Statement'!D8 -> 6736 | E6: ='Income Statement'!E8 -> 6861.5 | F6: ='Income Statement'!F8 -> 7162.5 | G6: ='Income Statement'!G8 -> 7618.2 | H6: ='Income Statement'!H8 -> 8098.8 | I6: ='Income Statement'!I8 -> 8496
A7: Net income | B7: ='Income Statement'!B12 -> 4425.96 | C7: ='Income Statement'!C12 -> 5001.36 | D7: ='Income Statement'!D12 -> 5166 | E7: ='Income Statement'!E12 -> 5595.66 | F7: ='Income Statement'!F12 -> 5890.5 | G7: ='Income Statement'!G12 -> 6273.288 | H7: ='Income Statement'!H12 -> 6718.992 | I7: ='Income Statement'!I12 -> 7052.64
A8: EPS (AED) | B8: ='Income Statement'!B13 -> 0.2118105 | C8: ='Income Statement'!C13 -> 0.23934708 | D8: ='Income Statement'!D13 -> 0.24722615 | E8: ='Income Statement'!E13 -> 0.26778813 | F8: ='Income Statement'!F13 -> 0.28189811 | G8: ='Income Statement'!G13 -> 0.30021697 | H8: ='Income Statement'!H13 -> 0.32154676 | I8: ='Income Statement'!I13 -> 0.33751395
A9: DPS (AED) | B9: ='Income Statement'!B15 -> 0.15553329 | C9: ='Income Statement'!C15 -> 0.16328603 | D9: ='Income Statement'!D15 -> 0.17151733 | E9: ='Income Statement'!E15 -> 0.1800932 | F9: ='Income Statement'!F15 -> 0.18909786 | G9: ='Income Statement'!G15 -> 0.19855275 | H9: ='Income Statement'!H15 -> 0.20848039 | I9: ='Income Statement'!I15 -> 0.21890441
A10: Free cash flow | B10: — | C10: — | D10: — | E10: ='Cash Flow'!E9 -> 4145.66 | F10: ='Cash Flow'!F9 -> 4990.5 | G10: ='Cash Flow'!G9 -> 5223.288 | H10: ='Cash Flow'!H9 -> 7618.992 | I10: ='Cash Flow'!I9 -> 7802.64
A11: Net cash / (net debt) | B11: ='Balance Sheet'!B18 -> 3180 | C11: ='Balance Sheet'!C18 -> 3900 | D11: ='Balance Sheet'!D18 -> 4780 | E11: ='Balance Sheet'!E18 -> 5162.46 | F11: ='Balance Sheet'!F18 -> 6201.6 | G11: ='Balance Sheet'!G18 -> 7275.96 | H11: ='Balance Sheet'!H18 -> 10538.578 | I11: ='Balance Sheet'!I18 -> 13767.024

Sheet Monte Carlo
A1: Monte Carlo — engine output
A2: 50,000 paths · 16 factors (7C+9D) · YZ-HAR width · Student-t(5) · drift OFF · seed 42. Prices in AED.
A3: Horizon | B3: p5 | C3: p25 | D3: p50 | E3: p75 | F3: p95
A4: T+20 sessions | B4: 3.052 | C4: 3.32 | D4: 3.454 | E4: 3.594 | F4: 3.858
A5: T+60 sessions | B5: 2.831 | C5: 3.222 | D5: 3.478 | E5: 3.747 | F5: 4.212
A7: Spot | B7: =Assumptions!B4 -> 3.44
A8: Diffusion vol (YZ-HAR) | B8: =Assumptions!B47 -> 0.1733
A9: Net 3-month factor drift | B9: =Assumptions!B48 -> 0.0165
A11: PROBABILITY ZONES (T+60)
A12: < -10% | B12: 0.16
A13: -10..-5% | B13: 0.128
A14: -5..+5% | B14: 0.348
A15: +5..+10% | B15: 0.141
A16: >+10% | B16: 0.222
A18: TOUCH-PROBABILITY LADDER
A19: Level (AED) | B19: T+20 | C19: T+60
A20: 3.9 | B20: 0.055 | C20: 0.247
A21: 3.75 | B21: 0.144 | C21: 0.404
A22: 3.65 | B22: 0.271 | C22: 0.546
A23: 3.55 | B23: 0.488 | C23: 0.715
A24: 3.35 | B24: 0.485 | C24: 0.682
A25: 3.25 | B25: 0.246 | C25: 0.486
A26: 3.15 | B26: 0.131 | C26: 0.342
A27: 3.05 | B27: 0.071 | C27: 0.233

Sheet Sensitivity
A1: DCF sensitivity — WACC × terminal g
A2: Fair value per share (AED). Recomputed live from the DCF FCFF stream.
A4: WACC \ g | B4: 0.015 | C4: 0.02 | D4: 0.025 | E4: 0.03 | F4: 0.035
A5: 0.09 | B5: =((DCF!$B$9/(1+$A5)^1+DCF!$C$9/(1+$A5)^2+DCF!$D$9/(1+$A5)^3+DCF!$E$9/(1+$A5)^4+DCF!$F$9/(1+$A5)^5)+(DCF!$F$9*(1+B$4)/($A5-B$4))/(1+$A5)^5+Assumptions!$B$7)/Assumptions!$B$5*Assumptions!$B$6 -> 4.6481083 | C5: =((DCF!$B$9/(1+$A5)^1+DCF!$C$9/(1+$A5)^2+DCF!$D$9/(1+$A5)^3+DCF!$E$9/(1+$A5)^4+DCF!$F$9/(1+$A5)^5)+(DCF!$F$9*(1+C$4)/($A5-C$4))/(1+$A5)^5+Assumptions!$B$7)/Assumptions!$B$5*Assumptions!$B$6 -> 4.9027542 | D5: =((DCF!$B$9/(1+$A5)^1+DCF!$C$9/(1+$A5)^2+DCF!$D$9/(1+$A5)^3+DCF!$E$9/(1+$A5)^4+DCF!$F$9/(1+$A5)^5)+(DCF!$F$9*(1+D$4)/($A5-D$4))/(1+$A5)^5+Assumptions!$B$7)/Assumptions!$B$5*Assumptions!$B$6 -> 5.1965765 | E5: =((DCF!$B$9/(1+$A5)^1+DCF!$C$9/(1+$A5)^2+DCF!$D$9/(1+$A5)^3+DCF!$E$9/(1+$A5)^4+DCF!$F$9/(1+$A5)^5)+(DCF!$F$9*(1+E$4)/($A5-E$4))/(1+$A5)^5+Assumptions!$B$7)/Assumptions!$B$5*Assumptions!$B$6 -> 5.539369 | F5: =((DCF!$B$9/(1+$A5)^1+DCF!$C$9/(1+$A5)^2+DCF!$D$9/(1+$A5)^3+DCF!$E$9/(1+$A5)^4+DCF!$F$9/(1+$A5)^5)+(DCF!$F$9*(1+F$4)/($A5-F$4))/(1+$A5)^5+Assumptions!$B$7)/Assumptions!$B$5*Assumptions!$B$6 -> 5.9444876
A6: 0.095 | B6: =((DCF!$B$9/(1+$A6)^1+DCF!$C$9/(1+$A6)^2+DCF!$D$9/(1+$A6)^3+DCF!$E$9/(1+$A6)^4+DCF!$F$9/(1+$A6)^5)+(DCF!$F$9*(1+B$4)/($A6-B$4))/(1+$A6)^5+Assumptions!$B$7)/Assumptions!$B$5*Assumptions!$B$6 -> 4.3544892 | C6: =((DCF!$B$9/(1+$A6)^1+DCF!$C$9/(1+$A6)^2+DCF!$D$9/(1+$A6)^3+DCF!$E$9/(1+$A6)^4+DCF!$F$9/(1+$A6)^5)+(DCF!$F$9*(1+C$4)/($A6-C$4))/(1+$A6)^5+Assumptions!$B$7)/Assumptions!$B$5*Assumptions!$B$6 -> 4.5732625 | D6: =((DCF!$B$9/(1+$A6)^1+DCF!$C$9/(1+$A6)^2+DCF!$D$9/(1+$A6)^3+DCF!$E$9/(1+$A6)^4+DCF!$F$9/(1+$A6)^5)+(DCF!$F$9*(1+D$4)/($A6-D$4))/(1+$A6)^5+Assumptions!$B$7)/Assumptions!$B$5*Assumptions!$B$6 -> 4.8232891 | E6: =((DCF!$B$9/(1+$A6)^1+DCF!$C$9/(1+$A6)^2+DCF!$D$9/(1+$A6)^3+DCF!$E$9/(1+$A6)^4+DCF!$F$9/(1+$A6)^5)+(DCF!$F$9*(1+E$4)/($A6-E$4))/(1+$A6)^5+Assumptions!$B$7)/Assumptions!$B$5*Assumptions!$B$6 -> 5.1117814 | F6: =((DCF!$B$9/(1+$A6)^1+DCF!$C$9/(1+$A6)^2+DCF!$D$9/(1+$A6)^3+DCF!$E$9/(1+$A6)^4+DCF!$F$9/(1+$A6)^5)+(DCF!$F$9*(1+F$4)/($A6-F$4))/(1+$A6)^5+Assumptions!$B$7)/Assumptions!$B$5*Assumptions!$B$6 -> 5.4483557
A7: 0.1 | B7: =((DCF!$B$9/(1+$A7)^1+DCF!$C$9/(1+$A7)^2+DCF!$D$9/(1+$A7)^3+DCF!$E$9/(1+$A7)^4+DCF!$F$9/(1+$A7)^5)+(DCF!$F$9*(1+B$4)/($A7-B$4))/(1+$A7)^5+Assumptions!$B$7)/Assumptions!$B$5*Assumptions!$B$6 -> 4.0956936 | C7: =((DCF!$B$9/(1+$A7)^1+DCF!$C$9/(1+$A7)^2+DCF!$D$9/(1+$A7)^3+DCF!$E$9/(1+$A7)^4+DCF!$F$9/(1+$A7)^5)+(DCF!$F$9*(1+C$4)/($A7-C$4))/(1+$A7)^5+Assumptions!$B$7)/Assumptions!$B$5*Assumptions!$B$6 -> 4.285243 | D7: =((DCF!$B$9/(1+$A7)^1+DCF!$C$9/(1+$A7)^2+DCF!$D$9/(1+$A7)^3+DCF!$E$9/(1+$A7)^4+DCF!$F$9/(1+$A7)^5)+(DCF!$F$9*(1+D$4)/($A7-D$4))/(1+$A7)^5+Assumptions!$B$7)/Assumptions!$B$5*Assumptions!$B$6 -> 4.5000656 | E7: =((DCF!$B$9/(1+$A7)^1+DCF!$C$9/(1+$A7)^2+DCF!$D$9/(1+$A7)^3+DCF!$E$9/(1+$A7)^4+DCF!$F$9/(1+$A7)^5)+(DCF!$F$9*(1+E$4)/($A7-E$4))/(1+$A7)^5+Assumptions!$B$7)/Assumptions!$B$5*Assumptions!$B$6 -> 4.7455772 | F7: =((DCF!$B$9/(1+$A7)^1+DCF!$C$9/(1+$A7)^2+DCF!$D$9/(1+$A7)^3+DCF!$E$9/(1+$A7)^4+DCF!$F$9/(1+$A7)^5)+(DCF!$F$9*(1+F$4)/($A7-F$4))/(1+$A7)^5+Assumptions!$B$7)/Assumptions!$B$5*Assumptions!$B$6 -> 5.0288598
A8: 0.105 | B8: =((DCF!$B$9/(1+$A8)^1+DCF!$C$9/(1+$A8)^2+DCF!$D$9/(1+$A8)^3+DCF!$E$9/(1+$A8)^4+DCF!$F$9/(1+$A8)^5)+(DCF!$F$9*(1+B$4)/($A8-B$4))/(1+$A8)^5+Assumptions!$B$7)/Assumptions!$B$5*Assumptions!$B$6 -> 3.8659117 | C8: =((DCF!$B$9/(1+$A8)^1+DCF!$C$9/(1+$A8)^2+DCF!$D$9/(1+$A8)^3+DCF!$E$9/(1+$A8)^4+DCF!$F$9/(1+$A8)^5)+(DCF!$F$9*(1+C$4)/($A8-C$4))/(1+$A8)^5+Assumptions!$B$7)/Assumptions!$B$5*Assumptions!$B$6 -> 4.0313711 | D8: =((DCF!$B$9/(1+$A8)^1+DCF!$C$9/(1+$A8)^2+DCF!$D$9/(1+$A8)^3+DCF!$E$9/(1+$A8)^4+DCF!$F$9/(1+$A8)^5)+(DCF!$F$9*(1+D$4)/($A8-D$4))/(1+$A8)^5+Assumptions!$B$7)/Assumptions!$B$5*Assumptions!$B$6 -> 4.2175129 | E8: =((DCF!$B$9/(1+$A8)^1+DCF!$C$9/(1+$A8)^2+DCF!$D$9/(1+$A8)^3+DCF!$E$9/(1+$A8)^4+DCF!$F$9/(1+$A8)^5)+(DCF!$F$9*(1+E$4)/($A8-E$4))/(1+$A8)^5+Assumptions!$B$7)/Assumptions!$B$5*Assumptions!$B$6 -> 4.4284737 | F8: =((DCF!$B$9/(1+$A8)^1+DCF!$C$9/(1+$A8)^2+DCF!$D$9/(1+$A8)^3+DCF!$E$9/(1+$A8)^4+DCF!$F$9/(1+$A8)^5)+(DCF!$F$9*(1+F$4)/($A8-F$4))/(1+$A8)^5+Assumptions!$B$7)/Assumptions!$B$5*Assumptions!$B$6 -> 4.6695717
A9: 0.11 | B9: =((DCF!$B$9/(1+$A9)^1+DCF!$C$9/(1+$A9)^2+DCF!$D$9/(1+$A9)^3+DCF!$E$9/(1+$A9)^4+DCF!$F$9/(1+$A9)^5)+(DCF!$F$9*(1+B$4)/($A9-B$4))/(1+$A9)^5+Assumptions!$B$7)/Assumptions!$B$5*Assumptions!$B$6 -> 3.660557 | C9: =((DCF!$B$9/(1+$A9)^1+DCF!$C$9/(1+$A9)^2+DCF!$D$9/(1+$A9)^3+DCF!$E$9/(1+$A9)^4+DCF!$F$9/(1+$A9)^5)+(DCF!$F$9*(1+C$4)/($A9-C$4))/(1+$A9)^5+Assumptions!$B$7)/Assumptions!$B$5*Assumptions!$B$6 -> 3.8059502 | D9: =((DCF!$B$9/(1+$A9)^1+DCF!$C$9/(1+$A9)^2+DCF!$D$9/(1+$A9)^3+DCF!$E$9/(1+$A9)^4+DCF!$F$9/(1+$A9)^5)+(DCF!$F$9*(1+D$4)/($A9-D$4))/(1+$A9)^5+Assumptions!$B$7)/Assumptions!$B$5*Assumptions!$B$6 -> 3.9684485 | E9: =((DCF!$B$9/(1+$A9)^1+DCF!$C$9/(1+$A9)^2+DCF!$D$9/(1+$A9)^3+DCF!$E$9/(1+$A9)^4+DCF!$F$9/(1+$A9)^5)+(DCF!$F$9*(1+E$4)/($A9-E$4))/(1+$A9)^5+Assumptions!$B$7)/Assumptions!$B$5*Assumptions!$B$6 -> 4.151259 | F9: =((DCF!$B$9/(1+$A9)^1+DCF!$C$9/(1+$A9)^2+DCF!$D$9/(1+$A9)^3+DCF!$E$9/(1+$A9)^4+DCF!$F$9/(1+$A9)^5)+(DCF!$F$9*(1+F$4)/($A9-F$4))/(1+$A9)^5+Assumptions!$B$7)/Assumptions!$B$5*Assumptions!$B$6 -> 4.3584442

Sheet Per-Share & Ratios
A1: Per-share & ratios (the Data Miner)
A2: Identical panel across every study. Per-share in AED; current-price multiples at spot.
A3: 2023 | B3: 2024 | C3: 2025 | D3: 2026E | E3: 2027E | F3: 2028E | G3: 2029E | H3: 2030E
A4: EPS (AED) | B4: ='Income Statement'!B13 -> 0.2118105 | C4: ='Income Statement'!C13 -> 0.23934708 | D4: ='Income Statement'!D13 -> 0.24722615 | E4: ='Income Statement'!E13 -> 0.26778813 | F4: ='Income Statement'!F13 -> 0.28189811 | G4: ='Income Statement'!G13 -> 0.30021697 | H4: ='Income Statement'!H13 -> 0.32154676 | I4: ='Income Statement'!I13 -> 0.33751395
A5: DPS (AED) | B5: ='Income Statement'!B15 -> 0.15553329 | C5: ='Income Statement'!C15 -> 0.16328603 | D5: ='Income Statement'!D15 -> 0.17151733 | E5: ='Income Statement'!E15 -> 0.1800932 | F5: ='Income Statement'!F15 -> 0.18909786 | G5: ='Income Statement'!G15 -> 0.19855275 | H5: ='Income Statement'!H15 -> 0.20848039 | I5: ='Income Statement'!I15 -> 0.21890441
A6: BVPS (AED) | B6: ='Balance Sheet'!B16/Assumptions!$B$5*Assumptions!$B$6 -> 0.9513852 | C6: ='Balance Sheet'!C16/Assumptions!$B$5*Assumptions!$B$6 -> 1.0274769 | D6: ='Balance Sheet'!D16/Assumptions!$B$5*Assumptions!$B$6 -> 1.10309 | E6: ='Balance Sheet'!E16/Assumptions!$B$5*Assumptions!$B$6 -> 1.1907849 | F6: ='Balance Sheet'!F16/Assumptions!$B$5*Assumptions!$B$6 -> 1.2835852 | G6: ='Balance Sheet'!G16/Assumptions!$B$5*Assumptions!$B$6 -> 1.3852494 | H6: ='Balance Sheet'!H16/Assumptions!$B$5*Assumptions!$B$6 -> 1.4983158 | I6: ='Balance Sheet'!I16/Assumptions!$B$5*Assumptions!$B$6 -> 1.6169253
A7: EBITDA margin | B7: ='Income Statement'!B6 -> 0.33228208 | C7: ='Income Statement'!C6 -> 0.35401998 | D7: ='Income Statement'!D6 -> 0.36791207 | E7: ='Income Statement'!E6 -> 0.37 | F7: ='Income Statement'!F6 -> 0.375 | G7: ='Income Statement'!G6 -> 0.378 | H7: ='Income Statement'!H6 -> 0.382 | I7: ='Income Statement'!I6 -> 0.385
A8: Net margin | B8: ='Income Statement'!B12/'Income Statement'!B4 -> 0.19386597 | C8: ='Income Statement'!C12/'Income Statement'!C4 -> 0.20473882 | D8: ='Income Statement'!D12/'Income Statement'!D4 -> 0.22008265 | E8: ='Income Statement'!E12/'Income Statement'!E4 -> 0.23363925 | F8: ='Income Statement'!F12/'Income Statement'!F4 -> 0.23468127 | G8: ='Income Statement'!G12/'Income Statement'!G4 -> 0.23320773 | H8: ='Income Statement'!H12/'Income Statement'!H4 -> 0.23658423 | I8: ='Income Statement'!I12/'Income Statement'!I4 -> 0.23826486
A9: Payout ratio | B9: ='Income Statement'!B16 -> 0.73430397 | C9: ='Income Statement'!C16 -> 0.68221444 | D9: ='Income Statement'!D16 -> 0.69376694 | E9: ='Income Statement'!E16 -> 0.6725212 | F9: ='Income Statement'!F16 -> 0.67080214 | G9: ='Income Statement'!G16 -> 0.66136418 | H9: ='Income Statement'!H16 -> 0.64836726 | I9: ='Income Statement'!I16 -> 0.64857885
A10: ROE | B10: ='Income Statement'!B12/'Balance Sheet'!B16 -> 0.2226338 | C10: ='Income Statement'!C12/'Balance Sheet'!C16 -> 0.23294644 | D10: ='Income Statement'!D12/'Balance Sheet'!D16 -> 0.22412148 | E10: ='Income Statement'!E12/'Balance Sheet'!E16 -> 0.22488371 | F10: ='Income Statement'!F12/'Balance Sheet'!F16 -> 0.21961777 | G10: ='Income Statement'!G12/'Balance Sheet'!G16 -> 0.21672413 | H10: ='Income Statement'!H12/'Balance Sheet'!H16 -> 0.21460547 | I10: ='Income Statement'!I12/'Balance Sheet'!I16 -> 0.20873812
A11: Net debt / EBITDA | B11: =-'Balance Sheet'!B18/'Income Statement'!B5 -> -0.41919325 | C11: =-'Balance Sheet'!C18/'Income Statement'!C5 -> -0.45097132 | D11: =-'Balance Sheet'!D18/'Income Statement'!D5 -> -0.55349699 | E11: =-'Balance Sheet'!E18/'Income Statement'!E5 -> -0.5825718 | F11: =-'Balance Sheet'!F18/'Income Statement'!F5 -> -0.65886853 | G11: =-'Balance Sheet'!G18/'Income Statement'!G5 -> -0.71556028 | H11: =-'Balance Sheet'!H18/'Income Statement'!H5 -> -0.97140491 | I11: =-'Balance Sheet'!I18/'Income Statement'!I5 -> -1.2080576
A12: Effective tax rate | B12: =Assumptions!$B$16 -> 0.16 | C12: =Assumptions!$B$16 -> 0.16 | D12: =Assumptions!$B$16 -> 0.16 | E12: =Assumptions!$B$16 -> 0.16 | F12: =Assumptions!$B$16 -> 0.16 | G12: =Assumptions!$B$16 -> 0.16 | H12: =Assumptions!$B$16 -> 0.16 | I12: =Assumptions!$B$16 -> 0.16
A14: CURRENT-PRICE MULTIPLES (at spot)
A15: P/E (FY25) | B15: =Assumptions!B4/'Income Statement'!D13 -> 13.914385
A16: P/E (FY26E) | B16: =Assumptions!B4/'Income Statement'!E13 -> 12.845976
A17: P/B (FY25) | B17: =Assumptions!B4/('Balance Sheet'!D16/Assumptions!B5*Assumptions!B6) -> 3.1185126
A18: EV/EBITDA (FY25) | B18: =(Assumptions!B4*Assumptions!B5/Assumptions!B6-Assumptions!B7)/'Income Statement'!D5 -> 7.7699995
A19: Dividend yield (FY25) | B19: ='Income Statement'!D15/Assumptions!B4 -> 0.049859689
A20: Dividend yield (FY26E) | B20: ='Income Statement'!E15/Assumptions!B4 -> 0.052352674
A21: FCF yield (FY26E) | B21: ='Cash Flow'!E9/(Assumptions!B4*Assumptions!B5/Assumptions!B6) -> 0.057673359

Sheet Peer & Sector
A1: Peer set & sector
A2: No perfect comparable — a global gas-infrastructure / midstream + regional set is the reference.
A3: Peer group | B3: Names | C3: Typical valuation
A4: Global LNG / gas midstream | B4: Cheniere, Williams, ONEOK, Enbridge, Sempra | C4: EV/EBITDA ~9–12x; yield 3–7%
A5: European gas infrastructure | B5: Snam, Enagás, Fluxys | C5: EV/EBITDA ~8–10x; high payout
A6: APAC LNG producers | B6: Woodside, Santos, PETRONAS-linked | C6: EV/EBITDA ~5–7x; oil-linked
A7: Gulf / ADX energy | B7: ADNOC Drilling, ADNOC Distribution, Aramco | C7: EV/EBITDA ~7–9x; 4–6% yield
A8: ADNOC Gas (this study) | B8: — | C8: EV/EBITDA ~7.8x; ~5% yield
A10: Sector risks | B10: Brent/oil-linkage on exports; regional security (Hormuz); gas-allocation & tariff policy; controlling-shareholder capital allocation; energy transition on terminal value.
