Workbook

Sheet READ FIRST
A1: Testahil — Agthia Group PJSC (ADX: AGTHIA)
A2: Companion model · Independent Valuation Study · Educational analysis · Not investment advice
A4: ⚠ INDICATIVE ONLY · FAILED CALIBRATION TEST. The Step 0 backtest of the Monte Carlo lens on AGTHIA does not beat the zero-drift random-walk benchmark (CRPS skill −0.004 on non-overlapping windows; ≤ 0 on all schemes). The §3/Monte Carlo outputs are therefore indicative only. The fundamental valuation sheets are unaffected. See the study, Appendix B.
A6: What this workbook is. A transparent companion to the Agthia valuation study: every assumption is exposed, every output traceable. A blue cell is an input;
A7: a black cell is a formula. All inputs live on the Assumptions sheet — change one (the WACC build, a segment margin, a multiple) and the whole model reprices.
A9: What it is not. It is not investment advice, a recommendation, or a target. Values are model outputs presented as ranges. The preparer is not licensed by any
A10: securities regulator in any jurisdiction, and may hold, take, or dispose of a position in the security discussed. See the study Disclosure & Disclaimer.
A12: Currency. AED millions unless stated; per-share values in AED; dividends in fils (1/100 AED). Spot and market data as of 6 July 2026.
A13: Historical financials are company disclosure (ADX preliminary FY2025 results, 5 March 2026; Q1 2026 release, 12 May 2026). Where a historical line is not
A14: separately disclosed in the preliminary release (D&A, net finance cost, tax, minorities), it is estimated to balance to disclosed totals (revenue, EBITDA,
A15: net profit, EPS, total assets, equity) and marked blue as an input.
A17: Sheets: Summary · Fundamental Valuation · Assumptions · SOTP · Segments · Relative & Normalized · DCF · Income Statement · Balance Sheet · Cash Flow ·
A18: Summary Financials · Monte Carlo · Sensitivity · Per-Share & Ratios · Peer & Sector.

Sheet Summary
A1: Valuation summary — Agthia Group (ADX: AGTHIA)
A2: Four-lens fair value vs spot. Base links live; bear/bull are scenario runs (hardcoded from the study engine).
B3: Bear | C3: Base | D3: Bull | E3: Weight
A4: Consolidated DCF (primary) | B4: 2.76 | C4: =DCF!B23 -> 4.5991063 | D4: 7.07 | E4: =Assumptions!$B$36 -> 0.35
A5: Segment SOTP | B5: 3.09 | C5: =SOTP!C12 -> 4.2409362 | D5: 5.71 | E5: =Assumptions!$B$37 -> 0.25
A6: Relative multiples | B6: 3.07 | C6: ='Relative & Normalized'!C4 -> 3.8324465 | D6: 4.97 | E6: =Assumptions!$B$38 -> 0.15
A7: Normalized earnings | B7: 3.41 | C7: ='Relative & Normalized'!C6 -> 4.5117884 | D7: 5.76 | E7: =Assumptions!$B$39 -> 0.25
A8: Weighted central | B8: =SUMPRODUCT(B4:B7,$E$4:$E$7) -> 3.0515 | C8: =SUMPRODUCT(C4:C7,$E$4:$E$7) -> 4.3727353 | D8: =SUMPRODUCT(D4:D7,$E$4:$E$7) -> 6.0875
A10: Spot price (AED) | C10: =Assumptions!$B$4 -> 3.51
A11: Upside to central base | C11: =C8/C10-1 -> 0.24579354
A13: Read: meaningfully undervalued on a one-off-laden 2025 the market treats as structural; the swing factors are the Snacking reset (coffee + EGP) and the KSA protein ramp. §3 Monte Carlo is INDICATIVE ONLY (failed Step 0).

Sheet Fundamental Valuation
A1: Fundamental valuation — football field data
A2: Bear/base/bull per lens (links to Summary). Figure 1 of the study is drawn from this table.
A3: Lens | B3: Bear | C3: Base | D3: Bull
A4: Consolidated DCF (primary) | B4: =Summary!B4 -> 2.76 | C4: =Summary!C4 -> 4.5991063 | D4: =Summary!D4 -> 7.07
A5: Segment SOTP | B5: =Summary!B5 -> 3.09 | C5: =Summary!C5 -> 4.2409362 | D5: =Summary!D5 -> 5.71
A6: Relative multiples | B6: =Summary!B6 -> 3.07 | C6: =Summary!C6 -> 3.8324465 | D6: =Summary!D6 -> 4.97
A7: Normalized earnings | B7: =Summary!B7 -> 3.41 | C7: =Summary!C7 -> 4.5117884 | D7: =Summary!D7 -> 5.76
A8: Weighted central | B8: =Summary!B8 -> 3.0515 | C8: =Summary!C8 -> 4.3727353 | D8: =Summary!D8 -> 6.0875
A9: Spot | C9: =Assumptions!$B$4 -> 3.51

Sheet Assumptions
A1: Assumptions — the single input layer
A2: All blue cells are inputs. Every other sheet links here.
A3: ANCHORS
A4: Spot price (AED/share) | B4: 3.51
A5: Shares outstanding (mn) | B5: 831.156
A6: Consolidated net debt (AED mn) | B6: 1300
A7: Cash & equivalents (AED mn) | B7: 530.7
A8: Minorities — estimated value (AED mn) | B8: 260
A9: Tax rate (Pillar II blended) | B9: 0.2
A11: COST OF CAPITAL — Ke = rf + β × ERP (§3.5-G)
A12: Risk-free rate (rf) | B12: 0.042
A13: Equity risk premium (ERP) | B13: 0.06
A14: Beta (band 0.8–1.3) | B14: 0.9
A15: Ke — UAE sleeve = rf + β×ERP | B15: =B12+B14*B13 -> 0.096
A16: Ke — Egypt/Jordan sleeve (judgment) | B16: 0.17
A17: UAE sleeve weight (of equity value) | B17: 0.5
A18: Ke — blended | B18: =B17*B15+(1-B17)*B16 -> 0.133
A19: Equity weight (E/(D+E)) | B19: 0.69
A20: Cost of debt, after tax | B20: 0.045
A21: WACC = wE×Ke + wD×Kd | B21: =B19*B18+(1-B19)*B20 -> 0.10572
A22: Terminal growth (g) | B22: 0.0225
A24: SOTP — EV/EBITDA multiples on FY26E segment EBITDA
A25: Water & Food multiple | B25: 10.5
A26: Agri-Business multiple | B26: 6
A27: Snacking multiple | B27: 7.5
A28: Protein & Frozen multiple | B28: 6.5
A30: RELATIVE & NORMALIZED
A31: EV/EBITDA target multiple (FY26E group) | B31: 7.5
A32: Mid-cycle attributable net profit (AED mn) | B32: 300
A33: Justified P/E | B33: 12.5
A35: SYNTHESIS WEIGHTS
A36: DCF weight | B36: 0.35
A37: SOTP weight | B37: 0.25
A38: Relative weight | B38: 0.15
A39: Normalized-earnings weight | B39: 0.25
A41: WORKING CAPITAL (% of revenue)
A42: Inventory | B42: 0.195
A43: Trade & other receivables | B43: 0.18
A44: Trade & other payables | B44: 0.225
A46: MONTE CARLO (engine inputs — see study §3 / Appendix B)
...

Sheet SOTP
A1: Segment sum-of-the-parts (cross-check lens)
A2: Each segment marked at FY26E EBITDA × a class multiple. Links: Income Statement + Assumptions.
A3: Part | B3: Basis | C3: Value (AED mn)
A4: Water & Food | B4: FY26E EBITDA × multiple (branded water #1; Riviere D2C) | C4: ='Income Statement'!E10*Assumptions!$B$25 -> 2187.8892
A5: Agri-Business | B5: FY26E EBITDA × multiple (regulated flour & feed, B2B) | C5: ='Income Statement'!E11*Assumptions!$B$26 -> 1362.4491
A6: Snacking | B6: FY26E EBITDA × multiple (Abu Auf/BMB/Al Foah, reset year) | C6: ='Income Statement'!E12*Assumptions!$B$27 -> 917.16975
A7: Protein & Frozen | B7: FY26E EBITDA × multiple (Nabil/Atyab + KSA ramp) | C7: ='Income Statement'!E13*Assumptions!$B$28 -> 617.37156
A8: Σ Enterprise value | C8: =SUM(C4:C7) -> 5084.8796
A9: less: consolidated net debt | C9: =-Assumptions!$B$6 -> -1300
A10: less: minorities (est. value) | C10: =-Assumptions!$B$8 -> -260
A11: SOTP equity value | C11: =C8+C9+C10 -> 3524.8796
A12: SOTP fair value per share (AED) | C12: =C11/Assumptions!$B$5 -> 4.2409362
A14: No conglomerate discount is applied: the four segments share one management, one balance sheet and one distribution backbone; the class multiples already carry the segment risk.

Sheet Segments
A1: Segment view
A2: Revenue, EBITDA and margin by segment, FY24–FY30E. All links to the Income Statement.
C3: FY24 | D3: FY25 | E3: FY26E | F3: FY27E | G3: FY28E | H3: FY29E | I3: FY30E
A4: Water & Food revenue | C4: ='Income Statement'!C4 -> 1082.2 | D4: ='Income Statement'!D4 -> 1240.3 | E4: ='Income Statement'!E4 -> 1389.136 | F4: ='Income Statement'!F4 -> 1486.3755 | G4: ='Income Statement'!G4 -> 1575.5581 | H4: ='Income Statement'!H4 -> 1654.336 | I4: ='Income Statement'!I4 -> 1728.7811
A5: Agri-Business revenue | C5: ='Income Statement'!C5 -> 1332.2 | D5: ='Income Statement'!D5 -> 1223.2 | E5: ='Income Statement'!E5 -> 1247.664 | F5: ='Income Statement'!F5 -> 1278.8556 | G5: ='Income Statement'!G5 -> 1310.827 | H5: ='Income Statement'!H5 -> 1343.5977 | I5: ='Income Statement'!I5 -> 1377.1876
A6: Snacking revenue | C6: ='Income Statement'!C6 -> 1491.8 | D6: ='Income Statement'!D6 -> 1386.5 | E6: ='Income Statement'!E6 -> 1358.77 | F6: ='Income Statement'!F6 -> 1440.2962 | G6: ='Income Statement'!G6 -> 1541.1169 | H6: ='Income Statement'!H6 -> 1633.584 | I6: ='Income Statement'!I6 -> 1715.2631
A7: Protein & Frozen revenue | C7: ='Income Statement'!C7 -> 1008.5 | D7: ='Income Statement'!D7 -> 995.6 | E7: ='Income Statement'!E7 -> 1055.336 | F7: ='Income Statement'!F7 -> 1129.2095 | G7: ='Income Statement'!G7 -> 1196.9621 | H7: ='Income Statement'!H7 -> 1256.8102 | I7: ='Income Statement'!I7 -> 1313.3667
A8: Water & Food EBITDA | C8: ='Income Statement'!C10 -> 172.5 | D8: ='Income Statement'!D10 -> 170.9 | E8: ='Income Statement'!E10 -> 208.3704 | F8: ='Income Statement'!F10 -> 225.92908 | G8: ='Income Statement'!G10 -> 242.63594 | H8: ='Income Statement'!H10 -> 256.42207 | I8: ='Income Statement'!I10 -> 269.68985
A9: Agri-Business EBITDA | C9: ='Income Statement'!C11 -> 222.5 | D9: ='Income Statement'!D11 -> 222.2 | E9: ='Income Statement'!E11 -> 227.07485 | F9: ='Income Statement'!F11 -> 232.75172 | G9: ='Income Statement'!G11 -> 238.57051 | H9: ='Income Statement'!H11 -> 244.53477 | I9: ='Income Statement'!I11 -> 250.64814
A10: Snacking EBITDA | C10: ='Income Statement'!C12 -> 183.3 | D10: ='Income Statement'!D12 -> 17 | E10: ='Income Statement'!E12 -> 122.2893 | F10: ='Income Statement'!F12 -> 151.2311 | G10: ='Income Statement'!G12 -> 177.22845 | H10: ='Income Statement'!H12 -> 196.03007 | I10: ='Income Statement'!I12 -> 205.83158
A11: Protein & Frozen EBITDA | C11: ='Income Statement'!C13 -> 118 | D11: ='Income Statement'!D13 -> 72.7 | E11: ='Income Statement'!E13 -> 94.98024 | F11: ='Income Statement'!F13 -> 118.567 | G11: ='Income Statement'!G13 -> 137.65064 | H11: ='Income Statement'!H13 -> 150.81722 | I11: ='Income Statement'!I13 -> 164.17083
A13: W&F margin | C13: =C8/C4 -> 0.15939752 | D13: =D8/D4 -> 0.13778924 | E13: =E8/E4 -> 0.15 | F13: =F8/F4 -> 0.152 | G13: =G8/G4 -> 0.154 | H13: =H8/H4 -> 0.155 | I13: =I8/I4 -> 0.156
A14: Agri margin | C14: =C9/C5 -> 0.16701696 | D14: =D9/D5 -> 0.18165468 | E14: =E9/E5 -> 0.182 | F14: =F9/F5 -> 0.182 | G14: =G9/G5 -> 0.182 | H14: =H9/H5 -> 0.182 | I14: =I9/I5 -> 0.182
A15: Snacking margin | C15: =C10/C6 -> 0.1228717 | D15: =D10/D6 -> 0.012261089 | E15: =E10/E6 -> 0.09 | F15: =F10/F6 -> 0.105 | G15: =G10/G6 -> 0.115 | H15: =H10/H6 -> 0.12 | I15: =I10/I6 -> 0.12
A16: P&F margin | C16: =C11/C7 -> 0.11700545 | D16: =D11/D7 -> 0.073021294 | E16: =E11/E7 -> 0.09 | F16: =F11/F7 -> 0.105 | G16: =G11/G7 -> 0.115 | H16: =H11/H7 -> 0.12 | I16: =I11/I7 -> 0.125
A18: Snacking % of group revenue | C18: =C6/'Income Statement'!C8 -> 0.30353836 | D18: =D6/'Income Statement'!D8 -> 0.28613588 | E18: =E6/'Income Statement'!E8 -> 0.2690151 | F18: =F6/'Income Statement'!F8 -> 0.26998449 | G18: =G6/'Income Statement'!G8 -> 0.27400245 | H18: =H6/'Income Statement'!H8 -> 0.27742748 | I18: =I6/'Income Statement'!I8 -> 0.27960479

Sheet Relative & Normalized
A1: Relative & normalized-earnings lenses
A2: Links to Assumptions and the Income Statement.
A3: Lens | B3: Workings | C3: AED/share
A4: Relative EV/EBITDA | B4: FY26E group EBITDA × multiple − net debt − minorities, /sh | C4: =('Income Statement'!E15*Assumptions!$B$31-Assumptions!$B$6-Assumptions!$B$8)/Assumptions!$B$5 -> 3.8324465
A5: implied EV (AED mn) | C5: ='Income Statement'!E15*Assumptions!$B$31 -> 4745.3609
A6: Normalized earnings | B6: Mid-cycle attributable NP × justified P/E, /sh | C6: =Assumptions!$B$32*Assumptions!$B$33/Assumptions!$B$5 -> 4.5117884
A7: normalized EPS (AED) | C7: =Assumptions!$B$32/Assumptions!$B$5 -> 0.36094307

Sheet DCF
A1: Discounted cash flow — the primary lens (explicit 5-year FCFF)
A2: Revenue → EBITDA → D&A → EBIT → NOPAT → +D&A − capex − ΔWC → FCFF, discounted at the §G WACC. Links: Income Statement + Assumptions.
E3: FY26E | F3: FY27E | G3: FY28E | H3: FY29E | I3: FY30E
A4: Revenue | E4: ='Income Statement'!E8 -> 5050.906 | F4: ='Income Statement'!F8 -> 5334.7368 | G4: ='Income Statement'!G8 -> 5624.4641 | H4: ='Income Statement'!H8 -> 5888.3278 | I4: ='Income Statement'!I8 -> 6134.5985
A5: EBITDA | E5: ='Income Statement'!E15 -> 632.71479 | F5: ='Income Statement'!F15 -> 708.4789 | G5: ='Income Statement'!G15 -> 776.08554 | H5: ='Income Statement'!H15 -> 827.80415 | I5: ='Income Statement'!I15 -> 870.3404
A6: D&A | E6: ='Income Statement'!E19 -> 262.64711 | F6: ='Income Statement'!F19 -> 272.07158 | G6: ='Income Statement'!G19 -> 286.84767 | H6: ='Income Statement'!H19 -> 294.41639 | I6: ='Income Statement'!I19 -> 306.72992
A7: EBIT | E7: =E5-E6 -> 370.06768 | F7: =F5-F6 -> 436.40732 | G7: =G5-G6 -> 489.23787 | H7: =H5-H6 -> 533.38776 | I7: =I5-I6 -> 563.61048
A8: NOPAT = EBIT×(1−tax) | E8: =E7*(1-Assumptions!$B$9) -> 296.05414 | F8: =F7*(1-Assumptions!$B$9) -> 349.12586 | G8: =G7*(1-Assumptions!$B$9) -> 391.3903 | H8: =H7*(1-Assumptions!$B$9) -> 426.71021 | I8: =I7*(1-Assumptions!$B$9) -> 450.88838
A9: + D&A | E9: =E6 -> 262.64711 | F9: =F6 -> 272.07158 | G9: =G6 -> 286.84767 | H9: =H6 -> 294.41639 | I9: =I6 -> 306.72992
A10: − Capex | E10: =-'Income Statement'!E8*Assumptions!E64 -> -191.93443 | F10: =-'Income Statement'!F8*Assumptions!F64 -> -202.72 | G10: =-'Income Statement'!G8*Assumptions!G64 -> -213.72963 | H10: =-'Income Statement'!H8*Assumptions!H64 -> -223.75646 | I10: =-'Income Statement'!I8*Assumptions!I64 -> -233.11474
A11: − Increase in net WC | E11: =-Assumptions!E65 -> -22 | F11: =-Assumptions!F65 -> -24 | G11: =-Assumptions!G65 -> -18 | H11: =-Assumptions!H65 -> -16 | I11: =-Assumptions!I65 -> -15
A12: FCFF | E12: =E8+E9+E10+E11 -> 344.76682 | F12: =F8+F9+F10+F11 -> 394.47743 | G12: =G8+G9+G10+G11 -> 446.50833 | H12: =H8+H9+H10+H11 -> 481.37014 | I12: =I8+I9+I10+I11 -> 509.50356
A13: Discount factor | E13: =1/(1+Assumptions!$B$21)^1 -> 0.90438809 | F13: =1/(1+Assumptions!$B$21)^2 -> 0.81791782 | G13: =1/(1+Assumptions!$B$21)^3 -> 0.73971514 | H13: =1/(1+Assumptions!$B$21)^4 -> 0.66898956 | I13: =1/(1+Assumptions!$B$21)^5 -> 0.60502619
A14: PV of FCFF | E14: =E12*E13 -> 311.80301 | F14: =F12*F13 -> 322.65012 | G14: =G12*G13 -> 330.28897 | H14: =H12*H13 -> 322.0316 | I14: =I12*I13 -> 308.263
A16: Σ PV of explicit FCFF (FY26E–30E) | B16: =SUM(E14:I14) -> 1595.0367
A17: Terminal value (Gordon) | B17: =I12*(1+Assumptions!$B$22)/(Assumptions!$B$21-Assumptions!$B$22) -> 6260.1225
A18: PV of terminal value | B18: =B17/(1+Assumptions!$B$21)^5 -> 3787.5381
A19: Enterprise value | B19: =B16+B18 -> 5382.5748
A20: less: consolidated net debt | B20: =-Assumptions!$B$6 -> -1300
A21: less: minorities (est. value) | B21: =-Assumptions!$B$8 -> -260
A22: Equity value | B22: =B19+B20+B21 -> 3822.5748
A23: Fair value per share (AED) | B23: =B22/Assumptions!$B$5 -> 4.5991063
A24: % terminal of EV | B24: =B18/B19 -> 0.7036666

Sheet Income Statement
A1: Income statement (AED mn, consolidated)
A2: FY23–FY25 disclosed / estimated-to-balance (blue); FY26E–FY30E forecast (formulas). Source: ADX preliminary FY2025 results (5 Mar 2026).
B3: FY23 | C3: FY24 | D3: FY25 | E3: FY26E | F3: FY27E | G3: FY28E | H3: FY29E | I3: FY30E
A4: Water & Food | C4: 1082.2 | D4: 1240.3 | E4: =D4*(1+Assumptions!E53) -> 1389.136 | F4: =E4*(1+Assumptions!F53) -> 1486.3755 | G4: =F4*(1+Assumptions!G53) -> 1575.5581 | H4: =G4*(1+Assumptions!H53) -> 1654.336 | I4: =H4*(1+Assumptions!I53) -> 1728.7811
A5: Agri-Business | C5: 1332.2 | D5: 1223.2 | E5: =D5*(1+Assumptions!E54) -> 1247.664 | F5: =E5*(1+Assumptions!F54) -> 1278.8556 | G5: =F5*(1+Assumptions!G54) -> 1310.827 | H5: =G5*(1+Assumptions!H54) -> 1343.5977 | I5: =H5*(1+Assumptions!I54) -> 1377.1876
A6: Snacking | C6: 1491.8 | D6: 1386.5 | E6: =D6*(1+Assumptions!E55) -> 1358.77 | F6: =E6*(1+Assumptions!F55) -> 1440.2962 | G6: =F6*(1+Assumptions!G55) -> 1541.1169 | H6: =G6*(1+Assumptions!H55) -> 1633.584 | I6: =H6*(1+Assumptions!I55) -> 1715.2631
A7: Protein & Frozen | C7: 1008.5 | D7: 995.6 | E7: =D7*(1+Assumptions!E56) -> 1055.336 | F7: =E7*(1+Assumptions!F56) -> 1129.2095 | G7: =F7*(1+Assumptions!G56) -> 1196.9621 | H7: =G7*(1+Assumptions!H56) -> 1256.8102 | I7: =H7*(1+Assumptions!I56) -> 1313.3667
A8: Total revenue | B8: 4561.2 | C8: =SUM(C4:C7) -> 4914.7 | D8: =SUM(D4:D7) -> 4845.6 | E8: =SUM(E4:E7) -> 5050.906 | F8: =SUM(F4:F7) -> 5334.7368 | G8: =SUM(G4:G7) -> 5624.4641 | H8: =SUM(H4:H7) -> 5888.3278 | I8: =SUM(I4:I7) -> 6134.5985
A10: Water & Food EBITDA | C10: 172.5 | D10: 170.9 | E10: =E4*Assumptions!E57 -> 208.3704 | F10: =F4*Assumptions!F57 -> 225.92908 | G10: =G4*Assumptions!G57 -> 242.63594 | H10: =H4*Assumptions!H57 -> 256.42207 | I10: =I4*Assumptions!I57 -> 269.68985
A11: Agri-Business EBITDA | C11: 222.5 | D11: 222.2 | E11: =E5*Assumptions!E58 -> 227.07485 | F11: =F5*Assumptions!F58 -> 232.75172 | G11: =G5*Assumptions!G58 -> 238.57051 | H11: =H5*Assumptions!H58 -> 244.53477 | I11: =I5*Assumptions!I58 -> 250.64814
A12: Snacking EBITDA | C12: 183.3 | D12: 17 | E12: =E6*Assumptions!E59 -> 122.2893 | F12: =F6*Assumptions!F59 -> 151.2311 | G12: =G6*Assumptions!G59 -> 177.22845 | H12: =H6*Assumptions!H59 -> 196.03007 | I12: =I6*Assumptions!I59 -> 205.83158
A13: Protein & Frozen EBITDA | C13: 118 | D13: 72.7 | E13: =E7*Assumptions!E60 -> 94.98024 | F13: =F7*Assumptions!F60 -> 118.567 | G13: =G7*Assumptions!G60 -> 137.65064 | H13: =H7*Assumptions!H60 -> 150.81722 | I13: =I7*Assumptions!I60 -> 164.17083
A14: Corporate / other / eliminations | C14: =C15-SUM(C10:C13) -> -17.5 | D14: =D15-SUM(D10:D13) -> -19.4 | E14: =Assumptions!E61 -> -20 | F14: =Assumptions!F61 -> -20 | G14: =Assumptions!G61 -> -20 | H14: =Assumptions!H61 -> -20 | I14: =Assumptions!I61 -> -20
A15: Group EBITDA (reported) | B15: 689.3 | C15: 678.8 | D15: 463.4 | E15: =SUM(E10:E14) -> 632.71479 | F15: =SUM(F10:F14) -> 708.4789 | G15: =SUM(G10:G14) -> 776.08554 | H15: =SUM(H10:H14) -> 827.80415 | I15: =SUM(I10:I14) -> 870.3404
A16: EBITDA margin | B16: =B15/B8 -> 0.15112251 | C16: =C15/C8 -> 0.13811626 | D16: =D15/D8 -> 0.095633152 | E16: =E15/E8 -> 0.12526758 | F16: =F15/F8 -> 0.13280484 | G16: =G15/G8 -> 0.13798391 | H16: =H15/H8 -> 0.14058391 | I16: =I15/I8 -> 0.14187406
A17: One-off items (memo; Al Foah 92.0 + legacy receivables 47.1 + Timarat 4.4) | D17: 143.4
A18: Underlying EBITDA (memo) | B18: 689.3 | C18: 688.8 | D18: =D15+D17 -> 606.8 | E18: =E15 -> 632.71479 | F18: =F15 -> 708.4789 | G18: =G15 -> 776.08554 | H18: =H15 -> 827.80415 | I18: =I15 -> 870.3404
A19: D&A | B19: 240 | C19: 245 | D19: 250 | E19: =E8*Assumptions!E62 -> 262.64711 | F19: =F8*Assumptions!F62 -> 272.07158 | G19: =G8*Assumptions!G62 -> 286.84767 | H19: =H8*Assumptions!H62 -> 294.41639 | I19: =I8*Assumptions!I62 -> 306.72992
A20: EBIT | B20: =B15-B19 -> 449.3 | C20: =C15-C19 -> 433.8 | D20: =D15-D19 -> 213.4 | E20: =E15-E19 -> 370.06768 | F20: =F15-F19 -> 436.40732 | G20: =G15-G19 -> 489.23787 | H20: =H15-H19 -> 533.38776 | I20: =I15-I19 -> 563.61048
A21: Net finance cost | B21: 110.7 | C21: 62 | D21: 88.3 | E21: =Assumptions!E63 -> 60 | F21: =Assumptions!F63 -> 56 | G21: =Assumptions!G63 -> 52 | H21: =Assumptions!H63 -> 47 | I21: =Assumptions!I63 -> 42
A22: Profit before tax | B22: =B20-B21 -> 338.6 | C22: =C20-C21 -> 371.8 | D22: =D20-D21 -> 125.1 | E22: =E20-E21 -> 310.06768 | F22: =F20-F21 -> 380.40732 | G22: =G20-G21 -> 437.23787 | H22: =H20-H21 -> 486.38776 | I22: =I20-I21 -> 521.61048
A23: Tax | B23: 39 | C23: 50 | D23: 24.5 | E23: =MAX(0,E22)*Assumptions!$B$9 -> 62.013535 | F23: =MAX(0,F22)*Assumptions!$B$9 -> 76.081464 | G23: =MAX(0,G22)*Assumptions!$B$9 -> 87.447575 | H23: =MAX(0,H22)*Assumptions!$B$9 -> 97.277551 | I23: =MAX(0,I22)*Assumptions!$B$9 -> 104.3221
A24: Net profit (group) | B24: =B22-B23 -> 299.6 | C24: =C22-C23 -> 321.8 | D24: =D22-D23 -> 100.6 | E24: =E22-E23 -> 248.05414 | F24: =F22-F23 -> 304.32586 | G24: =G22-G23 -> 349.7903 | H24: =H22-H23 -> 389.11021 | I24: =I22-I23 -> 417.28838
A25: Minorities | B25: 25.3 | C25: 25.9 | D25: 15 | E25: =E24*Assumptions!E66 -> 32.247038 | F25: =F24*Assumptions!F66 -> 39.562361 | G25: =G24*Assumptions!G66 -> 45.472739 | H25: =H24*Assumptions!H66 -> 50.584327 | I25: =I24*Assumptions!I66 -> 54.24749
A26: Attributable net profit | B26: =B24-B25 -> 274.3 | C26: =C24-C25 -> 295.9 | D26: =D24-D25 -> 85.6 | E26: =E24-E25 -> 215.8071 | F26: =F24-F25 -> 264.76349 | G26: =G24-G25 -> 304.31756 | H26: =H24-H25 -> 338.52588 | I26: =I24-I25 -> 363.04089
A27: EPS (AED) | B27: =B26/Assumptions!$B$5 -> 0.33002228 | C27: =C26/Assumptions!$B$5 -> 0.35601018 | D27: =D26/Assumptions!$B$5 -> 0.10298909 | E27: =E26/Assumptions!$B$5 -> 0.25964693 | F27: =F26/Assumptions!$B$5 -> 0.3185485 | G27: =G26/Assumptions!$B$5 -> 0.36613772 | H27: =H26/Assumptions!$B$5 -> 0.40729524 | I27: =I26/Assumptions!$B$5 -> 0.43679032
A29: FY23 segment split not restated in the preliminary release; total-only shown. Blue historical D&A / finance / tax / minorities are estimated to balance to disclosed totals (EBITDA, net profit, EPS).

Sheet Balance Sheet
A1: Balance sheet (AED mn, consolidated)
A2: Historicals anchored to disclosed totals (assets, equity); working capital modeled off Assumptions; PP&E/goodwill is the balancing asset block.
B3: FY23 | C3: FY24 | D3: FY25 | E3: FY26E | F3: FY27E | G3: FY28E | H3: FY29E | I3: FY30E
A4: PP&E, goodwill & intangibles (plug) | B4: =B9-SUM(B5:B7) -> 4579.85 | C4: =C9-SUM(C5:C7) -> 4340.6875 | D4: =D9-SUM(D5:D7) -> 3968.2 | E4: =D4+'Income Statement'!E8*Assumptions!E64-'Income Statement'!E19 -> 3897.4873 | F4: =E4+'Income Statement'!F8*Assumptions!F64-'Income Statement'!F19 -> 3828.1357 | G4: =F4+'Income Statement'!G8*Assumptions!G64-'Income Statement'!G19 -> 3755.0177 | H4: =G4+'Income Statement'!H8*Assumptions!H64-'Income Statement'!H19 -> 3684.3578 | I4: =H4+'Income Statement'!I8*Assumptions!I64-'Income Statement'!I19 -> 3610.7426
A5: Inventory | B5: ='Income Statement'!B8*Assumptions!$B$42 -> 889.434 | C5: ='Income Statement'!C8*Assumptions!$B$42 -> 958.3665 | D5: ='Income Statement'!D8*Assumptions!$B$42 -> 944.892 | E5: ='Income Statement'!E8*Assumptions!$B$42 -> 984.92667 | F5: ='Income Statement'!F8*Assumptions!$B$42 -> 1040.2737 | G5: ='Income Statement'!G8*Assumptions!$B$42 -> 1096.7705 | H5: ='Income Statement'!H8*Assumptions!$B$42 -> 1148.2239 | I5: ='Income Statement'!I8*Assumptions!$B$42 -> 1196.2467
A6: Trade & other receivables | B6: ='Income Statement'!B8*Assumptions!$B$43 -> 821.016 | C6: ='Income Statement'!C8*Assumptions!$B$43 -> 884.646 | D6: ='Income Statement'!D8*Assumptions!$B$43 -> 872.208 | E6: ='Income Statement'!E8*Assumptions!$B$43 -> 909.16308 | F6: ='Income Statement'!F8*Assumptions!$B$43 -> 960.25263 | G6: ='Income Statement'!G8*Assumptions!$B$43 -> 1012.4035 | H6: ='Income Statement'!H8*Assumptions!$B$43 -> 1059.899 | I6: ='Income Statement'!I8*Assumptions!$B$43 -> 1104.2277
A7: Cash & equivalents | B7: 350 | C7: 420 | D7: 530.7 | E7: ='Cash Flow'!E14 -> 609.3724 | F7: ='Cash Flow'!F14 -> 717.35 | G7: ='Cash Flow'!G14 -> 855.1621 | H7: ='Cash Flow'!H14 -> 1005.1767 | I7: ='Cash Flow'!I14 -> 1158.065
A9: Total assets | B9: 6640.3 | C9: 6603.7 | D9: 6316 | E9: =SUM(E4:E7) -> 6400.9495 | F9: =SUM(F4:F7) -> 6546.0121 | G9: =SUM(G4:G7) -> 6719.3538 | H9: =SUM(H4:H7) -> 6897.6574 | I9: =SUM(I4:I7) -> 7069.282
A11: Shareholders’ equity | B11: 2909.8 | C11: 2824.6 | D11: 2628.8 | E11: =D11+'Income Statement'!E26-Assumptions!E68 -> 2642.6362 | F11: =E11+'Income Statement'!F26-Assumptions!F68 -> 2685.481 | G11: =F11+'Income Statement'!G26-Assumptions!G68 -> 2745.4387 | H11: =G11+'Income Statement'!H26-Assumptions!H68 -> 2815.5012 | I11: =H11+'Income Statement'!I26-Assumptions!I68 -> 2882.6506
A12: Minority interests | B12: 255 | C12: 265 | D12: 275 | E12: =D12+'Income Statement'!E25/2 -> 291.12352 | F12: =E12+'Income Statement'!F25/2 -> 310.9047 | G12: =F12+'Income Statement'!G25/2 -> 333.64107 | H12: =G12+'Income Statement'!H25/2 -> 358.93323 | I12: =H12+'Income Statement'!I25/2 -> 386.05698
A13: Borrowings & lease liabilities | B13: 1250 | C13: 1438 | D13: 1830.7 | E13: =D13 -> 1830.7 | F13: =D13 -> 1830.7 | G13: =D13 -> 1830.7 | H13: =D13 -> 1830.7 | I13: =D13 -> 1830.7
A14: Trade & other payables | B14: ='Income Statement'!B8*Assumptions!$B$44 -> 1026.27 | C14: ='Income Statement'!C8*Assumptions!$B$44 -> 1105.8075 | D14: ='Income Statement'!D8*Assumptions!$B$44 -> 1090.26 | E14: ='Income Statement'!E8*Assumptions!$B$44 -> 1136.4539 | F14: ='Income Statement'!F8*Assumptions!$B$44 -> 1200.3158 | G14: ='Income Statement'!G8*Assumptions!$B$44 -> 1265.5044 | H14: ='Income Statement'!H8*Assumptions!$B$44 -> 1324.8737 | I14: ='Income Statement'!I8*Assumptions!$B$44 -> 1380.2847
A15: Other liabilities (plug) | B15: =B9-B11-B12-B13-B14 -> 1199.23 | C15: =C9-C11-C12-C13-C14 -> 970.2925 | D15: =D9-D11-D12-D13-D14 -> 491.24 | E15: =E9-E11-E12-E13-E14 -> 500.0359 | F15: =F9-F11-F12-F13-F14 -> 518.61053 | G15: =G9-G11-G12-G13-G14 -> 544.06961 | H15: =H9-H11-H12-H13-H14 -> 567.64916 | I15: =I9-I11-I12-I13-I14 -> 589.58977
A16: Total equity & liabilities | B16: =SUM(B11:B15) -> 6640.3 | C16: =SUM(C11:C15) -> 6603.7 | D16: =SUM(D11:D15) -> 6316 | E16: =SUM(E11:E15) -> 6400.9495 | F16: =SUM(F11:F15) -> 6546.0121 | G16: =SUM(G11:G15) -> 6719.3538 | H16: =SUM(H11:H15) -> 6897.6574 | I16: =SUM(I11:I15) -> 7069.282
A18: Net debt | B18: =B13-B7 -> 900 | C18: =C13-C7 -> 1018 | D18: =D13-D7 -> 1300 | E18: =E13-E7 -> 1221.3276 | F18: =F13-F7 -> 1113.35 | G18: =G13-G7 -> 975.5379 | H18: =H13-H7 -> 825.52332 | I18: =I13-I7 -> 672.63503
A19: Net debt / EBITDA | B19: =B18/'Income Statement'!B15 -> 1.3056724 | C19: =C18/'Income Statement'!C15 -> 1.4997054 | D19: =D18/'Income Statement'!D15 -> 2.8053517 | E19: =E18/'Income Statement'!E15 -> 1.9302972 | F19: =F18/'Income Statement'!F15 -> 1.5714653 | G19: =G18/'Income Statement'!G15 -> 1.2569979 | H19: =H18/'Income Statement'!H15 -> 0.99724472 | I19: =I18/'Income Statement'!I15 -> 0.77284133

Sheet Cash Flow
A1: Cash flow (AED mn, forecast)
A2: Derived from the Income Statement and Assumptions. FY25 actual: operating cash flow AED 434.7mn; capex 143.5; free cash flow 317.8 (disclosed).
E3: FY26E | F3: FY27E | G3: FY28E | H3: FY29E | I3: FY30E
A4: Net profit (group) | E4: ='Income Statement'!E24 -> 248.05414 | F4: ='Income Statement'!F24 -> 304.32586 | G4: ='Income Statement'!G24 -> 349.7903 | H4: ='Income Statement'!H24 -> 389.11021 | I4: ='Income Statement'!I24 -> 417.28838
A5: + D&A | E5: ='Income Statement'!E19 -> 262.64711 | F5: ='Income Statement'!F19 -> 272.07158 | G5: ='Income Statement'!G19 -> 286.84767 | H5: ='Income Statement'!H19 -> 294.41639 | I5: ='Income Statement'!I19 -> 306.72992
A6: − Increase in net working capital | E6: =-Assumptions!E65 -> -22 | F6: =-Assumptions!F65 -> -24 | G6: =-Assumptions!G65 -> -18 | H6: =-Assumptions!H65 -> -16 | I6: =-Assumptions!I65 -> -15
A7: Operating cash flow | E7: =SUM(E4:E6) -> 488.70125 | F7: =SUM(F4:F6) -> 552.39743 | G7: =SUM(G4:G6) -> 618.63797 | H7: =SUM(H4:H6) -> 667.52659 | I7: =SUM(I4:I6) -> 709.01831
A8: − Capex | E8: =-'Income Statement'!E8*Assumptions!E64 -> -191.93443 | F8: =-'Income Statement'!F8*Assumptions!F64 -> -202.72 | G8: =-'Income Statement'!G8*Assumptions!G64 -> -213.72963 | H8: =-'Income Statement'!H8*Assumptions!H64 -> -223.75646 | I8: =-'Income Statement'!I8*Assumptions!I64 -> -233.11474
A9: Free cash flow | E9: =E7+E8 -> 296.76682 | F9: =F7+F8 -> 349.67743 | G9: =G7+G8 -> 404.90833 | H9: =H7+H8 -> 443.77014 | I9: =I7+I8 -> 475.90356
A10: − Dividends, common | E10: =-Assumptions!E68 -> -201.97091 | F10: =-Assumptions!F68 -> -221.91865 | G10: =-Assumptions!G68 -> -244.35986 | H10: =-Assumptions!H68 -> -268.46339 | I10: =-Assumptions!I68 -> -295.89154
A11: − Dividends to minorities | E11: =-'Income Statement'!E25/2 -> -16.123519 | F11: =-'Income Statement'!F25/2 -> -19.781181 | G11: =-'Income Statement'!G25/2 -> -22.736369 | H11: =-'Income Statement'!H25/2 -> -25.292163 | I11: =-'Income Statement'!I25/2 -> -27.123745
A12: Net change in cash | E12: =E9+E10+E11 -> 78.672398 | F12: =F9+F10+F11 -> 107.9776 | G12: =G9+G10+G11 -> 137.8121 | H12: =H9+H10+H11 -> 150.01459 | I12: =I9+I10+I11 -> 152.88828
A13: Opening cash | E13: ='Balance Sheet'!D7 -> 530.7 | F13: =E14 -> 609.3724 | G13: =F14 -> 717.35 | H13: =G14 -> 855.1621 | I13: =H14 -> 1005.1767
A14: Closing cash | E14: =E12+E13 -> 609.3724 | F14: =F12+F13 -> 717.35 | G14: =G12+G13 -> 855.1621 | H14: =H12+H13 -> 1005.1767 | I14: =I12+I13 -> 1158.065

Sheet Summary Financials
A1: Summary financials (AED mn)
A2: Every cell links to the statement sheets — nothing is re-keyed.
B3: FY23 | C3: FY24 | D3: FY25 | E3: FY26E | F3: FY27E | G3: FY28E | H3: FY29E | I3: FY30E
A4: Revenue | B4: ='Income Statement'!B8 -> 4561.2 | C4: ='Income Statement'!C8 -> 4914.7 | D4: ='Income Statement'!D8 -> 4845.6 | E4: ='Income Statement'!E8 -> 5050.906 | F4: ='Income Statement'!F8 -> 5334.7368 | G4: ='Income Statement'!G8 -> 5624.4641 | H4: ='Income Statement'!H8 -> 5888.3278 | I4: ='Income Statement'!I8 -> 6134.5985
A5: Group EBITDA (reported) | B5: ='Income Statement'!B15 -> 689.3 | C5: ='Income Statement'!C15 -> 678.8 | D5: ='Income Statement'!D15 -> 463.4 | E5: ='Income Statement'!E15 -> 632.71479 | F5: ='Income Statement'!F15 -> 708.4789 | G5: ='Income Statement'!G15 -> 776.08554 | H5: ='Income Statement'!H15 -> 827.80415 | I5: ='Income Statement'!I15 -> 870.3404
A6: Underlying EBITDA | B6: ='Income Statement'!B18 -> 689.3 | C6: ='Income Statement'!C18 -> 688.8 | D6: ='Income Statement'!D18 -> 606.8 | E6: ='Income Statement'!E18 -> 632.71479 | F6: ='Income Statement'!F18 -> 708.4789 | G6: ='Income Statement'!G18 -> 776.08554 | H6: ='Income Statement'!H18 -> 827.80415 | I6: ='Income Statement'!I18 -> 870.3404
A7: EBIT | B7: ='Income Statement'!B20 -> 449.3 | C7: ='Income Statement'!C20 -> 433.8 | D7: ='Income Statement'!D20 -> 213.4 | E7: ='Income Statement'!E20 -> 370.06768 | F7: ='Income Statement'!F20 -> 436.40732 | G7: ='Income Statement'!G20 -> 489.23787 | H7: ='Income Statement'!H20 -> 533.38776 | I7: ='Income Statement'!I20 -> 563.61048
A8: Net profit (group) | B8: ='Income Statement'!B24 -> 299.6 | C8: ='Income Statement'!C24 -> 321.8 | D8: ='Income Statement'!D24 -> 100.6 | E8: ='Income Statement'!E24 -> 248.05414 | F8: ='Income Statement'!F24 -> 304.32586 | G8: ='Income Statement'!G24 -> 349.7903 | H8: ='Income Statement'!H24 -> 389.11021 | I8: ='Income Statement'!I24 -> 417.28838
A9: Attributable net profit | B9: ='Income Statement'!B26 -> 274.3 | C9: ='Income Statement'!C26 -> 295.9 | D9: ='Income Statement'!D26 -> 85.6 | E9: ='Income Statement'!E26 -> 215.8071 | F9: ='Income Statement'!F26 -> 264.76349 | G9: ='Income Statement'!G26 -> 304.31756 | H9: ='Income Statement'!H26 -> 338.52588 | I9: ='Income Statement'!I26 -> 363.04089
A10: EPS (AED) | B10: ='Income Statement'!B27 -> 0.33002228 | C10: ='Income Statement'!C27 -> 0.35601018 | D10: ='Income Statement'!D27 -> 0.10298909 | E10: ='Income Statement'!E27 -> 0.25964693 | F10: ='Income Statement'!F27 -> 0.3185485 | G10: ='Income Statement'!G27 -> 0.36613772 | H10: ='Income Statement'!H27 -> 0.40729524 | I10: ='Income Statement'!I27 -> 0.43679032
A11: Total assets | B11: ='Balance Sheet'!B9 -> 6640.3 | C11: ='Balance Sheet'!C9 -> 6603.7 | D11: ='Balance Sheet'!D9 -> 6316 | E11: ='Balance Sheet'!E9 -> 6400.9495 | F11: ='Balance Sheet'!F9 -> 6546.0121 | G11: ='Balance Sheet'!G9 -> 6719.3538 | H11: ='Balance Sheet'!H9 -> 6897.6574 | I11: ='Balance Sheet'!I9 -> 7069.282
A12: Shareholders’ equity | B12: ='Balance Sheet'!B11 -> 2909.8 | C12: ='Balance Sheet'!C11 -> 2824.6 | D12: ='Balance Sheet'!D11 -> 2628.8 | E12: ='Balance Sheet'!E11 -> 2642.6362 | F12: ='Balance Sheet'!F11 -> 2685.481 | G12: ='Balance Sheet'!G11 -> 2745.4387 | H12: ='Balance Sheet'!H11 -> 2815.5012 | I12: ='Balance Sheet'!I11 -> 2882.6506
A13: Net debt | B13: ='Balance Sheet'!B18 -> 900 | C13: ='Balance Sheet'!C18 -> 1018 | D13: ='Balance Sheet'!D18 -> 1300 | E13: ='Balance Sheet'!E18 -> 1221.3276 | F13: ='Balance Sheet'!F18 -> 1113.35 | G13: ='Balance Sheet'!G18 -> 975.5379 | H13: ='Balance Sheet'!H18 -> 825.52332 | I13: ='Balance Sheet'!I18 -> 672.63503
A14: Free cash flow | C14: 495.6 | D14: 317.8 | E14: ='Cash Flow'!E9 -> 296.76682 | F14: ='Cash Flow'!F9 -> 349.67743 | G14: ='Cash Flow'!G9 -> 404.90833 | H14: ='Cash Flow'!H9 -> 443.77014 | I14: ='Cash Flow'!I9 -> 475.90356

Sheet Monte Carlo
A1: Monte Carlo — engine outputs (INDICATIVE ONLY · FAILED CALIBRATION TEST)
A2: 50,000 paths · 16 factors · seed 42 · YZ-HAR width, Student-t(5) shape, zero secular drift. Step 0 CRPS skill ≤ 0 — see the Testahil calibration ledger.
A3: Probability read (T+60)
A4: P(price above spot) | C4: 0.508
A5: P(≥ +10%) vs P(≤ −10%) | C5: 20.4% vs 17.9% · odds 1.14
A6: Median (AED) and % move | C6: 3.52 (+0.2%)
A7: 50% band (25th–75th) | C7: 3.26 – 3.79 (-7.2% to +8.0%)
A8: Touch(+10%) / touch(−10%) | C8: 37% / 32%
A10: Percentile map (AED/share)
A11: Horizon | B11: p5 | C11: p25 | D11: p50 | E11: p75 | F11: p95
A12: T+20 sessions | B12: 3.107 | C12: 3.359 | D12: 3.511 | E12: 3.669 | F12: 3.954
A13: T+60 sessions | B13: 2.845 | C13: 3.258 | D13: 3.518 | E13: 3.791 | F13: 4.308
A15: Inputs (from Assumptions): σ annualized | D15: =Assumptions!$B$47 -> 0.2616
A16: net 3-month factor drift | D16: =Assumptions!$B$48 -> 0.008
A17: horizon (sessions) | D17: =Assumptions!$B$49 -> 60
A19: Level-touch ladder
A20: Level | B20: T+20 | C20: T+60
A21: 4.4 | B21: 0.009 | C21: 0.068
A22: 4.2 | B22: 0.022 | C22: 0.125
A23: 4 | B23: 0.062 | C23: 0.239
A24: 3.7 | B24: 0.36 | C24: 0.594
A25: 3.4 | B25: 0.535 | C25: 0.715
A26: 3.2 | B26: 0.151 | C26: 0.376
A27: 3 | B27: 0.036 | C27: 0.171

Sheet Sensitivity
A1: DCF sensitivity — WACC × terminal growth
A2: Fair value (AED/share). Live: each cell rediscounts the DCF sheet FCFF at the row WACC / column g.
A4: WACC \ g | B4: 0.015 | C4: 0.0225 | D4: 0.03
A5: 0.096 | B5: =(DCF!$E$12/(1+$A5)^1+DCF!$F$12/(1+$A5)^2+DCF!$G$12/(1+$A5)^3+DCF!$H$12/(1+$A5)^4+DCF!$I$12/(1+$A5)^5+DCF!$I$12*(1+B$4)/($A5-B$4)/(1+$A5)^5-Assumptions!$B$6-Assumptions!$B$8)/Assumptions!$B$5 -> 4.9510107 | C5: =(DCF!$E$12/(1+$A5)^1+DCF!$F$12/(1+$A5)^2+DCF!$G$12/(1+$A5)^3+DCF!$H$12/(1+$A5)^4+DCF!$I$12/(1+$A5)^5+DCF!$I$12*(1+C$4)/($A5-C$4)/(1+$A5)^5-Assumptions!$B$6-Assumptions!$B$8)/Assumptions!$B$5 -> 5.4862049 | D5: =(DCF!$E$12/(1+$A5)^1+DCF!$F$12/(1+$A5)^2+DCF!$G$12/(1+$A5)^3+DCF!$H$12/(1+$A5)^4+DCF!$I$12/(1+$A5)^5+DCF!$I$12*(1+D$4)/($A5-D$4)/(1+$A5)^5-Assumptions!$B$6-Assumptions!$B$8)/Assumptions!$B$5 -> 6.1430341
A6: 0.101 | B6: =(DCF!$E$12/(1+$A6)^1+DCF!$F$12/(1+$A6)^2+DCF!$G$12/(1+$A6)^3+DCF!$H$12/(1+$A6)^4+DCF!$I$12/(1+$A6)^5+DCF!$I$12*(1+B$4)/($A6-B$4)/(1+$A6)^5-Assumptions!$B$6-Assumptions!$B$8)/Assumptions!$B$5 -> 4.5388729 | C6: =(DCF!$E$12/(1+$A6)^1+DCF!$F$12/(1+$A6)^2+DCF!$G$12/(1+$A6)^3+DCF!$H$12/(1+$A6)^4+DCF!$I$12/(1+$A6)^5+DCF!$I$12*(1+C$4)/($A6-C$4)/(1+$A6)^5-Assumptions!$B$6-Assumptions!$B$8)/Assumptions!$B$5 -> 5.002329 | D6: =(DCF!$E$12/(1+$A6)^1+DCF!$F$12/(1+$A6)^2+DCF!$G$12/(1+$A6)^3+DCF!$H$12/(1+$A6)^4+DCF!$I$12/(1+$A6)^5+DCF!$I$12*(1+D$4)/($A6-D$4)/(1+$A6)^5-Assumptions!$B$6-Assumptions!$B$8)/Assumptions!$B$5 -> 5.5636983
A7: 0.106 | B7: =(DCF!$E$12/(1+$A7)^1+DCF!$F$12/(1+$A7)^2+DCF!$G$12/(1+$A7)^3+DCF!$H$12/(1+$A7)^4+DCF!$I$12/(1+$A7)^5+DCF!$I$12*(1+B$4)/($A7-B$4)/(1+$A7)^5-Assumptions!$B$6-Assumptions!$B$8)/Assumptions!$B$5 -> 4.172256 | C7: =(DCF!$E$12/(1+$A7)^1+DCF!$F$12/(1+$A7)^2+DCF!$G$12/(1+$A7)^3+DCF!$H$12/(1+$A7)^4+DCF!$I$12/(1+$A7)^5+DCF!$I$12*(1+C$4)/($A7-C$4)/(1+$A7)^5-Assumptions!$B$6-Assumptions!$B$8)/Assumptions!$B$5 -> 4.5766247 | D7: =(DCF!$E$12/(1+$A7)^1+DCF!$F$12/(1+$A7)^2+DCF!$G$12/(1+$A7)^3+DCF!$H$12/(1+$A7)^4+DCF!$I$12/(1+$A7)^5+DCF!$I$12*(1+D$4)/($A7-D$4)/(1+$A7)^5-Assumptions!$B$6-Assumptions!$B$8)/Assumptions!$B$5 -> 5.0608031
A8: 0.111 | B8: =(DCF!$E$12/(1+$A8)^1+DCF!$F$12/(1+$A8)^2+DCF!$G$12/(1+$A8)^3+DCF!$H$12/(1+$A8)^4+DCF!$I$12/(1+$A8)^5+DCF!$I$12*(1+B$4)/($A8-B$4)/(1+$A8)^5-Assumptions!$B$6-Assumptions!$B$8)/Assumptions!$B$5 -> 3.8440425 | C8: =(DCF!$E$12/(1+$A8)^1+DCF!$F$12/(1+$A8)^2+DCF!$G$12/(1+$A8)^3+DCF!$H$12/(1+$A8)^4+DCF!$I$12/(1+$A8)^5+DCF!$I$12*(1+C$4)/($A8-C$4)/(1+$A8)^5-Assumptions!$B$6-Assumptions!$B$8)/Assumptions!$B$5 -> 4.199228 | D8: =(DCF!$E$12/(1+$A8)^1+DCF!$F$12/(1+$A8)^2+DCF!$G$12/(1+$A8)^3+DCF!$H$12/(1+$A8)^4+DCF!$I$12/(1+$A8)^5+DCF!$I$12*(1+D$4)/($A8-D$4)/(1+$A8)^5-Assumptions!$B$6-Assumptions!$B$8)/Assumptions!$B$5 -> 4.6201885
A9: 0.116 | B9: =(DCF!$E$12/(1+$A9)^1+DCF!$F$12/(1+$A9)^2+DCF!$G$12/(1+$A9)^3+DCF!$H$12/(1+$A9)^4+DCF!$I$12/(1+$A9)^5+DCF!$I$12*(1+B$4)/($A9-B$4)/(1+$A9)^5-Assumptions!$B$6-Assumptions!$B$8)/Assumptions!$B$5 -> 3.5485245 | C9: =(DCF!$E$12/(1+$A9)^1+DCF!$F$12/(1+$A9)^2+DCF!$G$12/(1+$A9)^3+DCF!$H$12/(1+$A9)^4+DCF!$I$12/(1+$A9)^5+DCF!$I$12*(1+C$4)/($A9-C$4)/(1+$A9)^5-Assumptions!$B$6-Assumptions!$B$8)/Assumptions!$B$5 -> 3.8623847 | D9: =(DCF!$E$12/(1+$A9)^1+DCF!$F$12/(1+$A9)^2+DCF!$G$12/(1+$A9)^3+DCF!$H$12/(1+$A9)^4+DCF!$I$12/(1+$A9)^5+DCF!$I$12*(1+D$4)/($A9-D$4)/(1+$A9)^5-Assumptions!$B$6-Assumptions!$B$8)/Assumptions!$B$5 -> 4.2309879
A11: Cells near spot (AED 3.51) show what the market is paying for; the base case (10.6% / 2.25%) reads AED 4.60.
A13: Crux in real units — green coffee ($/lb) × EGP/USD (AED/share, DCF post-shift):
A14: coffee \ EGP | B14: 48 | C14: 52 | D14: 58
A15: 2.8 | B15: 4.92 | C15: 4.87 | D15: 4.8
A16: 3.4 | B16: 4.65 | C16: 4.6 | D16: 4.53
A17: 4 | B17: 4.37 | C17: 4.33 | D17: 4.26

Sheet Per-Share & Ratios
A1: Per-share & ratios — the standing dashboard
A2: Identical panel across every Testahil study. Links to statements / Assumptions; spot-based multiples use the study-date price.
B3: FY23 | C3: FY24 | D3: FY25 | E3: FY26E | F3: FY27E | G3: FY28E | H3: FY29E | I3: FY30E
A4: EPS (AED) | B4: ='Income Statement'!B27 -> 0.33002228 | C4: ='Income Statement'!C27 -> 0.35601018 | D4: ='Income Statement'!D27 -> 0.10298909 | E4: ='Income Statement'!E27 -> 0.25964693 | F4: ='Income Statement'!F27 -> 0.3185485 | G4: ='Income Statement'!G27 -> 0.36613772 | H4: ='Income Statement'!H27 -> 0.40729524 | I4: ='Income Statement'!I27 -> 0.43679032
A5: DPS (fils) | C5: 19.5 | D5: 22.102 | E5: =Assumptions!E67 -> 24.3 | F5: =Assumptions!F67 -> 26.7 | G5: =Assumptions!G67 -> 29.4 | H5: =Assumptions!H67 -> 32.3 | I5: =Assumptions!I67 -> 35.6
A6: BVPS (AED) | B6: ='Balance Sheet'!B11/Assumptions!$B$5 -> 3.5009072 | C6: ='Balance Sheet'!C11/Assumptions!$B$5 -> 3.3983993 | D6: ='Balance Sheet'!D11/Assumptions!$B$5 -> 3.1628238 | E6: ='Balance Sheet'!E11/Assumptions!$B$5 -> 3.1794708 | F6: ='Balance Sheet'!F11/Assumptions!$B$5 -> 3.2310193 | G6: ='Balance Sheet'!G11/Assumptions!$B$5 -> 3.303157 | H6: ='Balance Sheet'!H11/Assumptions!$B$5 -> 3.3874522 | I6: ='Balance Sheet'!I11/Assumptions!$B$5 -> 3.4682425
A7: P/E (at spot) | B7: =Assumptions!$B$4/'Income Statement'!B27 -> 10.635645 | C7: =Assumptions!$B$4/'Income Statement'!C27 -> 9.8592685 | D7: =Assumptions!$B$4/'Income Statement'!D27 -> 34.08128 | E7: =Assumptions!$B$4/'Income Statement'!E27 -> 13.518357 | F7: =Assumptions!$B$4/'Income Statement'!F27 -> 11.01873 | G7: =Assumptions!$B$4/'Income Statement'!G27 -> 9.5865568 | H7: =Assumptions!$B$4/'Income Statement'!H27 -> 8.6178273 | I7: =Assumptions!$B$4/'Income Statement'!I27 -> 8.0358924
A8: P/B (at spot) | B8: =Assumptions!$B$4/('Balance Sheet'!B11/Assumptions!$B$5) -> 1.0025973 | C8: =Assumptions!$B$4/('Balance Sheet'!C11/Assumptions!$B$5) -> 1.0328392 | D8: =Assumptions!$B$4/('Balance Sheet'!D11/Assumptions!$B$5) -> 1.1097678 | E8: =Assumptions!$B$4/('Balance Sheet'!E11/Assumptions!$B$5) -> 1.1039573 | F8: =Assumptions!$B$4/('Balance Sheet'!F11/Assumptions!$B$5) -> 1.0863445 | G8: =Assumptions!$B$4/('Balance Sheet'!G11/Assumptions!$B$5) -> 1.0626198 | H8: =Assumptions!$B$4/('Balance Sheet'!H11/Assumptions!$B$5) -> 1.036177 | I8: =Assumptions!$B$4/('Balance Sheet'!I11/Assumptions!$B$5) -> 1.01204
A9: Dividend yield (at spot) | C9: =C5/100/Assumptions!$B$4 -> 0.055555556 | D9: =D5/100/Assumptions!$B$4 -> 0.062968661 | E9: =E5/100/Assumptions!$B$4 -> 0.069230769 | F9: =F5/100/Assumptions!$B$4 -> 0.076068376 | G9: =G5/100/Assumptions!$B$4 -> 0.083760684 | H9: =H5/100/Assumptions!$B$4 -> 0.092022792 | I9: =I5/100/Assumptions!$B$4 -> 0.1014245
A10: FCF yield (at spot) | D10: =317.8/(Assumptions!$B$4*Assumptions!$B$5) -> 0.1089342 | E10: ='Cash Flow'!E9/(Assumptions!$B$4*Assumptions!$B$5) -> 0.10172453 | F10: ='Cash Flow'!F9/(Assumptions!$B$4*Assumptions!$B$5) -> 0.11986101 | G10: ='Cash Flow'!G9/(Assumptions!$B$4*Assumptions!$B$5) -> 0.13879284 | H10: ='Cash Flow'!H9/(Assumptions!$B$4*Assumptions!$B$5) -> 0.15211373 | I10: ='Cash Flow'!I9/(Assumptions!$B$4*Assumptions!$B$5) -> 0.16312829
A11: EV/EBITDA (at spot) | B11: =(Assumptions!$B$4*Assumptions!$B$5+'Balance Sheet'!B18)/'Income Statement'!B15 -> 5.5380205 | C11: =(Assumptions!$B$4*Assumptions!$B$5+'Balance Sheet'!C18)/'Income Statement'!C15 -> 5.7975214 | D11: =(Assumptions!$B$4*Assumptions!$B$5+'Balance Sheet'!D18)/'Income Statement'!D15 -> 9.1009011 | E11: =(Assumptions!$B$4*Assumptions!$B$5+'Balance Sheet'!E18)/'Income Statement'!E15 -> 6.5411545 | F11: =(Assumptions!$B$4*Assumptions!$B$5+'Balance Sheet'!F18)/'Income Statement'!F15 -> 5.6892415 | G11: =(Assumptions!$B$4*Assumptions!$B$5+'Balance Sheet'!G18)/'Income Statement'!G15 -> 5.0160649 | H11: =(Assumptions!$B$4*Assumptions!$B$5+'Balance Sheet'!H18)/'Income Statement'!H15 -> 4.521457 | I11: =(Assumptions!$B$4*Assumptions!$B$5+'Balance Sheet'!I18)/'Income Statement'!I15 -> 4.1248144
A12: EBITDA margin | B12: ='Income Statement'!B15/'Income Statement'!B8 -> 0.15112251 | C12: ='Income Statement'!C15/'Income Statement'!C8 -> 0.13811626 | D12: ='Income Statement'!D15/'Income Statement'!D8 -> 0.095633152 | E12: ='Income Statement'!E15/'Income Statement'!E8 -> 0.12526758 | F12: ='Income Statement'!F15/'Income Statement'!F8 -> 0.13280484 | G12: ='Income Statement'!G15/'Income Statement'!G8 -> 0.13798391 | H12: ='Income Statement'!H15/'Income Statement'!H8 -> 0.14058391 | I12: ='Income Statement'!I15/'Income Statement'!I8 -> 0.14187406
A13: EBIT margin | B13: ='Income Statement'!B20/'Income Statement'!B8 -> 0.098504779 | C13: ='Income Statement'!C20/'Income Statement'!C8 -> 0.088265815 | D13: ='Income Statement'!D20/'Income Statement'!D8 -> 0.044039954 | E13: ='Income Statement'!E20/'Income Statement'!E8 -> 0.073267583 | F13: ='Income Statement'!F20/'Income Statement'!F8 -> 0.081804845 | G13: ='Income Statement'!G20/'Income Statement'!G8 -> 0.086983909 | H13: ='Income Statement'!H20/'Income Statement'!H8 -> 0.090583911 | I13: ='Income Statement'!I20/'Income Statement'!I8 -> 0.091874061
A14: Net margin (group) | B14: ='Income Statement'!B24/'Income Statement'!B8 -> 0.065684469 | C14: ='Income Statement'!C24/'Income Statement'!C8 -> 0.065477038 | D14: ='Income Statement'!D24/'Income Statement'!D8 -> 0.020761103 | E14: ='Income Statement'!E24/'Income Statement'!E8 -> 0.049110821 | F14: ='Income Statement'!F24/'Income Statement'!F8 -> 0.057046086 | G14: ='Income Statement'!G24/'Income Statement'!G8 -> 0.062190867 | H14: ='Income Statement'!H24/'Income Statement'!H8 -> 0.066081615 | I14: ='Income Statement'!I24/'Income Statement'!I8 -> 0.068022118
A15: Effective tax rate | B15: ='Income Statement'!B23/'Income Statement'!B22 -> 0.11518015 | C15: ='Income Statement'!C23/'Income Statement'!C22 -> 0.1344809 | D15: ='Income Statement'!D23/'Income Statement'!D22 -> 0.19584333 | E15: ='Income Statement'!E23/'Income Statement'!E22 -> 0.2 | F15: ='Income Statement'!F23/'Income Statement'!F22 -> 0.2 | G15: ='Income Statement'!G23/'Income Statement'!G22 -> 0.2 | H15: ='Income Statement'!H23/'Income Statement'!H22 -> 0.2 | I15: ='Income Statement'!I23/'Income Statement'!I22 -> 0.2
A16: ROAE (attributable) | C16: ='Income Statement'!C26/(('Balance Sheet'!C11+'Balance Sheet'!B11)/2) -> 0.10320173 | D16: ='Income Statement'!D26/(('Balance Sheet'!D11+'Balance Sheet'!C11)/2) -> 0.031393259 | E16: ='Income Statement'!E26/(('Balance Sheet'!E11+'Balance Sheet'!D11)/2) -> 0.081877915 | F16: ='Income Statement'!F26/(('Balance Sheet'!F11+'Balance Sheet'!E11)/2) -> 0.099383509 | G16: ='Income Statement'!G26/(('Balance Sheet'!G11+'Balance Sheet'!F11)/2) -> 0.11206852 | H16: ='Income Statement'!H26/(('Balance Sheet'!H11+'Balance Sheet'!G11)/2) -> 0.12175132 | I16: ='Income Statement'!I26/(('Balance Sheet'!I11+'Balance Sheet'!H11)/2) -> 0.12742409
A17: ROAIC (NOPAT / avg equity+ND) | B17: ='Income Statement'!B20*(1-Assumptions!$B$9)/('Balance Sheet'!B11+'Balance Sheet'!B12+'Balance Sheet'!B18) -> 0.088427475 | C17: ='Income Statement'!C20*(1-Assumptions!$B$9)/('Balance Sheet'!C11+'Balance Sheet'!C12+'Balance Sheet'!C18) -> 0.084487292 | D17: ='Income Statement'!D20*(1-Assumptions!$B$9)/('Balance Sheet'!D11+'Balance Sheet'!D12+'Balance Sheet'!D18) -> 0.040610876 | E17: ='Income Statement'!E20*(1-Assumptions!$B$9)/('Balance Sheet'!E11+'Balance Sheet'!E12+'Balance Sheet'!E18) -> 0.071251003 | F17: ='Income Statement'!F20*(1-Assumptions!$B$9)/('Balance Sheet'!F11+'Balance Sheet'!F12+'Balance Sheet'!F18) -> 0.084950926 | G17: ='Income Statement'!G20*(1-Assumptions!$B$9)/('Balance Sheet'!G11+'Balance Sheet'!G12+'Balance Sheet'!G18) -> 0.096529519 | H17: ='Income Statement'!H20*(1-Assumptions!$B$9)/('Balance Sheet'!H11+'Balance Sheet'!H12+'Balance Sheet'!H18) -> 0.10667868 | I17: ='Income Statement'!I20*(1-Assumptions!$B$9)/('Balance Sheet'!I11+'Balance Sheet'!I12+'Balance Sheet'!I18) -> 0.11439969
A18: Net debt / EBITDA | B18: ='Balance Sheet'!B18/'Income Statement'!B15 -> 1.3056724 | C18: ='Balance Sheet'!C18/'Income Statement'!C15 -> 1.4997054 | D18: ='Balance Sheet'!D18/'Income Statement'!D15 -> 2.8053517 | E18: ='Balance Sheet'!E18/'Income Statement'!E15 -> 1.9302972 | F18: ='Balance Sheet'!F18/'Income Statement'!F15 -> 1.5714653 | G18: ='Balance Sheet'!G18/'Income Statement'!G15 -> 1.2569979 | H18: ='Balance Sheet'!H18/'Income Statement'!H15 -> 0.99724472 | I18: ='Balance Sheet'!I18/'Income Statement'!I15 -> 0.77284133
A19: Payout ratio (DPS/EPS) | C19: =C5/100/'Income Statement'!C27 -> 0.54773714 | D19: =D5/100/'Income Statement'!D27 -> 2.1460526 | E19: =E5/100/'Income Statement'!E27 -> 0.93588629 | F19: =F5/100/'Income Statement'!F27 -> 0.83817693 | G19: =G5/100/'Income Statement'!G27 -> 0.80297655 | H19: =H5/100/'Income Statement'!H27 -> 0.79303653 | I19: =I5/100/'Income Statement'!I27 -> 0.81503638
A20: Revenue YoY | C20: ='Income Statement'!C8/'Income Statement'!B8-1 -> 0.077501535 | D20: ='Income Statement'!D8/'Income Statement'!C8-1 -> -0.014059861 | E20: ='Income Statement'!E8/'Income Statement'!D8-1 -> 0.042369572 | F20: ='Income Statement'!F8/'Income Statement'!E8-1 -> 0.056194045 | G20: ='Income Statement'!G8/'Income Statement'!F8-1 -> 0.054309563 | H20: ='Income Statement'!H8/'Income Statement'!G8-1 -> 0.046913572 | I20: ='Income Statement'!I8/'Income Statement'!H8-1 -> 0.041823541

Sheet Peer & Sector
A1: Peer set & sector
A2: GCC/MENA food & beverage staples. Ranges are indicative context (preparer’s judgment from public data), not a comp model.
A3: Peer | B3: What it is | C3: Typical valuation (indicative)
A4: Almarai (Tadawul: 2280) | B4: GCC dairy & food champion, KSA | C4: EV/EBITDA ~9–11×; P/E ~16–20×
A5: Savola Group (Tadawul: 2050) | B5: KSA food holdco (retail, oils, sugar) | C5: SOTP; holdco discount
A6: Americana Restaurants (ADX/Tadawul) | B6: MENA QSR platform | C6: P/E ~14–18×; growth premium
A7: Juhayna (EGX: JUFO) | B7: Egypt dairy & juice | C7: EV/EBITDA ~5–7× (EGP risk)
A8: NADEC (Tadawul: 6010) | B8: KSA dairy & agri | C8: EV/EBITDA ~7–9×
A9: Agthia (ADX: AGTHIA) — at spot | B9: UAE multi-category F&B (this study) | C9: EV/underlying EBITDA ~7.0×; yield ~6.3%
A11: Principal sector risks: input-commodity cycles (wheat, coffee, resin), EGP/JOD translation, regulated flour & feed margins, water-category price competition, regional geopolitics/logistics, and Pillar-II tax.
