Workbook

Sheet READ FIRST
A1: Testahil — Aldar Properties PJSC (ADX: ALDAR)
A2: Companion model · Independent Valuation Study · Educational analysis · Not investment advice
A4: What this workbook is. A transparent companion to the Aldar valuation study. Every blue cell is an input; every
A5: black cell is a formula; green cells link across sheets. All inputs live on the Assumptions sheet — change one
A6: (the recurring-asset GAV, a development-EBITDA margin, the discount rate) and the whole model reprices.
A8: What it is not. It is not investment advice, a recommendation, or a price target. Values are model outputs shown
A9: as ranges. The preparer is not licensed by any securities regulator and may hold a position in the security.
A11: Method. Mixed real-estate name valued SPLIT-THE-LEGS: Aldar Development (going-concern DCF, finite horizon, NO
A12: perpetual terminal — split-NAV discipline) + Aldar Investment (recurring platform marked at cap-rate GAV, the
A13: only perpetually-capitalised leg). A consolidated FCFF DCF and relative multiples cross-check. International name
A14: → zero secular drift in the Monte Carlo (§3 / Monte Carlo sheet).
A16: Currency. AED bn unless stated; per-share in AED. Spot AED 8.30 (3 Jul 2026); ~7.854bn shares; mkt cap ~AED 65.2bn.
... A21: Income Statement · Balance Sheet · Cash Flow · Summary Financials · Monte Carlo · Sensitivity · Per-Share & Ratios · Peer & Sector.

Sheet Summary
A1: Valuation summary — Aldar Properties (ADX: ALDAR)
A2: Four-lens fair value vs spot. Base links live; bear/bull are scenario outputs (study §1.5).
A3: Lens | B3: Bear | C3: Base | D3: Bull | E3: Weight
A4: SOTP / RNAV (risk-adjusted) | B4: 7.24 | C4: =SOTP!D9 -> 10.142433 | D4: 11.29 | E4: =Assumptions!$B$49 -> 0.4
A5: Consolidated DCF (FCFF) | B5: 8.14 | C5: =DCF!B24 -> 9.8069643 | D5: 11.62 | E5: =Assumptions!$B$50 -> 0.25
A6: Relative multiples | B6: 6.62 | C6: ='Relative & Normalized'!E9 -> 9.4525 | D6: 12.13 | E6: =Assumptions!$B$51 -> 0.15
A7: SOTP — full execution | B7: 10.14 | C7: 11.29 | D7: 12.64 | E7: =Assumptions!$B$52 -> 0.2
A8: Weighted central | B8: =SUMPRODUCT(B4:B7,E4:E7) -> 7.952 | C8: =SUMPRODUCT(C4:C7,E4:E7) -> 10.184589 | D8: =SUMPRODUCT(D4:D7,E4:E7) -> 11.7685
A10: Spot price (AED) | C10: =Assumptions!$B$4 -> 8.3
A11: Upside to central base | C11: =C8/C10-1 -> 0.22705894
A13: Read: modestly undervalued vs a split-legs RNAV; the swing is how much the development franchise is worth beyond current backlog.

Sheet Fundamental Valuation
A1: Fundamental valuation — football-field data
A2: Bear/base/bull per lens (links to Summary).
A3: Lens | B3: Bear | C3: Base | D3: Bull
A4: =Summary!A4 -> SOTP / RNAV (risk-adjusted) | B4: =Summary!B4 -> 7.24 | C4: =Summary!C4 -> 10.142433 | D4: =Summary!D4 -> 11.29
A5: =Summary!A5 -> Consolidated DCF (FCFF) | B5: =Summary!B5 -> 8.14 | C5: =Summary!C5 -> 9.8069643 | D5: =Summary!D5 -> 11.62
A6: =Summary!A6 -> Relative multiples | B6: =Summary!B6 -> 6.62 | C6: =Summary!C6 -> 9.4525 | D6: =Summary!D6 -> 12.13
A7: =Summary!A7 -> SOTP — full execution | B7: =Summary!B7 -> 10.14 | C7: =Summary!C7 -> 11.29 | D7: =Summary!D7 -> 12.64
A8: Weighted central | B8: =Summary!B8 -> 7.952 | C8: =Summary!C8 -> 10.184589 | D8: =Summary!D8 -> 11.7685
A9: Spot | C9: =Assumptions!$B$4 -> 8.3

Sheet Assumptions
A1: Assumptions — the single input layer
A2: All blue cells are inputs. Every other sheet links here.
A3: ANCHORS
A4: Spot price (AED/share) | B4: 8.3
A5: Shares outstanding (bn) | B5: 7.854
A6: Net debt (AED bn, incl. hybrids) | B6: 5.5
A7: Non-controlling interests (AED bn) | B7: 3
A8: COST OF CAPITAL (Ke = rf + ERP)
A9: Risk-free rate (AD 10-yr) | B9: 0.048
A10: Equity risk premium | B10: 0.044
A11: Beta | B11: 1
A12: Cost of equity (Ke) | B12: =B9+B11*B10 -> 0.092
A13: After-tax cost of debt (Kd) | B13: 0.049
A14: Group WACC | B14: 0.085
A15: Development WACC | B15: 0.09
A16: Terminal growth (consolidated) | B16: 0.025
A17: Effective tax rate (DMTT) | B17: 0.12
A18: ALDAR INVESTMENT (recurring — cap-rate leg)
A19: Recurring-asset GAV (AED bn) | B19: 52
A20: Recurring adj EBITDA (AED bn) | B20: 3.2
A21: ALDAR DEVELOPMENT (finite DCF leg — 10-yr EBITDA, AED bn)
A22: Dev EBITDA yr1 | B22: 7.6
A23: Dev EBITDA yr2 | B23: 8.3
A24: Dev EBITDA yr3 | B24: 8.9
A25: Dev EBITDA yr4 | B25: 9.2
A26: Dev EBITDA yr5 | B26: 9.2
A27: Dev EBITDA yr6 | B27: 8.8
A28: Dev EBITDA yr7 | B28: 8.3
A29: Dev EBITDA yr8 | B29: 7.6
A30: Dev EBITDA yr9 | B30: 6.8
A31: Dev EBITDA yr10 | B31: 6
A32: Dev D&A (% of EBITDA) | B32: 0.035
A33: Dev land-replenishment tail (AED bn PV) | B33: 5
A34: CONSOLIDATED FORECAST (AED bn)
A35: Group revenue 2026e | B35: 37
A36: Group revenue 2027e | B36: 41
A37: Group revenue 2028e | B37: 45
A38: Group revenue 2029e | B38: 48
A39: Group revenue 2030e | B39: 50.5
A40: Group EBITDA margin 2026e | B40: 0.315
...

Sheet SOTP
A1: Sum-of-the-parts / RNAV (primary lens)
A2: Split the legs: development = finite DCF (no perpetual terminal); investment = cap-rate GAV. Links to Assumptions + DCF.
A3: Component | B3: Basis | C3: Value (AED bn) | D3: AED/share
A4: Aldar Investment (recurring) | B4: Recurring-asset GAV (cap-rate) | C4: =Assumptions!$B$19 -> 52 | D4: =C4/Assumptions!$B$5 -> 6.6208302
A5: Aldar Development (finite DCF) | B5: 10-yr FCFF + land tail (no perpetual g) | C5: =DCF!B32 -> 36.158667 | D5: =C5/Assumptions!$B$5 -> 4.6038538
A6: Gross asset value (GAV) | C6: =C4+C5 -> 88.158667 | D6: =C6/Assumptions!$B$5 -> 11.224684
A7: less: net debt (incl. hybrids) | C7: =-Assumptions!$B$6 -> -5.5 | D7: =C7/Assumptions!$B$5 -> -0.70028011
A8: less: non-controlling interests | C8: =-Assumptions!$B$7 -> -3 | D8: =C8/Assumptions!$B$5 -> -0.38197097
A9: SOTP equity value (risk-adjusted) | C9: =C6+C7+C8 -> 79.658667 | D9: =C9/Assumptions!$B$5 -> 10.142433
A10: vs spot | D10: =D9/Assumptions!$B$4-1 -> 0.22197986
A12: Memo — implied recurring yield | D12: =Assumptions!$B$20/Assumptions!$B$19 -> 0.061538462
A13: Memo — implied recurring EV/EBITDA | D13: =Assumptions!$B$19/Assumptions!$B$20 -> 16.25

Sheet Segments
A1: Segment view — Development vs Investment
A2: Links to Income Statement.
A3: AED bn | B3: FY2023a | C3: FY2024a | D3: FY2025a | E3: 2026e | F3: 2027e | G3: 2028e | H3: 2029e | I3: 2030e
A4: Aldar Development revenue | B4: ='Income Statement'!B4 -> 8.71 | C4: ='Income Statement'!C4 -> 15.7 | D4: ='Income Statement'!D4 -> 24.8 | E4: ='Income Statement'!E4 -> 27.01 | F4: ='Income Statement'!F4 -> 29.93 | G4: ='Income Statement'!G4 -> 32.85 | H4: ='Income Statement'!H4 -> 35.04 | I4: ='Income Statement'!I4 -> 36.865
A5: Aldar Investment revenue | B5: ='Income Statement'!B5 -> 5.8 | C5: ='Income Statement'!C5 -> 7 | D5: ='Income Statement'!D5 -> 9 | E5: ='Income Statement'!E5 -> 9.99 | F5: ='Income Statement'!F5 -> 11.07 | G5: ='Income Statement'!G5 -> 12.15 | H5: ='Income Statement'!H5 -> 12.96 | I5: ='Income Statement'!I5 -> 13.635
A6: Group revenue | B6: ='Income Statement'!B6 -> 14.2 | C6: ='Income Statement'!C6 -> 23 | D6: ='Income Statement'!D6 -> 33.8 | E6: ='Income Statement'!E6 -> 37 | F6: ='Income Statement'!F6 -> 41 | G6: ='Income Statement'!G6 -> 45 | H6: ='Income Statement'!H6 -> 48 | I6: ='Income Statement'!I6 -> 50.5
A8: Aldar Development EBITDA (est.) | B8: 2.47 | C8: 4.3 | D8: 7.2 | E8: =E4*0.28 -> 7.5628 | F8: =F4*0.28 -> 8.3804 | G8: =G4*0.28 -> 9.198 | H8: =H4*0.28 -> 9.8112 | I8: =I4*0.28 -> 10.3222
A9: Aldar Investment adj EBITDA (est.) | B9: 2.25 | C9: 2.7 | D9: 3.2 | E9: =E5*0.42 -> 4.1958 | F9: =F5*0.42 -> 4.6494 | G9: =G5*0.42 -> 5.103 | H9: =H5*0.42 -> 5.4432 | I9: =I5*0.42 -> 5.7267
A10: Development backlog (AED bn) | B10: 36.8 | C10: 54.6 | D10: 71.7
A11: Recurring-asset GAV (AED bn) | B11: 33 | C11: 42 | D11: 49

Sheet Relative & Normalized
A1: Relative multiples & discount-to-NAV
A2: Links to Assumptions / SOTP.
A3: Lens | B3: Aldar now | C3: Fair low | D3: Fair high | E3: Implied AED/sh
A4: P/E (FY25 EPS 0.96) | B4: 8.65 | C4: 8.64 | D4: 11.52 | E4: =AVERAGE(C4:D4) -> 10.08
A5: P/B (BVPS ~5.1) | B5: 1.63 | C5: 6.62 | D5: 9.17 | E5: =AVERAGE(C5:D5) -> 7.895
A6: EV/EBITDA (FY25 11.2) | B6: 6.31 | C6: 9.28 | D6: 12.13 | E6: =AVERAGE(C6:D6) -> 10.705
A7: Discount to NAV | B7: 0.18 | C7: 8.62 | D7: 9.64 | E7: =AVERAGE(C7:D7) -> 9.13
A9: Relative blended midpoint | E9: =AVERAGE(E4:E7) -> 9.4525
A11: Property-cycle framing replaces 'normalized earnings' for developers (see study §1.4).

Sheet DCF
A1: Going-concern DCF — consolidated FCFF cross-check (exit multiple, not a perpetuity) + development-leg DCF (for SOTP)
A2: Waterfall: Revenue→EBITDA→D&A→EBIT→NOPAT→+D&A→−Capex→−Land investment→−ΔWC→FCFF→DF→PV. Terminal = exit EV/EBITDA multiple anchored to Aldar's own ~6.6x; Gordon perpetuity disclosed but NOT used (device A-7).
A3: CONSOLIDATED FCFF (AED bn) | E3: 2026e | F3: 2027e | G3: 2028e | H3: 2029e | I3: 2030e
A4: Revenue | E4: =Assumptions!$B$35 -> 37 | F4: =Assumptions!$B$36 -> 41 | G4: =Assumptions!$B$37 -> 45 | H4: =Assumptions!$B$38 -> 48 | I4: =Assumptions!$B$39 -> 50.5
A5: EBITDA | E5: =E4*Assumptions!$B$40 -> 11.655 | F5: =F4*Assumptions!$B$41 -> 12.71 | G5: =G4*Assumptions!$B$42 -> 13.725 | H5: =H4*Assumptions!$B$43 -> 14.544 | I5: =I4*Assumptions!$B$44 -> 15.251
A6: D&A | E6: =-E4*Assumptions!$B$45 -> -0.74 | F6: =-F4*Assumptions!$B$45 -> -0.82 | G6: =-G4*Assumptions!$B$45 -> -0.9 | H6: =-H4*Assumptions!$B$45 -> -0.96 | I6: =-I4*Assumptions!$B$45 -> -1.01
A7: EBIT | E7: =E5+E6 -> 10.915 | F7: =F5+F6 -> 11.89 | G7: =G5+G6 -> 12.825 | H7: =H5+H6 -> 13.584 | I7: =I5+I6 -> 14.241
A8: NOPAT = EBIT×(1−tax) | E8: =E7*(1-Assumptions!$B$17) -> 9.6052 | F8: =F7*(1-Assumptions!$B$17) -> 10.4632 | G8: =G7*(1-Assumptions!$B$17) -> 11.286 | H8: =H7*(1-Assumptions!$B$17) -> 11.95392 | I8: =I7*(1-Assumptions!$B$17) -> 12.53208
A9: + D&A | E9: =-E6 -> 0.74 | F9: =-F6 -> 0.82 | G9: =-G6 -> 0.9 | H9: =-H6 -> 0.96 | I9: =-I6 -> 1.01
A10: − Capex | E10: =-Assumptions!$B$46 -> -0.9 | F10: =-Assumptions!$B$46 -> -0.9 | G10: =-Assumptions!$B$46 -> -0.9 | H10: =-Assumptions!$B$46 -> -0.9 | I10: =-Assumptions!$B$46 -> -0.9
A11: − Land investment | E11: -3.6 | F11: -3.6 | G11: -3.7 | H11: -3.7 | I11: -3.7
A12: − Δ working capital | E12: -1.5 | F12: -1.2 | G12: -1 | H12: -0.9 | I12: -0.8
A13: Free cash flow to firm | E13: =E8+E9+E10+E11+E12 -> 4.3452 | F13: =F8+F9+F10+F11+F12 -> 5.5832 | G13: =G8+G9+G10+G11+G12 -> 6.586 | H13: =H8+H9+H10+H11+H12 -> 7.41392 | I13: =I8+I9+I10+I11+I12 -> 8.14208
A14: Discount factor @ WACC | E14: =1/(1+Assumptions!$B$14)^1 -> 0.92165899 | F14: =1/(1+Assumptions!$B$14)^2 -> 0.84945529 | G14: =1/(1+Assumptions!$B$14)^3 -> 0.7829081 | H14: =1/(1+Assumptions!$B$14)^4 -> 0.72157428 | I14: =1/(1+Assumptions!$B$14)^5 -> 0.66504542
A15: PV of FCFF | E15: =E13*E14 -> 4.0047926 | F15: =F13*F14 -> 4.7426788 | G15: =G13*G14 -> 5.1562327 | H15: =H13*H14 -> 5.349694 | I15: =I13*I14 -> 5.414853
A17: Σ PV of explicit FCFF (2026e–2030e) | B17: =SUM(E15:I15) -> 24.668251
A18: Terminal value (exit EV/EBITDA ×) | B18: =I5*Assumptions!$B$47 -> 91.506
A19: PV of terminal value | B19: =B18*I14 -> 60.855647
A20: Enterprise value | B20: =B17+B19 -> 85.523898
A21: less: net debt (incl. hybrids) | B21: =-Assumptions!$B$6 -> -5.5
A22: less: non-controlling interests | B22: =-Assumptions!$B$7 -> -3
A23: Equity value | B23: =B20+B21+B22 -> 77.023898
A24: Fair value per share (AED) — consolidated DCF | B24: =B23/Assumptions!$B$5 -> 9.8069643
A25: vs spot | B25: =B24/Assumptions!$B$4-1 -> 0.18156196
A26: % terminal of EV (device A-7) | B26: =B19/B20 -> 0.71156306
A27: Memo — Gordon-perpetuity FV (disclosed, not used) | B27: =(B17+(I13*(1+Assumptions!$B$16)/(Assumptions!$B$14-Assumptions!$B$16))*I14-Assumptions!$B$6-Assumptions!$B$7)/Assumptions!$B$5 -> 13.836515
A28: WACC (≈ Ke, modest net debt) | B28: =Assumptions!$B$14 -> 0.085
A29: Ke = rf + beta × ERP | B29: =Assumptions!$B$12 -> 0.092
A31: DEVELOPMENT LEG — finite DCF (AED bn)
A32: Development enterprise value | B32: =SUM(B38:K38)+Assumptions!$B$33 -> 36.158667
A33: land-replenishment tail (PV, memo) | B33: =Assumptions!$B$33 -> 5
A35: Dev EBITDA | B35: =Assumptions!$B$22 -> 7.6 | C35: =Assumptions!$B$23 -> 8.3 | D35: =Assumptions!$B$24 -> 8.9 | E35: =Assumptions!$B$25 -> 9.2 | F35: =Assumptions!$B$26 -> 9.2 | G35: =Assumptions!$B$27 -> 8.8 | H35: =Assumptions!$B$28 -> 8.3 | I35: =Assumptions!$B$29 -> 7.6 | J35: =Assumptions!$B$30 -> 6.8 | K35: =Assumptions!$B$31 -> 6
A36: Dev FCFF (≈70% cash-conv, after tax/capex/WC) | B36: =(B35*(1-Assumptions!$B$32))*(1-Assumptions!$B$17)+B35*Assumptions!$B$32-1.6-1.3 -> 3.81992 | C36: =(C35*(1-Assumptions!$B$32))*(1-Assumptions!$B$17)+C35*Assumptions!$B$32-1.7-1.1 -> 4.53886 | D36: =(D35*(1-Assumptions!$B$32))*(1-Assumptions!$B$17)+D35*Assumptions!$B$32-1.8-1 -> 5.06938 | E36: =(E35*(1-Assumptions!$B$32))*(1-Assumptions!$B$17)+E35*Assumptions!$B$32-1.9-0.9 -> 5.33464 | F36: =(F35*(1-Assumptions!$B$32))*(1-Assumptions!$B$17)+F35*Assumptions!$B$32-1.9-0.8 -> 5.43464 | G36: =(G35*(1-Assumptions!$B$32))*(1-Assumptions!$B$17)+G35*Assumptions!$B$32-1.7-0.6 -> 5.48096 | H36: =(H35*(1-Assumptions!$B$32))*(1-Assumptions!$B$17)+H35*Assumptions!$B$32-1.5-0.5 -> 5.33886 | I36: =(I35*(1-Assumptions!$B$32))*(1-Assumptions!$B$17)+I35*Assumptions!$B$32-1.3-0.4 -> 5.01992 | J36: =(J35*(1-Assumptions!$B$32))*(1-Assumptions!$B$17)+J35*Assumptions!$B$32-1.1-0.3 -> 4.61256 | K36: =(K35*(1-Assumptions!$B$32))*(1-Assumptions!$B$17)+K35*Assumptions!$B$32-0.9-0.2 -> 4.2052
A37: Discount factor | B37: =1/(1+Assumptions!$B$15)^1 -> 0.91743119 | C37: =1/(1+Assumptions!$B$15)^2 -> 0.84167999 | D37: =1/(1+Assumptions!$B$15)^3 -> 0.77218348 | E37: =1/(1+Assumptions!$B$15)^4 -> 0.70842521 | F37: =1/(1+Assumptions!$B$15)^5 -> 0.64993139 | G37: =1/(1+Assumptions!$B$15)^6 -> 0.59626733 | H37: =1/(1+Assumptions!$B$15)^7 -> 0.54703424 | I37: =1/(1+Assumptions!$B$15)^8 -> 0.50186628 | J37: =1/(1+Assumptions!$B$15)^9 -> 0.46042778 | K37: =1/(1+Assumptions!$B$15)^10 -> 0.42241081
A38: PV of dev FCFF | B38: =B36*B37 -> 3.5045138 | C38: =C36*C37 -> 3.8202677 | D38: =D36*D37 -> 3.9144915 | E38: =E36*E37 -> 3.7791935 | F38: =F36*F37 -> 3.5321431 | G38: =G36*G37 -> 3.2681174 | H38: =H36*H37 -> 2.9205392 | I38: =I36*I37 -> 2.5193286 | ... K38: =K36*K37 -> 1.7763219

Sheet Income Statement
A1: Income statement (AED bn, consolidated)
A2: FY2023–FY2025 disclosed (blue); 2026e–2030e forecast (formula). Links to Assumptions.
A3: AED bn | B3: FY2023a | C3: FY2024a | D3: FY2025a | E3: 2026e | F3: 2027e | G3: 2028e | H3: 2029e | I3: 2030e
A4: Aldar Development revenue | B4: 8.71 | C4: 15.7 | D4: 24.8 | E4: =E6*0.73 -> 27.01 | F4: =F6*0.73 -> 29.93 | G4: =G6*0.73 -> 32.85 | H4: =H6*0.73 -> 35.04 | I4: =I6*0.73 -> 36.865
A5: Aldar Investment revenue | B5: 5.8 | C5: 7 | D5: 9 | E5: =E6*0.27 -> 9.99 | F5: =F6*0.27 -> 11.07 | G5: =G6*0.27 -> 12.15 | H5: =H6*0.27 -> 12.96 | I5: =I6*0.27 -> 13.635
A6: Total revenue | B6: 14.2 | C6: 23 | D6: 33.8 | E6: =Assumptions!$B$35 -> 37 | F6: =Assumptions!$B$36 -> 41 | G6: =Assumptions!$B$37 -> 45 | H6: =Assumptions!$B$38 -> 48 | I6: =Assumptions!$B$39 -> 50.5
A8: EBITDA | B8: 5.1 | C8: 7.7 | D8: 11.2 | E8: =E6*Assumptions!$B$40 -> 11.655 | F8: =F6*Assumptions!$B$41 -> 12.71 | G8: =G6*Assumptions!$B$42 -> 13.725 | H8: =H6*Assumptions!$B$43 -> 14.544 | I8: =I6*Assumptions!$B$44 -> 15.251
A9: EBITDA margin | B9: =B8/B6 -> 0.35915493 | C9: =C8/C6 -> 0.33478261 | D9: =D8/D6 -> 0.33136095 | E9: =E8/E6 -> 0.315 | F9: =F8/F6 -> 0.31 | G9: =G8/G6 -> 0.305 | H9: =H8/H6 -> 0.303 | I9: =I8/I6 -> 0.302
A10: D&A | B10: -0.5 | C10: -0.6 | D10: -0.7 | E10: =-E6*Assumptions!$B$45 -> -0.74 | F10: =-F6*Assumptions!$B$45 -> -0.82 | G10: =-G6*Assumptions!$B$45 -> -0.9 | H10: =-H6*Assumptions!$B$45 -> -0.96 | I10: =-I6*Assumptions!$B$45 -> -1.01
A11: EBIT | B11: =B8+B10 -> 4.6 | C11: =C8+C10 -> 7.1 | D11: =D8+D10 -> 10.5 | E11: =E8+E10 -> 10.915 | F11: =F8+F10 -> 11.89 | G11: =G8+G10 -> 12.825 | H11: =H8+H10 -> 13.584 | I11: =I8+I10 -> 14.241
A12: Net finance cost | B12: -0.4 | C12: -0.5 | D12: -0.9 | E12: =-0.9 -> -0.9 | F12: =-0.9 -> -0.9 | G12: =-0.9 -> -0.9 | H12: =-0.9 -> -0.9 | I12: =-0.9 -> -0.9
A13: Fair-value gains / other (actuals) | B13: 0.3 | C13: 0.5 | D13: 0.6 | E13: =0 -> 0 | F13: =0 -> 0 | G13: =0 -> 0 | H13: =0 -> 0 | I13: =0 -> 0
A14: Profit before tax | B14: =B11+B12+B13 -> 4.5 | C14: =C11+C12+C13 -> 7.1 | D14: =D11+D12+D13 -> 10.2 | E14: =E11+E12+E13 -> 10.015 | F14: =F11+F12+F13 -> 10.99 | G14: =G11+G12+G13 -> 11.925 | H14: =H11+H12+H13 -> 12.684 | I14: =I11+I12+I13 -> 13.341
A15: Tax | B15: -0.3 | C15: -0.7 | D15: -1.4 | E15: =-MAX(0,E14)*Assumptions!$B$17 -> -1.2018 | F15: =-MAX(0,F14)*Assumptions!$B$17 -> -1.3188 | G15: =-MAX(0,G14)*Assumptions!$B$17 -> -1.431 | H15: =-MAX(0,H14)*Assumptions!$B$17 -> -1.52208 | I15: =-MAX(0,I14)*Assumptions!$B$17 -> -1.60092
A16: Net profit (group, after tax) | B16: =B14+B15 -> 4.2 | C16: =C14+C15 -> 6.4 | D16: =D14+D15 -> 8.8 | E16: =E14+E15 -> 8.8132 | F16: =F14+F15 -> 9.6712 | G16: =G14+G15 -> 10.494 | H16: =H14+H15 -> 11.16192 | I16: =I14+I15 -> 11.74008
A17: less: non-controlling interest | B17: -0.5 | C17: -0.9 | D17: -1.2 | E17: =-E16*0.12 -> -1.057584 | F17: =-F16*0.12 -> -1.160544 | G17: =-G16*0.12 -> -1.25928 | H17: =-H16*0.12 -> -1.3394304 | I17: =-I16*0.12 -> -1.4088096
A18: Attributable net profit | B18: =B16+B17 -> 3.7 | C18: =C16+C17 -> 5.5 | D18: =D16+D17 -> 7.6 | E18: =E16+E17 -> 7.755616 | F18: =F16+F17 -> 8.510656 | G18: =G16+G17 -> 9.23472 | H18: =H16+H17 -> 9.8224896 | I18: =I16+I17 -> 10.33127
A19: EPS (AED) | B19: =B18/Assumptions!$B$5 -> 0.47109753 | C19: =C18/Assumptions!$B$5 -> 0.70028011 | D19: =D18/Assumptions!$B$5 -> 0.96765979 | E19: =E18/Assumptions!$B$5 -> 0.98747339 | F19: =F18/Assumptions!$B$5 -> 1.0836078 | G19: =G18/Assumptions!$B$5 -> 1.1757983 | H19: =H18/Assumptions!$B$5 -> 1.2506353 | I19: =I18/Assumptions!$B$5 -> 1.3154151
A20: DPS (AED) | B20: 0.17 | C20: 0.185 | D20: 0.205 | E20: =E19*0.55 -> 0.54311036 | F20: =F19*0.55 -> 0.59598431 | G20: =G19*0.55 -> 0.64668908 | H20: =H19*0.55 -> 0.68784941 | I20: =I19*0.55 -> 0.72347832
A22: Source: Aldar FY2023–FY2025 results & Q1 2026; forecast is the study's operating model. Figures rounded.

Sheet Balance Sheet
A1: Balance sheet (AED bn, consolidated)
A2: Historical anchored to disclosed totals; forecast rolls forward. Balance check = 0.
A3: AED bn | B3: FY2023a | C3: FY2024a | D3: FY2025a | E3: 2026e | F3: 2027e | G3: 2028e | H3: 2029e | I3: 2030e
A4: Cash & deposits | B4: 11.7 | C4: 15.1 | D4: 21 | E4: =D4+'Cash Flow'!E12 -> 23.887611 | F4: =E4+'Cash Flow'!F12 -> 27.59795 | G4: =F4+'Cash Flow'!G12 -> 32.012854 | H4: =G4+'Cash Flow'!H12 -> 36.932405 | I4: =H4+'Cash Flow'!I12 -> 42.300286
A5: Receivables | B5: 8 | C5: 10 | D5: 12 | E5: =D5 -> 12 | F5: =E5 -> 12 | G5: =F5 -> 12 | H5: =G5 -> 12 | I5: =H5 -> 12
A6: Development inventory / WIP | B6: 28 | C6: 33 | D6: 34 | E6: =D6 -> 34 | F6: =E6 -> 34 | G6: =F6 -> 34 | H6: =G6 -> 34 | I6: =H6 -> 34
A7: Investment property (recurring) | B7: 18 | C7: 22 | D7: 25 | E7: =D7+1 -> 26 | F7: =E7+1 -> 27 | G7: =F7+1 -> 28 | H7: =G7+1 -> 29 | I7: =H7+1 -> 30
A8: Other assets | B8: =(B11+B12+B13+B14+B15)-(B4+B5+B6+B7) -> 9.3 | C8: =(C11+C12+C13+C14+C15)-(C4+C5+C6+C7) -> 8.5 | D8: =(D11+D12+D13+D14+D15)-(D4+D5+D6+D7) -> 16 | E8: =(E11+E12+E13+E14+E15)-(E4+E5+E6+E7) -> 16.377978 | F8: =(F11+F12+F13+F14+F15)-(F4+F5+F6+F7) -> 16.348499 | G8: =(G11+G12+G13+G14+G15)-(G4+G5+G6+G7) -> 16.012691 | H8: =(H11+H12+H13+H14+H15)-(H4+H5+H6+H7) -> 15.49551 | I8: =(I11+I12+I13+I14+I15)-(I4+I5+I6+I7) -> 14.809827
A9: Total assets | B9: =SUM(B4:B8) -> 75 | C9: =SUM(C4:C8) -> 88.6 | D9: =SUM(D4:D8) -> 108 | E9: =SUM(E4:E8) -> 112.26559 | F9: =SUM(F4:F8) -> 116.94645 | G9: =SUM(G4:G8) -> 122.02555 | H9: =SUM(H4:H8) -> 127.42791 | I9: =SUM(I4:I8) -> 133.11011
A11: Debt (incl. hybrids) | B11: 12.1 | C11: 16.4 | D11: 26.5 | E11: =D11 -> 26.5 | F11: =E11 -> 26.5 | G11: =F11 -> 26.5 | H11: =G11 -> 26.5 | I11: =H11 -> 26.5
A12: Customer advances / contract liab. | B12: 15 | C12: 18 | D12: 20 | E12: =D12 -> 20 | F12: =E12 -> 20 | G12: =F12 -> 20 | H12: =G12 -> 20 | I12: =H12 -> 20
A13: Payables & other liabilities | B13: 14.9 | C13: 16.7 | D13: 18.5 | E13: =D13 -> 18.5 | F13: =E13 -> 18.5 | G13: =F13 -> 18.5 | H13: =G13 -> 18.5 | I13: =H13 -> 18.5
A14: Non-controlling interests | B14: 2 | C14: 2.6 | D14: 3 | E14: =D14 -> 3 | F14: =E14 -> 3 | G14: =F14 -> 3 | H14: =G14 -> 3 | I14: =H14 -> 3
A15: Equity (attributable) | B15: 31 | C15: 34.9 | D15: 40 | E15: =D15+'Income Statement'!E18-'Income Statement'!E18*0.45 -> 44.265589 | F15: =E15+'Income Statement'!F18-'Income Statement'!F18*0.45 -> 48.94645 | G15: =F15+'Income Statement'!G18-'Income Statement'!G18*0.45 -> 54.025546 | H15: =G15+'Income Statement'!H18-'Income Statement'!H18*0.45 -> 59.427915 | I15: =H15+'Income Statement'!I18-'Income Statement'!I18*0.45 -> 65.110114
A16: Total liabilities & equity | B16: =B11+B12+B13+B14+B15 -> 75 | C16: =C11+C12+C13+C14+C15 -> 88.6 | D16: =D11+D12+D13+D14+D15 -> 108 | E16: =E11+E12+E13+E14+E15 -> 112.26559 | F16: =F11+F12+F13+F14+F15 -> 116.94645 | G16: =G11+G12+G13+G14+G15 -> 122.02555 | H16: =H11+H12+H13+H14+H15 -> 127.42791 | I16: =I11+I12+I13+I14+I15 -> 133.11011
A18: Balance check (assets − L&E) | B18: =B9-B16 -> 0 | C18: =C9-C16 -> 0 | D18: =D9-D16 -> 0 | E18: =E9-E16 -> 0 | F18: =F9-F16 -> 0 | G18: =G9-G16 -> 0 | H18: =H9-H16 -> 0 | I18: =I9-I16 -> 0
A19: Net debt (debt − cash) | B19: =B11-B4 -> 0.4 | C19: =C11-C4 -> 1.3 | D19: =D11-D4 -> 5.5 | E19: =E11-E4 -> 2.6123888 | F19: =F11-F4 -> -1.0979504 | G19: =G11-G4 -> -5.5128544 | H19: =H11-H4 -> -10.432405 | I19: =I11-I4 -> -15.800286
A21: Historical 'Other assets' is a balancing plug to disclosed totals; forecast holds non-core lines flat.

Sheet Cash Flow
A1: Cash flow (AED bn, forecast)
A2: Derived from Income Statement & Balance Sheet.
A3: AED bn | E3: 2026e | F3: 2027e | G3: 2028e | H3: 2029e | I3: 2030e
A4: Attributable net profit | E4: ='Income Statement'!E18 -> 7.755616 | F4: ='Income Statement'!F18 -> 8.510656 | G4: ='Income Statement'!G18 -> 9.23472 | H4: ='Income Statement'!H18 -> 9.8224896 | I4: ='Income Statement'!I18 -> 10.33127
A5: + D&A | E5: =-'Income Statement'!E10 -> 0.74 | F5: =-'Income Statement'!F10 -> 0.82 | G5: =-'Income Statement'!G10 -> 0.9 | H5: =-'Income Statement'!H10 -> 0.96 | I5: =-'Income Statement'!I10 -> 1.01
A6: + NCI & non-cash | E6: =-'Income Statement'!E17 -> 1.057584 | F6: =-'Income Statement'!F17 -> 1.160544 | G6: =-'Income Statement'!G17 -> 1.25928 | H6: =-'Income Statement'!H17 -> 1.3394304 | I6: =-'Income Statement'!I17 -> 1.4088096
A7: − Δ working capital | E7: -1.5 | F7: -1.2 | G7: -1 | H7: -0.9 | I7: -0.8
A8: Operating cash flow | E8: =E4+E5+E6+E7 -> 8.0532 | F8: =F4+F5+F6+F7 -> 9.2912 | G8: =G4+G5+G6+G7 -> 10.394 | H8: =H4+H5+H6+H7 -> 11.22192 | I8: =I4+I5+I6+I7 -> 11.95008
A9: − Capex | E9: =-Assumptions!$B$46 -> -0.9 | F9: =-Assumptions!$B$46 -> -0.9 | G9: =-Assumptions!$B$46 -> -0.9 | H9: =-Assumptions!$B$46 -> -0.9 | I9: =-Assumptions!$B$46 -> -0.9
A10: Free cash flow | E10: =E8+E9 -> 7.1532 | F10: =F8+F9 -> 8.3912 | G10: =G8+G9 -> 9.494 | H10: =H8+H9 -> 10.32192 | I10: =I8+I9 -> 11.05008
A11: − Dividends | E11: =-'Income Statement'!E20*Assumptions!$B$5 -> -4.2655888 | F11: =-'Income Statement'!F20*Assumptions!$B$5 -> -4.6808608 | G11: =-'Income Statement'!G20*Assumptions!$B$5 -> -5.079096 | H11: =-'Income Statement'!H20*Assumptions!$B$5 -> -5.4023693 | I11: =-'Income Statement'!I20*Assumptions!$B$5 -> -5.6821987
A12: Net change in cash | E12: =E10+E11 -> 2.8876112 | F12: =F10+F11 -> 3.7103392 | G12: =G10+G11 -> 4.414904 | H12: =H10+H11 -> 4.9195507 | I12: =I10+I11 -> 5.3678813

Sheet Summary Financials
A1: Summary financials (AED bn)
A2: Every cell links to the statement sheets.
A3: AED bn | B3: FY2023a | C3: FY2024a | D3: FY2025a | E3: 2026e | F3: 2027e | G3: 2028e | H3: 2029e | I3: 2030e
A4: Revenue | B4: ='Income Statement'!B6 -> 14.2 | C4: ='Income Statement'!C6 -> 23 | D4: ='Income Statement'!D6 -> 33.8 | E4: ='Income Statement'!E6 -> 37 | F4: ='Income Statement'!F6 -> 41 | G4: ='Income Statement'!G6 -> 45 | H4: ='Income Statement'!H6 -> 48 | I4: ='Income Statement'!I6 -> 50.5
A5: EBITDA | B5: ='Income Statement'!B8 -> 5.1 | C5: ='Income Statement'!C8 -> 7.7 | D5: ='Income Statement'!D8 -> 11.2 | E5: ='Income Statement'!E8 -> 11.655 | F5: ='Income Statement'!F8 -> 12.71 | G5: ='Income Statement'!G8 -> 13.725 | H5: ='Income Statement'!H8 -> 14.544 | I5: ='Income Statement'!I8 -> 15.251
A6: EBIT | B6: ='Income Statement'!B11 -> 4.6 | C6: ='Income Statement'!C11 -> 7.1 | D6: ='Income Statement'!D11 -> 10.5 | E6: ='Income Statement'!E11 -> 10.915 | F6: ='Income Statement'!F11 -> 11.89 | G6: ='Income Statement'!G11 -> 12.825 | H6: ='Income Statement'!H11 -> 13.584 | I6: ='Income Statement'!I11 -> 14.241
A7: Attributable net profit | B7: ='Income Statement'!B18 -> 3.7 | C7: ='Income Statement'!C18 -> 5.5 | D7: ='Income Statement'!D18 -> 7.6 | E7: ='Income Statement'!E18 -> 7.755616 | F7: ='Income Statement'!F18 -> 8.510656 | G7: ='Income Statement'!G18 -> 9.23472 | H7: ='Income Statement'!H18 -> 9.8224896 | I7: ='Income Statement'!I18 -> 10.33127
A8: Total assets | B8: ='Balance Sheet'!B9 -> 75 | C8: ='Balance Sheet'!C9 -> 88.6 | D8: ='Balance Sheet'!D9 -> 108 | E8: ='Balance Sheet'!E9 -> 112.26559 | F8: ='Balance Sheet'!F9 -> 116.94645 | G8: ='Balance Sheet'!G9 -> 122.02555 | H8: ='Balance Sheet'!H9 -> 127.42791 | I8: ='Balance Sheet'!I9 -> 133.11011
A9: Equity (attributable) | B9: ='Balance Sheet'!B15 -> 31 | C9: ='Balance Sheet'!C15 -> 34.9 | D9: ='Balance Sheet'!D15 -> 40 | E9: ='Balance Sheet'!E15 -> 44.265589 | F9: ='Balance Sheet'!F15 -> 48.94645 | G9: ='Balance Sheet'!G15 -> 54.025546 | H9: ='Balance Sheet'!H15 -> 59.427915 | I9: ='Balance Sheet'!I15 -> 65.110114
A10: Net debt | B10: ='Balance Sheet'!B19 -> 0.4 | C10: ='Balance Sheet'!C19 -> 1.3 | D10: ='Balance Sheet'!D19 -> 5.5 | E10: ='Balance Sheet'!E19 -> 2.6123888 | F10: ='Balance Sheet'!F19 -> -1.0979504 | G10: ='Balance Sheet'!G19 -> -5.5128544 | H10: ='Balance Sheet'!H19 -> -10.432405 | I10: ='Balance Sheet'!I19 -> -15.800286
A11: Free cash flow | E11: ='Cash Flow'!E10 -> 7.1532 | F11: ='Cash Flow'!F10 -> 8.3912 | G11: ='Cash Flow'!G10 -> 9.494 | H11: ='Cash Flow'!H10 -> 10.32192 | I11: ='Cash Flow'!I10 -> 11.05008

Sheet Monte Carlo
A1: Monte Carlo — engine outputs
A2: 50,000 paths · 16 factors · seed 42 · YZ-HAR width · Student-t(5) · zero drift (international). Computed by the Testahil engine.
A3: Percentile map (AED/share)
A4: Horizon | B4: p5 | C4: p25 | D4: p50 | E4: p75 | F4: p95
A5: T+20 sessions | B5: 7.017 | C5: 7.858 | D5: 8.375 | E5: 8.925 | F5: 9.912
A6: T+60 sessions | B6: 6.363 | C6: 7.599 | D6: 8.496 | E6: 9.48 | F6: 11.293
A8: Probability read (T+60)
A9: P(above spot) | B9: 0.5581
A10: P(+10%) | B10: 0.3286
A11: P(−10%) | B11: 0.2193
A12: Odds (up/down) | B12: 1.4982
A13: Median (AED) | B13: 8.4963
A14: Median move | B14: 0.0237
A15: 50% band low | B15: 7.5989
A16: 50% band high | B16: 9.4797
A17: Touch +10% | B17: 0.5579
A18: Touch −10% | B18: 0.4245
A20: Level-touch ladder
A21: Level | B21: T+20 | C21: T+60
A22: 10.5 | B22: 0.028 | C22: 0.172
A23: 10 | B23: 0.065 | C23: 0.273
A24: 9.5 | B24: 0.155 | C24: 0.419
A25: 9 | B25: 0.346 | C25: 0.612
A26: 8.6 | B26: 0.614 | C26: 0.795
A27: 8.3 | B27: 1 | C27: 1
A28: 8 | B28: 0.54 | C28: 0.712
A29: 7.6 | B29: 0.26 | C29: 0.485
A30: 7.2 | B30: 0.116 | C30: 0.311
A31: 7 | B31: 0.076 | C31: 0.242
A34: Step 0 calibration (5-yr backtest)
A35: Scheme | B35: n | C35: CRPS skill | D35: Winkler skill | E35: PIT mean
A36: Non-overlapping (step 63d) | B36: 17 | C36: 0.018 | D36: 0.017 | E36: 0.584
A37: Monthly origins (step 21d) | B37: 49 | C37: 0.01 | D37: 0.059 | E37: 0.597
A38: Fortnightly (step 10d) | B38: 102 | C38: 0.009 | D38: 0.081 | E38: 0.587
A40: Pass gate: CRPS skill > 0 vs a zero-drift random-walk benchmark. All three schemes pass.

Sheet Sensitivity
A1: Sensitivity grids
A2: SOTP: dev WACC × dev EBITDA level. Consolidated DCF: WACC × exit EV/EBITDA multiple. Recomputed from Assumptions.
A3: SOTP fair value (AED/share): dev WACC ↓ × dev EBITDA shift →
A4: WACC \ ΔEBITDA | B4: -1.2 | C4: -0.6 | D4: +0.0 | E4: +0.6 | F4: +1.2
A5: 8.0% | B5: 9.42 | C5: 9.88 | D5: 10.33 | E5: 10.78 | F5: 11.23
A6: 8.5% | B6: 9.35 | C6: 9.79 | D6: 10.23 | E6: 10.67 | F6: 11.12
A7: 9.0% | B7: 9.28 | C7: 9.71 | D7: 10.14 | E7: 10.57 | F7: 11.01
A8: 9.5% | B8: 9.21 | C8: 9.63 | D8: 10.05 | E8: 10.48 | F8: 10.9
A9: 10.0% | B9: 9.14 | C9: 9.56 | D9: 9.97 | E9: 10.38 | F9: 10.8
A12: Consolidated DCF fair value (AED/share): WACC ↓ × exit EV/EBITDA multiple →
A13: WACC \ exit× | B13: 5.0x | C13: 5.5x | D13: 6.0x | E13: 6.5x | F13: 7.0x
A14: 7.5% | B14: 8.91 | C14: 9.59 | D14: 10.27 | E14: 10.94 | F14: 11.62
A15: 8.0% | B15: 8.71 | C15: 9.37 | D15: 10.03 | E15: 10.69 | F15: 11.36
A16: 8.5% | B16: 8.52 | C16: 9.16 | D16: 9.81 | E16: 10.45 | F16: 11.1
A17: 9.0% | B17: 8.32 | C17: 8.95 | D17: 9.59 | E17: 10.22 | F17: 10.85
A18: 9.5% | B18: 8.14 | C18: 8.75 | D18: 9.37 | E18: 9.99 | F18: 10.6

Sheet Per-Share & Ratios
A1: Per-share & ratios
A2: Links to statements / Assumptions.
B3: FY2023a | C3: FY2024a | D3: FY2025a | E3: 2026e | F3: 2027e | G3: 2028e | H3: 2029e | I3: 2030e
A4: EPS (AED) | B4: ='Income Statement'!B19 -> 0.47109753 | C4: ='Income Statement'!C19 -> 0.70028011 | D4: ='Income Statement'!D19 -> 0.96765979 | E4: ='Income Statement'!E19 -> 0.98747339 | F4: ='Income Statement'!F19 -> 1.0836078 | G4: ='Income Statement'!G19 -> 1.1757983 | H4: ='Income Statement'!H19 -> 1.2506353 | I4: ='Income Statement'!I19 -> 1.3154151
A5: DPS (AED) | B5: ='Income Statement'!B20 -> 0.17 | C5: ='Income Statement'!C20 -> 0.185 | D5: ='Income Statement'!D20 -> 0.205 | E5: ='Income Statement'!E20 -> 0.54311036 | F5: ='Income Statement'!F20 -> 0.59598431 | G5: ='Income Statement'!G20 -> 0.64668908 | H5: ='Income Statement'!H20 -> 0.68784941 | I5: ='Income Statement'!I20 -> 0.72347832
A6: BVPS (AED) | B6: ='Balance Sheet'!B15/Assumptions!$B$5 -> 3.9470334 | C6: ='Balance Sheet'!C15/Assumptions!$B$5 -> 4.4435956 | D6: ='Balance Sheet'!D15/Assumptions!$B$5 -> 5.0929463 | E6: ='Balance Sheet'!E15/Assumptions!$B$5 -> 5.6360566 | F6: ='Balance Sheet'!F15/Assumptions!$B$5 -> 6.2320409 | G6: ='Balance Sheet'!G15/Assumptions!$B$5 -> 6.87873 | H6: ='Balance Sheet'!H15/Assumptions!$B$5 -> 7.5665794 | I6: ='Balance Sheet'!I15/Assumptions!$B$5 -> 8.2900578
A7: P/E (x) | B7: =Assumptions!$B$4/'Income Statement'!B19 -> 17.618432 | C7: =Assumptions!$B$4/'Income Statement'!C19 -> 11.8524 | D7: =Assumptions!$B$4/'Income Statement'!D19 -> 8.5773947 | E7: =Assumptions!$B$4/'Income Statement'!E19 -> 8.4052898 | F7: =Assumptions!$B$4/'Income Statement'!F19 -> 7.6595976 | G7: =Assumptions!$B$4/'Income Statement'!G19 -> 7.0590337 | H7: =Assumptions!$B$4/'Income Statement'!H19 -> 6.636627 | I7: =Assumptions!$B$4/'Income Statement'!I19 -> 6.3097952
A8: P/B (x) | B8: =Assumptions!$B$4/'Balance Sheet'!B15*Assumptions!$B$5 -> 2.1028452 | C8: =Assumptions!$B$4/'Balance Sheet'!C15*Assumptions!$B$5 -> 1.8678567 | D8: =Assumptions!$B$4/'Balance Sheet'!D15*Assumptions!$B$5 -> 1.629705 | E8: =Assumptions!$B$4/'Balance Sheet'!E15*Assumptions!$B$5 -> 1.4726609 | F8: =Assumptions!$B$4/'Balance Sheet'!F15*Assumptions!$B$5 -> 1.3318269 | G8: =Assumptions!$B$4/'Balance Sheet'!G15*Assumptions!$B$5 -> 1.2066181 | H8: =Assumptions!$B$4/'Balance Sheet'!H15*Assumptions!$B$5 -> 1.0969289 | I8: =Assumptions!$B$4/'Balance Sheet'!I15*Assumptions!$B$5 -> 1.0011993
A9: EBITDA margin | B9: ='Income Statement'!B8/'Income Statement'!B6 -> 0.35915493 | C9: ='Income Statement'!C8/'Income Statement'!C6 -> 0.33478261 | D9: ='Income Statement'!D8/'Income Statement'!D6 -> 0.33136095 | E9: ='Income Statement'!E8/'Income Statement'!E6 -> 0.315 | F9: ='Income Statement'!F8/'Income Statement'!F6 -> 0.31 | G9: ='Income Statement'!G8/'Income Statement'!G6 -> 0.305 | H9: ='Income Statement'!H8/'Income Statement'!H6 -> 0.303 | I9: ='Income Statement'!I8/'Income Statement'!I6 -> 0.302

Sheet Peer & Sector
A1: Peer set & sector
A2: GCC / UAE developers and diversified real-estate platforms.
A3: Peer | B3: Profile | C3: Typical valuation
A4: Emaar Properties (DFM) | B4: Dubai developer + malls/hospitality | C4: P/E ~8–10x; EV/EBITDA ~7–9x
A5: Emaar Development (DFM) | B5: Dubai pure development | C5: P/E ~6–8x; discount to NAV
A6: TAQA / ADNOC-linked (ADX) | B6: Abu Dhabi infrastructure | C6: utility multiples
A7: DAMAC / Deyaar (DFM) | B7: Dubai developers | C7: P/E ~6–9x; NAV discount
A8: Aldar (ADX: ALDAR) | B8: AD developer + AED 52bn recurring platform | C8: P/E ~8.6x; ~18% discount to RNAV
A10: Analyst context: sell-side targets AED 11.0–12.2 (FCFF DCF, WACC ~8%); our exit-multiple DCF AED 9.81, RNAV AED 10.14. Verify live before use.
