Workbook

Sheet READ FIRST
A1: Testahil — Beltone Financial Holding (EGX: BTFH)
A2: Companion model · Independent Valuation Study · Educational analysis · Not investment advice
A4: What this workbook is. A transparent companion to the BTFH valuation study. Every blue cell is an input; every
A5: black cell is a formula; green cells link across sheets. All inputs live on the Assumptions sheet — change one
A6: (a platform P/B mark, the complexity discount, the cost of equity, a growth rate) and the whole model reprices.
A8: What it is not. It is not investment advice, a recommendation, or a price target. Values are model outputs shown
A9: as ranges. The preparer is not licensed by any securities regulator and may hold a position in the security.
A11: Entity note. Beltone Financial Holding S.A.E. (brand: Beltone Holding) is an EGX-listed financial holding company:
A12: an Investment Bank platform (brokerage, investment banking, asset management, research), an Egypt NBFI lending
A13: platform (leasing & factoring, consumer finance 'seven', mortgage, microfinance, SMEs), Beltone Capital / Venture
A14: Capital, and — consolidated from Q1 2026 — Baobab Group, a pan-African microfinance banking group acquired for
A15: EUR 197.6m from the majority shareholder (Chimera / 2PointZero, Abu Dhabi) via the Lumen Aegis SPV (Dec 2025).
... A24: Income Statement · Balance Sheet · Cash Flow · Summary Financials · Monte Carlo · Sensitivity · Per-Share & Ratios · Peer & Sector.

Sheet Summary
A1: Valuation summary — Beltone Financial Holding (EGX: BTFH)
A2: Four-lens fair value vs spot; Monte Carlo three-month map. Base links live (study §1.5, §3).
A4: Lens | B4: Bear | C4: Base | D4: Bull | E4: Weight
A5: ='Fundamental Valuation'!A5 -> Sum-of-the-parts | B5: ='Fundamental Valuation'!B5 -> 1.8 | C5: ='Fundamental Valuation'!C5 -> 2.7013183 | D5: ='Fundamental Valuation'!D5 -> 3.68 | E5: ='Fundamental Valuation'!E5 -> 0.4
A6: ='Fundamental Valuation'!A6 -> Equity DCF / residual income | B6: ='Fundamental Valuation'!B6 -> 1.75 | C6: ='Fundamental Valuation'!C6 -> 2.50705 | D6: ='Fundamental Valuation'!D6 -> 3.95 | E6: ='Fundamental Valuation'!E6 -> 0.2
A7: ='Fundamental Valuation'!A7 -> Relative multiples | B7: ='Fundamental Valuation'!B7 -> 1.68 | C7: ='Fundamental Valuation'!C7 -> 2.6436414 | D7: ='Fundamental Valuation'!D7 -> 3.9 | E7: ='Fundamental Valuation'!E7 -> 0.15
A8: ='Fundamental Valuation'!A8 -> Normalized earnings | B8: ='Fundamental Valuation'!B8 -> 2.29 | C8: ='Fundamental Valuation'!C8 -> 3.619649 | D8: ='Fundamental Valuation'!D8 -> 5.13 | E8: ='Fundamental Valuation'!E8 -> 0.25
A9: Weighted central | B9: ='Fundamental Valuation'!B9 -> 1.8945 | C9: ='Fundamental Valuation'!C9 -> 2.8833958 | D9: ='Fundamental Valuation'!D9 -> 4.1295
A10: Spot price (EGP) | C10: =Assumptions!B5 -> 2.97
A11: Upside / (downside) to central base | C11: =C9/Assumptions!B5-1 -> -0.029159669
A13: Monte Carlo (T+60): p5 / p50 / p95 | B13: 2.04 | C13: 2.89 | D13: 4.04
A15: Read: fairly valued, price ~3% ahead of the central; the answer turns on the ROE bridge (§1.7) — whether the enlarged, Baobab-
A16: consolidated book can lift attributable ROE from ~11% today toward the high-teens that a premium to book requires.

Sheet Fundamental Valuation
A1: Fundamental valuation — football field data
A2: Bear/base/bull per lens; base links live to the lens sheets, bear/bull are scenario outputs (study §1.5).
A4: Lens | B4: Bear | C4: Base | D4: Bull | E4: Weight
A5: Sum-of-the-parts | B5: 1.8 | C5: =SOTP!E11 -> 2.7013183 | D5: 3.68 | E5: =Assumptions!B45 -> 0.4
A6: Equity DCF / residual income | B6: 1.75 | C6: =DCF!B12 -> 2.50705 | D6: 3.95 | E6: =Assumptions!B46 -> 0.2
A7: Relative multiples | B7: 1.68 | C7: ='Relative & Normalized'!B8 -> 2.6436414 | D7: 3.9 | E7: =Assumptions!B47 -> 0.15
A8: Normalized earnings | B8: 2.29 | C8: ='Relative & Normalized'!B20 -> 3.619649 | D8: 5.13 | E8: =Assumptions!B48 -> 0.25
A9: Weighted central | B9: =SUMPRODUCT(B5:B8,$E$5:$E$8) -> 1.8945 | C9: =SUMPRODUCT(C5:C8,$E$5:$E$8) -> 2.8833958 | D9: =SUMPRODUCT(D5:D8,$E$5:$E$8) -> 4.1295
A10: Spot (EGP) | C10: =Assumptions!B5 -> 2.97
A11: Spot premium / (discount) to central base | C11: =Assumptions!B5/C9-1 -> 0.030035494

Sheet Assumptions
A1: Assumptions — the single input layer (blue cells)
A2: Change any blue cell; every downstream sheet reprices. Sources & as-of dates noted at right.
A4: Market & share data | B4: Value | D4: Source / note
A5: Spot price (EGP, 1 Jul 2026 close) | B5: 2.97 | D5: Uploaded daily price history, 1-Jul-2026
A6: Shares outstanding (m) | B6: 10718.1 | D6: Issued capital EGP 21,436m / par EGP 2; post Apr-2025 raise (EGX disclosures)
A7: Attributable equity, 31-Dec-2025 (EGP m) | B7: 23253 | D7: FY2025 statements (aggregated); total equity 23,499 less MI 246
A8: Minority interest, 31-Dec-2025 (EGP m) | B8: 246 | C8: 3.79 | D8: FY2025 statements (aggregated)
A9: 52-week low / high (EGP) | B9: 2.65 | D9: From uploaded price history (high 3.79 in C-col note)
A10: EGP per USD (study date, approx.) | B10: 49.7 | D10: Implied by Q1-2026 press conversions (TechCabal, Jun-2026)
A11: EGP per EUR (study date, approx.) | B11: 57.5 | D11: Approximate cross at study date; Baobab consideration EUR 197.6m
A13: SOTP — allocated equity & marks | B13: Equity (EGP m) | C13: Justified P/B | D13: Note
A14: Egypt NBFI lending platform | B14: 8000 | C14: 1.6 | D14: Leasing & factoring, seven, mortgage, micro, SMEs; ROE ~26% justified
A15: Investment Bank platform | B15: 4500 | C15: 1.9 | D15: Brokerage 5.6% share, IB, AM EGP 49bn AUM; asset-light, EFG-plus mark
A16: Baobab (pan-Africa, at ~cost) | B16: 8500 | C16: 1 | D16: EUR 197.6m consideration; related-party purchase — marked at ~cost
A17: Beltone Capital / VC / other & surplus | B17: 2900 | C17: 0.8 | D17: NSC 51%, VC AUM EGP 2.7bn, residual holdco items
A18: Allocation check — sum of buckets (= attributable book) | B18: =SUM(B14:B17) -> 23900
A19: Complexity / related-party discount | B19: 0.1
A21: Equity DCF / residual income | B21: Value | D21: Note
A22: Cost of equity (COE) | B22: 0.23 | D22: T-bill ~19–20% falling + equity premium; nominal EGP
A23: Terminal P/E on 2030E NPAT&MI | B23: 8 | D23: Through-cycle EM-financial multiple
A24: Dividend payout 2026–27 / 2028–30 | B24: 0 | C24: 0.2 | D24: Growth phase: nil, then 20% (cell C below)
A25: Long-run nominal growth g (justified P/B) | B25: 0.15 | D25: ~nominal GDP; used on Sensitivity sheet
A26: Sustainable ROE (normalized lens) | B26: 0.18 | D26: The §1.7 ROE-bridge landing point
A27: Justified P/E (normalized lens) | B27: 9 | D27: Mid-cycle EM diversified-financial
A28: 2026E P/E (relative lens) | B28: 10 | D28: EFG ~10.5x trailing; small discount for float/seasoning
A29: P/B cross-check multiple | B29: 1.2 | D29: EFG ~1.2x; Egyptian financials range 0.9–2.6x
A31: Forecast drivers | B31: 2026E | C31: 2027E | D31: 2028E | E31: 2029E | F31: 2030E
A32: Operating revenue (2026E level, EGP m; then growth) | B32: 29000 | C32: 0.28 | D32: 0.22 | E32: 0.18 | F32: 0.15
A33: Net operating profit margin | B33: 0.19 | C33: 0.205 | D33: 0.22 | E33: 0.23 | F33: 0.24
A34: Finance & central costs (% of revenue) | B34: -0.055 | C34: -0.052 | D34: -0.05 | E34: -0.046 | F34: -0.042
A35: FX & non-recurring (EGP m) | B35: 0 | C35: 0 | D35: 0 | E35: 0 | F35: 0
A36: Effective tax rate | B36: 0.25 | C36: 0.25 | D36: 0.25 | E36: 0.25 | F36: 0.25
A37: Minority share of NPAT | B37: 0.035 | C37: 0.035 | D37: 0.035 | E37: 0.035 | F37: 0.035
A38: Total assets (2026E level, EGP m; then growth) | B38: 145000 | C38: 0.22 | D38: 0.19 | E38: 0.16 | F38: 0.14
A39: Net lending portfolio (2026E level; then growth) | B39: 105000 | C39: 0.24 | D39: 0.2 | E39: 0.17 | F39: 0.15
A40: Customer deposits (2026E level; then growth) | B40: 30000 | C40: 0.2 | D40: 0.2 | E40: 0.18 | F40: 0.16
A41: Cash (% of total assets) | B41: 0.08 | C41: 0.08 | D41: 0.08 | E41: 0.08 | F41: 0.08
A42: Other liabilities (% of total assets) | B42: 0.12 | C42: 0.12 | D42: 0.12 | E42: 0.12 | F42: 0.12
A44: Lens weights (§1.5) | B44: Weight
A45: Sum-of-the-parts | B45: 0.4
...

Sheet SOTP
A1: Sum-of-the-parts — the primary lens
A2: Attributable book (EGP 23.9bn incl. Q1-2026 profit) allocated to four platforms; each marked at a justified P/B; complexity discount applied.
A4: Platform | B4: Allocated equity (EGP m) | C4: Justified P/B | D4: Value (EGP m) | E4: EGP / share
A5: Egypt NBFI lending platform | B5: =Assumptions!B14 -> 8000 | C5: =Assumptions!C14 -> 1.6 | D5: =B5*C5 -> 12800 | E5: =D5/Assumptions!$B$6 -> 1.1942415
A6: Investment Bank platform | B6: =Assumptions!B15 -> 4500 | C6: =Assumptions!C15 -> 1.9 | D6: =B6*C6 -> 8550 | E6: =D6/Assumptions!$B$6 -> 0.79771601
A7: Baobab (pan-Africa) | B7: =Assumptions!B16 -> 8500 | C7: =Assumptions!C16 -> 1 | D7: =B7*C7 -> 8500 | E7: =D7/Assumptions!$B$6 -> 0.79305101
A8: Beltone Capital / VC / other | B8: =Assumptions!B17 -> 2900 | C8: =Assumptions!C17 -> 0.8 | D8: =B8*C8 -> 2320 | E8: =D8/Assumptions!$B$6 -> 0.21645627
A9: Σ marked platform value (pre-discount) | B9: =SUM(B5:B8) -> 23900 | D9: =SUM(D5:D8) -> 32170 | E9: =D9/Assumptions!$B$6 -> 3.0014648
A10: less: complexity / related-party discount | D10: =-D9*Assumptions!B19 -> -3217 | E10: =D10/Assumptions!$B$6 -> -0.30014648
A11: SOTP equity value | D11: =D9+D10 -> 28953 | E11: =D11/Assumptions!$B$6 -> 2.7013183
A13: Market-implied discount to pre-discount NAV | E13: =1-Assumptions!B5/E9 -> 0.010483152
A15: Allocation note. Buckets are a preparer judgment summing to attributable book — the group does not disclose allocated equity by
A16: platform. Baobab is held near cost (EUR 197.6m ≈ EGP 11.4bn gross; net-of-funding allocation shown) because it was purchased from
A17: the majority shareholder — a related-party mark that deserves an independent test, which is what the bear case applies.

Sheet Segments
A1: Segments — platform operating revenue, portfolios, franchise KPIs
A2: Company disclosure; FY2025 platform split part-estimated from 1H2025 detail (flagged).
A4: Operating revenue (EGP m) | B4: FY2024 | C4: FY2025 (est. split) | D4: Q1-2026
A5: Investment Bank platform | B5: 1300 | C5: 2300 | D5: 700
A6: Egypt NBFI platform | B6: 5800 | C6: 9600 | D6: 2300
A7: Baobab (pan-Africa; from Q1-26) | B7: 0 | C7: 0 | D7: 3600
A8: Beltone Capital / VC / other | B8: 100 | C8: 900 | D8: 200
A9: Total operating revenue | B9: =SUM(B5:B8) -> 7200 | C9: =SUM(C5:C8) -> 12800 | D9: =SUM(D5:D8) -> 6800
A11: Portfolios & KPIs | B11: FY2024 | C11: FY2025 | D11: Q1-2026
A12: Gross lending portfolio (EGP bn) | B12: 26.1 | C12: 38.6 | D12: 101.1
A13: of which Baobab (EGP bn) | B13: 0 | C13: 0 | D13: 60.9
A14: Assets under management (EGP bn) | B14: 22.6 | C14: 39.2 | D14: 49
A15: Brokerage market share | B15: 0.044 | C15: 0.05 | D15: 0.056
A16: Brokerage executions (EGP bn, FY) | B16: — | C16: 136 | D16: —
A17: seven consumer-finance portfolio (EGP bn) | B17: 4.4 | C17: 6.2 | D17: —
A18: Mortgage portfolio (EGP bn, 1H25) | B18: — | C18: 7.3 | D18: —
A19: Securitizations closed (FY2025, EGP bn) | B19: — | C19: 6.4 | D19: —
A21: Sources: FY2024/FY2025 earnings releases; 1H2025 earnings release (EGX bulletin); Q1-2026 results & press (May–Jun 2026).
A22: Baobab: acquired via Lumen Aegis SPV from the majority shareholder for EUR 197.6m; contributed 53% of Q1-2026 operating revenue.

Sheet Relative & Normalized
A1: Relative multiples & normalized earnings power
A2: Lens 3: 2026E P/E and a P/B cross-check. Lens 4: sustainable mid-cycle earnings × a justified multiple.
A4: Relative multiples | B4: Value
A5: 2026E NPAT & minority (EGP m) | B5: ='Income Statement'!E14 -> 2833.4812
A6: 2026E EPS (EGP) | B6: =B5/Assumptions!B6 -> 0.26436414
A7: Applied P/E | B7: =Assumptions!B28 -> 10
A8: Relative fair value (EGP/share) | B8: =B6*B7 -> 2.6436414
A10: BVPS, 31-Dec-2025 (EGP) | B10: ='Balance Sheet'!D18 -> 2.1695077
A11: P/B cross-check multiple | B11: =Assumptions!B29 -> 1.2
A12: P/B cross-check value (EGP/share) | B12: =B10*B11 -> 2.6034092
A14: Normalized earnings power | B14: Value
A15: Attributable book, today (EGP m, incl. Q1-26 NI) | B15: 23948
A16: Sustainable ROE (the bridge landing point) | B16: =Assumptions!B26 -> 0.18
A17: Mid-cycle NPAT & minority (EGP m) | B17: =B15*B16 -> 4310.64
A18: Mid-cycle EPS (EGP) | B18: =B17/Assumptions!B6 -> 0.40218322
A19: Justified P/E | B19: =Assumptions!B27 -> 9
A20: Normalized fair value (EGP/share) | B20: =B18*B19 -> 3.619649
A22: The normalized lens asks what the enlarged book earns once Baobab is integrated, the two raises are deployed and the book seasons —
A23: it is the recovery/deployment ceiling, exactly as the normalized lens was the JLR-recovery ceiling in the TMPV study.

Sheet DCF
A1: DCF - free cash flow to equity, year by year
A2: NPAT less capital retained for book growth = distributable FCFE; each year discounted at the cost of equity (the WACC-equivalent for a financial); terminal at 8.0x 2030E NPAT&MI. FCFF/WACC on enterprise value is not meaningful for a lender - deposits and borrowings are operating liabilities.
A4: EGP m | B4: 2026E | C4: 2027E | D4: 2028E | E4: 2029E | F4: 2030E | G4: Terminal
A5: NPAT & minority | B5: ='Income Statement'!E14 -> 2833.4812 | C5: ='Income Statement'!F14 -> 4110.4368 | D5: ='Income Statement'!G14 -> 5571.9254 | E5: ='Income Statement'!H14 -> 7116.3321 | F5: ='Income Statement'!I14 -> 8806.4609
A6: (-) Retained for book growth | B6: =-B5*(1-Assumptions!$B$24) -> -2833.4812 | C6: =-C5*(1-Assumptions!$B$24) -> -4110.4368 | D6: =-D5*(1-Assumptions!$C$24) -> -4457.5404 | E6: =-E5*(1-Assumptions!$C$24) -> -5693.0657 | F6: =-F5*(1-Assumptions!$C$24) -> -7045.1687
A7: Free cash flow to equity (FCFE) | B7: =B5+B6 -> 0 | C7: =C5+C6 -> 0 | D7: =D5+D6 -> 1114.3851 | E7: =E5+E6 -> 1423.2664 | F7: =F5+F6 -> 1761.2922
A8: Terminal value (8.0x 2030E NPAT&MI) | G8: =F5*Assumptions!B23 -> 70451.687
A9: Discount factor @ COE | B9: =1/(1+Assumptions!$B$22)^1 -> 0.81300813 | C9: =1/(1+Assumptions!$B$22)^2 -> 0.66098222 | D9: =1/(1+Assumptions!$B$22)^3 -> 0.53738392 | E9: =1/(1+Assumptions!$B$22)^4 -> 0.43689749 | F9: =1/(1+Assumptions!$B$22)^5 -> 0.35520122 | G9: =F9 -> 0.35520122
A10: PV of FCFE / terminal | B10: =B7*B9 -> 0 | C10: =C7*C9 -> 0 | D10: =D7*D9 -> 598.85263 | E10: =E7*E9 -> 621.82153 | F10: =F7*F9 -> 625.61312 | G10: =G8*G9 -> 25024.525
A11: Equity value (S PV, EGP m) | B11: =SUM(B10:G10) -> 26870.812
A12: Value per share (EGP) | B12: =B11/Assumptions!B6 -> 2.50705
A14: Cost of equity (operative input) | B14: =Assumptions!B22 -> 0.23
A15: COE build (reference): 17.5% blended risk-free + 1.0 beta x 5.5% ERP = 23.0%; WACC = COE here because equity cash flows are discounted.
A17: Residual-income cross-check
A18: Book value, start of year | B18: ='Balance Sheet'!D14 -> 23253 | C18: ='Balance Sheet'!E14 -> 26086.481 | D18: ='Balance Sheet'!F14 -> 30196.918 | E18: ='Balance Sheet'!G14 -> 34654.458 | F18: ='Balance Sheet'!H14 -> 40347.524
A19: ROE on opening book | B19: =B5/B18 -> 0.12185444 | C19: =C5/C18 -> 0.15756961 | D19: =D5/D18 -> 0.18451967 | E19: =E5/E18 -> 0.20535113 | F19: =F5/F18 -> 0.21826521
A20: Residual income (NI - COE x book) | B20: =B5-Assumptions!$B$22*B18 -> -2514.7087 | C20: =C5-Assumptions!$B$22*C18 -> -1889.4539 | D20: =D5-Assumptions!$B$22*D18 -> -1373.3657 | E20: =E5-Assumptions!$B$22*E18 -> -854.19336 | F20: =F5-Assumptions!$B$22*F18 -> -473.4696
A21: PV of residual income | B21: =B20*B9 -> -2044.4787 | C21: =C20*C9 -> -1248.8954 | D21: =D20*D9 -> -738.02465 | E21: =E20*E9 -> -373.19494 | F21: =F20*F9 -> -168.17698
A22: RI value = opening book + S PV(RI) + PV(terminal premium) | B22: =B18+SUM(B21:F21)+(G10-F18*F9) -> 29373.265
A23: RI value per share (EGP) | B23: =B22/Assumptions!B6 -> 2.7405291
A25: The RI construction lands modestly higher (2.74 vs 2.51) because it credits book compounding above COE explicitly; we take the
A26: more conservative FCFE construction as the section 1.2 base. Near-term RI is negative (ROE 11-15% vs a 23% COE): the case is back-loaded, which is why section 1.7 is the crux.

Sheet Income Statement
A1: Income statement — consolidated (EGP m)
A2: 3 years historical (company disclosure; lines marked (est.) reconcile to disclosed anchors) + 5-year forecast.
A4: EGP m | B4: FY2023 | C4: FY2024 | D4: FY2025 | E4: 2026E | F4: 2027E | G4: 2028E | H4: 2029E | I4: 2030E
A5: Operating revenue | B5: 1800 | C5: 7200 | D5: 12800 | E5: =Assumptions!B32 -> 29000 | F5: =E5*(1+Assumptions!C32) -> 37120 | G5: =F5*(1+Assumptions!D32) -> 45286.4 | H5: =G5*(1+Assumptions!E32) -> 53437.952 | I5: =H5*(1+Assumptions!F32) -> 61453.645
A6: Net operating profit (est. hist.) | B6: 700 | C6: 2700 | D6: 4400 | E6: =E5*Assumptions!B33 -> 5510 | F6: =F5*Assumptions!C33 -> 7609.6 | G6: =G5*Assumptions!D33 -> 9963.008 | H6: =H5*Assumptions!E33 -> 12290.729 | I6: =I5*Assumptions!F33 -> 14748.875
A7: Finance & central costs, net (est. hist.) | B7: -250 | C7: -800 | D7: -1900 | E7: =E5*Assumptions!B34 -> -1595 | F7: =F5*Assumptions!C34 -> -1930.24 | G7: =G5*Assumptions!D34 -> -2264.32 | H7: =H5*Assumptions!E34 -> -2458.1458 | I7: =I5*Assumptions!F34 -> -2581.0531
A8: Recurring profit before tax | B8: =B6+B7 -> 450 | C8: =C6+C7 -> 1900 | D8: =D6+D7 -> 2500 | E8: =E6+E7 -> 3915 | F8: =F6+F7 -> 5679.36 | G8: =G6+G7 -> 7698.688 | H8: =H6+H7 -> 9832.5832 | I8: =I6+I7 -> 12167.822
A9: FX & non-recurring items (est. hist.) | B9: 50 | C9: 700 | D9: -700 | E9: =Assumptions!B35 -> 0 | F9: =Assumptions!C35 -> 0 | G9: =Assumptions!D35 -> 0 | H9: =Assumptions!E35 -> 0 | I9: =Assumptions!F35 -> 0
A10: Profit before tax | B10: =B8+B9 -> 500 | C10: =C8+C9 -> 2600 | D10: =D8+D9 -> 1800 | E10: =E8+E9 -> 3915 | F10: =F8+F9 -> 5679.36 | G10: =G8+G9 -> 7698.688 | H10: =H8+H9 -> 9832.5832 | I10: =I8+I9 -> 12167.822
A11: Income tax (est. hist.) | B11: -110 | C11: -700 | D11: -350 | E11: =-E10*Assumptions!B36 -> -978.75 | F11: =-F10*Assumptions!C36 -> -1419.84 | G11: =-G10*Assumptions!D36 -> -1924.672 | H11: =-H10*Assumptions!E36 -> -2458.1458 | I11: =-I10*Assumptions!F36 -> -3041.9554
A12: Net profit after tax | B12: =B10+B11 -> 390 | C12: =C10+C11 -> 1900 | D12: =D10+D11 -> 1450 | E12: =E10+E11 -> 2936.25 | F12: =F10+F11 -> 4259.52 | G12: =G10+G11 -> 5774.016 | H12: =H10+H11 -> 7374.4374 | I12: =I10+I11 -> 9125.8663
A13: Minority interest (est. hist.) | B13: -21 | C13: -198 | D13: -103 | E13: =-E12*Assumptions!B37 -> -102.76875 | F13: =-F12*Assumptions!C37 -> -149.0832 | G13: =-G12*Assumptions!D37 -> -202.09056 | H13: =-H12*Assumptions!E37 -> -258.10531 | I13: =-I12*Assumptions!F37 -> -319.40532
A14: Net profit after tax & minority | B14: =B12+B13 -> 369 | C14: =C12+C13 -> 1702 | D14: =D12+D13 -> 1347 | E14: =E12+E13 -> 2833.4812 | F14: =F12+F13 -> 4110.4368 | G14: =G12+G13 -> 5571.9254 | H14: =H12+H13 -> 7116.3321 | I14: =I12+I13 -> 8806.4609
A15: Basic EPS (EGP) | B15: 0.07 | C15: 0.31 | D15: 0.146 | E15: =E14/Assumptions!$B$6 -> 0.26436414 | F15: =F14/Assumptions!$B$6 -> 0.38350424 | G15: =G14/Assumptions!$B$6 -> 0.5198613 | H15: =H14/Assumptions!$B$6 -> 0.66395463 | I15: =I14/Assumptions!$B$6 -> 0.82164385
A16: Revenue growth | B16: n/m | C16: =C5/B5-1 -> 3 | D16: =D5/C5-1 -> 0.77777778 | E16: =E5/D5-1 -> 1.265625 | F16: =F5/E5-1 -> 0.28 | G16: =G5/F5-1 -> 0.22 | H16: =H5/G5-1 -> 0.18 | I16: =I5/H5-1 -> 0.15
A17: NPAT&MI margin | B17: =B14/B5 -> 0.205 | C17: =C14/C5 -> 0.23638889 | D17: =D14/D5 -> 0.10523438 | E17: =E14/E5 -> 0.09770625 | F17: =F14/F5 -> 0.11073375 | G17: =G14/G5 -> 0.1230375 | H17: =H14/H5 -> 0.13317 | I17: =I14/I5 -> 0.1433025
A19: Disclosed anchors: FY2023 NPAT&MI EGP 369m; FY2024 op. revenue EGP 7.2bn, recurring PBT EGP 1.9bn, NPAT&MI EGP 1,702m;
A20: FY2025 op. revenue EGP 12.8bn, recurring PBT EGP 2.5bn, NPAT&MI EGP 1,347m (FX loss on USD long). Source: company earnings releases.

Sheet Balance Sheet
A1: Balance sheet — consolidated (EGP m)
A2: Historical per FY statements (aggregated); Baobab consolidates from 2026. Borrowings are the balancing item in forecast.
A4: EGP m | B4: FY2023 | C4: FY2024 | D4: FY2025 | E4: 2026E | F4: 2027E | G4: 2028E | H4: 2029E | I4: 2030E
A5: Cash & equivalents | B5: 3343 | C5: 3457 | D5: 8099 | E5: =E8*Assumptions!B41 -> 11600 | F5: =F8*Assumptions!C41 -> 14152 | G5: =G8*Assumptions!D41 -> 16840.88 | H5: =H8*Assumptions!E41 -> 19535.421 | I5: =I8*Assumptions!F41 -> 22270.38
A6: Net lending portfolio (gross hist.) | B6: 12400 | C6: 26100 | D6: 38600 | E6: =Assumptions!B39 -> 105000 | F6: =E6*(1+Assumptions!C39) -> 130200 | G6: =F6*(1+Assumptions!D39) -> 156240 | H6: =G6*(1+Assumptions!E39) -> 182800.8 | I6: =H6*(1+Assumptions!F39) -> 210220.92
A7: Other assets (plug) | B7: =B8-B5-B6 -> 2542 | C7: =C8-C5-C6 -> 4190 | D7: =D8-D5-D6 -> 6325 | E7: =E8-E5-E6 -> 28400 | F7: =F8-F5-F6 -> 32548 | G7: =G8-G5-G6 -> 37430.12 | H7: =H8-H5-H6 -> 41856.539 | I7: =I8-I5-I6 -> 45888.447
A8: Total assets | B8: 18285 | C8: 33747 | D8: 53024 | E8: =Assumptions!B38 -> 145000 | F8: =E8*(1+Assumptions!C38) -> 176900 | G8: =F8*(1+Assumptions!D38) -> 210511 | H8: =G8*(1+Assumptions!E38) -> 244192.76 | I8: =H8*(1+Assumptions!F38) -> 278379.75
A10: Customer deposits (Baobab) | B10: 0 | C10: 0 | D10: 0 | E10: =Assumptions!B40 -> 30000 | F10: =E10*(1+Assumptions!C40) -> 36000 | G10: =F10*(1+Assumptions!D40) -> 43200 | H10: =G10*(1+Assumptions!E40) -> 50976 | I10: =H10*(1+Assumptions!F40) -> 59132.16
A11: Borrowings & debt (forecast = balancing) | B11: 6058 | C11: 12263 | D11: 15940 | E11: =E8-E15-E10-E12 -> 71164.75 | F11: =F8-F15-F10-F12 -> 88977.23 | G11: =G8-G15-G10-G12 -> 106695.28 | H11: =H8-H15-H10-H12 -> 122608.06 | I11: =I8-I15-I10-I12 -> 137171.87
A12: Other liabilities | B12: 1755 | C12: 9011 | D12: 13585 | E12: =E8*Assumptions!B42 -> 17400 | F12: =F8*Assumptions!C42 -> 21228 | G12: =G8*Assumptions!D42 -> 25261.32 | H12: =H8*Assumptions!E42 -> 29303.131 | I12: =I8*Assumptions!F42 -> 33405.57
A13: Total liabilities | B13: =B10+B11+B12 -> 7813 | C13: =C10+C11+C12 -> 21274 | D13: =D10+D11+D12 -> 29525 | E13: =E10+E11+E12 -> 118564.75 | F13: =F10+F11+F12 -> 146205.23 | G13: =G10+G11+G12 -> 175156.6 | H13: =H10+H11+H12 -> 202887.19 | I13: =I10+I11+I12 -> 229709.6
A14: Attributable equity | B14: 10366 | C14: 12290 | D14: 23253 | E14: =D14+'Income Statement'!E14 -> 26086.481 | F14: =E14+'Income Statement'!F14 -> 30196.918 | G14: =F14+'Income Statement'!G14*(1-Assumptions!$C$24) -> 34654.458 | H14: =G14+'Income Statement'!H14*(1-Assumptions!$C$24) -> 40347.524 | I14: =H14+'Income Statement'!I14*(1-Assumptions!$C$24) -> 47392.693
A15: Total equity (incl. minority) | B15: =B14+B16 -> 10472 | C15: =C14+C16 -> 12473 | D15: =D14+D16 -> 23499 | E15: =E14+E16 -> 26435.25 | F15: =F14+F16 -> 30694.77 | G15: =G14+G16 -> 35354.401 | H15: =H14+H16 -> 41305.572 | I15: =I14+I16 -> 48670.146
A16: Minority interest | B16: 106 | C16: 183 | D16: 246 | E16: =D16-'Income Statement'!E13 -> 348.76875 | F16: =E16-'Income Statement'!F13 -> 497.85195 | G16: =F16-'Income Statement'!G13 -> 699.94251 | H16: =G16-'Income Statement'!H13 -> 958.04782 | I16: =H16-'Income Statement'!I13 -> 1277.4531
A17: Balance check (assets − liab − equity) | B17: =B8-B13-B15 -> 0 | C17: =C8-C13-C15 -> 0 | D17: =D8-D13-D15 -> 0 | E17: =E8-E13-E15 -> 0 | F17: =F8-F13-F15 -> 0 | G17: =G8-G13-G15 -> 0 | H17: =H8-H13-H15 -> 0 | I17: =I8-I13-I15 -> 0
A18: Book value per share (EGP) | B18: =B14/Assumptions!$B$6 -> 0.96714903 | C18: =C14/Assumptions!$B$6 -> 1.1466585 | D18: =D14/Assumptions!$B$6 -> 2.1695077 | E18: =E14/Assumptions!$B$6 -> 2.4338718 | F18: =F14/Assumptions!$B$6 -> 2.817376 | G18: =G14/Assumptions!$B$6 -> 3.2332651 | H18: =H14/Assumptions!$B$6 -> 3.7644288 | I18: =I14/Assumptions!$B$6 -> 4.4217439
A20: Historical totals: FY2023/24/25 assets 18,285 / 33,747 / 53,024; equity (incl. MI) 10,472 / 12,473 / 23,499; issued capital
A21: EGP 10,927m (2023–24) and 21,436m (2025). Hist. portfolio shown gross per releases. Sources: FY statements via public aggregation, EGX disclosures.

Sheet Cash Flow
A1: Cash flow — financial-holding presentation (EGP m)
A2: Portfolio growth is the investing use; deposits/borrowings the funding source. 'Other' plugs to the BS cash movement.
A4: EGP m | B4: FY2024 | C4: FY2025 | D4: 2026E | E4: 2027E | F4: 2028E | G4: 2029E | H4: 2030E
A5: Net profit after tax | B5: ='Income Statement'!C12 -> 1900 | C5: ='Income Statement'!D12 -> 1450 | D5: ='Income Statement'!E12 -> 2936.25 | E5: ='Income Statement'!F12 -> 4259.52 | F5: ='Income Statement'!G12 -> 5774.016 | G5: ='Income Statement'!H12 -> 7374.4374 | H5: ='Income Statement'!I12 -> 9125.8663
A6: Increase in net lending portfolio | B6: =-('Balance Sheet'!C6-'Balance Sheet'!B6) -> -13700 | C6: =-('Balance Sheet'!D6-'Balance Sheet'!C6) -> -12500 | D6: =-('Balance Sheet'!E6-'Balance Sheet'!D6) -> -66400 | E6: =-('Balance Sheet'!F6-'Balance Sheet'!E6) -> -25200 | F6: =-('Balance Sheet'!G6-'Balance Sheet'!F6) -> -26040 | G6: =-('Balance Sheet'!H6-'Balance Sheet'!G6) -> -26560.8 | H6: =-('Balance Sheet'!I6-'Balance Sheet'!H6) -> -27420.12
A7: Increase in customer deposits | B7: ='Balance Sheet'!C10-'Balance Sheet'!B10 -> 0 | C7: ='Balance Sheet'!D10-'Balance Sheet'!C10 -> 0 | D7: ='Balance Sheet'!E10-'Balance Sheet'!D10 -> 30000 | E7: ='Balance Sheet'!F10-'Balance Sheet'!E10 -> 6000 | F7: ='Balance Sheet'!G10-'Balance Sheet'!F10 -> 7200 | G7: ='Balance Sheet'!H10-'Balance Sheet'!G10 -> 7776 | H7: ='Balance Sheet'!I10-'Balance Sheet'!H10 -> 8156.16
A8: Increase in borrowings & debt | B8: ='Balance Sheet'!C11-'Balance Sheet'!B11 -> 6205 | C8: ='Balance Sheet'!D11-'Balance Sheet'!C11 -> 3677 | D8: ='Balance Sheet'!E11-'Balance Sheet'!D11 -> 55224.75 | E8: ='Balance Sheet'!F11-'Balance Sheet'!E11 -> 17812.48 | F8: ='Balance Sheet'!G11-'Balance Sheet'!F11 -> 17718.049 | G8: ='Balance Sheet'!H11-'Balance Sheet'!G11 -> 15912.778 | H8: ='Balance Sheet'!I11-'Balance Sheet'!H11 -> 14563.814
A9: Rights issues (paid-in capital) | B9: 0 | C9: 0 | D9: 10510 | E9: 0 | F9: 0 | G9: 0 | H9: 0
A10: Dividends paid | B10: 0 | C10: 0 | D10: 0 | E10: =-'Income Statement'!F14*Assumptions!$C$24 -> -822.08736 | F10: =-'Income Statement'!G14*Assumptions!$C$24 -> -1114.3851 | G10: =-'Income Statement'!H14*Assumptions!$C$24 -> -1423.2664 | H10: =-'Income Statement'!I14*Assumptions!$C$24 -> -1761.2922
A11: Other operating, FX & consolidation (plug) | B11: =B13-SUM(B5:B10) -> 5709 | C11: =C13-SUM(C5:C10) -> 12015 | D11: =D13-SUM(D5:D10) -> -28770 | E11: =E13-SUM(E5:E10) -> 502.08736 | F11: =F13-SUM(F5:F10) -> -848.8 | G11: =G13-SUM(G5:G10) -> -384.608 | H11: =H13-SUM(H5:H10) -> 70.53088
A12: Cash, beginning of period | B12: ='Balance Sheet'!B5 -> 3343 | C12: ='Balance Sheet'!C5 -> 3457 | D12: ='Balance Sheet'!D5 -> 8099 | E12: ='Balance Sheet'!E5 -> 11600 | F12: ='Balance Sheet'!F5 -> 14152 | G12: ='Balance Sheet'!G5 -> 16840.88 | H12: ='Balance Sheet'!H5 -> 19535.421
A13: Net change in cash | B13: ='Balance Sheet'!C5-'Balance Sheet'!B5 -> 114 | C13: ='Balance Sheet'!D5-'Balance Sheet'!C5 -> 4642 | D13: ='Balance Sheet'!E5-'Balance Sheet'!D5 -> 3501 | E13: ='Balance Sheet'!F5-'Balance Sheet'!E5 -> 2552 | F13: ='Balance Sheet'!G5-'Balance Sheet'!F5 -> 2688.88 | G13: ='Balance Sheet'!H5-'Balance Sheet'!G5 -> 2694.5408 | H13: ='Balance Sheet'!I5-'Balance Sheet'!H5 -> 2734.9589
A14: Cash, end of period | B14: =B12+B13 -> 3457 | C14: =C12+C13 -> 8099 | D14: =D12+D13 -> 11600 | E14: =E12+E13 -> 14152 | F14: =F12+F13 -> 16840.88 | G14: =G12+G13 -> 19535.421 | H14: =H12+H13 -> 22270.38
A16: 2025 'Other' absorbs FX/other comprehensive losses (~EGP −0.7bn) and working-capital swings; 2026 absorbs Baobab first-time consolidation.

Sheet Summary Financials
A1: Summary financials — every cell links to the statement sheets
A4: EGP m | B4: FY2023 | C4: FY2024 | D4: FY2025 | E4: 2026E | F4: 2027E | G4: 2028E | H4: 2029E | I4: 2030E
A5: Operating revenue | B5: ='Income Statement'!B5 -> 1800 | C5: ='Income Statement'!C5 -> 7200 | D5: ='Income Statement'!D5 -> 12800 | E5: ='Income Statement'!E5 -> 29000 | F5: ='Income Statement'!F5 -> 37120 | G5: ='Income Statement'!G5 -> 45286.4 | H5: ='Income Statement'!H5 -> 53437.952 | I5: ='Income Statement'!I5 -> 61453.645
A6: Recurring profit before tax | B6: ='Income Statement'!B8 -> 450 | C6: ='Income Statement'!C8 -> 1900 | D6: ='Income Statement'!D8 -> 2500 | E6: ='Income Statement'!E8 -> 3915 | F6: ='Income Statement'!F8 -> 5679.36 | G6: ='Income Statement'!G8 -> 7698.688 | H6: ='Income Statement'!H8 -> 9832.5832 | I6: ='Income Statement'!I8 -> 12167.822
A7: NPAT & minority | B7: ='Income Statement'!B14 -> 369 | C7: ='Income Statement'!C14 -> 1702 | D7: ='Income Statement'!D14 -> 1347 | E7: ='Income Statement'!E14 -> 2833.4812 | F7: ='Income Statement'!F14 -> 4110.4368 | G7: ='Income Statement'!G14 -> 5571.9254 | H7: ='Income Statement'!H14 -> 7116.3321 | I7: ='Income Statement'!I14 -> 8806.4609
A8: Basic EPS (EGP) | B8: ='Income Statement'!B15 -> 0.07 | C8: ='Income Statement'!C15 -> 0.31 | D8: ='Income Statement'!D15 -> 0.146 | E8: ='Income Statement'!E15 -> 0.26436414 | F8: ='Income Statement'!F15 -> 0.38350424 | G8: ='Income Statement'!G15 -> 0.5198613 | H8: ='Income Statement'!H15 -> 0.66395463 | I8: ='Income Statement'!I15 -> 0.82164385
A9: Total assets | B9: ='Balance Sheet'!B8 -> 18285 | C9: ='Balance Sheet'!C8 -> 33747 | D9: ='Balance Sheet'!D8 -> 53024 | E9: ='Balance Sheet'!E8 -> 145000 | F9: ='Balance Sheet'!F8 -> 176900 | G9: ='Balance Sheet'!G8 -> 210511 | H9: ='Balance Sheet'!H8 -> 244192.76 | I9: ='Balance Sheet'!I8 -> 278379.75
A10: Net lending portfolio | B10: ='Balance Sheet'!B6 -> 12400 | C10: ='Balance Sheet'!C6 -> 26100 | D10: ='Balance Sheet'!D6 -> 38600 | E10: ='Balance Sheet'!E6 -> 105000 | F10: ='Balance Sheet'!F6 -> 130200 | G10: ='Balance Sheet'!G6 -> 156240 | H10: ='Balance Sheet'!H6 -> 182800.8 | I10: ='Balance Sheet'!I6 -> 210220.92
A11: Borrowings & debt | B11: ='Balance Sheet'!B11 -> 6058 | C11: ='Balance Sheet'!C11 -> 12263 | D11: ='Balance Sheet'!D11 -> 15940 | E11: ='Balance Sheet'!E11 -> 71164.75 | F11: ='Balance Sheet'!F11 -> 88977.23 | G11: ='Balance Sheet'!G11 -> 106695.28 | H11: ='Balance Sheet'!H11 -> 122608.06 | I11: ='Balance Sheet'!I11 -> 137171.87
A12: Attributable equity | B12: ='Balance Sheet'!B14 -> 10366 | C12: ='Balance Sheet'!C14 -> 12290 | D12: ='Balance Sheet'!D14 -> 23253 | E12: ='Balance Sheet'!E14 -> 26086.481 | F12: ='Balance Sheet'!F14 -> 30196.918 | G12: ='Balance Sheet'!G14 -> 34654.458 | H12: ='Balance Sheet'!H14 -> 40347.524 | I12: ='Balance Sheet'!I14 -> 47392.693
A13: Book value per share (EGP) | B13: ='Balance Sheet'!B18 -> 0.96714903 | C13: ='Balance Sheet'!C18 -> 1.1466585 | D13: ='Balance Sheet'!D18 -> 2.1695077 | E13: ='Balance Sheet'!E18 -> 2.4338718 | F13: ='Balance Sheet'!F18 -> 2.817376 | G13: ='Balance Sheet'!G18 -> 3.2332651 | H13: ='Balance Sheet'!H18 -> 3.7644288 | I13: ='Balance Sheet'!I18 -> 4.4217439
A14: Attributable ROE (avg. book) | B14: n/m | C14: ='Income Statement'!C14/(('Balance Sheet'!B14+'Balance Sheet'!C14)/2) -> 0.15024718 | D14: ='Income Statement'!D14/(('Balance Sheet'!C14+'Balance Sheet'!D14)/2) -> 0.075795515 | E14: ='Income Statement'!E14/(('Balance Sheet'!D14+'Balance Sheet'!E14)/2) -> 0.11485655 | F14: ='Income Statement'!F14/(('Balance Sheet'!E14+'Balance Sheet'!F14)/2) -> 0.14606214 | G14: ='Income Statement'!G14/(('Balance Sheet'!F14+'Balance Sheet'!G14)/2) -> 0.17183677 | H14: ='Income Statement'!H14/(('Balance Sheet'!G14+'Balance Sheet'!H14)/2) -> 0.18976384 | I14: ='Income Statement'!I14/(('Balance Sheet'!H14+'Balance Sheet'!I14)/2) -> 0.20073944

Sheet Monte Carlo
A1: Monte Carlo — three-month probabilistic price map
A2: 50,000 paths, seed 42; YZ-HAR width, Student-t(5) innovations, drift OFF (EGX non-developer class, Step 0). Simulation outputs from mc_v2.py.
A4: Engine parameter | B4: Value
A5: Anchor (spot, 1 Jul 2026) | B5: 2.97
A6: HAR-forecast daily σ | B6: 0.0244
A7: Annualized σ (HAR) | B7: 0.388
A8: 60-session horizon σ | B8: 0.189
A9: Trailing 252d close-close vol (benchmark) | B9: 0.345
A10: Net continuous drift (7 factors, 3M) | B10: 0.02
A11: Σ prob × mean impact (9 events) | B11: -0.0255
A12: Simulated annualized path vol (events widen) | B12: 0.452
A13: Paths / seed | B13: 50000
A15: Percentile map (EGP/share) | B15: p5 | C15: p25 | D15: p50 | E15: p75 | F15: p95
A16: T+20 sessions | B16: 2.39 | C16: 2.74 | D16: 2.95 | E16: 3.17 | F16: 3.58
A17: T+60 sessions | B17: 2.04 | C17: 2.53 | D17: 2.89 | E17: 3.29 | F17: 4.04
A19: Level-touch ladder | B19: T+20 touch | C19: T+60 touch | D19: Note
A20: EGP 3.80 | B20: 0.03 | C20: 0.16 | D20: Above the 52-wk high 3.79
A21: EGP 3.50 | B21: 0.11 | C21: 0.31 | D21: Toward the normalized lens
A22: EGP 3.30 | B22: 0.26 | C22: 0.48 | D22: Upper band
A23: EGP 3.10 | B23: 0.57 | C23: 0.73 | D23: Just above spot
A24: EGP 2.80 | B24: 0.51 | C24: 0.73 | D24: Just below spot
A25: EGP 2.60 | B25: 0.22 | C25: 0.49 | D25: Toward the 52-wk low 2.65
A26: EGP 2.40 | B26: 0.08 | C26: 0.29 | D26: Below the 52-wk low
A27: EGP 2.10 | B27: 0.01 | C27: 0.11 | D27: Deep downside / bear lens zone
A29: Probability zones (T+60) | B29: Range | C29: Probability
A30: Deep downside | B30: < 2.40 | C30: 0.17
A31: Lower band | B31: 2.40 – 2.80 | C31: 0.26
A32: Around spot | B32: 2.80 – 3.20 | C32: 0.27
A33: Upper band | B33: 3.20 – 3.60 | C33: 0.16
A34: Strong upside | B34: > 3.60 | C34: 0.13
A36: Lens independence: paths diffuse from spot; the §1 fundamental value gap is deliberately kept out of the drift.

Sheet Sensitivity
A1: Sensitivity — the two grids that carry the answer
A2: Grid 1: justified P/B on sustainable ROE × COE (× BVPS). Grid 2: SOTP per share on the complexity discount × the Baobab mark.
A4: Justified value per share (EGP) — g = 15%
A5: COE \ ROE | B5: 12% | C5: 15% | D5: 18% | E5: 21% | F5: 24%
A6: 26% | B6: =MAX((0.12-Assumptions!$B$25)/(0.26-Assumptions!$B$25),0.35)*'Balance Sheet'!$D$18 -> 0.75932768 | C6: =MAX((0.15-Assumptions!$B$25)/(0.26-Assumptions!$B$25),0.35)*'Balance Sheet'!$D$18 -> 0.75932768 | D6: =MAX((0.18-Assumptions!$B$25)/(0.26-Assumptions!$B$25),0.35)*'Balance Sheet'!$D$18 -> 0.75932768 | E6: =MAX((0.21-Assumptions!$B$25)/(0.26-Assumptions!$B$25),0.35)*'Balance Sheet'!$D$18 -> 1.1833678 | F6: =MAX((0.24-Assumptions!$B$25)/(0.26-Assumptions!$B$25),0.35)*'Balance Sheet'!$D$18 -> 1.7750517
A7: 24% | B7: =MAX((0.12-Assumptions!$B$25)/(0.24-Assumptions!$B$25),0.35)*'Balance Sheet'!$D$18 -> 0.75932768 | C7: =MAX((0.15-Assumptions!$B$25)/(0.24-Assumptions!$B$25),0.35)*'Balance Sheet'!$D$18 -> 0.75932768 | D7: =MAX((0.18-Assumptions!$B$25)/(0.24-Assumptions!$B$25),0.35)*'Balance Sheet'!$D$18 -> 0.75932768 | E7: =MAX((0.21-Assumptions!$B$25)/(0.24-Assumptions!$B$25),0.35)*'Balance Sheet'!$D$18 -> 1.4463384 | F7: =MAX((0.24-Assumptions!$B$25)/(0.24-Assumptions!$B$25),0.35)*'Balance Sheet'!$D$18 -> 2.1695077
A8: 22% | B8: =MAX((0.12-Assumptions!$B$25)/(0.22-Assumptions!$B$25),0.35)*'Balance Sheet'!$D$18 -> 0.75932768 | C8: =MAX((0.15-Assumptions!$B$25)/(0.22-Assumptions!$B$25),0.35)*'Balance Sheet'!$D$18 -> 0.75932768 | D8: =MAX((0.18-Assumptions!$B$25)/(0.22-Assumptions!$B$25),0.35)*'Balance Sheet'!$D$18 -> 0.929789 | E8: =MAX((0.21-Assumptions!$B$25)/(0.22-Assumptions!$B$25),0.35)*'Balance Sheet'!$D$18 -> 1.859578 | F8: =MAX((0.24-Assumptions!$B$25)/(0.22-Assumptions!$B$25),0.35)*'Balance Sheet'!$D$18 -> 2.789367
A9: 20% | B9: =MAX((0.12-Assumptions!$B$25)/(0.2-Assumptions!$B$25),0.35)*'Balance Sheet'!$D$18 -> 0.75932768 | C9: =MAX((0.15-Assumptions!$B$25)/(0.2-Assumptions!$B$25),0.35)*'Balance Sheet'!$D$18 -> 0.75932768 | D9: =MAX((0.18-Assumptions!$B$25)/(0.2-Assumptions!$B$25),0.35)*'Balance Sheet'!$D$18 -> 1.3017046 | E9: =MAX((0.21-Assumptions!$B$25)/(0.2-Assumptions!$B$25),0.35)*'Balance Sheet'!$D$18 -> 2.6034092 | F9: =MAX((0.24-Assumptions!$B$25)/(0.2-Assumptions!$B$25),0.35)*'Balance Sheet'!$D$18 -> 3.9051138
A11: SOTP value per share (EGP) — discount × Baobab P/B mark
A12: Discount \ Baobab P/B | B12: 0.60x | C12: 0.80x | D12: 1.00x | E12: 1.20x | F12: 1.40x
A13: 0% | B13: =((Assumptions!$B$14*Assumptions!$C$14+Assumptions!$B$15*Assumptions!$C$15+Assumptions!$B$16*0.6+Assumptions!$B$17*Assumptions!$C$17)*(1-0))/Assumptions!$B$6 -> 2.6842444 | C13: =((Assumptions!$B$14*Assumptions!$C$14+Assumptions!$B$15*Assumptions!$C$15+Assumptions!$B$16*0.8+Assumptions!$B$17*Assumptions!$C$17)*(1-0))/Assumptions!$B$6 -> 2.8428546 | D13: =((Assumptions!$B$14*Assumptions!$C$14+Assumptions!$B$15*Assumptions!$C$15+Assumptions!$B$16*1+Assumptions!$B$17*Assumptions!$C$17)*(1-0))/Assumptions!$B$6 -> 3.0014648 | E13: =((Assumptions!$B$14*Assumptions!$C$14+Assumptions!$B$15*Assumptions!$C$15+Assumptions!$B$16*1.2+Assumptions!$B$17*Assumptions!$C$17)*(1-0))/Assumptions!$B$6 -> 3.160075 | F13: =((Assumptions!$B$14*Assumptions!$C$14+Assumptions!$B$15*Assumptions!$C$15+Assumptions!$B$16*1.4+Assumptions!$B$17*Assumptions!$C$17)*(1-0))/Assumptions!$B$6 -> 3.3186852
A14: 5% | B14: =((Assumptions!$B$14*Assumptions!$C$14+Assumptions!$B$15*Assumptions!$C$15+Assumptions!$B$16*0.6+Assumptions!$B$17*Assumptions!$C$17)*(1-0.05))/Assumptions!$B$6 -> 2.5500322 | C14: =((Assumptions!$B$14*Assumptions!$C$14+Assumptions!$B$15*Assumptions!$C$15+Assumptions!$B$16*0.8+Assumptions!$B$17*Assumptions!$C$17)*(1-0.05))/Assumptions!$B$6 -> 2.7007119 | D14: =((Assumptions!$B$14*Assumptions!$C$14+Assumptions!$B$15*Assumptions!$C$15+Assumptions!$B$16*1+Assumptions!$B$17*Assumptions!$C$17)*(1-0.05))/Assumptions!$B$6 -> 2.8513916 | E14: =((Assumptions!$B$14*Assumptions!$C$14+Assumptions!$B$15*Assumptions!$C$15+Assumptions!$B$16*1.2+Assumptions!$B$17*Assumptions!$C$17)*(1-0.05))/Assumptions!$B$6 -> 3.0020713 | F14: =((Assumptions!$B$14*Assumptions!$C$14+Assumptions!$B$15*Assumptions!$C$15+Assumptions!$B$16*1.4+Assumptions!$B$17*Assumptions!$C$17)*(1-0.05))/Assumptions!$B$6 -> 3.152751
A15: 10% | B15: =((Assumptions!$B$14*Assumptions!$C$14+Assumptions!$B$15*Assumptions!$C$15+Assumptions!$B$16*0.6+Assumptions!$B$17*Assumptions!$C$17)*(1-0.1))/Assumptions!$B$6 -> 2.41582 | C15: =((Assumptions!$B$14*Assumptions!$C$14+Assumptions!$B$15*Assumptions!$C$15+Assumptions!$B$16*0.8+Assumptions!$B$17*Assumptions!$C$17)*(1-0.1))/Assumptions!$B$6 -> 2.5585691 | D15: =((Assumptions!$B$14*Assumptions!$C$14+Assumptions!$B$15*Assumptions!$C$15+Assumptions!$B$16*1+Assumptions!$B$17*Assumptions!$C$17)*(1-0.1))/Assumptions!$B$6 -> 2.7013183 | E15: =((Assumptions!$B$14*Assumptions!$C$14+Assumptions!$B$15*Assumptions!$C$15+Assumptions!$B$16*1.2+Assumptions!$B$17*Assumptions!$C$17)*(1-0.1))/Assumptions!$B$6 -> 2.8440675 | F15: =((Assumptions!$B$14*Assumptions!$C$14+Assumptions!$B$15*Assumptions!$C$15+Assumptions!$B$16*1.4+Assumptions!$B$17*Assumptions!$C$17)*(1-0.1))/Assumptions!$B$6 -> 2.9868167
A16: 15% | B16: =((Assumptions!$B$14*Assumptions!$C$14+Assumptions!$B$15*Assumptions!$C$15+Assumptions!$B$16*0.6+Assumptions!$B$17*Assumptions!$C$17)*(1-0.15))/Assumptions!$B$6 -> 2.2816077 | C16: =((Assumptions!$B$14*Assumptions!$C$14+Assumptions!$B$15*Assumptions!$C$15+Assumptions!$B$16*0.8+Assumptions!$B$17*Assumptions!$C$17)*(1-0.15))/Assumptions!$B$6 -> 2.4164264 | D16: =((Assumptions!$B$14*Assumptions!$C$14+Assumptions!$B$15*Assumptions!$C$15+Assumptions!$B$16*1+Assumptions!$B$17*Assumptions!$C$17)*(1-0.15))/Assumptions!$B$6 -> 2.5512451 | E16: =((Assumptions!$B$14*Assumptions!$C$14+Assumptions!$B$15*Assumptions!$C$15+Assumptions!$B$16*1.2+Assumptions!$B$17*Assumptions!$C$17)*(1-0.15))/Assumptions!$B$6 -> 2.6860638 | F16: =((Assumptions!$B$14*Assumptions!$C$14+Assumptions!$B$15*Assumptions!$C$15+Assumptions!$B$16*1.4+Assumptions!$B$17*Assumptions!$C$17)*(1-0.15))/Assumptions!$B$6 -> 2.8208824
A17: 20% | B17: =((Assumptions!$B$14*Assumptions!$C$14+Assumptions!$B$15*Assumptions!$C$15+Assumptions!$B$16*0.6+Assumptions!$B$17*Assumptions!$C$17)*(1-0.2))/Assumptions!$B$6 -> 2.1473955 | C17: =((Assumptions!$B$14*Assumptions!$C$14+Assumptions!$B$15*Assumptions!$C$15+Assumptions!$B$16*0.8+Assumptions!$B$17*Assumptions!$C$17)*(1-0.2))/Assumptions!$B$6 -> 2.2742837 | D17: =((Assumptions!$B$14*Assumptions!$C$14+Assumptions!$B$15*Assumptions!$C$15+Assumptions!$B$16*1+Assumptions!$B$17*Assumptions!$C$17)*(1-0.2))/Assumptions!$B$6 -> 2.4011718 | E17: =((Assumptions!$B$14*Assumptions!$C$14+Assumptions!$B$15*Assumptions!$C$15+Assumptions!$B$16*1.2+Assumptions!$B$17*Assumptions!$C$17)*(1-0.2))/Assumptions!$B$6 -> 2.52806 | F17: =((Assumptions!$B$14*Assumptions!$C$14+Assumptions!$B$15*Assumptions!$C$15+Assumptions!$B$16*1.4+Assumptions!$B$17*Assumptions!$C$17)*(1-0.2))/Assumptions!$B$6 -> 2.6549482
A19: Read grid 1 as the whole argument: at an 18% sustainable ROE and a 22% COE the shares are worth about book ×1 (~EGP 2.2–2.4);
A20: the market's 2.97 needs either ~21% ROE or a COE below 21% — i.e. it is already paying for most of the bridge.

Sheet Per-Share & Ratios
A1: Per-share values & ratios
A2: All formulas; multiples struck on the 1-Jul-2026 spot.
A4: Metric | B4: FY2023 | C4: FY2024 | D4: FY2025 | E4: 2026E | F4: 2027E | G4: 2028E | H4: 2029E | I4: 2030E
A5: EPS (EGP) | B5: ='Income Statement'!B15 -> 0.07 | C5: ='Income Statement'!C15 -> 0.31 | D5: ='Income Statement'!D15 -> 0.146 | E5: ='Income Statement'!E15 -> 0.26436414 | F5: ='Income Statement'!F15 -> 0.38350424 | G5: ='Income Statement'!G15 -> 0.5198613 | H5: ='Income Statement'!H15 -> 0.66395463 | I5: ='Income Statement'!I15 -> 0.82164385
A6: BVPS (EGP) | B6: ='Balance Sheet'!B18 -> 0.96714903 | C6: ='Balance Sheet'!C18 -> 1.1466585 | D6: ='Balance Sheet'!D18 -> 2.1695077 | E6: ='Balance Sheet'!E18 -> 2.4338718 | F6: ='Balance Sheet'!F18 -> 2.817376 | G6: ='Balance Sheet'!G18 -> 3.2332651 | H6: ='Balance Sheet'!H18 -> 3.7644288 | I6: ='Balance Sheet'!I18 -> 4.4217439
A7: DPS (EGP) | B7: 0 | C7: 0 | D7: 0 | E7: 0 | F7: ='Income Statement'!G14*Assumptions!$C$24/Assumptions!$B$6 -> 0.10397226 | G7: ='Income Statement'!H14*Assumptions!$C$24/Assumptions!$B$6 -> 0.13279093 | H7: ='Income Statement'!I14*Assumptions!$C$24/Assumptions!$B$6 -> 0.16432877
A8: P/E at spot | B8: =IF(B5=0,"n/m",Assumptions!$B$5/B5) -> 42.428571 | C8: =IF(C5=0,"n/m",Assumptions!$B$5/C5) -> 9.5806452 | D8: =IF(D5=0,"n/m",Assumptions!$B$5/D5) -> 20.342466 | E8: =IF(E5=0,"n/m",Assumptions!$B$5/E5) -> 11.234504 | F8: =IF(F5=0,"n/m",Assumptions!$B$5/F5) -> 7.7443733 | G8: =IF(G5=0,"n/m",Assumptions!$B$5/G5) -> 5.7130623 | H8: =IF(H5=0,"n/m",Assumptions!$B$5/H5) -> 4.4731972 | I8: =IF(I5=0,"n/m",Assumptions!$B$5/I5) -> 3.6147048
A9: P/B at spot | B9: =Assumptions!$B$5/B6 -> 3.0708814 | C9: =Assumptions!$B$5/C6 -> 2.5901348 | D9: =Assumptions!$B$5/D6 -> 1.3689742 | E9: =Assumptions!$B$5/E6 -> 1.2202779 | F9: =Assumptions!$B$5/F6 -> 1.0541724 | G9: =Assumptions!$B$5/G6 -> 0.91857609 | H9: =Assumptions!$B$5/H6 -> 0.78896432 | I9: =Assumptions!$B$5/I6 -> 0.6716807
A10: Attributable ROE (avg.) | B10: ='Summary Financials'!B14 -> n/m | C10: ='Summary Financials'!C14 -> 0.15024718 | D10: ='Summary Financials'!D14 -> 0.075795515 | E10: ='Summary Financials'!E14 -> 0.11485655 | F10: ='Summary Financials'!F14 -> 0.14606214 | G10: ='Summary Financials'!G14 -> 0.17183677 | H10: ='Summary Financials'!H14 -> 0.18976384 | I10: ='Summary Financials'!I14 -> 0.20073944
A11: Dividend yield at spot | B11: =B7/Assumptions!$B$5 -> 0 | C11: =C7/Assumptions!$B$5 -> 0 | D11: =D7/Assumptions!$B$5 -> 0 | E11: =E7/Assumptions!$B$5 -> 0 | F11: =F7/Assumptions!$B$5 -> 0.035007495 | G11: =G7/Assumptions!$B$5 -> 0.044710749 | H11: =H7/Assumptions!$B$5 -> 0.055329552 | I11: =I7/Assumptions!$B$5 -> 0
A12: Assets / equity (leverage) | B12: ='Balance Sheet'!B8/'Balance Sheet'!B15 -> 1.7460848 | C12: ='Balance Sheet'!C8/'Balance Sheet'!C15 -> 2.7056041 | D12: ='Balance Sheet'!D8/'Balance Sheet'!D15 -> 2.2564364 | E12: ='Balance Sheet'!E8/'Balance Sheet'!E15 -> 5.4851004 | F12: ='Balance Sheet'!F8/'Balance Sheet'!F15 -> 5.7631968 | G12: ='Balance Sheet'!G8/'Balance Sheet'!G15 -> 5.9543082 | H12: ='Balance Sheet'!H8/'Balance Sheet'!H15 -> 5.91186 | I12: ='Balance Sheet'!I8/'Balance Sheet'!I15 -> 5.7197229

Sheet Peer & Sector
A1: Peer set & sector structure
A2: Approximate peer marks as of Jun–Jul 2026 (public data; flagged approximate). BTFH rows link live.
A4: Name | B4: Ticker | C4: P/E (trailing) | D4: P/B | E4: ROE | F4: Note
A5: EFG Holding | B5: HRHO | C5: 10.5 | D5: 1.2 | E5: 0.13 | F5: Closest listed comparable: IB + NBFI platform; ~EGP 42bn mkt cap
A6: Contact Financial | B6: CNFN | C6: 8.5 | D6: 1.4 | E6: 0.19 | F6: Pure NBFI consumer/auto lender
A7: Commercial International Bank | B7: COMI | C7: 5.5 | D7: 2.2 | E7: 0.38 | F7: Bank reference point: high-ROE, premium P/B
A8: Fawry | B8: FWRY | C8: 28 | D8: 6 | E8: 0.24 | F8: Payments/growth reference — not a valuation comp
A9: Baobab-type frontier microfinance | B9: — | C9: 6 | D9: 0.9 | E9: 0.16 | F9: Frontier microfinance banks trade at/below book
A10: Beltone (BTFH) — on FY2025 / 2026E | B10: BTFH | C10: =Assumptions!B5/'Income Statement'!D15 -> 20.342466 | D10: =Assumptions!B5/'Balance Sheet'!D18 -> 1.3689742 | E10: ='Summary Financials'!D14 -> 0.075795515
A12: Sector structure. Egyptian capital-markets revenue pools (brokerage, AM, IB) are in a cyclical upswing as the CBE cuts from the
A13: 27.25% peak; NBFI lending competes on funding cost and distribution; pan-African microfinance adds a frontier credit cycle.
A14: Principal risks: cost of risk on a 236%-grown book; FX on USD/EUR funding; related-party governance; further dilution.
