Workbook

Sheet READ FIRST
A1: Testahil — Independent Valuation Study — Educational Analysis. Not investment advice.
A2: DEWA — Dubai Electricity and Water Authority PJSC (DFM: DEWA) — model dated 11 July 2026, anchor close AED 2.79 (10-Jul-2026).
A4: This workbook is the calculation layer behind the DEWA valuation study. Every number in the study traces to a cell here.
A5: Blue cells are hardcoded inputs (all on the Assumptions sheet). Black cells are formulas. Green cells are links from another sheet.
A6: Nothing in this file is a recommendation, rating, or price target. Fair value is presented only as ranges and distributions.
A7: The preparer is not licensed by any securities regulator; see the Disclosure & Disclaimer in the companion study document.
A9: Sheet map: 1 READ FIRST · 2 Summary · 3 Assumptions · 4 Driver Build · 5 DDM · 6 DCF · 7 Relative & P-B · 8 Income Statement
A10: 9 Balance Sheet · 10 Cash Flow · 11 Operations & Structure · 12 Monte Carlo · 13 Sensitivity · 14 Per-Share & Ratios · 15 Peer & Sector · 16 Research Register · 17 Experts
A12: Sources: FY2023–FY2025 KPMG-audited consolidated financial statements (dewa.gov.ae, 27-Feb-2026); Q1-2026 results release (12-May-2026);
A13: UAE MoF T-Bond auctions; Damodaran country-risk file (5-Jan-2026 vintage); dated market quotes as labelled. Forecasts are the preparer's judgments.

Sheet Summary
A1: Valuation summary — every read at a glance
A2: Fair value ranges and distributions only. No rating, no price target. Spot AED 2.79 (10-Jul-2026).
A4: Lens | B4: Bear | C4: Base | D4: Bull | E4: Weight / note
A5: §1.1 Dividend policy DDM (PRIMARY) | B5: 2.09 | C5: 3.83 | D5: 5.9 | E5: 35% — the instrument trades on its dividend
A6: §1.2 FCFF DCF (ceiling framing) | B6: 1.55 | C6: 3.36 | D6: 6.49 | E6: 20% — TV = 86.7% of EV, disclosed; treat as ceiling
A7: §1.3 Relative EV/EBITDA | B7: 2.55 | C7: 2.93 | D7: 3.31 | E7: 25% — 9x/10x/11x on FY26E
A8: §1.4 Justified P/B | B8: 2.5 | C8: 2.91 | D8: 3.65 | E8: 20% — ROE 9.3%, justified 1.60x vs spot 1.53x
A9: Weighted fundamental central | B9: =B5*0.35+B6*0.2+B7*0.25+B8*0.2 -> 2.179 | C9: =C5*0.35+C6*0.2+C7*0.25+C8*0.2 -> 3.327 | D9: =D5*0.35+D6*0.2+D7*0.25+D8*0.2 -> 4.9205 | E9: weights sum to 1.00; central AED 3.32 = 19.1% vs spot
A11: Monte Carlo (3-month, genuine T+60)
A12: Median T+60 (AED) | B12: 2.805546
A13: P(close above spot) | B13: 0.5209
A14: P(≥ +10%) / P(≤ −10%) | B14: 20.3% / 15.5%
A15: Odds ratio (up:down 10%) | B15: 1.3057308
A16: 90% band T+60 (AED) | B16: 2.33 – 3.39
A17: 50% band T+60 (AED) | B17: 2.61 – 3.02
A19: Two clocks: the fundamental range is a ~12-month basis; the MC band is a genuine 3-month distribution. They answer different questions and are never blended.
A21: Calibration status
A22: DEWA verdict: BOUNDARY → parity tier ("calibrated, market-panel validated, no demonstrated single-name edge"). UAE panel fit read live from the production fit at build time.

Sheet Assumptions
A1: Assumptions — the single blue-cell input layer
A2: Every hardcoded number in the model lives here. Change a blue cell; the workbook recalculates.
A4: Input | B4: FY26E | C4: FY27E | D4: FY28E | E4: FY29E | F4: FY30E | G4: Source / basis
A5: Revenue growth | B5: 0.075 | C5: 0.06 | D5: 0.055 | E5: 0.05 | F5: 0.045 | G5: FY25 +6.0% actual; Q1-26 +8.2%; Dubai demand + tariff mix + Empower consolidation step-up in FY26
A6: EBITDA margin | B6: 0.542 | C6: 0.546 | D6: 0.55 | E6: 0.553 | F6: 0.555 | G6: FY25 53.8% company basis; clean-share rise trims fuel cost; Empower 56.8% margin mixes in at 80%
A7: D&A % of revenue | B7: 0.206 | C7: 0.208 | D7: 0.21 | E7: 0.212 | F7: 0.213 | G7: FY25 20.4%; rises with the Hassyan SWRO + solar commissioning wave
A8: Capex (AED mn) | B8: 12500 | C8: 13500 | D8: 14000 | E8: 14000 | F8: 13500 | G8: FY25 actual 11.72bn groupwide; 2030 build-out (23GW / 735 MIGD) keeps intensity elevated
A9: ΔWC % of Δrevenue | B9: 0.01 | C9: 0.01 | D9: 0.01 | E9: 0.01 | F9: 0.01 | G9: regulated receivable/payable cycle; FY25 WC release treated as non-recurring
A10: Net finance cost (AED mn) | B10: 700 | C10: 780 | D10: 850 | E10: 910 | F10: 950 | G10: FY25 net 617; rises with Empower funding + capex debt, offset by deposit income
A11: Effective tax rate | B11: 0.095 | C11: 0.095 | D11: 0.095 | E11: 0.095 | F11: 0.095 | G11: 9% UAE CT + DMTT top-up mix; FY25 actual 9.5% of PBT
A12: NCI share of PAT | B12: 0.06 | C12: 0.06 | D12: 0.06 | E12: 0.06 | F12: 0.06 | G12: FY25 7.8% pre-deal; falls to ~6% with Empower at 80% from Feb-26
A14: Cost of capital
A15: Risk-free (AED, MoF Jan-2031 T-Bond) | B15: 0.043 | G15: UAE MoF auction 23-May-2026, YTM 4.30% — longest AED sovereign point
A16: ERP — rating basis (UAE Aa2) | B16: 0.0487 | G16: Damodaran original ctryprem.html, 5-Jan-2026 vintage: 4.23% mature + 0.64% CRP
A17: ERP — CDS basis (Abu Dhabi proxy) | B17: 0.0493 | G17: same file, Abu Dhabi CDS row (no UAE-federal CDS exists)
A18: Beta (regression, weekly, own panel proxy) | B18: 0.5 | G18: OLS 221 wks vs equal-wt 14-name UAE proxy: 0.42 (SE 0.055, R² 20.5%); rounded up for proxy-construction risk
A19: Kd pre-tax (blended) | B19: 0.049 | G19: FY25 interest paid 2,203 / avg borrowings ~44.9bn = 4.9%; A3/AA- issuer
A20: Tax shield rate | B20: 0.09 | G20: UAE corporate tax
A21: Terminal growth | B21: 0.025 | G21: Dubai population + electrification, below nominal GDP; sensitised 1.5–3.5%
A22: Empower 24% purchase (Feb-26, AED mn) | B22: 5184 | G22: Dubai Holding sale to DEWA, 10-Feb-2026 — named transaction
A23: Empower market cap (aggregator, flagged) | B23: 16000 | G23: DFM ~May-2026; deal-date cap 17.9bn
A24: Shares outstanding (mn) | B24: 50000 | G24: FY25 FS: EPS 0.167 on NP att 8,346.9mn
A25: Spot (10-Jul-2026 close) | B25: 2.79 | G25: DFM close, attached daily history
A26: MC rf — CBUAE base rate (live) | B26: 0.0365 | G26: held 17-Jun-2026; carry anchor for the price forecast
A27: DPS (policy floor / share) | B27: 0.124 | G27: AED 6.2bn / 50,000mn shares; policy runs to Oct-2027

Sheet Driver Build
A1: Driver build — sourced, then built
A2: Bottom-up only where a disclosed figure or dated quote exists; top-down flagged. Full sourcing detail is in the Research Register sheet.
A4: Driver | B4: Mode | C4: Value
A5: FY26E revenue growth +7.5% | B5: top-down (guided by Q1) | C5: Q1-26 +8.2% y/y; no formal guidance issued
A6: FY27-30E growth 6.0→4.5% | B6: top-down | C6: Dubai D33 demand: FY25 peak +5.8%, customers +4.5%/yr
A7: EBITDA margin 54.2→55.5% | B7: bottom-up (mix) | C7: clean share 16.2%→~25% cuts fuel; Empower 56.8% margin at 80%
A8: Capex AED 12.5–14.0bn | B8: bottom-up (program) | C8: 2030: >23GW, 735 MIGD; Hassyan SWRO waves; FY25 actual 11.72bn
A9: Tax 9.5% | B9: bottom-up (regime) | C9: 9% CT + DMTT; FY25 actual 947.6/10,003 = 9.5%
A10: NCI 6.0% | B10: bottom-up (deal) | C10: Empower 56→80% (Feb-26, AED 5.184bn named transaction)
A11: WACC inputs | B11: bottom-up (sourced) | C11: rf 4.30% MoF; ERP 4.87% Damodaran original; beta regression 0.42→0.50 used
A12: Terminal g 2.5% | B12: top-down | C12: house view, below Dubai nominal GDP; sensitised
A13: Dividend AED 6.2bn floor | B13: bottom-up (policy) | C13: stated policy to Oct-2027; FY25 paid 6.2bn; the post-2027 policy is THE CRUX

Sheet DDM
A1: §1.1 Dividend policy DDM — the primary lens
A2: DEWA listed as an income instrument: AED 6.2bn/yr policy floor to Oct-2027. The post-2027 policy is the crux.
A4: DPS0 (policy floor) | B4: =Assumptions!B27 -> 0.124
A5: Stage-1 growth (5 yrs, base) | B5: 0.055
A6: Terminal growth (base) | B6: 0.03
A7: Ke (rating-basis) | B7: =Assumptions!B15+Assumptions!B18*Assumptions!B16 -> 0.06735
A9: Year | B9: 1 | C9: 2 | D9: 3 | E9: 4 | F9: 5 | G9: Terminal
A10: DPS path (AED) | B10: =B4*(1+$B$5) -> 0.13082 | C10: =B10*(1+$B$5) -> 0.1380151 | D10: =C10*(1+$B$5) -> 0.14560593 | E10: =D10*(1+$B$5) -> 0.15361426 | F10: =E10*(1+$B$5) -> 0.16206304 | G10: =F10*(1+$B$6) -> 0.16692493
A11: Discount factor | B11: =1/(1+$B$7)^1 -> 0.9368998 | C11: =1/(1+$B$7)^2 -> 0.87778123 | D11: =1/(1+$B$7)^3 -> 0.82239306 | E11: =1/(1+$B$7)^4 -> 0.77049989 | F11: =1/(1+$B$7)^5 -> 0.72188119
A12: PV of DPS | B12: =B10*B11 -> 0.12256523 | C12: =C10*C11 -> 0.12114706 | D12: =D10*D11 -> 0.11974531 | E12: =E10*E11 -> 0.11835977 | F12: =F10*F11 -> 0.11699026
A14: PV of stage-1 dividends | B14: =SUM(B12:F12) -> 0.59880763
A15: Terminal value at t5 | B15: =G10/($B$7-$B$6) -> 4.4692084
A16: PV of terminal value | B16: =B15*F11 -> 3.2262375
A17: DDM fair value / share (base) | B17: =B14+B16 -> 3.8250451
A19: Scenario grid
A20: Scenario | B20: Stage-1 g | C20: Terminal g | D20: Fair value | E20: vs spot
A21: Bear — policy frozen at 6.2bn, then flat | B21: 0 | C21: 0.01 | D21: 2.09 | E21: =D21/Assumptions!B25-1 -> -0.25089606
A22: Base — modest step-ups, 3.0% perpetual | B22: 0.055 | C22: 0.03 | D22: 3.83 | E22: =D22/Assumptions!B25-1 -> 0.37275986
A23: Bull — payout steps up post-2027 | B23: 0.09 | C23: 0.04 | D23: 5.9 | E23: =D23/Assumptions!B25-1 -> 1.1146953
A24: Deep bear — cut ~20% to 4.96bn to fund the build, then flat | B24: −20% step | C24: 0 | D24: =0.124*0.8/B7 -> 1.4729027 | E24: =D24/Assumptions!B25-1 -> -0.47207787
A26: Market-implied read, dual-framed. Single-stage (Ke − spot dividend yield): | B26: =B7-Assumptions!B27/Assumptions!B25 -> 0.022905556 | C26: 2.29% — path-free framing
A27: Two-stage (hold the base 5.5% stage-1 path, solve terminal g so PV = spot): 1.33% — lower because stage 1 already grows the coupon. Both framings stated; the study body quotes the two-stage number as the sharper read.

Sheet DCF
A1: §1.2 FCFF DCF — full waterfall, ceiling framing
A2: Revenue→EBITDA→D&A→EBIT→NOPAT→+D&A→−Capex→−ΔWC→FCFF→DF→PV, every line shown. TV share of EV disclosed.
A4: AED mn | B4: FY26E | C4: FY27E | D4: FY28E | E4: FY29E | F4: FY30E
A5: Revenue | B5: ='Income Statement'!E5 -> 35304.96 | C5: ='Income Statement'!F5 -> 37423.257 | D5: ='Income Statement'!G5 -> 39481.536 | E5: ='Income Statement'!H5 -> 41455.613 | F5: ='Income Statement'!I5 -> 43321.116
A6: EBITDA | B6: ='Income Statement'!E8 -> 19135.288 | C6: ='Income Statement'!F8 -> 20433.098 | D6: ='Income Statement'!G8 -> 21714.845 | E6: ='Income Statement'!H8 -> 22924.954 | F6: ='Income Statement'!I8 -> 24043.219
A7: – D&A | B7: ='Income Statement'!E9 -> -7272.8217 | C7: ='Income Statement'!F9 -> -7784.0375 | D7: ='Income Statement'!G9 -> -8291.1227 | E7: ='Income Statement'!H9 -> -8788.59 | F7: ='Income Statement'!I9 -> -9227.3977
A8: EBIT | B8: =B6+B7 -> 11862.466 | C8: =C6+C7 -> 12649.061 | D8: =D6+D7 -> 13423.722 | E8: =E6+E7 -> 14136.364 | F8: =F6+F7 -> 14815.822
A9: NOPAT (after 9.5% tax) | B9: =B8*(1-Assumptions!B11) -> 10735.532 | C9: =C8*(1-Assumptions!C11) -> 11447.4 | D9: =D8*(1-Assumptions!D11) -> 12148.469 | E9: =E8*(1-Assumptions!E11) -> 12793.41 | F9: =F8*(1-Assumptions!F11) -> 13408.319
A10: + D&A | B10: =-B7 -> 7272.8217 | C10: =-C7 -> 7784.0375 | D10: =-D7 -> 8291.1227 | E10: =-E7 -> 8788.59 | F10: =-F7 -> 9227.3977
A11: – Capex | B11: =-Assumptions!B8 -> -12500 | C11: =-Assumptions!C8 -> -13500 | D11: =-Assumptions!D8 -> -14000 | E11: =-Assumptions!E8 -> -14000 | F11: =-Assumptions!F8 -> -13500
A12: – ΔWC (1% of Δrevenue) | B12: =-(B5-'Income Statement'!D5)*Assumptions!B9 -> -24.631367 | C12: =-(C5-B5)*Assumptions!C9 -> -21.182976 | D12: =-(D5-C5)*Assumptions!D9 -> -20.582792 | E12: =-(E5-D5)*Assumptions!E9 -> -19.740768 | F12: =-(F5-E5)*Assumptions!F9 -> -18.655026
A13: FCFF | B13: =B9+B10+B11+B12 -> 5483.7225 | C13: =C9+C10+C11+C12 -> 5710.2547 | D13: =D9+D10+D11+D12 -> 6419.0086 | E13: =E9+E10+E11+E12 -> 7562.2588 | F13: =F9+F10+F11+F12 -> 9117.0612
A14: WACC (rating basis) | B14: =Assumptions!B15+Assumptions!B18*Assumptions!B16 -> 0.06735 | C14: Ke — equity weight 78.3% / debt 21.7%
A15: WACC blended | B15: =0.783*B14+0.217*Assumptions!B19*(1-Assumptions!B20) -> 0.06241108
A16: Discount factor | B16: =1/(1+$B$15)^1 -> 0.94125524 | C16: =1/(1+$B$15)^2 -> 0.88596143 | D16: =1/(1+$B$15)^3 -> 0.83391585 | E16: =1/(1+$B$15)^4 -> 0.78492766 | F16: =1/(1+$B$15)^5 -> 0.73881728
A17: PV of FCFF | B17: =B13*B16 -> 5161.5825 | C17: =C13*C16 -> 5059.0655 | D17: =D13*D16 -> 5352.913 | E17: =E13*E16 -> 5935.8261 | F17: =F13*F16 -> 6735.8424
A19: Sum PV of explicit FCFF | B19: =SUM(B17:F17) -> 28245.229
A20: Terminal value at t5 | B20: =F13*(1+Assumptions!B21)/(B15-Assumptions!B21) -> 249791.98
A21: PV of terminal value | B21: =B20*F16 -> 184550.63
A22: Enterprise value | B22: =B19+B21 -> 212795.86
A23: TV as % of EV (disclosed) | B23: =B21/B22 -> 0.86726608 | C23: 86.7% — that is why this lens is framed as a CEILING, weighted 20%
A24: – Net debt (post-Empower, pro forma) | B24: -36273 | C24: 31,089 FY25 + 5,184 Empower payment (Feb-26)
A25: – NCI (marked) | B25: =-B36 -> -8598.019 | C25: Empower 20% at ~16bn DFM cap + others at book
A26: Equity value | B26: =B22+B24+B25 -> 167924.84
A27: Fair value / share (AED) | B27: =B26/Assumptions!B24 -> 3.3584968
A28: Alt framing (+ treasury assets 6,631) | B28: =(B26+6631)/Assumptions!B24 -> 3.4911168 | C28: dual framing — term deposits + other financial assets at amortised cost
A30: QC receipts: IC 128,859 → ROIC 7.69% vs WACC 6.24%; steady-state reinvestment g/ROIC = 32.5%, consistent with the capex path.
A32: NCI marked bridge — how the 8,598 deduction is built (AED mn)
A33: NCI book value, audited (31-Dec-25) | B33: 6753.019
A34: − Empower NCI component at 44% of Empower book equity (derived from segment disclosure, not a stated FS line) | B34: -1355
A35: + Empower 20% residual minority marked at DFM market cap (0.20 × 16,000) | B35: =0.2*Assumptions!B23 -> 3200
A36: NCI as deducted in the bridge (feeds B25) = | B36: =B33+B34+B35 -> 8598.019
A37: Only the listed Empower stub is marked to its DFM price; IPP and other minorities stay at audited book.

Sheet Relative & P-B
A1: §1.3 Relative EV/EBITDA + §1.4 Justified P/B
A2: Two market-family lenses. Kept separate from the DCF family; the synthesis never blends non-overlapping methods.
A4: Relative — EV/EBITDA on FY26E
A5: Spot EV (mkt cap + ND PF + NCI) | B5: =Assumptions!B25*Assumptions!B24+36273+8598 -> 184371
A6: FY26E EBITDA | B6: ='Income Statement'!E8 -> 19135.288
A7: Implied spot multiple | B7: =B5/B6 -> 9.6351306
A9: Multiple scenario | B9: EV | C9: Equity | D9: AED / share
A10: 9.0x (bear) | B10: ='Income Statement'!E8*9 -> 172217.59 | C10: =B10-36273-8598 -> 127346.59 | D10: =C10/Assumptions!B24 -> 2.5469319
A11: 10.0x (base) | B11: ='Income Statement'!E8*10 -> 191352.88 | C11: =B11-36273-8598 -> 146481.88 | D11: =C11/Assumptions!B24 -> 2.9296376
A12: 11.0x (bull) | B12: ='Income Statement'!E8*11 -> 210488.17 | C12: =B12-36273-8598 -> 165617.17 | D12: =C12/Assumptions!B24 -> 3.3123434
A14: Justified P/B
A15: BVPS (owners, FY25) | B15: 1.82
A16: Sustainable ROE | B16: 0.0926
A17: Ke | B17: =Assumptions!B15+Assumptions!B18*Assumptions!B16 -> 0.06735
A18: g (long-run) | B18: 0.025
A19: Justified P/B = (ROE−g)/(Ke−g) | B19: =(B16-B18)/(B17-B18) -> 1.596222
A20: Fair value / share | B20: =B19*B15 -> 2.905124
A21: Spot P/B (check) | B21: =Assumptions!B25/B15 -> 1.532967
A23: Bear 2.28 (ROE 8.5%, g 2.0%) · Base 2.91 · Bull 3.66 (ROE 10.5%, g 3.0%) — grid in the study §1.9.

Sheet Income Statement
A1: Income statement — 3-year historical + 5-year forecast (consolidated, AED mn)
A2: FY23–FY25 = KPMG-audited FS. Forecast rows are formulas off Assumptions.
A4: AED mn | B4: FY23 | C4: FY24 | D4: FY25 | E4: FY26E | F4: FY27E | G4: FY28E | H4: FY29E | I4: FY30E
A5: Revenue | B5: 29178.009 | C5: 30977.351 | D5: 32841.823 | E5: =D5*(1+Assumptions!B5) -> 35304.96 | F5: =E5*(1+Assumptions!C5) -> 37423.257 | G5: =F5*(1+Assumptions!D5) -> 39481.536 | H5: =G5*(1+Assumptions!E5) -> 41455.613 | I5: =H5*(1+Assumptions!F5) -> 43321.116
A6: Cost of sales | B6: -17932.654 | C6: -19170.338 | D6: -19776.71 | E6: =E8-E5 -> -16169.672 | F6: =F8-F5 -> -16990.159 | G6: =G8-G5 -> -17766.691 | H6: =H8-H5 -> -18530.659 | I6: =I8-I5 -> -19277.897
A7: Gross profit | B7: 11245.355 | C7: 11807.013 | D7: 13065.113 | E7: =E5*0.4 -> 14121.984 | F7: =F5*0.4 -> 14969.303 | G7: =G5*0.4 -> 15792.615 | H7: =H5*0.4 -> 16582.245 | I7: =I5*0.4 -> 17328.446
A8: EBITDA | B8: 14884.312 | C8: 15892.457 | D8: 17660.637 | E8: =E5*Assumptions!B6 -> 19135.288 | F8: =F5*Assumptions!C6 -> 20433.098 | G8: =G5*Assumptions!D6 -> 21714.845 | H8: =H5*Assumptions!E6 -> 22924.954 | I8: =I5*Assumptions!F6 -> 24043.219
A9: – D&A | B9: -6126.978 | C9: -6567.932 | D9: -6709.126 | E9: =-E5*Assumptions!B7 -> -7272.8217 | F9: =-F5*Assumptions!C7 -> -7784.0375 | G9: =-G5*Assumptions!D7 -> -8291.1227 | H9: =-H5*Assumptions!E7 -> -8788.59 | I9: =-I5*Assumptions!F7 -> -9227.3977
A10: Operating profit (EBIT) | B10: 8757.334 | C10: 9324.525 | D10: 10951.511 | E10: =E9+E8 -> 11862.466 | F10: =F9+F8 -> 12649.061 | G10: =G9+G8 -> 13423.722 | H10: =H9+H8 -> 14136.364 | I10: =I9+I8 -> 14815.822
A11: – Net finance cost | B11: -810.887 | C11: -1174.018 | D11: -617.299 | E11: =-Assumptions!B10 -> -700 | F11: =-Assumptions!C10 -> -780 | G11: =-Assumptions!D10 -> -850 | H11: =-Assumptions!E10 -> -910 | I11: =-Assumptions!F10 -> -950
A12: – Regulatory deferral movement | B12: -104.588 | C12: -167.413 | D12: -331.269 | E12: 0 | F12: 0 | G12: 0 | H12: 0 | I12: 0
A13: Profit before tax | B13: 7841.859 | C13: 7983.094 | D13: 10002.943 | E13: =E10+E11+E12 -> 11162.466 | F13: =F10+F11+F12 -> 11869.061 | G13: =G10+G11+G12 -> 12573.722 | H13: =H10+H11+H12 -> 13226.364 | I13: =I10+I11+I12 -> 13865.822
A14: – Income tax | B14: 91.902 | C14: -748.905 | D14: -947.599 | E14: =-E13*Assumptions!B11 -> -1060.4343 | F14: =-F13*Assumptions!C11 -> -1127.5608 | G14: =-G13*Assumptions!D11 -> -1194.5036 | H14: =-H13*Assumptions!E11 -> -1256.5046 | I14: =-I13*Assumptions!F11 -> -1317.2531
A15: Profit after tax | B15: 7933.761 | C15: 7234.189 | D15: 9055.344 | E15: =E13+E14 -> 10102.032 | F15: =F13+F14 -> 10741.5 | G15: =G13+G14 -> 11379.219 | H15: =H13+H14 -> 11969.86 | I15: =I13+I14 -> 12548.569
A16: – Non-controlling interests | B16: -232.938 | C16: -221.529 | D16: -708.457 | E16: =-E15*Assumptions!B12 -> -606.12193 | F16: =-F15*Assumptions!C12 -> -644.49001 | G16: =-G15*Assumptions!D12 -> -682.75313 | H16: =-H15*Assumptions!E12 -> -718.19157 | I16: =-I15*Assumptions!F12 -> -752.91411
A17: Net profit attributable | B17: 7700.823 | C17: 7012.66 | D17: 8346.887 | E17: =E15+E16 -> 9495.9102 | F17: =F15+F16 -> 10097.01 | G17: =G15+G16 -> 10696.466 | H17: =H15+H16 -> 11251.668 | I17: =I15+I16 -> 11795.654
A18: EPS (AED) | B18: 0.154 | C18: 0.14 | D18: 0.167 | E18: =E17/50000 -> 0.1899182 | F18: =F17/50000 -> 0.2019402 | G18: =G17/50000 -> 0.21392931 | H18: =H17/50000 -> 0.22503336 | I18: =I17/50000 -> 0.23591309
A20: FY23 is the FY2024 audited statements’ comparative column in full (KPMG, signed 27-Feb-2025) — the restated presentation. FY23 income tax was a +91.902 deferred-tax CREDIT (first recognition of the UAE corporate-tax regime), hence the positive sign. FY23 engine EBITDA 14,884 reconciles to DEWA’s own stated "EBITDA of AED 14.8 billion" for 2023.

Sheet Balance Sheet
A1: Balance sheet — audited three-year view (KPMG, AED mn)
A2: FY23 from the audited FY2023 statements (balance-sheet face as reproduced in DEWA’s Integrated Report 2023) and the FY24 statements’ equity comparatives; FY24 = comparative column of the FY25 audited FS; FY25 = audited. Provenance: official FS only, never an aggregator.
A4: AED mn | B4: FY23 | C4: FY24 | D4: FY25
A5: Non-current assets | B5: 162239.2 | C5: 165466 | D5: 171450.62
A6: Current assets | B6: 18924.305 | C6: 19290 | D6: 23688.154
A7: Total assets | B7: 181163.51 | C7: 184755.31 | D7: 195138.78
A8: Equity — owners | B8: 89212.243 | C8: 89349.233 | D8: 91016.516
A9: Equity — non-controlling interests | B9: 3489.111 | C9: 5638.617 | D9: 6753.019
A10: Total equity | B10: =B8+B9 -> 92701.354 | C10: =C8+C9 -> 94987.85 | D10: =D8+D9 -> 97769.535
A11: Borrowings — non-current | B11: 27341.537 | C11: 28828.861 | D11: 31921.882
A12: Borrowings — current | B12: 11546.029 | C12: 7141.9 | D12: 6654.393
A13: Total liabilities | B13: 88262.222 | C13: 89400.114 | D13: 96670.629
A14: Regulatory deferral credit balance | B14: 199.931 | C14: 367.344 | D14: 698.613
A15: Cash & equivalents (balance-sheet face) | B15: 5300.171 | C15: 5373.629 | D15: 7487.233
A16: Net debt — strict (borrowings − cash) | B16: =B11+B12-B15 -> 33587.395 | C16: =C11+C12-C15 -> 30597.132 | D16: =D11+D12-D15 -> 31089.042
A17: Net debt — pro forma (post-Empower, Feb-26) | B17: — | C17: — | D17: =D16+Assumptions!B22 -> 36273.042
A19: Balance-sheet identity (IFRS 14 presentation): Total assets = Total equity + Total liabilities + Regulatory deferral credit balance.
A20: Identity residual per column — LIVE formula, must be 0.000: | B20: =B7-B10-B13-B14 -> 1.1397105e-11 | C20: =C7-C10-C13-C14 -> -2.6716407e-12 | D20: =D7-D10-D13-D14 -> -2.5011104e-12
A22: Restatement note: the FY24 statements regrouped certain FY23 cash-flow lines (≈AED 536mn between operating and investing); this workbook uses the restated — most recent audited — presentation throughout.
A23: FY23 cash note: the CF-basis year-end cash was 4,658.317 — AED 641.854mn of overdraft-style balances sat inside FY23 current borrowings and are netted in the CF definition; net debt is identical on either basis.

Sheet Cash Flow
A1: Cash flow — audited three-year view (KPMG, AED mn)
A2: Interest and dividend rows are memo items inside the investing/financing totals shown; the cash walk ties on CFO − investing − financing. FY23 = restated comparatives from the FY2024 audited statements. Provenance: official FS only.
A4: AED mn | B4: FY23 | C4: FY24 | D4: FY25
A5: Cash generated from operations | B5: 16517.646 | C5: 17435.409 | D5: 21850.477
A6: – Capex (cash, net of capital payables) | B6: -6804.683 | C6: -9267.317 | D6: -10590.21
A7: Free cash flow (CFO − capex) | B7: =B5+B6 -> 9712.963 | C7: =C5+C6 -> 8168.092 | D7: =D5+D6 -> 11260.267
A8: – Interest paid on borrowings (memo) | B8: -2377.823 | C8: -2577.233 | D8: -2203.097
A9: – Dividends — owners (memo) | B9: -7870 | C9: -6200 | D9: -6200
A10: – Dividends — NCI (memo) | B10: -378.23 | C10: -385.236 | D10: -1160.422
A11: Net cash used in investing (incl. capex, deposits) | B11: -4775.778 | C11: -6933.156 | D11: -14415
A12: Net cash used in financing (incl. interest, dividends) | B12: -11805.847 | C12: -9786.941 | D12: -5322
A13: Cash & equivalents, year-end | B13: 4658.317 | C13: 5373.629 | D13: 7487.233
A14: Cash-walk residual (= end − open − CFO − investing − financing) — LIVE formula: | B14: =B13-4722.296-B5-B11-B12 -> 0 | C14: =C13-B13-C5-C11-C12 -> 0 | D14: =D13-C13-D5-D11-D12 -> 0.127
A15: FY23 opening cash was 4,722.296 (audited). FY25 investing/financing are the FS’s rounded presentation, so the FY25 residual of 0.13 is display rounding, not a tie failure; FY25 investing is mostly term-deposit placement (14,659 placed vs 10,203 matured), not spending.
A16: Dividend cover, dual-framed (FY25):
A17: Dividend cover — all framings (FY25): | B17: 1.4604839 | C17: 1.46x — gross framing
A18: Gross: total PAT / total dividends paid (incl. NCI) = 9,055 / 7,360 | B18: ='Income Statement'!D15/(-D9-D10) -> 1.2302751 | C18: 1.23x — the gross framing
A19: Owner: attributable PAT / owner dividends = 8,347 / 6,200 | B19: ='Income Statement'!D17/(-D9) -> 1.3462721 | C19: 1.35x — the owner framing
A20: Policy floor: group PAT vs the AED 6.2bn policy floor alone | B20: ='Income Statement'!D15/6200 -> 1.4605394 | C20: 1.46x — valid only against the floor, not against dividends actually paid
A21: All three framings appear wherever the cover is cited; the study body leads with 1.23x / 1.35x.

Sheet Operations & Structure
A1: Operations & group structure — the physical system behind the financials
A2: Sources: FY25 directors’ report and note 1 to the audited FS; Q1-2026 results release (12-May-2026); Empower disclosures (DFM, 10-Feb-2026).
A4: FY25 operating KPIs
A5: Metric | B5: FY25 | C5: FY24 / prior | D5: Change
A6: Installed generation capacity (MW) | B6: 17979 | C6: 17167 | D6: +4.7%
A7: — of which clean (MW / % of fleet) | B7: 3860 | D7: 21.5% of fleet
A8: Gross generation (TWh) | B8: 62.21 | C8: 59.19 | D8: +5.10%
A9: — clean generation (TWh / % of output) | B9: 10.1 | C9: 6.63 | D9: +52.4% → 16.23%
A10: Peak demand (MW) | B10: 11391 | C10: 10764 | D10: +5.83%
A11: Desalinated water produced (bn imperial gallons) | B11: 161.505 | C11: 151.5 | D11: +6.62%
A12: Peak water demand (MIGD) | B12: 487 | C12: 455 | D12: +7.0%
A13: Installed desalination capacity (MIGD) | B13: 555
A14: Customer accounts | B14: 1327182 | C14: 1270273 | D14: +4.48%
A15: Transmission / distribution losses | B15: 2.0% / 4.4% | D15: world-class
A16: Customer minutes lost (CML, min/yr) | B16: 0.82 | D16: vs ~15 in leading EU utilities
A18: Q1-2026 operational read
A19: Metric | B19: Q1-26 | C19: Note
A20: Generation (TWh) | B20: 11.09 | C20: clean 2.06 TWh — 18.6% of output
A21: Water (bn IG) | B21: 37.57
A22: Customer accounts | B22: 1347000 | C22: +5.08% LTM — ~65k adds
A24: 2030 targets (Dubai Clean Energy Strategy / D33 alignment)
A25: Target | B25: 2030 | C25: vs FY25
A26: Generation capacity (MW) | B26: 23000 | C26: =B26/17979-1 -> 0.27927026
A27: Renewable capacity (MW, 36.1% of fleet) | B27: 8300
A28: Desalination capacity (MIGD) | B28: 735
A29: — of which SWRO (MIGD) | B29: 308
A31: Build pipeline in flight
A32: • 1,800 MW solar IPP (MBR Solar Park phase) — 86% complete, on line 2026
A33: • Noor Energy 1 — 950 MW CSP+PV hybrid, fully grid-connected in FY25
A34: • Hassyan Water 1/A — 180 MIGD SWRO, early production achieved
A35: • Hatta pumped-storage hydro — 1,500 MWh, commissioning
A37: Group structure (note 1, FY25 audited FS)
A38: Entity | B38: Held | C38: What it does
A39: Empower (Emirates Central Cooling) — DFM listed | B39: 80% | C39: district cooling; bought up from 56% for AED 5,184mn, 10-Feb-2026
A40: Mai Dubai | B40: 100% | C40: bottled water
A41: Digital DEWA / Moro (Data Hub Integrated Solutions) | B41: 100% | C41: data centres, IT infrastructure
A42: Etihad ESCO / Etihad Clean Energy | B42: 100% | C42: energy-efficiency retrofits, solar rental
A43: Shuaa Energy 1 / 2 / 3 / 4 (solar IPPs) | B43: 51-60% | C43: MBR Solar Park phases; partners fund minority share
A44: Noor Energy 1 (950 MW CSP hybrid) | B44: 51% | C44: concentrated solar + PV
A45: Hassyan Energy Phase 1 | B45: 51% | C45: Hassyan power complex
...

Sheet Monte Carlo
A1: Monte Carlo — carry-anchored YZ-HAR-t (engine v3)
A2: 50,000 paths, seed 42. UAE market fit read live from the production fit at run time. Genuine 3-month horizon.
A4: Inputs
A5: Spot (10-Jul-2026) | B5: 2.79
A6: rf — CBUAE base rate | B6: 0.0365
A7: Dividend yield q | B7: 0.044444444
A8: t-dist ν (market fit, live-read) | B8: 10
A9: cone width (market fit, live-read) | B9: 1.049
A10: HAR σ (60d, annualised) | B10: 0.22698862
A11: Carry drift (60d) | B11: -0.0018179664
A12: Event-ledger drift (60d) | B12: 0.007
A13: Total drift (60d) | B13: 0.0051820336
A15: Percentile | B15: p5 | C15: p25 | D15: p50 | E15: p75 | F15: p95
A16: T+20 (AED) | B16: 2.508 | C16: 2.681 | D16: 2.795 | E16: 2.914 | F16: 3.109
A17: T+60 (AED) | B17: 2.33 | C17: 2.611 | D17: 2.806 | E17: 3.015 | F17: 3.388
A19: Probability read (T+60) — house presentation order
A20: P(close above spot) | B20: 0.5209
A21: P(≥ +10%) | B21: 0.20278
A22: P(≤ −10%) | B22: 0.1553
A23: Odds up : down | B23: =B21/B22 -> 1.3057308
A24: Median T+60 (AED) | B24: 2.805546
A25: Median vs spot | B25: 0.0055720348
A26: 50% band (p25–p75) | B26: =C17 -> 2.611 | C26: =E17 -> 3.015 | D26: =C17/B5 -> 0.93584229 | E26: =E17/B5 -> 1.0806452 | F26: of spot
A27: Touch ±10% inside the window (any close at/beyond) | B27: 0.3572 | C27: 0.28424 | D27: up 3.069 / down 2.511 by T+60 (T+20: 11.9% / 8.1%)
A29: Probability zones (T+60 close)
A30: Zone (AED) | B30: Probability
A31: < 2.40 | B31: 0.07854
A32: 2.40 – 2.60 | B32: 0.1585
A33: 2.60 – 2.95 | B33: 0.44252
A34: 2.95 – 3.20 | B34: 0.2052
A35: > 3.20 | B35: 0.11524
A37: Touch probabilities (any close at/beyond level within horizon)
A38: Level (AED) | B38: P touch ≤ T+20 | C38: P touch ≤ T+60
A39: 3.3 | B39: 0.01448 | C39: 0.12626
A40: 3.2 | B40: 0.03564 | C40: 0.19994
A41: 3.1 | B41: 0.09086 | C41: 0.31342
A42: 3 | B42: 0.2169 | C42: 0.4724
A43: 2.9 | B43: 0.46464 | C43: 0.67738
A44: 2.8 | B44: 0.84394 | C44: 0.91296
A45: 2.7 | B45: 0.50336 | C45: 0.6903
...

Sheet Sensitivity
A1: Sensitivity — DCF/share on WACC × terminal g; DDM/share on Ke × perpetual g
A2: The crux grid (DDM) is the one that matters: the instrument trades on its dividend.
A4: DCF value/share (AED)
A5: WACC \ tg | B5: 1.5% | C5: 2.0% | D5: 2.5% | E5: 3.0% | F5: 3.5%
A6: 5.50% | B6: 3.22 | C6: 3.75 | D6: 4.45 | E6: 5.43 | F6: 6.9
A7: 6.00% | B7: 2.74 | C7: 3.15 | D7: 3.66 | E7: 4.35 | F7: 5.31
A8: 6.24% | B8: 2.55 | C8: 2.91 | D8: 3.36 | E8: 3.95 | F8: 4.76
A9: 6.50% | B9: 2.36 | C9: 2.68 | D9: 3.07 | E9: 3.58 | F9: 4.25
A10: 7.00% | B10: 2.05 | C10: 2.31 | D10: 2.62 | E10: 3 | F10: 3.5
A12: DDM value/share (AED)
A13: Ke \ g∞ | B13: 1.0% | C13: 2.0% | D13: 3.0% | E13: 3.5% | F13: 4.0%
A14: 6.00% | B14: 3.06 | C14: 3.7 | D14: 4.77 | E14: 5.62 | F14: 6.91
A15: 6.74% | B15: 2.66 | C15: 3.12 | D15: 3.82 | E15: 4.34 | F15: 5.04
A16: 7.00% | B16: 2.54 | C16: 2.95 | D16: 3.57 | E16: 4.01 | F16: 4.6
A17: 7.50% | B17: 2.34 | C17: 2.68 | D17: 3.17 | E17: 3.51 | F17: 3.94
A18: 8.00% | B18: 2.17 | C18: 2.45 | D18: 2.85 | E18: 3.12 | F18: 3.45
A20: Stress column — post-2027 policy: frozen 6.2bn forever at Ke 6.74% ⇒ 2.21 (bear anchor); +9%/yr steps then 4% ⇒ 5.43 (bull anchor). This is the crux in AED/share.

Sheet Per-Share & Ratios
A1: Per-share & ratios — history + forecast
A2: Forecast rows are formulas off the Income Statement / Assumptions.
B4: FY23 | C4: FY24 | D4: FY25 | E4: FY26E | F4: FY27E | G4: FY28E | H4: FY29E | I4: FY30E
A5: EPS (AED) | B5: 0.154 | C5: 0.14 | D5: 0.167 | E5: ='Income Statement'!E18 -> 0.1899182 | F5: ='Income Statement'!F18 -> 0.2019402 | G5: ='Income Statement'!G18 -> 0.21392931 | H5: ='Income Statement'!H18 -> 0.22503336 | I5: ='Income Statement'!I18 -> 0.23591309
A6: DPS (AED) | B6: 0.124 | C6: 0.124 | D6: 0.124 | E6: 0.124 | F6: 0.124 | G6: 0.13 | H6: 0.13 | I6: 0.13
A7: Payout (owner basis) | B7: =B6/B5 -> 0.80519481 | C7: =C6/C5 -> 0.88571429 | D7: =D6/D5 -> 0.74251497 | E7: =E6/E5 -> 0.65291266 | F7: =F6/F5 -> 0.61404316 | G7: =G6/G5 -> 0.60767736 | H7: =H6/H5 -> 0.57769213 | I7: =I6/I5 -> 0.55105039
A8: Dividend yield at spot | B8: =B6/Assumptions!$B$25 -> 0.044444444 | C8: =C6/Assumptions!$B$25 -> 0.044444444 | D8: =D6/Assumptions!$B$25 -> 0.044444444 | E8: =E6/Assumptions!$B$25 -> 0.044444444 | F8: =F6/Assumptions!$B$25 -> 0.044444444 | G8: =G6/Assumptions!$B$25 -> 0.046594982 | H8: =H6/Assumptions!$B$25 -> 0.046594982 | I8: =I6/Assumptions!$B$25 -> 0.046594982
A9: P/E at spot | B9: =Assumptions!$B$25/B5 -> 18.116883 | C9: =Assumptions!$B$25/C5 -> 19.928571 | D9: =Assumptions!$B$25/D5 -> 16.706587 | E9: =Assumptions!$B$25/E5 -> 14.690535 | F9: =Assumptions!$B$25/F5 -> 13.815971 | G9: =Assumptions!$B$25/G5 -> 13.041691 | H9: =Assumptions!$B$25/H5 -> 12.398162 | I9: =Assumptions!$B$25/I5 -> 11.826389
A10: Net debt (AED mn) | B10: 33587.395 | C10: 30597.132 | D10: 31089 | E10: 36273 | F10: =E10+Assumptions!C8-'Income Statement'!F8*0.7 -> 35469.831 | G10: =F10+Assumptions!D8-'Income Statement'!G8*0.7 -> 34269.44 | H10: =G10+Assumptions!E8-'Income Statement'!H8*0.7 -> 32221.972 | I10: =H10+Assumptions!F8-'Income Statement'!I8*0.7 -> 28891.718
A11: ND / EBITDA | B11: =B10/'Income Statement'!B8 -> 2.2565635 | C11: =C10/'Income Statement'!C8 -> 1.9252613 | D11: =D10/'Income Statement'!D8 -> 1.7603555 | E11: =E10/'Income Statement'!E8 -> 1.8956077 | F11: =F10/'Income Statement'!F8 -> 1.7359008 | G11: =G10/'Income Statement'!G8 -> 1.5781572 | H11: =H10/'Income Statement'!H8 -> 1.4055414 | I11: =I10/'Income Statement'!I8 -> 1.2016576
A12: ROE — closing owners’ equity | B12: 0.0863 | C12: 0.0785 | D12: 0.0917
A13: ROE — average owners’ equity (the sustainable-return input in §1.4) | B13: 0.0862 | C13: 0.0785 | D13: 0.0926
A14: The per-share vital signs, in one place:
A15: BVPS — owners (AED) | B15: 1.7842449 | C15: 1.7869847 | D15: 1.8203303
A16: P/B at spot | B16: =Assumptions!$B$25/B15 -> 1.5636867 | C16: =Assumptions!$B$25/C15 -> 1.5612893 | D16: =Assumptions!$B$25/D15 -> 1.5326889
A17: FCF yield at spot ((CFO − capex) / market cap) | B17: ='Cash Flow'!B7/(Assumptions!$B$25*Assumptions!$B$24) -> 0.069626975 | C17: ='Cash Flow'!C7/(Assumptions!$B$25*Assumptions!$B$24) -> 0.058552631 | D17: ='Cash Flow'!D7/(Assumptions!$B$25*Assumptions!$B$24) -> 0.08071876
A18: EV/EBITDA at spot (EV = mkt cap + PF net debt + marked NCI) | B18: =(Assumptions!$B$25*Assumptions!$B$24+36273+8598)/'Income Statement'!B8 -> 12.386935 | C18: =(Assumptions!$B$25*Assumptions!$B$24+36273+8598)/'Income Statement'!C8 -> 11.601164 | D18: =(Assumptions!$B$25*Assumptions!$B$24+36273+8598)/'Income Statement'!D8 -> 10.439657 | E18: =(Assumptions!$B$25*Assumptions!$B$24+36273+8598)/'Income Statement'!E8 -> 9.6351306 | F18: =(Assumptions!$B$25*Assumptions!$B$24+36273+8598)/'Income Statement'!F8 -> 9.0231543
A19: ROIC — NOPAT / invested capital (FY25) | D19: 0.0769
A20: EBITDA margin (engine basis) | B20: ='Income Statement'!B8/'Income Statement'!B5 -> 0.51012089 | C20: ='Income Statement'!C8/'Income Statement'!C5 -> 0.51303473 | D20: ='Income Statement'!D8/'Income Statement'!D5 -> 0.53774838 | E20: ='Income Statement'!E8/'Income Statement'!E5 -> 0.542 | F20: ='Income Statement'!F8/'Income Statement'!F5 -> 0.546
A21: Effective tax rate | B21: =-'Income Statement'!B14/'Income Statement'!B13 -> -0.011719415 | C21: =-'Income Statement'!C14/'Income Statement'!C13 -> 0.093811372 | D21: =-'Income Statement'!D14/'Income Statement'!D13 -> 0.09473202 | E21: =-'Income Statement'!E14/'Income Statement'!E13 -> 0.095 | F21: =-'Income Statement'!F14/'Income Statement'!F13 -> 0.095
A23: Debt headroom: at 3.0x ND/EBITDA FY26E the balance sheet supports ~AED 21bn more debt ≈ AED 0.42/sh of optional distribution capacity — an option, not a forecast.

Sheet Peer & Sector
A1: Peer & sector — GCC utilities + regulated-income comparables
A2: Dated market quotes; aggregator-basis multiples flagged as such.
A4: Name | B4: Mkt | C4: EV/EBITDA | D4: P/E | E4: Yield | F4: P/B | G4: Note
A5: DEWA (this study) | B5: DFM | C5: 9.6x | D5: 14.7x | E5: 4.4% | F5: 1.53x | G5: FY26E basis, model-derived
A6: TAQA | B6: ADX | C6: ~13x | D6: ~26x | E6: ~1.6% | F6: ~2.9x | G6: grid+gen+water; scarcity premium
A7: Empower (56→80% sub) | B7: DFM | C7: 12.7x | D7: ~18x | E7: 5.4% | F7: ~3.4x | G7: district cooling; consolidated from Feb-26
A8: Saudi Electricity | B8: Tadawul | C8: ~11x | D8: ~15x | E8: ~4.0% | F8: ~1.1x | G8: regulated WACC framework, different regime
A9: ACWA Power | B9: Tadawul | C9: ~20x | D9: ~35x | E9: ~0.8% | F9: ~4.5x | G9: developer economics, not a utility comp
A10: National Central Cooling (Tabreed) | B10: DFM | C10: ~11x | D10: ~14x | E10: ~4.7% | F10: ~1.5x | G10: cooling infra income
A12: Peer multiples are aggregator-screen levels (dated ~Jul-2026) used only for context; the relative lens prices DEWA on its own FY26E EBITDA at 9–11x, deliberately below TAQA.

Sheet Research Register
A1: Research Register — four rings, classified
A2: B = base-rate/quantitative · S = structural · D = directional · C = colour. Full register mirrors Appendix B of the study.
A4: # | B4: Ring | C4: Finding | D4: Class | E4: Source (dated)
A5: 1 | B5: Global | C5: Fed funds path: cuts priced H2-26; UAE peg imports US policy | D5: B | E5: CME/FedWatch via press, Jun-2026
A6: 2 | B6: Global | C6: Brent range ~$65–80; fuel cost pass-through via regulatory deferral | D6: D | E6: market strip, Jul-2026
A7: 3 | B7: Global | C7: Data-centre power demand supercycle; GCC positioning | D7: S | E7: Wood Mackenzie, 2025-26
A8: 4 | B8: Country | C8: UAE MoF AED T-Bond Jan-2031 YTM 4.30% — DCF rf | D8: B | E8: MoF auction result, 23-May-2026
A9: 5 | B9: Country | C9: CBUAE base rate 3.65%, held — MC carry anchor | D9: B | E9: CBUAE, 17-Jun-2026
A10: 6 | B10: Country | C10: Damodaran UAE Aa2 ERP 4.87% / AD CDS 4.93% | D10: B | E10: ctryprem.html, 5-Jan-2026 vintage
A11: 7 | B11: Country | C11: Dubai D33 agenda: Industry-Friendly Power Policy; Shams rooftop cap ~2MW; no corporate PPAs | D11: S | E11: Dubai govt releases, 2025-26
A12: 8 | B12: Country | C12: DFM closed 2–3 Mar-2026 (regional escalation); −13.7% drawdown, recovered | D12: C | E12: DFM notices; price history
A13: 9 | B13: Industry | C13: UAE data-centre load 3 TWh (2025) → >6 TWh by 2030; Stargate UAE $1.5bn; AWS-e& $1bn | D13: S | E13: WoodMac; company announcements 2025-26
A14: 10 | B14: Industry | C14: UAE power demand → 225 TWh by 2040 scenario | D14: D | E14: sector studies 2025
A15: 11 | B15: Industry | C15: Tariff pass-through discussions ongoing; DSCE regulates; geopolitics cited as delay | D15: D | E15: Empower CFO remarks, May-2026
A16: 12 | B16: Company | C16: FY25 audited FS: rev 32,842; EBITDA 17,661 (engine basis; company 17,329-flagged); att NP 8,347; ND 31,089 | D16: B | E16: KPMG-audited FS, 27-Feb-2026
... A21: 17 | B21: Company | C21: 2030 targets: >23GW (8.3GW renewable), 735 MIGD; Hassyan SWRO +60 MIGD live, +120 due 2026 | D21: S | E21: company releases 2025-26

Sheet Experts
A1: Appendix C — expert panel (four genuinely different methods)
A2: Four experts, cast for this class of business, labelled Expert 1-4 only. Each shows workings and a falsifier.
B4: Bear | C4: Base | D4: Bull | E4: Method + falsifier
A5: Expert 1 — forensic accountant | B5: 2.35 | C5: 2.85 | D5: 3.3 | E5: Audits the book before pricing it: cash-backs FY25 earnings (CFO 124% of engine EBITDA), verifies the equity statement ties exactly, values 1.820 BVPS × a conservative ROE-implied multiple band. Falsifier: cash conversion below 90% or a receivables accrual build for two consecutive halves.
A6: Expert 2 — earnings-power analyst | B6: 2.47 | C6: 3.04 | D6: 3.42 | E6: Normalised FY26E EPS 0.190 × a through-cycle regulated-utility P/E band 13-18x, cross-checked at 10x EV/EBITDA. Falsifier: an H1-2026 print with attributable EPS growth below ~8% year-on-year.
A7: Expert 3 — macro-policy strategist | B7: 2.3 | C7: 3.52 | D7: 4.6 | E7: State tree on the Oct-2027 reset: frozen / CPI-linked / payout-ratio regimes, probability-weighted. Falsifier: an H1-2026 or FY-2026 results call that explicitly defers all policy guidance past 2027.
A8: Expert 4 — cash-returns analyst | B8: 2.55 | C8: 3.11 | D8: 3.75 | E8: RAB-flavoured: EV on invested capital 128.9bn with ROIC 7.7% vs WACC 6.2%, cross-checked at an 8.1% FCF yield. Falsifier: a DSCE tariff decision that compresses the realised spread below ~100bp.
A10: Panel read: bases 2.85 / 3.04 / 3.52 / 3.11 straddle the weighted central 3.32; no expert sits below spot at base.
