Workbook

Sheet READ FIRST
A1: Testahil · Independent Valuation Study — Educational Analysis · Not investment advice
A3: Dubai Islamic Bank PJSC (DFM: DIB) — companion model to the 11 July 2026 valuation study.
A5: READ THIS FIRST — THE CALIBRATION TEST FAILED.
A6: DIB did NOT pass our pre-publication calibration test. Under the fitted UAE market model, DIB's own five-year
A7: backtest does NOT beat a naive random walk: skill score −0.025, with the 90% confidence interval entirely below
A8: zero across every resampling scheme tested. Accordingly NO price-distribution forecast is published for DIB. The
A9: "Monte Carlo" sheet is an ILLUSTRATIVE VOLATILITY MAP ONLY — it is not a validated forecast, nothing is entered on
A10: the Calibration Ledger against it, and its percentiles must not be read as a forecast. Diagnosis in full on that sheet.
A12: WHAT THIS IS. An independent, educational valuation model. Not investment advice, not a recommendation, no rating and
A13: no price target. It presents fair-value ranges — distributions, not tips. The preparer is not licensed by the FRA, the SCA,
A14: or any securities regulator, holds no CFA charter, and this file has not been reviewed by any authority.
A16: HOW TO USE IT. Every input lives on the Assumptions sheet in a blue cell. Change one — the NPM path, the cost of risk,
... A26: directly are flagged inline and logged on our public driver ledger.

Sheet Summary
A1: Dubai Islamic Bank PJSC (DFM: DIB)
A2: Independent valuation study · 11 July 2026 · all figures AED unless noted
A4: Spot (03-Jul-2026 close) | B4: 7.72
A5: Spot since the data cut (09-Jul, aggregator) | B5: 7.54
A6: Shares outstanding (mn) | B6: 7227
A7: Market cap (AED mn) | B7: =Summary!B5*Summary!B7
A8: Book value per share (common, ex-AT1) | B8: =Assumptions!B36/Assumptions!B6
A9: P/B (spot / BVPS) | B9: =Summary!B5/Summary!B9
A10: FY25 EPS | B10: 0.98
A11: P/E (trailing) | B11: =Summary!B5/Summary!B11
A12: FY25 DPS · dividend yield | B12: 0.35
A13: Dividend yield | B13: =Summary!B13/Summary!B5
A15: THE FIVE LENSES | B15: Value (AED) | C15: Weight | D15: Contribution
A16: Dividend discount model (primary) | B16: =DDM!B17 | C16: 0.3 | D16: =B16*C16
A17: Residual income | B17: ='Residual Income'!B18 | C17: 0.2 | D17: =B17*C17
A18: Equity DCF (FCFE) | B18: =FCFE!B28 | C18: 0.15 | D18: =B18*C18
A19: Relative multiples | B19: ='Relative & Normalized'!B11 | C19: 0.2 | D19: =B19*C19
A20: Normalized (through-cycle) | B20: ='Relative & Normalized'!B19 | C20: 0.15 | D20: =B20*C20
A21: Weighted central | C21: =SUM(C16:C20) | D21: =SUM(D16:D20)
A22: Implied gap to spot | B22: =D21/B5-1
A24: Calibration tier | B24: FAILED — no price forecast published
A25: Peace-time reference (adder = 0) | B25: 11.863624

Sheet Assumptions
A1: Assumptions — the single blue-input layer
A2: Blue = change me. Every other cell in this workbook is a formula pointing here.
A4: MARKET
A5: Spot (AED, 03-Jul-2026 close) | B5: 7.72 | D5: last bar of the supplied price history
A6: Shares outstanding (mn) | B6: 7227 | D6: 7,240.744mn issued less ~13.7mn treasury
A7: FY25 DPS (AED) — trailing yield anchor | B7: 0.35 | D7: cut from 45 fils; AGM-approved 02-Apr-2026
A8: Market cap (AED mn) | B8: =B5*B6
A10: COST OF EQUITY (Ke) — built bottom-up
A11: Risk-free (AED 10Y, constructed) | B11: 0.047 | D11: UST10Y 4.58% + ~12bp AED pickup (MoF May-26 auctions). Never UST alone (peg rule).
A12: ERP — rating-based (Damodaran 05-Jan-2026) | B12: 0.0487 | D12: UAE Aa2: CRP 0.64% + mature-market 4.23%
A13: ERP — CDS-based (cross-check) | B13: 0.0493 | D13: publish both bases
A14: Beta | B14: 1 | D14: regression attempted vs the DFM index: n=19, β=0.80, R²=29.9% — below our 24-observation minimum, so beta defaults to 1.00
A15: Conflict-risk adder (2026 Iran war) | B15: 0.01 | D15: ceasefire-holding basis; sensitized 0 ↔ 2.5pt
A16: Ke = rf + β·ERP + adder | B16: =B11+B14*B12+B15
A17: Terminal growth g | B17: 0.04
A18: Terminal ROE | B18: 0.155
A19: Through-cycle ROE (normalized lens) | B19: 0.15 | D19: below the normalised FY24–25 average; haircut for the lower-rate regime
A21: DRIVER PATHS (FY26E–FY30E) | E21: FY26E | F21: FY27E | G21: FY28E | H21: FY29E | I21: FY30E
A22: Financing + sukuk growth % | E22: 0.1 | F22: 0.09 | G22: 0.08 | H22: 0.08 | I22: 0.07 | K22: FY26 = management guidance (~10%)
A23: Net profit margin % (the NIM analogue) | E23: 0.023 | F23: 0.0228 | G23: 0.0232 | H23: 0.0236 | I23: 0.024 | K23: FY26 = management guidance (2.3%). THE CRUX.
A24: Non-funded income growth % | E24: 0.1 | F24: 0.07 | G24: 0.07 | H24: 0.07 | I24: 0.07 | K24: The Q1-26 +30% headline is ONE line (other income 105->587); the recurring fee lines FELL. Not extrapolated.
A25: Cost-to-income % | E25: 0.28 | F25: 0.278 | G25: 0.275 | H25: 0.273 | I25: 0.27 | K25: FY26 = management guidance (28%)
A26: Cost of risk (bp on avg financing+sukuk) | E26: 45 | F26: 45 | G26: 40 | H26: 35 | I26: 35 | K26: FY26 = the Q1-26 print (45bp) vs FY25 14bp
A27: Effective tax rate % | E27: 0.15 | F27: 0.15 | G27: 0.15 | H27: 0.15 | I27: 0.15 | K27: 15% minimum-tax floor. NB: FY25 ACTUALLY printed 13.3% (associates enter pre-tax profit net of their own tax), so <15% IS possible — but Q1-26 printed 15.4%, so we take the floor as the conservative base.
A28: DPS (AED) — board policy, not a plug | E28: 0.35 | F28: 0.39 | G28: 0.45 | H28: 0.52 | I28: 0.59 | K28: held at 35 fils through the FY26 dip, then progressive
A29: RWA density (% of financing+sukuk) | E29: 0.83959701 | F29: 0.83159701 | G29: 0.82359701 | H29: 0.81559701 | I29: 0.80759701
A30: AT1 sukuk distributions (AED mn) | E30: 553 | F30: 649 | G30: 649 | H30: 649 | I30: 649 | K30: existing 7,350 @ ~5.7% + USD1bn @ 6.25% from Jun-26
A32: BALANCE-SHEET & REGULATORY CAPITAL (Dec-2025) — ALL COMPANY-DISCLOSED
A33: Net financing + sukuk, Dec-25 (AED mn) | B33: 352644 | D33: official (FS deck slide 13)
A34: Total assets, Dec-25 (AED mn) | B34: 415948 | D34: official
A35: Customer deposits, Dec-25 (AED mn) | B35: 320184 | D35: official
A36: Equity attributable to owners, Dec-25 | B36: 49908 | D36: official (audited FS)
A37: Tier-1 sukuk outstanding, Dec-25 | B37: 7346 | D37: official
A38: Common equity (ex-AT1), Dec-25 | B38: =B36-B37
A39: Risk-weighted assets, Dec-25 | B39: 298900 | D39: DISCLOSED — FY25 deck slide 18 (RWA movement bridge). NOT derived.
A40: CET1 capital, Dec-25 | B40: 36900 | D40: DISCLOSED — FY25 deck slide 18 (regulatory capital). NOT derived.
A41: CET1 ratio (check) = CET1 capital / RWA | B41: =B40/B39 | D41: ties to the disclosed 12.3% — this is a CHECK, not an input
A42: RWA density, Dec-25 = RWA / (financing+sukuk) | B42: =B39/B33
A43: Avg profit-bearing assets / avg total assets | B43: 0.90733906 | D43: CALIBRATED on the DISCLOSED FY25 funded income (8,972) at the disclosed 2.6% NPM; cross-checks to 0.906 on FY24
A44: NCI share of net profit | B44: 0.0394 | D44: FY25 actual 308 / 7,808
...

Sheet Driver Build
A1: Driver build — the machinery
A2: Every line is a formula off Assumptions. AED mn.
E4: FY26E | F4: FY27E | G4: FY28E | H4: FY29E | I4: FY30E
A5: Net financing + sukuk (close) | E5: =Assumptions!$B$33*(1+Assumptions!E$22) | F5: =E5*(1+Assumptions!F$22) | G5: =F5*(1+Assumptions!G$22) | H5: =G5*(1+Assumptions!H$22) | I5: =H5*(1+Assumptions!I$22)
A6: Total assets | E6: =E5*Assumptions!$B$34/Assumptions!$B$33 | F6: =F5*Assumptions!$B$34/Assumptions!$B$33 | G6: =G5*Assumptions!$B$34/Assumptions!$B$33 | H6: =H5*Assumptions!$B$34/Assumptions!$B$33 | I6: =I5*Assumptions!$B$34/Assumptions!$B$33
A7: Customer deposits | E7: =E5*Assumptions!$B$35/Assumptions!$B$33 | F7: =F5*Assumptions!$B$35/Assumptions!$B$33 | G7: =G5*Assumptions!$B$35/Assumptions!$B$33 | H7: =H5*Assumptions!$B$35/Assumptions!$B$33 | I7: =I5*Assumptions!$B$35/Assumptions!$B$33
A8: Average financing + sukuk | E8: =AVERAGE(Assumptions!$B$33,E5) | F8: =AVERAGE(E5,F5) | G8: =AVERAGE(F5,G5) | H8: =AVERAGE(G5,H5) | I8: =AVERAGE(H5,I5)
A9: Average profit-bearing assets | E9: =Assumptions!$B$43*AVERAGE(Assumptions!$B$34,E6) | F9: =Assumptions!$B$43*AVERAGE(E6,F6) | G9: =Assumptions!$B$43*AVERAGE(F6,G6) | H9: =Assumptions!$B$43*AVERAGE(G6,H6) | I9: =Assumptions!$B$43*AVERAGE(H6,I6)
A11: Funded income = NPM × avg profit-bearing assets | E11: =Assumptions!E$23*E9 | F11: =Assumptions!F$23*F9 | G11: =Assumptions!G$23*G9 | H11: =Assumptions!H$23*H9 | I11: =Assumptions!I$23*I9
A12: Non-funded income | E12: =4279*(1+Assumptions!E$24) | F12: =E12*(1+Assumptions!F$24) | G12: =F12*(1+Assumptions!G$24) | H12: =G12*(1+Assumptions!H$24) | I12: =H12*(1+Assumptions!I$24)
A13: Operating revenue | E13: =E11+E12 | F13: =F11+F12 | G13: =G11+G12 | H13: =H11+H12 | I13: =I11+I12
A14: Operating expenses | E14: =-E13*Assumptions!E$25 | F14: =-F13*Assumptions!F$25 | G14: =-G13*Assumptions!G$25 | H14: =-H13*Assumptions!H$25 | I14: =-I13*Assumptions!I$25
A15: Pre-provision operating profit | E15: =E13+E14 | F15: =F13+F14 | G15: =G13+G14 | H15: =H13+H14 | I15: =I13+I14
A16: Impairment charge | E16: =-Assumptions!E$26/10000*E8 | F16: =-Assumptions!F$26/10000*F8 | G16: =-Assumptions!G$26/10000*G8 | H16: =-Assumptions!H$26/10000*H8 | I16: =-Assumptions!I$26/10000*I8
A17: Profit before tax | E17: =E15+E16 | F17: =F15+F16 | G17: =G15+G16 | H17: =H15+H16 | I17: =I15+I16
A18: Tax | E18: =-E17*Assumptions!E$27 | F18: =-F17*Assumptions!F$27 | G18: =-G17*Assumptions!G$27 | H18: =-H17*Assumptions!H$27 | I18: =-I17*Assumptions!I$27
A19: Net profit after tax | E19: =E17+E18 | F19: =F17+F18 | G19: =G17+G18 | H19: =H17+H18 | I19: =I17+I18
A20: less: non-controlling interests | E20: =-E19*Assumptions!$B$44 | F20: =-F19*Assumptions!$B$44 | G20: =-G19*Assumptions!$B$44 | H20: =-H19*Assumptions!$B$44 | I20: =-I19*Assumptions!$B$44
A21: Profit attributable to owners | E21: =E19+E20 | F21: =F19+F20 | G21: =G19+G20 | H21: =H19+H20 | I21: =I19+I20
A22: less: AT1 sukuk distributions | E22: =-Assumptions!E$30 | F22: =-Assumptions!F$30 | G22: =-Assumptions!G$30 | H22: =-Assumptions!H$30 | I22: =-Assumptions!I$30
A23: Earnings to common | E23: =E21+E22 | F23: =F21+F22 | G23: =G21+G22 | H23: =H21+H22 | I23: =I21+I22
A24: EPS (AED) | E24: =E23/Assumptions!$B$6 | F24: =F23/Assumptions!$B$6 | G24: =G23/Assumptions!$B$6 | H24: =H23/Assumptions!$B$6 | I24: =I23/Assumptions!$B$6
A26: CAPITAL SCHEDULE — the crux
A27: Risk-weighted assets | E27: =E5*Assumptions!E$29 | F27: =F5*Assumptions!F$29 | G27: =G5*Assumptions!G$29 | H27: =H5*Assumptions!H$29 | I27: =I5*Assumptions!I$29
A28: Dividends paid | E28: =-Assumptions!E$28*Assumptions!$B$6 | F28: =-Assumptions!F$28*Assumptions!$B$6 | G28: =-Assumptions!G$28*Assumptions!$B$6 | H28: =-Assumptions!H$28*Assumptions!$B$6 | I28: =-Assumptions!I$28*Assumptions!$B$6
A29: Retained earnings | E29: =E23+E28 | F29: =F23+F28 | G29: =G23+G28 | H29: =H23+H28 | I29: =I23+I28
A30: CET1 capital (close) | E30: =Assumptions!$B$40+E29 | F30: =E30+F29 | G30: =F30+G29 | H30: =G30+H29 | I30: =H30+I29
A31: CET1 ratio ← OUTPUT of the dividend policy | E31: =E30/E27 | F31: =F30/F27 | G31: =G30/G27 | H31: =H30/H27 | I31: =I30/I27
A32: Payout ratio | E32: =-E28/E23 | F32: =-F28/F23 | G32: =-G28/G23 | H32: =-H28/H23 | I32: =-I28/I23
A33: Capital-constrained retention (FCFE basis) | E33: =E27*Assumptions!$B$45-Assumptions!$B$40 | F33: =(F27-E27)*Assumptions!$B$45 | G33: =(G27-F27)*Assumptions!$B$45 | H33: =(H27-G27)*Assumptions!$B$45 | I33: =(I27-H27)*Assumptions!$B$45
A35: The dividend is board policy (Assumptions row 28); CET1 is what falls out of it. That inversion is deliberate — letting the payout be a pure capital residual produces a cut to 28 fils and then a tripling, and no board behaves that way.

Sheet DDM
A1: Dividend discount model — the primary lens
A2: For a bank, deposits are an operating input: everything discounts at Ke.
E4: FY26E | F4: FY27E | G4: FY28E | H4: FY29E | I4: FY30E
A5: EPS (AED) | E5: ='Driver Build'!E24 | F5: ='Driver Build'!F24 | G5: ='Driver Build'!G24 | H5: ='Driver Build'!H24 | I5: ='Driver Build'!I24
A6: DPS (AED) | E6: =Assumptions!E$28 | F6: =Assumptions!F$28 | G6: =Assumptions!G$28 | H6: =Assumptions!H$28 | I6: =Assumptions!I$28
A7: Payout | E7: =E6/E5 | F7: =F6/F5 | G7: =G6/G5 | H7: =H6/H5 | I7: =I6/I5
A8: Discount factor @ Ke | E8: =1/(1+Assumptions!$B$16)^1 | F8: =1/(1+Assumptions!$B$16)^2 | G8: =1/(1+Assumptions!$B$16)^3 | H8: =1/(1+Assumptions!$B$16)^4 | I8: =1/(1+Assumptions!$B$16)^5
A9: PV of dividend | E9: =E6*E8 | F9: =F6*F8 | G9: =G6*G8 | H9: =H6*H8 | I9: =I6*I8
A11: TERMINAL BLOCK
A12: Terminal payout = 1 − g / terminal ROE | B12: =1-Assumptions!$B$17/Assumptions!$B$18
A13: Terminal DPS (FY31) = EPS(FY30) × (1+g) × payout | B13: ='Driver Build'!I24*(1+Assumptions!$B$17)*B12
A14: Terminal value = terminal DPS / (Ke − g) | B14: =B13/(Assumptions!$B$16-Assumptions!$B$17)
A15: PV of terminal value | B15: =B14*I8
A16: Σ PV of explicit dividends (FY26–30) | B16: =SUM(E9:I9)
A17: DDM FAIR VALUE (AED / share) | B17: =B15+B16
A18: Terminal value as % of total (how much of this number is the terminal assumption?) | B18: =B15/B17
A20: 85% of the DDM sits in the terminal block. That makes this number a claim about DIB's steady state (a 15.5% ROE growing at 4%), not about the next five dividends. The Sensitivity sheet stresses exactly that claim.

Sheet FCFE
A1: Equity DCF (FCFE) — the full build, revenue to cash
A2: Not what the board chooses to pay: what the bank COULD pay after funding its own growth at target capital.
E4: FY26E | F4: FY27E | G4: FY28E | H4: FY29E | I4: FY30E
A5: Operating revenue | E5: ='Driver Build'!E13 | F5: ='Driver Build'!F13 | G5: ='Driver Build'!G13 | H5: ='Driver Build'!H13 | I5: ='Driver Build'!I13
A6: Operating expenses | E6: ='Driver Build'!E14 | F6: ='Driver Build'!F14 | G6: ='Driver Build'!G14 | H6: ='Driver Build'!H14 | I6: ='Driver Build'!I14
A7: Pre-provision operating profit | E7: ='Driver Build'!E15 | F7: ='Driver Build'!F15 | G7: ='Driver Build'!G15 | H7: ='Driver Build'!H15 | I7: ='Driver Build'!I15
A8: Impairment charge | E8: ='Driver Build'!E16 | F8: ='Driver Build'!F16 | G8: ='Driver Build'!G16 | H8: ='Driver Build'!H16 | I8: ='Driver Build'!I16
A9: Profit before tax | E9: ='Driver Build'!E17 | F9: ='Driver Build'!F17 | G9: ='Driver Build'!G17 | H9: ='Driver Build'!H17 | I9: ='Driver Build'!I17
A10: Tax | E10: ='Driver Build'!E18 | F10: ='Driver Build'!F18 | G10: ='Driver Build'!G18 | H10: ='Driver Build'!H18 | I10: ='Driver Build'!I18
A11: Net profit after tax | E11: ='Driver Build'!E19 | F11: ='Driver Build'!F19 | G11: ='Driver Build'!G19 | H11: ='Driver Build'!H19 | I11: ='Driver Build'!I19
A12: less: non-controlling interests | E12: ='Driver Build'!E20 | F12: ='Driver Build'!F20 | G12: ='Driver Build'!G20 | H12: ='Driver Build'!H20 | I12: ='Driver Build'!I20
A13: Profit attributable to owners | E13: ='Driver Build'!E21 | F13: ='Driver Build'!F21 | G13: ='Driver Build'!G21 | H13: ='Driver Build'!H21 | I13: ='Driver Build'!I21
A14: less: AT1 sukuk distributions | E14: ='Driver Build'!E22 | F14: ='Driver Build'!F22 | G14: ='Driver Build'!G22 | H14: ='Driver Build'!H22 | I14: ='Driver Build'!I22
A15: Earnings to common | E15: ='Driver Build'!E23 | F15: ='Driver Build'!F23 | G15: ='Driver Build'!G23 | H15: ='Driver Build'!H23 | I15: ='Driver Build'!I23
A16: less: equity retained for RWA growth (at target CET1) | E16: =-'Driver Build'!E33 | F16: =-'Driver Build'!F33 | G16: =-'Driver Build'!G33 | H16: =-'Driver Build'!H33 | I16: =-'Driver Build'!I33
A17: Free cash flow to equity (FCFE) | E17: =E15+E16 | F17: =F15+F16 | G17: =G15+G16 | H17: =H15+H16 | I17: =I15+I16
A18: Discount factor @ Ke | E18: =1/(1+Assumptions!$B$16)^1 | F18: =1/(1+Assumptions!$B$16)^2 | G18: =1/(1+Assumptions!$B$16)^3 | H18: =1/(1+Assumptions!$B$16)^4 | I18: =1/(1+Assumptions!$B$16)^5
A19: PV of FCFE | E19: =E17*E18 | F19: =F17*F18 | G19: =G17*G18 | H19: =H17*H18 | I19: =I17*I18
A21: TERMINAL VALUE & BRIDGE TO PER-SHARE
A22: Σ PV of explicit FCFE (FY26–30) | B22: =SUM(E19:I19)
A23: Terminal FCFE (FY31) = FY30 × (1+g) | B23: =I17*(1+Assumptions!$B$17)
A24: Terminal value = terminal FCFE / (Ke − g) | B24: =B23/(Assumptions!$B$16-Assumptions!$B$17)
A25: PV of terminal value | B25: =B24*I18
A26: Equity value = Σ PV explicit + PV terminal | B26: =B22+B25
A27: ÷ shares outstanding (mn) | B27: =Assumptions!$B$6
A28: FCFE VALUE PER SHARE (AED) | B28: =B26/B27
A29: Memo: terminal value as % of equity value | B29: =B25/B26

Sheet Residual Income
A1: Residual income — book value plus the value of excess returns
A2: The lens least dependent on terminal assumptions, and the natural cross-check on both DCFs.
E4: FY26E | F4: FY27E | G4: FY28E | H4: FY29E | I4: FY30E
A5: Opening common equity | E5: =Assumptions!$B$38 | F5: =E6 | G5: =F6 | H5: =G6 | I5: =H6
A6: Closing common equity | E6: =E5+'Driver Build'!E23+'Driver Build'!E28 | F6: =F5+'Driver Build'!F23+'Driver Build'!F28 | G6: =G5+'Driver Build'!G23+'Driver Build'!G28 | H6: =H5+'Driver Build'!H23+'Driver Build'!H28 | I6: =I5+'Driver Build'!I23+'Driver Build'!I28
A7: Net profit to common | E7: ='Driver Build'!E23 | F7: ='Driver Build'!F23 | G7: ='Driver Build'!G23 | H7: ='Driver Build'!H23 | I7: ='Driver Build'!I23
A8: Equity charge (Ke × opening equity) | E8: =-Assumptions!$B$16*E5 | F8: =-Assumptions!$B$16*F5 | G8: =-Assumptions!$B$16*G5 | H8: =-Assumptions!$B$16*H5 | I8: =-Assumptions!$B$16*I5
A9: Residual income | E9: =E7+E8 | F9: =F7+F8 | G9: =G7+G8 | H9: =H7+H8 | I9: =I7+I8
A10: Discount factor @ Ke | E10: =1/(1+Assumptions!$B$16)^1 | F10: =1/(1+Assumptions!$B$16)^2 | G10: =1/(1+Assumptions!$B$16)^3 | H10: =1/(1+Assumptions!$B$16)^4 | I10: =1/(1+Assumptions!$B$16)^5
A11: PV of residual income | E11: =E9*E10 | F11: =F9*F10 | G11: =G9*G10 | H11: =H9*H10 | I11: =I9*I10
A13: Common book value (Dec-2025) | B13: =Assumptions!$B$38
A14: Σ PV of explicit residual income | B14: =SUM(E11:I11)
A15: PV of terminal residual income | B15: =I9*(1+Assumptions!$B$17)/(Assumptions!$B$16-Assumptions!$B$17)*I10
A16: Equity value | B16: =B13+B14+B15
A17: ÷ shares (mn) | B17: =Assumptions!$B$6
A18: RESIDUAL-INCOME VALUE PER SHARE (AED) | B18: =B16/B17
A19: Implied P/B on current common book | B19: =B18/(Assumptions!$B$38/Assumptions!$B$6)

Sheet Relative & Normalized
A1: Relative multiples and normalized (through-cycle) value
A2: The two market-anchored lenses — the discipline on the DCF family.
A4: RELATIVE
A5: DIB book value per share (common, ex-AT1) | B5: =Assumptions!$B$38/Assumptions!$B$6
A6: Sector P/B mark (UAE large-cap band) | B6: =Assumptions!$B$48
A7: Value on P/B | B7: =B5*B6
A8: FY26E EPS | B8: ='Driver Build'!E24
A9: Sector forward P/E mark | B9: =Assumptions!$B$49
A10: Value on P/E | B10: =B8*B9
A11: RELATIVE VALUE (50/50 blend) | B11: =AVERAGE(B7,B10)
A12: DIB's OWN P/B at spot | B12: =Assumptions!$B$5/(Assumptions!$B$38/Assumptions!$B$6)
A13: DIB's OWN trailing P/E at spot | B13: =Assumptions!$B$5/0.98
A15: NORMALIZED (THROUGH-CYCLE)
A16: Through-cycle ROE | B16: =Assumptions!$B$19
A17: Normalized EPS = ROE × BVPS | B17: =B16*(Assumptions!$B$38/Assumptions!$B$6)
A18: Justified P/B = (ROE − g) / (Ke − g) | B18: =(B16-Assumptions!$B$17)/(Assumptions!$B$16-Assumptions!$B$17)
A19: NORMALIZED VALUE (AED / share) | B19: =B18*(Assumptions!$B$38/Assumptions!$B$6)
A20: Implied P/E on normalized earnings | B20: =B19/B18
A22: Valuing normalized earnings at the P/B their ROE justifies — rather than an arbitrarily low multiple — keeps this lens internally consistent with the other four, which all discount at the same Ke.

Sheet Income Statement
A1: Income statement — 3 years history + 5-year model
A2: AED mn. History: DIB press releases + FY25 audited consolidated FS.
B4: FY23 | C4: FY24 | D4: FY25 | E4: FY26E | F4: FY27E | G4: FY28E | H4: FY29E | I4: FY30E
A5: Funded income (the spread) | D5: 8972 | E5: ='Driver Build'!E11 | F5: ='Driver Build'!F11 | G5: ='Driver Build'!G11 | H5: ='Driver Build'!H11 | I5: ='Driver Build'!I11
A6: Non-funded income (fees, FX, trading) | D6: 4279 | E6: ='Driver Build'!E12 | F6: ='Driver Build'!F12 | G6: ='Driver Build'!G12 | H6: ='Driver Build'!H12 | I6: ='Driver Build'!I12
A7: Operating revenue | B7: 11665 | C7: 12837 | D7: 13251 | E7: ='Driver Build'!E13 | F7: ='Driver Build'!F13 | G7: ='Driver Build'!G13 | H7: ='Driver Build'!H13 | I7: ='Driver Build'!I13
A8: Operating expenses | B8: -3161 | C8: -3425 | D8: -3763 | E8: ='Driver Build'!E14 | F8: ='Driver Build'!F14 | G8: ='Driver Build'!G14 | H8: ='Driver Build'!H14 | I8: ='Driver Build'!I14
A9: Pre-provision operating profit | B9: 8504 | C9: 9412 | D9: 9488 | E9: ='Driver Build'!E15 | F9: ='Driver Build'!F15 | G9: ='Driver Build'!G15 | H9: ='Driver Build'!H15 | I9: ='Driver Build'!I15
A10: Impairment charge (net) | B10: -1396 | C10: -407 | D10: -485 | E10: ='Driver Build'!E16 | F10: ='Driver Build'!F16 | G10: ='Driver Build'!G16 | H10: ='Driver Build'!H16 | I10: ='Driver Build'!I16
A11: Profit before tax (REPORTED) | B11: 7108 | C11: 9005 | D11: 9003 | E11: ='Driver Build'!E17 | F11: ='Driver Build'!F17 | G11: ='Driver Build'!G17 | H11: ='Driver Build'!H17 | I11: ='Driver Build'!I17
A13: FY24 NORMALISATION — DISCLOSED LINE BY LINE (FY25 deck, slide 10) | B13: FY24 reported | C13: FY24 normalised | D13: legacy recovery
A14: Net funded income | B14: 8949 | C14: 8691 | D14: 258
A15: Non-funded income | B15: 3887 | C15: 3887 | D15: 0
A16: Operating revenue | B16: 12837 | C16: 12579 | D16: 258
A17: Operating expenses | B17: -3425 | C17: -3425 | D17: 0
A18: Pre-provision operating profit | B18: 9412 | C18: 9154 | D18: 258
A19: Net impairment charges | B19: -407 | C19: -1677 | D19: 1270
A20: Profit before tax | B20: 9005 | C20: 7477 | D20: 1528
A21: Net profit after tax | B21: 8165 | C21: 6637 | D21: 1528
A23: Tax | B23: -98 | C23: -840 | D23: -1195 | E23: ='Driver Build'!E18 | F23: ='Driver Build'!F18 | G23: ='Driver Build'!G18 | H23: ='Driver Build'!H18 | I23: ='Driver Build'!I18
A24: Net profit after tax | B24: 7010 | C24: 8165 | D24: 7808 | E24: ='Driver Build'!E19 | F24: ='Driver Build'!F19 | G24: ='Driver Build'!G19 | H24: ='Driver Build'!H19 | I24: ='Driver Build'!I19
A25: less: non-controlling interests | B25: -200 | C25: -231 | D25: -308 | E25: ='Driver Build'!E20 | F25: ='Driver Build'!F20 | G25: ='Driver Build'!G20 | H25: ='Driver Build'!H20 | I25: ='Driver Build'!I20
A26: Profit attributable to owners | B26: 6810 | C26: 7934 | D26: 7500 | E26: ='Driver Build'!E21 | F26: ='Driver Build'!F21 | G26: ='Driver Build'!G21 | H26: ='Driver Build'!H21 | I26: ='Driver Build'!I21
A27: less: AT1 sukuk distributions | B27: -576 | C27: -576 | D27: -419 | E27: ='Driver Build'!E22 | F27: ='Driver Build'!F22 | G27: ='Driver Build'!G22 | H27: ='Driver Build'!H22 | I27: ='Driver Build'!I22
A28: Earnings to common | B28: 6234 | C28: 7358 | D28: 7081 | E28: ='Driver Build'!E23 | F28: ='Driver Build'!F23 | G28: ='Driver Build'!G23 | H28: ='Driver Build'!H23 | I28: ='Driver Build'!I23
A29: EPS (AED) | B29: 0.863 | C29: 1.018 | D29: 0.98 | E29: ='Driver Build'!E24 | F29: ='Driver Build'!F24 | G29: ='Driver Build'!G24 | H29: ='Driver Build'!H24 | I29: ='Driver Build'!I24
A30: DPS (AED) | B30: 0.45 | C30: 0.45 | D30: 0.35 | E30: =Assumptions!E$28 | F30: =Assumptions!F$28 | G30: =Assumptions!G$28 | H30: =Assumptions!H$28 | I30: =Assumptions!I$28
A32: THE DUAL FRAME. DIB's FY25 pre-tax profit of AED 9,003mn is FLAT against the REPORTED FY24 base (9,005) and +20% against the
A33: NORMALISED one (7,477). Net profit reads -4% or +18% on the same two bases. Operating revenue is +3% reported, +5% normalised —
A34: DIB's own words: 'growth of 5% YoY over normalized revenues of FY24'. Both framings are stated everywhere the figure appears.
A35: SOURCE: the AED 1,528mn split (258 into funded income, 1,270 into impairment) is DIB's own disclosure — the income-statement
A36: slide of the FY2025 investor presentation. It is not our derivation. The reported FY24 cost of risk of 14bp is flattered by it;
A37: the bank's own normalised charge is 1,677mn, or 58bp. That is the number the cost-of-risk debate in this study turns on.

Sheet Balance Sheet
A1: Balance sheet & capital
A2: AED mn. FY26E+ assets and deposits held at the Dec-25 mix — presentation scaffolding, not drivers.
B4: FY23 | C4: FY24 | D4: FY25 | E4: FY26E | F4: FY27E | G4: FY28E | H4: FY29E | I4: FY30E
A5: Total assets | B5: 314000 | C5: 344687 | D5: 415948 | E5: ='Driver Build'!E6 | F5: ='Driver Build'!F6 | G5: ='Driver Build'!G6 | H5: ='Driver Build'!H6 | I5: ='Driver Build'!I6
A6: Net financing + sukuk investments | B6: 274000 | C6: 294588 | D6: 352644 | E6: ='Driver Build'!E5 | F6: ='Driver Build'!F5 | G6: ='Driver Build'!G5 | H6: ='Driver Build'!H5 | I6: ='Driver Build'!I5
A7: Customer deposits | B7: 222000 | C7: 248546 | D7: 320184 | E7: ='Driver Build'!E7 | F7: ='Driver Build'!F7 | G7: ='Driver Build'!G7 | H7: ='Driver Build'!H7 | I7: ='Driver Build'!I7
A8: Financing-to-deposit ratio | B8: =B6/B7 | C8: =C6/C7 | D8: =D6/D7 | E8: =E6/E7 | F8: =F6/F7 | G8: =G6/G7 | H8: =H6/H7 | I8: =I6/I7
A10: Equity attributable to owners | D10: =Assumptions!$B$36
A11: less: Tier-1 (AT1) sukuk | D11: =-Assumptions!$B$37
A12: Common equity (ex-AT1) | D12: =Assumptions!$B$38 | E12: ='Residual Income'!E8 | F12: ='Residual Income'!F8 | G12: ='Residual Income'!G8 | H12: ='Residual Income'!H8 | I12: ='Residual Income'!I8
A13: CET1 capital (DISCLOSED, not derived) | C13: 34000 | D13: =Assumptions!$B$40 | E13: ='Driver Build'!E30 | F13: ='Driver Build'!F30 | G13: ='Driver Build'!G30 | H13: ='Driver Build'!H30 | I13: ='Driver Build'!I30
A14: Risk-weighted assets (DISCLOSED, not derived) | C14: 257200 | D14: =Assumptions!$B$39 | E14: ='Driver Build'!E27 | F14: ='Driver Build'!F27 | G14: ='Driver Build'!G27 | H14: ='Driver Build'!H27 | I14: ='Driver Build'!I27
A15: CET1 ratio | C15: 0.132 | D15: =Assumptions!$B$40/Assumptions!$B$39 | E15: ='Driver Build'!E31 | F15: ='Driver Build'!F31 | G15: ='Driver Build'!G31 | H15: ='Driver Build'!H31 | I15: ='Driver Build'!I31
A16: Effective regulatory floor (Fitch 12% + 0.5% CCyB) | D16: 0.125 | E16: 0.125 | F16: 0.125 | G16: 0.125 | H16: 0.125 | I16: 0.125
A18: CAR (total capital, reported) | B18: 0.173 | C18: 0.183 | D18: 0.155
A19: NPF ratio (reported) | B19: 0.054 | C19: 0.04 | D19: 0.0265
A20: Coverage incl. collateral (reported) | B20: 1.21 | C20: 1.38 | D20: 1.6
A22: RISK-WEIGHTED ASSETS AND CET1 CAPITAL ARE PUBLISHED FIGURES, and this model uses them directly. Both come from the
A23: regulatory-capital slide of the FY2025 and Q1-2026 investor presentations (RWA movement bridge and CET1 capital bridge):
A24: RWA 257.2bn (Dec-24) -> 298.9bn (Dec-25) -> 305.0bn (Q1-26); CET1 capital 34.0 -> 36.9 -> 38.5bn. The check ties:
A25: 36,900 / 298,900 = 12.35%, against the 12.3% CET1 ratio the bank reports. Only the forward DENSITY FADE is our own assumption.
A26: The CET1 GLIDE (FY26E+) is an OUTPUT of the dividend policy, not an input — see the Driver Build sheet.
A27: Q1-2026 anchors (official): total assets 420,000 · financing+sukuk 364,000 · deposits 322,000 · CET1 12.6% · CAR 15.8% · NPF 2.5%.

Sheet Cash Flow
A1: Cash flow — the capital equation
A2: For a bank the meaningful cash statement is the capital walk: what is earned, what growth consumes, what is left to pay.
E4: FY26E | F4: FY27E | G4: FY28E | H4: FY29E | I4: FY30E
A5: Earnings to common | E5: ='Driver Build'!E23 | F5: ='Driver Build'!F23 | G5: ='Driver Build'!G23 | H5: ='Driver Build'!H23 | I5: ='Driver Build'!I23
A6: less: dividends paid (board policy) | E6: ='Driver Build'!E28 | F6: ='Driver Build'!F28 | G6: ='Driver Build'!G28 | H6: ='Driver Build'!H28 | I6: ='Driver Build'!I28
A7: Retained earnings → CET1 | E7: =E5+E6 | F7: =F5+F6 | G7: =G5+G6 | H7: =H5+H6 | I7: =I5+I6
A9: Capital ABSORBED by RWA growth (at target CET1) | E9: =-'Driver Build'!E33 | F9: =-'Driver Build'!F33 | G9: =-'Driver Build'!G33 | H9: =-'Driver Build'!H33 | I9: =-'Driver Build'!I33
A10: Free cash flow to equity (distributable capacity) | E10: =E5+E9 | F10: =F5+F9 | G10: =G5+G9 | H10: =H5+H9 | I10: =I5+I9
A11: Dividend cover (FCFE / dividends paid) | E11: =E10/-E6 | F11: =F10/-F6 | G11: =G10/-G6 | H11: =H10/-H6 | I11: =I10/-I6
A13: Cumulative FY26–30 dividends (AED mn) | B13: =-SUM(E6:I6)
A14: Cumulative FY26–30 FCFE (AED mn) | B14: =SUM(E10:I10)
A16: A bank has no capex line and no working-capital line. The item it cannot avoid is the fresh equity it must retain each year to hold its
A17: capital ratio as the balance sheet grows — that is the analogue of capex, and it is the line above. FCFE is what remains: genuinely
A18: distributable, whether or not it is actually paid. The gap between FCFE and the declared dividend is the capital DIB is accumulating.

Sheet Monte Carlo
A1: Monte Carlo — ILLUSTRATIVE VOLATILITY MAP ONLY
A2: NOT a validated forecast. The calibration test FAILED.
A3: THE CALIBRATION TEST FAILED. No price-distribution forecast is published for DIB. The percentiles below describe the width of the engine's cone; they are NOT a forecast and nothing is entered on the Calibration Ledger against them.
A5: THE BACKTEST, IN THE OPEN
A6: Design | B6: walk-forward, h=60 trading days, non-overlapping, post-2022 break
A7: Windows | B7: 14
A8: Skill score vs a naive random walk | B8: -0.024700655
A9: Skill score on median placement | B9: 0.0029933837
A10: Skill score on interval width | B10: -0.030774145
A11: Coverage 50 / 80 / 90 | B11: 0.43 / 0.79 / 1.00
A12: Calibration mean (0.50 = perfectly centred) | B12: 0.57585714
A13: Bootstrap 90% CI — resampling scheme 1 | B13: [-0.0346, -0.0028]
A14: Bootstrap 90% CI — resampling scheme 2 | B14: [-0.0349, -0.0028]
A15: Bootstrap 90% CI — resampling scheme 3 | B15: [-0.0345, -0.0014]
A16: VERDICT (all three schemes agree) | B16: FAIL
A18: DIAGNOSIS — why it failed, and why that is not the same as "the model is broken"
A19: No structural defect was found. The three causes a FAIL is meant to flag are all absent:
A20: · price-limit censoring — none (largest daily move in the sample 8.99%; the DFM limit was never struck)
A21: · degenerate volatility — none (9.2% zero-return days, normal for a DFM large-cap)
A22: · data quality — the Yang-Zhang variance proxy is unbiased at 1.017× close-to-close realized vol
A24: The mechanism is this. The UAE profile is CARRY-ONLY (no signal survived the AE panel), and DIB's carry is ~0 because
A25: its dividend yield (4.53%) almost exactly offsets the risk-free rate (3.65%). Engine and benchmark therefore share an
A26: IDENTICAL centre — the median-placement skill score is 0.000, a dead heat. The test collapses to a pure WIDTH contest.
A28: And on width the engine is right, not wrong: its 60-day sigma (0.105) matches the full-sample realized 60-day dispersion
A29: (0.114) far better than the naive benchmark does (0.093, ~19% too narrow — DIB's 60-day variance is 1.23x what
A30: square-root-of-time scaling implies, so the random walk systematically under-disperses). But the 14 non-overlapping
A31: windows we specified in advance happened to draw a QUIET subsample (realized sd 0.083). Against quiet outcomes, the
... A43: ILLUSTRATIVE CONE (width only — read as a volatility map, NOT a forecast)
B44: T+20 (AED) | C44: T+60 (AED)
A45: 5th percentile | B45: 6.9684201 | C45: 6.4633208
A46: 25th percentile | B46: 7.4497627 | C46: 7.2508327
A47: 50th percentile | B47: 7.715666 | C47: 7.7069376
A48: 75th percentile | B48: 7.9941035 | C48: 8.1934005
A49: 95th percentile | B49: 8.5500149 | C49: 9.1770294
A51: Anchor vol (annualized, YZ-HAR) | B51: 0.22496337
A52: Carry over 60d = ln(1+rf) − ln(1+q) | B52: -0.0020213013
A53: rf (CBUAE base rate) | B53: 0.0365
A54: q (DIB dividend yield at spot) | B54: 0.045336788
A55: Paths · seed · shape | B55: 50,000 · 42 · Student-t(4)
A57: Carry is essentially zero: DIB pays out its risk-free carry as dividend. Expected total return ~ the risk-free rate, delivered as
...

Sheet Sensitivity
A1: Sensitivity — Ke × terminal growth, beta, and the crux in real units
A4: WEIGHTED CENTRAL (AED)
A5: Ke ↓ / g → | B5: 0.03 | C5: 0.035 | D5: 0.04 | E5: 0.045
A6: 0.0957 | B6: 10.99 | C6: 11.39 | D6: 11.86 | E6: 12.43
A7: 0.1007 | B7: 10.26 | C7: 10.58 | D7: 10.95 | E7: 11.39
A8: 0.1057 | B8: 9.63 | C8: 9.89 | D8: 10.18 | E8: 10.53
A9: 0.1107 | B9: 9.08 | C9: 9.29 | D9: 9.52 | E9: 9.79
A10: 0.1157 | B10: 8.59 | C10: 8.76 | D10: 8.95 | E10: 9.17
A11: 0.1207 | B11: 8.16 | C11: 8.3 | D11: 8.45 | E11: 8.62
A13: DDM ALONE (AED)
A14: Ke ↓ / g → | B14: 0.03 | C14: 0.035 | D14: 0.04 | E14: 0.045
A15: 0.0957 | B15: 12.12 | C15: 12.57 | D15: 13.11 | E15: 13.75
A16: 0.1007 | B16: 11.14 | C16: 11.5 | D16: 11.91 | E16: 12.4
A17: 0.1057 | B17: 10.29 | C17: 10.58 | D17: 10.9 | E17: 11.27
A18: 0.1107 | B18: 9.56 | C18: 9.78 | D18: 10.03 | E18: 10.32
A19: 0.1157 | B19: 8.91 | C19: 9.09 | D19: 9.28 | E19: 9.51
A20: 0.1207 | B20: 8.33 | C20: 8.47 | D20: 8.63 | E20: 8.8
A22: BETA GRID (beta defaults to 1.0 — the regression had only 19 observations, below our 24 minimum)
A23: Beta | B23: 0.8 | C23: 0.9 | D23: 1 | E23: 1.1 | F23: 1.2 | G23: 1.3
A24: Weighted central (AED) | B24: 11.81 | C24: 10.93 | D24: 10.18 | E24: 9.54 | F24: 8.98 | G24: 8.49
A25: SECTOR P/B MARK — the relative lens is 20% of the central, so this input is sensitized
A26: Sector P/B mark | B26: 1.3 | C26: 1.4 | D26: 1.45 | E26: 1.52 | F26: 1.6
A27: Relative-lens value (AED) | B27: 7.6957337 | C27: 7.9901989 | D27: 8.1374315 | E27: 8.3435572 | F27: 8.5791293
A29: THE CRUX, IN REAL UNITS | B29: Effect on central (AED/share)
A30: NPM +10bp across the path (≈ AED 0.47bn revenue/yr) | B30: 0.32394929
A31: NPM −10bp across the path | B31: -0.32394929
A32: NPM −20bp (the bear rate path) | B32: -0.64789859
A33: Cost of risk +10bp (≈ AED 0.44bn pre-tax/yr) | B33: -0.41556708
A34: Cost of risk −10bp | B34: 0.41556708
A35: Cost of risk to 60bp (the FY24 NORMALISED charge) | B35: -0.62335063
A36: Effective tax back to 9% (management's stated aim) | B36: 0.69748877
A37: Conflict adder → 0 (peace) | B37: 1.6805653
A38: Conflict adder → 2.5pt (renewed Hormuz closure) | B38: -1.7317221
A40: Both ERP bases are carried: rating-based Ke 10.57% and CDS-based 10.63%. The published central uses the rating basis.

Sheet Per-Share & Ratios
A1: Per-share and ratio dashboard
A2: The same fixed panel is carried in every Testahil study, so names can be compared like for like.
B4: FY23 | C4: FY24 | D4: FY25 | E4: FY26E | F4: FY27E | G4: FY28E | H4: FY29E | I4: FY30E
A5: EPS (AED) | B5: 0.863 | C5: 1.018 | D5: 0.98 | E5: ='Driver Build'!E24 | F5: ='Driver Build'!F24 | G5: ='Driver Build'!G24 | H5: ='Driver Build'!H24 | I5: ='Driver Build'!I24
A6: DPS (AED) | B6: 0.45 | C6: 0.45 | D6: 0.35 | E6: =Assumptions!E$28 | F6: =Assumptions!F$28 | G6: =Assumptions!G$28 | H6: =Assumptions!H$28 | I6: =Assumptions!I$28
A7: BVPS — common, ex-AT1 (AED) | D7: =Assumptions!$B$38/Assumptions!$B$6 | E7: ='Residual Income'!E8/Assumptions!$B$6 | F7: ='Residual Income'!F8/Assumptions!$B$6 | G7: ='Residual Income'!G8/Assumptions!$B$6 | H7: ='Residual Income'!H8/Assumptions!$B$6 | I7: ='Residual Income'!I8/Assumptions!$B$6
A8: Payout ratio | B8: 0.522 | C8: 0.442 | D8: 0.357 | E8: =Assumptions!E$28/'Driver Build'!E24 | F8: =Assumptions!F$28/'Driver Build'!F24 | G8: =Assumptions!G$28/'Driver Build'!G24 | H8: =Assumptions!H$28/'Driver Build'!H24 | I8: =Assumptions!I$28/'Driver Build'!I24
A10: P/E (at spot) | B10: =Assumptions!$B$5/B5 | C10: =Assumptions!$B$5/C5 | D10: =Assumptions!$B$5/D5 | E10: =Assumptions!$B$5/E5 | F10: =Assumptions!$B$5/F5 | G10: =Assumptions!$B$5/G5 | H10: =Assumptions!$B$5/H5 | I10: =Assumptions!$B$5/I5
A11: P/B (at spot) | D11: =Assumptions!$B$5/D7 | E11: =Assumptions!$B$5/E7 | F11: =Assumptions!$B$5/F7 | G11: =Assumptions!$B$5/G7 | H11: =Assumptions!$B$5/H7 | I11: =Assumptions!$B$5/I7
A12: Dividend yield (at spot) | B12: =B6/Assumptions!$B$5 | C12: =C6/Assumptions!$B$5 | D12: =D6/Assumptions!$B$5 | E12: =E6/Assumptions!$B$5 | F12: =F6/Assumptions!$B$5 | G12: =G6/Assumptions!$B$5 | H12: =H6/Assumptions!$B$5 | I12: =I6/Assumptions!$B$5
A14: Net profit margin (NPM) | B14: 0.03 | C14: 0.03 | D14: 0.026 | E14: =Assumptions!E$23 | F14: =Assumptions!F$23 | G14: =Assumptions!G$23 | H14: =Assumptions!H$23 | I14: =Assumptions!I$23
A15: Cost-to-income | B15: 0.271 | C15: 0.2668 | D15: 0.284 | E15: 0.28 | F15: 0.278 | G15: 0.275 | H15: 0.273 | I15: 0.27
A16: Cost of risk (bp) | B16: 57 | C16: 14 | D16: 14 | E16: 45 | F16: 45 | G16: 40 | H16: 35 | I16: 35
A17: Effective tax rate | B17: 0.0138 | C17: 0.0933 | D17: 0.1327 | E17: 0.15 | F17: 0.15 | G17: 0.15 | H17: 0.15 | I17: 0.15
A18: RoAA (post-tax) | D18: 0.0205 | E18: 0.0161 | F18: 0.0159 | G18: 0.0165 | H18: 0.0171 | I18: 0.0173
A19: ROE (on common equity) | D19: 0.1721 | E19: 0.1399 | F19: 0.1383 | G19: 0.1449 | H19: 0.1503 | I19: 0.152
A20: RoTE — post-tax (DIB DISCLOSED, FY23-25) | C20: 0.22 | D20: 0.19
A21: RoTE — pre-tax (DIB DISCLOSED) | D21: 0.22
A22: memo: FY24 RoTE NORMALISED (post-tax) | C22: 0.18
A23: CET1 ratio | D23: 0.123 | E23: ='Driver Build'!E31 | F23: ='Driver Build'!F31 | G23: ='Driver Build'!G31 | H23: ='Driver Build'!H31 | I23: ='Driver Build'!I31
A24: Financing + sukuk growth | C24: 0.075 | D24: 0.197 | E24: =Assumptions!E$22 | F24: =Assumptions!F$22 | G24: =Assumptions!G$22 | H24: =Assumptions!H$22 | I24: =Assumptions!I$22
A26: RoTE figures are DIB's OWN disclosure (the income-statement slide of the FY2025 investor presentation), not a third-party
A27: computation. Third-party peer tables are not used here — see the Peer & Sector sheet for why.
A28: NORMALISED RETURN ON COMMON EQUITY: FY24 (excluding the legacy recovery) 15.5%, FY25 17.2% -> a two-year average of 16.3%.
A29: The FY26E-30E path (13.8-15.2%) sits deliberately BELOW that history: margin compression and a normalised cost of risk.

Sheet Peer & Sector
A1: Peer set and sector
A2: Market multiples are aggregator-sourced MARKET DATA (KAMCO Invest research, prices 12-Feb-2026) — never used for statement lines.
A4: Bank | B4: P/B | C4: ROTE | D4: Div yield | E4: Cost-to-income | F4: Read vs DIB
A6: THE SECTOR MARK IS ANCHORED SAME-DAY. Applying a peer multiple struck months ago to today's share price manufactures cheapness
A7: out of nothing more than the passage of time — and after a war, that error would be large. So the marks (1.45x book, 9.0x forward
A8: earnings) are anchored on the only rigorous same-day comparator available: ADCB at 1.52x book and 8.7x forward earnings at the
A9: IDENTICAL 03-Jul close (Testahil ADCB study, 10-Jul-2026). Third-party peer tables struck earlier in the year are NOT used here:
A10: one widely circulated set carried ADCB at 11.4% RoTE against ADCB's own Q1-26 disclosure of 18.1%.
A11: Like-for-like, same day: DIB 1.31x vs ADCB 1.52x — a ~14% discount on a comparable return. That gap is real.
A13: SECTOR
A14: UAE banking sector total assets (Q1-2026) | B14: AED 5.56tn, +17.7% YoY
A15: Sector loan growth / deposit growth | B15: +20.3% / +17.4% YoY
A16: Sector CAR / net NPL | B16: 16.8% / 1.5%
A17: CBUAE base rate | B17: 3.65% (cut Dec-2025, held Jan/Mar/Jun-2026)
A18: CBUAE 2026 GDP forecast | B18: 1.7% — CUT from 5.6% (June-2026 QER, the war's bill)
A19: Counter-cyclical buffer on UAE private-sector credit | B19: 0.5% from 2026
A20: DIB ratings | B20: Moody's A3 stable · Fitch A
A21: Fitch downgrade trigger | B21: CET1 sustainably below 12%, or impaired financing above 7%

Sheet Earnings Drivers
A1: Driver table — how each assumption was set
A2: Every driver names the research-register line that justifies it. See the study, Appendix B.
A4: Driver | B4: Mode | C4: Justification, and the research-register line that supports it | D4: Logged?
A5: Financing + sukuk growth (10%→7%) | B5: Top-down | C5: FY26 IS management guidance (10%). No unit-level pipeline disclosure exists. The FY27–30 fade is our own assumption. [F14, F25] | D5: YES
A6: NPM (2.30% trough 2.28% → 2.40%) | B6: Top-down | C6: FY26 IS management guidance (2.3%). DIB does NOT publish a 25bp/100bp margin-sensitivity table — we searched the FY25 presentation, the results release, the audited statements and Pillar 3, and recorded the negative finding (F09). The path is anchored on the disclosed quarterly margin series (3.0 → 2.6 → 2.5) and the central-bank rate path. [F01, F09, F15] | D6: YES
A7: Non-funded income (+10% then +7%) | B7: Top-down | C7: The Q1-26 headline was +30% YoY — but the composition (disclosed) shows it is ONE line: other income 105 → 587. Fees/commission/FX FELL 505 → 427; property income FELL 274 → 162. The recurring franchise lines are declining, so the headline is not extrapolated. [F24] | D7: YES
A8: Cost-to-income (28.5% → 27.2%) | B8: Top-down | C8: FY26 IS management guidance (28%). Reported quarterly; unit economics are not. The glide beyond FY26 is held deliberately SHALLOW — assumed operating leverage is the most common way a forecast flatters itself. [F17] | D8: YES
A9: Cost of risk (45bp flat → 35bp) | B9: Top-down | C9: FY26 IS the Q1-26 print (45bp), not a forecast. It steps up hard from FY25's 14bp — a benign base, and the FY24 figure is flattered by the legacy recovery (normalised: 58bp). Counter-evidence, disclosed: asset quality is IMPROVING (Q1-26 NPF 2.5%, a decade low; cash coverage 122%). [F11, F15, F26] | D9: YES
A10: Effective tax rate (15.0% flat) | B10: Top-down | C10: Q1-26 printed 15.4%, so we take the 15% minimum-tax rate as the base. NOTE the countervailing evidence, all disclosed: FY25 ACTUALLY printed 13.3% — in the FIRST year the top-up tax applied — and Q1-25 ran 14.75% against a 13.3% full year, so the first quarter runs ABOVE the year. A sub-15% consolidated rate is demonstrably POSSIBLE (associates enter pre-tax profit already net of their own tax). 15.0% is therefore a conservative floor we have chosen, not a statutory necessity. [F06, F12] | D10: YES
A11: DPS (0.35 held, then progressive) | B11: Board policy | C11: FY25 DPS of 35 fils is DISCLOSED (approved at the AGM on 02-Apr-2026, AED 2.53bn). Held flat through the FY26 earnings dip (no second cut), then progressive. CET1 is the OUTPUT, not an input. [F17] | D11: YES
A12: RWA density (84.8%, −0.8pt/yr) | B12: DISCLOSED | C12: Risk-weighted assets are PUBLISHED — the regulatory-capital slide of both investor presentations: 257.2bn Dec-24, 298.9bn Dec-25, 305.0bn Q1-26. CET1 capital likewise (34.0 / 36.9 / 38.5bn). Only the forward DENSITY FADE (−0.8pt/yr) is our own assumption. [F19] | D12: fade only
A13: Beta (1.00) | B13: FALLBACK | C13: A regression against the DFM General Index was genuinely attempted: n=19, beta 0.796, R-sq 29.9%, SE 0.296. The fit quality and sign are fine; the sample is 19 observations against our 24-observation minimum. Two sources tried (investing.com serves 20 rows only; dfm.ae renders client-side). Beta therefore defaults to 1.00 and is sensitized 0.8–1.3. [F20] | D13: YES

Sheet Summary Financials
A1: Summary financials
A2: Every cell on this sheet is a link. Nothing here is typed.
B4: FY23 | C4: FY24 | D4: FY25 | E4: FY26E | F4: FY27E | G4: FY28E | H4: FY29E | I4: FY30E
A5: Operating revenue | B5: ='Income Statement'!B7 | C5: ='Income Statement'!C7 | D5: ='Income Statement'!D7 | E5: ='Income Statement'!E7 | F5: ='Income Statement'!F7 | G5: ='Income Statement'!G7 | H5: ='Income Statement'!H7 | I5: ='Income Statement'!I7
A6: Pre-provision operating profit | B6: ='Income Statement'!B9 | C6: ='Income Statement'!C9 | D6: ='Income Statement'!D9 | E6: ='Income Statement'!E9 | F6: ='Income Statement'!F9 | G6: ='Income Statement'!G9 | H6: ='Income Statement'!H9 | I6: ='Income Statement'!I9
A7: Impairment charge | B7: ='Income Statement'!B10 | C7: ='Income Statement'!C10 | D7: ='Income Statement'!D10 | E7: ='Income Statement'!E10 | F7: ='Income Statement'!F10 | G7: ='Income Statement'!G10 | H7: ='Income Statement'!H10 | I7: ='Income Statement'!I10
A8: Profit before tax (reported) | B8: ='Income Statement'!B11 | C8: ='Income Statement'!C11 | D8: ='Income Statement'!D11 | E8: ='Income Statement'!E11 | F8: ='Income Statement'!F11 | G8: ='Income Statement'!G11 | H8: ='Income Statement'!H11 | I8: ='Income Statement'!I11
A9: Net profit after tax | B9: ='Income Statement'!B15 | C9: ='Income Statement'!C15 | D9: ='Income Statement'!D15 | E9: ='Income Statement'!E15 | F9: ='Income Statement'!F15 | G9: ='Income Statement'!G15 | H9: ='Income Statement'!H15 | I9: ='Income Statement'!I15
A10: Earnings to common | B10: ='Income Statement'!B19 | C10: ='Income Statement'!C19 | D10: ='Income Statement'!D19 | E10: ='Income Statement'!E19 | F10: ='Income Statement'!F19 | G10: ='Income Statement'!G19 | H10: ='Income Statement'!H19 | I10: ='Income Statement'!I19
A11: EPS (AED) | B11: ='Income Statement'!B20 | C11: ='Income Statement'!C20 | D11: ='Income Statement'!D20 | E11: ='Income Statement'!E20 | F11: ='Income Statement'!F20 | G11: ='Income Statement'!G20 | H11: ='Income Statement'!H20 | I11: ='Income Statement'!I20
A12: DPS (AED) | B12: ='Income Statement'!B21 | C12: ='Income Statement'!C21 | D12: ='Income Statement'!D21 | E12: ='Income Statement'!E21 | F12: ='Income Statement'!F21 | G12: ='Income Statement'!G21 | H12: ='Income Statement'!H21 | I12: ='Income Statement'!I21
A14: Total assets | B14: ='Balance Sheet'!B5 | C14: ='Balance Sheet'!C5 | D14: ='Balance Sheet'!D5 | E14: ='Balance Sheet'!E5 | F14: ='Balance Sheet'!F5 | G14: ='Balance Sheet'!G5 | H14: ='Balance Sheet'!H5 | I14: ='Balance Sheet'!I5
A15: Net financing + sukuk | B15: ='Balance Sheet'!B6 | C15: ='Balance Sheet'!C6 | D15: ='Balance Sheet'!D6 | E15: ='Balance Sheet'!E6 | F15: ='Balance Sheet'!F6 | G15: ='Balance Sheet'!G6 | H15: ='Balance Sheet'!H6 | I15: ='Balance Sheet'!I6
A16: Customer deposits | B16: ='Balance Sheet'!B7 | C16: ='Balance Sheet'!C7 | D16: ='Balance Sheet'!D7 | E16: ='Balance Sheet'!E7 | F16: ='Balance Sheet'!F7 | G16: ='Balance Sheet'!G7 | H16: ='Balance Sheet'!H7 | I16: ='Balance Sheet'!I7
A17: CET1 capital | B17: ='Balance Sheet'!B13 | C17: ='Balance Sheet'!C13 | D17: ='Balance Sheet'!D13 | E17: ='Balance Sheet'!E13 | F17: ='Balance Sheet'!F13 | G17: ='Balance Sheet'!G13 | H17: ='Balance Sheet'!H13 | I17: ='Balance Sheet'!I13
A18: Risk-weighted assets | B18: ='Balance Sheet'!B14 | C18: ='Balance Sheet'!C14 | D18: ='Balance Sheet'!D14 | E18: ='Balance Sheet'!E14 | F18: ='Balance Sheet'!F14 | G18: ='Balance Sheet'!G14 | H18: ='Balance Sheet'!H14 | I18: ='Balance Sheet'!I14
A19: CET1 ratio | B19: ='Balance Sheet'!B15 | C19: ='Balance Sheet'!C15 | D19: ='Balance Sheet'!D15 | E19: ='Balance Sheet'!E15 | F19: ='Balance Sheet'!F15 | G19: ='Balance Sheet'!G15 | H19: ='Balance Sheet'!H15 | I19: ='Balance Sheet'!I15
