Workbook

Sheet READ FIRST
A1: Testahil — e& / Emirates Telecommunications Group (ADX: EAND)
A3: Companion model · Independent Valuation Study · Educational analysis · Not investment advice
A5: What this workbook is. A transparent companion to the e& valuation study. Every blue cell is an input; every
A6: black cell is a formula; green cells link across sheets. All inputs live on the Assumptions sheet — change one
A7: (a segment growth rate, the EBITDA margin path, the 2027 royalty rate, a stake mark, the beta) and the whole
A8: model reprices through the DCF, the SOTP bridge and every ratio.
A10: What it is not. It is not investment advice, a recommendation, or a price target. Values are model outputs shown
A11: as ranges. The preparer is not licensed by any securities regulator and may hold a position in the security.
A13: Entity note. e& (Emirates Telecommunications Group) consolidates e& UAE, Maroc Telecom (53%), PPF Telecom /
A14: e& CEE (50%+1), e& Egypt (66%), PTCL (26% + management control; 23.4% economic), e& enterprise and e& life;
A15: Mobily (28.0%) and, until the 10-Jul-2026 sale completes, Vodafone Group (16.21% issued / 17.13% voting) are
A16: equity-accounted. House lens: consolidated FCFF DCF + a sourced stake/claims bridge (SOTP), cross-checked by
... A31: Per-Share & Ratios · Peer & Sector.

Sheet Summary
A1: Summary — every read at a glance
A2: Fair-value distribution, never a target. PARITY calibration tier: market-panel validated, no single-name edge claimed.
A4: Spot (9-Jul-2026) | B4: =Assumptions!B5 -> 19.66
A5: Market cap (AED mn) | B5: =Assumptions!B5*Assumptions!B6 -> 170979.09
A6: Weighted fundamental central (AED) | B6: ='Fundamental Valuation'!B11 -> 22.716597
A7: vs spot | B7: =B6/B4-1 -> 0.1554729
A9: Monte Carlo probability read (T+60, carry-anchored v3)
A10: P(price above spot at T+60) | B10: 0.54486
A11: P(≥ +10%) / P(≤ −10%) | B11: 17.8% / 11.6% → odds 1.53
A12: Median path (AED / move) | B12: 19.86 / +1.0%
A13: 50% band (25th–75th) | B13: 18.68 – 21.09 (-5.0% / +7.3%)
A14: Touch ±10% anytime within T+60 | B14: up 31% / down 22%
A16: Key balance-sheet & policy anchors
A17: Net debt Q1-26 (AED mn / × LTM EBITDA) | B17: 29,792 / 0.90×
A18: FY26E DPS (guided) / yield on spot | B18: 0.95 / 4.8%
A19: Royalty regime | B19: 38% + 9% CT to 31-Dec-2026; 2027+ = the crux
A20: Vodafone exit (announced 10-Jul-26) | B20: AED 21.8bn gross / ~4.7bn net
A21: Backtest verdict | B21: PARITY at panel and name level (robust, blocks 2/3/4); UAE production fit ν=4, cal 1.07 (10-name panel)

Sheet Fundamental Valuation
A1: Fundamental valuation — four lenses, weighted central
A2: The DCF and market lenses are never blended into one point; the football field carries the divergence.
B4: bear | C4: base | D4: bull | E4: weight
A5: FCFF DCF + stakes bridge (primary) | B5: 20.260759 | C5: ='SOTP Bridge'!B18 -> 28.384392 | D5: 39.035289 | E5: 0.35
A6: Dividend discount (policy lens) | B6: 12.192116 | C6: =C9 -> 17.028274 | D6: 21.622342 | E6: 0.25
A7: Relative EV/EBITDA | B7: 21.761676 | C7: ='Relative & Normalized'!C8 -> 23.724958 | D7: 25.68824 | E7: 0.2
A8: Normalized earnings | B8: 15.6 | C8: ='Relative & Normalized'!C13 -> 18.9 | D8: 22.72 | E8: 0.2
A9: DDM detail: PV of DPS FY26–30 + terminal at g | B9: =SUMPRODUCT(Assumptions!B75:B79,1/(1+Assumptions!B55)^ROW(INDIRECT("1:5"))) -> 3.9616405 | C9: =B9+Assumptions!B79*(1+Assumptions!B80)/(Assumptions!B55-Assumptions!B80)/(1+Assumptions!B55)^5 -> 17.028274 | D9: ← PV dividends | full DDM
A11: Weighted central (base) | B11: =SUMPRODUCT(C5:C8,E5:E8) -> 22.716597 | C11: =B11/Assumptions!B5-1 -> 0.1554729
A12: Weighted bear / bull | B12: =SUMPRODUCT(B5:B8,E5:E8) -> 17.61163 | C12: =SUMPRODUCT(D5:D8,E5:E8) -> 28.749585
A14: Reading the divergence: the DCF (long-duration, WACC 7.6%, TV 79% of EV) sits far above the dividend lens (payout ~70% at Ke 9.2%); the gap prices the 2027 royalty reset, the conglomerate/NCI structure and the terminal assumption. The weighted central is a synthesis, not a blend of like-for-like.

Sheet Assumptions
A1: Assumptions — the single input layer
A2: All blue cells are inputs. Every other sheet links here.
A4: Market & shares
A5: Spot price (AED, 9-Jul-2026 close) | B5: 19.66
A6: Shares outstanding (mn) | B6: 8696.8
A8: Revenue growth (y/y)
A9: FY26E revenue growth | B9: 0.09 | C9: FY26E: guidance +8–10% cc
A10: FY27E revenue growth | B10: 0.035 | C10: sector CAGR 3–4% (top-down)
A11: FY28E revenue growth | B11: 0.035
A12: FY29E revenue growth | B12: 0.032
A13: FY30E revenue growth | B13: 0.03
A15: Margins & intensity (% of revenue)
A16: FY26E EBITDA margin | B16: 0.43
A17: FY27E EBITDA margin | B17: 0.432
A18: FY28E EBITDA margin | B18: 0.434
A19: FY29E EBITDA margin | B19: 0.436
A20: FY30E EBITDA margin | B20: 0.438
A21: FY26E D&A | B21: 0.146
A22: FY27E D&A | B22: 0.143
A23: FY28E D&A | B23: 0.14
A24: FY29E D&A | B24: 0.137
A25: FY30E D&A | B25: 0.135
A26: FY26E capex (all-in, incl. spectrum allowance) | B26: 0.173
A27: FY27E capex (all-in, incl. spectrum allowance) | B27: 0.169
... A35: FY30E working-capital outflow | B35: 0.0015
A37: Royalty & tax (the §1.7 crux)
A38: UAE federal royalty rate (2024–26 regime; 2027+ = the reset) | B38: 0.38 | C38: expires 31-Dec-2026 — sensitised on the Sensitivity sheet
A39: UAE corporate tax rate (royalty deductible) | B39: 0.09
A40: International blended tax rate | B40: 0.27
A41: UAE share of group EBIT | B41: 0.57 | C41: segment table
A42: Effective royalty+tax on EBIT (t_eff, computed) | B42: =B41*(B38+B39*(1-B38))+(1-B41)*B40 -> 0.364506
A44: Cost of capital (bottom-up, sourced)
A45: Risk-free (AED T-Bond Jan-2031, 23-May-26 auction) | B45: 0.043
A46: ERP — UAE rating-based (Damodaran 5-Jan-26) | B46: 0.0487
A47: ERP — Abu Dhabi CDS-based (alternative) | B47: 0.0493
A48: Beta (regression inaccessible → 1.0; grid 0.8–1.3) | B48: 1
A49: Kd pretax — AED tranche (EIBOR 3.93% + 65bp) | B49: 0.046
A50: Kd pretax — non-AED blend (EUR/PKR/MAD) | B50: 0.051
A51: % debt in AED | B51: 0.48
A52: Interest tax shield (blended) | B52: 0.25
...

Sheet SOTP Bridge
A1: SOTP bridge — core EV to equity per share
A2: Consolidated DCF core + sourced stake marks − debt-like claims − NCI at market where listed.
B4: AED mn | C4: AED / share | D4: note
A5: Core enterprise value (DCF sheet) | B5: =DCF!B20 -> 262487.71 | C5: =B5/Assumptions!$B$6 -> 30.182102
A6: + Vodafone at deal value (announced 10-Jul-26) | B6: =Assumptions!B61 -> 21800 | C6: =B6/Assumptions!$B$6 -> 2.5066691 | D6: dual frame: undisturbed market ≈ 19,063
A7: + Mobily 28.0% at market | B7: =Assumptions!B63 -> 12572.236 | C7: =B7/Assumptions!$B$6 -> 1.4456164 | D7: SAR 59.70 (6-Jul-26)
A8: + Term deposits (amortised cost) | B8: =Assumptions!B64 -> 10765 | C8: =B8/Assumptions!$B$6 -> 1.2378116 | D8: Q1-26 FS
A9: + Other investments (book) | B9: =Assumptions!B65 -> 2541 | C9: =B9/Assumptions!$B$6 -> 0.29217643
A10: − Net debt (Q1-26) | B10: =-Assumptions!B66 -> -29792 | C10: =B10/Assumptions!$B$6 -> -3.4256278 | D10: borrowings 66,574 − cash 36,782
A11: − PPF NCI put liability | B11: =-Assumptions!B67 -> -11658 | C11: =B11/Assumptions!$B$6 -> -1.3404931 | D11: on-BS conditional commitment
A12: − NCI: Maroc Telecom 47% at market | B12: =-Assumptions!B68 -> -15190.368 | C12: =B12/Assumptions!$B$6 -> -1.7466618 | D12: IAM MAD 91.90 (1-Jul)
A13: − NCI: PTCL 76.6% at market | B13: =-Assumptions!B69 -> -3765.3114 | C13: =B13/Assumptions!$B$6 -> -0.43295366 | D13: PKR 377bn cap (Jul-26)
A14: − NCI: e& Egypt 34% | B14: =-Assumptions!B70 -> -1489.2 | C14: =B14/Assumptions!$B$6 -> -0.1712354 | D14: 4.0× EBITDA − debt (flagged)
A15: − NCI: Careem (deal-implied, half-weight) | B15: =-Assumptions!B71 -> -917.6843 | C15: =B15/Assumptions!$B$6 -> -0.10551977 | D15: pending Uber close
A16: − NCI: other minorities (book residual) | B16: =-Assumptions!B72 -> -500 | C16: =B16/Assumptions!$B$6 -> -0.057492411
A17: Equity value | B17: =SUM(B5:B16) -> 246853.38 | C17: =B17/Assumptions!$B$6 -> 28.384392
A18: DCF fair value per share (AED) | B18: =C17 -> 28.384392 | C18: =B18/Assumptions!$B$5-1 -> 0.44376357 | D18: vs spot
A20: Framing note: gross deal proceeds AED 21.8bn vs ~AED 4.7bn net cash after the associated financing unwind — both framings stated; net debt above already carries the financing.

Sheet Segments
A1: Segments — FY2024/FY2025 revenue, EBITDA, capex (AED mn)
A2: e& Q4-2025 earnings release. Mobily & Vodafone are equity-accounted associates (not consolidated).
B4: Rev FY24 | C4: Rev FY25 | D4: EBITDA FY24 | E4: EBITDA FY25 | F4: Margin FY25 | G4: Capex FY25 | H4: OpFCF FY25
A5: e& UAE | B5: 33097 | C5: 34705 | D5: 17419 | E5: 17772 | F5: =IF(C5<>0,E5/C5,"n/m") -> 0.5120876 | G5: 3118 | H5: =E5-G5 -> 14654
A6: e& international (subtotal) | B6: 21764 | C6: 32411 | D6: 9421 | E6: 14435 | F6: =IF(C6<>0,E6/C6,"n/m") -> 0.44537348
A7: Maroc Telecom (53%) | B7: 13495 | C7: 13697 | D7: 7180 | E7: 7250 | F7: =IF(C7<>0,E7/C7,"n/m") -> 0.52931299 | G7: 4324 | H7: =E7-G7 -> 2926
A8: PPF / e& CEE (50%+1) | B8: 2725 | C8: 9961 | D8: 1183 | E8: 4433 | F8: =IF(C8<>0,E8/C8,"n/m") -> 0.44503564 | G8: 2955 | H8: =E8-G8 -> 1478
A9: e& Egypt (66%) | B9: 3603 | C9: 4739 | D9: 1050 | E9: 1570 | F9: =IF(C9<>0,E9/C9,"n/m") -> 0.33129352 | G9: 1594 | H9: =E9-G9 -> -24
A10: PTCL (26%; 23.4% econ.) | B10: 1445 | C10: 3274 | D10: 8 | E10: 938 | F10: =IF(C10<>0,E10/C10,"n/m") -> 0.28649969 | G10: 705 | H10: =E10-G10 -> 233
A11: Afghanistan (100%) | B11: 496 | C11: 740 | D11: 0 | E11: 244 | F11: =IF(C11<>0,E11/C11,"n/m") -> 0.32972973 | G11: 232 | H11: =E11-G11 -> 12
A12: e& enterprise | B12: 2922 | C12: 3556 | D12: 175 | E12: 211 | F12: =IF(C12<>0,E12/C12,"n/m") -> 0.059336333
A13: e& life | B13: 2009 | C13: 2622 | D13: -654 | E13: -715 | F13: =IF(C13<>0,E13/C13,"n/m") -> -0.2726926
A14: Other / eliminations | B14: -590 | C14: -435 | D14: 93 | E14: 319 | F14: =IF(C14<>0,E14/C14,"n/m") -> -0.73333333 | G14: 739 | H14: =E14-G14 -> -420
A15: Group | B15: 59203 | C15: 72858 | D15: 26454 | E15: 32022 | F15: =E15/C15 -> 0.43951248 | G15: 13668 | H15: =E15-G15 -> 18354
A17: ARPU memo: UAE blended mobile ARPU AED 76 (Q4-25) vs 80 (Q4-24); FBB ARPL 466. Subscribers 244.7mn group (FY25), UAE 16.6mn (Q1-26). OpFCF = EBITDA − capex: the UAE alone is ~80% of the group total — the cash-conversion story in one column.

Sheet Relative & Normalized
A1: Relative (EV/EBITDA through the bridge) & normalized earnings
A4: FY26E EBITDA (DCF sheet) | B4: =DCF!C6 -> 34148.545
A5: EV/EBITDA multiple — bear / base / bull | B5: 6 | C5: 6.5 | D5: 7
A6: Implied core EV at multiple | B6: =B4*B5 -> 204891.27 | C6: =B4*C5 -> 221965.54 | D6: =B4*D5 -> 239039.81
A7: Bridge (stakes − debt-like − NCI, from SOTP) | B7: ='SOTP Bridge'!B17-DCF!B20 -> -15634.328
A8: Equity at multiple / per share | B8: =(B6+$B$7)/Assumptions!$B$6 -> 21.761676 | C8: =(C6+$B$7)/Assumptions!$B$6 -> 23.724958 | D8: =(D6+$B$7)/Assumptions!$B$6 -> 25.68824
A9: (row 9 = base per-share for the lens table)
A10: Normalized earnings lens
A11: Clean EPS — bear / base (FY26E guided) / bull | B11: 1.3 | C11: 1.35 | D11: 1.42
A12: Justified P/E — bear / base / bull | B12: 12 | C12: 14 | D12: 16
A13: Normalized value per share | B13: =B11*B12 -> 15.6 | C13: =C11*C12 -> 18.9 | D13: =D11*D12 -> 22.72
A15: EV/OpFCF cross-check (OpFCF = EBITDA − capex)
A16: FY26E OpFCF (DCF sheet: EBITDA − capex) | B16: =DCF!C6-(-DCF!C11) -> 20409.712
A17: EV/OpFCF multiple — bear / base / bull | B17: 10 | C17: 11 | D17: 12
A18: Implied equity / share (same bridge) | B18: =(B17*$B$16+$B$7)/Assumptions!$B$6 -> 21.67036 | C18: =(C17*$B$16+$B$7)/Assumptions!$B$6 -> 24.017167 | D18: =(D17*$B$16+$B$7)/Assumptions!$B$6 -> 26.363974
A19: Multiple implied by spot | B19: =(Assumptions!$B$5*Assumptions!$B$6-$B$7)/$B$16 -> 9.1433637
A21: Peer anchors: stc ~7.5×, du ~6.3×, Zain/Ooredoo 5–6×, Maroc Telecom ~5.5× EV/EBITDA; GCC telecom P/E 12–16×. e& carries a conglomerate structure (NCI-heavy international) — the base 6.5× sits between the UAE duopoly and the emerging-market holdings.

Sheet DCF
A1: FCFF DCF — full waterfall, 5-year explicit + terminal
A2: Every driver pulls from Assumptions. Standard row order per house rule; TV disclosed as % of EV.
B4: FY25A | C4: FY26E | D4: FY27E | E4: FY28E | F4: FY29E | G4: FY30E
A5: Revenue | B5: 72858 | C5: =B5*(1+Assumptions!$B$9) -> 79415.22 | D5: =C5*(1+Assumptions!$B$10) -> 82194.753 | E5: =D5*(1+Assumptions!$B$11) -> 85071.569 | F5: =E5*(1+Assumptions!$B$12) -> 87793.859 | G5: =F5*(1+Assumptions!$B$13) -> 90427.675
A6: EBITDA | B6: 32022 | C6: =C5*Assumptions!$B$16 -> 34148.545 | D6: =D5*Assumptions!$B$17 -> 35508.133 | E6: =E5*Assumptions!$B$18 -> 36921.061 | F6: =F5*Assumptions!$B$19 -> 38278.123 | G6: =G5*Assumptions!$B$20 -> 39607.322
A7: D&A | B7: -10672 | C7: =-C5*Assumptions!$B$21 -> -11594.622 | D7: =-D5*Assumptions!$B$22 -> -11753.85 | E7: =-E5*Assumptions!$B$23 -> -11910.02 | F7: =-F5*Assumptions!$B$24 -> -12027.759 | G7: =-G5*Assumptions!$B$25 -> -12207.736
A8: EBIT | B8: =B6+B7 -> 21350 | C8: =C6+C7 -> 22553.922 | D8: =D6+D7 -> 23754.284 | E8: =E6+E7 -> 25011.041 | F8: =F6+F7 -> 26250.364 | G8: =G6+G7 -> 27399.586
A9: NOPAT (EBIT × (1−t_eff)) | C9: =C8*(1-Assumptions!$B$42) -> 14332.882 | D9: =D8*(1-Assumptions!$B$42) -> 15095.705 | E9: =E8*(1-Assumptions!$B$42) -> 15894.367 | F9: =F8*(1-Assumptions!$B$42) -> 16681.949 | G9: =G8*(1-Assumptions!$B$42) -> 17412.272
A10: + D&A | C10: =-C7 -> 11594.622 | D10: =-D7 -> 11753.85 | E10: =-E7 -> 11910.02 | F10: =-F7 -> 12027.759 | G10: =-G7 -> 12207.736
A11: − Capex | C11: =-C5*Assumptions!$B$26 -> -13738.833 | D11: =-D5*Assumptions!$B$27 -> -13890.913 | E11: =-E5*Assumptions!$B$28 -> -14036.809 | F11: =-F5*Assumptions!$B$29 -> -14222.605 | G11: =-G5*Assumptions!$B$30 -> -14468.428
A12: − Δ working capital | C12: =-C5*Assumptions!$B$31 -> -119.12283 | D12: =-D5*Assumptions!$B$32 -> -123.29213 | E12: =-E5*Assumptions!$B$33 -> -127.60735 | F12: =-F5*Assumptions!$B$34 -> -131.69079 | G12: =-G5*Assumptions!$B$35 -> -135.64151
A13: Free cash flow to firm | C13: =C9+C10+C11+C12 -> 12069.549 | D13: =D9+D10+D11+D12 -> 12835.349 | E13: =E9+E10+E11+E12 -> 13639.97 | F13: =F9+F10+F11+F12 -> 14355.411 | G13: =G9+G10+G11+G12 -> 15015.939
A14: Discount factor | C14: =1/(1+Assumptions!$B$57)^1 -> 0.92918129 | D14: =1/(1+Assumptions!$B$57)^2 -> 0.86337787 | E14: =1/(1+Assumptions!$B$57)^3 -> 0.80223456 | F14: =1/(1+Assumptions!$B$57)^4 -> 0.74542135 | G14: =1/(1+Assumptions!$B$57)^5 -> 0.69263157
A15: PV of FCFF | C15: =C13*C14 -> 11214.799 | D15: =D13*D14 -> 11081.756 | E15: =E13*E14 -> 10942.455 | F15: =F13*F14 -> 10700.83 | G15: =G13*G14 -> 10400.513
A17: Sum of PV of FCFF (FY26E–FY30E) | B17: =SUM(C15:G15) -> 54340.354
A18: Terminal value = FCFF FY30E × (1+g) / (WACC − g) | B18: =G13*(1+Assumptions!$B$54)/(Assumptions!$B$57-Assumptions!$B$54) -> 300516.7
A19: PV of terminal value | B19: =B18*G14 -> 208147.35
A20: Core enterprise value (consolidated) | B20: =B17+B19 -> 262487.71
A21: Terminal value as % of core EV (disclosed) | B21: =B19/B20 -> 0.79297943
A23: Ke shown explicitly: rf + β × ERP | B23: =Assumptions!$B$55 -> 0.0917
A24: WACC (rating ERP) / WACC (CDS ERP) | B24: =Assumptions!$B$57 -> 0.076216246 | C24: =Assumptions!$B$58 -> 0.076648097

Sheet Income Statement
A1: Income statement — FY2023–FY2025 actual, FY2026E–FY2030E forecast (AED mn)
A2: Historical: e& official releases / audited FS. FY23 rows marked n/d precede the 2024 royalty-presentation restatement.
B4: FY23 | C4: FY24 | D4: FY25 | E4: FY26E | F4: FY27E | G4: FY28E | H4: FY29E | I4: FY30E
A5: Revenue | B5: 53752 | C5: 59203 | D5: 72858 | E5: =D5*(1+Assumptions!$B$9) -> 79415.22 | F5: =E5*(1+Assumptions!$B$10) -> 82194.753 | G5: =F5*(1+Assumptions!$B$11) -> 85071.569 | H5: =G5*(1+Assumptions!$B$12) -> 87793.859 | I5: =H5*(1+Assumptions!$B$13) -> 90427.675
A6: Direct cost of sales | B6: -14714 | C6: -17784 | D6: -22759
A7: Staff costs | B7: -4354 | C7: -5245 | D7: -6044
A8: Network & IT | B8: -2851 | C8: -3162 | D8: -3863
A9: Marketing | B9: -979 | C9: -1204 | D9: -1461
A10: Other operating expenses | B10: -3905 | C10: -4770 | D10: -5610
A11: Total opex (forecast = revenue − EBITDA) | B11: =-SUM(B6:B10) -> 26803 | C11: =-SUM(C6:C10) -> 32165 | D11: =-SUM(D6:D10) -> 39737 | E11: =-(E5-E12) -> -45266.675 | F11: =-(F5-F12) -> -46686.62 | G11: =-(G5-G12) -> -48150.508 | H11: =-(H5-H12) -> -49515.737 | I11: =-(I5-I12) -> -50820.353
A12: EBITDA | B12: 26117 | C12: 26454 | D12: 32022 | E12: =E5*Assumptions!$B$16 -> 34148.545 | F12: =F5*Assumptions!$B$17 -> 35508.133 | G12: =G5*Assumptions!$B$18 -> 36921.061 | H12: =H5*Assumptions!$B$19 -> 38278.123 | I12: =I5*Assumptions!$B$20 -> 39607.322
A13: EBITDA margin | B13: =B12/B5 -> 0.4858796 | C13: =C12/C5 -> 0.44683546 | D13: =D12/D5 -> 0.43951248 | E13: =E12/E5 -> 0.43 | F13: =F12/F5 -> 0.432 | G13: =G12/G5 -> 0.434 | H13: =H12/H5 -> 0.436 | I13: =I12/I5 -> 0.438
A14: Depreciation & amortisation | B14: -7569 | C14: -7313 | D14: -10672 | E14: =-E5*Assumptions!$B$21 -> -11594.622 | F14: =-F5*Assumptions!$B$22 -> -11753.85 | G14: =-G5*Assumptions!$B$23 -> -11910.02 | H14: =-H5*Assumptions!$B$24 -> -12027.759 | I14: =-I5*Assumptions!$B$25 -> -12207.736
A15: Share of associates & JVs | B15: n/d | C15: 2475.4 | D15: 1948.5 | E15: =Assumptions!$B$83 -> 1200 | F15: =Assumptions!$B$83 -> 1200 | G15: =Assumptions!$B$83 -> 1200 | H15: =Assumptions!$B$83 -> 1200 | I15: =Assumptions!$B$83 -> 1200
A16: Impairment & other one-offs | B16: n/d | C16: -1294.6 | D16: -26.8 | E16: 0 | F16: 0 | G16: 0 | H16: 0 | I16: 0
A17: FX gains/(losses) | B17: n/d | C17: -260 | D17: -28 | E17: 0 | F17: 0 | G17: 0 | H17: 0 | I17: 0
A18: Operating profit before royalty | B18: n/d | C18: 20061.4 | D18: 23240.7 | E18: =E12+E14+E15+E16+E17 -> 23753.922 | F18: =F12+F14+F15+F16+F17 -> 24954.284 | G18: =G12+G14+G15+G16+G17 -> 26211.041 | H18: =H12+H14+H15+H16+H17 -> 27450.364 | I18: =I12+I14+I15+I16+I17 -> 28599.586
A19: Net finance income/(cost) + tax, combined (actual residual) | B19: n/d | C19: -4196.1 | D19: 338.8
A20: Net finance income/(cost) — forecast | E20: =Assumptions!$B$84*0.85^0 -> -850 | F20: =Assumptions!$B$84*0.85^1 -> -722.5 | G20: =Assumptions!$B$84*0.85^2 -> -614.125 | H20: =Assumptions!$B$84*0.85^3 -> -522.00625 | I20: =Assumptions!$B$84*0.85^4 -> -443.70531
A21: Federal royalty + income tax — forecast | E21: =-(E18+E20)*Assumptions!$B$85 -> -9047.0494 | F21: =-(F18+F20)*Assumptions!$B$85 -> -9571.5545 | G21: =-(G18+G20)*Assumptions!$B$85 -> -10110.782 | H21: =-(H18+H20)*Assumptions!$B$85 -> -10636.701 | I21: =-(I18+I20)*Assumptions!$B$85 -> -11121.573
A22: Federal royalty (memo, actual) | B22: n/d | C22: -5282 | D22: -7423
A23: Profit for the period | B23: n/d | C23: 10583.3 | D23: 16156.5 | E23: =E18+E20+E21 -> 13856.873 | F23: =F18+F20+F21 -> 14660.229 | G23: =G18+G20+G21 -> 15486.134 | H23: =H18+H20+H21 -> 16291.656 | I23: =I18+I20+I21 -> 17034.308
A24: attributable to NCI | B24: n/d | C24: -169.1 | D24: 1796.3 | E24: =E23*Assumptions!$B$86 -> 1593.5404 | F24: =F23*Assumptions!$B$86 -> 1685.9263 | G24: =G23*Assumptions!$B$86 -> 1780.9055 | H24: =H23*Assumptions!$B$86 -> 1873.5405 | I24: =I23*Assumptions!$B$86 -> 1958.9454
A25: Net profit attributable to owners | B25: 10305 | C25: 10752.5 | D25: 14360.2 | E25: =E23-E24 -> 12263.333 | F25: =F23-F24 -> 12974.303 | G25: =G23-G24 -> 13705.229 | H25: =H23-H24 -> 14418.116 | I25: =I23-I24 -> 15075.362
A26: EPS (AED) | B26: 1.18 | C26: 1.24 | D26: 1.65 | E26: =E25/Assumptions!$B$6*1000/1000 -> 1.4100971 | F26: =F25/Assumptions!$B$6*1000/1000 -> 1.4918479 | G26: =G25/Assumptions!$B$6*1000/1000 -> 1.5758933 | H26: =H25/Assumptions!$B$6*1000/1000 -> 1.6578645 | I26: =I25/Assumptions!$B$6*1000/1000 -> 1.7334378
A27: EPS ex-one-offs (FY25: Khazna gain, MT settlement, VOD bargain) | D27: 1.31
A29: FY23 n/d rows precede the 2024 restatement that moved the federal royalty below operating profit; FY23 royalty and the finance/tax split were not re-presented. FY25 royalty 7,423 is the exact sum of the four quarterly charges (3,277 / 1,189 / 1,426 / 1,531).

Sheet Balance Sheet
A1: Balance sheet — FY2023–FY2025 + Q1-2026 (AED mn)
A2: e& audited FS (Dec) and Q1-2026 interim FS (EY-reviewed).
B4: Dec-23 | C4: Dec-24 | D4: Dec-25 | E4: Mar-26
A5: Cash & bank balances | B5: 28989 | C5: 33628 | D5: 34308 | E5: 36782
A6: Term deposits (amortised cost) | B6: n/d | C6: n/d | D6: 10425 | E6: 10765
A7: Goodwill | B7: n/d | C7: 24955 | D7: 30068 | E7: 30068
A8: Associates & JVs (incl. Vodafone, Mobily) | B8: n/d | C8: n/d | D8: 21128 | E8: 20885
A9: Total assets | B9: 147613 | C9: 183327 | D9: 205059 | E9: 207682
A10: Total borrowings | B10: 49041 | C10: 69195 | D10: 67639 | E10: 66574
A11: of which: AED 48% / EUR 33% / PKR 7% / MAD 3% / other 9%
A12: Net debt (borrowings − cash) | B12: 20051 | C12: 35567 | D12: 33331 | E12: 29792
A13: PPF NCI put liability (conditional commitment) | B13: n/d | C13: 8098 | D13: 11658 | E13: 11658
A14: Federal royalty payable | B14: n/d | C14: n/d | D14: 9053 | E14: 9287
A15: Equity attributable to owners | B15: n/d | C15: 45601 | D15: 51708 | E15: 50488
A16: Non-controlling interests | B16: n/d | C16: 8320 | D16: 10055 | E16: 9369
A17: Total equity | B17: 51710 | C17: 53920 | D17: 61763 | E17: 59857
A18: Net debt / EBITDA (trailing) | C18: 1.3444848 | D18: 1.0408781 | E18: =E12/32747 -> 0.90976273
A20: Dec-24 saw borrowings step up ~AED 20bn on PPF consolidation; the Q1-26 net-debt print (0.90× LTM EBITDA) is the study’s balance-sheet anchor. The PPF put is carried as a liability with the corresponding NCI derecognised — the SOTP deducts the put, not a second PPF NCI line.

Sheet Cash Flow
A1: Cash flow — FY2023–FY2025 (AED mn)
A2: e& audited consolidated statements.
B4: FY23 | C4: FY24 | D4: FY25
A5: Net cash from operating activities | B5: 15206 | C5: 21733 | D5: 26051
A6: federal royalty paid (within operating) | B6: n/d | C6: -6328 | D6: -5274
A7: Net cash used in investing activities | B7: -8738 | C7: -15766 | D7: -8386
A8: capex (PP&E + intangibles, incl. licences) | B8: n/d | C8: -9507 | D8: -13668
A9: capex ex-licences (co-disclosed) | B9: n/d | C9: -8206 | D9: -11200
A10: Khazna 40% proceeds (FY25) | D10: 8009
A11: Net cash from/(used in) financing activities | B11: -10599 | C11: 392 | D11: -17185
A12: dividends paid to owners | B12: n/d | C12: n/d | D12: -8092
A13: Net change in cash | B13: =B5+B7+B11 -> -4131 | C13: =C5+C7+C11 -> 6359 | D13: =D5+D7+D11 -> 480
A15: Simple FCF (operating − capex incl. licences) | C15: =C5+C8 -> 12226 | D15: =D5+D8 -> 12383
A17: FY24 financing was net positive on the PPF acquisition draw-downs; FY25 financing turned −17.2bn as dividends, royalty catch-up and deleveraging resumed. Royalty paid lags royalty expensed (payable 9.3bn at Mar-26) — the accountant expert normalises for this accrual.

Sheet Summary Financials
A1: Summary financials — all links (green)
A2: Nothing typed here; every cell links to the statements.
B4: FY23 | C4: FY24 | D4: FY25 | E4: FY26E | F4: FY27E | G4: FY28E | H4: FY29E | I4: FY30E
A5: Revenue | B5: ='Income Statement'!B5 -> 53752 | C5: ='Income Statement'!C5 -> 59203 | D5: ='Income Statement'!D5 -> 72858 | E5: ='Income Statement'!E5 -> 79415.22 | F5: ='Income Statement'!F5 -> 82194.753 | G5: ='Income Statement'!G5 -> 85071.569 | H5: ='Income Statement'!H5 -> 87793.859 | I5: ='Income Statement'!I5 -> 90427.675
A6: EBITDA | B6: ='Income Statement'!B12 -> 26117 | C6: ='Income Statement'!C12 -> 26454 | D6: ='Income Statement'!D12 -> 32022 | E6: ='Income Statement'!E12 -> 34148.545 | F6: ='Income Statement'!F12 -> 35508.133 | G6: ='Income Statement'!G12 -> 36921.061 | H6: ='Income Statement'!H12 -> 38278.123 | I6: ='Income Statement'!I12 -> 39607.322
A7: EBITDA margin | B7: =B6/B5 -> 0.4858796 | C7: =C6/C5 -> 0.44683546 | D7: =D6/D5 -> 0.43951248 | E7: =E6/E5 -> 0.43 | F7: =F6/F5 -> 0.432 | G7: =G6/G5 -> 0.434 | H7: =H6/H5 -> 0.436 | I7: =I6/I5 -> 0.438
A8: Operating profit before royalty | B8: ='Income Statement'!B18 -> n/d | C8: ='Income Statement'!C18 -> 20061.4 | D8: ='Income Statement'!D18 -> 23240.7 | E8: ='Income Statement'!E18 -> 23753.922 | F8: ='Income Statement'!F18 -> 24954.284 | G8: ='Income Statement'!G18 -> 26211.041 | H8: ='Income Statement'!H18 -> 27450.364 | I8: ='Income Statement'!I18 -> 28599.586
A9: Net profit attributable | B9: ='Income Statement'!B25 -> 10305 | C9: ='Income Statement'!C25 -> 10752.5 | D9: ='Income Statement'!D25 -> 14360.2 | E9: ='Income Statement'!E25 -> 12263.333 | F9: ='Income Statement'!F25 -> 12974.303 | G9: ='Income Statement'!G25 -> 13705.229 | H9: ='Income Statement'!H25 -> 14418.116 | I9: ='Income Statement'!I25 -> 15075.362
A10: EPS (AED) | B10: ='Income Statement'!B26 -> 1.18 | C10: ='Income Statement'!C26 -> 1.24 | D10: ='Income Statement'!D26 -> 1.65 | E10: ='Income Statement'!E26 -> 1.4100971 | F10: ='Income Statement'!F26 -> 1.4918479 | G10: ='Income Statement'!G26 -> 1.5758933 | H10: ='Income Statement'!H26 -> 1.6578645 | I10: ='Income Statement'!I26 -> 1.7334378
A11: Net debt (Dec-23/24/25 + Mar-26 in FY26E col) | B11: ='Balance Sheet'!B12 -> 20051 | C11: ='Balance Sheet'!C12 -> 35567 | D11: ='Balance Sheet'!D12 -> 33331 | E11: ='Balance Sheet'!E12 -> 29792
A12: Operating cash flow (FY23–25) | B12: ='Cash Flow'!B5 -> 15206 | C12: ='Cash Flow'!C5 -> 21733 | D12: ='Cash Flow'!D5 -> 26051
A13: DPS (AED) | B13: 0.8 | C13: 0.83 | D13: 0.9 | E13: =Assumptions!B75 -> 0.95 | F13: =Assumptions!B76 -> 0.99 | G13: =Assumptions!B77 -> 1.03 | H13: =Assumptions!B78 -> 1.07 | I13: =Assumptions!B79 -> 1.11

Sheet Monte Carlo
A1: Monte Carlo — carry-anchored YZ-HAR, Student-t(4), width_cal 1.07 (production UAE panel fit)
A2: Simulation outputs (50,000 paths, seed 42). Carry-anchored engine; the simulation carries no fundamental drift.
A4: Engine & carry
A5: Anchor volatility (annualised, calibrated) | B5: 0.23340372
A6: Shape ν (UAE production panel fit, 10 names) | B6: 4
A7: Width calibration (UAE fit) | B7: 1.07
A8: rf — CBUAE Base Rate (17-Jun-2026, production carry) | B8: 0.0365
A9: Forward dividend yield (0.95 / 19.66) | B9: 0.048321465
A10: Carry drift per quarter (rf − q) | B10: -0.0027001494
A11: Continuous-factor tilt per quarter | B11: 0.002
A12: Discrete event ledger, expected per quarter | B12: 0.01
A14: Percentile map (AED) | B14: T+20 | C14: T+60
A15: 5th percentile | B15: 17.838172 | C15: 16.703715
A16: 25th percentile | B16: 19.04796 | C16: 18.68316
A17: 50th percentile | B17: 19.724077 | C17: 19.856625
A18: 75th percentile | B18: 20.433037 | C18: 21.086682
A19: 95th percentile | B19: 21.812842 | C19: 23.589442
A21: Probability read (T+60)
A22: P(above spot) | B22: 54.5%
A23: P(≥ +10%) / P(≤ −10%) → odds | B23: 17.8% / 11.6% → 1.53
A24: Median / move | B24: 19.86 / +1.0%
A25: 50% band | B25: 18.68 – 21.09
A26: Touch ±10% anytime | B26: up 31% / down 22%
A28: Touch-probability ladder (anytime within horizon) | B28: T+20 | C28: T+60
A29: AED 23 (above spot) | B29: 0.0241 | C29: 0.12656
A30: AED 22 (above spot) | B30: 0.06484 | C30: 0.24036
A31: AED 21 (above spot) | B31: 0.20804 | C31: 0.45892
A32: AED 20 (above spot) | B32: 0.6649 | C32: 0.81408
A33: AED 19 (below spot) | B33: 0.41734 | C33: 0.61516
A34: AED 18 (below spot) | B34: 0.1033 | C34: 0.28182
A35: AED 17 (below spot) | B35: 0.02816 | C35: 0.1199
A36: AED 16 (below spot) | B36: 0.00834 | C36: 0.05076
A38: Probability zones at T+60 (AED)
A39: < 17.00 | B39: 0.06328
A40: 17.00–18.50 | B40: 0.1556
A41: 18.50–20.50 | B41: 0.42382
A42: 20.50–22.00 | B42: 0.21762
A43: > 22.00 | B43: 0.13968
A45: Independence note: the fundamental value gap (§1) never enters the MC drift; the price centre is the money-market carry (rf − dividend yield ≈ −0.2%/quarter) plus a disclosed, probability-weighted event ledger. Expected total return ≈ the 3.93% money-market rate, delivered mostly as the 4.8% dividend.

Sheet Sensitivity
A1: Sensitivity — WACC × g · margin × capex · the royalty crux · beta grid
A2: Computed grids (values); the live formulas sit in DCF/Assumptions — change inputs there to reprice.
A4: DCF/share: WACC (rows) × terminal g (cols)
B5: 0.015 | C5: 0.02 | D5: 0.025 | E5: 0.03 | F5: 0.035
A6: 0.066216246 | B6: 29.459158 | C6: 32.281303 | D6: 35.788166 | E6: 40.26334 | F6: 46.172118
A7: 0.071216246 | B7: 26.63853 | C7: 28.915644 | D7: 31.685467 | E7: 35.127312 | F7: 39.519516
A8: 0.076216246 | B8: 24.279323 | C8: 26.149301 | D8: 28.384392 | E8: 31.103099 | F8: 34.481426
A9: 0.081216246 | B9: 22.276998 | C9: 23.835407 | D9: 25.671033 | E9: 27.865066 | F9: 30.533831
A10: 0.086216246 | B10: 20.556372 | C10: 21.871458 | D10: 23.40137 | E10: 25.203431 | F10: 27.357344
A12: DCF/share: EBITDA margin shift (rows) × capex shift (cols)
B13: -1.0pp | C13: -0.5pp | D13: +0.0pp | E13: +0.5pp | F13: +1.0pp
A14: -1.0pp | B14: 29.052717 | C14: 28.135962 | D14: 27.219207 | E14: 26.302452 | F14: 25.385697
A15: -0.5pp | B15: 29.635309 | C15: 28.718555 | D15: 27.8018 | E15: 26.885045 | F15: 25.96829
A16: +0.0pp | B16: 30.217902 | C16: 29.301147 | D16: 28.384392 | E16: 27.467637 | F16: 26.550882
A17: +0.5pp | B17: 30.800494 | C17: 29.883739 | D17: 28.966984 | E17: 28.050229 | F17: 27.133474
A18: +1.0pp | B18: 31.383086 | C18: 30.466331 | D18: 29.549576 | E18: 28.632821 | F18: 27.716066
A20: THE CRUX — 2027+ royalty rate → t_eff → DCF/share
A21: royalty rate | B21: t_eff | C21: DCF AED/sh | D21: Δ vs base
A22: 0.3 | B22: 0.32301 | C22: 30.674107 | D22: 2.2897149
A23: 0.34 | B23: 0.343758 | C23: 29.529249 | D23: 1.1448575
A24: 0.38 | B24: 0.364506 | C24: 28.384392 | D24: 0
A25: 0.42 | B25: 0.385254 | C25: 27.239534 | D25: -1.1448575
A26: 0.46 | B26: 0.406002 | C26: 26.094677 | D26: -2.2897149
A28: Beta grid (regression inaccessible → assumed 1.0, sensitised)
A29: beta | B29: Ke | C29: WACC | D29: DCF AED/sh
A30: 0.8 | B30: 0.08196 | C30: 0.069205871 | D30: 33.223419
A31: 0.9 | B31: 0.08683 | C31: 0.072711059 | D31: 30.626002
A32: 1 | B32: 0.0917 | C32: 0.076216246 | D32: 28.384392
A33: 1.1 | B33: 0.09657 | C33: 0.079721434 | D33: 26.430211
A34: 1.2 | B34: 0.10144 | C34: 0.083226622 | D34: 24.711546
A35: 1.3 | B35: 0.10631 | C35: 0.086731809 | D35: 23.188275
A37: Each 4pp on the 2027 royalty ≈ AED 1.1/share of DCF value — the single largest policy swing in the model, and undecided as of the study date.

Sheet Per-Share & Ratios
A1: Per-share & ratios dashboard
A2: Formulas link to the statements and Assumptions.
B4: FY23 | C4: FY24 | D4: FY25 | E4: FY26E | F4: FY27E | G4: FY28E | H4: FY29E | I4: FY30E
A5: EPS (AED) | B5: ='Income Statement'!B26 -> 1.18 | C5: ='Income Statement'!C26 -> 1.24 | D5: ='Income Statement'!D26 -> 1.65 | E5: ='Income Statement'!E26 -> 1.4100971 | F5: ='Income Statement'!F26 -> 1.4918479 | G5: ='Income Statement'!G26 -> 1.5758933 | H5: ='Income Statement'!H26 -> 1.6578645 | I5: ='Income Statement'!I26 -> 1.7334378
A6: DPS (AED) | B6: 0.8 | C6: 0.83 | D6: 0.9 | E6: =Assumptions!B75 -> 0.95 | F6: =Assumptions!B76 -> 0.99 | G6: =Assumptions!B77 -> 1.03 | H6: =Assumptions!B78 -> 1.07 | I6: =Assumptions!B79 -> 1.11
A7: Payout ratio | B7: =B6/B5 -> 0.6779661 | C7: =C6/C5 -> 0.66935484 | D7: =D6/D5 -> 0.54545455 | E7: =E6/E5 -> 0.67371246 | F7: =F6/F5 -> 0.66360653 | G7: =G6/G5 -> 0.65359755 | H7: =H6/H5 -> 0.6454086 | I7: =I6/I5 -> 0.64034601
A8: Dividend yield on spot | B8: =B6/Assumptions!$B$5 -> 0.04069176 | C8: =C6/Assumptions!$B$5 -> 0.042217701 | D8: =D6/Assumptions!$B$5 -> 0.04577823 | E8: =E6/Assumptions!$B$5 -> 0.048321465 | F8: =F6/Assumptions!$B$5 -> 0.050356053 | G8: =G6/Assumptions!$B$5 -> 0.052390641 | H8: =H6/Assumptions!$B$5 -> 0.054425229 | I8: =I6/Assumptions!$B$5 -> 0.056459817
A9: P/E on spot | B9: =Assumptions!$B$5/B5 -> 16.661017 | C9: =Assumptions!$B$5/C5 -> 15.854839 | D9: =Assumptions!$B$5/D5 -> 11.915152 | E9: =Assumptions!$B$5/E5 -> 13.942302 | F9: =Assumptions!$B$5/F5 -> 13.178287 | G9: =Assumptions!$B$5/G5 -> 12.475464 | H9: =Assumptions!$B$5/H5 -> 11.858629 | I9: =Assumptions!$B$5/I5 -> 11.341624
A10: Revenue growth y/y | C10: ='Income Statement'!C5/'Income Statement'!B5-1 -> 0.10141018 | D10: ='Income Statement'!D5/'Income Statement'!C5-1 -> 0.2306471 | E10: ='Income Statement'!E5/'Income Statement'!D5-1 -> 0.09 | F10: ='Income Statement'!F5/'Income Statement'!E5-1 -> 0.035 | G10: ='Income Statement'!G5/'Income Statement'!F5-1 -> 0.035 | H10: ='Income Statement'!H5/'Income Statement'!G5-1 -> 0.032 | I10: ='Income Statement'!I5/'Income Statement'!H5-1 -> 0.03
A11: EBITDA margin | B11: ='Income Statement'!B12/'Income Statement'!B5 -> 0.4858796 | C11: ='Income Statement'!C12/'Income Statement'!C5 -> 0.44683546 | D11: ='Income Statement'!D12/'Income Statement'!D5 -> 0.43951248 | E11: ='Income Statement'!E12/'Income Statement'!E5 -> 0.43 | F11: ='Income Statement'!F12/'Income Statement'!F5 -> 0.432 | G11: ='Income Statement'!G12/'Income Statement'!G5 -> 0.434 | H11: ='Income Statement'!H12/'Income Statement'!H5 -> 0.436 | I11: ='Income Statement'!I12/'Income Statement'!I5 -> 0.438
A12: Net margin (attributable) | B12: ='Income Statement'!B25/'Income Statement'!B5 -> 0.1917138 | C12: ='Income Statement'!C25/'Income Statement'!C5 -> 0.18162086 | D12: ='Income Statement'!D25/'Income Statement'!D5 -> 0.19709847 | E12: ='Income Statement'!E25/'Income Statement'!E5 -> 0.15442043 | F12: ='Income Statement'!F25/'Income Statement'!F5 -> 0.15784831 | G12: ='Income Statement'!G25/'Income Statement'!G5 -> 0.16110234 | H12: ='Income Statement'!H25/'Income Statement'!H5 -> 0.16422693 | I12: ='Income Statement'!I25/'Income Statement'!I5 -> 0.16671182
A13: ROE (attributable, on FY25 equity) | D13: ='Income Statement'!D25/'Balance Sheet'!D15 -> 0.27771718
A14: Net debt / EBITDA | C14: ='Balance Sheet'!C12/'Income Statement'!C12 -> 1.3444848 | D14: ='Balance Sheet'!D12/'Income Statement'!D12 -> 1.0408781
A15: OpFCF (EBITDA − capex, AED mn) | C15: ='Income Statement'!C12+'Cash Flow'!C8 -> 16947 | D15: ='Income Statement'!D12+'Cash Flow'!D8 -> 18354 | E15: ='Income Statement'!E12-'Income Statement'!E5*Assumptions!$B$26 -> 20409.712 | F15: ='Income Statement'!F12-'Income Statement'!F5*Assumptions!$B$27 -> 21617.22 | G15: ='Income Statement'!G12-'Income Statement'!G5*Assumptions!$B$28 -> 22884.252 | H15: ='Income Statement'!H12-'Income Statement'!H5*Assumptions!$B$29 -> 24055.517 | I15: ='Income Statement'!I12-'Income Statement'!I5*Assumptions!$B$30 -> 25138.894
A16: OpFCF margin | C16: =C15/'Income Statement'!C5 -> 0.28625239 | D16: =D15/'Income Statement'!D5 -> 0.25191468 | E16: =E15/'Income Statement'!E5 -> 0.257 | F16: =F15/'Income Statement'!F5 -> 0.263 | G16: =G15/'Income Statement'!G5 -> 0.269 | H16: =H15/'Income Statement'!H5 -> 0.274 | I16: =I15/'Income Statement'!I5 -> 0.278
A17: ROIC (NOPAT / equity+net debt+put), FY25 | D17: =('Income Statement'!D12+'Income Statement'!D14)*(1-Assumptions!$B$42)/('Balance Sheet'!D17+'Balance Sheet'!D12+'Balance Sheet'!D13) -> 0.12709642 | E17: =Assumptions!$B$57 -> 0.076216246 | F17: ← vs WACC
A18: Interest cover / leverage incl. put (Q1-26 memo) | D18: 9.9x cover · 0.91x / 1.27x
A20: Spot metrics memo: trailing P/E 11.9× (reported) / 15.0× (ex-one-offs); FY26E P/E 14.6×; yield 4.8%; EV/EBITDA (cons., incl. NCI at market) ≈ 7.2× FY25 / 7.0× FY26E.

Sheet Peer & Sector
A1: Peer & sector snapshot (as of early-Jul-2026 quotes)
A2: Sourced dated quotes; aggregator-marked cells flagged. Used only to anchor the relative lens.
B4: Mkt cap (AED bn) | C4: EV/EBITDA (fwd) | D4: P/E (fwd) | E4: Div yield | F4: note
A5: e& (EAND) — this study | B5: 171 | C5: 7 | D5: 14.6 | E5: 0.048 | F5: at spot 19.66
A6: stc (Tadawul 7010) | B6: 218 | C6: 7.5 | D6: 15.5 | E6: 0.04 | F6: GCC incumbent benchmark
A7: du / EITC (DFM) | B7: 46.6 | C7: 6.3 | D7: 14 | E7: 0.052 | F7: UAE duopoly peer; cap $12.7bn Mar-26
A8: Zain Group (Boursa KW) | B8: 20.5 | C8: 5.5 | D8: 12 | E8: 0.065 | F8: aggregator est., flagged
A9: Ooredoo (QSE) | B9: 42 | C9: 5.8 | D9: 11.5 | E9: 0.055 | F9: aggregator est., flagged
A10: Maroc Telecom (IAM) | B10: 32.3 | C10: 5.5 | D10: 11.6 | E10: 0.044 | F10: MAD 91.90 (BMCE 1-Jul); e& 53%
A11: Mobily (Tadawul 7020) | B11: 44.8 | C11: 7.8 | D11: 16 | E11: 0.03 | F11: SAR 59.70 (6-Jul); e& 28%
A13: Sector frame: UAE telecom is a regulated duopoly (97.5% of sector revenue), quality-led competition; sector revenue AED 50bn+ growing ~3–4%. e& trades between the pure UAE duopoly multiple and the EM-holdings discount its NCI-heavy international portfolio commands.
