Workbook

Sheet READ FIRST
A1: Testahil — e-finance for Digital and Financial Investments (EGX: EFIH)
A2: Companion model · Independent Valuation Study · Educational analysis · Not investment advice
A5: What this workbook is. A transparent companion to the EFIH valuation study. Every blue cell is an input; every
A6: black cell is a formula; green cells link across sheets. All inputs live on the Assumptions sheet — change one
A7: (a segment multiple, the WACC, a growth rate) and the whole model reprices.
A9: What it is not. It is not investment advice, a recommendation, or a price target. Values are model outputs shown
A10: as ranges. The preparer is not licensed by any securities regulator and may hold a position in the security.
A12: Currency. EGP million unless stated. Spot EGP 20.74 (1 Jul 2026). Shares 3,466.67 mn (par EGP 0.50).
A13: Lens. e-finance is an asset-light, cash-generative, near-debt-free payments-infrastructure group. The heaviest-
A14: weighted lens is a going-concern FCFF DCF on EGP-appropriate parameters (WACC 22%, terminal growth 11%);
A15: a segment sum-of-the-parts, relative multiples and normalized earnings complete the four-lens football field.
A17: Historical. FY2024 & FY2025 are company disclosure (FY2025 earnings release, 04 Mar 2026). FY2023 is
... A22: Income Statement · Balance Sheet · Cash Flow · Summary Financials · Monte Carlo · Sensitivity · Per-Share & Ratios · Peer & Sector.

Sheet Summary
A1: Valuation summary — e-finance (EGX: EFIH)
A2: Four-lens fair value vs spot. Base links live; bear/bull are scenario outputs (see study §1.5).
B3: Bear | C3: Base | D3: Bull | E3: Weight
A4: Sum-of-the-parts | B4: 9.5 | C4: =SOTP!E14 -> 12.330314 | D4: 22 | E4: =Assumptions!$B$34 -> 0.25
A5: Going-concern DCF | B5: 7.5 | C5: =DCF!B21 -> 10.748718 | D5: 22 | E5: =Assumptions!$B$35 -> 0.35
A6: Relative multiples | B6: 13 | C6: ='Relative & Normalized'!C4 -> 18.167002 | D6: 26 | E6: =Assumptions!$B$36 -> 0.2
A7: Normalized earnings | B7: 13 | C7: ='Relative & Normalized'!C6 -> 18.403828 | D7: 26 | E7: =Assumptions!$B$37 -> 0.2
A8: Weighted central | B8: =SUMPRODUCT(B4:B7,$E$4:$E$7) -> 10.2 | C8: =SUMPRODUCT(C4:C7,$E$4:$E$7) -> 14.158796 | D8: =SUMPRODUCT(D4:D7,$E$4:$E$7) -> 23.6
A10: Spot price (EGP) | C10: =Assumptions!$B$4 -> 20.74
A11: Spot vs central base | C11: =C10/C8-1 -> 0.46481385
A13: Read: the market is pricing continued exceptional growth — spot sits above the blended fair value; the swing factor is the multiple placed on Cloud/Transaction and the EGP discount rate.

Sheet Fundamental Valuation
A1: Fundamental valuation — football-field data
A2: Bear/base/bull per lens (links to Summary).
A3: Lens | B3: Bear | C3: Base | D3: Bull
A4: Sum-of-the-parts | B4: =Summary!B4 -> 9.5 | C4: =Summary!C4 -> 12.330314 | D4: =Summary!D4 -> 22
A5: Going-concern DCF | B5: =Summary!B5 -> 7.5 | C5: =Summary!C5 -> 10.748718 | D5: =Summary!D5 -> 22
A6: Relative multiples | B6: =Summary!B6 -> 13 | C6: =Summary!C6 -> 18.167002 | D6: =Summary!D6 -> 26
A7: Normalized earnings | B7: =Summary!B7 -> 13 | C7: =Summary!C7 -> 18.403828 | D7: =Summary!D7 -> 26
A8: Weighted central | B8: =Summary!B8 -> 10.2 | C8: =Summary!C8 -> 14.158796 | D8: =Summary!D8 -> 23.6
A9: Spot | C9: =Assumptions!$B$4 -> 20.74

Sheet Assumptions
A1: Assumptions — the single input layer
A2: All blue cells are inputs. Every other sheet links here.
A3: ANCHORS
A4: Spot price (EGP/share) | B4: 20.74
A5: Shares outstanding (mn) | B5: 3466.67
A6: Net cash — cash less debt (EGP mn) | B6: 1379
A7: WACC (EGP) | B7: 0.21
A8: Terminal growth (EGP nominal) | B8: 0.11
A9: Tax rate | B9: 0.225
A10: NCI economic share of operations | B10: 0.2
A12: SOTP — segment marks (FY2025 basis)
A13: Transaction FY25 revenue (EGP mn) | B13: 2678.8
A14: Transaction segment EBITDA margin | B14: 0.58
A15: Transaction EV/EBITDA | B15: 16
A16: Cloud FY25 revenue (EGP mn) | B16: 2386.5
A17: Cloud segment EBITDA margin | B17: 0.53
A18: Cloud EV/EBITDA | B18: 20
A19: Build & Operate FY25 revenue (EGP mn) | B19: 1162.9
A20: Build & Operate segment EBITDA margin | B20: 0.3
A21: Build & Operate EV/EBITDA | B21: 7
A22: Other FY25 revenue (EGP mn) | B22: 544.9
A23: Other segment EBITDA margin | B23: 0.28
A24: Other EV/EBITDA | B24: 12
A25: Complexity / holdco discount | B25: 0.05
A27: RELATIVE & NORMALIZED
A28: Normalized EBITDA (EGP mn) | B28: 4400
A29: EV/EBITDA target multiple | B29: 14
A30: Mid-cycle net profit after NCI (EGP mn) | B30: 2900
A31: Justified P/E | B31: 22
A33: SYNTHESIS WEIGHTS
A34: SOTP weight | B34: 0.25
A35: DCF weight | B35: 0.35
A36: Relative weight | B36: 0.2
A37: Normalized-earnings weight | B37: 0.2
A39: WORKING CAPITAL (% of revenue)
A40: Receivables | B40: 0.22
A41: Payables | B41: 0.15
A43: MONTE CARLO
A44: Diffusion volatility (annualized) | B44: 0.5088
A45: Net 3-month drift (drift OFF) | B45: 0
...

Sheet SOTP
A1: Sum-of-the-parts by segment (primary-lens sheet)
A2: Each segment marked on FY2025 EBITDA × an EV/EBITDA fitting its economics. Links to Assumptions.
A3: Segment | B3: Basis | C3: Segment EBITDA | D3: EV/EBITDA | E3: EV (EGP mn)
A4: Transaction | B4: Payment-rails infra | C4: =Assumptions!B13*Assumptions!B14 -> 1553.704 | D4: =Assumptions!B15 -> 16 | E4: =C4*D4 -> 24859.264
A5: Cloud | B5: Gov cloud hosting | C5: =Assumptions!B16*Assumptions!B17 -> 1264.845 | D5: =Assumptions!B18 -> 20 | E5: =C5*D5 -> 25296.9
A6: Build & Operate | B6: Project supply+operate | C6: =Assumptions!B19*Assumptions!B20 -> 348.87 | D6: =Assumptions!B21 -> 7 | E6: =C6*D6 -> 2442.09
A7: Other | B7: Card/BPO/embedded fin | C7: =Assumptions!B22*Assumptions!B23 -> 152.572 | D7: =Assumptions!B24 -> 12 | E7: =C7*D7 -> 1830.864
A8: Σ Enterprise value | E8: =SUM(E4:E7) -> 54429.118
A9: less: complexity / holdco discount | E9: =-E8*Assumptions!B25 -> -2721.4559
A10: Enterprise value (post-discount) | E10: =E8+E9 -> 51707.662
A11: EV attributable to controlling (×(1−NCI)) | E11: =E10*(1-Assumptions!B10) -> 41366.13
A12: + Net cash | E12: =Assumptions!B6 -> 1379
A13: Controlling equity value | E13: =E11+E12 -> 42745.13
A14: SOTP fair value per share (EGP) | E14: =E13/Assumptions!B5 -> 12.330314

Sheet Segments
A1: Segment view
A2: Revenue by segment and mix, FY2023–FY2030E (links to Income Statement).
B3: FY2023 | C3: FY2024 | D3: FY2025 | E3: FY2026E | F3: FY2027E | G3: FY2028E | H3: FY2029E | I3: FY2030E
A4: Transaction revenue | B4: ='Income Statement'!B4 -> 1610 | C4: ='Income Statement'!C4 -> 2062 | D4: ='Income Statement'!D4 -> 2678.8 | E4: ='Income Statement'!E4 -> 3536.016 | F4: ='Income Statement'!F4 -> 4384.6598 | G4: ='Income Statement'!G4 -> 5217.7452 | H4: ='Income Statement'!H4 -> 6000.407 | I4: ='Income Statement'!I4 -> 6720.4558
A5: Cloud revenue | B5: ='Income Statement'!B5 -> 1030 | C5: ='Income Statement'!C5 -> 1580.8 | D5: ='Income Statement'!D5 -> 2386.5 | E5: ='Income Statement'!E5 -> 3460.425 | F5: ='Income Statement'!F5 -> 4671.5737 | G5: ='Income Statement'!G5 -> 5932.8987 | H5: ='Income Statement'!H5 -> 7178.8074 | I5: ='Income Statement'!I5 -> 8327.4166
A6: Build & Operate revenue | B6: ='Income Statement'!B6 -> 990 | C6: ='Income Statement'!C6 -> 1222.6 | D6: ='Income Statement'!D6 -> 1162.9 | E6: ='Income Statement'!E6 -> 1232.674 | F6: ='Income Statement'!F6 -> 1331.2879 | G6: ='Income Statement'!G6 -> 1437.791 | H6: ='Income Statement'!H6 -> 1538.4363 | I6: ='Income Statement'!I6 -> 1630.7425
A7: Other revenue | B7: ='Income Statement'!B7 -> 286 | C7: ='Income Statement'!C7 -> 344 | D7: ='Income Statement'!D7 -> 544.9 | E7: ='Income Statement'!E7 -> 724.717 | F7: ='Income Statement'!F7 -> 920.39059 | G7: ='Income Statement'!G7 -> 1122.8765 | H7: ='Income Statement'!H7 -> 1324.9943 | I7: ='Income Statement'!I7 -> 1523.7434
A8: Total revenue | B8: ='Income Statement'!B8 -> 3916 | C8: ='Income Statement'!C8 -> 5209.4 | D8: ='Income Statement'!D8 -> 6773.1 | E8: ='Income Statement'!E8 -> 8953.832 | F8: ='Income Statement'!F8 -> 11307.912 | G8: ='Income Statement'!G8 -> 13711.311 | H8: ='Income Statement'!H8 -> 16042.645 | I8: ='Income Statement'!I8 -> 18202.358
A9: Transaction % of revenue | B9: =B4/B8 -> 0.41113381 | C9: =C4/C8 -> 0.39582294 | D9: =D4/D8 -> 0.39550575 | E9: =E4/E8 -> 0.3949165 | F9: =F4/F8 -> 0.3877515 | G9: =G4/G8 -> 0.38054312 | H9: =H4/H8 -> 0.37402853 | I9: =I4/I8 -> 0.36920797
A10: Cloud % of revenue | B10: =B5/B8 -> 0.26302349 | C10: =C5/C8 -> 0.30345145 | D10: =D5/D8 -> 0.35234974 | E10: =E5/E8 -> 0.38647419 | F10: =F5/F8 -> 0.41312434 | G10: =G5/G8 -> 0.43270104 | H10: =H5/H8 -> 0.44748278 | I10: =I5/I8 -> 0.45749108
A11: Build & Operate % of revenue | B11: =B6/B8 -> 0.25280899 | C11: =C6/C8 -> 0.23469114 | D11: =D6/D8 -> 0.17169391 | E11: =E6/E8 -> 0.13766999 | F11: =F6/F8 -> 0.11773066 | G11: =G6/G8 -> 0.10486167 | H11: =H6/H8 -> 0.095896675 | I11: =I6/I8 -> 0.089589627
A12: Group revenue YoY | C12: =C8/B8-1 -> 0.33028601 | D12: =D8/C8-1 -> 0.30016893 | E12: =E8/D8-1 -> 0.32196956 | F12: =F8/E8-1 -> 0.26291314 | G12: =G8/F8-1 -> 0.21254138 | H12: =H8/G8-1 -> 0.17002995 | I12: =I8/H8-1 -> 0.13462327

Sheet Relative & Normalized
A1: Relative & normalized-earnings lenses
A2: Links to Assumptions.
A3: Lens | B3: Workings | C3: EGP/share
A4: Relative EV/EBITDA | B4: Norm EBITDA × mult + net cash, /sh | C4: =(Assumptions!B28*Assumptions!B29+Assumptions!B6)/Assumptions!B5 -> 18.167002
A5: implied EV (EGP mn) | C5: =Assumptions!B28*Assumptions!B29 -> 61600
A6: Normalized earnings | B6: Mid-cycle NP after NCI × P/E, /sh | C6: =Assumptions!B30*Assumptions!B31/Assumptions!B5 -> 18.403828
A7: normalized EPS (EGP) | C7: =Assumptions!B30/Assumptions!B5 -> 0.83653766

Sheet DCF
A1: Discounted cash flow — explicit 5-year FCFF (EGP)
A2: NOPAT + D&A − capex − ΔWC + after-tax net investment income, discounted at WACC. Links to statements / Assumptions.
E3: FY2026E | F3: FY2027E | G3: FY2028E | H3: FY2029E | I3: FY2030E
A4: EBIT | E4: ='Income Statement'!E15 -> 4118.7627 | F4: ='Income Statement'!F15 -> 5179.0237 | G4: ='Income Statement'!G15 -> 6170.0901 | H4: ='Income Statement'!H15 -> 7090.8491 | I4: ='Income Statement'!I15 -> 7918.0259
A5: NOPAT = EBIT×(1−tax) | E5: =E4*(1-Assumptions!$B$9) -> 3192.0411 | F5: =F4*(1-Assumptions!$B$9) -> 4013.7434 | G5: =G4*(1-Assumptions!$B$9) -> 4781.8198 | H5: =H4*(1-Assumptions!$B$9) -> 5495.408 | I5: =I4*(1-Assumptions!$B$9) -> 6136.4701
A6: + D&A | E6: ='Income Statement'!E14 -> 358.15328 | F6: ='Income Statement'!F14 -> 474.93231 | G6: ='Income Statement'!G14 -> 617.00901 | H6: ='Income Statement'!H14 -> 770.04696 | I6: ='Income Statement'!I14 -> 910.11792
A7: − Capex | E7: =-'Income Statement'!E8*Assumptions!E56 -> -492.46076 | F7: =-'Income Statement'!F8*Assumptions!F56 -> -621.93517 | G7: =-'Income Statement'!G8*Assumptions!G56 -> -685.56557 | H7: =-'Income Statement'!H8*Assumptions!H56 -> -721.91902 | I7: =-'Income Statement'!I8*Assumptions!I56 -> -728.09433
A8: − Increase in net WC | E8: =-(('Balance Sheet'!E6-'Balance Sheet'!E14)-('Balance Sheet'!D6-'Balance Sheet'!D14)) -> -152.65124 | F8: =-(('Balance Sheet'!F6-'Balance Sheet'!F14)-('Balance Sheet'!E6-'Balance Sheet'!E14)) -> -164.78561 | G8: =-(('Balance Sheet'!G6-'Balance Sheet'!G14)-('Balance Sheet'!F6-'Balance Sheet'!F14)) -> -168.23795 | H8: =-(('Balance Sheet'!H6-'Balance Sheet'!H14)-('Balance Sheet'!G6-'Balance Sheet'!G14)) -> -163.19335 | I8: =-(('Balance Sheet'!I6-'Balance Sheet'!I14)-('Balance Sheet'!H6-'Balance Sheet'!H14)) -> -151.17993
A9: + After-tax net investment income | E9: =('Income Statement'!E17-'Income Statement'!E16)*(1-Assumptions!$B$9) -> 697.5 | F9: =('Income Statement'!F17-'Income Statement'!F16)*(1-Assumptions!$B$9) -> 740.125 | G9: =('Income Statement'!G17-'Income Statement'!G16)*(1-Assumptions!$B$9) -> 790.5 | H9: =('Income Statement'!H17-'Income Statement'!H16)*(1-Assumptions!$B$9) -> 840.875 | I9: =('Income Statement'!I17-'Income Statement'!I16)*(1-Assumptions!$B$9) -> 891.25
A10: FCFF | E10: =E5+E6+E7+E8+E9 -> 3602.5824 | F10: =F5+F6+F7+F8+F9 -> 4442.0799 | G10: =G5+G6+G7+G8+G9 -> 5335.5253 | H10: =H5+H6+H7+H8+H9 -> 6221.2176 | I10: =I5+I6+I7+I8+I9 -> 7058.5637
A11: Discount factor | E11: =1/(1+Assumptions!$B$7)^1 -> 0.82644628 | F11: =1/(1+Assumptions!$B$7)^2 -> 0.68301346 | G11: =1/(1+Assumptions!$B$7)^3 -> 0.56447393 | H11: =1/(1+Assumptions!$B$7)^4 -> 0.46650738 | I11: =1/(1+Assumptions!$B$7)^5 -> 0.38554329
A12: PV of FCFF | E12: =E10*E11 -> 2977.3408 | F12: =F10*F11 -> 3034.0004 | G12: =G10*G11 -> 3011.765 | H12: =H10*H11 -> 2902.2439 | I12: =I10*I11 -> 2721.3819
A14: Σ PV of explicit FCFF (FY26–30) | B14: =SUM(E12:I12) -> 14646.732
A15: Terminal value (Gordon) | B15: =I10*(1+Assumptions!$B$8)/(Assumptions!$B$7-Assumptions!$B$8) -> 78350.057
A16: PV of terminal value | B16: =B15/(1+Assumptions!$B$7)^5 -> 30207.339
A17: Enterprise value | B17: =B14+B16 -> 44854.071
A18: EV attributable to controlling (×(1−NCI)) | B18: =B17*(1-Assumptions!$B$10) -> 35883.257
A19: + Net cash | B19: =Assumptions!$B$6 -> 1379
A20: Controlling equity value | B20: =B18+B19 -> 37262.257
A21: Fair value per share (EGP) | B21: =B20/Assumptions!$B$5 -> 10.748718
A22: % terminal of EV | B22: =B16/B17 -> 0.67345813

Sheet Income Statement
A1: Income statement (EGP mn, consolidated)
A2: FY2023–FY2025 historical (blue; FY2023 reconstructed); FY2026E–FY2030E forecast (formulas linking to Assumptions)
B3: FY2023 | C3: FY2024 | D3: FY2025 | E3: FY2026E | F3: FY2027E | G3: FY2028E | H3: FY2029E | I3: FY2030E
A4: Transaction revenue | B4: 1610 | C4: 2062 | D4: 2678.8 | E4: =D4*(1+Assumptions!E49) -> 3536.016 | F4: =E4*(1+Assumptions!F49) -> 4384.6598 | G4: =F4*(1+Assumptions!G49) -> 5217.7452 | H4: =G4*(1+Assumptions!H49) -> 6000.407 | I4: =H4*(1+Assumptions!I49) -> 6720.4558
A5: Cloud revenue | B5: 1030 | C5: 1580.8 | D5: 2386.5 | E5: =D5*(1+Assumptions!E50) -> 3460.425 | F5: =E5*(1+Assumptions!F50) -> 4671.5737 | G5: =F5*(1+Assumptions!G50) -> 5932.8987 | H5: =G5*(1+Assumptions!H50) -> 7178.8074 | I5: =H5*(1+Assumptions!I50) -> 8327.4166
A6: Build & Operate revenue | B6: 990 | C6: 1222.6 | D6: 1162.9 | E6: =D6*(1+Assumptions!E51) -> 1232.674 | F6: =E6*(1+Assumptions!F51) -> 1331.2879 | G6: =F6*(1+Assumptions!G51) -> 1437.791 | H6: =G6*(1+Assumptions!H51) -> 1538.4363 | I6: =H6*(1+Assumptions!I51) -> 1630.7425
A7: Other revenue | B7: 286 | C7: 344 | D7: 544.9 | E7: =D7*(1+Assumptions!E52) -> 724.717 | F7: =E7*(1+Assumptions!F52) -> 920.39059 | G7: =F7*(1+Assumptions!G52) -> 1122.8765 | H7: =G7*(1+Assumptions!H52) -> 1324.9943 | I7: =H7*(1+Assumptions!I52) -> 1523.7434
A8: Total revenue | B8: =SUM(B4:B7) -> 3916 | C8: =SUM(C4:C7) -> 5209.4 | D8: =SUM(D4:D7) -> 6773.1 | E8: =SUM(E4:E7) -> 8953.832 | F8: =SUM(F4:F7) -> 11307.912 | G8: =SUM(G4:G7) -> 13711.311 | H8: =SUM(H4:H7) -> 16042.645 | I8: =SUM(I4:I7) -> 18202.358
A10: Gross profit | B10: 2036 | C10: 2787.3 | D10: 3818.8 | E10: =E8*Assumptions!E53 -> 5058.9151 | F10: =F8*Assumptions!F53 -> 6388.9703 | G10: =G8*Assumptions!G53 -> 7678.3344 | H10: =H8*Assumptions!H53 -> 8903.668 | I10: =I8*Assumptions!I53 -> 10011.297
A11: Operating expenses (excl. D&A) | B11: =-( B10-B12) -> -235 | C11: =-( C10-C12) -> -336.8 | D11: =-( D10-D12) -> -486.4 | E11: =-( E10-E12) -> -581.99908 | F11: =-( F10-F12) -> -735.01429 | G11: =-( G10-G12) -> -891.23524 | H11: =-( H10-H12) -> -1042.7719 | I11: =-( I10-I12) -> -1183.1533
A12: EBITDA | B12: 1801 | C12: 2450.5 | D12: 3332.4 | E12: =E8*Assumptions!E54 -> 4476.916 | F12: =F8*Assumptions!F54 -> 5653.956 | G12: =G8*Assumptions!G54 -> 6787.0991 | H12: =H8*Assumptions!H54 -> 7860.896 | I12: =I8*Assumptions!I54 -> 8828.1438
A13: EBITDA margin | B13: =B12/B8 -> 0.45990807 | C13: =C12/C8 -> 0.47039966 | D13: =D12/D8 -> 0.49200514 | E13: =E12/E8 -> 0.5 | F13: =F12/F8 -> 0.5 | G13: =G12/G8 -> 0.495 | H13: =H12/H8 -> 0.49 | I13: =I12/I8 -> 0.485
A14: D&A | B14: 180 | C14: 230 | D14: 252.4 | E14: =E8*Assumptions!E55 -> 358.15328 | F14: =F8*Assumptions!F55 -> 474.93231 | G14: =G8*Assumptions!G55 -> 617.00901 | H14: =H8*Assumptions!H55 -> 770.04696 | I14: =I8*Assumptions!I55 -> 910.11792
A15: EBIT | B15: =B12-B14 -> 1621 | C15: =C12-C14 -> 2220.5 | D15: =D12-D14 -> 3080 | E15: =E12-E14 -> 4118.7627 | F15: =F12-F14 -> 5179.0237 | G15: =G12-G14 -> 6170.0901 | H15: =H12-H14 -> 7090.8491 | I15: =I12-I14 -> 7918.0259
A16: Finance cost | B16: 40 | C16: 50 | D16: 50 | E16: =Assumptions!E57 -> 60 | F16: =Assumptions!F57 -> 65 | G16: =Assumptions!G57 -> 70 | H16: =Assumptions!H57 -> 75 | I16: =Assumptions!I57 -> 80
A17: Investment & interest income | B17: 500 | C17: 785.4 | D17: 893 | E17: =Assumptions!E58 -> 960 | F17: =Assumptions!F58 -> 1020 | G17: =Assumptions!G58 -> 1090 | H17: =Assumptions!H58 -> 1160 | I17: =Assumptions!I58 -> 1230
A18: PBT | B18: =B15-B16+B17 -> 2081 | C18: =C15-C16+C17 -> 2955.9 | D18: =D15-D16+D17 -> 3923 | E18: =E15-E16+E17 -> 5018.7627 | F18: =F15-F16+F17 -> 6134.0237 | G18: =G15-G16+G17 -> 7190.0901 | H18: =H15-H16+H17 -> 8175.8491 | I18: =I15-I16+I17 -> 9068.0259
A19: Tax | B19: 468 | C19: 665 | D19: 895 | E19: =E18*Assumptions!$B$9 -> 1129.2216 | F19: =F18*Assumptions!$B$9 -> 1380.1553 | G19: =G18*Assumptions!$B$9 -> 1617.7703 | H19: =H18*Assumptions!$B$9 -> 1839.566 | I19: =I18*Assumptions!$B$9 -> 2040.3058
A20: Net profit (before NCI) | B20: =B18-B19 -> 1613 | C20: =C18-C19 -> 2290.9 | D20: =D18-D19 -> 3028 | E20: =E18-E19 -> 3889.5411 | F20: =F18-F19 -> 4753.8684 | G20: =G18-G19 -> 5572.3198 | H20: =H18-H19 -> 6336.283 | I20: =I18-I19 -> 7027.7201
A21: less: non-controlling interests | B21: 323 | C21: 514.9 | D21: 622.6 | E21: =E20*Assumptions!$B$10 -> 777.90822 | F21: =F20*Assumptions!$B$10 -> 950.77368 | G21: =G20*Assumptions!$B$10 -> 1114.464 | H21: =H20*Assumptions!$B$10 -> 1267.2566 | I21: =I20*Assumptions!$B$10 -> 1405.544
A22: Net profit after NCI | B22: =B20-B21 -> 1290 | C22: =C20-C21 -> 1776 | D22: =D20-D21 -> 2405.4 | E22: =E20-E21 -> 3111.6329 | F22: =F20-F21 -> 3803.0947 | G22: =G20-G21 -> 4457.8559 | H22: =H20-H21 -> 5069.0264 | I22: =I20-I21 -> 5622.176
A23: net profit margin | B23: =B22/B8 -> 0.32941777 | C23: =C22/C8 -> 0.34092218 | D23: =D22/D8 -> 0.35514019 | E23: =E22/E8 -> 0.34751969 | F23: =F22/F8 -> 0.33632157 | G23: =G22/G8 -> 0.3251225 | H23: =H22/H8 -> 0.31597199 | I23: =I22/I8 -> 0.30887075
A25: Source: e-finance FY2025 earnings release (04 Mar 2026), ent.news/2026/3/269.pdf. FY2024 disclosed; FY2023 reconstructed from 9M2024 y-o-y growth. Forecast = formulas.

Sheet Balance Sheet
A1: Balance sheet (EGP mn, consolidated)
A2: Historical anchored to disclosed total assets / controlling equity / net cash; financial investments plug to balance. Forecast rolls forward.
B3: FY2023 | C3: FY2024 | D3: FY2025 | E3: FY2026E | F3: FY2027E | G3: FY2028E | H3: FY2029E | I3: FY2030E
A4: PP&E + intangibles | B4: 2100 | C4: 2400 | D4: 2600 | E4: =D4+'Income Statement'!E8*Assumptions!E56-'Income Statement'!E14 -> 2734.3075 | F4: =E4+'Income Statement'!F8*Assumptions!F56-'Income Statement'!F14 -> 2881.3103 | G4: =F4+'Income Statement'!G8*Assumptions!G56-'Income Statement'!G14 -> 2949.8669 | H4: =G4+'Income Statement'!H8*Assumptions!H56-'Income Statement'!H14 -> 2901.739 | I4: =H4+'Income Statement'!I8*Assumptions!I56-'Income Statement'!I14 -> 2719.7154
A5: Financial investments (T-bills, FVOCI, associates) | B5: =(B11+B12+B13+B14+B15)-(B4+B6+B7+B8) -> 2898.88 | C5: =(C11+C12+C13+C14+C15)-(C4+C6+C7+C8) -> 3746.342 | D5: =(D11+D12+D13+D14+D15)-(D4+D6+D7+D8) -> 5822.883 | E5: =D5 -> 5822.883 | F5: =E5 -> 5822.883 | G5: =F5 -> 5822.883 | H5: =G5 -> 5822.883 | I5: =H5 -> 5822.883
A6: Receivables | B6: ='Income Statement'!B8*Assumptions!$B$40 -> 861.52 | C6: ='Income Statement'!C8*Assumptions!$B$40 -> 1146.068 | D6: ='Income Statement'!D8*Assumptions!$B$40 -> 1490.082 | E6: ='Income Statement'!E8*Assumptions!$B$40 -> 1969.843 | F6: ='Income Statement'!F8*Assumptions!$B$40 -> 2487.7407 | G6: ='Income Statement'!G8*Assumptions!$B$40 -> 3016.4885 | H6: ='Income Statement'!H8*Assumptions!$B$40 -> 3529.3819 | I6: ='Income Statement'!I8*Assumptions!$B$40 -> 4004.5188
A7: Cash & equivalents | B7: 1140 | C7: 1306 | D7: 1491 | E7: ='Cash Flow'!E14 -> 4613.5824 | F7: ='Cash Flow'!F14 -> 8495.6623 | G7: ='Cash Flow'!G14 -> 13181.188 | H7: ='Cash Flow'!H14 -> 18642.405 | I7: ='Cash Flow'!I14 -> 24820.969
A8: Other assets | B8: 400 | C8: 450 | D8: 500 | E8: =D8 -> 500 | F8: =E8 -> 500 | G8: =F8 -> 500 | H8: =G8 -> 500 | I8: =H8 -> 500
A9: Total assets | B9: =SUM(B4:B8) -> 7400.4 | C9: =SUM(C4:C8) -> 9048.41 | D9: =SUM(D4:D8) -> 11903.965 | E9: =SUM(E4:E8) -> 15640.616 | F9: =SUM(F4:F8) -> 20187.596 | G9: =SUM(G4:G8) -> 25470.426 | H9: =SUM(H4:H8) -> 31396.409 | I9: =SUM(I4:I8) -> 37868.086
A11: Controlling shareholders’ equity | B11: 5300 | C11: 6680 | D11: 8626 | E11: =D11+'Income Statement'!E22-Assumptions!E59 -> 11257.633 | F11: =E11+'Income Statement'!F22-Assumptions!F59 -> 14500.728 | G11: =F11+'Income Statement'!G22-Assumptions!G59 -> 18308.583 | H11: =G11+'Income Statement'!H22-Assumptions!H59 -> 22617.61 | I11: =H11+'Income Statement'!I22-Assumptions!I59 -> 27359.786
A12: Non-controlling interests (equity) | B12: 1100 | C12: 1300 | D12: 1500 | E12: =D12+'Income Statement'!E21 -> 2277.9082 | F12: =E12+'Income Statement'!F21 -> 3228.6819 | G12: =F12+'Income Statement'!G21 -> 4343.1459 | H12: =G12+'Income Statement'!H21 -> 5610.4025 | I12: =H12+'Income Statement'!I21 -> 7015.9465
A13: Borrowings | B13: 90 | C13: 100 | D13: 112 | E13: =D13 -> 112 | F13: =E13 -> 112 | G13: =F13 -> 112 | H13: =G13 -> 112 | I13: =H13 -> 112
A14: Payables | B14: ='Income Statement'!B8*Assumptions!$B$41 -> 587.4 | C14: ='Income Statement'!C8*Assumptions!$B$41 -> 781.41 | D14: ='Income Statement'!D8*Assumptions!$B$41 -> 1015.965 | E14: ='Income Statement'!E8*Assumptions!$B$41 -> 1343.0748 | F14: ='Income Statement'!F8*Assumptions!$B$41 -> 1696.1868 | G14: ='Income Statement'!G8*Assumptions!$B$41 -> 2056.6967 | H14: ='Income Statement'!H8*Assumptions!$B$41 -> 2406.3967 | I14: ='Income Statement'!I8*Assumptions!$B$41 -> 2730.3537
A15: Provisions, deferred revenue & other | B15: 323 | C15: 187 | D15: 650 | E15: =D15 -> 650 | F15: =E15 -> 650 | G15: =F15 -> 650 | H15: =G15 -> 650 | I15: =H15 -> 650
A16: Total liabilities & equity | B16: =B11+B12+B13+B14+B15 -> 7400.4 | C16: =C11+C12+C13+C14+C15 -> 9048.41 | D16: =D11+D12+D13+D14+D15 -> 11903.965 | E16: =E11+E12+E13+E14+E15 -> 15640.616 | F16: =F11+F12+F13+F14+F15 -> 20187.596 | G16: =G11+G12+G13+G14+G15 -> 25470.426 | H16: =H11+H12+H13+H14+H15 -> 31396.409 | I16: =I11+I12+I13+I14+I15 -> 37868.086
A18: Balance check (assets − L&E) | B18: =B9-B16 -> 0 | C18: =C9-C16 -> 0 | D18: =D9-D16 -> 0 | E18: =E9-E16 -> 0 | F18: =F9-F16 -> 0 | G18: =G9-G16 -> 0 | H18: =H9-H16 -> 0 | I18: =I9-I16 -> 0
A19: Net cash (cash − borrowings) | B19: =B7-B13 -> 1050 | C19: =C7-C13 -> 1206 | D19: =D7-D13 -> 1379 | E19: =E7-E13 -> 4501.5824 | F19: =F7-F13 -> 8383.6623 | G19: =G7-G13 -> 13069.188 | H19: =H7-H13 -> 18530.405 | I19: =I7-I13 -> 24708.969
A20: Net working capital (recv − pay) | B20: =B6-B14 -> 274.12 | C20: =C6-C14 -> 364.658 | D20: =D6-D14 -> 474.117 | E20: =E6-E14 -> 626.76824 | F20: =F6-F14 -> 791.55385 | G20: =G6-G14 -> 959.79179 | H20: =H6-H14 -> 1122.9851 | I20: =I6-I14 -> 1274.1651

Sheet Cash Flow
A1: Cash flow (EGP mn, forecast)
A2: Derived from the Income Statement and Balance Sheet. Closing cash ties to the Balance Sheet.
E3: FY2026E | F3: FY2027E | G3: FY2028E | H3: FY2029E | I3: FY2030E
A4: Net profit after NCI | E4: ='Income Statement'!E22 -> 3111.6329 | F4: ='Income Statement'!F22 -> 3803.0947 | G4: ='Income Statement'!G22 -> 4457.8559 | H4: ='Income Statement'!H22 -> 5069.0264 | I4: ='Income Statement'!I22 -> 5622.176
A5: + NCI | E5: ='Income Statement'!E21 -> 777.90822 | F5: ='Income Statement'!F21 -> 950.77368 | G5: ='Income Statement'!G21 -> 1114.464 | H5: ='Income Statement'!H21 -> 1267.2566 | I5: ='Income Statement'!I21 -> 1405.544
A6: + D&A | E6: ='Income Statement'!E14 -> 358.15328 | F6: ='Income Statement'!F14 -> 474.93231 | G6: ='Income Statement'!G14 -> 617.00901 | H6: ='Income Statement'!H14 -> 770.04696 | I6: ='Income Statement'!I14 -> 910.11792
A7: − Increase in net working capital | E7: =-(('Balance Sheet'!E6-'Balance Sheet'!E14)-('Balance Sheet'!D6-'Balance Sheet'!D14)) -> -152.65124 | F7: =-(('Balance Sheet'!F6-'Balance Sheet'!F14)-('Balance Sheet'!E6-'Balance Sheet'!E14)) -> -164.78561 | G7: =-(('Balance Sheet'!G6-'Balance Sheet'!G14)-('Balance Sheet'!F6-'Balance Sheet'!F14)) -> -168.23795 | H7: =-(('Balance Sheet'!H6-'Balance Sheet'!H14)-('Balance Sheet'!G6-'Balance Sheet'!G14)) -> -163.19335 | I7: =-(('Balance Sheet'!I6-'Balance Sheet'!I14)-('Balance Sheet'!H6-'Balance Sheet'!H14)) -> -151.17993
A8: Operating cash flow | E8: =E4+E5+E6+E7 -> 4095.0431 | F8: =F4+F5+F6+F7 -> 5064.0151 | G8: =G4+G5+G6+G7 -> 6021.0909 | H8: =H4+H5+H6+H7 -> 6943.1366 | I8: =I4+I5+I6+I7 -> 7786.658
A9: − Capex | E9: =-'Income Statement'!E8*Assumptions!E56 -> -492.46076 | F9: =-'Income Statement'!F8*Assumptions!F56 -> -621.93517 | G9: =-'Income Statement'!G8*Assumptions!G56 -> -685.56557 | H9: =-'Income Statement'!H8*Assumptions!H56 -> -721.91902 | I9: =-'Income Statement'!I8*Assumptions!I56 -> -728.09433
A10: Free cash flow | E10: =E8+E9 -> 3602.5824 | F10: =F8+F9 -> 4442.0799 | G10: =G8+G9 -> 5335.5253 | H10: =H8+H9 -> 6221.2176 | I10: =I8+I9 -> 7058.5637
A11: − Dividend | E11: =-Assumptions!E59 -> -480 | F11: =-Assumptions!F59 -> -560 | G11: =-Assumptions!G59 -> -650 | H11: =-Assumptions!H59 -> -760 | I11: =-Assumptions!I59 -> -880
A12: Net change in cash | E12: =E10+E11 -> 3122.5824 | F12: =F10+F11 -> 3882.0799 | G12: =G10+G11 -> 4685.5253 | H12: =H10+H11 -> 5461.2176 | I12: =I10+I11 -> 6178.5637
A13: Opening cash | E13: ='Balance Sheet'!D7 -> 1491 | F13: ='Balance Sheet'!E7 -> 4613.5824 | G13: ='Balance Sheet'!F7 -> 8495.6623 | H13: ='Balance Sheet'!G7 -> 13181.188 | I13: ='Balance Sheet'!H7 -> 18642.405
A14: Closing cash | E14: =E13+E12 -> 4613.5824 | F14: =F13+F12 -> 8495.6623 | G14: =G13+G12 -> 13181.188 | H14: =H13+H12 -> 18642.405 | I14: =I13+I12 -> 24820.969

Sheet Summary Financials
A1: Summary financials (EGP mn)
A2: Every cell links to the statement sheets.
B3: FY2023 | C3: FY2024 | D3: FY2025 | E3: FY2026E | F3: FY2027E | G3: FY2028E | H3: FY2029E | I3: FY2030E
A4: Revenue | B4: ='Income Statement'!B8 -> 3916 | C4: ='Income Statement'!C8 -> 5209.4 | D4: ='Income Statement'!D8 -> 6773.1 | E4: ='Income Statement'!E8 -> 8953.832 | F4: ='Income Statement'!F8 -> 11307.912 | G4: ='Income Statement'!G8 -> 13711.311 | H4: ='Income Statement'!H8 -> 16042.645 | I4: ='Income Statement'!I8 -> 18202.358
A5: EBITDA | B5: ='Income Statement'!B12 -> 1801 | C5: ='Income Statement'!C12 -> 2450.5 | D5: ='Income Statement'!D12 -> 3332.4 | E5: ='Income Statement'!E12 -> 4476.916 | F5: ='Income Statement'!F12 -> 5653.956 | G5: ='Income Statement'!G12 -> 6787.0991 | H5: ='Income Statement'!H12 -> 7860.896 | I5: ='Income Statement'!I12 -> 8828.1438
A6: EBIT | B6: ='Income Statement'!B15 -> 1621 | C6: ='Income Statement'!C15 -> 2220.5 | D6: ='Income Statement'!D15 -> 3080 | E6: ='Income Statement'!E15 -> 4118.7627 | F6: ='Income Statement'!F15 -> 5179.0237 | G6: ='Income Statement'!G15 -> 6170.0901 | H6: ='Income Statement'!H15 -> 7090.8491 | I6: ='Income Statement'!I15 -> 7918.0259
A7: Net profit after NCI | B7: ='Income Statement'!B22 -> 1290 | C7: ='Income Statement'!C22 -> 1776 | D7: ='Income Statement'!D22 -> 2405.4 | E7: ='Income Statement'!E22 -> 3111.6329 | F7: ='Income Statement'!F22 -> 3803.0947 | G7: ='Income Statement'!G22 -> 4457.8559 | H7: ='Income Statement'!H22 -> 5069.0264 | I7: ='Income Statement'!I22 -> 5622.176
A8: Total assets | B8: ='Balance Sheet'!B9 -> 7400.4 | C8: ='Balance Sheet'!C9 -> 9048.41 | D8: ='Balance Sheet'!D9 -> 11903.965 | E8: ='Balance Sheet'!E9 -> 15640.616 | F8: ='Balance Sheet'!F9 -> 20187.596 | G8: ='Balance Sheet'!G9 -> 25470.426 | H8: ='Balance Sheet'!H9 -> 31396.409 | I8: ='Balance Sheet'!I9 -> 37868.086
A9: Controlling equity | B9: ='Balance Sheet'!B11 -> 5300 | C9: ='Balance Sheet'!C11 -> 6680 | D9: ='Balance Sheet'!D11 -> 8626 | E9: ='Balance Sheet'!E11 -> 11257.633 | F9: ='Balance Sheet'!F11 -> 14500.728 | G9: ='Balance Sheet'!G11 -> 18308.583 | H9: ='Balance Sheet'!H11 -> 22617.61 | I9: ='Balance Sheet'!I11 -> 27359.786
A10: Net cash | B10: ='Balance Sheet'!B19 -> 1050 | C10: ='Balance Sheet'!C19 -> 1206 | D10: ='Balance Sheet'!D19 -> 1379 | E10: ='Balance Sheet'!E19 -> 4501.5824 | F10: ='Balance Sheet'!F19 -> 8383.6623 | G10: ='Balance Sheet'!G19 -> 13069.188 | H10: ='Balance Sheet'!H19 -> 18530.405 | I10: ='Balance Sheet'!I19 -> 24708.969
A11: Free cash flow | E11: ='Cash Flow'!E10 -> 3602.5824 | F11: ='Cash Flow'!F10 -> 4442.0799 | G11: ='Cash Flow'!G10 -> 5335.5253 | H11: ='Cash Flow'!H10 -> 6221.2176 | I11: ='Cash Flow'!I10 -> 7058.5637

Sheet Monte Carlo
A1: Monte Carlo — engine outputs
A2: 50,000 paths · YZ-HAR width · Student-t(5) innovations · drift OFF · seed 42 · computed by the Testahil MC engine (values, not a sheet simulation).
A3: Percentile map (EGP/share)
A4: Horizon | B4: p5 | C4: p25 | D4: p50 | E4: p75 | F4: p95
A5: T+20 sessions | B5: 16.58 | C5: 19.13 | D5: 20.74 | E5: 22.48 | F5: 25.94
A6: T+60 sessions | B6: 14.08 | C6: 18.04 | D6: 20.74 | E6: 23.85 | F6: 30.56
A8: Inputs (from Assumptions): diffusion σ | D8: =Assumptions!$B$44 -> 0.5088
A9: net 3-month drift (OFF) | D9: =Assumptions!$B$45 -> 0
A11: Level-touch ladder
A12: Level | B12: P(touch) T+20 | C12: P(touch) T+60
A13: 26 | B13: 0.079 | C13: 0.264
A14: 24 | B14: 0.203 | C14: 0.44
A15: 23 | B15: 0.334 | C15: 0.564
A16: 22 | B16: 0.533 | C16: 0.716
A17: 21 | B17: 0.808 | C17: 0.889
A18: 20 | B18: 0.665 | C18: 0.8
A19: 19 | B19: 0.395 | C19: 0.617
A20: 18 | B20: 0.212 | C20: 0.451

Sheet Sensitivity
A1: Relative-lens sensitivity — the multiple the market pays
A2: Fair value (EGP/share) by normalized EBITDA (EGP mn) × EV/EBITDA multiple. Live off Assumptions net cash & shares.
A4: EBITDA \ mult | B4: 12 | C4: 13 | D4: 14 | E4: 15 | F4: 16 | G4: 18
A5: 3800 | B5: =($A5*B$4+Assumptions!$B$6)/Assumptions!$B$5 -> 13.551622 | C5: =($A5*C$4+Assumptions!$B$6)/Assumptions!$B$5 -> 14.647774 | D5: =($A5*D$4+Assumptions!$B$6)/Assumptions!$B$5 -> 15.743927 | E5: =($A5*E$4+Assumptions!$B$6)/Assumptions!$B$5 -> 16.84008 | F5: =($A5*F$4+Assumptions!$B$6)/Assumptions!$B$5 -> 17.936233 | G5: =($A5*G$4+Assumptions!$B$6)/Assumptions!$B$5 -> 20.128538
A6: 4000 | B6: =($A6*B$4+Assumptions!$B$6)/Assumptions!$B$5 -> 14.243929 | C6: =($A6*C$4+Assumptions!$B$6)/Assumptions!$B$5 -> 15.397774 | D6: =($A6*D$4+Assumptions!$B$6)/Assumptions!$B$5 -> 16.551619 | E6: =($A6*E$4+Assumptions!$B$6)/Assumptions!$B$5 -> 17.705464 | F6: =($A6*F$4+Assumptions!$B$6)/Assumptions!$B$5 -> 18.859309 | G6: =($A6*G$4+Assumptions!$B$6)/Assumptions!$B$5 -> 21.166999
A7: 4200 | B7: =($A7*B$4+Assumptions!$B$6)/Assumptions!$B$5 -> 14.936236 | C7: =($A7*C$4+Assumptions!$B$6)/Assumptions!$B$5 -> 16.147773 | D7: =($A7*D$4+Assumptions!$B$6)/Assumptions!$B$5 -> 17.35931 | E7: =($A7*E$4+Assumptions!$B$6)/Assumptions!$B$5 -> 18.570848 | F7: =($A7*F$4+Assumptions!$B$6)/Assumptions!$B$5 -> 19.782385 | G7: =($A7*G$4+Assumptions!$B$6)/Assumptions!$B$5 -> 22.205459
A8: 4400 | B8: =($A8*B$4+Assumptions!$B$6)/Assumptions!$B$5 -> 15.628543 | C8: =($A8*C$4+Assumptions!$B$6)/Assumptions!$B$5 -> 16.897772 | D8: =($A8*D$4+Assumptions!$B$6)/Assumptions!$B$5 -> 18.167002 | E8: =($A8*E$4+Assumptions!$B$6)/Assumptions!$B$5 -> 19.436231 | F8: =($A8*F$4+Assumptions!$B$6)/Assumptions!$B$5 -> 20.705461 | G8: =($A8*G$4+Assumptions!$B$6)/Assumptions!$B$5 -> 23.24392
A9: 4600 | B9: =($A9*B$4+Assumptions!$B$6)/Assumptions!$B$5 -> 16.32085 | C9: =($A9*C$4+Assumptions!$B$6)/Assumptions!$B$5 -> 17.647771 | D9: =($A9*D$4+Assumptions!$B$6)/Assumptions!$B$5 -> 18.974693 | E9: =($A9*E$4+Assumptions!$B$6)/Assumptions!$B$5 -> 20.301615 | F9: =($A9*F$4+Assumptions!$B$6)/Assumptions!$B$5 -> 21.628537 | G9: =($A9*G$4+Assumptions!$B$6)/Assumptions!$B$5 -> 24.28238
A10: 4800 | B10: =($A10*B$4+Assumptions!$B$6)/Assumptions!$B$5 -> 17.013157 | C10: =($A10*C$4+Assumptions!$B$6)/Assumptions!$B$5 -> 18.397771 | D10: =($A10*D$4+Assumptions!$B$6)/Assumptions!$B$5 -> 19.782385 | E10: =($A10*E$4+Assumptions!$B$6)/Assumptions!$B$5 -> 21.166999 | F10: =($A10*F$4+Assumptions!$B$6)/Assumptions!$B$5 -> 22.551613 | G10: =($A10*G$4+Assumptions!$B$6)/Assumptions!$B$5 -> 25.320841
A12: Cells near spot (EGP 20.74) show how much forward growth the market has already capitalized.

Sheet Per-Share & Ratios
A1: Per-share & ratios
A2: Links to statements / Assumptions.
B3: FY2023 | C3: FY2024 | D3: FY2025 | E3: FY2026E | F3: FY2027E | G3: FY2028E | H3: FY2029E | I3: FY2030E
A4: EPS (EGP) | B4: ='Income Statement'!B22/Assumptions!$B$5 -> 0.37211503 | C4: ='Income Statement'!C22/Assumptions!$B$5 -> 0.5123072 | D4: ='Income Statement'!D22/Assumptions!$B$5 -> 0.69386472 | E4: ='Income Statement'!E22/Assumptions!$B$5 -> 0.89758555 | F4: ='Income Statement'!F22/Assumptions!$B$5 -> 1.0970455 | G4: ='Income Statement'!G22/Assumptions!$B$5 -> 1.2859187 | H4: ='Income Statement'!H22/Assumptions!$B$5 -> 1.4622178 | I4: ='Income Statement'!I22/Assumptions!$B$5 -> 1.62178
A5: Book value/share (EGP) | B5: ='Balance Sheet'!B11/Assumptions!$B$5 -> 1.5288447 | C5: ='Balance Sheet'!C11/Assumptions!$B$5 -> 1.9269212 | D5: ='Balance Sheet'!D11/Assumptions!$B$5 -> 2.4882668 | E5: ='Balance Sheet'!E11/Assumptions!$B$5 -> 3.247391 | F5: ='Balance Sheet'!F11/Assumptions!$B$5 -> 4.1828982 | G5: ='Balance Sheet'!G11/Assumptions!$B$5 -> 5.2813171 | H5: ='Balance Sheet'!H11/Assumptions!$B$5 -> 6.5243043 | I5: ='Balance Sheet'!I11/Assumptions!$B$5 -> 7.8922384
A6: EBITDA margin | B6: ='Income Statement'!B12/'Income Statement'!B8 -> 0.45990807 | C6: ='Income Statement'!C12/'Income Statement'!C8 -> 0.47039966 | D6: ='Income Statement'!D12/'Income Statement'!D8 -> 0.49200514 | E6: ='Income Statement'!E12/'Income Statement'!E8 -> 0.5 | F6: ='Income Statement'!F12/'Income Statement'!F8 -> 0.5 | G6: ='Income Statement'!G12/'Income Statement'!G8 -> 0.495 | H6: ='Income Statement'!H12/'Income Statement'!H8 -> 0.49 | I6: ='Income Statement'!I12/'Income Statement'!I8 -> 0.485
A7: Net cash / EBITDA | B7: ='Balance Sheet'!B19/'Income Statement'!B12 -> 0.58300944 | C7: ='Balance Sheet'!C19/'Income Statement'!C12 -> 0.49214446 | D7: ='Balance Sheet'!D19/'Income Statement'!D12 -> 0.41381587 | E7: ='Balance Sheet'!E19/'Income Statement'!E12 -> 1.0055097 | F7: ='Balance Sheet'!F19/'Income Statement'!F12 -> 1.4827958 | G7: ='Balance Sheet'!G19/'Income Statement'!G12 -> 1.9255926 | H7: ='Balance Sheet'!H19/'Income Statement'!H12 -> 2.3572892 | I7: ='Balance Sheet'!I19/'Income Statement'!I12 -> 2.7988861
A8: Return on equity | B8: ='Income Statement'!B22/'Balance Sheet'!B11 -> 0.24339623 | C8: ='Income Statement'!C22/'Balance Sheet'!C11 -> 0.26586826 | D8: ='Income Statement'!D22/'Balance Sheet'!D11 -> 0.27885463 | E8: ='Income Statement'!E22/'Balance Sheet'!E11 -> 0.27640206 | F8: ='Income Statement'!F22/'Balance Sheet'!F11 -> 0.26226923 | G8: ='Income Statement'!G22/'Balance Sheet'!G11 -> 0.24348448 | H8: ='Income Statement'!H22/'Balance Sheet'!H11 -> 0.22411857 | I8: ='Income Statement'!I22/'Balance Sheet'!I11 -> 0.2054905
A9: Revenue YoY | C9: ='Income Statement'!C8/'Income Statement'!B8-1 -> 0.33028601 | D9: ='Income Statement'!D8/'Income Statement'!C8-1 -> 0.30016893 | E9: ='Income Statement'!E8/'Income Statement'!D8-1 -> 0.32196956 | F9: ='Income Statement'!F8/'Income Statement'!E8-1 -> 0.26291314 | G9: ='Income Statement'!G8/'Income Statement'!F8-1 -> 0.21254138 | H9: ='Income Statement'!H8/'Income Statement'!G8-1 -> 0.17002995 | I9: ='Income Statement'!I8/'Income Statement'!H8-1 -> 0.13462327

Sheet Peer & Sector
A1: Peer set & sector
A2: Egyptian fintech / payments infrastructure; no single clean comparable.
A3: Peer / part | B3: Closest peers | C3: Typical valuation
A4: Payment rails / processing | B4: Fawry (EGX), Network Intl, Geidea | C4: EV/EBITDA ~10–18x; growth-linked
A5: Gov cloud / IT services | B5: regional cloud/IT names | C5: EV/Rev ~3–7x; scarcity premium
A6: Card & embedded finance | B6: Marqeta, Paymob, MNT-Halan | C6: early-stage / strategic marks
A8: Analyst 12-month targets (context, not model inputs): range ≈ EGP 18.2–21.9 (mean ≈ 20.2). Sources: sell-side compilations, mid-2026.
