Workbook

Sheet READ FIRST
A1: READ FIRST — DISCLOSURE & DISCLAIMER (educational valuation study; not investment advice)
A2: NATURE OF THIS WORKBOOK
A3: This workbook is an educational valuation exercise and an expression of the preparer's personal analytical opinion, based exclusively on publicly available information and the assumptions stated in the text and this model. It is published free of charge to demonstrate methodology and to invite scrutiny of that methodology.
A5: NO ADVICE, NO RECOMMENDATION, NO SOLICITATION
A6: Nothing here constitutes investment advice, financial consultancy, securities analysis, a research recommendation, a rating, a price target, an offer, or a solicitation to buy, sell or hold any security. No statement is directed at the objectives, situation or needs of any person.
A8: NO LICENSED ACTIVITY
A9: The preparer is not licensed or registered with any securities regulator, carries on no regulated activity, manages no money, and accepts no clients, fees or funds.
A11: ESTIMATES AND UNCERTAINTY
A12: All values are model outputs resting on explicit, subjective assumptions; they are illustrative, highly uncertain and likely to prove wrong in material respects. Emaar's reported financials are company disclosure; the FORWARD assumptions — the value of the recurring mall/hospitality portfolio, the marks on the listed subsidiary stakes (Emaar Development, Emaar Misr), the NAV/conglomerate discount, and the multiples applied — are the preparer's judgments. Presented as ranges and distributions because no single number should be relied on.
A14: NO LIABILITY / READER'S RESPONSIBILITY
A15: To the maximum extent permitted by law, the preparer accepts no liability for any decision, action or loss in reliance on this workbook. Any person considering an investment decision should conduct their own assessment and consult a licensed advisor.
A17: HOLDINGS DISCLOSURE
... A21: Blue cells are hardcoded inputs (edit to your own view); black cells are formulas; green cells link across sheets. The valuation is a revalued-net-asset / sum-of-the-parts (RNAV/SOTP): the listed subsidiary stakes at market value (Emaar Development, Emaar Misr), the recurring mall/hospitality/leasing portfolio on an EV/EBITDA multiple, international development at NAV, plus parent & recurring net cash, less a NAV/conglomerate discount — cross-checked against a going-concern FCFF DCF, relative multiples and normalized earnings. Currency is AED unless stated; valuation in AED billion, per-share in AED.

Sheet Summary
A1: EMAAR PROPERTIES PJSC (DFM: EMAAR) — VALUATION SUMMARY
A2: Four-lens fair value vs spot. Base links live; bear/bull are scenario outputs (study §1.5). Educational; not advice.
B3: Bear | C3: Base | D3: Bull | E3: Weight
A4: Sum-of-the-parts (RNAV) | B4: ='RNAV & SOTP'!D13 -> 10.498634 | C4: ='RNAV & SOTP'!B13 -> 14.116086 | D4: ='RNAV & SOTP'!C13 -> 17.265212 | E4: =Assumptions!$B$35 -> 0.35
A5: Consolidated DCF | B5: =Assumptions!B68 -> 11 | C5: =DCF!B20 -> 14.738939 | D5: =Assumptions!C68 -> 19.5 | E5: =Assumptions!$B$36 -> 0.2
A6: Relative multiples | B6: =Assumptions!B69 -> 12.7 | C6: ='Relative & Normalized'!B12 -> 15.529231 | D6: =Assumptions!C69 -> 18.3 | E6: =Assumptions!$B$37 -> 0.15
A7: Normalized earnings | B7: =Assumptions!B70 -> 11.03 | C7: ='Relative & Normalized'!B17 -> 15.271493 | D7: =Assumptions!C70 -> 20.19 | E7: =Assumptions!$B$38 -> 0.3
A8: Weighted central | B8: =SUMPRODUCT(B4:B7,E4:E7) -> 11.088522 | C8: =SUMPRODUCT(C4:C7,E4:E7) -> 14.79925 | D8: =SUMPRODUCT(D4:D7,E4:E7) -> 18.744824
A10: Spot price (AED, 29-Jun-26) | C10: =Assumptions!$B$5 -> 12.14
A11: Upside to central base | C11: =C8/C10-1 -> 0.21904864
A13: Read: undervalued across every lens; the swing factors are the recurring EV/EBITDA mark and the NAV/conglomerate discount.

Sheet Fundamental Valuation
A1: FUNDAMENTAL VALUATION — football-field data
A2: Bear/base/bull per lens (links to Summary). Weighted central computed there.
A3: Lens | B3: Bear | C3: Base | D3: Bull
A4: Sum-of-the-parts (RNAV) | B4: =Summary!B4 -> 10.498634 | C4: =Summary!C4 -> 14.116086 | D4: =Summary!D4 -> 17.265212
A5: Consolidated DCF | B5: =Summary!B5 -> 11 | C5: =Summary!C5 -> 14.738939 | D5: =Summary!D5 -> 19.5
A6: Relative multiples | B6: =Summary!B6 -> 12.7 | C6: =Summary!C6 -> 15.529231 | D6: =Summary!D6 -> 18.3
A7: Normalized earnings | B7: =Summary!B7 -> 11.03 | C7: =Summary!C7 -> 15.271493 | D7: =Summary!D7 -> 20.19
A8: Weighted central | B8: =Summary!B8 -> 11.088522 | C8: =Summary!C8 -> 14.79925 | D8: =Summary!D8 -> 18.744824
A9: Spot | C9: =Assumptions!$B$5 -> 12.14

Sheet Assumptions
A1: EMAAR PROPERTIES PJSC (DFM: EMAAR) — ASSUMPTIONS
A2: All blue cells are inputs. AED billion unless noted. Edit to your own view.
A4: GLOBAL & CORPORATE
A5: Spot price (AED, 29-Jun-26 close) | B5: 12.14
A6: Shares outstanding (bn) | B6: 8.84
A7: Consolidated net cash (AED bn) | B7: 25
A8: Tax rate (UAE corporate, effective) | B8: 0.09
A10: RNAV/SOTP — LISTED STAKES (at market)
A11: Stake | B11: Ownership % | C11: Sub mkt cap (bn) | D11: Stake value (bn) | E11: Basis
A12: Emaar Development PJSC (DFM: EMAARDEV) | B12: 0.854 | C12: 55.3 | D12: =B12*C12 -> 47.2262 | E12: listed at market
A13: Emaar Misr for Development (EGX: EMFD) | B13: 0.857 | C13: 4.15 | D13: =B13*C13 -> 3.55655 | E13: listed at market (EGP→AED)
A14: Listed subtotal | D14: =SUM(D12:D13) -> 50.78275
A16: RNAV/SOTP — RECURRING, INTERNATIONAL, NET CASH & DISCOUNT
A17: Item | B17: Base | C17: Bull | D17: Bear | E17: Basis
A18: Recurring EBITDA (malls+hospitality+leasing, AED bn) | B18: 5.8
A19: Recurring EV/EBITDA multiple (x) | B19: 14 | C19: 16 | D19: 11 | E19: the swing factor
A20: International development NAV (India+other, AED bn) | B20: 6 | C20: 8 | D20: 4
A21: Parent & recurring net cash (AED bn) | B21: 18 | C21: 18 | D21: 14
A22: NAV / conglomerate discount | B22: 0.2 | C22: 0.1 | D22: 0.3
A24: RELATIVE & NORMALIZED
A25: EBITDA 2025 (AED bn) | B25: 25.6
A26: EV/EBITDA multiple (x) | B26: 5
A27: Normalized EPS (AED) | B27: 1.85
A28: Relative P/E (x) | B28: 8
A29: BVPS — attributable (AED) | B29: 9.05
A30: Justified P/B (x) | B30: 1.6
A31: Normalized through-cycle net (AED bn) | B31: 15
A32: Normalized justified P/E (x) | B32: 9
A34: FOUR-METHOD WEIGHTS
A35: RNAV/SOTP | B35: 0.35
A36: Going-concern DCF | B36: 0.2
A37: Relative multiples | B37: 0.15
A38: Normalized earnings | B38: 0.3
A41: DCF INPUTS
A42: WACC (AED) | B42: 0.12
A43: Terminal growth g | B43: 0.025
A44: Tax rate (DCF) | B44: 0.09
A46: DCF FCFF PROFILE (AED bn) — fade, land-replenishment discipline
A47: Year | B47: FCFF
A48: 2026 | B48: 14
...

Sheet RNAV & SOTP
A1: RNAV / SUM-OF-THE-PARTS — revalued net asset value (base / bull / bear)
A2: Listed subsidiary stakes at market; recurring portfolio on EV/EBITDA; international at NAV; net cash added; NAV/conglomerate discount applied. AED bn; per-share AED.
A4: Asset | B4: Base (bn) | C4: Bull (bn) | D4: Bear (bn) | E4: Basis
A5: Emaar Development stake (85.4%) | B5: =Assumptions!D12 -> 47.2262 | C5: =Assumptions!D12 -> 47.2262 | D5: =Assumptions!D12 -> 47.2262 | E5: listed at market
A6: Emaar Misr stake (85.7%) | B6: =Assumptions!D13 -> 3.55655 | C6: =Assumptions!D13 -> 3.55655 | D6: =Assumptions!D13 -> 3.55655 | E6: listed at market (EGP→AED)
A7: Recurring portfolio (malls+hotels+leasing) | B7: =Assumptions!B18*Assumptions!B19 -> 81.2 | C7: =Assumptions!B18*Assumptions!C19 -> 92.8 | D7: =Assumptions!B18*Assumptions!D19 -> 63.8 | E7: EV/EBITDA on recurring EBITDA
A8: International development (India+other) | B8: =Assumptions!B20 -> 6 | C8: =Assumptions!C20 -> 8 | D8: =Assumptions!D20 -> 4 | E8: NAV estimate
A9: Parent & recurring net cash | B9: =Assumptions!B21 -> 18 | C9: =Assumptions!C21 -> 18 | D9: =Assumptions!D21 -> 14 | E9: group net cash net of listed-sub cash
A10: Gross NAV (AED bn) | B10: =SUM(B5:B9) -> 155.98275 | C10: =SUM(C5:C9) -> 169.58275 | D10: =SUM(D5:D9) -> 132.58275
A11: Gross NAV / share (AED) | B11: =B10/Assumptions!$B$6 -> 17.645107 | C11: =C10/Assumptions!$B$6 -> 19.183569 | D11: =D10/Assumptions!$B$6 -> 14.998049
A12: (-) NAV / conglomerate discount | B12: =Assumptions!B22 -> 0.2 | C12: =Assumptions!C22 -> 0.1 | D12: =Assumptions!D22 -> 0.3
A13: VALUE / SHARE (AED) | B13: =B11*(1-B12) -> 14.116086 | C13: =C11*(1-C12) -> 17.265212 | D13: =D11*(1-D12) -> 10.498634
A14: vs spot | B14: =B13/Assumptions!$B$5-1 -> 0.16277479 | C14: =C13/Assumptions!$B$5-1 -> 0.42217563 | D14: =D13/Assumptions!$B$5-1 -> -0.13520313
A16: Base = 20% discount on the sum of parts. Bull = 10% discount + recurring at 16x + higher international NAV. Bear = 30% discount + recurring at 11x + lower marks. Gross NAV ~AED 17.6/share; the market prices a ~31% discount to that sum at spot. Listed stakes are held constant across scenarios; the recurring multiple and the discount drive the range.

Sheet Segments
A1: HOLDING-COMPANY & SEGMENT ASSETS — what Emaar owns
A2: How each piece is valued. Source: Emaar IR / DFM segment disclosures (FY2025).
A4: Dimension | B4: Listed subsidiary stakes | C4: Recurring portfolio (owned) | D4: Development (UAE, via ED)
A5: What it is | B5: Emaar Development ~85.4% (DFM), Emaar Misr ~85.7% (EGX) | C5: Dubai Mall + malls, Address/Vida hotels, leisure & entertainment | D5: Master-planned communities: Downtown, Dubai Hills, Beachfront, Creek Harbour
A6: Valuation basis | B6: Market value × ownership | C6: EV/EBITDA on recurring EBITDA | D6: Captured in the Emaar Development market stake
A7: Earnings driver | B7: Sub share prices; ED off-plan sales; EMFD Egypt cycle | C7: Mall footfall & rents (98% occ); hotel RevPAR; tourism | D7: Contracted sales; % completion recognition; land re-load
A8: Cyclicality | B8: Market-linked; EMFD carries Egypt FX/rate risk | C8: Moderate — Dubai retail & tourism cycle | D8: Off-plan demand; supply pipeline; mortgage rates
A9: Profitability | B9: ED ~56% NPBT margin; EMFD profitable | C9: Malls ~70% EBITDA margin; hotels ~30% | D9: Backlog AED 155bn at healthy margins
A10: Valuation lens | B10: at market (no normalization) | C10: ~14x EV/EBITDA (prime Dubai retail) | D10: market stake (ED ~5x P/E)
A12: The crown jewel is the recurring portfolio — Dubai Mall is the world's most-visited mall — carried outside the listed stakes and marked here on a multiple. Most of the debate is (i) the recurring multiple and (ii) the NAV/conglomerate discount. The development engine sits inside the listed Emaar Development stake, taken at market. Sources: Emaar IR, DFM (FY2025); verify live.

Sheet Relative & Normalized
A1: RELATIVE MULTIPLES & NORMALIZED EARNINGS POWER
A2: Multiples on group metrics vs Aldar/sector; through-cycle earnings as a discipline. Cross-checks on the RNAV.
A4: RELATIVE MULTIPLES (AED bn unless noted)
A5: Implied EV — EV/EBITDA | B5: =Assumptions!B25*Assumptions!B26 -> 128 | E5: EBITDA x EV/EBITDA
A6: value/share (AED) | B6: =(B5+Assumptions!B7)/Assumptions!$B$6 -> 17.307692
A7: Implied equity — P/E (norm EPS x P/E) | B7: =Assumptions!B27*Assumptions!B28 -> 14.8 | E7: normalized EPS x P/E
A8: Implied equity — P/B (BVPS x P/B) | B8: =Assumptions!B29*Assumptions!B30 -> 14.48 | E8: BVPS x justified P/B
A9: RELATIVE BLENDED MIDPOINT (AED) | B9: =AVERAGE(B6,B7,B8) -> 15.529231
A11: RELATIVE VALUE / SHARE (blended, AED)
B12: =B9 -> 15.529231
A14: NORMALIZED THROUGH-CYCLE EARNINGS POWER
A15: Normalized net profit (AED bn) | B15: =Assumptions!B31 -> 15
A16: Justified P/E (x) | B16: =Assumptions!B32 -> 9
A17: NORMALIZED VALUE / SHARE (AED) | B17: =B15*B16/Assumptions!$B$6 -> 15.271493
A18: Normalized P/E at spot (x) | B18: =Assumptions!B5/(B15/Assumptions!B6) -> 7.1545067 | E18: on through-cycle EPS
A20: Relative blends EV/EBITDA (5x, conservative vs Emaar's own ~3.2x and peers ~6-8x), P/E (8x normalized) and P/B (1.6x justified by ~24.7% ROE). Emaar screens cheap on every relative gauge. Normalized uses through-cycle net ~AED 15bn at 9x. Sources: Emaar IR; peer multiples (Aldar) — verify live.

Sheet DCF
A1: GOING-CONCERN DCF — unlevered FCFF (cross-check)
A2: FCFF fades as backlog runs off and land is replenished; recurring is the durable annuity. Discounted at WACC; modest terminal. AED bn.
A4: AED bn | B4: 2026 | C4: 2027 | D4: 2028 | E4: 2029 | F4: 2030
A5: Unlevered FCFF (input profile) | B5: =Assumptions!B48 -> 14 | C5: =Assumptions!B49 -> 13 | D5: =Assumptions!B50 -> 12 | E5: =Assumptions!B51 -> 11 | F5: =Assumptions!B52 -> 10
A6: Discount factor @ WACC | B6: =1/(1+Assumptions!$B$42)^1 -> 0.89285714 | C6: =1/(1+Assumptions!$B$42)^2 -> 0.79719388 | D6: =1/(1+Assumptions!$B$42)^3 -> 0.71178025 | E6: =1/(1+Assumptions!$B$42)^4 -> 0.63551808 | F6: =1/(1+Assumptions!$B$42)^5 -> 0.56742686
A7: PV of FCFF | B7: =B5*B6 -> 12.5 | C7: =C5*C6 -> 10.36352 | D7: =D5*D6 -> 8.541363 | E7: =E5*E6 -> 6.9906989 | F7: =F5*F6 -> 5.6742686
A9: PV of explicit FCFF (Σ) | B9: =SUM(B7:F7) -> 44.069851
A10: Terminal value (Gordon on 2030 FCFF) | B10: =F5*(1+Assumptions!B43)/(Assumptions!B42-Assumptions!B43) -> 107.89474
A11: PV of terminal value | B11: =B10/(1+Assumptions!B42)^5 -> 61.222371
A12: Enterprise value (operating) | B12: =B9+B11 -> 105.29222
A13: (+) Consolidated net cash | B13: =Assumptions!B7 -> 25
A14: Equity value (AED bn) | B14: =B12+B13 -> 130.29222
A16: Shares (bn) | B16: =Assumptions!B6 -> 8.84
A18: VALUE / SHARE (AED)
B20: =B14/B16 -> 14.738939
A21: vs spot | B21: =B20/Assumptions!B5-1 -> 0.21408065
A23: The DCF deliberately capitalizes a FADING cash-flow stream, not the 2025 peak: development excess cash is assumed to decline toward a sustainable level as backlog converts and land must be re-purchased at market cost, with the recurring portfolio as the durable annuity and a modest 2.5% terminal. It answers a narrow question — what is a conservative capitalization of Emaar's cash worth — and lands close to the RNAV base, corroborating it. A cross-check, not the primary lens.

Sheet Income Statement
A1: CONSOLIDATED INCOME STATEMENT — AED bn
A2: Actuals Emaar IR (FY2023-2025). Forecast 2026e-2030e: revenue, OP and net link to Assumptions.
A4: AED bn | B4: 2023a | C4: 2024a | D4: 2025a | E4: 2026e | F4: 2027e | G4: 2028e | H4: 2029e | I4: 2030e
A5: Development revenue | B5: 18.5 | C5: 27 | D5: 39 | E5: =Assumptions!B56-E6 -> 36 | F5: =Assumptions!B57-F6 -> 37.5 | G5: =Assumptions!B58-G6 -> 39 | H5: =Assumptions!B59-H6 -> 40.5 | I5: =Assumptions!B60-I6 -> 42
A6: Recurring revenue | B6: 8.2 | C6: 8.5 | D6: 10.5 | E6: 11 | F6: 11.5 | G6: 12 | H6: 12.5 | I6: 13
A7: Total revenue | B7: =B5+B6 -> 26.7 | C7: =C5+C6 -> 35.5 | D7: =D5+D6 -> 49.5 | E7: =Assumptions!B56 -> 47 | F7: =Assumptions!B57 -> 49 | G7: =Assumptions!B58 -> 51 | H7: =Assumptions!B59 -> 53 | I7: =Assumptions!B60 -> 55
A8: growth YoY | C8: =C7/B7-1 -> 0.32958801 | D8: =D7/C7-1 -> 0.3943662 | E8: =E7/D7-1 -> -0.050505051 | F8: =F7/E7-1 -> 0.042553191 | G8: =G7/F7-1 -> 0.040816327 | H8: =H7/G7-1 -> 0.039215686 | I8: =I7/H7-1 -> 0.037735849
A9: (Operating expenses) | B9: =-(B7-B10) -> -15.2 | C9: =-(C7-C10) -> -18 | D9: =-(D7-D10) -> -25.5 | E9: =-(E7-E10) -> -24.5 | F9: =-(F7-F10) -> -25.5 | G9: =-(G7-G10) -> -26.5 | H9: =-(H7-H10) -> -27.5 | I9: =-(I7-I10) -> -28.5
A10: Operating profit (EBIT) | B10: 11.5 | C10: 17.5 | D10: 24 | E10: =Assumptions!C56 -> 22.5 | F10: =Assumptions!C57 -> 23.5 | G10: =Assumptions!C58 -> 24.5 | H10: =Assumptions!C59 -> 25.5 | I10: =Assumptions!C60 -> 26.5
A11: OP margin | B11: =B10/B7 -> 0.43071161 | C11: =C10/C7 -> 0.49295775 | D11: =D10/D7 -> 0.48484848 | E11: =E10/E7 -> 0.4787234 | F11: =F10/F7 -> 0.47959184 | G11: =G10/G7 -> 0.48039216 | H11: =H10/H7 -> 0.48113208 | I11: =I10/I7 -> 0.48181818
A12: Net finance income & associates | B12: 1 | C12: 1.2 | D12: 1.7 | E12: 1.3 | F12: 1.4 | G12: 1.5 | H12: 1.6 | I12: 1.7
A13: Pre-tax profit | B13: =B10+B12 -> 12.5 | C13: =C10+C12 -> 18.7 | D13: =D10+D12 -> 25.7 | E13: =E10+E12 -> 23.8 | F13: =F10+F12 -> 24.9 | G13: =G10+G12 -> 26 | H13: =H10+H12 -> 27.1 | I13: =I10+I12 -> 28.2
A14: Tax & minority interests | B14: =B15-B13 -> -1.5 | C14: =C15-C13 -> -5 | D14: =D15-D13 -> -6.8 | E14: =E15-E13 -> -8 | F14: =F15-F13 -> -8.4 | G14: =G15-G13 -> -8.7 | H14: =H15-H13 -> -9.1 | I14: =I15-I13 -> -9.4
A15: Net profit attributable | B15: 11 | C15: 13.7 | D15: 18.9 | E15: =Assumptions!D56 -> 15.8 | F15: =Assumptions!D57 -> 16.5 | G15: =Assumptions!D58 -> 17.3 | H15: =Assumptions!D59 -> 18 | I15: =Assumptions!D60 -> 18.8
A16: net margin | B16: =B15/B7 -> 0.41198502 | C16: =C15/C7 -> 0.38591549 | D16: =D15/D7 -> 0.38181818 | E16: =E15/E7 -> 0.33617021 | F16: =F15/F7 -> 0.33673469 | G16: =G15/G7 -> 0.33921569 | H16: =H15/H7 -> 0.33962264 | I16: =I15/I7 -> 0.34181818
A17: EPS (AED) | B17: =B15/Assumptions!$B$6 -> 1.2443439 | C17: =C15/Assumptions!$B$6 -> 1.5497738 | D17: =D15/Assumptions!$B$6 -> 2.138009 | E17: =E15/Assumptions!$B$6 -> 1.7873303 | F17: =F15/Assumptions!$B$6 -> 1.8665158 | G17: =G15/Assumptions!$B$6 -> 1.9570136 | H17: =H15/Assumptions!$B$6 -> 2.0361991 | I17: =I15/Assumptions!$B$6 -> 2.1266968
A19: Development (UAE build-to-sell via Emaar Development + Creek Harbour + international) dominates revenue; the recurring portfolio (malls, hotels, leasing) is smaller but higher-margin and more durable. FY2025 was a record on strong recognition off a AED 155bn backlog; 2026e is set modestly below 2025 on normalization (consensus ~11% net decline). UAE 9% corporate tax applies from 2023; minority interests reflect the ~15% of Emaar Development and ~14% of Emaar Misr held by others. Actuals anchored to Emaar IR; sub-lines approximate.

Sheet Balance Sheet
A1: CONSOLIDATED BALANCE SHEET — AED bn
A2: Totals anchored to reported filings (end-2025: assets ~185, equity ~95, cash ~35, debt ~10); sub-lines approximate.
A4: AED bn | B4: 2023a | C4: 2024a | D4: 2025a | E4: 2026e | F4: 2027e | G4: 2028e | H4: 2029e | I4: 2030e
A5: Cash & bank balances | B5: 28 | C5: 32 | D5: 35 | E5: 37 | F5: 39 | G5: 41 | H5: 43 | I5: 46
A6: Trade & other receivables | B6: 10 | C6: 11 | D6: 12 | E6: 13 | F6: 14 | G6: 15 | H6: 16 | I6: 17
A7: Development properties (inventory/WIP) | B7: 42 | C7: 45 | D7: 48 | E7: 50 | F7: 52 | G7: 54 | H7: 56 | I7: 58
A8: Total current assets | B8: =SUM(B5:B7) -> 80 | C8: =SUM(C5:C7) -> 88 | D8: =SUM(D5:D7) -> 95 | E8: =SUM(E5:E7) -> 100 | F8: =SUM(F5:F7) -> 105 | G8: =SUM(G5:G7) -> 110 | H8: =SUM(H5:H7) -> 115 | I8: =SUM(I5:I7) -> 121
A9: Investment properties (malls/hotels) | B9: 58 | C9: 62 | D9: 66 | E9: 68 | F9: 70 | G9: 72 | H9: 74 | I9: 76
A10: Property, plant & equipment | B10: 8 | C10: 8.5 | D10: 9 | E10: 9.5 | F10: 10 | G10: 10.5 | H10: 11 | I10: 11.5
A11: Investments in associates & JVs | B11: 7 | C11: 7.5 | D11: 8 | E11: 8.3 | F11: 8.6 | G11: 8.9 | H11: 9.2 | I11: 9.5
A12: Other non-current assets | B12: 8 | C12: 8 | D12: 9 | E12: 9 | F12: 9 | G12: 9 | H12: 9 | I12: 9
A13: Total non-current assets | B13: =SUM(B9:B12) -> 81 | C13: =SUM(C9:C12) -> 86 | D13: =SUM(D9:D12) -> 92 | E13: =SUM(E9:E12) -> 94.8 | F13: =SUM(F9:F12) -> 97.6 | G13: =SUM(G9:G12) -> 100.4 | H13: =SUM(H9:H12) -> 103.2 | I13: =SUM(I9:I12) -> 106
A14: Total assets | B14: =B8+B13 -> 161 | C14: =C8+C13 -> 174 | D14: =D8+D13 -> 187 | E14: =E8+E13 -> 194.8 | F14: =F8+F13 -> 202.6 | G14: =G8+G13 -> 210.4 | H14: =H8+H13 -> 218.2 | I14: =I8+I13 -> 227
A15: Trade & other payables | B15: 16 | C15: 17 | D15: 18 | E15: 19 | F15: 20 | G15: 21 | H15: 22 | I15: 23
A16: Advances from customers (deferred rev) | B16: 30 | C16: 34 | D16: 38 | E16: 40 | F16: 42 | G16: 44 | H16: 46 | I16: 48
A17: Total current liabilities | B17: =SUM(B15:B16) -> 46 | C17: =SUM(C15:C16) -> 51 | D17: =SUM(D15:D16) -> 56 | E17: =SUM(E15:E16) -> 59 | F17: =SUM(F15:F16) -> 62 | G17: =SUM(G15:G16) -> 65 | H17: =SUM(H15:H16) -> 68 | I17: =SUM(I15:I16) -> 71
A18: Borrowings, bonds & leases | B18: 11 | C18: 11 | D18: 10 | E18: 10 | F18: 10 | G18: 10 | H18: 10 | I18: 10
A19: Other non-current liabilities | B19: 4 | C19: 4 | D19: 4 | E19: 4 | F19: 4 | G19: 4 | H19: 4 | I19: 4
A20: Total liabilities | B20: =B17+B18+B19 -> 61 | C20: =C17+C18+C19 -> 66 | D20: =D17+D18+D19 -> 70 | E20: =E17+E18+E19 -> 73 | F20: =F17+F18+F19 -> 76 | G20: =G17+G18+G19 -> 79 | H20: =H17+H18+H19 -> 82 | I20: =I17+I18+I19 -> 85
A21: Equity attributable to owners | B21: 62 | C21: 70 | D21: 80 | E21: 86 | F21: 92 | G21: 98 | H21: 104 | I21: 110
A22: Non-controlling interests | B22: 12 | C22: 13 | D22: 15 | E22: 16 | F22: 17 | G22: 18 | H22: 19 | I22: 20
A23: Total equity | B23: =SUM(B21:B22) -> 74 | C23: =SUM(C21:C22) -> 83 | D23: =SUM(D21:D22) -> 95 | E23: =SUM(E21:E22) -> 102 | F23: =SUM(F21:F22) -> 109 | G23: =SUM(G21:G22) -> 116 | H23: =SUM(H21:H22) -> 123 | I23: =SUM(I21:I22) -> 130
A24: Total liabilities & equity | B24: =B20+B23 -> 135 | C24: =C20+C23 -> 149 | D24: =D20+D23 -> 165 | E24: =E20+E23 -> 175 | F24: =F20+F23 -> 185 | G24: =G20+G23 -> 195 | H24: =H20+H23 -> 205 | I24: =I20+I23 -> 215
A25: BVPS — attributable (AED) | B25: =B21/Assumptions!$B$6 -> 7.0135747 | C25: =C21/Assumptions!$B$6 -> 7.918552 | D25: =D21/Assumptions!$B$6 -> 9.0497738 | E25: =E21/Assumptions!$B$6 -> 9.7285068 | F25: =F21/Assumptions!$B$6 -> 10.40724 | G25: =G21/Assumptions!$B$6 -> 11.085973 | H25: =H21/Assumptions!$B$6 -> 11.764706 | I25: =I21/Assumptions!$B$6 -> 12.443439
A26: Net cash (cash − debt) | B26: =B5-B18 -> 17 | C26: =C5-C18 -> 21 | D26: =D5-D18 -> 25 | E26: =E5-E18 -> 27 | F26: =F5-F18 -> 29 | G26: =G5-G18 -> 31 | H26: =H5-H18 -> 33 | I26: =I5-I18 -> 36
A28: Totals anchored to Emaar's reported balance sheet; sub-lines are approximate allocations. Investment properties (the recurring malls/hotels) are carried at cost/valuation on the books (~AED 66bn) BELOW their market value — the RNAV lens marks them to ~AED 81bn via EV/EBITDA, which is the source of the NAV uplift. Equity attributable ~AED 80bn = book ~AED 9.05/share (P/B ~1.34x). Large customer advances reflect off-plan pre-sales. Net cash ~AED 25bn.

Sheet Cash Flow
A1: CONSOLIDATED CASH FLOW — AED bn (simplified)
A2: Actuals approximate. Forecast: OCF ≈ net + non-cash; investing = capex; financing = dividends.
A4: AED bn | B4: 2023a | C4: 2024a | D4: 2025a | E4: 2026e | F4: 2027e | G4: 2028e | H4: 2029e | I4: 2030e
A5: Operating cash flow | B5: 14 | C5: 17 | D5: 20 | E5: 18 | F5: 19 | G5: 20 | H5: 21 | I5: 22
A6: Capex (investing) | B6: -2 | C6: -2.2 | D6: -2.5 | E6: -2.5 | F6: -2.6 | G6: -2.7 | H6: -2.8 | I6: -2.9
A7: Financing (dividends/other) | B7: -6.5 | C7: -7.5 | D7: -8.8 | E7: -9 | F7: -9.2 | G7: -9.5 | H7: -9.8 | I7: -10.1
A8: Net change in cash | B8: =SUM(B5:B7) -> 5.5 | C8: =SUM(C5:C7) -> 7.3 | D8: =SUM(D5:D7) -> 8.7 | E8: =SUM(E5:E7) -> 6.5 | F8: =SUM(F5:F7) -> 7.2 | G8: =SUM(G5:G7) -> 7.8 | H8: =SUM(H5:H7) -> 8.4 | I8: =SUM(I5:I7) -> 9
A9: Memo — free cash flow (OCF + capex) | B9: =B5+B6 -> 12 | C9: =C5+C6 -> 14.8 | D9: =D5+D6 -> 17.5 | E9: =E5+E6 -> 15.5 | F9: =F5+F6 -> 16.4 | G9: =G5+G6 -> 17.3 | H9: =H5+H6 -> 18.2 | I9: =I5+I6 -> 19.1
A11: Emaar generates very strong operating cash flow and reinvests modestly (asset-light off-plan model with escrowed pre-sales), so free cash flow is high — funding a ~100%-of-share-capital dividend (AED 8.8bn, ~AED 1.0/share, ~8% yield). Financing reflects that dividend; any buyback/treasury-cancellation would be an incremental catalyst. Simplified and illustrative.

Sheet Summary Financials
A1: EMAAR PROPERTIES — SUMMARY FINANCIALS (live links)
A2: Every cell links to the Income Statement / Balance Sheet / Cash Flow sheets.
A4: AED bn | B4: 2023a | C4: 2024a | D4: 2025a | E4: 2026e | F4: 2027e | G4: 2028e | H4: 2029e | I4: 2030e
A5: Revenue | B5: ='Income Statement'!B7 -> 26.7 | C5: ='Income Statement'!C7 -> 35.5 | D5: ='Income Statement'!D7 -> 49.5 | E5: ='Income Statement'!E7 -> 47 | F5: ='Income Statement'!F7 -> 49 | G5: ='Income Statement'!G7 -> 51 | H5: ='Income Statement'!H7 -> 53 | I5: ='Income Statement'!I7 -> 55
A6: Operating profit | B6: ='Income Statement'!B10 -> 11.5 | C6: ='Income Statement'!C10 -> 17.5 | D6: ='Income Statement'!D10 -> 24 | E6: ='Income Statement'!E10 -> 22.5 | F6: ='Income Statement'!F10 -> 23.5 | G6: ='Income Statement'!G10 -> 24.5 | H6: ='Income Statement'!H10 -> 25.5 | I6: ='Income Statement'!I10 -> 26.5
A7: Net profit attrib. | B7: ='Income Statement'!B15 -> 11 | C7: ='Income Statement'!C15 -> 13.7 | D7: ='Income Statement'!D15 -> 18.9 | E7: ='Income Statement'!E15 -> 15.8 | F7: ='Income Statement'!F15 -> 16.5 | G7: ='Income Statement'!G15 -> 17.3 | H7: ='Income Statement'!H15 -> 18 | I7: ='Income Statement'!I15 -> 18.8
A8: EPS (AED) | B8: ='Income Statement'!B17 -> 1.2443439 | C8: ='Income Statement'!C17 -> 1.5497738 | D8: ='Income Statement'!D17 -> 2.138009 | E8: ='Income Statement'!E17 -> 1.7873303 | F8: ='Income Statement'!F17 -> 1.8665158 | G8: ='Income Statement'!G17 -> 1.9570136 | H8: ='Income Statement'!H17 -> 2.0361991 | I8: ='Income Statement'!I17 -> 2.1266968
A9: Total assets | B9: ='Balance Sheet'!B15 -> 16 | C9: ='Balance Sheet'!C15 -> 17 | D9: ='Balance Sheet'!D15 -> 18 | E9: ='Balance Sheet'!E15 -> 19 | F9: ='Balance Sheet'!F15 -> 20 | G9: ='Balance Sheet'!G15 -> 21 | H9: ='Balance Sheet'!H15 -> 22 | I9: ='Balance Sheet'!I15 -> 23
A10: Total equity | B10: ='Balance Sheet'!B25 -> 7.0135747 | C10: ='Balance Sheet'!C25 -> 7.918552 | D10: ='Balance Sheet'!D25 -> 9.0497738 | E10: ='Balance Sheet'!E25 -> 9.7285068 | F10: ='Balance Sheet'!F25 -> 10.40724 | G10: ='Balance Sheet'!G25 -> 11.085973 | H10: ='Balance Sheet'!H25 -> 11.764706 | I10: ='Balance Sheet'!I25 -> 12.443439
A11: Net cash | B11: ='Balance Sheet'!B27 -> 0 | C11: ='Balance Sheet'!C27 -> 0 | D11: ='Balance Sheet'!D27 -> 0 | E11: ='Balance Sheet'!E27 -> 0 | F11: ='Balance Sheet'!F27 -> 0 | G11: ='Balance Sheet'!G27 -> 0 | H11: ='Balance Sheet'!H27 -> 0 | I11: ='Balance Sheet'!I27 -> 0
A12: BVPS (AED) | B12: ='Balance Sheet'!B26 -> 17 | C12: ='Balance Sheet'!C26 -> 21 | D12: ='Balance Sheet'!D26 -> 25 | E12: ='Balance Sheet'!E26 -> 27 | F12: ='Balance Sheet'!F26 -> 29 | G12: ='Balance Sheet'!G26 -> 31 | H12: ='Balance Sheet'!H26 -> 33 | I12: ='Balance Sheet'!I26 -> 36
A13: Operating cash flow | B13: ='Cash Flow'!B5 -> 14 | C13: ='Cash Flow'!C5 -> 17 | D13: ='Cash Flow'!D5 -> 20 | E13: ='Cash Flow'!E5 -> 18 | F13: ='Cash Flow'!F5 -> 19 | G13: ='Cash Flow'!G5 -> 20 | H13: ='Cash Flow'!H5 -> 21 | I13: ='Cash Flow'!I5 -> 22
A14: Free cash flow | B14: ='Cash Flow'!B9 -> 12 | C14: ='Cash Flow'!C9 -> 14.8 | D14: ='Cash Flow'!D9 -> 17.5 | E14: ='Cash Flow'!E9 -> 15.5 | F14: ='Cash Flow'!F9 -> 16.4 | G14: ='Cash Flow'!G9 -> 17.3 | H14: ='Cash Flow'!H9 -> 18.2 | I14: ='Cash Flow'!I9 -> 19.1

Sheet Monte Carlo
A1: MONTE CARLO — ONE 16-FACTOR MODEL (50,000 paths, seed 42)
A2: Seven continuous factors compound daily; nine discrete events arrive as jumps. Idiosyncratic diffusion at realized 3M vol.
A4: CORE INPUTS
A5: Anchor price (AED, 29-Jun-26) | B5: 12.14
A6: Horizon T+20 (sessions) | B6: 20
A7: Horizon T+60 (sessions) | B7: 63
A8: Idiosyncratic 3M volatility (top-up) | B8: 0.167
A9: 52-week low reference (AED) | B9: 10.15
A10: SMA50 / structure (AED) | B10: 12.01
A11: SMA200 (AED) | B11: 13.53
A12: 52-week high reference (AED) | B12: 17.25
A13: SMA100 (AED) | B13: 13.04 | C13: MACD(12,26,9) +0.17 line / +0.14 signal / +0.04 hist (momentum turning up)
A14: SEVEN CONTINUOUS FACTORS
A15: Factor | B15: 3M drift | C15: 3M vol | G15: Channel
A16: US/Fed rate path (AED peg → mortgage, discounting) | B16: -0.005 | C16: 0.04
A17: Dubai residential price & off-plan absorption | B17: 0.01 | C17: 0.05
A18: DFM / foreign-flows beta | B18: 0.005 | C18: 0.05
A19: Oil / GCC liquidity | B19: 0.003 | C19: 0.04
A20: Population & golden-visa demand | B20: 0.005 | C20: 0.03
A21: Recurring: retail & tourism trajectory | B21: 0.003 | C21: 0.03
A22: Construction cost / margin | B22: -0.004 | C22: 0.03
A24: NINE DISCRETE EVENTS
A25: Event | B25: Prob | C25: Impact μ | D25: Impact σ | G25: Channel
A26: Backlog conversion / strong launches & sales | B26: 0.5 | C26: 0.06 | D26: 0.04
A27: Dubai property-cycle re-rating / discount compression | B27: 0.3 | C27: 0.05 | D27: 0.03
A28: Emaar Development / recurring crystallization or special dividend | B28: 0.25 | C28: 0.04 | D28: 0.03
A29: Dubai Holding ownership-driven re-rating / buyback | B29: 0.25 | C29: 0.04 | D29: 0.03
A30: Quarterly earnings surprise (two-sided) | B30: 0.4 | C30: 0 | D30: 0.05
A31: Dubai property correction / oversupply fear | B31: 0.3 | C31: -0.06 | D31: 0.04
A32: Fed higher-for-longer / affordability shock | B32: 0.3 | C32: -0.05 | D32: 0.04
A33: Egypt macro/FX shock (Emaar Misr) | B33: 0.25 | C33: -0.04 | D33: 0.03
A34: Regional geopolitical / risk-off | B34: 0.25 | C34: -0.06 | D34: 0.04
A36: FACTOR MOMENTS (live)
A37: Expected 3M log-return μ | B37: =SUM(B16:B22)+SUMPRODUCT(B26:B34,C26:C34) -> 0.024
A38: 3M variance | B38: =SUMPRODUCT(C16:C22,C16:C22)+SUMPRODUCT(B26:B34,D26:D34^2+(1-B26:B34)*C26:C34^2)+B8^2 -> 0.047175
A39: 3M volatility σ | B39: =SQRT(B38) -> 0.21719807
A40: Annualized vol (x2) | B40: =B39*2 -> 0.43439613
A42: PERCENTILES (AED/share)
A43: Horizon | B43: 5% | C43: 25% | D43: Median | E43: 75% | F43: 95% | G43: Source
A44: T+20 — engine (simulated) | B44: 9.979 | C44: 11.223 | D44: 12.181 | E44: 13.222 | F44: 14.856 | G44: 50k paths · seed 42
...

Sheet Sensitivity
A1: SENSITIVITY — value/share (AED)
A2: Top: RNAV NAV-discount x recurring EV/EBITDA multiple. Bottom: DCF WACC x terminal growth. Both computed live.
A4: RNAV: NAV discount (down) / recurring EV/EBITDA multiple x (right)
A5: disc / mult | B5: 11 | C5: 12 | D5: 14 | E5: 16 | F5: 18
A6: 0.3 | B6: =((Assumptions!$D$14+Assumptions!$B$18*B$5+Assumptions!$B$20+Assumptions!$B$21)/Assumptions!$B$6)*(1-$A6) -> 10.973747 | C6: =((Assumptions!$D$14+Assumptions!$B$18*C$5+Assumptions!$B$20+Assumptions!$B$21)/Assumptions!$B$6)*(1-$A6) -> 11.433023 | D6: =((Assumptions!$D$14+Assumptions!$B$18*D$5+Assumptions!$B$20+Assumptions!$B$21)/Assumptions!$B$6)*(1-$A6) -> 12.351575 | E6: =((Assumptions!$D$14+Assumptions!$B$18*E$5+Assumptions!$B$20+Assumptions!$B$21)/Assumptions!$B$6)*(1-$A6) -> 13.270127 | F6: =((Assumptions!$D$14+Assumptions!$B$18*F$5+Assumptions!$B$20+Assumptions!$B$21)/Assumptions!$B$6)*(1-$A6) -> 14.188679
A7: 0.25 | B7: =((Assumptions!$D$14+Assumptions!$B$18*B$5+Assumptions!$B$20+Assumptions!$B$21)/Assumptions!$B$6)*(1-$A7) -> 11.757586 | C7: =((Assumptions!$D$14+Assumptions!$B$18*C$5+Assumptions!$B$20+Assumptions!$B$21)/Assumptions!$B$6)*(1-$A7) -> 12.249668 | D7: =((Assumptions!$D$14+Assumptions!$B$18*D$5+Assumptions!$B$20+Assumptions!$B$21)/Assumptions!$B$6)*(1-$A7) -> 13.233831 | E7: =((Assumptions!$D$14+Assumptions!$B$18*E$5+Assumptions!$B$20+Assumptions!$B$21)/Assumptions!$B$6)*(1-$A7) -> 14.217993 | F7: =((Assumptions!$D$14+Assumptions!$B$18*F$5+Assumptions!$B$20+Assumptions!$B$21)/Assumptions!$B$6)*(1-$A7) -> 15.202156
A8: 0.2 | B8: =((Assumptions!$D$14+Assumptions!$B$18*B$5+Assumptions!$B$20+Assumptions!$B$21)/Assumptions!$B$6)*(1-$A8) -> 12.541425 | C8: =((Assumptions!$D$14+Assumptions!$B$18*C$5+Assumptions!$B$20+Assumptions!$B$21)/Assumptions!$B$6)*(1-$A8) -> 13.066312 | D8: =((Assumptions!$D$14+Assumptions!$B$18*D$5+Assumptions!$B$20+Assumptions!$B$21)/Assumptions!$B$6)*(1-$A8) -> 14.116086 | E8: =((Assumptions!$D$14+Assumptions!$B$18*E$5+Assumptions!$B$20+Assumptions!$B$21)/Assumptions!$B$6)*(1-$A8) -> 15.16586 | F8: =((Assumptions!$D$14+Assumptions!$B$18*F$5+Assumptions!$B$20+Assumptions!$B$21)/Assumptions!$B$6)*(1-$A8) -> 16.215633
A9: 0.15 | B9: =((Assumptions!$D$14+Assumptions!$B$18*B$5+Assumptions!$B$20+Assumptions!$B$21)/Assumptions!$B$6)*(1-$A9) -> 13.325264 | C9: =((Assumptions!$D$14+Assumptions!$B$18*C$5+Assumptions!$B$20+Assumptions!$B$21)/Assumptions!$B$6)*(1-$A9) -> 13.882957 | D9: =((Assumptions!$D$14+Assumptions!$B$18*D$5+Assumptions!$B$20+Assumptions!$B$21)/Assumptions!$B$6)*(1-$A9) -> 14.998341 | E9: =((Assumptions!$D$14+Assumptions!$B$18*E$5+Assumptions!$B$20+Assumptions!$B$21)/Assumptions!$B$6)*(1-$A9) -> 16.113726 | F9: =((Assumptions!$D$14+Assumptions!$B$18*F$5+Assumptions!$B$20+Assumptions!$B$21)/Assumptions!$B$6)*(1-$A9) -> 17.229111
A10: 0.1 | B10: =((Assumptions!$D$14+Assumptions!$B$18*B$5+Assumptions!$B$20+Assumptions!$B$21)/Assumptions!$B$6)*(1-$A10) -> 14.109104 | C10: =((Assumptions!$D$14+Assumptions!$B$18*C$5+Assumptions!$B$20+Assumptions!$B$21)/Assumptions!$B$6)*(1-$A10) -> 14.699601 | D10: =((Assumptions!$D$14+Assumptions!$B$18*D$5+Assumptions!$B$20+Assumptions!$B$21)/Assumptions!$B$6)*(1-$A10) -> 15.880597 | E10: =((Assumptions!$D$14+Assumptions!$B$18*E$5+Assumptions!$B$20+Assumptions!$B$21)/Assumptions!$B$6)*(1-$A10) -> 17.061592 | F10: =((Assumptions!$D$14+Assumptions!$B$18*F$5+Assumptions!$B$20+Assumptions!$B$21)/Assumptions!$B$6)*(1-$A10) -> 18.242588
A12: DCF: WACC (down) / terminal growth g (right)
A13: WACC / g | B13: 0.015 | C13: 0.02 | D13: 0.025 | E13: 0.03 | F13: 0.035
A14: 0.105 | B14: =(SUMPRODUCT(DCF!$B$5:$F$5,(1+$A14)^-{1,2,3,4,5})+DCF!$F$5*(1+B$13)/($A14-B$13)/(1+$A14)^5+Assumptions!$B$7)/Assumptions!$B$6 -> 15.736946 | C14: =(SUMPRODUCT(DCF!$B$5:$F$5,(1+$A14)^-{1,2,3,4,5})+DCF!$F$5*(1+C$13)/($A14-C$13)/(1+$A14)^5+Assumptions!$B$7)/Assumptions!$B$6 -> 16.232861 | D14: =(SUMPRODUCT(DCF!$B$5:$F$5,(1+$A14)^-{1,2,3,4,5})+DCF!$F$5*(1+D$13)/($A14-D$13)/(1+$A14)^5+Assumptions!$B$7)/Assumptions!$B$6 -> 16.790765 | E14: =(SUMPRODUCT(DCF!$B$5:$F$5,(1+$A14)^-{1,2,3,4,5})+DCF!$F$5*(1+E$13)/($A14-E$13)/(1+$A14)^5+Assumptions!$B$7)/Assumptions!$B$6 -> 17.423057 | F14: =(SUMPRODUCT(DCF!$B$5:$F$5,(1+$A14)^-{1,2,3,4,5})+DCF!$F$5*(1+F$13)/($A14-F$13)/(1+$A14)^5+Assumptions!$B$7)/Assumptions!$B$6 -> 18.145676
A15: 0.11 | B15: =(SUMPRODUCT(DCF!$B$5:$F$5,(1+$A15)^-{1,2,3,4,5})+DCF!$F$5*(1+B$13)/($A15-B$13)/(1+$A15)^5+Assumptions!$B$7)/Assumptions!$B$6 -> 15.104541 | C15: =(SUMPRODUCT(DCF!$B$5:$F$5,(1+$A15)^-{1,2,3,4,5})+DCF!$F$5*(1+C$13)/($A15-C$13)/(1+$A15)^5+Assumptions!$B$7)/Assumptions!$B$6 -> 15.540314 | D15: =(SUMPRODUCT(DCF!$B$5:$F$5,(1+$A15)^-{1,2,3,4,5})+DCF!$F$5*(1+D$13)/($A15-D$13)/(1+$A15)^5+Assumptions!$B$7)/Assumptions!$B$6 -> 16.027353 | E15: =(SUMPRODUCT(DCF!$B$5:$F$5,(1+$A15)^-{1,2,3,4,5})+DCF!$F$5*(1+E$13)/($A15-E$13)/(1+$A15)^5+Assumptions!$B$7)/Assumptions!$B$6 -> 16.575273 | F15: =(SUMPRODUCT(DCF!$B$5:$F$5,(1+$A15)^-{1,2,3,4,5})+DCF!$F$5*(1+F$13)/($A15-F$13)/(1+$A15)^5+Assumptions!$B$7)/Assumptions!$B$6 -> 17.196249
A16: 0.12 | B16: =(SUMPRODUCT(DCF!$B$5:$F$5,(1+$A16)^-{1,2,3,4,5})+DCF!$F$5*(1+B$13)/($A16-B$13)/(1+$A16)^5+Assumptions!$B$7)/Assumptions!$B$6 -> 14.018226 | C16: =(SUMPRODUCT(DCF!$B$5:$F$5,(1+$A16)^-{1,2,3,4,5})+DCF!$F$5*(1+C$13)/($A16-C$13)/(1+$A16)^5+Assumptions!$B$7)/Assumptions!$B$6 -> 14.360564 | D16: =(SUMPRODUCT(DCF!$B$5:$F$5,(1+$A16)^-{1,2,3,4,5})+DCF!$F$5*(1+D$13)/($A16-D$13)/(1+$A16)^5+Assumptions!$B$7)/Assumptions!$B$6 -> 14.738939 | E16: =(SUMPRODUCT(DCF!$B$5:$F$5,(1+$A16)^-{1,2,3,4,5})+DCF!$F$5*(1+E$13)/($A16-E$13)/(1+$A16)^5+Assumptions!$B$7)/Assumptions!$B$6 -> 15.159355 | F16: =(SUMPRODUCT(DCF!$B$5:$F$5,(1+$A16)^-{1,2,3,4,5})+DCF!$F$5*(1+F$13)/($A16-F$13)/(1+$A16)^5+Assumptions!$B$7)/Assumptions!$B$6 -> 15.629232
A17: 0.13 | B17: =(SUMPRODUCT(DCF!$B$5:$F$5,(1+$A17)^-{1,2,3,4,5})+DCF!$F$5*(1+B$13)/($A17-B$13)/(1+$A17)^5+Assumptions!$B$7)/Assumptions!$B$6 -> 13.118265 | C17: =(SUMPRODUCT(DCF!$B$5:$F$5,(1+$A17)^-{1,2,3,4,5})+DCF!$F$5*(1+C$13)/($A17-C$13)/(1+$A17)^5+Assumptions!$B$7)/Assumptions!$B$6 -> 13.392494 | D17: =(SUMPRODUCT(DCF!$B$5:$F$5,(1+$A17)^-{1,2,3,4,5})+DCF!$F$5*(1+D$13)/($A17-D$13)/(1+$A17)^5+Assumptions!$B$7)/Assumptions!$B$6 -> 13.69284 | E17: =(SUMPRODUCT(DCF!$B$5:$F$5,(1+$A17)^-{1,2,3,4,5})+DCF!$F$5*(1+E$13)/($A17-E$13)/(1+$A17)^5+Assumptions!$B$7)/Assumptions!$B$6 -> 14.02322 | F17: =(SUMPRODUCT(DCF!$B$5:$F$5,(1+$A17)^-{1,2,3,4,5})+DCF!$F$5*(1+F$13)/($A17-F$13)/(1+$A17)^5+Assumptions!$B$7)/Assumptions!$B$6 -> 14.388378
A18: 0.14 | B18: =(SUMPRODUCT(DCF!$B$5:$F$5,(1+$A18)^-{1,2,3,4,5})+DCF!$F$5*(1+B$13)/($A18-B$13)/(1+$A18)^5+Assumptions!$B$7)/Assumptions!$B$6 -> 12.360039 | C18: =(SUMPRODUCT(DCF!$B$5:$F$5,(1+$A18)^-{1,2,3,4,5})+DCF!$F$5*(1+C$13)/($A18-C$13)/(1+$A18)^5+Assumptions!$B$7)/Assumptions!$B$6 -> 12.583297 | D18: =(SUMPRODUCT(DCF!$B$5:$F$5,(1+$A18)^-{1,2,3,4,5})+DCF!$F$5*(1+D$13)/($A18-D$13)/(1+$A18)^5+Assumptions!$B$7)/Assumptions!$B$6 -> 12.825969 | E18: =(SUMPRODUCT(DCF!$B$5:$F$5,(1+$A18)^-{1,2,3,4,5})+DCF!$F$5*(1+E$13)/($A18-E$13)/(1+$A18)^5+Assumptions!$B$7)/Assumptions!$B$6 -> 13.090701 | F18: =(SUMPRODUCT(DCF!$B$5:$F$5,(1+$A18)^-{1,2,3,4,5})+DCF!$F$5*(1+F$13)/($A18-F$13)/(1+$A18)^5+Assumptions!$B$7)/Assumptions!$B$6 -> 13.380647
A20: RNAV grid flexes the two biggest swing factors — the NAV/conglomerate discount and the recurring EV/EBITDA multiple — with all else at base marks. DCF grid flexes WACC and terminal growth on the fixed fading FCFF profile. Base case: discount 20%, recurring 14x; WACC 12%, g 2.5%.

Sheet Per-Share & Ratios
A1: PER-SHARE & RATIOS (at spot)
A2: Drivers link to Income Statement / Balance Sheet / Assumptions.
A5: Share price (AED, 29-Jun-26) | B5: =Assumptions!B5 -> 12.14
A6: Shares outstanding (bn) | B6: =Assumptions!B6 -> 8.84
A7: Market cap (AED bn) | B7: =Assumptions!B5*Assumptions!B6 -> 107.3176
A8: 2025a EPS (AED) | B8: ='Income Statement'!D17 -> 2.138009
A9: Normalized EPS (AED) | B9: =Assumptions!B27 -> 1.85
A10: BVPS (AED) | B10: ='Balance Sheet'!D25 -> 9.0497738
A11: Dividend per share (AED) | B11: =1 -> 1
A12: P/E on 2025a (x) | B12: =B5/B8 -> 5.6781799
A13: P/E normalized (x) | B13: =B5/B9 -> 6.5621622
A14: P/B (x) | B14: =B5/B10 -> 1.34147
A15: Dividend yield | B15: =B11/B5 -> 0.082372323
A16: EV/EBITDA (x, 2025a) | B16: =(B7-Assumptions!B7)/Assumptions!B25 -> 3.2155313
A17: Gross NAV per share (AED) | B17: ='RNAV & SOTP'!B11 -> 17.645107
A18: Discount to gross NAV at spot | B18: =B5/B17-1 -> -0.31199059
A20: Emaar trades at ~6x reported earnings, ~3.2x EV/EBITDA and ~1.3x book with a ~25% ROE and an ~8% dividend yield — cheap on every operating gauge. The discount to gross NAV (~31% at spot) is the RNAV lens's summary of the same cheapness. Dividend is ~AED 1.0/share (100% of share capital, ~50% of earnings).

Sheet Peer & Sector
A1: PEER & SECTOR CONTEXT — UAE / GCC real estate
A2: External sourced data (not model outputs). Verify live before use. As of mid-2026.
A4: Metric | B4: Emaar (EMAAR) | C4: Aldar (ALDAR, Abu Dhabi) | D4: Emaar Development (EMAARDEV)
A5: Business | B5: Developer + malls/hotels + holdco | C5: Abu Dhabi developer + recurring | D5: UAE build-to-sell (Emaar sub)
A6: Trailing P/E (x) | B6: ~6x | C6: ~9-11x | D6: ~5x
A7: EV/EBITDA (x) | B7: ~3.2x | C7: ~10-13x | D7: n/m (build-sell)
A8: Discount to gross NAV | B8: ~31% | C8: n/a (operating) | D8: n/a
A9: Dividend yield | B9: ~8% | C9: ~4% | D9: ~5%
A10: 2025 performance | B10: record sales/rev/profit | C10: record; strong Abu Dhabi cycle | D10: record UAE sales AED 71.1bn
A11: ROE | B11: ~25% | C11: ~15-18% | D11: very high (asset-light)
A13: Emaar screens materially cheaper than Aldar on every multiple despite comparable or higher profitability and a much higher dividend yield — part of a persistent UAE/DFM discount and the conglomerate structure. The relevant gauges for Emaar are the discount to gross NAV and the recurring-portfolio mark. Sources: company IR, exchange data; verify live.
