Workbook

Sheet READ FIRST
A1: Testahil — Emirates NBD Bank PJSC (DFM: EMIRATESNBD) · Companion valuation model
A3: Independent Valuation Study — Educational Analysis. Not investment advice. No rating, no price target.
A5: What this workbook is. A transparent, fully-linked bank valuation model. Blue cells are inputs; black cells are formulas; green cells link across sheets.
A6: Every downstream cell links back to the Assumptions sheet — change one input (e.g. sustainable ROTE, Ke, terminal growth) and the whole model reprices.
A7: Primary lens: Dividend-discount / residual-income on tangible book (a bank is worth its book plus the PV of returns above the cost of equity).
A9: What it is not. Not investment advice, not a recommendation, and not a price target. All outputs are ranges/distributions. The preparer is not licensed by any securities regulator and discloses a possible holding.
A11: Currency. AED (UAE dirham) throughout; figures in AED billion unless stated. Spot AED 30.64, close 3 July 2026; 6.317bn shares.
A12: Historical financials (FY2023–FY2025) are the company's own disclosure (annual reports, quarterly results, DFM filings); some line splits are estimated to tie to disclosed totals and are flagged.
A14: Sheets: Summary · Fundamental Valuation · Assumptions · DDM · Segments · Relative & Normalized · DCF (FCFE) · Income Statement · Balance Sheet · Cash Flow · Summary Financials · Monte Carlo · Sensitivity · Per-Share & Ratios · Peer & Sector.

Sheet Summary
A1: Valuation summary — Emirates NBD (DFM: EMIRATESNBD)
A2: Four-lens fair value vs spot. AED/share.
A3: Lens | B3: Bear | C3: Base | D3: Bull | E3: Weight
A4: DDM / residual income | B4: 25 | C4: =DDM!B21 -> 32.880106 | D4: 44 | E4: =Assumptions!$B$29 -> 0.4
A5: FCFE discounted cash flow | B5: 24 | C5: =DCF!B15 -> 31.049432 | D5: 46 | E5: =Assumptions!$B$30 -> 0.2
A6: Relative multiples | B6: 27 | C6: ='Relative & Normalized'!B8 -> 33.441507 | D6: 42 | E6: =Assumptions!$B$31 -> 0.2
A7: Normalized earnings | B7: 24 | C7: ='Relative & Normalized'!B11 -> 31.381985 | D7: 40 | E7: =Assumptions!$B$32 -> 0.2
A8: Weighted central | B8: =SUMPRODUCT(B4:B7,$E$4:$E$7) -> 25 | C8: =SUMPRODUCT(C4:C7,$E$4:$E$7) -> 32.326627 | D8: =SUMPRODUCT(D4:D7,$E$4:$E$7) -> 43.2
A10: Spot price (AED) | B10: =Assumptions!$B$4 -> 30.64
A11: Upside to central base | B11: =C8/B10-1 -> 0.055046577
A13: Read: modestly undervalued (~+7%); the swing is sustainable ROTE as rates fall and cost of risk normalizes.

Sheet Fundamental Valuation
A1: Fundamental valuation — football field (links to Summary)
A2: Bear/base/bull per lens.
A3: Lens | B3: Bear | C3: Base | D3: Bull
A4: =Summary!A4 -> DDM / residual income | B4: =Summary!B4 -> 25 | C4: =Summary!C4 -> 32.880106 | D4: =Summary!D4 -> 44
A5: =Summary!A5 -> FCFE discounted cash flow | B5: =Summary!B5 -> 24 | C5: =Summary!C5 -> 31.049432 | D5: =Summary!D5 -> 46
A6: =Summary!A6 -> Relative multiples | B6: =Summary!B6 -> 27 | C6: =Summary!C6 -> 33.441507 | D6: =Summary!D6 -> 42
A7: =Summary!A7 -> Normalized earnings | B7: =Summary!B7 -> 24 | C7: =Summary!C7 -> 31.381985 | D7: =Summary!D7 -> 40
A8: Weighted central | B8: =Summary!B8 -> 25 | C8: =Summary!C8 -> 32.326627 | D8: =Summary!D8 -> 43.2
A9: Spot | B9: =Assumptions!$B$4 -> 30.64

Sheet Assumptions
A1: Assumptions — the single input layer
A2: All blue cells are inputs. Every other sheet links here.
A3: ANCHORS
A4: Spot price (AED/share) | B4: 30.64
A5: Shares outstanding (bn) | B5: 6.317
A6: Tangible common equity, FY25 (AED bn) | B6: 118
A7: Total equity, FY25 (AED bn) | B7: 135
A8: RWA, FY25 (AED bn) | B8: 730
A10: COST OF EQUITY (Ke = rf + beta x ERP)
A11: Risk-free rate (UAE/US 10y, AED peg) | B11: 0.043
A12: Beta (house band 0.8–1.3) | B12: 1.1
A13: Equity risk premium | B13: 0.06
A14: Ke (base, incl. small EM/execution premium) | B14: 0.115
A15: Terminal growth g | B15: 0.045
A17: DDM / RESIDUAL INCOME
A18: Sustainable (terminal) ROTE | B18: 0.155
A19: Payout ratio (through cycle) | B19: 0.5
A20: ROTE path FY26E–FY30E | B20: 0.189 | C20: 0.175 | D20: 0.168 | E20: 0.162 | F20: 0.158
A22: RELATIVE & NORMALIZED
A23: Justified P/TBV (relative) | B23: 1.75
A24: Justified P/E (relative) | B24: 9
A25: Normalized through-cycle ROTE | B25: 0.16
A26: Normalized justified P/E | B26: 10.5
A28: SYNTHESIS WEIGHTS
A29: DDM weight | B29: 0.4
A30: FCFE-DCF weight | B30: 0.2
A31: Relative weight | B31: 0.2
A32: Normalized weight | B32: 0.2
A34: MONTE CARLO (§3, from mc_v2 YZ-HAR)
A35: Engine horizon vol (annualized) | B35: 0.45
A36: Secular drift | B36: ON
A37: Level-anchor window (days) | B37: 120
A39: FORECAST DRIVERS (FY26E–FY30E)
B40: FY26E | C40: FY27E | D40: FY28E | E40: FY29E | F40: FY30E
A41: Total income (AED bn) | B41: 51.8 | C41: 53.9 | D41: 56.5 | E41: 59.6 | F41: 62.9
A42: Net interest income (AED bn) | B42: 34.5 | C42: 35.6 | D42: 37.2 | E42: 39.2 | F42: 41.2
A43: Non-funded income (AED bn) | B43: 17.3 | C43: 18.3 | D43: 19.3 | E43: 20.4 | F43: 21.7
A44: Operating expenses (AED bn) | B44: -16.1 | C44: -16.9 | D44: -17.7 | E44: -18.6 | F44: -19.5
A45: Impairment (AED bn) | B45: -3 | C45: -4 | D45: -4.8 | E45: -5.5 | F45: -6.2
A46: Associates/JV & hyperinflation (AED bn) | B46: -2.5 | C46: -2 | D46: -1.6 | E46: -1.4 | F46: -1.2
...

Sheet DDM
A1: Dividend-discount / residual income — primary lens (AED/share)
A2: Value = tangible book + PV of returns above the cost of equity.
A4: Tangible book value / share (FY25) | B4: =Assumptions!$B$6/Assumptions!$B$5 -> 18.679753
A5: Cost of equity (Ke) | B5: =Assumptions!$B$14 -> 0.115
A6: Terminal growth g | B6: =Assumptions!$B$15 -> 0.045
A7: Sustainable ROTE | B7: =Assumptions!$B$18 -> 0.155
A8: Payout ratio | B8: =Assumptions!$B$19 -> 0.5
A10: Year | B10: ROTE | C10: Opening TBV | D10: EPS | E10: Residual income | F10: Disc factor | G10: PV of RI
A11: FY26E | B11: =Assumptions!$B$20 -> 0.189 | C11: =B4 -> 18.679753 | D11: =B11*C11 -> 3.5304733 | E11: =(B11-$B$5)*C11 -> 1.3823017 | F11: =1/(1+$B$5)^1 -> 0.89686099 | G11: =E11*F11 -> 1.2397325
A12: FY27E | B12: =Assumptions!$C$20 -> 0.175 | C12: =C11*(1+B11*(1-Assumptions!$B$19)) -> 20.44499 | D12: =B12*C12 -> 3.5778732 | E12: =(B12-$B$5)*C12 -> 1.2266994 | F12: =1/(1+$B$5)^2 -> 0.80435963 | G12: =E12*F12 -> 0.98670746
A13: FY28E | B13: =Assumptions!$D$20 -> 0.168 | C13: =C12*(1+B12*(1-Assumptions!$B$19)) -> 22.233926 | D13: =B13*C13 -> 3.7352996 | E13: =(B13-$B$5)*C13 -> 1.1783981 | F13: =1/(1+$B$5)^3 -> 0.72139877 | G13: =E13*F13 -> 0.85009494
A14: FY29E | B14: =Assumptions!$E$20 -> 0.162 | C14: =C13*(1+B13*(1-Assumptions!$B$19)) -> 24.101576 | D14: =B14*C14 -> 3.9044553 | E14: =(B14-$B$5)*C14 -> 1.1327741 | F14: =1/(1+$B$5)^4 -> 0.64699441 | G14: =E14*F14 -> 0.7328985
A15: FY30E | B15: =Assumptions!$F$20 -> 0.158 | C15: =C14*(1+B14*(1-Assumptions!$B$19)) -> 26.053804 | D15: =B15*C15 -> 4.116501 | E15: =(B15-$B$5)*C15 -> 1.1203136 | F15: =1/(1+$B$5)^5 -> 0.58026405 | G15: =E15*F15 -> 0.65007768
A17: Σ PV of explicit residual income | B17: =SUM(G11:G15) -> 4.4595111
A18: Terminal residual income (yr6) | B18: =($B$7-$B$5)*C15*(1+B15*(1-$B$8))*(1+$B$6) -> 1.1750839
A19: Terminal value (Gordon) | B19: =B18/($B$5-$B$6) -> 16.786912
A20: PV of terminal value | B20: =B19*F15 -> 9.7408417
A21: DDM fair value / share | B21: =B4+B17+B20 -> 32.880106
A22: Implied P/TBV | B22: =B21/B4 -> 1.7602002
A24: Bear / Bull (from Summary sensitivity band)

Sheet Segments
A1: Divisional view (FY25 income, AED bn)
A2: Contribution by business line (disclosed / estimated).
A3: Segment | B3: FY25 income | C3: Share of income | D3: Note
A4: Retail Banking & Wealth (RBWM) | B4: 19.7 | C4: =B4/$B$9 -> 0.39959432 | D4: Deposits, cards, wealth
A5: Corporate & Institutional (C&IB) | B5: 9 | C5: =B5/$B$9 -> 0.18255578 | D5: Landmark regional deals
A6: Emirates Islamic | B6: 6 | C6: =B6/$B$9 -> 0.12170385 | D6: Record PBT AED 3.9bn
A7: Global Markets & Treasury | B7: 4.5 | C7: =B7/$B$9 -> 0.09127789 | D7: NII + trading
A8: International (incl. DenizBank, KSA, Egypt) | B8: 10.1 | C8: =B8/$B$9 -> 0.20486815 | D8: ~35% of group income
A9: Total operating income | B9: =SUM(B4:B8) -> 49.3

Sheet Relative & Normalized
A1: Relative multiples & normalized earnings
A2: Links to Assumptions.
A4: TBVPS (FY25) | B4: =Assumptions!$B$6/Assumptions!$B$5 -> 18.679753
A5: EPS (FY25) | B5: ='Income Statement'!D13/Assumptions!$B$5 -> 3.7992718
A6: Relative — P/TBV based | B6: =Assumptions!$B$23*B4 -> 32.689568
A7: Relative — P/E based | B7: =Assumptions!$B$24*B5 -> 34.193446
A8: Relative fair value (avg) | B8: =AVERAGE(B6:B7) -> 33.441507
A10: Normalized EPS (through-cycle ROTE × TBVPS) | B10: =Assumptions!$B$25*B4 -> 2.9887605
A11: Normalized fair value (× justified P/E) | B11: =B10*Assumptions!$B$26 -> 31.381985

Sheet DCF
A1: Discounted cash flow — free cash flow to equity, 5-year explicit
A2: FCFE = net profit − required capital build; discounted at Ke. Terminal value disclosed as % of equity value.
B4: FY26E | C4: FY27E | D4: FY28E | E4: FY29E | F4: FY30E
A5: Net profit | B5: ='Income Statement'!E13 -> 24.8 | C5: ='Income Statement'!F13 -> 25.4 | D5: ='Income Statement'!G13 -> 26.6 | E5: ='Income Statement'!H13 -> 28 | F5: ='Income Statement'!I13 -> 29.5
A6: − Required equity build (CET1 × ΔRWA) | B6: ='Cash Flow'!B5 -> -12.76 | C6: ='Cash Flow'!C5 -> -13.05 | D6: ='Cash Flow'!D5 -> -13.195 | E6: ='Cash Flow'!E5 -> -13.05 | F6: ='Cash Flow'!F5 -> -12.615
A7: Free cash flow to equity (FCFE) | B7: =B5+B6 -> 12.04 | C7: =C5+C6 -> 12.35 | D7: =D5+D6 -> 13.405 | E7: =E5+E6 -> 14.95 | F7: =F5+F6 -> 16.885
A8: Discount factor @ Ke | B8: =1/(1+Assumptions!$B$14)^1 -> 0.89686099 | C8: =1/(1+Assumptions!$B$14)^2 -> 0.80435963 | D8: =1/(1+Assumptions!$B$14)^3 -> 0.72139877 | E8: =1/(1+Assumptions!$B$14)^4 -> 0.64699441 | F8: =1/(1+Assumptions!$B$14)^5 -> 0.58026405
A9: PV of FCFE | B9: =B7*B8 -> 10.798206 | C9: =C7*C8 -> 9.9338414 | D9: =D7*D8 -> 9.6703505 | E9: =E7*E8 -> 9.6725665 | F9: =F7*F8 -> 9.7977584
A11: Σ PV of explicit FCFE | B11: =SUM(B9:F9) -> 49.872723
A12: Terminal value (Gordon on FCFE) | B12: =F7*(1+Assumptions!$B$15)/(Assumptions!$B$14-Assumptions!$B$15) -> 252.06893
A13: PV of terminal value | B13: =B12*F8 -> 146.26654
A14: Equity value (AED bn) | B14: =B11+B13 -> 196.13926
A15: Fair value / share (AED) | B15: =B14/Assumptions!$B$5 -> 31.049432
A16: Terminal value as % of equity value | B16: =B13/B14 -> 0.74572799
A18: Ke = rf + beta × ERP = | B18: =Assumptions!$B$11+Assumptions!$B$12*Assumptions!$B$13 -> 0.109 | C18: (base Ke used above may add a small EM/execution premium)

Sheet Income Statement
A1: Income statement — bank format (AED bn)
A2: FY23–FY25 disclosed; FY26E–FY30E forecast links to Assumptions drivers.
B3: FY23 | C3: FY24 | D3: FY25 | E3: FY26E | F3: FY27E | G3: FY28E | H3: FY29E | I3: FY30E
A4: Net interest income | B4: 29 | C4: 32 | D4: 33.8 | E4: =Assumptions!$B$42 -> 34.5 | F4: =Assumptions!$C$42 -> 35.6 | G4: =Assumptions!$D$42 -> 37.2 | H4: =Assumptions!$E$42 -> 39.2 | I4: =Assumptions!$F$42 -> 41.2
A5: Non-funded income | B5: 14 | C5: 12.1 | D5: 15.5 | E5: =Assumptions!$B$43 -> 17.3 | F5: =Assumptions!$C$43 -> 18.3 | G5: =Assumptions!$D$43 -> 19.3 | H5: =Assumptions!$E$43 -> 20.4 | I5: =Assumptions!$F$43 -> 21.7
A6: Total operating income | B6: 43 | C6: 44.1 | D6: 49.3 | E6: =E4+E5 -> 51.8 | F6: =F4+F5 -> 53.9 | G6: =G4+G5 -> 56.5 | H6: =H4+H5 -> 59.6 | I6: =I4+I5 -> 62.9
A7: Operating expenses | B7: -11.6 | C7: -13 | D7: -15 | E7: =Assumptions!$B$44 -> -16.1 | F7: =Assumptions!$C$44 -> -16.9 | G7: =Assumptions!$D$44 -> -17.7 | H7: =Assumptions!$E$44 -> -18.6 | I7: =Assumptions!$F$44 -> -19.5
A8: Pre-provision operating profit | B8: 31.4 | C8: 31.1 | D8: 34.3 | E8: =E6+E7 -> 35.7 | F8: =F6+F7 -> 37 | G8: =G6+G7 -> 38.8 | H8: =H6+H7 -> 41 | I8: =I6+I7 -> 43.4
A9: Impairment allowance | B9: -6.5 | C9: -3.7 | D9: -1.5 | E9: =Assumptions!$B$45 -> -3 | F9: =Assumptions!$C$45 -> -4 | G9: =Assumptions!$D$45 -> -4.8 | H9: =Assumptions!$E$45 -> -5.5 | I9: =Assumptions!$F$45 -> -6.2
A10: Associates / JV & hyperinflation | B10: -1.2 | C10: -0.3 | D10: -3 | E10: =Assumptions!$B$46 -> -2.5 | F10: =Assumptions!$C$46 -> -2 | G10: =Assumptions!$D$46 -> -1.6 | H10: =Assumptions!$E$46 -> -1.4 | I10: =Assumptions!$F$46 -> -1.2
A11: Profit before tax | B11: 23.7 | C11: 27.1 | D11: 29.8 | E11: =E8+E9+E10 -> 30.2 | F11: =F8+F9+F10 -> 31 | G11: =G8+G9+G10 -> 32.4 | H11: =H8+H9+H10 -> 34.1 | I11: =I8+I9+I10 -> 36
A12: Tax | B12: -2.2 | C12: -4.1 | D12: -5.8 | E12: =Assumptions!$B$47 -> -5.4 | F12: =Assumptions!$C$47 -> -5.6 | G12: =Assumptions!$D$47 -> -5.8 | H12: =Assumptions!$E$47 -> -6.1 | I12: =Assumptions!$F$47 -> -6.5
A13: Net profit (attributable) | B13: 21.5 | C13: 23 | D13: 24 | E13: =E11+E12 -> 24.8 | F13: =F11+F12 -> 25.4 | G13: =G11+G12 -> 26.6 | H13: =H11+H12 -> 28 | I13: =I11+I12 -> 29.5
A15: Source: Emirates NBD FY2023–FY2025 results & annual reports; DFM filings. FY26E–FY30E: preparer forecast (Assumptions).

Sheet Balance Sheet
A1: Balance sheet — bank format (AED bn)
A2: FY23–FY25 disclosed; FY26E–FY30E links to Assumptions.
B3: FY23 | C3: FY24 | D3: FY25 | E3: FY26E | F3: FY27E | G3: FY28E | H3: FY29E | I3: FY30E
A4: Net loans & financing | B4: 440 | C4: 520 | D4: 640 | E4: =Assumptions!$B$48 -> 715 | F4: =Assumptions!$C$48 -> 790 | G4: =Assumptions!$D$48 -> 865 | H4: =Assumptions!$E$48 -> 940 | I4: =Assumptions!$F$48 -> 1015
A5: Investments & other earning assets | B5: 337 | C5: 377 | D5: 345 | E5: =E8-E4-E6 -> 374 | F5: =F8-F4-F6 -> 398 | G5: =G8-G4-G6 -> 426.5 | H5: =H8-H4-H6 -> 455 | I5: =I8-I4-I6 -> 483.5
A6: Cash & due from banks | B6: 86 | C6: 100 | D6: 110 | E6: =0.1*E8 -> 121 | F6: =0.1*F8 -> 132 | G6: =0.1*G8 -> 143.5 | H6: =0.1*H8 -> 155 | I6: =0.1*I8 -> 166.5
A8: Total assets | B8: 863 | C8: 997 | D8: 1095 | E8: =Assumptions!$B$50 -> 1210 | F8: =Assumptions!$C$50 -> 1320 | G8: =Assumptions!$D$50 -> 1435 | H8: =Assumptions!$E$50 -> 1550 | I8: =Assumptions!$F$50 -> 1665
A10: Customer deposits | B10: 590 | C10: 671 | D10: 790 | E10: =Assumptions!$B$49 -> 880 | F10: =Assumptions!$C$49 -> 965 | G10: =Assumptions!$D$49 -> 1050 | H10: =Assumptions!$E$49 -> 1135 | I10: =Assumptions!$F$49 -> 1220
A11: Borrowings & sukuk | B11: 120 | C11: 148 | D11: 104 | E11: =E8-E10-E13-E12 -> 104.5487 | F11: =F8-F10-F13-F12 -> 105.1291 | G11: =G8-G10-G13-G12 -> 109.8412 | H11: =H8-H10-H13-H12 -> 113.785 | I11: =I8-I10-I13-I12 -> 116.8605
A12: Other liabilities | B12: 52 | C12: 60 | D12: 66 | E12: =0.06*E8 -> 72.6 | F12: =0.06*F8 -> 79.2 | G12: =0.06*G8 -> 86.1 | H12: =0.06*H8 -> 93 | I12: =0.06*I8 -> 99.9
A13: Total equity | B13: 101 | C13: 118 | D13: 135 | E13: =D13+'Income Statement'!E13+Assumptions!$B$52*-Assumptions!$B$5 -> 152.8513 | F13: =E13+'Income Statement'!F13+Assumptions!$C$52*-Assumptions!$B$5 -> 170.6709 | G13: =F13+'Income Statement'!G13+Assumptions!$D$52*-Assumptions!$B$5 -> 189.0588 | H13: =G13+'Income Statement'!H13+Assumptions!$E$52*-Assumptions!$B$5 -> 208.215 | I13: =H13+'Income Statement'!I13+Assumptions!$F$52*-Assumptions!$B$5 -> 228.2395
A15: Tangible common equity | B15: 85 | C15: 100 | D15: 118 | E15: =D15+(E13-D13) -> 135.8513 | F15: =E15+(F13-E13) -> 153.6709 | G15: =F15+(G13-F13) -> 172.0588 | H15: =G15+(H13-G13) -> 191.215 | I15: =H15+(I13-H13) -> 211.2395
A16: Risk-weighted assets (RWA) | B16: 600 | C16: 660 | D16: 730 | E16: =Assumptions!$B$51 -> 818 | F16: =Assumptions!$C$51 -> 908 | G16: =Assumptions!$D$51 -> 999 | H16: =Assumptions!$E$51 -> 1089 | I16: =Assumptions!$F$51 -> 1176
A18: Balance check (A − L − E) | B18: =B8-B10-B11-B12-B13 -> 0 | C18: =C8-C10-C11-C12-C13 -> 0 | D18: =D8-D10-D11-D12-D13 -> 0 | E18: =E8-E10-E11-E12-E13 -> 0 | F18: =F8-F10-F11-F12-F13 -> 0 | G18: =G8-G10-G11-G12-G13 -> 0 | H18: =H8-H10-H11-H12-H13 -> 0 | I18: =I8-I10-I11-I12-I13 -> 0
A20: Source: Emirates NBD FY2023–FY2025 disclosures. Some splits estimated to tie to disclosed totals (flagged).

Sheet Cash Flow
A1: Capital & distribution flow (AED bn)
A2: Bank funds-flow: earnings less required capital build = distributable.
B3: FY26E | C3: FY27E | D3: FY28E | E3: FY29E | F3: FY30E
A4: Net profit | B4: ='Income Statement'!E13 -> 24.8 | C4: ='Income Statement'!F13 -> 25.4 | D4: ='Income Statement'!G13 -> 26.6 | E4: ='Income Statement'!H13 -> 28 | F4: ='Income Statement'!I13 -> 29.5
A5: − Increase in required equity (CET1 × ΔRWA) | B5: =-0.145*('Balance Sheet'!E16-'Balance Sheet'!D16) -> -12.76 | C5: =-0.145*('Balance Sheet'!F16-'Balance Sheet'!E16) -> -13.05 | D5: =-0.145*('Balance Sheet'!G16-'Balance Sheet'!F16) -> -13.195 | E5: =-0.145*('Balance Sheet'!H16-'Balance Sheet'!G16) -> -13.05 | F5: =-0.145*('Balance Sheet'!I16-'Balance Sheet'!H16) -> -12.615
A6: Free cash flow to equity (FCFE) | B6: =B4+B5 -> 12.04 | C6: =C4+C5 -> 12.35 | D6: =D4+D5 -> 13.405 | E6: =E4+E5 -> 14.95 | F6: =F4+F5 -> 16.885
A7: − Dividends | B7: =-Assumptions!$B$52*Assumptions!$B$5 -> -6.9487 | C7: =-Assumptions!$C$52*Assumptions!$B$5 -> -7.5804 | D7: =-Assumptions!$D$52*Assumptions!$B$5 -> -8.2121 | E7: =-Assumptions!$E$52*Assumptions!$B$5 -> -8.8438 | F7: =-Assumptions!$F$52*Assumptions!$B$5 -> -9.4755
A8: Retained / surplus capital | B8: =B6+B7 -> 5.0913 | C8: =C6+C7 -> 4.7696 | D8: =D6+D7 -> 5.1929 | E8: =E6+E7 -> 6.1062 | F8: =F6+F7 -> 7.4095
A10: FCFE = net profit − capital retained to fund RWA growth at a ~14.5% CET1 target. Feeds the DCF sheet.

Sheet Summary Financials
A1: Summary financials (AED bn) — every cell links to the statements
B4: FY23 | C4: FY24 | D4: FY25 | E4: FY26E | F4: FY27E | G4: FY28E | H4: FY29E | I4: FY30E
A5: Total operating income | B5: ='Income Statement'!B6 -> 43 | C5: ='Income Statement'!C6 -> 44.1 | D5: ='Income Statement'!D6 -> 49.3 | E5: ='Income Statement'!E6 -> 51.8 | F5: ='Income Statement'!F6 -> 53.9 | G5: ='Income Statement'!G6 -> 56.5 | H5: ='Income Statement'!H6 -> 59.6 | I5: ='Income Statement'!I6 -> 62.9
A6: Pre-provision profit | B6: ='Income Statement'!B8 -> 31.4 | C6: ='Income Statement'!C8 -> 31.1 | D6: ='Income Statement'!D8 -> 34.3 | E6: ='Income Statement'!E8 -> 35.7 | F6: ='Income Statement'!F8 -> 37 | G6: ='Income Statement'!G8 -> 38.8 | H6: ='Income Statement'!H8 -> 41 | I6: ='Income Statement'!I8 -> 43.4
A7: Net profit | B7: ='Income Statement'!B13 -> 21.5 | C7: ='Income Statement'!C13 -> 23 | D7: ='Income Statement'!D13 -> 24 | E7: ='Income Statement'!E13 -> 24.8 | F7: ='Income Statement'!F13 -> 25.4 | G7: ='Income Statement'!G13 -> 26.6 | H7: ='Income Statement'!H13 -> 28 | I7: ='Income Statement'!I13 -> 29.5
A8: Total assets | B8: ='Balance Sheet'!B8 -> 863 | C8: ='Balance Sheet'!C8 -> 997 | D8: ='Balance Sheet'!D8 -> 1095 | E8: ='Balance Sheet'!E8 -> 1210 | F8: ='Balance Sheet'!F8 -> 1320 | G8: ='Balance Sheet'!G8 -> 1435 | H8: ='Balance Sheet'!H8 -> 1550 | I8: ='Balance Sheet'!I8 -> 1665
A9: Net loans | B9: ='Balance Sheet'!B4 -> 440 | C9: ='Balance Sheet'!C4 -> 520 | D9: ='Balance Sheet'!D4 -> 640 | E9: ='Balance Sheet'!E4 -> 715 | F9: ='Balance Sheet'!F4 -> 790 | G9: ='Balance Sheet'!G4 -> 865 | H9: ='Balance Sheet'!H4 -> 940 | I9: ='Balance Sheet'!I4 -> 1015
A10: Deposits | B10: ='Balance Sheet'!B10 -> 590 | C10: ='Balance Sheet'!C10 -> 671 | D10: ='Balance Sheet'!D10 -> 790 | E10: ='Balance Sheet'!E10 -> 880 | F10: ='Balance Sheet'!F10 -> 965 | G10: ='Balance Sheet'!G10 -> 1050 | H10: ='Balance Sheet'!H10 -> 1135 | I10: ='Balance Sheet'!I10 -> 1220
A11: Total equity | B11: ='Balance Sheet'!B13 -> 101 | C11: ='Balance Sheet'!C13 -> 118 | D11: ='Balance Sheet'!D13 -> 135 | E11: ='Balance Sheet'!E13 -> 152.8513 | F11: ='Balance Sheet'!F13 -> 170.6709 | G11: ='Balance Sheet'!G13 -> 189.0588 | H11: ='Balance Sheet'!H13 -> 208.215 | I11: ='Balance Sheet'!I13 -> 228.2395
A12: RWA | B12: ='Balance Sheet'!B16 -> 600 | C12: ='Balance Sheet'!C16 -> 660 | D12: ='Balance Sheet'!D16 -> 730 | E12: ='Balance Sheet'!E16 -> 818 | F12: ='Balance Sheet'!F16 -> 908 | G12: ='Balance Sheet'!G16 -> 999 | H12: ='Balance Sheet'!H16 -> 1089 | I12: ='Balance Sheet'!I16 -> 1176

Sheet Monte Carlo
A1: Monte Carlo — engine output (§3)
A2: 50,000 paths · seed 42 · YZ-HAR width · Student-t(5) · secular drift ON · Gulf-bank 16-factor overlay.
A4: Horizon | B4: p5 | C4: p25 | D4: p50 | E4: p75 | F4: p95
A5: T+20 sessions | B5: 23.69 | C5: 28.14 | D5: 31.04 | E5: 34.23 | F5: 40.59
A6: T+60 sessions | B6: 22.31 | C6: 27.97 | D6: 31.81 | E6: 36.15 | F6: 45.24
A8: Engine horizon vol (annualized) | C8: 0.45
A9: Net continuous-factor drift (incremental) | C9: 0.006
A10: Secular drift | C10: ON (calibrated, Step 0)
A12: Level-touch ladder
A13: Level (AED) | B13: T+20 touch | C13: T+60 touch
A14: 37 | B14: 0.198 | C14: 0.348
A15: 35 | B15: 0.334 | C15: 0.494
A16: 34 | B16: 0.431 | C16: 0.582
A17: 33 | B17: 0.548 | C17: 0.679
A18: 32 | B18: 0.682 | C18: 0.779
A19: 31 | B19: 0.819 | C19: 0.876
A20: 30 | B20: 0.739 | C20: 0.794
A21: 29 | B21: 0.577 | C21: 0.66
A22: 28 | B22: 0.43 | C22: 0.531

Sheet Sensitivity
A1: DDM fair value — sustainable ROTE × Ke (AED/share)
A2: Gordon justified P/TBV × TBVPS; g from Assumptions.
A4: ROTE \ Ke | B4: 0.105 | C4: 0.11 | D4: 0.115 | E4: 0.12 | F4: 0.125 | G4: 0.13
A5: 0.14 | B5: =(($A5-Assumptions!$B$15)/(B$4-Assumptions!$B$15))*((Assumptions!$B$6)/Assumptions!$B$5) -> 29.576276 | C5: =(($A5-Assumptions!$B$15)/(C$4-Assumptions!$B$15))*((Assumptions!$B$6)/Assumptions!$B$5) -> 27.301178 | D5: =(($A5-Assumptions!$B$15)/(D$4-Assumptions!$B$15))*((Assumptions!$B$6)/Assumptions!$B$5) -> 25.351093 | E5: =(($A5-Assumptions!$B$15)/(E$4-Assumptions!$B$15))*((Assumptions!$B$6)/Assumptions!$B$5) -> 23.661021 | F5: =(($A5-Assumptions!$B$15)/(F$4-Assumptions!$B$15))*((Assumptions!$B$6)/Assumptions!$B$5) -> 22.182207 | G5: =(($A5-Assumptions!$B$15)/(G$4-Assumptions!$B$15))*((Assumptions!$B$6)/Assumptions!$B$5) -> 20.877371
A6: 0.155 | B6: =(($A6-Assumptions!$B$15)/(B$4-Assumptions!$B$15))*((Assumptions!$B$6)/Assumptions!$B$5) -> 34.246214 | C6: =(($A6-Assumptions!$B$15)/(C$4-Assumptions!$B$15))*((Assumptions!$B$6)/Assumptions!$B$5) -> 31.61189 | D6: =(($A6-Assumptions!$B$15)/(D$4-Assumptions!$B$15))*((Assumptions!$B$6)/Assumptions!$B$5) -> 29.353898 | E6: =(($A6-Assumptions!$B$15)/(E$4-Assumptions!$B$15))*((Assumptions!$B$6)/Assumptions!$B$5) -> 27.396971 | F6: =(($A6-Assumptions!$B$15)/(F$4-Assumptions!$B$15))*((Assumptions!$B$6)/Assumptions!$B$5) -> 25.68466 | G6: =(($A6-Assumptions!$B$15)/(G$4-Assumptions!$B$15))*((Assumptions!$B$6)/Assumptions!$B$5) -> 24.173798
A7: 0.165 | B7: =(($A7-Assumptions!$B$15)/(B$4-Assumptions!$B$15))*((Assumptions!$B$6)/Assumptions!$B$5) -> 37.359506 | C7: =(($A7-Assumptions!$B$15)/(C$4-Assumptions!$B$15))*((Assumptions!$B$6)/Assumptions!$B$5) -> 34.485698 | D7: =(($A7-Assumptions!$B$15)/(D$4-Assumptions!$B$15))*((Assumptions!$B$6)/Assumptions!$B$5) -> 32.022434 | E7: =(($A7-Assumptions!$B$15)/(E$4-Assumptions!$B$15))*((Assumptions!$B$6)/Assumptions!$B$5) -> 29.887605 | F7: =(($A7-Assumptions!$B$15)/(F$4-Assumptions!$B$15))*((Assumptions!$B$6)/Assumptions!$B$5) -> 28.01963 | G7: =(($A7-Assumptions!$B$15)/(G$4-Assumptions!$B$15))*((Assumptions!$B$6)/Assumptions!$B$5) -> 26.371416
A8: 0.175 | B8: =(($A8-Assumptions!$B$15)/(B$4-Assumptions!$B$15))*((Assumptions!$B$6)/Assumptions!$B$5) -> 40.472798 | C8: =(($A8-Assumptions!$B$15)/(C$4-Assumptions!$B$15))*((Assumptions!$B$6)/Assumptions!$B$5) -> 37.359506 | D8: =(($A8-Assumptions!$B$15)/(D$4-Assumptions!$B$15))*((Assumptions!$B$6)/Assumptions!$B$5) -> 34.69097 | E8: =(($A8-Assumptions!$B$15)/(E$4-Assumptions!$B$15))*((Assumptions!$B$6)/Assumptions!$B$5) -> 32.378239 | F8: =(($A8-Assumptions!$B$15)/(F$4-Assumptions!$B$15))*((Assumptions!$B$6)/Assumptions!$B$5) -> 30.354599 | G8: =(($A8-Assumptions!$B$15)/(G$4-Assumptions!$B$15))*((Assumptions!$B$6)/Assumptions!$B$5) -> 28.569034
A9: 0.185 | B9: =(($A9-Assumptions!$B$15)/(B$4-Assumptions!$B$15))*((Assumptions!$B$6)/Assumptions!$B$5) -> 43.58609 | C9: =(($A9-Assumptions!$B$15)/(C$4-Assumptions!$B$15))*((Assumptions!$B$6)/Assumptions!$B$5) -> 40.233314 | D9: =(($A9-Assumptions!$B$15)/(D$4-Assumptions!$B$15))*((Assumptions!$B$6)/Assumptions!$B$5) -> 37.359506 | E9: =(($A9-Assumptions!$B$15)/(E$4-Assumptions!$B$15))*((Assumptions!$B$6)/Assumptions!$B$5) -> 34.868872 | F9: =(($A9-Assumptions!$B$15)/(F$4-Assumptions!$B$15))*((Assumptions!$B$6)/Assumptions!$B$5) -> 32.689568 | G9: =(($A9-Assumptions!$B$15)/(G$4-Assumptions!$B$15))*((Assumptions!$B$6)/Assumptions!$B$5) -> 30.766652
A10: 0.195 | B10: =(($A10-Assumptions!$B$15)/(B$4-Assumptions!$B$15))*((Assumptions!$B$6)/Assumptions!$B$5) -> 46.699383 | C10: =(($A10-Assumptions!$B$15)/(C$4-Assumptions!$B$15))*((Assumptions!$B$6)/Assumptions!$B$5) -> 43.107122 | D10: =(($A10-Assumptions!$B$15)/(D$4-Assumptions!$B$15))*((Assumptions!$B$6)/Assumptions!$B$5) -> 40.028042 | E10: =(($A10-Assumptions!$B$15)/(E$4-Assumptions!$B$15))*((Assumptions!$B$6)/Assumptions!$B$5) -> 37.359506 | F10: =(($A10-Assumptions!$B$15)/(F$4-Assumptions!$B$15))*((Assumptions!$B$6)/Assumptions!$B$5) -> 35.024537 | G10: =(($A10-Assumptions!$B$15)/(G$4-Assumptions!$B$15))*((Assumptions!$B$6)/Assumptions!$B$5) -> 32.96427

Sheet Per-Share & Ratios
A1: Per-share & ratios (the standardized dashboard)
A2: Links to statements / Assumptions.
B4: FY23 | C4: FY24 | D4: FY25 | E4: FY26E | F4: FY27E | G4: FY28E | H4: FY29E | I4: FY30E
A5: EPS (AED) | B5: ='Income Statement'!B13/Assumptions!$B$5 -> 3.4035143 | C5: ='Income Statement'!C13/Assumptions!$B$5 -> 3.6409688 | D5: ='Income Statement'!D13/Assumptions!$B$5 -> 3.7992718 | E5: ='Income Statement'!E13/Assumptions!$B$5 -> 3.9259142 | F5: ='Income Statement'!F13/Assumptions!$B$5 -> 4.020896 | G5: ='Income Statement'!G13/Assumptions!$B$5 -> 4.2108596 | H5: ='Income Statement'!H13/Assumptions!$B$5 -> 4.4324838 | I5: ='Income Statement'!I13/Assumptions!$B$5 -> 4.6699383
A6: DPS (AED) | B6: =1.2 -> 1.2 | C6: =1 -> 1 | D6: =1 -> 1 | E6: =1.1 -> 1.1 | F6: =1.2 -> 1.2 | G6: =1.3 -> 1.3 | H6: =1.4 -> 1.4 | I6: =1.5 -> 1.5
A7: TBVPS (AED) | B7: ='Balance Sheet'!B15/Assumptions!$B$5 -> 13.455754 | C7: ='Balance Sheet'!C15/Assumptions!$B$5 -> 15.830299 | D7: ='Balance Sheet'!D15/Assumptions!$B$5 -> 18.679753 | E7: ='Balance Sheet'!E15/Assumptions!$B$5 -> 21.505667 | F7: ='Balance Sheet'!F15/Assumptions!$B$5 -> 24.326563 | G7: ='Balance Sheet'!G15/Assumptions!$B$5 -> 27.237423 | H7: ='Balance Sheet'!H15/Assumptions!$B$5 -> 30.269907 | I7: ='Balance Sheet'!I15/Assumptions!$B$5 -> 33.439845
A8: BVPS (AED) | B8: ='Balance Sheet'!B13/Assumptions!$B$5 -> 15.988602 | C8: ='Balance Sheet'!C13/Assumptions!$B$5 -> 18.679753 | D8: ='Balance Sheet'!D13/Assumptions!$B$5 -> 21.370904 | E8: ='Balance Sheet'!E13/Assumptions!$B$5 -> 24.196818 | F8: ='Balance Sheet'!F13/Assumptions!$B$5 -> 27.017714 | G8: ='Balance Sheet'!G13/Assumptions!$B$5 -> 29.928574 | H8: ='Balance Sheet'!H13/Assumptions!$B$5 -> 32.961057 | I8: ='Balance Sheet'!I13/Assumptions!$B$5 -> 36.130996
A9: P/E (x) | B9: =Assumptions!$B$4/(B5) -> 9.0024595 | C9: =Assumptions!$B$4/(C5) -> 8.4153426 | D9: =Assumptions!$B$4/(D5) -> 8.0647033 | E9: =Assumptions!$B$4/(E5) -> 7.8045516 | F9: =Assumptions!$B$4/(F5) -> 7.6201921 | G9: =Assumptions!$B$4/(G5) -> 7.2764241 | H9: =Assumptions!$B$4/(H5) -> 6.9126029 | I9: =Assumptions!$B$4/(I5) -> 6.5611146
A10: P/TBV (x) | B10: =Assumptions!$B$4/(B7) -> 2.2770927 | C10: =Assumptions!$B$4/(C7) -> 1.9355288 | D10: =Assumptions!$B$4/(D7) -> 1.6402786 | E10: =Assumptions!$B$4/(E7) -> 1.4247407 | F10: =Assumptions!$B$4/(F7) -> 1.2595285 | G10: =Assumptions!$B$4/(G7) -> 1.1249229 | H10: =Assumptions!$B$4/(H7) -> 1.0122264 | I10: =Assumptions!$B$4/(I7) -> 0.91627219
A11: Dividend yield | B11: =B6/Assumptions!$B$4 -> 0.039164491 | C11: =C6/Assumptions!$B$4 -> 0.032637076 | D11: =D6/Assumptions!$B$4 -> 0.032637076 | E11: =E6/Assumptions!$B$4 -> 0.035900783 | F11: =F6/Assumptions!$B$4 -> 0.039164491 | G11: =G6/Assumptions!$B$4 -> 0.042428198 | H11: =H6/Assumptions!$B$4 -> 0.045691906 | I11: =I6/Assumptions!$B$4 -> 0.048955614
A12: ROTE | B12: =0.195 -> 0.195 | C12: =0.212 -> 0.212 | D12: =0.2 -> 0.2 | E12: =0.189 -> 0.189 | F12: =0.175 -> 0.175 | G12: =0.168 -> 0.168 | H12: =0.162 -> 0.162 | I12: =0.158 -> 0.158
A13: NIM | B13: =0.036 -> 0.036 | C13: =0.04 -> 0.04 | D13: =0.0346 -> 0.0346 | E13: =0.0325 -> 0.0325 | F13: =0.0315 -> 0.0315 | G13: =0.031 -> 0.031 | H13: =0.0308 -> 0.0308 | I13: =0.0305 -> 0.0305
A14: Cost-income ratio | B14: =-'Income Statement'!B7/'Income Statement'!B6 -> 0.26976744 | C14: =-'Income Statement'!C7/'Income Statement'!C6 -> 0.29478458 | D14: =-'Income Statement'!D7/'Income Statement'!D6 -> 0.30425963 | E14: =-'Income Statement'!E7/'Income Statement'!E6 -> 0.31081081 | F14: =-'Income Statement'!F7/'Income Statement'!F6 -> 0.3135436 | G14: =-'Income Statement'!G7/'Income Statement'!G6 -> 0.31327434 | H14: =-'Income Statement'!H7/'Income Statement'!H6 -> 0.31208054 | I14: =-'Income Statement'!I7/'Income Statement'!I6 -> 0.3100159
A15: NPL ratio | B15: =0.046 -> 0.046 | C15: =0.033 -> 0.033 | D15: =0.024 -> 0.024 | E15: =0.026 -> 0.026 | F15: =0.029 -> 0.029 | G15: =0.031 -> 0.031 | H15: =0.032 -> 0.032 | I15: =0.032 -> 0.032
A16: CET1 ratio | B16: =0.147 -> 0.147 | C16: =0.149 -> 0.149 | D16: =0.144 -> 0.144 | E16: =0.145 -> 0.145 | F16: =0.146 -> 0.146 | G16: =0.146 -> 0.146 | H16: =0.147 -> 0.147 | I16: =0.148 -> 0.148
A17: Total CAR | B17: =0.169 -> 0.169 | C17: =0.172 -> 0.172 | D17: =0.166 -> 0.166 | E17: =0.167 -> 0.167 | F17: =0.168 -> 0.168 | G17: =0.169 -> 0.169 | H17: =0.17 -> 0.17 | I17: =0.171 -> 0.171
A18: RWA density (RWA/assets) | B18: ='Balance Sheet'!B16/'Balance Sheet'!B8 -> 0.69524913 | C18: ='Balance Sheet'!C16/'Balance Sheet'!C8 -> 0.66198596 | D18: ='Balance Sheet'!D16/'Balance Sheet'!D8 -> 0.66666667 | E18: ='Balance Sheet'!E16/'Balance Sheet'!E8 -> 0.67603306 | F18: ='Balance Sheet'!F16/'Balance Sheet'!F8 -> 0.68787879 | G18: ='Balance Sheet'!G16/'Balance Sheet'!G8 -> 0.69616725 | H18: ='Balance Sheet'!H16/'Balance Sheet'!H8 -> 0.70258065 | I18: ='Balance Sheet'!I16/'Balance Sheet'!I8 -> 0.70630631

Sheet Peer & Sector
A1: Peer set & sector (indicative, 2025)
A2: Gulf banks — P/TBV & P/E context.
A4: Bank | B4: P/TBV (x) | C4: P/E (x) | D4: Note
A5: Emirates NBD (this study) | B5: 1.64 | C5: 8.3 | D5: ROTE ~19-20%, mid multiple
A6: First Abu Dhabi Bank (FAB) | B6: 1.4 | C6: 9.7 | D6: Largest UAE bank
A7: Abu Dhabi Commercial (ADCB) | B7: 1.3 | C7: 9 | D7: De-risked book
A8: Dubai Islamic Bank (DIB) | B8: 1.3 | C8: 7 | D8: UAE Islamic
A9: Qatar National Bank (QNB) | B9: 1.7 | C9: 9 | D9: Largest GCC bank
A10: Al Rajhi Bank | B10: 3 | C10: 18 | D10: Saudi Islamic premium
A11: Abu Dhabi Islamic (ADIB) | B11: 3.5 | C11: 13 | D11: Highest Gulf P/TBV
A13: Source: AGBI/Forbes ME/company disclosures 2025 (indicative; multiples move with price).
