Workbook

Sheet READ FIRST
A1: Telecom Egypt (EGX: ETEL) — Independent Valuation Model · Educational Analysis
A3: READ FIRST — what this workbook is, and is not.
A4: This model is a valuation exercise and an expression of personal analytical opinion, published free of charge for educational purposes. It is NOT investment
A5: advice, NOT a recommendation or solicitation to buy, sell or hold any security, and NOT directed at the circumstances of any reader. The preparer is not
A6: licensed by any securities regulator in any jurisdiction (including the Egyptian FRA), provides no financial consultancy, manages no money, and accepts no
A7: fees, funds or clients. All values are model outputs presented as ranges and distributions because no single number should be relied on.
A9: How to use: the Assumptions sheet is the single input layer — every blue cell is an input, every other sheet links to it, so changing one input (the VFE
A10: mark, the complexity discount, a growth rate) reprices the whole model. Black cells are formulas; do not overwrite them.
A12: Reported figures are drawn from Telecom Egypt public disclosure (FY2025 audited results, 26 Feb 2026; Q1 2026 release, May 2026; FY2024 and FY2023
A13: releases), EGX/LSE filings and market data as of 01 Jul 2026. Forward-looking inputs — the SOTP marks, the VFE stake mark, the complexity discount,
A14: projections, multiples, the DCF and the Monte-Carlo factor probabilities — are the preparer’s own judgments and are flagged as inputs.
A16: Holdings disclosure: the preparer may hold, and may in the future take or dispose of, a position in the security discussed in this report.
A17: Companion document: ETEL_Valuation_Study_03-07-2026_public.docx (same edition, same inputs).

Sheet Summary
A1: Telecom Egypt (EGX: ETEL) — summary · edition 03-07-2026
A3: Spot (01 Jul 2026) | B3: =Assumptions!$B$5 -> 92.61
A4: Market cap (EGP bn) | B4: =Assumptions!$B$5*Assumptions!$B$6/1000 -> 158.09175
A5: Weighted central fair value (EGP/share) | B5: ='Fundamental Valuation'!D9 -> 117.66791 | D5: 40/20/15/25 across SOTP · DCF · Relative · Normalized
A6: vs spot | B6: ='Fundamental Valuation'!D9/Assumptions!$B$5-1 -> 0.27057451
A7: Bear – Bull central | B7: ='Fundamental Valuation'!C9 -> 82.008466 | C7: ='Fundamental Valuation'!E9 -> 160.01241
A8: SOTP (primary) | B8: =SOTP!C18 -> 118.1835 | D8: Market-implied discount at spot: SOTP!C19
A9: DCF cross-check | B9: =DCF!B26 -> 106.52143
A10: Relative / Normalized | B10: ='Relative & Normalized'!C7 -> 103.2 | C10: ='Relative & Normalized'!C12 -> 134.44088
A11: MC T+60 median (EGP) | B11: 106.3 | D11: p5–p95: 78–145 · IQR 94–119
A12: MC T+20 median (EGP) | B12: 96.9
A13: Step 0 verdict | B13: PASS — drift-ON | D13: CRPS skill +13.0%, Winkler +20.3%, PIT KS p=0.54, n=17 non-overlapping
A14: Dividend (FY25, paid 30 Apr 2026) | B14: 1.5 | D14: Proposed/paid EGP 1.50; payout ~12.6%
A15: State ownership | B15: 0.7 | D15: MoF ~70% since May-2023 9.5%+0.5% sale; free float ~30%

Sheet Fundamental Valuation
A1: Synthesis — four lenses, one weighted central (EGP/share)
A4: Lens | B4: Weight | C4: Bear | D4: Base | E4: Bull | F4: Reference
A5: Sum-of-the-parts | B5: =Assumptions!$B$45 -> 0.4 | C5: =SOTP!B18 -> 83.277194 | D5: =SOTP!C18 -> 118.1835 | E5: =SOTP!D18 -> 157.55944 | F5: SOTP sheet
A6: Core-FCFF DCF + stake | B6: =Assumptions!$B$46 -> 0.2 | C6: 70 | D6: =DCF!B26 -> 106.52143 | E6: 154 | F6: DCF sheet (bear/bull re-run at 25%/10% and 21.5%/12%)
A7: Relative multiples | B7: =Assumptions!$B$47 -> 0.15 | C7: ='Relative & Normalized'!B7 -> 77.545 | D7: ='Relative & Normalized'!C7 -> 103.2 | E7: ='Relative & Normalized'!D7 -> 142.5 | F7: Relative & Normalized
A8: Normalized earnings | B8: =Assumptions!$B$48 -> 0.25 | C8: ='Relative & Normalized'!B12 -> 92.263352 | D8: ='Relative & Normalized'!C12 -> 134.44088 | E8: ='Relative & Normalized'!D12 -> 179.25451 | F8: Relative & Normalized
A9: Weighted central | C9: =SUMPRODUCT($B$5:$B$8,C5:C8) -> 82.008466 | D9: =SUMPRODUCT($B$5:$B$8,D5:D8) -> 117.66791 | E9: =SUMPRODUCT($B$5:$B$8,E5:E8) -> 160.01241
A10: vs spot | D10: =D9/Assumptions!$B$5-1 -> 0.27057451
A11: Spot / market cap | D11: =Assumptions!$B$5 -> 92.61 | E11: =Assumptions!$B$5*Assumptions!$B$6/1000 -> 158.09175

Sheet Assumptions
A1: Assumptions — the single input layer
A2: All blue cells are inputs. Every other sheet links here. Source and as-of date noted beside each anchor.
A4: ANCHORS
A5: Spot price (EGP/share) | B5: 92.61 | H5: Uploaded daily history, close 01 Jul 2026 (Investing.com export)
A6: Shares outstanding (mn) | B6: 1707.07 | H6: 1,707,071,600 shares; company/EGX disclosure
A7: Market cap (EGP bn) | B7: =B5*B6/1000 -> 158.09175 | H7: spot × shares
A8: USD/EGP | B8: 49.1 | H8: Investing.com / TradingEconomics, 01 Jul 2026
A9: Net debt, latest (EGP bn) | B9: 58 | H9: FY25 BS: gross 73.8 − cash 7.7 = 66.1; Q1-26 release: net debt −EGP 8bn QoQ, ND/EBITDA 1.3×
A10: Complexity / control discount | B10: 0.15 | H10: Judgment: 70% state holding, associate-heavy NAV; market implies ~33% (SOTP sheet)
A11: WACC (EGP nominal) | B11: 0.23 | H11: Judgment: EGP risk-free ~19% + equity premium; CBE easing cycle
A12: Terminal growth (nominal) | B12: 0.11 | H12: Judgment: long-run EGP inflation ~8–10% + ~2% real
A13: Effective tax + minorities rate | B13: 0.305 | H13: Balances FY25 reported NPAT (see Income Statement)
A14: Employee / board profit share (EPS wedge) | B14: 0.1 | H14: EPS ≈ NPAT×(1−share)/shares; reconciles reported EPS 11.93 FY25
A16: SOTP — BASE MARKS
A17: Core 2026E EBITDA (EGP bn) | B17: 52.6 | H17: FY25 47.5 reported; Q1-26 12.6 (45% margin); NTRA +13–15% tariffs → 2026E
A18: Core EV/EBITDA multiple | B18: 3.25 | H18: Judgment: EM incumbent, heavy capex; peers ~3–5.5× (Peer & Sector)
A19: VFE income to TE, FY25 (EGP bn) | B19: 14.8 | H19: FY25 release: VFE investment income +71% YoY
A20: TE stake in Vodafone Egypt | B20: 0.45 | H20: Company disclosure
A21: VFE mark — P/E on 100% attributable profit | B21: 8 | H21: Judgment; cross-check: Vodacom 2021-22 deal ~US$2.7bn for 55%
A22: Other assets (data-hub JV, land, non-core) (EGP bn) | B22: 6 | H22: Judgment
A24: FORECAST DRIVERS (FY26E–FY30E)
B25: FY26E | C25: FY27E | D25: FY28E | E25: FY29E | F25: FY30E
A26: Revenue growth | B26: 0.12 | C26: 0.1 | D26: 0.09 | E26: 0.08 | F26: 0.07
A27: EBITDA margin | B27: 0.44 | C27: 0.435 | D27: 0.43 | E27: 0.43 | F27: 0.43
A28: D&A % of revenue | B28: 0.131 | C28: 0.131 | D28: 0.13 | E28: 0.128 | F28: 0.127
A29: VFE income growth | B29: 0.2 | C29: 0.15 | D29: 0.12 | E29: 0.1 | F29: 0.09
A30: Net finance cost (EGP bn) | B30: 14.5 | C30: 12.5 | D30: 11 | E30: 10 | F30: 9
A31: In-service capex % of revenue (DCF basis) | B31: 0.21 | C31: 0.205 | D31: 0.2 | E31: 0.195 | F31: 0.19 | H31: DCF capex basis = in-service (maintainable); cash capex incl. licences drives the CF statement — judgment, flagged
A32: Dividend per share (EGP) | B32: 2 | C32: 2.6 | D32: 3.3 | E32: 4 | F32: 4.7
A33: Cash capex % of revenue | B33: 0.26 | C33: 0.24 | D33: 0.23 | E33: 0.22 | F33: 0.21
A34: VFE dividends received, net (EGP bn) | B34: 4.5 | C34: 5.5 | D34: 6.5 | E34: 7.5 | F34: 8.5
A35: Core cash-tax rate (DCF) | B35: 0.225
A36: ΔWC, % of incremental revenue (DCF) | B36: 0.05
A38: RELATIVE & NORMALIZED
A39: Relative blended EPS (EGP) | B39: 12.9
A40: Relative justified P/E | B40: 8
A41: Normalized mid-cycle NPAT (EGP bn) | B41: 30
A42: Normalized justified P/E | B42: 8.5
A44: LENS WEIGHTS
A45: Sum-of-the-parts | B45: 0.4
...

Sheet SOTP
A1: Sum-of-the-parts — the primary lens (EGP bn; per share in EGP)
A2: Each part marked on the basis that best fits it; net debt deducted; a complexity / state-control discount applied. Bear and bull marks are inputs on this sheet.
B4: Bear | C4: Base | D4: Bull | E4: Basis
A5: Core EBITDA 2026E | B5: 50 | C5: =Assumptions!$B$17 -> 52.6 | D5: 55 | E5: FY25 47.5; Q1-26 12.6 at 45%; NTRA tariffs
A6: Core EV/EBITDA | B6: 2.75 | C6: =Assumptions!$B$18 -> 3.25 | D6: 3.75 | E6: EM incumbent, capex-heavy
A7: Core enterprise value | B7: =B5*B6 -> 137.5 | C7: =C5*C6 -> 170.95 | D7: =D5*D6 -> 206.25
A8: VFE 100% profit (FY25) | B8: =C8 -> 32.888889 | C8: =Assumptions!$B$19/Assumptions!$B$20 -> 32.888889 | D8: =C8 -> 32.888889 | E8: 14.8 / 45% = 32.9
A9: VFE P/E mark | B9: 6.5 | C9: =Assumptions!$B$21 -> 8 | D9: 9.5 | E9: Cross-check: Vodacom 2021-22 deal ~US$2.7bn for 55% ≈ EGP 110bn for 45% at 49.1
A10: VFE stake (45%) | B10: =B8*B9*Assumptions!$B$20 -> 96.2 | C10: =C8*C9*Assumptions!$B$20 -> 118.4 | D10: =D8*D9*Assumptions!$B$20 -> 140.6
A11: Other (data-hub JV, land, non-core) | B11: 4 | C11: =Assumptions!$B$22 -> 6 | D11: 8 | E11: Judgment
A12: Σ Enterprise value | B12: =B7+B10+B11 -> 237.7 | C12: =C7+C10+C11 -> 295.35 | D12: =D7+D10+D11 -> 354.85
A13: less: net debt | B13: 60 | C13: =Assumptions!$B$9 -> 58 | D13: 56 | E13: FY25 BS 66.1; Q1-26 −8bn QoQ
A14: Equity value (pre-discount) | B14: =B12-B13 -> 177.7 | C14: =C12-C13 -> 237.35 | D14: =D12-D13 -> 298.85
A15: per share, pre-discount | B15: =B14*1000/Assumptions!$B$6 -> 104.09649 | C15: =C14*1000/Assumptions!$B$6 -> 139.03941 | D15: =D14*1000/Assumptions!$B$6 -> 175.06605
A16: Complexity / state-control discount | B16: 0.2 | C16: =Assumptions!$B$10 -> 0.15 | D16: 0.1 | E16: Market-implied at spot ≈ row 19
A17: SOTP equity value | B17: =B14*(1-B16) -> 142.16 | C17: =C14*(1-C16) -> 201.7475 | D17: =D14*(1-D16) -> 268.965
A18: SOTP per share | B18: =B17*1000/Assumptions!$B$6 -> 83.277194 | C18: =C17*1000/Assumptions!$B$6 -> 118.1835 | D18: =D17*1000/Assumptions!$B$6 -> 157.55944
A19: Market-implied discount at spot | C19: =1-Assumptions!$B$5*Assumptions!$B$6/1000/C14 -> 0.33392984 | E19: 1 − market cap / pre-discount equity

Sheet Segments
A1: Segment revenue and the three engines (EGP bn)
A4: Segment | B4: FY24 | C4: FY25 | D4: Growth | E4: Mix FY25 | F4: Scorecard
A5: Home & Consumer | B5: 36.034 | C5: 52.086 | D5: =C5/B5-1 -> 0.44546817 | E5: =C5/$C$10 -> 0.48827726 | F5: Retail engine: data +46%; NTRA +13–15% tariffs from mid-2026
A6: Enterprise | B6: 8.312 | C6: 9.788 | D6: =C6/B6-1 -> 0.17757459 | E6: =C6/$C$10 -> 0.091757052 | F6: Steady; data centers and cloud attach
A7: Domestic wholesale | B7: 9.293 | C7: 10.294 | D7: =C7/B7-1 -> 0.10771548 | E7: =C7/$C$10 -> 0.09650052 | F7: VFE EGP 30bn infrastructure agreements to 2034
A8: Int’l carrier affairs (ICA) | B8: 14.21 | C8: 18.202 | D8: =C8/B8-1 -> 0.28092892 | E8: =C8/$C$10 -> 0.17063362 | F8: IIC 13.1bn (+30%); USD-linked
A9: Int’l customers & networks (IC&N) | B9: 13.829 | C9: 16.303 | D9: =C9/B9-1 -> 0.17889941 | E9: =C9/$C$10 -> 0.15283155 | F9: Subsea/cables +31%; Red Sea corridor
A10: Total | B10: 81.678 | C10: 106.673 | D10: =C10/B10-1 -> 0.30601876 | E10: =C10/$C$10 -> 1
A12: Three engines scorecard
A13: Part | B13: Growth | C13: FX sensitivity | D13: Capital intensity | E13: Swing role
A14: Core retail (H&C + Enterprise) | B14: High (tariffs + data) | C14: Low (EGP) | D14: High (fibre, 5G) | E14: Cash engine
A15: Core wholesale & int’l (DW+ICA+IC&N) | B15: High (subsea, IIC) | C15: High (USD-linked) | D15: Moderate | E15: Growth + FX hedge
A16: VFE 45% stake | B16: High (+71% income) | C16: Moderate | D16: Nil to TE (associate) | E16: Dominant value swing

Sheet Relative & Normalized
A1: Relative multiples and normalized earnings power
B4: Bear | C4: Base | D4: Bull | E4: Basis
A5: RELATIVE — EPS basis (EGP) | B5: 11.93 | C5: =Assumptions!$B$39 -> 12.9 | D5: 15 | E5: Bear: FY25 reported; base: blended FY25/26E; bull: 2026E model
A6: Justified P/E | B6: 6.5 | C6: =Assumptions!$B$40 -> 8 | D6: 9.5 | E6: EM incumbents ~6–10×
A7: Relative fair value / share | B7: =B5*B6 -> 77.545 | C7: =C5*C6 -> 103.2 | D7: =D5*D6 -> 142.5
A9: NORMALIZED — mid-cycle NPAT (EGP bn) | B9: 25 | C9: =Assumptions!$B$41 -> 30 | D9: 34 | E9: 2026–27 run-rate ex-FX noise
A10: normalized EPS | B10: =B9*(1-Assumptions!$B$14)*1000/Assumptions!$B$6 -> 13.180479 | C10: =C9*(1-Assumptions!$B$14)*1000/Assumptions!$B$6 -> 15.816575 | D10: =D9*(1-Assumptions!$B$14)*1000/Assumptions!$B$6 -> 17.925451
A11: Justified P/E | B11: 7 | C11: =Assumptions!$B$42 -> 8.5 | D11: 10 | E11: Through-cycle, sub-peer
A12: Normalized fair value / share | B12: =B10*B11 -> 92.263352 | C12: =C10*C11 -> 134.44088 | D12: =D10*D11 -> 179.25451

Sheet DCF
A1: Core-FCFF DCF + the stake — the cash-flow cross-check (FCFF built from the forecast statements)
A2: FCFF derived per year: EBITDA − D&A = EBIT → less cash tax → NOPAT → + D&A − in-service capex − ΔWC. WACC, growth, tax and capex basis are Assumptions inputs.
B4: FY26E | C4: FY27E | D4: FY28E | E4: FY29E | F4: FY30E
A5: Revenue | B5: ='Income Statement'!E5 -> 119.47376 | C5: ='Income Statement'!F5 -> 131.42114 | D5: ='Income Statement'!G5 -> 143.24904 | E5: ='Income Statement'!H5 -> 154.70896 | F5: ='Income Statement'!I5 -> 165.53859
A6: EBITDA | B6: ='Income Statement'!E7 -> 52.568454 | C6: ='Income Statement'!F7 -> 57.168194 | D6: ='Income Statement'!G7 -> 61.597086 | E6: ='Income Statement'!H7 -> 66.524853 | F6: ='Income Statement'!I7 -> 71.181593
A7: less: D&A | B7: =-'Income Statement'!E9 -> -15.651063 | C7: =-'Income Statement'!F9 -> -17.216169 | D7: =-'Income Statement'!G9 -> -18.622375 | E7: =-'Income Statement'!H9 -> -19.802747 | F7: =-'Income Statement'!I9 -> -21.023401
A8: EBIT | B8: =B6+B7 -> 36.917392 | C8: =C6+C7 -> 39.952025 | D8: =D6+D7 -> 42.974711 | E8: =E6+E7 -> 46.722106 | F8: =F6+F7 -> 50.158192
A9: less: cash tax | B9: =-B8*Assumptions!$B$35 -> -8.3064132 | C9: =-C8*Assumptions!$B$35 -> -8.9892057 | D9: =-D8*Assumptions!$B$35 -> -9.6693101 | E9: =-E8*Assumptions!$B$35 -> -10.512474 | F9: =-F8*Assumptions!$B$35 -> -11.285593
A10: NOPAT | B10: =B8+B9 -> 28.610979 | C10: =C8+C9 -> 30.96282 | D10: =D8+D9 -> 33.305401 | E10: =E8+E9 -> 36.209632 | F10: =F8+F9 -> 38.872599
A11: add: D&A | B11: ='Income Statement'!E9 -> 15.651063 | C11: ='Income Statement'!F9 -> 17.216169 | D11: ='Income Statement'!G9 -> 18.622375 | E11: ='Income Statement'!H9 -> 19.802747 | F11: ='Income Statement'!I9 -> 21.023401
A12: less: in-service capex (DCF basis) | B12: =-B5*Assumptions!B$31 -> -25.08949 | C12: =-C5*Assumptions!C$31 -> -26.941333 | D12: =-D5*Assumptions!D$31 -> -28.649808 | E12: =-E5*Assumptions!E$31 -> -30.168247 | F12: =-F5*Assumptions!F$31 -> -31.452332
A13: less: ΔWC | B13: =-('Income Statement'!E5-'Income Statement'!D5)*Assumptions!$B$36 -> -0.640038 | C13: =-('Income Statement'!F5-'Income Statement'!E5)*Assumptions!$B$36 -> -0.5973688 | D13: =-('Income Statement'!G5-'Income Statement'!F5)*Assumptions!$B$36 -> -0.59139511 | E13: =-('Income Statement'!H5-'Income Statement'!G5)*Assumptions!$B$36 -> -0.57299615 | F13: =-('Income Statement'!I5-'Income Statement'!H5)*Assumptions!$B$36 -> -0.54148136
A14: Core FCFF (built) | B14: =B10+B11+B12+B13 -> 18.532514 | C14: =C10+C11+C12+C13 -> 20.640287 | D14: =D10+D11+D12+D13 -> 22.686574 | E14: =E10+E11+E12+E13 -> 25.271136 | F14: =F10+F11+F12+F13 -> 27.902187
A15: Discount factor | B15: =1/(1+Assumptions!$B$11)^1 -> 0.81300813 | C15: =1/(1+Assumptions!$B$11)^2 -> 0.66098222 | D15: =1/(1+Assumptions!$B$11)^3 -> 0.53738392 | E15: =1/(1+Assumptions!$B$11)^4 -> 0.43689749 | F15: =1/(1+Assumptions!$B$11)^5 -> 0.35520122
A16: PV of FCFF | B16: =B14*B15 -> 15.067084 | C16: =C14*C15 -> 13.642863 | D16: =D14*D15 -> 12.1914 | E16: =E14*E15 -> 11.040896 | F16: =F14*F15 -> 9.9108906
A18: Σ PV, explicit years FY26E–FY30E | B18: =SUM(B16:F16) -> 61.853133
A19: Terminal value (Gordon on FY30E FCFF) | B19: =F14*(1+Assumptions!$B$12)/(Assumptions!$B$11-Assumptions!$B$12) -> 258.09523
A20: PV of terminal value | B20: =B19*F15 -> 91.675738
A21: Core enterprise value | B21: =B18+B20 -> 153.52887
A22: + VFE stake (SOTP mark) | B22: =SOTP!C10 -> 118.4
A23: − Net debt | B23: =-Assumptions!$B$9 -> -58
A24: Equity value (pre-discount) | B24: =B21+B22+B23 -> 213.92887
A25: × (1 − complexity discount) | B25: =B24*(1-Assumptions!$B$10) -> 181.83954
A26: DCF fair value per share (EGP) | B26: =B25*1000/Assumptions!$B$6 -> 106.52143
A28: Per-share sensitivity — WACC × terminal growth
C29: 0.1 | D29: 0.11 | E29: 0.12
B30: 0.215 | C30: =((SUMPRODUCT($B$14:$F$14,1/(1+$B30)^{1,2,3,4,5})+$F$14*(1+C$29)/($B30-C$29)/(1+$B30)^5)+$B$22+$B$23)*(1-Assumptions!$B$10)*1000/Assumptions!$B$6 -> 112.14145 | D30: =((SUMPRODUCT($B$14:$F$14,1/(1+$B30)^{1,2,3,4,5})+$F$14*(1+D$29)/($B30-D$29)/(1+$B30)^5)+$B$22+$B$23)*(1-Assumptions!$B$10)*1000/Assumptions!$B$6 -> 117.4212 | E30: =((SUMPRODUCT($B$14:$F$14,1/(1+$B30)^{1,2,3,4,5})+$F$14*(1+E$29)/($B30-E$29)/(1+$B30)^5)+$B$22+$B$23)*(1-Assumptions!$B$10)*1000/Assumptions!$B$6 -> 123.81248
B31: 0.23 | C31: =((SUMPRODUCT($B$14:$F$14,1/(1+$B31)^{1,2,3,4,5})+$F$14*(1+C$29)/($B31-C$29)/(1+$B31)^5)+$B$22+$B$23)*(1-Assumptions!$B$10)*1000/Assumptions!$B$6 -> 102.63044 | D31: =((SUMPRODUCT($B$14:$F$14,1/(1+$B31)^{1,2,3,4,5})+$F$14*(1+D$29)/($B31-D$29)/(1+$B31)^5)+$B$22+$B$23)*(1-Assumptions!$B$10)*1000/Assumptions!$B$6 -> 106.52143 | E31: =((SUMPRODUCT($B$14:$F$14,1/(1+$B31)^{1,2,3,4,5})+$F$14*(1+E$29)/($B31-E$29)/(1+$B31)^5)+$B$22+$B$23)*(1-Assumptions!$B$10)*1000/Assumptions!$B$6 -> 111.11988
B32: 0.25 | C32: =((SUMPRODUCT($B$14:$F$14,1/(1+$B32)^{1,2,3,4,5})+$F$14*(1+C$29)/($B32-C$29)/(1+$B32)^5)+$B$22+$B$23)*(1-Assumptions!$B$10)*1000/Assumptions!$B$6 -> 92.910575 | D32: =((SUMPRODUCT($B$14:$F$14,1/(1+$B32)^{1,2,3,4,5})+$F$14*(1+D$29)/($B32-D$29)/(1+$B32)^5)+$B$22+$B$23)*(1-Assumptions!$B$10)*1000/Assumptions!$B$6 -> 95.620433 | E32: =((SUMPRODUCT($B$14:$F$14,1/(1+$B32)^{1,2,3,4,5})+$F$14*(1+E$29)/($B32-E$29)/(1+$B32)^5)+$B$22+$B$23)*(1-Assumptions!$B$10)*1000/Assumptions!$B$6 -> 98.747192

Sheet Income Statement
A1: Income statement — consolidated (EGP bn)
A2: FY23–FY25 as reported / derived from company releases; FY26E–FY30E model. EBIT here = EBITDA − D&A (model definition; the EAS summary line differs).
B4: FY23 | C4: FY24 | D4: FY25 | E4: FY26E | F4: FY27E | G4: FY28E | H4: FY29E | I4: FY30E | J4: Source / note
A5: Revenue | B5: 56.7 | C5: 81.678 | D5: 106.673 | E5: =D5*(1+Assumptions!B$26) -> 119.47376 | F5: =E5*(1+Assumptions!C$26) -> 131.42114 | G5: =F5*(1+Assumptions!D$26) -> 143.24904 | H5: =G5*(1+Assumptions!E$26) -> 154.70896 | I5: =H5*(1+Assumptions!F$26) -> 165.53859 | J5: FY25/FY24: FY25 earnings release (26 Feb 2026); FY23: FY23 release / Daily News Egypt (Mar 2024)
A6: growth % | B6: n/d | C6: =C5/B5-1 -> 0.4405291 | D6: =D5/C5-1 -> 0.30601876 | E6: =E5/D5-1 -> 0.12 | F6: =F5/E5-1 -> 0.1 | G6: =G5/F5-1 -> 0.09 | H6: =H5/G5-1 -> 0.08 | I6: =I5/H5-1 -> 0.07
A7: EBITDA | B7: 22.5 | C7: 32.623 | D7: 47.495 | E7: =E5*Assumptions!B$27 -> 52.568454 | F7: =F5*Assumptions!C$27 -> 57.168194 | G7: =G5*Assumptions!D$27 -> 61.597086 | H7: =H5*Assumptions!E$27 -> 66.524853 | I7: =I5*Assumptions!F$27 -> 71.181593 | J7: FY25/FY24 reported; FY23 derived from FY24 release “EBITDA +45%”
A8: margin | B8: =B7/B5 -> 0.3968254 | C8: =C7/C5 -> 0.39940988 | D8: =D7/D5 -> 0.44523919 | E8: =E7/E5 -> 0.44 | F8: =F7/F5 -> 0.435 | G8: =G7/G5 -> 0.43 | H8: =H7/H5 -> 0.43 | I8: =I7/I5 -> 0.43
A9: D&A | B9: 7.9 | C9: 11.7 | D9: 13.6 | E9: =E5*Assumptions!B$28 -> 15.651063 | F9: =F5*Assumptions!C$28 -> 17.216169 | G9: =G5*Assumptions!D$28 -> 18.622375 | H9: =H5*Assumptions!E$28 -> 19.802747 | I9: =I5*Assumptions!F$28 -> 21.023401 | J9: FY25: release “D&A +16%”; FY24 “+48%”; chained
A10: EBIT (model) | B10: =B7-B9 -> 14.6 | C10: =C7-C9 -> 20.923 | D10: =D7-D9 -> 33.895 | E10: =E7-E9 -> 36.917392 | F10: =F7-F9 -> 39.952025 | G10: =G7-G9 -> 42.974711 | H10: =H7-H9 -> 46.722106 | I10: =I7-I9 -> 50.158192
A11: VFE investment income | B11: 5.28 | C11: 8.655 | D11: 14.8 | E11: =D11*(1+Assumptions!B$29) -> 17.76 | F11: =E11*(1+Assumptions!C$29) -> 20.424 | G11: =F11*(1+Assumptions!D$29) -> 22.87488 | H11: =G11*(1+Assumptions!E$29) -> 25.162368 | I11: =H11*(1+Assumptions!F$29) -> 27.426981 | J11: FY25 release: +71% YoY; FY24 release: +64% YoY; chained
A12: Net finance cost & other | B12: -4.75 | C12: -15.55 | D12: -16.25 | E12: =-Assumptions!B$30 -> -14.5 | F12: =-Assumptions!C$30 -> -12.5 | G12: =-Assumptions!D$30 -> -11 | H12: =-Assumptions!E$30 -> -10 | I12: =-Assumptions!F$30 -> -9 | J12: Historical = balancing to reported NPAT at the stated effective rate (incl. FX losses: 4.9 FY24; Q1-26 5.3 non-cash)
A13: PBT | B13: =B10+B11+B12 -> 15.13 | C13: =C10+C11+C12 -> 14.028 | D13: =D10+D11+D12 -> 32.445 | E13: =E10+E11+E12 -> 40.177392 | F13: =F10+F11+F12 -> 47.876025 | G13: =G10+G11+G12 -> 54.849591 | H13: =H10+H11+H12 -> 61.884474 | I13: =I10+I11+I12 -> 68.585173
A14: NPAT | B14: =B13*(1-0.24) -> 11.4988 | C14: =C13*(1-0.28) -> 10.10016 | D14: =D13*(1-Assumptions!$B$13) -> 22.549275 | E14: =E13*(1-Assumptions!$B$13) -> 27.923287 | F14: =F13*(1-Assumptions!$B$13) -> 33.273838 | G14: =G13*(1-Assumptions!$B$13) -> 38.120466 | H14: =H13*(1-Assumptions!$B$13) -> 43.00971 | I14: =I13*(1-Assumptions!$B$13) -> 47.666696 | J14: Reported: 11.5 / 10.098 / 22.555; effective tax+minorities 24% / 28% / 30.5%
A15: margin | B15: =B14/B5 -> 0.20280071 | C15: =C14/C5 -> 0.12365827 | D15: =D14/D5 -> 0.2113869 | E15: =E14/E5 -> 0.233719 | F15: =F14/F5 -> 0.25318483 | G15: =G14/G5 -> 0.26611324 | H15: =H14/H5 -> 0.278004 | I15: =I14/I5 -> 0.28794915
A16: EPS, reported basis (EGP) | B16: =B14*(1-Assumptions!$B$14)*1000/Assumptions!$B$6 -> 6.0623876 | C16: =C14*(1-Assumptions!$B$14)*1000/Assumptions!$B$6 -> 5.3249978 | D16: =D14*(1-Assumptions!$B$14)*1000/Assumptions!$B$6 -> 11.88841 | E16: =E14*(1-Assumptions!$B$14)*1000/Assumptions!$B$6 -> 14.721692 | F16: =F14*(1-Assumptions!$B$14)*1000/Assumptions!$B$6 -> 17.542604 | G16: =G14*(1-Assumptions!$B$14)*1000/Assumptions!$B$6 -> 20.09784 | H16: =H14*(1-Assumptions!$B$14)*1000/Assumptions!$B$6 -> 22.675543 | I16: =I14*(1-Assumptions!$B$14)*1000/Assumptions!$B$6 -> 25.130795 | J16: Reported EPS: ~5.4 / 4.79 / 11.93 (post profit-share wedge)

Sheet Balance Sheet
A1: Balance sheet — consolidated (EGP bn)
A2: FY24/FY25 per FY2025 earnings release; FY23 anchored to disclosed items (cash, gross-debt growth, ND/EBITDA 1.7×), remainder estimated. Forecast is a simplified roll-forward.
B4: FY23 | C4: FY24 | D4: FY25 | E4: FY26E | F4: FY27E | G4: FY28E | H4: FY29E | I4: FY30E | J4: Source / note
A5: Cash & equivalents | B5: 10.443 | C5: 7.565 | D5: 7.685 | E5: =D5 -> 7.685 | F5: =D5 -> 7.685 | G5: =D5 -> 7.685 | H5: =D5 -> 7.685 | I5: =D5 -> 7.685 | J5: FY23 = FY24 opening cash (FY25 CF stmt); held flat in forecast
A6: Other current assets | B6: 22 | C6: 35.384 | D6: 39.079 | E6: =E5*0+'Income Statement'!E5*0.37 -> 44.205291 | F6: =F5*0+'Income Statement'!F5*0.37 -> 48.62582 | G6: =G5*0+'Income Statement'!G5*0.37 -> 53.002144 | H6: =H5*0+'Income Statement'!H5*0.37 -> 57.242316 | I6: =I5*0+'Income Statement'!I5*0.37 -> 61.249278 | J6: FY23 est.; forecast ≈ 37% of revenue
A7: Current assets | B7: =B5+B6 -> 32.443 | C7: =C5+C6 -> 42.949 | D7: =D5+D6 -> 46.764 | E7: =E5+E6 -> 51.890291 | F7: =F5+F6 -> 56.31082 | G7: =G5+G6 -> 60.687144 | H7: =H5+H6 -> 64.927316 | I7: =I5+I6 -> 68.934278
A8: Net fixed assets | B8: 72 | C8: 104.141 | D8: 119.829 | E8: =D8+'Income Statement'!E5*Assumptions!B$33-'Income Statement'!E9 -> 135.24112 | F8: =E8+'Income Statement'!F5*Assumptions!C$33-'Income Statement'!F9 -> 149.56602 | G8: =F8+'Income Statement'!G5*Assumptions!D$33-'Income Statement'!G9 -> 163.89092 | H8: =G8+'Income Statement'!H5*Assumptions!E$33-'Income Statement'!H9 -> 178.12415 | I8: =H8+'Income Statement'!I5*Assumptions!F$33-'Income Statement'!I9 -> 191.86385 | J8: FY23 est.; forecast: + cash capex − D&A
A9: Investments (VFE, equity method) | B9: 12 | C9: 18.848 | D9: 30.851 | E9: =D9+'Income Statement'!E11-Assumptions!B$34 -> 44.111 | F9: =E9+'Income Statement'!F11-Assumptions!C$34 -> 59.035 | G9: =F9+'Income Statement'!G11-Assumptions!D$34 -> 75.40988 | H9: =G9+'Income Statement'!H11-Assumptions!E$34 -> 93.072248 | I9: =H9+'Income Statement'!I11-Assumptions!F$34 -> 111.99923 | J9: FY23 est.; forecast: + VFE income − dividends received
A10: Other non-current assets (bal.) | B10: 11.8 | C10: 32.014 | D10: 28.439 | E10: =E16-E7-E8-E9 -> 23.686174 | F10: =F16-F7-F8-F9 -> 19.718352 | G10: =G16-G7-G8-G9 -> 15.398135 | H10: =H16-H7-H8-H9 -> 11.021319 | I10: =I16-I7-I8-I9 -> 6.7766813 | J10: Balancing line in forecast
A11: Total assets | B11: =B7+B8+B9+B10 -> 128.243 | C11: =C7+C8+C9+C10 -> 197.952 | D11: =D7+D8+D9+D10 -> 225.883 | E11: =E7+E8+E9+E10 -> 254.92858 | F11: =F7+F8+F9+F10 -> 284.63019 | G11: =G7+G8+G9+G10 -> 315.38608 | H11: =H7+H8+H9+H10 -> 347.14503 | I11: =I7+I8+I9+I10 -> 379.57404
A12: Gross debt | B12: 49.7 | C12: 81.476 | D12: 73.759 | E12: =E18+E5 -> 73.140626 | F12: =F18+F5 -> 69.438722 | G12: =G18+G5 -> 63.385479 | H12: =H18+H5 -> 54.942623 | I12: =I18+I5 -> 44.063666 | J12: FY24: ST 43.1 + LT 38.4; FY25: 38.4 + 35.3; FY23 derived (FY24 “gross debt +64%”)
A13: Other liabilities | B13: 41 | C13: 70.539 | D13: 88.435 | E13: =D13*( 'Income Statement'!E5/'Income Statement'!D5 )^0.5 -> 93.590807 | F13: =D13*( 'Income Statement'!F5/'Income Statement'!D5 )^0.5 -> 98.158866 | G13: =D13*( 'Income Statement'!G5/'Income Statement'!D5 )^0.5 -> 102.48087 | H13: =D13*( 'Income Statement'!H5/'Income Statement'!D5 )^0.5 -> 106.50124 | I13: =D13*( 'Income Statement'!I5/'Income Statement'!D5 )^0.5 -> 110.16574 | J13: FY24/FY25 = other current 46.4/53.7 + other non-current 24.1/34.7; FY23 est.; forecast scales slowly with revenue
A14: Total liabilities | B14: =B12+B13 -> 90.7 | C14: =C12+C13 -> 152.015 | D14: =D12+D13 -> 162.194 | E14: =E12+E13 -> 166.73143 | F14: =F12+F13 -> 167.59759 | G14: =G12+G13 -> 165.86634 | H14: =H12+H13 -> 161.44386 | I14: =I12+I13 -> 154.2294
A15: Equity | B15: 37.5 | C15: 45.938 | D15: 63.688 | E15: =D15+'Income Statement'!E14-Assumptions!B$32*Assumptions!$B$6/1000 -> 88.197147 | F15: =E15+'Income Statement'!F14-Assumptions!C$32*Assumptions!$B$6/1000 -> 117.0326 | G15: =F15+'Income Statement'!G14-Assumptions!D$32*Assumptions!$B$6/1000 -> 149.51974 | H15: =G15+'Income Statement'!H14-Assumptions!E$32*Assumptions!$B$6/1000 -> 185.70117 | I15: =H15+'Income Statement'!I14-Assumptions!F$32*Assumptions!$B$6/1000 -> 225.34463 | J15: FY23 est.; forecast: + NPAT − dividends declared
A16: Total liabilities + equity | B16: =B14+B15 -> 128.2 | C16: =C14+C15 -> 197.953 | D16: =D14+D15 -> 225.882 | E16: =E14+E15 -> 254.92858 | F16: =F14+F15 -> 284.63019 | G16: =G14+G15 -> 315.38608 | H16: =H14+H15 -> 347.14503 | I16: =I14+I15 -> 379.57404
A17: Check (TA − TL+E) | B17: =B11-B16 -> 0.043 | C17: =C11-C16 -> -0.001 | D17: =D11-D16 -> 0.001 | E17: =E11-E16 -> 0 | F17: =F11-F16 -> 0 | G17: =G11-G16 -> 0 | H17: =H11-H16 -> 0 | I17: =I11-I16 -> 0
A18: Net debt | B18: =B12-B5 -> 39.257 | C18: =C12-C5 -> 73.911 | D18: =D12-D5 -> 66.074 | E18: =D18-DCF!B14+(-'Income Statement'!E12)+Assumptions!B$32*Assumptions!$B$6/1000 -> 65.455626 | F18: =E18-DCF!C14+(-'Income Statement'!F12)+Assumptions!C$32*Assumptions!$B$6/1000 -> 61.753722 | G18: =F18-DCF!D14+(-'Income Statement'!G12)+Assumptions!D$32*Assumptions!$B$6/1000 -> 55.700479 | H18: =G18-DCF!E14+(-'Income Statement'!H12)+Assumptions!E$32*Assumptions!$B$6/1000 -> 47.257623 | I18: =H18-DCF!F14+(-'Income Statement'!I12)+Assumptions!F$32*Assumptions!$B$6/1000 -> 36.378666 | J18: Forecast: − FCFF + net finance cost + dividends paid
A19: Net debt / EBITDA | B19: =B18/'Income Statement'!B7 -> 1.7447556 | C19: =C18/'Income Statement'!C7 -> 2.2656102 | D19: =D18/'Income Statement'!D7 -> 1.391178 | E19: =E18/'Income Statement'!E7 -> 1.2451503 | F19: =F18/'Income Statement'!F7 -> 1.0802112 | G19: =G18/'Income Statement'!G7 -> 0.90427133 | H19: =H18/'Income Statement'!H7 -> 0.71037546 | I19: =I18/'Income Statement'!I7 -> 0.51106844 | J19: Company-stated: 1.7× FY23, 2.2× FY24, 1.3× FY25

Sheet Cash Flow
A1: Cash flow — consolidated (EGP bn)
A2: FY24/FY25 as reported (FY2025 release); FY23 partially disclosed. Forecast is a simplified indirect build.
B4: FY23 | C4: FY24 | D4: FY25 | E4: FY26E | F4: FY27E | G4: FY28E | H4: FY29E | I4: FY30E | J4: Source / note
A5: Operating cash flow | B5: n/d | C5: 21.52 | D5: 37.624 | E5: ='Income Statement'!E14+'Income Statement'!E9-('Income Statement'!E11-Assumptions!B$34)-0.6 -> 29.71435 | F5: ='Income Statement'!F14+'Income Statement'!F9-('Income Statement'!F11-Assumptions!C$34)-0.6 -> 34.966006 | G5: ='Income Statement'!G14+'Income Statement'!G9-('Income Statement'!G11-Assumptions!D$34)-0.6 -> 39.767961 | H5: ='Income Statement'!H14+'Income Statement'!H9-('Income Statement'!H11-Assumptions!E$34)-0.6 -> 44.550089 | I5: ='Income Statement'!I14+'Income Statement'!I9-('Income Statement'!I11-Assumptions!F$34)-0.6 -> 49.163115 | J5: Forecast: NPAT + D&A − (VFE income − dividends) − ΔWC 0.6
A6: Investing cash flow | B6: n/d | C6: -31.546 | D6: -29.222 | E6: =-'Income Statement'!E5*Assumptions!B$33 -> -31.063178 | F6: =-'Income Statement'!F5*Assumptions!C$33 -> -31.541073 | G6: =-'Income Statement'!G5*Assumptions!D$33 -> -32.947279 | H6: =-'Income Statement'!H5*Assumptions!E$33 -> -34.035971 | I6: =-'Income Statement'!I5*Assumptions!F$33 -> -34.763104 | J6: Forecast = − cash capex (incl. licences)
A7: Financing cash flow | B7: n/d | C7: 6.922 | D7: -8.307 | E7: =-(E5+E6) -> 1.3488277 | F7: =-(F5+F6) -> -3.4249338 | G7: =-(G5+G6) -> -6.8206822 | H7: =-(H5+H6) -> -10.514117 | I7: =-(I5+I6) -> -14.400012 | J7: Forecast plug: cash held flat
A8: Net change in cash | B8: n/d | C8: =C5+C6+C7 -> -3.104 | D8: =D5+D6+D7 -> 0.095 | E8: =E5+E6+E7 -> 0 | F8: =F5+F6+F7 -> 0 | G8: =G5+G6+G7 -> 0 | H8: =H5+H6+H7 -> 0 | I8: =I5+I6+I7 -> 0
A9: Cash, end of period | B9: 10.443 | C9: 7.565 | D9: 7.685 | E9: =D9+E8 -> 7.685 | F9: =E9+F8 -> 7.685 | G9: =F9+G8 -> 7.685 | H9: =G9+H8 -> 7.685 | I9: =H9+I8 -> 7.685 | J9: FY23 = FY24 opening balance per FY25 CF statement
A10: Cash capex (incl. licences), memo | B10: 26.4 | C10: 35.1 | D10: 29.6 | E10: ='Income Statement'!E5*Assumptions!B$33 -> 31.063178 | F10: ='Income Statement'!F5*Assumptions!C$33 -> 31.541073 | G10: ='Income Statement'!G5*Assumptions!D$33 -> 32.947279 | H10: ='Income Statement'!H5*Assumptions!E$33 -> 34.035971 | I10: ='Income Statement'!I5*Assumptions!F$33 -> 34.763104 | J10: Company releases: FY23 26.4 · FY24 35.1 · FY25 29.6 (28% of sales)
A11: FCFF (core, DCF build), memo | B11: n/d | C11: -1.6 | D11: 21.1 | E11: =DCF!B14 -> 18.532514 | F11: =DCF!C14 -> 20.640287 | G11: =DCF!D14 -> 22.686574 | H11: =DCF!E14 -> 25.271136 | I11: =DCF!F14 -> 27.902187 | J11: FY25 release (company definition): 21.1 vs (1.6) FY24; forecast = the DCF sheet build

Sheet Summary Financials
A1: Summary financials — every cell links to the statement sheets (EGP bn)
B4: FY23 | C4: FY24 | D4: FY25 | E4: FY26E | F4: FY27E | G4: FY28E | H4: FY29E | I4: FY30E
A5: Revenue | B5: ='Income Statement'!B5 -> 56.7 | C5: ='Income Statement'!C5 -> 81.678 | D5: ='Income Statement'!D5 -> 106.673 | E5: ='Income Statement'!E5 -> 119.47376 | F5: ='Income Statement'!F5 -> 131.42114 | G5: ='Income Statement'!G5 -> 143.24904 | H5: ='Income Statement'!H5 -> 154.70896 | I5: ='Income Statement'!I5 -> 165.53859
A6: EBITDA | B6: ='Income Statement'!B7 -> 22.5 | C6: ='Income Statement'!C7 -> 32.623 | D6: ='Income Statement'!D7 -> 47.495 | E6: ='Income Statement'!E7 -> 52.568454 | F6: ='Income Statement'!F7 -> 57.168194 | G6: ='Income Statement'!G7 -> 61.597086 | H6: ='Income Statement'!H7 -> 66.524853 | I6: ='Income Statement'!I7 -> 71.181593
A7: NPAT | B7: ='Income Statement'!B14 -> 11.4988 | C7: ='Income Statement'!C14 -> 10.10016 | D7: ='Income Statement'!D14 -> 22.549275 | E7: ='Income Statement'!E14 -> 27.923287 | F7: ='Income Statement'!F14 -> 33.273838 | G7: ='Income Statement'!G14 -> 38.120466 | H7: ='Income Statement'!H14 -> 43.00971 | I7: ='Income Statement'!I14 -> 47.666696
A8: EPS (EGP) | B8: ='Income Statement'!B16 -> 6.0623876 | C8: ='Income Statement'!C16 -> 5.3249978 | D8: ='Income Statement'!D16 -> 11.88841 | E8: ='Income Statement'!E16 -> 14.721692 | F8: ='Income Statement'!F16 -> 17.542604 | G8: ='Income Statement'!G16 -> 20.09784 | H8: ='Income Statement'!H16 -> 22.675543 | I8: ='Income Statement'!I16 -> 25.130795
A9: Operating cash flow | B9: ='Cash Flow'!B5 -> n/d | C9: ='Cash Flow'!C5 -> 21.52 | D9: ='Cash Flow'!D5 -> 37.624 | E9: ='Cash Flow'!E5 -> 29.71435 | F9: ='Cash Flow'!F5 -> 34.966006 | G9: ='Cash Flow'!G5 -> 39.767961 | H9: ='Cash Flow'!H5 -> 44.550089 | I9: ='Cash Flow'!I5 -> 49.163115
A10: FCFF (memo) | B10: ='Cash Flow'!B11 -> n/d | C10: ='Cash Flow'!C11 -> -1.6 | D10: ='Cash Flow'!D11 -> 21.1 | E10: ='Cash Flow'!E11 -> 18.532514 | F10: ='Cash Flow'!F11 -> 20.640287 | G10: ='Cash Flow'!G11 -> 22.686574 | H10: ='Cash Flow'!H11 -> 25.271136 | I10: ='Cash Flow'!I11 -> 27.902187
A11: Net debt | B11: ='Balance Sheet'!B18 -> 39.257 | C11: ='Balance Sheet'!C18 -> 73.911 | D11: ='Balance Sheet'!D18 -> 66.074 | E11: ='Balance Sheet'!E18 -> 65.455626 | F11: ='Balance Sheet'!F18 -> 61.753722 | G11: ='Balance Sheet'!G18 -> 55.700479 | H11: ='Balance Sheet'!H18 -> 47.257623 | I11: ='Balance Sheet'!I18 -> 36.378666
A12: Equity | B12: ='Balance Sheet'!B15 -> 37.5 | C12: ='Balance Sheet'!C15 -> 45.938 | D12: ='Balance Sheet'!D15 -> 63.688 | E12: ='Balance Sheet'!E15 -> 88.197147 | F12: ='Balance Sheet'!F15 -> 117.0326 | G12: ='Balance Sheet'!G15 -> 149.51974 | H12: ='Balance Sheet'!H15 -> 185.70117 | I12: ='Balance Sheet'!I15 -> 225.34463

Sheet Monte Carlo
A1: Monte Carlo — the probabilistic price map (engine outputs, mc_v2, 50,000 paths, seed 42)
A2: Width: pooled log-HAR (lags 1/5/22) on a Yang-Zhang variance proxy · Shape: unit-variance Student-t(5) per-path mixture · Drift: EGX secular ON + factor layer. Paths diffuse from spot; the §1 value gap is kept out of the drift.
A4: Anchor (EGP) | B4: 92.61
A5: Annualized path vol (%) | B5: 38.3
A6: Secular drift, 3M (%) | B6: 9.7
A7: Continuous-factor drift, 3M (%) | B7: 2.3
A8: Discrete-event expectation, 3M (%) | B8: 2.2
A10: Percentile map (EGP/share)
A11: Horizon | B11: p5 | C11: p25 | D11: p50 | E11: p75 | F11: p95
A12: T+20 sessions | B12: 80.7 | C12: 90.5 | D12: 96.9 | E12: 103.7 | F12: 116.5
A13: T+60 sessions | B13: 77.5 | C13: 94.3 | D13: 106.3 | E13: 119.4 | F13: 145.3
A15: Level-touch ladder (running max/min)
A16: Level | B16: T+20 touch | C16: T+60 touch
A17: 120 | B17: 0.05 | C17: 0.33
A18: 113 | B18: 0.11 | C18: 0.49
A19: 105 | B19: 0.3 | C19: 0.7
A20: 100 | B20: 0.53 | C20: 0.83
A21: 95 | B21: 0.81 | C21: 0.94
A22: 90 | B22: 0.53 | C22: 0.62
A23: 85 | B23: 0.22 | C23: 0.34
A24: 80 | B24: 0.08 | C24: 0.18
A25: 75 | B25: 0.03 | C25: 0.1
A27: Probability zones at T+60
A28: Zone | B28: Range (EGP) | C28: Probability
A29: Deep downside | B29: < 75 | C29: 0.04
A30: Lower band | B30: 75–87 | C30: 0.1
A31: Around spot | B31: 87–100 | C31: 0.23
A32: Upper band | B32: 100–115 | C32: 0.31
A33: Strong upside | B33: > 115 | C33: 0.32
A35: Factor stack — 7 continuous + 9 discrete (judgment inputs, calibrated=False pending sign-off)
A36: Continuous factor | B36: 3M drift | D36: Discrete event | E36: Prob. | F36: Mean impact | G36: Spread
A37: CBE policy-rate path (easing) | B37: 0.012 | D37: Q2 2026 results (13 Aug) | E37: 0.85 | F37: 0.005 | G37: 0.04
A38: EGP/USD path (appreciation) | B38: -0.008 | D38: NTRA tariff implementation read-through | E38: 0.45 | F38: 0.02 | G38: 0.03
A39: Inflation / NTRA tariff pass-through | B39: 0.01 | D39: Government sell-down / placement (overhang) | E39: 0.25 | F39: -0.04 | G39: 0.04
A40: EGX30 & foreign flows | B40: 0.008 | D40: VFE monetization / stake headline | E40: 0.15 | F40: 0.06 | G40: 0.05
A41: Data demand / broadband ARPU | B41: 0.006 | D41: New EGP step-move (either direction) | E41: 0.2 | F41: 0.01 | G41: 0.06
A42: VFE earnings momentum | B42: 0.005 | D42: Dividend-policy / payout surprise | E42: 0.15 | F42: 0.015 | G42: 0.03
A43: Capex intensity / FCF drag | B43: -0.01 | D43: Red Sea / subsea disruption | E43: 0.25 | F43: -0.025 | G43: 0.04
D44: New cable / IRU / data-hub deal (Helios close) | E44: 0.45 | F44: 0.02 | G44: 0.03
D45: Index / MSCI flow event | E45: 0.25 | F45: 0.012 | G45: 0.03

Sheet Sensitivity
A1: SOTP sensitivity — VFE mark × complexity discount (EGP/share, post-discount, live formulas)
A3: Discount \ VFE P/E | B3: 6.5 | C3: 7 | D3: 7.5 | E3: 8 | F3: 8.5 | G3: 9 | H3: 9.5
A4: 0.05 | B4: =(Assumptions!$B$17*Assumptions!$B$18+Assumptions!$B$19/Assumptions!$B$20*B$3*Assumptions!$B$20+Assumptions!$B$22-Assumptions!$B$9)*(1-$A4)*1000/Assumptions!$B$6 -> 119.73293 | C4: =(Assumptions!$B$17*Assumptions!$B$18+Assumptions!$B$19/Assumptions!$B$20*C$3*Assumptions!$B$20+Assumptions!$B$22-Assumptions!$B$9)*(1-$A4)*1000/Assumptions!$B$6 -> 123.8511 | D4: =(Assumptions!$B$17*Assumptions!$B$18+Assumptions!$B$19/Assumptions!$B$20*D$3*Assumptions!$B$20+Assumptions!$B$22-Assumptions!$B$9)*(1-$A4)*1000/Assumptions!$B$6 -> 127.96927 | E4: =(Assumptions!$B$17*Assumptions!$B$18+Assumptions!$B$19/Assumptions!$B$20*E$3*Assumptions!$B$20+Assumptions!$B$22-Assumptions!$B$9)*(1-$A4)*1000/Assumptions!$B$6 -> 132.08744 | F4: =(Assumptions!$B$17*Assumptions!$B$18+Assumptions!$B$19/Assumptions!$B$20*F$3*Assumptions!$B$20+Assumptions!$B$22-Assumptions!$B$9)*(1-$A4)*1000/Assumptions!$B$6 -> 136.2056 | G4: =(Assumptions!$B$17*Assumptions!$B$18+Assumptions!$B$19/Assumptions!$B$20*G$3*Assumptions!$B$20+Assumptions!$B$22-Assumptions!$B$9)*(1-$A4)*1000/Assumptions!$B$6 -> 140.32377 | H4: =(Assumptions!$B$17*Assumptions!$B$18+Assumptions!$B$19/Assumptions!$B$20*H$3*Assumptions!$B$20+Assumptions!$B$22-Assumptions!$B$9)*(1-$A4)*1000/Assumptions!$B$6 -> 144.44194
A5: 0.1 | B5: =(Assumptions!$B$17*Assumptions!$B$18+Assumptions!$B$19/Assumptions!$B$20*B$3*Assumptions!$B$20+Assumptions!$B$22-Assumptions!$B$9)*(1-$A5)*1000/Assumptions!$B$6 -> 113.4312 | C5: =(Assumptions!$B$17*Assumptions!$B$18+Assumptions!$B$19/Assumptions!$B$20*C$3*Assumptions!$B$20+Assumptions!$B$22-Assumptions!$B$9)*(1-$A5)*1000/Assumptions!$B$6 -> 117.33262 | D5: =(Assumptions!$B$17*Assumptions!$B$18+Assumptions!$B$19/Assumptions!$B$20*D$3*Assumptions!$B$20+Assumptions!$B$22-Assumptions!$B$9)*(1-$A5)*1000/Assumptions!$B$6 -> 121.23404 | E5: =(Assumptions!$B$17*Assumptions!$B$18+Assumptions!$B$19/Assumptions!$B$20*E$3*Assumptions!$B$20+Assumptions!$B$22-Assumptions!$B$9)*(1-$A5)*1000/Assumptions!$B$6 -> 125.13547 | F5: =(Assumptions!$B$17*Assumptions!$B$18+Assumptions!$B$19/Assumptions!$B$20*F$3*Assumptions!$B$20+Assumptions!$B$22-Assumptions!$B$9)*(1-$A5)*1000/Assumptions!$B$6 -> 129.03689 | G5: =(Assumptions!$B$17*Assumptions!$B$18+Assumptions!$B$19/Assumptions!$B$20*G$3*Assumptions!$B$20+Assumptions!$B$22-Assumptions!$B$9)*(1-$A5)*1000/Assumptions!$B$6 -> 132.93831 | H5: =(Assumptions!$B$17*Assumptions!$B$18+Assumptions!$B$19/Assumptions!$B$20*H$3*Assumptions!$B$20+Assumptions!$B$22-Assumptions!$B$9)*(1-$A5)*1000/Assumptions!$B$6 -> 136.83973
A6: 0.15 | B6: =(Assumptions!$B$17*Assumptions!$B$18+Assumptions!$B$19/Assumptions!$B$20*B$3*Assumptions!$B$20+Assumptions!$B$22-Assumptions!$B$9)*(1-$A6)*1000/Assumptions!$B$6 -> 107.12947 | C6: =(Assumptions!$B$17*Assumptions!$B$18+Assumptions!$B$19/Assumptions!$B$20*C$3*Assumptions!$B$20+Assumptions!$B$22-Assumptions!$B$9)*(1-$A6)*1000/Assumptions!$B$6 -> 110.81414 | D6: =(Assumptions!$B$17*Assumptions!$B$18+Assumptions!$B$19/Assumptions!$B$20*D$3*Assumptions!$B$20+Assumptions!$B$22-Assumptions!$B$9)*(1-$A6)*1000/Assumptions!$B$6 -> 114.49882 | E6: =(Assumptions!$B$17*Assumptions!$B$18+Assumptions!$B$19/Assumptions!$B$20*E$3*Assumptions!$B$20+Assumptions!$B$22-Assumptions!$B$9)*(1-$A6)*1000/Assumptions!$B$6 -> 118.1835 | F6: =(Assumptions!$B$17*Assumptions!$B$18+Assumptions!$B$19/Assumptions!$B$20*F$3*Assumptions!$B$20+Assumptions!$B$22-Assumptions!$B$9)*(1-$A6)*1000/Assumptions!$B$6 -> 121.86817 | G6: =(Assumptions!$B$17*Assumptions!$B$18+Assumptions!$B$19/Assumptions!$B$20*G$3*Assumptions!$B$20+Assumptions!$B$22-Assumptions!$B$9)*(1-$A6)*1000/Assumptions!$B$6 -> 125.55285 | H6: =(Assumptions!$B$17*Assumptions!$B$18+Assumptions!$B$19/Assumptions!$B$20*H$3*Assumptions!$B$20+Assumptions!$B$22-Assumptions!$B$9)*(1-$A6)*1000/Assumptions!$B$6 -> 129.23752
A7: 0.2 | B7: =(Assumptions!$B$17*Assumptions!$B$18+Assumptions!$B$19/Assumptions!$B$20*B$3*Assumptions!$B$20+Assumptions!$B$22-Assumptions!$B$9)*(1-$A7)*1000/Assumptions!$B$6 -> 100.82773 | C7: =(Assumptions!$B$17*Assumptions!$B$18+Assumptions!$B$19/Assumptions!$B$20*C$3*Assumptions!$B$20+Assumptions!$B$22-Assumptions!$B$9)*(1-$A7)*1000/Assumptions!$B$6 -> 104.29566 | D7: =(Assumptions!$B$17*Assumptions!$B$18+Assumptions!$B$19/Assumptions!$B$20*D$3*Assumptions!$B$20+Assumptions!$B$22-Assumptions!$B$9)*(1-$A7)*1000/Assumptions!$B$6 -> 107.76359 | E7: =(Assumptions!$B$17*Assumptions!$B$18+Assumptions!$B$19/Assumptions!$B$20*E$3*Assumptions!$B$20+Assumptions!$B$22-Assumptions!$B$9)*(1-$A7)*1000/Assumptions!$B$6 -> 111.23153 | F7: =(Assumptions!$B$17*Assumptions!$B$18+Assumptions!$B$19/Assumptions!$B$20*F$3*Assumptions!$B$20+Assumptions!$B$22-Assumptions!$B$9)*(1-$A7)*1000/Assumptions!$B$6 -> 114.69946 | G7: =(Assumptions!$B$17*Assumptions!$B$18+Assumptions!$B$19/Assumptions!$B$20*G$3*Assumptions!$B$20+Assumptions!$B$22-Assumptions!$B$9)*(1-$A7)*1000/Assumptions!$B$6 -> 118.16739 | H7: =(Assumptions!$B$17*Assumptions!$B$18+Assumptions!$B$19/Assumptions!$B$20*H$3*Assumptions!$B$20+Assumptions!$B$22-Assumptions!$B$9)*(1-$A7)*1000/Assumptions!$B$6 -> 121.63532
A8: 0.25 | B8: =(Assumptions!$B$17*Assumptions!$B$18+Assumptions!$B$19/Assumptions!$B$20*B$3*Assumptions!$B$20+Assumptions!$B$22-Assumptions!$B$9)*(1-$A8)*1000/Assumptions!$B$6 -> 94.526001 | C8: =(Assumptions!$B$17*Assumptions!$B$18+Assumptions!$B$19/Assumptions!$B$20*C$3*Assumptions!$B$20+Assumptions!$B$22-Assumptions!$B$9)*(1-$A8)*1000/Assumptions!$B$6 -> 97.777185 | D8: =(Assumptions!$B$17*Assumptions!$B$18+Assumptions!$B$19/Assumptions!$B$20*D$3*Assumptions!$B$20+Assumptions!$B$22-Assumptions!$B$9)*(1-$A8)*1000/Assumptions!$B$6 -> 101.02837 | E8: =(Assumptions!$B$17*Assumptions!$B$18+Assumptions!$B$19/Assumptions!$B$20*E$3*Assumptions!$B$20+Assumptions!$B$22-Assumptions!$B$9)*(1-$A8)*1000/Assumptions!$B$6 -> 104.27956 | F8: =(Assumptions!$B$17*Assumptions!$B$18+Assumptions!$B$19/Assumptions!$B$20*F$3*Assumptions!$B$20+Assumptions!$B$22-Assumptions!$B$9)*(1-$A8)*1000/Assumptions!$B$6 -> 107.53074 | G8: =(Assumptions!$B$17*Assumptions!$B$18+Assumptions!$B$19/Assumptions!$B$20*G$3*Assumptions!$B$20+Assumptions!$B$22-Assumptions!$B$9)*(1-$A8)*1000/Assumptions!$B$6 -> 110.78192 | H8: =(Assumptions!$B$17*Assumptions!$B$18+Assumptions!$B$19/Assumptions!$B$20*H$3*Assumptions!$B$20+Assumptions!$B$22-Assumptions!$B$9)*(1-$A8)*1000/Assumptions!$B$6 -> 114.03311
A10: Every 1.0× on the VFE mark ≈ EGP 7.4/share post-discount; every 5pp of discount ≈ EGP 7.0/share.

Sheet Per-Share & Ratios
A1: Per-share and ratios
B4: FY23 | C4: FY24 | D4: FY25 | E4: FY26E | F4: FY27E | G4: FY28E | H4: FY29E | I4: FY30E
A5: EPS (EGP) | B5: ='Income Statement'!B16 -> 6.0623876 | C5: ='Income Statement'!C16 -> 5.3249978 | D5: ='Income Statement'!D16 -> 11.88841 | E5: ='Income Statement'!E16 -> 14.721692 | F5: ='Income Statement'!F16 -> 17.542604 | G5: ='Income Statement'!G16 -> 20.09784 | H5: ='Income Statement'!H16 -> 22.675543 | I5: ='Income Statement'!I16 -> 25.130795
A6: DPS (EGP) | B6: n/d | C6: 1.5 | D6: 1.5 | E6: =Assumptions!B$32 -> 2 | F6: =Assumptions!C$32 -> 2.6 | G6: =Assumptions!D$32 -> 3.3 | H6: =Assumptions!E$32 -> 4 | I6: =Assumptions!F$32 -> 4.7 | J6: DPS FY24/FY25 EGP 1.50 declared (paid 30 Apr 2026)
A7: Payout (DPS/EPS) | B7: =IFERROR(B6/B5,"") | C7: =IFERROR(C6/C5,"") -> 0.28169026 | D7: =IFERROR(D6/D5,"") -> 0.12617331 | E7: =IFERROR(E6/E5,"") -> 0.13585395 | F7: =IFERROR(F6/F5,"") -> 0.1482106 | G7: =IFERROR(G6/G5,"") -> 0.16419675 | H7: =IFERROR(H6/H5,"") -> 0.17640151 | I7: =IFERROR(I6/I5,"") -> 0.18702154
A8: BVPS (EGP) | B8: ='Balance Sheet'!B15*1000/Assumptions!$B$6 -> 21.967465 | C8: ='Balance Sheet'!C15*1000/Assumptions!$B$6 -> 26.910437 | D8: ='Balance Sheet'!D15*1000/Assumptions!$B$6 -> 37.30837 | E8: ='Balance Sheet'!E15*1000/Assumptions!$B$6 -> 51.665806 | F8: ='Balance Sheet'!F15*1000/Assumptions!$B$6 -> 68.557589 | G8: ='Balance Sheet'!G15*1000/Assumptions!$B$6 -> 87.588522 | H8: ='Balance Sheet'!H15*1000/Assumptions!$B$6 -> 108.78357 | I8: ='Balance Sheet'!I15*1000/Assumptions!$B$6 -> 132.00667
A9: P/E at spot | B9: =Assumptions!$B$5/'Income Statement'!B16 -> 15.27616 | C9: =Assumptions!$B$5/'Income Statement'!C16 -> 17.391556 | D9: =Assumptions!$B$5/'Income Statement'!D16 -> 7.7899402 | E9: =Assumptions!$B$5/'Income Statement'!E16 -> 6.2907172 | F9: =Assumptions!$B$5/'Income Statement'!F16 -> 5.2791477 | G9: =Assumptions!$B$5/'Income Statement'!G16 -> 4.6079579 | H9: =Assumptions!$B$5/'Income Statement'!H16 -> 4.084136 | I9: =Assumptions!$B$5/'Income Statement'!I16 -> 3.6851202
A10: EV/EBITDA at spot (core) | B10: =(Assumptions!$B$5*Assumptions!$B$6/1000+'Balance Sheet'!B18)/'Income Statement'!B7 -> 8.7710557 | C10: =(Assumptions!$B$5*Assumptions!$B$6/1000+'Balance Sheet'!C18)/'Income Statement'!C7 -> 7.1116314 | D10: =(Assumptions!$B$5*Assumptions!$B$6/1000+'Balance Sheet'!D18)/'Income Statement'!D7 -> 4.7197758 | E10: =(Assumptions!$B$5*Assumptions!$B$6/1000+'Balance Sheet'!E18)/'Income Statement'!E7 -> 4.2525005 | F10: =(Assumptions!$B$5*Assumptions!$B$6/1000+'Balance Sheet'!F18)/'Income Statement'!F7 -> 3.8455907 | G10: =(Assumptions!$B$5*Assumptions!$B$6/1000+'Balance Sheet'!G18)/'Income Statement'!G7 -> 3.4708173 | H10: =(Assumptions!$B$5*Assumptions!$B$6/1000+'Balance Sheet'!H18)/'Income Statement'!H7 -> 3.0868069 | I10: =(Assumptions!$B$5*Assumptions!$B$6/1000+'Balance Sheet'!I18)/'Income Statement'!I7 -> 2.7320324
A11: FCFF yield on EV | B11: =IFERROR('Cash Flow'!B11/(Assumptions!$B$5*Assumptions!$B$6/1000+'Balance Sheet'!B18),"n/d") -> n/d | C11: =IFERROR('Cash Flow'!C11/(Assumptions!$B$5*Assumptions!$B$6/1000+'Balance Sheet'!C18),"n/d") -> -0.0068964699 | D11: =IFERROR('Cash Flow'!D11/(Assumptions!$B$5*Assumptions!$B$6/1000+'Balance Sheet'!D18),"n/d") -> 0.094126778 | E11: =IFERROR('Cash Flow'!E11/(Assumptions!$B$5*Assumptions!$B$6/1000+'Balance Sheet'!E18),"n/d") -> 0.08290195 | F11: =IFERROR('Cash Flow'!F11/(Assumptions!$B$5*Assumptions!$B$6/1000+'Balance Sheet'!F18),"n/d") -> 0.09388543 | G11: =IFERROR('Cash Flow'!G11/(Assumptions!$B$5*Assumptions!$B$6/1000+'Balance Sheet'!G18),"n/d") -> 0.10611505 | H11: =IFERROR('Cash Flow'!H11/(Assumptions!$B$5*Assumptions!$B$6/1000+'Balance Sheet'!H18),"n/d") -> 0.1230641 | I11: =IFERROR('Cash Flow'!I11/(Assumptions!$B$5*Assumptions!$B$6/1000+'Balance Sheet'!I18),"n/d") -> 0.14347779
A12: ROE | B12: ='Income Statement'!B14/'Balance Sheet'!B15 -> 0.30663467 | C12: ='Income Statement'!C14/'Balance Sheet'!C15 -> 0.21986504 | D12: ='Income Statement'!D14/'Balance Sheet'!D15 -> 0.35405846 | E12: ='Income Statement'!E14/'Balance Sheet'!E15 -> 0.3166008 | F12: ='Income Statement'!F14/'Balance Sheet'!F15 -> 0.28431255 | G12: ='Income Statement'!G14/'Balance Sheet'!G15 -> 0.25495273 | H12: ='Income Statement'!H14/'Balance Sheet'!H15 -> 0.2316071 | I12: ='Income Statement'!I14/'Balance Sheet'!I15 -> 0.21152798
A13: Net debt / EBITDA | B13: ='Balance Sheet'!B19 -> 1.7447556 | C13: ='Balance Sheet'!C19 -> 2.2656102 | D13: ='Balance Sheet'!D19 -> 1.391178 | E13: ='Balance Sheet'!E19 -> 1.2451503 | F13: ='Balance Sheet'!F19 -> 1.0802112 | G13: ='Balance Sheet'!G19 -> 0.90427133 | H13: ='Balance Sheet'!H19 -> 0.71037546 | I13: ='Balance Sheet'!I19 -> 0.51106844

Sheet Peer & Sector
A1: Peer set, sector structure, and risks
A4: Peer | B4: Market | C4: Typical EV/EBITDA | D4: Typical P/E | E4: Note
A5: Vodacom Group | B5: JSE | C5: 4.0–5.0× | D5: 9–11× | E5: Owns 55% of VFE; the natural read-across for the stake
A6: stc (Saudi Telecom) | B6: Tadawul | C6: 7–8× | D6: 15–17× | E6: GCC quality premium
A7: e& (Etisalat) | B7: ADX | C7: 5.5–6.5× | D7: 10–12× | E7: Regional incumbent
A8: Ooredoo | B8: QSE | C8: 4.5–5.5× | D8: 10–12× | E8: MENA multi-market
A9: Turk Telekom | B9: BIST | C9: 3–4× | D9: 5–8× | E9: High-inflation EM incumbent — closest macro analogue
A10: Mobily | B10: Tadawul | C10: 6–7× | D10: 13–15× | E10: Mobile pure-play
A12: Egypt market structure
A13: Mobile: Vodafone Egypt (~42–43% share) · Orange Egypt · e& Egypt · WE (Telecom Egypt, ~10–13%)
A14: Fixed: Telecom Egypt is the monopoly fixed-line and fibre incumbent; wholesale to all MNOs
A15: Subsea: Egypt carries a dominant share of Europe–Asia traffic; TE lands/operates the corridor (SEA-ME-WE, AAE, Coral Bridge)
A17: Principal risks
A18: State sell-down overhang (70% MoF holding under the divestment programme)
A19: EGP regime: appreciation cuts USD wholesale; a new step-devaluation resets costs and FX losses
A20: NTRA / regulatory pricing risk in both directions
A21: Capex intensity: cash capex ~28–31% of sales suppresses FCF
A22: VFE mark is judgmental — associate, unlisted, one 2022 transaction reference
A23: Red Sea / subsea geopolitical disruption
