Workbook

Sheet READ FIRST
A1: Testahil — GB Corp S.A.E. (EGX: GBCO)
A3: Companion model · Independent Valuation Study · Educational analysis · Not investment advice
A5: What this workbook is. A transparent companion to the GBCO valuation study. Every blue cell is an input; every
A6: black cell is a formula; green cells link across sheets. All inputs live on the Assumptions sheet — change one
A7: (the complexity discount, the Auto gross margin, a growth rate, the GB Capital multiple) and the whole model reprices.
A9: What it is not. It is not investment advice, a recommendation, or a price target. Values are model outputs shown
A10: as ranges. The preparer is not licensed by any securities regulator and may hold a position in the security.
A12: Entity note. GB Corp S.A.E. (formerly GB Auto / Ghabbour Auto; renamed March 2023) is an operating company with a
A13: captive finance arm: GB Auto (passenger cars, CV&CE, trading, light mobility; Egypt · Iraq · Jordan) plus GB Capital
A14: (leasing, factoring, consumer finance, SME lending) and associate stakes in MNT-Halan, Bedaya and Kaf.
A15: House lens: split the legs — Auto = FCFF DCF; captive lender = adjusted book × a return-justified multiple;
A16: the fintech associate = balance-sheet carrying value cross-checked to the June-2026 USD 1.4bn funding round.
... A23: Income Statement · Balance Sheet · Cash Flow · Summary Financials · Monte Carlo · Sensitivity · Per-Share & Ratios · Peer & Sector.

Sheet Summary
A1: Valuation summary — GB Corp (EGX: GBCO)
A2: Four-lens fair value vs spot. Base links live; bear/bull are scenario outputs (study §1.5).
B5: Bear | C5: Base | D5: Bull | E5: Weight
A6: Sum-of-the-parts (split legs) | B6: 20.9 | C6: =SOTP!C14 -> 38.380081 | D6: 60.8 | E6: =Assumptions!B32 -> 0.4
A7: Pre-discount NAV (DCF-anchored) | B7: 25.5 | C7: =SOTP!C11 -> 42.644535 | D7: 63.3 | E7: =Assumptions!B33 -> 0.15
A8: Relative multiples | B8: 24.3 | C8: ='Relative & Normalized'!C6 -> 28.8807 | D8: 33.4 | E8: =Assumptions!B34 -> 0.2
A9: Normalized earnings | B9: 24.9 | C9: ='Relative & Normalized'!C9 -> 32.88807 | D9: 42 | E9: =Assumptions!B35 -> 0.25
A10: Weighted central | B10: =SUMPRODUCT(B6:B9,$E$6:$E$9) -> 23.27 | C10: =SUMPRODUCT(C6:C9,$E$6:$E$9) -> 35.74687 | D10: =SUMPRODUCT(D6:D9,$E$6:$E$9) -> 50.995
A12: Spot price (EGP) | B12: =Assumptions!B5 -> 31.25
A13: Upside to central base | B13: =C10/Assumptions!B5-1 -> 0.14389984
A15: Read: roughly fairly valued — the price already pays for the recovery; the swing is Auto cash conversion (working capital), the Egyptian nominal rate path, and the complexity discount.

Sheet Fundamental Valuation
A1: Fundamental valuation — football-field data
A2: Bear/base/bull per lens (links to Summary).
A5: Lens | B5: Bear | C5: Base | D5: Bull
A6: Sum-of-the-parts (split legs) | B6: =Summary!B6 -> 20.9 | C6: =Summary!C6 -> 38.380081 | D6: =Summary!D6 -> 60.8
A7: Pre-discount NAV (DCF-anchored) | B7: =Summary!B7 -> 25.5 | C7: =Summary!C7 -> 42.644535 | D7: =Summary!D7 -> 63.3
A8: Relative multiples | B8: =Summary!B8 -> 24.3 | C8: =Summary!C8 -> 28.8807 | D8: =Summary!D8 -> 33.4
A9: Normalized earnings | B9: =Summary!B9 -> 24.9 | C9: =Summary!C9 -> 32.88807 | D9: =Summary!D9 -> 42
A10: Weighted central | B10: =Summary!B10 -> 23.27 | C10: =Summary!C10 -> 35.74687 | D10: =Summary!D10 -> 50.995
A11: Spot | B11: =Assumptions!B5 -> 31.25

Sheet Assumptions
A1: Assumptions — the single input layer
A2: All blue cells are inputs. Every other sheet links here.
A4: ANCHORS
A5: Spot price (EGP/share) | B5: 31.25
A6: Shares outstanding (mn) | B6: 1085.5
A7: Tax rate | B7: 0.28
A8: COST OF CAPITAL — bottom-up, sourced (house rule §3.5-G, rebuilt 09-07-2026; full detail row 82+)
A9: Risk-free rate (Egypt 10Y local govt bond, 3-Jul-2026) | B9: 0.2255 | C9: SOURCE: investing.com, "Egypt 10-Year Bond Yield Historical Data" — market quote, per Damodaran's own stated method (use the local bond yield directly when a liquid local market exists).
A10: Equity beta (see row 86 for why =1.0) | B10: 1 | C10: CORRECTED 09-07-2026: was 0.95 (unsourced "house band" guess). A genuine GBCO-vs-EGX30 regression was attempted (n=5 annual: beta=-0.15, R2=0.008, unusable; higher-frequency EGX30 data inaccessible via available tools) and rejected. Beta=1.0 per standing instruction when no reliable regression is obtainable — see wacc_builder.py.
A11: Equity risk premium — Egypt, CDS-based (primary; rating-based alt. at row 84) | B11: 0.0941 | C11: CORRECTED 09-07-2026: was 0.07 (flat unsourced house number), then briefly 0.1487 (WRONG — a secondary source's misquote). Verified against Damodaran's own ORIGINAL file (ctryprem.html), Egypt row, "Last updated January 2026": country risk premium 9.71% + mature-market ERP 4.23% = 13.94%.
A12: Cost of equity Ke = rf + β × ERP | B12: =B9+B10*B11 -> 0.3196 | C12: Same Damodaran original file, CDS column — uses Egypt's actual sovereign CDS spread (3.41%), more current than the rating-based figure since CDS prices continuously.
A13: Pre-tax cost of debt (EGP; ~100% of debt is EGP-denominated, row 88) | B13: 0.207 | C13: Primary Ke, used in the base-case WACC below.
A14: After-tax Kd | B14: =B13*(1-B7) -> 0.14904
A15: Debt weight D/(D+E) — sourced, row 89 | B15: =38041.4/(31.25*1085.5+38041.4) -> 0.52862241 | C15: CORRECTED 09-07-2026: was 0.21 (flat unsourced guess). SOURCE: CBE weighted-average EGP bank lending rate, <12mo tenor, Feb-2026 (CEIC/TradingEconomics quoting CBE); cross-checked against CBE's own overnight lending-rate ceiling 20.0% (held since the Apr-2026 policy pause). Currency mix: 5 separately disclosed GB Corp/GB Capital financing facilities found (Drive Finance EGP5bn syndication, Ghabbour Egypt EGP1.2bn Sadat facility, GB Lease EGP4.16bn securitization, Drive Finance EGP2.4bn bond, GB Capital Securitization EGP28.8bn book) are ALL EGP-denominated; zero USD facilities found in any search — treated as ~100% local currency.
A16: WACC | B16: =(1-B15)*B12+B15*B14 -> 0.22943816
A17: Terminal growth (nominal EGP) | B17: 0.115 | C17: CORRECTED 09-07-2026: was 0.35 (assumed, not computed). Market cap = spot(31.25) x shares(1,085.5mn) = 33,922; total debt = FY25 disclosed consolidated borrowings (38,041.4). D/(D+E) = 38,041.4/(33,922+38,041.4).
A18: SOTP — the three legs (split-the-legs, §3.5-F5) | B18: =(1-B17)*B13+B17*B16 -> 0.20958039
A19: GB Auto net debt (31 Dec 2025) | B19: 15210 | C19: disclosed; 1Q26 ND/EBITDA 2.14x
A20: GB Auto non-controlling interests | B20: 800.4
A21: GB Capital adjusted operating equity | B21: 9500 | C21: from disclosed adjusted-ROAE basis (NP 1,366 / 15.1%)
A22: GB Capital multiple (× adjusted book) | B22: 1 | C22: return-justified ~1× book
A23: Associates carrying value (MNT-Halan + Bedaya + Kaf) | B23: =B79+B80 -> 28060.65 | C23: FY25 carrying 13,689.5 — split in the MNT-Halan detail block (rows 75–80)
A24: Associates mark (× carrying) | B24: 1
A25: Complexity / conglomerate discount | B25: 0.1 | C25: sensitized 0–20%
A26: RELATIVE & NORMALIZED
A27: FY26E group net profit for the relative lens | B27: 3300 | C27: aligned to the IS build (≈ EGP 3.3bn FY26E)
A28: Justified P/E (base) | B28: 9.5
A29: Mid-cycle group PAT (normalized) | B29: 4200
A30: Justified through-cycle P/E | B30: 8.5
A31: SYNTHESIS WEIGHTS
A32: SOTP weight | B32: 0.4
A33: Pre-discount NAV weight | B33: 0.15
A34: Relative weight | B34: 0.2
A35: Normalized-earnings weight | B35: 0.25
A36: MONTE CARLO (YZ-HAR v2 — no KVOL; engine outputs on the Monte Carlo sheet)
A37: Anchor volatility (HAR forecast, annualized) | B37: 0.4957
A38: Secular drift (daily log-return, expanding window) | B38: 0.00164
A39: Net factor drift per quarter (16-factor stack) | B39: 0.0146
A40: Paths / seed | B40: 50,000 / 42
A41: FORECAST DRIVERS (FY26E–FY30E) — units × ASP build; drivers disclosed
...

Sheet SOTP
A1: Sum-of-the-parts — split the legs (primary lens, §3.5-F5)
A2: Auto = FCFF DCF · captive lender = adjusted book × multiple · fintech associate = carrying value ≈ Jun-26 round. Links to DCF / Assumptions.
A5: Leg | B5: Basis | C5: Value (EGP mn)
A6: GB Auto operating leg | B6: FCFF DCF (§1.2): EV − net debt − NCI | C6: =DCF!B25 -> 8729.9922
A7: GB Capital lending leg | B7: Adjusted operating book 9,500 × 1.0× | C7: =Assumptions!B21*Assumptions!B22 -> 9500
A8: Associate — MNT-Halan (~20% est.) | B8: USD 1.4bn Jun-26 round × stake × FX, × mark | C8: =Assumptions!B79*Assumptions!B24 -> 27670.65
A9: Other associates (Bedaya, Kaf) | B9: Residual carrying value × mark | C9: =Assumptions!B80*Assumptions!B24 -> 390
A10: Σ Equity value (pre-discount) | C10: =SUM(C6:C9) -> 46290.642
A11: per share (EGP), pre-discount | C11: =C10/Assumptions!B6 -> 42.644535
A12: less: complexity / conglomerate discount | B12: applied | C12: =-C10*Assumptions!B25 -> -4629.0642
A13: SOTP equity value | C13: =C10+C12 -> 41661.578
A14: SOTP fair value per share (EGP) | C14: =C13/Assumptions!B6 -> 38.380081
A15: Upside / (downside) vs spot | C15: =C14/Assumptions!B5-1 -> 0.22816259
A16: memo: MNT-Halan share of SOTP value | B16: C8 ÷ Σ legs (discount pro-rata) | C16: =C8/C10 -> 0.59775904
A17: memo: MNT-Halan per share, post-discount (EGP) | C17: =C8*(1-Assumptions!B25)/Assumptions!B6 -> 22.942041
A19: The market-implied read: mkt cap − lender − associates ≈ EGP 10.7bn for the Auto leg ≈ 4.0× FY26E Auto EBITDA. Roughly a third of the market value is the MNT-Halan stake, marked to a first-close price.
A20: MNT-Halan stake sensitivity — now largely resolved: 41.61% is a confirmed, dated figure (9-Jun-2026)
A21: GB stake in MNT-Halan | B21: MNT-Halan value (EGP mn) | C21: SOTP fair value/sh (EGP)
A22: 0.2 | B22: =A22*Assumptions!$B$76*Assumptions!$B$78 -> 13300 | C22: =((DCF!$B$25)+B22+Assumptions!$B$80+Assumptions!$B$21*Assumptions!$B$22)*(1-Assumptions!$B$25)/Assumptions!$B$6 -> 26.465217 | D22: prior placeholder (wrong)
A23: 0.25 | B23: =A23*Assumptions!$B$76*Assumptions!$B$78 -> 16625 | C23: =((DCF!$B$25)+B23+Assumptions!$B$80+Assumptions!$B$21*Assumptions!$B$22)*(1-Assumptions!$B$25)/Assumptions!$B$6 -> 29.222011
A24: 0.3 | B24: =A24*Assumptions!$B$76*Assumptions!$B$78 -> 19950 | C24: =((DCF!$B$25)+B24+Assumptions!$B$80+Assumptions!$B$21*Assumptions!$B$22)*(1-Assumptions!$B$25)/Assumptions!$B$6 -> 31.978805
A25: 0.3545 | B25: =A25*Assumptions!$B$76*Assumptions!$B$78 -> 23574.25 | C25: =((DCF!$B$25)+B25+Assumptions!$B$80+Assumptions!$B$21*Assumptions!$B$22)*(1-Assumptions!$B$25)/Assumptions!$B$6 -> 34.983711 | D25: implied by pro-rata defense of the 2024 raise only
A26: 0.4 | B26: =A26*Assumptions!$B$76*Assumptions!$B$78 -> 26600 | C26: =((DCF!$B$25)+B26+Assumptions!$B$80+Assumptions!$B$21*Assumptions!$B$22)*(1-Assumptions!$B$25)/Assumptions!$B$6 -> 37.492393
A27: 0.4258 | B27: =A27*Assumptions!$B$76*Assumptions!$B$78 -> 28315.7 | C27: =((DCF!$B$25)+B27+Assumptions!$B$80+Assumptions!$B$21*Assumptions!$B$22)*(1-Assumptions!$B$25)/Assumptions!$B$6 -> 38.914899 | D27: superseded — was the pre-transaction figure (28-Jul-2024)
A28: 0.4161 | B28: =A28*Assumptions!$B$76*Assumptions!$B$78 -> 27670.65 | C28: =((DCF!$B$25)+B28+Assumptions!$B$80+Assumptions!$B$21*Assumptions!$B$22)*(1-Assumptions!$B$25)/Assumptions!$B$6 -> 38.380081 | D28: CONFIRMED current (GB Corp PR, 9-Jun-2026, post Al Ahly round) — base case
A29: Every 5pp of stake ≈ EGP 3.3/share of SOTP fair value — by far the single largest swing factor in this study; confirm the FY25 annual-report associates footnote before relying on any point estimate.

Sheet Segments
A1: Segment view — the units × ASP build
A2: Volumes and ASP per line of business, FY23–FY30E. Drivers disclosed in company releases; forecast links to Assumptions.
B4: FY23 | C4: FY24 | D4: FY25 | E4: FY26E | F4: FY27E | G4: FY28E | H4: FY29E | I4: FY30E
A6: PC volume (units) | B6: 26994 | C6: 42043 | D6: 56548 | E6: =D6*(1+Assumptions!$C$43) -> 63333.76 | F6: =E6*(1+Assumptions!$D$43) -> 72200.486 | G6: =F6*(1+Assumptions!$E$43) -> 79420.535 | H6: =G6*(1+Assumptions!$F$43) -> 85774.178 | I6: =H6*(1+Assumptions!$G$43) -> 90920.629
A7: PC volume (units) | B7: 26994 | C7: 42043 | D7: 56548 | E7: =D7*(1+Assumptions!$C$43) -> 63333.76 | F7: =E7*(1+Assumptions!$D$43) -> 72200.486 | G7: =F7*(1+Assumptions!$E$43) -> 79420.535 | H7: =G7*(1+Assumptions!$F$43) -> 85774.178 | I7: =H7*(1+Assumptions!$G$43) -> 90920.629
A8: PC revenue | B8: 16544.3 | C8: 36533.4 | D8: 52827.3 | E8: =E7*E9 -> 62716.571 | F8: =F7*F9 -> 76501.673 | G8: =G7*G9 -> 90042.469 | H8: =H7*H9 -> 103080.62 | I8: =I7*I9 -> 115821.38
A9: PC ASP (EGP mn/unit) | B9: =B8/B7 -> 0.61288805 | C9: =C8/C7 -> 0.86895321 | D9: =D8/D7 -> 0.9342028 | E9: =D9*(1+Assumptions!$C$44) -> 0.99025497 | F9: =E9*(1+Assumptions!$D$44) -> 1.0595728 | G9: =F9*(1+Assumptions!$E$44) -> 1.1337429 | H9: =G9*(1+Assumptions!$F$44) -> 1.2017675 | I9: =H9*(1+Assumptions!$G$44) -> 1.2738735
A10: CV&CE volume (units) | B10: 2273 | C10: 2096 | D10: 3404 | E10: =D10*(1+Assumptions!$C$45) -> 4255 | F10: =E10*(1+Assumptions!$D$45) -> 5020.9 | G10: =F10*(1+Assumptions!$E$45) -> 5623.408 | H10: =G10*(1+Assumptions!$F$45) -> 6185.7488 | I10: =H10*(1+Assumptions!$G$45) -> 6680.6087
A11: CV&CE revenue | B11: 2323 | C11: 3984.5 | D11: 5956.8 | E11: =D11*(1+Assumptions!$C$45)*(1+Assumptions!$C$46) -> 7818.3 | F11: =E11*(1+Assumptions!$D$45)*(1+Assumptions!$D$46) -> 9686.8737 | G11: =F11*(1+Assumptions!$E$45)*(1+Assumptions!$E$46) -> 11391.763 | H11: =G11*(1+Assumptions!$F$45)*(1+Assumptions!$F$46) -> 13157.487 | I11: =H11*(1+Assumptions!$G$45)*(1+Assumptions!$G$46) -> 14920.59
A12: Light-Mobility volume (units) | B12: 13610 | C12: 20189 | D12: 33906 | E12: =D12*(1+Assumptions!$C$47) -> 44077.8 | F12: =E12*(1+Assumptions!$D$47) -> 52893.36 | G12: =F12*(1+Assumptions!$E$47) -> 60827.364 | H12: =G12*(1+Assumptions!$F$47) -> 68126.648 | I12: =H12*(1+Assumptions!$G$47) -> 74939.312
A13: Light-Mobility revenue | B13: 854.2 | C13: 1378.2 | D13: 2203.8 | E13: =D13*(1+Assumptions!$C$47)*(1+Assumptions!$C$48) -> 3008.187 | F13: =E13*(1+Assumptions!$D$47)*(1+Assumptions!$D$48) -> 3790.3156 | G13: =F13*(1+Assumptions!$E$47)*(1+Assumptions!$E$48) -> 4576.8061 | H13: =G13*(1+Assumptions!$F$47)*(1+Assumptions!$F$48) -> 5382.324 | I13: =H13*(1+Assumptions!$G$47)*(1+Assumptions!$G$48) -> 6216.5842
A14: Trading revenue (tires + parts) | B14: 2506.8 | C14: 3815.5 | D14: 4242.8 | E14: =D14*(1+Assumptions!$C$49) -> 5006.504 | F14: =E14*(1+Assumptions!$D$49) -> 5757.4796 | G14: =F14*(1+Assumptions!$E$49) -> 6448.3772 | H14: =G14*(1+Assumptions!$F$49) -> 7093.2149 | I14: =H14*(1+Assumptions!$G$49) -> 7802.5364
A15: Other Auto / after-sales & adj. | B15: 7625.2 | C15: 1353.4 | D15: 1127.6 | E15: =0 -> 0 | F15: =0 -> 0 | G15: =0 -> 0 | H15: =0 -> 0 | I15: =0 -> 0
A16: GB Auto total revenue | B16: 23854 | C16: 47065 | D16: 66358.3 | E16: =SUM(E8,E11,E13,E14,E15) -> 78549.562 | F16: =SUM(F8,F11,F13,F14,F15) -> 95736.342 | G16: =SUM(G8,G11,G13,G14,G15) -> 112459.42 | H16: =SUM(H8,H11,H13,H14,H15) -> 128713.64 | I16: =SUM(I8,I11,I13,I14,I15) -> 144761.09
A17: GB Capital revenue | B17: 4950.9 | C17: 7383.6 | D17: 14743 | E17: =D17*(1+Assumptions!$C$50) -> 21377.35 | F17: =E17*(1+Assumptions!$D$50) -> 27790.555 | G17: =F17*(1+Assumptions!$E$50) -> 34738.194 | H17: =G17*(1+Assumptions!$F$50) -> 41685.832 | I17: =H17*(1+Assumptions!$G$50) -> 49189.282
A18: Intercompany eliminations | B18: -487.7 | C18: -479 | D18: -871.5 | E18: =-(E16+E17)*Assumptions!$C$73 -> -1099.196 | F18: =-(F16+F17)*Assumptions!$D$73 -> -1358.7959 | G18: =-(G16+G17)*Assumptions!$E$73 -> -1619.1737 | H18: =-(H16+H17)*Assumptions!$F$73 -> -1874.3942 | I18: =-(I16+I17)*Assumptions!$G$73 -> -2133.4541
A19: Group revenue | B19: =B16+B17+B18 -> 28317.2 | C19: =C16+C17+C18 -> 53969.6 | D19: =D16+D17+D18 -> 80229.8 | E19: =E16+E17+E18 -> 98827.716 | F19: =F16+F17+F18 -> 122168.1 | G19: =G16+G17+G18 -> 145578.44 | H19: =H16+H17+H18 -> 168525.08 | I19: =I16+I17+I18 -> 191816.92
A21: Auto gross profit | B21: 5813.1 | C21: 9057.4 | D21: 9837.1 | E21: =E16*Assumptions!$C$52 -> 10839.839 | F21: =F16*Assumptions!$D$52 -> 13594.561 | G21: =G16*Assumptions!$E$52 -> 16306.615 | H21: =H16*Assumptions!$F$52 -> 18663.478 | I21: =I16*Assumptions!$G$52 -> 20990.359
A22: Auto gross margin | B22: =B21/B16 -> 0.24369498 | C22: =C21/C16 -> 0.19244449 | D22: =D21/D16 -> 0.14824219 | E22: =E21/E16 -> 0.138 | F22: =F21/F16 -> 0.142 | G22: =G21/G16 -> 0.145 | H22: =H21/H16 -> 0.145 | I22: =I21/I16 -> 0.145
A23: Auto EBIT (operating profit) | B23: 3460.9 | C23: 5564.9 | D23: 5830.9 | E23: =E21-E16*Assumptions!$C$53+E16*Assumptions!$C$54+E16*Assumptions!$C$55 -> 5812.6676 | F23: =F21-F16*Assumptions!$D$53+F16*Assumptions!$D$54+F16*Assumptions!$D$55 -> 7563.171 | G23: =G21-G16*Assumptions!$E$53+G16*Assumptions!$E$54+G16*Assumptions!$E$55 -> 9334.1315 | H23: =H21-H16*Assumptions!$F$53+H16*Assumptions!$F$54+H16*Assumptions!$F$55 -> 10811.946 | I23: =I21-I16*Assumptions!$G$53+I16*Assumptions!$G$54+I16*Assumptions!$G$55 -> 12159.932
A24: Auto D&A | B24: 374.3 | C24: 525.7 | D24: 683.3 | E24: =E16*Assumptions!$C$56 -> 864.04518 | F24: =F16*Assumptions!$D$56 -> 1053.0998 | G24: =G16*Assumptions!$E$56 -> 1237.0536 | H24: =H16*Assumptions!$F$56 -> 1415.8501 | I24: =I16*Assumptions!$G$56 -> 1592.372
A25: Auto EBITDA | B25: 3794.6 | C25: 5880.5 | D25: 6363.3 | E25: =E23+E24 -> 6676.7127 | F25: =F23+F24 -> 8616.2708 | G25: =G23+G24 -> 10571.185 | H25: =H23+H24 -> 12227.796 | I25: =I23+I24 -> 13752.304
A26: Auto EBITDA margin | B26: =B25/B16 -> 0.15907605 | C26: =C25/C16 -> 0.12494423 | D26: =D25/D16 -> 0.095893053 | E26: =E25/E16 -> 0.085 | F26: =F25/F16 -> 0.09 | G26: =G25/G16 -> 0.094 | H26: =H25/H16 -> 0.095 | I26: =I25/I16 -> 0.095
A27: GB Capital operating profit | B27: 243.7 | C27: 380.1 | D27: 788.5
A28: GB Capital net profit (after NCI) | B28: 1207.6 | C28: 1091.5 | D28: 1365.9
A29: GB Capital on-book loan portfolio | B29: 8980.5 | C29: 13183.4 | D29: 19495.2
A31: Source: GB Corp 4Q23 / 4Q24 / 4Q25 earnings releases (Tables 1–14). Other Auto = after-sales & regional lines folded into the four LoBs from FY24; forecast conservatively set to zero.

Sheet Relative & Normalized
A1: Relative & normalized-earnings lenses
A2: Links to Assumptions and the Income Statement.
A5: Lens | B5: Workings | C5: EGP/share
A6: Relative P/E | B6: FY26E group NP (conservative input) × justified P/E, /sh | C6: =Assumptions!B27*Assumptions!B28/Assumptions!B6 -> 28.8807
A7: implied FY26E EPS (EGP) | C7: =Assumptions!B27/Assumptions!B6 -> 3.0400737
A8: IS-build FY26E EPS, for reference | C8: ='Income Statement'!E26/Assumptions!B6 -> 3.0377829
A9: Normalized earnings power | B9: Mid-cycle group PAT × through-cycle P/E, /sh | C9: =Assumptions!B29*Assumptions!B30/Assumptions!B6 -> 32.88807
A10: normalized EPS (EGP) | C10: =Assumptions!B29/Assumptions!B6 -> 3.8691847
A12: P/B cross-check: spot / FY25 BVPS | C12: =Assumptions!B5/('Balance Sheet'!D16/Assumptions!B6) -> 1.1783052

Sheet DCF
A1: DCF — GB Auto operating leg, explicit 5-year FCFF
A2: Revenue → EBITDA → D&A → EBIT → NOPAT → +D&A → −Capex → −ΔWC → FCFF → discount factor → PV. Links to Segments / Balance Sheet / Assumptions.
B4: FY26E | C4: FY27E | D4: FY28E | E4: FY29E | F4: FY30E
A6: Auto revenue | B6: =Segments!E16 -> 78549.562 | C6: =Segments!F16 -> 95736.342 | D6: =Segments!G16 -> 112459.42 | E6: =Segments!H16 -> 128713.64 | F6: =Segments!I16 -> 144761.09
A7: EBITDA | B7: =Segments!E25 -> 6676.7127 | C7: =Segments!F25 -> 8616.2708 | D7: =Segments!G25 -> 10571.185 | E7: =Segments!H25 -> 12227.796 | F7: =Segments!I25 -> 13752.304
A8: D&A | B8: =-Segments!E24 -> -864.04518 | C8: =-Segments!F24 -> -1053.0998 | D8: =-Segments!G24 -> -1237.0536 | E8: =-Segments!H24 -> -1415.8501 | F8: =-Segments!I24 -> -1592.372
A9: EBIT | B9: =Segments!E23 -> 5812.6676 | C9: =Segments!F23 -> 7563.171 | D9: =Segments!G23 -> 9334.1315 | E9: =Segments!H23 -> 10811.946 | F9: =Segments!I23 -> 12159.932
A10: NOPAT = EBIT × (1 − tax) | B10: =B9*(1-Assumptions!$B$7) -> 4185.1206 | C10: =C9*(1-Assumptions!$B$7) -> 5445.4831 | D10: =D9*(1-Assumptions!$B$7) -> 6720.5747 | E10: =E9*(1-Assumptions!$B$7) -> 7784.6012 | F10: =F9*(1-Assumptions!$B$7) -> 8755.1509
A11: + D&A | B11: =Segments!E24 -> 864.04518 | C11: =Segments!F24 -> 1053.0998 | D11: =Segments!G24 -> 1237.0536 | E11: =Segments!H24 -> 1415.8501 | F11: =Segments!I24 -> 1592.372
A12: − Capex | B12: =-Assumptions!$C$57 -> -3000 | C12: =-Assumptions!$D$57 -> -2400 | D12: =-Assumptions!$E$57 -> -2500 | E12: =-Assumptions!$F$57 -> -2600 | F12: =-Assumptions!$G$57 -> -2800
A13: − Increase in net working capital | B13: =-'Balance Sheet'!E31 -> -1898.6338 | C13: =-'Balance Sheet'!F31 -> -3118.4516 | D13: =-'Balance Sheet'!G31 -> -2493.8772 | E13: =-'Balance Sheet'!H31 -> -2532.6072 | F13: =-'Balance Sheet'!I31 -> -2163.0652
A14: FCFF | B14: =SUM(B10:B13) -> 150.532 | C14: =SUM(C10:C13) -> 980.13126 | D14: =SUM(D10:D13) -> 2963.751 | E14: =SUM(E10:E13) -> 4067.844 | F14: =SUM(F10:F13) -> 5384.4578
A15: Discount factor | B15: =1/(1+Assumptions!$B$16)^1 -> 0.81337967 | C15: =1/(1+Assumptions!$B$16)^2 -> 0.66158648 | D15: =1/(1+Assumptions!$B$16)^3 -> 0.53812099 | E15: =1/(1+Assumptions!$B$16)^4 -> 0.43769667 | F15: =1/(1+Assumptions!$B$16)^5 -> 0.35601357
A16: PV of FCFF | B16: =B14*B15 -> 122.43967 | C16: =C14*C15 -> 648.44159 | D16: =D14*D15 -> 1594.8566 | E16: =E14*E15 -> 1780.4818 | F16: =F14*F15 -> 1916.94
A18: Σ PV of explicit FCFF (FY26–30E) | B18: =SUM(B16:F16) -> 6063.1597
A19: Terminal value (Gordon) | B19: =F14*(1+Assumptions!$B$17)/(Assumptions!$B$16-Assumptions!$B$17) -> 52462.136
A20: PV of terminal value | B20: =B19*F15 -> 18677.232
A21: Enterprise value — Auto leg | B21: =B18+B20 -> 24740.392
A22: % terminal of EV (device A-7) | B22: =B20/B21 -> 0.75492871
A23: less: Auto net debt | B23: =-Assumptions!$B$19 -> -15210
A24: less: Auto non-controlling interests | B24: =-Assumptions!$B$20 -> -800.4
A25: Auto equity value | B25: =B21-Assumptions!$B$19-Assumptions!$B$20 -> 8729.9922
A27: EV sensitivity per +1pp Auto GPM (helper for Sensitivity) | B27: =0.01*(1-Assumptions!$B$7)*(SUMPRODUCT(B6:F6,B15:F15)+F6*(1+Assumptions!$B$17)/(Assumptions!$B$16-Assumptions!$B$17)*F15) -> 5743.8498
A29: WACC is built on the Assumptions sheet as Ke = rf + β × ERP (house rule §3.5-G) blended with after-tax Kd.

Sheet Income Statement
A1: Income statement (EGP mn, consolidated)
A2: FY23–FY25 disclosed (blue); FY26E–FY30E formulas linking to Segments and Assumptions.
B4: FY23 | C4: FY24 | D4: FY25 | E4: FY26E | F4: FY27E | G4: FY28E | H4: FY29E | I4: FY30E
A6: GB Auto revenue | B6: 23854 | C6: 47065 | D6: 66358.3 | E6: =Segments!E16 -> 78549.562 | F6: =Segments!F16 -> 95736.342 | G6: =Segments!G16 -> 112459.42 | H6: =Segments!H16 -> 128713.64 | I6: =Segments!I16 -> 144761.09
A7: GB Capital revenue | B7: 4950.9 | C7: 7383.6 | D7: 14743 | E7: =Segments!E17 -> 21377.35 | F7: =Segments!F17 -> 27790.555 | G7: =Segments!G17 -> 34738.194 | H7: =Segments!H17 -> 41685.832 | I7: =Segments!I17 -> 49189.282
A8: Intercompany eliminations | B8: -487.7 | C8: -479 | D8: -871.5 | E8: =Segments!E18 -> -1099.196 | F8: =Segments!F18 -> -1358.7959 | G8: =Segments!G18 -> -1619.1737 | H8: =Segments!H18 -> -1874.3942 | I8: =Segments!I18 -> -2133.4541
A9: Total revenue | B9: 28317.2 | C9: 53969.5 | D9: 80229.8 | E9: =SUM(E6:E8) -> 98827.716 | F9: =SUM(F6:F8) -> 122168.1 | G9: =SUM(G6:G8) -> 145578.44 | H9: =SUM(H6:H8) -> 168525.08 | I9: =SUM(I6:I8) -> 191816.92
A10: Gross profit | B10: 6884.3 | C10: 10514.6 | D10: 12431.1 | E10: =Segments!E21+Segments!E17*Assumptions!$C$67+Segments!E18*0.2 -> 14638.942 | F10: =Segments!F21+Segments!F17*Assumptions!$D$67+Segments!F18*0.2 -> 18603.007 | G10: =Segments!G21+Segments!G17*Assumptions!$E$67+Segments!G18*0.2 -> 22652.514 | H10: =Segments!H21+Segments!H17*Assumptions!$F$67+Segments!H18*0.2 -> 26375.651 | I10: =Segments!I21+Segments!I17*Assumptions!$G$67+Segments!I18*0.2 -> 30204.767
A11: Gross profit margin | B11: =B10/B9 -> 0.24311373 | C11: =C10/C9 -> 0.19482485 | D11: =D10/D9 -> 0.15494367 | E11: =E10/E9 -> 0.14812588 | F11: =F10/F9 -> 0.15227385 | G11: =G10/G9 -> 0.1556035 | H11: =H10/H9 -> 0.15650876 | I11: =I10/I9 -> 0.15746664
A12: Selling, marketing & administration | B12: -3430.8 | C12: -4843.6 | D12: -6547.3 | E12: =-E9*Assumptions!$C$64 -> -7906.2172 | F12: =-F9*Assumptions!$D$64 -> -9651.28 | G12: =-G9*Assumptions!$E$64 -> -11355.118 | H12: =-H9*Assumptions!$F$64 -> -13060.694 | I12: =-I9*Assumptions!$G$64 -> -14769.903
A13: Other income (expenses) | B13: 518.8 | C13: 505.6 | D13: 912.2 | E13: =E9*Assumptions!$C$65 -> 1087.1049 | F13: =F9*Assumptions!$D$65 -> 1343.8491 | G13: =G9*Assumptions!$E$65 -> 1601.3628 | H13: =H9*Assumptions!$F$65 -> 1853.7759 | I13: =I9*Assumptions!$G$65 -> 2109.9861
A14: Provisions (net) | B14: -268.9 | C14: -355.7 | D14: -165.1 | E14: =E9*Assumptions!$C$66 -> -296.48315 | F14: =F9*Assumptions!$D$66 -> -366.5043 | G14: =G9*Assumptions!$E$66 -> -436.73531 | H14: =H9*Assumptions!$F$66 -> -505.57525 | I14: =I9*Assumptions!$G$66 -> -575.45076
A15: Operating profit | B15: 3703.4 | C15: 5820.8 | D15: 6631 | E15: =SUM(E10,E12:E14) -> 7523.3466 | F15: =SUM(F10,F12:F14) -> 9929.0716 | G15: =SUM(G10,G12:G14) -> 12462.023 | H15: =SUM(H10,H12:H14) -> 14663.158 | I15: =SUM(I10,I12:I14) -> 16969.399
A16: Investment gains from associates | B16: 1066.1 | C16: 867.6 | D16: 974.8 | E16: =Assumptions!$C$68 -> 1250 | F16: =Assumptions!$D$68 -> 1430 | G16: =Assumptions!$E$68 -> 1630 | H16: =Assumptions!$F$68 -> 1830 | I16: =Assumptions!$G$68 -> 2030
A17: EBIT | B17: 4769.5 | C17: 6688.5 | D17: 7605.7 | E17: =E15+E16 -> 8773.3466 | F17: =F15+F16 -> 11359.072 | G17: =G15+G16 -> 14092.023 | H17: =H15+H16 -> 16493.158 | I17: =I15+I16 -> 18999.399
A18: Group D&A | B18: 820 | C18: 1030 | D18: 1243 | E18: =Segments!E24+Assumptions!$C$59 -> 1424.0452 | F18: =Segments!F24+Assumptions!$D$59 -> 1693.0998 | G18: =Segments!G24+Assumptions!$E$59 -> 1967.0536 | H18: =Segments!H24+Assumptions!$F$59 -> 2245.8501 | I18: =Segments!I24+Assumptions!$G$59 -> 2532.372
A19: EBITDA (EBIT + D&A) | B19: =B17+B18 -> 5589.5 | C19: =C17+C18 -> 7718.5 | D19: =D17+D18 -> 8848.7 | E19: =E17+E18 -> 10197.392 | F19: =F17+F18 -> 13052.171 | G19: =G17+G18 -> 16059.077 | H19: =H17+H18 -> 18739.008 | I19: =I17+I18 -> 21531.771
A20: Foreign exchange gains (losses) | B20: -1499.2 | C20: -291.6 | D20: -37.1 | E20: =0 -> 0 | F20: =0 -> 0 | G20: =0 -> 0 | H20: =0 -> 0 | I20: =0 -> 0
A21: Net finance cost | B21: -965.8 | C21: -2397.8 | D21: -3702.1 | E21: =Assumptions!$C$69 -> -4100 | F21: =Assumptions!$D$69 -> -3800 | G21: =Assumptions!$E$69 -> -3500 | H21: =Assumptions!$F$69 -> -3300 | I21: =Assumptions!$G$69 -> -3100
A22: Earnings before tax | B22: 2304.4 | C22: 3999.1 | D22: 3866.5 | E22: =E17+E20+E21 -> 4673.3466 | F22: =F17+F20+F21 -> 7559.0716 | G22: =G17+G20+G21 -> 10592.023 | H22: =H17+H20+H21 -> 13193.158 | I22: =I17+I20+I21 -> 15899.399
A23: Income taxes | B23: -493.2 | C23: -939.2 | D23: -1086.1 | E23: =-E22*Assumptions!$B$7 -> -1308.537 | F23: =-F22*Assumptions!$B$7 -> -2116.5401 | G23: =-G22*Assumptions!$B$7 -> -2965.7665 | H23: =-H22*Assumptions!$B$7 -> -3694.0842 | I23: =-I22*Assumptions!$B$7 -> -4451.8318
A24: Net profit before minority interest | B24: 1811.2 | C24: 3059.9 | D24: 2780.5 | E24: =E22+E23 -> 3364.8095 | F24: =F22+F23 -> 5442.5316 | G24: =G22+G23 -> 7626.2567 | H24: =H22+H23 -> 9499.0736 | I24: =I22+I23 -> 11447.568
A25: Minority interest | B25: 79.5 | C25: -131.8 | D25: 99.6 | E25: =E24*Assumptions!$C$70 -> -67.296191 | F25: =F24*Assumptions!$D$70 -> -108.85063 | G25: =G24*Assumptions!$E$70 -> -152.52513 | H25: =H24*Assumptions!$F$70 -> -189.98147 | I25: =I24*Assumptions!$G$70 -> -228.95135
A26: Net profit (attributable) | B26: 1890.8 | C26: 2928.1 | D26: 2880 | E26: =E24+E25 -> 3297.5133 | F26: =F24+F25 -> 5333.6809 | G26: =G24+G25 -> 7473.7316 | H26: =H24+H25 -> 9309.0922 | I26: =I24+I25 -> 11218.616
A27: Net profit margin | B27: =B26/B9 -> 0.066772138 | C27: =C26/C9 -> 0.054254718 | D27: =D26/D9 -> 0.035896886 | E27: =E26/E9 -> 0.033366281 | F27: =F26/F9 -> 0.04365854 | G27: =G26/G9 -> 0.051338178 | H27: =H26/H9 -> 0.055238615 | I27: =I26/I9 -> 0.058486061
A29: Source: GB Corp 4Q23 / 4Q24 / 4Q25 earnings releases, Table 1 & Table 11 (segment IS). FY23 operating profit shown after provisions for cross-year consistency with the FY25 layout.

Sheet Balance Sheet
A1: Balance sheet (EGP mn, consolidated)
A2: FY23–FY25 grouped from the disclosed segment balance sheets to a house layout (blue). Forecast rolls forward; the check row is zero by clean-surplus construction.
B4: FY23 | C4: FY24 | D4: FY25 | E4: FY26E | F4: FY27E | G4: FY28E | H4: FY29E | I4: FY30E
A6: PP&E, intangibles, ROU & inv. property | B6: 6937.4 | C6: 10360.6 | D6: 13389.1 | E6: =D6+Assumptions!$C$57+Assumptions!$C$58-'Income Statement'!E18 -> 15665.055 | F6: =E6+Assumptions!$D$57+Assumptions!$D$58-'Income Statement'!F18 -> 17171.955 | G6: =F6+Assumptions!$E$57+Assumptions!$E$58-'Income Statement'!G18 -> 18604.901 | H6: =G6+Assumptions!$F$57+Assumptions!$F$58-'Income Statement'!H18 -> 19959.051 | I6: =H6+Assumptions!$G$57+Assumptions!$G$58-'Income Statement'!I18 -> 21326.679
A7: Investments in associates (MNT-Halan, Bedaya, Kaf) | B7: 10732.4 | C7: 11743.6 | D7: 13689.5 | E7: =D7+Assumptions!$C$68 -> 14939.5 | F7: =E7+Assumptions!$D$68 -> 16369.5 | G7: =F7+Assumptions!$E$68 -> 17999.5 | H7: =G7+Assumptions!$F$68 -> 19829.5 | I7: =H7+Assumptions!$G$68 -> 21859.5
A8: GB Capital loan book (on balance sheet) | B8: 7681.4 | C8: 11483 | D8: 17518.3 | E8: =D8*(1+Assumptions!$C$51) -> 23649.705 | F8: =E8*(1+Assumptions!$D$51) -> 30271.622 | G8: =F8*(1+Assumptions!$E$51) -> 37536.812 | H8: =G8*(1+Assumptions!$F$51) -> 45044.174 | I8: =H8*(1+Assumptions!$G$51) -> 53152.125
A9: Inventories | B9: 6366.1 | C9: 21134.3 | D9: 24649.7 | E9: =Segments!E16*Assumptions!$C$60 -> 28277.842 | F9: =Segments!F16*Assumptions!$D$60 -> 32358.883 | G9: =Segments!G16*Assumptions!$E$60 -> 35987.013 | H9: =Segments!H16*Assumptions!$F$60 -> 39643.802 | I9: =Segments!I16*Assumptions!$G$60 -> 42849.284
A10: Trade receivables — Auto | B10: 1743.5 | C10: 3708.7 | D10: 5316.9 | E10: =Segments!E16*Assumptions!$C$61 -> 6283.9649 | F10: =Segments!F16*Assumptions!$D$61 -> 7658.9073 | G10: =Segments!G16*Assumptions!$E$61 -> 8996.7532 | H10: =Segments!H16*Assumptions!$F$61 -> 10297.092 | I10: =Segments!I16*Assumptions!$G$61 -> 11580.887
A11: Advances, debtors & other current | B11: 1039.1 | C11: 2942.2 | D11: 4670.6 | E11: =Segments!E16*Assumptions!$C$62 -> 5498.4693 | F11: =Segments!F16*Assumptions!$D$62 -> 6605.8076 | G11: =Segments!G16*Assumptions!$E$62 -> 7591.0106 | H11: =Segments!H16*Assumptions!$F$62 -> 8495.1005 | I11: =Segments!I16*Assumptions!$G$62 -> 9337.0905
A12: Cash & cash equivalents | B12: 4504.2 | C12: 7420.9 | D12: 9523.6 | E12: ='Cash Flow'!E18 -> 6370.764 | F12: ='Cash Flow'!F18 -> 3535.9742 | G12: ='Cash Flow'!G18 -> 2744.4208 | H12: ='Cash Flow'!H18 -> 3143.7384 | I12: ='Cash Flow'!I18 -> 4778.9382
A13: Other assets (DTA, held-for-sale, misc.) | B13: 3581.4 | C13: 3931.9 | D13: 2601.3 | E13: =D13 -> 2601.3 | F13: =E13 -> 2601.3 | G13: =F13 -> 2601.3 | H13: =G13 -> 2601.3 | I13: =H13 -> 2601.3
A14: TOTAL ASSETS | B14: =SUM(B6:B13) -> 42585.5 | C14: =SUM(C6:C13) -> 72725.2 | D14: =SUM(D6:D13) -> 91359 | E14: =SUM(E6:E13) -> 103286.6 | F14: =SUM(F6:F13) -> 116573.95 | G14: =SUM(G6:G13) -> 132061.71 | H14: =SUM(H6:H13) -> 149013.76 | I14: =SUM(I6:I13) -> 167485.8
A16: Equity attributable to shareholders | B16: 19838.8 | C16: 25438.5 | D16: 28788.7 | E16: =D16+'Income Statement'!E26+'Cash Flow'!E15 -> 31624.561 | F16: =E16+'Income Statement'!F26+'Cash Flow'!F15 -> 36158.19 | G16: =F16+'Income Statement'!G26+'Cash Flow'!G15 -> 42436.125 | H16: =G16+'Income Statement'!H26+'Cash Flow'!H15 -> 50069.58 | I16: =H16+'Income Statement'!I26+'Cash Flow'!I15 -> 59044.473
A17: Non-controlling interests | B17: 1363 | C17: 1978.4 | D17: 1801.4 | E17: =D17-'Income Statement'!E25 -> 1868.6962 | F17: =E17-'Income Statement'!F25 -> 1977.5468 | G17: =F17-'Income Statement'!G25 -> 2130.072 | H17: =G17-'Income Statement'!H25 -> 2320.0534 | I17: =H17-'Income Statement'!I25 -> 2549.0048
A18: Total equity | B18: 21201.8 | C18: 27417 | D18: 30590.2 | E18: =E16+E17 -> 33493.258 | F18: =F16+F17 -> 38135.737 | G18: =G16+G17 -> 44566.197 | H18: =H16+H17 -> 52389.634 | I18: =I16+I17 -> 61593.478
A19: Borrowings (loans, overdrafts & bonds) | B19: 12517.7 | C19: 22608.7 | D19: 38041.4 | E19: =D19+Assumptions!$C$71 -> 43541.4 | F19: =E19+Assumptions!$D$71 -> 48741.4 | G19: =F19+Assumptions!$E$71 -> 54341.4 | H19: =G19+Assumptions!$F$71 -> 60141.4 | I19: =H19+Assumptions!$G$71 -> 66241.4
A20: Trade & notes payables | B20: 7398.7 | C20: 19717.6 | D20: 18436.5 | E20: =Segments!E16*Assumptions!$C$63+2716.3 -> 21960.943 | F20: =Segments!F16*Assumptions!$D$63+2716.3 -> 25405.813 | G20: =Segments!G16*Assumptions!$E$63+2716.3 -> 28863.114 | H20: =Segments!H16*Assumptions!$F$63+2716.3 -> 32191.724 | I20: =Segments!I16*Assumptions!$G$63+2716.3 -> 35359.927
A21: Lease obligations | B21: 371.3 | C21: 1123.8 | D21: 1554.3 | E21: =D21 -> 1554.3 | F21: =E21 -> 1554.3 | G21: =F21 -> 1554.3 | H21: =G21 -> 1554.3 | I21: =H21 -> 1554.3
A22: Provisions | B22: 347.7 | C22: 709.9 | D22: 794.9 | E22: =D22 -> 794.9 | F22: =E22 -> 794.9 | G22: =F22 -> 794.9 | H22: =G22 -> 794.9 | I22: =H22 -> 794.9
A23: Other liabilities | B23: 415.2 | C23: 746.2 | D23: 1178.2 | E23: =D23 -> 1178.2 | F23: =E23 -> 1178.2 | G23: =F23 -> 1178.2 | H23: =G23 -> 1178.2 | I23: =H23 -> 1178.2
A24: Deferred tax liabilities | B24: 333.1 | C24: 402 | D24: 763.5 | E24: =D24 -> 763.5 | F24: =E24 -> 763.5 | G24: =F24 -> 763.5 | H24: =G24 -> 763.5 | I24: =H24 -> 763.5
A25: TOTAL EQUITY & LIABILITIES | B25: =B18+SUM(B19:B24) -> 42585.5 | C25: =C18+SUM(C19:C24) -> 72725.2 | D25: =D18+SUM(D19:D24) -> 91359 | E25: =E18+SUM(E19:E24) -> 103286.5 | F25: =F18+SUM(F19:F24) -> 116573.85 | G25: =G18+SUM(G19:G24) -> 132061.61 | H25: =H18+SUM(H19:H24) -> 149013.66 | I25: =I18+SUM(I19:I24) -> 167485.7
A27: Balance check (assets − L&E) | B27: =B14-B25 -> 0 | C27: =C14-C25 -> 0 | D27: =D14-D25 -> 0 | E27: =E14-E25 -> 0.1 | F27: =F14-F25 -> 0.1 | G27: =G14-G25 -> 0.1 | H27: =H14-H25 -> 0.1 | I27: =I14-I25 -> 0.1
A28: Group net debt (borrowings − cash) | B28: =B19-B12 -> 8013.5 | C28: =C19-C12 -> 15187.8 | D28: =D19-D12 -> 28517.8 | E28: =E19-E12 -> 37170.636 | F28: =F19-F12 -> 45205.426 | G28: =G19-G12 -> 51596.979 | H28: =H19-H12 -> 56997.662 | I28: =I19-I12 -> 61462.462
A30: Net Auto working capital (inv + rec + adv − pay) | B30: =B9+B10+B11-(B20-2716.3) -> 4466.3 | C30: =C9+C10+C11-(C20-2716.3) -> 10783.9 | D30: =D9+D10+D11-(D20-2716.3) -> 18917 | E30: =E9+E10+E11-(E20-2716.3) -> 20815.634 | F30: =F9+F10+F11-(F20-2716.3) -> 23934.085 | G30: =G9+G10+G11-(G20-2716.3) -> 26427.963 | H30: =H9+H10+H11-(H20-2716.3) -> 28960.57 | I30: =I9+I10+I11-(I20-2716.3) -> 31123.635
A31: Increase in net Auto working capital | E31: =E30-D30 -> 1898.6338 | F31: =F30-E30 -> 3118.4516 | G31: =G30-F30 -> 2493.8772 | H31: =H30-G30 -> 2532.6072 | I31: =I30-H30 -> 2163.0652
A33: Historic mapping note: lines grouped from the disclosed 4Q23/4Q24/4Q25 segment balance sheets (Table 12/13). "GB Capital loan book (on BS)" = notes receivable + GB Capital trade receivables net of eliminations; the disclosed portfolio metric (EGP 19.5bn FY25) differs by provisions and presentation. Payables forecast holds the non-Auto payables block (EGP 2,716mn) flat.

Sheet Cash Flow
A1: Cash flow (EGP mn, forecast)
A2: Derived from the Income Statement and Balance Sheet. Closing cash ties to the Balance Sheet; every balance-sheet movement is captured, so the check row is zero.
E4: FY26E | F4: FY27E | G4: FY28E | H4: FY29E | I4: FY30E
A6: Net profit before minority interest | E6: ='Income Statement'!E24 -> 3364.8095 | F6: ='Income Statement'!F24 -> 5442.5316 | G6: ='Income Statement'!G24 -> 7626.2567 | H6: ='Income Statement'!H24 -> 9499.0736 | I6: ='Income Statement'!I24 -> 11447.568
A7: + D&A | E7: ='Income Statement'!E18 -> 1424.0452 | F7: ='Income Statement'!F18 -> 1693.0998 | G7: ='Income Statement'!G18 -> 1967.0536 | H7: ='Income Statement'!H18 -> 2245.8501 | I7: ='Income Statement'!I18 -> 2532.372
A8: − Associates income (non-cash) | E8: =-'Income Statement'!E16 -> -1250 | F8: =-'Income Statement'!F16 -> -1430 | G8: =-'Income Statement'!G16 -> -1630 | H8: =-'Income Statement'!H16 -> -1830 | I8: =-'Income Statement'!I16 -> -2030
A9: − Increase in net Auto working capital | E9: =-'Balance Sheet'!E31 -> -1898.6338 | F9: =-'Balance Sheet'!F31 -> -3118.4516 | G9: =-'Balance Sheet'!G31 -> -2493.8772 | H9: =-'Balance Sheet'!H31 -> -2532.6072 | I9: =-'Balance Sheet'!I31 -> -2163.0652
A10: − Increase in GB Capital loan book | E10: =-('Balance Sheet'!E8-'Balance Sheet'!D8) -> -6131.405 | F10: =-('Balance Sheet'!F8-'Balance Sheet'!E8) -> -6621.9174 | G10: =-('Balance Sheet'!G8-'Balance Sheet'!F8) -> -7265.1894 | H10: =-('Balance Sheet'!H8-'Balance Sheet'!G8) -> -7507.3624 | I10: =-('Balance Sheet'!I8-'Balance Sheet'!H8) -> -8107.9513
A11: Operating cash flow | E11: =SUM(E6:E10) -> -4491.1841 | F11: =SUM(F6:F10) -> -4034.7377 | G11: =SUM(G6:G10) -> -1795.7563 | H11: =SUM(H6:H10) -> -125.04588 | I11: =SUM(I6:I10) -> 1678.9231
A12: − Capex (Auto + rental fleet) | E12: =-Assumptions!$C$57-Assumptions!$C$58 -> -3700 | F12: =-Assumptions!$D$57-Assumptions!$D$58 -> -3200 | G12: =-Assumptions!$E$57-Assumptions!$E$58 -> -3400 | H12: =-Assumptions!$F$57-Assumptions!$F$58 -> -3600 | I12: =-Assumptions!$G$57-Assumptions!$G$58 -> -3900
A13: Free cash flow | E13: =E11+E12 -> -8191.1841 | F13: =F11+F12 -> -7234.7377 | G13: =G11+G12 -> -5195.7563 | H13: =H11+H12 -> -3725.0459 | I13: =I11+I12 -> -2221.0769
A14: + Increase in borrowings (net) | E14: =Assumptions!$C$71 -> 5500 | F14: =Assumptions!$D$71 -> 5200 | G14: =Assumptions!$E$71 -> 5600 | H14: =Assumptions!$F$71 -> 5800 | I14: =Assumptions!$G$71 -> 6100
A15: − Dividends paid | E15: =-'Income Statement'!E26*Assumptions!$C$72 -> -461.65187 | F15: =-'Income Statement'!F26*Assumptions!$D$72 -> -800.05214 | G15: =-'Income Statement'!G26*Assumptions!$E$72 -> -1195.7971 | H15: =-'Income Statement'!H26*Assumptions!$F$72 -> -1675.6366 | I15: =-'Income Statement'!I26*Assumptions!$G$72 -> -2243.7233
A16: Net change in cash | E16: =E13+E14+E15 -> -3152.836 | F16: =F13+F14+F15 -> -2834.7898 | G16: =G13+G14+G15 -> -791.55338 | H16: =H13+H14+H15 -> 399.31753 | I16: =I13+I14+I15 -> 1635.1999
A17: Opening cash | E17: ='Balance Sheet'!D12 -> 9523.6 | F17: =E18 -> 6370.764 | G17: =F18 -> 3535.9742 | H17: =G18 -> 2744.4208 | I17: =H18 -> 3143.7384
A18: Closing cash | E18: =E17+E16 -> 6370.764 | F18: =F17+F16 -> 3535.9742 | G18: =G17+G16 -> 2744.4208 | H18: =H17+H16 -> 3143.7384 | I18: =I17+I16 -> 4778.9382
A20: Historical group cash-flow statements are published per segment (GB Auto CF in each release); the forecast is the consolidated clean-surplus build.

Sheet Summary Financials
A1: Summary financials (EGP mn)
A2: Every cell links to the statement sheets.
B4: FY23 | C4: FY24 | D4: FY25 | E4: FY26E | F4: FY27E | G4: FY28E | H4: FY29E | I4: FY30E
A6: Revenue | B6: ='Income Statement'!B9 -> 28317.2 | C6: ='Income Statement'!C9 -> 53969.5 | D6: ='Income Statement'!D9 -> 80229.8 | E6: ='Income Statement'!E9 -> 98827.716 | F6: ='Income Statement'!F9 -> 122168.1 | G6: ='Income Statement'!G9 -> 145578.44 | H6: ='Income Statement'!H9 -> 168525.08 | I6: ='Income Statement'!I9 -> 191816.92
A7: EBITDA | B7: ='Income Statement'!B19 -> 5589.5 | C7: ='Income Statement'!C19 -> 7718.5 | D7: ='Income Statement'!D19 -> 8848.7 | E7: ='Income Statement'!E19 -> 10197.392 | F7: ='Income Statement'!F19 -> 13052.171 | G7: ='Income Statement'!G19 -> 16059.077 | H7: ='Income Statement'!H19 -> 18739.008 | I7: ='Income Statement'!I19 -> 21531.771
A8: EBIT | B8: ='Income Statement'!B17 -> 4769.5 | C8: ='Income Statement'!C17 -> 6688.5 | D8: ='Income Statement'!D17 -> 7605.7 | E8: ='Income Statement'!E17 -> 8773.3466 | F8: ='Income Statement'!F17 -> 11359.072 | G8: ='Income Statement'!G17 -> 14092.023 | H8: ='Income Statement'!H17 -> 16493.158 | I8: ='Income Statement'!I17 -> 18999.399
A9: Net profit (attributable) | B9: ='Income Statement'!B26 -> 1890.8 | C9: ='Income Statement'!C26 -> 2928.1 | D9: ='Income Statement'!D26 -> 2880 | E9: ='Income Statement'!E26 -> 3297.5133 | F9: ='Income Statement'!F26 -> 5333.6809 | G9: ='Income Statement'!G26 -> 7473.7316 | H9: ='Income Statement'!H26 -> 9309.0922 | I9: ='Income Statement'!I26 -> 11218.616
A10: Total assets | B10: ='Balance Sheet'!B14 -> 42585.5 | C10: ='Balance Sheet'!C14 -> 72725.2 | D10: ='Balance Sheet'!D14 -> 91359 | E10: ='Balance Sheet'!E14 -> 103286.6 | F10: ='Balance Sheet'!F14 -> 116573.95 | G10: ='Balance Sheet'!G14 -> 132061.71 | H10: ='Balance Sheet'!H14 -> 149013.76 | I10: ='Balance Sheet'!I14 -> 167485.8
A11: Total equity | B11: ='Balance Sheet'!B18 -> 21201.8 | C11: ='Balance Sheet'!C18 -> 27417 | D11: ='Balance Sheet'!D18 -> 30590.2 | E11: ='Balance Sheet'!E18 -> 33493.258 | F11: ='Balance Sheet'!F18 -> 38135.737 | G11: ='Balance Sheet'!G18 -> 44566.197 | H11: ='Balance Sheet'!H18 -> 52389.634 | I11: ='Balance Sheet'!I18 -> 61593.478
A12: Group net debt | B12: ='Balance Sheet'!B28 -> 8013.5 | C12: ='Balance Sheet'!C28 -> 15187.8 | D12: ='Balance Sheet'!D28 -> 28517.8 | E12: ='Balance Sheet'!E28 -> 37170.636 | F12: ='Balance Sheet'!F28 -> 45205.426 | G12: ='Balance Sheet'!G28 -> 51596.979 | H12: ='Balance Sheet'!H28 -> 56997.662 | I12: ='Balance Sheet'!I28 -> 61462.462
A13: Free cash flow (forecast) | E13: ='Cash Flow'!E13 -> -8191.1841 | F13: ='Cash Flow'!F13 -> -7234.7377 | G13: ='Cash Flow'!G13 -> -5195.7563 | H13: ='Cash Flow'!H13 -> -3725.0459 | I13: ='Cash Flow'!I13 -> -2221.0769

Sheet Monte Carlo
A1: Monte Carlo — engine outputs (YZ-HAR v2)
A2: 50,000 paths · 16 factors · seed 42 · computed by the Testahil MC engine (values, not a sheet simulation). No KVOL — the retired multiplier is replaced by the HAR width.
A5: The probability read (T+60)
A6: P(price above spot) | B6: 0.71394
A7: P(+10%) vs P(−10%) — odds | B7: 54% vs 15% · 3.6:1
A8: Median level (EGP) and % move | B8: 34.98 (+11.9%)
A9: 50% band (25th–75th) | B9: 30.6 – 40.1 (-2% / +28%)
A10: Touch(+10%) / touch(−10%) | B10: 76% / 38%
A12: Percentile map (EGP/share)
A13: Horizon | B13: p5 | C13: p25 | D13: p50 | E13: p75 | F13: p95
A14: T+20 sessions | B14: 26.1 | C14: 30 | D14: 32.5 | E14: 35.1 | F14: 40.5
A15: T+60 sessions | B15: 24 | C15: 30.6 | D15: 35 | E15: 40.1 | F15: 51.1
A17: Engine inputs (from Assumptions)
A18: Anchor volatility (HAR, annualized) | B18: =Assumptions!B37 -> 0.4957
A19: Secular drift (daily) | B19: =Assumptions!B38 -> 0.00164
A20: Net factor drift / quarter | B20: =Assumptions!B39 -> 0.0146
A22: Level-touch ladder (probability of touching by horizon)
A23: Level (EGP) | B23: T+20 | C23: T+60
A24: 40 | B24: 0.08442 | C24: 0.3736
A25: 38 | B25: 0.15298 | C25: 0.49572
A26: 36 | B26: 0.28754 | C26: 0.63612
A27: 34 | B27: 0.51416 | C27: 0.7882
A28: 32 | B28: 0.8164 | C28: 0.92818
A29: 30 | B29: 0.52736 | C29: 0.6416
A30: 28 | B30: 0.22086 | C30: 0.36742
A31: 26 | B31: 0.08616 | C31: 0.20414

Sheet Sensitivity
A1: SOTP sensitivity — Auto margin × complexity discount
A2: Fair value (EGP/share, post-discount). Live off Assumptions and the DCF helper (EV per +1pp GPM).
A5: GPM shift \ discount | B5: 0 | C5: 0.05 | D5: 0.1 | E5: 0.15 | F5: 0.2
A6: -0.02 | B6: =((DCF!$B$21+$A6*100*DCF!$B$27-Assumptions!$B$19-Assumptions!$B$20+Assumptions!$B$21*Assumptions!$B$22+Assumptions!$B$23*Assumptions!$B$24)*(1-B$5))/Assumptions!$B$6 -> 32.06167 | C6: =((DCF!$B$21+$A6*100*DCF!$B$27-Assumptions!$B$19-Assumptions!$B$20+Assumptions!$B$21*Assumptions!$B$22+Assumptions!$B$23*Assumptions!$B$24)*(1-C$5))/Assumptions!$B$6 -> 30.458586 | D6: =((DCF!$B$21+$A6*100*DCF!$B$27-Assumptions!$B$19-Assumptions!$B$20+Assumptions!$B$21*Assumptions!$B$22+Assumptions!$B$23*Assumptions!$B$24)*(1-D$5))/Assumptions!$B$6 -> 28.855503 | E6: =((DCF!$B$21+$A6*100*DCF!$B$27-Assumptions!$B$19-Assumptions!$B$20+Assumptions!$B$21*Assumptions!$B$22+Assumptions!$B$23*Assumptions!$B$24)*(1-E$5))/Assumptions!$B$6 -> 27.252419 | F6: =((DCF!$B$21+$A6*100*DCF!$B$27-Assumptions!$B$19-Assumptions!$B$20+Assumptions!$B$21*Assumptions!$B$22+Assumptions!$B$23*Assumptions!$B$24)*(1-F$5))/Assumptions!$B$6 -> 25.649336
A7: -0.01 | B7: =((DCF!$B$21+$A7*100*DCF!$B$27-Assumptions!$B$19-Assumptions!$B$20+Assumptions!$B$21*Assumptions!$B$22+Assumptions!$B$23*Assumptions!$B$24)*(1-B$5))/Assumptions!$B$6 -> 37.353102 | C7: =((DCF!$B$21+$A7*100*DCF!$B$27-Assumptions!$B$19-Assumptions!$B$20+Assumptions!$B$21*Assumptions!$B$22+Assumptions!$B$23*Assumptions!$B$24)*(1-C$5))/Assumptions!$B$6 -> 35.485447 | D7: =((DCF!$B$21+$A7*100*DCF!$B$27-Assumptions!$B$19-Assumptions!$B$20+Assumptions!$B$21*Assumptions!$B$22+Assumptions!$B$23*Assumptions!$B$24)*(1-D$5))/Assumptions!$B$6 -> 33.617792 | E7: =((DCF!$B$21+$A7*100*DCF!$B$27-Assumptions!$B$19-Assumptions!$B$20+Assumptions!$B$21*Assumptions!$B$22+Assumptions!$B$23*Assumptions!$B$24)*(1-E$5))/Assumptions!$B$6 -> 31.750137 | F7: =((DCF!$B$21+$A7*100*DCF!$B$27-Assumptions!$B$19-Assumptions!$B$20+Assumptions!$B$21*Assumptions!$B$22+Assumptions!$B$23*Assumptions!$B$24)*(1-F$5))/Assumptions!$B$6 -> 29.882482
A8: 0 | B8: =((DCF!$B$21+$A8*100*DCF!$B$27-Assumptions!$B$19-Assumptions!$B$20+Assumptions!$B$21*Assumptions!$B$22+Assumptions!$B$23*Assumptions!$B$24)*(1-B$5))/Assumptions!$B$6 -> 42.644535 | C8: =((DCF!$B$21+$A8*100*DCF!$B$27-Assumptions!$B$19-Assumptions!$B$20+Assumptions!$B$21*Assumptions!$B$22+Assumptions!$B$23*Assumptions!$B$24)*(1-C$5))/Assumptions!$B$6 -> 40.512308 | D8: =((DCF!$B$21+$A8*100*DCF!$B$27-Assumptions!$B$19-Assumptions!$B$20+Assumptions!$B$21*Assumptions!$B$22+Assumptions!$B$23*Assumptions!$B$24)*(1-D$5))/Assumptions!$B$6 -> 38.380081 | E8: =((DCF!$B$21+$A8*100*DCF!$B$27-Assumptions!$B$19-Assumptions!$B$20+Assumptions!$B$21*Assumptions!$B$22+Assumptions!$B$23*Assumptions!$B$24)*(1-E$5))/Assumptions!$B$6 -> 36.247854 | F8: =((DCF!$B$21+$A8*100*DCF!$B$27-Assumptions!$B$19-Assumptions!$B$20+Assumptions!$B$21*Assumptions!$B$22+Assumptions!$B$23*Assumptions!$B$24)*(1-F$5))/Assumptions!$B$6 -> 34.115628
A9: 0.01 | B9: =((DCF!$B$21+$A9*100*DCF!$B$27-Assumptions!$B$19-Assumptions!$B$20+Assumptions!$B$21*Assumptions!$B$22+Assumptions!$B$23*Assumptions!$B$24)*(1-B$5))/Assumptions!$B$6 -> 47.935967 | C9: =((DCF!$B$21+$A9*100*DCF!$B$27-Assumptions!$B$19-Assumptions!$B$20+Assumptions!$B$21*Assumptions!$B$22+Assumptions!$B$23*Assumptions!$B$24)*(1-C$5))/Assumptions!$B$6 -> 45.539168 | D9: =((DCF!$B$21+$A9*100*DCF!$B$27-Assumptions!$B$19-Assumptions!$B$20+Assumptions!$B$21*Assumptions!$B$22+Assumptions!$B$23*Assumptions!$B$24)*(1-D$5))/Assumptions!$B$6 -> 43.14237 | E9: =((DCF!$B$21+$A9*100*DCF!$B$27-Assumptions!$B$19-Assumptions!$B$20+Assumptions!$B$21*Assumptions!$B$22+Assumptions!$B$23*Assumptions!$B$24)*(1-E$5))/Assumptions!$B$6 -> 40.745572 | F9: =((DCF!$B$21+$A9*100*DCF!$B$27-Assumptions!$B$19-Assumptions!$B$20+Assumptions!$B$21*Assumptions!$B$22+Assumptions!$B$23*Assumptions!$B$24)*(1-F$5))/Assumptions!$B$6 -> 38.348773
A10: 0.02 | B10: =((DCF!$B$21+$A10*100*DCF!$B$27-Assumptions!$B$19-Assumptions!$B$20+Assumptions!$B$21*Assumptions!$B$22+Assumptions!$B$23*Assumptions!$B$24)*(1-B$5))/Assumptions!$B$6 -> 53.227399 | C10: =((DCF!$B$21+$A10*100*DCF!$B$27-Assumptions!$B$19-Assumptions!$B$20+Assumptions!$B$21*Assumptions!$B$22+Assumptions!$B$23*Assumptions!$B$24)*(1-C$5))/Assumptions!$B$6 -> 50.566029 | D10: =((DCF!$B$21+$A10*100*DCF!$B$27-Assumptions!$B$19-Assumptions!$B$20+Assumptions!$B$21*Assumptions!$B$22+Assumptions!$B$23*Assumptions!$B$24)*(1-D$5))/Assumptions!$B$6 -> 47.904659 | E10: =((DCF!$B$21+$A10*100*DCF!$B$27-Assumptions!$B$19-Assumptions!$B$20+Assumptions!$B$21*Assumptions!$B$22+Assumptions!$B$23*Assumptions!$B$24)*(1-E$5))/Assumptions!$B$6 -> 45.243289 | F10: =((DCF!$B$21+$A10*100*DCF!$B$27-Assumptions!$B$19-Assumptions!$B$20+Assumptions!$B$21*Assumptions!$B$22+Assumptions!$B$23*Assumptions!$B$24)*(1-F$5))/Assumptions!$B$6 -> 42.581919
A12: Bold-face cells near spot (31.25) show how much Auto-margin recovery the price already carries.

Sheet Per-Share & Ratios
A1: Per-share & ratios — the standing dashboard (device A-5)
A2: Links to statements / Assumptions.
B4: FY23 | C4: FY24 | D4: FY25 | E4: FY26E | F4: FY27E | G4: FY28E | H4: FY29E | I4: FY30E
A6: EPS (EGP) | B6: ='Income Statement'!B26/Assumptions!$B$6 -> 1.7418701 | C6: ='Income Statement'!C26/Assumptions!$B$6 -> 2.6974666 | D6: ='Income Statement'!D26/Assumptions!$B$6 -> 2.6531552 | E6: ='Income Statement'!E26/Assumptions!$B$6 -> 3.0377829 | F6: ='Income Statement'!F26/Assumptions!$B$6 -> 4.9135707 | G6: ='Income Statement'!G26/Assumptions!$B$6 -> 6.885059 | H6: ='Income Statement'!H26/Assumptions!$B$6 -> 8.5758564 | I6: ='Income Statement'!I26/Assumptions!$B$6 -> 10.334976
A7: DPS (EGP) | B7: ='Income Statement'!B26*0.13/Assumptions!$B$6 -> 0.22644311 | C7: ='Income Statement'!C26*0.13/Assumptions!$B$6 -> 0.35067066 | D7: ='Income Statement'!D26*0.13/Assumptions!$B$6 -> 0.34491018 | E7: ='Income Statement'!E26*Assumptions!C$72/Assumptions!$B$6 -> 0.42528961 | F7: ='Income Statement'!F26*Assumptions!D$72/Assumptions!$B$6 -> 0.7370356 | G7: ='Income Statement'!G26*Assumptions!E$72/Assumptions!$B$6 -> 1.1016094 | H7: ='Income Statement'!H26*Assumptions!F$72/Assumptions!$B$6 -> 1.5436542 | I7: ='Income Statement'!I26*Assumptions!G$72/Assumptions!$B$6 -> 2.0669952
A8: Book value / share (EGP) | B8: ='Balance Sheet'!B16/Assumptions!$B$6 -> 18.276186 | C8: ='Balance Sheet'!C16/Assumptions!$B$6 -> 23.434823 | D8: ='Balance Sheet'!D16/Assumptions!$B$6 -> 26.521142 | E8: ='Balance Sheet'!E16/Assumptions!$B$6 -> 29.133636 | F8: ='Balance Sheet'!F16/Assumptions!$B$6 -> 33.310171 | G8: ='Balance Sheet'!G16/Assumptions!$B$6 -> 39.09362 | H8: ='Balance Sheet'!H16/Assumptions!$B$6 -> 46.125823 | I8: ='Balance Sheet'!I16/Assumptions!$B$6 -> 54.393803
A9: P/E at spot (×) | B9: =Assumptions!$B$5/('Income Statement'!B26/Assumptions!$B$6) -> 17.940488 | C9: =Assumptions!$B$5/('Income Statement'!C26/Assumptions!$B$6) -> 11.584944 | D9: =Assumptions!$B$5/('Income Statement'!D26/Assumptions!$B$6) -> 11.778429 | E9: =Assumptions!$B$5/('Income Statement'!E26/Assumptions!$B$6) -> 10.287108 | F9: =Assumptions!$B$5/('Income Statement'!F26/Assumptions!$B$6) -> 6.359937 | G9: =Assumptions!$B$5/('Income Statement'!G26/Assumptions!$B$6) -> 4.5388137 | H9: =Assumptions!$B$5/('Income Statement'!H26/Assumptions!$B$6) -> 3.6439509 | I9: =Assumptions!$B$5/('Income Statement'!I26/Assumptions!$B$6) -> 3.0237129
A10: P/B at spot (×) | B10: =Assumptions!$B$5/('Balance Sheet'!B16/Assumptions!$B$6) -> 1.7098753 | C10: =Assumptions!$B$5/('Balance Sheet'!C16/Assumptions!$B$6) -> 1.3334857 | D10: =Assumptions!$B$5/('Balance Sheet'!D16/Assumptions!$B$6) -> 1.1783052 | E10: =Assumptions!$B$5/('Balance Sheet'!E16/Assumptions!$B$6) -> 1.0726433 | F10: =Assumptions!$B$5/('Balance Sheet'!F16/Assumptions!$B$6) -> 0.9381519 | G10: =Assumptions!$B$5/('Balance Sheet'!G16/Assumptions!$B$6) -> 0.79936316 | H10: =Assumptions!$B$5/('Balance Sheet'!H16/Assumptions!$B$6) -> 0.67749469 | I10: =Assumptions!$B$5/('Balance Sheet'!I16/Assumptions!$B$6) -> 0.57451397
A11: Dividend yield at spot | B11: =B7/Assumptions!$B$5 -> 0.0072461796 | C11: =C7/Assumptions!$B$5 -> 0.011221461 | D11: =D7/Assumptions!$B$5 -> 0.011037126 | E11: =E7/Assumptions!$B$5 -> 0.013609267 | F11: =F7/Assumptions!$B$5 -> 0.023585139 | G11: =G7/Assumptions!$B$5 -> 0.035251502 | H11: =H7/Assumptions!$B$5 -> 0.049396933 | I11: =I7/Assumptions!$B$5 -> 0.066143845
A12: EBITDA margin | B12: ='Income Statement'!B19/'Income Statement'!B9 -> 0.19738887 | C12: ='Income Statement'!C19/'Income Statement'!C9 -> 0.14301596 | D12: ='Income Statement'!D19/'Income Statement'!D9 -> 0.11029194 | E12: ='Income Statement'!E19/'Income Statement'!E9 -> 0.10318352 | F12: ='Income Statement'!F19/'Income Statement'!F9 -> 0.1068378 | G12: ='Income Statement'!G19/'Income Statement'!G9 -> 0.1103122 | H12: ='Income Statement'!H19/'Income Statement'!H9 -> 0.11119418 | I12: ='Income Statement'!I19/'Income Statement'!I9 -> 0.11225168
A13: Net margin | B13: ='Income Statement'!B26/'Income Statement'!B9 -> 0.066772138 | C13: ='Income Statement'!C26/'Income Statement'!C9 -> 0.054254718 | D13: ='Income Statement'!D26/'Income Statement'!D9 -> 0.035896886 | E13: ='Income Statement'!E26/'Income Statement'!E9 -> 0.033366281 | F13: ='Income Statement'!F26/'Income Statement'!F9 -> 0.04365854 | G13: ='Income Statement'!G26/'Income Statement'!G9 -> 0.051338178 | H13: ='Income Statement'!H26/'Income Statement'!H9 -> 0.055238615 | I13: ='Income Statement'!I26/'Income Statement'!I9 -> 0.058486061
A14: ROAE (attributable) | B14: ='Income Statement'!B26/'Balance Sheet'!B16 -> 0.095308184 | C14: ='Income Statement'!C26/'Balance Sheet'!C16 -> 0.11510506 | D14: ='Income Statement'!D26/'Balance Sheet'!D16 -> 0.10003925 | E14: ='Income Statement'!E26/'Balance Sheet'!E16 -> 0.10427064 | F14: ='Income Statement'!F26/'Balance Sheet'!F16 -> 0.14750962 | G14: ='Income Statement'!G26/'Balance Sheet'!G16 -> 0.1761172 | H14: ='Income Statement'!H26/'Balance Sheet'!H16 -> 0.18592311 | I14: ='Income Statement'!I26/'Balance Sheet'!I16 -> 0.19000282
A15: Group net debt / EBITDA (×) | B15: ='Balance Sheet'!B28/'Income Statement'!B19 -> 1.4336703 | C15: ='Balance Sheet'!C28/'Income Statement'!C19 -> 1.9677139 | D15: ='Balance Sheet'!D28/'Income Statement'!D19 -> 3.2228237 | E15: ='Balance Sheet'!E28/'Income Statement'!E19 -> 3.6451121 | F15: ='Balance Sheet'!F28/'Income Statement'!F19 -> 3.463441 | G15: ='Balance Sheet'!G28/'Income Statement'!G19 -> 3.212948 | H15: ='Balance Sheet'!H28/'Income Statement'!H19 -> 3.0416584 | I15: ='Balance Sheet'!I28/'Income Statement'!I19 -> 2.8545009
A16: Revenue YoY | C16: ='Income Statement'!C9/'Income Statement'!B9-1 -> 0.90589112 | D16: ='Income Statement'!D9/'Income Statement'!C9-1 -> 0.48657668 | E16: ='Income Statement'!E9/'Income Statement'!D9-1 -> 0.23180808 | F16: ='Income Statement'!F9/'Income Statement'!E9-1 -> 0.23617247 | G16: ='Income Statement'!G9/'Income Statement'!F9-1 -> 0.19162396 | H16: ='Income Statement'!H9/'Income Statement'!G9-1 -> 0.15762394 | I16: ='Income Statement'!I9/'Income Statement'!H9-1 -> 0.13820993
A17: EPS YoY | C17: =('Income Statement'!C26/'Income Statement'!B26)-1 -> 0.54860377 | D17: =('Income Statement'!D26/'Income Statement'!C26)-1 -> -0.016427035 | E17: =('Income Statement'!E26/'Income Statement'!D26)-1 -> 0.14496991 | F17: =('Income Statement'!F26/'Income Statement'!E26)-1 -> 0.61748578 | G17: =('Income Statement'!G26/'Income Statement'!F26)-1 -> 0.40123334 | H17: =('Income Statement'!H26/'Income Statement'!G26)-1 -> 0.24557486 | I17: =('Income Statement'!I26/'Income Statement'!H26)-1 -> 0.20512463
A19: Group net-debt/EBITDA blends the lender funding book; the Auto-leg discipline metric is Auto ND/EBITDA (2.39× FY25, 2.14× 1Q26, disclosed).

Sheet Peer & Sector
A1: Peer set & sector
A2: No clean single comparable — GB Corp is an auto operator plus an NBFI plus a fintech associate. Split by leg.
A5: Leg | B5: Closest peers | C5: Typical valuation
A6: Auto assembly & distribution | B6: Al Watania (KSA autos), Saudi Co. for Vehicles, Türk Traktör, Astra Industrial; EGX consumer durables | C6: EV/EBITDA ~4–6× (EM distribution); P/E ~8–12×
A7: NBFI / leasing & consumer finance | B7: EFG Hermes (NBFI arm), Contact Financial (CNFN), Raya Holding finance leg | C7: P/B ~1.0–1.8× on mid-teens ROE; P/E ~6–10×
A8: Fintech associate (MNT-Halan) | B8: Fawry (FWRY), e-Finance (EFIH), MNT-Halan private rounds | C8: Private marks; EV/Rev 2–5×; last round USD 1.4bn (Jun-26)
A10: Sector context: Egypt PC registrations ~210k in 2025 (+40% y/y), GB share ~21%; CBE easing cycle (19.00% deposit rate) supports affordability and GB Capital margins; BYD entering Egypt; Iraq/Jordan drag from the regional conflict; Sadat CKD facility inaugurated Jun-2026.
A11: Analyst context is deliberately not used as a model input (house rule: no rating, no target).
