Workbook

Sheet READ FIRST
B2: GB Corp (GBCO.CA / EGX) — valuation model, fundamental refresh of 19 August 2026
B6: What this file is. The full re-build of the July 2026 model on the H1-2026 disclosure set: the KPMG-reviewed consolidated interim financial statements of 30 June 2026 and the 2Q/1H26 results release, both published 13 August 2026.
B8: Blue cells are inputs — every one is a disclosed figure, a sourced market quote, or a stated modelling decision, annotated where it sits. Black cells are formulas: change a blue driver on the Assumptions sheet and the fair value reprices through Segments, the cash-flow model, the holding bridge and the summary.
B10: The contested stake is computed both ways, side by side, and never averaged: MNT-Halan at the June-2026 funding-round mark (USD 1.4bn, first close) and at the company's own balance-sheet carrying value (EGP 15.72bn, equity-method, which the reviewer could not verify — a qualified review conclusion, second consecutive period). The two SOTP and central values are shown in parallel everywhere.
B12: The price-probability sheet reproduces the site's published price map unchanged (struck 22 July 2026). This refresh moves the fundamental fair-value range only; the price map and technical levels are on their own clock and were not re-struck.
B14: Line-of-business revenue is on the results-release basis; per-line margins are anchored on the statements' segment note, whose boundaries differ slightly (statement passenger-car revenue includes after-sales). Flagged here once; both bases are shown on Segments.
B16: All amounts in EGP millions unless stated. Model date 19 August 2026.

Sheet Summary
B2: GB Corp — fair value at a glance (refresh of 19 August 2026)
A4: Last library close (22-Jul-26) | B4: =Assumptions!B6
A5: Fair value — bear | B5: ='Fundamental Valuation'!B15
A6: Fair value — base (round mark) | B6: ='Fundamental Valuation'!B16
A7: Fair value — central under the balance-sheet mark | B7: ='Fundamental Valuation'!B12
A8: Fair value — bull | B8: ='Fundamental Valuation'!B17
A10: H1-26 group revenue (+35.2%) | B10: 48474.374
A11: H1-26 group net profit (−24.5%) | B11: 1262.006
A12: Automotive net debt, 30-Jun-26 (2.14x EBITDA) | B12: 14493.6
A13: MNT-Halan gap, per share (round vs book, post-discount) | B13: 12.232871
A15: The July study's range was 23.3 / 35.7 / 51. The base barely moves; the bear deepens because the company's own accounts now carry the contested stake at half the round, under a qualified review.

Sheet Fundamental Valuation
B2: Four lenses, one field — the synthesis (both framings of the contested stake)
A4: Lens | B4: Value / share | C4: Weight
A5: Sum of the parts — round mark | B5: ='SOTP Bridge'!B13 | C5: 0.4
A6: Sum of the parts — balance-sheet mark | B6: ='SOTP Bridge'!C13 | C6: same weight as row 5 — the framings alternate, they never blend
A7: Book value & sustainable return | B7: 30.819224 | C7: 0.15 | D7: restated book per share (30-Jun-26 parent equity / shares)
A8: Relative multiples | B8: ='Relative & Normalized'!C6 | C8: 0.2
A9: Normalised earnings power | B9: ='Relative & Normalized'!C14 | C9: 0.25
A11: Weighted central — round mark | B11: =B5*C5+B7*C7+B8*C8+B9*C9
A12: Weighted central — balance-sheet mark | B12: =B6*C5+B7*C7+B8*C8+B9*C9
A14: Published range
A15: Bear (balance-sheet-mark world, operating bear) | B15: 19.4
A16: Base (round-mark central) | B16: =B11
A17: Bull (round-mark world, operating bull) | B17: 47.4

Sheet Assumptions
B2: Assumptions — every driver of the model, with source and date
B4: Capital & market
B5: 1085.5 | C5: Shares outstanding (mn) — 2Q/1H26 release
B6: 31.31 | C6: Last library close, 22-Jul-2026 (published page anchor)
B7: 29.7 | C7: EGX quote on the company's IR page, 19-Aug-2026 (market-cap basis)
B8: 0.225 | C8: Statutory corporate tax (FS note 11-C)
B9: 0.115 | C9: Terminal growth, nominal EGP
B11: Cost of capital (v2: rf* = observed yield − sovereign's own default spread)
B12: 0.2292 | C12: Egypt 10Y local yield, investing.com 19-Aug-2026
B13: 0.0637 | C13: Adjusted default spread, rating basis — Damodaran Jan-2026
B14: 0.0341 | C14: Sovereign CDS spread — Damodaran Jan-2026
B15: 0.1394 | C15: Total ERP, rating basis — Damodaran Jan-2026
B16: 0.0941 | C16: Total ERP, sovereign-CDS basis — Damodaran Jan-2026
B17: 0.89274821 | C17: Weekly beta vs EGX30, 5y Dimson (n=255, R2 0.24) — own regression
B18: 0.2082 | C18: Avg rate, current EGP borrowings H1-26 — FS note 26 (variable-rate book)
B19: 0.1968 | C19: USD tranche in local-equivalent terms: 7.78% + expected depreciation
B20: 0.9 | C20: EGP share of auto-leg debt (USD split not disclosed; bounded, flagged)
B21: 25078.9 | C21: Auto-leg gross debt + leasing notes, 30-Jun-26 (release table 7)
B22: =B7*B5 | C22: Market capitalisation (IR-page quote x shares)
B23: =B22/(B22+B21) | C23: Equity weight (market value)
B24: =1-B23 | C24: Debt weight
B25: =B12-B14+B17*B16 | C25: Cost of equity, CDS basis
B26: =B12-B13+B17*B15 | C26: Cost of equity, rating basis
B27: =B20*B18+(1-B20)*B19 | C27: Blended pre-tax cost of debt
B28: =B27*(1-B8) | C28: After-tax cost of debt
B29: =B23*B25+B24*B28 | C29: WACC — CDS-basis ERP (primary)
B30: =B23*B26+B24*B28 | C30: WACC — rating-basis ERP (published alongside)
B32: Growth & operating drivers (FY27E-FY30E; FY26E is anchored on the H1 actual)
A33: pc volume growth | E33: anchored | F33: 0.09 | G33: 0.08 | H33: 0.06 | I33: 0.05
A34: pc price growth | E34: anchored | F34: 0.08 | G34: 0.07 | H34: 0.06 | I34: 0.06
A35: cv volume growth | E35: anchored | F35: 0.14 | G35: 0.1 | H35: 0.08 | I35: 0.07
A36: cv price growth | E36: anchored | F36: 0.07 | G36: 0.06 | H36: 0.06 | I36: 0.05
A37: lm volume growth | E37: anchored | F37: 0.16 | G37: 0.13 | H37: 0.11 | I37: 0.09
A38: lm price growth | E38: anchored | F38: 0.06 | G38: 0.05 | H38: 0.05 | I38: 0.05
A39: trading growth | E39: anchored | F39: 0.11 | G39: 0.1 | H39: 0.09 | I39: 0.08
A40: other-auto growth | E40: anchored | F40: 0.1 | G40: 0.1 | H40: 0.09 | I40: 0.08
A41: imported-cost escalator (FX path) | E41: 0.045 | F41: 0.08 | G41: 0.07 | H41: 0.06 | I41: 0.05
A42: domestic-cost escalator (CPI path) | E42: 0.06 | F42: 0.12 | G42: 0.1 | H42: 0.09 | I42: 0.08
A43: GS&A % of revenue | E43: 0.071 | F43: 0.0705 | G43: 0.07 | H43: 0.0692 | I43: 0.0685
A44: D&A % of revenue | E44: 0.01 | F44: 0.0102 | G44: 0.0104 | H44: 0.0104 | I44: 0.0104
...

Sheet SOTP Bridge
B2: Holding bridge — the group as the sum of its parts, with the contested stake both ways
B4: Round mark | C4: Balance-sheet mark
A5: Automotive equity value (cash-flow model) | B5: =DCF!B34 | C5: =DCF!B34
A6: GB Capital operating equity (ex-associates) | B6: =Assumptions!B63 | C6: =Assumptions!B63
A7: MNT-Halan stake | B7: =Assumptions!B67 | C7: =Assumptions!B59
A8: Other associates | B8: =Assumptions!B60 | C8: =Assumptions!B60
A9: Investments at fair value (OCI) | B9: =Assumptions!B61 | C9: =Assumptions!B61
A10: Sum of the parts | B10: =SUM(B5:B9) | C10: =SUM(C5:C9)
A11: Holding-company discount | B11: =-B10*Assumptions!B62 | C11: =-C10*Assumptions!B62
A12: Equity value | B12: =B10+B11 | C12: =C10+C11
A13: Per share | B13: =B12/Assumptions!B5 | C13: =C12/Assumptions!B5
A15: The gap between the two columns is one judgement: EGP 14,754mn of MNT-Halan mark — 12.23 per share after the discount. The reviewer could not verify the balance-sheet figure (qualified conclusion); the round is real third-party money but a first close with a second pending. Neither is averaged away.
A17: Bear cases (operating bear + leg haircuts + 18% discount) | B17: 17.401613 | C17: 8.9661839
A18: Bull cases (operating bull + 4% discount) | B18: 54.717399 | C18: 40.452291
A19: Case values re-run the cash-flow model under the shifted drivers described in the study's sensitivity section; recorded here as results of that re-run.

Sheet Segments
B2: Line-of-business build (release basis; margins anchored on the statements' segment note)
B4: FY23 | C4: FY24 | D4: FY25 | E4: FY26E | F4: FY27E | G4: FY28E | H4: FY29E | I4: FY30E
A5: PC volumes (units) | B5: 26994 | C5: 42043 | D5: 56548 | E5: 64300 | F5: =E5*(1+Assumptions!F33) | G5: =F5*(1+Assumptions!G33) | H5: =G5*(1+Assumptions!H33) | I5: =H5*(1+Assumptions!I33)
A6: PC average selling price (EGP mn) | B6: =B7/B5 | C6: =C7/C5 | D6: =D7/D5 | E6: =E7/E5 | F6: =E6*(1+Assumptions!F34) | G6: =F6*(1+Assumptions!G34) | H6: =G6*(1+Assumptions!H34) | I6: =H6*(1+Assumptions!I34)
A7: PC revenue | B7: 16544.3 | C7: 36533.4 | D7: 52827.3 | E7: =B38+(E5-B37)*(B38/B37)*1.025 | F7: =F5*F6 | G7: =G5*G6 | H7: =H5*H6 | I7: =I5*I6
A8: CV&CE revenue | B8: 2323 | C8: 3984.5 | D8: 5956.8 | E8: 10100 | F8: =E8*(1+Assumptions!F35)*(1+Assumptions!F36) | G8: =F8*(1+Assumptions!G35)*(1+Assumptions!G36) | H8: =G8*(1+Assumptions!H35)*(1+Assumptions!H36) | I8: =H8*(1+Assumptions!I35)*(1+Assumptions!I36)
A9: Light-Mobility revenue | B9: 854.2 | C9: 1378.2 | D9: 2203.8 | E9: 3350 | F9: =E9*(1+Assumptions!F37)*(1+Assumptions!F38) | G9: =F9*(1+Assumptions!G37)*(1+Assumptions!G38) | H9: =G9*(1+Assumptions!H37)*(1+Assumptions!H38) | I9: =H9*(1+Assumptions!I37)*(1+Assumptions!I38)
A10: Trading revenue | B10: 2506.8 | C10: 3815.5 | D10: 4242.8 | E10: 4800 | F10: =E10*(1+Assumptions!F39) | G10: =F10*(1+Assumptions!G39) | H10: =G10*(1+Assumptions!H39) | I10: =H10*(1+Assumptions!I39)
A11: Other automotive revenue | B11: 7625.2 | C11: 1353.4 | D11: 1127.6 | E11: 1340 | F11: =E11*(1+Assumptions!F40) | G11: =F11*(1+Assumptions!G40) | H11: =G11*(1+Assumptions!H40) | I11: =H11*(1+Assumptions!I40)
A12: Automotive revenue | B12: =SUM(B7:B11) | C12: =SUM(C7:C11) | D12: =SUM(D7:D11) | E12: =SUM(E7:E11) | F12: =SUM(F7:F11) | G12: =SUM(G7:G11) | H12: =SUM(H7:H11) | I12: =SUM(I7:I11)
A13: Automotive gross profit | B13: 5813.1 | C13: 9057.4 | D13: 9837.1 | E13: =B40+(E12-B39)*B48 | F13: =F7*(1-F17)+F8*(1-F18)+F9*(1-F19)+F10*(1-F20)+F11*(1-F21) | G13: =G7*(1-G17)+G8*(1-G18)+G9*(1-G19)+G10*(1-G20)+G11*(1-G21) | H13: =H7*(1-H17)+H8*(1-H18)+H9*(1-H19)+H10*(1-H20)+H11*(1-H21) | I13: =I7*(1-I17)+I8*(1-I18)+I9*(1-I19)+I10*(1-I20)+I11*(1-I21)
A14: Automotive gross margin | B14: =B13/B12 | C14: =C13/C12 | D14: =D13/D12 | E14: =E13/E12 | F14: =F13/F12 | G14: =G13/G12 | H14: =H13/H12 | I14: =I13/I12
A16: Cost side — cost per revenue-unit by line (statement-note anchors; escalated one class per physical driver: imported share on the FX path, domestic share on the CPI path; FY28E+ cost moves with price — one measured year of compression carried, not a story)
A17: PC cost ratio | E17: 0.86683703 | F17: =E17*(1+Assumptions!B52*Assumptions!F41+(1-Assumptions!B52)*Assumptions!F42)/(1+Assumptions!F34) | G17: =F17 | H17: =G17 | I17: =H17
A18: CV&CE cost ratio | E18: 0.81364704 | F18: =E18*(1+Assumptions!C52*Assumptions!F41+(1-Assumptions!C52)*Assumptions!F42)/(1+Assumptions!F36) | G18: =F18 | H18: =G18 | I18: =H18
A19: LM cost ratio | E19: 0.88542193 | F19: =E19*(1+Assumptions!D52*Assumptions!F41+(1-Assumptions!D52)*Assumptions!F42)/(1+Assumptions!F38) | G19: =F19 | H19: =G19 | I19: =H19
A20: Trading cost ratio | E20: 0.79734177 | F20: =E20*(1+Assumptions!E52*Assumptions!F41+(1-Assumptions!E52)*Assumptions!F42)/(1+0.06)*1.04 | G20: =F20 | H20: =G20 | I20: =H20
A21: Other-auto cost ratio | E21: 0.818 | F21: =E21*(1+Assumptions!E52*Assumptions!F41+(1-Assumptions!E52)*Assumptions!F42)/(1+0.06) | G21: =F21 | H21: =G21 | I21: =H21
A23: GB Capital
A24: GB Capital revenue | B24: 4950.9 | C24: 7383.6 | D24: 14743 | E24: 18700 | F24: =E24*(1+0.2) | G24: =F24*(1+0.17) | H24: =G24*(1+0.15) | I24: =H24*(1+0.12)
A25: GB Capital net profit (after tax & NCI, incl associates) | E25: 1450 | F25: 1750 | G25: 2050 | H25: 2350 | I25: 2650
A36: H1-2026 actuals (release / statements)
A37: PC volumes H1-26 (units) | B37: 29554
A38: PC revenue H1-26 | B38: 30595.7
A39: Auto revenue H1-26 | B39: 40021.5
A40: Auto gross profit H1-26 | B40: 5722.1
A41: Auto GPM H1-25 | B41: 0.15492604
A42: Auto GPM H2-25 (derived from FY25 less H1-25) | B42: 0.14249725
A43: CV&CE revenue H1-26 | B43: 4749.1
A44: Light-Mobility revenue H1-26 | B44: 1435.2
A45: Trading revenue H1-26 | B45: 2572.3
A46: Other-auto revenue H1-26 (residual) | B46: 669.2
A47: Auto GPM H1-26 | B47: =B40/B39
A48: H2-26E GPM (H1 less the measured FY25 seasonal gap) | B48: =B47-(B41-B42)

Sheet Relative & Normalized
B2: Relative multiples and normalised earnings power
A4: FY26E group earnings per share | B4: ='Income Statement'!E17
A5: Multiple band (bear / base / bull) | B5: 8 | C5: 9.5 | D5: 11
A6: Relative lens value | B6: =B4*B5 | C6: =B4*C5 | D6: =B4*D5
A8: Normalisation walk (mid-cycle)
A9: FY27E automotive EBIT | B9: =DCF!F10
A10: Normalised finance cost (net debt x the eased-rate endpoint) | B10: =-Assumptions!B64*0.17
A11: Tax at the statutory 22.5% | B11: =-(B9+B10)*Assumptions!B8
A12: GB Capital net profit (FY27E, incl associates) | B12: =Segments!F25
A13: Normalised group profit | B13: =B9+B10+B11+B12
A14: Normalised earnings lens (x 7.5 / 8.5 / 9.5) | B14: =B13*0.85/Assumptions!B5*7.5 | C14: =B13/Assumptions!B5*8.5 | D14: =B13*1.12/Assumptions!B5*9.5

Sheet DCF
B2: Automotive leg — free cash flow to the firm, discounted at the group's own cost of capital
E4: FY26E | F4: FY27E | G4: FY28E | H4: FY29E | I4: FY30E
A5: Revenue | E5: =Segments!E12 | F5: =Segments!F12 | G5: =Segments!G12 | H5: =Segments!H12 | I5: =Segments!I12
A6: Gross profit | E6: =Segments!E13 | F6: =Segments!F13 | G6: =Segments!G13 | H6: =Segments!H13 | I6: =Segments!I13
A7: GS&A | E7: =-E5*Assumptions!E43 | F7: =-F5*Assumptions!F43 | G7: =-G5*Assumptions!G43 | H7: =-H5*Assumptions!H43 | I7: =-I5*Assumptions!I43
A8: Other operating income | E8: =E5*Assumptions!$B$50 | F8: =F5*Assumptions!$B$50 | G8: =G5*Assumptions!$B$50 | H8: =H5*Assumptions!$B$50 | I8: =I5*Assumptions!$B$50
A9: Net provisions | E9: =E5*Assumptions!$B$51 | F9: =F5*Assumptions!$B$51 | G9: =G5*Assumptions!$B$51 | H9: =H5*Assumptions!$B$51 | I9: =I5*Assumptions!$B$51
A10: EBIT | E10: =E6+E7+E8+E9 | F10: =F6+F7+F8+F9 | G10: =G6+G7+G8+G9 | H10: =H6+H7+H8+H9 | I10: =I6+I7+I8+I9
A11: Effective tax rate | E11: =Assumptions!E45 | F11: =Assumptions!F45 | G11: =Assumptions!G45 | H11: =Assumptions!H45 | I11: =Assumptions!I45
A12: NOPAT | E12: =E10*(1-E11) | F12: =F10*(1-F11) | G12: =G10*(1-G11) | H12: =H10*(1-H11) | I12: =I10*(1-I11)
A13: Depreciation & amortisation | E13: =E5*Assumptions!E44 | F13: =F5*Assumptions!F44 | G13: =G5*Assumptions!G44 | H13: =H5*Assumptions!H44 | I13: =I5*Assumptions!I44
A14: EBITDA | E14: =E10+E13 | F14: =F10+F13 | G14: =G10+G13 | H14: =H10+H13 | I14: =I10+I13
A15: Capex | E15: =-Assumptions!E46 | F15: =-Assumptions!F46 | G15: =-Assumptions!G46 | H15: =-Assumptions!H46 | I15: =-Assumptions!I46
A16: Working capital (level) | E16: =E5*Assumptions!E47 | F16: =F5*Assumptions!F47 | G16: =G5*Assumptions!G47 | H16: =H5*Assumptions!H47 | I16: =I5*Assumptions!I47
A17: Change in working capital | E17: =E16-18917.0 | F17: =F16-E16 | G17: =G16-F16 | H17: =H16-G16 | I17: =I16-H16
A18: Free cash flow to the firm | E18: =E12+E13+E15-E17 | F18: =F12+F13+F15-F17 | G18: =G12+G13+G15-G17 | H18: =H12+H13+H15-H17 | I18: =I12+I13+I15-I17
A20: Valuation is dated 30 June 2026: the realized first half is carried at its actual, and the second half plus four further years are discounted mid-period.
A21: H1-26 realized free cash flow | B21: =Assumptions!B66
A22: H2-26E free cash flow | B22: =E18-B21
A24: Discount period (years) | E24: 0.5 | F24: 1.5 | G24: 2.5 | H24: 3.5 | I24: 4.5
A25: Discount factor | E25: =1/(1+Assumptions!$B$29)^E24 | F25: =1/(1+Assumptions!$B$29)^F24 | G25: =1/(1+Assumptions!$B$29)^G24 | H25: =1/(1+Assumptions!$B$29)^H24 | I25: =1/(1+Assumptions!$B$29)^I24
A26: Present value | E26: =B22*E25 | F26: =F18*F25 | G26: =G18*G25 | H26: =H18*H25 | I26: =I18*I25
A28: Sum of discounted flows | B28: =SUM(E26:I26)
A29: Terminal value (Gordon on FY30E) | B29: =I18*(1+Assumptions!B9)/(Assumptions!B29-Assumptions!B9)
A30: PV of terminal value | B30: =B29*I25
A31: Enterprise value — automotive | B31: =B28+B30
A32: Less: automotive net debt (30-Jun-26) | B32: =-Assumptions!B64
A33: Less: automotive non-controlling interests | B33: =-Assumptions!B65
A34: Automotive equity value | B34: =B31+B32+B33
A35: Per share | B35: =B34/Assumptions!B5
A37: Terminal share of enterprise value | B37: =B30/B31

Sheet Income Statement
B2: Group income statement — three disclosed years and the five-year model
B4: FY23 | C4: FY24 | D4: FY25 | E4: FY26E | F4: FY27E | G4: FY28E | H4: FY29E | I4: FY30E
A5: Automotive revenue | B5: 23854 | C5: 47065 | D5: 66358.3 | E5: =Segments!E12 | F5: =Segments!F12 | G5: =Segments!G12 | H5: =Segments!H12 | I5: =Segments!I12
A6: GB Capital revenue | B6: 4950.9 | C6: 7383.6 | D6: 14743 | E6: =Segments!E24 | F6: =Segments!F24 | G6: =Segments!G24 | H6: =Segments!H24 | I6: =Segments!I24
A7: Inter-segment eliminations | B7: -487.7 | C7: -479.1 | D7: -871.5 | E7: =-(E5+E6)*0.013 | F7: =-(F5+F6)*0.013 | G7: =-(G5+G6)*0.013 | H7: =-(H5+H6)*0.013 | I7: =-(I5+I6)*0.013
A8: Group revenue | B8: =SUM(B5:B7) | C8: =SUM(C5:C7) | D8: =SUM(D5:D7) | E8: =SUM(E5:E7) | F8: =SUM(F5:F7) | G8: =SUM(G5:G7) | H8: =SUM(H5:H7) | I8: =SUM(I5:I7)
A10: Automotive EBIT | E10: =DCF!E10 | F10: =DCF!F10 | G10: =DCF!G10 | H10: =DCF!H10 | I10: =DCF!I10
A11: Automotive finance cost | E11: =-(2206.7+0.5*Assumptions!B64*Assumptions!E48) | F11: =-'Balance Sheet'!E10*Assumptions!F48 | G11: =-'Balance Sheet'!F10*Assumptions!G48 | H11: =-'Balance Sheet'!G10*Assumptions!H48 | I11: =-'Balance Sheet'!H10*Assumptions!I48
A12: Automotive profit before tax | E12: =E10+E11 | F12: =F10+F11 | G12: =G10+G11 | H12: =H10+H11 | I12: =I10+I11
A13: Automotive tax | E13: =-E12*DCF!E11 | F13: =-F12*DCF!F11 | G13: =-G12*DCF!G11 | H13: =-H12*DCF!H11 | I13: =-I12*DCF!I11
A14: Automotive net profit | E14: =E12+E13 | F14: =F12+F13 | G14: =G12+G13 | H14: =H12+H13 | I14: =I12+I13
A15: GB Capital net profit (incl associates) | E15: =Segments!E25 | F15: =Segments!F25 | G15: =Segments!G25 | H15: =Segments!H25 | I15: =Segments!I25
A16: Group net profit (attributable) | E16: =E14+E15 | F16: =F14+F15 | G16: =G14+G15 | H16: =H14+H15 | I16: =I14+I15
A17: Earnings per share (EGP) | E17: =E16/Assumptions!$B$5 | F17: =F16/Assumptions!$B$5 | G17: =G16/Assumptions!$B$5 | H17: =H16/Assumptions!$B$5 | I17: =I16/Assumptions!$B$5
A19: Historical group lines (disclosed): net profit attributable FY23 1,890.8 / FY24 2,928.1 / FY25 2,880.0; H1-26 actual 1,262.0 (EPS 1.163). The model's FY26E includes that realized half.

Sheet Balance Sheet
B2: Condensed group balance-sheet model (working capital on its measured cycle)
D4: FY25 | E4: FY26E | F4: FY27E | G4: FY28E | H4: FY29E | I4: FY30E
A5: Automotive working capital | D5: 18917 | E5: =DCF!E16 | F5: =DCF!F16 | G5: =DCF!G16 | H5: =DCF!H16 | I5: =DCF!I16
A6: Net PP&E and intangibles (roll: + capex − D&A) | D6: 13389.1 | E6: =D6+DCF!E15*-1-DCF!E13 | F6: =E6+DCF!F15*-1-DCF!F13 | G6: =F6+DCF!G15*-1-DCF!G13 | H6: =G6+DCF!H15*-1-DCF!H13 | I6: =H6+DCF!I15*-1-DCF!I13
A7: Investments in associates (roll: + equity pickup) | D7: 16230.465 | E7: =D7+850.0 | F7: =E7+1065.0 | G7: =F7+1330.0 | H7: =G7+1600.0 | I7: =H7+1870.0
A8: GB Capital operating net assets (held) | D8: 6267.335 | E8: =Assumptions!$B$63 | F8: =Assumptions!$B$63 | G8: =Assumptions!$B$63 | H8: =Assumptions!$B$63 | I8: =Assumptions!$B$63
A10: Automotive net debt (cash-sweep roll) | D10: 14493.6 | E10: =D10-(DCF!E18+'Income Statement'!E11*(1-DCF!E11)-E12*0.85) | F10: =E10-(DCF!F18+'Income Statement'!F11*(1-DCF!F11)-F12*0.85) | G10: =F10-(DCF!G18+'Income Statement'!G11*(1-DCF!G11)-G12*0.85) | H10: =G10-(DCF!H18+'Income Statement'!H11*(1-DCF!H11)-H12*0.85) | I10: =H10-(DCF!I18+'Income Statement'!I11*(1-DCF!I11)-I12*0.85)
A11: Parent equity (roll: + profit − dividends) | D11: 33454.268 | E11: =D11+'Income Statement'!E16-E12 | F11: =E11+'Income Statement'!F16-F12 | G11: =F11+'Income Statement'!G16-G12 | H11: =G11+'Income Statement'!H16-H12 | I11: =H11+'Income Statement'!I16-I12
A12: Dividends paid (per-share held at the FY25 level) | E12: =0.35*Assumptions!$B$5 | F12: =0.35*Assumptions!$B$5 | G12: =0.35*Assumptions!$B$5 | H12: =0.35*Assumptions!$B$5 | I12: =0.35*Assumptions!$B$5
A14: FY25 associates column is the restated figure (the statements' note on prior-period adjustments raised the opening MNT B.V. carrying by 2,460.2).
A16: Book value per share | E16: =E11/Assumptions!$B$5 | F16: =F11/Assumptions!$B$5 | G16: =G11/Assumptions!$B$5 | H16: =H11/Assumptions!$B$5 | I16: =I11/Assumptions!$B$5
A18: Measured conversion cycle at 30-Jun-26 (from the statements): inventory 122 days of cost, receivables 27 days of revenue, payables 82 days of cost — a 67-day cash cycle. The working-capital ratio above projects that cycle; the five disclosed quarterly snapshots (16.7-18.9bn) are the anchor.

Sheet Cash Flow
B2: Condensed group cash-flow model
E4: FY26E | F4: FY27E | G4: FY28E | H4: FY29E | I4: FY30E
A5: Group net profit | E5: ='Income Statement'!E16 | F5: ='Income Statement'!F16 | G5: ='Income Statement'!G16 | H5: ='Income Statement'!H16 | I5: ='Income Statement'!I16
A6: Depreciation & amortisation | E6: =DCF!E13 | F6: =DCF!F13 | G6: =DCF!G13 | H6: =DCF!H13 | I6: =DCF!I13
A7: Change in working capital | E7: =-DCF!E17 | F7: =-DCF!F17 | G7: =-DCF!G17 | H7: =-DCF!H17 | I7: =-DCF!I17
A8: Capex | E8: =DCF!E15 | F8: =DCF!F15 | G8: =DCF!G15 | H8: =DCF!H15 | I8: =DCF!I15
A9: Dividends paid | E9: =-'Balance Sheet'!E12 | F9: =-'Balance Sheet'!F12 | G9: =-'Balance Sheet'!G12 | H9: =-'Balance Sheet'!H12 | I9: =-'Balance Sheet'!I12
A10: Operating & investing cash flow after dividends | E10: =SUM(E5:E9) | F10: =SUM(F5:F9) | G10: =SUM(G5:G9) | H10: =SUM(H5:H9) | I10: =SUM(I5:I9)
A11: Change in automotive net debt (from the sweep) | E11: ='Balance Sheet'!E10-Assumptions!B64 | F11: ='Balance Sheet'!F10-'Balance Sheet'!E10 | G11: ='Balance Sheet'!G10-'Balance Sheet'!F10 | H11: ='Balance Sheet'!H10-'Balance Sheet'!G10 | I11: ='Balance Sheet'!I10-'Balance Sheet'!H10
A13: Signs follow the model: a positive change in net debt funds the gap between spending and the cash the businesses release.

Sheet Summary Financials
B2: Summary financials (links)
B4: FY23 | C4: FY24 | D4: FY25 | E4: FY26E | F4: FY27E | G4: FY28E | H4: FY29E | I4: FY30E
A5: Group revenue | B5: ='Income Statement'!B8 | C5: ='Income Statement'!C8 | D5: ='Income Statement'!D8 | E5: ='Income Statement'!E8 | F5: ='Income Statement'!F8 | G5: ='Income Statement'!G8 | H5: ='Income Statement'!H8 | I5: ='Income Statement'!I8
A6: Automotive EBITDA | B6: 3794.6 | C6: 5880.5 | D6: 6363.3 | E6: =DCF!E14 | F6: =DCF!F14 | G6: =DCF!G14 | H6: =DCF!H14 | I6: =DCF!I14
A7: Group net profit (attributable) | B7: 1890.8 | C7: 2928.1 | D7: 2880 | E7: ='Income Statement'!E16 | F7: ='Income Statement'!F16 | G7: ='Income Statement'!G16 | H7: ='Income Statement'!H16 | I7: ='Income Statement'!I16
A8: Earnings per share (EGP) | B8: 1.742 | C8: 2.697 | D8: 2.653 | E8: ='Income Statement'!E17 | F8: ='Income Statement'!F17 | G8: ='Income Statement'!G17 | H8: ='Income Statement'!H17 | I8: ='Income Statement'!I17

Sheet Monte Carlo
B2: Published price-probability map — reproduced unchanged from the live page
A4: This sheet is a copy, not a computation. The map was struck on the closing library of 22 July 2026 and computed on 28 July 2026 (the page's own stamps: price data 2026-07-22, computed 2026-07-28). This refresh changes the fundamental fair-value range only; the probability map was NOT re-struck and is four weeks stale against the refresh date — its 1-month window resolves 23 August 2026. A fresh price data-set re-strikes it on its own clock.
A6: Horizon | C6: 5th | D6: 25th | E6: median | F6: 75th | G6: 95th
A7: 1 month (resolves 23-Aug-26) | C7: 25.55 | D7: 29.31 | E7: 31.78 | F7: 34.47 | G7: 39.54
A8: 3 months (resolves 22-Oct-26) | C8: 22.08 | D8: 28.34 | E8: 32.8 | F8: 37.86 | G8: 48.54
A10: Touch ladder (level, probability of touching within 1 month / 3 months, %)
B11: 40 | C11: 7 | D11: 30
B12: 38 | C12: 13 | D12: 40
B13: 36 | C13: 25 | D13: 54
B14: 34 | C14: 46 | D14: 71
B15: 32 | C15: 78 | D15: 89
B16: 30 | C16: 59 | D16: 73
B17: 28 | C17: 27 | D17: 48
B18: 26 | C18: 11 | D18: 30

Sheet Sensitivity
B2: Sum-of-the-parts per share — MNT-Halan mark x holding discount (live formulas)
C4: 0 | D4: 0.05 | E4: 0.1 | F4: 0.15 | G4: 0.2
B5: 0.5 | C5: =(DCF!$B$34+Assumptions!$B$63+Assumptions!$B$67*$B5+Assumptions!$B$60+Assumptions!$B$61)*(1-C$4)/Assumptions!$B$5 | D5: =(DCF!$B$34+Assumptions!$B$63+Assumptions!$B$67*$B5+Assumptions!$B$60+Assumptions!$B$61)*(1-D$4)/Assumptions!$B$5 | E5: =(DCF!$B$34+Assumptions!$B$63+Assumptions!$B$67*$B5+Assumptions!$B$60+Assumptions!$B$61)*(1-E$4)/Assumptions!$B$5 | F5: =(DCF!$B$34+Assumptions!$B$63+Assumptions!$B$67*$B5+Assumptions!$B$60+Assumptions!$B$61)*(1-F$4)/Assumptions!$B$5 | G5: =(DCF!$B$34+Assumptions!$B$63+Assumptions!$B$67*$B5+Assumptions!$B$60+Assumptions!$B$61)*(1-G$4)/Assumptions!$B$5
B6: 0.625 | C6: =(DCF!$B$34+Assumptions!$B$63+Assumptions!$B$67*$B6+Assumptions!$B$60+Assumptions!$B$61)*(1-C$4)/Assumptions!$B$5 | D6: =(DCF!$B$34+Assumptions!$B$63+Assumptions!$B$67*$B6+Assumptions!$B$60+Assumptions!$B$61)*(1-D$4)/Assumptions!$B$5 | E6: =(DCF!$B$34+Assumptions!$B$63+Assumptions!$B$67*$B6+Assumptions!$B$60+Assumptions!$B$61)*(1-E$4)/Assumptions!$B$5 | F6: =(DCF!$B$34+Assumptions!$B$63+Assumptions!$B$67*$B6+Assumptions!$B$60+Assumptions!$B$61)*(1-F$4)/Assumptions!$B$5 | G6: =(DCF!$B$34+Assumptions!$B$63+Assumptions!$B$67*$B6+Assumptions!$B$60+Assumptions!$B$61)*(1-G$4)/Assumptions!$B$5
B7: 0.75 | C7: =(DCF!$B$34+Assumptions!$B$63+Assumptions!$B$67*$B7+Assumptions!$B$60+Assumptions!$B$61)*(1-C$4)/Assumptions!$B$5 | D7: =(DCF!$B$34+Assumptions!$B$63+Assumptions!$B$67*$B7+Assumptions!$B$60+Assumptions!$B$61)*(1-D$4)/Assumptions!$B$5 | E7: =(DCF!$B$34+Assumptions!$B$63+Assumptions!$B$67*$B7+Assumptions!$B$60+Assumptions!$B$61)*(1-E$4)/Assumptions!$B$5 | F7: =(DCF!$B$34+Assumptions!$B$63+Assumptions!$B$67*$B7+Assumptions!$B$60+Assumptions!$B$61)*(1-F$4)/Assumptions!$B$5 | G7: =(DCF!$B$34+Assumptions!$B$63+Assumptions!$B$67*$B7+Assumptions!$B$60+Assumptions!$B$61)*(1-G$4)/Assumptions!$B$5
B8: 0.875 | C8: =(DCF!$B$34+Assumptions!$B$63+Assumptions!$B$67*$B8+Assumptions!$B$60+Assumptions!$B$61)*(1-C$4)/Assumptions!$B$5 | D8: =(DCF!$B$34+Assumptions!$B$63+Assumptions!$B$67*$B8+Assumptions!$B$60+Assumptions!$B$61)*(1-D$4)/Assumptions!$B$5 | E8: =(DCF!$B$34+Assumptions!$B$63+Assumptions!$B$67*$B8+Assumptions!$B$60+Assumptions!$B$61)*(1-E$4)/Assumptions!$B$5 | F8: =(DCF!$B$34+Assumptions!$B$63+Assumptions!$B$67*$B8+Assumptions!$B$60+Assumptions!$B$61)*(1-F$4)/Assumptions!$B$5 | G8: =(DCF!$B$34+Assumptions!$B$63+Assumptions!$B$67*$B8+Assumptions!$B$60+Assumptions!$B$61)*(1-G$4)/Assumptions!$B$5
B9: 1 | C9: =(DCF!$B$34+Assumptions!$B$63+Assumptions!$B$67*$B9+Assumptions!$B$60+Assumptions!$B$61)*(1-C$4)/Assumptions!$B$5 | D9: =(DCF!$B$34+Assumptions!$B$63+Assumptions!$B$67*$B9+Assumptions!$B$60+Assumptions!$B$61)*(1-D$4)/Assumptions!$B$5 | E9: =(DCF!$B$34+Assumptions!$B$63+Assumptions!$B$67*$B9+Assumptions!$B$60+Assumptions!$B$61)*(1-E$4)/Assumptions!$B$5 | F9: =(DCF!$B$34+Assumptions!$B$63+Assumptions!$B$67*$B9+Assumptions!$B$60+Assumptions!$B$61)*(1-F$4)/Assumptions!$B$5 | G9: =(DCF!$B$34+Assumptions!$B$63+Assumptions!$B$67*$B9+Assumptions!$B$60+Assumptions!$B$61)*(1-G$4)/Assumptions!$B$5
A11: The company's own balance-sheet mark equals 52% of the round — between the first and second rows. The July study's margin axis is retained as a line: ±1pt of automotive gross margin moves the automotive leg by about 6.49 per share.

Sheet Per-Share & Ratios
B2: Per-share values and ratios
E4: FY26E | F4: FY27E | G4: FY28E | H4: FY29E | I4: FY30E
A5: Earnings per share | E5: ='Income Statement'!E17 | F5: ='Income Statement'!F17 | G5: ='Income Statement'!G17 | H5: ='Income Statement'!H17 | I5: ='Income Statement'!I17
A6: Book value per share | E6: ='Balance Sheet'!E16 | F6: ='Balance Sheet'!F16 | G6: ='Balance Sheet'!G16 | H6: ='Balance Sheet'!H16 | I6: ='Balance Sheet'!I16
A7: Return on equity | E7: ='Income Statement'!E16/'Balance Sheet'!E11 | F7: ='Income Statement'!F16/'Balance Sheet'!F11 | G7: ='Income Statement'!G16/'Balance Sheet'!G11 | H7: ='Income Statement'!H16/'Balance Sheet'!H11 | I7: ='Income Statement'!I16/'Balance Sheet'!I11
A8: Net debt / automotive EBITDA | E8: ='Balance Sheet'!E10/DCF!E14 | F8: ='Balance Sheet'!F10/DCF!F14 | G8: ='Balance Sheet'!G10/DCF!G14 | H8: ='Balance Sheet'!H10/DCF!H14 | I8: ='Balance Sheet'!I10/DCF!I14
A9: Price / earnings at the last close | E9: =Assumptions!$B$6/'Income Statement'!E17 | F9: =Assumptions!$B$6/'Income Statement'!F17 | G9: =Assumptions!$B$6/'Income Statement'!G17 | H9: =Assumptions!$B$6/'Income Statement'!H17 | I9: =Assumptions!$B$6/'Income Statement'!I17
A10: Price / book at the last close | E10: =Assumptions!$B$6/'Balance Sheet'!E16 | F10: =Assumptions!$B$6/'Balance Sheet'!F16 | G10: =Assumptions!$B$6/'Balance Sheet'!G16 | H10: =Assumptions!$B$6/'Balance Sheet'!H16 | I10: =Assumptions!$B$6/'Balance Sheet'!I16
A11: Dividend yield at the last close (payout held) | E11: =0.35/Assumptions!$B$6 | F11: =0.35/Assumptions!$B$6 | G11: =0.35/Assumptions!$B$6 | H11: =0.35/Assumptions!$B$6 | I11: =0.35/Assumptions!$B$6

Sheet Peer & Sector
B2: Peer frame (context only — never a source for the subject's own numbers)
A4: Peer | B4: Trailing P/E | C4: Note
A5: Contact Financial (EGX) — consumer/NBFS | B5: 9.41 | C5: the direct Egyptian financing peer
A6: Dogus Otomotiv (Istanbul) — auto distribution | B6: 12.55 | C6: P/B 0.62 on inflation-restated book
A7: AutoNation (US) — auto retail | B7: 9.11 | C7: mature-market anchor; fwd 8.35
A8: Bajaj Auto (India) — two/three-wheelers | B8: 27.56 | C8: partner brand; rich-market multiple
A10: GB Corp at the last close on FY26E earnings | B10: =Assumptions!B6/'Income Statement'!E17
A11: GB Corp at the last close on restated book | B11: =Assumptions!B6/('Fundamental Valuation'!B7)
A13: All peer marks 19-Aug-2026, aggregator-sourced (market data only). One material aggregator discrepancy was logged: Contact Financial's market capitalisation is quoted between EGP 4.5bn and 6.6bn across services on different dates.
