Workbook

Sheet READ FIRST
A1: Testahil · Independent Valuation Study — Educational Analysis · Not investment advice
A3: Heliopolis Company for Housing & Development — Misr El Gadida (EGX: HELI) · companion model to the Word study of 03-07-2026.
A5: READ FIRST — what this workbook is, and is not. This model is a valuation exercise and an expression of personal analytical
A6: opinion, published free of charge for educational purposes. It is NOT investment advice, NOT a recommendation or solicitation
A7: to buy, sell or hold any security, and NOT directed at the circumstances of any reader. The preparer is not licensed by any
A8: securities regulator in any jurisdiction (including the Egyptian FRA), manages no money and accepts no fees, funds or clients.
A9: All values are model outputs presented as ranges and distributions because no single number should be relied on.
A11: How to use it: every blue cell on the Assumptions sheet is an input; every other sheet links back to it, so changing one
A12: input (a land mark, the RNAV discount, the WACC) reprices the whole model. Reported FY2023–FY2025 figures are the company’s
A13: own disclosure to the EGX (standardised presentation via S&P Capital IQ, retrieved 03 Jul 2026); FY2026E–FY2030E and every
A14: mark are the preparer’s judgments. Holdings disclosure: the preparer may hold, and may in the future take or dispose of, a
A15: position in the security discussed in this report.
... A19: Per-Share & Ratios · Peer & Sector.

Sheet Summary
A1: HELI — every read at a glance
A2: Heliopolis Company for Housing & Development (EGX: HELI) · spot EGP 6.43 · 01 Jul 2026 · 4,005mn shares · mkt cap ≈ EGP 25.8bn
A4: Lens / read | B4: Output | C4: Takeaway
A5: FUNDAMENTAL
A6: Sum-of-the-parts RNAV (primary) | B6: =RNAV!C19 -> 8.2974389 | C6: +29% vs spot
A7: Consolidated DCF | B7: =DCF!B21 -> 8.3023473 | C7: Cash-flow cross-check
A8: Relative multiples | B8: ='Relative & Normalized'!B8 -> 7.4531778 | C8: The floor
A9: Normalized earnings power | B9: ='Relative & Normalized'!B16 -> 9.2628194 | C9: The ceiling
A10: Weighted central | B10: ='Fundamental Valuation'!D9 -> 8.4131265 | C10: Blend 40/20/15/25
A11: TECHNICAL
A12: Trend & momentum | B12: Above SMA100/200; at SMA20/50 | C12: Uptrend pausing; RSI 49
A13: MONTE CARLO (3 months)
A14: T+20 (p5/p50/p95) | B14: 5.37 / 6.54 / 7.89 | C14: Median ≈ spot
A15: T+60 (p5/p50/p95) | B15: 4.84 / 6.74 / 9.27 | C15: 50% band 5.95–7.60
A16: EXPERT PANEL
A17: Expert 1 — RNAV & discount | B17: 8.6 | C17: The anchor
A18: Expert 2 — contracted-annuity DCF | B18: 7.9 | C18: The floor of the panel
A19: Expert 3 — macro-policy / privatization | B19: 7 | C19: Most state-sceptical

Sheet Fundamental Valuation
A1: Synthesis — four lenses, weights and the central value
A2: Bear/bull spans mirror the study §1.5; base cells link live to the lens sheets.
A4: Lens | B4: Weight | C4: Bear | D4: Base | E4: Bull
A5: Sum-of-the-parts RNAV | B5: =Assumptions!B34 -> 0.4 | C5: 4.6 | D5: =RNAV!C19 -> 8.2974389 | E5: 12.4
A6: Consolidated DCF | B6: =Assumptions!B35 -> 0.2 | C6: 4.9 | D6: =DCF!B21 -> 8.3023473 | E6: 12.1
A7: Relative multiples | B7: =Assumptions!B36 -> 0.15 | C7: 5.2 | D7: ='Relative & Normalized'!B8 -> 7.4531778 | E7: 9.6
A8: Normalized earnings power | B8: =Assumptions!B37 -> 0.25 | C8: 6.4 | D8: ='Relative & Normalized'!B16 -> 9.2628194 | E8: 12
A9: Weighted central | B9: =SUM(B5:B8) -> 1 | C9: =SUMPRODUCT($B$5:$B$8,C5:C8) -> 5.2 | D9: =SUMPRODUCT($B$5:$B$8,D5:D8) -> 8.4131265 | E9: =SUMPRODUCT($B$5:$B$8,E5:E8) -> 11.82
A11: Spot (EGP) | B11: =Assumptions!B5 -> 6.43
A12: Upside to weighted central | B12: =D9/B11-1 -> 0.30841781

Sheet Assumptions
A1: Assumptions — the single input layer
A2: All blue cells are inputs. Every other sheet links here. Sources per cell in column C.
A4: ANCHORS
A5: Spot price (EGP/share) | B5: 6.43 | C5: EGX close 01 Jul 2026
A6: Shares outstanding (mn) | B6: 4005.26 | C6: Capital EGP 1,001mn, par 0.25; EGX
A7: Net debt, Mar-2026 (EGP mn) | B7: 4952 | C7: S&P CIQ standardised BS, 31 Mar 2026
A8: WACC | B8: 0.205 | C8: Ke ~24-25% EGP, blended w/ debt
A9: Terminal growth (nominal EGP) | B9: 0.12 | C9: ≈ long-run EGP inflation + ~2%
A10: Tax rate | B10: 0.225 | C10: Egyptian corporate rate
A12: RNAV — BASE MARKS (EGP mn PV unless noted)
A13: Madinet Masr JDA, 491 fd (PV of min guarantee) | B13: 16500 | C13: JDA Aug-25: min EGP 53.18bn/9y; Asharq
A14: MG Urban Dev JDA, 77 fd (PV of min guarantee) | B14: 1100 | C14: Dec-23: min EGP 3.394bn/14y @32.1%
A15: Middle East Dev JDA land, feddans | B15: 1759 | C15: Jan-25 + 2nd plot; Asharq/ArabFinance
A16: G Developments JDA land, feddans | B16: 1800 | C16: 2024 “New Cairo” project
A17: SODIC East residual land, feddans | B17: 655 | C17: 2018/19 co-development
A18: PV per feddan — undisclosed-term JDAs (EGP mn) | B18: 9 | C18: judgment; see study §1.1
A19: PV per feddan — SODIC East residual (EGP mn) | B19: 6 | C19: older vintage, sold-through tail
A20: Unallocated NH + auction plots, feddans | B20: 350 | C20: 8 plots + Green Kasaba + 75-fd site
A21: Cash value per feddan — unallocated (EGP mn) | B21: 8 | C21: vs Heliopark 8.85m/fd (2023 New Cairo)
A22: New Obour plot, feddans | B22: 60 | C22: received Jul-2025
A23: Heliopolis district heritage & rental portfolio (EGP mn) | B23: 6000 | C23: judgment mark; Korba/Merryland/Sheraton
A24: PV of unallocated overhead (EGP mn) | B24: 2500 | C24: ~5x SG&A run-rate
A25: RNAV discount (state control, timing, opacity) | B25: 0.4 | C25: EGX developer 40-60% range
A27: RELATIVE & NORMALIZED
A28: FY26E EPS (link check vs IS) | B28: 0.87
A29: Justified P/E | B29: 8.5
A30: Mid-cycle recurring net income (EGP mn) | B30: 5300 | C30: partnership run-rate; §1.4
A31: Justified mid-cycle P/E | B31: 7
A33: SYNTHESIS WEIGHTS
A34: RNAV weight | B34: 0.4
A35: DCF weight | B35: 0.2
A36: Relative weight | B36: 0.15
A37: Normalized-earnings weight | B37: 0.25
A39: MONTE CARLO (from the YZ-HAR engine, Step 0 App B)
A40: YZ-HAR projected annualized vol | B40: 0.382 | C40: pooled log-HAR (1/5/22) on YZ proxy
A41: Simulated path vol (with events) | B41: 0.434 | C41: 50k paths, seed 42
A42: Net continuous-factor 3M drift | B42: 0.04 | C42: 7 C-factors; §3
A43: Secular drift (Step 0: OFF for HELI) | B43: 0 | C43: drift-on failed CRPS; App B
A45: FORECAST DRIVERS (FY26E–FY30E)
B46: FY26E | C46: FY27E | D46: FY28E | E46: FY29E | F46: FY30E
...

Sheet RNAV
A1: Sum-of-the-parts RNAV — the primary lens
A2: Marks are the preparer’s judgments (flagged); contracted minimum guarantees anchor the two disclosed JDAs.
A4: Component | B4: Basis | C4: Value (EGP mn)
A5: Madinet Masr JDA (491 fd) | B5: PV of EGP 53.18bn / 9y minimum guarantee | C5: =Assumptions!B13 -> 16500
A6: MG Urban Development JDA (77 fd) | B6: PV of EGP 3.394bn / 14y minimum (32.1% share) | C6: =Assumptions!B14 -> 1100
A7: Middle East Development JDA (1,759 fd) | B7: PV/feddan × feddans (terms undisclosed) | C7: =Assumptions!B15*Assumptions!B18 -> 15831
A8: G Developments JDA (1,800 fd) | B8: PV/feddan × feddans (terms undisclosed) | C8: =Assumptions!B16*Assumptions!B18 -> 16200
A9: SODIC East residual (655 fd) | B9: PV/feddan × feddans (sold-through tail) | C9: =Assumptions!B17*Assumptions!B19 -> 3930
A10: Unallocated New Heliopolis + auction plots (350 fd) | B10: Cash mark per feddan | C10: =Assumptions!B20*Assumptions!B21 -> 2800
A11: New Obour plot (60 fd) | B11: Cash mark per feddan | C11: =Assumptions!B22*Assumptions!B21 -> 480
A12: Heritage & rental portfolio (Korba, Merryland, Sheraton) | B12: Judgment mark | C12: =Assumptions!B23 -> 6000
A13: Gross asset value | B13: Σ components | C13: =SUM(C5:C12) -> 62841
A14: Less: PV of unallocated overhead | B14: ~5× SG&A run-rate | C14: =-Assumptions!B24 -> -2500
A15: Less: net debt (Mar-26) | C15: =-Assumptions!B7 -> -4952
A16: NAV, pre-discount | C16: =C13+C14+C15 -> 55389
A17: NAV per share, pre-discount (EGP) | C17: =C16/Assumptions!B6 -> 13.829065
A18: RNAV discount | B18: state control · timing · disclosure opacity | C18: =Assumptions!B25 -> 0.4
A19: RNAV fair value per share (EGP) | C19: =C17*(1-C18) -> 8.2974389
A20: Implied discount at spot | B20: 1 − spot / pre-discount NAV | C20: =1-Assumptions!B5/C17 -> 0.53503725

Sheet Segments
A1: Segments — the land bank by disposition
A2: New Heliopolis City = 5,885 feddans (Decree 193/1995); Heliopark (1,695 fd, New Cairo) sold 2023.
A4: Block | B4: Feddans | C4: Status / partner | D4: Disclosed economics
A5: Madinet Masr JDA | B5: 491 | C5: Signed Aug-2025; two plots | D5: 36.5% semi-finished / 20% finished; min EGP 53.18bn/9y; EGP 1.1bn at signing
A6: G Developments JDA | B6: 1800 | C6: Signed 2024; “New Cairo” project | D6: Terms undisclosed; won vs Hassan Allam & Majid Al Futtaim
A7: Middle East Development JDA | B7: 1759 | C7: Jan-2025 + second plot | D7: EGP 594mn revenue to HELI in 2025; sales under way
A8: SODIC East | B8: 655 | C8: 2018/19 co-development | D8: Revenue-share; sold-through tail
A9: MG Urban Development JDA | B9: 77 | C9: Signed Dec-2023 | D9: 32.1% revenue share; min EGP 3.394bn/14y
A10: Hospitality / retail project | B10: 75 | C10: Designs complete Jun-2026 | D10: EGP 5bn planned capex
A11: Auction & Green Kasaba plots | B11: 275 | C11: 8 plots offered; Smash club offer | D11: Cash monetisation
A12: New Obour plot | B12: 60 | C12: Received Jul-2025 | D12: Undeveloped
A13: Heliopolis district portfolio | B13: — | C13: Korba heritage, Merryland, Sheraton units | D13: Rental + hotel-conversion offers
A14: Committed to partnerships (fd) | B14: =SUM(B5:B9) -> 4782

Sheet Relative & Normalized
A1: Relative multiples and normalized earnings power
A4: Relative lens | B4: Value
A5: FY26E net income (EGP mn) | B5: ='Income Statement'!E17 -> 3511.99
A6: FY26E EPS (EGP) | B6: =B5/Assumptions!B6 -> 0.87684445
A7: Justified P/E | B7: =Assumptions!B29 -> 8.5
A8: Relative fair value (EGP/share) | B8: =B6*B7 -> 7.4531778
A9: P/E at spot (FY26E) | B9: =Assumptions!B5/B6 -> 7.3331136
A10: P/B at spot (FY25 BVPS 2.58) | B10: =Assumptions!B5/2.58 -> 2.4922481
A12: Normalized-earnings lens | B12: Value
A13: Mid-cycle recurring net income (EGP mn) | B13: =Assumptions!B30 -> 5300
A14: Normalized EPS (EGP) | B14: =B13/Assumptions!B6 -> 1.3232599
A15: Justified mid-cycle P/E | B15: =Assumptions!B31 -> 7
A16: Normalized fair value (EGP/share) | B16: =B14*B15 -> 9.2628194

Sheet DCF
A1: Consolidated DCF — FCFF, 5-yr forecast + terminal
A2: Every input links to Assumptions. WACC and terminal growth are the swing inputs.
A4: EGP mn | B4: FY26E | C4: FY27E | D4: FY28E | E4: FY29E | F4: FY30E
A5: EBIT | B5: ='Income Statement'!E10 -> 2331.6 | C5: ='Income Statement'!F10 -> 3526 | D5: ='Income Statement'!G10 -> 4780 | E5: ='Income Statement'!H10 -> 5750 | F5: ='Income Statement'!I10 -> 6465
A6: Land-sale & other gains | B6: =Assumptions!B51 -> 2600 | C6: =Assumptions!C51 -> 1200 | D6: =Assumptions!D51 -> 900 | E6: =Assumptions!E51 -> 700 | F6: =Assumptions!F51 -> 500
A7: Tax on EBIT + gains | B7: =-(B5+B6)*Assumptions!$B$10 -> -1109.61 | C7: =-(C5+C6)*Assumptions!$B$10 -> -1063.35 | D7: =-(D5+D6)*Assumptions!$B$10 -> -1278 | E7: =-(E5+E6)*Assumptions!$B$10 -> -1451.25 | F7: =-(F5+F6)*Assumptions!$B$10 -> -1567.125
A8: NOPAT | B8: =B5+B6+B7 -> 3821.99 | C8: =C5+C6+C7 -> 3662.65 | D8: =D5+D6+D7 -> 4402 | E8: =E5+E6+E7 -> 4998.75 | F8: =F5+F6+F7 -> 5397.875
A9: + D&A | B9: =Assumptions!B54 -> 35 | C9: =Assumptions!C54 -> 40 | D9: =Assumptions!D54 -> 45 | E9: =Assumptions!E54 -> 50 | F9: =Assumptions!F54 -> 55
A10: − Capex | B10: =-Assumptions!B55 -> -1000 | C10: =-Assumptions!C55 -> -1500 | D10: =-Assumptions!D55 -> -1500 | E10: =-Assumptions!E55 -> -500 | F10: =-Assumptions!F55 -> -200
A11: − Δ Working capital | B11: =-(Assumptions!B56+Assumptions!B57-Assumptions!B58) -> -940 | C11: =-(Assumptions!C56+Assumptions!C57-Assumptions!C58) -> -640 | D11: =-(Assumptions!D56+Assumptions!D57-Assumptions!D58) -> 360 | E11: =-(Assumptions!E56+Assumptions!E57-Assumptions!E58) -> 360 | F11: =-(Assumptions!F56+Assumptions!F57-Assumptions!F58) -> 360
A12: FCFF | B12: =SUM(B8:B11) -> 1916.99 | C12: =SUM(C8:C11) -> 1562.65 | D12: =SUM(D8:D11) -> 3307 | E12: =SUM(E8:E11) -> 4908.75 | F12: =SUM(F8:F11) -> 5612.875
A13: Discount factor | B13: =1/(1+Assumptions!$B$8)^1 -> 0.82987552 | C13: =1/(1+Assumptions!$B$8)^2 -> 0.68869338 | D13: =1/(1+Assumptions!$B$8)^3 -> 0.57152977 | E13: =1/(1+Assumptions!$B$8)^4 -> 0.47429857 | F13: =1/(1+Assumptions!$B$8)^5 -> 0.39360877
A14: PV of FCFF | B14: =B12*B13 -> 1590.8631 | C14: =C12*C13 -> 1076.1867 | D14: =D12*D13 -> 1890.049 | E14: =E12*E13 -> 2328.2131 | F14: =F12*F13 -> 2209.2768
A16: Terminal value (FY30) | F16: =F12*(1+Assumptions!$B$9)/(Assumptions!$B$8-Assumptions!$B$9) -> 73957.882
A17: PV of terminal value | B17: =F16*F13 -> 29110.471
A18: Enterprise value | B18: =SUM(B14:F14)+B17 -> 38205.06
A19: Less: net debt | B19: =-Assumptions!$B$7 -> -4952
A20: Equity value | B20: =B18+B19 -> 33253.06
A21: DCF fair value / share (EGP) | B21: =B20/Assumptions!$B$6 -> 8.3023473

Sheet Income Statement
A1: Income statement (EGP mn) — 3yr historical + 5yr forecast
A2: FY2023–FY2025 as reported (S&P CIQ standardised); FY2026E–FY2030E model. Calendar fiscal year.
A4: EGP mn | B4: FY23 | C4: FY24 | D4: FY25 | E4: FY26E | F4: FY27E | G4: FY28E | H4: FY29E | I4: FY30E
A5: Operating revenue | B5: 15580 | C5: 1055 | D5: 3135 | E5: =Assumptions!B47 -> 3070 | F5: =Assumptions!C47 -> 4600 | G5: =Assumptions!D47 -> 6200 | H5: =Assumptions!E47 -> 7400 | I5: =Assumptions!F47 -> 8300
A6: Cost of revenue | B6: -3365 | C6: -294 | D6: -268 | E6: =-Assumptions!B47*Assumptions!B48 -> -368.4 | F6: =-Assumptions!C47*Assumptions!C48 -> -644 | G6: =-Assumptions!D47*Assumptions!D48 -> -930 | H6: =-Assumptions!E47*Assumptions!E48 -> -1110 | I6: =-Assumptions!F47*Assumptions!F48 -> -1245
A7: Gross profit | B7: =B5+B6 -> 12215 | C7: =C5+C6 -> 761 | D7: =D5+D6 -> 2867 | E7: =E5+E6 -> 2701.6 | F7: =F5+F6 -> 3956 | G7: =G5+G6 -> 5270 | H7: =H5+H6 -> 6290 | I7: =I5+I6 -> 7055
A8: SG&A | B8: -262 | C8: -193 | D8: -278 | E8: =-Assumptions!B49 -> -330 | F8: =-Assumptions!C49 -> -390 | G8: =-Assumptions!D49 -> -450 | H8: =-Assumptions!E49 -> -500 | I8: =-Assumptions!F49 -> -550
A9: Other operating, net | B9: -1356 | C9: 410 | D9: 152 | E9: =Assumptions!B50 -> -40 | F9: =Assumptions!C50 -> -40 | G9: =Assumptions!D50 -> -40 | H9: =Assumptions!E50 -> -40 | I9: =Assumptions!F50 -> -40
A10: EBIT (operating income) | B10: =B7+B8+B9 -> 10597 | C10: =C7+C8+C9 -> 978 | D10: =D7+D8+D9 -> 2741 | E10: =E7+E8+E9 -> 2331.6 | F10: =F7+F8+F9 -> 3526 | G10: =G7+G8+G9 -> 4780 | H10: =H7+H8+H9 -> 5750 | I10: =I7+I8+I9 -> 6465
A11: Land-sale & other gains | B11: 0 | C11: 0 | D11: 0 | E11: =Assumptions!B51 -> 2600 | F11: =Assumptions!C51 -> 1200 | G11: =Assumptions!D51 -> 900 | H11: =Assumptions!E51 -> 700 | I11: =Assumptions!F51 -> 500
A12: Interest income | B12: 262 | C12: 2436 | D12: 738 | E12: =Assumptions!B52 -> 500 | F12: =Assumptions!C52 -> 420 | G12: =Assumptions!D52 -> 450 | H12: =Assumptions!E52 -> 520 | I12: =Assumptions!F52 -> 600
A13: Interest expense | B13: -338 | C13: -246 | D13: -114 | E13: =Assumptions!B53 -> -900 | F13: =Assumptions!C53 -> -800 | G13: =Assumptions!D53 -> -650 | H13: =Assumptions!E53 -> -500 | I13: =Assumptions!F53 -> -380
A14: Other non-operating | B14: -36 | C14: 0 | D14: 8 | E14: 0 | F14: 0 | G14: 0 | H14: 0 | I14: 0
A15: Pre-tax income | B15: =SUM(B10:B14) -> 10485 | C15: =SUM(C10:C14) -> 3168 | D15: =SUM(D10:D14) -> 3373 | E15: =SUM(E10:E14) -> 4531.6 | F15: =SUM(F10:F14) -> 4346 | G15: =SUM(G10:G14) -> 5480 | H15: =SUM(H10:H14) -> 6470 | I15: =SUM(I10:I14) -> 7185
A16: Income tax | B16: -2676 | C16: -608 | D16: -668 | E16: =-E15*Assumptions!$B$10 -> -1019.61 | F16: =-F15*Assumptions!$B$10 -> -977.85 | G16: =-G15*Assumptions!$B$10 -> -1233 | H16: =-H15*Assumptions!$B$10 -> -1455.75 | I16: =-I15*Assumptions!$B$10 -> -1616.625
A17: Net income | B17: =B15+B16 -> 7809 | C17: =C15+C16 -> 2560 | D17: =D15+D16 -> 2705 | E17: =E15+E16 -> 3511.99 | F17: =F15+F16 -> 3368.15 | G17: =G15+G16 -> 4247 | H17: =H15+H16 -> 5014.25 | I17: =I15+I16 -> 5568.375
A18: EPS (EGP) | B18: =B17/Assumptions!$B$6 -> 1.9496862 | C18: =C17/Assumptions!$B$6 -> 0.63915951 | D18: =D17/Assumptions!$B$6 -> 0.6753619 | E18: =E17/Assumptions!$B$6 -> 0.87684445 | F18: =F17/Assumptions!$B$6 -> 0.84093167 | G18: =G17/Assumptions!$B$6 -> 1.0603556 | H18: =H17/Assumptions!$B$6 -> 1.2519162 | I18: =I17/Assumptions!$B$6 -> 1.3902656
A19: EBITDA (EBIT + D&A) | B19: =B10+6 -> 10603 | C19: =C10+7 -> 985 | D19: =D10+20 -> 2761 | E19: =E10+Assumptions!B54 -> 2366.6 | F19: =F10+Assumptions!C54 -> 3566 | G19: =G10+Assumptions!D54 -> 4825 | H19: =H10+Assumptions!E54 -> 5800 | I19: =I10+Assumptions!F54 -> 6520
A21: Note: FY23 includes the EGP 15bn Heliopark land sale to the National Social Insurance Authority. FY26E–FY30E gains line = plot auctions & asset sales.

Sheet Balance Sheet
A1: Balance sheet (EGP mn) — 3yr historical + 5yr forecast
A2: FY2023–FY2025 as reported (S&P CIQ standardised); forecast cash is the model plug.
A4: EGP mn | B4: FY23 | C4: FY24 | D4: FY25 | E4: FY26E | F4: FY27E | G4: FY28E | H4: FY29E | I4: FY30E
A5: Cash & ST investments | B5: 10658 | C5: 4858 | D5: 1761 | E5: ='Cash Flow'!E17 -> 747.99 | F5: ='Cash Flow'!F17 -> 416.14 | G5: ='Cash Flow'!G17 -> 1368.14 | H5: ='Cash Flow'!H17 -> 3692.39 | I5: ='Cash Flow'!I17 -> 6475.765
A6: Receivables | B6: 889 | C6: 578 | D6: 762 | E6: =D6+Assumptions!B57 -> 1002 | F6: =E6+Assumptions!C57 -> 1242 | G6: =F6+Assumptions!D57 -> 1482 | H6: =G6+Assumptions!E57 -> 1722 | I6: =H6+Assumptions!F57 -> 1962
A7: Inventory (land & WIP) | B7: 2438 | C7: 4588 | D7: 16862 | E7: =D7+Assumptions!B56 -> 17662 | F7: =E7+Assumptions!C56 -> 18162 | G7: =F7+Assumptions!D56 -> 17662 | H7: =G7+Assumptions!E56 -> 17162 | I7: =H7+Assumptions!F56 -> 16662
A8: Other current assets | B8: 1737 | C8: 3617 | D8: 658 | E8: 658 | F8: 658 | G8: 658 | H8: 658 | I8: 658
A9: Total current assets | B9: =SUM(B5:B8) -> 15722 | C9: =SUM(C5:C8) -> 13641 | D9: =SUM(D5:D8) -> 20043 | E9: =SUM(E5:E8) -> 20069.99 | F9: =SUM(F5:F8) -> 20478.14 | G9: =SUM(G5:G8) -> 21170.14 | H9: =SUM(H5:H8) -> 23234.39 | I9: =SUM(I5:I8) -> 25757.765
A10: PP&E, net | B10: 53 | C10: 21 | D10: 1681 | E10: =D10+Assumptions!B55-Assumptions!B54 -> 2646 | F10: =E10+Assumptions!C55-Assumptions!C54 -> 4106 | G10: =F10+Assumptions!D55-Assumptions!D54 -> 5561 | H10: =G10+Assumptions!E55-Assumptions!E54 -> 6011 | I10: =H10+Assumptions!F55-Assumptions!F54 -> 6156
A11: Other long-term assets | B11: 40 | C11: 718 | D11: 632 | E11: 632 | F11: 632 | G11: 632 | H11: 632 | I11: 632
A12: Total assets | B12: =B9+B10+B11 -> 15815 | C12: =C9+C10+C11 -> 14380 | D12: =D9+D10+D11 -> 22356 | E12: =E9+E10+E11 -> 23347.99 | F12: =F9+F10+F11 -> 25216.14 | G12: =G9+G10+G11 -> 27363.14 | H12: =H9+H10+H11 -> 29877.39 | I12: =I9+I10+I11 -> 32545.765
A13: Payables & accrued | B13: 741 | C13: 371 | D13: 1857 | E13: =D13+Assumptions!B58 -> 1957 | F13: =E13+Assumptions!C58 -> 2057 | G13: =F13+Assumptions!D58 -> 2157 | H13: =G13+Assumptions!E58 -> 2257 | I13: =H13+Assumptions!F58 -> 2357
A14: Total debt | B14: 1601 | C14: 615 | D14: 6478 | E14: =D14-Assumptions!B60 -> 5600 | F14: =E14-Assumptions!C60 -> 5300 | G14: =F14-Assumptions!D60 -> 4800 | H14: =G14-Assumptions!E60 -> 4300 | I14: =H14-Assumptions!F60 -> 3800
A15: Taxes payable & other current | B15: 3878 | C15: 1482 | D15: 1407 | E15: 1407 | F15: 1407 | G15: 1407 | H15: 1407 | I15: 1407
A16: Other long-term liabilities | B16: 832 | C16: 2508 | D16: 2296 | E16: 2296 | F16: 2296 | G16: 2296 | H16: 2296 | I16: 2296
A17: Total liabilities | B17: =SUM(B13:B16) -> 7052 | C17: =SUM(C13:C16) -> 4976 | D17: =SUM(D13:D16) -> 12038 | E17: =SUM(E13:E16) -> 11260 | F17: =SUM(F13:F16) -> 11060 | G17: =SUM(G13:G16) -> 10660 | H17: =SUM(H13:H16) -> 10260 | I17: =SUM(I13:I16) -> 9860
A18: Paid-in capital & other | B18: 383 | C18: 383 | D18: 1050 | E18: 1050 | F18: 1050 | G18: 1050 | H18: 1050 | I18: 1050
A19: Retained earnings | B19: 8379 | C19: 9020 | D19: 9267 | E19: =D19+'Income Statement'!E17-Assumptions!B59 -> 11036.99 | F19: =E19+'Income Statement'!F17-Assumptions!C59 -> 13105.14 | G19: =F19+'Income Statement'!G17-Assumptions!D59 -> 15652.14 | H19: =G19+'Income Statement'!H17-Assumptions!E59 -> 18566.39 | I19: =H19+'Income Statement'!I17-Assumptions!F59 -> 21634.765
A20: Shareholders' equity | B20: =B18+B19 -> 8762 | C20: =C18+C19 -> 9403 | D20: =D18+D19 -> 10317 | E20: =E18+E19 -> 12086.99 | F20: =F18+F19 -> 14155.14 | G20: =G18+G19 -> 16702.14 | H20: =H18+H19 -> 19616.39 | I20: =I18+I19 -> 22684.765
A21: Total liabilities & equity | B21: =B17+B20 -> 15814 | C21: =C17+C20 -> 14379 | D21: =D17+D20 -> 22355 | E21: =E17+E20 -> 23346.99 | F21: =F17+F20 -> 25215.14 | G21: =G17+G20 -> 27362.14 | H21: =H17+H20 -> 29876.39 | I21: =I17+I20 -> 32544.765
A22: Balance check (must be 0) | B22: =B12-B21 -> 1 | C22: =C12-C21 -> 1 | D22: =D12-D21 -> 1 | E22: =E12-E21 -> 1 | F22: =F12-F21 -> 1 | G22: =G12-G21 -> 1 | H22: =H12-H21 -> 1 | I22: =I12-I21 -> 1
A23: Net cash / (debt) | B23: =B5-B14 -> 9057 | C23: =C5-C14 -> 4243 | D23: =D5-D14 -> -4717 | E23: =E5-E14 -> -4852.01 | F23: =F5-F14 -> -4883.86 | G23: =G5-G14 -> -3431.86 | H23: =H5-H14 -> -607.61 | I23: =I5-I14 -> 2675.765
A24: Book value per share (EGP) | B24: =B20/Assumptions!$B$6 -> 2.1876233 | C24: =C20/Assumptions!$B$6 -> 2.3476628 | D24: =D20/Assumptions!$B$6 -> 2.5758627 | E24: =E20/Assumptions!$B$6 -> 3.0177791 | F24: =F20/Assumptions!$B$6 -> 3.5341376 | G24: =G20/Assumptions!$B$6 -> 4.1700514 | H24: =H20/Assumptions!$B$6 -> 4.8976571 | I24: =I20/Assumptions!$B$6 -> 5.6637434

Sheet Cash Flow
A1: Cash flow (EGP mn) — 3yr historical + 5yr forecast
A2: Historical per S&P CIQ standardised; forecast built from the drivers on Assumptions.
A4: EGP mn | B4: FY23 | C4: FY24 | D4: FY25 | E4: FY26E | F4: FY27E | G4: FY28E | H4: FY29E | I4: FY30E
A5: Net income | B5: 7809 | C5: 2560 | D5: 2705 | E5: ='Income Statement'!E17 -> 3511.99 | F5: ='Income Statement'!F17 -> 3368.15 | G5: ='Income Statement'!G17 -> 4247 | H5: ='Income Statement'!H17 -> 5014.25 | I5: ='Income Statement'!I17 -> 5568.375
A6: D&A | B6: 6 | C6: 7 | D6: 20 | E6: =Assumptions!B54 -> 35 | F6: =Assumptions!C54 -> 40 | G6: =Assumptions!D54 -> 45 | H6: =Assumptions!E54 -> 50 | I6: =Assumptions!F54 -> 55
A7: Δ Inventory | B7: -5 | C7: -2150 | D7: -12274 | E7: =-Assumptions!B56 -> -800 | F7: =-Assumptions!C56 -> -500 | G7: =-Assumptions!D56 -> 500 | H7: =-Assumptions!E56 -> 500 | I7: =-Assumptions!F56 -> 500
A8: Δ Receivables | B8: 697 | C8: 312 | D8: -184 | E8: =-Assumptions!B57 -> -240 | F8: =-Assumptions!C57 -> -240 | G8: =-Assumptions!D57 -> -240 | H8: =-Assumptions!E57 -> -240 | I8: =-Assumptions!F57 -> -240
A9: Δ Payables & other | B9: 2023 | C9: -6136 | D9: 8420 | E9: =Assumptions!B58 -> 100 | F9: =Assumptions!C58 -> 100 | G9: =Assumptions!D58 -> 100 | H9: =Assumptions!E58 -> 100 | I9: =Assumptions!F58 -> 100
A10: Operating cash flow | B10: =SUM(B5:B9) -> 10530 | C10: =SUM(C5:C9) -> -5407 | D10: =SUM(D5:D9) -> -1313 | E10: =SUM(E5:E9) -> 2606.99 | F10: =SUM(F5:F9) -> 2768.15 | G10: =SUM(G5:G9) -> 4652 | H10: =SUM(H5:H9) -> 5424.25 | I10: =SUM(I5:I9) -> 5983.375
A11: Capex | B11: -30 | C11: -4 | D11: -1680 | E11: =-Assumptions!B55 -> -1000 | F11: =-Assumptions!C55 -> -1500 | G11: =-Assumptions!D55 -> -1500 | H11: =-Assumptions!E55 -> -500 | I11: =-Assumptions!F55 -> -200
A12: Free cash flow | B12: =B10+B11 -> 10500 | C12: =C10+C11 -> -5411 | D12: =D10+D11 -> -2993 | E12: =E10+E11 -> 1606.99 | F12: =F10+F11 -> 1268.15 | G12: =G10+G11 -> 3152 | H12: =H10+H11 -> 4924.25 | I12: =I10+I11 -> 5783.375
A13: Dividends paid | B13: -45 | C13: -1787 | D13: -1742 | E13: =-Assumptions!B59 -> -1742 | F13: =-Assumptions!C59 -> -1300 | G13: =-Assumptions!D59 -> -1700 | H13: =-Assumptions!E59 -> -2100 | I13: =-Assumptions!F59 -> -2500
A14: Debt drawn / (repaid), net | B14: -1000 | C14: -986 | D14: 5863 | E14: =-Assumptions!B60 -> -878 | F14: =-Assumptions!C60 -> -300 | G14: =-Assumptions!D60 -> -500 | H14: =-Assumptions!E60 -> -500 | I14: =-Assumptions!F60 -> -500
A15: Other investing / financing | B15: -9407 | C15: 9317 | D15: -9538 | E15: 0 | F15: 0 | G15: 0 | H15: 0 | I15: 0
A16: Net change in cash | B16: =B12+B13+B14+B15 -> 48 | C16: =C12+C13+C14+C15 -> 1133 | D16: =D12+D13+D14+D15 -> -8410 | E16: =E12+E13+E14+E15 -> -1013.01 | F16: =F12+F13+F14+F15 -> -331.85 | G16: =G12+G13+G14+G15 -> 952 | H16: =H12+H13+H14+H15 -> 2324.25 | I16: =I12+I13+I14+I15 -> 2783.375
A17: Cash, end of period | B17: 10658 | C17: 4858 | D17: 1761 | E17: =D17+E16 -> 747.99 | F17: =E17+F16 -> 416.14 | G17: =F17+G16 -> 1368.14 | H17: =G17+H16 -> 3692.39 | I17: =H17+I16 -> 6475.765
A19: FY23 “other investing” = CD placements of Heliopark proceeds; FY24 = maturities; FY25 = land purchase settled through investing per CIQ mapping.

Sheet Summary Financials
A1: Summary financials — every cell links to the statement sheets
A4: EGP mn | B4: FY23 | C4: FY24 | D4: FY25 | E4: FY26E | F4: FY27E | G4: FY28E | H4: FY29E | I4: FY30E
A5: Revenue | B5: ='Income Statement'!B5 -> 15580 | C5: ='Income Statement'!C5 -> 1055 | D5: ='Income Statement'!D5 -> 3135 | E5: ='Income Statement'!E5 -> 3070 | F5: ='Income Statement'!F5 -> 4600 | G5: ='Income Statement'!G5 -> 6200 | H5: ='Income Statement'!H5 -> 7400 | I5: ='Income Statement'!I5 -> 8300
A6: EBIT | B6: ='Income Statement'!B10 -> 10597 | C6: ='Income Statement'!C10 -> 978 | D6: ='Income Statement'!D10 -> 2741 | E6: ='Income Statement'!E10 -> 2331.6 | F6: ='Income Statement'!F10 -> 3526 | G6: ='Income Statement'!G10 -> 4780 | H6: ='Income Statement'!H10 -> 5750 | I6: ='Income Statement'!I10 -> 6465
A7: Net income | B7: ='Income Statement'!B17 -> 7809 | C7: ='Income Statement'!C17 -> 2560 | D7: ='Income Statement'!D17 -> 2705 | E7: ='Income Statement'!E17 -> 3511.99 | F7: ='Income Statement'!F17 -> 3368.15 | G7: ='Income Statement'!G17 -> 4247 | H7: ='Income Statement'!H17 -> 5014.25 | I7: ='Income Statement'!I17 -> 5568.375
A8: EPS (EGP) | B8: ='Income Statement'!B18 -> 1.9496862 | C8: ='Income Statement'!C18 -> 0.63915951 | D8: ='Income Statement'!D18 -> 0.6753619 | E8: ='Income Statement'!E18 -> 0.87684445 | F8: ='Income Statement'!F18 -> 0.84093167 | G8: ='Income Statement'!G18 -> 1.0603556 | H8: ='Income Statement'!H18 -> 1.2519162 | I8: ='Income Statement'!I18 -> 1.3902656
A9: Total assets | B9: ='Balance Sheet'!B12 -> 15815 | C9: ='Balance Sheet'!C12 -> 14380 | D9: ='Balance Sheet'!D12 -> 22356 | E9: ='Balance Sheet'!E12 -> 23347.99 | F9: ='Balance Sheet'!F12 -> 25216.14 | G9: ='Balance Sheet'!G12 -> 27363.14 | H9: ='Balance Sheet'!H12 -> 29877.39 | I9: ='Balance Sheet'!I12 -> 32545.765
A10: Shareholders' equity | B10: ='Balance Sheet'!B20 -> 8762 | C10: ='Balance Sheet'!C20 -> 9403 | D10: ='Balance Sheet'!D20 -> 10317 | E10: ='Balance Sheet'!E20 -> 12086.99 | F10: ='Balance Sheet'!F20 -> 14155.14 | G10: ='Balance Sheet'!G20 -> 16702.14 | H10: ='Balance Sheet'!H20 -> 19616.39 | I10: ='Balance Sheet'!I20 -> 22684.765
A11: Net cash / (debt) | B11: ='Balance Sheet'!B23 -> 9057 | C11: ='Balance Sheet'!C23 -> 4243 | D11: ='Balance Sheet'!D23 -> -4717 | E11: ='Balance Sheet'!E23 -> -4852.01 | F11: ='Balance Sheet'!F23 -> -4883.86 | G11: ='Balance Sheet'!G23 -> -3431.86 | H11: ='Balance Sheet'!H23 -> -607.61 | I11: ='Balance Sheet'!I23 -> 2675.765
A12: Operating cash flow | B12: ='Cash Flow'!B10 -> 10530 | C12: ='Cash Flow'!C10 -> -5407 | D12: ='Cash Flow'!D10 -> -1313 | E12: ='Cash Flow'!E10 -> 2606.99 | F12: ='Cash Flow'!F10 -> 2768.15 | G12: ='Cash Flow'!G10 -> 4652 | H12: ='Cash Flow'!H10 -> 5424.25 | I12: ='Cash Flow'!I10 -> 5983.375
A13: Free cash flow | B13: ='Cash Flow'!B12 -> 10500 | C13: ='Cash Flow'!C12 -> -5411 | D13: ='Cash Flow'!D12 -> -2993 | E13: ='Cash Flow'!E12 -> 1606.99 | F13: ='Cash Flow'!F12 -> 1268.15 | G13: ='Cash Flow'!G12 -> 3152 | H13: ='Cash Flow'!H12 -> 4924.25 | I13: ='Cash Flow'!I12 -> 5783.375

Sheet Monte Carlo
A1: Monte Carlo — YZ-HAR width, t5 innovations, 16 factors, 50,000 paths (seed 42)
A2: Paths diffuse from spot; the §1 value gap is deliberately kept out of the drift. Percentiles hard-coded from the run.
A4: Horizon | B4: p5 | C4: p25 | D4: p50 | E4: p75 | F4: p95
A5: T+20 sessions | B5: 5.37 | C5: 6.09 | D5: 6.54 | E5: 7.01 | F5: 7.89
A6: T+60 sessions | B6: 4.84 | C6: 5.95 | D6: 6.74 | E6: 7.6 | F6: 9.27
A8: Engine line | B8: Value
A9: Spot / anchor (EGP) | B9: =Assumptions!B5 -> 6.43
A10: YZ-HAR annualized vol | B10: =Assumptions!B40 -> 0.382
A11: Simulated path vol (with events) | B11: =Assumptions!B41 -> 0.434
A12: Net continuous 3M drift | B12: =Assumptions!B42 -> 0.04
A13: Secular drift (Step 0 verdict) | B13: =Assumptions!B43 -> 0
A15: Touch level (EGP) | B15: by T+20 | C15: by T+60
A16: 8 | B16: 0.06 | C16: 0.28
A17: 7.5 | B17: 0.16 | C17: 0.44
A18: 7 | B18: 0.39 | C18: 0.67
A19: 6.75 | B19: 0.59 | C19: 0.79
A20: 6.1 | B20: 0.46 | C20: 0.63
A21: 5.75 | B21: 0.21 | C21: 0.41
A22: 5.4 | B22: 0.09 | C22: 0.25
A23: 5 | B23: 0.03 | C23: 0.13

Sheet Sensitivity
A1: RNAV sensitivity — land & partnership marks × RNAV discount (EGP/share)
A2: Rows: discount. Columns: uniform shift on the land/partnership block (86% of GAV). Live formulas.
A4: Discount \ mark shift | B4: -30% | C4: -15% | D4: +0% | E4: +15% | F4: +30%
A5: 0.25 | B5: =((RNAV!$C$13*(1+-0.3*0.86))-Assumptions!$B$24-Assumptions!$B$7)/Assumptions!$B$6*(1-0.25) -> 7.3358575 | C5: =((RNAV!$C$13*(1+-0.15*0.86))-Assumptions!$B$24-Assumptions!$B$7)/Assumptions!$B$6*(1-0.25) -> 8.853828 | D5: =((RNAV!$C$13*(1+0*0.86))-Assumptions!$B$24-Assumptions!$B$7)/Assumptions!$B$6*(1-0.25) -> 10.371799 | E5: =((RNAV!$C$13*(1+0.15*0.86))-Assumptions!$B$24-Assumptions!$B$7)/Assumptions!$B$6*(1-0.25) -> 11.889769 | F5: =((RNAV!$C$13*(1+0.3*0.86))-Assumptions!$B$24-Assumptions!$B$7)/Assumptions!$B$6*(1-0.25) -> 13.40774
A6: 0.3 | B6: =((RNAV!$C$13*(1+-0.3*0.86))-Assumptions!$B$24-Assumptions!$B$7)/Assumptions!$B$6*(1-0.3) -> 6.8468003 | C6: =((RNAV!$C$13*(1+-0.15*0.86))-Assumptions!$B$24-Assumptions!$B$7)/Assumptions!$B$6*(1-0.3) -> 8.2635728 | D6: =((RNAV!$C$13*(1+0*0.86))-Assumptions!$B$24-Assumptions!$B$7)/Assumptions!$B$6*(1-0.3) -> 9.6803453 | E6: =((RNAV!$C$13*(1+0.15*0.86))-Assumptions!$B$24-Assumptions!$B$7)/Assumptions!$B$6*(1-0.3) -> 11.097118 | F6: =((RNAV!$C$13*(1+0.3*0.86))-Assumptions!$B$24-Assumptions!$B$7)/Assumptions!$B$6*(1-0.3) -> 12.51389
A7: 0.35 | B7: =((RNAV!$C$13*(1+-0.3*0.86))-Assumptions!$B$24-Assumptions!$B$7)/Assumptions!$B$6*(1-0.35) -> 6.3577431 | C7: =((RNAV!$C$13*(1+-0.15*0.86))-Assumptions!$B$24-Assumptions!$B$7)/Assumptions!$B$6*(1-0.35) -> 7.6733176 | D7: =((RNAV!$C$13*(1+0*0.86))-Assumptions!$B$24-Assumptions!$B$7)/Assumptions!$B$6*(1-0.35) -> 8.9888921 | E7: =((RNAV!$C$13*(1+0.15*0.86))-Assumptions!$B$24-Assumptions!$B$7)/Assumptions!$B$6*(1-0.35) -> 10.304467 | F7: =((RNAV!$C$13*(1+0.3*0.86))-Assumptions!$B$24-Assumptions!$B$7)/Assumptions!$B$6*(1-0.35) -> 11.620041
A8: 0.4 | B8: =((RNAV!$C$13*(1+-0.3*0.86))-Assumptions!$B$24-Assumptions!$B$7)/Assumptions!$B$6*(1-0.4) -> 5.868686 | C8: =((RNAV!$C$13*(1+-0.15*0.86))-Assumptions!$B$24-Assumptions!$B$7)/Assumptions!$B$6*(1-0.4) -> 7.0830624 | D8: =((RNAV!$C$13*(1+0*0.86))-Assumptions!$B$24-Assumptions!$B$7)/Assumptions!$B$6*(1-0.4) -> 8.2974389 | E8: =((RNAV!$C$13*(1+0.15*0.86))-Assumptions!$B$24-Assumptions!$B$7)/Assumptions!$B$6*(1-0.4) -> 9.5118153 | F8: =((RNAV!$C$13*(1+0.3*0.86))-Assumptions!$B$24-Assumptions!$B$7)/Assumptions!$B$6*(1-0.4) -> 10.726192
A9: 0.45 | B9: =((RNAV!$C$13*(1+-0.3*0.86))-Assumptions!$B$24-Assumptions!$B$7)/Assumptions!$B$6*(1-0.45) -> 5.3796288 | C9: =((RNAV!$C$13*(1+-0.15*0.86))-Assumptions!$B$24-Assumptions!$B$7)/Assumptions!$B$6*(1-0.45) -> 6.4928072 | D9: =((RNAV!$C$13*(1+0*0.86))-Assumptions!$B$24-Assumptions!$B$7)/Assumptions!$B$6*(1-0.45) -> 7.6059856 | E9: =((RNAV!$C$13*(1+0.15*0.86))-Assumptions!$B$24-Assumptions!$B$7)/Assumptions!$B$6*(1-0.45) -> 8.719164 | F9: =((RNAV!$C$13*(1+0.3*0.86))-Assumptions!$B$24-Assumptions!$B$7)/Assumptions!$B$6*(1-0.45) -> 9.8323424
A10: 0.5 | B10: =((RNAV!$C$13*(1+-0.3*0.86))-Assumptions!$B$24-Assumptions!$B$7)/Assumptions!$B$6*(1-0.5) -> 4.8905716 | C10: =((RNAV!$C$13*(1+-0.15*0.86))-Assumptions!$B$24-Assumptions!$B$7)/Assumptions!$B$6*(1-0.5) -> 5.902552 | D10: =((RNAV!$C$13*(1+0*0.86))-Assumptions!$B$24-Assumptions!$B$7)/Assumptions!$B$6*(1-0.5) -> 6.9145324 | E10: =((RNAV!$C$13*(1+0.15*0.86))-Assumptions!$B$24-Assumptions!$B$7)/Assumptions!$B$6*(1-0.5) -> 7.9265128 | F10: =((RNAV!$C$13*(1+0.3*0.86))-Assumptions!$B$24-Assumptions!$B$7)/Assumptions!$B$6*(1-0.5) -> 8.9384931
A11: 0.55 | B11: =((RNAV!$C$13*(1+-0.3*0.86))-Assumptions!$B$24-Assumptions!$B$7)/Assumptions!$B$6*(1-0.55) -> 4.4015145 | C11: =((RNAV!$C$13*(1+-0.15*0.86))-Assumptions!$B$24-Assumptions!$B$7)/Assumptions!$B$6*(1-0.55) -> 5.3122968 | D11: =((RNAV!$C$13*(1+0*0.86))-Assumptions!$B$24-Assumptions!$B$7)/Assumptions!$B$6*(1-0.55) -> 6.2230792 | E11: =((RNAV!$C$13*(1+0.15*0.86))-Assumptions!$B$24-Assumptions!$B$7)/Assumptions!$B$6*(1-0.55) -> 7.1338615 | F11: =((RNAV!$C$13*(1+0.3*0.86))-Assumptions!$B$24-Assumptions!$B$7)/Assumptions!$B$6*(1-0.55) -> 8.0446438
A13: DCF sensitivity — WACC × terminal growth (EGP/share)
A14: WACC \ g | B14: 10% | C14: 11% | D14: 12% | E14: 13% | F14: 14%
A15: 0.18 | B15: =(SUMPRODUCT(DCF!$B$12:$F$12,1/(1+0.18)^{1,2,3,4,5})+DCF!$F$12*(1+0.1)/(0.18-0.1)/(1+0.18)^5-Assumptions!$B$7)/Assumptions!$B$6 -> 9.6192733 | C15: =(SUMPRODUCT(DCF!$B$12:$F$12,1/(1+0.18)^{1,2,3,4,5})+DCF!$F$12*(1+0.11)/(0.18-0.11)/(1+0.18)^5-Assumptions!$B$7)/Assumptions!$B$6 -> 10.910013 | D15: =(SUMPRODUCT(DCF!$B$12:$F$12,1/(1+0.18)^{1,2,3,4,5})+DCF!$F$12*(1+0.12)/(0.18-0.12)/(1+0.18)^5-Assumptions!$B$7)/Assumptions!$B$6 -> 12.630999 | E15: =(SUMPRODUCT(DCF!$B$12:$F$12,1/(1+0.18)^{1,2,3,4,5})+DCF!$F$12*(1+0.13)/(0.18-0.13)/(1+0.18)^5-Assumptions!$B$7)/Assumptions!$B$6 -> 15.040379 | F15: =(SUMPRODUCT(DCF!$B$12:$F$12,1/(1+0.18)^{1,2,3,4,5})+DCF!$F$12*(1+0.14)/(0.18-0.14)/(1+0.18)^5-Assumptions!$B$7)/Assumptions!$B$6 -> 18.65445
A16: 0.19 | B16: =(SUMPRODUCT(DCF!$B$12:$F$12,1/(1+0.19)^{1,2,3,4,5})+DCF!$F$12*(1+0.1)/(0.19-0.1)/(1+0.19)^5-Assumptions!$B$7)/Assumptions!$B$6 -> 8.3071476 | C16: =(SUMPRODUCT(DCF!$B$12:$F$12,1/(1+0.19)^{1,2,3,4,5})+DCF!$F$12*(1+0.11)/(0.19-0.11)/(1+0.19)^5-Assumptions!$B$7)/Assumptions!$B$6 -> 9.2777342 | D16: =(SUMPRODUCT(DCF!$B$12:$F$12,1/(1+0.19)^{1,2,3,4,5})+DCF!$F$12*(1+0.12)/(0.19-0.12)/(1+0.19)^5-Assumptions!$B$7)/Assumptions!$B$6 -> 10.525631 | E16: =(SUMPRODUCT(DCF!$B$12:$F$12,1/(1+0.19)^{1,2,3,4,5})+DCF!$F$12*(1+0.13)/(0.19-0.13)/(1+0.19)^5-Assumptions!$B$7)/Assumptions!$B$6 -> 12.189494 | F16: =(SUMPRODUCT(DCF!$B$12:$F$12,1/(1+0.19)^{1,2,3,4,5})+DCF!$F$12*(1+0.14)/(0.19-0.14)/(1+0.19)^5-Assumptions!$B$7)/Assumptions!$B$6 -> 14.518902
A17: 0.205 | B17: =(SUMPRODUCT(DCF!$B$12:$F$12,1/(1+0.205)^{1,2,3,4,5})+DCF!$F$12*(1+0.1)/(0.205-0.1)/(1+0.205)^5-Assumptions!$B$7)/Assumptions!$B$6 -> 6.8128894 | C17: =(SUMPRODUCT(DCF!$B$12:$F$12,1/(1+0.205)^{1,2,3,4,5})+DCF!$F$12*(1+0.11)/(0.205-0.11)/(1+0.205)^5-Assumptions!$B$7)/Assumptions!$B$6 -> 7.4792258 | D17: =(SUMPRODUCT(DCF!$B$12:$F$12,1/(1+0.205)^{1,2,3,4,5})+DCF!$F$12*(1+0.12)/(0.205-0.12)/(1+0.205)^5-Assumptions!$B$7)/Assumptions!$B$6 -> 8.3023473 | E17: =(SUMPRODUCT(DCF!$B$12:$F$12,1/(1+0.205)^{1,2,3,4,5})+DCF!$F$12*(1+0.13)/(0.205-0.13)/(1+0.205)^5-Assumptions!$B$7)/Assumptions!$B$6 -> 9.3449679 | F17: =(SUMPRODUCT(DCF!$B$12:$F$12,1/(1+0.205)^{1,2,3,4,5})+DCF!$F$12*(1+0.14)/(0.205-0.14)/(1+0.205)^5-Assumptions!$B$7)/Assumptions!$B$6 -> 10.708395
A18: 0.22 | B18: =(SUMPRODUCT(DCF!$B$12:$F$12,1/(1+0.22)^{1,2,3,4,5})+DCF!$F$12*(1+0.1)/(0.22-0.1)/(1+0.22)^5-Assumptions!$B$7)/Assumptions!$B$6 -> 5.6974838 | C18: =(SUMPRODUCT(DCF!$B$12:$F$12,1/(1+0.22)^{1,2,3,4,5})+DCF!$F$12*(1+0.11)/(0.22-0.11)/(1+0.22)^5-Assumptions!$B$7)/Assumptions!$B$6 -> 6.176711 | D18: =(SUMPRODUCT(DCF!$B$12:$F$12,1/(1+0.22)^{1,2,3,4,5})+DCF!$F$12*(1+0.12)/(0.22-0.12)/(1+0.22)^5-Assumptions!$B$7)/Assumptions!$B$6 -> 6.7517835 | E18: =(SUMPRODUCT(DCF!$B$12:$F$12,1/(1+0.22)^{1,2,3,4,5})+DCF!$F$12*(1+0.13)/(0.22-0.13)/(1+0.22)^5-Assumptions!$B$7)/Assumptions!$B$6 -> 7.45465 | F18: =(SUMPRODUCT(DCF!$B$12:$F$12,1/(1+0.22)^{1,2,3,4,5})+DCF!$F$12*(1+0.14)/(0.22-0.14)/(1+0.22)^5-Assumptions!$B$7)/Assumptions!$B$6 -> 8.3332331
A19: 0.235 | B19: =(SUMPRODUCT(DCF!$B$12:$F$12,1/(1+0.235)^{1,2,3,4,5})+DCF!$F$12*(1+0.1)/(0.235-0.1)/(1+0.235)^5-Assumptions!$B$7)/Assumptions!$B$6 -> 4.8343739 | C19: =(SUMPRODUCT(DCF!$B$12:$F$12,1/(1+0.235)^{1,2,3,4,5})+DCF!$F$12*(1+0.11)/(0.235-0.11)/(1+0.235)^5-Assumptions!$B$7)/Assumptions!$B$6 -> 5.1913532 | D19: =(SUMPRODUCT(DCF!$B$12:$F$12,1/(1+0.235)^{1,2,3,4,5})+DCF!$F$12*(1+0.12)/(0.235-0.12)/(1+0.235)^5-Assumptions!$B$7)/Assumptions!$B$6 -> 5.6104159 | E19: =(SUMPRODUCT(DCF!$B$12:$F$12,1/(1+0.235)^{1,2,3,4,5})+DCF!$F$12*(1+0.13)/(0.235-0.13)/(1+0.235)^5-Assumptions!$B$7)/Assumptions!$B$6 -> 6.1093 | F19: =(SUMPRODUCT(DCF!$B$12:$F$12,1/(1+0.235)^{1,2,3,4,5})+DCF!$F$12*(1+0.14)/(0.235-0.14)/(1+0.235)^5-Assumptions!$B$7)/Assumptions!$B$6 -> 6.7132124

Sheet Per-Share & Ratios
A1: Per-share values and ratios
A4: Metric | B4: FY23 | C4: FY24 | D4: FY25 | E4: FY26E | F4: FY27E | G4: FY28E | H4: FY29E | I4: FY30E
A5: EPS (EGP) | B5: ='Income Statement'!B18 -> 1.9496862 | C5: ='Income Statement'!C18 -> 0.63915951 | D5: ='Income Statement'!D18 -> 0.6753619 | E5: ='Income Statement'!E18 -> 0.87684445 | F5: ='Income Statement'!F18 -> 0.84093167 | G5: ='Income Statement'!G18 -> 1.0603556 | H5: ='Income Statement'!H18 -> 1.2519162 | I5: ='Income Statement'!I18 -> 1.3902656
A6: BVPS (EGP) | B6: ='Balance Sheet'!B24 -> 2.1876233 | C6: ='Balance Sheet'!C24 -> 2.3476628 | D6: ='Balance Sheet'!D24 -> 2.5758627 | E6: ='Balance Sheet'!E24 -> 3.0177791 | F6: ='Balance Sheet'!F24 -> 3.5341376 | G6: ='Balance Sheet'!G24 -> 4.1700514 | H6: ='Balance Sheet'!H24 -> 4.8976571 | I6: ='Balance Sheet'!I24 -> 5.6637434
A7: DPS declared (EGP) | B7: 0.446 | C7: 0.435 | D7: 0.435 | E7: =Assumptions!C59/Assumptions!$B$6 -> 0.32457319 | F7: =Assumptions!D59/Assumptions!$B$6 -> 0.42444186 | G7: =Assumptions!E59/Assumptions!$B$6 -> 0.52431053 | H7: =Assumptions!F59/Assumptions!$B$6 -> 0.6241792
A8: ROE | B8: ='Income Statement'!B17/'Balance Sheet'!B20 -> 0.89123488 | C8: ='Income Statement'!C17/'Balance Sheet'!C20 -> 0.27225354 | D8: ='Income Statement'!D17/'Balance Sheet'!D20 -> 0.26218862 | E8: ='Income Statement'!E17/'Balance Sheet'!E20 -> 0.29055952 | F8: ='Income Statement'!F17/'Balance Sheet'!F20 -> 0.23794537 | G8: ='Income Statement'!G17/'Balance Sheet'!G20 -> 0.25427879 | H8: ='Income Statement'!H17/'Balance Sheet'!H20 -> 0.25561533 | I8: ='Income Statement'!I17/'Balance Sheet'!I20 -> 0.24546761
A9: Net margin | B9: ='Income Statement'!B17/'Income Statement'!B5 -> 0.50121951 | C9: ='Income Statement'!C17/'Income Statement'!C5 -> 2.4265403 | D9: ='Income Statement'!D17/'Income Statement'!D5 -> 0.86283892 | E9: ='Income Statement'!E17/'Income Statement'!E5 -> 1.1439707 | F9: ='Income Statement'!F17/'Income Statement'!F5 -> 0.73220652 | G9: ='Income Statement'!G17/'Income Statement'!G5 -> 0.685 | H9: ='Income Statement'!H17/'Income Statement'!H5 -> 0.67760135 | I9: ='Income Statement'!I17/'Income Statement'!I5 -> 0.67088855
A10: P/E at spot | B10: =Assumptions!$B$5/'Income Statement'!B18 -> 3.2979667 | C10: =Assumptions!$B$5/'Income Statement'!C18 -> 10.060087 | D10: =Assumptions!$B$5/'Income Statement'!D18 -> 9.5208214 | E10: =Assumptions!$B$5/'Income Statement'!E18 -> 7.3331136 | F10: =Assumptions!$B$5/'Income Statement'!F18 -> 7.6462811 | G10: =Assumptions!$B$5/'Income Statement'!G18 -> 6.0640032 | H10: =Assumptions!$B$5/'Income Statement'!H18 -> 5.1361264 | I10: =Assumptions!$B$5/'Income Statement'!I18 -> 4.6250157
A11: P/B at spot | B11: =Assumptions!$B$5/'Balance Sheet'!B24 -> 2.9392629 | C11: =Assumptions!$B$5/'Balance Sheet'!C24 -> 2.7388942 | D11: =Assumptions!$B$5/'Balance Sheet'!D24 -> 2.496251 | E11: =Assumptions!$B$5/'Balance Sheet'!E24 -> 2.130706 | F11: =Assumptions!$B$5/'Balance Sheet'!F24 -> 1.8193972 | G11: =Assumptions!$B$5/'Balance Sheet'!G24 -> 1.5419474 | H11: =Assumptions!$B$5/'Balance Sheet'!H24 -> 1.3128726 | I11: =Assumptions!$B$5/'Balance Sheet'!I24 -> 1.1352915
A12: Dividend yield at spot | B12: 0.069362364 | C12: 0.067651633 | D12: 0.067651633

Sheet Peer & Sector
A1: Peer set — EGX land-bank developers
A2: Closing prices 01 Jul 2026 from the attached daily histories; multiples indicative (trailing, rounded).
A4: Peer | B4: Ticker | C4: Close (EGP) | D4: Positioning
A5: Talaat Moustafa Group | B5: TMGH | C5: 70.1 | D5: Scale developer; recurring hospitality; sector bellwether
A6: Palm Hills Developments | B6: PHDC | C6: 9.62 | D6: West/East Cairo launches; high asset turn
A7: SODIC | B7: OCDI | C7: 20.61 | D7: Premium brand; HELI’s 2018/19 partner on SODIC East
A8: Emaar Misr | B8: EMFD | C8: 13.5 | D8: Coastal + Uptown; net-cash balance sheet
A9: Madinet Masr | B9: MASR | D9: HELI’s 2025 JDA counterparty (491 fd)
A10: Orascom Development Egypt | B10: ORHD | C10: 37.9 | D10: Town developer; recurring hotels
A11: Heliopolis Housing | B11: HELI | C11: 6.43 | D11: State-controlled land bank converting to partnership annuities
A13: Sector: EGX real estate = land-bank optionality + off-plan absorption; sector trades 40–60% below stated NAVs; rates easing is the common tailwind.
