Workbook

Sheet READ FIRST
A1: Testahil — International Holding Company PJSC (ADX: IHC)
A2: Companion model · Independent Valuation Study · Educational analysis · Not investment advice
A6: What this workbook is. A transparent companion to the IHC valuation study. Every blue cell is an input;
A7: every black cell is a formula; green cells link across sheets. All inputs live on the Assumptions sheet —
A8: change one (a stake %, a single mark, the applied NAV premium, a growth rate) and the whole model reprices.
A10: What it is not. It is not investment advice, a recommendation, or a price target. Values are model outputs
A11: shown as ranges. The preparer is not licensed by any securities regulator and may hold, and may in the future
A12: take or dispose of, a position in the security discussed in this report.
A14: Lens. IHC is a holding company → primary lens is holdco NAV with disciplined-SOTP mechanics (§3.5-F4):
A15: each leg on its own basis (listed stakes at look-through market value; unlisted platforms at book/mark),
A16: holding-level net cash as a single explicit line, no blanket conglomerate discount.
A18: Currency. AED million unless stated; per-share in AED. FX at study date USD/AED 3.6725 (peg). Spot AED 382.30
... A26: Income Statement · Balance Sheet · Cash Flow · Summary Financials · Monte Carlo · Sensitivity · Per-Share & Ratios · Peer & Sector.

Sheet Summary
A1: Valuation summary — International Holding Company (ADX: IHC)
A2: Four-lens fair value vs spot. Base links live; bear/bull are scenario outputs (study §1.5).
A3: Lens | B3: Bear | C3: Base | D3: Bull | E3: Weight
A4: Sum-of-the-parts (NAV) | B4: 95 | C4: =SOTP!C16 | D4: 175 | E4: =Assumptions!B36
A5: Consolidated DCF (operating) | B5: 55 | C5: =DCF!B28 | D5: 130 | E5: =Assumptions!B37
A6: Relative multiples | B6: 85 | C6: ='Relative & Normalized'!C5 | D6: 160 | E6: =Assumptions!B38
A7: Normalized earnings (mid-cycle) | B7: 80 | C7: ='Relative & Normalized'!C9 | D7: 145 | E7: =Assumptions!B39
A8: Weighted central | B8: =SUMPRODUCT(B4:B7,$E$4:$E$7) | C8: =SUMPRODUCT(C4:C7,$E$4:$E$7) | D8: =SUMPRODUCT(D4:D7,$E$4:$E$7)
A10: Spot price (AED) | C10: =Assumptions!B4
A11: Spot premium to central base | C11: =C10/C8-1
A13: Read: on every fundamental lens IHC is worth a fraction of its market price; the market price
A14: embeds a large scarcity / sponsor / consolidation premium that fundamentals do not underwrite.

Sheet Fundamental Valuation
A1: Fundamental valuation — football field data
A2: Bear/base/bull per lens (links to Summary).
A3: Lens | B3: Bear | C3: Base | D3: Bull
A4: Sum-of-the-parts (NAV) | B4: =Summary!B4 | C4: =Summary!C4 | D4: =Summary!D4
A5: Consolidated DCF (operating) | B5: =Summary!B5 | C5: =Summary!C5 | D5: =Summary!D5
A6: Relative multiples | B6: =Summary!B6 | C6: =Summary!C6 | D6: =Summary!D6
A7: Normalized earnings (mid-cycle) | B7: =Summary!B7 | C7: =Summary!C7 | D7: =Summary!D7
A8: Weighted central | B8: =Summary!B8 | C8: =Summary!C8 | D8: =Summary!D8
A9: Spot | C9: =Assumptions!B4

Sheet Assumptions
A1: Assumptions — the single input layer
A2: All blue cells are inputs. Every other sheet links here.
A3: ANCHORS
A4: Spot price (AED/share) | B4: 382.3
A5: Shares outstanding (m) | B5: 2180
A6: USD/AED (peg) | B6: 3.6725
A7: Holdco net cash (AED m) [+ adds to NAV] | B7: 20000 | C7: parent-level; flagged
A8: Consolidated net debt (AED m) [DCF] | B8: 25570 | C8: debt 100,470 − cash 74,900
A9: WACC | B9: 0.093 | C9: =Ke·we + Kd(1−t)·wd, see DCF
A10: Terminal growth | B10: 0.035
A11: Tax rate (forecast) | B11: 0.09 | C11: UAE corp tax
A12: Risk-free rate (rf) | B12: 0.043
A13: Equity risk premium (ERP) | B13: 0.055
A14: Beta (house) | B14: 1 | C14: observed −0.24 = thin-float artifact; not used
A16: SOTP — base marks (AED m / stakes)
A17: Alpha Dhabi — ADX market cap | B17: 69500 | C17: holds NMDC 77% + Aldar → no double-count
A18: IHC stake in Alpha Dhabi | B18: 0.6
A19: Merged Multiply/2PointZero/Ghitha — entity value | B19: 120000
A20: IHC look-through stake in merged entity | B20: 0.55 | C20: flagged
A21: Other listed subs (look-through) | B21: 25000 | C21: flagged
A22: IRH — metals (unlisted mark) | B22: 40000 | C22: flagged estimate
A23: RIQ — reinsurance (unlisted mark) | B23: 8000 | C23: flagged estimate
A24: Private industrial/food/tech + long tail | B24: 60000 | C24: flagged, book-based
A25: NAV premium/(discount) applied | B25: 0 | C25: base = NAV; no arbitrary premium
A27: RELATIVE & NORMALIZED
A28: Attributable NI, normalized (AED m) | B28: 18000 | C28: ex lumpy revaluation gains
A29: Justified P/E | B29: 12
A30: Attributable book equity (AED m) | B30: 151500 | C30: BVPS 69.51 × shares
A31: Justified P/B | B31: 1.5
A32: Mid-cycle recurring attributable earnings (AED m) | B32: 16500
A33: Mid-cycle P/E | B33: 12
A35: SYNTHESIS WEIGHTS
A36: SOTP weight | B36: 0.45
A37: DCF weight | B37: 0.15
A38: Relative weight | B38: 0.2
A39: Normalized weight | B39: 0.2
A41: FORECAST DRIVERS (FY26E–FY30E) | E41: FY26E | F41: FY27E | G41: FY28E | H41: FY29E | I41: FY30E
A42: Revenue growth | E42: 0.12 | F42: 0.1 | G42: 0.09 | H42: 0.08 | I42: 0.07
A43: EBITDA margin | E43: 0.2 | F43: 0.2 | G43: 0.2 | H43: 0.2 | I43: 0.2
A44: D&A (% revenue) | E44: 0.05 | F44: 0.05 | G44: 0.05 | H44: 0.05 | I44: 0.05
...

Sheet SOTP
A1: Sum-of-the-parts / holdco NAV (primary lens)
A2: Each leg on its own basis, spot-FX. Listed stakes at look-through market value; unlisted at book/mark. Links to Assumptions.
A3: Part | B3: Basis | C3: Value (AED m) | D3: % of GAV
A4: Alpha Dhabi Holding (60%) | B4: ADX mcap × stake | C4: =Assumptions!B17*Assumptions!B18 | D4: =C4/$C$10
A5: Merged Multiply/2PointZero/Ghitha | B5: Entity value × look-through | C5: =Assumptions!B19*Assumptions!B20 | D5: =C5/$C$10
A6: Other listed subsidiaries | B6: Look-through market | C6: =Assumptions!B21 | D6: =C6/$C$10
A7: IRH — metals & mining | B7: Book / mark (unlisted) | C7: =Assumptions!B22 | D7: =C7/$C$10
A8: RIQ — reinsurance | B8: Book / mark (unlisted) | C8: =Assumptions!B23 | D8: =C8/$C$10
A9: Private industrial/food/tech + tail | B9: Book-based (1,300 subs) | C9: =Assumptions!B24 | D9: =C9/$C$10
A10: Σ Gross asset value (GAV) | C10: =SUM(C4:C9)
A11: plus: holdco net cash | C11: =Assumptions!B7
A12: NAV (pre-premium) | C12: =C10+C11
A13: per share (AED) | C13: =C12/Assumptions!B5
A14: apply: NAV premium/(discount) | B14: applied | C14: =C12*Assumptions!B25
A15: SOTP equity value | C15: =C12+C14
A16: SOTP fair value per share (AED) | C16: =C15/Assumptions!B5
A18: Memo: implied premium of spot to NAV | C18: =Assumptions!B4/C16-1
A19: Memo: spot / NAV multiple | C19: =Assumptions!B4/C13

Sheet Segments
A1: Operating segments — FY2025 revenue (AED m)
A2: Company disclosure, FY2025 results (15 Feb 2026). Investment-led profit sits above operating segments (see IS).
A3: Segment | B3: Revenue | C3: % of total
A4: Real Estate & Construction | B4: 44200 | C4: =B4/$B$12
A5: Marine & Dredging (NMDC) | B5: 30200 | C5: =B5/$B$12
A6: Services & other | B6: 8700 | C6: =B6/$B$12
A7: Energy | B7: 8300 | C7: =B7/$B$12
A8: Hospitality & Leisure | B8: 7600 | C8: =B8/$B$12
A9: Food & Agriculture | B9: 5600 | C9: =B9/$B$12
A10: Technology | B10: 4200 | C10: =B10/$B$12
A11: Financial Services | B11: 4000 | C11: =B11/$B$12
A12: Σ (gross, pre-elimination) | B12: =SUM(B4:B11)
A13: Reported group revenue FY2025 | B13: 111400

Sheet Relative & Normalized
A1: Relative multiples & normalized earnings
A2: Peer holdcos trade at 8–14× P/E and often a discount to book. IHC at ~35× P/E, ~5.5× attributable book.
A3: Method | B3: Basis | C3: Value / share (AED)
A4: Relative — P/E on normalized attrib. NI | B4: =Assumptions!B28&" × "&Assumptions!B29 | C4: =Assumptions!B28*Assumptions!B29/Assumptions!B5
A5: Relative — blended (P/E & P/B avg) | B5: avg of P/E and P/B marks | C5: =AVERAGE(C4,C6)
A6: Relative — P/B on attributable book | B6: =Assumptions!B30&" × "&Assumptions!B31 | C6: =Assumptions!B30*Assumptions!B31/Assumptions!B5
A8: Normalized — mid-cycle earnings power | B8: strip one-off revaluation gains
A9: Normalized fair value / share (AED) | B9: =Assumptions!B32&" × "&Assumptions!B33 | C9: =Assumptions!B32*Assumptions!B33/Assumptions!B5
A11: Memo: current P/E (spot × shares / attrib NI FY25) | C11: =Assumptions!B4*Assumptions!B5/21647
A12: Memo: current P/B (spot × shares / attrib book) | C12: =Assumptions!B4*Assumptions!B5/Assumptions!B30

Sheet DCF
A1: Discounted cash flow — consolidated operating FCFF (cross-check lens)
A2: Deliberately excludes portfolio revaluation & associate income (an investment holdco's value sits in the SOTP). Ke published as rf + ERP. TV disclosed as % of EV.
A3: AED m | B3: FY26E | C3: FY27E | D3: FY28E | E3: FY29E | F3: FY30E
A4: Revenue | B4: ='Income Statement'!E4 | C4: ='Income Statement'!F4 | D4: ='Income Statement'!G4 | E4: ='Income Statement'!H4 | F4: ='Income Statement'!I4
A5: EBITDA | B5: ='Income Statement'!E5 | C5: ='Income Statement'!F5 | D5: ='Income Statement'!G5 | E5: ='Income Statement'!H5 | F5: ='Income Statement'!I5
A6: less: D&A | B6: ='Income Statement'!E6 | C6: ='Income Statement'!F6 | D6: ='Income Statement'!G6 | E6: ='Income Statement'!H6 | F6: ='Income Statement'!I6
A7: EBIT | B7: =B5+B6 | C7: =C5+C6 | D7: =D5+D6 | E7: =E5+E6 | F7: =F5+F6
A8: less: tax on EBIT | B8: =-B7*Assumptions!B11 | C8: =-C7*Assumptions!B11 | D8: =-D7*Assumptions!B11 | E8: =-E7*Assumptions!B11 | F8: =-F7*Assumptions!B11
A9: NOPAT | B9: =B7+B8 | C9: =C7+C8 | D9: =D7+D8 | E9: =E7+E8 | F9: =F7+F8
A10: add: D&A | B10: =-B6 | C10: =-C6 | D10: =-D6 | E10: =-E6 | F10: =-F6
A11: less: capex | B11: =-'Income Statement'!E4*Assumptions!E45 | C11: =-'Income Statement'!F4*Assumptions!F45 | D11: =-'Income Statement'!G4*Assumptions!G45 | E11: =-'Income Statement'!H4*Assumptions!H45 | F11: =-'Income Statement'!I4*Assumptions!I45
A12: less: ΔWorking capital | B12: =-('Income Statement'!E4-'Income Statement'!D4)*Assumptions!E46 | C12: =-('Income Statement'!F4-'Income Statement'!E4)*Assumptions!F46 | D12: =-('Income Statement'!G4-'Income Statement'!F4)*Assumptions!G46 | E12: =-('Income Statement'!H4-'Income Statement'!G4)*Assumptions!H46 | F12: =-('Income Statement'!I4-'Income Statement'!H4)*Assumptions!I46
A13: Free cash flow to firm (FCFF) | B13: =B9+B10+B11+B12 | C13: =C9+C10+C11+C12 | D13: =D9+D10+D11+D12 | E13: =E9+E10+E11+E12 | F13: =F9+F10+F11+F12
A14: Discount factor @ WACC | B14: =1/(1+Assumptions!B9)^1 | C14: =1/(1+Assumptions!B9)^2 | D14: =1/(1+Assumptions!B9)^3 | E14: =1/(1+Assumptions!B9)^4 | F14: =1/(1+Assumptions!B9)^5
A15: PV of FCFF | B15: =B13*B14 | C15: =C13*C14 | D15: =D13*D14 | E15: =E13*E14 | F15: =F13*F14
A17: Cost of equity Ke = rf + β × ERP | B17: =Assumptions!B12+Assumptions!B14*Assumptions!B13 | C17: rf 4.3% + 1.0 × ERP 5.5%
A18: WACC | B18: =Assumptions!B9 | C18: Ke·we + Kd(1−t)·wd
A19: Terminal growth g | B19: =Assumptions!B10
A20: Σ PV of FCFF (FY26–30) | B20: =SUM(B15:F15)
A21: Terminal value (undiscounted) | B21: =F13*(1+B19)/(B18-B19)
A22: PV of terminal value | B22: =B21/(1+B18)^5
A23: Enterprise value | B23: =B20+B22
A24: Terminal value as % of EV | B24: =B22/B23 | C24: high-terminal disclosure (device A-7)
A25: less: consolidated net debt | B25: =-Assumptions!B8
A26: less: minority interest (proportional) | B26: =-(B23+B25)*(99200/250700) | C26: MI share of equity
A27: Attributable equity value | B27: =B23+B25+B26
A28: DCF fair value per share (AED) | B28: =B27/Assumptions!B5

Sheet Income Statement
A1: Appendix A.1 — Income statement (AED m)
A2: 3 yr historical + 5 yr forecast. FY2025 audited (15 Feb 2026); FY2023 estimated (flagged). Forecast links to Assumptions.
A3: AED m | B3: FY23e | C3: FY24A | D3: FY25A | E3: FY26E | F3: FY27E | G3: FY28E | H3: FY29E | I3: FY30E
A4: Revenue | B4: 62000 | C4: 86290 | D4: 111400 | E4: =D4*(1+Assumptions!E42) | F4: =E4*(1+Assumptions!F42) | G4: =F4*(1+Assumptions!G42) | H4: =G4*(1+Assumptions!H42) | I4: =H4*(1+Assumptions!I42)
A5: EBITDA | B5: 12400 | C5: 17300 | D5: 22660 | E5: =E4*Assumptions!E43 | F5: =F4*Assumptions!F43 | G5: =G4*Assumptions!G43 | H5: =H4*Assumptions!H43 | I5: =I4*Assumptions!I43
A6: D&A | B6: -3100 | C6: -4300 | D6: -5030 | E6: =-E4*Assumptions!E44 | F6: =-F4*Assumptions!F44 | G6: =-G4*Assumptions!G44 | H6: =-H4*Assumptions!H44 | I6: =-I4*Assumptions!I44
A7: EBIT (operating) | B7: =B5+B6 | C7: =C5+C6 | D7: =D5+D6 | E7: =E5+E6 | F7: =F5+F6 | G7: =G5+G6 | H7: =H5+H6 | I7: =I5+I6
A8: Investment / associate income & FV gains | B8: 26600 | C8: 17035 | D8: 22670 | E8: =Assumptions!E47 | F8: =Assumptions!F47 | G8: =Assumptions!G47 | H8: =Assumptions!H47 | I8: =Assumptions!I47
A9: Net finance cost | B9: -2000 | C9: -2800 | D9: -3500 | E9: =Assumptions!E48 | F9: =Assumptions!F48 | G9: =Assumptions!G48 | H9: =Assumptions!H48 | I9: =Assumptions!I48
A10: Profit before tax | B10: =B7+B8+B9 | C10: =C7+C8+C9 | D10: =D7+D8+D9 | E10: =E7+E8+E9 | F10: =F7+F8+F9 | G10: =G7+G8+G9 | H10: =H7+H8+H9 | I10: =I7+I8+I9
A11: Tax | B11: -1000 | C11: -1550 | D11: -2100 | E11: =-E10*Assumptions!B11 | F11: =-F10*Assumptions!B11 | G11: =-G10*Assumptions!B11 | H11: =-H10*Assumptions!B11 | I11: =-I10*Assumptions!B11
A12: Profit after tax (group) | B12: =B10+B11 | C12: =C10+C11 | D12: =D10+D11 | E12: =E10+E11 | F12: =F10+F11 | G12: =G10+G11 | H12: =H10+H11 | I12: =I10+I11
A13: Minority interest | B13: -12900 | C13: -10011 | D13: -13053 | E13: =-E12*Assumptions!E49 | F13: =-F12*Assumptions!F49 | G13: =-G12*Assumptions!G49 | H13: =-H12*Assumptions!H49 | I13: =-I12*Assumptions!I49
A14: Attributable net income | B14: =B12+B13 | C14: =C12+C13 | D14: =D12+D13 | E14: =E12+E13 | F14: =F12+F13 | G14: =G12+G13 | H14: =H12+H13 | I14: =I12+I13
A15: EPS (AED) | B15: =B14/Assumptions!B5 | C15: =C14/Assumptions!B5 | D15: =D14/Assumptions!B5 | E15: =E14/Assumptions!B5 | F15: =F14/Assumptions!B5 | G15: =G14/Assumptions!B5 | H15: =H14/Assumptions!B5 | I15: =I14/Assumptions!B5

Sheet Balance Sheet
A1: Appendix A.2 — Balance sheet (AED m)
A2: 3 yr historical + 5 yr forecast. FY2025 audited; FY2023 and some line items estimated to balance to disclosed totals (flagged).
A3: AED m | B3: FY23e | C3: FY24A | D3: FY25A | E3: FY26E | F3: FY27E | G3: FY28E | H3: FY29E | I3: FY30E
A5: Cash & bank balances | B5: 45000 | C5: 55236 | D5: 74900 | E5: ='Cash Flow'!E12 | F5: ='Cash Flow'!F12 | G5: ='Cash Flow'!G12 | H5: ='Cash Flow'!H12 | I5: ='Cash Flow'!I12
A6: Property, plant & equipment | B6: 70000 | C6: 85000 | D6: 95000 | E6: =D6+'Income Statement'!E4*Assumptions!E45+'Income Statement'!E6 | F6: =E6+'Income Statement'!F4*Assumptions!F45+'Income Statement'!F6 | G6: =F6+'Income Statement'!G4*Assumptions!G45+'Income Statement'!G6 | H6: =G6+'Income Statement'!H4*Assumptions!H45+'Income Statement'!H6 | I6: =H6+'Income Statement'!I4*Assumptions!I45+'Income Statement'!I6
A7: Other assets (WC, goodwill, etc.) | B7: 60000 | C7: 70000 | D7: 80000 | E7: ='Income Statement'!E4*0.62 | F7: ='Income Statement'!F4*0.62 | G7: ='Income Statement'!G4*0.62 | H7: ='Income Statement'!H4*0.62 | I7: ='Income Statement'!I4*0.62
A8: Financial investments & associates (plug) | B8: =B9-B5-B6-B7 | C8: =C9-C5-C6-C7 | D8: =D9-D5-D6-D7 | E8: =E9-E5-E6-E7 | F8: =F9-F5-F6-F7 | G8: =G9-G5-G6-G7 | H8: =H9-H5-H6-H7 | I8: =I9-I5-I6-I7
A9: Total assets | B9: =B17+B13 | C9: =C17+C13 | D9: =D17+D13 | E9: =E17+E13 | F9: =F17+F13 | G9: =G17+G13 | H9: =H17+H13 | I9: =I17+I13
A11: Total borrowings | B11: 80000 | C11: 92000 | D11: 100470 | E11: 105000 | F11: 108000 | G11: 110000 | H11: 112000 | I11: 114000
A12: Other liabilities | B12: 50000 | C12: 65500 | D12: 77430 | E12: ='Income Statement'!E4*0.62 | F12: ='Income Statement'!F4*0.62 | G12: ='Income Statement'!G4*0.62 | H12: ='Income Statement'!H4*0.62 | I12: ='Income Statement'!I4*0.62
A13: Total liabilities | B13: =B11+B12 | C13: =C11+C12 | D13: =D11+D12 | E13: =E11+E12 | F13: =F11+F12 | G13: =G11+G12 | H13: =H11+H12 | I13: =I11+I12
A15: Attributable equity | B15: 120000 | C15: 140000 | D15: 151500 | E15: =D15+'Income Statement'!E14 | F15: =E15+'Income Statement'!F14 | G15: =F15+'Income Statement'!G14 | H15: =G15+'Income Statement'!H14 | I15: =H15+'Income Statement'!I14
A16: Minority interest | B16: 80000 | C16: 104300 | D16: 99200 | E16: =D16-'Income Statement'!E13 | F16: =E16-'Income Statement'!F13 | G16: =F16-'Income Statement'!G13 | H16: =G16-'Income Statement'!H13 | I16: =H16-'Income Statement'!I13
A17: Total equity | B17: =B15+B16 | C17: =C15+C16 | D17: =D15+D16 | E17: =E15+E16 | F17: =F15+F16 | G17: =G15+G16 | H17: =H15+H16 | I17: =I15+I16
A19: Check: assets − (equity+liab) | B19: =B9-(B17+B13) | C19: =C9-(C17+C13) | D19: =D9-(D17+D13) | E19: =E9-(E17+E13) | F19: =F9-(F17+F13) | G19: =G9-(G17+G13) | H19: =H9-(H17+H13) | I19: =I9-(I17+I13)

Sheet Cash Flow
A1: Appendix A.3 — Cash flow (AED m)
A2: Operating proxy consistent with the DCF FCFF build. Near-zero dividend.
A3: AED m | B3: FY23e | C3: FY24A | D3: FY25A | E3: FY26E | F3: FY27E | G3: FY28E | H3: FY29E | I3: FY30E
A4: EBITDA | B4: 12400 | C4: 17300 | D4: 22660 | E4: ='Income Statement'!E5 | F4: ='Income Statement'!F5 | G4: ='Income Statement'!G5 | H4: ='Income Statement'!H5 | I4: ='Income Statement'!I5
A5: less: tax paid | B5: -1000 | C5: -1550 | D5: -2100 | E5: ='Income Statement'!E11 | F5: ='Income Statement'!F11 | G5: ='Income Statement'!G11 | H5: ='Income Statement'!H11 | I5: ='Income Statement'!I11
A6: less: ΔWorking capital | B6: -1000 | C6: -1200 | D6: -1400 | E6: =-('Income Statement'!E4-'Income Statement'!D4)*Assumptions!E46 | F6: =-('Income Statement'!F4-'Income Statement'!E4)*Assumptions!F46 | G6: =-('Income Statement'!G4-'Income Statement'!F4)*Assumptions!G46 | H6: =-('Income Statement'!H4-'Income Statement'!G4)*Assumptions!H46 | I6: =-('Income Statement'!I4-'Income Statement'!H4)*Assumptions!I46
A7: Cash flow from operations | B7: =B4+B5+B6 | C7: =C4+C5+C6 | D7: =D4+D5+D6 | E7: =E4+E5+E6 | F7: =F4+F5+F6 | G7: =G4+G5+G6 | H7: =H4+H5+H6 | I7: =I4+I5+I6
A8: less: capex | B8: -3720 | C8: -5177 | D8: -6684 | E8: =-'Income Statement'!E4*Assumptions!E45 | F8: =-'Income Statement'!F4*Assumptions!F45 | G8: =-'Income Statement'!G4*Assumptions!G45 | H8: =-'Income Statement'!H4*Assumptions!H45 | I8: =-'Income Statement'!I4*Assumptions!I45
A9: Free cash flow | B9: =B7+B8 | C9: =C7+C8 | D9: =D7+D8 | E9: =E7+E8 | F9: =F7+F8 | G9: =G7+G8 | H9: =H7+H8 | I9: =I7+I8
A10: Net financing & investing (incl. Δdebt, ~0 div) | B10: 2000 | C10: 3000 | D10: 8000 | E10: 3000 | F10: 3000 | G10: 2000 | H10: 2000 | I10: 2000
A11: Net change in cash | B11: =B9+B10 | C11: =C9+C10 | D11: =D9+D10 | E11: =E9+E10 | F11: =F9+F10 | G11: =G9+G10 | H11: =H9+H10 | I11: =I9+I10
A12: Ending cash & bank | B12: 45000 | C12: 55236 | D12: 74900 | E12: =D12+E11 | F12: =E12+F11 | G12: =F12+G11 | H12: =G12+H11 | I12: =H12+I11

Sheet Summary Financials
A1: Summary financials (AED m) — every cell links to the statement sheets
A3: AED m | B3: FY23e | C3: FY24A | D3: FY25A | E3: FY26E | F3: FY27E | G3: FY28E | H3: FY29E | I3: FY30E
A4: Revenue | B4: ='Income Statement'!B4 | C4: ='Income Statement'!C4 | D4: ='Income Statement'!D4 | E4: ='Income Statement'!E4 | F4: ='Income Statement'!F4 | G4: ='Income Statement'!G4 | H4: ='Income Statement'!H4 | I4: ='Income Statement'!I4
A5: EBITDA | B5: ='Income Statement'!B5 | C5: ='Income Statement'!C5 | D5: ='Income Statement'!D5 | E5: ='Income Statement'!E5 | F5: ='Income Statement'!F5 | G5: ='Income Statement'!G5 | H5: ='Income Statement'!H5 | I5: ='Income Statement'!I5
A6: EBIT | B6: ='Income Statement'!B7 | C6: ='Income Statement'!C7 | D6: ='Income Statement'!D7 | E6: ='Income Statement'!E7 | F6: ='Income Statement'!F7 | G6: ='Income Statement'!G7 | H6: ='Income Statement'!H7 | I6: ='Income Statement'!I7
A7: Profit before tax | B7: ='Income Statement'!B10 | C7: ='Income Statement'!C10 | D7: ='Income Statement'!D10 | E7: ='Income Statement'!E10 | F7: ='Income Statement'!F10 | G7: ='Income Statement'!G10 | H7: ='Income Statement'!H10 | I7: ='Income Statement'!I10
A8: Attributable net income | B8: ='Income Statement'!B14 | C8: ='Income Statement'!C14 | D8: ='Income Statement'!D14 | E8: ='Income Statement'!E14 | F8: ='Income Statement'!F14 | G8: ='Income Statement'!G14 | H8: ='Income Statement'!H14 | I8: ='Income Statement'!I14
A9: EPS (AED) | B9: ='Income Statement'!B15 | C9: ='Income Statement'!C15 | D9: ='Income Statement'!D15 | E9: ='Income Statement'!E15 | F9: ='Income Statement'!F15 | G9: ='Income Statement'!G15 | H9: ='Income Statement'!H15 | I9: ='Income Statement'!I15
A10: Total assets | B10: ='Balance Sheet'!B9 | C10: ='Balance Sheet'!C9 | D10: ='Balance Sheet'!D9 | E10: ='Balance Sheet'!E9 | F10: ='Balance Sheet'!F9 | G10: ='Balance Sheet'!G9 | H10: ='Balance Sheet'!H9 | I10: ='Balance Sheet'!I9
A11: Total equity | B11: ='Balance Sheet'!B17 | C11: ='Balance Sheet'!C17 | D11: ='Balance Sheet'!D17 | E11: ='Balance Sheet'!E17 | F11: ='Balance Sheet'!F17 | G11: ='Balance Sheet'!G17 | H11: ='Balance Sheet'!H17 | I11: ='Balance Sheet'!I17
A12: Attributable equity | B12: ='Balance Sheet'!B15 | C12: ='Balance Sheet'!C15 | D12: ='Balance Sheet'!D15 | E12: ='Balance Sheet'!E15 | F12: ='Balance Sheet'!F15 | G12: ='Balance Sheet'!G15 | H12: ='Balance Sheet'!H15 | I12: ='Balance Sheet'!I15
A13: Total borrowings | B13: ='Balance Sheet'!B11 | C13: ='Balance Sheet'!C11 | D13: ='Balance Sheet'!D11 | E13: ='Balance Sheet'!E11 | F13: ='Balance Sheet'!F11 | G13: ='Balance Sheet'!G11 | H13: ='Balance Sheet'!H11 | I13: ='Balance Sheet'!I11
A14: Cash & bank | B14: ='Balance Sheet'!B5 | C14: ='Balance Sheet'!C5 | D14: ='Balance Sheet'!D5 | E14: ='Balance Sheet'!E5 | F14: ='Balance Sheet'!F5 | G14: ='Balance Sheet'!G5 | H14: ='Balance Sheet'!H5 | I14: ='Balance Sheet'!I5
A15: Free cash flow | B15: ='Cash Flow'!B9 | C15: ='Cash Flow'!C9 | D15: ='Cash Flow'!D9 | E15: ='Cash Flow'!E9 | F15: ='Cash Flow'!F9 | G15: ='Cash Flow'!G9 | H15: ='Cash Flow'!H9 | I15: ='Cash Flow'!I9

Sheet Monte Carlo
A1: Monte Carlo — YZ-HAR width · Student-t(5) · zero drift (international) · 16 factors (7C+9D) · 50k paths · seed 42
A2: Paths diffuse from spot as near-term price; the §1 value gap is kept out of the drift (lens independence).
A4: Spot (AED) | B4: 382.3
A5: YZ-HAR σ (annualized) | B5: 0.061
A6: Net 3-month factor drift | B6: 0.025
A7: Realized path vol (with event overlay) | B7: 0.2407
A9: Percentile | B9: T+20 (AED) | C9: T+60 (AED)
A10: 5th | B10: 340.57 | C10: 322.62
A11: 25th | B11: 376.01 | C11: 364.78
A12: 50th | B12: 384.38 | C12: 391.29
A13: 75th | B13: 397.08 | C13: 418.19
A14: 95th | B14: 427.86 | C14: 462.27
A16: Touch-probability ladder
A17: Level (AED) | B17: × spot | C17: P(touch) T+20 | D17: P(touch) T+60
A18: 393.77 | B18: 1.03x | C18: 0.354 | D18: 0.67
A19: 405.24 | B19: 1.06x | C19: 0.211 | D19: 0.51
A20: 420.53 | B20: 1.10x | C20: 0.096 | D20: 0.326
A21: 439.64 | B21: 1.15x | C21: 0.029 | D21: 0.168
A22: 458.76 | B22: 1.20x | C22: 0.009 | D22: 0.079
A23: 370.83 | B23: 0.97x | C23: 0.233 | D23: 0.471
A24: 359.36 | B24: 0.94x | C24: 0.144 | D24: 0.335
A25: 344.07 | B25: 0.90x | C25: 0.076 | D25: 0.204
A26: 324.95 | B26: 0.85x | C26: 0.025 | D26: 0.09
A27: 305.84 | B27: 0.80x | C27: 0.006 | D27: 0.033

Sheet Sensitivity
A1: Sensitivity — primary lens (SOTP) and DCF cross-check
A2: §1.9 grid. Crux swung in observable units: the applied NAV premium and the private-arm mark; and WACC × terminal g.
A4: SOTP fair value / share (AED): NAV premium (rows) × private-arm mark AED m (cols)
B5: 40k | C5: 50k | D5: 60k | E5: 70k | F5: 80k
A6: -20% | B6: 88.3 | C6: 92 | D6: 95.7 | E6: 99.3 | F6: 103
A7: -10% | B7: 99.4 | C7: 103.5 | D7: 107.6 | E7: 111.8 | F7: 115.9
A8: +0% | B8: 110.4 | C8: 115 | D8: 119.6 | E8: 124.2 | F8: 128.8
A9: +10% | B9: 121.5 | C9: 126.5 | D9: 131.5 | E9: 136.6 | F9: 141.6
A10: +20% | B10: 132.5 | C10: 138 | D10: 143.5 | E10: 149 | F10: 154.5
A12: DCF fair value / share (AED): WACC (rows) × terminal g (cols)
B13: 2.5% | C13: 3.0% | D13: 3.5% | E13: 4.0% | F13: 4.5%
A14: 8.3% | B14: 84.3 | C14: 91.4 | D14: 99.9 | E14: 110.5 | F14: 123.8
A15: 8.8% | B15: 76.8 | C15: 82.7 | D15: 89.7 | E15: 98.1 | F15: 108.5
A16: 9.3% | B16: 70.5 | C16: 75.4 | D16: 81.2 | E16: 88 | F16: 96.3
A17: 9.8% | B17: 65.1 | C17: 69.2 | D17: 74 | E17: 79.7 | F17: 86.4
A18: 10.3% | B18: 60.3 | C18: 63.9 | D18: 68 | E18: 72.7 | F18: 78.2
A20: Spot AED 382.30 sits far above every fundamental cell — the premium, not the point estimate, is the story.

Sheet Per-Share & Ratios
A1: Per-share & ratios dashboard (Data Miner)
A2: Fixed panel, identical across studies. Forward P/E and P/B use study-date spot; ratios link to the statements.
A3: Metric | B3: FY23e | C3: FY24A | D3: FY25A | E3: FY26E | F3: FY27E | G3: FY28E | H3: FY29E | I3: FY30E
A4: EPS (AED) | B4: ='Income Statement'!B15 | C4: ='Income Statement'!C15 | D4: ='Income Statement'!D15 | E4: ='Income Statement'!E15 | F4: ='Income Statement'!F15 | G4: ='Income Statement'!G15 | H4: ='Income Statement'!H15 | I4: ='Income Statement'!I15
A5: DPS (AED) | B5: 0 | C5: 0 | D5: 0 | E5: 0 | F5: 0 | G5: 0 | H5: 0 | I5: 0
A6: BVPS (AED) | B6: ='Balance Sheet'!B15/Assumptions!B5 | C6: ='Balance Sheet'!C15/Assumptions!B5 | D6: ='Balance Sheet'!D15/Assumptions!B5 | E6: ='Balance Sheet'!E15/Assumptions!B5 | F6: ='Balance Sheet'!F15/Assumptions!B5 | G6: ='Balance Sheet'!G15/Assumptions!B5 | H6: ='Balance Sheet'!H15/Assumptions!B5 | I6: ='Balance Sheet'!I15/Assumptions!B5
A7: P/E (spot ÷ EPS) | B7: =Assumptions!B4/'Income Statement'!B15 | C7: =Assumptions!B4/'Income Statement'!C15 | D7: =Assumptions!B4/'Income Statement'!D15 | E7: =Assumptions!B4/'Income Statement'!E15 | F7: =Assumptions!B4/'Income Statement'!F15 | G7: =Assumptions!B4/'Income Statement'!G15 | H7: =Assumptions!B4/'Income Statement'!H15 | I7: =Assumptions!B4/'Income Statement'!I15
A8: P/B (spot ÷ BVPS) | B8: =Assumptions!B4/('Balance Sheet'!B15/Assumptions!B5) | C8: =Assumptions!B4/('Balance Sheet'!C15/Assumptions!B5) | D8: =Assumptions!B4/('Balance Sheet'!D15/Assumptions!B5) | E8: =Assumptions!B4/('Balance Sheet'!E15/Assumptions!B5) | F8: =Assumptions!B4/('Balance Sheet'!F15/Assumptions!B5) | G8: =Assumptions!B4/('Balance Sheet'!G15/Assumptions!B5) | H8: =Assumptions!B4/('Balance Sheet'!H15/Assumptions!B5) | I8: =Assumptions!B4/('Balance Sheet'!I15/Assumptions!B5)
A9: EV/EBITDA | B9: =((Assumptions!B4*Assumptions!B5)+Assumptions!B8)/'Income Statement'!B5 | C9: =((Assumptions!B4*Assumptions!B5)+Assumptions!B8)/'Income Statement'!C5 | D9: =((Assumptions!B4*Assumptions!B5)+Assumptions!B8)/'Income Statement'!D5 | E9: =((Assumptions!B4*Assumptions!B5)+Assumptions!B8)/'Income Statement'!E5 | F9: =((Assumptions!B4*Assumptions!B5)+Assumptions!B8)/'Income Statement'!F5 | G9: =((Assumptions!B4*Assumptions!B5)+Assumptions!B8)/'Income Statement'!G5 | H9: =((Assumptions!B4*Assumptions!B5)+Assumptions!B8)/'Income Statement'!H5 | I9: =((Assumptions!B4*Assumptions!B5)+Assumptions!B8)/'Income Statement'!I5
A10: FCF yield | B10: ='Cash Flow'!B9/(Assumptions!B4*Assumptions!B5) | C10: ='Cash Flow'!C9/(Assumptions!B4*Assumptions!B5) | D10: ='Cash Flow'!D9/(Assumptions!B4*Assumptions!B5) | E10: ='Cash Flow'!E9/(Assumptions!B4*Assumptions!B5) | F10: ='Cash Flow'!F9/(Assumptions!B4*Assumptions!B5) | G10: ='Cash Flow'!G9/(Assumptions!B4*Assumptions!B5) | H10: ='Cash Flow'!H9/(Assumptions!B4*Assumptions!B5) | I10: ='Cash Flow'!I9/(Assumptions!B4*Assumptions!B5)
A11: Dividend yield | B11: 0 | C11: 0 | D11: 0 | E11: 0 | F11: 0 | G11: 0 | H11: 0 | I11: 0
A12: EBITDA margin | B12: ='Income Statement'!B5/'Income Statement'!B4 | C12: ='Income Statement'!C5/'Income Statement'!C4 | D12: ='Income Statement'!D5/'Income Statement'!D4 | E12: ='Income Statement'!E5/'Income Statement'!E4 | F12: ='Income Statement'!F5/'Income Statement'!F4 | G12: ='Income Statement'!G5/'Income Statement'!G4 | H12: ='Income Statement'!H5/'Income Statement'!H4 | I12: ='Income Statement'!I5/'Income Statement'!I4
A13: Net margin (attrib.) | B13: ='Income Statement'!B14/'Income Statement'!B4 | C13: ='Income Statement'!C14/'Income Statement'!C4 | D13: ='Income Statement'!D14/'Income Statement'!D4 | E13: ='Income Statement'!E14/'Income Statement'!E4 | F13: ='Income Statement'!F14/'Income Statement'!F4 | G13: ='Income Statement'!G14/'Income Statement'!G4 | H13: ='Income Statement'!H14/'Income Statement'!H4 | I13: ='Income Statement'!I14/'Income Statement'!I4
A14: Effective tax rate | B14: =-'Income Statement'!B11/'Income Statement'!B10 | C14: =-'Income Statement'!C11/'Income Statement'!C10 | D14: =-'Income Statement'!D11/'Income Statement'!D10 | E14: =-'Income Statement'!E11/'Income Statement'!E10 | F14: =-'Income Statement'!F11/'Income Statement'!F10 | G14: =-'Income Statement'!G11/'Income Statement'!G10 | H14: =-'Income Statement'!H11/'Income Statement'!H10 | I14: =-'Income Statement'!I11/'Income Statement'!I10
A15: Net debt / EBITDA | B15: =Assumptions!B8/'Income Statement'!B5 | C15: =Assumptions!B8/'Income Statement'!C5 | D15: =Assumptions!B8/'Income Statement'!D5 | E15: =Assumptions!B8/'Income Statement'!E5 | F15: =Assumptions!B8/'Income Statement'!F5 | G15: =Assumptions!B8/'Income Statement'!G5 | H15: =Assumptions!B8/'Income Statement'!H5 | I15: =Assumptions!B8/'Income Statement'!I5
A16: ROAE (attrib.) | B16: n/a | C16: ='Income Statement'!C14/AVERAGE('Balance Sheet'!B15,'Balance Sheet'!C15) | D16: ='Income Statement'!D14/AVERAGE('Balance Sheet'!C15,'Balance Sheet'!D15) | E16: ='Income Statement'!E14/AVERAGE('Balance Sheet'!D15,'Balance Sheet'!E15) | F16: ='Income Statement'!F14/AVERAGE('Balance Sheet'!E15,'Balance Sheet'!F15) | G16: ='Income Statement'!G14/AVERAGE('Balance Sheet'!F15,'Balance Sheet'!G15) | H16: ='Income Statement'!H14/AVERAGE('Balance Sheet'!G15,'Balance Sheet'!H15) | I16: ='Income Statement'!I14/AVERAGE('Balance Sheet'!H15,'Balance Sheet'!I15)
A17: ROAA (group) | B17: n/a | C17: ='Income Statement'!C12/AVERAGE('Balance Sheet'!B9,'Balance Sheet'!C9) | D17: ='Income Statement'!D12/AVERAGE('Balance Sheet'!C9,'Balance Sheet'!D9) | E17: ='Income Statement'!E12/AVERAGE('Balance Sheet'!D9,'Balance Sheet'!E9) | F17: ='Income Statement'!F12/AVERAGE('Balance Sheet'!E9,'Balance Sheet'!F9) | G17: ='Income Statement'!G12/AVERAGE('Balance Sheet'!F9,'Balance Sheet'!G9) | H17: ='Income Statement'!H12/AVERAGE('Balance Sheet'!G9,'Balance Sheet'!H9) | I17: ='Income Statement'!I12/AVERAGE('Balance Sheet'!H9,'Balance Sheet'!I9)

Sheet Peer & Sector
A1: Appendix C — peer set, sector structure & risks
A2: Illustrative peer multiples (flagged). Conglomerate holdcos typically trade at 8–14× P/E and a discount to book; IHC is a large outlier.
A3: Peer / comparator | B3: P/E (x) | C3: P/B (x) | D3: NAV disc/(prem) | E3: Note
A4: Alpha Dhabi Holding (ADX, IHC 60%) | B4: 15 | C4: 1.5 | D4: ~0% | E4: listed sub; own tree
A5: Regional GCC investment holdco (avg) | B5: 12 | C5: 1.3 | D5: 10–25% disc | E5: illustrative
A6: Global diversified conglomerate (avg) | B6: 13 | C6: 1.4 | D6: 10–30% disc | E6: illustrative
A7: Global listed-holding / investor co (avg) | B7: 11 | C7: 1.1 | D7: 15–35% disc | E7: illustrative
A8: International Holding Company (IHC) | B8: 35 | C8: 5.5 | D8: large premium | E8: subject
A11: Sector & structure
A12: IHC sits atop the Royal Group / Sheikh Tahnoon bin Zayed ecosystem; ~1,300 subsidiaries across 8 verticals
A13: (real estate & construction, marine & dredging, energy, hospitality, food & agriculture, technology, financial services, services).
A14: Free float is modest and turnover is low, so the daily tape is very sticky (observed beta −0.24 is a float artifact,
A15: not a true low-risk signal). Reported profit is investment-led — associate income and fair-value gains routinely exceed
A16: operating EBITDA — so the SOTP, not an operating DCF, is the primary lens.
A18: Key risks
A19: 1. Concentration on the sponsor / key-man; related-party governance and disclosure.
A20: 2. Lumpy revaluation earnings — a large share of profit is non-cash fair-value gains that need not recur.
A21: 3. Valuation-premium compression — the market premium to NAV is the dominant price risk.
A22: 4. EM / frontier exposure (India Sammaan, Pakistan FWBL, African metals) and FX translation.
A23: 5. Thin float / low liquidity — wide effective bid-ask on size.
