Workbook

Sheet READ FIRST
A1: Testahil · Independent Valuation Study — Educational Analysis · Not investment advice
A2: Juhayna Food Industries (EGX: JUFO) — linked valuation model
A4: This workbook is the companion model to the Juhayna valuation study. It is an educational artifact, not a
A5: recommendation, research note, or price target. No buy / sell / hold / rating language appears anywhere.
A7: HOW IT IS WIRED
A8: • All blue cells on the Assumptions sheet are inputs. Every other sheet links back to Assumptions —
A9: there are no hard-coded duplicates. Change one input (e.g. WACC, terminal growth, a margin, or a
A10: target multiple) and the whole model reprices: statements → DCF → the four lenses → Summary.
A11: • Reporting currency is the Egyptian pound (EGP). All monetary figures are EGP millions unless noted.
A12: • Historical columns FY23–FY25 are the audited consolidated figures; FY26E–FY30E are forecast.
A14: THE FOUR LENSES (Summary sheet)
A15: 1. Discounted cash flow (FCFF) — the primary lens for a going-concern staples producer.
... A24: The preparer may hold, and may in the future take or dispose of, a position in the security discussed in this report.

Sheet Summary
A1: Valuation summary — Juhayna Food Industries (EGX: JUFO)
A2: Four-lens fair value vs spot. Base links live; bear/bull are scenario reads.
B3: Bear | C3: Base | D3: Bull | E3: Weight
A4: Discounted cash flow (FCFF) | B4: ='FCFF Valuation'!B7 -> 20.428974 | C4: =DCF!B19 -> 24.253293 | D4: ='FCFF Valuation'!D7 -> 34.02563 | E4: =Assumptions!$B$43 -> 0.4
A5: Relative multiples | B5: 24 | C5: ='Relative & Normalized'!B9 -> 28.663746 | D5: 33 | E5: =Assumptions!$B$44 -> 0.25
A6: Normalized earnings | B6: 24 | C6: ='Relative & Normalized'!B15 -> 28.64867 | D6: 33 | E6: =Assumptions!$B$45 -> 0.25
A7: Segment sum | B7: 18 | C7: =Segments!B14 -> 20.496295 | D7: 28 | E7: =Assumptions!$B$46 -> 0.1
A8: Weighted central | B8: =SUMPRODUCT(B4:B7,$E$4:$E$7) -> 21.97159 | C8: =SUMPRODUCT(C4:C7,$E$4:$E$7) -> 26.079051 | D8: =SUMPRODUCT(D4:D7,$E$4:$E$7) -> 32.910252
A10: Spot price (EGP) | C10: =Assumptions!$B$4 -> 29.99
A11: Upside / (downside) to base central | C11: =C8/C10-1 -> -0.13040844
A13: Read:
A14: Modestly rich to fair on cautious assumptions. The base central sits a little below spot; the market prices a fuller recovery
A15: in gross margin (post orange-concentrate normalization) and faster EGP disinflation. Swing factors: margins and the rate path.

Sheet Fundamental Valuation
A1: Fundamental valuation — overview
A2: The four lenses, their weights, and the weighted central fair value.
B3: Fair value | C3: Weight | D3: Contribution
A4: Discounted cash flow (FCFF) | B4: =DCF!B19 -> 24.253293 | C4: =Assumptions!$B$43 -> 0.4 | D4: =B4*C4 -> 9.7013173
A5: Relative multiples | B5: ='Relative & Normalized'!B9 -> 28.663746 | C5: =Assumptions!$B$44 -> 0.25 | D5: =B5*C5 -> 7.1659366
A6: Normalized earnings | B6: ='Relative & Normalized'!B15 -> 28.64867 | C6: =Assumptions!$B$45 -> 0.25 | D6: =B6*C6 -> 7.1621674
A7: Segment sum | B7: =Segments!B14 -> 20.496295 | C7: =Assumptions!$B$46 -> 0.1 | D7: =B7*C7 -> 2.0496295
A8: Weighted central fair value | B8: =SUMPRODUCT(B4:B7,C4:C7) -> 26.079051
A9: Spot (EGP) | B9: =Assumptions!$B$4 -> 29.99
A10: Upside / (downside) | B10: =B8/B9-1 -> -0.13040844

Sheet Assumptions
A1: Assumptions — the single input layer
A2: All blue cells are inputs. Every other sheet links here; there are no hard-coded duplicates.
A3: ANCHORS
A4: Spot price (EGP/share) | B4: 29.99
A5: Close date | B5: 01-Jul-2026
A6: Shares outstanding (mn) | B6: 1176.76
A7: Net debt, FY25 (EGP mn) | B7: 5960
A8: USD/EGP | B8: 49.5
A9: WACC | B9: 0.195
A10: Terminal growth (nominal EGP) | B10: 0.12
A11: Tax rate | B11: 0.225
A13: FORECAST DRIVERS (FY26E–FY30E)
E14: FY26E | F14: FY27E | G14: FY28E | H14: FY29E | I14: FY30E
A15: Revenue growth | E15: 0.22 | F15: 0.18 | G15: 0.15 | H15: 0.13 | I15: 0.12
A16: Gross margin | E16: 0.25 | F16: 0.255 | G16: 0.26 | H16: 0.265 | I16: 0.265
A17: SG&A (% of sales) | E17: 0.12 | F17: 0.118 | G17: 0.116 | H17: 0.114 | I17: 0.113
A18: Other operating income (% of sales) | E18: 0.01 | F18: 0.01 | G18: 0.01 | H18: 0.01 | I18: 0.01
A19: Other expenses (% of sales) | E19: 0.004 | F19: 0.004 | G19: 0.004 | H19: 0.004 | I19: 0.004
A20: D&A (% of sales) | E20: 0.019 | F20: 0.02 | G20: 0.021 | H20: 0.022 | I20: 0.023
A21: Capex (% of sales) | E21: 0.09 | F21: 0.078 | G21: 0.068 | H21: 0.058 | I21: 0.052
A22: Finance cost (EGP mn) | E22: 1350 | F22: 1300 | G22: 1200 | H22: 1100 | I22: 1000
A24: WORKING CAPITAL (% of revenue)
A25: Inventory | B25: 0.19
A26: Receivables | B26: 0.068
A27: Payables | B27: 0.078
A28: Minimum cash (EGP mn) | B28: 800
A30: RELATIVE & NORMALIZED
A31: Target EV/EBITDA (forward) | B31: 7
A32: Justified P/E (normalized) | B32: 12
A34: SEGMENT MARGINS & MULTIPLES (normalized)
B35: EBIT margin | C35: EV/EBIT x
A36: Dairy | B36: 0.13 | C36: 7
A37: Fermented | B37: 0.16 | C37: 8
A38: Juice | B38: 0.14 | C38: 7.5
A39: Concentrates & Agri | B39: 0.1 | C39: 5
A40: 3rd-party distribution | B40: 0.03 | C40: 4
A42: SYNTHESIS WEIGHTS
A43: DCF (FCFF) weight | B43: 0.4
A44: Relative weight | B44: 0.25
A45: Normalized-earnings weight | B45: 0.25
...

Sheet FCFF Valuation
A1: FCFF valuation — the primary lens
A2: Going-concern discounted cash flow. Base links live to the DCF sheet; bear/bull are scenario reads (Sensitivity sheet).
B3: Bear | C3: Base | D3: Bull
A4: Enterprise value (EGP mn) | B4: 30000 | C4: =DCF!B16 -> 34500.305 | D4: 46000
A5: less: net debt (EGP mn) | B5: =-Assumptions!$B$7 -> -5960 | C5: =-Assumptions!$B$7 -> -5960 | D5: =-Assumptions!$B$7 -> -5960
A6: Equity value (EGP mn) | B6: =B4+B5 -> 24040 | C6: =C4+C5 -> 28540.305 | D6: =D4+D5 -> 40040
A7: Fair value per share (EGP) | B7: =B6/Assumptions!$B$6 -> 20.428974 | C7: =C6/Assumptions!$B$6 -> 24.253293 | D7: =D6/Assumptions!$B$6 -> 34.02563
A8: Spot price (EGP) | C8: =Assumptions!$B$4 -> 29.99
A9: Upside / (downside) to base | C9: =C7/C8-1 -> -0.19128732
A11: Bear ≈ WACC 22% with margins holding near the FY25 reported trough; Bull ≈ WACC 18% with gross margin recovering toward the FY24 profile and capex intensity normalizing. Base is the live DCF.
A13: Read:
A14: On cautious nominal-EGP cash-flow assumptions the primary lens sits modestly below spot; the market is pricing a fuller
A15: margin recovery and a faster fall in Egyptian rates. The swing factors are gross-margin normalization and WACC (rate path).

Sheet Segments
A1: Segment revenue & sum-of-segments cross-check
A2: FY24–FY25 audited segment sales; normalized margins & multiples on Assumptions.
B3: FY24 rev | C3: FY25 rev | D3: Norm. EBIT % | E3: Norm. EBIT | F3: EV/EBIT x | G3: Segment EV
A4: Dairy | B4: 11644 | C4: 15310 | D4: =Assumptions!B36 -> 0.13 | E4: =C4*D4 -> 1990.3 | F4: =Assumptions!C36 -> 7 | G4: =E4*F4 -> 13932.1
A5: Fermented | B5: 4822 | C5: 6929 | D5: =Assumptions!B37 -> 0.16 | E5: =C5*D5 -> 1108.64 | F5: =Assumptions!C37 -> 8 | G5: =E5*F5 -> 8869.12
A6: Juice | B6: 4526 | C6: 6254 | D6: =Assumptions!B38 -> 0.14 | E6: =C6*D6 -> 875.56 | F6: =Assumptions!C38 -> 7.5 | G6: =E6*F6 -> 6566.7
A7: Concentrates & Agri | B7: 3152 | C7: 1401 | D7: =Assumptions!B39 -> 0.1 | E7: =C7*D7 -> 140.1 | F7: =Assumptions!C39 -> 5 | G7: =E7*F7 -> 700.5
A8: 3rd-party distribution | B8: 159 | C8: 90 | D8: =Assumptions!B40 -> 0.03 | E8: =C8*D8 -> 2.7 | F8: =Assumptions!C40 -> 4 | G8: =E8*F8 -> 10.8
A9: Total | B9: =SUM(B4:B8) -> 24303 | C9: =SUM(C4:C8) -> 29984 | G9: =SUM(G4:G8) -> 30079.22
A11: Aggregate segment EV | B11: =G9 -> 30079.22
A12: less: net debt | B12: =-Assumptions!$B$7 -> -5960
A13: Equity value | B13: =B11+B12 -> 24119.22
A14: Segment-sum fair value/share (EGP) | B14: =B13/Assumptions!$B$6 -> 20.496295
A16: Source: Juhayna FY25 & FY24 segment disclosure (earnings releases). Normalized EBIT margins and EV/EBIT multiples are analyst judgments held on Assumptions; concentrates/agri is marked cautiously given its cyclicality. This lens is a cross-check, not the primary read.

Sheet Relative & Normalized
A1: Relative multiples & normalized earnings
A2: Forward EBITDA × peer EV/EBITDA; mid-cycle net profit × justified P/E.
A3: RELATIVE — EV/EBITDA
A4: Forward EBITDA, FY26E (EGP mn) | B4: ='Income Statement'!E14 -> 5670.05
A5: Target EV/EBITDA | B5: =Assumptions!$B$31 -> 7
A6: Implied EV | B6: =B4*B5 -> 39690.35
A7: less: net debt | B7: =-Assumptions!$B$7 -> -5960
A8: Equity value | B8: =B6+B7 -> 33730.35
A9: Relative fair value/share (EGP) | B9: =B8/Assumptions!$B$6 -> 28.663746
A11: NORMALIZED — P/E
A12: Mid-cycle net profit, FY26E (EGP mn) | B12: ='Income Statement'!E21 -> 2809.384
A13: Justified P/E | B13: =Assumptions!$B$32 -> 12
A14: Equity value | B14: =B12*B13 -> 33712.608
A15: Normalized fair value/share (EGP) | B15: =B14/Assumptions!$B$6 -> 28.64867
A17: Peer set and multiple derivation are on the Peer & Sector sheet. Forward EBITDA and net profit link from the income statement, so a change in any margin driver reprices both lenses.

Sheet DCF
A1: Discounted cash flow — explicit 5-year FCFF
A2: NOPAT + D&A − capex − ΔWC, discounted at WACC. All inputs live on Assumptions.
E3: FY26E | F3: FY27E | G3: FY28E | H3: FY29E | I3: FY30E
A4: EBIT | E4: ='Income Statement'!E12 -> 4975.0116 | F4: ='Income Statement'!F12 -> 6172.6725 | G4: ='Income Statement'!G12 -> 7446.056 | H4: ='Income Statement'!H12 -> 8806.6987 | I4: ='Income Statement'!I12 -> 9926.3274
A5: NOPAT = EBIT×(1−tax) | E5: =E4*(1-Assumptions!$B$11) -> 3855.634 | F5: =F4*(1-Assumptions!$B$11) -> 4783.8212 | G5: =G4*(1-Assumptions!$B$11) -> 5770.6934 | H5: =H4*(1-Assumptions!$B$11) -> 6825.1915 | I5: =I4*(1-Assumptions!$B$11) -> 7692.9037
A6: + D&A | E6: ='Income Statement'!E13 -> 695.03839 | F6: ='Income Statement'!F13 -> 863.31084 | G6: ='Income Statement'!G13 -> 1042.4478 | H6: ='Income Statement'!H13 -> 1234.0597 | I6: ='Income Statement'!I13 -> 1444.9717
A7: − Capex | E7: =-'Income Statement'!E4*Assumptions!E21 -> -3292.2871 | F7: =-'Income Statement'!F4*Assumptions!F21 -> -3366.9123 | G7: =-'Income Statement'!G4*Assumptions!G21 -> -3375.5454 | H7: =-'Income Statement'!H4*Assumptions!H21 -> -3253.4301 | I7: =-'Income Statement'!I4*Assumptions!I21 -> -3266.8926
A8: − Δ net working capital | E8: =-(('Balance Sheet'!E8+'Balance Sheet'!E9-'Balance Sheet'!E17)-('Balance Sheet'!D8+'Balance Sheet'!D9-'Balance Sheet'!D17)) -> -1078.4742 | F8: =-(('Balance Sheet'!F8+'Balance Sheet'!F9-'Balance Sheet'!F17)-('Balance Sheet'!E8+'Balance Sheet'!E9-'Balance Sheet'!E17)) -> -1185.2234 | G8: =-(('Balance Sheet'!G8+'Balance Sheet'!G9-'Balance Sheet'!G17)-('Balance Sheet'!F8+'Balance Sheet'!F9-'Balance Sheet'!F17)) -> -1165.4696 | H8: =-(('Balance Sheet'!H8+'Balance Sheet'!H9-'Balance Sheet'!H17)-('Balance Sheet'!G8+'Balance Sheet'!G9-'Balance Sheet'!G17)) -> -1161.5847 | I8: =-(('Balance Sheet'!I8+'Balance Sheet'!I9-'Balance Sheet'!I17)-('Balance Sheet'!H8+'Balance Sheet'!H9-'Balance Sheet'!H17)) -> -1211.6222
A9: FCFF | E9: =E5+E6+E7+E8 -> 179.91106 | F9: =F5+F6+F7+F8 -> 1094.9964 | G9: =G5+G6+G7+G8 -> 2272.1262 | H9: =H5+H6+H7+H8 -> 3644.2363 | I9: =I5+I6+I7+I8 -> 4659.3606
A10: Discount factor | E10: =1/(1+Assumptions!$B$9)^1 -> 0.83682008 | F10: =1/(1+Assumptions!$B$9)^2 -> 0.70026785 | G10: =1/(1+Assumptions!$B$9)^3 -> 0.5859982 | H10: =1/(1+Assumptions!$B$9)^4 -> 0.49037507 | I10: =1/(1+Assumptions!$B$9)^5 -> 0.4103557
A11: PV of FCFF | E11: =E9*E10 -> 150.55319 | F11: =F9*F10 -> 766.79078 | G11: =G9*G10 -> 1331.4619 | H11: =H9*H10 -> 1787.0426 | I11: =I9*I10 -> 1911.9952
A13: Σ PV of explicit FCFF (FY26–30) | B13: =SUM(E11:I11) -> 5947.8437
A14: Terminal value (Gordon) | B14: =I9*(1+Assumptions!$B$10)/(Assumptions!$B$9-Assumptions!$B$10) -> 69579.785
A15: PV of terminal value | B15: =B14/(1+Assumptions!$B$9)^5 -> 28552.462
A16: Enterprise value | B16: =B13+B15 -> 34500.305
A17: less: net debt | B17: =-Assumptions!$B$7 -> -5960
A18: Equity value | B18: =B16+B17 -> 28540.305
A19: Fair value per share (EGP) | B19: =B18/Assumptions!$B$6 -> 24.253293
A20: % terminal of EV | B20: =B15/B16 -> 0.82760026
A22: Nominal-EGP FCFF. The high nominal WACC and nominal terminal growth reflect Egypt's interest-rate and inflation environment; the WACC−g spread, not either level alone, drives the terminal value. Capex intensity is front-loaded (expansion phase) and tapers, so free cash flow builds over the explicit window.

Sheet Income Statement
A1: Income statement (EGP mn, consolidated)
A2: FY23–FY25 audited (blue); FY26E–FY30E forecast (linked to Assumptions).
B3: FY23 | C3: FY24 | D3: FY25 | E3: FY26E | F3: FY27E | G3: FY28E | H3: FY29E | I3: FY30E
A4: Net revenue | B4: 15536.2 | C4: 24302.6 | D4: 29984.4 | E4: =D4*(1+Assumptions!E15) -> 36580.968 | F4: =E4*(1+Assumptions!F15) -> 43165.542 | G4: =F4*(1+Assumptions!G15) -> 49640.374 | H4: =G4*(1+Assumptions!H15) -> 56093.622 | I4: =H4*(1+Assumptions!I15) -> 62824.857
A5: Cost of sales | B5: -11926.1 | C5: -16912.9 | D5: -23103.6 | E5: =-E4*(1-Assumptions!E16) -> -27435.726 | F5: =-F4*(1-Assumptions!F16) -> -32158.329 | G5: =-G4*(1-Assumptions!G16) -> -36733.876 | H5: =-H4*(1-Assumptions!H16) -> -41228.812 | I5: =-I4*(1-Assumptions!I16) -> -46176.27
A6: Gross profit | B6: =B4+B5 -> 3610.1 | C6: =C4+C5 -> 7389.7 | D6: =D4+D5 -> 6880.8 | E6: =E4+E5 -> 9145.242 | F6: =F4+F5 -> 11007.213 | G6: =G4+G5 -> 12906.497 | H6: =H4+H5 -> 14864.81 | I6: =I4+I5 -> 16648.587
A7: Gross margin | B7: =B6/B4 -> 0.23236699 | C7: =C6/C4 -> 0.30407035 | D7: =D6/D4 -> 0.22947933 | E7: =E6/E4 -> 0.25 | F7: =F6/F4 -> 0.255 | G7: =G6/G4 -> 0.26 | H7: =H6/H4 -> 0.265 | I7: =I6/I4 -> 0.265
A8: Other operating income | B8: 160 | C8: 332.9 | D8: 325.6 | E8: =E4*Assumptions!E18 -> 365.80968 | F8: =F4*Assumptions!F18 -> 431.65542 | G8: =G4*Assumptions!G18 -> 496.40374 | H8: =H4*Assumptions!H18 -> 560.93622 | I8: =I4*Assumptions!I18 -> 628.24857
A9: SG&A expenses | B9: -1730.2 | C9: -2804.7 | D9: -3567.9 | E9: =-E4*Assumptions!E17 -> -4389.7162 | F9: =-F4*Assumptions!F17 -> -5093.534 | G9: =-G4*Assumptions!G17 -> -5758.2833 | H9: =-H4*Assumptions!H17 -> -6394.6729 | I9: =-I4*Assumptions!I17 -> -7099.2088
A10: Trade receivables (loss)/gain | B10: 6 | C10: -3.1 | D10: 7.2 | E10: 0 | F10: 0 | G10: 0 | H10: 0 | I10: 0
A11: Other expenses | B11: -243.9 | C11: -221.9 | D11: -72.5 | E11: =-E4*Assumptions!E19 -> -146.32387 | F11: =-F4*Assumptions!F19 -> -172.66217 | G11: =-G4*Assumptions!G19 -> -198.56149 | H11: =-H4*Assumptions!H19 -> -224.37449 | I11: =-I4*Assumptions!I19 -> -251.29943
A12: EBIT (operating profit) | B12: =B6+B8+B9+B10+B11 -> 1802 | C12: =C6+C8+C9+C10+C11 -> 4692.9 | D12: =D6+D8+D9+D10+D11 -> 3573.2 | E12: =E6+E8+E9+E10+E11 -> 4975.0116 | F12: =F6+F8+F9+F10+F11 -> 6172.6725 | G12: =G6+G8+G9+G10+G11 -> 7446.056 | H12: =H6+H8+H9+H10+H11 -> 8806.6987 | I12: =I6+I8+I9+I10+I11 -> 9926.3274
A13: D&A | B13: 330.6 | C13: 389.8 | D13: 522.1 | E13: =E4*Assumptions!E20 -> 695.03839 | F13: =F4*Assumptions!F20 -> 863.31084 | G13: =G4*Assumptions!G20 -> 1042.4478 | H13: =H4*Assumptions!H20 -> 1234.0597 | I13: =I4*Assumptions!I20 -> 1444.9717
A14: EBITDA | B14: =B12+B13 -> 2132.6 | C14: =C12+C13 -> 5082.7 | D14: =D12+D13 -> 4095.3 | E14: =E12+E13 -> 5670.05 | F14: =F12+F13 -> 7035.9834 | G14: =G12+G13 -> 8488.5039 | H14: =H12+H13 -> 10040.758 | I14: =I12+I13 -> 11371.299
A15: EBITDA margin | B15: =B14/B4 -> 0.13726651 | C15: =C14/C4 -> 0.20914223 | D15: =D14/D4 -> 0.13658102 | E15: =E14/E4 -> 0.155 | F15: =F14/F4 -> 0.163 | G15: =G14/G4 -> 0.171 | H15: =H14/H4 -> 0.179 | I15: =I14/I4 -> 0.181
A16: Net finance cost | B16: -320.9 | C16: -596.4 | D16: -1168.8 | E16: =-Assumptions!E22 -> -1350 | F16: =-Assumptions!F22 -> -1300 | G16: =-Assumptions!G22 -> -1200 | H16: =-Assumptions!H22 -> -1100 | I16: =-Assumptions!I22 -> -1000
A17: Share of equity investees | B17: -1.3 | C17: 2.4 | D17: 0 | E17: 0 | F17: 0 | G17: 0 | H17: 0 | I17: 0
A18: Loss on sale of investment (FV) | B18: -115.1 | C18: -522.1 | D18: 0 | E18: 0 | F18: 0 | G18: 0 | H18: 0 | I18: 0
A19: Profit before tax | B19: =B12+B16+B17+B18 -> 1364.7 | C19: =C12+C16+C17+C18 -> 3576.8 | D19: =D12+D16+D17+D18 -> 2404.4 | E19: =E12+E16+E17+E18 -> 3625.0116 | F19: =F12+F16+F17+F18 -> 4872.6725 | G19: =G12+G16+G17+G18 -> 6246.056 | H19: =H12+H16+H17+H18 -> 7706.6987 | I19: =I12+I16+I17+I18 -> 8926.3274
A20: Income tax | B20: -343.2 | C20: -841.5 | D20: -494.4 | E20: =-MAX(0,E19)*Assumptions!$B$11 -> -815.62762 | F20: =-MAX(0,F19)*Assumptions!$B$11 -> -1096.3513 | G20: =-MAX(0,G19)*Assumptions!$B$11 -> -1405.3626 | H20: =-MAX(0,H19)*Assumptions!$B$11 -> -1734.0072 | I20: =-MAX(0,I19)*Assumptions!$B$11 -> -2008.4237
A21: Net profit after tax | B21: =B19+B20 -> 1021.5 | C21: =C19+C20 -> 2735.3 | D21: =D19+D20 -> 1910 | E21: =E19+E20 -> 2809.384 | F21: =F19+F20 -> 3776.3212 | G21: =G19+G20 -> 4840.6934 | H21: =H19+H20 -> 5972.6915 | I21: =I19+I20 -> 6917.9037
A22: Net margin | B22: =B21/B4 -> 0.065749669 | C22: =C21/C4 -> 0.11255174 | D22: =D21/D4 -> 0.063699791 | E22: =E21/E4 -> 0.076799062 | F22: =F21/F4 -> 0.087484624 | G22: =G21/G4 -> 0.09751525 | H22: =H21/H4 -> 0.10647719 | I22: =I21/I4 -> 0.11011412
A23: EPS (EGP) | B23: =B21/Assumptions!$B$6 -> 0.86806146 | C23: =C21/Assumptions!$B$6 -> 2.3244332 | D23: =D21/Assumptions!$B$6 -> 1.6231007 | E23: =E21/Assumptions!$B$6 -> 2.3873891 | F23: =F21/Assumptions!$B$6 -> 3.2090836 | G23: =G21/Assumptions!$B$6 -> 4.1135775 | H23: =H21/Assumptions!$B$6 -> 5.0755392 | I23: =I21/Assumptions!$B$6 -> 5.878772
A25: Source: Juhayna audited consolidated income statements — FY25 & FY24 release (12 Mar 2026); FY23 comparative in FY24 release (25 Mar 2025). SG&A = selling & marketing + G&A. D&A reconstructed from cash-flow depreciation & amortization lines. FY24 gross margin was lifted by exceptional orange-concentrate prices; FY25 reflects their normalization plus the Feb-2025 merger.

Sheet Balance Sheet
A1: Balance sheet (EGP mn, consolidated)
A2: FY23–FY25 audited (blue); FY26E–FY30E forecast (working capital & PP&E linked to Assumptions).
B3: FY23 | C3: FY24 | D3: FY25 | E3: FY26E | F3: FY27E | G3: FY28E | H3: FY29E | I3: FY30E
A4: PP&E | B4: 3077.7 | C4: 3886.9 | D4: 5175.6 | E4: ='Cash Flow'!E12 -> 7772.8487 | F4: ='Cash Flow'!F12 -> 10276.45 | G4: ='Cash Flow'!G12 -> 12609.548 | H4: ='Cash Flow'!H12 -> 14628.918 | I4: ='Cash Flow'!I12 -> 16450.839
A5: Projects under construction | B5: 299.3 | C5: 1511.9 | D5: 2722.2 | E5: =D5 -> 2722.2 | F5: =D5 -> 2722.2 | G5: =D5 -> 2722.2 | H5: =D5 -> 2722.2 | I5: =D5 -> 2722.2
A6: Biological assets | B6: 334.6 | C6: 489.2 | D6: 641.2 | E6: =D6 -> 641.2 | F6: =D6 -> 641.2 | G6: =D6 -> 641.2 | H6: =D6 -> 641.2 | I6: =D6 -> 641.2
A7: Other non-current assets | B7: 152.4 | C7: 208.9 | D7: 401.4 | E7: =D7 -> 401.4 | F7: =D7 -> 401.4 | G7: =D7 -> 401.4 | H7: =D7 -> 401.4 | I7: =D7 -> 401.4
A8: Inventory | B8: 2783.5 | C8: 4177.1 | D8: 5815.7 | E8: ='Income Statement'!E4*Assumptions!$B$25 -> 6950.3839 | F8: ='Income Statement'!F4*Assumptions!$B$25 -> 8201.453 | G8: ='Income Statement'!G4*Assumptions!$B$25 -> 9431.671 | H8: ='Income Statement'!H4*Assumptions!$B$25 -> 10657.788 | I8: ='Income Statement'!I4*Assumptions!$B$25 -> 11936.723
A9: Trade & other receivables | B9: 837.7 | C9: 1505.3 | D9: 2033.9 | E9: ='Income Statement'!E4*Assumptions!$B$26 -> 2487.5058 | F9: ='Income Statement'!F4*Assumptions!$B$26 -> 2935.2569 | G9: ='Income Statement'!G4*Assumptions!$B$26 -> 3375.5454 | H9: ='Income Statement'!H4*Assumptions!$B$26 -> 3814.3663 | I9: ='Income Statement'!I4*Assumptions!$B$26 -> 4272.0903
A10: Other current assets | B10: 29.5 | C10: 43.5 | D10: 604.5 | E10: =D10 -> 604.5 | F10: =D10 -> 604.5 | G10: =D10 -> 604.5 | H10: =D10 -> 604.5 | I10: =D10 -> 604.5
A11: Cash & equivalents | B11: 1093.5 | C11: 1811.2 | D11: 1091.8 | E11: =MAX(Assumptions!$B$28,'Cash Flow'!E19) -> 800 | F11: =MAX(Assumptions!$B$28,'Cash Flow'!F19) -> 800 | G11: =MAX(Assumptions!$B$28,'Cash Flow'!G19) -> 800 | H11: =MAX(Assumptions!$B$28,'Cash Flow'!H19) -> 920.302 | I11: =MAX(Assumptions!$B$28,'Cash Flow'!I19) -> 3421.0819
A12: Total assets | B12: =SUM(B4:B11) -> 8608.2 | C12: =SUM(C4:C11) -> 13634 | D12: =SUM(D4:D11) -> 18486.3 | E12: =SUM(E4:E11) -> 22380.038 | F12: =SUM(F4:F11) -> 26582.46 | G12: =SUM(G4:G11) -> 30586.064 | H12: =SUM(H4:H11) -> 34390.675 | I12: =SUM(I4:I11) -> 40450.034
A13: Total equity | B13: 4249.8 | C13: 6339.3 | D13: 8032.5 | E13: =D13+'Income Statement'!E21-'Cash Flow'!E15 -> 10280.007 | F13: =E13+'Income Statement'!F21-'Cash Flow'!F15 -> 13301.064 | G13: =F13+'Income Statement'!G21-'Cash Flow'!G15 -> 17173.619 | H13: =G13+'Income Statement'!H21-'Cash Flow'!H15 -> 21951.772 | I13: =H13+'Income Statement'!I21-'Cash Flow'!I15 -> 27486.095
A14: Interest-bearing debt | B14: 1301 | C14: 3759.1 | D14: 7051.5 | E14: ='Cash Flow'!E18 -> 8234.6157 | F14: ='Cash Flow'!F18 -> 8902.3836 | G14: ='Cash Flow'!G18 -> 8528.396 | H14: ='Cash Flow'!H18 -> 7051.5 | I14: ='Cash Flow'!I18 -> 7051.5
A15: Lease liabilities | B15: 111.8 | C15: 151.5 | D15: 209.4 | E15: =D15 -> 209.4 | F15: =D15 -> 209.4 | G15: =D15 -> 209.4 | H15: =D15 -> 209.4 | I15: =D15 -> 209.4
A16: Deferred tax | B16: 321.8 | C16: 387.4 | D16: 509.3 | E16: =D16 -> 509.3 | F16: =D16 -> 509.3 | G16: =D16 -> 509.3 | H16: =D16 -> 509.3 | I16: =D16 -> 509.3
A17: Trade & other payables | B17: 2261.1 | C17: 2006.7 | D17: 2343.5 | E17: ='Income Statement'!E4*Assumptions!$B$27 -> 2853.3155 | F17: ='Income Statement'!F4*Assumptions!$B$27 -> 3366.9123 | G17: ='Income Statement'!G4*Assumptions!$B$27 -> 3871.9491 | H17: ='Income Statement'!H4*Assumptions!$B$27 -> 4375.3025 | I17: ='Income Statement'!I4*Assumptions!$B$27 -> 4900.3388
A18: Provisions, tax & other liab. | B18: 403.9 | C18: 973.1 | D18: 293.4 | E18: =D18 -> 293.4 | F18: =D18 -> 293.4 | G18: =D18 -> 293.4 | H18: =D18 -> 293.4 | I18: =D18 -> 293.4
A19: Total equity & liabilities | B19: =B13+B14+B15+B16+B17+B18 -> 8649.4 | C19: =C13+C14+C15+C16+C17+C18 -> 13617.1 | D19: =D13+D14+D15+D16+D17+D18 -> 18439.6 | E19: =E13+E14+E15+E16+E17+E18 -> 22380.038 | F19: =F13+F14+F15+F16+F17+F18 -> 26582.46 | G19: =G13+G14+G15+G16+G17+G18 -> 30586.064 | H19: =H13+H14+H15+H16+H17+H18 -> 34390.675 | I19: =I13+I14+I15+I16+I17+I18 -> 40450.034
A20: Check: assets − E&L | B20: =B12-B19 -> -41.2 | C20: =C12-C19 -> 16.9 | D20: =D12-D19 -> 46.7 | E20: =E12-E19 -> 0 | F20: =F12-F19 -> 0 | G20: =G12-G19 -> 0 | H20: =H12-H19 -> 0 | I20: =I12-I19 -> 0
A22: Source: Juhayna audited consolidated balance sheets, FY25 & FY24 releases. Forecast: inventory/receivables/payables driven off revenue via Assumptions; PP&E rolls forward with capex less D&A; cash and debt come from the cash-flow sheet; a residual plug ("Other current assets" held flat) absorbs minor non-modelled items. FY23 "other" lines grouped for clarity.

Sheet Cash Flow
A1: Cash flow (EGP mn, consolidated)
A2: FY23–FY25 audited (blue); FY26E–FY30E derived from the statements and Assumptions.
B3: FY23 | C3: FY24 | D3: FY25 | E3: FY26E | F3: FY27E | G3: FY28E | H3: FY29E | I3: FY30E
A4: Net profit after tax | B4: ='Income Statement'!B21 -> 1021.5 | C4: ='Income Statement'!C21 -> 2735.3 | D4: ='Income Statement'!D21 -> 1910 | E4: ='Income Statement'!E21 -> 2809.384 | F4: ='Income Statement'!F21 -> 3776.3212 | G4: ='Income Statement'!G21 -> 4840.6934 | H4: ='Income Statement'!H21 -> 5972.6915 | I4: ='Income Statement'!I21 -> 6917.9037
A5: + D&A | B5: ='Income Statement'!B13 -> 330.6 | C5: ='Income Statement'!C13 -> 389.8 | D5: ='Income Statement'!D13 -> 522.1 | E5: ='Income Statement'!E13 -> 695.03839 | F5: ='Income Statement'!F13 -> 863.31084 | G5: ='Income Statement'!G13 -> 1042.4478 | H5: ='Income Statement'!H13 -> 1234.0597 | I5: ='Income Statement'!I13 -> 1444.9717
A6: + Net finance cost | B6: =-'Income Statement'!B16 -> 320.9 | C6: =-'Income Statement'!C16 -> 596.4 | D6: =-'Income Statement'!D16 -> 1168.8 | E6: =-'Income Statement'!E16 -> 1350 | F6: =-'Income Statement'!F16 -> 1300 | G6: =-'Income Statement'!G16 -> 1200 | H6: =-'Income Statement'!H16 -> 1100 | I6: =-'Income Statement'!I16 -> 1000
A7: − Δ Inventory | B7: 0 | C7: -1393.6 | D7: -1638.6 | E7: =-('Balance Sheet'!E8-'Balance Sheet'!D8) -> -1134.6839 | F7: =-('Balance Sheet'!F8-'Balance Sheet'!E8) -> -1251.0691 | G7: =-('Balance Sheet'!G8-'Balance Sheet'!F8) -> -1230.218 | H7: =-('Balance Sheet'!H8-'Balance Sheet'!G8) -> -1226.1172 | I7: =-('Balance Sheet'!I8-'Balance Sheet'!H8) -> -1278.9346
A8: − Δ Receivables | B8: 0 | C8: -667.6 | D8: -528.6 | E8: =-('Balance Sheet'!E9-'Balance Sheet'!D9) -> -453.60582 | F8: =-('Balance Sheet'!F9-'Balance Sheet'!E9) -> -447.75105 | G8: =-('Balance Sheet'!G9-'Balance Sheet'!F9) -> -440.28853 | H8: =-('Balance Sheet'!H9-'Balance Sheet'!G9) -> -438.8209 | I8: =-('Balance Sheet'!I9-'Balance Sheet'!H9) -> -457.72396
A9: + Δ Payables | B9: 0 | C9: -254.4 | D9: 336.8 | E9: =('Balance Sheet'!E17-'Balance Sheet'!D17) -> 509.8155 | F9: =('Balance Sheet'!F17-'Balance Sheet'!E17) -> 513.59679 | G9: =('Balance Sheet'!G17-'Balance Sheet'!F17) -> 505.03684 | H9: =('Balance Sheet'!H17-'Balance Sheet'!G17) -> 503.35339 | I9: =('Balance Sheet'!I17-'Balance Sheet'!H17) -> 525.0363
A10: Operating cash flow | B10: =B4+B5+B6+B7+B8+B9 -> 1673 | C10: =C4+C5+C6+C7+C8+C9 -> 1405.9 | D10: =D4+D5+D6+D7+D8+D9 -> 1770.5 | E10: =E4+E5+E6+E7+E8+E9 -> 3775.9482 | F10: =F4+F5+F6+F7+F8+F9 -> 4754.4087 | G10: =G4+G5+G6+G7+G8+G9 -> 5917.6716 | H10: =H4+H5+H6+H7+H8+H9 -> 7145.1664 | I10: =I4+I5+I6+I7+I8+I9 -> 8151.2532
A11: − Capex | B11: -561.5 | C11: -2356.9 | D11: -2979.7 | E11: =-'Income Statement'!E4*Assumptions!E21 -> -3292.2871 | F11: =-'Income Statement'!F4*Assumptions!F21 -> -3366.9123 | G11: =-'Income Statement'!G4*Assumptions!G21 -> -3375.5454 | H11: =-'Income Statement'!H4*Assumptions!H21 -> -3253.4301 | I11: =-'Income Statement'!I4*Assumptions!I21 -> -3266.8926
A12: PP&E roll (memo) | B12: 3077.7 | C12: 3886.9 | D12: 5175.6 | E12: ='Cash Flow'!D12-E11-'Income Statement'!E13 -> 7772.8487 | F12: ='Cash Flow'!E12-F11-'Income Statement'!F13 -> 10276.45 | G12: ='Cash Flow'!F12-G11-'Income Statement'!G13 -> 12609.548 | H12: ='Cash Flow'!G12-H11-'Income Statement'!H13 -> 14628.918 | I12: ='Cash Flow'!H12-I11-'Income Statement'!I13 -> 16450.839
A13: − Net finance paid | B13: =-'Income Statement'!B16 -> 320.9 | C13: =-'Income Statement'!C16 -> 596.4 | D13: =-'Income Statement'!D16 -> 1168.8 | E13: =-'Income Statement'!E16 -> 1350 | F13: =-'Income Statement'!F16 -> 1300 | G13: =-'Income Statement'!G16 -> 1200 | H13: =-'Income Statement'!H16 -> 1100 | I13: =-'Income Statement'!I16 -> 1000
A14: Free cash flow to firm (memo) | B14: =B10+B11 -> 1111.5 | C14: =C10+C11 -> -951 | D14: =D10+D11 -> -1209.2 | E14: =E10+E11 -> 483.66106 | F14: =F10+F11 -> 1387.4964 | G14: =G10+G11 -> 2542.1262 | H14: =H10+H11 -> 3891.7363 | I14: =I10+I11 -> 4884.3606
A15: Dividends paid | B15: 141.2 | C15: 188.3 | D15: 282.4 | E15: ='Income Statement'!E21*0.2 -> 561.87681 | F15: ='Income Statement'!F21*0.2 -> 755.26424 | G15: ='Income Statement'!G21*0.2 -> 968.13869 | H15: ='Income Statement'!H21*0.2 -> 1194.5383 | I15: ='Income Statement'!I21*0.2 -> 1383.5807
A16: Net change in cash (pre-financing plug) | E16: =E10+E11-E13-E15 -> -1428.2157 | F16: =F10+F11-F13-F15 -> -667.76784 | G16: =G10+G11-G13-G15 -> 373.98754 | H16: =H10+H11-H13-H15 -> 1597.198 | I16: =I10+I11-I13-I15 -> 2500.7799
A17: Cash & equivalents, year-end | B17: 1093.5 | C17: 1811.2 | D17: 1091.8 | E17: ='Balance Sheet'!E11 -> 800 | F17: ='Balance Sheet'!F11 -> 800 | G17: ='Balance Sheet'!G11 -> 800 | H17: ='Balance Sheet'!H11 -> 920.302 | I17: ='Balance Sheet'!I11 -> 3421.0819
A18: Interest-bearing debt, year-end | B18: 1301 | C18: 3759.1 | D18: 7051.5 | E18: =$D$18+MAX(0,Assumptions!$B$28-'Cash Flow'!E19) -> 8234.6157 | F18: =$D$18+MAX(0,Assumptions!$B$28-'Cash Flow'!F19) -> 8902.3836 | G18: =$D$18+MAX(0,Assumptions!$B$28-'Cash Flow'!G19) -> 8528.396 | H18: =$D$18+MAX(0,Assumptions!$B$28-'Cash Flow'!H19) -> 7051.5 | I18: =$D$18+MAX(0,Assumptions!$B$28-'Cash Flow'!I19) -> 7051.5
A19: memo: cash if debt held flat | E19: =('Balance Sheet'!E13+$D$18+'Balance Sheet'!E15+'Balance Sheet'!E16+'Balance Sheet'!E17+'Balance Sheet'!E18)-('Balance Sheet'!E4+'Balance Sheet'!E5+'Balance Sheet'!E6+'Balance Sheet'!E7+'Balance Sheet'!E8+'Balance Sheet'!E9+'Balance Sheet'!E10) -> -383.11575 | F19: =('Balance Sheet'!F13+$D$18+'Balance Sheet'!F15+'Balance Sheet'!F16+'Balance Sheet'!F17+'Balance Sheet'!F18)-('Balance Sheet'!F4+'Balance Sheet'!F5+'Balance Sheet'!F6+'Balance Sheet'!F7+'Balance Sheet'!F8+'Balance Sheet'!F9+'Balance Sheet'!F10) -> -1050.8836 | G19: =('Balance Sheet'!G13+$D$18+'Balance Sheet'!G15+'Balance Sheet'!G16+'Balance Sheet'!G17+'Balance Sheet'!G18)-('Balance Sheet'!G4+'Balance Sheet'!G5+'Balance Sheet'!G6+'Balance Sheet'!G7+'Balance Sheet'!G8+'Balance Sheet'!G9+'Balance Sheet'!G10) -> -676.89604 | H19: =('Balance Sheet'!H13+$D$18+'Balance Sheet'!H15+'Balance Sheet'!H16+'Balance Sheet'!H17+'Balance Sheet'!H18)-('Balance Sheet'!H4+'Balance Sheet'!H5+'Balance Sheet'!H6+'Balance Sheet'!H7+'Balance Sheet'!H8+'Balance Sheet'!H9+'Balance Sheet'!H10) -> 920.302 | I19: =('Balance Sheet'!I13+$D$18+'Balance Sheet'!I15+'Balance Sheet'!I16+'Balance Sheet'!I17+'Balance Sheet'!I18)-('Balance Sheet'!I4+'Balance Sheet'!I5+'Balance Sheet'!I6+'Balance Sheet'!I7+'Balance Sheet'!I8+'Balance Sheet'!I9+'Balance Sheet'!I10) -> 3421.0819
A20: Source: Juhayna audited consolidated cash-flow statements, FY25 & FY24 releases. Forecast: indirect method from the modelled statements; working-capital deltas come from the balance sheet; capex and dividends per Assumptions (20% payout); the debt line absorbs the residual financing need with a 50% sweep of surplus. FCFF (gold) feeds the DCF.

Sheet Summary Financials
A1: Summary financials (EGP mn)
A2: Every cell links to the statement sheets — no re-entry.
B3: FY23 | C3: FY24 | D3: FY25 | E3: FY26E | F3: FY27E | G3: FY28E | H3: FY29E | I3: FY30E
A4: Net revenue | B4: ='Income Statement'!B4 -> 15536.2 | C4: ='Income Statement'!C4 -> 24302.6 | D4: ='Income Statement'!D4 -> 29984.4 | E4: ='Income Statement'!E4 -> 36580.968 | F4: ='Income Statement'!F4 -> 43165.542 | G4: ='Income Statement'!G4 -> 49640.374 | H4: ='Income Statement'!H4 -> 56093.622 | I4: ='Income Statement'!I4 -> 62824.857
A5: Gross profit | B5: ='Income Statement'!B6 -> 3610.1 | C5: ='Income Statement'!C6 -> 7389.7 | D5: ='Income Statement'!D6 -> 6880.8 | E5: ='Income Statement'!E6 -> 9145.242 | F5: ='Income Statement'!F6 -> 11007.213 | G5: ='Income Statement'!G6 -> 12906.497 | H5: ='Income Statement'!H6 -> 14864.81 | I5: ='Income Statement'!I6 -> 16648.587
A6: EBIT | B6: ='Income Statement'!B12 -> 1802 | C6: ='Income Statement'!C12 -> 4692.9 | D6: ='Income Statement'!D12 -> 3573.2 | E6: ='Income Statement'!E12 -> 4975.0116 | F6: ='Income Statement'!F12 -> 6172.6725 | G6: ='Income Statement'!G12 -> 7446.056 | H6: ='Income Statement'!H12 -> 8806.6987 | I6: ='Income Statement'!I12 -> 9926.3274
A7: EBITDA | B7: ='Income Statement'!B14 -> 2132.6 | C7: ='Income Statement'!C14 -> 5082.7 | D7: ='Income Statement'!D14 -> 4095.3 | E7: ='Income Statement'!E14 -> 5670.05 | F7: ='Income Statement'!F14 -> 7035.9834 | G7: ='Income Statement'!G14 -> 8488.5039 | H7: ='Income Statement'!H14 -> 10040.758 | I7: ='Income Statement'!I14 -> 11371.299
A8: Net profit | B8: ='Income Statement'!B21 -> 1021.5 | C8: ='Income Statement'!C21 -> 2735.3 | D8: ='Income Statement'!D21 -> 1910 | E8: ='Income Statement'!E21 -> 2809.384 | F8: ='Income Statement'!F21 -> 3776.3212 | G8: ='Income Statement'!G21 -> 4840.6934 | H8: ='Income Statement'!H21 -> 5972.6915 | I8: ='Income Statement'!I21 -> 6917.9037
A9: Operating cash flow | B9: ='Cash Flow'!B10 -> 1673 | C9: ='Cash Flow'!C10 -> 1405.9 | D9: ='Cash Flow'!D10 -> 1770.5 | E9: ='Cash Flow'!E10 -> 3775.9482 | F9: ='Cash Flow'!F10 -> 4754.4087 | G9: ='Cash Flow'!G10 -> 5917.6716 | H9: ='Cash Flow'!H10 -> 7145.1664 | I9: ='Cash Flow'!I10 -> 8151.2532
A10: Capex | B10: ='Cash Flow'!B11 -> -561.5 | C10: ='Cash Flow'!C11 -> -2356.9 | D10: ='Cash Flow'!D11 -> -2979.7 | E10: ='Cash Flow'!E11 -> -3292.2871 | F10: ='Cash Flow'!F11 -> -3366.9123 | G10: ='Cash Flow'!G11 -> -3375.5454 | H10: ='Cash Flow'!H11 -> -3253.4301 | I10: ='Cash Flow'!I11 -> -3266.8926
A11: Free cash flow to firm | B11: ='Cash Flow'!B14 -> 1111.5 | C11: ='Cash Flow'!C14 -> -951 | D11: ='Cash Flow'!D14 -> -1209.2 | E11: ='Cash Flow'!E14 -> 483.66106 | F11: ='Cash Flow'!F14 -> 1387.4964 | G11: ='Cash Flow'!G14 -> 2542.1262 | H11: ='Cash Flow'!H14 -> 3891.7363 | I11: ='Cash Flow'!I14 -> 4884.3606
A12: Total assets | B12: ='Balance Sheet'!B12 -> 8608.2 | C12: ='Balance Sheet'!C12 -> 13634 | D12: ='Balance Sheet'!D12 -> 18486.3 | E12: ='Balance Sheet'!E12 -> 22380.038 | F12: ='Balance Sheet'!F12 -> 26582.46 | G12: ='Balance Sheet'!G12 -> 30586.064 | H12: ='Balance Sheet'!H12 -> 34390.675 | I12: ='Balance Sheet'!I12 -> 40450.034
A13: Total equity | B13: ='Balance Sheet'!B13 -> 4249.8 | C13: ='Balance Sheet'!C13 -> 6339.3 | D13: ='Balance Sheet'!D13 -> 8032.5 | E13: ='Balance Sheet'!E13 -> 10280.007 | F13: ='Balance Sheet'!F13 -> 13301.064 | G13: ='Balance Sheet'!G13 -> 17173.619 | H13: ='Balance Sheet'!H13 -> 21951.772 | I13: ='Balance Sheet'!I13 -> 27486.095
A14: Interest-bearing debt | B14: ='Balance Sheet'!B14 -> 1301 | C14: ='Balance Sheet'!C14 -> 3759.1 | D14: ='Balance Sheet'!D14 -> 7051.5 | E14: ='Balance Sheet'!E14 -> 8234.6157 | F14: ='Balance Sheet'!F14 -> 8902.3836 | G14: ='Balance Sheet'!G14 -> 8528.396 | H14: ='Balance Sheet'!H14 -> 7051.5 | I14: ='Balance Sheet'!I14 -> 7051.5

Sheet Monte Carlo
A1: Monte Carlo — engine outputs
A2: 50,000 paths · YZ-HAR width · Student-t(5) shape · secular drift ON · 16 factors · seed 42.
A3: Percentile map (EGP/share)
B4: p5 | C4: p25 | D4: p50 | E4: p75 | F4: p95
A5: T+20 sessions | B5: 26.041924 | C5: 28.922994 | D5: 30.668942 | E5: 32.537523 | F5: 36.154829
A6: T+60 sessions | B6: 24.168181 | C6: 28.964407 | D6: 32.072383 | E6: 35.461175 | F6: 42.629772
A8: Inputs (from Assumptions): σ | D8: =Assumptions!$B$49 -> 0.37350107
A9: net 3-month secular drift | D9: =Assumptions!$B$50 -> 0.086751258
A10: spot | D10: =Assumptions!$B$4 -> 29.99
A12: Level-touch ladder
B13: T+20 | C13: T+60
A14: 40 | B14: 0.017 | C14: 0.136
A15: 38 | B15: 0.035 | C15: 0.216
A16: 36 | B16: 0.08 | C16: 0.339
A17: 34 | B17: 0.197 | C17: 0.522
A18: 32 | B18: 0.475 | C18: 0.75
A19: 30 | B19: 0.906 | C19: 0.961
A20: 28 | B20: 0.295 | C20: 0.457
A21: 26 | B21: 0.085 | C21: 0.215
A22: 24 | B22: 0.025 | C22: 0.098
A24: Percentiles and touch probabilities are engine outputs (computed externally, seed 42). σ and drift shown link to Assumptions. The paths diffuse from spot; the §1 fundamental value gap is deliberately kept out of the drift (lens independence).

Sheet Sensitivity
A1: DCF sensitivity — fair value per share (EGP)
A2: Base WACC & terminal growth from Assumptions; grid recomputes the equity value per share.
A3: Terminal growth →
A4: WACC ↓ | B4: g=10% | C4: g=11% | D4: g=12% | E4: g=13% | F4: g=14%
A5: 0.175 | B5: =((DCF!E9/(1+$A5)^1+DCF!F9/(1+$A5)^2+DCF!G9/(1+$A5)^3+DCF!H9/(1+$A5)^4+DCF!I9/(1+$A5)^5)+(DCF!I9*(1+0.1)/($A5-0.1)/(1+$A5)^5)-Assumptions!$B$7)/Assumptions!$B$6 -> 26.250805 | C5: =((DCF!E9/(1+$A5)^1+DCF!F9/(1+$A5)^2+DCF!G9/(1+$A5)^3+DCF!H9/(1+$A5)^4+DCF!I9/(1+$A5)^5)+(DCF!I9*(1+0.11)/($A5-0.11)/(1+$A5)^5)-Assumptions!$B$7)/Assumptions!$B$6 -> 30.511813 | D5: =((DCF!E9/(1+$A5)^1+DCF!F9/(1+$A5)^2+DCF!G9/(1+$A5)^3+DCF!H9/(1+$A5)^4+DCF!I9/(1+$A5)^5)+(DCF!I9*(1+0.12)/($A5-0.12)/(1+$A5)^5)-Assumptions!$B$7)/Assumptions!$B$6 -> 36.322278 | E5: =((DCF!E9/(1+$A5)^1+DCF!F9/(1+$A5)^2+DCF!G9/(1+$A5)^3+DCF!H9/(1+$A5)^4+DCF!I9/(1+$A5)^5)+(DCF!I9*(1+0.13)/($A5-0.13)/(1+$A5)^5)-Assumptions!$B$7)/Assumptions!$B$6 -> 44.715172 | F5: =((DCF!E9/(1+$A5)^1+DCF!F9/(1+$A5)^2+DCF!G9/(1+$A5)^3+DCF!H9/(1+$A5)^4+DCF!I9/(1+$A5)^5)+(DCF!I9*(1+0.14)/($A5-0.14)/(1+$A5)^5)-Assumptions!$B$7)/Assumptions!$B$6 -> 57.904006
A6: 0.19 | B6: =((DCF!E9/(1+$A6)^1+DCF!F9/(1+$A6)^2+DCF!G9/(1+$A6)^3+DCF!H9/(1+$A6)^4+DCF!I9/(1+$A6)^5)+(DCF!I9*(1+0.1)/($A6-0.1)/(1+$A6)^5)-Assumptions!$B$7)/Assumptions!$B$6 -> 20.349462 | C6: =((DCF!E9/(1+$A6)^1+DCF!F9/(1+$A6)^2+DCF!G9/(1+$A6)^3+DCF!H9/(1+$A6)^4+DCF!I9/(1+$A6)^5)+(DCF!I9*(1+0.11)/($A6-0.11)/(1+$A6)^5)-Assumptions!$B$7)/Assumptions!$B$6 -> 23.091782 | D6: =((DCF!E9/(1+$A6)^1+DCF!F9/(1+$A6)^2+DCF!G9/(1+$A6)^3+DCF!H9/(1+$A6)^4+DCF!I9/(1+$A6)^5)+(DCF!I9*(1+0.12)/($A6-0.12)/(1+$A6)^5)-Assumptions!$B$7)/Assumptions!$B$6 -> 26.617622 | E6: =((DCF!E9/(1+$A6)^1+DCF!F9/(1+$A6)^2+DCF!G9/(1+$A6)^3+DCF!H9/(1+$A6)^4+DCF!I9/(1+$A6)^5)+(DCF!I9*(1+0.13)/($A6-0.13)/(1+$A6)^5)-Assumptions!$B$7)/Assumptions!$B$6 -> 31.318741 | F6: =((DCF!E9/(1+$A6)^1+DCF!F9/(1+$A6)^2+DCF!G9/(1+$A6)^3+DCF!H9/(1+$A6)^4+DCF!I9/(1+$A6)^5)+(DCF!I9*(1+0.14)/($A6-0.14)/(1+$A6)^5)-Assumptions!$B$7)/Assumptions!$B$6 -> 37.900309
A7: 0.205 | B7: =((DCF!E9/(1+$A7)^1+DCF!F9/(1+$A7)^2+DCF!G9/(1+$A7)^3+DCF!H9/(1+$A7)^4+DCF!I9/(1+$A7)^5)+(DCF!I9*(1+0.1)/($A7-0.1)/(1+$A7)^5)-Assumptions!$B$7)/Assumptions!$B$6 -> 16.160813 | C7: =((DCF!E9/(1+$A7)^1+DCF!F9/(1+$A7)^2+DCF!G9/(1+$A7)^3+DCF!H9/(1+$A7)^4+DCF!I9/(1+$A7)^5)+(DCF!I9*(1+0.11)/($A7-0.11)/(1+$A7)^5)-Assumptions!$B$7)/Assumptions!$B$6 -> 18.043497 | D7: =((DCF!E9/(1+$A7)^1+DCF!F9/(1+$A7)^2+DCF!G9/(1+$A7)^3+DCF!H9/(1+$A7)^4+DCF!I9/(1+$A7)^5)+(DCF!I9*(1+0.12)/($A7-0.12)/(1+$A7)^5)-Assumptions!$B$7)/Assumptions!$B$6 -> 20.369165 | E7: =((DCF!E9/(1+$A7)^1+DCF!F9/(1+$A7)^2+DCF!G9/(1+$A7)^3+DCF!H9/(1+$A7)^4+DCF!I9/(1+$A7)^5)+(DCF!I9*(1+0.13)/($A7-0.13)/(1+$A7)^5)-Assumptions!$B$7)/Assumptions!$B$6 -> 23.315011 | F7: =((DCF!E9/(1+$A7)^1+DCF!F9/(1+$A7)^2+DCF!G9/(1+$A7)^3+DCF!H9/(1+$A7)^4+DCF!I9/(1+$A7)^5)+(DCF!I9*(1+0.14)/($A7-0.14)/(1+$A7)^5)-Assumptions!$B$7)/Assumptions!$B$6 -> 27.167271
A8: 0.22 | B8: =((DCF!E9/(1+$A8)^1+DCF!F9/(1+$A8)^2+DCF!G9/(1+$A8)^3+DCF!H9/(1+$A8)^4+DCF!I9/(1+$A8)^5)+(DCF!I9*(1+0.1)/($A8-0.1)/(1+$A8)^5)-Assumptions!$B$7)/Assumptions!$B$6 -> 13.041199 | C8: =((DCF!E9/(1+$A8)^1+DCF!F9/(1+$A8)^2+DCF!G9/(1+$A8)^3+DCF!H9/(1+$A8)^4+DCF!I9/(1+$A8)^5)+(DCF!I9*(1+0.11)/($A8-0.11)/(1+$A8)^5)-Assumptions!$B$7)/Assumptions!$B$6 -> 14.39522 | D8: =((DCF!E9/(1+$A8)^1+DCF!F9/(1+$A8)^2+DCF!G9/(1+$A8)^3+DCF!H9/(1+$A8)^4+DCF!I9/(1+$A8)^5)+(DCF!I9*(1+0.12)/($A8-0.12)/(1+$A8)^5)-Assumptions!$B$7)/Assumptions!$B$6 -> 16.020044 | E8: =((DCF!E9/(1+$A8)^1+DCF!F9/(1+$A8)^2+DCF!G9/(1+$A8)^3+DCF!H9/(1+$A8)^4+DCF!I9/(1+$A8)^5)+(DCF!I9*(1+0.13)/($A8-0.13)/(1+$A8)^5)-Assumptions!$B$7)/Assumptions!$B$6 -> 18.00594 | F8: =((DCF!E9/(1+$A8)^1+DCF!F9/(1+$A8)^2+DCF!G9/(1+$A8)^3+DCF!H9/(1+$A8)^4+DCF!I9/(1+$A8)^5)+(DCF!I9*(1+0.14)/($A8-0.14)/(1+$A8)^5)-Assumptions!$B$7)/Assumptions!$B$6 -> 20.488311
A10: Read across the base row/column (WACC 19.5%, g 12%). The fair value is highly geared to the WACC−g spread — the central tension in valuing an EGP compounder while rates and inflation are still falling.

Sheet Per-Share & Ratios
A1: Per-share & ratios
A2: Linked to the statements; spot from Assumptions.
B3: FY23 | C3: FY24 | D3: FY25 | E3: FY26E | F3: FY27E | G3: FY28E | H3: FY29E | I3: FY30E
A4: EPS (EGP) | B4: ='Income Statement'!B23 -> 0.86806146 | C4: ='Income Statement'!C23 -> 2.3244332 | D4: ='Income Statement'!D23 -> 1.6231007 | E4: ='Income Statement'!E23 -> 2.3873891 | F4: ='Income Statement'!F23 -> 3.2090836 | G4: ='Income Statement'!G23 -> 4.1135775 | H4: ='Income Statement'!H23 -> 5.0755392 | I4: ='Income Statement'!I23 -> 5.878772
A5: P/E (at spot) | B5: =Assumptions!$B$4/B4 -> 34.548245 | C5: =Assumptions!$B$4/C4 -> 12.90207 | D5: =Assumptions!$B$4/D4 -> 18.47698 | E5: =Assumptions!$B$4/E4 -> 12.56184 | F5: =Assumptions!$B$4/F4 -> 9.3453471 | G5: =Assumptions!$B$4/G4 -> 7.2904911 | H5: =Assumptions!$B$4/H4 -> 5.9087319 | I5: =Assumptions!$B$4/I4 -> 5.1014055
A6: EV/EBITDA (at spot) | B6: =(Assumptions!$B$4*Assumptions!$B$6+Assumptions!$B$7)/'Income Statement'!B14 -> 19.343071 | C6: =(Assumptions!$B$4*Assumptions!$B$6+Assumptions!$B$7)/'Income Statement'!C14 -> 8.1159684 | D6: =(Assumptions!$B$4*Assumptions!$B$6+Assumptions!$B$7)/'Income Statement'!D14 -> 10.072774 | E6: =(Assumptions!$B$4*Assumptions!$B$6+Assumptions!$B$7)/'Income Statement'!E14 -> 7.2752501 | F6: =(Assumptions!$B$4*Assumptions!$B$6+Assumptions!$B$7)/'Income Statement'!F14 -> 5.8628667 | G6: =(Assumptions!$B$4*Assumptions!$B$6+Assumptions!$B$7)/'Income Statement'!G14 -> 4.8596352 | H6: =(Assumptions!$B$4*Assumptions!$B$6+Assumptions!$B$7)/'Income Statement'!H14 -> 4.1083582 | I6: =(Assumptions!$B$4*Assumptions!$B$6+Assumptions!$B$7)/'Income Statement'!I14 -> 3.6276447
A7: Net debt / EBITDA | B7: ='Balance Sheet'!B14/'Income Statement'!B14-'Cash Flow'!B17/'Income Statement'!B14 -> 0.097299072 | C7: ='Balance Sheet'!C14/'Income Statement'!C14-'Cash Flow'!C17/'Income Statement'!C14 -> 0.38324119 | D7: ='Balance Sheet'!D14/'Income Statement'!D14-'Cash Flow'!D17/'Income Statement'!D14 -> 1.4552536 | E7: ='Balance Sheet'!E14/'Income Statement'!E14-'Cash Flow'!E17/'Income Statement'!E14 -> 1.3112081 | F7: ='Balance Sheet'!F14/'Income Statement'!F14-'Cash Flow'!F17/'Income Statement'!F14 -> 1.1515638 | G7: ='Balance Sheet'!G14/'Income Statement'!G14-'Cash Flow'!G17/'Income Statement'!G14 -> 0.91045444 | H7: ='Balance Sheet'!H14/'Income Statement'!H14-'Cash Flow'!H17/'Income Statement'!H14 -> 0.61063097 | I7: ='Balance Sheet'!I14/'Income Statement'!I14-'Cash Flow'!I17/'Income Statement'!I14 -> 0.31926151
A8: Return on equity | B8: ='Income Statement'!B21/'Balance Sheet'!B13 -> 0.24036425 | C8: ='Income Statement'!C21/'Balance Sheet'!C13 -> 0.43148297 | D8: ='Income Statement'!D21/'Balance Sheet'!D13 -> 0.237784 | E8: ='Income Statement'!E21/'Balance Sheet'!E13 -> 0.27328619 | F8: ='Income Statement'!F21/'Balance Sheet'!F13 -> 0.28391121 | G8: ='Income Statement'!G21/'Balance Sheet'!G13 -> 0.28186799 | H8: ='Income Statement'!H21/'Balance Sheet'!H13 -> 0.27208243 | I8: ='Income Statement'!I21/'Balance Sheet'!I13 -> 0.2516874
A9: Gross / EBITDA / net margin | B9: ='Income Statement'!B15 -> 0.13726651 | C9: ='Income Statement'!C15 -> 0.20914223 | D9: ='Income Statement'!D15 -> 0.13658102 | E9: ='Income Statement'!E15 -> 0.155 | F9: ='Income Statement'!F15 -> 0.163 | G9: ='Income Statement'!G15 -> 0.171 | H9: ='Income Statement'!H15 -> 0.179 | I9: ='Income Statement'!I15 -> 0.181
A11: P/E and EV/EBITDA are computed at the current spot to show how today's price maps onto the forecast earnings path. Net debt uses interest-bearing debt less cash.

Sheet Peer & Sector
A1: Peer set & sector
A2: Indicative multiples used to anchor the relative lens (analyst-compiled, Jul-2026).
B3: P/E | C3: EV/EBITDA | D3: Note
A4: Obour Land (EGX: OLFI) | B4: 11.4 | C4: 6.5 | D4: dairy/cheese, net-cash
A5: Edita Food (EGX: EFID) | B5: 11 | C5: 7.5 | D5: snacks, high margin
A6: Arabian Food/Domty (EGX: DOMTY) | B6: 12 | C6: 7 | D6: cheese/milk
A7: Almarai (Tadawul) | B7: 18 | C7: 12 | D7: KSA dairy, premium
A8: Savola (Tadawul) | B8: 14 | C8: 9 | D8: KSA food conglomerate
A9: Egypt-staples median | B9: =MEDIAN(B4:B6) -> 11.4 | C9: =MEDIAN(C4:C6) -> 7
A11: Applied to JUFO — EV/EBITDA | B11: =Assumptions!$B$31 -> 7
A12: Applied to JUFO — P/E | B12: =Assumptions!$B$32 -> 12
A14: Sources: Obour Land, Edita — Investing.com / EFG Hermes (fwd P/E ~11x); Almarai, Savola — regional comps. Egypt names carry a country/liquidity discount to KSA peers. JUFO is applied at ~7.0x EV/EBITDA and ~12x P/E — a premium to Obour Land for scale/brand, a discount to Almarai for leverage and country risk.
