Workbook

Sheet READ FIRST
A1: READ FIRST — DISCLOSURE & DISCLAIMER (educational valuation study; not investment advice)
A2: NATURE OF THIS WORKBOOK
A3: This workbook is an educational valuation exercise and an expression of the preparer's personal analytical opinion, based exclusively on publicly available information and on the assumptions stated in the text and this model. It is published free of charge to demonstrate methodology and to invite scrutiny of that methodology.
A5: NO ADVICE, NO RECOMMENDATION, NO SOLICITATION
A6: Nothing here constitutes investment advice, financial consultancy, securities analysis, a research recommendation, a rating, a price target, an offer, or a solicitation to buy, sell or hold any security. No statement is directed at the objectives, situation or needs of any person.
A8: NO LICENSED ACTIVITY
A9: The preparer is not licensed or registered with any securities regulator, carries on no regulated activity, manages no money, and accepts no clients, fees or funds.
A11: ESTIMATES AND UNCERTAINTY
A12: All values are model outputs resting on explicit, subjective assumptions; they are illustrative, highly uncertain and likely to prove wrong in material respects. Kakao's reported financials are company disclosure; the FORWARD assumptions — the holding-company discount, the marks on unlisted subsidiaries (Kakao Entertainment, Kakao Mobility), the value of the core KakaoTalk platform, and the multiples applied — are the preparer's judgments. Presented as ranges and distributions because no single number should be relied on.
A14: NO LIABILITY / READER'S RESPONSIBILITY
A15: To the maximum extent permitted by law, the preparer accepts no liability for any decision, action or loss in reliance on this workbook. Any person considering an investment decision should conduct their own assessment and consult a licensed advisor.
A17: HOLDINGS DISCLOSURE
... A21: Blue cells are hardcoded inputs (edit to your own view); black cells are formulas; green cells link across sheets. The valuation is a holding-company sum-of-the-parts: listed stakes at market value, unlisted subsidiaries at transaction-implied marks, the core KakaoTalk operating business on a multiple, plus parent net cash, less a holding-company discount — cross-checked against a consolidated DCF, relative multiples and normalized earnings. Currency is KRW unless stated; valuation in KRW trillion, per-share in KRW.

Sheet Summary
A1: KAKAO CORP. (KRX: 035720) — VALUATION SUMMARY
A2: Holding-company SOTP (listed stakes + unlisted marks + core platform + net cash, less holdco discount) + DCF + relative + normalized. Educational; not advice.
A4: HEADLINE — VALUE PER SHARE (KRW)
A5: Weighted central fundamental | B5: ='Fundamental Valuation'!B11 -> 34256.695
A6: SOTP base (32% holdco discount) | B6: =SOTP!B16 -> 35214.838
A7: SOTP bull (22% discount) | B7: =SOTP!C16 -> 46399.862
A8: SOTP bear (48% discount) | B8: =SOTP!D16 -> 21744.805
A9: Consolidated DCF (FCFF) | B9: =DCF!B22 -> 24503.471
A10: Market price (26-Jun-26) | B10: =Assumptions!B5 -> 33150
A11: Spot premium to central | B11: =B10/B5-1 -> -0.032305955
A13: WHAT THE NUMBER RESTS ON (edit on Assumptions)
A14: Gross NAV per share (KRW) | B14: =SOTP!B14 -> 51786.526
A15: Base holdco discount | B15: =Assumptions!C24 -> 0.32
A16: DCF WACC | B16: =Assumptions!B44 -> 0.095
A17: Parent net cash (KRW tn) | B17: =Assumptions!B7 -> 1.5
A19: METHODOLOGY
A20: - Holding-company SOTP — listed stakes at market (KakaoBank, KakaoPay, Kakao Games, SM Entertainment), unlisted subs at transaction marks (Kakao Entertainment, Kakao Mobility), the core KakaoTalk platform on a multiple, plus parent net cash, less a holdco discount. Primary lens.
A21: - The holding-company discount is the dominant swing factor: gross NAV is ~KRW 51,800/share; the market prices a ~36% discount; the base case applies 32%.
A22: - Consolidated DCF (FCFF) is a deliberately narrow cross-check on the operating business plus net cash only — it excludes the equity-method stake market values, so it lands well below the SOTP.
A23: - Relative multiples (EV/Sales, EV/EBITDA, P/E vs Naver) and normalized through-cycle earnings complete the picture.
A24: - Spot sits a few percent below the weighted central — Kakao screens roughly fairly valued, with the upside case resting on holdco-discount compression, AI monetization and stake crystallization.
A25: - Reported financials are company disclosure (Kakao IR / DART); forward inputs are the preparer's judgments.
A26: - Monte Carlo (16 factors, 50k paths, seed 42) describes near-term PRICE, not value; net ~flat 3M drift, very wide cone (Kakao realized vol ~51%).

Sheet Fundamental Valuation
A1: FUNDAMENTAL VALUATION — FIVE METHODS
A2: Holding-company SOTP (primary) + DCF cross-check + relative + normalized. Spot sits a few percent below the weighted central.
A4: THE METHODS — value per share (KRW)
A5: Method | B5: KRW/sh | C5: vs spot | D5: Weight | E5: Note
A6: SOTP — base (32% discount) | B6: =SOTP!B16 -> 35214.838 | C6: =B6/Assumptions!$B$5-1 -> 0.062287712 | D6: 0.25 | E6: primary lens
A7: SOTP — bull (22% discount) | B7: =SOTP!C16 -> 46399.862 | C7: =B7/Assumptions!$B$5-1 -> 0.39969418 | D7: 0.15 | E7: ceiling if discount compresses
A8: Consolidated DCF (FCFF) | B8: =DCF!B22 -> 24503.471 | C8: =B8/Assumptions!$B$5-1 -> -0.26083043 | D8: 0.1 | E8: narrow cash-flow cross-check
A9: Relative multiples (blended) | B9: ='Relative & Normalized'!B12 -> 31223.054 | C9: =B9/Assumptions!$B$5-1 -> -0.058128077 | D9: 0.25 | E9: vs Naver / sector
A10: Normalized earnings power | B10: ='Relative & Normalized'!B17 -> 32947.583 | C10: =B10/Assumptions!$B$5-1 -> -0.0061060817 | D10: 0.25 | E10: through-cycle discipline
A11: WEIGHTED CENTRAL FUNDAMENTAL VALUE | B11: =SUMPRODUCT(B6:B10,D6:D10) -> 34256.695 | C11: =B11/Assumptions!$B$5-1 -> 0.033384472 | D11: =SUM(D6:D10) -> 1
A12: Memo: spot price (26-Jun-26) | B12: =Assumptions!B5 -> 33150
A13: Spot premium to central | B13: =B12/B11-1 -> -0.032305955 | E13: market prices a normal holdco discount
A15: RANGE: bear (wide discount) → bull (discount compression)
A16: Bear / wide-discount floor (SOTP bear) | B16: =SOTP!D16 -> 21744.805
A17: Bull / discount-compression ceiling (SOTP bull) | B17: =SOTP!C16 -> 46399.862

Sheet Assumptions
A1: KAKAO CORP. (KRX: 035720) — ASSUMPTIONS
A2: All blue cells are inputs. KRW trillion unless noted. Edit to your own view.
A4: GLOBAL & CORPORATE
A5: Spot price (KRW, 26-Jun-26 close) | B5: 33150
A6: Shares outstanding (bn) | B6: 0.4407
A7: Parent net cash (KRW tn, base) | B7: 1.5
A8: Tax rate (effective) | B8: 0.22
A10: SOTP — LISTED STAKES (at market)
A11: Stake | B11: Ownership % | C11: Sub mkt cap (tn) | D11: Stake value (tn)
A12: KakaoBank | B12: 0.2716 | C12: 10.6 | D12: =B12*C12 -> 2.87896
A13: KakaoPay | B13: 0.445 | C13: 5.75 | D13: =B13*C13 -> 2.55875
A14: Kakao Games | B14: 0.1468 | C14: 0.85 | D14: =B14*C14 -> 0.12478
A15: SM Entertainment (direct) | B15: 0.2076 | C15: 1.57 | D15: =B15*C15 -> 0.325932
A16: Listed subtotal | D16: =SUM(D12:D15) -> 5.888422
A18: SOTP — UNLISTED, CORE & HOLDCO DISCOUNT
A19: Item | B19: Ownership % | C19: EV base (tn) | D19: EV bull | E19: EV bear
A20: Kakao Entertainment | B20: 0.6603 | C20: 8 | D20: 10 | E20: 6
A21: Kakao Mobility | B21: 0.573 | C21: 5.5 | D21: 6.5 | E21: 4.5
A22: Core operating business EV (Talk Biz+Daum+AI) | C22: 7 | D22: 8.5 | E22: 5
A23: Parent net cash | C23: 1.5 | D23: 1.5 | E23: 1
A24: Holdco discount | C24: 0.32 | D24: 0.22 | E24: 0.48
A26: RELATIVE & NORMALIZED
A27: Consolidated revenue 2025 (KRW tn) | B27: 8.1
A28: EV/Sales multiple (x) | B28: 1.8
A29: Consolidated EBITDA (KRW tn) | B29: 1.3
A30: EV/EBITDA multiple (x) | B30: 9
A31: Net profit — relative (KRW tn) | B31: 0.6
A32: Relative P/E (x) | B32: 20
A33: Normalized through-cycle net (KRW tn) | B33: 0.66
A34: Normalized justified P/E (x) | B34: 22
A36: FIVE-METHOD WEIGHTS
A37: SOTP — base | B37: 0.25
A38: SOTP — bull | B38: 0.15
A39: Consolidated DCF (FCFF) | B39: 0.1
A40: Relative multiples | B40: 0.25
A41: Normalized earnings | B41: 0.25
A43: DCF INPUTS
A44: WACC (KRW) | B44: 0.095
A45: Terminal growth g | B45: 0.03
A46: Stage-1 FCFF growth | B46: 0.08
...

Sheet SOTP
A1: SUM-OF-THE-PARTS — holding-company NAV (base / bull / bear)
A2: Listed stakes at market; unlisted subs at transaction marks; core platform on a multiple; parent net cash added; holdco discount applied. KRW tn; per-share KRW.
A4: Asset | B4: Base (tn) | C4: Bull (tn) | D4: Bear (tn) | E4: Basis
A5: KakaoBank (27.16%) | B5: =Assumptions!D12 -> 2.87896 | C5: =Assumptions!D12 -> 2.87896 | D5: =Assumptions!D12 -> 2.87896 | E5: listed at market
A6: KakaoPay (44.5%) | B6: =Assumptions!D13 -> 2.55875 | C6: =Assumptions!D13 -> 2.55875 | D6: =Assumptions!D13 -> 2.55875 | E6: listed at market
A7: Kakao Games (14.68%) | B7: =Assumptions!D14 -> 0.12478 | C7: =Assumptions!D14 -> 0.12478 | D7: =Assumptions!D14 -> 0.12478 | E7: listed at market
A8: SM Entertainment (20.76%) | B8: =Assumptions!D15 -> 0.325932 | C8: =Assumptions!D15 -> 0.325932 | D8: =Assumptions!D15 -> 0.325932 | E8: listed at market
A9: Kakao Entertainment (66.03%) | B9: =Assumptions!B20*Assumptions!C20 -> 5.2824 | C9: =Assumptions!B20*Assumptions!D20 -> 6.603 | D9: =Assumptions!B20*Assumptions!E20 -> 3.9618 | E9: unlisted; transaction mark
A10: Kakao Mobility (57.3%) | B10: =Assumptions!B21*Assumptions!C21 -> 3.1515 | C10: =Assumptions!B21*Assumptions!D21 -> 3.7245 | D10: =Assumptions!B21*Assumptions!E21 -> 2.5785 | E10: unlisted; 2025 deal range
A11: Core operating business | B11: =Assumptions!C22 -> 7 | C11: =Assumptions!D22 -> 8.5 | D11: =Assumptions!E22 -> 5 | E11: Talk Biz + Daum + AI, on a multiple
A12: Parent net cash | B12: =Assumptions!C23 -> 1.5 | C12: =Assumptions!D23 -> 1.5 | D12: =Assumptions!E23 -> 1 | E12: parent-standalone
A13: Gross NAV (KRW tn) | B13: =SUM(B5:B12) -> 22.822322 | C13: =SUM(C5:C12) -> 26.215922 | D13: =SUM(D5:D12) -> 18.428722
A14: Gross NAV / share (KRW) | B14: =B13/Assumptions!$B$6*1000 -> 51786.526 | C14: =C13/Assumptions!$B$6*1000 -> 59487.002 | D14: =D13/Assumptions!$B$6*1000 -> 41816.932
A15: (-) Holdco discount | B15: =Assumptions!C24 -> 0.32 | C15: =Assumptions!D24 -> 0.22 | D15: =Assumptions!E24 -> 0.48
A16: VALUE / SHARE (KRW) | B16: =B14*(1-B15) -> 35214.838 | C16: =C14*(1-C15) -> 46399.862 | D16: =D14*(1-D15) -> 21744.805
A17: vs spot | B17: =B16/Assumptions!$B$5-1 -> 0.062287712 | C17: =C16/Assumptions!$B$5-1 -> 0.39969418 | D17: =D16/Assumptions!$B$5-1 -> -0.34404812
A19: Base = 32% holdco discount on transaction-marked assets. Bull = 22% discount + higher unlisted marks (Kakao Entertainment KRW 10tn, Mobility KRW 6.5tn) + stronger core. Bear = 48% discount + lower marks. Gross NAV ~KRW 51,800/share; the market prices a ~36% discount at spot. Listed stakes are held constant across scenarios; the discount and unlisted marks drive the range.

Sheet Segments
A1: HOLDING-COMPANY ASSETS — stakes & operating segments
A2: What Kakao owns and how each piece is valued. Source: Kakao IR / DART segment disclosures (FY2025).
A4: Dimension | B4: Listed financial stakes | C4: Unlisted subsidiaries | D4: Core platform (parent)
A5: What it is | B5: KakaoBank 27%, KakaoPay 45%, Kakao Games 15%, SM Ent 21% | C5: Kakao Entertainment 66%, Kakao Mobility 57% | D5: KakaoTalk (Talk Biz: ads + commerce), Daum portal, AI (Kanana)
A6: Valuation basis | B6: Market value × ownership | C6: Transaction-implied EV × ownership | D6: EV/EBITDA on standalone profit
A7: Earnings driver | B7: Sub share prices; KakaoBank loan growth; KakaoPay TPV | C7: Webtoon/music/IP; mobility GMV; deal marks | D7: MAU × ad load × commerce GMV
A8: Cyclicality | B8: Market-linked; bank rate-sensitive | C8: Content hit-driven; mobility scaling | D8: Moderate — domestic ad cycle
A9: Profitability | B9: KakaoBank/Pay profitable; Games swing | C9: Ent profitable; Mobility near breakeven | D9: Talk Biz 30%+ OPM — the profit engine
A10: Valuation lens | B10: at market (no normalization) | C10: haircut to 2023–25 deal marks | D10: ~10x EV/EBITDA, net of New-Initiatives loss
A12: KakaoTalk's Talk Biz (advertising + commerce) carries a 30%+ operating margin and is the dominant standalone profit engine; the loss-making New Initiatives (cloud, AI, healthcare) are a drag the core mark nets against. Most of Kakao's value sits in the listed and unlisted stakes, which is why the holding-company discount dominates the valuation. Sources: Kakao IR, DART (FY2025); verify live.

Sheet Relative & Normalized
A1: RELATIVE MULTIPLES & NORMALIZED EARNINGS POWER
A2: Multiples on consolidated metrics vs Naver/sector; through-cycle earnings as a discipline. Cross-checks on the SOTP.
A4: RELATIVE MULTIPLES (KRW tn unless noted)
A5: Implied EV — EV/Sales | B5: =Assumptions!B27*Assumptions!B28 -> 14.58 | E5: revenue x EV/Sales
A6: Implied equity — EV/Sales (+ net cash) | B6: =B5+Assumptions!B7 -> 16.08
A7: value/share (KRW) | B7: =B6/Assumptions!$B$6*1000 -> 36487.406
A8: Implied EV — EV/EBITDA | B8: =Assumptions!B29*Assumptions!B30 -> 11.7 | E8: EBITDA x EV/EBITDA
A9: value/share (KRW) | B9: =(B8+Assumptions!B7)/Assumptions!$B$6*1000 -> 29952.349
A10: Implied equity — P/E (NI x P/E) | B10: =Assumptions!B31*Assumptions!B32 -> 12
A11: value/share (KRW) | B11: =B10/Assumptions!$B$6*1000 -> 27229.408
A12: RELATIVE BLENDED MIDPOINT (KRW) | B12: =AVERAGE(B7,B9,B11) -> 31223.054
A14: NORMALIZED THROUGH-CYCLE EARNINGS POWER
A15: Normalized net profit (KRW tn) | B15: =Assumptions!B33 -> 0.66
A16: Justified P/E (x) | B16: =Assumptions!B34 -> 22
A17: NORMALIZED VALUE / SHARE (KRW) | B17: =B15*B16/Assumptions!$B$6*1000 -> 32947.583
A18: Normalized P/E at spot (x) | B18: =Assumptions!B5/(B15/Assumptions!B6*1000) -> 22.135159 | E18: on through-cycle EPS
A20: Relative lens blends EV/Sales (1.8x, below Naver's ~2.9x for lower growth/margin), EV/EBITDA (9x) and P/E (20x). The P/E lens is depressed because Kakao's reported earnings capture little of the listed-stake value — the SOTP is the more complete lens. Normalized uses through-cycle net of ~KRW 0.66tn at 22x. Sources: Kakao IR; peer multiples Naver IR; verify live.

Sheet DCF
A1: CONSOLIDATED DCF — unlevered FCFF (cross-check)
A2: FCFF = OP x (1-tax) + D&A - capex - dWC, discounted at WACC; normalized terminal. Operating business + net cash only (excludes equity-method stakes).
A4: KRW tn | B4: 2026 | C4: 2027 | D4: 2028 | E4: 2029 | F4: 2030
A5: Operating profit | B5: =Assumptions!C52 -> 0.8 | C5: =Assumptions!C53 -> 0.92 | D5: =Assumptions!C54 -> 1.05 | E5: =Assumptions!C55 -> 1.18 | F5: =Assumptions!C56 -> 1.3
A6: NOPAT (x(1-tax)) | B6: =B5*(1-Assumptions!$B$48) -> 0.624 | C6: =C5*(1-Assumptions!$B$48) -> 0.7176 | D6: =D5*(1-Assumptions!$B$48) -> 0.819 | E6: =E5*(1-Assumptions!$B$48) -> 0.9204 | F6: =F5*(1-Assumptions!$B$48) -> 1.014
A7: (+) D&A | B7: =Assumptions!B60 -> 0.57 | C7: =Assumptions!B61 -> 0.6 | D7: =Assumptions!B62 -> 0.63 | E7: =Assumptions!B63 -> 0.66 | F7: =Assumptions!B64 -> 0.69
A8: (-) Capex | B8: =-Assumptions!C60 -> -0.8 | C8: =-Assumptions!C61 -> -0.84 | D8: =-Assumptions!C62 -> -0.88 | E8: =-Assumptions!C63 -> -0.92 | F8: =-Assumptions!C64 -> -0.96
A9: (-) dWorking capital | B9: =-Assumptions!D60 -> -0.05 | C9: =-Assumptions!D61 -> -0.03 | D9: =-Assumptions!D62 -> -0.02 | E9: =-Assumptions!D63 -> -0.02 | F9: =-Assumptions!D64 -> -0.02
A10: Unlevered FCFF | B10: =B6+B7+B8+B9 -> 0.344 | C10: =C6+C7+C8+C9 -> 0.4476 | D10: =D6+D7+D8+D9 -> 0.549 | E10: =E6+E7+E8+E9 -> 0.6404 | F10: =F6+F7+F8+F9 -> 0.724
A11: Discount factor @ WACC | B11: =1/(1+Assumptions!$B$44)^1 -> 0.91324201 | C11: =1/(1+Assumptions!$B$44)^2 -> 0.83401097 | D11: =1/(1+Assumptions!$B$44)^3 -> 0.76165385 | E11: =1/(1+Assumptions!$B$44)^4 -> 0.69557429 | F11: =1/(1+Assumptions!$B$44)^5 -> 0.63522767
A12: PV of FCFF | B12: =B10*B11 -> 0.31415525 | C12: =C10*C11 -> 0.37330331 | D12: =D10*D11 -> 0.41814796 | E12: =E10*E11 -> 0.44544578 | F12: =F10*F11 -> 0.45990483
A14: PV of explicit FCFF (S) | B14: =SUM(B12:F12) -> 2.0109571
A15: Terminal value (Gordon, normalized FCFF) | B15: =F10*(1+Assumptions!B45)/(Assumptions!B44-Assumptions!B45) -> 11.472615
A16: PV of terminal value | B16: =B15/(1+Assumptions!B44)^5 -> 7.2877227
A17: Enterprise value (operating) | B17: =B14+B16 -> 9.2986798
A18: (+) Parent net cash | B18: =Assumptions!B7 -> 1.5
A19: Equity value (KRW tn) | B19: =B17+B18 -> 10.79868
A21: Shares (bn) | B21: =Assumptions!B6 -> 0.4407
A22: VALUE / SHARE (KRW) | B22: =B19/B21*1000 -> 24503.471
A23: vs spot | B23: =B22/Assumptions!B5-1 -> -0.26083043
A25: The DCF deliberately values only the consolidated operating business plus parent net cash; it EXCLUDES the equity-method stake market values (KakaoBank etc.) that the SOTP captures, so it lands well below the SOTP. It answers a narrow question — what is Kakao's owned operating cash flow worth — and shows that the operating engine alone does not carry the price; the value is in the stakes. A cross-check, not the primary lens.

Sheet Income Statement
A1: CONSOLIDATED INCOME STATEMENT — KRW tn
A2: Actuals Kakao IR (FY2023 restated basis). Forecast 2026e-2030e: OP and net link to Assumptions; revenue split hardcoded.
A4: KRW tn | B4: 2023a | C4: 2024a | D4: 2025a | E4: 2026e | F4: 2027e | G4: 2028e | H4: 2029e | I4: 2030e
A5: Platform revenue | B5: 3.5 | C5: 3.9 | D5: 4.32 | E5: 4.75 | F5: 5.25 | G5: 5.7 | H5: 6.15 | I5: 6.6
A6: Content revenue | B6: 4.06 | C6: 3.97 | D6: 3.78 | E6: 3.65 | F6: 3.65 | G6: 3.7 | H6: 3.75 | I6: 3.8
A7: Total revenue | B7: =B5+B6 -> 7.56 | C7: =C5+C6 -> 7.87 | D7: =D5+D6 -> 8.1 | E7: =E5+E6 -> 8.4 | F7: =F5+F6 -> 8.9 | G7: =G5+G6 -> 9.4 | H7: =H5+H6 -> 9.9 | I7: =I5+I6 -> 10.4
A8: growth YoY | C8: =C7/B7-1 -> 0.041005291 | D8: =D7/C7-1 -> 0.029224905 | E8: =E7/D7-1 -> 0.037037037 | F8: =F7/E7-1 -> 0.05952381 | G8: =G7/F7-1 -> 0.056179775 | H8: =H7/G7-1 -> 0.053191489 | I8: =I7/H7-1 -> 0.050505051
A9: (Operating expenses) | B9: =-(B7-B10) -> -7.06 | C9: =-(C7-C10) -> -7.38 | D9: =-(D7-D10) -> -7.37 | E9: =-(E7-E10) -> -7.6 | F9: =-(F7-F10) -> -7.98 | G9: =-(G7-G10) -> -8.35 | H9: =-(H7-H10) -> -8.72 | I9: =-(I7-I10) -> -9.1
A10: Operating profit | B10: 0.5 | C10: 0.49 | D10: 0.73 | E10: =Assumptions!C52 -> 0.8 | F10: =Assumptions!C53 -> 0.92 | G10: =Assumptions!C54 -> 1.05 | H10: =Assumptions!C55 -> 1.18 | I10: =Assumptions!C56 -> 1.3
A11: OP margin | B11: =B10/B7 -> 0.066137566 | C11: =C10/C7 -> 0.062261753 | D11: =D10/D7 -> 0.090123457 | E11: =E10/E7 -> 0.095238095 | F11: =F10/F7 -> 0.10337079 | G11: =G10/G7 -> 0.11170213 | H11: =H10/H7 -> 0.11919192 | I11: =I10/I7 -> 0.125
A12: Net non-operating & associates | B12: -0.4 | C12: -0.65 | D12: -0.05 | E12: 0 | F12: 0.02 | G12: 0.03 | H12: 0.04 | I12: 0.05
A13: Pre-tax profit/(loss) | B13: =B10+B12 -> 0.1 | C13: =C10+C12 -> -0.16 | D13: =D10+D12 -> 0.68 | E13: =E10+E12 -> 0.8 | F13: =F10+F12 -> 0.94 | G13: =G10+G12 -> 1.08 | H13: =H10+H12 -> 1.22 | I13: =I10+I12 -> 1.35
A14: Income tax & minority interests | B14: =B15-B13 -> -0.05 | C14: =C15-C13 -> 0 | D14: =D15-D13 -> -0.15 | E14: =E15-E13 -> -0.22 | F14: =F15-F13 -> -0.24 | G14: =G15-G13 -> -0.26 | H14: =H15-H13 -> -0.27 | I14: =I15-I13 -> -0.27
A15: Net profit/(loss) attributable | B15: 0.05 | C15: -0.16 | D15: 0.53 | E15: =Assumptions!D52 -> 0.58 | F15: =Assumptions!D53 -> 0.7 | G15: =Assumptions!D54 -> 0.82 | H15: =Assumptions!D55 -> 0.95 | I15: =Assumptions!D56 -> 1.08
A16: net margin | B16: =B15/B7 -> 0.0066137566 | C16: =C15/C7 -> -0.020330368 | D16: =D15/D7 -> 0.065432099 | E16: =E15/E7 -> 0.069047619 | F16: =F15/F7 -> 0.078651685 | G16: =G15/G7 -> 0.087234043 | H16: =H15/H7 -> 0.095959596 | I16: =I15/I7 -> 0.10384615
A17: EPS (KRW) | B17: =B15/Assumptions!$B$6*1000 -> 113.45587 | C17: =C15/Assumptions!$B$6*1000 -> -363.05877 | D17: =D15/Assumptions!$B$6*1000 -> 1202.6322 | E17: =E15/Assumptions!$B$6*1000 -> 1316.088 | F17: =F15/Assumptions!$B$6*1000 -> 1588.3821 | G17: =G15/Assumptions!$B$6*1000 -> 1860.6762 | H17: =H15/Assumptions!$B$6*1000 -> 2155.6614 | I17: =I15/Assumptions!$B$6*1000 -> 2450.6467
A19: Platform (Talk Biz, Portal, Mobility/Pay) now exceeds Content (Games, Story, Music, Media), which fell as Games revenue declined. FY2022-2023 on Kakao's restated basis, so 2025 (KRW 8.10tn) was the first year above KRW 8tn. FY2024 was a net loss on impairments; FY2025 a record net profit. Forecast deliberately below management's 2026 >10% revenue-growth / ~10% OP-margin guidance.

Sheet Balance Sheet
A1: CONSOLIDATED BALANCE SHEET — KRW tn
A2: Totals anchored to reported filings (end-2025: assets ~27.8tn, equity ~19.0tn, cash ~6.8tn, debt ~2.9tn); sub-lines approximate.
A4: KRW tn | B4: 2023a | C4: 2024a | D4: 2025a | E4: 2026e | F4: 2027e | G4: 2028e | H4: 2029e | I4: 2030e
A5: Cash & cash equivalents | B5: 5.8 | C5: 6.5 | D5: 6.8 | E5: 7.2 | F5: 7.7 | G5: 8.2 | H5: 8.8 | I5: 9.5
A6: ST financial instruments & other | B6: 2.3 | C6: 2.4 | D6: 2.5 | E6: 2.5 | F6: 2.5 | G6: 2.5 | H6: 2.5 | I6: 2.5
A7: Trade & other receivables | B7: 1.4 | C7: 1.5 | D7: 1.5 | E7: 1.6 | F7: 1.7 | G7: 1.8 | H7: 1.9 | I7: 2
A8: Total current assets | B8: =SUM(B5:B7) -> 9.5 | C8: =SUM(C5:C7) -> 10.4 | D8: =SUM(D5:D7) -> 10.8 | E8: =SUM(E5:E7) -> 11.3 | F8: =SUM(F5:F7) -> 11.9 | G8: =SUM(G5:G7) -> 12.5 | H8: =SUM(H5:H7) -> 13.2 | I8: =SUM(I5:I7) -> 14
A9: Property, plant & equipment | B9: 2.8 | C9: 3 | D9: 3.2 | E9: 3.4 | F9: 3.6 | G9: 3.8 | H9: 4 | I9: 4.2
A10: Goodwill & intangible assets | B10: 8 | C10: 7.7 | D10: 7.5 | E10: 7.5 | F10: 7.5 | G10: 7.5 | H10: 7.5 | I10: 7.5
A11: Investments in associates | B11: 3.4 | C11: 3.5 | D11: 3.5 | E11: 3.6 | F11: 3.7 | G11: 3.8 | H11: 3.9 | I11: 4
A12: Other non-current assets | B12: 2.8 | C12: 2.4 | D12: 2.8 | E12: 2.8 | F12: 2.8 | G12: 2.8 | H12: 2.8 | I12: 2.8
A13: Total non-current assets | B13: =SUM(B9:B12) -> 17 | C13: =SUM(C9:C12) -> 16.6 | D13: =SUM(D9:D12) -> 17 | E13: =SUM(E9:E12) -> 17.3 | F13: =SUM(F9:F12) -> 17.6 | G13: =SUM(G9:G12) -> 17.9 | H13: =SUM(H9:H12) -> 18.2 | I13: =SUM(I9:I12) -> 18.5
A14: Total assets | B14: =B8+B13 -> 26.5 | C14: =C8+C13 -> 27 | D14: =D8+D13 -> 27.8 | E14: =E8+E13 -> 28.6 | F14: =F8+F13 -> 29.5 | G14: =G8+G13 -> 30.4 | H14: =H8+H13 -> 31.4 | I14: =I8+I13 -> 32.5
A15: Trade & other payables | B15: 2 | C15: 2.1 | D15: 2.2 | E15: 2.3 | F15: 2.4 | G15: 2.5 | H15: 2.6 | I15: 2.7
A16: Other current liabilities | B16: 2.8 | C16: 3 | D16: 3.3 | E16: 3.3 | F16: 3.3 | G16: 3.3 | H16: 3.3 | I16: 3.3
A17: Total current liabilities | B17: =SUM(B15:B16) -> 4.8 | C17: =SUM(C15:C16) -> 5.1 | D17: =SUM(D15:D16) -> 5.5 | E17: =SUM(E15:E16) -> 5.6 | F17: =SUM(F15:F16) -> 5.7 | G17: =SUM(G15:G16) -> 5.8 | H17: =SUM(H15:H16) -> 5.9 | I17: =SUM(I15:I16) -> 6
A18: Borrowings, bonds & leases | B18: 2.5 | C18: 2.7 | D18: 2.9 | E18: 2.9 | F18: 2.9 | G18: 2.9 | H18: 2.9 | I18: 2.9
A19: Other non-current liabilities | B19: 0.5 | C19: 0.5 | D19: 0.4 | E19: 0.4 | F19: 0.4 | G19: 0.4 | H19: 0.4 | I19: 0.4
A20: Total liabilities | B20: =B17+B18+B19 -> 7.8 | C20: =C17+C18+C19 -> 8.3 | D20: =D17+D18+D19 -> 8.8 | E20: =E17+E18+E19 -> 8.9 | F20: =F17+F18+F19 -> 9 | G20: =G17+G18+G19 -> 9.1 | H20: =H17+H18+H19 -> 9.2 | I20: =I17+I18+I19 -> 9.3
A21: Equity attributable to owners | B21: 11 | C21: 10.3 | D21: 10.5 | E21: 11 | F21: 11.6 | G21: 12.3 | H21: 13.1 | I21: 14
A22: Non-controlling interests | B22: 7.7 | C22: 8.4 | D22: 8.5 | E22: 8.7 | F22: 8.9 | G22: 9 | H22: 9.1 | I22: 9.2
A23: Total equity | B23: =SUM(B21:B22) -> 18.7 | C23: =SUM(C21:C22) -> 18.7 | D23: =SUM(D21:D22) -> 19 | E23: =SUM(E21:E22) -> 19.7 | F23: =SUM(F21:F22) -> 20.5 | G23: =SUM(G21:G22) -> 21.3 | H23: =SUM(H21:H22) -> 22.2 | I23: =SUM(I21:I22) -> 23.2
A24: Total liabilities & equity | B24: =B20+B23 -> 26.5 | C24: =C20+C23 -> 27 | D24: =D20+D23 -> 27.8 | E24: =E20+E23 -> 28.6 | F24: =F20+F23 -> 29.5 | G24: =G20+G23 -> 30.4 | H24: =H20+H23 -> 31.4 | I24: =I20+I23 -> 32.5
A25: BVPS — attributable (KRW) | B25: =B21/Assumptions!$B$6*1000 -> 24960.29 | C25: =C21/Assumptions!$B$6*1000 -> 23371.908 | D25: =D21/Assumptions!$B$6*1000 -> 23825.732 | E25: =E21/Assumptions!$B$6*1000 -> 24960.29 | F25: =F21/Assumptions!$B$6*1000 -> 26321.761 | G25: =G21/Assumptions!$B$6*1000 -> 27910.143 | H25: =H21/Assumptions!$B$6*1000 -> 29725.437 | I25: =I21/Assumptions!$B$6*1000 -> 31767.642
A26: Net cash (cash − debt) | B26: =B5-B18 -> 3.3 | C26: =C5-C18 -> 3.8 | D26: =D5-D18 -> 3.9 | E26: =E5-E18 -> 4.3 | F26: =F5-F18 -> 4.8 | G26: =G5-G18 -> 5.3 | H26: =H5-H18 -> 5.9 | I26: =I5-I18 -> 6.6
A28: Totals tie to Kakao's reported balance sheet; sub-lines are approximate allocations. Large non-controlling interests (~8.5tn) reflect consolidated stakes in KakaoPay, Kakao Entertainment, Mobility and Games. Equity attributable to owners ~10.5tn = book ~KRW 23,800/share (P/B ~1.4x). Book understates the holding-company NAV, so discount-to-NAV (not P/B) is the more informative gauge.

Sheet Cash Flow
A1: CONSOLIDATED CASH FLOW — KRW tn (simplified)
A2: Actuals approximate. Forecast: OCF approx net + D&A - dWC; investing = capex; financing = dividends/buybacks.
A4: KRW tn | B4: 2023a | C4: 2024a | D4: 2025a | E4: 2026e | F4: 2027e | G4: 2028e | H4: 2029e | I4: 2030e
A5: Operating cash flow | B5: 0.92 | C5: 0.95 | D5: 1.1 | E5: =Assumptions!D52+Assumptions!B60-Assumptions!D60 -> 1.1 | F5: =Assumptions!D53+Assumptions!B61-Assumptions!D61 -> 1.27 | G5: =Assumptions!D54+Assumptions!B62-Assumptions!D62 -> 1.43 | H5: =Assumptions!D55+Assumptions!B63-Assumptions!D63 -> 1.59 | I5: =Assumptions!D56+Assumptions!B64-Assumptions!D64 -> 1.75
A6: Capex (investing) | B6: -0.58 | C6: -0.6 | D6: -0.55 | E6: =-Assumptions!C60 -> -0.8 | F6: =-Assumptions!C61 -> -0.84 | G6: =-Assumptions!C62 -> -0.88 | H6: =-Assumptions!C63 -> -0.92 | I6: =-Assumptions!C64 -> -0.96
A7: Financing (div/buyback/other) | B7: -0.1 | C7: -0.12 | D7: -0.2 | E7: -0.15 | F7: -0.17 | G7: -0.19 | H7: -0.21 | I7: -0.23
A8: Net change in cash | B8: =B5+B6+B7 -> 0.24 | C8: =C5+C6+C7 -> 0.23 | D8: =D5+D6+D7 -> 0.35 | E8: =E5+E6+E7 -> 0.15 | F8: =F5+F6+F7 -> 0.26 | G8: =G5+G6+G7 -> 0.36 | H8: =H5+H6+H7 -> 0.46 | I8: =I5+I6+I7 -> 0.56
A9: Memo - free cash flow (OCF + capex) | B9: =B5+B6 -> 0.34 | C9: =C5+C6 -> 0.35 | D9: =D5+D6 -> 0.55 | E9: =E5+E6 -> 0.3 | F9: =F5+F6 -> 0.43 | G9: =G5+G6 -> 0.55 | H9: =H5+H6 -> 0.67 | I9: =I5+I6 -> 0.79
A11: Kakao generates solid operating cash flow but reinvests heavily in content, AI and infrastructure, so free cash flow is well below the headline asset value. Financing reflects modest dividends and any buyback/treasury activity (a value-up catalyst if treasury shares are cancelled). Simplified and illustrative.

Sheet Summary Financials
A1: KAKAO CORP. — SUMMARY FINANCIALS (live links)
A2: Every cell links to the Income Statement / Balance Sheet / Cash Flow sheets.
A4: KRW tn | B4: 2023a | C4: 2024a | D4: 2025a | E4: 2026e | F4: 2027e | G4: 2028e | H4: 2029e | I4: 2030e
A5: Revenue | B5: ='Income Statement'!B7 -> 7.56 | C5: ='Income Statement'!C7 -> 7.87 | D5: ='Income Statement'!D7 -> 8.1 | E5: ='Income Statement'!E7 -> 8.4 | F5: ='Income Statement'!F7 -> 8.9 | G5: ='Income Statement'!G7 -> 9.4 | H5: ='Income Statement'!H7 -> 9.9 | I5: ='Income Statement'!I7 -> 10.4
A6: Operating profit | B6: ='Income Statement'!B10 -> 0.5 | C6: ='Income Statement'!C10 -> 0.49 | D6: ='Income Statement'!D10 -> 0.73 | E6: ='Income Statement'!E10 -> 0.8 | F6: ='Income Statement'!F10 -> 0.92 | G6: ='Income Statement'!G10 -> 1.05 | H6: ='Income Statement'!H10 -> 1.18 | I6: ='Income Statement'!I10 -> 1.3
A7: Net profit | B7: ='Income Statement'!B15 -> 0.05 | C7: ='Income Statement'!C15 -> -0.16 | D7: ='Income Statement'!D15 -> 0.53 | E7: ='Income Statement'!E15 -> 0.58 | F7: ='Income Statement'!F15 -> 0.7 | G7: ='Income Statement'!G15 -> 0.82 | H7: ='Income Statement'!H15 -> 0.95 | I7: ='Income Statement'!I15 -> 1.08
A8: EPS (KRW) | B8: ='Income Statement'!B17 -> 113.45587 | C8: ='Income Statement'!C17 -> -363.05877 | D8: ='Income Statement'!D17 -> 1202.6322 | E8: ='Income Statement'!E17 -> 1316.088 | F8: ='Income Statement'!F17 -> 1588.3821 | G8: ='Income Statement'!G17 -> 1860.6762 | H8: ='Income Statement'!H17 -> 2155.6614 | I8: ='Income Statement'!I17 -> 2450.6467
A9: Total assets | B9: ='Balance Sheet'!B14 -> 26.5 | C9: ='Balance Sheet'!C14 -> 27 | D9: ='Balance Sheet'!D14 -> 27.8 | E9: ='Balance Sheet'!E14 -> 28.6 | F9: ='Balance Sheet'!F14 -> 29.5 | G9: ='Balance Sheet'!G14 -> 30.4 | H9: ='Balance Sheet'!H14 -> 31.4 | I9: ='Balance Sheet'!I14 -> 32.5
A10: Total equity | B10: ='Balance Sheet'!B23 -> 18.7 | C10: ='Balance Sheet'!C23 -> 18.7 | D10: ='Balance Sheet'!D23 -> 19 | E10: ='Balance Sheet'!E23 -> 19.7 | F10: ='Balance Sheet'!F23 -> 20.5 | G10: ='Balance Sheet'!G23 -> 21.3 | H10: ='Balance Sheet'!H23 -> 22.2 | I10: ='Balance Sheet'!I23 -> 23.2
A11: Net cash | B11: ='Balance Sheet'!B26 -> 3.3 | C11: ='Balance Sheet'!C26 -> 3.8 | D11: ='Balance Sheet'!D26 -> 3.9 | E11: ='Balance Sheet'!E26 -> 4.3 | F11: ='Balance Sheet'!F26 -> 4.8 | G11: ='Balance Sheet'!G26 -> 5.3 | H11: ='Balance Sheet'!H26 -> 5.9 | I11: ='Balance Sheet'!I26 -> 6.6
A12: BVPS (KRW) | B12: ='Balance Sheet'!B25 -> 24960.29 | C12: ='Balance Sheet'!C25 -> 23371.908 | D12: ='Balance Sheet'!D25 -> 23825.732 | E12: ='Balance Sheet'!E25 -> 24960.29 | F12: ='Balance Sheet'!F25 -> 26321.761 | G12: ='Balance Sheet'!G25 -> 27910.143 | H12: ='Balance Sheet'!H25 -> 29725.437 | I12: ='Balance Sheet'!I25 -> 31767.642
A13: Operating cash flow | B13: ='Cash Flow'!B5 -> 0.92 | C13: ='Cash Flow'!C5 -> 0.95 | D13: ='Cash Flow'!D5 -> 1.1 | E13: ='Cash Flow'!E5 -> 1.1 | F13: ='Cash Flow'!F5 -> 1.27 | G13: ='Cash Flow'!G5 -> 1.43 | H13: ='Cash Flow'!H5 -> 1.59 | I13: ='Cash Flow'!I5 -> 1.75
A14: Free cash flow | B14: ='Cash Flow'!B9 -> 0.34 | C14: ='Cash Flow'!C9 -> 0.35 | D14: ='Cash Flow'!D9 -> 0.55 | E14: ='Cash Flow'!E9 -> 0.3 | F14: ='Cash Flow'!F9 -> 0.43 | G14: ='Cash Flow'!G9 -> 0.55 | H14: ='Cash Flow'!H9 -> 0.67 | I14: ='Cash Flow'!I9 -> 0.79

Sheet Monte Carlo
A1: MONTE CARLO — ONE 16-FACTOR MODEL (50,000 paths, seed 42)
A2: Seven continuous factors compound daily; nine discrete events arrive as jumps. Idiosyncratic noise tops up to realized 3M vol.
A4: CORE INPUTS
A5: Anchor price (KRW, 26-Jun-26) | B5: 33150
A6: Horizon T+20 (sessions) | B6: 20
A7: Horizon T+60 (sessions) | B7: 60
A8: Idiosyncratic 3M volatility | B8: 0.239
A9: 52-week low reference (KRW) | B9: 32250
A10: Round / support level (KRW) | B10: 32000
A11: SMA50 / structure (KRW) | B11: 42949
A12: 52-week high reference (KRW) | B12: 71600
A14: SEVEN CONTINUOUS FACTORS
A15: Factor | B15: 3M drift | C15: 3M vol | H15: Channel
A16: KakaoTalk ad & commerce trajectory | B16: 0.01 | C16: 0.06 | H16: master domestic ad/commerce driver
A17: AI monetization (OpenAI / Kanana) ramp | B17: 0.005 | C17: 0.05 | H17: AI optionality (early)
A18: KOSPI / foreign-flows beta | B18: 0 | C18: 0.06 | H18: market liquidity
A19: USD/KRW translation | B19: 0 | C19: 0.03 | H19: domestic — minimal FX
A20: New Initiatives loss trajectory (narrowing) | B20: 0.003 | C20: 0.03 | H20: narrowing losses
A21: Ad-market / consumer-spend softness | B21: -0.01 | C21: 0.04 | H21: ad-cycle softness
A22: Content / Games trajectory | B22: -0.006 | C22: 0.03 | H22: content/games drag
A24: NINE DISCRETE EVENTS
A25: Event | B25: Prob | C25: Impact mu | D25: Impact sigma | H25: Channel
A26: AI traction / ChatGPT-in-Kakao monetization | B26: 0.35 | C26: 0.07 | D26: 0.04 | H26: pivotal upside catalyst
A27: Holdco-discount compression / value-up (treasury cxl) | B27: 0.35 | C27: 0.05 | D27: 0.03 | H27: value-up / activist
A28: Stake crystallization (Kakao Ent or Mobility sale/IPO) | B28: 0.3 | C28: 0.05 | D28: 0.04 | H28: portfolio crystallization
A29: KakaoBank / KakaoPay re-rating | B29: 0.3 | C29: 0.03 | D29: 0.03 | H29: sub re-rating
A30: Quarterly ad/commerce surprise (two-sided) | B30: 0.4 | C30: 0.02 | D30: 0.05 | H30: two-sided
A31: Ad-market / commerce disappointment | B31: 0.35 | C31: -0.06 | D31: 0.04 | H31: demand left-tail
A32: Regulatory / antitrust action (platform law) | B32: 0.3 | C32: -0.05 | D32: 0.04 | H32: policy shock
A33: Founder-acquittal appeal revives bank-divestiture risk | B33: 0.15 | C33: -0.08 | D33: 0.05 | H33: removes/revives bank risk
A34: Broad KOSPI / EM risk-off | B34: 0.25 | C34: -0.06 | D34: 0.04 | H34: market risk-off
A36: FACTOR MOMENTS (live)
A37: Expected 3M log-return mu | B37: =SUM(B16:B22)+SUMPRODUCT(B26:B34,C26:C34) -> 0.013
A38: 3M variance | B38: =SUMPRODUCT(C16:C22,C16:C22)+SUMPRODUCT(B26:B34,D26:D34^2+(1-B26:B34)*C26:C34^2)+B8^2 -> 0.0808895
A39: 3M volatility sigma | B39: =SQRT(B38) -> 0.28441079
A40: Annualized vol (x2) | B40: =B39*2 -> 0.56882159 | H40: engine total 3M vol ~28.5% (ann ~57%)
A42: PERCENTILES (KRW/share)
A43: Horizon | B43: 5% | C43: 25% | D43: Median | E43: 75% | F43: 95% | G43: Source
A44: T+20 — engine (simulated) | B44: 25397 | C44: 29794 | D44: 33300 | E44: 37199 | F44: 43720 | G44: 50k paths · seed 42
A45: T+20 — closed-form (live) | B45: =$B$5*EXP($B$37*20/60+(-1.6449)*$B$39*SQRT(20/60)) -> 25413.38 | C45: =$B$5*EXP($B$37*20/60+(-0.6745)*$B$39*SQRT(20/60)) -> 29803.326 | D45: =$B$5*EXP($B$37*20/60+(0)*$B$39*SQRT(20/60)) -> 33293.962 | E45: =$B$5*EXP($B$37*20/60+(0.6745)*$B$39*SQRT(20/60)) -> 37193.428 | F45: =$B$5*EXP($B$37*20/60+(1.6449)*$B$39*SQRT(20/60)) -> 43618.278
...

Sheet Sensitivity
A1: SENSITIVITY — value/share (KRW)
A2: Top: SOTP holdco discount x Kakao Entertainment EV. Bottom: DCF WACC x terminal growth. Both computed live.
A4: SOTP: Holdco discount (down) / Kakao Entertainment EV, KRW tn (right)
A5: disc / Ent EV | B5: 6 | C5: 7 | D5: 8 | E5: 9 | F5: 10
A6: 0.42 | B6: =((Assumptions!$D$16+0.6603*6+Assumptions!$B$21*Assumptions!$C$21+Assumptions!$C$22+Assumptions!$C$23)/Assumptions!$B$6*1000)*(1-$A6) -> 28298.159 | C6: =((Assumptions!$D$16+0.6603*7+Assumptions!$B$21*Assumptions!$C$21+Assumptions!$C$22+Assumptions!$C$23)/Assumptions!$B$6*1000)*(1-$A6) -> 29167.172 | D6: =((Assumptions!$D$16+0.6603*8+Assumptions!$B$21*Assumptions!$C$21+Assumptions!$C$22+Assumptions!$C$23)/Assumptions!$B$6*1000)*(1-$A6) -> 30036.185 | E6: =((Assumptions!$D$16+0.6603*9+Assumptions!$B$21*Assumptions!$C$21+Assumptions!$C$22+Assumptions!$C$23)/Assumptions!$B$6*1000)*(1-$A6) -> 30905.198 | F6: =((Assumptions!$D$16+0.6603*10+Assumptions!$B$21*Assumptions!$C$21+Assumptions!$C$22+Assumptions!$C$23)/Assumptions!$B$6*1000)*(1-$A6) -> 31774.211
A7: 0.37 | B7: =((Assumptions!$D$16+0.6603*6+Assumptions!$B$21*Assumptions!$C$21+Assumptions!$C$22+Assumptions!$C$23)/Assumptions!$B$6*1000)*(1-$A7) -> 30737.656 | C7: =((Assumptions!$D$16+0.6603*7+Assumptions!$B$21*Assumptions!$C$21+Assumptions!$C$22+Assumptions!$C$23)/Assumptions!$B$6*1000)*(1-$A7) -> 31681.584 | D7: =((Assumptions!$D$16+0.6603*8+Assumptions!$B$21*Assumptions!$C$21+Assumptions!$C$22+Assumptions!$C$23)/Assumptions!$B$6*1000)*(1-$A7) -> 32625.511 | E7: =((Assumptions!$D$16+0.6603*9+Assumptions!$B$21*Assumptions!$C$21+Assumptions!$C$22+Assumptions!$C$23)/Assumptions!$B$6*1000)*(1-$A7) -> 33569.439 | F7: =((Assumptions!$D$16+0.6603*10+Assumptions!$B$21*Assumptions!$C$21+Assumptions!$C$22+Assumptions!$C$23)/Assumptions!$B$6*1000)*(1-$A7) -> 34513.367
A8: 0.32 | B8: =((Assumptions!$D$16+0.6603*6+Assumptions!$B$21*Assumptions!$C$21+Assumptions!$C$22+Assumptions!$C$23)/Assumptions!$B$6*1000)*(1-$A8) -> 33177.152 | C8: =((Assumptions!$D$16+0.6603*7+Assumptions!$B$21*Assumptions!$C$21+Assumptions!$C$22+Assumptions!$C$23)/Assumptions!$B$6*1000)*(1-$A8) -> 34195.995 | D8: =((Assumptions!$D$16+0.6603*8+Assumptions!$B$21*Assumptions!$C$21+Assumptions!$C$22+Assumptions!$C$23)/Assumptions!$B$6*1000)*(1-$A8) -> 35214.838 | E8: =((Assumptions!$D$16+0.6603*9+Assumptions!$B$21*Assumptions!$C$21+Assumptions!$C$22+Assumptions!$C$23)/Assumptions!$B$6*1000)*(1-$A8) -> 36233.68 | F8: =((Assumptions!$D$16+0.6603*10+Assumptions!$B$21*Assumptions!$C$21+Assumptions!$C$22+Assumptions!$C$23)/Assumptions!$B$6*1000)*(1-$A8) -> 37252.523
A9: 0.27 | B9: =((Assumptions!$D$16+0.6603*6+Assumptions!$B$21*Assumptions!$C$21+Assumptions!$C$22+Assumptions!$C$23)/Assumptions!$B$6*1000)*(1-$A9) -> 35616.649 | C9: =((Assumptions!$D$16+0.6603*7+Assumptions!$B$21*Assumptions!$C$21+Assumptions!$C$22+Assumptions!$C$23)/Assumptions!$B$6*1000)*(1-$A9) -> 36710.406 | D9: =((Assumptions!$D$16+0.6603*8+Assumptions!$B$21*Assumptions!$C$21+Assumptions!$C$22+Assumptions!$C$23)/Assumptions!$B$6*1000)*(1-$A9) -> 37804.164 | E9: =((Assumptions!$D$16+0.6603*9+Assumptions!$B$21*Assumptions!$C$21+Assumptions!$C$22+Assumptions!$C$23)/Assumptions!$B$6*1000)*(1-$A9) -> 38897.922 | F9: =((Assumptions!$D$16+0.6603*10+Assumptions!$B$21*Assumptions!$C$21+Assumptions!$C$22+Assumptions!$C$23)/Assumptions!$B$6*1000)*(1-$A9) -> 39991.679
A10: 0.22 | B10: =((Assumptions!$D$16+0.6603*6+Assumptions!$B$21*Assumptions!$C$21+Assumptions!$C$22+Assumptions!$C$23)/Assumptions!$B$6*1000)*(1-$A10) -> 38056.145 | C10: =((Assumptions!$D$16+0.6603*7+Assumptions!$B$21*Assumptions!$C$21+Assumptions!$C$22+Assumptions!$C$23)/Assumptions!$B$6*1000)*(1-$A10) -> 39224.818 | D10: =((Assumptions!$D$16+0.6603*8+Assumptions!$B$21*Assumptions!$C$21+Assumptions!$C$22+Assumptions!$C$23)/Assumptions!$B$6*1000)*(1-$A10) -> 40393.49 | E10: =((Assumptions!$D$16+0.6603*9+Assumptions!$B$21*Assumptions!$C$21+Assumptions!$C$22+Assumptions!$C$23)/Assumptions!$B$6*1000)*(1-$A10) -> 41562.163 | F10: =((Assumptions!$D$16+0.6603*10+Assumptions!$B$21*Assumptions!$C$21+Assumptions!$C$22+Assumptions!$C$23)/Assumptions!$B$6*1000)*(1-$A10) -> 42730.835
A12: DCF: WACC (down) / terminal growth g (right)
A13: WACC / g | B13: 0.02 | C13: 0.025 | D13: 0.03 | E13: 0.035 | F13: 0.04
A14: 0.085 | B14: =(SUMPRODUCT(DCF!$B$10:$F$10,(1+$A14)^-{1,2,3,4,5})+DCF!$F$10*(1+0.02)/($A14-0.02)/(1+$A14)^5+Assumptions!$B$7)/Assumptions!$B$6*1000 -> 25247.123 | C14: =(SUMPRODUCT(DCF!$B$10:$F$10,(1+$A14)^-{1,2,3,4,5})+DCF!$F$10*(1+0.025)/($A14-0.025)/(1+$A14)^5+Assumptions!$B$7)/Assumptions!$B$6*1000 -> 26766.907 | D14: =(SUMPRODUCT(DCF!$B$10:$F$10,(1+$A14)^-{1,2,3,4,5})+DCF!$F$10*(1+0.03)/($A14-0.03)/(1+$A14)^5+Assumptions!$B$7)/Assumptions!$B$6*1000 -> 28563.016 | E14: =(SUMPRODUCT(DCF!$B$10:$F$10,(1+$A14)^-{1,2,3,4,5})+DCF!$F$10*(1+0.035)/($A14-0.035)/(1+$A14)^5+Assumptions!$B$7)/Assumptions!$B$6*1000 -> 30718.346 | F14: =(SUMPRODUCT(DCF!$B$10:$F$10,(1+$A14)^-{1,2,3,4,5})+DCF!$F$10*(1+0.04)/($A14-0.04)/(1+$A14)^5+Assumptions!$B$7)/Assumptions!$B$6*1000 -> 33352.639
A15: 0.09 | B15: =(SUMPRODUCT(DCF!$B$10:$F$10,(1+$A15)^-{1,2,3,4,5})+DCF!$F$10*(1+0.02)/($A15-0.02)/(1+$A15)^5+Assumptions!$B$7)/Assumptions!$B$6*1000 -> 23592.188 | C15: =(SUMPRODUCT(DCF!$B$10:$F$10,(1+$A15)^-{1,2,3,4,5})+DCF!$F$10*(1+0.025)/($A15-0.025)/(1+$A15)^5+Assumptions!$B$7)/Assumptions!$B$6*1000 -> 24871.122 | D15: =(SUMPRODUCT(DCF!$B$10:$F$10,(1+$A15)^-{1,2,3,4,5})+DCF!$F$10*(1+0.03)/($A15-0.03)/(1+$A15)^5+Assumptions!$B$7)/Assumptions!$B$6*1000 -> 26363.212 | E15: =(SUMPRODUCT(DCF!$B$10:$F$10,(1+$A15)^-{1,2,3,4,5})+DCF!$F$10*(1+0.035)/($A15-0.035)/(1+$A15)^5+Assumptions!$B$7)/Assumptions!$B$6*1000 -> 28126.59 | F15: =(SUMPRODUCT(DCF!$B$10:$F$10,(1+$A15)^-{1,2,3,4,5})+DCF!$F$10*(1+0.04)/($A15-0.04)/(1+$A15)^5+Assumptions!$B$7)/Assumptions!$B$6*1000 -> 30242.645
A16: 0.095 | B16: =(SUMPRODUCT(DCF!$B$10:$F$10,(1+$A16)^-{1,2,3,4,5})+DCF!$F$10*(1+0.02)/($A16-0.02)/(1+$A16)^5+Assumptions!$B$7)/Assumptions!$B$6*1000 -> 22159.435 | C16: =(SUMPRODUCT(DCF!$B$10:$F$10,(1+$A16)^-{1,2,3,4,5})+DCF!$F$10*(1+0.025)/($A16-0.025)/(1+$A16)^5+Assumptions!$B$7)/Assumptions!$B$6*1000 -> 23247.737 | D16: =(SUMPRODUCT(DCF!$B$10:$F$10,(1+$A16)^-{1,2,3,4,5})+DCF!$F$10*(1+0.03)/($A16-0.03)/(1+$A16)^5+Assumptions!$B$7)/Assumptions!$B$6*1000 -> 24503.471 | E16: =(SUMPRODUCT(DCF!$B$10:$F$10,(1+$A16)^-{1,2,3,4,5})+DCF!$F$10*(1+0.035)/($A16-0.035)/(1+$A16)^5+Assumptions!$B$7)/Assumptions!$B$6*1000 -> 25968.494 | F16: =(SUMPRODUCT(DCF!$B$10:$F$10,(1+$A16)^-{1,2,3,4,5})+DCF!$F$10*(1+0.04)/($A16-0.04)/(1+$A16)^5+Assumptions!$B$7)/Assumptions!$B$6*1000 -> 27699.885
A17: 0.1 | B17: =(SUMPRODUCT(DCF!$B$10:$F$10,(1+$A17)^-{1,2,3,4,5})+DCF!$F$10*(1+0.02)/($A17-0.02)/(1+$A17)^5+Assumptions!$B$7)/Assumptions!$B$6*1000 -> 20907.171 | C17: =(SUMPRODUCT(DCF!$B$10:$F$10,(1+$A17)^-{1,2,3,4,5})+DCF!$F$10*(1+0.025)/($A17-0.025)/(1+$A17)^5+Assumptions!$B$7)/Assumptions!$B$6*1000 -> 21842.239 | D17: =(SUMPRODUCT(DCF!$B$10:$F$10,(1+$A17)^-{1,2,3,4,5})+DCF!$F$10*(1+0.03)/($A17-0.03)/(1+$A17)^5+Assumptions!$B$7)/Assumptions!$B$6*1000 -> 22910.889 | E17: =(SUMPRODUCT(DCF!$B$10:$F$10,(1+$A17)^-{1,2,3,4,5})+DCF!$F$10*(1+0.035)/($A17-0.035)/(1+$A17)^5+Assumptions!$B$7)/Assumptions!$B$6*1000 -> 24143.947 | F17: =(SUMPRODUCT(DCF!$B$10:$F$10,(1+$A17)^-{1,2,3,4,5})+DCF!$F$10*(1+0.04)/($A17-0.04)/(1+$A17)^5+Assumptions!$B$7)/Assumptions!$B$6*1000 -> 25582.514
A18: 0.105 | B18: =(SUMPRODUCT(DCF!$B$10:$F$10,(1+$A18)^-{1,2,3,4,5})+DCF!$F$10*(1+0.02)/($A18-0.02)/(1+$A18)^5+Assumptions!$B$7)/Assumptions!$B$6*1000 -> 19803.515 | C18: =(SUMPRODUCT(DCF!$B$10:$F$10,(1+$A18)^-{1,2,3,4,5})+DCF!$F$10*(1+0.025)/($A18-0.025)/(1+$A18)^5+Assumptions!$B$7)/Assumptions!$B$6*1000 -> 20613.743 | D18: =(SUMPRODUCT(DCF!$B$10:$F$10,(1+$A18)^-{1,2,3,4,5})+DCF!$F$10*(1+0.03)/($A18-0.03)/(1+$A18)^5+Assumptions!$B$7)/Assumptions!$B$6*1000 -> 21532.002 | E18: =(SUMPRODUCT(DCF!$B$10:$F$10,(1+$A18)^-{1,2,3,4,5})+DCF!$F$10*(1+0.035)/($A18-0.035)/(1+$A18)^5+Assumptions!$B$7)/Assumptions!$B$6*1000 -> 22581.441 | F18: =(SUMPRODUCT(DCF!$B$10:$F$10,(1+$A18)^-{1,2,3,4,5})+DCF!$F$10*(1+0.04)/($A18-0.04)/(1+$A18)^5+Assumptions!$B$7)/Assumptions!$B$6*1000 -> 23792.332
A20: SOTP grid flexes the two biggest swing factors — the holdco discount and the Kakao Entertainment mark — with all else at base. DCF grid flexes WACC and terminal growth on the fixed explicit FCFF. The DCF stays well below the SOTP across the grid because it excludes the equity-method stake values. Base case: discount 32%, Ent EV KRW 8tn; WACC 9.5%, g 3.0%.

Sheet Per-Share & Ratios
A1: PER-SHARE & RATIOS (at spot)
A2: Drivers link to Income Statement / Balance Sheet / Assumptions. Multiples reflect that reported earnings exclude most stake value.
A5: Share price (KRW, 26-Jun-26) | B5: =Assumptions!B5 -> 33150
A6: Shares outstanding (bn) | B6: =Assumptions!B6 -> 0.4407
A7: Market cap (KRW tn) | B7: =Assumptions!B5*Assumptions!B6/1000 -> 14.609205
A8: 2025a EPS (KRW) | B8: ='Income Statement'!D17 -> 1202.6322
A9: Normalized EPS (KRW) | B9: =Assumptions!B33/Assumptions!B6*1000 -> 1497.6174
A10: BVPS (KRW) | B10: ='Balance Sheet'!D25 -> 23825.732
A11: Parent net cash per share (KRW) | B11: =Assumptions!B7/Assumptions!B6*1000 -> 3403.676
A12: P/E on 2025a (x) | B12: =B5/B8 -> 27.564538
A13: P/E normalized (x) | B13: =B5/B9 -> 22.135159
A14: P/B (x) | B14: =B5/B10 -> 1.3913529
A15: Gross NAV per share (KRW) | B15: =SOTP!B14 -> 51786.526
A16: Discount to gross NAV at spot | B16: =B5/B15-1 -> -0.3598721
A18: Kakao trades at a high P/E on reported earnings because those earnings capture little of the listed-stake value — which is exactly why the holding-company SOTP (not the P/E) is the primary lens. P/B near ~1x and the discount to gross NAV (~36% at spot) are the more informative gauges. The parent net-cash-per-share figure is a conservative floor element.

Sheet Peer & Sector
A1: PEER & SECTOR CONTEXT — Korean internet / platform
A2: External sourced data (not model outputs). Verify live before use. As of mid-2026.
A4: Metric | B4: Kakao (035720) | C4: Naver (035420) | D4: NCsoft / Krafton
A5: Business | B5: Messaging platform + holdco | C5: Search/commerce/content | D5: Games
A6: Fwd P/E (x) | B6: ~25x (depressed earnings) | C6: ~12-16x | D6: varies
A7: EV/EBITDA (x) | B7: ~9-11x | C7: ~9-14x | D7: varies
A8: Holdco discount | B8: ~36% to gross NAV | C8: n/a (operating co) | D8: n/a
A9: Key listed stakes | B9: KakaoBank, KakaoPay, Games, SM | C9: minimal | D9: -
A10: 2025 revenue trend | B10: +modest, record net | C10: steady growth | D10: cyclical
A11: AI angle | B11: OpenAI tie-up + Kanana | C11: HyperCLOVA X | D11: -
A13: Kakao screens optically expensive on P/E versus Naver, but that comparison is misleading: Kakao is a holding company whose value sits largely in listed and unlisted stakes outside its reported earnings, while Naver is more of a pure operating company. The relevant gauges for Kakao are the discount to gross NAV and the stake marks. Sources: company IR, sector trackers; verify live.
