Workbook

Sheet READ FIRST
A1: Testahil — Independent Valuation Study · Educational analysis, not investment advice
A5: LULU — Lulu Retail Holdings PLC (ADX: LULU) · anchor AED 0.94, 10 July 2026
A7: WHAT THIS IS. A valuation exercise published free of charge for educational purposes. It is NOT investment advice,
A8: NOT a recommendation, and NOT a price target. The preparer is not licensed by any securities regulator. Every output
A9: is a range or a distribution. No single number here should be relied upon.
A11: HOW TO USE IT. Every BLUE cell on Assumptions is an input; everything else is a live formula pointing at one. Change
A12: a blue cell and the DCF, the relative lens, the DDM, the normalized lens and the football field all recompute.
A14: THE THREE CLOCKS, KEPT SEPARATE.
A15: T+60 sessions Monte Carlo price probabilities. Its drift is the money-market carry — never the fair-value gap.
A16: ~12 months The weighted fundamental central. A risk-adjusted range, not a target.
A17: Multi-year The DCF. A statement about terminal economics, not a 2026 expectation.
A19: TWO THINGS TO KNOW BEFORE ANY NUMBER.
... A29: ratios, flagged on Assumptions, and flagged as a derivation. No aggregator supplies a financial line.

Sheet Assumptions
A1: Assumptions — the single input layer
A2: BLUE = hardcoded input. Every other cell in this workbook is a formula pointing here. DERIVED lines are flagged.
A4: Market & shares
A5: Spot price (AED, 10-Jul-2026 close) | B5: 0.94 | C5: ADX close, from the attached daily history
A6: Shares outstanding (mn) | B6: 10328.9 | C6: FY2025 audited FS, Note 1
A7: AED / USD peg | B7: 3.6725 | C7: Central Bank of the UAE — fixed
A8: Market cap (AED mn) | B8: =Assumptions!$B$5*Assumptions!$B$6 -> 9709.166 | C8: formula
A9: Market cap (US$ mn) | B9: =Assumptions!$B$8/Assumptions!$B$7 -> 2643.7484 | C9: formula
A11: FY2025 audited base (US$ mn) — company disclosure only
A12: Revenue | B12: 7933.97 | C12: FY2025 audited FS
A13: Gross profit | B13: 1822.836 | C13: FY2025 audited FS
A14: Other operating income | B14: 302.553 | C14: FY2025 audited FS
A15: Operating expenses (incl. D&A) | B15: -1731.157 | C15: FY2025 audited FS
A16: EBIT | B16: =Assumptions!$B$13+Assumptions!$B$14+Assumptions!$B$15 -> 394.232 | C16: formula
A17: D&A — property, plant & equipment | B17: 167.018 | C17: FY2025 audited FS
A18: D&A — right-of-use assets | B18: 219.381 | C18: FY2025 audited FS
A19: D&A — investment property | B19: 1.547 | C19: FY2025 audited FS
A20: EBITDA (reconciled — ties to co.-stated 782.2) | B20: =Assumptions!$B$16+Assumptions!$B$17+Assumptions!$B$18+Assumptions!$B$19 -> 782.178 | C20: formula
A21: Finance costs, net | B21: -162.201 | C21: FY2025 audited FS
A22: Tax | B22: -27.499 | C22: FY2025 audited FS
A23: Net profit | B23: =Assumptions!$B$16+Assumptions!$B$21+Assumptions!$B$22 -> 204.532 | C23: formula
A24: Interest expense (FY2025) | B24: 149.421 | C24: FY2025 audited FS
A25: Revenue FY2024 (base for ΔWC) | B25: 7620.802 | C25: FY2024 audited FS
A27: Balance sheet & the derived debt split (US$ mn)
A28: Cash & equivalents | B28: 329.543 | C28: FY2025 audited FS
A29: Right-of-use assets | B29: 1765.769 | C29: FY2025 audited FS
A30: Net debt / EBITDA — IFRS-16 basis | B30: 3.2 | C30: company-stated, FY2025
A31: Net debt / EBITDA — excluding leases | B31: 1.1 | C31: company-stated, FY2025
A32: Net debt, IFRS-16 (DERIVED) | B32: =Assumptions!$B$30*Assumptions!$B$20 -> 2502.9696 | C32: DERIVED from the stated ratio
A33: Net debt, ex-lease (DERIVED) | B33: =Assumptions!$B$31*Assumptions!$B$20 -> 860.3958 | C33: DERIVED from the stated ratio
A34: Lease liabilities (DERIVED) | B34: =Assumptions!$B$32-Assumptions!$B$33 -> 1642.5738 | C34: DERIVED — cross-check: 93% of RoU
A35: Gross bank debt (DERIVED) | B35: =Assumptions!$B$33+Assumptions!$B$28 -> 1189.9388 | C35: DERIVED
A36: Total interest-bearing debt | B36: =Assumptions!$B$34+Assumptions!$B$35 -> 2832.5126 | C36: formula
A37: Lease liabilities as % of RoU assets | B37: =Assumptions!$B$34/Assumptions!$B$29 -> 0.93023142 | C37: the cross-check on the derivation
A38: RoU additions FY2025 (DERIVED) | B38: 258.757 | C38: DERIVED from the RoU roll-forward
A39: Operating WC / revenue | B39: 0.0448 | C39: FY2023 — last year payables are disclosed
A41: Cost of capital
A42: Risk-free rate (rf) | B42: 0.043 | C42: AED T-Bond Jan-2031, MoF auction 23-May-26 — LOCAL bond
A43: ERP — rating basis | B43: 0.0487 | C43: Damodaran ORIGINAL ctryprem.html, 5-Jan-26, UAE Aa2
A44: ERP — CDS basis | B44: 0.0493 | C44: same file, Abu Dhabi CDS (no UAE-federal row)
...

Sheet Segments
A1: The engine — six countries, driven by SPACE and DENSITY (US$ mn)
A2: space(t) = space(t−1) + new stores × new-store size · revenue(t) = revenue(t−1) × (1+space growth) × (1+density growth) · opex(t) = opex(t−1) × (1+space growth) × (1+mature-store inflation) · EBITDA = revenue × contribution − opex
A4: RETAIL SPACE (m sqm) | B4: FY25A | C4: FY26E | D4: FY27E | E4: FY28E | F4: FY29E | G4: FY30E | H4: Q1-26 actual sqm
A5: UAE | B5: 0.52627151 | C5: =B5+Assumptions!B$98*Assumptions!$B$66/1000000+$H$5/1000000 -> 0.54543651 | D5: =C5+Assumptions!C$98*Assumptions!$B$66/1000000 -> 0.56503651 | E5: =D5+Assumptions!D$98*Assumptions!$B$66/1000000 -> 0.58463651 | F5: =E5+Assumptions!E$98*Assumptions!$B$66/1000000 -> 0.60143651 | G5: =F5+Assumptions!F$98*Assumptions!$B$66/1000000 -> 0.61823651 | H5: 10765
A6: KSA | B6: 0.33814986 | C6: =B6+Assumptions!B$99*Assumptions!$B$66/1000000+$H$6/1000000 -> 0.35021386 | D6: =C6+Assumptions!C$99*Assumptions!$B$66/1000000 -> 0.36421386 | E6: =D6+Assumptions!D$99*Assumptions!$B$66/1000000 -> 0.37821386 | F6: =E6+Assumptions!E$99*Assumptions!$B$66/1000000 -> 0.38941386 | G6: =F6+Assumptions!F$99*Assumptions!$B$66/1000000 -> 0.40061386 | H6: 3664
A7: Oman | B7: 0.21211517 | C7: =B7+Assumptions!B$100*Assumptions!$B$66/1000000+$H$7/1000000 -> 0.21674717 | D7: =C7+Assumptions!C$100*Assumptions!$B$66/1000000 -> 0.22234717 | E7: =D7+Assumptions!D$100*Assumptions!$B$66/1000000 -> 0.22794717 | F7: =E7+Assumptions!E$100*Assumptions!$B$66/1000000 -> 0.23354717 | G7: =F7+Assumptions!F$100*Assumptions!$B$66/1000000 -> 0.23914717 | H7: 1832
A8: Qatar | B8: 0.12429186 | C8: =B8+Assumptions!B$101*Assumptions!$B$66/1000000+$H$8/1000000 -> 0.12709186 | D8: =C8+Assumptions!C$101*Assumptions!$B$66/1000000 -> 0.12989186 | E8: =D8+Assumptions!D$101*Assumptions!$B$66/1000000 -> 0.13269186 | F8: =E8+Assumptions!E$101*Assumptions!$B$66/1000000 -> 0.13549186 | G8: =F8+Assumptions!F$101*Assumptions!$B$66/1000000 -> 0.13829186 | H8: 0
A9: Kuwait | B9: 0.089566143 | C9: =B9+Assumptions!B$102*Assumptions!$B$66/1000000+$H$9/1000000 -> 0.093230143 | D9: =C9+Assumptions!C$102*Assumptions!$B$66/1000000 -> 0.096030143 | E9: =D9+Assumptions!D$102*Assumptions!$B$66/1000000 -> 0.098830143 | F9: =E9+Assumptions!E$102*Assumptions!$B$66/1000000 -> 0.10163014 | G9: =F9+Assumptions!F$102*Assumptions!$B$66/1000000 -> 0.10443014 | H9: 3664
A10: Other | B10: 0.089605459 | C10: =B10+Assumptions!B$103*Assumptions!$B$66/1000000+$H$10/1000000 -> 0.089605459 | D10: =C10+Assumptions!C$103*Assumptions!$B$66/1000000 -> 0.089605459 | E10: =D10+Assumptions!D$103*Assumptions!$B$66/1000000 -> 0.089605459 | F10: =E10+Assumptions!E$103*Assumptions!$B$66/1000000 -> 0.089605459 | G10: =F10+Assumptions!F$103*Assumptions!$B$66/1000000 -> 0.089605459 | H10: 0
A11: GROUP SPACE | B11: =SUM(B5:B10) -> 1.38 | C11: =SUM(C5:C10) -> 1.422325 | D11: =SUM(D5:D10) -> 1.467125 | E11: =SUM(E5:E10) -> 1.511925 | F11: =SUM(F5:F10) -> 1.551125 | G11: =SUM(G5:G10) -> 1.590325
A12: space growth | C12: =C11/B11-1 -> 0.03067029 | D12: =D11/C11-1 -> 0.031497724 | E12: =E11/D11-1 -> 0.030535912 | F12: =F11/E11-1 -> 0.025927212 | G12: =G11/F11-1 -> 0.02527198
A14: REVENUE = prior × (1 + space growth) × (1 + DENSITY growth) | B14: FY25A | C14: FY26E | D14: FY27E | E14: FY28E | F14: FY29E | G14: FY30E
A15: UAE | B15: 2920 | C15: =B15*(C5/B5)*(1+Assumptions!B$89) -> 2980.9413 | D15: =C15*(D5/C5)*(1+Assumptions!C$89) -> 3103.5003 | E15: =D15*(E5/D5)*(1+Assumptions!D$89) -> 3227.2104 | F15: =E15*(F5/E5)*(1+Assumptions!E$89) -> 3336.5466 | G15: =F15*(G5/F5)*(1+Assumptions!F$89) -> 3446.8955
A16: KSA | B16: 1518 | C16: =B16*(C6/B6)*(1+Assumptions!B$90) -> 1517.1314 | D16: =C16*(D6/C6)*(1+Assumptions!C$90) -> 1577.7796 | E16: =D16*(E6/D6)*(1+Assumptions!D$90) -> 1638.4278 | F16: =E16*(F6/E6)*(1+Assumptions!E$90) -> 1686.9464 | G16: =F16*(G6/F6)*(1+Assumptions!F$90) -> 1735.4649
A17: Oman | B17: 1189 | C17: =B17*(C7/B7)*(1+Assumptions!B$91) -> 1190.6651 | D17: =C17*(D7/C7)*(1+Assumptions!C$91) -> 1227.535 | E17: =D17*(E7/D7)*(1+Assumptions!D$91) -> 1264.7437 | F17: =E17*(F7/E7)*(1+Assumptions!E$91) -> 1302.2939 | G17: =F17*(G7/F7)*(1+Assumptions!F$91) -> 1340.1879
A18: Qatar | B18: 1122 | C18: =B18*(C8/B8)*(1+Assumptions!B$92) -> 1124.3305 | D18: =C18*(D8/C8)*(1+Assumptions!C$92) -> 1154.8464 | E18: =D18*(E8/D8)*(1+Assumptions!D$92) -> 1185.6395 | F18: =E18*(F8/E8)*(1+Assumptions!E$92) -> 1216.7116 | G18: =F18*(G8/F8)*(1+Assumptions!F$92) -> 1248.0647
A19: Kuwait | B19: 696 | C19: =B19*(C9/B9)*(1+Assumptions!B$93) -> 717.22747 | D19: =C19*(D9/C9)*(1+Assumptions!C$93) -> 746.15579 | E19: =D19*(E9/D9)*(1+Assumptions!D$93) -> 775.59095 | F19: =E19*(F9/E9)*(1+Assumptions!E$93) -> 805.5402 | G19: =F19*(G9/F9)*(1+Assumptions!F$93) -> 836.01088
A20: Other | B20: 489 | C20: =B20*(C10/B10)*(1+Assumptions!B$94) -> 479.22 | D20: =C20*(D10/C10)*(1+Assumptions!C$94) -> 481.6161 | E20: =D20*(E10/D10)*(1+Assumptions!D$94) -> 484.02418 | F20: =E20*(F10/E10)*(1+Assumptions!E$94) -> 486.4443 | G20: =F20*(G10/F10)*(1+Assumptions!F$94) -> 488.87652
A21: GROUP REVENUE | B21: =SUM(B15:B20) -> 7934 | C21: =SUM(C15:C20) -> 8009.5158 | D21: =SUM(D15:D20) -> 8291.4332 | E21: =SUM(E15:E20) -> 8575.6365 | F21: =SUM(F15:F20) -> 8834.4829 | G21: =SUM(G15:G20) -> 9095.5005
A22: revenue growth | C22: =C21/B21-1 -> 0.0095180001 | D22: =D21/C21-1 -> 0.035197811 | E22: =E21/D21-1 -> 0.034276739 | F22: =F21/E21-1 -> 0.030183928 | G22: =G21/F21-1 -> 0.029545313
A23: GROUP SALES DENSITY (US$/sqm) | B23: =B21/B11 -> 5749.2754 | C23: =C21/C11 -> 5631.2839 | D23: =D21/D11 -> 5651.4838 | E23: =E21/E11 -> 5671.9986 | F23: =F21/F11 -> 5695.5325 | G23: =G21/G11 -> 5719.2715
A25: CASH OPEX = prior × (1 + space growth) × (1 + MATURE-store inflation) | B25: FY25A | C25: FY26E | D25: FY27E | E25: FY28E | F25: FY29E | G25: FY30E
A26: UAE | B26: =B15*Assumptions!$B$69-B36 -> 424.72326 | C26: =B26*(C5/B5)*(1+Assumptions!B$84) -> 433.58737 | D26: =C26*(D5/C5)*(1+Assumptions!C$84) -> 451.41396 | E26: =D26*(E5/D5)*(1+Assumptions!D$84) -> 469.40799 | F26: =E26*(F5/E5)*(1+Assumptions!E$84) -> 485.31129 | G26: =F26*(G5/F5)*(1+Assumptions!F$84) -> 501.36188
A27: KSA | B27: =B16*Assumptions!$B$69-B37 -> 335.94894 | C27: =B27*(C6/B6)*(1+Assumptions!B$84) -> 342.7154 | D27: =C27*(D6/C6)*(1+Assumptions!C$84) -> 358.19773 | E27: =D27*(E6/D6)*(1+Assumptions!D$84) -> 373.82631 | F27: =E27*(F6/E6)*(1+Assumptions!E$84) -> 386.82086 | G27: =F27*(G6/F6)*(1+Assumptions!F$84) -> 399.93601
A28: Oman | B28: =B17*Assumptions!$B$69-B38 -> 186.11488 | C28: =B28*(C7/B7)*(1+Assumptions!B$84) -> 187.32642 | D28: =C28*(D7/C7)*(1+Assumptions!C$84) -> 193.12712 | E28: =D28*(E7/D7)*(1+Assumptions!D$84) -> 198.98115 | F28: =E28*(F7/E7)*(1+Assumptions!E$84) -> 204.88888 | G28: =F28*(G7/F7)*(1+Assumptions!F$84) -> 210.85072
A29: Qatar | B29: =B18*Assumptions!$B$69-B39 -> 167.56661 | C29: =B29*(C8/B8)*(1+Assumptions!B$84) -> 168.77136 | D29: =C29*(D8/C8)*(1+Assumptions!C$84) -> 173.35207 | E29: =D29*(E8/D8)*(1+Assumptions!D$84) -> 177.97436 | F29: =E29*(F8/E8)*(1+Assumptions!E$84) -> 182.63853 | G29: =F29*(G8/F8)*(1+Assumptions!F$84) -> 187.34491
A30: Kuwait | B30: =B19*Assumptions!$B$69-B40 -> 87.547736 | C30: =B30*(C9/B9)*(1+Assumptions!B$84) -> 89.762229 | D30: =C30*(D9/C9)*(1+Assumptions!C$84) -> 92.920367 | E30: =D30*(E9/D9)*(1+Assumptions!D$84) -> 96.107842 | F30: =E30*(F9/E9)*(1+Assumptions!E$84) -> 99.324869 | G30: =F30*(G9/F9)*(1+Assumptions!F$84) -> 102.57166
A31: Other | B31: =B20*Assumptions!$B$69-B41 -> 141.31761 | C31: =B31*(C10/B10)*(1+Assumptions!B$84) -> 139.19784 | D31: =C31*(D10/C10)*(1+Assumptions!C$84) -> 139.89383 | E31: =D31*(E10/D10)*(1+Assumptions!D$84) -> 140.5933 | F31: =E31*(F10/E10)*(1+Assumptions!E$84) -> 141.29627 | G31: =F31*(G10/F10)*(1+Assumptions!F$84) -> 142.00275
A32: GROUP CASH OPEX | B32: =SUM(B26:B31) -> 1343.219 | C32: =SUM(C26:C31) -> 1361.3606 | D32: =SUM(D26:D31) -> 1408.9051 | E32: =SUM(E26:E31) -> 1456.8909 | F32: =SUM(F26:F31) -> 1500.2807 | G32: =SUM(G26:G31) -> 1544.0679
A33: opex growth | C33: =C32/B32-1 -> 0.013506058 | D33: =D32/C32-1 -> 0.034924213 | E33: =E32/D32-1 -> 0.034058972 | F33: =F32/E32-1 -> 0.029782437 | G33: =G32/F32-1 -> 0.02918603
A35: EBITDA = revenue × contribution − cash opex | B35: FY25A | C35: FY26E | D35: FY27E | E35: FY28E | F35: FY29E | G35: FY30E
A36: UAE | B36: 357.5 | C36: =C15*Assumptions!B$85-C26 -> 361.9802 | D36: =D15*Assumptions!C$85-D26 -> 379.96622 | E36: =E15*Assumptions!D$85-E26 -> 395.11223 | F36: =F15*Assumptions!E$85-F26 -> 408.49843 | G36: =G15*Assumptions!F$85-G26 -> 422.00861
A37: KSA | B37: 70.7 | C37: =C16*Assumptions!B$85-C27 -> 62.183727 | D37: =D16*Assumptions!C$85-D27 -> 64.465258 | E37: =E16*Assumptions!D$85-E27 -> 65.083403 | F37: =F16*Assumptions!E$85-F27 -> 65.086228 | G37: =G16*Assumptions!F$85-G27 -> 64.968453
A38: Oman | B38: 132.4 | C38: =C17*Assumptions!B$85-C28 -> 130.44386 | D38: =D17*Assumptions!C$85-D28 -> 135.71068 | E38: =E17*Assumptions!D$85-E28 -> 139.82431 | F38: =F17*Assumptions!E$85-F28 -> 143.97569 | G38: =G17*Assumptions!F$85-G28 -> 148.16508
A39: Qatar | B39: 133 | C39: =C18*Assumptions!B$85-C29 -> 131.29521 | D39: =D18*Assumptions!C$85-D29 -> 136.0136 | E39: =E18*Assumptions!D$85-E29 -> 139.64029 | F39: =F18*Assumptions!E$85-F29 -> 143.29985 | G39: =G18*Assumptions!F$85-G29 -> 146.99251
A40: Kuwait | B40: 98.9 | C40: =C19*Assumptions!B$85-C30 -> 101.65479 | D40: =D19*Assumptions!C$85-D30 -> 106.96334 | E40: =E19*Assumptions!D$85-E30 -> 111.66109 | F40: =F19*Assumptions!E$85-F30 -> 116.46701 | G40: =G19*Assumptions!F$85-G30 -> 121.38284
A41: Other | B41: -10.322 | C41: =C20*Assumptions!B$85-C31 -> -11.301368 | D41: =D20*Assumptions!C$85-D31 -> -10.876259 | E41: =E20*Assumptions!D$85-E31 -> -10.93064 | F41: =F20*Assumptions!E$85-F31 -> -10.985293 | G41: =G20*Assumptions!F$85-G31 -> -11.04022
A42: GROUP EBITDA | B42: =SUM(B36:B41) -> 782.178 | C42: =SUM(C36:C41) -> 776.25642 | D42: =SUM(D36:D41) -> 812.24284 | E42: =SUM(E36:E41) -> 840.39069 | F42: =SUM(F36:F41) -> 866.34191 | G42: =SUM(G36:G41) -> 892.47728
A43: EBITDA margin | B43: =B42/B21 -> 0.098585581 | C43: =C42/C21 -> 0.096916772 | D43: =D42/D21 -> 0.097961694 | E43: =E42/E21 -> 0.097997471 | F43: =F42/F21 -> 0.098063681 | G43: =G42/G21 -> 0.098122944
A45: FY2025 SEGMENT ECONOMICS — space rebuilt from the DISCLOSED format split
...

Sheet Estate & Leverage
A1: Sales density, and the cost model rebuilt from DISCLOSURE
A2: Nothing on this sheet is assumed. Every input is a figure Lulu published.
A4: THE ESTATE — sales per square metre
B5: FY2024 | C5: FY2025 | D5: Q1-2026
A6: Retail space (m sqm) | B6: =Assumptions!$B$56 -> 1.3068182 | C6: =Assumptions!$B$55 -> 1.38 | D6: =Assumptions!$B$63 -> 1.399926
A7: Revenue (US$ mn) | B7: =Assumptions!$B$25 -> 7620.802 | C7: =Assumptions!$B$12 -> 7933.97 | D7: 2020
A8: SALES DENSITY (US$ / sqm) | B8: =Assumptions!$B$58 -> 5831.5702 | C8: =Assumptions!$B$57 -> 5749.2536
A9: change, year on year | C9: =Assumptions!$B$59 -> -0.014115684 | D9: =Assumptions!$B$65 -> -0.080890461
A10: Q1-2026 space is DISCLOSED (11 Express = 20,153 sqm, less a 227 sqm Mini Market closure). The only estimate in the Q1 density figure is Q1-2025 space, which is not disclosed — so the result is BOUNDED −4.3% to −9.4%, not asserted.
A12: THE COST MODEL — calibrated on two periods, both from disclosure
B13: Space growth | C13: Cash opex growth | D13: ⇒ MATURE-store inflation | E13: Density growth
A14: FY2025 (audited) | B14: =Assumptions!$B$73 -> 0.056 | C14: =Assumptions!$B$72 -> 0.055304014 | D14: =Assumptions!$B$74 -> -0.0006590775 | E14: =Assumptions!$B$59 -> -0.014115684
A15: Q1-2026 (DISCLOSED) | B15: =Assumptions!$B$64 -> 0.056457319 | C15: =Assumptions!$B$75 -> 0.011 | D15: =Assumptions!$B$76 -> -0.04302807 | E15: =Assumptions!$B$65 -> -0.080890461
A17: BREAK-EVEN: density growth = mature-store cost inflation
A18: opex tracks SPACE. revenue tracks SPACE × DENSITY. So the margin is flat only when the density you lose equals the cost you cut from the stores you already have. Derived, not assumed.
A20: THE Q1-2026 MARGIN BRIDGE — every input DISCLOSED
A21: Q1-2025 revenue (US$ mn) | B21: 2080.3296
A22: Q1-2025 gross margin (DISCLOSED) | B22: 0.223
A23: Q1-2026 revenue (DISCLOSED) | B23: 2020
A24: Q1-2026 gross profit (DISCLOSED) | B24: 449
A25: Q1-2026 EBITDA (DISCLOSED) | B25: 192
A26: Q1-2026 cash opex growth (DISCLOSED) | B26: 0.011
A28: ⇒ Q1-2026 cash opex | B28: =B24+B23*Assumptions!$B$14/Assumptions!$B$12-B25 -> 334.03042
A29: ⇒ Q1-2025 cash opex | B29: =B28/(1+B26) -> 330.39607
A30: ⇒ Q1-2025 EBITDA | B30: =B21*B22+B21*Assumptions!$B$14/Assumptions!$B$12-B29 -> 212.84845
A31: Q1-2025 EBITDA margin | B31: =B30/B21 -> 0.10231477
A32: − contribution margin | B32: =(B24+B23*Assumptions!$B$14/Assumptions!$B$12)/B23-(B21*B22+B21*Assumptions!$B$14/Assumptions!$B$12)/B21 -> -0.00072277228
A33: − OPERATING DELEVERAGE | B33: =-(B28/B23-B29/B21) -> -0.0065424963
A34: → Q1-2026 EBITDA margin | B34: =B25/B23 -> 0.095049505
A36: Nine-tenths of the margin decline is OPERATING DELEVERAGE. The gross margin barely moved. The margin fell because revenue fell while the cost of the estate did not — and the estate had just grown.

Sheet Dividend Cover
A1: The dividend is 96% of EARNINGS and 1.4× covered by CASH — both are true
B4: FY25A | C4: FY26E | D4: FY27E | E4: FY28E | F4: FY29E | G4: FY30E
A5: EBITDA | B5: 782.178 | C5: 776.25707 | D5: 812.2435 | E5: 840.39135 | F5: 866.34258 | G5: 892.47795
A6: − cash lease payments (principal + interest) | B6: -277.86041 | C6: -286.19622 | D6: -294.78211 | E6: -303.62557 | F6: -312.73434 | G6: -322.11637
A7: − bank interest | B7: -63.066756 | C7: -63.066756 | D7: -63.066756 | E7: -63.066756 | F7: -63.066756 | G7: -63.066756
A8: − cash tax | B8: -27.499 | C8: -26.631071 | D8: -29.704932 | E8: -31.948252 | F8: -34.095907 | G8: -36.163344
A9: − capex (PPE) | B9: -138.501 | C9: -104.12378 | D9: -107.78871 | E9: -111.48335 | F9: -114.84835 | G9: -118.24158
A10: → FREE CASH FLOW | B10: =SUM(B5:B9) -> 275.25083 | C10: =SUM(C5:C9) -> 296.23924 | D10: =SUM(D5:D9) -> 316.901 | E10: =SUM(E5:E9) -> 330.26742 | F10: =SUM(F5:F9) -> 341.59722 | G10: =SUM(G5:G9) -> 352.8899
A11: Dividend bill at 7 fils | B11: 196.9 | C11: 196.87488 | D11: 196.87488 | E11: 196.87488 | F11: 196.87488 | G11: 196.87488
A12: COVER | B12: =B10/B11 -> 1.397922 | C12: =C10/C11 -> 1.5047081 | D12: =D10/D11 -> 1.6096568 | E12: =E10/E11 -> 1.6775498 | F12: =F10/F11 -> 1.735098 | G12: =G10/G11 -> 1.7924577
A14: FY2025 EPS (AED) | B14: =Assumptions!$B$23/Assumptions!$B$6*Assumptions!$B$7 -> 0.072722533
A15: FY2025 DPS declared (AED) | B15: =Assumptions!$B$122 -> 0.07
A16: FY2025 payout ratio — on EARNINGS | B16: =B15/B14 -> 0.96256273
A17: FY2025 cover — on CASH | B17: =B10/B11 -> 1.397922
A18: Stated policy payout | B18: =Assumptions!$B$121 -> 0.75
A19: Dividend yield at 7 fils | B19: =Assumptions!$B$122/Assumptions!$B$5 -> 0.074468085
A21: Both are true, and the reconciliation is that D&A (US$388mn) is nearly THREE TIMES capex (US$139mn) — because THE LEASES ARE THE CAPEX. LULU does not buy its stores; it rents them, and the rent is already deducted above as a cash lease payment. Right-of-use depreciation is a non-cash charge sitting on top of a cash rent that has already been paid. Strip the double-count and the payout is comfortable. The first version of this model read the payout off EARNINGS, called it over-distributed, and cut the forecast DPS to 5.5 fils. That was wrong: the base is 6.0 fils.

Sheet DCF
A1: DCF — the full FCFF waterfall, discounted to PV (US$ mn)
A2: Terminal = exit EV/EBITDA on FY30E EBITDA. The Gordon terminal is computed alongside it, only to show what it would have done.
B4: FY26E | C4: FY27E | D4: FY28E | E4: FY29E | F4: FY30E
A5: Revenue ← sum of the six country models | B5: =Segments!C$21 -> 8009.5158 | C5: =Segments!D$21 -> 8291.4332 | D5: =Segments!E$21 -> 8575.6365 | E5: =Segments!F$21 -> 8834.4829 | F5: =Segments!G$21 -> 9095.5005
A6: EBITDA ← sum of the six country models | B6: =Segments!C$42 -> 776.25642 | C6: =Segments!D$42 -> 812.24284 | D6: =Segments!E$42 -> 840.39069 | E6: =Segments!F$42 -> 866.34191 | F6: =Segments!G$42 -> 892.47728
A7: − D&A | B7: =-B5*Assumptions!B$108 -> -392.46627 | C7: =-C5*Assumptions!C$108 -> -404.62194 | D7: =-D5*Assumptions!D$108 -> -415.91837 | E7: =-E5*Assumptions!E$108 -> -425.82208 | F7: =-F5*Assumptions!F$108 -> -436.58402
A8: → EBIT | B8: =B6+B7 -> 383.79014 | C8: =C6+C7 -> 407.6209 | D8: =D6+D7 -> 424.47232 | E8: =E6+E7 -> 440.51984 | F8: =F6+F7 -> 455.89326
A9: NOPAT = EBIT × (1 − t) | B9: =B8*(1-Assumptions!$B$47) -> 337.73533 | C9: =C8*(1-Assumptions!$B$47) -> 358.70639 | D9: =D8*(1-Assumptions!$B$47) -> 373.53564 | E9: =E8*(1-Assumptions!$B$47) -> 387.65746 | F9: =F8*(1-Assumptions!$B$47) -> 401.18607
A10: + D&A | B10: =-B7 -> 392.46627 | C10: =-C7 -> 404.62194 | D10: =-D7 -> 415.91837 | E10: =-E7 -> 425.82208 | F10: =-F7 -> 436.58402
A11: − Capex (PPE) | B11: =-B5*Assumptions!B$109 -> -104.12371 | C11: =-C5*Assumptions!C$109 -> -107.78863 | D11: =-D5*Assumptions!D$109 -> -111.48327 | E11: =-E5*Assumptions!E$109 -> -114.84828 | F11: =-F5*Assumptions!F$109 -> -118.24151
A12: − Lease additions (new right-of-use) | B12: =-B5*Assumptions!B$110 -> -248.29499 | C12: =-C5*Assumptions!C$110 -> -252.88871 | D12: =-D5*Assumptions!D$110 -> -252.98128 | E12: =-E5*Assumptions!E$110 -> -251.78276 | F12: =-F5*Assumptions!F$110 -> -251.94536
A13: − ΔOperating working capital | B13: =-(B5*Assumptions!B$111-Assumptions!$B$12*Assumptions!$B$39) -> -3.3844524 | C13: =-(C5*Assumptions!C$111-B5*Assumptions!B$111) -> -12.6299 | D13: =-(D5*Assumptions!D$111-C5*Assumptions!C$111) -> -12.732308 | E13: =-(E5*Assumptions!E$111-D5*Assumptions!D$111) -> -11.596318 | F13: =-(F5*Assumptions!F$111-E5*Assumptions!E$111) -> -11.693587
A14: → FCFF | B14: =SUM(B9:B13) -> 374.39845 | C14: =SUM(C9:C13) -> 390.02109 | D14: =SUM(D9:D13) -> 412.25715 | E14: =SUM(E9:E13) -> 435.25217 | F14: =SUM(F9:F13) -> 455.88963
A15: × Discount factor @ WACC | B15: =(1+Assumptions!$B$51)^-1 -> 0.94662955 | C15: =(1+Assumptions!$B$51)^-2 -> 0.8961075 | D15: =(1+Assumptions!$B$51)^-3 -> 0.84828183 | E15: =(1+Assumptions!$B$51)^-4 -> 0.80300865 | F15: =(1+Assumptions!$B$51)^-5 -> 0.76015171
A16: → PV of FCFF | B16: =B14*B15 -> 354.41664 | C16: =C14*C15 -> 349.50082 | D16: =D14*D15 -> 349.71025 | E16: =E14*E15 -> 349.51126 | F16: =F14*F15 -> 346.54529
A18: Sum of PV of FCFF (5 years) | B18: =SUM(B16:F16) -> 1749.6843
A19: Terminal value = exit multiple × FY30E EBITDA | B19: =Assumptions!$B$114*F6 -> 6693.5796
A20: PV of terminal value | B20: =B19*F15 -> 5088.136
A21: ENTERPRISE VALUE | B21: =B18+B20 -> 6837.8203
A22: terminal value as % of EV | B22: =B20/B21 -> 0.74411666
A23: − Net debt (bank, ex-lease) | B23: =-Assumptions!$B$33 -> -860.3958
A24: − Lease liabilities (IFRS-16) | B24: =-Assumptions!$B$34 -> -1642.5738
A25: EQUITY VALUE (US$ mn) | B25: =B21+B23+B24 -> 4334.8507
A26: Value per share (US$) | B26: =B25/Assumptions!$B$6 -> 0.41968173
A27: VALUE PER SHARE (AED) | B27: =B26*Assumptions!$B$7 -> 1.5412812
A28: vs spot | B28: =B27/Assumptions!$B$5-1 -> 0.63966081
A30: CROSS-CHECK — what a Gordon terminal would have produced instead
A31: Gordon TV = FCFF(FY30E) × (1+g) ÷ (WACC − g) | B31: =F14*(1+Assumptions!$B$125)/(Assumptions!$B$51-Assumptions!$B$125) -> 16220.066
A32: WACC − g spread | B32: =Assumptions!$B$51-Assumptions!$B$125 -> 0.028879451
A33: Gordon TV ÷ exit-multiple TV | B33: =B31/B19 -> 2.4232275
A34: implied perpetual g inside the exit multiple | B34: =(Assumptions!$B$51*B19-F14)/(B19+F14) -> -0.010981136
A36: The exit multiple is the CONSERVATIVE choice — it implies a NEGATIVE perpetual growth rate. A Gordon terminal at a 2.9% spread is a bet on the discount rate, not a valuation of a grocer.

Sheet Fundamental Valuation
A1: The four lenses, and the weighted central
B4: Bear | C4: Base | D4: Bull | E4: Weight | F4: Weighted (base)
A5: DCF (FCFF, exit-multiple terminal) | B5: 0.66395427 | C5: =DCF!$B$27 -> 1.5412812 | D5: 2.390182 | E5: =Assumptions!$B$128 -> 0.3 | F5: =C5*E5 -> 0.46238435
A6: Relative EV/EBITDA | B6: 0.90407213 | C6: ='Relative & Normalized'!$C$11 -> 1.1800731 | D6: 1.4560775 | E6: =Assumptions!$B$129 -> 0.3 | F6: =C6*E6 -> 0.35402193
A7: Dividend discount (policy) | B7: 0.69943628 | C7: ='Dividend Discount'!$B$10 -> 1.1521416 | D7: 1.5020522 | E7: =Assumptions!$B$130 -> 0.25 | F7: =C7*E7 -> 0.2880354
A8: Normalized earnings | B8: 0.91109407 | C8: 1.1595743 | D8: 1.4080545 | E8: =Assumptions!$B$131 -> 0.15 | F8: =C8*E8 -> 0.17393614
A9: WEIGHTED CENTRAL | B9: =SUMPRODUCT(B5:B8,$E$5:$E$8) -> 0.7819311 | C9: =SUMPRODUCT(C5:C8,$E$5:$E$8) -> 1.2783778 | D9: =SUMPRODUCT(D5:D8,$E$5:$E$8) -> 1.7405991
A10: vs spot | C10: =C9/Assumptions!$B$5-1 -> 0.3599764
A12: The DCF and the market lenses are deliberately NOT blended into one point — the football field carries the divergence and §1.5 of the study reads it. The DCF sits above the market lenses because it capitalises five years of EBITDA growth (777 → 977) before applying the same 7.5× the market lens applies today.

Sheet Relative & Normalized
A1: Relative multiples, and normalized earnings power
A4: RELATIVE — EV/EBITDA applied to FY26E
B5: 6.5× (bear) | C5: 7.5× (base) | D5: 8.5× (bull)
A6: FY26E EBITDA (US$ mn) | B6: =DCF!$B$6 -> 776.25642 | C6: =DCF!$B$6 -> 776.25642 | D6: =DCF!$B$6 -> 776.25642
A7: Multiple | B7: =Assumptions!$B$115 -> 6.5 | C7: =Assumptions!$B$117 -> 7.5 | D7: =Assumptions!$B$116 -> 8.5
A8: Implied enterprise value | B8: =B6*B7 -> 5045.6667 | C8: =C6*C7 -> 5821.9231 | D8: =D6*D7 -> 6598.1796
A9: − Net debt (IFRS-16) | B9: =-Assumptions!$B$32 -> -2502.9696 | C9: =-Assumptions!$B$32 -> -2502.9696 | D9: =-Assumptions!$B$32 -> -2502.9696
A10: Implied equity value | B10: =B8+B9 -> 2542.6971 | C10: =C8+C9 -> 3318.9535 | D10: =D8+D9 -> 4095.21
A11: AED / share | B11: =B10/Assumptions!$B$6*Assumptions!$B$7 -> 0.90407063 | C11: =C10/Assumptions!$B$6*Assumptions!$B$7 -> 1.1800731 | D11: =D10/Assumptions!$B$6*Assumptions!$B$7 -> 1.4560755
A12: vs spot | B12: =B11/Assumptions!$B$5-1 -> -0.038222729 | C12: =C11/Assumptions!$B$5-1 -> 0.2553969 | D12: =D11/Assumptions!$B$5-1 -> 0.54901652
A14: WHERE THE MARKET ALREADY IS — the crux, in real units
A15: Spot enterprise value (mkt cap + net debt) | B15: =Assumptions!$B$9+Assumptions!$B$32 -> 5146.718
A16: Spot EV ÷ FY2025 EBITDA | B16: =B15/Assumptions!$B$20 -> 6.5799831
A17: Spot EV ÷ FY26E EBITDA | B17: =B15/DCF!$B$6 -> 6.6301777
A18: At a 7.5× peer mark, spot implies FY26E EBITDA of | B18: =B15/Assumptions!$B$117 -> 686.22907
A19: … versus FY2025 actual EBITDA | B19: =B18/Assumptions!$B$20-1 -> -0.12266892
A20: … i.e. an FY26E EBITDA margin of | B20: =B18/DCF!$B$5 -> 0.085676723
A22: NORMALIZED EARNINGS — through-cycle
A23: Through-cycle EBITDA margin (FY23–25 average) | B23: 0.10198887
A24: Applied to FY26E revenue | B24: =B23*DCF!$B$5 -> 816.88147
A25: − D&A | B25: =-DCF!$B$5*Assumptions!B$108 -> -392.46627
A26: − Net finance cost | B26: -160
A27: → Normalized PBT | B27: =B24+B25+B26 -> 264.41519
A28: × (1 − ETR) | B28: =1-Assumptions!$B$124 -> 0.881
A29: → Normalized net profit | B29: =B27*B28 -> 232.94978
A30: Normalized EPS (AED) | B30: =B29/Assumptions!$B$6*Assumptions!$B$7 -> 0.08282664
B31: 11× | C31: 14× | D31: 17×
A32: AED / share | B32: =$B$30*11 -> 0.91109304 | C32: =$B$30*14 -> 1.159573 | D32: =$B$30*17 -> 1.4080529

Sheet Dividend Discount
A1: The policy lens — what a holder actually receives
A2: Terminal = DPS(FY30E) capitalised at an observable terminal dividend yield, not a Gordon g.
B4: FY26E | C4: FY27E | D4: FY28E | E4: FY29E | F4: FY30E | G4: Terminal
A5: DPS (AED) | B5: =Assumptions!$B$120 -> 0.06 | C5: =B5*(1+Assumptions!$B$119) -> 0.063 | D5: =C5*(1+Assumptions!$B$119) -> 0.06615 | E5: =D5*(1+Assumptions!$B$119) -> 0.0694575 | F5: =E5*(1+Assumptions!$B$119) -> 0.072930375 | G5: =F5/Assumptions!$B$118 -> 1.2155063
A6: Discount factor @ Ke | B6: =(1+Assumptions!$B$48)^-1 -> 0.93737026 | C6: =(1+Assumptions!$B$48)^-2 -> 0.87866301 | D6: =(1+Assumptions!$B$48)^-3 -> 0.82363257 | E6: =(1+Assumptions!$B$48)^-4 -> 0.77204868 | F6: =(1+Assumptions!$B$48)^-5 -> 0.72369548 | G6: =(1+Assumptions!$B$48)^-5 -> 0.72369548
A7: PV | B7: =B5*B6 -> 0.056242216 | C7: =C5*C6 -> 0.05535577 | D7: =D5*D6 -> 0.054483295 | E7: =E5*E6 -> 0.053624571 | F7: =F5*F6 -> 0.052779382 | G7: =G5*G6 -> 0.87965637
A10: DDM VALUE (AED/share) — base | B10: =SUM(B7:G7) -> 1.1521416
A11: vs spot | B11: =B10/Assumptions!$B$5-1 -> 0.22568256
A13: FY2025 EPS (AED) | B13: =Assumptions!$B$23/Assumptions!$B$6*Assumptions!$B$7 -> 0.072722533
A14: FY2025 payout ratio — ACTUAL | B14: =Assumptions!$B$122/B13 -> 0.96256273
A15: Stated policy payout | B15: =Assumptions!$B$121 -> 0.75
A16: FY26E EPS (AED) | B16: ='Income Statement'!E20 -> 0.070101062
A17: FY26E DPS at the stated policy (AED) | B17: =B16*B15 -> 0.052575796
A18: Dividend yield at 7 fils | B18: =Assumptions!$B$122/Assumptions!$B$5 -> 0.074468085
A19: Dividend yield at the policy DPS | B19: =B17/Assumptions!$B$5 -> 0.055931698
A21: The company paid 96% of FY2025 earnings against a stated 75% policy. Held to that policy on FY26E earnings, the DPS falls to ~5.2 fils and the yield support weakens from 7.4% to ~5.5%. That is why the DDM base uses 5.5 fils, not the trailing 7.0 — and why the dividend is one of this study's named falsifiers.

Sheet Income Statement
A1: Income statement — 3 historical (audited) + 5 forecast (US$ mn)
B4: FY23 | C4: FY24 | D4: FY25 | E4: FY26E | F4: FY27E | G4: FY28E | H4: FY29E | I4: FY30E
A5: Revenue | B5: 7277.956 | C5: 7620.802 | D5: 7933.97 | E5: =DCF!B5 -> 8009.5158 | F5: =DCF!C5 -> 8291.4332 | G5: =DCF!D5 -> 8575.6365 | H5: =DCF!E5 -> 8834.4829 | I5: =DCF!F5 -> 9095.5005
A6: Gross profit | B6: 1675.127 | C6: 1764.885 | D6: 1822.836
A7: gross margin | B7: =B6/B5 -> 0.23016449 | C7: =C6/C5 -> 0.23158783 | D7: =D6/D5 -> 0.22975081
A8: Other operating income | B8: 273.167 | C8: 299.869 | D8: 302.553
A9: Operating expenses (incl. D&A) | B9: -1580.173 | C9: -1656.799 | D9: -1731.157
A10: EBIT | B10: =B6+B8+B9 -> 368.121 | C10: =C6+C8+C9 -> 407.955 | D10: =D6+D8+D9 -> 394.232 | E10: =DCF!B8 -> 383.79014 | F10: =DCF!C8 -> 407.6209 | G10: =DCF!D8 -> 424.47232 | H10: =DCF!E8 -> 440.51984 | I10: =DCF!F8 -> 455.89326
A11: D&A | B11: 384.879 | C11: 383.98 | D11: 387.946 | E11: =-DCF!B7 -> 392.46627 | F11: =-DCF!C7 -> 404.62194 | G11: =-DCF!D7 -> 415.91837 | H11: =-DCF!E7 -> 425.82208 | I11: =-DCF!F7 -> 436.58402
A12: EBITDA | B12: =B10+B11 -> 753 | C12: =C10+C11 -> 791.935 | D12: =D10+D11 -> 782.178 | E12: =E10+E11 -> 776.25642 | F12: =F10+F11 -> 812.24284 | G12: =G10+G11 -> 840.39069 | H12: =H10+H11 -> 866.34191 | I12: =I10+I11 -> 892.47728
A13: EBITDA margin | B13: =B12/B5 -> 0.10346312 | C13: =C12/C5 -> 0.10391754 | D13: =D12/D5 -> 0.098585954 | E13: =E12/E5 -> 0.096916772 | F13: =F12/F5 -> 0.097961694 | G13: =G12/G5 -> 0.097997471 | H13: =H12/H5 -> 0.098063681 | I13: =I12/I5 -> 0.098122944
A14: Finance costs, net | B14: -153.403 | C14: -169.375 | D14: -162.201 | E14: -160 | F14: -158 | G14: -156 | H14: -154 | I14: -152
A15: Profit before tax | B15: =B10+B14 -> 214.718 | C15: =C10+C14 -> 238.58 | D15: =D10+D14 -> 232.031 | E15: =E10+E14 -> 223.79014 | F15: =F10+F14 -> 249.6209 | G15: =G10+G14 -> 268.47232 | H15: =H10+H14 -> 286.51984 | I15: =I10+I14 -> 303.89326
A16: Tax | B16: -22.674 | C16: -22.3 | D16: -27.499 | E16: =-E15*Assumptions!$B$124 -> -26.631027 | F16: =-F15*Assumptions!$B$124 -> -29.704887 | G16: =-G15*Assumptions!$B$124 -> -31.948206 | H16: =-H15*Assumptions!$B$124 -> -34.09586 | I16: =-I15*Assumptions!$B$124 -> -36.163298
A17: NET PROFIT (continuing) | B17: =B15+B16 -> 192.044 | C17: =C15+C16 -> 216.28 | D17: =D15+D16 -> 204.532 | E17: =E15+E16 -> 197.15912 | F17: =F15+F16 -> 219.91601 | G17: =G15+G16 -> 236.52411 | H17: =H15+H16 -> 252.42398 | I17: =I15+I16 -> 267.72996
A18: effective tax rate | B18: =-B16/B15 -> 0.10559897 | C18: =-C16/C15 -> 0.093469696 | D18: =-D16/D15 -> 0.11851434 | E18: =-E16/E15 -> 0.119 | F18: =-F16/F15 -> 0.119 | G18: =-G16/G15 -> 0.119 | H18: =-H16/H15 -> 0.119 | I18: =-I16/I15 -> 0.119
A19: EPS (US cents) | B19: =B17/Assumptions!$B$6*100 -> 1.859288 | C19: =C17/Assumptions!$B$6*100 -> 2.0939306 | D19: =D17/Assumptions!$B$6*100 -> 1.9801915 | E19: =E17/Assumptions!$B$6*100 -> 1.9088104 | F19: =F17/Assumptions!$B$6*100 -> 2.129133 | G19: =G17/Assumptions!$B$6*100 -> 2.2899255 | H19: =H17/Assumptions!$B$6*100 -> 2.4438612 | I19: =I17/Assumptions!$B$6*100 -> 2.5920472
A20: EPS (AED) | B20: =B17/Assumptions!$B$6*Assumptions!$B$7 -> 0.068282352 | C20: =C17/Assumptions!$B$6*Assumptions!$B$7 -> 0.076899602 | D20: =D17/Assumptions!$B$6*Assumptions!$B$7 -> 0.072722533 | E20: =E17/Assumptions!$B$6*Assumptions!$B$7 -> 0.070101062 | F20: =F17/Assumptions!$B$6*Assumptions!$B$7 -> 0.078192408 | G20: =G17/Assumptions!$B$6*Assumptions!$B$7 -> 0.084097514 | H20: =H17/Assumptions!$B$6*Assumptions!$B$7 -> 0.089750801 | I20: =I17/Assumptions!$B$6*Assumptions!$B$7 -> 0.095192932
A22: FY23 D&A is DERIVED (company-stated EBITDA 753.0 less the reconciled EBIT of 368.1). FY24 shows a 5.6 gap between the RECONCILED EBITDA (791.9) and the company's stated 786.3 — an "adjusted" definitional difference. This model uses the reconciled figure throughout, never the press-release one.
A23: Q1-2026 (interim, 11-May-26): revenue 2,020.0 (−2.9% y/y) · gross margin 22.2% · EBITDA 192.0 (9.5% margin) · net income 47.0 (−33% y/y). FY26E is built off this print, not off the reiterated guidance.

Sheet Balance Sheet
A1: Balance sheet — condensed house layout (US$ mn)
B4: Dec-23 | C4: Dec-24 | D4: Dec-25 | E4: Mar-26
A5: Cash & equivalents | B5: 277.694 | C5: 346.208 | D5: =Assumptions!$B$28 -> 329.543
A6: Inventories | B6: 1374.607 | C6: 1473.636 | D6: 1491.112
A7: Trade & other receivables | B7: 331.507 | C7: 411.605 | D7: 399.122
A8: Trade & other payables | B8: 1380.024
A9: Property, plant & equipment | B9: 1461.43 | C9: 1438.49 | D9: 1411.939
A10: Right-of-use assets | B10: 1868.395 | C10: 1726.393 | D10: =Assumptions!$B$29 -> 1765.769
A11: TOTAL ASSETS | B11: 8004.151 | C11: 5450.512 | D11: 5440.109
A12: Bank borrowings (DERIVED, FY25) | B12: 1129.003 | D12: =Assumptions!$B$35 -> 1189.9388
A13: Lease liabilities (DERIVED, FY25) | B13: 2001.102 | D13: =Assumptions!$B$34 -> 1642.5738
A14: TOTAL EQUITY | B14: 766.907 | C14: 992.856 | D14: 1004.763
A15: Net debt — IFRS-16 basis | D15: =Assumptions!$B$32 -> 2502.9696 | E15: 2503
A16: × EBITDA | D16: =D15/Assumptions!$B$20 -> 3.2 | E16: 3.3
A17: Net debt — excluding leases | D17: =Assumptions!$B$33 -> 860.3958
A18: × EBITDA | D18: =D17/Assumptions!$B$20 -> 1.1 | E18: 0.9
A19: Operating WC (inv + recv − pay) | B19: =B6+B7-B8 -> 326.09
A20: % of revenue | B20: =B19/'Income Statement'!B5 -> 0.044805162
A22: DUAL FRAMING (house rule) — the same leverage has two legitimate framings, and both are stated:
A23: net debt US$2,503m = 3.2× EBITDA INCLUDING IFRS-16 lease liabilities
A24: net debt US$ 860m = 1.1× EBITDA EXCLUDING them.
A25: The company states both. This model uses the INCLUDING basis throughout — EBITDA is post-IFRS-16, so leases must
A26: be debt in the bridge AND lease additions must be a capex charge in the FCFF. Mixing the two framings is the
A27: classic IFRS-16 valuation error: rent-free EBITDA that never pays for its own leases.
A29: LIKEWISE "WORKING CAPITAL". The company reports a US$205m deficit — but that is CURRENT ASSETS minus CURRENT
A30: LIABILITIES, contaminated by short-term debt and the current portion of lease liabilities. OPERATING working
A31: capital (inventory + receivables − payables) was POSITIVE US$326m in FY2023 — the last year all three lines are
A32: disclosed. The model uses the operating measure (4.48% of revenue). FY24/FY25 payables were NOT disclosed in the
A33: sources captured; that gap is flagged wherever it is used rather than silently estimated.
A35: Bank debt and lease liabilities are DERIVED from the company-stated 3.2× / 1.1× ratios plus cash. CROSS-CHECK: the
... A37: confidence in the derivation.

Sheet Cash Flow
A1: Cash flow — and the FCFF reconciliation receipt (US$ mn)
B4: FY24 | C4: FY25
A5: Net cash from operating activities | B5: 358.129 | C5: 596.362
A6: Capex — property, plant & equipment | B6: -141.712 | C6: -138.501
A7: Lease principal repaid (in financing) | B7: -186.48 | C7: -190.804
A8: Dividends paid | B8: 0 | C8: -182.812
A9: Net cash used in financing | B9: -151.386 | C9: -484.091
A11: THE RECONCILIATION — two independent routes to FY2025 FCFF
A12: Route A — the NOPAT waterfall
A13: NOPAT = EBIT × (1 − t) | B13: =Assumptions!$B$16*(1-Assumptions!$B$47) -> 346.92416
A14: + D&A | B14: =Assumptions!$B$17+Assumptions!$B$18+Assumptions!$B$19 -> 387.946
A15: − Capex (PPE) | B15: =C6 -> -138.501
A16: − Lease additions (new RoU) | B16: =-Assumptions!$B$38 -> -258.757
A17: − ΔOperating working capital | B17: =-Assumptions!$B$39*(Assumptions!$B$12-Assumptions!$B$25) -> -14.029926
A18: → FCFF (route A) | B18: =SUM(B13:B17) -> 323.58223
A20: Route B — rebuilt from the AUDITED cash-flow statement
A21: Net cash from operating activities | B21: =C5 -> 596.362
A22: + after-tax interest (interest sits INSIDE OCF) | B22: =Assumptions!$B$24*(1-Assumptions!$B$47) -> 131.49048
A23: − Capex (PPE) | B23: =C6 -> -138.501
A24: − Lease additions (new RoU) | B24: =-Assumptions!$B$38 -> -258.757
A25: → FCFF (route B) | B25: =SUM(B21:B24) -> 330.59448
A27: GAP (route B − route A) | B27: =B25-B18 -> 7.0122464
A28: as % of route A | B28: =B27/B18 -> 0.021670678
A30: The test that proves interest is an OPERATING item:
A31: EBITDA − interest − cash tax − OCF | B31: =Assumptions!$B$20-Assumptions!$B$24+Assumptions!$B$22-C5 -> 8.896
A32: ≈ zero ⇒ interest is already inside OCF, so route B is right to add it back. Two routes built from different statements land within ~2% of each other. That is the receipt.

Sheet Sensitivity
A1: Sensitivity — WACC × exit multiple, the beta grid, and the crux
A4: DCF value (AED/share): WACC (rows) × exit EV/EBITDA (columns)
B5: 6.0x | C5: 6.5x | D5: 7.5x | E5: 8.5x | F5: 9.5x
A6: 0.056379451 | B6: 1.1794577 | C6: 1.3000655 | D6: 1.5412812 | E6: 1.7824969 | F6: 2.0237125
A7: 0.062379451 | B7: 1.1286171 | C7: 1.2458574 | D7: 1.480338 | E7: 1.7148186 | F7: 1.9492992
A8: 0.068379451 | B8: 1.0793934 | C8: 1.1933783 | D8: 1.4213483 | E8: 1.6493182 | F8: 1.8772882
A9: 0.074379451 | B9: 1.0317255 | C9: 1.142563 | D9: 1.364238 | E9: 1.585913 | F9: 1.8075881
A10: 0.080379451 | B10: 0.98555512 | C10: 1.0933489 | D10: 1.3089364 | E10: 1.524524 | F10: 1.7401115
A11: Pink cells bracket spot at AED 0.94.
A13: THE BETA GRID — the honesty tax on a MEASURED β of 0.489
A14: Beta | B14: Ke | C14: WACC | D14: DCF (AED/sh)
A15: 0.49 | B15: 0.066863 | C15: 0.056402961 | D15: 1.5410385
A16: 0.66 | B16: 0.075142 | C16: 0.060399775 | D16: 1.5002263
A17: 0.85 | B17: 0.084395 | C17: 0.064866801 | D17: 1.4556506
A18: 1 | B18: 0.0917 | C18: 0.068393401 | D18: 1.4212133
A19: 1.2 | B19: 0.10144 | C19: 0.073095535 | D19: 1.3763044
A20: 1.4 | B20: 0.11118 | C20: 0.077797668 | D20: 1.3325153
A22: Because the terminal is an OBSERVABLE exit multiple and not a Gordon formula, the DCF is now robust to beta: the whole 0.49 → 1.40 range moves it by only AED 0.21. Under a Gordon terminal the same move was worth multiples of the share price. Removing that leverage is the single most important modelling decision in this study — and it is why beta, though carefully measured, is NOT the crux.
A24: THE CRUX, IN REAL UNITS — FY26E SALES DENSITY (not the margin: the margin is downstream)
A25: Density Δ | B25: Revenue | C25: Rev growth | D25: EBITDA | E25: Margin | F25: DCF (AED) | G25: Rel @7.5× (AED)
A26: -0.08 | B26: 7523.1279 | C26: -0.051782667 | D26: 644.16505 | E26: 0.085624631 | F26: 1.0938666 | G26: 0.82782921
A27: -0.06 | B27: 7686.6741 | C27: -0.031169246 | D27: 687.81304 | E27: 0.089481228 | F27: 1.2443065 | G27: 0.94422393
A28: -0.04 | B28: 7850.2204 | C28: -0.010555826 | D28: 731.46103 | E28: 0.093177133 | F28: 1.3947463 | G28: 1.0606186
A29: -0.02 | B29: 8013.7667 | C29: 0.010057594 | D29: 775.10902 | E29: 0.096722185 | F29: 1.5451862 | G29: 1.1770133
A30: 0 | B30: 8177.3129 | C30: 0.030671014 | D30: 818.75701 | E30: 0.10012543 | F30: 1.695626 | G30: 1.2934081
A31: 0.02 | B31: 8340.8592 | C31: 0.051284435 | D31: 862.405 | E31: 0.10339522 | F31: 1.8460659 | G31: 1.4098028
A33: Read this as a causal chain: DENSITY → REVENUE → OPERATING LEVERAGE → MARGIN → VALUE. Q1-2026 printed roughly −9%. Management's guidance requires density FLAT for the year. This study's base assumes −2.3%: better than Q1, worse than flat. The H1 print on 19-Aug-2026 tests it, and by the cost model of 'Estate & Leverage' the revenue in that print IS the margin in that print.

Sheet Monte Carlo
A1: Monte Carlo v3 — carry-anchored YZ-HAR-t (engine/mc_v3.py)
A2: The drift is the money-market carry. The fundamental gap NEVER enters it — that is the lens-independence rule.
A4: Engine | B4: carry-anchored YZ-HAR-t · 50,000 paths · seed 42
A5: Market profile | B5: AE (UAE) — read LIVE from engine/market_profiles.py
A6: Student-t shape ν | B6: 10
A7: Width calibration | B7: 1.049
A8: Signal | B8: OFF — carry-only (ablated on the AE panel; fallback rule)
A9: rf — carry anchor (CBUAE base rate) | B9: 0.0365
A10: Dividend yield q — declared (7 fils) | B10: 0.074468085
A11: Dividend yield q — at the 75% policy | B11: 0.05593179
A12: Carry over 60 sessions (log) | B12: -0.0086116803
A13: Event-ledger drift | B13: 0.00225
A14: σ over 60 sessions | B14: 0.1651613
A16: GATE — UAE market panel (14 names, 237 windows) | B16: PARITY +0.49% CI90 [−0.24%, +1.26%]
A17: GATE — LULU name level | B17: NOT IDENTIFIED — 2 test windows against the ~18 a meaningful test needs
A18: Calibration tier | B18: PARITY — market-panel validated; NO single-name edge claimed
A20: PERCENTILE MAP (AED)
B21: T+20 | C21: T+60 | D21: move at T+60
A22: 5th | B22: 0.80288901 | C22: 0.71344694 | D22: =C22/Assumptions!$B$5-1 -> -0.24101389
A23: 25th | B23: 0.88363715 | C23: 0.84226151 | D23: =C23/Assumptions!$B$5-1 -> -0.10397711
A24: 50th (median) | B24: 0.93756102 | C24: 0.93326496 | D24: =C24/Assumptions!$B$5-1 -> -0.0071649315
A25: 75th | B25: 0.99570935 | C25: 1.0357829 | D25: =C25/Assumptions!$B$5-1 -> 0.10189665
A26: 95th | B26: 1.0958775 | C26: 1.2228495 | D26: =C26/Assumptions!$B$5-1 -> 0.30090374
A28: P(price above spot at T+60) | B28: 0.48048
A29: P(≥ +10%) | B29: 0.25348
A30: P(≤ −10%) | B30: 0.25926
A31: Odds ratio (up10 ÷ down10) | B31: 0.97770578
A32: T+20 cohort matures | B32: 07 Aug 2026
A33: T+60 cohort matures | B33: 02 Oct 2026
A35: LEVEL-TOUCH LADDER
B36: vs spot | C36: P(touch by T+20) | D36: P(touch by T+60)
A37: AED 1.30 | B37: 0.38297872 | C37: 0.00252 | D37: 0.04304
A38: AED 1.20 | B38: 0.27659574 | C38: 0.01168 | D38: 0.10666
A39: AED 1.10 | B39: 0.17021277 | C39: 0.07162 | D39: 0.26702
A40: AED 1.05 | B40: 0.11702128 | C40: 0.17896 | D40: 0.41352
A41: AED 1.00 | B41: 0.063829787 | C41: 0.40398 | D41: 0.6181
A42: AED 0.95 | B42: 0.010638298 | C42: 0.7911 | D42: 0.87672
A43: AED 0.90 | B43: -0.042553191 | C43: 0.54248 | D43: 0.72902
A44: AED 0.85 | B44: -0.095744681 | C44: 0.22128 | D44: 0.4792
A45: AED 0.80 | B45: -0.14893617 | C45: 0.07014 | D45: 0.27824
...

Sheet MC Factors
A1: The event ledger — discrete, probability-weighted
B4: Probability | C4: Impact | D4: Contribution
A5: H1-2026 (19-Aug): Q2 revenue also falls — a 2nd down quarter (the strait was blockaded through Apr–May) | B5: 0.7 | C5: -0.02 | D5: =B5*C5 -> -0.014
A6: H1-2026: FY26 revenue guidance (+4–5%) formally withdrawn or cut | B6: 0.45 | C6: -0.03 | D6: =B6*C6 -> -0.0135
A7: H1-2026: guidance held — density stabilises as the March non-food deferral unwinds | B7: 0.35 | C7: 0.03 | D7: =B7*C7 -> 0.0105
A8: Hormuz normalisation (MOU 17-Jun; blockade lifted) feeds into an H2 non-food recovery | B8: 0.55 | C8: 0.025 | D8: =B8*C8 -> 0.01375
A9: Renewed escalation or re-closure of the strait | B9: 0.15 | C9: -0.035 | D9: =B9*C9 -> -0.00525
A10: Cost programme delivers again: mature-store opex down a 2nd consecutive period | B10: 0.5 | C10: 0.015 | D10: =B10*C10 -> 0.0075
A11: Interim DPS held at 3.5 fils (the 1.40× cash cover is defended) | B11: 0.6 | C11: 0.015 | D11: =B11*C11 -> 0.009
A12: Interim DPS cut toward the 75%-of-earnings policy | B12: 0.25 | C12: -0.025 | D12: =B12*C12 -> -0.00625
A13: Placement / lock-up release from the 70.44% controlling stake | B13: 0.1 | C13: -0.025 | D13: =B13*C13 -> -0.0025
A14: Re-rating toward Al Othaim's ~8.9× from LULU's 6.6× | B14: 0.15 | C14: 0.02 | D14: =B14*C14 -> 0.003
A15: NET EVENT-LEDGER DRIFT | D15: =SUM(D5:D14) -> 0.00225
A17: The ledger is net NEGATIVE. On the evidence of Q1, the H1-2026 print (19-Aug) and the interim dividend decision are each more likely to disappoint than to surprise. This is why the Monte-Carlo median sits BELOW spot while the fundamental lenses sit above it — and the two are not in conflict. They are different clocks.

Sheet Per-Share & Ratios
A1: Per-share, returns, and the retail operating dashboard
A4: Spot (AED) | B4: =Assumptions!$B$5 -> 0.94
A5: IPO price (14-Nov-2024) | B5: 2.04
A6: Drawdown from the IPO price | B6: =B4/B5-1 -> -0.53921569
A7: 52-week range (AED) | B7: 0.93 – 1.29
A8: FY2025 EPS (AED) | B8: ='Income Statement'!D20 -> 0.072722533
A9: FY26E EPS (AED) | B9: ='Income Statement'!E20 -> 0.070101062
A10: P/E — trailing | B10: =B4/B8 -> 12.925842
A11: P/E — FY26E | B11: =B4/B9 -> 13.409212
A12: Dividend yield — 7 fils declared | B12: =Assumptions!$B$122/B4 -> 0.074468085
A13: Dividend yield — at the 75% policy | B13: ='Dividend Discount'!B18/B4 -> 0.079221367
A14: EV/EBITDA — FY2025 | B14: ='Relative & Normalized'!B16 -> 6.5799831
A15: EV/EBITDA — FY26E | B15: ='Relative & Normalized'!B17 -> 6.6301777
A17: ROIC (FY2025, after tax) | B17: 0.099071266
A18: WACC | B18: =Assumptions!$B$51 -> 0.056379451
A19: ROIC − WACC spread | B19: =B17-B18 -> 0.042691815
A20: ROE (FY2025) | B20: 0.20356243
A22: Stores — FY25 / Q1-26 | B22: 267 / 277
A23: Retail space (m sqm, FY25) | B23: 1.38
A24: Private label % of retail sales (Q1-26) | B24: 0.302
A25: E-commerce % of retail sales (Q1-26) | B25: 0.079
A26: E-commerce growth (Q1-26, y/y) | B26: 0.61
A27: Loyalty members (mn) | B27: 8.4
A28: Revenue linked to loyalty members | B28: 0.67
A29: LFL sales growth — FY25 / Q4-25 | B29: +2.3% / −1.1%
A30: UAE segment EBITDA margin (FY25) | B30: 0.122
A31: KSA segment EBITDA margin (FY25) | B31: 0.047

Sheet Peer & Sector
A1: Peer set — secondary market data, flagged as such
B4: EV/EBITDA | C4: EBITDA margin | D4: Div. yield | E4: Note
A5: LULU (this study) — at spot 0.94 | B5: ='Relative & Normalized'!B17 -> 6.6301777 | C5: 0.0986 | D5: 0.0745 | E5: FY26E basis, post-IFRS-16
A6: Abdullah Al Othaim (Tadawul 4001) | B6: 8.9 | C6: 0.065 | D6: 0.067 | E6: the TIGHTEST structural comp — KSA grocery
A7: Spinneys 1961 (DFM) | C7: 0.2 | D7: 0.046 | E7: premium/Waitrose model — NOT margin-comparable
A8: BinDawood (Tadawul 4161) | E8: KSA grocery
A9: Tesco (LSE) | B9: 6.5 | E9: international mass grocer
A10: Ahold Delhaize (AMS) | B10: 5.5 | E10: international mass grocer
A11: Carrefour (EPA) | E11: international mass grocer
A12: Jerónimo Martins (ELI) | E12: the premium multiple within the group
A13: Majid Al Futtaim / Carrefour UAE | E13: largest UAE competitor — UNLISTED
A14: Union Coop (UAE) | E14: exploring an IPO
A16: LULU trades at roughly 6.6× FY26E EV/EBITDA against Al Othaim's ~8.9× — a ~26% discount to its closest
A17: structural comparable, on a business that is #1 in four of the six GCC markets it operates in.
A18: That discount IS the study.
A20: Peer multiples are secondary/vendor data and are flagged as such. They set a RANGE (6.5–8.5×), never a point.
A21: No LULU financial-statement line item anywhere in this workbook comes from an aggregator.

Sheet Sources
A1: Research sources — every finding dated and attributed
A4: Scope | B4: What kind of finding | C4: Finding | D4: Source | E4: Date
A5: Global | B5: Structural | C5: AED hard-pegged to USD at 3.6725; CBUAE Base Rate 3.65% tracks the Fed. AED T-Bond programme is the study's rf source: Jan-2031 tranche cleared 4.30% (23-May-26 auction); longest AED tenor is the 7-yr Feb-2033 T-Sukuk at 4.13% (Apr-26). No 10-yr AED tenor exists. | D5: UAE Ministry of Finance T-Bond auction releases; CBUAE | E5: 23 May 2026
A6: Global | B6: Structural | C6: Global food commodity prices and freight are LULU's principal input cost. The 2026 Strait of Hormuz crisis (US/Israel strikes and IRGC VHF closure warnings 28-Feb-26; formal IRGC closure announced 2-Mar-26; 'complete control' declared 4-Mar-26; US naval blockade 13-Apr to 29-May; Islamabad MOU signed 17-Jun-26 and the strait reopening) disrupted GCC food imports; regional consumer price spikes wer | D6: Company Q1-2026 results commentary; press coverage of the disruption | E6: 11 May 2026
A7: Global | B7: COLOR | C7: Global grocery retail is a low-growth, low-margin, defensive category. Global retail sector EV/EBITDA ~11.7x (all retail); listed food retailers cluster far lower at ~5-7x (Tesco, Ahold Delhaize, Carrefour), with Jeronimo Martins at a premium. | D7: Statista global retail sector multiples; peer quotes | E7: 11 Jul 2026
A8: Global | B8: Structural | C8: LULU sources from 85 countries via 19 sourcing centres — an unusually deep own-import chain for a regional grocer. The Hormuz disruption tested it directly; management reported all stores remained open and well-stocked, which is the falsifiable claim. | D8: Company Q1-2026 earnings release | E8: 11 May 2026
A9: Country | B9: COLOR | C9: UAE Aa2 (Moody's). GDP +5.6% (2025), non-oil +6.1%. Inflation 1.3% avg 2025; food inflation easing. Peg intact — no devaluation channel. Q1/Q2-2026 growth sharply decelerated on the Hormuz closure. KSA: Vision-2030 population and retail growth, offset by Saudization labour cost. | D9: CBUAE; World Bank; Damodaran country file (Aa2) | E9: 11 Jul 2026
A10: Country | B10: Unlocks a driver | C10: UAE 9% federal corporate tax effective for FYs beginning on/after 1-Jun-2023. KSA subsidiary taxed under Saudi CIT/zakat. Group effective tax rate FY2025 = 11.85% (27.499 / 232.031), FY2024 = 9.35% — rising with the KSA mix. No price caps on grocery retail. | D10: FY2025 audited consolidated financial statements (Deloitte) | E10: 18 Mar 2026
A11: Country | B11: Structural | C11: The 2026 regional escalation / Strait of Hormuz closure is the dominant country-ring event: it hit during the MARCH portion of Ramadan (c.18-Feb to 19-Mar-2026), grocery's seasonal peak. LULU's Q1-2026 revenue fell 2.9% and net income fell 33% — a Ramadan quarter that went backwards. | D11: Company Q1-2026 earnings release, 11-May-2026 | E11: 11 May 2026
A12: Industry | B12: COLOR | C12: GCC grocery market projected to reach c.US$101bn by 2028, a 4.2% CAGR 2023-28 (modern retail ~4.8%). LULU held 13.5% of the GCC modern offline grocery market in 2023 — #1 overall, and #1 in Oman, Qatar, Kuwait and Bahrain; #2 in the UAE; fastest-growing player of scale in KSA. | D12: Euromonitor International, cited in the company's IPO/ITF disclosure | E12: 14 Nov 2024
A13: Industry | B13: Structural | C13: Grocery pricing is pass-through-constrained and promotional. LULU's gross margin has been flat-to-down: 23.02% (FY23) -> 23.16% (FY24) -> 22.98% (FY25), and 22.2% in Q1-2026. The EBITDA margin fell to 9.5% in Q4-2025 and again 9.5% in Q1-2026, from 9.86% for FY25. | D13: FY2023-FY2025 audited FS; Q1-2026 earnings release | E13: 11 May 2026
A14: Industry | B14: Structural | C14: Discounters and quick-commerce aggregators are entering GCC grocery. Saudi broker commentary on Al Othaim explicitly names 'new discounters such as Lulu' and convenience formats (BinDawood's 'dash') as margin pressures — i.e. the discount channel is live in KSA, LULU's weakest-margin market (4.7% segment EBITDA margin FY25). | D14: Al-Jazira Capital broker note on Al Othaim; sector coverage | E14: 11 Jul 2026
A15: Industry | B15: Unlocks a driver | C15: E-commerce is additive, not substitutive, for LULU: FY2025 online sales US$451.1m, +38.6%, 6.0% of retail sales; Q1-2026 US$150m, +61%, 7.9% of sales. About half the estate is e-commerce enabled; quick-commerce (45-90 min) live; Amazon partnership in the UAE. | D15: FY2025 results; Q1-2026 earnings release | E15: 11 May 2026
... A30: Company | B30: Context | C30: Q1-2026 trading SHAPE: 'Trading in January and February was in line with the Company's expectations'; 'March saw a slowdown, particularly in non-food'. By category: CPG and Fresh Food INCREASED y/y; Lifestyle modestly down; Electrical 'a particularly pronounced decline ... mostly during March'. Capex 1.3% of sales. Loyalty-linked sales c.70%. 690,000 daily shoppers. | D30: Lulu Retail Q1-2026 press release | E30: 11 May 2026
A32: “Searched — not found” rows (shaded) are deliberate: a figure that was looked for and shown not to exist is part of the record, and each is carried through the study as an explicit limitation rather than quietly filled with an estimate.
A34: Scope = which layer the finding sits in (company / industry / country / global). "Searched — not found" rows are deliberate: a figure looked for and shown not to exist is part of the record.. Coverage is categories CLOSED, never query count.

Sheet Ledger
A1: Calibration Ledger — the cohort this study registers
B4: Value
A5: Ticker | B5: LULU
A6: Market | B6: AE — Abu Dhabi Securities Exchange
A7: Anchor date | B7: 10 Jul 2026
A8: Anchor price (AED) | B8: 0.94
A9: Engine | B9: mc_v3 — carry-anchored YZ-HAR-t
A10: ν / width_cal | B10: 10 / 1.049 (UAE market fit, read live from the repo)
A11: Signal | B11: OFF — carry-only
A12: Price-history screen (corporate actions, bad prints) | B12: PASS — 410 rows, 0 repairs, 248.8 rows/yr vs the ADX calendar
A13: Market-panel validation (14 ADX/DFM names) | B13: PARITY — 14 names, 237 windows, +0.49% CI90 [−0.24%, +1.26%]
A14: Name-level verdict | B14: NOT IDENTIFIED — 2 test windows vs the ~18 a meaningful test needs
A15: Calibration tier | B15: PARITY — market-panel validated, NO single-name edge claimed
A16: T+20 cohort matures | B16: 07 Aug 2026
A17: T+60 cohort matures | B17: 02 Oct 2026
A18: T+20 p5 / p50 / p95 | B18: 0.80 / 0.94 / 1.10
A19: T+60 p5 / p50 / p95 | B19: 0.71 / 0.93 / 1.22
A20: Grading rule | B20: graded against these FROZEN percentiles on maturity; never retro-edited
A22: Ledgers are APPEND-ONLY. This cohort will be graded against the percentiles above exactly as they stand today — pass or fail — and published on the public Calibration Ledger.
