Workbook

Sheet READ FIRST
A1: Testahil — Modon Holding PSC (ADX: MODON) · Revision 2
A3: Companion model · Independent Valuation Study · Educational analysis · Not investment advice
A5: REVISION 2 (9 Aug 2026). This edition restrikes the valuation on the 30-Jun-2026 reviewed balance
A6: sheet and the H1-2026 results release (revenue backlog AED 65.4bn, 95% development; H1 real-estate
A7: sales AED 26bn) — disclosures the first edition failed to carry into its drivers, a defect surfaced
A8: by external audits and accepted. The audits' other accepted findings are implemented throughout:
A9: the bridge uses AVAILABLE cash (AED 8.6bn) rather than gross cash including project escrow; the
A10: terminal debt weight is DERIVED from the model's own terminal-year balance sheet; working capital
A11: is built from components (receivable days, land-bank conversion, payables/advances cover); D&A is
A12: charged on the asset base; beta is a regression (1.03 vs an equal-weight panel proxy), no longer an
A13: assumption; and the mid-chain hardcoded numerals the audits found are eliminated.
A15: What this workbook is. Every blue cell is an input; every black cell is a formula; green cells link
... A42: Peer & Sector.

Sheet Summary
A1: Summary — valuation at a glance (revision 3)
A2: All values link live to their source sheets
A4: Lens | B4: Bear | C4: Base | D4: Bull | E4: Weight | F4: Contribution | G4: vs spot
A5: Discounted cash flow (primary) | B5: 2.6432323 | C5: =DCF!C62 | D5: 4.1337525 | E5: =Assumptions!$C$82 | F5: =C5*E5 | G5: =C5/$C$14-1
A6: Relative multiples | B6: ='Relative & Normalized'!C12 | C6: ='Relative & Normalized'!C11 | D6: ='Relative & Normalized'!D12 | E6: =Assumptions!$C$83 | F6: =C6*E6 | G6: =C6/$C$14-1
A7: Normalised earnings power | B7: ='Relative & Normalized'!E28 | C7: ='Relative & Normalized'!C28 | D7: ='Relative & Normalized'!F28 | E7: =Assumptions!$C$84 | F7: =C7*E7 | G7: =C7/$C$14-1
A8: Book value and sustainable return | B8: ='Relative & Normalized'!E36 | C8: ='Relative & Normalized'!C36 | D8: ='Relative & Normalized'!F36 | E8: =Assumptions!$C$85 | F8: =C8*E8 | G8: =C8/$C$14-1
A9: Weighted central | B9: =MIN(B5:B8) | C9: =SUM(F5:F8) | D9: =MAX(D5:D8) | E9: =SUM(E5:E8) | G9: =C9/$C$14-1
A11: The contested judgement: DCF base vs run-off stress | C11: =DCF!C62 | D11: 2.6432323
A12: Terminal value share of DCF enterprise value | C12: =DCF!C49
A13: Expert panel median | C13: 2.4787456
A14: Market price (anchor, 7-Aug-2026) | C14: =Assumptions!$C$4
A16: Key figure | B16: Value
A17: Market capitalisation (AED mn) | C17: =Assumptions!$C$4*Assumptions!$C$5
A18: Net cash, strict basis (all cash − all debt, 30-Jun-2026) | C18: =Assumptions!$C$9-Assumptions!$C$10
A19: Net debt, company definition (available cash − debt, disclosed) | C19: -912
A20: FY2026E revenue (H1 actual + H2 model) | C20: =Assumptions!$C$19+DCF!B5
A21: FY2026E attributable profit | C21: ='Relative & Normalized'!C5
A22: Cost of capital (explicit window) | C22: =DCF!C36
A23: Cost of capital (terminal, derived weights) | C23: =DCF!C38
A24: Terminal growth | C24: =Assumptions!$C$66
A26: Monte Carlo price map (engine re-run, pasted) | B26: 1 month | C26: 3 months
A27: 5th percentile | B27: 2.537068 | C27: 2.3199657
A28: 25th percentile | B28: 2.718596 | C28: 2.6379757
A29: Median | B29: 2.8383089 | C29: 2.8576479
A30: 75th percentile | B30: 2.9639422 | C30: 3.0947734
A31: 95th percentile | B31: 3.1696329 | C31: 3.5237234

Sheet Fundamental Valuation
A1: Fundamental valuation — four lenses, the contested judgement and the stresses
A4: Lens / step | B4: Basis | C4: AED per share
A5: Discounted cash flow (primary) | B5: links to the DCF sheet | C5: =DCF!C62
A6: run-off stress | B6: launches halve and fade (engine re-run; vectors on Assumptions) | C6: 2.6432323
A7: growth-hold alternative | B7: sales hold near the realised pace (engine re-run) | C7: 4.1337525
A8: Egypt-risk stress | B8: non-UAE revenue share carries the Egypt premium (engine re-run) | C8: 2.8275648
A9: gross-cash bridge alternative | B9: escrow/restricted cash included (engine re-run) | C9: 3.7716284
A10: Relative multiples | B10: justified P/E vs the rebuilt attributable peer set | C10: ='Relative & Normalized'!C11
A11: Normalised earnings power | B11: through-cycle sales, margin, multiple | C11: ='Relative & Normalized'!C28
A12: Book value and sustainable return | B12: justified P/B on sustainable ROE, rolled | C12: ='Relative & Normalized'!C36
A14: Weighted central (links to Summary) | C14: =Summary!C9
A16: What the market price implies | B16: cost-of-equity adder reconciling the base DCF to spot (engine solve) | C16: 0.02693415
A18: Expert panel (engine re-runs, worked in Appendix C) | B18: Method | C18: AED per share
A19: Expert 1 | B19: asset value (RNAV) | C19: 4.0580711
A20: Expert 2 | B20: owner cash flow, run-off stress basis | C20: 2.4787456
A21: Expert 3 | B21: peer-multiple convergence | C21: 1.8148554
A22: Panel median | C22: =MEDIAN(C19:C21)

Sheet Assumptions
A1: Assumptions — every blue cell reprices the model
A2: Vectors run H2-2026E..FY2030E across columns C..G; scenario vectors at the foot are published for reproducibility of the pasted engine outputs
A3: Driver | C3: H2-26E / value | D3: FY27E | E3: FY28E | F3: FY29E | G3: FY30E
A4: Spot price (AED, 7-Aug-2026 close) | C4: 2.83
A5: Shares outstanding (mn) | C5: 16347.08
A6: 30-Jun-2026 anchors (reviewed interim + results release, pasted)
A7: Development backlog at 30-Jun-2026 (65.4bn × 95%, disclosed) | C7: 62130
A8: Unrestricted (available) cash at 30-Jun-2026 (disclosed) | C8: 8600
A9: Total cash and bank balances at 30-Jun-2026 (disclosed) | C9: 12303.24
A10: Gross debt incl. related-party loan at 30-Jun-2026 (disclosed) | C10: 9541.685
A11: Lease liabilities at 30-Jun-2026 (disclosed) | C11: 644.799
A12: Associates & JVs at carrying value, 30-Jun-2026 (disclosed) | C12: 2826.454
A13: Investments in financial assets, 30-Jun-2026 (disclosed) | C13: 392.972
A14: Non-controlling interests, 30-Jun-2026 (disclosed) | C14: 922.342
A15: Equity attributable to owners, 30-Jun-2026 (disclosed) | C15: 56396.629
A16: Receivables incl. related-party, 30-Jun-2026 (disclosed) | C16: 22155.68
A17: Inventories + development WIP, 30-Jun-2026 (disclosed) | C17: 34087.289
A18: Payables incl. advances + related-party, 30-Jun-2026 (disclosed) | C18: 22289.32
... A23: Depreciable asset base at 30-Jun-2026 (PP&E+IP+ROU+intangibles) | C23: 19736.134
A24: Forecast drivers (H2-2026 stub, then annual)
A25: Backlog conversion rate on opening development backlog | C25: 0.105 | D25: 0.25 | E25: 0.28 | F25: 0.3 | G25: 0.32
A26: New development sales (AED mn) | C26: 12000 | D26: 30000 | E26: 26000 | F26: 23000 | G26: 21000
A27: Land and plot sales revenue (AED mn) | C27: 700 | D27: 1400 | E27: 1300 | F27: 1200 | G27: 1100
A28: Development gross margin | C28: 0.41 | D28: 0.4 | E28: 0.39 | F28: 0.385 | G28: 0.38
A29: Asset & investment management growth (from FY27) | C29: 0 | D29: 0.09 | E29: 0.085 | F29: 0.08 | G29: 0.08
A30: Asset & investment management H2-2026E revenue | C30: 385
A31: Asset & investment management gross margin | C31: 0.68 | D31: 0.66 | E31: 0.65 | F31: 0.64 | G31: 0.64
A32: Hospitality growth (from FY27) | C32: 0 | D32: 0.07 | E32: 0.07 | F32: 0.06 | G32: 0.06
A33: Hospitality H2-2026E revenue | C33: 452
A34: Hospitality gross margin | C34: 0.29 | D34: 0.28 | E34: 0.29 | F34: 0.3 | G34: 0.3
A35: Events, catering & tourism growth (from FY27) | C35: 0 | D35: 0.045 | E35: 0.043 | F35: 0.041 | G35: 0.039
A36: Events, catering & tourism H2-2026E revenue | C36: 3000
A37: Events, catering & tourism gross margin | C37: 0.29 | D37: 0.27 | E37: 0.275 | F37: 0.28 | G37: 0.28
A38: H1-2026 AIM revenue (actual) | C38: 360.966
A39: H1-2026 Hospitality revenue (actual) | C39: 388.398
A40: H1-2026 ECT revenue (actual) | C40: 2775.402
A41: Others / eliminations revenue (full-year rate) | C41: -30
A42: Others gross loss (full-year rate) | C42: -120
A43: General & administrative / revenue | C43: 0.083 | D43: 0.088 | E43: 0.087 | F43: 0.086 | G43: 0.085
A44: Selling & marketing / revenue | C44: 0.017 | D44: 0.018 | E44: 0.017 | F44: 0.017 | G44: 0.016
...

Sheet SOTP Bridge
A1: SOTP bridge — segment EV split (weights DERIVED) and the EV → equity walk
A2: Weight = FY2025 segment gross profit less a revenue-proportional corporate load — all live formulas off Segments and the FY2025 disclosed opex
A4: FY2025 G&A + S&M (audited, for the load allocation) | B4: 1813.687
A5: Enterprise value by segment | B5: Weight (GP − load share) | C5: AED mn
A6: Real Estate Development | B6: =Segments!C5-$B$4*Segments!B5/Segments!B10 | C6: =MAX(B6,0)/(MAX(B$6,0)+MAX(B$7,0)+MAX(B$8,0)+MAX(B$9,0))*DCF!C48
A7: Asset & Investment Management | B7: =Segments!C6-$B$4*Segments!B6/Segments!B10 | C7: =MAX(B7,0)/(MAX(B$6,0)+MAX(B$7,0)+MAX(B$8,0)+MAX(B$9,0))*DCF!C48
A8: Hospitality | B8: =Segments!C7-$B$4*Segments!B7/Segments!B10 | C8: =MAX(B8,0)/(MAX(B$6,0)+MAX(B$7,0)+MAX(B$8,0)+MAX(B$9,0))*DCF!C48
A9: Events, Catering & Tourism | B9: =Segments!C8-$B$4*Segments!B8/Segments!B10 | C9: =MAX(B9,0)/(MAX(B$6,0)+MAX(B$7,0)+MAX(B$8,0)+MAX(B$9,0))*DCF!C48
A10: Enterprise value (links to DCF) | C10: =DCF!C48
A11: Terminal value share of enterprise value | C11: =DCF!C49
A12: + Unrestricted cash (disclosed) | C12: =Assumptions!$C$8
A13: − Gross debt incl. related-party loan | C13: =-Assumptions!$C$10
A14: − Lease liabilities | C14: =-Assumptions!$C$11
A15: + Associates & JVs | C15: =Assumptions!$C$12
A16: + Financial assets | C16: =Assumptions!$C$13
A17: − NCI (capitalised, links to DCF) | C17: =DCF!C58
A18: Equity attributable → per share → at anchor | C18: =C10+SUM(C12:C17)
A19: per share, 30-Jun-2026 | C19: =C18/Assumptions!$C$5
A20: per share at the 7-Aug-2026 anchor | C20: =C19*DCF!C61
A22: Book-NCI alternative framing (engine) | C22: 3.5562856

Sheet Segments
A1: Segments — FY2025 base, H1-2026 actuals, and the forecast build
A2: FY2025 base and H1-2026 actuals pasted (disclosed); every forecast cell is a formula off Assumptions
A4: FY2025 base (audited) | B4: Revenue | C4: Gross profit | D4: GP margin | E4: PBT | F4: Assets
A5: Real Estate Development | B5: 7403.313 | C5: 3232.891 | D5: =C5/B5 | E5: 2547.573 | F5: 55738.581
A6: Asset & Investment Management | B6: 654.658 | C6: 421.083 | D6: =C6/B6 | E6: 685.082 | F6: 11095.849
A7: Hospitality | B7: 791.771 | C7: 210.893 | D7: =C7/B7 | E7: -69.15 | F7: 4601.757
A8: Events, Catering & Tourism | B8: 5008.749 | C8: 1325.029 | D8: =C8/B8 | E8: 1061.602 | F8: 14118.268
A9: Others / eliminations | B9: -29.622 | C9: -164.637
A10: Group FY2025 | B10: =SUM(B5:B9) | C10: =SUM(C5:C9)
A12: Development build (from the 30-Jun-2026 disclosed backlog) | B12: H2-26E | C12: FY27E | D12: FY28E | E12: FY29E | F12: FY30E
A13: Opening development backlog | B13: =Assumptions!$C$7 | C13: =B16 | D13: =C16 | E13: =D16 | F13: =E16
A14: New development sales | B14: =Assumptions!$C$26 | C14: =Assumptions!$D$26 | D14: =Assumptions!$E$26 | E14: =Assumptions!$F$26 | F14: =Assumptions!$G$26
A15: Development revenue recognised (conv × opening) | B15: =Assumptions!$C$25*B13 | C15: =Assumptions!$D$25*C13 | D15: =Assumptions!$E$25*D13 | E15: =Assumptions!$F$25*E13 | F15: =Assumptions!$G$25*F13
A16: Closing backlog | B16: =B13+B14-B15 | C16: =C13+C14-C15 | D16: =D13+D14-D15 | E16: =E13+E14-E15 | F16: =F13+F14-F15
A17: Land and plot sales | B17: =Assumptions!$C$27 | C17: =Assumptions!$D$27 | D17: =Assumptions!$E$27 | E17: =Assumptions!$F$27 | F17: =Assumptions!$G$27
A18: Real Estate Development revenue | B18: =B15+B17 | C18: =C15+C17 | D18: =D15+D17 | E18: =E15+E17 | F18: =F15+F17
A20: Segment revenue forecast | B20: H2-26E | C20: FY27E | D20: FY28E | E20: FY29E | F20: FY30E
A21: Real Estate Development | B21: =B18 | C21: =C18 | D21: =D18 | E21: =E18 | F21: =F18
A22: Asset & Investment Management | B22: =Assumptions!$C$30 | C22: =(Assumptions!$C$38+Assumptions!$C$30)*(1+Assumptions!$D$29) | D22: =C22*(1+Assumptions!$E$29) | E22: =D22*(1+Assumptions!$F$29) | F22: =E22*(1+Assumptions!$G$29)
A23: Hospitality | B23: =Assumptions!$C$33 | C23: =(Assumptions!$C$39+Assumptions!$C$33)*(1+Assumptions!$D$32) | D23: =C23*(1+Assumptions!$E$32) | E23: =D23*(1+Assumptions!$F$32) | F23: =E23*(1+Assumptions!$G$32)
A24: Events, Catering & Tourism | B24: =Assumptions!$C$36 | C24: =(Assumptions!$C$40+Assumptions!$C$36)*(1+Assumptions!$D$35) | D24: =C24*(1+Assumptions!$E$35) | E24: =D24*(1+Assumptions!$F$35) | F24: =E24*(1+Assumptions!$G$35)
A25: Others / eliminations (half-year in the stub) | B25: =Assumptions!$C$41*0.5 | C25: =Assumptions!$C$41*1.0 | D25: =Assumptions!$C$41*1.0 | E25: =Assumptions!$C$41*1.0 | F25: =Assumptions!$C$41*1.0
A26: Group revenue | B26: =SUM(B21:B25) | C26: =SUM(C21:C25) | D26: =SUM(D21:D25) | E26: =SUM(E21:E25) | F26: =SUM(F21:F25)
A28: Gross profit build (margin × revenue) | B28: H2-26E | C28: FY27E | D28: FY28E | E28: FY29E | F28: FY30E
A29: Real Estate Development | B29: =B21*Assumptions!$C$28 | C29: =C21*Assumptions!$D$28 | D29: =D21*Assumptions!$E$28 | E29: =E21*Assumptions!$F$28 | F29: =F21*Assumptions!$G$28
A30: Asset & Investment Management | B30: =B22*Assumptions!$C$31 | C30: =C22*Assumptions!$D$31 | D30: =D22*Assumptions!$E$31 | E30: =E22*Assumptions!$F$31 | F30: =F22*Assumptions!$G$31
A31: Hospitality | B31: =B23*Assumptions!$C$34 | C31: =C23*Assumptions!$D$34 | D31: =D23*Assumptions!$E$34 | E31: =E23*Assumptions!$F$34 | F31: =F23*Assumptions!$G$34
A32: Events, Catering & Tourism | B32: =B24*Assumptions!$C$37 | C32: =C24*Assumptions!$D$37 | D32: =D24*Assumptions!$E$37 | E32: =E24*Assumptions!$F$37 | F32: =F24*Assumptions!$G$37
A33: Others (half-year in the stub) | B33: =Assumptions!$C$42*0.5 | C33: =Assumptions!$C$42*1.0 | D33: =Assumptions!$C$42*1.0 | E33: =Assumptions!$C$42*1.0 | F33: =Assumptions!$C$42*1.0
A34: Group gross profit | B34: =SUM(B29:B33) | C34: =SUM(C29:C33) | D34: =SUM(D29:D33) | E34: =SUM(E29:E33) | F34: =SUM(F29:F33)
A35: Group gross margin (output) | B35: =B34/B26 | C35: =C34/C26 | D35: =D34/D26 | E35: =E34/E26 | F35: =F34/F26

Sheet Relative & Normalized
A1: Relative multiples · normalised earnings power · book value
A2: One attributable-earnings basis throughout; the EV/EBITDA leg is a labelled, unanchored cross-check and is NOT averaged into the lens
A4: Relative multiples (P/E leg = the lens) | B4: Value
A5: FY2026E attributable profit = H1 actual + H2 model | C5: =Assumptions!$C$21+'Income Statement'!F17
A6: Justified P/E × FY2026E EPS | C6: =Assumptions!$C$75*C5/Assumptions!$C$5
A7: FY2026E EBITDA (H1 adjusted-EBITDA + H2 model) | C7: =Assumptions!$C$22+DCF!B13
A8: EV/EBITDA cross-check (house multiple, unanchored — labelled) | C8: =(Assumptions!$C$76*C7+Assumptions!$C$8-Assumptions!$C$10-Assumptions!$C$11+Assumptions!$C$12+Assumptions!$C$13-MAX(Assumptions!$C$14,0.02*(Assumptions!$C$76*C7+Assumptions!$C$8-Assumptions!$C$10-Assumptions!$C$11+Assumptions!$C$12+Assumptions!$C$13-Assumptions!$C$14)))/Assumptions!$C$5
A11: Relative lens (P/E leg) | C11: =C6
A12: bear / bull (lens scaled to the peer-set floor 4.73x and ceiling 8.10x) | C12: =C11*4.73/Assumptions!$C$75 | D12: =C11*8.1/Assumptions!$C$75
A14: Trailing cross-checks | B14: Value
A15: Trailing P/E on FY2025 attributable profit | C15: =DCF!C33/Assumptions!$C$71
A16: Trailing P/E on FY2025 group profit (dual-framed) | C16: =DCF!C33/Assumptions!$C$70
A17: Trailing EV/EBITDA (mktcap + FY2025 strict net debt over house EBITDA) | C17: =(DCF!C33+Assumptions!$C$73)/Assumptions!$C$72
A19: Normalised earnings power | B19: Value
A20: Through-cycle revenue = 85% × cycle sales + recurring legs × 1.15 | C20: =Assumptions!$C$77*0.85+Assumptions!$C$79*1.15
A21: Through-cycle net margin | C21: =Assumptions!$C$78
A22: Normalised net profit | C22: =C20*C21
A23: Normalised EPS | C23: =C22/Assumptions!$C$5
A28: Normalised lens = EPS × through-cycle P/E | C28: =C23*Assumptions!$C$80 | E28: =C23*6 | F28: =C23*10.5
A30: Book value & sustainable return (rolled to the anchor like the DCF) | B30: Value
A31: Book value per share (30-Jun-2026 attributable equity) | C31: =Assumptions!$C$15/Assumptions!$C$5
A32: Justified P/B = (ROE − g)/(Ke − g) | C32: =(Assumptions!$C$81-Assumptions!$C$66)/(DCF!C30-Assumptions!$C$66)
A36: Book lens = BVPS × justified P/B × anchor roll | C36: =C31*C32*DCF!C61 | E36: =C31*((0.055-Assumptions!$C$66)/(DCF!C30-Assumptions!$C$66))*DCF!C61 | F36: =C31*((0.095-Assumptions!$C$66)/(DCF!C30-Assumptions!$C$66))*DCF!C61

Sheet DCF
A1: DCF — waterfall, working-capital components, cost of capital, terminal block, bridge
A2: Valuation date 30-Jun-2026; H2-2026 stub then annual; every chain live
A4: Waterfall (AED mn) | B4: H2-26E | C4: FY27E | D4: FY28E | E4: FY29E | F4: FY30E
A5: Revenue | B5: =Segments!B26 | C5: =Segments!C26 | D5: =Segments!D26 | E5: =Segments!E26 | F5: =Segments!F26
A6: Gross profit | B6: =Segments!B34 | C6: =Segments!C34 | D6: =Segments!D34 | E6: =Segments!E34 | F6: =Segments!F34
A7: General & administrative | B7: =-Assumptions!$C$43*B5 | C7: =-Assumptions!$D$43*C5 | D7: =-Assumptions!$E$43*D5 | E7: =-Assumptions!$F$43*E5 | F7: =-Assumptions!$G$43*F5
A8: Selling & marketing | B8: =-Assumptions!$C$44*B5 | C8: =-Assumptions!$D$44*C5 | D8: =-Assumptions!$E$44*D5 | E8: =-Assumptions!$F$44*E5 | F8: =-Assumptions!$G$44*F5
A9: Investment and other income | B9: =Assumptions!$C$45 | C9: =Assumptions!$D$45 | D9: =Assumptions!$E$45 | E9: =Assumptions!$F$45 | F9: =Assumptions!$G$45
A10: EBIT (post-D&A, ex-fair-value items) | B10: =SUM(B6:B9) | C10: =SUM(C6:C9) | D10: =SUM(D6:D9) | E10: =SUM(E6:E9) | F10: =SUM(F6:F9)
A11: EBITDA margin (output) | B11: =(B10+B12)/B5 | C11: =(C10+C12)/C5 | D11: =(D10+D12)/D5 | E11: =(E10+E12)/E5 | F11: =(F10+F12)/F5
A12: Depreciation & amortisation (asset-base) | B12: =Assumptions!$C$46*(B21+Assumptions!$C$47/2)*0.5 | C12: =Assumptions!$C$46*(C21+Assumptions!$D$47/2)*1.0 | D12: =Assumptions!$C$46*(D21+Assumptions!$E$47/2)*1.0 | E12: =Assumptions!$C$46*(E21+Assumptions!$F$47/2)*1.0 | F12: =Assumptions!$C$46*(F21+Assumptions!$G$47/2)*1.0
A13: EBITDA | B13: =B10+B12 | C13: =C10+C12 | D13: =D10+D12 | E13: =E10+E12 | F13: =F10+F12
A14: NOPAT = EBIT × (1 − t) | B14: =B10*(1-Assumptions!$C$48) | C14: =C10*(1-Assumptions!$C$48) | D14: =D10*(1-Assumptions!$C$48) | E14: =E10*(1-Assumptions!$C$48) | F14: =F10*(1-Assumptions!$C$48)
A15: + D&A | B15: =B12 | C15: =C12 | D15: =D12 | E15: =E12 | F15: =F12
A16: − Capital expenditure | B16: =-Assumptions!$C$47 | C16: =-Assumptions!$D$47 | D16: =-Assumptions!$E$47 | E16: =-Assumptions!$F$47 | F16: =-Assumptions!$G$47
A17: − Δ working capital (from components below) | B17: =-B26 | C17: =-C26 | D17: =-D26 | E17: =-E26 | F17: =-F26
A18: Free cash flow to firm | B18: =SUM(B14:B17) | C18: =SUM(C14:C17) | D18: =SUM(D14:D17) | E18: =SUM(E14:E17) | F18: =SUM(F14:F17)
A19: Discount factor (period-end from 30-Jun-2026) | B19: =1/(1+$C$36)^0.5 | C19: =1/(1+$C$36)^1.5 | D19: =1/(1+$C$36)^2.5 | E19: =1/(1+$C$36)^3.5 | F19: =1/(1+$C$36)^4.5
A20: PV of FCFF | B20: =B18*B19 | C20: =C18*C19 | D20: =D18*D19 | E20: =E18*E19 | F20: =F18*F19
A21: Depreciable asset base (opening) | B21: =Assumptions!$C$23 | C21: =B21+Assumptions!$C$47-B12 | D21: =C21+Assumptions!$D$47-C12 | E21: =D21+Assumptions!$E$47-D12 | F21: =E21+Assumptions!$F$47-E12
A22: Receivables (days × revenue) | B22: =Assumptions!$C$55/365*(Assumptions!$C$19+B5) | C22: =Assumptions!$D$55/365*C5 | D22: =Assumptions!$E$55/365*D5 | E22: =Assumptions!$F$55/365*E5 | F22: =Assumptions!$G$55/365*F5
A23: Inventories + WIP (roll) | B23: =Assumptions!$C$17+Assumptions!$C$56*Assumptions!$C$26-Assumptions!$C$57*Segments!B18*(1-Assumptions!$C$28) | C23: =B23+Assumptions!$C$56*Assumptions!$D$26-Assumptions!$C$57*Segments!C18*(1-Assumptions!$D$28) | D23: =C23+Assumptions!$C$56*Assumptions!$E$26-Assumptions!$C$57*Segments!D18*(1-Assumptions!$E$28) | E23: =D23+Assumptions!$C$56*Assumptions!$F$26-Assumptions!$C$57*Segments!E18*(1-Assumptions!$F$28) | F23: =E23+Assumptions!$C$56*Assumptions!$G$26-Assumptions!$C$57*Segments!F18*(1-Assumptions!$G$28)
A24: Payables + advances (cover × costs) | B24: =Assumptions!$C$58*(Assumptions!$C$19+B5-Assumptions!$C$20-B6) | C24: =Assumptions!$D$58*(C5-C6) | D24: =Assumptions!$E$58*(D5-D6) | E24: =Assumptions!$F$58*(E5-E6) | F24: =Assumptions!$G$58*(F5-F6)
A25: Net working capital | B25: =B22+B23-B24 | C25: =C22+C23-C24 | D25: =D22+D23-D24 | E25: =E22+E23-E24 | F25: =F22+F23-F24
A26: Δ working capital | B26: =B25-(Assumptions!$C$16+Assumptions!$C$17-Assumptions!$C$18) | C26: =C25-B25 | D26: =D25-C25 | E26: =E25-D25 | F26: =F25-E25
A28: Cost of capital — built on the sheet
A29: Normalised risk-free rate rf* = AED yield − sovereign spread | C29: =Assumptions!$C$60-Assumptions!$C$61
A30: Cost of equity Ke = rf* + β × ERP (β from the panel-proxy regression) | C30: =C29+Assumptions!$C$63*Assumptions!$C$62
A31: Marginal cost of debt Kd = 6M EIBOR + margin | C31: =Assumptions!$C$64+Assumptions!$C$65
A32: Kd after tax | C32: =C31*(1-Assumptions!$C$48)
A33: Market capitalisation (spot × shares) | C33: =Assumptions!$C$4*Assumptions!$C$5
A34: Equity weight E/(E+D), debt at the 30-Jun-2026 book | C34: =C33/(C33+Assumptions!$C$10)
A35: Debt weight D/(E+D) | C35: =1-C34
A36: Cost of capital (explicit window) | C36: =C34*C30+C35*C32
A37: Terminal debt weight — DERIVED from the FY2030E balance sheet | C37: ='Balance Sheet'!J12/('Balance Sheet'!J12+'Balance Sheet'!J14+'Balance Sheet'!J15)
A38: Terminal cost of capital (derived weights) | C38: =(1-C37)*C30+C37*C31*(1-Assumptions!$C$48)
A40: Terminal block — reinvestment derived
A41: Terminal growth g | C41: =Assumptions!$C$66
A42: Terminal return on invested capital | C42: =Assumptions!$C$67
A43: Reinvestment rate = g / ROIC | C43: =C41/C42
...

Sheet Income Statement
A1: Income statement — 3 years audited + H1-2026 actual + forecast
A2: FY2023 is the Q Holding perimeter; FY2024 contains the AED 9,192mn bargain gain (dual-framed); column E is the H1-2026 actual; forecast runs H2-2026E..FY2030E
B4: FY2023 | C4: FY2024 | D4: FY2025 | E4: H1-26A | F4: H2-26E | G4: FY27E | H4: FY28E | I4: FY29E | J4: FY30E
A5: Revenue | B5: 994.293 | C5: 6511.182 | D5: 13828.869 | E5: 9188.304 | F5: =DCF!B5 | G5: =DCF!C5 | H5: =DCF!D5 | I5: =DCF!E5 | J5: =DCF!F5
A6: Gross profit | B6: 599.559 | C6: 2316.507 | D6: 5025.259 | E6: 3201.275 | F6: =DCF!B6 | G6: =DCF!C6 | H6: =DCF!D6 | I6: =DCF!E6 | J6: =DCF!F6
A7: EBITDA (house) | B7: 673.353 | C7: 9794.942 | D7: 4895.552 | F7: =DCF!B13 | G7: =DCF!C13 | H7: =DCF!D13 | I7: =DCF!E13 | J7: =DCF!F13
A8: EBITDA margin | B8: =B7/B5 | C8: =C7/C5 | D8: =D7/D5 | F8: =F7/F5 | G8: =G7/G5 | H8: =H7/H5 | I8: =I7/I5 | J8: =J7/J5
A9: Depreciation & amortisation | B9: 27.719 | C9: 265.122 | D9: 610.483 | F9: =DCF!B12 | G9: =DCF!C12 | H9: =DCF!D12 | I9: =DCF!E12 | J9: =DCF!F12
A10: EBIT | B10: =B7-B9 | C10: =C7-C9 | D10: =D7-D9 | F10: =F7-F9 | G10: =G7-G9 | H10: =H7-H9 | I10: =I7-I9 | J10: =J7-J9
A11: Net finance result | B11: 8.518 | C11: -156.667 | D11: -127.466 | F11: =(Assumptions!$C$52*'Balance Sheet'!E9-(DCF!$C$31*(Assumptions!$C$10+Assumptions!$C$51)/2+Assumptions!$C$53))*0.5 | G11: =(Assumptions!$C$52*'Balance Sheet'!F9-(DCF!$C$31*(Assumptions!$C$51+Assumptions!$D$51)/2+Assumptions!$C$53))*1.0 | H11: =(Assumptions!$C$52*'Balance Sheet'!G9-(DCF!$C$31*(Assumptions!$D$51+Assumptions!$E$51)/2+Assumptions!$C$53))*1.0 | I11: =(Assumptions!$C$52*'Balance Sheet'!H9-(DCF!$C$31*(Assumptions!$E$51+Assumptions!$F$51)/2+Assumptions!$C$53))*1.0 | J11: =(Assumptions!$C$52*'Balance Sheet'!I9-(DCF!$C$31*(Assumptions!$F$51+Assumptions!$G$51)/2+Assumptions!$C$53))*1.0
A12: Associates & JVs | B12: -0.697 | C12: 115.114 | D12: 263.592 | F12: =Assumptions!$C$50 | G12: =Assumptions!$D$50 | H12: =Assumptions!$E$50 | I12: =Assumptions!$F$50 | J12: =Assumptions!$G$50
A13: Profit before tax | B13: =B10+B11+B12 | C13: =C10+C11+C12 | D13: =D10+D11+D12 | E13: 2601.227 | F13: =F10+F11+F12 | G13: =G10+G11+G12 | H13: =H10+H11+H12 | I13: =I10+I11+I12 | J13: =J10+J11+J12
A14: Income tax | B14: -79.504 | C14: -98.815 | D14: -495.49 | E14: -401.202 | F14: =-F13*Assumptions!$C$48 | G14: =-G13*Assumptions!$C$48 | H14: =-H13*Assumptions!$C$48 | I14: =-I13*Assumptions!$C$48 | J14: =-J13*Assumptions!$C$48
A15: Profit for the year | B15: =B13+B14 | C15: =C13+C14 | D15: =D13+D14 | E15: 2202.138 | F15: =F13+F14 | G15: =G13+G14 | H15: =H13+H14 | I15: =I13+I14 | J15: =J13+J14
A16: Non-controlling interests | B16: 112.682 | C16: -33.739 | D16: -94.397 | E16: 39.172 | F16: =F15*Assumptions!$C$49 | G16: =G15*Assumptions!$C$49 | H16: =H15*Assumptions!$C$49 | I16: =I15*Assumptions!$C$49 | J16: =J15*Assumptions!$C$49
A17: Attributable profit | B17: =B15-B16 | C17: =C15-C16 | D17: =D15-D16 | E17: 2162.966 | F17: =F15-F16 | G17: =G15-G16 | H17: =H15-H16 | I17: =I15-I16 | J17: =J15-J16

Sheet Balance Sheet
A1: Balance sheet — audited history, 30-Jun-2026 actual, and the roll-forward
A2: Column E = 30-Jun-2026 reviewed actuals; forecast rolls equity on retained profit, debt on the drawn path, cash from free cash flow
B4: FY2023 | C4: FY2024 | D4: FY2025 | E4: 30-Jun-26A | F4: H2-26E | G4: FY27E | H4: FY28E | I4: FY29E | J4: FY30E
A5: Receivables incl. related-party | B5: 1685.533 | C5: 12843.804 | D5: 16635.123 | E5: =Assumptions!$C$16 | F5: =DCF!B22 | G5: =DCF!C22 | H5: =DCF!D22 | I5: =DCF!E22 | J5: =DCF!F22
A6: Inventories + development WIP | B6: 2246.917 | C6: 32047.946 | D6: 33409.382 | E6: =Assumptions!$C$17 | F6: =DCF!B23 | G6: =DCF!C23 | H6: =DCF!D23 | I6: =DCF!E23 | J6: =DCF!F23
A7: Payables incl. advances + related-party | B7: - | C7: 18029.912 | D7: 23101.595 | E7: =Assumptions!$C$18 | F7: =DCF!B24 | G7: =DCF!C24 | H7: =DCF!D24 | I7: =DCF!E24 | J7: =DCF!F24
A8: Net working capital (components) | B8: - | C8: =C5+C6-C7 | D8: =D5+D6-D7 | E8: =E5+E6-E7 | F8: =DCF!B25 | G8: =DCF!C25 | H8: =DCF!D25 | I8: =DCF!E25 | J8: =DCF!F25
A9: Cash and bank balances | B9: 2259.902 | C9: 7009.67 | D9: 12641.987 | E9: =Assumptions!$C$9 | F9: =E9+DCF!B18+'Income Statement'!F11-('Income Statement'!F13-DCF!B10)*Assumptions!$C$48+(Assumptions!$C$51-Assumptions!$C$10) | G9: =F9+DCF!C18+'Income Statement'!G11-('Income Statement'!G13-DCF!C10)*Assumptions!$C$48+(Assumptions!$D$51-Assumptions!$C$51) | H9: =G9+DCF!D18+'Income Statement'!H11-('Income Statement'!H13-DCF!D10)*Assumptions!$C$48+(Assumptions!$E$51-Assumptions!$D$51) | I9: =H9+DCF!E18+'Income Statement'!I11-('Income Statement'!I13-DCF!E10)*Assumptions!$C$48+(Assumptions!$F$51-Assumptions!$E$51) | J9: =I9+DCF!F18+'Income Statement'!J11-('Income Statement'!J13-DCF!F10)*Assumptions!$C$48+(Assumptions!$G$51-Assumptions!$F$51)
A10: Total assets (audited) | B10: 21311.081 | C10: 75925.281 | D10: 87030.985 | E10: 91985.93 | F10: - | G10: - | H10: - | I10: - | J10: -
A12: Gross debt incl. related-party loan | B12: 1976.135 | C12: 5364.11 | D12: 6789.086 | E12: =Assumptions!$C$10 | F12: =Assumptions!$C$51 | G12: =Assumptions!$D$51 | H12: =Assumptions!$E$51 | I12: =Assumptions!$F$51 | J12: =Assumptions!$G$51
A13: Net debt (− = net cash) | B13: =B12-B9 | C13: =C12-C9 | D13: =D12-D9 | E13: =E12-E9 | F13: =F12-F9 | G13: =G12-G9 | H13: =H12-H9 | I13: =I12-I9 | J13: =J12-J9
A14: Equity attributable to owners | B14: 13769.094 | C14: 49676.408 | D14: 53902.504 | E14: =Assumptions!$C$15 | F14: =E14+'Income Statement'!F17 | G14: =F14+'Income Statement'!G17 | H14: =G14+'Income Statement'!H17 | I14: =H14+'Income Statement'!I17 | J14: =I14+'Income Statement'!J17
A15: Non-controlling interests | B15: 1149.566 | C15: 1186.183 | D15: 847.48 | E15: =Assumptions!$C$14 | F15: =E15+'Income Statement'!F16 | G15: =F15+'Income Statement'!G16 | H15: =G15+'Income Statement'!H16 | I15: =H15+'Income Statement'!I16 | J15: =I15+'Income Statement'!J16
A16: Net debt / EBITDA | B16: =(B12-B9)/673.3530000000001 | C16: =(C12-C9)/9794.942 | D16: =(D12-D9)/4895.552000000001 | F16: =(F12-F9)/DCF!B13 | G16: =(G12-G9)/DCF!C13 | H16: =(H12-H9)/DCF!D13 | I16: =(I12-I9)/DCF!E13 | J16: =(J12-J9)/DCF!F13

Sheet Cash Flow
A1: Cash flow — audited history, H1-2026 actual, and the forecast chain
A2: Forecast rows link to the DCF waterfall; the IFRS operating-cash-flow actuals are shown separately from the model construct (different measures, not one series)
B4: FY2024A | C4: FY2025A | D4: H1-26A | E4: H2-26E | F4: FY27E | G4: FY28E | H4: FY29E | I4: FY30E
A5: IFRS net cash from operating activities (audited/reviewed) | B5: 3231.447 | C5: 3860.373 | D5: -3921.027
A6: Capital expenditure (PP&E + intangibles + IP) | B6: 1247 | C6: 1260.566 | D6: 312.49
A8: Model construct (NOT the IFRS measure): links to the DCF waterfall
A9: NOPAT | E9: =DCF!B14 | F9: =DCF!C14 | G9: =DCF!D14 | H9: =DCF!E14 | I9: =DCF!F14
A10: + D&A | E10: =DCF!B15 | F10: =DCF!C15 | G10: =DCF!D15 | H10: =DCF!E15 | I10: =DCF!F15
A11: − Capex | E11: =DCF!B16 | F11: =DCF!C16 | G11: =DCF!D16 | H11: =DCF!E16 | I11: =DCF!F16
A12: − Δ working capital | E12: =DCF!B17 | F12: =DCF!C17 | G12: =DCF!D17 | H12: =DCF!E17 | I12: =DCF!F17
A13: Free cash flow to firm | E13: =DCF!B18 | F13: =DCF!C18 | G13: =DCF!D18 | H13: =DCF!E18 | I13: =DCF!F18
A15: Implied H2-2026 IFRS-basis operating recovery required by the model: the H1 actual was −3,921; the model's FY2026 working-capital absorption of 938 implies roughly +5,978 of H2 operating cash flow — stated, not hidden

Sheet Summary Financials
A1: Summary financials — the model in one table
A2: Every row links live
B4: FY2023 | C4: FY2024 | D4: FY2025 | E4: H1-26A | F4: H2-26E | G4: FY27E | H4: FY28E | I4: FY29E | J4: FY30E
A5: Revenue | B5: ='Income Statement'!B5 | C5: ='Income Statement'!C5 | D5: ='Income Statement'!D5 | E5: ='Income Statement'!E5 | F5: ='Income Statement'!F5 | G5: ='Income Statement'!G5 | H5: ='Income Statement'!H5 | I5: ='Income Statement'!I5 | J5: ='Income Statement'!J5
A6: EBITDA | B6: ='Income Statement'!B7 | C6: ='Income Statement'!C7 | D6: ='Income Statement'!D7 | E6: - | F6: ='Income Statement'!F7 | G6: ='Income Statement'!G7 | H6: ='Income Statement'!H7 | I6: ='Income Statement'!I7 | J6: ='Income Statement'!J7
A7: EBITDA margin | B7: ='Income Statement'!B8 | C7: ='Income Statement'!C8 | D7: ='Income Statement'!D8 | E7: - | F7: ='Income Statement'!F8 | G7: ='Income Statement'!G8 | H7: ='Income Statement'!H8 | I7: ='Income Statement'!I8 | J7: ='Income Statement'!J8
A8: Attributable profit | B8: ='Income Statement'!B17 | C8: ='Income Statement'!C17 | D8: ='Income Statement'!D17 | E8: ='Income Statement'!E17 | F8: ='Income Statement'!F17 | G8: ='Income Statement'!G17 | H8: ='Income Statement'!H17 | I8: ='Income Statement'!I17 | J8: ='Income Statement'!J17
A9: Free cash flow to firm | B9: - | C9: - | D9: - | E9: - | F9: ='Cash Flow'!E13 | G9: ='Cash Flow'!F13 | H9: ='Cash Flow'!G13 | I9: ='Cash Flow'!H13 | J9: ='Cash Flow'!I13
A10: Net debt (− = net cash) | B10: ='Balance Sheet'!B13 | C10: ='Balance Sheet'!C13 | D10: ='Balance Sheet'!D13 | E10: ='Balance Sheet'!E13 | F10: ='Balance Sheet'!F13 | G10: ='Balance Sheet'!G13 | H10: ='Balance Sheet'!H13 | I10: ='Balance Sheet'!I13 | J10: ='Balance Sheet'!J13
A11: Equity attributable | B11: ='Balance Sheet'!B14 | C11: ='Balance Sheet'!C14 | D11: ='Balance Sheet'!D14 | E11: ='Balance Sheet'!E14 | F11: ='Balance Sheet'!F14 | G11: ='Balance Sheet'!G14 | H11: ='Balance Sheet'!H14 | I11: ='Balance Sheet'!I14 | J11: ='Balance Sheet'!J14
A13: Invested capital: 30-Jun-2026 base + cumulative (capex − D&A + ΔWC) | E13: =Assumptions!$C$15+Assumptions!$C$14+Assumptions!$C$10-Assumptions!$C$9 | F13: =E13+DCF!B16*-1-DCF!B12+DCF!B26 | G13: =F13+DCF!C16*-1-DCF!C12+DCF!C26 | H13: =G13+DCF!D16*-1-DCF!D12+DCF!D26 | I13: =H13+DCF!E16*-1-DCF!E12+DCF!E26 | J13: =I13+DCF!F16*-1-DCF!F12+DCF!F26

Sheet Monte Carlo
A1: Monte Carlo price map — engine re-run (pasted, does not reprice)
A2: Struck 2026-08-07 at spot 2.83; 50,000 paths, seed 42; unchanged from the first edition (the price series and anchor are unchanged)
B4: 1 month | C4: 3 months
A5: Sessions in window | B5: 20 | C5: 63
A6: Grade date | B6: 2026-09-07 | C6: 2026-11-09
A7: Annualised anchor volatility | B7: 0.25166322 | C7: 0.26372485
A8: 5th percentile | B8: 2.537068 | C8: 2.3199657
A9: 25th percentile | B9: 2.718596 | C9: 2.6379757
A10: Median | B10: 2.8383089 | C10: 2.8576479
A11: 75th percentile | B11: 2.9639422 | C11: 3.0947734
A12: 95th percentile | B12: 3.1696329 | C12: 3.5237234
A13: P(close above spot) | B13: 0.51874 | C13: 0.53302
A14: P(≥ +10%) | B14: 0.08014 | C14: 0.23496
A15: P(≤ −10%) | B15: 0.05528 | C15: 0.16866
A16: P(touch +5% at any point) | B16: 0.3935 | C16: 0.6544
A17: P(touch −5% at any point) | B17: 0.34584 | C17: 0.589
A19: Calibration evidence (walk-forward, this name)
A20: Windows scored (post-break) | B20: 17
A21: CRPS skill vs carry-anchored random walk | B21: 0.042398909
A22: Verdict | B22: PASS
A23: Coverage of the 80% band (over-covered: bands run wide) | B23: 0.94117647
A24: Coverage of the 90% band | B24: 0.94117647
A25: PIT mean (0.5 = centred) | B25: 0.43918529

Sheet Sensitivity
A1: Sensitivity — each cell is a complete engine revaluation (pasted)
A2: Rebuilt at revision 2 on the base convention: explicit and terminal rates shift TOGETHER, so the centre cell equals the base case. Driver vectors on Assumptions
A4: Ke shift \ g | B4: 1.5% | C4: 2.0% | D4: 2.5% | E4: 3.0% | F4: 3.5%
A5: 10.19% | B5: 4.0014413 | C5: 3.9594628 | D5: 3.9103448 | E5: 3.8527483 | F5: 3.7849775
A6: 10.69% | B6: 3.8161866 | C6: 3.7701813 | D6: 3.7169874 | E6: 3.6553302 | F6: 3.5836145
A7: 11.19% | B7: 3.6472097 | C7: 3.5983027 | D7: 3.5422817 | E7: 3.4779504 | F7: 3.4038278
A8: 11.69% | B8: 3.4924502 | C8: 3.4415194 | D8: 3.3836306 | E8: 3.3176709 | F8: 3.2422767
A9: 12.19% | B9: 3.3501819 | C9: 3.2979153 | D9: 3.2388987 | E9: 3.1721029 | F9: 3.0962784
A11: Beta 0.8 → 1.2 (base 1.03) | B11: 0.95 | C11: 1.35 | D11: 1.75 | E11: 2.14 | F11: 2.54
A12: DCF per share | B12: 5.596771 | C12: 4.33279 | D12: 3.5422817 | E12: 3.0000677 | F12: 2.5990309
A14: Development margin shift (pts) | B14: -0.04 | C14: -0.02 | D14: +0.00 | E14: +0.02 | F14: +0.04
A15: DCF per share | B15: 3.2369665 | C15: 3.3896241 | D15: 3.5422817 | E15: 3.6949394 | F15: 3.847597
A17: Conversion-rate shift (pts) | B17: -0.06 | C17: -0.03 | D17: +0.00 | E17: +0.03 | F17: +0.06
A18: DCF per share | B18: 3.1998284 | C18: 3.3833963 | D18: 3.5422817 | E18: 3.6791582 | F18: 3.796505
A20: New-sales multiple of base | B20: 0.50 | C20: 0.75 | D20: 1.00 | E20: 1.25 | F20: 1.50
A21: DCF per share | B21: 2.827625 | C21: 3.1852381 | D21: 3.5422817 | E21: 3.8993254 | F21: 4.2563691
A23: Working-capital shift (AED mn/yr) | B23: -1000 | C23: -500 | D23: +0 | E23: +500 | F23: +1000
A24: DCF per share | B24: 3.306873 | C24: 3.4245774 | D24: 3.5422817 | E24: 3.6599861 | F24: 3.7776905
A26: Receivable-days shift | B26: -60 | C26: -30 | D26: +0 | E26: +30 | F26: +60
A27: DCF per share | B27: 3.8566895 | C27: 3.6994856 | D27: 3.5422817 | E27: 3.3850779 | F27: 3.227874
A29: Cost-of-equity adder (0 = base) | B29: +0.000 | C29: +0.005 | D29: +0.010 | E29: +0.015 | F29: +0.020
A30: DCF per share | B30: 3.5422817 | C30: 3.3836306 | D30: 3.2388987 | E30: 3.1063141 | F30: 2.9843943

Sheet Per-Share & Ratios
A1: Per-share figures and ratios — all live formulas
B4: FY2023 | C4: FY2024 | D4: FY2025 | E4: H1-26A | F4: H2-26E | G4: FY27E | H4: FY28E | I4: FY29E | J4: FY30E
A5: EPS (attributable; H1 and the stub are part-year) | B5: ='Income Statement'!B17/Assumptions!$C$5 | C5: ='Income Statement'!C17/Assumptions!$C$5 | D5: ='Income Statement'!D17/Assumptions!$C$5 | E5: ='Income Statement'!E17/Assumptions!$C$5 | F5: ='Income Statement'!F17/Assumptions!$C$5 | G5: ='Income Statement'!G17/Assumptions!$C$5 | H5: ='Income Statement'!H17/Assumptions!$C$5 | I5: ='Income Statement'!I17/Assumptions!$C$5 | J5: ='Income Statement'!J17/Assumptions!$C$5
A6: Book value per share | B6: ='Balance Sheet'!B14/Assumptions!$C$5 | C6: ='Balance Sheet'!C14/Assumptions!$C$5 | D6: ='Balance Sheet'!D14/Assumptions!$C$5 | E6: ='Balance Sheet'!E14/Assumptions!$C$5 | F6: ='Balance Sheet'!F14/Assumptions!$C$5 | G6: ='Balance Sheet'!G14/Assumptions!$C$5 | H6: ='Balance Sheet'!H14/Assumptions!$C$5 | I6: ='Balance Sheet'!I14/Assumptions!$C$5 | J6: ='Balance Sheet'!J14/Assumptions!$C$5
A7: Return on attributable equity (avg; part-year annualised) | B7: - | C7: ='Income Statement'!C17/1.0/(('Balance Sheet'!C14+'Balance Sheet'!B14)/2) | D7: ='Income Statement'!D17/1.0/(('Balance Sheet'!D14+'Balance Sheet'!C14)/2) | E7: ='Income Statement'!E17/0.5/(('Balance Sheet'!E14+'Balance Sheet'!D14)/2) | F7: ='Income Statement'!F17/0.5/(('Balance Sheet'!F14+'Balance Sheet'!E14)/2) | G7: ='Income Statement'!G17/1.0/(('Balance Sheet'!G14+'Balance Sheet'!F14)/2) | H7: ='Income Statement'!H17/1.0/(('Balance Sheet'!H14+'Balance Sheet'!G14)/2) | I7: ='Income Statement'!I17/1.0/(('Balance Sheet'!I14+'Balance Sheet'!H14)/2) | J7: ='Income Statement'!J17/1.0/(('Balance Sheet'!J14+'Balance Sheet'!I14)/2)
A8: Return on invested capital (avg base, annualised) | B8: - | C8: - | D8: - | E8: - | F8: =DCF!B14/0.5/(('Summary Financials'!F13+'Summary Financials'!E13)/2) | G8: =DCF!C14/1.0/(('Summary Financials'!G13+'Summary Financials'!F13)/2) | H8: =DCF!D14/1.0/(('Summary Financials'!H13+'Summary Financials'!G13)/2) | I8: =DCF!E14/1.0/(('Summary Financials'!I13+'Summary Financials'!H13)/2) | J8: =DCF!F14/1.0/(('Summary Financials'!J13+'Summary Financials'!I13)/2)
A9: P/E at spot (full years) | B9: =Assumptions!$C$4/B5 | C9: =Assumptions!$C$4/C5 | D9: =Assumptions!$C$4/D5 | E9: - | F9: - | G9: =Assumptions!$C$4/G5 | H9: =Assumptions!$C$4/H5 | I9: =Assumptions!$C$4/I5 | J9: =Assumptions!$C$4/J5
A10: P/B at spot | B10: =Assumptions!$C$4/B6 | C10: =Assumptions!$C$4/C6 | D10: =Assumptions!$C$4/D6 | E10: =Assumptions!$C$4/E6 | F10: =Assumptions!$C$4/F6 | G10: =Assumptions!$C$4/G6 | H10: =Assumptions!$C$4/H6 | I10: =Assumptions!$C$4/I6 | J10: =Assumptions!$C$4/J6

Sheet Peer & Sector
A1: Peer & sector — one attributable basis, cross-checks only
A2: Peer attributable profits from each company's own audited filings/releases; prices 7-Aug-2026; every multiple is a live formula from its own row
A4: Peer | B4: Spot | C4: Shares (mn) | D4: Mkt cap | E4: FY2025 attributable NP | F4: Trailing P/E (attr) | G4: Backlog (own disclosure)
A5: Aldar Properties (ADX) | B5: 7.78 | C5: 7862.6 | D5: =B5*C5 | E5: 7548 | F5: =D5/E5 | G5: 71700
A6: Emaar Properties (DFM) | B6: 11.5 | C6: 8838 | D6: =B6*C6 | E6: 17599 | F6: =D6/E6 | G6: 155000
A7: Emaar Development (DFM) | B7: 13.38 | C7: 4000 | D7: =B7*C7 | E7: 11316 | F7: =D7/E7 | G7: 125200
A8: Modon Holding (this study) | B8: =Assumptions!$C$4 | C8: =Assumptions!$C$5 | D8: =B8*C8 | E8: =Assumptions!$C$71 | F8: =D8/E8 | G8: 65400
A9: (Modon backlog = 30-Jun-2026 group figure; peers = FY2025 development backlogs from their own releases — one definition per row, dated)
A11: Sector context (ADREC 2025, regulator): AED 142bn transactions (+44%); residential AED 76bn (+67%); off-plan 71% of residential deals; expatriate and foreign buyers 62% of residential sales value.
