Workbook

Sheet READ FIRST
A1: Testahil · Independent Valuation Study — Educational Analysis · Not investment advice
A3: Qatar Gas Transport Company Q.P.S.C. (Nakilat) — QE: QGTS. Companion model to the study dated 05 Jul 2026.
A5: READ FIRST — what this is, and is not. This workbook is an educational valuation exercise and a personal analytical
A6: opinion, published free of charge. It is NOT investment advice, NOT a recommendation to buy, sell or hold, and NOT
A7: directed at any reader's circumstances. The preparer is not licensed by any securities regulator, holds no brokerage
A8: authorisation, manages no money, and takes no fees or clients. All values are model outputs shown as ranges.
A10: Illustrative Monte Carlo. For Nakilat the probabilistic engine did NOT beat its naïve random-walk benchmark in the
A11: Step-0 calibration (CRPS skill ≈ 0). The 'Monte Carlo' sheet is included for illustration and methodological
A12: transparency only and must not be relied upon as a forecast for this security.
A14: Holdings disclosure. The preparer may hold, and may in the future take or dispose of, a position in the security
A15: discussed in this report, and may transact at any time without notice.
A17: How to use: change the blue inputs on the Assumptions sheet; every downstream sheet (DCF, statements, lenses,
... A20: Currency: Qatari riyal (QAR). USD/QAR 3.64. Figures in QAR bn unless stated. Market data as of 05 Jul 2026.

Sheet Summary
A1: Valuation summary — Qatar Gas Transport Company (QE: QGTS)
A2: Educational analysis. Not investment advice. Fair-value ranges & distributions only.
A4: Lens / read | B4: Output (QAR) | C4: vs spot
A5: FUNDAMENTAL
A6: DCF (primary) | B6: =DCF!$B$26 -> 4.9019032 | C6: =B6/Assumptions!$B$5-1 -> 0.13496254
A7: Two-stage DDM | B7: ='Fundamental Valuation'!D6 -> 3.5607273 | C7: =B7/Assumptions!$B$5-1 -> -0.17556673
A8: Relative multiples | B8: ='Relative & Normalized'!C7 -> 4.0028881 | C8: =B8/Assumptions!$B$5-1 -> -0.073190996
A9: Fleet-replacement NAV | B9: ='Fundamental Valuation'!D8 -> 4.0605054 | C9: =B9/Assumptions!$B$5-1 -> -0.059850564
A10: Weighted central | B10: ='Fundamental Valuation'!D9 -> 4.2884663 | C10: =B10/Assumptions!$B$5-1 -> -0.0070696231
A11: MONTE CARLO (illustrative only)
A12: T+60 median | B12: ='Monte Carlo'!D6 -> 4.3966584 | C12: =B12/Assumptions!$B$5-1 -> 0.017980634
A14: Spot (QAR, 05 Jul 2026) | B14: =Assumptions!$B$5 -> 4.319

Sheet Fundamental Valuation
A1: Fundamental valuation — five-lens football field
A2: Base values link to the lens sheets; weighted central computed here.
A4: Lens | B4: Weight | C4: Bear | D4: Base | E4: Bull
A5: DCF (contracted FCFF) | B5: 0.4 | C5: 2.4061532 | D5: =DCF!$B$26 -> 4.9019032 | E5: 8.6665247
A6: Two-stage DDM | B6: 0.2 | C6: 2.3671093 | D6: 3.5607273 | E6: 4.6192244
A7: Relative multiples | B7: 0.15 | C7: 3.2220217 | D7: ='Relative & Normalized'!C7 -> 4.0028881 | E7: 4.7837545
A8: Fleet-replacement NAV | B8: 0.25 | C8: 3.1790209 | D8: 4.0605054 | E8: 5.162361
A9: Weighted central | C9: =SUMPRODUCT($B$5:$B$8,C5:C8) -> 2.7139416 | D9: =SUMPRODUCT($B$5:$B$8,D5:D8) -> 4.2884663 | E9: =SUMPRODUCT($B$5:$B$8,E5:E8) -> 6.3986082
A11: Spot (QAR) | B11: =Assumptions!$B$5 -> 4.319
A12: Central vs spot | B12: =D9/Assumptions!$B$5-1 -> -0.0070696231

Sheet Assumptions
A1: Assumptions — the single blue-cell input layer
A2: Blue = input (change these). Black = formula. Green = cross-sheet link. Downstream sheets link here.
A4: Market & share data
A5: Spot price (QAR) | B5: 4.319 | C5: 05 Jul 2026 close
A6: Shares outstanding (bn) | B6: 5.54 | C6: Qatar Exchange
A7: USD/QAR (peg) | B7: 3.64 | C7: pegged
A8: Market cap (QAR bn) | B8: =Assumptions!$B$5*Assumptions!$B$6 -> 23.92726 | C8: computed: spot x shares
A9: Net debt (QAR bn, FY25) | B9: 18.2 | C9: total debt − cash
A10: Enterprise value (QAR bn) | B10: =Assumptions!$B$8+Assumptions!$B$9 -> 42.12726 | C10: computed: mcap + net debt
A11: Cost of capital (Ke shown explicitly = rf + b*ERP)
A12: Risk-free rate | B12: 0.045 | C12: Qatar sovereign / USD base
A13: Equity-risk premium | B13: 0.055
A14: Beta (house floor 0.8; realised ~0.34) | B14: 0.8
A15: Cost of equity Ke = rf + b*ERP | B15: =Assumptions!$B$12+Assumptions!$B$14*Assumptions!$B$13 -> 0.089 | C15: published explicitly
A16: After-tax cost of debt | B16: 0.0475 | C16: IG / ECA financing; tax ~0
A17: Equity weight | B17: =Assumptions!$B$8/Assumptions!$B$10 -> 0.5679757 | C17: market weights
A18: Debt weight | B18: =Assumptions!$B$9/Assumptions!$B$10 -> 0.4320243
A19: WACC (base input, ~7.5%) | B19: 0.075 | C19: CAPM-implied ~7.1%; rounded up for charter concentration
A20: Terminal growth g | B20: 0.015 | C20: charter escalation
A21: Tax rate | B21: 0 | C21: Qatar: ~0 on Qatari-owned
A22: DCF operating drivers
A23: FY25 charter revenue (QAR bn) | B23: 4.039 | C23: reported
A24: Revenue CAGR (5-yr) | B24: 0.04
A25: EBITDA margin | B25: 0.71
A26: FY25 D&A (QAR bn) | B26: 0.9 | C26: approx.
A27: D&A growth | B27: 0.02
A28: FY25 maintenance capex (QAR bn) | B28: 0.58
A29: Maintenance capex growth | B29: 0.02
A30: FY25 JV income (QAR bn) | B30: 0.64
A31: JV stub multiple | B31: 8.5
A32: Dividend-discount (two-stage)
A33: FY25 DPS (QAR) | B33: 0.144 | C33: 14.4 dirhams
A34: Stage-1 DPS growth (6 yrs) | B34: 0.085
A35: Terminal DPS growth | B35: 0.03
A36: DDM cost of equity | B36: 0.085
A37: Relative & NAV
A38: FY25 EBITDA (QAR bn) | B38: 2.884 | C38: computed: EBIT + D&A
A39: EV/EBITDA multiple (base) | B39: 14
A40: Mid-cycle EPS (QAR) | B40: 0.335
A41: Justified P/E (base) | B41: 13
...

Sheet Primary Lens (DCF)
A1: Primary lens — DCF (see DCF sheet)
A4: Fair value per share (QAR) | B4: =DCF!$B$26 -> 4.9019032

Sheet Segments
A1: Segments — wholly-owned vs joint-venture vs services
A4: Segment | B4: Basis | C4: FY25 contribution
A5: Wholly-owned LNG fleet | B5: Consolidated charter hire, ~20-yr QatarEnergy | C5: ~QAR 4.0 bn revenue
A6: Joint-venture vessel stakes | B6: Equity-method, ~40 vessels | C6: ~QAR 0.64 bn (JV income)
A7: FSRU & LPG carriers | B7: Long-term hire | C7: included above
A8: Shipyard & marine services | B8: Fee income (QFAB / QSTS JVs) | C8: modest stub

Sheet Relative & Normalized
A1: Relative multiples & contracted-earnings frame
A4: Relative (EV/EBITDA) | B4: Bear | C4: Base | D4: Bull
A5: EBITDA (QAR bn) | B5: =Assumptions!$B$38 -> 2.884 | C5: =Assumptions!$B$38 -> 2.884 | D5: =Assumptions!$B$38 -> 2.884
A6: EV/EBITDA multiple | B6: 12.5 | C6: =Assumptions!$B$39 -> 14 | D6: 15.5
A7: Fair value (QAR/share) | B7: =(B5*B6-Assumptions!$B$9)/Assumptions!$B$6 -> 3.2220217 | C7: =(C5*C6-Assumptions!$B$9)/Assumptions!$B$6 -> 4.0028881 | D7: =(D5*D6-Assumptions!$B$9)/Assumptions!$B$6 -> 4.7837545
A9: P/E cross-read
A10: Mid-cycle EPS (QAR) | B10: =Assumptions!$B$40 -> 0.335
A11: Justified P/E | B11: =Assumptions!$B$41 -> 13
A12: Fair value (QAR/share) | B12: =B10*B11 -> 4.355

Sheet DCF
A1: DCF — contracted-fleet FCFF (primary lens)
A2: FCFF 5-yr explicit + terminal. Inputs link to Assumptions. Terminal FCFF: renewal capex = D&A.
A4: QAR bn | B4: Yr 1 | C4: Yr 2 | D4: Yr 3 | E4: Yr 4 | F4: Yr 5
A5: Charter revenue | B5: =Assumptions!$B$23*(1+Assumptions!$B$24)^1 -> 4.20056 | C5: =Assumptions!$B$23*(1+Assumptions!$B$24)^2 -> 4.3685824 | D5: =Assumptions!$B$23*(1+Assumptions!$B$24)^3 -> 4.5433257 | E5: =Assumptions!$B$23*(1+Assumptions!$B$24)^4 -> 4.7250587 | F5: =Assumptions!$B$23*(1+Assumptions!$B$24)^5 -> 4.9140611
A6: EBITDA | B6: =B5*Assumptions!$B$25 -> 2.9823976 | C6: =C5*Assumptions!$B$25 -> 3.1016935 | D6: =D5*Assumptions!$B$25 -> 3.2257612 | E6: =E5*Assumptions!$B$25 -> 3.3547917 | F6: =F5*Assumptions!$B$25 -> 3.4889834
A7: - Depreciation & amortisation | B7: =-Assumptions!$B$26*(1+Assumptions!$B$27)^1 -> -0.918 | C7: =-Assumptions!$B$26*(1+Assumptions!$B$27)^2 -> -0.93636 | D7: =-Assumptions!$B$26*(1+Assumptions!$B$27)^3 -> -0.9550872 | E7: =-Assumptions!$B$26*(1+Assumptions!$B$27)^4 -> -0.97418894 | F7: =-Assumptions!$B$26*(1+Assumptions!$B$27)^5 -> -0.99367272
A8: EBIT | B8: =B6+B7 -> 2.0643976 | C8: =C6+C7 -> 2.1653335 | D8: =D6+D7 -> 2.270674 | E8: =E6+E7 -> 2.3806027 | F8: =F6+F7 -> 2.4953106
A9: NOPAT = EBIT x (1 - tax) | B9: =B8*(1-Assumptions!$B$21) -> 2.0643976 | C9: =C8*(1-Assumptions!$B$21) -> 2.1653335 | D9: =D8*(1-Assumptions!$B$21) -> 2.270674 | E9: =E8*(1-Assumptions!$B$21) -> 2.3806027 | F9: =F8*(1-Assumptions!$B$21) -> 2.4953106
A10: + Depreciation & amortisation | B10: =Assumptions!$B$26*(1+Assumptions!$B$27)^1 -> 0.918 | C10: =Assumptions!$B$26*(1+Assumptions!$B$27)^2 -> 0.93636 | D10: =Assumptions!$B$26*(1+Assumptions!$B$27)^3 -> 0.9550872 | E10: =Assumptions!$B$26*(1+Assumptions!$B$27)^4 -> 0.97418894 | F10: =Assumptions!$B$26*(1+Assumptions!$B$27)^5 -> 0.99367272
A11: - Maintenance / drydock capex | B11: =-Assumptions!$B$28*(1+Assumptions!$B$29)^1 -> -0.5916 | C11: =-Assumptions!$B$28*(1+Assumptions!$B$29)^2 -> -0.603432 | D11: =-Assumptions!$B$28*(1+Assumptions!$B$29)^3 -> -0.61550064 | E11: =-Assumptions!$B$28*(1+Assumptions!$B$29)^4 -> -0.62781065 | F11: =-Assumptions!$B$28*(1+Assumptions!$B$29)^5 -> -0.64036687
A12: - Change in working capital | B12: =0 -> 0 | C12: =0 -> 0 | D12: =0 -> 0 | E12: =0 -> 0 | F12: =0 -> 0
A13: Free cash flow to firm | B13: =B9+B10+B11+B12 -> 2.3907976 | C13: =C9+C10+C11+C12 -> 2.4982615 | D13: =D9+D10+D11+D12 -> 2.6102606 | E13: =E9+E10+E11+E12 -> 2.726981 | F13: =F9+F10+F11+F12 -> 2.8486165
A14: Discount factor @ WACC | B14: =1/(1+Assumptions!$B$19)^1 -> 0.93023256 | C14: =1/(1+Assumptions!$B$19)^2 -> 0.86533261 | D14: =1/(1+Assumptions!$B$19)^3 -> 0.80496057 | E14: =1/(1+Assumptions!$B$19)^4 -> 0.74880053 | F14: =1/(1+Assumptions!$B$19)^5 -> 0.69655863
A15: PV of FCFF | B15: =B13*B14 -> 2.2239978 | C15: =C13*C14 -> 2.1618272 | D15: =D13*D14 -> 2.1011569 | E15: =E13*E14 -> 2.0419648 | F15: =F13*F14 -> 1.9842284
A17: DCF bridge to equity value
A18: Sum PV explicit FCFF (yrs 1-5) | B18: =SUM(B15:F15) -> 10.513175
A19: Terminal value = Yr5 NOPAT x(1+g)/(WACC-g) | B19: =F9*(1+Assumptions!$B$20)/(Assumptions!$B$19-Assumptions!$B$20) -> 42.212338
A20: PV of terminal value | B20: =B19/((1+Assumptions!$B$19)^5) -> 29.403369
A21: Enterprise value - operations | B21: =B18+B20 -> 39.916544
A22: + Joint-venture fleet stub (JV x mult) | B22: =Assumptions!$B$30*Assumptions!$B$31 -> 5.44
A23: Enterprise value - total | B23: =B21+B22 -> 45.356544
A24: - Net debt | B24: =-Assumptions!$B$9 -> -18.2
A25: Equity value | B25: =B23+B24 -> 27.156544
A26: Fair value per share (QAR) | B26: =B25/Assumptions!$B$6 -> 4.9019032
A27: Terminal value as % of EV | B27: =B20/B23 -> 0.64827181

Sheet Income Statement
A1: Income statement (consolidated, QAR bn)
A2: FY23-25 reported (blue); FY26-30e forecast (formulas link to Assumptions).
A4: Line | B4: FY23 | C4: FY24 | D4: FY25 | E4: FY26e | F4: FY27e | G4: FY28e | H4: FY29e | I4: FY30e
A5: Charter revenue | B5: 3.626 | C5: 3.669 | D5: 4.039 | E5: =Assumptions!$B$23*(1+Assumptions!$B$24)^1 -> 4.20056 | F5: =Assumptions!$B$23*(1+Assumptions!$B$24)^2 -> 4.3685824 | G5: =Assumptions!$B$23*(1+Assumptions!$B$24)^3 -> 4.5433257 | H5: =Assumptions!$B$23*(1+Assumptions!$B$24)^4 -> 4.7250587 | I5: =Assumptions!$B$23*(1+Assumptions!$B$24)^5 -> 4.9140611
A6: EBITDA | B6: 2.716 | C6: 2.748 | D6: 2.884 | E6: =E5*Assumptions!$B$25 -> 2.9823976 | F6: =F5*Assumptions!$B$25 -> 3.1016935 | G6: =G5*Assumptions!$B$25 -> 3.2257612 | H6: =H5*Assumptions!$B$25 -> 3.3547917 | I6: =I5*Assumptions!$B$25 -> 3.4889834
A7: - D&A | B7: -0.935 | C7: -0.839 | D7: -0.9 | E7: =-Assumptions!$B$26*(1+Assumptions!$B$27)^1 -> -0.918 | F7: =-Assumptions!$B$26*(1+Assumptions!$B$27)^2 -> -0.93636 | G7: =-Assumptions!$B$26*(1+Assumptions!$B$27)^3 -> -0.9550872 | H7: =-Assumptions!$B$26*(1+Assumptions!$B$27)^4 -> -0.97418894 | I7: =-Assumptions!$B$26*(1+Assumptions!$B$27)^5 -> -0.99367272
A8: EBIT | B8: =B6+B7 -> 1.781 | C8: =C6+C7 -> 1.909 | D8: =D6+D7 -> 1.984 | E8: =E6+E7 -> 2.0643976 | F8: =F6+F7 -> 2.1653335 | G8: =G6+G7 -> 2.270674 | H8: =H6+H7 -> 2.3806027 | I8: =I6+I7 -> 2.4953106
A9: - Net finance cost | B9: -1.007 | C9: -0.946 | D9: -0.882 | E9: -0.84 | F9: -0.82 | G9: -0.85 | H9: -0.87 | I9: -0.845
A10: + Share of JV results | B10: 0.785 | C10: 0.675 | D10: 0.64 | E10: 0.645 | F10: 0.66 | G10: 0.68 | H10: 0.7 | I10: 0.72
A11: Net profit | B11: =B8+B9+B10 -> 1.559 | C11: =C8+C9+C10 -> 1.638 | D11: =D8+D9+D10 -> 1.742 | E11: =E8+E9+E10 -> 1.8693976 | F11: =F8+F9+F10 -> 2.0053335 | G11: =G8+G9+G10 -> 2.100674 | H11: =H8+H9+H10 -> 2.2106027 | I11: =I8+I9+I10 -> 2.3703106
A12: EPS (QAR) | B12: =B11/Assumptions!$B$6 -> 0.28140794 | C12: =C11/Assumptions!$B$6 -> 0.29566787 | D12: =D11/Assumptions!$B$6 -> 0.31444043 | E12: =E11/Assumptions!$B$6 -> 0.33743639 | F12: =F11/Assumptions!$B$6 -> 0.36197356 | G12: =G11/Assumptions!$B$6 -> 0.37918304 | H12: =H11/Assumptions!$B$6 -> 0.39902577 | I12: =I11/Assumptions!$B$6 -> 0.42785391
A13: DPS (QAR) | B13: 0.13 | C13: 0.14 | D13: 0.144 | E13: 0.15 | F13: 0.158 | G13: 0.166 | H13: 0.175 | I13: 0.185

Sheet Balance Sheet
A1: Balance sheet (consolidated, QAR bn)
A2: FY23-25 reported; FY26-27e trajectory (newbuild-financed).
A4: Line | B4: FY23 | C4: FY24 | D4: FY25 | E4: FY26e | F4: FY27e
A5: Total assets | B5: 31.977 | C5: 34.36 | D5: 36.43 | E5: 38.9 | F5: 41.5
A6: Property & equipment (vessels) | B6: 23.9 | C6: 24.6 | D6: 25.1 | E6: 27.5 | F6: 30.2
A7: Cash & deposits | B7: 2.2 | C7: 2.6 | D7: 2.4 | E7: 2.3 | F7: 2.2
A8: Total debt | B8: 17.6 | C8: 19.5 | D8: 20.6 | E8: 22 | F8: 24
A9: Total equity (common) | B9: 12.084 | C9: 13.259 | D9: 13.845 | E9: 14.5 | F9: 15.2
A10: Net debt | B10: =B8-B7 -> 15.4 | C10: =C8-C7 -> 16.9 | D10: =D8-D7 -> 18.2 | E10: =E8-E7 -> 19.7 | F10: =F8-F7 -> 21.8
A11: Book value / share (QAR) | B11: =B9/Assumptions!$B$6 -> 2.1812274 | C11: =C9/Assumptions!$B$6 -> 2.3933213 | D11: =D9/Assumptions!$B$6 -> 2.4990975 | E11: =E9/Assumptions!$B$6 -> 2.6173285 | F11: =F9/Assumptions!$B$6 -> 2.7436823

Sheet Cash Flow
A1: Cash flow & markers (QAR bn)
A2: Approximate from summary disclosure; sub-1x FCF dividend cover reflects newbuild capex.
A4: Line | B4: FY23 | C4: FY24 | D4: FY25
A5: Operating cash flow (approx.) | B5: 2.6 | C5: 2.7 | D5: 2.8
A6: Maintenance / drydock capex | B6: -0.5 | C6: -0.6 | D6: -0.6
A7: Growth capex (newbuild programme) | B7: -0.6 | C7: -1.4 | D7: -1.8
A8: Dividends paid | B8: -0.72 | C8: -0.78 | D8: -0.8
A9: Net finance cost | B9: -1.007 | C9: -0.946 | D9: -0.882

Sheet Summary Financials
A1: Summary financials
A2: Every cell links to the statement sheets (green).
A4: Line | B4: FY23 | C4: FY24 | D4: FY25 | E4: FY26e | F4: FY30e
A5: Charter revenue | B5: ='Income Statement'!B5 -> 3.626 | C5: ='Income Statement'!C5 -> 3.669 | D5: ='Income Statement'!D5 -> 4.039 | E5: ='Income Statement'!E5 -> 4.20056 | F5: ='Income Statement'!I5 -> 4.9140611
A6: EBITDA | B6: ='Income Statement'!B6 -> 2.716 | C6: ='Income Statement'!C6 -> 2.748 | D6: ='Income Statement'!D6 -> 2.884 | E6: ='Income Statement'!E6 -> 2.9823976 | F6: ='Income Statement'!I6 -> 3.4889834
A7: Net profit | B7: ='Income Statement'!B11 -> 1.559 | C7: ='Income Statement'!C11 -> 1.638 | D7: ='Income Statement'!D11 -> 1.742 | E7: ='Income Statement'!E11 -> 1.8693976 | F7: ='Income Statement'!I11 -> 2.3703106
A8: EPS (QAR) | B8: ='Income Statement'!B12 -> 0.28140794 | C8: ='Income Statement'!C12 -> 0.29566787 | D8: ='Income Statement'!D12 -> 0.31444043 | E8: ='Income Statement'!E12 -> 0.33743639 | F8: ='Income Statement'!I12 -> 0.42785391

Sheet Monte Carlo
A1: Monte Carlo — illustrative only (engine ties benchmark, see Calibration)
A2: YZ-HAR width, Student-t(5), zero drift, 16 factors, 50,000 paths, seed 42. NOT a reliable forecast for this name.
A4: Horizon | B4: p5 | C4: p25 | D4: p50 | E4: p75 | F4: p95
A5: T+20 sessions | B5: 3.8608187 | C5: 4.1637378 | D5: 4.34337 | E5: 4.5350515 | F5: 4.8765
A6: T+60 sessions | B6: 3.5967306 | C6: 4.075662 | D6: 4.3966584 | E6: 4.738791 | F6: 5.3644637
A8: Ann. vol (YZ-HAR) | B8: 0.23233908
A9: Net drift (quarter) | B9: 0.012
A11: Level-touch ladder
A12: Level (QAR) | B12: T+20 touch | C12: T+60 touch
A13: 4.9 | B13: 0.0687 | C13: 0.28008
A14: 4.7 | B14: 0.1823 | C14: 0.45322
A15: 4.55 | B15: 0.37136 | C15: 0.62682
A16: 4.4 | B16: 0.68452 | C16: 0.83074
A17: 4.32 | B17: 0.88582 | C17: 0.94066
A18: 4.2 | B18: 0.52248 | C18: 0.69058
A19: 4.05 | B19: 0.23748 | C19: 0.45482
A20: 3.9 | B20: 0.09866 | C20: 0.28392

Sheet Sensitivity
A1: DCF sensitivity — WACC x terminal growth (QAR/share)
A2: Base cell near spot boxed in the study figure.
A4: WACC \ g | B4: 1.0% | C4: 1.5% | D4: 2.0% | E4: 2.5%
A5: 6.50% | B5: 5.68 | C5: 6.32 | D5: 7.1 | E5: 8.07
A6: 7.00% | B6: 5.03 | C6: 5.55 | D6: 6.17 | E6: 6.94
A7: 7.25% | B7: 4.74 | C7: 5.21 | D7: 5.77 | E7: 6.46
A8: 7.50% | B8: 4.47 | C8: 4.9 | D8: 5.41 | E8: 6.03
A9: 8.00% | B9: 3.99 | C9: 4.36 | D9: 4.78 | E9: 5.28

Sheet Per-Share & Ratios
A1: Per-share & ratios dashboard (the house Data Miner)
A4: Metric | B4: FY25 | C4: Metric | D4: FY25
A5: EPS (QAR) | B5: =Assumptions!$B$6*0+'Income Statement'!D12 -> 0.31444043 | C5: P/E | D5: =Assumptions!$B$5/'Income Statement'!D12 -> 13.735511
A6: DPS (QAR) | B6: ='Income Statement'!D13 -> 0.144 | C6: P/B | D6: =Assumptions!$B$5/'Balance Sheet'!D10 -> 0.23730769
A7: BVPS (QAR) | B7: ='Balance Sheet'!D10 -> 18.2 | C7: EV/EBITDA | D7: =Assumptions!$B$10/Assumptions!$B$38 -> 14.607233
A8: Dividend yield | B8: ='Income Statement'!D13/Assumptions!$B$5 -> 0.033341051 | C8: Net debt / EBITDA | D8: =Assumptions!$B$9/Assumptions!$B$38 -> 6.3106796
A9: Payout ratio | B9: ='Income Statement'!D13/'Income Statement'!D12 -> 0.45795637 | C9: ROE (approx.) | D9: 0.125
A10: EBITDA margin | B10: =Assumptions!$B$25 -> 0.71 | C10: Beta (realised) | D10: 0.34

Sheet Peer & Sector
A1: Peer set & sector structure
A4: Peer | B4: Profile | C4: EV/EBITDA | D4: Div yield
A5: Nakilat (QGTS) | B5: 20-25-yr QatarEnergy charters | C5: ~14-15x | D5: ~3.3%
A6: Flex LNG (FLNG) | B6: Long + some spot cover | C6: ~13x | D6: ~9-10%
A7: Capital Clean Energy (CCEC) | B7: Long charters + newbuilds | C7: ~11-13x | D7: ~4-5%
A8: ADNOC L&S | B8: Integrated logistics & shipping | C8: ~9-11x | D8: ~3-4%
A9: Bahri (Saudi) | B9: VLCC/product/dry - cyclical | C9: ~7-9x | D9: ~4-6%
A10: Excelerate Energy (EE) | B10: FSRU / LNG infrastructure | C10: premium | D10: ~1%
