Workbook

Sheet READ FIRST
A1: TESTAHIL — INDEPENDENT VALUATION STUDY · EDUCATIONAL ANALYSIS · NOT INVESTMENT ADVICE
A4: Orascom Construction PLC (EGX: ORAS) — workbook companion to the study dated 30 June 2026.
A6: This model is educational. It is not investment advice, not a recommendation, and not a price target.
A7: It presents a distribution of fair-value estimates across independent methods, plus a probabilistic 3-month price map.
A9: HOW TO USE: every blue cell on the 'Assumptions' sheet is an input. Change a blue cell and the whole model reprices —
A10: all downstream sheets link back to Assumptions; there are no hard-coded duplicates of an input.
A12: Primary lens: going-concern FCFF (DCF), cross-checked by SOTP/RNAV, relative multiples, and normalized earnings.
A13: Reporting currency is USD (company reports in USD); per-share values convert to EGP at the USD/EGP on Assumptions.
A14: The EGX line trades in EGP; spot 720 EGP ≈ $14.63 at 49.2, ≈ 8.3x earnings.
A16: Net cash is shown two ways — reported, and 'usable' (net of client advances / bonding). This is the model's central swing.
A18: Figures are unaudited estimates from company disclosure; see source notes. Rounding may cause small differences.
A19: Full disclosures are in the accompanying Word study.

Sheet Summary
A1: SUMMARY — ORASCOM CONSTRUCTION (EGX: ORAS)
A3: Item | B3: Value | C3: Note
A4: Spot (EGP, 30-Jun-26) | B4: =Assumptions!$B$5 -> 720 | C4: EGX close
A5: Weighted central FV (EGP) | B5: ='Fundamental Valuation'!B9 -> 927.63493 | C5: four-lens
A6: Upside / (downside) | B6: ='Fundamental Valuation'!B9/Assumptions!$B$5-1 -> 0.28838184
A7: FCFF DCF (EGP) | B7: =DCF!B18 -> 1005.9458 | C7: primary
A8: SOTP / RNAV (EGP) | B8: =SOTP!B11 -> 1030.3426 | C8: cross-check
A9: Relative (EGP) | B9: ='Relative & Normalized'!D7 -> 897.89702
A10: Normalized (EGP) | B10: ='Relative & Normalized'!D12 -> 740.2323 | C10: bear anchor
A11: P/E (reported) | B11: =(Assumptions!$B$5/Assumptions!$B$6*Assumptions!$B$7)/Assumptions!$B$14 -> 8.2786598
A12: EV/EBITDA (adj, usable cash) | B12: =(Assumptions!$B$5/Assumptions!$B$6*Assumptions!$B$7-Assumptions!$B$25)/Assumptions!$B$13 -> 4.3937787
A13: MC median T+60 (EGP) | B13: 714 | C13: 3-month price map
A14: P(touch central FV by T+60) | B14: 23% | C14: two-clocks
A15: Backlog (USD bn) | B15: =Assumptions!$B$27/1000 -> 9.0254 | C15: $13.0bn pro forma

Sheet Fundamental Valuation
A1: FUNDAMENTAL VALUATION — FOUR-LENS SYNTHESIS
A3: Method | B3: Fair value (EGP) | C3: vs spot | D3: Weight | E3: Contribution
A4: FCFF DCF (primary) | B4: =DCF!B18 -> 1005.9458 | C4: =B4/Assumptions!$B$5-1 -> 0.39714689 | D4: =Assumptions!$B$58 -> 0.25 | E4: =B4*D4 -> 251.48644
A5: SOTP — base | B5: =SOTP!B11 -> 1030.3426 | C5: =B5/Assumptions!$B$5-1 -> 0.43103146 | D5: =Assumptions!$B$59 -> 0.18 | E5: =B5*D5 -> 185.46168
A6: SOTP — bull | B6: =SOTP!B21 -> 1271.9673 | C6: =B6/Assumptions!$B$5-1 -> 0.76662129 | D6: =Assumptions!$B$60 -> 0.07 | E6: =B6*D6 -> 89.037713
A7: Relative multiples | B7: ='Relative & Normalized'!D7 -> 897.89702 | C7: =B7/Assumptions!$B$5-1 -> 0.2470792 | D7: =Assumptions!$B$61 -> 0.2 | E7: =B7*D7 -> 179.5794
A8: Normalized earnings | B8: ='Relative & Normalized'!D12 -> 740.2323 | C8: =B8/Assumptions!$B$5-1 -> 0.028100423 | D8: =Assumptions!$B$62 -> 0.3 | E8: =B8*D8 -> 222.06969
A9: Weighted central (EGP) | B9: =SUM(E4:E8)/SUM(D4:D8) -> 927.63493
A10: Spot (EGP) | B10: =Assumptions!$B$5 -> 720
A11: Upside / (downside) | B11: ='Fundamental Valuation'!B9/Assumptions!$B$5-1 -> 0.28838184
A13: Range low (EGP) | B13: =MIN(B4:B8) -> 740.2323
A14: Range high (EGP) | B14: =MAX(B4:B8) -> 1271.9673

Sheet Assumptions
A1: ORASCOM CONSTRUCTION (EGX: ORAS) — ASSUMPTIONS
A2: All blue cells are inputs. USD million unless noted. Edit to reprice the whole model.
A4: GLOBAL & CORPORATE
A5: Spot price (EGP, 30-Jun-26 close) | B5: 720 | D5: EGX close (user data)
A6: USD/EGP | B6: 49.2 | D6: interbank 29-Jun-26
A7: Shares outstanding (m, net of treasury) | B7: 110.2 | D7: issued ~116.6m
A8: Tax rate (effective) | B8: 0.22
A10: FY2025 REPORTED (USD m) — company PR 31-Mar-2026
A11: Revenue | B11: 5049.8
A12: EBITDA (reported) | B12: 305
A13: EBITDA (adjusted, ex one-offs) | B13: 276 | D13: ex $29m claim/arbitration
A14: Net income attributable | B14: 194.8
A15: Net income (adjusted) | B15: 165.8
A16: of which BESIX 50% equity income | B16: 24.7
A17: of which concessions net | B17: 12.7
A18: of which materials/equip/FM net | B18: 25.6
A19: D&A | B19: 45 | D19: est.
A20: Capex | B20: 80 | D20: est.
A22: BALANCE SHEET (USD m) — est. anchored to disclosed totals
A23: Gross cash | B23: 1100 | D23: TA $5.2bn, cash end-24 $1,041m
A24: Gross debt | B24: 560 | D24: D/E ~0.6x
A25: Usable net cash (ex client advances) | B25: 400 | D25: CENTRAL SWING
A26: Shareholders' equity | B26: 873.2
A27: Backlog (consolidated) | B27: 9025.4
A28: Backlog (pro forma incl. 50% BESIX) | B28: 12963.6
A30: DCF INPUTS
A31: WACC (USD) | B31: 0.12
A32: Terminal growth g | B32: 0.035
A33: Stage-1 FCFF growth | B33: 0.08
A34: FCFF base year (USD m) | B34: 110.18 | D34: NOPAT+D&A−capex−ΔWC
A35: BESIX 50% stake value (USD m) | B35: 240 | D35: ~10x equity income
A37: SOTP MARKS (USD m)
A38: Core E&C EBITDA (pure) | B38: 206 | D38: ex concessions & materials
A39: Core E&C EV/EBITDA (x) | B39: 5.5
A40: Concessions platform equity | B40: 330 | D40: 912.5MW op +900MW signed
A41: Materials/equip/FM equity | B41: 204.8 | D41: ~8x net
A43: RELATIVE & NORMALIZED
A44: Peer EV/EBITDA (x) | B44: 5.5
A45: Peer P/E (x) | B45: 10
A46: Peer EV/Sales (x) | B46: 0.35
...

Sheet SOTP
A1: SUM-OF-THE-PARTS / RNAV (cross-check)
A3: Component | B3: USD m | C3: Basis
A4: Core E&C operating EV | B4: =Assumptions!$B$38*Assumptions!$B$39 -> 1133 | C4: EV/EBITDA
A5: Concessions platform (renewables/water) | B5: =Assumptions!$B$40 -> 330 | C5: equity, growing 6x
A6: BESIX 50% stake | B6: =Assumptions!$B$35 -> 240 | C6: ~10x equity income
A7: Building materials / equipment / FM | B7: =Assumptions!$B$41 -> 204.8 | C7: ~8x net income
A8: Usable net cash (ex client advances) | B8: =Assumptions!$B$25 -> 400 | C8: reported less advances
A9: Equity value (USD m) | B9: =SUM(B4:B8) -> 2307.8
A10: Per share (USD) | B10: =SOTP!B9/Assumptions!$B$7 -> 20.941924
A11: Per share (EGP) | B11: =SOTP!B9/Assumptions!$B$7*Assumptions!$B$6 -> 1030.3426
A12: vs spot | B12: =SOTP!B11/Assumptions!$B$5-1 -> 0.43103146
A14: SOTP — BULL CASE
A15: Core E&C operating EV | B15: =Assumptions!$B$38*Assumptions!$B$51 -> 1339
A16: Concessions (premium) | B16: =Assumptions!$B$52 -> 450
A17: BESIX 50% (bull) | B17: =Assumptions!$B$53 -> 290
A18: Materials/equip/FM (bull) | B18: =Assumptions!$B$54 -> 230
A19: Net cash (full reported) | B19: =Assumptions!$B$55 -> 540
A20: Equity value (bull) | B20: =SUM(B15:B19) -> 2849
A21: Per share (EGP, bull) | B21: =SOTP!B20/Assumptions!$B$7*Assumptions!$B$6 -> 1271.9673

Sheet Segments
A1: SEGMENTS (FY2025, USD m / %)
A3: Segment | B3: Revenue | C3: EBITDA | D3: Backlog share
A4: MEA (Egypt+Gulf) | B4: 2849.3 | C4: 236.4 | D4: 54.3% Egy +11% Gulf
A5: USA (Weitz/Contrack) | B5: 2200.5 | C5: 68.6 | D5: 32.1%
A6: Concessions (net inc $12.7m) | B6: — | C6: — | D6: renewables/water
A7: Materials/Equip/FM (net $25.6m) | B7: — | C7: — | D7: —
A8: BESIX 50% (equity, net $24.7m) | B8: — | C8: — | D8: €6.7bn standalone
A9: Group revenue | B9: =Assumptions!$B$11 -> 5049.8

Sheet Relative & Normalized
A1: RELATIVE MULTIPLES & NORMALIZED EARNINGS
A3: Lens | B3: Metric (USD m) | C3: Multiple | D3: Per share (EGP)
A4: EV/EBITDA | B4: =Assumptions!$B$13 -> 276 | C4: =Assumptions!$B$44 -> 5.5 | D4: =(Assumptions!$B$13*Assumptions!$B$44+Assumptions!$B$25)/Assumptions!$B$7*Assumptions!$B$6 -> 856.31216
A5: P/E (reported) | B5: =Assumptions!$B$14 -> 194.8 | C5: =Assumptions!$B$45 -> 10 | D5: =(Assumptions!$B$14*Assumptions!$B$45)/Assumptions!$B$7*Assumptions!$B$6 -> 869.70599
A6: EV/Sales | B6: =Assumptions!$B$11 -> 5049.8 | C6: =Assumptions!$B$46 -> 0.35 | D6: =(Assumptions!$B$11*Assumptions!$B$46+Assumptions!$B$25)/Assumptions!$B$7*Assumptions!$B$6 -> 967.67292
A7: Relative mean (EGP) | D7: =AVERAGE(D4:D6) -> 897.89702
A9: Normalized earnings power
A10: Normalized net (USD m) | B10: =Assumptions!$B$47 -> 165.8
A11: Justified P/E | C11: =Assumptions!$B$48 -> 10
A12: Per share (EGP) | D12: =Assumptions!$B$47*Assumptions!$B$48/Assumptions!$B$7*Assumptions!$B$6 -> 740.2323

Sheet DCF
A1: CONSOLIDATED FCFF DCF — going-concern (primary lens)
A2: FCFF grows at stage-1 rate; Gordon terminal. BESIX stake + usable net cash added to operating EV.
A4: USD m | B4: 2026e | C4: 2027e | D4: 2028e | E4: 2029e | F4: 2030e
A5: Unlevered FCFF | B5: =Assumptions!$B$34*(1+Assumptions!$B$33) -> 118.9944 | C5: =B5*(1+Assumptions!$B$33) -> 128.51395 | D5: =C5*(1+Assumptions!$B$33) -> 138.79507 | E5: =D5*(1+Assumptions!$B$33) -> 149.89867 | F5: =E5*(1+Assumptions!$B$33) -> 161.89057
A6: Discount factor @ WACC | B6: =1/(1+Assumptions!$B$31)^1 -> 0.89285714 | C6: =1/(1+Assumptions!$B$31)^2 -> 0.79719388 | D6: =1/(1+Assumptions!$B$31)^3 -> 0.71178025 | E6: =1/(1+Assumptions!$B$31)^4 -> 0.63551808 | F6: =1/(1+Assumptions!$B$31)^5 -> 0.56742686
A7: PV of FCFF | B7: =B5*B6 -> 106.245 | C7: =C5*C6 -> 102.45054 | D7: =D5*D6 -> 98.791588 | E7: =E5*E6 -> 95.263317 | F7: =F5*F6 -> 91.861056
A9: PV of explicit FCFF | B9: =SUM(B7:F7) -> 494.6115
A10: Terminal value (Gordon) | B10: =F5*(1+Assumptions!$B$32)/(Assumptions!$B$31-Assumptions!$B$32) -> 1971.2557
A11: PV of terminal value | B11: =B10/(1+Assumptions!$B$31)^5 -> 1118.5434
A12: Operating enterprise value | B12: =B9+B11 -> 1613.1549
A13: (+) Usable net cash | B13: =Assumptions!$B$25 -> 400
A14: (+) BESIX 50% stake | B14: =Assumptions!$B$35 -> 240
A15: Equity value (USD m) | B15: =B12+B13+B14 -> 2253.1549
A17: Per share (USD) | B17: =DCF!B15/Assumptions!$B$7 -> 20.446052
A18: Per share (EGP) | B18: =DCF!B15/Assumptions!$B$7*Assumptions!$B$6 -> 1005.9458
A19: vs spot | B19: =DCF!B18/Assumptions!$B$5-1 -> 0.39714689

Sheet Income Statement
A1: CONSOLIDATED INCOME STATEMENT (USD m)
B3: 2023a | C3: 2024a | D3: 2025a | E3: 2026e | F3: 2027e | G3: 2028e | H3: 2029e | I3: 2030e
A4: MEA revenue | B4: 1842 | C4: 1611 | D4: 2849 | E4: 3050 | F4: 3300 | G4: 3520 | H4: 3700 | I4: 3870
A5: USA revenue | B5: 1600 | C5: 1644 | D5: 2201 | E5: 2500 | F5: 2750 | G5: 2980 | H5: 3200 | I5: 3430
A6: Total revenue | B6: 3442 | C6: 3255 | D6: 5050 | E6: 5550 | F6: 6050 | G6: 6500 | H6: 6900 | I6: 7300
A7: growth YoY | B7: — | C7: -5% | D7: +55% | E7: +10% | F7: +9% | G7: +7% | H7: +6% | I7: +6%
A8: Operating expenses | B8: -3252 | C8: -3103 | D8: -4745 | E8: -5220 | F8: -5690 | G8: -6112 | H8: -6486 | I8: -6862
A9: EBITDA | B9: 190 | C9: 152 | D9: 305 | E9: 330 | F9: 360 | G9: 388 | H9: 414 | I9: 438
A10: EBITDA margin | B10: 5.5% | C10: 4.7% | D10: 6.0% | E10: 5.9% | F10: 6.0% | G10: 6.0% | H10: 6.0% | I10: 6.0%
A11: (−) D&A | B11: -30 | C11: -31 | D11: -45 | E11: -50 | F11: -55 | G11: -59 | H11: -62 | I11: -66
A12: Operating profit (EBIT) | B12: 160 | C12: 121 | D12: 260 | E12: 280 | F12: 305 | G12: 329 | H12: 352 | I12: 372
A13: Net finance, FX & associates | B13: 50 | C13: 29 | D13: 14 | E13: 18 | F13: 23 | G13: 32 | H13: 40 | I13: 48
A14: Pre-tax profit | B14: 210 | C14: 150 | D14: 274 | E14: 298 | F14: 328 | G14: 361 | H14: 392 | I14: 420
A15: Tax & minorities | B15: -51 | C15: -32 | D15: -79 | E15: -88 | F15: -100 | G15: -115 | H15: -127 | I15: -139
A16: Net income (attrib.) | B16: 159 | C16: 118 | D16: 195 | E16: 210 | F16: 228 | G16: 246 | H16: 265 | I16: 281
A17: net margin | B17: 4.6% | C17: 3.6% | D17: 3.9% | E17: 3.8% | F17: 3.8% | G17: 3.8% | H17: 3.8% | I17: 3.9%
A18: of which one-offs | B18: 107 | C18: 0 | D18: 29 | E18: 0 | F18: 0 | G18: 0 | H18: 0 | I18: 0
A19: Adjusted net income | B19: 52 | C19: 118 | D19: 166 | E19: 210 | F19: 228 | G19: 246 | H19: 265 | I19: 281
A20: EPS (USD) | B20: 1.44 | C20: 1.07 | D20: 1.77 | E20: 1.91 | F20: 2.07 | G20: 2.23 | H20: 2.4 | I20: 2.55

Sheet Balance Sheet
A1: CONSOLIDATED BALANCE SHEET (USD m)
B3: 2023a | C3: 2024a | D3: 2025a | E3: 2026e | F3: 2027e | G3: 2028e | H3: 2029e | I3: 2030e
A4: Cash & equivalents | B4: 696 | C4: 1041 | D4: 1100 | E4: 1180 | F4: 1270 | G4: 1360 | H4: 1450 | I4: 1540
A5: Trade & other receivables | B5: 1200 | C5: 1728 | D5: 2050 | E5: 2250 | F5: 2450 | G5: 2630 | H5: 2790 | I5: 2950
A6: Contract work in progress | B6: 600 | C6: 673 | D6: 820 | E6: 900 | F6: 980 | G6: 1050 | H6: 1110 | I6: 1175
A7: Inventories | B7: 180 | C7: 271 | D7: 330 | E7: 360 | F7: 390 | G7: 420 | H7: 445 | I7: 470
A8: Total current assets | B8: 2676 | C8: 3713 | D8: 4300 | E8: 4690 | F8: 5090 | G8: 5460 | H8: 5795 | I8: 6135
A9: Property, plant & equipment | B9: 450 | C9: 500 | D9: 620 | E9: 710 | F9: 800 | G9: 880 | H9: 955 | I9: 1030
A10: Concessions & infra assets | B10: 250 | C10: 275 | D10: 330 | E10: 370 | F10: 410 | G10: 450 | H10: 485 | I10: 520
A11: Investments (BESIX & assoc.) | B11: 300 | C11: 330 | D11: 360 | E11: 386 | F11: 414 | G11: 444 | H11: 476 | I11: 510
A12: Goodwill & other non-current | B12: 420 | C12: 382 | D12: 490 | E12: 520 | F12: 550 | G12: 580 | H12: 610 | I12: 640
A13: Total non-current assets | B13: 1420 | C13: 1487 | D13: 1800 | E13: 1986 | F13: 2174 | G13: 2354 | H13: 2526 | I13: 2700
A14: Total assets | B14: 4096 | C14: 5200 | D14: 6100 | E14: 6676 | F14: 7264 | G14: 7814 | H14: 8321 | I14: 8835
A15: Trade & other payables | B15: 1500 | C15: 2033 | D15: 2560 | E15: 2810 | F15: 3050 | G15: 3270 | H15: 3470 | I15: 3670
... A27: Net cash (cash − borrowings) | B27: 246 | C27: 521 | D27: 540 | E27: 590 | F27: 650 | G27: 710 | H27: 775 | I27: 840

Sheet Cash Flow
A1: CONSOLIDATED CASH FLOW (USD m)
B3: 2023a | C3: 2024a | D3: 2025a | E3: 2026e | F3: 2027e | G3: 2028e | H3: 2029e | I3: 2030e
A4: Operating cash flow | B4: 217 | C4: 645 | D4: 520 | E4: 470 | F4: 500 | G4: 540 | H4: 575 | I4: 610
A5: Investing cash flow | B5: 84 | C5: -63 | D5: -150 | E5: -180 | F5: -190 | G5: -200 | H5: -210 | I5: -220
A6: Financing cash flow | B6: -72 | C6: 3 | D6: -180 | E6: -210 | F6: -220 | G6: -250 | H6: -275 | I6: -290
A7: Net change in cash | B7: 229 | C7: 584 | D7: 190 | E7: 80 | F7: 90 | G7: 90 | H7: 90 | I7: 100

Sheet Summary Financials
A1: SUMMARY FINANCIALS (links to statement sheets)
B3: 2023a | C3: 2024a | D3: 2025a | E3: 2026e | F3: 2027e | G3: 2028e | H3: 2029e | I3: 2030e
A4: Total revenue | B4: ='Income Statement'!B6 -> 3442 | C4: ='Income Statement'!C6 -> 3255 | D4: ='Income Statement'!D6 -> 5050 | E4: ='Income Statement'!E6 -> 5550 | F4: ='Income Statement'!F6 -> 6050 | G4: ='Income Statement'!G6 -> 6500 | H4: ='Income Statement'!H6 -> 6900 | I4: ='Income Statement'!I6 -> 7300
A5: EBITDA | B5: ='Income Statement'!B9 -> 190 | C5: ='Income Statement'!C9 -> 152 | D5: ='Income Statement'!D9 -> 305 | E5: ='Income Statement'!E9 -> 330 | F5: ='Income Statement'!F9 -> 360 | G5: ='Income Statement'!G9 -> 388 | H5: ='Income Statement'!H9 -> 414 | I5: ='Income Statement'!I9 -> 438
A6: Net income (attrib.) | B6: ='Income Statement'!B16 -> 159 | C6: ='Income Statement'!C16 -> 118 | D6: ='Income Statement'!D16 -> 195 | E6: ='Income Statement'!E16 -> 210 | F6: ='Income Statement'!F16 -> 228 | G6: ='Income Statement'!G16 -> 246 | H6: ='Income Statement'!H16 -> 265 | I6: ='Income Statement'!I16 -> 281
A7: Total assets | B7: ='Balance Sheet'!B14 -> 4096 | C7: ='Balance Sheet'!C14 -> 5200 | D7: ='Balance Sheet'!D14 -> 6100 | E7: ='Balance Sheet'!E14 -> 6676 | F7: ='Balance Sheet'!F14 -> 7264 | G7: ='Balance Sheet'!G14 -> 7814 | H7: ='Balance Sheet'!H14 -> 8321 | I7: ='Balance Sheet'!I14 -> 8835
A8: Equity attributable | B8: ='Balance Sheet'!B22 -> 696 | C8: ='Balance Sheet'!C22 -> 873 | D8: ='Balance Sheet'!D22 -> 873 | E8: ='Balance Sheet'!E22 -> 996 | F8: ='Balance Sheet'!F22 -> 1149 | G8: ='Balance Sheet'!G22 -> 1284 | H8: ='Balance Sheet'!H22 -> 1408 | I8: ='Balance Sheet'!I22 -> 1537
A9: Operating cash flow | B9: ='Cash Flow'!B4 -> 217 | C9: ='Cash Flow'!C4 -> 645 | D9: ='Cash Flow'!D4 -> 520 | E9: ='Cash Flow'!E4 -> 470 | F9: ='Cash Flow'!F4 -> 500 | G9: ='Cash Flow'!G4 -> 540 | H9: ='Cash Flow'!H4 -> 575 | I9: ='Cash Flow'!I4 -> 610

Sheet Monte Carlo
A1: MONTE CARLO — 16-FACTOR MODEL (50,000 paths, seed 42)
A2: 7 continuous factors compound daily; 9 discrete events arrive with probability. Paths diffuse from spot;
A3: the §1 fundamental value gap is deliberately kept OUT of the drift (lens independence).
A5: CORE INPUTS
A6: Anchor price (EGP) | B6: 720
A7: Horizon T+20 (sessions) | B7: 20
A8: Horizon T+60 (sessions) | B8: 60
A9: Trailing-252 annualized vol | B9: 0.336
A10: Calibration KVOL | B10: 1.4
A11: Idiosyncratic diffusion (ann) | B11: 0.412
A12: Net 3M factor drift | B12: 0.017
A13: SMA50 (EGP) | B13: 686
A14: 52-week low (EGP) | B14: 282
A15: 52-week high (EGP) | B15: 800
A17: SEVEN CONTINUOUS FACTORS
A18: Factor | B18: 3M drift | C18: 3M vol | H18: Channel
A19: US infrastructure / data-center capex cycle | B19: 0.008 | C19: 0.06 | H19: Weitz; 32% of backlog, fastest-growing leg
A20: Egypt/MENA FX-funded infra execution | B20: 0.004 | C20: 0.05 | H20: 54% of backlog; IFI-funded, USD-denominated
A21: EGP/USD translation & EGX cross-listing premium | B21: 0 | C21: 0.05 | H21: USD reporting; EGP-line premium dynamics
A22: EGX30 / foreign flows & EGP-hedge bid | B22: 0.006 | C22: 0.06 | H22: market beta + trapped-EGP bid for USD assets
A23: Input cost (steel/cement/labour) & margin | B23: -0.006 | C23: 0.04 | H23: contractor gross-margin channel
A24: Gulf infra-capex & oil-linked liquidity | B24: 0.004 | C24: 0.05 | H24: KSA/UAE pipeline (Qurayyah, Project Wave)
A25: Interest-rate / working-capital funding cost | B25: -0.004 | C25: 0.04 | H25: CBE/USD rates; long-cycle WC funding
A27: NINE DISCRETE EVENTS
A28: Event | B28: Prob | C28: Impact μ | D28: Impact σ | H28: Channel
A29: OCI Global combination outcome | B29: 0.45 | C29: 0.01 | D29: 0.08 | H29: pivotal, two-sided: terms / completion / collapse
A30: Major contract award (US DC / KSA power / rail) | B30: 0.5 | C30: 0.025 | D30: 0.05 | H30: per named mega-tender
A31: Geopolitical / regional security shock | B31: 0.3 | C31: -0.09 | D31: 0.05 | H31: MENA risk premium
A32: Quarterly earnings / backlog-burn surprise | B32: 0.5 | C32: 0.01 | D32: 0.06 | H32: two-sided print
A33: EGP devaluation step / FX-regime move | B33: 0.3 | C33: 0.02 | D33: 0.06 | H33: lifts EGP value of USD-linked equity
A34: Public-sector receivables / cash-conversion | B34: 0.3 | C34: -0.05 | D34: 0.04 | H34: Egypt arrears; advances unwind
A35: Concessions BOO milestone / monetization | B35: 0.35 | C35: 0.025 | D35: 0.04 | H35: renewables platform crystallization
A36: Claim / arbitration settlement | B36: 0.3 | C36: 0.02 | D36: 0.05 | H36: legacy claims (cf. $29m FY25 gain)
A37: Dividend / capital-return surprise | B37: 0.3 | C37: 0.015 | D37: 0.04 | H37: payout growth (3.2% yield)
A39: PERCENTILE TABLE (EGP)
A40: Horizon | B40: 5% | C40: 25% | D40: Median | E40: 75% | F40: 95%
A41: T+20 | B41: 575 | C41: 658 | D41: 719 | E41: 785 | F41: 893
A42: T+60 | B42: 488 | C42: 611 | D42: 714 | E42: 834 | F42: 1040

Sheet Sensitivity
A1: DCF SENSITIVITY — per-share EGP (WACC × terminal g)
A3: WACC \ g | B3: 0.025 | C3: 0.03 | D3: 0.035 | E3: 0.04 | F3: 0.045
A4: 0.105 | B4: =((Assumptions!$B$34*(1+Assumptions!$B$33)^1/(1+0.105)^1+Assumptions!$B$34*(1+Assumptions!$B$33)^2/(1+0.105)^2+Assumptions!$B$34*(1+Assumptions!$B$33)^3/(1+0.105)^3+Assumptions!$B$34*(1+Assumptions!$B$33)^4/(1+0.105)^4+Assumptions!$B$34*(1+Assumptions!$B$33)^5/(1+0.105)^5)+(Assumptions!$B$34*(1+Assumptions!$B$33)^5*(1+0.025)/(0.105-0.025)/(1+0.105)^5)+Assumptions!$B$25+Assumptions!$B$35)/Assumptions!$B$7*Assumptions!$B$6 -> 1077.6098 | C4: =((Assumptions!$B$34*(1+Assumptions!$B$33)^1/(1+0.105)^1+Assumptions!$B$34*(1+Assumptions!$B$33)^2/(1+0.105)^2+Assumptions!$B$34*(1+Assumptions!$B$33)^3/(1+0.105)^3+Assumptions!$B$34*(1+Assumptions!$B$33)^4/(1+0.105)^4+Assumptions!$B$34*(1+Assumptions!$B$33)^5/(1+0.105)^5)+(Assumptions!$B$34*(1+Assumptions!$B$33)^5*(1+0.03)/(0.105-0.03)/(1+0.105)^5)+Assumptions!$B$25+Assumptions!$B$35)/Assumptions!$B$7*Assumptions!$B$6 -> 1118.0091 | D4: =((Assumptions!$B$34*(1+Assumptions!$B$33)^1/(1+0.105)^1+Assumptions!$B$34*(1+Assumptions!$B$33)^2/(1+0.105)^2+Assumptions!$B$34*(1+Assumptions!$B$33)^3/(1+0.105)^3+Assumptions!$B$34*(1+Assumptions!$B$33)^4/(1+0.105)^4+Assumptions!$B$34*(1+Assumptions!$B$33)^5/(1+0.105)^5)+(Assumptions!$B$34*(1+Assumptions!$B$33)^5*(1+0.035)/(0.105-0.035)/(1+0.105)^5)+Assumptions!$B$25+Assumptions!$B$35)/Assumptions!$B$7*Assumptions!$B$6 -> 1164.1799 | E4: =((Assumptions!$B$34*(1+Assumptions!$B$33)^1/(1+0.105)^1+Assumptions!$B$34*(1+Assumptions!$B$33)^2/(1+0.105)^2+Assumptions!$B$34*(1+Assumptions!$B$33)^3/(1+0.105)^3+Assumptions!$B$34*(1+Assumptions!$B$33)^4/(1+0.105)^4+Assumptions!$B$34*(1+Assumptions!$B$33)^5/(1+0.105)^5)+(Assumptions!$B$34*(1+Assumptions!$B$33)^5*(1+0.04)/(0.105-0.04)/(1+0.105)^5)+Assumptions!$B$25+Assumptions!$B$35)/Assumptions!$B$7*Assumptions!$B$6 -> 1217.4538 | F4: =((Assumptions!$B$34*(1+Assumptions!$B$33)^1/(1+0.105)^1+Assumptions!$B$34*(1+Assumptions!$B$33)^2/(1+0.105)^2+Assumptions!$B$34*(1+Assumptions!$B$33)^3/(1+0.105)^3+Assumptions!$B$34*(1+Assumptions!$B$33)^4/(1+0.105)^4+Assumptions!$B$34*(1+Assumptions!$B$33)^5/(1+0.105)^5)+(Assumptions!$B$34*(1+Assumptions!$B$33)^5*(1+0.045)/(0.105-0.045)/(1+0.105)^5)+Assumptions!$B$25+Assumptions!$B$35)/Assumptions!$B$7*Assumptions!$B$6 -> 1279.6067
A5: 0.11 | B5: =((Assumptions!$B$34*(1+Assumptions!$B$33)^1/(1+0.11)^1+Assumptions!$B$34*(1+Assumptions!$B$33)^2/(1+0.11)^2+Assumptions!$B$34*(1+Assumptions!$B$33)^3/(1+0.11)^3+Assumptions!$B$34*(1+Assumptions!$B$33)^4/(1+0.11)^4+Assumptions!$B$34*(1+Assumptions!$B$33)^5/(1+0.11)^5)+(Assumptions!$B$34*(1+Assumptions!$B$33)^5*(1+0.025)/(0.11-0.025)/(1+0.11)^5)+Assumptions!$B$25+Assumptions!$B$35)/Assumptions!$B$7*Assumptions!$B$6 -> 1029.6959 | C5: =((Assumptions!$B$34*(1+Assumptions!$B$33)^1/(1+0.11)^1+Assumptions!$B$34*(1+Assumptions!$B$33)^2/(1+0.11)^2+Assumptions!$B$34*(1+Assumptions!$B$33)^3/(1+0.11)^3+Assumptions!$B$34*(1+Assumptions!$B$33)^4/(1+0.11)^4+Assumptions!$B$34*(1+Assumptions!$B$33)^5/(1+0.11)^5)+(Assumptions!$B$34*(1+Assumptions!$B$33)^5*(1+0.03)/(0.11-0.03)/(1+0.11)^5)+Assumptions!$B$25+Assumptions!$B$35)/Assumptions!$B$7*Assumptions!$B$6 -> 1064.7044 | D5: =((Assumptions!$B$34*(1+Assumptions!$B$33)^1/(1+0.11)^1+Assumptions!$B$34*(1+Assumptions!$B$33)^2/(1+0.11)^2+Assumptions!$B$34*(1+Assumptions!$B$33)^3/(1+0.11)^3+Assumptions!$B$34*(1+Assumptions!$B$33)^4/(1+0.11)^4+Assumptions!$B$34*(1+Assumptions!$B$33)^5/(1+0.11)^5)+(Assumptions!$B$34*(1+Assumptions!$B$33)^5*(1+0.035)/(0.11-0.035)/(1+0.11)^5)+Assumptions!$B$25+Assumptions!$B$35)/Assumptions!$B$7*Assumptions!$B$6 -> 1104.3808 | E5: =((Assumptions!$B$34*(1+Assumptions!$B$33)^1/(1+0.11)^1+Assumptions!$B$34*(1+Assumptions!$B$33)^2/(1+0.11)^2+Assumptions!$B$34*(1+Assumptions!$B$33)^3/(1+0.11)^3+Assumptions!$B$34*(1+Assumptions!$B$33)^4/(1+0.11)^4+Assumptions!$B$34*(1+Assumptions!$B$33)^5/(1+0.11)^5)+(Assumptions!$B$34*(1+Assumptions!$B$33)^5*(1+0.04)/(0.11-0.04)/(1+0.11)^5)+Assumptions!$B$25+Assumptions!$B$35)/Assumptions!$B$7*Assumptions!$B$6 -> 1149.7252 | F5: =((Assumptions!$B$34*(1+Assumptions!$B$33)^1/(1+0.11)^1+Assumptions!$B$34*(1+Assumptions!$B$33)^2/(1+0.11)^2+Assumptions!$B$34*(1+Assumptions!$B$33)^3/(1+0.11)^3+Assumptions!$B$34*(1+Assumptions!$B$33)^4/(1+0.11)^4+Assumptions!$B$34*(1+Assumptions!$B$33)^5/(1+0.11)^5)+(Assumptions!$B$34*(1+Assumptions!$B$33)^5*(1+0.045)/(0.11-0.045)/(1+0.11)^5)+Assumptions!$B$25+Assumptions!$B$35)/Assumptions!$B$7*Assumptions!$B$6 -> 1202.0457
A6: 0.12 | B6: =((Assumptions!$B$34*(1+Assumptions!$B$33)^1/(1+0.12)^1+Assumptions!$B$34*(1+Assumptions!$B$33)^2/(1+0.12)^2+Assumptions!$B$34*(1+Assumptions!$B$33)^3/(1+0.12)^3+Assumptions!$B$34*(1+Assumptions!$B$33)^4/(1+0.12)^4+Assumptions!$B$34*(1+Assumptions!$B$33)^5/(1+0.12)^5)+(Assumptions!$B$34*(1+Assumptions!$B$33)^5*(1+0.025)/(0.12-0.025)/(1+0.12)^5)+Assumptions!$B$25+Assumptions!$B$35)/Assumptions!$B$7*Assumptions!$B$6 -> 949.06172 | C6: =((Assumptions!$B$34*(1+Assumptions!$B$33)^1/(1+0.12)^1+Assumptions!$B$34*(1+Assumptions!$B$33)^2/(1+0.12)^2+Assumptions!$B$34*(1+Assumptions!$B$33)^3/(1+0.12)^3+Assumptions!$B$34*(1+Assumptions!$B$33)^4/(1+0.12)^4+Assumptions!$B$34*(1+Assumptions!$B$33)^5/(1+0.12)^5)+(Assumptions!$B$34*(1+Assumptions!$B$33)^5*(1+0.03)/(0.12-0.03)/(1+0.12)^5)+Assumptions!$B$25+Assumptions!$B$35)/Assumptions!$B$7*Assumptions!$B$6 -> 975.92363 | D6: =((Assumptions!$B$34*(1+Assumptions!$B$33)^1/(1+0.12)^1+Assumptions!$B$34*(1+Assumptions!$B$33)^2/(1+0.12)^2+Assumptions!$B$34*(1+Assumptions!$B$33)^3/(1+0.12)^3+Assumptions!$B$34*(1+Assumptions!$B$33)^4/(1+0.12)^4+Assumptions!$B$34*(1+Assumptions!$B$33)^5/(1+0.12)^5)+(Assumptions!$B$34*(1+Assumptions!$B$33)^5*(1+0.035)/(0.12-0.035)/(1+0.12)^5)+Assumptions!$B$25+Assumptions!$B$35)/Assumptions!$B$7*Assumptions!$B$6 -> 1005.9458 | E6: =((Assumptions!$B$34*(1+Assumptions!$B$33)^1/(1+0.12)^1+Assumptions!$B$34*(1+Assumptions!$B$33)^2/(1+0.12)^2+Assumptions!$B$34*(1+Assumptions!$B$33)^3/(1+0.12)^3+Assumptions!$B$34*(1+Assumptions!$B$33)^4/(1+0.12)^4+Assumptions!$B$34*(1+Assumptions!$B$33)^5/(1+0.12)^5)+(Assumptions!$B$34*(1+Assumptions!$B$33)^5*(1+0.04)/(0.12-0.04)/(1+0.12)^5)+Assumptions!$B$25+Assumptions!$B$35)/Assumptions!$B$7*Assumptions!$B$6 -> 1039.7207 | F6: =((Assumptions!$B$34*(1+Assumptions!$B$33)^1/(1+0.12)^1+Assumptions!$B$34*(1+Assumptions!$B$33)^2/(1+0.12)^2+Assumptions!$B$34*(1+Assumptions!$B$33)^3/(1+0.12)^3+Assumptions!$B$34*(1+Assumptions!$B$33)^4/(1+0.12)^4+Assumptions!$B$34*(1+Assumptions!$B$33)^5/(1+0.12)^5)+(Assumptions!$B$34*(1+Assumptions!$B$33)^5*(1+0.045)/(0.12-0.045)/(1+0.12)^5)+Assumptions!$B$25+Assumptions!$B$35)/Assumptions!$B$7*Assumptions!$B$6 -> 1077.9989
A7: 0.13 | B7: =((Assumptions!$B$34*(1+Assumptions!$B$33)^1/(1+0.13)^1+Assumptions!$B$34*(1+Assumptions!$B$33)^2/(1+0.13)^2+Assumptions!$B$34*(1+Assumptions!$B$33)^3/(1+0.13)^3+Assumptions!$B$34*(1+Assumptions!$B$33)^4/(1+0.13)^4+Assumptions!$B$34*(1+Assumptions!$B$33)^5/(1+0.13)^5)+(Assumptions!$B$34*(1+Assumptions!$B$33)^5*(1+0.025)/(0.13-0.025)/(1+0.13)^5)+Assumptions!$B$25+Assumptions!$B$35)/Assumptions!$B$7*Assumptions!$B$6 -> 883.85953 | C7: =((Assumptions!$B$34*(1+Assumptions!$B$33)^1/(1+0.13)^1+Assumptions!$B$34*(1+Assumptions!$B$33)^2/(1+0.13)^2+Assumptions!$B$34*(1+Assumptions!$B$33)^3/(1+0.13)^3+Assumptions!$B$34*(1+Assumptions!$B$33)^4/(1+0.13)^4+Assumptions!$B$34*(1+Assumptions!$B$33)^5/(1+0.13)^5)+(Assumptions!$B$34*(1+Assumptions!$B$33)^5*(1+0.03)/(0.13-0.03)/(1+0.13)^5)+Assumptions!$B$25+Assumptions!$B$35)/Assumptions!$B$7*Assumptions!$B$6 -> 904.96874 | D7: =((Assumptions!$B$34*(1+Assumptions!$B$33)^1/(1+0.13)^1+Assumptions!$B$34*(1+Assumptions!$B$33)^2/(1+0.13)^2+Assumptions!$B$34*(1+Assumptions!$B$33)^3/(1+0.13)^3+Assumptions!$B$34*(1+Assumptions!$B$33)^4/(1+0.13)^4+Assumptions!$B$34*(1+Assumptions!$B$33)^5/(1+0.13)^5)+(Assumptions!$B$34*(1+Assumptions!$B$33)^5*(1+0.035)/(0.13-0.035)/(1+0.13)^5)+Assumptions!$B$25+Assumptions!$B$35)/Assumptions!$B$7*Assumptions!$B$6 -> 928.29997 | E7: =((Assumptions!$B$34*(1+Assumptions!$B$33)^1/(1+0.13)^1+Assumptions!$B$34*(1+Assumptions!$B$33)^2/(1+0.13)^2+Assumptions!$B$34*(1+Assumptions!$B$33)^3/(1+0.13)^3+Assumptions!$B$34*(1+Assumptions!$B$33)^4/(1+0.13)^4+Assumptions!$B$34*(1+Assumptions!$B$33)^5/(1+0.13)^5)+(Assumptions!$B$34*(1+Assumptions!$B$33)^5*(1+0.04)/(0.13-0.04)/(1+0.13)^5)+Assumptions!$B$25+Assumptions!$B$35)/Assumptions!$B$7*Assumptions!$B$6 -> 954.22357 | F7: =((Assumptions!$B$34*(1+Assumptions!$B$33)^1/(1+0.13)^1+Assumptions!$B$34*(1+Assumptions!$B$33)^2/(1+0.13)^2+Assumptions!$B$34*(1+Assumptions!$B$33)^3/(1+0.13)^3+Assumptions!$B$34*(1+Assumptions!$B$33)^4/(1+0.13)^4+Assumptions!$B$34*(1+Assumptions!$B$33)^5/(1+0.13)^5)+(Assumptions!$B$34*(1+Assumptions!$B$33)^5*(1+0.045)/(0.13-0.045)/(1+0.13)^5)+Assumptions!$B$25+Assumptions!$B$35)/Assumptions!$B$7*Assumptions!$B$6 -> 983.19699
A8: 0.14 | B8: =((Assumptions!$B$34*(1+Assumptions!$B$33)^1/(1+0.14)^1+Assumptions!$B$34*(1+Assumptions!$B$33)^2/(1+0.14)^2+Assumptions!$B$34*(1+Assumptions!$B$33)^3/(1+0.14)^3+Assumptions!$B$34*(1+Assumptions!$B$33)^4/(1+0.14)^4+Assumptions!$B$34*(1+Assumptions!$B$33)^5/(1+0.14)^5)+(Assumptions!$B$34*(1+Assumptions!$B$33)^5*(1+0.025)/(0.14-0.025)/(1+0.14)^5)+Assumptions!$B$25+Assumptions!$B$35)/Assumptions!$B$7*Assumptions!$B$6 -> 830.06053 | C8: =((Assumptions!$B$34*(1+Assumptions!$B$33)^1/(1+0.14)^1+Assumptions!$B$34*(1+Assumptions!$B$33)^2/(1+0.14)^2+Assumptions!$B$34*(1+Assumptions!$B$33)^3/(1+0.14)^3+Assumptions!$B$34*(1+Assumptions!$B$33)^4/(1+0.14)^4+Assumptions!$B$34*(1+Assumptions!$B$33)^5/(1+0.14)^5)+(Assumptions!$B$34*(1+Assumptions!$B$33)^5*(1+0.03)/(0.14-0.03)/(1+0.14)^5)+Assumptions!$B$25+Assumptions!$B$35)/Assumptions!$B$7*Assumptions!$B$6 -> 846.97527 | D8: =((Assumptions!$B$34*(1+Assumptions!$B$33)^1/(1+0.14)^1+Assumptions!$B$34*(1+Assumptions!$B$33)^2/(1+0.14)^2+Assumptions!$B$34*(1+Assumptions!$B$33)^3/(1+0.14)^3+Assumptions!$B$34*(1+Assumptions!$B$33)^4/(1+0.14)^4+Assumptions!$B$34*(1+Assumptions!$B$33)^5/(1+0.14)^5)+(Assumptions!$B$34*(1+Assumptions!$B$33)^5*(1+0.035)/(0.14-0.035)/(1+0.14)^5)+Assumptions!$B$25+Assumptions!$B$35)/Assumptions!$B$7*Assumptions!$B$6 -> 865.50093 | E8: =((Assumptions!$B$34*(1+Assumptions!$B$33)^1/(1+0.14)^1+Assumptions!$B$34*(1+Assumptions!$B$33)^2/(1+0.14)^2+Assumptions!$B$34*(1+Assumptions!$B$33)^3/(1+0.14)^3+Assumptions!$B$34*(1+Assumptions!$B$33)^4/(1+0.14)^4+Assumptions!$B$34*(1+Assumptions!$B$33)^5/(1+0.14)^5)+(Assumptions!$B$34*(1+Assumptions!$B$33)^5*(1+0.04)/(0.14-0.04)/(1+0.14)^5)+Assumptions!$B$25+Assumptions!$B$35)/Assumptions!$B$7*Assumptions!$B$6 -> 885.87915 | F8: =((Assumptions!$B$34*(1+Assumptions!$B$33)^1/(1+0.14)^1+Assumptions!$B$34*(1+Assumptions!$B$33)^2/(1+0.14)^2+Assumptions!$B$34*(1+Assumptions!$B$33)^3/(1+0.14)^3+Assumptions!$B$34*(1+Assumptions!$B$33)^4/(1+0.14)^4+Assumptions!$B$34*(1+Assumptions!$B$33)^5/(1+0.14)^5)+(Assumptions!$B$34*(1+Assumptions!$B$33)^5*(1+0.045)/(0.14-0.045)/(1+0.14)^5)+Assumptions!$B$25+Assumptions!$B$35)/Assumptions!$B$7*Assumptions!$B$6 -> 908.40245
A10: Spot (EGP) | B10: =Assumptions!$B$5 -> 720

Sheet Per-Share & Ratios
A1: PER-SHARE & RATIOS
A3: Spot (EGP) | B3: =Assumptions!$B$5 -> 720
A4: Spot (USD) | B4: =Assumptions!$B$5/Assumptions!$B$6 -> 14.634146
A5: Market cap (USD m) | B5: =Assumptions!$B$5/Assumptions!$B$6*Assumptions!$B$7 -> 1612.6829
A6: EPS (USD, reported) | B6: =Assumptions!$B$14/Assumptions!$B$7 -> 1.7676951
A7: P/E (reported) | B7: =(Assumptions!$B$5/Assumptions!$B$6*Assumptions!$B$7)/Assumptions!$B$14 -> 8.2786598
A8: P/E (adjusted) | B8: =(Assumptions!$B$5/Assumptions!$B$6*Assumptions!$B$7)/Assumptions!$B$15 -> 9.7266763
A9: EV (USD m, usable net cash) | B9: =Assumptions!$B$5/Assumptions!$B$6*Assumptions!$B$7-Assumptions!$B$25 -> 1212.6829
A10: EV/EBITDA (adjusted) | B10: =(Assumptions!$B$5/Assumptions!$B$6*Assumptions!$B$7-Assumptions!$B$25)/Assumptions!$B$13 -> 4.3937787
A11: EV/Revenue | B11: =(Assumptions!$B$5/Assumptions!$B$6*Assumptions!$B$7-Assumptions!$B$25)/Assumptions!$B$11 -> 0.24014474
A12: Dividend/share (USD) | B12: =0.47 -> 0.47
A13: Dividend yield | B13: =0.47/(Assumptions!$B$5/Assumptions!$B$6) -> 0.032116667
A14: Backlog / market cap (x) | B14: =Assumptions!$B$27/(Assumptions!$B$5/Assumptions!$B$6*Assumptions!$B$7) -> 5.5965124
A15: Net cash / market cap | B15: =Assumptions!$B$25/(Assumptions!$B$5/Assumptions!$B$6*Assumptions!$B$7) -> 0.24803388

Sheet Peer & Sector
A1: PEER SET & SECTOR (indicative)
A3: Peer | B3: Market | C3: EV/EBITDA | D3: P/E
A4: WeBuild (Salini) | B4: Italy | C4: ~4-5x | D4: ~10-12x
A5: Vinci | B5: France | C5: ~7-8x | D5: ~13-15x
A6: ACS / Hochtief | B6: Spain | C6: ~5-6x | D6: ~11-13x
A7: Hyundai E&C | B7: Korea | C7: ~4-5x | D7: ~9-11x
A8: Samsung C&T | B8: Korea | C8: ~6-7x | D8: ~12-14x
A9: Arabian Contracting | B9: KSA | C9: ~7-9x | D9: ~14-18x
A10: Elsewedy Electric | B10: Egypt | C10: ~4-5x | D10: ~6-8x
A11: ORAS (this study) | B11: Egypt/UAE | C11: ~4x | D11: ~8.3x
