Workbook

Sheet READ FIRST
A1: Testahil — Reliance Industries Ltd (NSE: RELIANCE)
A2: Companion model · Independent Valuation Study · Educational analysis · Not investment advice
A5: What this workbook is. A transparent companion to the Reliance valuation study. Every blue cell is an input; every
A6: black cell is a formula; green cells link across sheets. All inputs live on the Assumptions sheet — change one
A7: (the holdco discount, a Jio EV/EBITDA multiple, a growth rate) and the whole model reprices.
A9: What it is not. It is not investment advice, a recommendation, or a price target. Values are model outputs shown
A10: as ranges. The preparer is not licensed by any securities regulator and may hold a position in the security.
A12: Entity note. Reliance is valued as a holding company (holdco sum-of-the-parts): each business is marked on the basis
A13: that fits it and RIL's economic ownership stake applied, minority interests and consolidated net debt deducted.
A15: Currency. Rs crore unless stated; USD/INR 88 at study date. Spot Rs1,321.30 (06 Jul 2026). Shares ~1,353 crore.
A16: Historical financials are company disclosure (FY26 results, 24 Apr 2026); some P&L / balance-sheet line items are
A17: estimated to tie to disclosed totals (EBITDA, PAT attributable, net debt, equity) — flagged on the statements.
... A20: Income Statement · Balance Sheet · Cash Flow · Summary Financials · Monte Carlo · Sensitivity · Per-Share & Ratios · Peer & Sector.

Sheet Summary
A1: Valuation summary — Reliance Industries (NSE: RELIANCE)
A2: Four-lens fair value vs spot. Base links live; bear/bull are scenario outputs (see study §1.5).
B3: Bear | C3: Base | D3: Bull | E3: Weight
A4: Sum-of-the-parts | B4: 1008 | C4: =SOTP!C18 | D4: 1712 | E4: =Assumptions!$B$38
A5: Consolidated DCF | B5: 1120 | C5: =DCF!B19 | D5: 1660 | E5: =Assumptions!$B$39
A6: Relative multiples | B6: 1179 | C6: ='Relative & Normalized'!C4 | D6: 1509 | E6: =Assumptions!$B$40
A7: Normalized earnings | B7: 1231 | C7: ='Relative & Normalized'!C6 | D7: 1904 | E7: =Assumptions!$B$41
A8: Weighted central | B8: =SUMPRODUCT(B4:B7,E4:E7) | C8: =SUMPRODUCT(C4:C7,E4:E7) | D8: =SUMPRODUCT(D4:D7,E4:E7)
A10: Spot price (Rs) | C10: =Assumptions!$B$4
A11: Upside to central base | C11: =C8/C10-1
A13: Read: modestly undervalued; swing factors are the Jio IPO value-crystallisation, O2C margins and the holdco discount.

Sheet Fundamental Valuation
A1: Fundamental valuation — football field data
A2: Bear/base/bull per lens (links to Summary).
A3: Lens | B3: Bear | C3: Base | D3: Bull
A4: Sum-of-the-parts | B4: =Summary!B4 | C4: =Summary!C4 | D4: =Summary!D4
A5: Consolidated DCF | B5: =Summary!B5 | C5: =Summary!C5 | D5: =Summary!D5
A6: Relative multiples | B6: =Summary!B6 | C6: =Summary!C6 | D6: =Summary!D6
A7: Normalized earnings | B7: =Summary!B7 | C7: =Summary!C7 | D7: =Summary!D7
A8: Weighted central | B8: =Summary!B8 | C8: =Summary!C8 | D8: =Summary!D8
A9: Spot | C9: =Assumptions!$B$4

Sheet Assumptions
A1: Assumptions — the single input layer
A2: All blue cells are inputs. Every other sheet links here.
A3: ANCHORS
A4: Spot price (Rs/share) | B4: 1321.3
A5: Shares outstanding (cr) | B5: 1353
A6: USD/INR | B6: 88
A7: Consolidated net debt (Rs cr) | B7: 124717
A8: WACC | B8: 0.115
A9: Terminal growth | B9: 0.05
A10: Tax rate | B10: 0.25
A12: SOTP — base marks
A13: Jio Platforms FY26 EBITDA (Rs cr) | B13: 76255
A14: Jio EV/EBITDA multiple | B14: 13.5
A15: Jio net debt (Rs cr) | B15: 70781
A16: Jio — RIL stake | B16: 0.6643
A17: Reliance Retail FY26 EBITDA (Rs cr) | B17: 27033
A18: Retail EV/EBITDA multiple | B18: 28
A19: Retail net debt (Rs cr) | B19: 15000
A20: Retail — RIL stake | B20: 0.85
A21: O2C FY26 EBITDA (Rs cr) | B21: 60546
A22: O2C EV/EBITDA multiple | B22: 7
A23: Oil & Gas (E&P) FY26 EBITDA (Rs cr) | B23: 19050
A24: E&P EV/EBITDA multiple | B24: 5
... A29: Holdco / complexity discount | B29: 0.05
A31: RELATIVE & NORMALIZED
A32: Normalized consolidated EBITDA (Rs cr) | B32: 220000
A33: EV/EBITDA target multiple | B33: 8.7
A34: Mid-cycle PAT attributable (Rs cr) | B34: 105000
A35: Justified P/E | B35: 20
A37: SYNTHESIS WEIGHTS
A38: SOTP weight | B38: 0.4
A39: DCF weight | B39: 0.2
A40: Relative weight | B40: 0.15
A41: Normalized-earnings weight | B41: 0.25
A43: WORKING CAPITAL (% of revenue)
A44: Inventory | B44: 0.09
A45: Receivables | B45: 0.045
A46: Payables | B46: 0.16
A48: MONTE CARLO
A49: Diffusion volatility (annualized) | B49: 0.25
...

Sheet SOTP
A1: Holding-company sum-of-the-parts (primary lens)
A2: Each business marked on the basis that fits it; RIL stake applied; minority & net debt deducted. Links to Assumptions.
A3: Part | B3: Basis | C3: EV / value (Rs cr)
A4: Jio Platforms | B4: EBITDA × EV/EBITDA | C4: =Assumptions!$B$13*Assumptions!$B$14
A5: Reliance Retail | B5: EBITDA × EV/EBITDA | C5: =Assumptions!$B$17*Assumptions!$B$18
A6: O2C | B6: EBITDA × EV/EBITDA | C6: =Assumptions!$B$21*Assumptions!$B$22
A7: Oil & Gas (E&P) | B7: EBITDA × EV/EBITDA | C7: =Assumptions!$B$23*Assumptions!$B$24
A8: Media (JioStar) | B8: EBITDA × EV/EBITDA | C8: =Assumptions!$B$25*Assumptions!$B$26
A9: New Energy + other | B9: Invested capital + option value | C9: =Assumptions!$B$28
A10: Σ Gross enterprise value (100%) | C10: =SUM(C4:C9)
A11: less: consolidated net debt | C11: =-Assumptions!$B$7
A12: Equity value (100% basis) | C12: =C10+C11
A13: less: minority interest (Jio/Retail/Media ext.) | C13: =-((Assumptions!$B$13*Assumptions!$B$14-Assumptions!$B$15)*(1-Assumptions!$B$16)+(Assumptions!$B$17*Assumptions!$B$18-Assumptions!$B$19)*(1-Assumptions!$B$20)+(Assumptions!$B$25*Assumptions!$B$26)*(1-Assumptions!$B$27))
A14: RIL-attributable equity (pre-discount) | C14: =C12+C13
A15: per share (Rs) | C15: =C14/Assumptions!$B$5
A16: less: holdco / complexity discount | C16: =-C14*Assumptions!$B$29
A17: SOTP equity value | C17: =C14+C16
A18: SOTP fair value per share (Rs) | C18: =C17/Assumptions!$B$5
A19: Implied market discount to pre-disc NAV | C19: =1-Assumptions!$B$4/C15

Sheet Segments
A1: Segment view
A2: Revenue and EBITDA by segment, FY24–FY31 (links to Income Statement).
B3: FY24 | C3: FY25 | D3: FY26 | E3: FY27E | F3: FY28E | G3: FY29E | H3: FY30E | I3: FY31E
A4: O2C revenue | B4: ='Income Statement'!B4 | C4: ='Income Statement'!C4 | D4: ='Income Statement'!D4 | E4: ='Income Statement'!E4 | F4: ='Income Statement'!F4 | G4: ='Income Statement'!G4 | H4: ='Income Statement'!H4 | I4: ='Income Statement'!I4
A5: Jio (Digital) revenue | B5: ='Income Statement'!B5 | C5: ='Income Statement'!C5 | D5: ='Income Statement'!D5 | E5: ='Income Statement'!E5 | F5: ='Income Statement'!F5 | G5: ='Income Statement'!G5 | H5: ='Income Statement'!H5 | I5: ='Income Statement'!I5
A6: Retail revenue | B6: ='Income Statement'!B6 | C6: ='Income Statement'!C6 | D6: ='Income Statement'!D6 | E6: ='Income Statement'!E6 | F6: ='Income Statement'!F6 | G6: ='Income Statement'!G6 | H6: ='Income Statement'!H6 | I6: ='Income Statement'!I6
A7: O&G / Media / other revenue | B7: ='Income Statement'!B7 | C7: ='Income Statement'!C7 | D7: ='Income Statement'!D7 | E7: ='Income Statement'!E7 | F7: ='Income Statement'!F7 | G7: ='Income Statement'!G7 | H7: ='Income Statement'!H7 | I7: ='Income Statement'!I7
A8: O2C EBITDA | B8: ='Income Statement'!B11 | C8: ='Income Statement'!C11 | D8: ='Income Statement'!D11 | E8: ='Income Statement'!E11 | F8: ='Income Statement'!F11 | G8: ='Income Statement'!G11 | H8: ='Income Statement'!H11 | I8: ='Income Statement'!I11
A9: Jio EBITDA | B9: ='Income Statement'!B12 | C9: ='Income Statement'!C12 | D9: ='Income Statement'!D12 | E9: ='Income Statement'!E12 | F9: ='Income Statement'!F12 | G9: ='Income Statement'!G12 | H9: ='Income Statement'!H12 | I9: ='Income Statement'!I12
A10: Retail EBITDA | B10: ='Income Statement'!B13 | C10: ='Income Statement'!C13 | D10: ='Income Statement'!D13 | E10: ='Income Statement'!E13 | F10: ='Income Statement'!F13 | G10: ='Income Statement'!G13 | H10: ='Income Statement'!H13 | I10: ='Income Statement'!I13
A11: O&G/Media/other EBITDA | B11: ='Income Statement'!B14 | C11: ='Income Statement'!C14 | D11: ='Income Statement'!D14 | E11: ='Income Statement'!E14 | F11: ='Income Statement'!F14 | G11: ='Income Statement'!G14 | H11: ='Income Statement'!H14 | I11: ='Income Statement'!I14
A12: Jio EBITDA margin | B12: =B9/B5 | C12: =C9/C5 | D12: =D9/D5 | E12: =E9/E5 | F12: =F9/F5 | G12: =G9/G5 | H12: =H9/H5 | I12: =I9/I5
A13: O2C EBITDA margin | B13: =B8/B4 | C13: =C8/C4 | D13: =D8/D4 | E13: =E8/E4 | F13: =F8/F4 | G13: =G8/G4 | H13: =H8/H4 | I13: =I8/I4
A14: Retail EBITDA margin | B14: =B10/B6 | C14: =C10/C6 | D14: =D10/D6 | E14: =E10/E6 | F14: =F10/F6 | G14: =G10/G6 | H14: =H10/H6 | I14: =I10/I6
A15: Jio % of consolidated EBITDA | B15: =B9/'Income Statement'!B16 | C15: =C9/'Income Statement'!C16 | D15: =D9/'Income Statement'!D16 | E15: =E9/'Income Statement'!E16 | F15: =F9/'Income Statement'!F16 | G15: =G9/'Income Statement'!G16 | H15: =H9/'Income Statement'!H16 | I15: =I9/'Income Statement'!I16

Sheet Relative & Normalized
A1: Relative & normalized-earnings lenses
A2: Links to Assumptions.
A3: Lens | B3: Workings | C3: Rs/share
A4: Relative EV/EBITDA | B4: Norm EBITDA × mult − net debt, /sh | C4: =(Assumptions!$B$32*Assumptions!$B$33-Assumptions!$B$7)/Assumptions!$B$5
A5: implied EV (Rs cr) | C5: =Assumptions!$B$32*Assumptions!$B$33
A6: Normalized earnings | B6: Mid-cycle PAT × P/E, /sh | C6: =Assumptions!$B$34*Assumptions!$B$35/Assumptions!$B$5
A7: normalized EPS (Rs) | C7: =Assumptions!$B$34/Assumptions!$B$5

Sheet DCF
A1: Discounted cash flow — explicit 5-year FCFF
A2: NOPAT + D&A − capex − ΔWC, discounted at WACC. Links to Income Statement / Balance Sheet / Assumptions.
E3: FY27E | F3: FY28E | G3: FY29E | H3: FY30E | I3: FY31E
A4: EBIT | E4: ='Income Statement'!E19 | F4: ='Income Statement'!F19 | G4: ='Income Statement'!G19 | H4: ='Income Statement'!H19 | I4: ='Income Statement'!I19
A5: NOPAT = EBIT×(1−tax) | E5: =E4*(1-Assumptions!$B$10) | F5: =F4*(1-Assumptions!$B$10) | G5: =G4*(1-Assumptions!$B$10) | H5: =H4*(1-Assumptions!$B$10) | I5: =I4*(1-Assumptions!$B$10)
A6: + D&A | E6: ='Income Statement'!E18 | F6: ='Income Statement'!F18 | G6: ='Income Statement'!G18 | H6: ='Income Statement'!H18 | I6: ='Income Statement'!I18
A7: − Capex | E7: =-Assumptions!E68 | F7: =-Assumptions!F68 | G7: =-Assumptions!G68 | H7: =-Assumptions!H68 | I7: =-Assumptions!I68
A8: − Increase in net working capital | E8: =-(('Balance Sheet'!E5+'Balance Sheet'!E6-'Balance Sheet'!E15)-('Balance Sheet'!D5+'Balance Sheet'!D6-'Balance Sheet'!D15)) | F8: =-(('Balance Sheet'!F5+'Balance Sheet'!F6-'Balance Sheet'!F15)-('Balance Sheet'!E5+'Balance Sheet'!E6-'Balance Sheet'!E15)) | G8: =-(('Balance Sheet'!G5+'Balance Sheet'!G6-'Balance Sheet'!G15)-('Balance Sheet'!F5+'Balance Sheet'!F6-'Balance Sheet'!F15)) | H8: =-(('Balance Sheet'!H5+'Balance Sheet'!H6-'Balance Sheet'!H15)-('Balance Sheet'!G5+'Balance Sheet'!G6-'Balance Sheet'!G15)) | I8: =-(('Balance Sheet'!I5+'Balance Sheet'!I6-'Balance Sheet'!I15)-('Balance Sheet'!H5+'Balance Sheet'!H6-'Balance Sheet'!H15))
A9: Free cash flow to firm | E9: =E5+E6+E7+E8 | F9: =F5+F6+F7+F8 | G9: =G5+G6+G7+G8 | H9: =H5+H6+H7+H8 | I9: =I5+I6+I7+I8
A10: Discount factor | E10: =1/(1+Assumptions!$B$8)^1 | F10: =1/(1+Assumptions!$B$8)^2 | G10: =1/(1+Assumptions!$B$8)^3 | H10: =1/(1+Assumptions!$B$8)^4 | I10: =1/(1+Assumptions!$B$8)^5
A11: PV of FCFF | E11: =E9*E10 | F11: =F9*F10 | G11: =G9*G10 | H11: =H9*H10 | I11: =I9*I10
A13: Σ PV of explicit FCFF (FY27–31) | B13: =SUM(E11:I11)
A14: Terminal value (Gordon) | B14: =I9*(1+Assumptions!$B$9)/(Assumptions!$B$8-Assumptions!$B$9)
A15: PV of terminal value | B15: =B14/(1+Assumptions!$B$8)^5
A16: Enterprise value | B16: =B13+B15
A17: less: consolidated net debt | B17: =-Assumptions!$B$7
A18: Equity value | B18: =B16+B17
A19: Fair value per share (Rs) | B19: =B18/Assumptions!$B$5
A20: % terminal of EV | B20: =B15/B16

Sheet Income Statement
A1: Income statement (Rs cr, consolidated)
A2: FY24–FY26 disclosed / tied to reported totals (blue); FY27–FY31 forecast (formulas linking to Assumptions)
B3: FY24 | C3: FY25 | D3: FY26 | E3: FY27E | F3: FY28E | G3: FY29E | H3: FY30E | I3: FY31E
A4: O2C revenue | B4: 564794 | C4: 626921 | D4: 662401 | E4: =D4*(1+Assumptions!E54) | F4: =E4*(1+Assumptions!F54) | G4: =F4*(1+Assumptions!G54) | H4: =G4*(1+Assumptions!H54) | I4: =H4*(1+Assumptions!I54)
A5: Digital Services (Jio) revenue | B5: 110175 | C5: 129333 | D5: 146885 | E5: =D5*(1+Assumptions!E55) | F5: =E5*(1+Assumptions!F55) | G5: =F5*(1+Assumptions!G55) | H5: =G5*(1+Assumptions!H55) | I5: =H5*(1+Assumptions!I55)
A6: Reliance Retail revenue | B6: 306645 | C6: 330870 | D6: 370026 | E6: =D6*(1+Assumptions!E56) | F6: =E6*(1+Assumptions!F56) | G6: =F6*(1+Assumptions!G56) | H6: =G6*(1+Assumptions!H56) | I6: =H6*(1+Assumptions!I56)
A7: Oil & Gas / Media / other revenue | B7: 42000 | C7: 48000 | D7: 54909 | E7: =D7*(1+Assumptions!E57) | F7: =E7*(1+Assumptions!F57) | G7: =F7*(1+Assumptions!G57) | H7: =G7*(1+Assumptions!H57) | I7: =H7*(1+Assumptions!I57)
A8: less: inter-segment eliminations | B8: -124552 | C8: -170431 | D8: -158546 | E8: =Assumptions!E63*SUM(E4:E7) | F8: =Assumptions!F63*SUM(F4:F7) | G8: =Assumptions!G63*SUM(G4:G7) | H8: =Assumptions!H63*SUM(H4:H7) | I8: =Assumptions!I63*SUM(I4:I7)
A9: Total revenue | B9: =SUM(B4:B8) | C9: =SUM(C4:C8) | D9: =SUM(D4:D8) | E9: =SUM(E4:E8) | F9: =SUM(F4:F8) | G9: =SUM(G4:G8) | H9: =SUM(H4:H8) | I9: =SUM(I4:I8)
A11: O2C EBITDA | B11: 62000 | C11: 54988 | D11: 60546 | E11: =E4*Assumptions!E58 | F11: =F4*Assumptions!F58 | G11: =G4*Assumptions!G58 | H11: =H4*Assumptions!H58 | I11: =I4*Assumptions!I58
A12: Digital Services (Jio) EBITDA | B12: 54959 | C12: 64170 | D12: 76255 | E12: =E5*Assumptions!E59 | F12: =F5*Assumptions!F59 | G12: =G5*Assumptions!G59 | H12: =H5*Assumptions!H59 | I12: =I5*Assumptions!I59
A13: Reliance Retail EBITDA | B13: 21500 | C13: 25053 | D13: 27033 | E13: =E6*Assumptions!E60 | F13: =F6*Assumptions!F60 | G13: =G6*Assumptions!G60 | H13: =H6*Assumptions!H60 | I13: =I6*Assumptions!I60
A14: Oil & Gas / Media / other EBITDA | B14: 19000 | C14: 21000 | D14: 23935 | E14: =E7*Assumptions!E61 | F14: =F7*Assumptions!F61 | G14: =G7*Assumptions!G61 | H14: =H7*Assumptions!H61 | I14: =I7*Assumptions!I61
A15: Corporate / New Energy / unallocated EBITDA | B15: 21218 | C15: 18133 | D15: 20142 | E15: =Assumptions!E62 | F15: =Assumptions!F62 | G15: =Assumptions!G62 | H15: =Assumptions!H62 | I15: =Assumptions!I62
A16: Consolidated EBITDA | B16: =SUM(B11:B15) | C16: =SUM(C11:C15) | D16: =SUM(D11:D15) | E16: =SUM(E11:E15) | F16: =SUM(F11:F15) | G16: =SUM(G11:G15) | H16: =SUM(H11:H15) | I16: =SUM(I11:I15)
A17: EBITDA margin | B17: =B16/B9 | C17: =C16/C9 | D17: =D16/D9 | E17: =E16/E9 | F17: =F16/F9 | G17: =G16/G9 | H17: =H16/H9 | I17: =I16/I9
A18: Depreciation & amortisation | B18: 40012 | C18: 52000 | D18: 55000 | E18: =E9*Assumptions!E64 | F18: =F9*Assumptions!F64 | G18: =G9*Assumptions!G64 | H18: =H9*Assumptions!H64 | I18: =I9*Assumptions!I64
A19: EBIT | B19: =B16-B18 | C19: =C16-C18 | D19: =D16-D18 | E19: =E16-E18 | F19: =F16-F18 | G19: =G16-G18 | H19: =H16-H18 | I19: =I16-I18
A20: Finance cost | B20: 23118 | C20: 23000 | D20: 27157 | E20: =Assumptions!E65 | F20: =Assumptions!F65 | G20: =Assumptions!G65 | H20: =Assumptions!H65 | I20: =Assumptions!I65
A21: PBT | B21: =B19-B20 | C21: =C19-C20 | D21: =D19-D20 | E21: =E19-E20 | F21: =F19-F20 | G21: =G19-G20 | H21: =H19-H20 | I21: =I19-I20
A22: Tax | B22: 35926 | C22: 27000 | D22: 30000 | E22: =MAX(0,E21)*Assumptions!E66 | F22: =MAX(0,F21)*Assumptions!F66 | G22: =MAX(0,G21)*Assumptions!G66 | H22: =MAX(0,H21)*Assumptions!H66 | I22: =MAX(0,I21)*Assumptions!I66
A23: PAT (total, incl. minority) | B23: =B21-B22 | C23: =C21-C22 | D23: =D21-D22 | E23: =E21-E22 | F23: =F21-F22 | G23: =G21-G22 | H23: =H21-H22 | I23: =I21-I22
A24: less: minority interest & associates | B24: 10000 | C24: 11696 | D24: 14979 | E24: =E23*Assumptions!E67 | F24: =F23*Assumptions!F67 | G24: =G23*Assumptions!G67 | H24: =H23*Assumptions!H67 | I24: =I23*Assumptions!I67
A25: PAT attributable to owners | B25: =B23-B24 | C25: =C23-C24 | D25: =D23-D24 | E25: =E23-E24 | F25: =F23-F24 | G25: =G23-G24 | H25: =H23-H24 | I25: =I23-I24
A27: Source: RIL FY26 results (24 Apr 2026), Jio Platforms DRHP (19 Jun 2026); segment splits per company disclosure. Some finance/tax/minority lines estimated to tie to reported PAT. Forecast = formulas.

Sheet Balance Sheet
A1: Balance sheet (Rs cr, consolidated)
A2: Historical anchored to disclosed equity/borrowings/cash/net-debt; PP&E plugs to balance. Forecast rolls forward.
B3: FY24 | C3: FY25 | D3: FY26 | E3: FY27E | F3: FY28E | G3: FY29E | H3: FY30E | I3: FY31E
A4: PP&E + intangibles (incl. CWIP) | B4: =(B12+B13+B14+B15+B16)-(B5+B6+B7+B8+B9) | C4: =(C12+C13+C14+C15+C16)-(C5+C6+C7+C8+C9) | D4: =(D12+D13+D14+D15+D16)-(D5+D6+D7+D8+D9) | E4: =D4+Assumptions!E68-'Income Statement'!E18 | F4: =E4+Assumptions!F68-'Income Statement'!F18 | G4: =F4+Assumptions!G68-'Income Statement'!G18 | H4: =G4+Assumptions!H68-'Income Statement'!H18 | I4: =H4+Assumptions!I68-'Income Statement'!I18
A5: Inventory | B5: ='Income Statement'!B9*Assumptions!$B$44 | C5: ='Income Statement'!C9*Assumptions!$B$44 | D5: ='Income Statement'!D9*Assumptions!$B$44 | E5: ='Income Statement'!E9*Assumptions!$B$44 | F5: ='Income Statement'!F9*Assumptions!$B$44 | G5: ='Income Statement'!G9*Assumptions!$B$44 | H5: ='Income Statement'!H9*Assumptions!$B$44 | I5: ='Income Statement'!I9*Assumptions!$B$44
A6: Receivables | B6: ='Income Statement'!B9*Assumptions!$B$45 | C6: ='Income Statement'!C9*Assumptions!$B$45 | D6: ='Income Statement'!D9*Assumptions!$B$45 | E6: ='Income Statement'!E9*Assumptions!$B$45 | F6: ='Income Statement'!F9*Assumptions!$B$45 | G6: ='Income Statement'!G9*Assumptions!$B$45 | H6: ='Income Statement'!H9*Assumptions!$B$45 | I6: ='Income Statement'!I9*Assumptions!$B$45
A7: Cash & equivalents | B7: 80000 | C7: 85000 | D7: 90000 | E7: =D7+('Income Statement'!E23+'Income Statement'!E18-((E5+E6-E15)-(D5+D6-D15)))-Assumptions!E68-Assumptions!E69-Assumptions!E70 | F7: =E7+('Income Statement'!F23+'Income Statement'!F18-((F5+F6-F15)-(E5+E6-E15)))-Assumptions!F68-Assumptions!F69-Assumptions!F70 | G7: =F7+('Income Statement'!G23+'Income Statement'!G18-((G5+G6-G15)-(F5+F6-F15)))-Assumptions!G68-Assumptions!G69-Assumptions!G70 | H7: =G7+('Income Statement'!H23+'Income Statement'!H18-((H5+H6-H15)-(G5+G6-G15)))-Assumptions!H68-Assumptions!H69-Assumptions!H70 | I7: =H7+('Income Statement'!I23+'Income Statement'!I18-((I5+I6-I15)-(H5+H6-H15)))-Assumptions!I68-Assumptions!I69-Assumptions!I70
A8: Current investments | B8: 134000 | C8: 145447 | D8: 159704 | E8: =D8 | F8: =E8 | G8: =F8 | H8: =G8 | I8: =H8
A9: Other assets | B9: 620000 | C9: 700000 | D9: 760000 | E9: =D9 | F9: =E9 | G9: =F9 | H9: =G9 | I9: =H9
A10: Total assets | B10: =SUM(B4:B9) | C10: =SUM(C4:C9) | D10: =SUM(D4:D9) | E10: =SUM(E4:E9) | F10: =SUM(F4:F9) | G10: =SUM(G4:G9) | H10: =SUM(H4:H9) | I10: =SUM(I4:I9)
A12: Equity (incl. minority) | B12: 900000 | C12: 1010000 | D12: 1120000 | E12: =D12+'Income Statement'!E23-Assumptions!E69 | F12: =E12+'Income Statement'!F23-Assumptions!F69 | G12: =F12+'Income Statement'!G23-Assumptions!G69 | H12: =G12+'Income Statement'!H23-Assumptions!H69 | I12: =H12+'Income Statement'!I23-Assumptions!I69
A13: Borrowings (gross debt) | B13: 330000 | C13: 347530 | D13: 374421 | E13: =D13-Assumptions!E70 | F13: =E13-Assumptions!F70 | G13: =F13-Assumptions!G70 | H13: =G13-Assumptions!H70 | I13: =H13-Assumptions!I70
A14: Provisions | B14: 70000 | C14: 78000 | D14: 85000 | E14: =D14 | F14: =E14 | G14: =F14 | H14: =G14 | I14: =H14
A15: Payables | B15: ='Income Statement'!B9*Assumptions!$B$46 | C15: ='Income Statement'!C9*Assumptions!$B$46 | D15: ='Income Statement'!D9*Assumptions!$B$46 | E15: ='Income Statement'!E9*Assumptions!$B$46 | F15: ='Income Statement'!F9*Assumptions!$B$46 | G15: ='Income Statement'!G9*Assumptions!$B$46 | H15: ='Income Statement'!H9*Assumptions!$B$46 | I15: ='Income Statement'!I9*Assumptions!$B$46
A16: Other liabilities | B16: 260000 | C16: 290000 | D16: 320000 | E16: =D16 | F16: =E16 | G16: =F16 | H16: =G16 | I16: =H16
A17: Total liabilities & equity | B17: =B12+B13+B14+B15+B16 | C17: =C12+C13+C14+C15+C16 | D17: =D12+D13+D14+D15+D16 | E17: =E12+E13+E14+E15+E16 | F17: =F12+F13+F14+F15+F16 | G17: =G12+G13+G14+G15+G16 | H17: =H12+H13+H14+H15+H16 | I17: =I12+I13+I14+I15+I16
A19: Balance check (assets − L&E) | B19: =B10-B17 | C19: =C10-C17 | D19: =D10-D17 | E19: =E10-E17 | F19: =F10-F17 | G19: =G10-G17 | H19: =H10-H17 | I19: =I10-I17
A20: Net debt | B20: =B13-B7-B8 | C20: =C13-C7-C8 | D20: =D13-D7-D8 | E20: =E13-E7-E8 | F20: =F13-F7-F8 | G20: =G13-G7-G8 | H20: =H13-H7-H8 | I20: =I13-I7-I8

Sheet Cash Flow
A1: Cash flow (Rs cr, forecast)
A2: Derived from the Income Statement and Balance Sheet. Closing cash ties to the Balance Sheet.
E3: FY27E | F3: FY28E | G3: FY29E | H3: FY30E | I3: FY31E
A4: PAT (total) | E4: ='Income Statement'!E23 | F4: ='Income Statement'!F23 | G4: ='Income Statement'!G23 | H4: ='Income Statement'!H23 | I4: ='Income Statement'!I23
A5: + D&A | E5: ='Income Statement'!E18 | F5: ='Income Statement'!F18 | G5: ='Income Statement'!G18 | H5: ='Income Statement'!H18 | I5: ='Income Statement'!I18
A6: − Increase in net working capital | E6: =-(('Balance Sheet'!E5+'Balance Sheet'!E6-'Balance Sheet'!E15)-('Balance Sheet'!D5+'Balance Sheet'!D6-'Balance Sheet'!D15)) | F6: =-(('Balance Sheet'!F5+'Balance Sheet'!F6-'Balance Sheet'!F15)-('Balance Sheet'!E5+'Balance Sheet'!E6-'Balance Sheet'!E15)) | G6: =-(('Balance Sheet'!G5+'Balance Sheet'!G6-'Balance Sheet'!G15)-('Balance Sheet'!F5+'Balance Sheet'!F6-'Balance Sheet'!F15)) | H6: =-(('Balance Sheet'!H5+'Balance Sheet'!H6-'Balance Sheet'!H15)-('Balance Sheet'!G5+'Balance Sheet'!G6-'Balance Sheet'!G15)) | I6: =-(('Balance Sheet'!I5+'Balance Sheet'!I6-'Balance Sheet'!I15)-('Balance Sheet'!H5+'Balance Sheet'!H6-'Balance Sheet'!H15))
A7: Operating cash flow | E7: =E4+E5+E6 | F7: =F4+F5+F6 | G7: =G4+G5+G6 | H7: =H4+H5+H6 | I7: =I4+I5+I6
A8: − Capex | E8: =-Assumptions!E68 | F8: =-Assumptions!F68 | G8: =-Assumptions!G68 | H8: =-Assumptions!H68 | I8: =-Assumptions!I68
A9: Free cash flow | E9: =E7+E8 | F9: =F7+F8 | G9: =G7+G8 | H9: =H7+H8 | I9: =I7+I8
A10: − Dividend | E10: =-Assumptions!E69 | F10: =-Assumptions!F69 | G10: =-Assumptions!G69 | H10: =-Assumptions!H69 | I10: =-Assumptions!I69
A11: − Debt repayment | E11: =-Assumptions!E70 | F11: =-Assumptions!F70 | G11: =-Assumptions!G70 | H11: =-Assumptions!H70 | I11: =-Assumptions!I70
A12: Net change in cash | E12: =E9+E10+E11 | F12: =F9+F10+F11 | G12: =G9+G10+G11 | H12: =H9+H10+H11 | I12: =I9+I10+I11
A13: Opening cash | E13: ='Balance Sheet'!D7 | F13: ='Balance Sheet'!E7 | G13: ='Balance Sheet'!F7 | H13: ='Balance Sheet'!G7 | I13: ='Balance Sheet'!H7
A14: Closing cash | E14: =E13+E12 | F14: =F13+F12 | G14: =G13+G12 | H14: =H13+H12 | I14: =I13+I12

Sheet Summary Financials
A1: Summary financials (Rs cr)
A2: Every cell links to the statement sheets.
B3: FY24 | C3: FY25 | D3: FY26 | E3: FY27E | F3: FY28E | G3: FY29E | H3: FY30E | I3: FY31E
A4: Revenue | B4: ='Income Statement'!B9 | C4: ='Income Statement'!C9 | D4: ='Income Statement'!D9 | E4: ='Income Statement'!E9 | F4: ='Income Statement'!F9 | G4: ='Income Statement'!G9 | H4: ='Income Statement'!H9 | I4: ='Income Statement'!I9
A5: EBITDA | B5: ='Income Statement'!B16 | C5: ='Income Statement'!C16 | D5: ='Income Statement'!D16 | E5: ='Income Statement'!E16 | F5: ='Income Statement'!F16 | G5: ='Income Statement'!G16 | H5: ='Income Statement'!H16 | I5: ='Income Statement'!I16
A6: EBIT | B6: ='Income Statement'!B19 | C6: ='Income Statement'!C19 | D6: ='Income Statement'!D19 | E6: ='Income Statement'!E19 | F6: ='Income Statement'!F19 | G6: ='Income Statement'!G19 | H6: ='Income Statement'!H19 | I6: ='Income Statement'!I19
A7: PAT (total) | B7: ='Income Statement'!B23 | C7: ='Income Statement'!C23 | D7: ='Income Statement'!D23 | E7: ='Income Statement'!E23 | F7: ='Income Statement'!F23 | G7: ='Income Statement'!G23 | H7: ='Income Statement'!H23 | I7: ='Income Statement'!I23
A8: PAT attributable | B8: ='Income Statement'!B25 | C8: ='Income Statement'!C25 | D8: ='Income Statement'!D25 | E8: ='Income Statement'!E25 | F8: ='Income Statement'!F25 | G8: ='Income Statement'!G25 | H8: ='Income Statement'!H25 | I8: ='Income Statement'!I25
A9: Total assets | B9: ='Balance Sheet'!B10 | C9: ='Balance Sheet'!C10 | D9: ='Balance Sheet'!D10 | E9: ='Balance Sheet'!E10 | F9: ='Balance Sheet'!F10 | G9: ='Balance Sheet'!G10 | H9: ='Balance Sheet'!H10 | I9: ='Balance Sheet'!I10
A10: Equity | B10: ='Balance Sheet'!B12 | C10: ='Balance Sheet'!C12 | D10: ='Balance Sheet'!D12 | E10: ='Balance Sheet'!E12 | F10: ='Balance Sheet'!F12 | G10: ='Balance Sheet'!G12 | H10: ='Balance Sheet'!H12 | I10: ='Balance Sheet'!I12
A11: Net debt | B11: ='Balance Sheet'!B20 | C11: ='Balance Sheet'!C20 | D11: ='Balance Sheet'!D20 | E11: ='Balance Sheet'!E20 | F11: ='Balance Sheet'!F20 | G11: ='Balance Sheet'!G20 | H11: ='Balance Sheet'!H20 | I11: ='Balance Sheet'!I20
A12: Free cash flow | E12: ='Cash Flow'!E9 | F12: ='Cash Flow'!F9 | G12: ='Cash Flow'!G9 | H12: ='Cash Flow'!H9 | I12: ='Cash Flow'!I9

Sheet Monte Carlo
A1: Monte Carlo — engine outputs
A2: 50,000 paths · 16 factors · seed 42 · YZ-HAR width, Student-t(5), zero secular drift (values, not a sheet simulation).
A3: Percentile map (Rs/share)
A4: Horizon | B4: p5 | C4: p25 | D4: p50 | E4: p75 | F4: p95
A5: T+20 sessions | B5: 1160 | C5: 1266 | D5: 1331 | E5: 1400 | F5: 1526
A6: T+60 sessions | B6: 1067 | C6: 1235 | D6: 1351 | E6: 1478 | F6: 1707
A8: Inputs (from Assumptions): σ | D8: =Assumptions!$B$49
A9: net 3-month drift | D9: =Assumptions!$B$50
A11: Level-touch ladder
A12: Level | B12: T+20 | C12: T+60
A13: 1550 | B13: 0.05542 | C13: 0.25138
A14: 1500 | B14: 0.10888 | C14: 0.35574
A15: 1450 | B15: 0.2094 | C15: 0.48842
A16: 1400 | B16: 0.39148 | C16: 0.65036
A17: 1350 | B17: 0.68206 | C17: 0.83284
A18: 1300 | B18: 0.68004 | C18: 0.79636
A19: 1250 | B19: 0.33888 | C19: 0.54914
A20: 1200 | B20: 0.1536 | C20: 0.36272
A21: 1150 | B21: 0.0653 | C21: 0.22714

Sheet Sensitivity
A1: SOTP sensitivity — the Jio-value swing
A2: Fair value (Rs/share, post-discount) by Jio EV/EBITDA × holdco discount. Live off Assumptions.
A4: Jio mult \ disc | B4: 0 | C4: 0.025 | D4: 0.05 | E4: 0.075 | F4: 0.1 | G4: 0.125
A5: 11 | B5: =(($A5*Assumptions!$B$13+Assumptions!$B$17*Assumptions!$B$18+Assumptions!$B$21*Assumptions!$B$22+Assumptions!$B$23*Assumptions!$B$24+Assumptions!$B$25*Assumptions!$B$26+Assumptions!$B$28-Assumptions!$B$7)-(($A5*Assumptions!$B$13-Assumptions!$B$15)*(1-Assumptions!$B$16)+(Assumptions!$B$17*Assumptions!$B$18-Assumptions!$B$19)*(1-Assumptions!$B$20)+(Assumptions!$B$25*Assumptions!$B$26)*(1-Assumptions!$B$27)))*(1-B$4)/Assumptions!$B$5 | C5: =(($A5*Assumptions!$B$13+Assumptions!$B$17*Assumptions!$B$18+Assumptions!$B$21*Assumptions!$B$22+Assumptions!$B$23*Assumptions!$B$24+Assumptions!$B$25*Assumptions!$B$26+Assumptions!$B$28-Assumptions!$B$7)-(($A5*Assumptions!$B$13-Assumptions!$B$15)*(1-Assumptions!$B$16)+(Assumptions!$B$17*Assumptions!$B$18-Assumptions!$B$19)*(1-Assumptions!$B$20)+(Assumptions!$B$25*Assumptions!$B$26)*(1-Assumptions!$B$27)))*(1-C$4)/Assumptions!$B$5 | D5: =(($A5*Assumptions!$B$13+Assumptions!$B$17*Assumptions!$B$18+Assumptions!$B$21*Assumptions!$B$22+Assumptions!$B$23*Assumptions!$B$24+Assumptions!$B$25*Assumptions!$B$26+Assumptions!$B$28-Assumptions!$B$7)-(($A5*Assumptions!$B$13-Assumptions!$B$15)*(1-Assumptions!$B$16)+(Assumptions!$B$17*Assumptions!$B$18-Assumptions!$B$19)*(1-Assumptions!$B$20)+(Assumptions!$B$25*Assumptions!$B$26)*(1-Assumptions!$B$27)))*(1-D$4)/Assumptions!$B$5 | E5: =(($A5*Assumptions!$B$13+Assumptions!$B$17*Assumptions!$B$18+Assumptions!$B$21*Assumptions!$B$22+Assumptions!$B$23*Assumptions!$B$24+Assumptions!$B$25*Assumptions!$B$26+Assumptions!$B$28-Assumptions!$B$7)-(($A5*Assumptions!$B$13-Assumptions!$B$15)*(1-Assumptions!$B$16)+(Assumptions!$B$17*Assumptions!$B$18-Assumptions!$B$19)*(1-Assumptions!$B$20)+(Assumptions!$B$25*Assumptions!$B$26)*(1-Assumptions!$B$27)))*(1-E$4)/Assumptions!$B$5 | F5: =(($A5*Assumptions!$B$13+Assumptions!$B$17*Assumptions!$B$18+Assumptions!$B$21*Assumptions!$B$22+Assumptions!$B$23*Assumptions!$B$24+Assumptions!$B$25*Assumptions!$B$26+Assumptions!$B$28-Assumptions!$B$7)-(($A5*Assumptions!$B$13-Assumptions!$B$15)*(1-Assumptions!$B$16)+(Assumptions!$B$17*Assumptions!$B$18-Assumptions!$B$19)*(1-Assumptions!$B$20)+(Assumptions!$B$25*Assumptions!$B$26)*(1-Assumptions!$B$27)))*(1-F$4)/Assumptions!$B$5 | G5: =(($A5*Assumptions!$B$13+Assumptions!$B$17*Assumptions!$B$18+Assumptions!$B$21*Assumptions!$B$22+Assumptions!$B$23*Assumptions!$B$24+Assumptions!$B$25*Assumptions!$B$26+Assumptions!$B$28-Assumptions!$B$7)-(($A5*Assumptions!$B$13-Assumptions!$B$15)*(1-Assumptions!$B$16)+(Assumptions!$B$17*Assumptions!$B$18-Assumptions!$B$19)*(1-Assumptions!$B$20)+(Assumptions!$B$25*Assumptions!$B$26)*(1-Assumptions!$B$27)))*(1-G$4)/Assumptions!$B$5
A6: 12 | B6: =(($A6*Assumptions!$B$13+Assumptions!$B$17*Assumptions!$B$18+Assumptions!$B$21*Assumptions!$B$22+Assumptions!$B$23*Assumptions!$B$24+Assumptions!$B$25*Assumptions!$B$26+Assumptions!$B$28-Assumptions!$B$7)-(($A6*Assumptions!$B$13-Assumptions!$B$15)*(1-Assumptions!$B$16)+(Assumptions!$B$17*Assumptions!$B$18-Assumptions!$B$19)*(1-Assumptions!$B$20)+(Assumptions!$B$25*Assumptions!$B$26)*(1-Assumptions!$B$27)))*(1-B$4)/Assumptions!$B$5 | C6: =(($A6*Assumptions!$B$13+Assumptions!$B$17*Assumptions!$B$18+Assumptions!$B$21*Assumptions!$B$22+Assumptions!$B$23*Assumptions!$B$24+Assumptions!$B$25*Assumptions!$B$26+Assumptions!$B$28-Assumptions!$B$7)-(($A6*Assumptions!$B$13-Assumptions!$B$15)*(1-Assumptions!$B$16)+(Assumptions!$B$17*Assumptions!$B$18-Assumptions!$B$19)*(1-Assumptions!$B$20)+(Assumptions!$B$25*Assumptions!$B$26)*(1-Assumptions!$B$27)))*(1-C$4)/Assumptions!$B$5 | D6: =(($A6*Assumptions!$B$13+Assumptions!$B$17*Assumptions!$B$18+Assumptions!$B$21*Assumptions!$B$22+Assumptions!$B$23*Assumptions!$B$24+Assumptions!$B$25*Assumptions!$B$26+Assumptions!$B$28-Assumptions!$B$7)-(($A6*Assumptions!$B$13-Assumptions!$B$15)*(1-Assumptions!$B$16)+(Assumptions!$B$17*Assumptions!$B$18-Assumptions!$B$19)*(1-Assumptions!$B$20)+(Assumptions!$B$25*Assumptions!$B$26)*(1-Assumptions!$B$27)))*(1-D$4)/Assumptions!$B$5 | E6: =(($A6*Assumptions!$B$13+Assumptions!$B$17*Assumptions!$B$18+Assumptions!$B$21*Assumptions!$B$22+Assumptions!$B$23*Assumptions!$B$24+Assumptions!$B$25*Assumptions!$B$26+Assumptions!$B$28-Assumptions!$B$7)-(($A6*Assumptions!$B$13-Assumptions!$B$15)*(1-Assumptions!$B$16)+(Assumptions!$B$17*Assumptions!$B$18-Assumptions!$B$19)*(1-Assumptions!$B$20)+(Assumptions!$B$25*Assumptions!$B$26)*(1-Assumptions!$B$27)))*(1-E$4)/Assumptions!$B$5 | F6: =(($A6*Assumptions!$B$13+Assumptions!$B$17*Assumptions!$B$18+Assumptions!$B$21*Assumptions!$B$22+Assumptions!$B$23*Assumptions!$B$24+Assumptions!$B$25*Assumptions!$B$26+Assumptions!$B$28-Assumptions!$B$7)-(($A6*Assumptions!$B$13-Assumptions!$B$15)*(1-Assumptions!$B$16)+(Assumptions!$B$17*Assumptions!$B$18-Assumptions!$B$19)*(1-Assumptions!$B$20)+(Assumptions!$B$25*Assumptions!$B$26)*(1-Assumptions!$B$27)))*(1-F$4)/Assumptions!$B$5 | G6: =(($A6*Assumptions!$B$13+Assumptions!$B$17*Assumptions!$B$18+Assumptions!$B$21*Assumptions!$B$22+Assumptions!$B$23*Assumptions!$B$24+Assumptions!$B$25*Assumptions!$B$26+Assumptions!$B$28-Assumptions!$B$7)-(($A6*Assumptions!$B$13-Assumptions!$B$15)*(1-Assumptions!$B$16)+(Assumptions!$B$17*Assumptions!$B$18-Assumptions!$B$19)*(1-Assumptions!$B$20)+(Assumptions!$B$25*Assumptions!$B$26)*(1-Assumptions!$B$27)))*(1-G$4)/Assumptions!$B$5
A7: 13 | B7: =(($A7*Assumptions!$B$13+Assumptions!$B$17*Assumptions!$B$18+Assumptions!$B$21*Assumptions!$B$22+Assumptions!$B$23*Assumptions!$B$24+Assumptions!$B$25*Assumptions!$B$26+Assumptions!$B$28-Assumptions!$B$7)-(($A7*Assumptions!$B$13-Assumptions!$B$15)*(1-Assumptions!$B$16)+(Assumptions!$B$17*Assumptions!$B$18-Assumptions!$B$19)*(1-Assumptions!$B$20)+(Assumptions!$B$25*Assumptions!$B$26)*(1-Assumptions!$B$27)))*(1-B$4)/Assumptions!$B$5 | C7: =(($A7*Assumptions!$B$13+Assumptions!$B$17*Assumptions!$B$18+Assumptions!$B$21*Assumptions!$B$22+Assumptions!$B$23*Assumptions!$B$24+Assumptions!$B$25*Assumptions!$B$26+Assumptions!$B$28-Assumptions!$B$7)-(($A7*Assumptions!$B$13-Assumptions!$B$15)*(1-Assumptions!$B$16)+(Assumptions!$B$17*Assumptions!$B$18-Assumptions!$B$19)*(1-Assumptions!$B$20)+(Assumptions!$B$25*Assumptions!$B$26)*(1-Assumptions!$B$27)))*(1-C$4)/Assumptions!$B$5 | D7: =(($A7*Assumptions!$B$13+Assumptions!$B$17*Assumptions!$B$18+Assumptions!$B$21*Assumptions!$B$22+Assumptions!$B$23*Assumptions!$B$24+Assumptions!$B$25*Assumptions!$B$26+Assumptions!$B$28-Assumptions!$B$7)-(($A7*Assumptions!$B$13-Assumptions!$B$15)*(1-Assumptions!$B$16)+(Assumptions!$B$17*Assumptions!$B$18-Assumptions!$B$19)*(1-Assumptions!$B$20)+(Assumptions!$B$25*Assumptions!$B$26)*(1-Assumptions!$B$27)))*(1-D$4)/Assumptions!$B$5 | E7: =(($A7*Assumptions!$B$13+Assumptions!$B$17*Assumptions!$B$18+Assumptions!$B$21*Assumptions!$B$22+Assumptions!$B$23*Assumptions!$B$24+Assumptions!$B$25*Assumptions!$B$26+Assumptions!$B$28-Assumptions!$B$7)-(($A7*Assumptions!$B$13-Assumptions!$B$15)*(1-Assumptions!$B$16)+(Assumptions!$B$17*Assumptions!$B$18-Assumptions!$B$19)*(1-Assumptions!$B$20)+(Assumptions!$B$25*Assumptions!$B$26)*(1-Assumptions!$B$27)))*(1-E$4)/Assumptions!$B$5 | F7: =(($A7*Assumptions!$B$13+Assumptions!$B$17*Assumptions!$B$18+Assumptions!$B$21*Assumptions!$B$22+Assumptions!$B$23*Assumptions!$B$24+Assumptions!$B$25*Assumptions!$B$26+Assumptions!$B$28-Assumptions!$B$7)-(($A7*Assumptions!$B$13-Assumptions!$B$15)*(1-Assumptions!$B$16)+(Assumptions!$B$17*Assumptions!$B$18-Assumptions!$B$19)*(1-Assumptions!$B$20)+(Assumptions!$B$25*Assumptions!$B$26)*(1-Assumptions!$B$27)))*(1-F$4)/Assumptions!$B$5 | G7: =(($A7*Assumptions!$B$13+Assumptions!$B$17*Assumptions!$B$18+Assumptions!$B$21*Assumptions!$B$22+Assumptions!$B$23*Assumptions!$B$24+Assumptions!$B$25*Assumptions!$B$26+Assumptions!$B$28-Assumptions!$B$7)-(($A7*Assumptions!$B$13-Assumptions!$B$15)*(1-Assumptions!$B$16)+(Assumptions!$B$17*Assumptions!$B$18-Assumptions!$B$19)*(1-Assumptions!$B$20)+(Assumptions!$B$25*Assumptions!$B$26)*(1-Assumptions!$B$27)))*(1-G$4)/Assumptions!$B$5
A8: 14 | B8: =(($A8*Assumptions!$B$13+Assumptions!$B$17*Assumptions!$B$18+Assumptions!$B$21*Assumptions!$B$22+Assumptions!$B$23*Assumptions!$B$24+Assumptions!$B$25*Assumptions!$B$26+Assumptions!$B$28-Assumptions!$B$7)-(($A8*Assumptions!$B$13-Assumptions!$B$15)*(1-Assumptions!$B$16)+(Assumptions!$B$17*Assumptions!$B$18-Assumptions!$B$19)*(1-Assumptions!$B$20)+(Assumptions!$B$25*Assumptions!$B$26)*(1-Assumptions!$B$27)))*(1-B$4)/Assumptions!$B$5 | C8: =(($A8*Assumptions!$B$13+Assumptions!$B$17*Assumptions!$B$18+Assumptions!$B$21*Assumptions!$B$22+Assumptions!$B$23*Assumptions!$B$24+Assumptions!$B$25*Assumptions!$B$26+Assumptions!$B$28-Assumptions!$B$7)-(($A8*Assumptions!$B$13-Assumptions!$B$15)*(1-Assumptions!$B$16)+(Assumptions!$B$17*Assumptions!$B$18-Assumptions!$B$19)*(1-Assumptions!$B$20)+(Assumptions!$B$25*Assumptions!$B$26)*(1-Assumptions!$B$27)))*(1-C$4)/Assumptions!$B$5 | D8: =(($A8*Assumptions!$B$13+Assumptions!$B$17*Assumptions!$B$18+Assumptions!$B$21*Assumptions!$B$22+Assumptions!$B$23*Assumptions!$B$24+Assumptions!$B$25*Assumptions!$B$26+Assumptions!$B$28-Assumptions!$B$7)-(($A8*Assumptions!$B$13-Assumptions!$B$15)*(1-Assumptions!$B$16)+(Assumptions!$B$17*Assumptions!$B$18-Assumptions!$B$19)*(1-Assumptions!$B$20)+(Assumptions!$B$25*Assumptions!$B$26)*(1-Assumptions!$B$27)))*(1-D$4)/Assumptions!$B$5 | E8: =(($A8*Assumptions!$B$13+Assumptions!$B$17*Assumptions!$B$18+Assumptions!$B$21*Assumptions!$B$22+Assumptions!$B$23*Assumptions!$B$24+Assumptions!$B$25*Assumptions!$B$26+Assumptions!$B$28-Assumptions!$B$7)-(($A8*Assumptions!$B$13-Assumptions!$B$15)*(1-Assumptions!$B$16)+(Assumptions!$B$17*Assumptions!$B$18-Assumptions!$B$19)*(1-Assumptions!$B$20)+(Assumptions!$B$25*Assumptions!$B$26)*(1-Assumptions!$B$27)))*(1-E$4)/Assumptions!$B$5 | F8: =(($A8*Assumptions!$B$13+Assumptions!$B$17*Assumptions!$B$18+Assumptions!$B$21*Assumptions!$B$22+Assumptions!$B$23*Assumptions!$B$24+Assumptions!$B$25*Assumptions!$B$26+Assumptions!$B$28-Assumptions!$B$7)-(($A8*Assumptions!$B$13-Assumptions!$B$15)*(1-Assumptions!$B$16)+(Assumptions!$B$17*Assumptions!$B$18-Assumptions!$B$19)*(1-Assumptions!$B$20)+(Assumptions!$B$25*Assumptions!$B$26)*(1-Assumptions!$B$27)))*(1-F$4)/Assumptions!$B$5 | G8: =(($A8*Assumptions!$B$13+Assumptions!$B$17*Assumptions!$B$18+Assumptions!$B$21*Assumptions!$B$22+Assumptions!$B$23*Assumptions!$B$24+Assumptions!$B$25*Assumptions!$B$26+Assumptions!$B$28-Assumptions!$B$7)-(($A8*Assumptions!$B$13-Assumptions!$B$15)*(1-Assumptions!$B$16)+(Assumptions!$B$17*Assumptions!$B$18-Assumptions!$B$19)*(1-Assumptions!$B$20)+(Assumptions!$B$25*Assumptions!$B$26)*(1-Assumptions!$B$27)))*(1-G$4)/Assumptions!$B$5
A9: 15 | B9: =(($A9*Assumptions!$B$13+Assumptions!$B$17*Assumptions!$B$18+Assumptions!$B$21*Assumptions!$B$22+Assumptions!$B$23*Assumptions!$B$24+Assumptions!$B$25*Assumptions!$B$26+Assumptions!$B$28-Assumptions!$B$7)-(($A9*Assumptions!$B$13-Assumptions!$B$15)*(1-Assumptions!$B$16)+(Assumptions!$B$17*Assumptions!$B$18-Assumptions!$B$19)*(1-Assumptions!$B$20)+(Assumptions!$B$25*Assumptions!$B$26)*(1-Assumptions!$B$27)))*(1-B$4)/Assumptions!$B$5 | C9: =(($A9*Assumptions!$B$13+Assumptions!$B$17*Assumptions!$B$18+Assumptions!$B$21*Assumptions!$B$22+Assumptions!$B$23*Assumptions!$B$24+Assumptions!$B$25*Assumptions!$B$26+Assumptions!$B$28-Assumptions!$B$7)-(($A9*Assumptions!$B$13-Assumptions!$B$15)*(1-Assumptions!$B$16)+(Assumptions!$B$17*Assumptions!$B$18-Assumptions!$B$19)*(1-Assumptions!$B$20)+(Assumptions!$B$25*Assumptions!$B$26)*(1-Assumptions!$B$27)))*(1-C$4)/Assumptions!$B$5 | D9: =(($A9*Assumptions!$B$13+Assumptions!$B$17*Assumptions!$B$18+Assumptions!$B$21*Assumptions!$B$22+Assumptions!$B$23*Assumptions!$B$24+Assumptions!$B$25*Assumptions!$B$26+Assumptions!$B$28-Assumptions!$B$7)-(($A9*Assumptions!$B$13-Assumptions!$B$15)*(1-Assumptions!$B$16)+(Assumptions!$B$17*Assumptions!$B$18-Assumptions!$B$19)*(1-Assumptions!$B$20)+(Assumptions!$B$25*Assumptions!$B$26)*(1-Assumptions!$B$27)))*(1-D$4)/Assumptions!$B$5 | E9: =(($A9*Assumptions!$B$13+Assumptions!$B$17*Assumptions!$B$18+Assumptions!$B$21*Assumptions!$B$22+Assumptions!$B$23*Assumptions!$B$24+Assumptions!$B$25*Assumptions!$B$26+Assumptions!$B$28-Assumptions!$B$7)-(($A9*Assumptions!$B$13-Assumptions!$B$15)*(1-Assumptions!$B$16)+(Assumptions!$B$17*Assumptions!$B$18-Assumptions!$B$19)*(1-Assumptions!$B$20)+(Assumptions!$B$25*Assumptions!$B$26)*(1-Assumptions!$B$27)))*(1-E$4)/Assumptions!$B$5 | F9: =(($A9*Assumptions!$B$13+Assumptions!$B$17*Assumptions!$B$18+Assumptions!$B$21*Assumptions!$B$22+Assumptions!$B$23*Assumptions!$B$24+Assumptions!$B$25*Assumptions!$B$26+Assumptions!$B$28-Assumptions!$B$7)-(($A9*Assumptions!$B$13-Assumptions!$B$15)*(1-Assumptions!$B$16)+(Assumptions!$B$17*Assumptions!$B$18-Assumptions!$B$19)*(1-Assumptions!$B$20)+(Assumptions!$B$25*Assumptions!$B$26)*(1-Assumptions!$B$27)))*(1-F$4)/Assumptions!$B$5 | G9: =(($A9*Assumptions!$B$13+Assumptions!$B$17*Assumptions!$B$18+Assumptions!$B$21*Assumptions!$B$22+Assumptions!$B$23*Assumptions!$B$24+Assumptions!$B$25*Assumptions!$B$26+Assumptions!$B$28-Assumptions!$B$7)-(($A9*Assumptions!$B$13-Assumptions!$B$15)*(1-Assumptions!$B$16)+(Assumptions!$B$17*Assumptions!$B$18-Assumptions!$B$19)*(1-Assumptions!$B$20)+(Assumptions!$B$25*Assumptions!$B$26)*(1-Assumptions!$B$27)))*(1-G$4)/Assumptions!$B$5
A10: 16 | B10: =(($A10*Assumptions!$B$13+Assumptions!$B$17*Assumptions!$B$18+Assumptions!$B$21*Assumptions!$B$22+Assumptions!$B$23*Assumptions!$B$24+Assumptions!$B$25*Assumptions!$B$26+Assumptions!$B$28-Assumptions!$B$7)-(($A10*Assumptions!$B$13-Assumptions!$B$15)*(1-Assumptions!$B$16)+(Assumptions!$B$17*Assumptions!$B$18-Assumptions!$B$19)*(1-Assumptions!$B$20)+(Assumptions!$B$25*Assumptions!$B$26)*(1-Assumptions!$B$27)))*(1-B$4)/Assumptions!$B$5 | C10: =(($A10*Assumptions!$B$13+Assumptions!$B$17*Assumptions!$B$18+Assumptions!$B$21*Assumptions!$B$22+Assumptions!$B$23*Assumptions!$B$24+Assumptions!$B$25*Assumptions!$B$26+Assumptions!$B$28-Assumptions!$B$7)-(($A10*Assumptions!$B$13-Assumptions!$B$15)*(1-Assumptions!$B$16)+(Assumptions!$B$17*Assumptions!$B$18-Assumptions!$B$19)*(1-Assumptions!$B$20)+(Assumptions!$B$25*Assumptions!$B$26)*(1-Assumptions!$B$27)))*(1-C$4)/Assumptions!$B$5 | D10: =(($A10*Assumptions!$B$13+Assumptions!$B$17*Assumptions!$B$18+Assumptions!$B$21*Assumptions!$B$22+Assumptions!$B$23*Assumptions!$B$24+Assumptions!$B$25*Assumptions!$B$26+Assumptions!$B$28-Assumptions!$B$7)-(($A10*Assumptions!$B$13-Assumptions!$B$15)*(1-Assumptions!$B$16)+(Assumptions!$B$17*Assumptions!$B$18-Assumptions!$B$19)*(1-Assumptions!$B$20)+(Assumptions!$B$25*Assumptions!$B$26)*(1-Assumptions!$B$27)))*(1-D$4)/Assumptions!$B$5 | E10: =(($A10*Assumptions!$B$13+Assumptions!$B$17*Assumptions!$B$18+Assumptions!$B$21*Assumptions!$B$22+Assumptions!$B$23*Assumptions!$B$24+Assumptions!$B$25*Assumptions!$B$26+Assumptions!$B$28-Assumptions!$B$7)-(($A10*Assumptions!$B$13-Assumptions!$B$15)*(1-Assumptions!$B$16)+(Assumptions!$B$17*Assumptions!$B$18-Assumptions!$B$19)*(1-Assumptions!$B$20)+(Assumptions!$B$25*Assumptions!$B$26)*(1-Assumptions!$B$27)))*(1-E$4)/Assumptions!$B$5 | F10: =(($A10*Assumptions!$B$13+Assumptions!$B$17*Assumptions!$B$18+Assumptions!$B$21*Assumptions!$B$22+Assumptions!$B$23*Assumptions!$B$24+Assumptions!$B$25*Assumptions!$B$26+Assumptions!$B$28-Assumptions!$B$7)-(($A10*Assumptions!$B$13-Assumptions!$B$15)*(1-Assumptions!$B$16)+(Assumptions!$B$17*Assumptions!$B$18-Assumptions!$B$19)*(1-Assumptions!$B$20)+(Assumptions!$B$25*Assumptions!$B$26)*(1-Assumptions!$B$27)))*(1-F$4)/Assumptions!$B$5 | G10: =(($A10*Assumptions!$B$13+Assumptions!$B$17*Assumptions!$B$18+Assumptions!$B$21*Assumptions!$B$22+Assumptions!$B$23*Assumptions!$B$24+Assumptions!$B$25*Assumptions!$B$26+Assumptions!$B$28-Assumptions!$B$7)-(($A10*Assumptions!$B$13-Assumptions!$B$15)*(1-Assumptions!$B$16)+(Assumptions!$B$17*Assumptions!$B$18-Assumptions!$B$19)*(1-Assumptions!$B$20)+(Assumptions!$B$25*Assumptions!$B$26)*(1-Assumptions!$B$27)))*(1-G$4)/Assumptions!$B$5
A12: Cells near spot (Rs1,321) show how much Jio value-crystallisation is already in the price.

Sheet Per-Share & Ratios
A1: Per-share & ratios
A2: Links to statements / Assumptions.
B3: FY24 | C3: FY25 | D3: FY26 | E3: FY27E | F3: FY28E | G3: FY29E | H3: FY30E | I3: FY31E
A4: EPS attributable (Rs) | B4: ='Income Statement'!B25/Assumptions!$B$5 | C4: ='Income Statement'!C25/Assumptions!$B$5 | D4: ='Income Statement'!D25/Assumptions!$B$5 | E4: ='Income Statement'!E25/Assumptions!$B$5 | F4: ='Income Statement'!F25/Assumptions!$B$5 | G4: ='Income Statement'!G25/Assumptions!$B$5 | H4: ='Income Statement'!H25/Assumptions!$B$5 | I4: ='Income Statement'!I25/Assumptions!$B$5
A5: Book value/share (Rs) | B5: ='Balance Sheet'!B12/Assumptions!$B$5 | C5: ='Balance Sheet'!C12/Assumptions!$B$5 | D5: ='Balance Sheet'!D12/Assumptions!$B$5 | E5: ='Balance Sheet'!E12/Assumptions!$B$5 | F5: ='Balance Sheet'!F12/Assumptions!$B$5 | G5: ='Balance Sheet'!G12/Assumptions!$B$5 | H5: ='Balance Sheet'!H12/Assumptions!$B$5 | I5: ='Balance Sheet'!I12/Assumptions!$B$5
A6: P/E (× spot) | B6: =Assumptions!$B$4/B4 | C6: =Assumptions!$B$4/C4 | D6: =Assumptions!$B$4/D4 | E6: =Assumptions!$B$4/E4 | F6: =Assumptions!$B$4/F4 | G6: =Assumptions!$B$4/G4 | H6: =Assumptions!$B$4/H4 | I6: =Assumptions!$B$4/I4
A7: EBITDA margin | B7: ='Income Statement'!B16/'Income Statement'!B9 | C7: ='Income Statement'!C16/'Income Statement'!C9 | D7: ='Income Statement'!D16/'Income Statement'!D9 | E7: ='Income Statement'!E16/'Income Statement'!E9 | F7: ='Income Statement'!F16/'Income Statement'!F9 | G7: ='Income Statement'!G16/'Income Statement'!G9 | H7: ='Income Statement'!H16/'Income Statement'!H9 | I7: ='Income Statement'!I16/'Income Statement'!I9
A8: Net debt / EBITDA | B8: ='Balance Sheet'!B20/'Income Statement'!B16 | C8: ='Balance Sheet'!C20/'Income Statement'!C16 | D8: ='Balance Sheet'!D20/'Income Statement'!D16 | E8: ='Balance Sheet'!E20/'Income Statement'!E16 | F8: ='Balance Sheet'!F20/'Income Statement'!F16 | G8: ='Balance Sheet'!G20/'Income Statement'!G16 | H8: ='Balance Sheet'!H20/'Income Statement'!H16 | I8: ='Balance Sheet'!I20/'Income Statement'!I16
A9: Revenue YoY | C9: ='Income Statement'!C9/'Income Statement'!B9-1 | D9: ='Income Statement'!D9/'Income Statement'!C9-1 | E9: ='Income Statement'!E9/'Income Statement'!D9-1 | F9: ='Income Statement'!F9/'Income Statement'!E9-1 | G9: ='Income Statement'!G9/'Income Statement'!F9-1 | H9: ='Income Statement'!H9/'Income Statement'!G9-1 | I9: ='Income Statement'!I9/'Income Statement'!H9-1

Sheet Peer & Sector
A1: Peer set & sector
A2: No clean comparable — split by part.
A3: Part | B3: Closest peers | C3: Typical valuation
A4: Jio (digital/telecom) | B4: Bharti Airtel; global telcos | C4: EV/EBITDA ~11–17x; growth
A5: Reliance Retail | B5: DMart, Trent, Zomato/Eternal | C5: EV/EBITDA ~25–35x; growth
A6: O2C (refining+petchem) | B6: RIL peers: IOC/BPCL; global refiners | C6: EV/EBITDA ~6–8x; cyclical
A7: Oil & Gas (E&P) | B7: ONGC, Oil India | C7: EV/EBITDA ~4–6x; depleting
A8: New Energy | B8: global solar / green-H2 | C8: strategic / optionality
A10: Analyst context (not model inputs): SOTP targets cluster Rs1,400–1,600; Jio IPO band ~$130–180bn (DRHP 19-Jun-2026).
