Workbook

Sheet READ FIRST
A1: RMDA — Tenth of Ramadan Pharmaceuticals (Rameda) — Valuation Model — READ FIRST
A4: TESTAHIL · Independent Valuation Study · Educational Analysis · EGX: RMDA · edition 13-07-2026 · reporting currency EGP (mn unless stated).
A6: This workbook is the companion model to RMDA_Valuation_Study_13-07-2026. It contains fair-value ranges and probability distributions only — no rating, no price target, no buy/sell/hold language.
A8: HOW TO USE: every hardcoded input lives in BLUE on the Assumptions sheet (and the blue actual-history columns of the statements, each tied to the audited FS). All black cells are formulas; green cells link across sheets. Change a blue cell and the whole model recalculates.
A10: STRUCTURE (canonical): Summary -> Fundamental Valuation (four lenses) -> Assumptions -> Valuation Bridge -> Segments -> Relative & Normalized -> DCF (full FCFF waterfall) -> Income Statement / Balance Sheet / Cash Flow (3 audited + 5 forecast columns) -> Summary Financials -> Monte Carlo -> Sensitivity -> Per-Share & Ratios -> Peer & Sector.
A12: TWO CLOCKS: the fundamental fair-value range is a ~12-month risk-adjusted anchor at the sourced EGP cost of capital; the Monte Carlo T+20/T+60 percentiles are the only genuinely 3-month figures. They are different objects and are never blended.
A14: DUAL FRAMING: net debt is stated both ex-lease (EGP 2,225mn, the ER framing) and including leases (EGP 2,307mn) wherever it appears.
A16: DISCLAIMER (summary; full text in the study): educational only; not investment advice; no licence with the FRA or any regulator; the preparer may hold positions; sources are the company's audited FS and official IR releases, believed reliable but not independently verified; forward-looking inputs are the preparer's judgments; do your own research; you are solely responsible for your decisions.
A18: Legend: BLUE = input you can edit · BLACK = formula · GREEN = link to another sheet · yellow fill = key levers.
A20: Example edit: Assumptions!B17 (FY26E EBITDA margin) — set 0.300 and watch DCF!B36 (fair value per share) move.

Sheet Summary
A1: Summary — the two clocks, side by side
A3: Read | B3: Value | C3: Meaning
A4: Spot (12-Jul-2026) | B4: =Assumptions!$B$4 | C4: EGX close, uploaded OHLC
A5: Fundamental central (weighted, ~12m anchor) | B5: ='Fundamental Valuation'!C8 | C5: At the sourced 22.55% EGP rf; the lens divergence is the finding
A6: Central band (bear–bull) | B6: =TEXT('Fundamental Valuation'!B8,"0.00")&" – "&TEXT('Fundamental Valuation'!D8,"0.00") | C6: Rate-path dependent
A7: DCF (discipline lens) | B7: =DCF!B36 | C7: TV share of EV disclosed on DCF!B30
A8: MC T+60 median (3-month clock) | B8: =Assumptions!$B$36 | C8: Engine output; the only genuinely 3-month figure
A9: MC T+60 5–95% band | B9: 3.95 – 6.84 | C9: 50,000 paths, seed 42
A10: P(T+60 above spot) | B10: 0.61544 | C10: Carry-anchored
A11: Step 0 verdict | B11: PASS | C11: 13 windows, CRPS +0.0273 CI[+0.004,+0.051]

Sheet Fundamental Valuation
A1: Four lenses and the weighted central (EGP/share)
A2: EFG house rule honoured: the DCF-vs-multiple gap is disclosed, not blended away — the divergence is the rate-path bet.
A3: Lens | B3: Bear | C3: Base | D3: Bull | E3: Weight / note
A4: FCFF DCF | B4: 1.1783548 | C4: =DCF!B36 | D4: 2.3103203 | E4: 0.35 — the discipline lens at the sourced 22.55% rf
A5: DDM (policy lens) | B5: 0.77685832 | C5: 1.0043244 | D5: 1.5402464 | E5: 0.15 — payout still ramping; near-noise at a 32% Ke
A6: Relative (own EV/EBITDA band) | B6: ='Relative & Normalized'!B8 | C6: ='Relative & Normalized'!C8 | D6: ='Relative & Normalized'!D8 | E6: 0.25 — what the market pays for this name
A7: Normalized earnings power | B7: ='Relative & Normalized'!B12 | C7: ='Relative & Normalized'!C12 | D7: ='Relative & Normalized'!D12 | E7: 0.25 — FY26E EPS × through-cycle P/E
A8: Weighted central | B8: =0.35*B4+0.15*B5+0.25*B6+0.25*B7 | C8: =0.35*C4+0.15*C5+0.25*C6+0.25*C7 | D8: =0.35*D4+0.15*D5+0.25*D6+0.25*D7
A9: vs spot | B9: =B8/Assumptions!$B$4-1 | C9: =C8/Assumptions!$B$4-1 | D9: =D8/Assumptions!$B$4-1
A11: Two clocks: this central band is the ~12-month risk-adjusted fundamental anchor; the Monte Carlo sheet carries the only genuinely 3-month figures. Full-execution upside (rate normalisation to a ~20% Ke) is a multi-year ceiling, not a near-term forecast.

Sheet Assumptions
A1: Assumptions — the single blue-cell input layer
A2: Every downstream sheet links back here. Sources per input; four-ring Sweep classification in the study §1.6.
A3: Input | B3: Value / FY26E | C3: FY27E | D3: FY28E | E3: FY29E | F3: FY30E | H3: Source / note
A4: Spot (EGP, 12-Jul-2026) | B4: 5 | H4: Uploaded OHLC last close
A5: Shares outstanding (mn) | B5: 2032.8173 | H5: FY25 FS Note 17: 2,000,000,000 post 0.3236 bonus (Nov-25)
A6: Forward tax rate | B6: 0.24 | H6: Normalised ETR (statutory 22.5% + non-deductibles; FY23-25: 22.7/23.6/26.2%)
A7: Risk-free (EGP 10Y) | B7: 0.2255 | H7: investing.com 3-Jul-2026 (<60d cache, CoC Reference)
A8: ERP — CDS basis (primary) | B8: 0.0941 | H8: Damodaran ORIGINAL ctryprem, Egypt row
A9: ERP — rating basis (alt) | B9: 0.1394 | H9: Damodaran ORIGINAL ctryprem, Egypt row
A10: Beta | B10: 1 | H10: House fallback 1.00 — genuine usability-gate failure (no EGX30 daily accessible); aggregators 0.26-0.49 as colour; sensitised 0.8-1.3
A11: Kd pre-tax (facility book) | B11: 0.235 | H11: 100% EGP-denominated (Note 20, 11 banks all EGP); anchored on 1Q26 observed effective 24.0% (132mn/2,204mn avg); no FX debt to blend
A12: Terminal growth (nominal EGP) | B12: 0.05 | H12: Standing Research Protocol (13-Jul-26): center 5% default for a mature EM name post-currency-turbulence; sensitised 3/4/5/6/7% x WACC grid; historical-CAGR/ROIC-RR reconciliation on the Assumptions tab below
A13: Private sales growth | B13: 0.16 | C13: 0.115 | D13: 0.1 | E13: 0.09 | F13: 0.085 | H13: 1Q26 +19%; EDA repricing lagged; taper
A14: Tender sales growth | B14: 0.2 | C14: 0.14 | D14: 0.12 | E14: 0.1 | F14: 0.09 | H14: UPA normalised; selective participation
A15: Export growth | B15: 0.35 | C15: 0.16 | D15: 0.13 | E15: 0.11 | F15: 0.1 | H15: Iraq recovery + Libya/Yemen/Sudan + new markets
A16: Toll manufacturing growth | B16: 0.3 | C16: 0.15 | D16: 0.12 | E16: 0.1 | F16: 0.1 | H16: Pricing + new contracts; capacity monetisation
A17: EBITDA margin | B17: 0.288 | C17: 0.294 | D17: 0.298 | E17: 0.3 | F17: 0.3 | H17: SG&A normalisation to the ~30% aspiration
A18: D&A % of revenue | B18: 0.026 | C18: 0.026 | D18: 0.026 | E18: 0.026 | F18: 0.026 | H18: Incl. FY25 595mn intangible additions amortising over 20y
A19: Capex % of revenue | B19: 0.03 | C19: 0.028 | D19: 0.026 | E19: 0.025 | F19: 0.025 | H19: Maintenance-only; EXCLUDES future portfolio acquisitions
A20: NWC / revenue (crux) | B20: 0.61 | C20: 0.585 | D20: 0.565 | E20: 0.55 | F20: 0.54 | H20: FY25 66.4% gliding to ~54% (1Q26: inventory -19% YTD)
A21: Kd path (interest on opening facilities) | B21: 0.23 | C21: 0.205 | D21: 0.185 | E21: 0.17 | F21: 0.16 | H21: CBE easing passed through with a lag
A22: Cash floor % of revenue | B22: 0.012 | H22: FY23-25 range 0.9-2.3%
A23: Dividend floor FY26 (EGP mn) | B23: 120 | H23: 2x EGP 60mn tranches (1Q26 ER); then max(120, 40% payout)
A24: Payout ratio from FY27E | B24: 0.4 | H24: Management target ~40% (FY25 ER)
A25: Gross margin path FY26E-30E | B25: 49.6% / 50.0% / 50.3% / 50.4% / 50.4% | H25: FY25 48.4% -> 1Q26 49.4%; mix glide, NOT extrapolating the one-off spare-parts base effect (ER26)
A26: FY25 anchors (audited; blue = sourced input) | B26: 4.2% / 4.1% / 4.0% / 4.0% / 4.0% | H26: 1Q26 4.3%; mild scale leverage. S&M is the DERIVED residual (~19.2%% declining), asserted vs 1Q26 18.9%
A27: FY25 revenue (EGP mn) | B27: 4096.0127 | H27: FS Note 23
A28: Private FY25 | B28: 3022.694 | H28: FS Note 4
A29: Tenders FY25 | B29: 544.982 | H29: FS Note 4
A30: Exports FY25 | B30: 243.546 | H30: FS Note 4
A31: Toll FY25 | B31: 284.791 | H31: FS Note 4
A32: Net debt FY25 incl. leases (PRIMARY bridge framing) | B32: 2307.218 | H32: Facilities 2,260.6 + bank credit 0.6 - cash 36.2 + lease liabilities 82.2 (FS Notes 12/20/6B); IFRS-16-consistent: EBITDA excludes rent, FCFF adds back all D&A, so the lease liability is deducted in the bridge
A33: Net debt FY25 ex-lease (published alt framing) | B33: 2225.0018 | H33: Facilities 2,260.6 + bank credit 0.6 - cash 36.2 (FS Notes 12/20); worth EGP +0.04/share vs primary
A34: Non-controlling interest (book) | B34: 42.122663 | H34: FS changes-in-equity
A35: Non-operating: real-estate units | B35: 93.839078 | H35: FS Note 14; one unit sold post-period for 55
A36: MC T+60 median (engine) | B36: 5.204753 | H36: mc_v3 carry-anchored, seed 42 — 3-month clock, never blended with the anchor
A40: Terminal growth -- historical reconciliation (Standing Research Protocol)
A41: Year | B41: Capex | C41: Capex/EBITDA | D41: Character | E41: NOPAT (EGP mn) | F41: Actual NOPAT growth | G41: ROIC | H41: RR | I41: Implied g (ROIC×RR)
A42: FY23 | B42: 253.48933 | C42: 0.47568931 | D42: base (no prior year) | E42: 349.60337
A43: FY24 | B43: 66.635908 | C43: 0.082593252 | D43: stable (self-funded) | E43: 549.75621 | F43: 0.57251404 | G43: 0.17458733 | H43: -0.030552972 | I43: -0.0053341618
...

Sheet Valuation Bridge
A1: EV → equity bridge (closes exactly; ASSERT-enforced in compute)
A2: Dual net-debt framing stated. Signs: net debt and NCI deducted; non-operating assets added.
A3: Bridge item | B3: EGP mn / EGP
A4: Enterprise value (DCF) | B4: =DCF!B29
A5: − Net debt (incl. leases; primary framing) | B5: =-Assumptions!$B$32
A6: − NCI (book) | B6: =-Assumptions!$B$34
A7: + Real-estate units (non-operating) | B7: =Assumptions!$B$35
A8: Equity value | B8: =B4+B5+B6+B7
A9: Per share (EGP) | B9: =B8/Assumptions!$B$5
A10: Memo: net debt incl. leases (alt framing) | B10: =Assumptions!$B$33
A11: Memo: equity under lease-inclusive framing | B11: =B4-B10-Assumptions!$B$34+Assumptions!$B$35
A12: Memo: per share (lease-inclusive) | B12: =B11/Assumptions!$B$5
A14: Leases (EGP 82.2mn) are serviced through rent inside EBITDA, so the primary bridge deducts ex-lease net debt; the lease-inclusive framing is shown per the dual-framing rule.

Sheet Segments
A1: Revenue by channel — audited FY23–FY25, forecast FY26E–FY30E (EGP mn)
A2: History blue (FS Note 4); forecast = prior year × (1 + Assumptions growth).
A3: EGP mn | B3: FY23 | C3: FY24 | D3: FY25 | E3: FY26E | F3: FY27E | G3: FY28E | H3: FY29E | I3: FY30E
A4: Private sales | B4: 1418.63 | C4: 2208.19 | D4: 3022.694 | E4: =D4*(1+Assumptions!B13) | F4: =E4*(1+Assumptions!C13) | G4: =F4*(1+Assumptions!D13) | H4: =G4*(1+Assumptions!E13) | I4: =H4*(1+Assumptions!F13)
A5: Tenders | B5: 189.47 | C5: 236.43 | D5: 544.982 | E5: =D5*(1+Assumptions!B14) | F5: =E5*(1+Assumptions!C14) | G5: =F5*(1+Assumptions!D14) | H5: =G5*(1+Assumptions!E14) | I5: =H5*(1+Assumptions!F14)
A6: Exports | B6: 180.244 | C6: 142.202 | D6: 243.546 | E6: =D6*(1+Assumptions!B15) | F6: =E6*(1+Assumptions!C15) | G6: =F6*(1+Assumptions!D15) | H6: =G6*(1+Assumptions!E15) | I6: =H6*(1+Assumptions!F15)
A7: Toll manufacturing | B7: 134.006 | C7: 181.866 | D7: 284.791 | E7: =D7*(1+Assumptions!B16) | F7: =E7*(1+Assumptions!C16) | G7: =F7*(1+Assumptions!D16) | H7: =G7*(1+Assumptions!E16) | I7: =H7*(1+Assumptions!F16)
A8: Total revenue | B8: =SUM(B4:B7) | C8: =SUM(C4:C7) | D8: =SUM(D4:D7) | E8: =SUM(E4:E7) | F8: =SUM(F4:F7) | G8: =SUM(G4:G7) | H8: =SUM(H4:H7) | I8: =SUM(I4:I7)
A9: Growth YoY | C9: =C8/B8-1 | D9: =D8/C8-1 | E9: =E8/D8-1 | F9: =F8/E8-1 | G9: =G8/F8-1 | H9: =H8/G8-1 | I9: =I8/H8-1
A11: Source: Rameda audited consolidated FS FY24/FY25, segment Note 4; forecast drivers per Assumptions rows 13-16.

Sheet Relative & Normalized
A1: Relative (own 12-month EV/EBITDA band) & normalized earnings power
A2: Same-name benchmark per house rule; band = the multiple range the market itself has paid for RMDA over the last 12 months.
B3: Bear | C3: Base | D3: Bull
A4: EV/EBITDA × on FY26E EBITDA | B4: 6.5 | C4: 8 | D4: 9.5
A5: FY26E EBITDA (link) | B5: ='Income Statement'!E11
A6: Implied EV | B6: =B4*$B$5 | C6: =C4*$B$5 | D6: =D4*$B$5
A7: Equity (− net debt − NCI + non-op) | B7: =B6-Assumptions!$B$32-Assumptions!$B$34+Assumptions!$B$35 | C7: =C6-Assumptions!$B$32-Assumptions!$B$34+Assumptions!$B$35 | D7: =D6-Assumptions!$B$32-Assumptions!$B$34+Assumptions!$B$35
A8: Relative value per share | B8: =B7/Assumptions!$B$5 | C8: =C7/Assumptions!$B$5 | D8: =D7/Assumptions!$B$5
A10: P/E × on FY26E attributable EPS | B10: 11 | C10: 13.5 | D10: 16
A11: FY26E EPS (attributable) | B11: ='Income Statement'!E21/Assumptions!$B$5
A12: Normalized value per share | B12: =B10*$B$11 | C12: =C10*$B$11 | D12: =D10*$B$11
A14: Anchors: spot EV/EBITDA 10.7x FY25 / 8.9x FY26E; trailing P/E 37x reported / 25x recurring. Band deliberately set BELOW today's multiple: it prices the finance-cost normalisation the market already assumes.

Sheet DCF
A1: FCFF DCF — five-year explicit forecast + terminal value
A2: Free cash flow to the firm, five-year explicit forecast. Every input links to the model's Assumptions sheet.
A3: EGP mn | B3: FY26E | C3: FY27E | D3: FY28E | E3: FY29E | F3: FY30E
A4: Revenue | B4: ='Income Statement'!E4 | C4: ='Income Statement'!F4 | D4: ='Income Statement'!G4 | E4: ='Income Statement'!H4 | F4: ='Income Statement'!I4
A5: EBITDA | B5: ='Income Statement'!E11 | C5: ='Income Statement'!F11 | D5: ='Income Statement'!G11 | E5: ='Income Statement'!H11 | F5: ='Income Statement'!I11
A6: D&A | B6: =-'Income Statement'!E10 | C6: =-'Income Statement'!F10 | D6: =-'Income Statement'!G10 | E6: =-'Income Statement'!H10 | F6: =-'Income Statement'!I10
A7: EBIT | B7: =B5+B6 | C7: =C5+C6 | D7: =D5+D6 | E7: =E5+E6 | F7: =F5+F6
A8: NOPAT (EBIT×(1−t)) | B8: =B7*(1-Assumptions!$B$6) | C8: =C7*(1-Assumptions!$B$6) | D8: =D7*(1-Assumptions!$B$6) | E8: =E7*(1-Assumptions!$B$6) | F8: =F7*(1-Assumptions!$B$6)
A9: + D&A | B9: =-B6 | C9: =-C6 | D9: =-D6 | E9: =-E6 | F9: =-F6
A10: − Capex | B10: =-'Income Statement'!E4*Assumptions!B19 | C10: =-'Income Statement'!F4*Assumptions!C19 | D10: =-'Income Statement'!G4*Assumptions!D19 | E10: =-'Income Statement'!H4*Assumptions!E19 | F10: =-'Income Statement'!I4*Assumptions!F19
A11: − Δ working capital | B11: =-('Income Statement'!E4*Assumptions!B20-('Balance Sheet'!$D8+'Balance Sheet'!$D9+'Balance Sheet'!$D11-'Balance Sheet'!$D16)) | C11: =-('Income Statement'!F4*Assumptions!C20-'Income Statement'!E4*Assumptions!B20) | D11: =-('Income Statement'!G4*Assumptions!D20-'Income Statement'!F4*Assumptions!C20) | E11: =-('Income Statement'!H4*Assumptions!E20-'Income Statement'!G4*Assumptions!D20) | F11: =-('Income Statement'!I4*Assumptions!F20-'Income Statement'!H4*Assumptions!E20)
A12: − Employee profit appropriation | B12: -20.985109 | C12: -38.622658 | D12: -53.168996 | E12: -66.649638 | F12: -79.843312
A13: Free cash flow to firm (FCFF) | B13: =B8+B9+B10+B11+B12 | C13: =C8+C9+C10+C11+C12 | D13: =D8+D9+D10+D11+D12 | E13: =E8+E9+E10+E11+E12 | F13: =F8+F9+F10+F11+F12
A14: Forward rate (sliding, Y1→Y5; addendum 13-Jul-26) | B14: 0.26604608 | C14: 0.23832948 | D14: 0.2161562 | E14: 0.19952624 | F14: 0.1884396
A15: Cumulative discount factor | B15: 0.78986067 | C15: 0.63784371 | D15: 0.52447516 | E15: 0.43723525 | F15: 0.367907
A16: PV of FCFF | B16: =B13*B15 | C16: =C13*C15 | D16: =D13*D15 | E16: =E13*E15 | F16: =F13*F15
A18: WACC build (SLIDING schedule: explicit-window -> terminal; Ke/Kd/WACC addendum 13-Jul-26; see Assumptions rows below TG-reconciliation for the sourced inputs)
A19: Ke, explicit window (net-CDS, primary) | B19: 0.2855 | C19: Ke, terminal (norm-built) | D19: 0.205
A20: Kd after-tax, explicit | B20: 0.1786 | C20: Kd after-tax, terminal | D20: 0.114
A21: We (mkt cap / (mkt cap + gross facilities)) | B21: 0.81801755
A22: WACC, explicit window (Y1 forward rate) | B22: 0.26604608 | C22: WACC, terminal (Y5+ forward rate) | D22: 0.1884396
A23: Retired-primary WACC (un-netted rf; flat; disclosed for audit trail) | B23: 0.29394048
A24: Row 14 is the per-year forward rate, sliding linearly from row 22's explicit-window value (Y1) to its terminal value (Y5) -- see docx §1.8 for the year-by-year table. Values sourced from compute.py's study_numbers_rmda.json (same pipeline as the DCF waterfall above).
A26: Terminal value = FCFF₅×(1+g)/(WACC_term−g) | B26: =F13*(1+Assumptions!$B$12)/(D22-Assumptions!$B$12)
A27: PV of terminal value | B27: =B26*F15
A28: PV of explicit FCFF (Σ) | B28: =SUM(B16:F16)
A29: Enterprise value | B29: =B27+B28
A30: Terminal value as % of EV (disclosed) | B30: =B27/B29
A31: − Net debt (incl. leases; primary IFRS-16 framing) | B31: =-Assumptions!$B$32
A32: − Non-controlling interest | B32: =-Assumptions!$B$34
A33: + Non-operating real-estate units | B33: =Assumptions!$B$35
A34: Equity value | B34: =B29+B31+B32+B33
A35: ÷ Shares (mn) | B35: =Assumptions!$B$5
A36: DCF fair value per share (EGP) | B36: =B34/B35
A37: vs spot | B37: =B36/Assumptions!$B$4-1
A39: Caption: Free cash flow to the firm, five-year explicit forecast, discounted on the SLIDING forward-rate schedule (explicit-window -> terminal norm-built rate; Ke/Kd/WACC addendum 13-Jul-2026). Every input links to the model's Assumptions sheet. Capex, ΔWC and the employee appropriation shown in parentheses (negative).

Sheet Income Statement
A1: Income statement — 3 audited + 5 forecast (EGP mn)
A2: Actuals blue, tied to audited FS notes; forecast black formulas. EBITDA = EBIT + D&A (company-adjusted 1,166 FY25 reconciles via provisions/UHT).
A3: EGP mn | B3: FY23 | C3: FY24 | D3: FY25 | E3: FY26E | F3: FY27E | G3: FY28E | H3: FY29E | I3: FY30E
A4: Revenue | B4: 1922.3507 | C4: 2768.6884 | D4: 4096.0127 | E4: =Segments!E8 | F4: =Segments!F8 | G4: =Segments!G8 | H4: =Segments!H8 | I4: =Segments!I8
A5: Cost of revenues | B5: 1016.4356 | C5: 1485.0244 | D5: 2114.4696 | E5: -2449.0967 | F5: -2731.1217 | G5: -3003.5377 | H5: -3278.0509 | I5: -3566.4249
A6: Gross profit | B6: =B4-B5 | C6: =C4-C5 | D6: =D4-D5 | E6: =E4+E5 | F6: =F4+F5 | G6: =G4+G5 | H6: =H4+H5 | I6: =I4+I5
A7: Selling & marketing | B7: 363.5805 | C7: 447.8768 | D7: 759.88459 | E7: -932.98922 | F7: -1043.2885 | G7: -1154.2771 | H7: -1255.705 | I7: -1366.1708
A8: General & administrative | B8: 82.330195 | C8: 112.42378 | D8: 149.99348 | E8: -204.09139 | F8: -223.95198 | G8: -241.73342 | H8: -264.35895 | I8: -287.61491
A9: EBIT (GP − S&M − G&A) | B9: =B6-B7-B8 | C9: =C6-C7-C8 | D9: =D6-D7-D8 | E9: =E11-E10 | F9: =F11-F10 | G9: =G11-G10 | H9: =H11-H10 | I9: =I11-I10
A10: D&A (total, CF basis) | B10: 72.883988 | C10: 83.432594 | D10: 92.226837 | E10: =E4*Assumptions!B18 | F10: =F4*Assumptions!C18 | G10: =G4*Assumptions!D18 | H10: =H4*Assumptions!E18 | I10: =I4*Assumptions!F18
A11: EBITDA (EBIT + D&A) | B11: =B9+B10 | C11: =C9+C10 | D11: =D9+D10 | E11: =E4*Assumptions!B17 | F11: =F4*Assumptions!C17 | G11: =G4*Assumptions!D17 | H11: =H4*Assumptions!E17 | I11: =I4*Assumptions!F17
A12: Other income | B12: 7.476152 | C12: 27.305011 | D12: 9.131977 | E12: 0 | F12: 0 | G12: 0 | H12: 0 | I12: 0
A13: Impairment of trade & notes receivable | B13: 3.808579 | C13: 11.442943 | D13: 104.79868 | E13: 0 | F13: 0 | G13: 0 | H13: 0 | I13: 0
A14: FX gain/(loss) | B14: 0.4241 | C14: 34.47665 | D14: -24.824553 | E14: 0 | F14: 0 | G14: 0 | H14: 0 | I14: 0
A15: Other charges (UHT & sundry, derived residual) | B15: -5.291891 | C15: -2.493715 | D15: -7.912984 | E15: 0 | F15: 0 | G15: 0 | H15: 0 | I15: 0
A16: Finance income | B16: 62.902521 | C16: 65.852148 | D16: 18.805832 | E16: ='Balance Sheet'!D12*0.15 | F16: ='Balance Sheet'!E12*0.15 | G16: ='Balance Sheet'!F12*0.15 | H16: ='Balance Sheet'!G12*0.15 | I16: ='Balance Sheet'!H12*0.15
A17: Finance expense | B17: 194.25931 | C17: 310.94187 | D17: 537.96708 | E17: ='Balance Sheet'!D14*Assumptions!B21 | F17: ='Balance Sheet'!E14*Assumptions!C21 | G17: ='Balance Sheet'!F14*Assumptions!D21 | H17: ='Balance Sheet'!G14*Assumptions!E21 | I17: ='Balance Sheet'!H14*Assumptions!F21
A18: Profit before tax | B18: =B9+B12-B13+B14+B15+B16-B17 | C18: =C9+C12-C13+C14+C15+C16-C17 | D18: =D9+D12-D13+D14+D15+D16-D17 | E18: =E9+E16-E17 | F18: =F9+F16-F17 | G18: =G9+G16-G17 | H18: =H9+H16-H17 | I18: =I9+I16-I17
A19: Income tax | B19: -74.241526 | C19: -124.31159 | D19: -110.88902 | E19: =-E18*Assumptions!$B$6 | F19: =-F18*Assumptions!$B$6 | G19: =-G18*Assumptions!$B$6 | H19: =-H18*Assumptions!$B$6 | I19: =-I18*Assumptions!$B$6
A20: Net income | B20: =B18+B19 | C20: =C18+C19 | D20: =D18+D19 | E20: =E18+E19 | F20: =F18+F19 | G20: =G18+G19 | H20: =H18+H19 | I20: =I18+I19
A21: attributable to parent | B21: 244.85945 | C21: 387.36687 | D21: 298.4647 | E21: =E20*0.953 | F21: =F20*0.953 | G21: =G20*0.953 | H21: =H20*0.953 | I21: =I20*0.953
A22: Dividends declared (EGP mn) | B22: 16.7625 | C22: 121.275 | D22: 188.9125 | E22: =Assumptions!$B$23 | F22: =MAX(Assumptions!$B$23,Assumptions!$B$24*F20) | G22: =MAX(Assumptions!$B$23,Assumptions!$B$24*G20) | H22: =MAX(Assumptions!$B$23,Assumptions!$B$24*H20) | I22: =MAX(Assumptions!$B$23,Assumptions!$B$24*I20)
A23: Memo: employees’ profit appropriation (cash, paid from prior-year NI; charged in FCFF) | E23: -20.985109 | F23: -38.622658 | G23: -53.168996 | H23: -66.649638 | I23: -79.843312
A24: Memo: share-based payment expense inside opex (non-cash; ESOP vesting) | E24: -64 | F24: -48 | G24: -24 | H24: 0 | I24: 0
A26: Sources: audited FS FY24/FY25 (Notes 23-30, CF statement); NCI share 4.7% of NI (FY25). FY25 one-off: EGP 99.4mn UCP/MEC receivable fully provisioned. Forecast cost lines: GM & G&A sourced drivers, S&M the derived residual (asserted 19.2% declining vs 1Q26 18.9%); appropriation = 6.7% of prior-year NI (EGM 20-May-26: EGP 21mn from FY25 profit).

Sheet Balance Sheet
A1: Balance sheet — 3 audited + 5 forecast (EGP mn)
A2: Actuals blue (FS notes); income-tax payable is the derived balancing line (documented); forecast facilities are the plug.
A3: EGP mn | B3: FY23 | C3: FY24 | D3: FY25 | E3: FY26E | F3: FY27E | G3: FY28E | H3: FY29E | I3: FY30E
A4: Fixed assets (incl. AUC) | B4: 593.65777 | C4: 613.15815 | D4: 719.99298 | E4: =D4+'Income Statement'!E4*Assumptions!B19-0.55*'Income Statement'!E10 | F4: =E4+'Income Statement'!F4*Assumptions!C19-0.55*'Income Statement'!F10 | G4: =F4+'Income Statement'!G4*Assumptions!D19-0.55*'Income Statement'!G10 | H4: =G4+'Income Statement'!H4*Assumptions!E19-0.55*'Income Statement'!H10 | I4: =H4+'Income Statement'!I4*Assumptions!F19-0.55*'Income Statement'!I10
A5: Right-of-use assets | B5: 12.391296 | C5: 8.357448 | D5: 72.155756 | E5: =$D5 | F5: =$D5 | G5: =$D5 | H5: =$D5 | I5: =$D5
A6: Intangible assets | B6: 589.27153 | C6: 552.78501 | D6: 1110.7974 | E6: =D6-0.45*'Income Statement'!E10 | F6: =E6-0.45*'Income Statement'!F10 | G6: =F6-0.45*'Income Statement'!G10 | H6: =G6-0.45*'Income Statement'!H10 | I6: =H6-0.45*'Income Statement'!I10
A7: Other assets (real-estate units) | B7: 0 | C7: 93.839078 | D7: 93.839078 | E7: =$D7 | F7: =$D7 | G7: =$D7 | H7: =$D7 | I7: =$D7
A8: Inventories (net) | B8: 303.2605 | C8: 751.33779 | D8: 1031.4651 | E8: ='Income Statement'!E4*(Assumptions!B20+$D16/'Income Statement'!$D4)*$D8/($D8+$D9+$D11) | F8: ='Income Statement'!F4*(Assumptions!C20+$D16/'Income Statement'!$D4)*$D8/($D8+$D9+$D11) | G8: ='Income Statement'!G4*(Assumptions!D20+$D16/'Income Statement'!$D4)*$D8/($D8+$D9+$D11) | H8: ='Income Statement'!H4*(Assumptions!E20+$D16/'Income Statement'!$D4)*$D8/($D8+$D9+$D11) | I8: ='Income Statement'!I4*(Assumptions!F20+$D16/'Income Statement'!$D4)*$D8/($D8+$D9+$D11)
A9: Trade & notes receivables (net) | B9: 1271.7423 | C9: 1478.9144 | D9: 2115.2899 | E9: ='Income Statement'!E4*(Assumptions!B20+$D16/'Income Statement'!$D4)*$D9/($D8+$D9+$D11) | F9: ='Income Statement'!F4*(Assumptions!C20+$D16/'Income Statement'!$D4)*$D9/($D8+$D9+$D11) | G9: ='Income Statement'!G4*(Assumptions!D20+$D16/'Income Statement'!$D4)*$D9/($D8+$D9+$D11) | H9: ='Income Statement'!H4*(Assumptions!E20+$D16/'Income Statement'!$D4)*$D9/($D8+$D9+$D11) | I9: ='Income Statement'!I4*(Assumptions!F20+$D16/'Income Statement'!$D4)*$D9/($D8+$D9+$D11)
A10: Treasury bills | B10: 260.89542 | C10: 189.7037 | D10: 0 | E10: 0 | F10: 0 | G10: 0 | H10: 0 | I10: 0
A11: Prepayments & other receivables | B11: 134.66945 | C11: 558.50657 | D11: 157.78315 | E11: ='Income Statement'!E4*(Assumptions!B20+$D16/'Income Statement'!$D4)*$D11/($D8+$D9+$D11) | F11: ='Income Statement'!F4*(Assumptions!C20+$D16/'Income Statement'!$D4)*$D11/($D8+$D9+$D11) | G11: ='Income Statement'!G4*(Assumptions!D20+$D16/'Income Statement'!$D4)*$D11/($D8+$D9+$D11) | H11: ='Income Statement'!H4*(Assumptions!E20+$D16/'Income Statement'!$D4)*$D11/($D8+$D9+$D11) | I11: ='Income Statement'!I4*(Assumptions!F20+$D16/'Income Statement'!$D4)*$D11/($D8+$D9+$D11)
A12: Cash & banks | B12: 52.358275 | C12: 64.688059 | D12: 36.178688 | E12: ='Income Statement'!E4*Assumptions!$B$22 | F12: ='Income Statement'!F4*Assumptions!$B$22 | G12: ='Income Statement'!G4*Assumptions!$B$22 | H12: ='Income Statement'!H4*Assumptions!$B$22 | I12: ='Income Statement'!I4*Assumptions!$B$22
A13: TOTAL ASSETS | B13: =SUM(B4:B12) | C13: =SUM(C4:C12) | D13: =SUM(D4:D12) | E13: =SUM(E4:E12) | F13: =SUM(F4:F12) | G13: =SUM(G4:G12) | H13: =SUM(H4:H12) | I13: =SUM(I4:I12)
A14: Credit facilities + bank credit | B14: 1060.2213 | C14: 1507.4604 | D14: 2261.1805 | E14: =E13-E20-E16-E15-E17-E18-E19 | F14: =F13-F20-F16-F15-F17-F18-F19 | G14: =G13-G20-G16-G15-G17-G18-G19 | H14: =H13-H20-H16-H15-H17-H18-H19 | I14: =I13-I20-I16-I15-I17-I18-I19
A15: Lease liabilities | B15: 16.507052 | C15: 11.674259 | D15: 82.216128 | E15: =$D15 | F15: =$D15 | G15: =$D15 | H15: =$D15 | I15: =$D15
A16: Trade, notes & other payables | B16: 232.18469 | C16: 527.24973 | D16: 584.1128 | E16: ='Income Statement'!E4*$D16/'Income Statement'!$D4 | F16: ='Income Statement'!F4*$D16/'Income Statement'!$D4 | G16: ='Income Statement'!G4*$D16/'Income Statement'!$D4 | H16: ='Income Statement'!H4*$D16/'Income Statement'!$D4 | I16: ='Income Statement'!I4*$D16/'Income Statement'!$D4
A17: Provisions | B17: 15.034468 | C17: 17.220844 | D17: 14.970947 | E17: =$D17 | F17: =$D17 | G17: =$D17 | H17: =$D17 | I17: =$D17
A18: Deferred tax liability (net) | B18: 58.234398 | C18: 77.282486 | D18: 68.571527 | E18: =$D18 | F18: =$D18 | G18: =$D18 | H18: =$D18 | I18: =$D18
A19: Income tax payable (derived) | B19: 60.565331 | C19: 98.758184 | D19: 116.54984 | E19: =$D19 | F19: =$D19 | G19: =$D19 | H19: =$D19 | I19: =$D19
A20: TOTAL EQUITY | B20: 1775.4993 | C20: 2071.6444 | D20: 2209.9003 | E20: =D20+'Income Statement'!E20-'Income Statement'!E22 | F20: =E20+'Income Statement'!F20-'Income Statement'!F22 | G20: =F20+'Income Statement'!G20-'Income Statement'!G22 | H20: =G20+'Income Statement'!H20-'Income Statement'!H22 | I20: =H20+'Income Statement'!I20-'Income Statement'!I22
A21: of which NCI | B21: 12.936522 | C21: 27.376784 | D21: 42.122663 | E21: =$D21 | F21: =$D21 | G21: =$D21 | H21: =$D21 | I21: =$D21
A22: Check: assets − liabilities − equity | B22: =B13-SUM(B14:B19)-B20 | C22: =C13-SUM(C14:C19)-C20 | D22: =D13-SUM(D14:D19)-D20 | E22: =E13-SUM(E14:E19)-E20 | F22: =F13-SUM(F14:F19)-F20 | G22: =G13-SUM(G14:G19)-G20 | H22: =H13-SUM(H14:H19)-H20 | I22: =I13-SUM(I14:I19)-I20
A24: Net debt ex-lease (facilities − cash) | B24: =B14-B12 | C24: =C14-C12 | D24: =D14-D12 | E24: =E14-E12 | F24: =F14-F12 | G24: =G14-G12 | H24: =H14-H12 | I24: =I14-I12
A25: Net debt incl. leases (dual framing) | B25: =B24+B15 | C25: =C24+C15 | D25: =D24+D15 | E25: =E24+E15 | F25: =F24+F15 | G25: =G24+G15 | H25: =H24+H15 | I25: =I24+I15
A27: Sources: audited FS FY24/FY25 (Notes 5-20); FY23 comparatives from FY24 FS. Forecast facilities = balancing plug (yellow).

Sheet Cash Flow
A1: Cash flow — audited FY23–FY25 and derived forecast (EGP mn)
A2: History blue from the audited indirect-method CF; forecast derived from the integrated statements.
A3: EGP mn | B3: FY23 | C3: FY24 | D3: FY25 | E3: FY26E | F3: FY27E | G3: FY28E | H3: FY29E | I3: FY30E
A4: Net operating cash flow (after interest & tax) | B4: -44.495469 | C4: -306.91963 | D4: -43.671581
A5: D&A add-back | B5: 72.883988 | C5: 83.432594 | D5: 92.226837
A6: Interest paid | B6: -186.52067 | C6: -294.65662 | D6: -526.80197
A7: Income taxes paid | B7: -60.685858 | C7: -67.070648 | D7: -101.80833
A8: Capex — tangible (FA + AUC) | B8: -91.045241 | C8: -64.929908 | D8: -155.8963
A9: Capex — intangible (product acquisitions) | B9: -162.44409 | C9: -1.706 | D9: -594.95016
A10: Dividends paid | B10: -16.7625 | C10: -121.275 | D10: -188.9125
A11: Forecast free cash flow build (links to DCF sheet)
A12: NOPAT | E12: =DCF!B8 | F12: =DCF!C8 | G12: =DCF!D8 | H12: =DCF!E8 | I12: =DCF!F8
A13: + D&A | E13: =DCF!B9 | F13: =DCF!C9 | G13: =DCF!D9 | H13: =DCF!E9 | I13: =DCF!F9
A14: − Capex | E14: =DCF!B10 | F14: =DCF!C10 | G14: =DCF!D10 | H14: =DCF!E10 | I14: =DCF!F10
A15: − Δ working capital | E15: =DCF!B11 | F15: =DCF!C11 | G15: =DCF!D11 | H15: =DCF!E11 | I15: =DCF!F11
A16: FCFF (after employee appropriation, per DCF!12) | E16: =SUM(E12:E15)+DCF!B12 | F16: =SUM(F12:F15)+DCF!C12 | G16: =SUM(G12:G15)+DCF!D12 | H16: =SUM(H12:H15)+DCF!E12 | I16: =SUM(I12:I15)+DCF!F12
A17: − Interest ×(1−t) | E17: =-'Income Statement'!E17*(1-Assumptions!$B$6) | F17: =-'Income Statement'!F17*(1-Assumptions!$B$6) | G17: =-'Income Statement'!G17*(1-Assumptions!$B$6) | H17: =-'Income Statement'!H17*(1-Assumptions!$B$6) | I17: =-'Income Statement'!I17*(1-Assumptions!$B$6)
A18: − Dividends | E18: =-'Income Statement'!E22 | F18: =-'Income Statement'!F22 | G18: =-'Income Statement'!G22 | H18: =-'Income Statement'!H22 | I18: =-'Income Statement'!I22
A19: Δ Net debt (implied) | E19: =-(E16+E17+E18)+('Balance Sheet'!E12-'Balance Sheet'!D12) | F19: =-(F16+F17+F18)+('Balance Sheet'!F12-'Balance Sheet'!E12) | G19: =-(G16+G17+G18)+('Balance Sheet'!G12-'Balance Sheet'!F12) | H19: =-(H16+H17+H18)+('Balance Sheet'!H12-'Balance Sheet'!G12) | I19: =-(I16+I17+I18)+('Balance Sheet'!I12-'Balance Sheet'!H12)
A21: FY25 note: net operating CF was −44mn AFTER EGP 527mn interest and 102mn tax paid; the EGP 595mn intangible line is the 2025 product-portfolio acquisitions.

Sheet Summary Financials
A1: Summary financials (EGP mn) — links only
A3: EGP mn | B3: FY23 | C3: FY24 | D3: FY25 | E3: FY26E | F3: FY27E | G3: FY28E | H3: FY29E | I3: FY30E
A4: Revenue | B4: ='Income Statement'!B4 | C4: ='Income Statement'!C4 | D4: ='Income Statement'!D4 | E4: ='Income Statement'!E4 | F4: ='Income Statement'!F4 | G4: ='Income Statement'!G4 | H4: ='Income Statement'!H4 | I4: ='Income Statement'!I4
A5: EBITDA | B5: ='Income Statement'!B11 | C5: ='Income Statement'!C11 | D5: ='Income Statement'!D11 | E5: ='Income Statement'!E11 | F5: ='Income Statement'!F11 | G5: ='Income Statement'!G11 | H5: ='Income Statement'!H11 | I5: ='Income Statement'!I11
A6: EBIT | B6: ='Income Statement'!B9 | C6: ='Income Statement'!C9 | D6: ='Income Statement'!D9 | E6: ='Income Statement'!E9 | F6: ='Income Statement'!F9 | G6: ='Income Statement'!G9 | H6: ='Income Statement'!H9 | I6: ='Income Statement'!I9
A7: Net income | B7: ='Income Statement'!B20 | C7: ='Income Statement'!C20 | D7: ='Income Statement'!D20 | E7: ='Income Statement'!E20 | F7: ='Income Statement'!F20 | G7: ='Income Statement'!G20 | H7: ='Income Statement'!H20 | I7: ='Income Statement'!I20
A8: Total assets | B8: ='Balance Sheet'!B13 | C8: ='Balance Sheet'!C13 | D8: ='Balance Sheet'!D13 | E8: ='Balance Sheet'!E13 | F8: ='Balance Sheet'!F13 | G8: ='Balance Sheet'!G13 | H8: ='Balance Sheet'!H13 | I8: ='Balance Sheet'!I13
A9: Total equity | B9: ='Balance Sheet'!B20 | C9: ='Balance Sheet'!C20 | D9: ='Balance Sheet'!D20 | E9: ='Balance Sheet'!E20 | F9: ='Balance Sheet'!F20 | G9: ='Balance Sheet'!G20 | H9: ='Balance Sheet'!H20 | I9: ='Balance Sheet'!I20
A10: Net debt (ex-lease) | B10: ='Balance Sheet'!B24 | C10: ='Balance Sheet'!C24 | D10: ='Balance Sheet'!D24 | E10: ='Balance Sheet'!E24 | F10: ='Balance Sheet'!F24 | G10: ='Balance Sheet'!G24 | H10: ='Balance Sheet'!H24 | I10: ='Balance Sheet'!I24

Sheet Monte Carlo
A1: Carry-anchored MC engine outputs (mc_v3, 50,000 paths, seed 42, t(ν=4), width_cal 0.909)
A2: Engine values, not spreadsheet formulas — reproduced bit-for-bit by the calibration pipeline. Live EG profile is carry-only.
A3: Percentile | B3: p5 | C3: p10 | D3: p25 | E3: p50 | F3: p75 | G3: p90 | H3: p95
A4: T+20 (EGP) | B4: 4.3205817 | C4: 4.5201457 | D4: 4.7967117 | E4: 5.0673632 | F4: 5.3564774 | G4: 5.6882924 | H4: 5.9508153
A5: T+60 (EGP) | B5: 3.9516957 | C5: 4.2732752 | D5: 4.7307903 | E5: 5.204753 | F5: 5.7280246 | G5: 6.3448012 | H5: 6.8401956
A7: Probability read | D7: Touch ladder (prob. of touching level any time)
A8: P(T+60 above spot) | B8: 0.61544 | D8: Level | E8: T+20 | F8: T+60
A9: P(≥ +10%) | B9: 0.34464 | D9: 6.5 | E9: 0.02266 | F9: 0.13124
A10: P(≤ −10%) | B10: 0.16218 | D10: 6 | E10: 0.06852 | F10: 0.27034
A11: Up/down 10% odds | B11: 2.1250462 | D11: 5.75 | E11: 0.12956 | F11: 0.39022
A12: Median T+60 | B12: 5.204753 | D12: 5.5 | E12: 0.26228 | F12: 0.55332
A13: Median move | B13: 0.040950594 | D13: 5.25 | E13: 0.52804 | F13: 0.7539
A14: Touch ≥ +10% anytime | B14: 0.55332 | D14: 4.75 | E14: 0.40114 | F14: 0.5735
A15: Touch ≤ −10% anytime | B15: 0.33736 | D15: 4.5 | E15: 0.1632 | F15: 0.33736
D16: 4.25 | E16: 0.0658 | F16: 0.19366
D17: 4 | E17: 0.02888 | F17: 0.1093
A19: Probability zones (T+60)
A20: < 4.00 | B20: 0.05528 | D20: Step 0 calibration (this name, live EG fit)
A21: 4.00–4.60 | B21: 0.14118 | D21: Windows (5yr, h=60, non-overlap) | F21: 13
A22: 4.60–5.20 | B22: 0.3008 | D22: CRPS skill vs carry-anchored RW | F22: 0.027349437
A23: 5.20–5.80 | B23: 0.27728 | D23: 90% CI low | F23: 0.0042053755
A24: 5.80–6.40 | B24: 0.13394 | D24: 90% CI high | F24: 0.0508281
A25: > 6.40 | B25: 0.09152 | D25: Verdict | F25: PASS
D26: Coverage 50/80/90 | F26: 0.54 / 0.85 / 0.85
D27: PIT mean | F27: 0.61186154
A29: Cleaning log: dropped 10 leading pre-listing placeholder rows (flat price, no volume) before 2019-12-11 · density 242.1 rows/yr vs EGX ~247 · post-clean max |log move| 0.187

Sheet Sensitivity
A1: Sensitivities (engine-computed grids; base cell matches DCF!B36)
A2: Explicit-window × terminal-anchor WACC; EBITDA margin × NWC glide; beta grid per the EFG 0.8–1.3 rule.
A3: WACC \ terminal g | B3: 3.0% | C3: 4.0% | D3: 5.0% | E3: 6.0% | F3: 7.0%
A4: 22.6% | B4: 2.4297077 | C4: 2.6546611 | D4: 2.9253183 | E4: 3.2571828 | F4: 3.6736638
A5: 24.6% | B5: 1.8984584 | C5: 2.0504615 | D5: 2.2281322 | E5: 2.4385714 | F5: 2.6917657
A6: 26.6% | B6: 1.5023105 | C6: 1.6099341 | D6: 1.7331058 | E6: 1.8754573 | F6: 2.0418465
A7: 28.6% | B7: 1.1957705 | C7: 1.274721 | D7: 1.3636376 | E7: 1.4645343 | F7: 1.5800073
A8: 30.6% | B8: 0.951691 | C8: 1.0112442 | D8: 1.0774722 | E8: 1.151564 | F8: 1.2350084
A10: EBITDA-margin shift \ NWC-ratio shift
A11: pp shift | B11: -4pp | C11: -2pp | D11: +0pp | E11: +2pp | F11: +4pp
A12: -1.0pp | B12: 1.7282614 | C12: 1.6632179 | D12: 1.5981743 | E12: 1.5331308 | F12: 1.4680873
A13: -0.5pp | B13: 1.7957271 | C13: 1.7306836 | D13: 1.6656401 | E13: 1.6005966 | F13: 1.535553
A14: +0.0pp | B14: 1.8631929 | C14: 1.7981494 | D14: 1.7331058 | E14: 1.6680623 | F14: 1.6030188
A15: +0.5pp | B15: 1.9306586 | C15: 1.8656151 | D15: 1.8005716 | E15: 1.735528 | F15: 1.6704845
A16: +1.0pp | B16: 1.9981244 | C16: 1.9330808 | D16: 1.8680373 | E16: 1.8029938 | F16: 1.7379502
A18: Beta grid (Ke = rf + β×ERP_CDS)
A19: β | B19: Ke
A20: 0.8 | B20: 0.26668 | D20: The crux in real units (FY26E)
A21: 0.9 | B21: 0.27609 | D21: Scenario | E21: Kd | F21: Net debt | G21: Interest | H21: NI (EGP mn) | I21: EPS
A22: 1 | B22: 0.2855 | D22: CBE holds (19.50%), slow WC fix | E22: 0.24 | F22: 2111 | G22: 506.64 | H22: 586.66554 | I22: 0.28859727
A23: 1.1 | B23: 0.29491 | D23: Base: staged cuts, WC glide | E23: 0.205 | F23: 1750 | G23: 358.75 | H23: 699.06194 | I23: 0.34388822
A24: 1.2 | B24: 0.30432 | D24: Fast easing + WC normalised | E24: 0.17 | F24: 1400 | G24: 238 | H24: 790.83194 | I24: 0.38903246
A25: 1.3 | B25: 0.31373
D26: Every 100bp on the 1Q26 net debt (EGP 2,111mn) ≈ EGP 21mn pre-tax.

Sheet Per-Share & Ratios
A1: Per-share figures and ratios (formulas off the statements)
B3: FY23 | C3: FY24 | D3: FY25 | E3: FY26E | F3: FY27E | G3: FY28E | H3: FY29E | I3: FY30E
A4: EPS (attributable, EGP) | B4: ='Income Statement'!B21/Assumptions!$B$5 | C4: ='Income Statement'!C21/Assumptions!$B$5 | D4: ='Income Statement'!D21/Assumptions!$B$5 | E4: ='Income Statement'!E21/Assumptions!$B$5 | F4: ='Income Statement'!F21/Assumptions!$B$5 | G4: ='Income Statement'!G21/Assumptions!$B$5 | H4: ='Income Statement'!H21/Assumptions!$B$5 | I4: ='Income Statement'!I21/Assumptions!$B$5
A5: DPS (EGP) | B5: ='Income Statement'!B22/Assumptions!$B$5 | C5: ='Income Statement'!C22/Assumptions!$B$5 | D5: ='Income Statement'!D22/Assumptions!$B$5 | E5: ='Income Statement'!E22/Assumptions!$B$5 | F5: ='Income Statement'!F22/Assumptions!$B$5 | G5: ='Income Statement'!G22/Assumptions!$B$5 | H5: ='Income Statement'!H22/Assumptions!$B$5 | I5: ='Income Statement'!I22/Assumptions!$B$5
A6: EBITDA margin | B6: ='Income Statement'!B11/'Income Statement'!B4 | C6: ='Income Statement'!C11/'Income Statement'!C4 | D6: ='Income Statement'!D11/'Income Statement'!D4 | E6: ='Income Statement'!E11/'Income Statement'!E4 | F6: ='Income Statement'!F11/'Income Statement'!F4 | G6: ='Income Statement'!G11/'Income Statement'!G4 | H6: ='Income Statement'!H11/'Income Statement'!H4 | I6: ='Income Statement'!I11/'Income Statement'!I4
A7: Net margin | B7: ='Income Statement'!B20/'Income Statement'!B4 | C7: ='Income Statement'!C20/'Income Statement'!C4 | D7: ='Income Statement'!D20/'Income Statement'!D4 | E7: ='Income Statement'!E20/'Income Statement'!E4 | F7: ='Income Statement'!F20/'Income Statement'!F4 | G7: ='Income Statement'!G20/'Income Statement'!G4 | H7: ='Income Statement'!H20/'Income Statement'!H4 | I7: ='Income Statement'!I20/'Income Statement'!I4
A8: Net debt / EBITDA (ex-lease) | B8: ='Balance Sheet'!B24/'Income Statement'!B11 | C8: ='Balance Sheet'!C24/'Income Statement'!C11 | D8: ='Balance Sheet'!D24/'Income Statement'!D11 | E8: ='Balance Sheet'!E24/'Income Statement'!E11 | F8: ='Balance Sheet'!F24/'Income Statement'!F11 | G8: ='Balance Sheet'!G24/'Income Statement'!G11 | H8: ='Balance Sheet'!H24/'Income Statement'!H11 | I8: ='Balance Sheet'!I24/'Income Statement'!I11
A9: ROE (NI / avg equity) | B9: — | C9: ='Income Statement'!C20/(('Balance Sheet'!C20+'Balance Sheet'!B20)/2) | D9: ='Income Statement'!D20/(('Balance Sheet'!D20+'Balance Sheet'!C20)/2) | E9: ='Income Statement'!E20/(('Balance Sheet'!E20+'Balance Sheet'!D20)/2) | F9: ='Income Statement'!F20/(('Balance Sheet'!F20+'Balance Sheet'!E20)/2) | G9: ='Income Statement'!G20/(('Balance Sheet'!G20+'Balance Sheet'!F20)/2) | H9: ='Income Statement'!H20/(('Balance Sheet'!H20+'Balance Sheet'!G20)/2) | I9: ='Income Statement'!I20/(('Balance Sheet'!I20+'Balance Sheet'!H20)/2)
A10: P/E at spot | B10: =Assumptions!$B$4/('Income Statement'!B21/Assumptions!$B$5) | C10: =Assumptions!$B$4/('Income Statement'!C21/Assumptions!$B$5) | D10: =Assumptions!$B$4/('Income Statement'!D21/Assumptions!$B$5) | E10: =Assumptions!$B$4/('Income Statement'!E21/Assumptions!$B$5) | F10: =Assumptions!$B$4/('Income Statement'!F21/Assumptions!$B$5) | G10: =Assumptions!$B$4/('Income Statement'!G21/Assumptions!$B$5) | H10: =Assumptions!$B$4/('Income Statement'!H21/Assumptions!$B$5) | I10: =Assumptions!$B$4/('Income Statement'!I21/Assumptions!$B$5)
A11: EV/EBITDA at spot | B11: =(Assumptions!$B$4*Assumptions!$B$5+'Balance Sheet'!B24+Assumptions!$B$34-Assumptions!$B$35)/'Income Statement'!B11 | C11: =(Assumptions!$B$4*Assumptions!$B$5+'Balance Sheet'!C24+Assumptions!$B$34-Assumptions!$B$35)/'Income Statement'!C11 | D11: =(Assumptions!$B$4*Assumptions!$B$5+'Balance Sheet'!D24+Assumptions!$B$34-Assumptions!$B$35)/'Income Statement'!D11 | E11: =(Assumptions!$B$4*Assumptions!$B$5+'Balance Sheet'!E24+Assumptions!$B$34-Assumptions!$B$35)/'Income Statement'!E11 | F11: =(Assumptions!$B$4*Assumptions!$B$5+'Balance Sheet'!F24+Assumptions!$B$34-Assumptions!$B$35)/'Income Statement'!F11 | G11: =(Assumptions!$B$4*Assumptions!$B$5+'Balance Sheet'!G24+Assumptions!$B$34-Assumptions!$B$35)/'Income Statement'!G11 | H11: =(Assumptions!$B$4*Assumptions!$B$5+'Balance Sheet'!H24+Assumptions!$B$34-Assumptions!$B$35)/'Income Statement'!H11 | I11: =(Assumptions!$B$4*Assumptions!$B$5+'Balance Sheet'!I24+Assumptions!$B$34-Assumptions!$B$35)/'Income Statement'!I11

Sheet Peer & Sector
A1: Peer set, sector structure and the same-name benchmark
A2: Egyptian generics are fragmented and thinly covered; disclosed peer multiples are stale/illiquid, so the primary relative anchor is RMDA's own traded multiple (house same-name rule).
A3: Item | B3: Detail
A4: Sector structure | B4: Fragmented branded-generics market: EIPICO, Amoun, Pharco, EPICO, GlaxoSmithKline Egypt, Ibnsina (distribution) among the larger names; Rameda mid-tier by revenue and 3rd fastest-growing by 3yr CAGR (IQVIA, FY22 rank cited in company deck).
A5: Pricing regime | B5: Egyptian Drug Authority sets/caps prices; catch-up post-devaluation is regulated and lagged — the FY23 margin trough vs the FY24/25 recovery.
A6: Demand | B6: Structural volume growth (population, chronic disease); defensive through cycles; consumer shift from branded innovators to quality generics (company ER).
A7: Cost side | B7: APIs and excipients USD-priced: a step-devaluation is the single nastiest margin scenario; regulated EGP prices reprice with a lag.
A8: RMDA own multiples (spot) | B8: EV/EBITDA 10.7x FY25 / 8.9x FY26E; P/E 37.2x reported FY25 / 24.7x recurring; the market pays growth-stock multiples against a 22.55% risk-free.
A9: Key risks | B9: Interest burden on EGP ~2.1-2.3bn net debt at ~20% rates; working-capital intensity (CCC ~215d); FX step risk; EDA pricing lag; distributor credit (UCP/MEC precedent); acquisition integration.
