Workbook

Sheet READ FIRST
A1: READ FIRST — DISCLOSURE & DISCLAIMER (educational valuation study; not investment advice)
A3: NATURE OF THIS WORKBOOK
A4: This workbook is an educational valuation exercise and an expression of the preparer's personal analytical opinion, based exclusively on publicly available information and on the assumptions stated in the text and this model. It is published free of charge to demonstrate methodology and to invite scrutiny of that methodology.
A6: NO ADVICE, NO RECOMMENDATION, NO SOLICITATION
A7: Nothing here constitutes investment advice, financial consultancy, securities analysis, a research recommendation, a rating, a price target, an offer, or a solicitation to buy, sell or hold any security. No statement is directed at the objectives, situation or needs of any person.
A9: NO LICENSED ACTIVITY
A10: The preparer is not licensed or registered with any securities regulator, carries on no regulated activity, manages no money, and accepts no clients, fees or funds.
A12: ESTIMATES AND UNCERTAINTY
A13: All values are model outputs resting on explicit, subjective assumptions; they are illustrative, highly uncertain and likely to prove wrong in material respects. Samsung's reported segment financials are disclosed by the company; the FORWARD assumptions — memory-cycle duration, normalized segment earnings, HBM share, foundry trajectory and the multiples applied — are the preparer's judgments. Presented as ranges and distributions because no single number should be relied on.
A15: NO LIABILITY / READER'S RESPONSIBILITY
A16: To the maximum extent permitted by law, the preparer accepts no liability for any decision, action or loss in reliance on this workbook. Any person considering an investment decision should conduct their own assessment and consult a licensed advisor.
A18: HOLDINGS DISCLOSURE
... A22: Blue cells are hardcoded inputs (edit to your own view); black cells are formulas; green cells link across sheets. The valuation is a sum-of-the-parts on normalized segment earnings, cross-checked against relative multiples and through-cycle earnings power, with net cash added. Currency is KRW unless stated; valuation in KRW trillion, per-share in KRW.

Sheet Summary
A1: SAMSUNG ELECTRONICS (KRX: 005930) — VALUATION SUMMARY
A2: SOTP on normalized segment earnings + DCF + relative + through-cycle. Educational; not advice.
A4: HEADLINE — VALUE PER SHARE (KRW)
A5: Weighted central fundamental | B5: ='Fundamental Valuation'!B11 -> 296501.91
A6: SOTP base (normalized) | B6: =SOTP!D16 -> 283499.25
A7: SOTP bull (supercycle) | B7: =SOTP!E16 -> 410754.15
A8: SOTP bear (cycle reversion) | B8: =SOTP!F16 -> 95052.79
A9: Consolidated DCF (FCFF) | B9: =DCF!B21 -> 214800.41
A10: Market price (26-Jun-26) | B10: =Assumptions!B5 -> 339500
A11: Spot premium to central | B11: =B10/B5-1 -> 0.14501791
A13: WHAT THE NUMBER RESTS ON (edit on Assumptions)
A14: Memory normalized OP (KRW tn) | B14: =Assumptions!B14 -> 175
A15: Memory EV/OP multiple (×) | B15: =Assumptions!C14 -> 9
A16: DCF WACC | B16: =Assumptions!B46 -> 0.085
A17: Net cash (KRW tn) | B17: =Assumptions!B7 -> 119.2
A19: METHODOLOGY
A20: - SOTP on NORMALIZED segment earnings (memory, System LSI, foundry, display, MX, VD/DA, Harman) + net cash — primary lens.
A21: - Memory is ~94% of peak operating profit and the swing factor; normalized to mid-cycle, peak as the bull case.
A22: - Consolidated DCF (FCFF) is a cross-check; it lands BELOW the SOTP because capex (~KRW 100tn/yr) consumes the supercycle cash.
A23: - Relative multiples (cheap vs TSMC on peak EPS, not cheap on normalized) and through-cycle earnings power complete the picture.
A24: - Spot trades above every fundamental lens except the supercycle case — the market prices the AI memory supercycle as durable.
A25: - Reported segment financials are company disclosure (Samsung IR); forward inputs are the preparer's judgments.
A26: - Monte Carlo (16 factors, 50k paths, seed 42) describes near-term PRICE, not value; net +5.4% 3M drift, right-skewed.

Sheet Fundamental Valuation
A1: FUNDAMENTAL VALUATION — FIVE METHODS
A2: SOTP (primary) + DCF cross-check + relative + normalized. Spot sits above every lens except the supercycle case.
A4: THE METHODS — value per share (KRW)
A5: Method | B5: KRW/sh | C5: vs spot | D5: Weight | E5: Note
A6: SOTP — normalized (base) | B6: =SOTP!D16 -> 283499.25 | C6: =B6/Assumptions!B5-1 -> -0.16495067 | D6: 0.25 | E6: primary lens
A7: SOTP — supercycle (bull) | B7: =SOTP!E16 -> 410754.15 | C7: =B7/Assumptions!B5-1 -> 0.20987967 | D7: 0.15 | E7: ceiling if cycle persists
A8: Consolidated DCF (FCFF) | B8: =DCF!B21 -> 214800.41 | C8: =B8/Assumptions!B5-1 -> -0.36730366 | D8: 0.1 | E8: cash-flow cross-check (capex-heavy)
A9: Relative multiples (blended) | B9: ='Relative & Normalized'!B12 -> 316742.08 | C9: =B9/Assumptions!B5-1 -> -0.067033633 | D9: 0.25 | E9: vs TSMC/SK Hynix/Micron
A10: Normalized earnings power | B10: ='Relative & Normalized'!B19 -> 253393.67 | C10: =B10/Assumptions!B5-1 -> -0.25362691 | D10: 0.25 | E10: through-cycle discipline
A11: WEIGHTED CENTRAL FUNDAMENTAL VALUE | B11: =SUMPRODUCT(B6:B10,D6:D10) -> 296501.91 | C11: =B11/Assumptions!B5-1 -> -0.12665122 | D11: =SUM(D6:D10) -> 1
A13: Memo: spot price (26-Jun-26) | B13: =Assumptions!B5 -> 339500
A14: Spot premium to central | B14: =Assumptions!B5/B11-1 -> 0.14501791 | E14: market prices the supercycle as durable
A16: RANGE: bear (cycle reversion) → bull (supercycle)
A17: Bear / cycle-reversion floor | B17: =SOTP!F16 -> 95052.79
A18: Bull / supercycle ceiling | B18: =SOTP!E16 -> 410754.15

Sheet Assumptions
A1: SAMSUNG ELECTRONICS (KRX: 005930) — ASSUMPTIONS
A2: All blue cells are inputs. KRW trillion unless noted. Edit to your own view.
A4: GLOBAL & CORPORATE
A5: Spot price (KRW, 26-Jun-26 close) | B5: 339500
A6: Shares outstanding ex-treasury (bn) | B6: 6.63
A7: Net cash (KRW tn, Q1-2026) | B7: 119.2
A8: Listed stakes / other (KRW tn) | B8: 25
A9: BVPS (KRW, FY2025) | B9: 64000
A10: Tax rate (effective) | B10: 0.16
A12: SOTP — SEGMENT NORMALIZED OP (KRW tn) & EV/OP MULTIPLE (×)
A13: Segment | B13: Norm OP (base) | C13: Mult × | D13: Bull OP | E13: Bull × | F13: Bear OP | G13: Bear ×
A14: Memory (DRAM/NAND/HBM) | B14: 175 | C14: 9 | D14: 230 | E14: 10 | F14: 60 | G14: 7
A15: System LSI | B15: 4 | C15: 8 | D15: 6 | E15: 8 | F15: 2 | G15: 7
A16: Samsung Display (SDC stake) | B16: 5 | C16: 6.5 | D16: 7 | E16: 7 | F16: 3 | G16: 5.5
A17: MX + Networks (handsets) | B17: 13 | C17: 6 | D17: 15 | E17: 6.5 | F17: 10 | G17: 5
A18: VD + DA (TV/appliances) | B18: 1.5 | C18: 5 | D18: 2 | E18: 5.5 | F18: 1 | G18: 4
A19: Harman (auto/audio) | B19: 1.3 | C19: 8 | D19: 1.6 | E19: 8.5 | F19: 1 | G19: 6.5
A20: Foundry EV (KRW tn) — option value | B20: 0 | D20: 60 | F20: -25 | H20: loss-making; 2027 break-even target → base 0, bull +60, bear -25
A22: RELATIVE & NORMALIZED EARNINGS
A23: 2026E net profit (KRW tn) | B23: 200
A24: 2027E net profit (KRW tn) | B24: 180
A25: Normalized through-cycle net (KRW tn) | B25: 120
A26: Normalized justified P/E (×) | B26: 14
A27: Relative P/E low (×) | B27: 9
A28: Relative P/E high (×) | B28: 12
A30: FOUR-METHOD WEIGHTS
A31: SOTP — normalized (base) | B31: 0.3
A32: SOTP — supercycle (bull) | B32: 0.15
A33: Relative multiples (blended) | B33: 0.25
A34: Normalized earnings power | B34: 0.3
A37: FORECAST INPUTS (KRW tn) — illustrative operating build
A38: Year | B38: Revenue | C38: Op profit | D38: Fin inc | E38: Net profit
A39: 2026 | B39: 530 | C39: 215 | D39: 11 | E39: 200
A40: 2027 | B40: 520 | C40: 190 | D40: 11 | E40: 180
A41: 2028 | B41: 455 | C41: 120 | D41: 12 | E41: 105
A42: 2029 | B42: 475 | C42: 132 | D42: 12 | E42: 116
A43: 2030 | B43: 495 | C43: 145 | D43: 13 | E43: 128
A45: DCF INPUTS
A46: WACC (KRW) | B46: 0.085
A47: Terminal growth g | B47: 0.025
...

Sheet SOTP
A1: SUM-OF-THE-PARTS — segment EV build (base / bull / bear)
A2: Each segment: normalized OP × EV/OP multiple. Net cash added. KRW tn; per-share KRW.
A4: Segment | B4: Base OP | C4: Base × | D4: Base EV | E4: Bull EV | F4: Bear EV | G4: Basis
A5: Memory (DRAM/NAND/HBM) | B5: =Assumptions!B14 -> 175 | C5: =Assumptions!C14 -> 9 | D5: =B5*C5 -> 1575 | E5: =Assumptions!D14*Assumptions!E14 -> 2300 | F5: =Assumptions!F14*Assumptions!G14 -> 420 | G5: primary driver; cyclical + HBM secular
A6: System LSI | B6: =Assumptions!B15 -> 4 | C6: =Assumptions!C15 -> 8 | D6: =B6*C6 -> 32 | E6: =Assumptions!D15*Assumptions!E15 -> 48 | F6: =Assumptions!F15*Assumptions!G15 -> 14 | G6: logic (Exynos, CIS)
A7: Samsung Display (SDC stake) | B7: =Assumptions!B16 -> 5 | C7: =Assumptions!C16 -> 6.5 | D7: =B7*C7 -> 32.5 | E7: =Assumptions!D16*Assumptions!E16 -> 49 | F7: =Assumptions!F16*Assumptions!G16 -> 16.5 | G7: OLED panels, mature
A8: MX + Networks (handsets) | B8: =Assumptions!B17 -> 13 | C8: =Assumptions!C17 -> 6 | D8: =B8*C8 -> 78 | E8: =Assumptions!D17*Assumptions!E17 -> 97.5 | F8: =Assumptions!F17*Assumptions!G17 -> 50 | G8: premium handsets, low growth
A9: VD + DA (TV/appliances) | B9: =Assumptions!B18 -> 1.5 | C9: =Assumptions!C18 -> 5 | D9: =B9*C9 -> 7.5 | E9: =Assumptions!D18*Assumptions!E18 -> 11 | F9: =Assumptions!F18*Assumptions!G18 -> 4 | G9: competitive, low margin
A10: Harman (auto/audio) | B10: =Assumptions!B19 -> 1.3 | C10: =Assumptions!C19 -> 8 | D10: =B10*C10 -> 10.4 | E10: =Assumptions!D19*Assumptions!E19 -> 13.6 | F10: =Assumptions!F19*Assumptions!G19 -> 6.5 | G10: auto electronics, growing
A11: Foundry (option value) | D11: =Assumptions!B20 -> 0 | E11: =Assumptions!D20 -> 60 | F11: =Assumptions!F20 -> -25 | G11: loss-making now; 2027 break-even target
A12: Operating EV | D12: =SUM(D5:D11) -> 1735.4 | E12: =SUM(E5:E11) -> 2579.1 | F12: =SUM(F5:F11) -> 486
A13: (+) Net cash | D13: =Assumptions!B7 -> 119.2 | E13: =Assumptions!B7 -> 119.2 | F13: =Assumptions!B7 -> 119.2
A14: (+) Listed stakes / other | D14: =Assumptions!B8 -> 25 | E14: =Assumptions!B8 -> 25 | F14: =Assumptions!B8 -> 25
A15: Equity value (KRW tn) | D15: =D12+D13+D14 -> 1879.6 | E15: =E12+E13+E14 -> 2723.3 | F15: =F12+F13+F14 -> 630.2
A16: VALUE / SHARE (KRW) | D16: =D15*1000/Assumptions!B6 -> 283499.25 | E16: =E15*1000/Assumptions!B6 -> 410754.15 | F16: =F15*1000/Assumptions!B6 -> 95052.79
A17: vs spot | D17: =D16/Assumptions!B5-1 -> -0.16495067 | E17: =E16/Assumptions!B5-1 -> 0.20987967 | F17: =F16/Assumptions!B5-1 -> -0.72002124
A19: Base = normalized mid-cycle (AI-elevated floor). Bull = supercycle persists + HBM share gain + foundry break-even. Bear = 2027 oversupply, foundry burn, segments compress.

Sheet Segments
A1: OPERATING SEGMENTS — cyclicality & multiple rationale
A2: Each segment valued on the multiple that fits its cyclicality. Source: Samsung IR segment disclosures (FY2025 / Q1-2026).
A4: Dimension | B4: Memory | C4: Foundry / System LSI | D4: MX + Networks | E4: VD+DA / Harman
A5: What it is | B5: DRAM, NAND, HBM | C5: Logic foundry + Exynos/CIS | D5: Galaxy handsets + networks | E5: TVs, appliances + auto
A6: Earnings driver | B6: Bit growth × ASP × HBM mix | C6: Wafer starts × node × yield | D6: Units × ASP × mix | E6: Units × ASP; auto design wins
A7: Cyclicality | B7: Extreme — full-loss to record in ~2yr | C7: High — utilization, yield ramp | D7: Moderate — premium cushions | E7: Low–moderate
A8: Currency | B8: Mostly USD-priced | C8: USD | D8: USD/global | E8: Global
A9: FY25→Q1-26 OP trend | B9: Trough '23 → record Q1-26 | C9: Loss, narrowing to <1tn/qtr | D9: Squeezed by memory input cost | E9: Thin, stable
A10: Norm OP (base, KRW tn) | B10: =Assumptions!B14 -> 175 | C10: =Assumptions!B15+Assumptions!B20*0 -> 4 | D10: =Assumptions!B17 -> 13 | E10: =Assumptions!B18+Assumptions!B19 -> 2.8
A11: EV/OP multiple | B11: =Assumptions!C14 -> 9 | C11: 8.0x logic / option foundry | D11: =Assumptions!C17 -> 6 | E11: 5.0–8.0x
A12: Why the multiple | B12: 8–10x: cyclical, HBM secular growth | C12: option value; 2027 B/E target | D12: 6x: premium but low growth | E12: low: commoditised / small
A15: Memory is ~94% of group operating profit at the Q1-2026 peak (DS division) — the dominant and most cyclical driver; the SOTP normalizes it to mid-cycle. Foundry is loss-making (2027 break-even target) and carried at option value.

Sheet Relative & Normalized
A1: RELATIVE MULTIPLES & NORMALIZED EARNINGS POWER
A2: Spot earnings are at a cyclical PEAK (DS=94% of OP); relative lens on elevated EPS vs through-cycle discipline.
A4: RELATIVE MULTIPLES
A5: 2026E EPS (KRW) | B5: =Assumptions!B23*1000/Assumptions!B6 -> 30165.913
A6: 2027E EPS (KRW) | B6: =Assumptions!B24*1000/Assumptions!B6 -> 27149.321
A7: Spot P/E on 2026E (×) | B7: =Assumptions!B5/B5 -> 11.254425 | E7: vs TSMC ~24x, SK Hynix ~7x fwd
A8: Spot P/E on 2027E (×) | B8: =Assumptions!B5/B6 -> 12.504917
A9: Implied value — P/E low × 2026E EPS | B9: =Assumptions!B27*B5 -> 271493.21
A10: Implied value — P/E high × 2026E EPS | B10: =Assumptions!B28*B5 -> 361990.95
A11: Spot P/B (BVPS-based) (×) | B11: =Assumptions!B5/Assumptions!B9 -> 5.3046875 | E11: ~5x vs 1–1.5x historical — peak extreme
A12: RELATIVE BLENDED MIDPOINT (KRW) | B12: =(B9+B10)/2 -> 316742.08
A15: NORMALIZED THROUGH-CYCLE EARNINGS POWER
A16: Normalized net profit (KRW tn) | B16: =Assumptions!B25 -> 120
A17: Normalized EPS (KRW) | B17: =B16*1000/Assumptions!B6 -> 18099.548
A18: Justified P/E (×) | B18: =Assumptions!B26 -> 14
A19: NORMALIZED VALUE / SHARE (KRW) | B19: =B17*B18 -> 253393.67
A21: Normalized P/E at spot (×) | B21: =Assumptions!B5/B17 -> 18.757375 | E21: on through-cycle EPS, the stock is not cheap

Sheet DCF
A1: CONSOLIDATED DCF — unlevered FCFF (cross-check)
A2: FCFF = OP×(1−tax) + D&A − capex − ΔWC, discounted at WACC; normalized terminal. A cross-check on the SOTP.
A4: KRW tn | B4: 2026 | C4: 2027 | D4: 2028 | E4: 2029 | F4: 2030
A5: Operating profit | B5: =Assumptions!C39 -> 215 | C5: =Assumptions!C40 -> 190 | D5: =Assumptions!C41 -> 120 | E5: =Assumptions!C42 -> 132 | F5: =Assumptions!C43 -> 145
A6: NOPAT (×(1−tax)) | B6: =B5*(1-Assumptions!B49) -> 176.3 | C6: =C5*(1-Assumptions!B49) -> 155.8 | D6: =D5*(1-Assumptions!B49) -> 98.4 | E6: =E5*(1-Assumptions!B49) -> 108.24 | F6: =F5*(1-Assumptions!B49) -> 118.9
A7: (+) D&A | B7: =Assumptions!B53 -> 52 | C7: =Assumptions!B54 -> 54 | D7: =Assumptions!B55 -> 56 | E7: =Assumptions!B56 -> 58 | F7: =Assumptions!B57 -> 60
A8: (−) Capex | B8: =-Assumptions!C53 -> -100 | C8: =-Assumptions!C54 -> -98 | D8: =-Assumptions!C55 -> -88 | E8: =-Assumptions!C56 -> -85 | F8: =-Assumptions!C57 -> -85
A9: (−) ΔWorking capital | B9: =-Assumptions!D53 -> -12 | C9: =-Assumptions!D54 -> -3 | D9: =-Assumptions!D55 -> 5 | E9: =-Assumptions!D56 -> -4 | F9: =-Assumptions!D57 -> -4
A10: Unlevered FCFF | B10: =B6+B7+B8+B9 -> 116.3 | C10: =C6+C7+C8+C9 -> 108.8 | D10: =D6+D7+D8+D9 -> 71.4 | E10: =E6+E7+E8+E9 -> 77.24 | F10: =F6+F7+F8+F9 -> 89.9
A11: Discount factor @ WACC | B11: =1/(1+Assumptions!B46)^1 -> 0.92165899 | C11: =1/(1+Assumptions!B46)^2 -> 0.84945529 | D11: =1/(1+Assumptions!B46)^3 -> 0.7829081 | E11: =1/(1+Assumptions!B46)^4 -> 0.72157428 | F11: =1/(1+Assumptions!B46)^5 -> 0.66504542
A12: PV of FCFF | B12: =B10*B11 -> 107.18894 | C12: =C10*C11 -> 92.420735 | D12: =D10*D11 -> 55.899638 | E12: =E10*E11 -> 55.734398 | F12: =F10*F11 -> 59.787584
A14: PV of explicit FCFF (Σ) | B14: =SUM(B12:F12) -> 371.03129
A15: Terminal value (normalized FCFF, Gordon) | B15: =Assumptions!B48*(1+Assumptions!B47)/(Assumptions!B46-Assumptions!B47) -> 1366.6667
A16: PV of terminal value | B16: =B15*F11 -> 908.89541
A17: Enterprise value | B17: =B14+B16 -> 1279.9267
A18: (+) Net cash | B18: =Assumptions!B7 -> 119.2
A19: (+) Listed stakes / other | B19: =Assumptions!B8 -> 25
A20: Equity value (KRW tn) | B20: =B17+B18+B19 -> 1424.1267
A21: VALUE / SHARE (KRW) | B21: =B20*1000/Assumptions!B6 -> 214800.41
A22: vs spot | B22: =B21/Assumptions!B5-1 -> -0.36730366
A24: The DCF lands below the SOTP because Samsung's enormous capex (~KRW 100tn/yr) consumes much of the supercycle's cash flow — on owned cash flow the stock looks even fuller. A cross-check, not the primary lens.

Sheet Income Statement
A1: CONSOLIDATED INCOME STATEMENT — KRW tn
A2: Actuals: Samsung IR (FY2023–FY2025). Forecast 2026e–2030e is an illustrative operating build; memory is the swing.
A4: KRW tn | B4: 2023a | C4: 2024a | D4: 2025a | E4: 2026e | F4: 2027e | G4: 2028e | H4: 2029e | I4: 2030e
A5: Revenue | B5: 258.94 | C5: 300.87 | D5: 333.6 | E5: =Assumptions!B39 -> 530 | F5: =Assumptions!B40 -> 520 | G5: =Assumptions!B41 -> 455 | H5: =Assumptions!B42 -> 475 | I5: =Assumptions!B43 -> 495
A6: growth YoY | C6: =C5/B5-1 -> 0.1619294 | D6: =D5/C5-1 -> 0.10878452 | E6: =E5/D5-1 -> 0.58872902 | F6: =F5/E5-1 -> -0.018867925 | G6: =G5/F5-1 -> -0.125 | H6: =H5/G5-1 -> 0.043956044 | I6: =I5/H5-1 -> 0.042105263
A7: Operating profit | B7: 6.57 | C7: 32.73 | D7: 43.6 | E7: =Assumptions!C39 -> 215 | F7: =Assumptions!C40 -> 190 | G7: =Assumptions!C41 -> 120 | H7: =Assumptions!C42 -> 132 | I7: =Assumptions!C43 -> 145
A8: OP margin | B8: =B7/B5 -> 0.025372673 | C8: =C7/C5 -> 0.10878452 | D8: =D7/D5 -> 0.13069544 | E8: =E7/E5 -> 0.40566038 | F8: =F7/F5 -> 0.36538462 | G8: =G7/G5 -> 0.26373626 | H8: =H7/H5 -> 0.27789474 | I8: =I7/I5 -> 0.29292929
A9: Net profit (attributable) | B9: 15.49 | C9: 34.45 | D9: 45.21 | E9: =Assumptions!E39 -> 200 | F9: =Assumptions!E40 -> 180 | G9: =Assumptions!E41 -> 105 | H9: =Assumptions!E42 -> 116 | I9: =Assumptions!E43 -> 128
A10: net margin | B10: =B9/B5 -> 0.059820808 | C10: =C9/C5 -> 0.11450128 | D10: =D9/D5 -> 0.13552158 | E10: =E9/E5 -> 0.37735849 | F10: =F9/F5 -> 0.34615385 | G10: =G9/G5 -> 0.23076923 | H10: =H9/H5 -> 0.24421053 | I10: =I9/I5 -> 0.25858586
A11: EPS (KRW) | B11: =B9*1000/Assumptions!B6 -> 2336.3499 | C11: =C9*1000/Assumptions!B6 -> 5196.0784 | D11: =D9*1000/Assumptions!B6 -> 6819.0045 | E11: =E9*1000/Assumptions!B6 -> 30165.913 | F11: =F9*1000/Assumptions!B6 -> 27149.321 | G11: =G9*1000/Assumptions!B6 -> 15837.104 | H11: =H9*1000/Assumptions!B6 -> 17496.229 | I11: =I9*1000/Assumptions!B6 -> 19306.184
A12: Memory/DS OP — memo | B12: -14.9 | D12: 24.9 | E12: 185 | F12: 160 | G12: 75 | H12: 85 | I12: 95
A14: FY2023 = memory trough (DS recorded a record full-year loss). Q1-2026 alone produced KRW 57.2tn operating profit (DS 53.7tn). Forecast assumes the supercycle peaks 2026–27, then memory normalizes. Illustrative, not guidance.

Sheet Balance Sheet
A1: CONSOLIDATED BALANCE SHEET — KRW tn (simplified)
A2: Actuals approximate (Samsung IR). Forecast rolls equity by retained earnings; fortress net-cash balance sheet.
A4: KRW tn | B4: 2023a | C4: 2024a | D4: 2025a | E4: 2026e | F4: 2027e | G4: 2028e | H4: 2029e | I4: 2030e
A5: Cash & financial investments | B5: 74 | C5: 92 | D5: 101 | E5: =D5+'Cash Flow'!E16 -> 161 | F5: =E5+'Cash Flow'!F16 -> 222 | G5: =F5+'Cash Flow'!G16 -> 258 | H5: =G5+'Cash Flow'!H16 -> 296.6 | I5: =H5+'Cash Flow'!I16 -> 344.4
A6: Receivables | B6: 45 | C6: 52 | D6: 60 | E6: =D6 -> 60 | F6: =E6 -> 60 | G6: =F6 -> 60 | H6: =G6 -> 60 | I6: =H6 -> 60
A7: Inventory | B7: 54 | C7: 56 | D7: 58 | E7: =D7 -> 58 | F7: =E7 -> 58 | G7: =F7 -> 58 | H7: =G7 -> 58 | I7: =H7 -> 58
A8: PP&E (net) | B8: 188 | C8: 205 | D8: 220 | E8: =D8+Assumptions!C53-Assumptions!B53 -> 268 | F8: =E8+Assumptions!C54-Assumptions!B54 -> 312 | G8: =F8+Assumptions!C55-Assumptions!B55 -> 344 | H8: =G8+Assumptions!C56-Assumptions!B56 -> 371 | I8: =H8+Assumptions!C57-Assumptions!B57 -> 396
A9: Other assets | B9: 95 | C9: 100 | D9: 105 | E9: =D9 -> 105 | F9: =E9 -> 105 | G9: =F9 -> 105 | H9: =G9 -> 105 | I9: =H9 -> 105
A10: Total assets | B10: =SUM(B5:B9) -> 456 | C10: =SUM(C5:C9) -> 505 | D10: =SUM(D5:D9) -> 544 | E10: =SUM(E5:E9) -> 652 | F10: =SUM(F5:F9) -> 757 | G10: =SUM(G5:G9) -> 825 | H10: =SUM(H5:H9) -> 890.6 | I10: =SUM(I5:I9) -> 963.4
A11: Debt | B11: 10 | C11: 10 | D11: 10 | E11: =D11 -> 10 | F11: =E11 -> 10 | G11: =F11 -> 10 | H11: =G11 -> 10 | I11: =H11 -> 10
A12: Payables | B12: 60 | C12: 62 | D12: 64 | E12: =D12 -> 64 | F12: =E12 -> 64 | G12: =F12 -> 64 | H12: =G12 -> 64 | I12: =H12 -> 64
A13: Other liabilities | B13: 62 | C13: 60 | D13: 60 | E13: =D13 -> 60 | F13: =E13 -> 60 | G13: =F13 -> 60 | H13: =G13 -> 60 | I13: =H13 -> 60
A14: Total liabilities | B14: =B11+B12+B13 -> 132 | C14: =C11+C12+C13 -> 132 | D14: =D11+D12+D13 -> 134 | E14: =E11+E12+E13 -> 134 | F14: =F11+F12+F13 -> 134 | G14: =G11+G12+G13 -> 134 | H14: =H11+H12+H13 -> 134 | I14: =I11+I12+I13 -> 134
A15: Total equity | B15: 364 | C15: 373 | D15: 424 | E15: =D15+'Income Statement'!E9*0.6 -> 544 | F15: =E15+'Income Statement'!F9*0.6 -> 652 | G15: =F15+'Income Statement'!G9*0.6 -> 715 | H15: =G15+'Income Statement'!H9*0.6 -> 784.6 | I15: =H15+'Income Statement'!I9*0.6 -> 861.4
A16: BVPS (KRW) | B16: =B15*1000/Assumptions!B6 -> 54901.961 | C16: =C15*1000/Assumptions!B6 -> 56259.427 | D16: =D15*1000/Assumptions!B6 -> 63951.735 | E16: =E15*1000/Assumptions!B6 -> 82051.282 | F16: =F15*1000/Assumptions!B6 -> 98340.875 | G16: =G15*1000/Assumptions!B6 -> 107843.14 | H16: =H15*1000/Assumptions!B6 -> 118340.87 | I16: =I15*1000/Assumptions!B6 -> 129924.59
A17: Net cash (cash − debt) | B17: =B5-B11 -> 64 | C17: =C5-C11 -> 82 | D17: =D5-D11 -> 91 | E17: =E5-E11 -> 151 | F17: =F5-F11 -> 212 | G17: =G5-G11 -> 248 | H17: =H5-H11 -> 286.6 | I17: =I5-I11 -> 334.4
A19: Simplified: working-capital lines held flat in the forecast; equity rolled at ~60% retention (the rest to dividends/buybacks/cancellations). Will not tie line-by-line to the reported balance sheet.

Sheet Cash Flow
A1: CONSOLIDATED CASH FLOW — KRW tn (simplified)
A2: Actuals approximate. Forecast: OCF ≈ net + D&A − ΔWC; investing = capex; financing = dividends/buybacks.
A4: KRW tn | B4: 2023a | C4: 2024a | D4: 2025a | E4: 2026e | F4: 2027e | G4: 2028e | H4: 2029e | I4: 2030e
A5: Operating cash flow | B5: 44.1 | C5: 75 | D5: 90 | E5: ='Income Statement'!E9+Assumptions!B53-Assumptions!D53 -> 240 | F5: ='Income Statement'!F9+Assumptions!B54-Assumptions!D54 -> 231 | G5: ='Income Statement'!G9+Assumptions!B55-Assumptions!D55 -> 166 | H5: ='Income Statement'!H9+Assumptions!B56-Assumptions!D56 -> 170 | I5: ='Income Statement'!I9+Assumptions!B57-Assumptions!D57 -> 184
A6: Capex (investing) | B6: -53.1 | C6: -49 | D6: -55 | E6: =-Assumptions!C53 -> -100 | F6: =-Assumptions!C54 -> -98 | G6: =-Assumptions!C55 -> -88 | H6: =-Assumptions!C56 -> -85 | I6: =-Assumptions!C57 -> -85
A7: Financing (div/buyback) | B7: -12 | C7: -18 | D7: -22 | E7: =-'Income Statement'!E9*0.4 -> -80 | F7: =-'Income Statement'!F9*0.4 -> -72 | G7: =-'Income Statement'!G9*0.4 -> -42 | H7: =-'Income Statement'!H9*0.4 -> -46.4 | I7: =-'Income Statement'!I9*0.4 -> -51.2
A8: Net change in cash | B8: =B5+B6+B7 -> -21 | C8: =C5+C6+C7 -> 8 | D8: =D5+D6+D7 -> 13 | E8: =E5+E6+E7 -> 60 | F8: =F5+F6+F7 -> 61 | G8: =G5+G6+G7 -> 36 | H8: =H5+H6+H7 -> 38.6 | I8: =I5+I6+I7 -> 47.8
A10: Memo — free cash flow (OCF + capex) | B10: =B5+B6 -> -9 | C10: =C5+C6 -> 26 | D10: =D5+D6 -> 35 | E10: =E5+E6 -> 140 | F10: =F5+F6 -> 133 | G10: =G5+G6 -> 78 | H10: =H5+H6 -> 85 | I10: =I5+I6 -> 99
A12: Memo — capex (positive) | B12: =-B6 -> 53.1 | C12: =-C6 -> 49 | D12: =-D6 -> 55 | E12: =-E6 -> 100 | F12: =-F6 -> 98 | G12: =-G6 -> 88 | H12: =-H6 -> 85 | I12: =-I6 -> 85
A16: Memo — net change (for BS link) | B16: =B8 -> -21 | C16: =C8 -> 8 | D16: =D8 -> 13 | E16: =E8 -> 60 | F16: =F8 -> 61 | G16: =G8 -> 36 | H16: =H8 -> 38.6 | I16: =I8 -> 47.8
A18: Samsung is a cash machine even mid-cycle, but capex is enormous — FCF is far below net income, which is precisely why the DCF lands below the SOTP.

Sheet Summary Financials
A1: SAMSUNG ELECTRONICS — SUMMARY FINANCIALS (live links)
A2: Every cell links to the Income Statement / Balance Sheet / Cash Flow sheets.
A4: KRW tn | B4: 2023a | C4: 2024a | D4: 2025a | E4: 2026e | F4: 2027e | G4: 2028e | H4: 2029e | I4: 2030e
A5: Revenue | B5: ='Income Statement'!B5 -> 258.94 | C5: ='Income Statement'!C5 -> 300.87 | D5: ='Income Statement'!D5 -> 333.6 | E5: ='Income Statement'!E5 -> 530 | F5: ='Income Statement'!F5 -> 520 | G5: ='Income Statement'!G5 -> 455 | H5: ='Income Statement'!H5 -> 475 | I5: ='Income Statement'!I5 -> 495
A6: Operating profit | B6: ='Income Statement'!B7 -> 6.57 | C6: ='Income Statement'!C7 -> 32.73 | D6: ='Income Statement'!D7 -> 43.6 | E6: ='Income Statement'!E7 -> 215 | F6: ='Income Statement'!F7 -> 190 | G6: ='Income Statement'!G7 -> 120 | H6: ='Income Statement'!H7 -> 132 | I6: ='Income Statement'!I7 -> 145
A7: Net profit | B7: ='Income Statement'!B9 -> 15.49 | C7: ='Income Statement'!C9 -> 34.45 | D7: ='Income Statement'!D9 -> 45.21 | E7: ='Income Statement'!E9 -> 200 | F7: ='Income Statement'!F9 -> 180 | G7: ='Income Statement'!G9 -> 105 | H7: ='Income Statement'!H9 -> 116 | I7: ='Income Statement'!I9 -> 128
A8: EPS (KRW) | B8: ='Income Statement'!B11 -> 2336.3499 | C8: ='Income Statement'!C11 -> 5196.0784 | D8: ='Income Statement'!D11 -> 6819.0045 | E8: ='Income Statement'!E11 -> 30165.913 | F8: ='Income Statement'!F11 -> 27149.321 | G8: ='Income Statement'!G11 -> 15837.104 | H8: ='Income Statement'!H11 -> 17496.229 | I8: ='Income Statement'!I11 -> 19306.184
A9: Total assets | B9: ='Balance Sheet'!B10 -> 456 | C9: ='Balance Sheet'!C10 -> 505 | D9: ='Balance Sheet'!D10 -> 544 | E9: ='Balance Sheet'!E10 -> 652 | F9: ='Balance Sheet'!F10 -> 757 | G9: ='Balance Sheet'!G10 -> 825 | H9: ='Balance Sheet'!H10 -> 890.6 | I9: ='Balance Sheet'!I10 -> 963.4
A10: Total equity | B10: ='Balance Sheet'!B15 -> 364 | C10: ='Balance Sheet'!C15 -> 373 | D10: ='Balance Sheet'!D15 -> 424 | E10: ='Balance Sheet'!E15 -> 544 | F10: ='Balance Sheet'!F15 -> 652 | G10: ='Balance Sheet'!G15 -> 715 | H10: ='Balance Sheet'!H15 -> 784.6 | I10: ='Balance Sheet'!I15 -> 861.4
A11: Net cash | B11: ='Balance Sheet'!B17 -> 64 | C11: ='Balance Sheet'!C17 -> 82 | D11: ='Balance Sheet'!D17 -> 91 | E11: ='Balance Sheet'!E17 -> 151 | F11: ='Balance Sheet'!F17 -> 212 | G11: ='Balance Sheet'!G17 -> 248 | H11: ='Balance Sheet'!H17 -> 286.6 | I11: ='Balance Sheet'!I17 -> 334.4
A12: BVPS (KRW) | B12: ='Balance Sheet'!B16 -> 54901.961 | C12: ='Balance Sheet'!C16 -> 56259.427 | D12: ='Balance Sheet'!D16 -> 63951.735 | E12: ='Balance Sheet'!E16 -> 82051.282 | F12: ='Balance Sheet'!F16 -> 98340.875 | G12: ='Balance Sheet'!G16 -> 107843.14 | H12: ='Balance Sheet'!H16 -> 118340.87 | I12: ='Balance Sheet'!I16 -> 129924.59
A13: Operating cash flow | B13: ='Cash Flow'!B5 -> 44.1 | C13: ='Cash Flow'!C5 -> 75 | D13: ='Cash Flow'!D5 -> 90 | E13: ='Cash Flow'!E5 -> 240 | F13: ='Cash Flow'!F5 -> 231 | G13: ='Cash Flow'!G5 -> 166 | H13: ='Cash Flow'!H5 -> 170 | I13: ='Cash Flow'!I5 -> 184
A14: Free cash flow | B14: ='Cash Flow'!B10 -> -9 | C14: ='Cash Flow'!C10 -> 26 | D14: ='Cash Flow'!D10 -> 35 | E14: ='Cash Flow'!E10 -> 140 | F14: ='Cash Flow'!F10 -> 133 | G14: ='Cash Flow'!G10 -> 78 | H14: ='Cash Flow'!H10 -> 85 | I14: ='Cash Flow'!I10 -> 99

Sheet Monte Carlo
A1: MONTE CARLO — ONE 16-FACTOR MODEL (50,000 paths, seed 42)
A2: Seven continuous factors compound daily; nine discrete events arrive as jumps. Idiosyncratic noise tops up to realized 3M vol.
A4: CORE INPUTS
A5: Anchor price (KRW, 26-Jun-26) | B5: =Assumptions!B5 -> 339500
A6: Horizon T+20 (sessions) | B6: 20
A7: Horizon T+60 (sessions) | B7: 60
A8: Idiosyncratic 3M volatility | B8: 0.145
A9: ATH (close) reference (KRW) | B9: 362500
A10: Round level (KRW) | B10: 400000
A11: SMA50 / structure (KRW) | B11: 286000
A12: Cycle-reversion zone (KRW) | B12: 250000
A14: SEVEN CONTINUOUS FACTORS
A15: Factor | B15: 3M drift | C15: 3M vol | H15: Channel
A16: DRAM/NAND ASP trajectory | B16: 0.015 | C16: 0.08 | H16: master memory-price driver
A17: HBM share vs SK Hynix / Nvidia alloc | B17: 0.015 | C17: 0.05 | H17: high-margin AI memory
A18: USD/KRW translation | B18: 0.005 | C18: 0.04 | H18: weak won = tailwind
A19: Global AI / datacenter capex | B19: 0.01 | C19: 0.05 | H19: demand pull
A20: KOSPI / foreign flows beta | B20: 0.005 | C20: 0.06 | H20: market liquidity
A21: Smartphone / PC demand (DX) | B21: -0.015 | C21: 0.03 | H21: handset/PC softness
A22: Foundry utilization / loss trajectory | B22: 0.005 | C22: 0.03 | H22: narrowing losses
A24: NINE DISCRETE EVENTS
A25: Event | B25: Prob | C25: Impact μ | D25: Impact σ | H25: Channel
A26: Nvidia HBM4 qualification / yield | B26: 0.45 | C26: 0.07 | D26: 0.04 | H26: pivotal catalyst
A27: Memory oversupply / cycle inflection | B27: 0.3 | C27: -0.09 | D27: 0.05 | H27: 2027 capacity — left tail
A28: US tariff / Section 232 / export ctrl | B28: 0.25 | C28: -0.06 | D28: 0.04 | H28: trade-policy shock
A29: Capital-return (buyback / cancellation) | B29: 0.5 | C29: 0.04 | D29: 0.03 | H29: ~KRW 90tn buyback decision
A30: Governance / Korea-discount compression | B30: 0.25 | C30: 0.03 | D30: 0.03 | H30: Commercial Act reform
A31: Quarterly earnings surprise (DS margin) | B31: 0.4 | C31: 0.03 | D31: 0.05 | H31: two-sided
A32: China demand / geopolitical shock | B32: 0.2 | C32: -0.07 | D32: 0.04 | H32: demand/risk
A33: KRW 1,000tn capex-plan headline | B33: 0.35 | C33: 0.01 | D33: 0.04 | H33: ambiguous: capex vs moat
A34: Labour / union disruption | B34: 0.15 | C34: -0.03 | D34: 0.03 | H34: operations
A36: FACTOR MOMENTS (live)
A37: Expected 3M log-return μ | B37: =SUM(B16:B22)+SUMPRODUCT(B26:B34,C26:C34) -> 0.054
A38: 3M variance | B38: =SUMSQ(C16:C22)+B8^2+SUMPRODUCT(B26:B34,C26:C34^2+D26:D34^2) -> 0.052055
A39: 3M volatility σ | B39: =SQRT(B38) -> 0.22815565
A40: Annualized vol (×2) | B40: =B39*2 -> 0.4563113 | H40: engine total 3M vol ~22.8% (ann ~46%)
A42: PERCENTILES (KRW/share)
A43: Horizon | B43: 5% | C43: 25% | D43: Median | E43: 75% | F43: 95% | G43: Source
A44: T+20 — engine (simulated) | B44: 277676 | C44: 316898 | D44: 346091 | E44: 378203 | F44: 430413 | G44: 50k paths · seed 42
A45: T+20 — closed-form (live) | B45: =B5*EXP(B37*20/60+-1.6449*B39*SQRT(20/60)) -> 278327.45 | C45: =B5*EXP(B37*20/60+-0.6745*B39*SQRT(20/60)) -> 316279.07 | D45: =B5*EXP(B37*20/60+0*B39*SQRT(20/60)) -> 345666.33 | E45: =B5*EXP(B37*20/60+0.6745*B39*SQRT(20/60)) -> 377784.13 | F45: =B5*EXP(B37*20/60+1.6449*B39*SQRT(20/60)) -> 429297.26
...

Sheet Sensitivity
A1: SENSITIVITY — value/share (KRW)
A2: Top: SOTP memory OP × multiple. Bottom: DCF WACC × terminal growth. Both computed live.
A4: SOTP: Memory norm OP (KRW tn) ↓ / EV/OP multiple (×) →
A5: OP ↓ / × → | B5: 7 | C5: 8 | D5: 9 | E5: 10 | F5: 11
A6: 80 | B6: =(80*7+(Assumptions!B15*Assumptions!C15+Assumptions!B16*Assumptions!C16+Assumptions!B17*Assumptions!C17+Assumptions!B18*Assumptions!C18+Assumptions!B19*Assumptions!C19+Assumptions!B20+Assumptions!B7+Assumptions!B8))*1000/Assumptions!B6 -> 130407.24 | C6: =(80*8+(Assumptions!B15*Assumptions!C15+Assumptions!B16*Assumptions!C16+Assumptions!B17*Assumptions!C17+Assumptions!B18*Assumptions!C18+Assumptions!B19*Assumptions!C19+Assumptions!B20+Assumptions!B7+Assumptions!B8))*1000/Assumptions!B6 -> 142473.6 | D6: =(80*9+(Assumptions!B15*Assumptions!C15+Assumptions!B16*Assumptions!C16+Assumptions!B17*Assumptions!C17+Assumptions!B18*Assumptions!C18+Assumptions!B19*Assumptions!C19+Assumptions!B20+Assumptions!B7+Assumptions!B8))*1000/Assumptions!B6 -> 154539.97 | E6: =(80*10+(Assumptions!B15*Assumptions!C15+Assumptions!B16*Assumptions!C16+Assumptions!B17*Assumptions!C17+Assumptions!B18*Assumptions!C18+Assumptions!B19*Assumptions!C19+Assumptions!B20+Assumptions!B7+Assumptions!B8))*1000/Assumptions!B6 -> 166606.33 | F6: =(80*11+(Assumptions!B15*Assumptions!C15+Assumptions!B16*Assumptions!C16+Assumptions!B17*Assumptions!C17+Assumptions!B18*Assumptions!C18+Assumptions!B19*Assumptions!C19+Assumptions!B20+Assumptions!B7+Assumptions!B8))*1000/Assumptions!B6 -> 178672.7
A7: 120 | B7: =(120*7+(Assumptions!B15*Assumptions!C15+Assumptions!B16*Assumptions!C16+Assumptions!B17*Assumptions!C17+Assumptions!B18*Assumptions!C18+Assumptions!B19*Assumptions!C19+Assumptions!B20+Assumptions!B7+Assumptions!B8))*1000/Assumptions!B6 -> 172639.52 | C7: =(120*8+(Assumptions!B15*Assumptions!C15+Assumptions!B16*Assumptions!C16+Assumptions!B17*Assumptions!C17+Assumptions!B18*Assumptions!C18+Assumptions!B19*Assumptions!C19+Assumptions!B20+Assumptions!B7+Assumptions!B8))*1000/Assumptions!B6 -> 190739.06 | D7: =(120*9+(Assumptions!B15*Assumptions!C15+Assumptions!B16*Assumptions!C16+Assumptions!B17*Assumptions!C17+Assumptions!B18*Assumptions!C18+Assumptions!B19*Assumptions!C19+Assumptions!B20+Assumptions!B7+Assumptions!B8))*1000/Assumptions!B6 -> 208838.61 | E7: =(120*10+(Assumptions!B15*Assumptions!C15+Assumptions!B16*Assumptions!C16+Assumptions!B17*Assumptions!C17+Assumptions!B18*Assumptions!C18+Assumptions!B19*Assumptions!C19+Assumptions!B20+Assumptions!B7+Assumptions!B8))*1000/Assumptions!B6 -> 226938.16 | F7: =(120*11+(Assumptions!B15*Assumptions!C15+Assumptions!B16*Assumptions!C16+Assumptions!B17*Assumptions!C17+Assumptions!B18*Assumptions!C18+Assumptions!B19*Assumptions!C19+Assumptions!B20+Assumptions!B7+Assumptions!B8))*1000/Assumptions!B6 -> 245037.71
A8: 160 | B8: =(160*7+(Assumptions!B15*Assumptions!C15+Assumptions!B16*Assumptions!C16+Assumptions!B17*Assumptions!C17+Assumptions!B18*Assumptions!C18+Assumptions!B19*Assumptions!C19+Assumptions!B20+Assumptions!B7+Assumptions!B8))*1000/Assumptions!B6 -> 214871.79 | C8: =(160*8+(Assumptions!B15*Assumptions!C15+Assumptions!B16*Assumptions!C16+Assumptions!B17*Assumptions!C17+Assumptions!B18*Assumptions!C18+Assumptions!B19*Assumptions!C19+Assumptions!B20+Assumptions!B7+Assumptions!B8))*1000/Assumptions!B6 -> 239004.52 | D8: =(160*9+(Assumptions!B15*Assumptions!C15+Assumptions!B16*Assumptions!C16+Assumptions!B17*Assumptions!C17+Assumptions!B18*Assumptions!C18+Assumptions!B19*Assumptions!C19+Assumptions!B20+Assumptions!B7+Assumptions!B8))*1000/Assumptions!B6 -> 263137.25 | E8: =(160*10+(Assumptions!B15*Assumptions!C15+Assumptions!B16*Assumptions!C16+Assumptions!B17*Assumptions!C17+Assumptions!B18*Assumptions!C18+Assumptions!B19*Assumptions!C19+Assumptions!B20+Assumptions!B7+Assumptions!B8))*1000/Assumptions!B6 -> 287269.98 | F8: =(160*11+(Assumptions!B15*Assumptions!C15+Assumptions!B16*Assumptions!C16+Assumptions!B17*Assumptions!C17+Assumptions!B18*Assumptions!C18+Assumptions!B19*Assumptions!C19+Assumptions!B20+Assumptions!B7+Assumptions!B8))*1000/Assumptions!B6 -> 311402.71
A9: 200 | B9: =(200*7+(Assumptions!B15*Assumptions!C15+Assumptions!B16*Assumptions!C16+Assumptions!B17*Assumptions!C17+Assumptions!B18*Assumptions!C18+Assumptions!B19*Assumptions!C19+Assumptions!B20+Assumptions!B7+Assumptions!B8))*1000/Assumptions!B6 -> 257104.07 | C9: =(200*8+(Assumptions!B15*Assumptions!C15+Assumptions!B16*Assumptions!C16+Assumptions!B17*Assumptions!C17+Assumptions!B18*Assumptions!C18+Assumptions!B19*Assumptions!C19+Assumptions!B20+Assumptions!B7+Assumptions!B8))*1000/Assumptions!B6 -> 287269.98 | D9: =(200*9+(Assumptions!B15*Assumptions!C15+Assumptions!B16*Assumptions!C16+Assumptions!B17*Assumptions!C17+Assumptions!B18*Assumptions!C18+Assumptions!B19*Assumptions!C19+Assumptions!B20+Assumptions!B7+Assumptions!B8))*1000/Assumptions!B6 -> 317435.9 | E9: =(200*10+(Assumptions!B15*Assumptions!C15+Assumptions!B16*Assumptions!C16+Assumptions!B17*Assumptions!C17+Assumptions!B18*Assumptions!C18+Assumptions!B19*Assumptions!C19+Assumptions!B20+Assumptions!B7+Assumptions!B8))*1000/Assumptions!B6 -> 347601.81 | F9: =(200*11+(Assumptions!B15*Assumptions!C15+Assumptions!B16*Assumptions!C16+Assumptions!B17*Assumptions!C17+Assumptions!B18*Assumptions!C18+Assumptions!B19*Assumptions!C19+Assumptions!B20+Assumptions!B7+Assumptions!B8))*1000/Assumptions!B6 -> 377767.72
A10: 240 | B10: =(240*7+(Assumptions!B15*Assumptions!C15+Assumptions!B16*Assumptions!C16+Assumptions!B17*Assumptions!C17+Assumptions!B18*Assumptions!C18+Assumptions!B19*Assumptions!C19+Assumptions!B20+Assumptions!B7+Assumptions!B8))*1000/Assumptions!B6 -> 299336.35 | C10: =(240*8+(Assumptions!B15*Assumptions!C15+Assumptions!B16*Assumptions!C16+Assumptions!B17*Assumptions!C17+Assumptions!B18*Assumptions!C18+Assumptions!B19*Assumptions!C19+Assumptions!B20+Assumptions!B7+Assumptions!B8))*1000/Assumptions!B6 -> 335535.44 | D10: =(240*9+(Assumptions!B15*Assumptions!C15+Assumptions!B16*Assumptions!C16+Assumptions!B17*Assumptions!C17+Assumptions!B18*Assumptions!C18+Assumptions!B19*Assumptions!C19+Assumptions!B20+Assumptions!B7+Assumptions!B8))*1000/Assumptions!B6 -> 371734.54 | E10: =(240*10+(Assumptions!B15*Assumptions!C15+Assumptions!B16*Assumptions!C16+Assumptions!B17*Assumptions!C17+Assumptions!B18*Assumptions!C18+Assumptions!B19*Assumptions!C19+Assumptions!B20+Assumptions!B7+Assumptions!B8))*1000/Assumptions!B6 -> 407933.63 | F10: =(240*11+(Assumptions!B15*Assumptions!C15+Assumptions!B16*Assumptions!C16+Assumptions!B17*Assumptions!C17+Assumptions!B18*Assumptions!C18+Assumptions!B19*Assumptions!C19+Assumptions!B20+Assumptions!B7+Assumptions!B8))*1000/Assumptions!B6 -> 444132.73
A13: DCF: WACC ↓ / terminal growth g →
A14: WACC ↓ / g → | B14: 0.015 | C14: 0.02 | D14: 0.025 | E14: 0.03 | F14: 0.035
A15: 0.075 | B15: 222043 | C15: 235732 | D15: 252160 | E15: 272239 | F15: 297337
A16: 0.08 | B16: 207392 | C16: 218762 | D16: 232200 | E16: 248326 | F16: 268035
A17: 0.085 | B17: 194824 | C17: 204392 | D17: 215555 | E17: 228747 | F17: 244577
A18: 0.09 | B18: 183923 | C18: 192065 | D18: 201458 | E18: 212417 | F18: 225369
A19: 0.095 | B19: 174377 | C19: 181372 | D19: 189365 | E19: 198588 | F19: 209348
A21: DCF grid values are engine-computed (closed-form FCFF). Base ≈ WACC 8.5%, g 2.5%. The DCF stays below the SOTP across most of the grid — capex-heavy cash flows.

Sheet Per-Share & Ratios
A1: PER-SHARE & RATIOS (at spot)
A2: Drivers link to Income Statement / Assumptions. Multiples on elevated forward EPS vs through-cycle.
A5: Share price (KRW, 26-Jun-26) | B5: =Assumptions!B5 -> 339500
A6: Shares outstanding (bn) | B6: =Assumptions!B6 -> 6.63
A7: Market cap (KRW tn) | B7: =B5*B6 -> 2250885
A8: 2026E EPS (KRW) | B8: =Assumptions!B23*1000/B6 -> 30165.913
A9: Normalized EPS (KRW) | B9: =Assumptions!B25*1000/B6 -> 18099.548
A10: BVPS (KRW) | B10: =Assumptions!B9 -> 64000
A11: Net cash per share (KRW) | B11: =Assumptions!B7*1000/B6 -> 17978.884
A12: P/E on 2026E (×) | B12: =B5/B8 -> 11.254425
A13: P/E normalized (×) | B13: =B5/B9 -> 18.757375
A14: P/B (×) | B14: =B5/B10 -> 5.3046875
A15: Net cash as % of market cap | B15: =Assumptions!B7/(B5*B6) -> 5.2956948e-05
A17: Net cash (~KRW 119tn) is ~5–6% of market cap and ~KRW 18,000/share — a valuation floor. P/B ~5x sits far above Samsung's historical 1–1.5x, reflecting the AI re-rating on peak earnings.

Sheet Peer & Sector
A1: PEER & SECTOR CONTEXT — memory / foundry
A2: External sourced data (not model outputs). Verify live before use. As of mid-2026.
A4: Metric | B4: Samsung (005930) | C4: SK Hynix | D4: TSMC / Micron
A5: Forward P/E (×) | B5: ~10–12x (2026E) | C5: ~6–7x | D5: TSMC ~24x
A6: HBM revenue share (Q1-26) | B6: ~21% | C6: ~58% (leader) | D6: Micron ~21%
A7: DRAM revenue share | B7: ~38% (leader) | C7: ~29% | D7: Micron ~22%
A8: NAND revenue share | B8: ~29% (leader) | C8: ~18% | D8: Kioxia ~14%
A9: Foundry share (2025) | B9: ~7% | C9: — | D9: TSMC ~70%
A10: Net cash | B10: ~KRW 119tn (large) | C10: net debt | D10: varies
A11: Q1-26 OP margin | B11: ~43% group / >70% chip | C11: ~72% | D11: —
A13: Samsung leads commodity DRAM/NAND on revenue but trails badly in high-margin HBM (SK Hynix ~58% vs Samsung ~21%) — the crux of the bull/bear debate. Sources: Counterpoint, TrendForce, Omdia (Q1-2026); verify live.
