Workbook

Sheet READ FIRST
A1: Testahil — Sinai Cement Company S.A.E. (EGX: SCEM)
A4: Companion model · Independent Valuation Study · Educational analysis · Not investment advice
A6: What this workbook is. A transparent companion to the SCEM valuation study. Every blue cell is an input;
A7: every black cell is a formula; green cells link across sheets.
A9: IT IS FORMULA-DRIVEN, AND THAT CLAIM IS TESTED. Every figure derivable from a driver is a live formula, so
A10: you can change a blue cell on Assumptions and watch the model reprice. The cost of equity is built from the
A11: risk-free rate NET of the sovereign spread, beta and the premium rather than pasted; the cost of debt is
A12: taxed in the sheet; the weights come from net debt and market capitalisation; the terminal rate is built
A13: from its own components; the glide fractions are visibly derived from the cost-of-debt path; the discount
A14: factors compound; the DCF waterfall chains from margin through EBIT, NOPAT and FCFF to present value; the
A15: terminal block chains from reinvestment = g / return on capital; and the statements, ratios and all four
A16: lenses run off the same cells. A driver test perturbs every input in place and confirms the headline moves.
... A49: No rating and no price target. Fair-value ranges and distributions only.

Sheet Summary
A1: Summary valuation table
A2: Sinai Cement Company S.A.E. · EGX: SCEM · EGP · 06-Aug-2026
B4: Value
A5: Spot price (EGP) | B5: =Assumptions!$B$5
A6: Shares outstanding (mn) | B6: =Assumptions!$B$6
A7: Market capitalisation (EGP mn) | B7: =Assumptions!$B$5*Assumptions!$B$6
A8: Net cash (EGP mn) | B8: =DCF!B36
A9: Enterprise value at spot (EGP mn) | B9: =B7-B8
A11: VALUATION BY LENS
A12: Lens | B12: Value per share (EGP) | C12: Weight | D12: vs spot | E12: Terminal value % of EV
A13: DCF (cash flow) | B13: ='Fundamental Valuation'!B5 | C13: ='Fundamental Valuation'!C5 | D13: =B13/$B$5-1 | E13: =DCF!B33
A14: Relative multiples | B14: ='Fundamental Valuation'!B6 | C14: ='Fundamental Valuation'!C6 | D14: =B14/$B$5-1
A15: Normalised earnings | B15: ='Fundamental Valuation'!B7 | C15: ='Fundamental Valuation'!C7 | D15: =B15/$B$5-1
A16: Asset / replacement cost | B16: ='Fundamental Valuation'!B8 | C16: ='Fundamental Valuation'!C8 | D16: =B16/$B$5-1
A17: Weighted central fair value (EGP) | B17: ='Fundamental Valuation'!D10 | D17: =B17/$B$5-1
A18: Range across the four lenses (EGP) | B18: =MIN(B13:B16) | C18: =MAX(B13:B16)
A19: Vicat tender offer, July 2025 (EGP) — reference, not a value | B19: =Assumptions!$B$86
A21: COST OF CAPITAL AND TERMINAL
A22: Cost of equity — explicit window | B22: =DCF!C45
A23: WACC — explicit window | B23: =DCF!C46
A24: WACC — terminal | B24: =DCF!C53
A25: Terminal growth | B25: =Assumptions!$B$55
A26: Terminal return on invested capital (replacement basis) | B26: =DCF!B24
A27: Terminal value as % of enterprise value | B27: =DCF!B33
A29: Terminal value share is linked live to the DCF sheet in both the lens table and the block above.

Sheet Fundamental Valuation
A1: Fundamental valuation — four lenses
A4: Lens | B4: Value per share (EGP) | C4: Weight | D4: Weighted
A5: DCF (cash flow) | B5: =DCF!B39 | C5: =Assumptions!$B$87 | D5: =B5*C5
A6: Relative multiples | B6: ='Relative & Normalized'!B15 | C6: =Assumptions!$B$88 | D6: =B6*C6
A7: Normalised earnings | B7: ='Relative & Normalized'!B26 | C7: =Assumptions!$B$89 | D7: =B7*C7
A8: Asset / replacement cost | B8: ='Relative & Normalized'!B38 | C8: =Assumptions!$B$90 | D8: =B8*C8
A10: Weighted central fair value (EGP) | D10: =SUM(D5:D8)
A11: Lowest lens | B11: =MIN(B5:B8)
A12: Highest lens | B12: =MAX(B5:B8)
A13: Median lens | B13: =MEDIAN(B5:B8)
A14: Spot price (EGP) | B14: =Assumptions!$B$5
A15: Central versus spot | B15: =D10/B14-1
A16: Terminal value as % of enterprise value (DCF lens) | B16: =DCF!B33
A18: The four lenses disagree by design — the spread between the cash-flow lens and the replacement-cost
A19: lens IS the question this company poses, and averaging it away would hide it.

Sheet Assumptions
A1: Assumptions — every driver, including the whole cost stack
A2: Blue cells are inputs. Nothing below a driver is typed.
A4: MARKET
A5: Spot price | B5: 79 | C5: EGP, close 06-Aug-2026
A6: Shares outstanding | B6: 260.81248 | C6: mn
A7: Statutory tax rate | B7: 0.225
A8: Effective tax rate (historical closure) | B8: 0.32
A9: USD/EGP (spot) | B9: 49.8
A11: PLANT — PHYSICAL
A12: Cement grinding capacity | B12: 3.8 | C12: Mt/yr
A13: Kiln clinker capacity | B13: 2.57 | C13: Mt/yr
A14: Clinker factor | B14: 0.6763 | C14: t clinker / t cement
A15: COST STACK — PHYSICAL AND MARKET DRIVERS
A16: Specific thermal energy | B16: 3.4 | C16: GJ/t clinker
A17: Delivered fuel cost | B17: 4 | C17: USD/GJ
A18: Specific electrical energy | B18: 100 | C18: kWh/t cement
A19: Industrial electricity tariff | B19: 2.6 | C19: EGP/kWh
A20: Raw materials & quarrying | B20: 190 | C20: EGP/t cement
A21: Packaging | B21: 55 | C21: EGP/t bagged
A22: Bagged share of despatches | B22: 0.7
A23: Distribution & selling | B23: 250 | C23: EGP/t cement
A24: Fixed cash cost | B24: 14.6 | C24: USD/t of capacity
A26: FORECAST PATHS — FY2025A then FY2026E to FY2030E
B27: FY2025A | C27: FY2026E | D27: FY2027E | E27: FY2028E | F27: FY2029E | G27: FY2030E
A28: Kiln utilisation | B28: 0.71 | C28: 0.717 | D28: 0.735 | E28: 0.753 | F28: 0.772 | G28: 0.791
A29: Domestic share of despatches | B29: 0.88 | C29: 0.87 | D29: 0.86 | E29: 0.85 | F29: 0.84 | G29: 0.83
A30: Domestic realised price | B30: 3503 | C30: 3713 | D30: 3880 | E30: 4074 | F30: 4297 | G30: 4512 | I30: EGP/t
A31: Export price | B31: 48 | C31: 47 | D31: 46 | E31: 45.5 | F31: 45 | G31: 45 | I31: USD/t
A32: USD/EGP path | B32: 49.8 | C32: 52.5 | D32: 55 | E32: 57.2 | F32: 59.3 | G32: 61.4
A33: Local cost inflation index | B33: 1 | C33: 1.14 | D33: 1.265 | E33: 1.365 | F33: 1.45 | G33: 1.53
A35: CAPITAL INTENSITY (FY2026E to FY2030E)
A36: D&A / revenue | B36: 0.046 | C36: 0.045 | D36: 0.044 | E36: 0.043 | F36: 0.042
A37: Capex / revenue | B37: 0.05 | C37: 0.048 | D37: 0.047 | E37: 0.046 | F37: 0.045
A38: Cost-of-debt path | B38: 0.215 | C38: 0.195 | D38: 0.18 | E38: 0.168 | F38: 0.16
A39: Yield earned on cash | B39: 0.19 | C39: 0.17 | D39: 0.15 | E39: 0.135 | F39: 0.125
A40: Delta working capital / delta revenue | B40: 0.08
A41: Dividend payout ratio | B41: 0.6
A42: Yield on cash, FY2025 | B42: 0.21
A44: COST OF CAPITAL
A45: Risk-free rate (EGP 10-year) | B45: 0.2231
...

Sheet EV Bridge
A1: Enterprise value to equity bridge
B4: EGP mn | C4: Per share (EGP)
A5: Present value of explicit free cash flow | B5: =DCF!B30 | C5: =B5/Assumptions!$B$6
A6: Present value of terminal value | B6: =DCF!B31 | C6: =B6/Assumptions!$B$6
A7: Enterprise value | B7: =DCF!B32 | C7: =B7/Assumptions!$B$6
A8: Plus net cash | B8: =DCF!B36 | C8: =B8/Assumptions!$B$6
A9: Equity value | B9: =DCF!B37 | C9: =B9/Assumptions!$B$6
A11: Terminal value as % of enterprise value | B11: =DCF!B33
A12: Memo: spot price | C12: =Assumptions!$B$5
A13: Memo: Vicat tender offer price (July 2025) | C13: =Assumptions!$B$86
A14: Fair value less spot | C14: =C9-C12
A15: Upside / (downside) to the cash-flow lens | C15: =C9/C12-1
A17: Terminal value share is linked live to the DCF sheet — never typed. The tender offer price is a
A18: disclosed reference point and an overhang, not a valuation.

Sheet Unit Build
A1: Bottom-up build — physical units in, EBITDA out
A2: EBITDA is a RESULT of this sheet, never an input.
B4: FY2025A | C4: FY2026E | D4: FY2027E | E4: FY2028E | F4: FY2029E | G4: FY2030E
A5: Kiln clinker capacity (Mt/yr) | B5: =Assumptions!$B$13 | C5: =Assumptions!$B$13 | D5: =Assumptions!$B$13 | E5: =Assumptions!$B$13 | F5: =Assumptions!$B$13 | G5: =Assumptions!$B$13
A6: Kiln utilisation | B6: =Assumptions!$B$28 | C6: =Assumptions!$C$28 | D6: =Assumptions!$D$28 | E6: =Assumptions!$E$28 | F6: =Assumptions!$F$28 | G6: =Assumptions!$G$28
A7: Clinker produced (Mt) | B7: =B5*B6 | C7: =C5*C6 | D7: =D5*D6 | E7: =E5*E6 | F7: =F5*F6 | G7: =G5*G6
A8: Cement grinding capacity (Mt/yr) | B8: =Assumptions!$B$12 | C8: =Assumptions!$B$12 | D8: =Assumptions!$B$12 | E8: =Assumptions!$B$12 | F8: =Assumptions!$B$12 | G8: =Assumptions!$B$12
A9: Clinker factor (t clinker / t cement) | B9: =Assumptions!$B$14 | C9: =Assumptions!$B$14 | D9: =Assumptions!$B$14 | E9: =Assumptions!$B$14 | F9: =Assumptions!$B$14 | G9: =Assumptions!$B$14
A10: Cement produced (Mt) | B10: =B7/B9 | C10: =C7/C9 | D10: =D7/D9 | E10: =E7/E9 | F10: =F7/F9 | G10: =G7/G9
A11: Domestic share | B11: =Assumptions!$B$29 | C11: =Assumptions!$C$29 | D11: =Assumptions!$D$29 | E11: =Assumptions!$E$29 | F11: =Assumptions!$F$29 | G11: =Assumptions!$G$29
A12: Domestic volume (Mt) | B12: =B10*B11 | C12: =C10*C11 | D12: =D10*D11 | E12: =E10*E11 | F12: =F10*F11 | G12: =G10*G11
A13: Export volume (Mt) | B13: =B10-B12 | C13: =C10-C12 | D13: =D10-D12 | E13: =E10-E12 | F13: =F10-F12 | G13: =G10-G12
A14: Domestic price (EGP/t) | B14: =Assumptions!$B$30 | C14: =Assumptions!$C$30 | D14: =Assumptions!$D$30 | E14: =Assumptions!$E$30 | F14: =Assumptions!$F$30 | G14: =Assumptions!$G$30
A15: Export price (USD/t) | B15: =Assumptions!$B$31 | C15: =Assumptions!$C$31 | D15: =Assumptions!$D$31 | E15: =Assumptions!$E$31 | F15: =Assumptions!$F$31 | G15: =Assumptions!$G$31
A16: USD/EGP | B16: =Assumptions!$B$32 | C16: =Assumptions!$C$32 | D16: =Assumptions!$D$32 | E16: =Assumptions!$E$32 | F16: =Assumptions!$F$32 | G16: =Assumptions!$G$32
A17: Domestic revenue (EGP mn) | B17: =B12*B14 | C17: =C12*C14 | D17: =D12*D14 | E17: =E12*E14 | F17: =F12*F14 | G17: =G12*G14
A18: Export revenue (EGP mn) | B18: =B13*B15*B16 | C18: =C13*C15*C16 | D18: =D13*D15*D16 | E18: =E13*E15*E16 | F18: =F13*F15*F16 | G18: =G13*G15*G16
A19: REVENUE (EGP mn) | B19: =B17+B18 | C19: =C17+C18 | D19: =D17+D18 | E19: =E17+E18 | F19: =F17+F18 | G19: =G17+G18
A20: Blended realised price (EGP/t) | B20: =B19/B10 | C20: =C19/C10 | D20: =D19/D10 | E20: =E19/E10 | F20: =F19/F10 | G20: =G19/G10
A22: COST STACK — EGP PER TONNE OF CEMENT
A23: Thermal fuel | B23: =Assumptions!$B$16*B9*Assumptions!$B$17*B16 | C23: =Assumptions!$B$16*C9*Assumptions!$B$17*C16 | D23: =Assumptions!$B$16*D9*Assumptions!$B$17*D16 | E23: =Assumptions!$B$16*E9*Assumptions!$B$17*E16 | F23: =Assumptions!$B$16*F9*Assumptions!$B$17*F16 | G23: =Assumptions!$B$16*G9*Assumptions!$B$17*G16
A24: Electrical power | B24: =Assumptions!$B$18*Assumptions!$B$19*Assumptions!$B$33 | C24: =Assumptions!$B$18*Assumptions!$B$19*Assumptions!$C$33 | D24: =Assumptions!$B$18*Assumptions!$B$19*Assumptions!$D$33 | E24: =Assumptions!$B$18*Assumptions!$B$19*Assumptions!$E$33 | F24: =Assumptions!$B$18*Assumptions!$B$19*Assumptions!$F$33 | G24: =Assumptions!$B$18*Assumptions!$B$19*Assumptions!$G$33
A25: Raw materials & quarrying | B25: =Assumptions!$B$20*Assumptions!$B$33 | C25: =Assumptions!$B$20*Assumptions!$C$33 | D25: =Assumptions!$B$20*Assumptions!$D$33 | E25: =Assumptions!$B$20*Assumptions!$E$33 | F25: =Assumptions!$B$20*Assumptions!$F$33 | G25: =Assumptions!$B$20*Assumptions!$G$33
A26: Packaging | B26: =Assumptions!$B$21*Assumptions!$B$22*Assumptions!$B$33 | C26: =Assumptions!$B$21*Assumptions!$B$22*Assumptions!$C$33 | D26: =Assumptions!$B$21*Assumptions!$B$22*Assumptions!$D$33 | E26: =Assumptions!$B$21*Assumptions!$B$22*Assumptions!$E$33 | F26: =Assumptions!$B$21*Assumptions!$B$22*Assumptions!$F$33 | G26: =Assumptions!$B$21*Assumptions!$B$22*Assumptions!$G$33
A27: Distribution & selling | B27: =Assumptions!$B$23*Assumptions!$B$33 | C27: =Assumptions!$B$23*Assumptions!$C$33 | D27: =Assumptions!$B$23*Assumptions!$D$33 | E27: =Assumptions!$B$23*Assumptions!$E$33 | F27: =Assumptions!$B$23*Assumptions!$F$33 | G27: =Assumptions!$B$23*Assumptions!$G$33
A28: TOTAL VARIABLE (EGP/t) | B28: =SUM(B23:B27) | C28: =SUM(C23:C27) | D28: =SUM(D23:D27) | E28: =SUM(E23:E27) | F28: =SUM(F23:F27) | G28: =SUM(G23:G27)
A30: PROFIT AND LOSS — EGP MILLION
A31: Revenue | B31: =B19 | C31: =C19 | D31: =D19 | E31: =E19 | F31: =F19 | G31: =G19
A32: Variable cost | B32: =B28*B10 | C32: =C28*C10 | D32: =D28*D10 | E32: =E28*E10 | F32: =F28*F10 | G32: =G28*G10
A33: Fixed cost | B33: =Assumptions!$B$24*B8*Assumptions!$B$9*Assumptions!$B$33 | C33: =Assumptions!$B$24*C8*Assumptions!$B$9*Assumptions!$C$33 | D33: =Assumptions!$B$24*D8*Assumptions!$B$9*Assumptions!$D$33 | E33: =Assumptions!$B$24*E8*Assumptions!$B$9*Assumptions!$E$33 | F33: =Assumptions!$B$24*F8*Assumptions!$B$9*Assumptions!$F$33 | G33: =Assumptions!$B$24*G8*Assumptions!$B$9*Assumptions!$G$33
A34: EBITDA (AN OUTPUT) | B34: =B31-B32-B33 | C34: =C31-C32-C33 | D34: =D31-D32-D33 | E34: =E31-E32-E33 | F34: =F31-F32-F33 | G34: =G31-G32-G33
A35: EBITDA margin | B35: =B34/B31 | C35: =C34/C31 | D35: =D34/D31 | E35: =E34/E31 | F35: =F34/F31 | G35: =G34/G31
A36: EBITDA per tonne (EGP) | B36: =B34/B10 | C36: =C34/C10 | D36: =D34/D10 | E36: =E34/E10 | F36: =F34/F10 | G36: =G34/G10
A38: VALIDATION — A TEST THAT CAN FAIL
A39: Bottom-up FY2025 revenue | B39: =B19
A40: Disclosed FY2025 revenue | B40: =Assumptions!$B$64
A41: Difference | B41: =B39/B40-1
A42: Bottom-up FY2025 EBITDA | B42: =B34
A43: EBITDA implied by closing disclosed profit | B43: ='Income Statement'!D6
A44: Difference | B44: =B42/B43-1
...

Sheet Relative & Normalized
A1: Relative multiples, normalised earnings and the asset lens
A4: RELATIVE — EV/EBITDA ON MID-CYCLE EARNINGS
A5: FY2025 revenue (disclosed) | B5: =Assumptions!$B$64
A6: Normalised revenue haircut | B6: =Assumptions!$B$85
A7: Normalised revenue base | B7: =B5*B6
A8: Mid-cycle EBITDA margin | B8: =Assumptions!$B$84
A9: Normalised EBITDA | B9: =B7*B8
A10: Justified EV/EBITDA | B10: =Assumptions!$B$82
A11: Implied enterprise value | B11: =B9*B10
A12: Plus net cash | B12: =DCF!B36
A13: Less non-controlling interests | B13: =-Assumptions!$B$61
A14: Implied equity value | B14: =B11+B12+B13
A15: Implied value per share (EGP) | B15: =B14/Assumptions!$B$6
A17: NORMALISED EARNINGS POWER
A18: Normalised EBITDA | B18: =B9
A19: Less D&A (FY2025) | B19: =-'Income Statement'!D8
A20: Normalised EBIT | B20: =B18+B19
A21: Normalised NOPAT | B21: =B20*(1-Assumptions!$B$7)
A22: Justified price/earnings | B22: =Assumptions!$B$83
A23: Operating equity value | B23: =B21*B22
A24: Plus net cash AT FACE (not capitalised) | B24: =DCF!B36
A25: Less non-controlling interests | B25: =-Assumptions!$B$61
A26: Implied value per share (EGP) | B26: =(B23+B24+B25)/Assumptions!$B$6
A28: ASSET LENS — EV PER TONNE OF CAPACITY (the cement sector yardstick)
A29: Enterprise value at spot (EGP mn) | B29: =Assumptions!$B$5*Assumptions!$B$6-DCF!B36
A30: Capacity (annual tonnes) | B30: =Assumptions!$B$12*1000000
A31: EV per tonne at spot (USD/t) | B31: =B29*1000000/B30/Assumptions!$B$9
A32: Replacement cost (USD/t) | B32: =Assumptions!$B$80
A33: Discount to replacement cost | B33: =B31/B32-1
A34: Justified EV per tonne (USD/t) | B34: =Assumptions!$B$81
A35: Implied enterprise value (EGP mn) | B35: =B34*B30*Assumptions!$B$9/1000000
A36: Plus net cash | B36: =DCF!B36
A37: Less non-controlling interests | B37: =-Assumptions!$B$61
A38: Implied value per share (EGP) | B38: =(B35+B36+B37)/Assumptions!$B$6
A40: MEMO — BOOK, SHOWN BUT NOT USED AS A LENS
A41: Book value per share (EGP) | B41: ='Balance Sheet'!D12/Assumptions!$B$74
A42: Sustainable return on equity | B42: =B21/'Balance Sheet'!D12
A44: A book/return lens is deliberately NOT one of the four. The El Hassana plant commissioned in 1997 and
A45: is carried at historic cost through a five-fold devaluation, so book value measures the accounting
A46: rather than the asset. The cement sector's own yardstick — enterprise value per annual tonne of
...

Sheet DCF
A1: Discounted cash flow — the primary lens
A2: Cost of capital built here, never pasted.
B4: FY2026E | C4: FY2027E | D4: FY2028E | E4: FY2029E | F4: FY2030E
A5: Revenue | B5: ='Unit Build'!C31 | C5: ='Unit Build'!D31 | D5: ='Unit Build'!E31 | E5: ='Unit Build'!F31 | F5: ='Unit Build'!G31
A6: EBITDA margin | B6: =B7/B5 | C6: =C7/C5 | D6: =D7/D5 | E6: =E7/E5 | F6: =F7/F5
A7: EBITDA | B7: ='Unit Build'!C34 | C7: ='Unit Build'!D34 | D7: ='Unit Build'!E34 | E7: ='Unit Build'!F34 | F7: ='Unit Build'!G34
A8: Depreciation & amortisation | B8: =B5*Assumptions!$B$36 | C8: =C5*Assumptions!$C$36 | D8: =D5*Assumptions!$D$36 | E8: =E5*Assumptions!$E$36 | F8: =F5*Assumptions!$F$36
A9: EBIT | B9: =B7-B8 | C9: =C7-C8 | D9: =D7-D8 | E9: =E7-E8 | F9: =F7-F8
A10: Tax rate | B10: =Assumptions!$B$7 | C10: =Assumptions!$B$7 | D10: =Assumptions!$B$7 | E10: =Assumptions!$B$7 | F10: =Assumptions!$B$7
A11: NOPAT (EBIT × (1 − t)) | B11: =B9*(1-B10) | C11: =C9*(1-C10) | D11: =D9*(1-D10) | E11: =E9*(1-E10) | F11: =F9*(1-F10)
A12: Memo: capital expenditure | B12: =B5*Assumptions!$B$37 | C12: =C5*Assumptions!$C$37 | D12: =D5*Assumptions!$D$37 | E12: =E5*Assumptions!$E$37 | F12: =F5*Assumptions!$F$37
A13: Memo: change in working capital | B13: =(B5-Assumptions!$B$64)*Assumptions!$B$40 | C13: =(C5-B5)*Assumptions!$B$40 | D13: =(D5-C5)*Assumptions!$B$40 | E13: =(E5-D5)*Assumptions!$B$40 | F13: =(F5-E5)*Assumptions!$B$40
A14: Net reinvestment (growth ÷ terminal ROIC) | B14: =MAX(B11-$B$23,0)/$B$24 | C14: =MAX(C11-B11,0)/$B$24 | D14: =MAX(D11-C11,0)/$B$24 | E14: =MAX(E11-D11,0)/$B$24 | F14: =MAX(F11-E11,0)/$B$24
A15: Free cash flow to the firm | B15: =(B11-B14)*(1-Assumptions!$B$56) | C15: =C11-C14 | D15: =D11-D14 | E15: =E11-E14 | F15: =F11-F14
A16: Glide fraction | B16: =(Assumptions!$B$38-Assumptions!$B$38)/(Assumptions!$B$38-Assumptions!$F$38) | C16: =(Assumptions!$B$38-Assumptions!$C$38)/(Assumptions!$B$38-Assumptions!$F$38) | D16: =(Assumptions!$B$38-Assumptions!$D$38)/(Assumptions!$B$38-Assumptions!$F$38) | E16: =(Assumptions!$B$38-Assumptions!$E$38)/(Assumptions!$B$38-Assumptions!$F$38) | F16: =(Assumptions!$B$38-Assumptions!$F$38)/(Assumptions!$B$38-Assumptions!$F$38)
A17: Forward cost of capital | B17: =$C$46-($C$46-$C$53)*B16 | C17: =$C$46-($C$46-$C$53)*C16 | D17: =$C$46-($C$46-$C$53)*D16 | E17: =$C$46-($C$46-$C$53)*E16 | F17: =$C$46-($C$46-$C$53)*F16
A18: Discount factor | B18: =1/(1+B17)^((1-Assumptions!$B$56)/2) | C18: =1/(1+B17)^(1-Assumptions!$B$56+0.5) | D18: =1/((1+B17)*(1+C17)^(1-Assumptions!$B$56+0.5)) | E18: =1/((1+B17)*(1+C17)*(1+D17)^(1-Assumptions!$B$56+0.5)) | F18: =1/((1+B17)*(1+C17)*(1+D17)*(1+E17)^(1-Assumptions!$B$56+0.5))
A19: Present value of FCFF | B19: =B15*B18 | C19: =C15*C18 | D19: =D15*D18 | E19: =E15*E18 | F19: =F15*F18
A21: TERMINAL BLOCK
A22: Replacement-cost invested capital (EGP mn) | B22: =Assumptions!$B$12*1000000*Assumptions!$B$80*Assumptions!$B$9/1000000
A23: FY2025 NOPAT (the reinvestment base) | B23: =('Income Statement'!D6-'Income Statement'!D8)*(1-Assumptions!$B$7)
A24: Terminal return on invested capital | B24: =F11*(1+Assumptions!$B$55)/B22
A25: Reinvestment rate (g ÷ ROIC) | B25: =Assumptions!$B$55/B24
A26: Terminal value | B26: =B28*(1-B25)/($C$53-Assumptions!$B$55)
A27: Present value of terminal value | B27: =B26*F18
A28: Terminal NOPAT | B28: =F11*(1+Assumptions!$B$55)
A29: ENTERPRISE TO EQUITY BRIDGE
A30: Present value of explicit years (FY2026E-FY2030E) | B30: =SUM(B19:F19)
A31: Present value of terminal value | B31: =B27
A32: Enterprise value | B32: =B30+B31
A33: Terminal value as % of enterprise value | B33: =B31/B32
A34: Cash at the valuation date | B34: ='Balance Sheet'!D7+B15/(1-Assumptions!$B$56)*Assumptions!$B$56
A35: Less gross debt | B35: =-Assumptions!$B$50
A36: Net cash (ADDED — the company is net cash) | B36: =B34+B35
A37: Equity value | B37: =B32+B36-B40
A38: Shares outstanding (mn) | B38: =Assumptions!$B$6
A39: Fair value per share (EGP) | B39: =B37/B38
A40: Less non-controlling interests | B40: =Assumptions!$B$61
A41: COST OF CAPITAL — BUILT HERE
A42: Risk-free rate (observed EGP 10-year) | C42: =Assumptions!$B$45
...

Sheet Income Statement
A1: Income statement — 3 years historical + 5-year forecast
A2: EGP mn
B4: FY2023 | C4: FY2024 | D4: FY2025 | E4: FY2026E | F4: FY2027E | G4: FY2028E | H4: FY2029E | I4: FY2030E
A5: Revenue | B5: =Assumptions!$B$62 | C5: =Assumptions!$B$63 | D5: =Assumptions!$B$64 | E5: =DCF!B5 | F5: =DCF!C5 | G5: =DCF!D5 | H5: =DCF!E5 | I5: =DCF!F5
A6: EBITDA | B6: =B9+B8 | C6: =C9+C8 | D6: =D9+D8 | E6: =DCF!B7 | F6: =DCF!C7 | G6: =DCF!D7 | H6: =DCF!E7 | I6: =DCF!F7
A7: EBITDA margin | B7: =B6/B5 | C7: =C6/C5 | D7: =D6/D5 | E7: =E6/E5 | F7: =F6/F5 | G7: =G6/G5 | H7: =H6/H5 | I7: =I6/I5
A8: Depreciation & amortisation | B8: =B5*Assumptions!$B$75 | C8: =C5*Assumptions!$B$76 | D8: =D5*Assumptions!$B$77 | E8: =DCF!B8 | F8: =DCF!C8 | G8: =DCF!D8 | H8: =DCF!E8 | I8: =DCF!F8
A9: EBIT | B9: =B14-B10 | C9: =Assumptions!$B$68-C8 | D9: =D14/(1-Assumptions!$B$8)-D10 | E9: =E6-E8 | F9: =F6-F8 | G9: =G6-G8 | H9: =H6-H8 | I9: =I6-I8
A10: Treasury / investment income | B10: =Assumptions!$B$71 | C10: =Assumptions!$B$59/1.25*0.9*Assumptions!$B$42 | D10: =(Assumptions!$B$59+Assumptions!$B$59/1.25)/2*Assumptions!$B$42 | E10: ='Balance Sheet'!D7*Assumptions!$B$39 | F10: ='Balance Sheet'!E7*Assumptions!$C$39 | G10: ='Balance Sheet'!F7*Assumptions!$D$39 | H10: ='Balance Sheet'!G7*Assumptions!$E$39 | I10: ='Balance Sheet'!H7*Assumptions!$F$39
A11: Gain on disposal of Sinai White stake | B11: =0 | C11: =Assumptions!$B$92*Assumptions!$B$93-Assumptions!$B$94 | D11: =0 | E11: =0 | F11: =0 | G11: =0 | H11: =0 | I11: =0
A12: Profit before tax | B12: =B9+B10+B11 | C12: =C9+C10+C11 | D12: =D9+D10+D11 | E12: =E9+E10+E11 | F12: =F9+F10+F11 | G12: =G9+G10+G11 | H12: =H9+H10+H11 | I12: =I9+I10+I11
A13: Tax | B13: =B12-B14 | C13: =C12-C14 | D13: =D12-D14 | E13: =E12*Assumptions!$B$7 | F13: =F12*Assumptions!$B$7 | G13: =G12*Assumptions!$B$7 | H13: =H12*Assumptions!$B$7 | I13: =I12*Assumptions!$B$7
A14: Profit after tax | B14: =Assumptions!$B$65 | C14: =Assumptions!$B$66 | D14: =Assumptions!$B$67 | E14: =E12-E13 | F14: =F12-F13 | G14: =G12-G13 | H14: =H12-H13 | I14: =I12-I13
A15: Profit after tax — disclosed | B15: =Assumptions!$B$65 | C15: =Assumptions!$B$66 | D15: =Assumptions!$B$67
A16: Earnings per share (EGP) | B16: =B14/Assumptions!$B$72 | C16: =C14/Assumptions!$B$73 | D16: =D14/Assumptions!$B$74 | E16: =E14/Assumptions!$B$6 | F16: =F14/Assumptions!$B$6 | G16: =G14/Assumptions!$B$6 | H16: =H14/Assumptions!$B$6 | I16: =I14/Assumptions!$B$6
A18: DERIVED LINES, stated plainly. Revenue and profit after tax are DISCLOSED (rows 5 and 15, in green).
A19: EBITDA, D&A, EBIT and treasury income for the historical years are DERIVED by closing the disclosed
A20: profit: FY2024 anchors on the one disclosed EBITDA figure and solves treasury income; FY2025 solves
A21: EBIT from disclosed profit after tax; FY2023 uses its own smaller cash balance. Row 13 is the residual
A22: tax charge, and row 15 sits beside row 14 so the reader can see the derivation closes to the print.

Sheet Balance Sheet
A1: Balance sheet — 3 years historical + 5-year forecast
A2: EGP mn
B4: FY2023 | C4: FY2024 | D4: FY2025 | E4: FY2026E | F4: FY2027E | G4: FY2028E | H4: FY2029E | I4: FY2030E
A5: Property, plant and equipment (net) | B5: 2285.624 | C5: =Assumptions!$B$69-C6-C7 | D5: =C5 | E5: =D5+DCF!B12-DCF!B8 | F5: =E5+DCF!C12-DCF!C8 | G5: =F5+DCF!D12-DCF!D8 | H5: =G5+DCF!E12-DCF!E8 | I5: =H5+DCF!F12-DCF!F8
A6: Working capital (net) | B6: 850 | C6: 900 | D6: =C6 | E6: =D6+DCF!B13 | F6: =E6+DCF!C13 | G6: =F6+DCF!D13 | H6: =G6+DCF!E13 | I6: =H6+DCF!F13
A7: Cash and equivalents | B7: 1078 | C7: =Assumptions!$B$59/1.25 | D7: =Assumptions!$B$59 | E7: =D7+'Cash Flow'!E14 | F7: =E7+'Cash Flow'!F14 | G7: =F7+'Cash Flow'!G14 | H7: =G7+'Cash Flow'!H14 | I7: =H7+'Cash Flow'!I14
A8: Total assets (condensed) | B8: =SUM(B5:B7) | C8: =Assumptions!$B$69 | D8: =SUM(D5:D7) | E8: =SUM(E5:E7) | F8: =SUM(F5:F7) | G8: =SUM(G5:G7) | H8: =SUM(H5:H7) | I8: =SUM(I5:I7)
A9: Gross debt | B9: =Assumptions!$B$50 | C9: =Assumptions!$B$50 | D9: =Assumptions!$B$50 | E9: =Assumptions!$B$50 | F9: =Assumptions!$B$50 | G9: =Assumptions!$B$50 | H9: =Assumptions!$B$50 | I9: =Assumptions!$B$50
A10: Other liabilities | B10: =B11-B9 | C10: =C11-C9 | D10: =D11-D9 | E10: =E11-E9 | F10: =F11-F9 | G10: =G11-G9 | H10: =H11-H9 | I10: =I11-I9
A11: Total liabilities | B11: =B8-B12 | C11: =Assumptions!$B$70 | D11: =D8-D12 | E11: =E8-E12 | F11: =F8-F12 | G11: =G8-G12 | H11: =H8-H12 | I11: =I8-I12
A12: Shareholders' equity | B12: =C12-Assumptions!$B$66 | C12: =C8-C11 | D12: =Assumptions!$B$60 | E12: =D12+'Income Statement'!E14-'Cash Flow'!E13 | F12: =E12+'Income Statement'!F14-'Cash Flow'!F13 | G12: =F12+'Income Statement'!G14-'Cash Flow'!G13 | H12: =G12+'Income Statement'!H14-'Cash Flow'!H13 | I12: =H12+'Income Statement'!I14-'Cash Flow'!I13
A13: Equity — reported cross-check | D13: =C12+Assumptions!$B$67
A14: Net cash | B14: =B7-B9 | C14: =C7-C9 | D14: =D7-D9 | E14: =E7-E9 | F14: =F7-F9 | G14: =G7-G9 | H14: =H7-H9 | I14: =I7-I9
A15: Return on equity | D15: =Assumptions!$B$67/D12 | E15: ='Income Statement'!E14/E12 | F15: ='Income Statement'!F14/F12 | G15: ='Income Statement'!G14/G12 | H15: ='Income Statement'!H14/H12 | I15: ='Income Statement'!I14/I12
A17: The FY2024 column is the DISCLOSED triple — total assets EGP 6,385.92mn less total liabilities EGP
A18: 1,610.86mn closes to equity of EGP 4,775.06mn exactly. Equity then ROLLS FORWARD: prior equity plus
A19: profit less dividends. Row 13 carries the REPORTED FY2025 equity beside the rolled figure: the two do
A20: not agree, and the gap implies a FY2025 distribution that no retrievable source reports. Disclosed, not
A21: plugged. Row 11 is the residual liability block, not an independently sourced line.

Sheet Cash Flow
A1: Cash flow — linked to the DCF waterfall
A2: EGP mn
E4: FY2026E | F4: FY2027E | G4: FY2028E | H4: FY2029E | I4: FY2030E
A5: EBITDA | E5: =DCF!B7 | F5: =DCF!C7 | G5: =DCF!D7 | H5: =DCF!E7 | I5: =DCF!F7
A6: Less change in working capital | E6: =-DCF!B13 | F6: =-DCF!C13 | G6: =-DCF!D13 | H6: =-DCF!E13 | I6: =-DCF!F13
A7: Less capital expenditure | E7: =-DCF!B12 | F7: =-DCF!C12 | G7: =-DCF!D12 | H7: =-DCF!E12 | I7: =-DCF!F12
A8: Operating free cash flow | E8: =SUM(E5:E7) | F8: =SUM(F5:F7) | G8: =SUM(G5:G7) | H8: =SUM(H5:H7) | I8: =SUM(I5:I7)
A9: NOPAT | E9: =DCF!B11 | F9: =DCF!C11 | G9: =DCF!D11 | H9: =DCF!E11 | I9: =DCF!F11
A10: Less net reinvestment (growth at terminal ROIC) | E10: =-DCF!B14 | F10: =-DCF!C14 | G10: =-DCF!D14 | H10: =-DCF!E14 | I10: =-DCF!F14
A11: Free cash flow to the firm | E11: =DCF!B15 | F11: =DCF!C15 | G11: =DCF!D15 | H11: =DCF!E15 | I11: =DCF!F15
A12: Treasury income after tax | E12: ='Income Statement'!E10*(1-Assumptions!$B$7) | F12: ='Income Statement'!F10*(1-Assumptions!$B$7) | G12: ='Income Statement'!G10*(1-Assumptions!$B$7) | H12: ='Income Statement'!H10*(1-Assumptions!$B$7) | I12: ='Income Statement'!I10*(1-Assumptions!$B$7)
A13: Dividends paid | E13: ='Income Statement'!E14*Assumptions!$B$41 | F13: ='Income Statement'!F14*Assumptions!$B$41 | G13: ='Income Statement'!G14*Assumptions!$B$41 | H13: ='Income Statement'!H14*Assumptions!$B$41 | I13: ='Income Statement'!I14*Assumptions!$B$41
A14: Net change in cash | E14: ='Income Statement'!E14+DCF!B8-DCF!B12-DCF!B13-E13 | F14: ='Income Statement'!F14+DCF!C8-DCF!C12-DCF!C13-F13 | G14: ='Income Statement'!G14+DCF!D8-DCF!D12-DCF!D13-G13 | H14: ='Income Statement'!H14+DCF!E8-DCF!E12-DCF!E13-H13 | I14: ='Income Statement'!I14+DCF!F8-DCF!F12-DCF!F13-I13
A18: Two presentations of the same year. Rows 5-8 build operating free cash flow from EBITDA; rows 9-13
A19: are the DCF waterfall's own free cash flow to the firm, linked cell-for-cell to the DCF sheet so the
A20: two can never drift. Treasury income is shown separately and is NOT in free cash flow to the firm.

Sheet Summary Financials
A1: Summary financials
A2: EGP mn unless stated
B4: FY2023 | C4: FY2024 | D4: FY2025 | E4: FY2026E | F4: FY2027E | G4: FY2028E | H4: FY2029E | I4: FY2030E
A5: Revenue | B5: ='Income Statement'!B5 | C5: ='Income Statement'!C5 | D5: ='Income Statement'!D5 | E5: ='Income Statement'!E5 | F5: ='Income Statement'!F5 | G5: ='Income Statement'!G5 | H5: ='Income Statement'!H5 | I5: ='Income Statement'!I5
A6: EBITDA | B6: ='Income Statement'!B6 | C6: ='Income Statement'!C6 | D6: ='Income Statement'!D6 | E6: ='Income Statement'!E6 | F6: ='Income Statement'!F6 | G6: ='Income Statement'!G6 | H6: ='Income Statement'!H6 | I6: ='Income Statement'!I6
A7: EBIT | B7: ='Income Statement'!B9 | C7: ='Income Statement'!C9 | D7: ='Income Statement'!D9 | E7: ='Income Statement'!E9 | F7: ='Income Statement'!F9 | G7: ='Income Statement'!G9 | H7: ='Income Statement'!H9 | I7: ='Income Statement'!I9
A8: Profit after tax | B8: ='Income Statement'!B14 | C8: ='Income Statement'!C14 | D8: ='Income Statement'!D14 | E8: ='Income Statement'!E14 | F8: ='Income Statement'!F14 | G8: ='Income Statement'!G14 | H8: ='Income Statement'!H14 | I8: ='Income Statement'!I14
A9: Sales volume (Mt) | D9: ='Unit Build'!B10 | E9: ='Unit Build'!C10 | F9: ='Unit Build'!D10 | G9: ='Unit Build'!E10 | H9: ='Unit Build'!F10 | I9: ='Unit Build'!G10
A10: Realised price (EGP/t) | D10: ='Unit Build'!B20 | E10: ='Unit Build'!C20 | F10: ='Unit Build'!D20 | G10: ='Unit Build'!E20 | H10: ='Unit Build'!F20 | I10: ='Unit Build'!G20
A11: Kiln utilisation | D11: ='Unit Build'!B6 | E11: ='Unit Build'!C6 | F11: ='Unit Build'!D6 | G11: ='Unit Build'!E6 | H11: ='Unit Build'!F6 | I11: ='Unit Build'!G6
A13: EBITDA margin | B13: =B6/B5 | C13: =C6/C5 | D13: =D6/D5 | E13: =E6/E5 | F13: =F6/F5 | G13: =G6/G5 | H13: =H6/H5 | I13: =I6/I5
A14: Revenue growth | C14: =C5/B5-1 | D14: =D5/C5-1 | E14: =E5/D5-1 | F14: =F5/E5-1 | G14: =G5/F5-1 | H14: =H5/G5-1 | I14: =I5/H5-1

Sheet Monte Carlo
A1: Probabilistic price map
A2: PASTED — a whole-model re-run. Does NOT redraw when a driver changes.
A4: Horizon | B4: Sessions | C4: Grade date | D4: 5th %ile | E4: 25th %ile | F4: Median | G4: 75th %ile | H4: 95th %ile
A5: 1M (1 month) | B5: 20 | C5: 2026-09-06 | D5: 62.142064 | E5: 72.943312 | F5: 80.174975 | G5: 88.183977 | H5: 103.4995
A6: 3M (3 months) | B6: 62 | C6: 2026-11-08 | D6: 52.125777 | E6: 69.749731 | F6: 82.778762 | G6: 98.073952 | H6: 131.35227
B8: P(above spot) | C8: P(+10% or more) | D8: P(-10% or more) | E8: P(touch +10%) | F8: P(touch -10%)
A9: 1M | B9: 0.54204 | C9: 0.2819 | D9: 0.19682 | E9: 0.4586 | F9: 0.35234
A10: 3M | B10: 0.57466 | C10: 0.4217 | D10: 0.27342 | E10: 0.70524 | F10: 0.56498
A12: CALIBRATION — READ THIS BEFORE THE MAP
A13: Market panel verdict (Egypt) | B13: PASS — skill +0.0158, 90% interval [0.009, 0.022]
A14: This name's verdict | B14: PARITY at every bootstrap block size {2,3,4}
A15: This name's CRPS skill vs a random walk | B15: -0.1276 — BELOW zero
A16: Coverage 50 / 80 / 90 | B16: 0.76 / 0.82 / 0.94 against nominal 0.50 / 0.80 / 0.90 — OVER-COVERED
A17: Cone width versus the benchmark | B17: 4.71x
A18: Why | B18: SCEM prints an unchanged close on 29.3% of sessions, 3.4x the Egyptian panel median and 2nd thinnest of 33 names. On such a series the benchmark's own volatility estimate collapses in quiet quarters.
A19: Consequence | B19: The map is ILLUSTRATIVE ONLY. It is materially too wide and must not be read with the confidence of a calibrated name.

Sheet Sensitivity
A1: Sensitivity
A2: PASTED — each cell is a complete revaluation. Does NOT redraw.
A4: Explicit WACC (rows) × terminal growth (columns) — fair value per share (EGP)
B5: g = 3% | C5: g = 4% | D5: g = 5% | E5: g = 6% | F5: g = 7%
A6: 0.25299216 | B6: 47.8524 | C6: 46.428078 | D6: 44.787774 | E6: 42.882068 | F6: 40.645069
A7: 0.26799216 | B7: 47.277767 | C7: 45.88984 | D7: 44.291426 | E7: 42.434363 | F7: 40.254436
A8: 0.28299216 | B8: 46.721341 | C8: 45.368579 | D8: 43.810638 | E8: 42.000575 | F8: 39.875793
A9: 0.29799216 | B9: 46.182371 | C9: 44.863595 | D9: 43.344773 | E9: 41.580134 | F9: 39.508651
A10: 0.31299216 | B10: 45.660142 | C10: 44.374224 | D10: 42.893222 | E10: 41.172501 | F10: 39.152548
A12: NET CASH — the largest single uncertainty, now sensitised
B13: 3,430 | C13: 4,180 | D13: 4,930 | E13: 5,680 | F13: 6,430
A14: Fair value per share (EGP) | B14: 38.05938 | C14: 40.935009 | D14: 43.810638 | E14: 46.686268 | F14: 49.561897
A16: Revision 1 called net cash the assumption where "an error matters more than
A17: almost any operating assumption", and then published no grid on it. This is that grid.
A20: Beta — fair value per share (EGP)
B21: β = 0.60 | C21: β = 0.80 | D21: β = 0.84 | E21: β = 1.00 | F21: β = 1.30
A22: Fair value | B22: 48.913575 | C22: 46.087769 | D22: 45.630253 | E22: 43.810638 | F22: 41.120647
A24: EBITDA margin shift — fair value per share (EGP)
B25: -4% | C25: -2% | D25: +0% | E25: +2% | F25: +4%
A26: Fair value | B26: 35.567102 | C26: 39.676449 | D26: 43.810638 | E26: 47.677359 | F26: 49.79502
A28: Note the terminal-growth row: HIGHER growth gives a LOWER value. That is not an error. Terminal
A29: return on capital (9.4%) is below the terminal cost of capital (16.3%), so growth must be bought with
A30: reinvestment that earns less than it costs. This company creates value by harvesting, not by growing.

Sheet Per-Share & Ratios
A1: Per-share and ratios
A2: Every figure is a formula
B4: FY2023 | C4: FY2024 | D4: FY2025 | E4: FY2026E | F4: FY2027E | G4: FY2028E | H4: FY2029E | I4: FY2030E
A5: Earnings per share (EGP) | B5: ='Income Statement'!B14/Assumptions!$B$6 | C5: ='Income Statement'!C14/Assumptions!$B$6 | D5: ='Income Statement'!D14/Assumptions!$B$6 | E5: ='Income Statement'!E14/Assumptions!$B$6 | F5: ='Income Statement'!F14/Assumptions!$B$6 | G5: ='Income Statement'!G14/Assumptions!$B$6 | H5: ='Income Statement'!H14/Assumptions!$B$6 | I5: ='Income Statement'!I14/Assumptions!$B$6
A6: Dividend per share (EGP) | E6: ='Cash Flow'!E13/Assumptions!$B$6 | F6: ='Cash Flow'!F13/Assumptions!$B$6 | G6: ='Cash Flow'!G13/Assumptions!$B$6 | H6: ='Cash Flow'!H13/Assumptions!$B$6 | I6: ='Cash Flow'!I13/Assumptions!$B$6
A7: Book value per share (EGP) | B7: ='Balance Sheet'!B12/Assumptions!$B$6 | C7: ='Balance Sheet'!C12/Assumptions!$B$6 | D7: ='Balance Sheet'!D12/Assumptions!$B$6 | E7: ='Balance Sheet'!E12/Assumptions!$B$6 | F7: ='Balance Sheet'!F12/Assumptions!$B$6 | G7: ='Balance Sheet'!G12/Assumptions!$B$6 | H7: ='Balance Sheet'!H12/Assumptions!$B$6 | I7: ='Balance Sheet'!I12/Assumptions!$B$6
A8: Free cash flow per share (EGP) | E8: =DCF!B15/Assumptions!$B$6 | F8: =DCF!C15/Assumptions!$B$6 | G8: =DCF!D15/Assumptions!$B$6 | H8: =DCF!E15/Assumptions!$B$6 | I8: =DCF!F15/Assumptions!$B$6
A9: Net cash per share (EGP) | B9: =('Balance Sheet'!B7-'Balance Sheet'!B9)/Assumptions!$B$6 | C9: =('Balance Sheet'!C7-'Balance Sheet'!C9)/Assumptions!$B$6 | D9: =('Balance Sheet'!D7-'Balance Sheet'!D9)/Assumptions!$B$6 | E9: =('Balance Sheet'!E7-'Balance Sheet'!E9)/Assumptions!$B$6 | F9: =('Balance Sheet'!F7-'Balance Sheet'!F9)/Assumptions!$B$6 | G9: =('Balance Sheet'!G7-'Balance Sheet'!G9)/Assumptions!$B$6 | H9: =('Balance Sheet'!H7-'Balance Sheet'!H9)/Assumptions!$B$6 | I9: =('Balance Sheet'!I7-'Balance Sheet'!I9)/Assumptions!$B$6
A10: Return on equity | B10: ='Income Statement'!B14/'Balance Sheet'!B12 | C10: ='Income Statement'!C14/'Balance Sheet'!C12 | D10: ='Income Statement'!D14/'Balance Sheet'!D12 | E10: ='Income Statement'!E14/'Balance Sheet'!E12 | F10: ='Income Statement'!F14/'Balance Sheet'!F12 | G10: ='Income Statement'!G14/'Balance Sheet'!G12 | H10: ='Income Statement'!H14/'Balance Sheet'!H12 | I10: ='Income Statement'!I14/'Balance Sheet'!I12
A11: EBITDA per tonne sold (EGP) | D11: ='Income Statement'!D6/'Summary Financials'!D9 | E11: ='Income Statement'!E6/'Summary Financials'!E9 | F11: ='Income Statement'!F6/'Summary Financials'!F9 | G11: ='Income Statement'!G6/'Summary Financials'!G9 | H11: ='Income Statement'!H6/'Summary Financials'!H9 | I11: ='Income Statement'!I6/'Summary Financials'!I9
A12: Price / earnings (at spot) | B12: =Assumptions!$B$5/B5 | C12: =Assumptions!$B$5/C5 | D12: =Assumptions!$B$5/D5 | E12: =Assumptions!$B$5/E5 | F12: =Assumptions!$B$5/F5 | G12: =Assumptions!$B$5/G5 | H12: =Assumptions!$B$5/H5 | I12: =Assumptions!$B$5/I5
A13: EV / EBITDA (at spot) | B13: =(Assumptions!$B$5*Assumptions!$B$6-('Balance Sheet'!B7-'Balance Sheet'!B9))/'Income Statement'!B6 | C13: =(Assumptions!$B$5*Assumptions!$B$6-('Balance Sheet'!C7-'Balance Sheet'!C9))/'Income Statement'!C6 | D13: =(Assumptions!$B$5*Assumptions!$B$6-('Balance Sheet'!D7-'Balance Sheet'!D9))/'Income Statement'!D6 | E13: =(Assumptions!$B$5*Assumptions!$B$6-('Balance Sheet'!E7-'Balance Sheet'!E9))/'Income Statement'!E6 | F13: =(Assumptions!$B$5*Assumptions!$B$6-('Balance Sheet'!F7-'Balance Sheet'!F9))/'Income Statement'!F6 | G13: =(Assumptions!$B$5*Assumptions!$B$6-('Balance Sheet'!G7-'Balance Sheet'!G9))/'Income Statement'!G6 | H13: =(Assumptions!$B$5*Assumptions!$B$6-('Balance Sheet'!H7-'Balance Sheet'!H9))/'Income Statement'!H6 | I13: =(Assumptions!$B$5*Assumptions!$B$6-('Balance Sheet'!I7-'Balance Sheet'!I9))/'Income Statement'!I6
A15: Price/earnings and EV/EBITDA are struck at the current spot against each year's earnings, so the
A16: forecast columns show what the reader is paying today for a future year — not a forecast of the multiple.

Sheet Peer & Sector
A1: Peer set and sector structure
A4: NAMED EGYPTIAN LISTED PEER
A5: Misr Beni Suef — FY2025 net sales (EGP mn) | B5: 5700
A6: Misr Beni Suef — FY2025 attributable profit (EGP mn) | B6: 3946
A7: Misr Beni Suef — earnings per share (EGP) | B7: 61.25
A8: Misr Beni Suef — market capitalisation (EGP mn) | B8: 13730
A9: Misr Beni Suef — trailing price/earnings | B9: 3.48
A10: Misr Beni Suef — EV/EBITDA | B10: 5.03
A11: Arabian Cement — FY2025 consolidated profit (EGP mn) | B11: 3600
A13: EGYPTIAN SECTOR STRUCTURE
A14: Nameplate capacity (Mt/yr) | B14: 76
A15: Domestic consumption 2025 (Mt) | B15: 54
A16: Production 2025 (Mt) | B16: 65
A17: Exports 2025 (Mt) | B17: 18.5
A18: Dormant capacity under revival from 2H-2026 (Mt) | B18: 12.6
A19: SCEM capacity as % of Egyptian capacity | B19: =Assumptions!$B$12/B14
A20: Revival capacity as % of domestic consumption | B20: =B18/B15
A21: Structural surplus (capacity less consumption, Mt) | B21: =B14-B15
A22: SCEM EV/EBITDA at spot on FY2026E | B22: ='Per-Share & Ratios'!E13
A24: The structural surplus is the whole sector case in one number: Egypt can make far more cement than
A25: it consumes, and 12.6Mt of dormant capacity is under study for revival inside the forecast window.
