Workbook

Sheet READ FIRST
A1: Testahil — The Saudi National Bank (Tadawul: 1180)
A2: Companion model · Independent Valuation Study · Educational analysis · Not investment advice
A4: What this workbook is. A transparent companion to the SNB valuation study. Every blue cell is an input; every
A5: black cell is a formula; green cells link across sheets. All inputs live on the Assumptions sheet — change one
A6: (the cost of equity, the terminal payout, a growth driver) and the whole model reprices.
A8: What it is not. It is not investment advice, a recommendation, or a price target. Values are model outputs shown
A9: as ranges. The preparer is not licensed by any securities regulator and may hold a position in the security.
A11: Lens. SNB is a bank, so the primary lens is a two-stage Dividend Discount Model (DDM); the DCF cross-check is a
A12: bank-appropriate Free-Cash-Flow-to-Equity (FCFE) build discounted at the cost of equity (FCFF/EV is not
A13: meaningful for a bank — leverage is its raw material). Cost of equity is published as Ke = rf + beta x ERP.
A15: Currency. SAR million unless stated (per-share figures in SAR). SAR pegged at 3.75/USD. Spot SAR 38.96 (2 Jul 2026).
A16: Historical financials are SNB disclosure (FY2024 annual; 9M-2025 reviewed statements; Q4-2024 earnings call).
... A20: Income Statement · Balance Sheet · Cash Flow · Summary Financials · Monte Carlo · Sensitivity · Per-Share & Ratios · Peer & Sector.

Sheet Summary
A1: Valuation summary — The Saudi National Bank (Tadawul: 1180)
A2: Four-lens fair value vs spot. Base links live; bear/bull are scenario outputs (study §1.5).
B3: Bear | C3: Base | D3: Bull | E3: Weight
A4: Dividend discount (DDM) | B4: ='Fundamental Valuation'!B4 -> 37 | C4: ='Fundamental Valuation'!C4 -> 44.222831 | D4: ='Fundamental Valuation'!D4 -> 55 | E4: =Assumptions!$B$21 -> 0.4
A5: Discounted cash flow (FCFF) | B5: ='Fundamental Valuation'!B5 -> 37 | C5: ='Fundamental Valuation'!C5 -> 44.848611 | D5: ='Fundamental Valuation'!D5 -> 56 | E5: =Assumptions!$B$22 -> 0.2
A6: Relative multiples | B6: ='Fundamental Valuation'!B6 -> 37 | C6: ='Fundamental Valuation'!C6 -> 46.089363 | D6: ='Fundamental Valuation'!D6 -> 53 | E6: =Assumptions!$B$23 -> 0.15
A7: Justified P/B (sustainable ROE) | B7: ='Fundamental Valuation'!B7 -> 34 | C7: ='Fundamental Valuation'!C7 -> 46.911928 | D7: ='Fundamental Valuation'!D7 -> 56 | E7: =Assumptions!$B$24 -> 0.25
A8: Weighted central | B8: ='Fundamental Valuation'!B8 -> 36.25 | C8: ='Fundamental Valuation'!C8 -> 45.300241 | D8: ='Fundamental Valuation'!D8 -> 55.15
A9: Spot price (SAR) | C9: =Assumptions!$B$4 -> 38.96
A10: Upside to central base | C10: =C8/C9-1 -> 0.1627372
A11: Read: modestly undervalued; the swing factor is NIM through the SAMA easing cycle vs CASA defence, and the shrinking international (Turkiye/legacy) drag.

Sheet Fundamental Valuation
A1: Fundamental valuation — football field data
A2: Bear/base/bull per lens. Base links live; bear/bull are scenario outputs (study §1.5).
A3: Lens | B3: Bear | C3: Base | D3: Bull
A4: Dividend discount (DDM) | B4: 37 | C4: =DDM!B14 -> 44.222831 | D4: 55
A5: Discounted cash flow (FCFF) | B5: 37 | C5: =DCF!B23 -> 44.848611 | D5: 56
A6: Relative multiples | B6: 37 | C6: ='Relative & Normalized'!C6 -> 46.089363 | D6: 53
A7: Justified P/B (sustainable ROE) | B7: 34 | C7: ='Relative & Normalized'!C7 -> 46.911928 | D7: 56
A8: Weighted central | B8: =SUMPRODUCT(B4:B7,Assumptions!$B$21:$B$24) -> 36.25 | C8: =SUMPRODUCT(C4:C7,Assumptions!$B$21:$B$24) -> 45.300241 | D8: =SUMPRODUCT(D4:D7,Assumptions!$B$21:$B$24) -> 55.15
A9: Spot | C9: =Assumptions!$B$4 -> 38.96

Sheet Assumptions
A1: Assumptions — the single input layer
A2: All blue cells are inputs. Every other sheet links here.
A3: ANCHORS
A4: Spot price (SAR/share) | B4: 38.96
A5: Shares outstanding (mn) | B5: 6000
A6: Risk-free rate (rf) | B6: 0.05
A7: Beta | B7: 0.95
A8: Equity risk premium (ERP) | B8: 0.06
A9: Cost of equity (Ke = rf + beta x ERP) | B9: =B6+B7*B8 -> 0.107
A10: Terminal growth (g) | B10: 0.045
A11: Effective zakat / tax rate | B11: 0.13
A12: SAMA repo (context) | B12: 0.0425
A13: DDM & CAPITAL
A14: Terminal payout ratio | B14: 0.6
A15: Sustainable ROE (terminal) | B15: 0.135
A16: CET1 target (FCFE capital) | B16: 0.17
A17: RELATIVE & JUSTIFIED
A18: Peer P/E target (x) | B18: 11
A19: Peer P/B target (x) | B19: 1.5
A20: SYNTHESIS WEIGHTS
A21: DDM weight | B21: 0.4
A22: FCFE-DCF weight | B22: 0.2
A23: Relative weight | B23: 0.15
A24: Justified-P/B weight | B24: 0.25
A25: Σ weights (check) | B25: =B21+B22+B23+B24 -> 1
A26: MONTE CARLO
A27: Diffusion volatility (annualized) | B27: 0.2119
A28: Net 3-month factor drift | B28: 0.019
A29: Innovations | B29: Student-t(5)
A30: Drift regime | B30: OFF (international)
A31: FORECAST DRIVERS (2026E–2030E)
B32: 2026E | C32: 2027E | D32: 2028E | E32: 2029E | F32: 2030E
A33: Financing growth | B33: 0.08 | C33: 0.075 | D33: 0.07 | E33: 0.065 | F33: 0.06
A34: Investment growth | B34: 0.07 | C34: 0.07 | D34: 0.07 | E34: 0.07 | F34: 0.07
A35: Deposit growth | B35: 0.082 | C35: 0.078 | D35: 0.07 | E35: 0.066 | F35: 0.062
A36: Net interest margin (NIM) | B36: 0.03 | C36: 0.03 | D36: 0.03 | E36: 0.03 | F36: 0.03
A37: Non-commission income growth | B37: 0.03 | C37: 0.06 | D37: 0.065 | E37: 0.065 | F37: 0.06
A38: Cost-to-income ratio | B38: 0.265 | C38: 0.26 | D38: 0.258 | E38: 0.255 | F38: 0.253
A39: Cost of risk (bps) | B39: 21 | C39: 21 | D39: 21 | E39: 22 | F39: 22
A40: Payout ratio | B40: 0.53 | C40: 0.55 | D40: 0.57 | E40: 0.59 | F40: 0.6
...

Sheet DDM
A1: Dividend discount model (primary lens)
A2: Two-stage DDM discounted at Ke = rf + beta x ERP. Links to Income Statement / Assumptions.
B3: 2026E | C3: 2027E | D3: 2028E | E3: 2029E | F3: 2030E
A4: EPS (SAR, post-AT1) | B4: ='Income Statement'!E16 -> 4.2207933 | C4: ='Income Statement'!F16 -> 4.5520108 | D4: ='Income Statement'!G16 -> 4.8912759 | E4: ='Income Statement'!H16 -> 5.2369718 | F4: ='Income Statement'!I16 -> 5.5936051
A5: Payout ratio | B5: =Assumptions!B40 -> 0.53 | C5: =Assumptions!C40 -> 0.55 | D5: =Assumptions!D40 -> 0.57 | E5: =Assumptions!E40 -> 0.59 | F5: =Assumptions!F40 -> 0.6
A6: DPS (SAR) | B6: =B4*B5 -> 2.2370204 | C6: =C4*C5 -> 2.503606 | D6: =D4*D5 -> 2.7880273 | E6: =E4*E5 -> 3.0898134 | F6: =F4*F5 -> 3.3561631
A7: Discount factor @ Ke | B7: =1/(1+Assumptions!$B$9)^1 -> 0.90334237 | C7: =1/(1+Assumptions!$B$9)^2 -> 0.81602743 | D7: =1/(1+Assumptions!$B$9)^3 -> 0.73715215 | E7: =1/(1+Assumptions!$B$9)^4 -> 0.66590077 | F7: =1/(1+Assumptions!$B$9)^5 -> 0.60153638
A8: PV of DPS | B8: =B6*B7 -> 2.0207953 | C8: =C6*C7 -> 2.0430111 | D8: =D6*D7 -> 2.0552003 | E8: =E6*E7 -> 2.0575091 | F8: =F6*F7 -> 2.0188542
A10: Σ PV of explicit DPS (2026–30) | B10: =SUM(B8:F8) -> 10.19537
A11: Terminal DPS (2031 = 2030 x (1+g)) | B11: =F6*(1+Assumptions!$B$10) -> 3.5071904
A12: Terminal value (Gordon) = TDPS/(Ke−g) | B12: =B11/(Assumptions!$B$9-Assumptions!$B$10) -> 56.567587
A13: PV of terminal value | B13: =B12*F7 -> 34.027461
A14: DDM fair value per share (SAR) | B14: =B10+B13 -> 44.222831
A15: terminal value as % of DDM value | B15: =B13/B14 -> 0.76945461
A16: Implied P/E on 2026E EPS | B16: =B14/B4 -> 10.477374
A17: Implied P/B on current common equity | B17: =B14/('Balance Sheet'!D17/Assumptions!$B$5) -> 1.4499289

Sheet Segments
A1: Segment view
A2: Operating income by segment (indicative shares applied to Income-Statement total operating income).
B3: 2023A | C3: 2024A | D3: 2025E | E3: 2026E | F3: 2027E | G3: 2028E | H3: 2029E | I3: 2030E
A4: Retail | B4: ='Income Statement'!B6*0.34 -> 11560 | C4: ='Income Statement'!C6*0.34 -> 12240 | D4: ='Income Statement'!D6*0.34 -> 13770 | E4: ='Income Statement'!E6*0.34 -> 14814.004 | F4: ='Income Statement'!F6*0.34 -> 15873.141 | G4: ='Income Statement'!G6*0.34 -> 16985.75 | H4: ='Income Statement'!H6*0.34 -> 18131.924 | I4: ='Income Statement'!I6*0.34 -> 19286.872
A5: Wholesale / Corporate | B5: ='Income Statement'!B6*0.34 -> 11560 | C5: ='Income Statement'!C6*0.34 -> 12240 | D5: ='Income Statement'!D6*0.34 -> 13770 | E5: ='Income Statement'!E6*0.34 -> 14814.004 | F5: ='Income Statement'!F6*0.34 -> 15873.141 | G5: ='Income Statement'!G6*0.34 -> 16985.75 | H5: ='Income Statement'!H6*0.34 -> 18131.924 | I5: ='Income Statement'!I6*0.34 -> 19286.872
A6: Treasury (investment book) | B6: ='Income Statement'!B6*0.24 -> 8160 | C6: ='Income Statement'!C6*0.24 -> 8640 | D6: ='Income Statement'!D6*0.24 -> 9720 | E6: ='Income Statement'!E6*0.24 -> 10456.944 | F6: ='Income Statement'!F6*0.24 -> 11204.57 | G6: ='Income Statement'!G6*0.24 -> 11989.941 | H6: ='Income Statement'!H6*0.24 -> 12799.005 | I6: ='Income Statement'!I6*0.24 -> 13614.263
A7: Capital Markets (SNB Capital) | B7: ='Income Statement'!B6*0.05 -> 1700 | C7: ='Income Statement'!C6*0.05 -> 1800 | D7: ='Income Statement'!D6*0.05 -> 2025 | E7: ='Income Statement'!E6*0.05 -> 2178.53 | F7: ='Income Statement'!F6*0.05 -> 2334.2855 | G7: ='Income Statement'!G6*0.05 -> 2497.9044 | H7: ='Income Statement'!H6*0.05 -> 2666.4594 | I7: ='Income Statement'!I6*0.05 -> 2836.3047
A8: International (Turkiye/legacy) | B8: ='Income Statement'!B6*0.03 -> 1020 | C8: ='Income Statement'!C6*0.03 -> 1080 | D8: ='Income Statement'!D6*0.03 -> 1215 | E8: ='Income Statement'!E6*0.03 -> 1307.118 | F8: ='Income Statement'!F6*0.03 -> 1400.5713 | G8: ='Income Statement'!G6*0.03 -> 1498.7426 | H8: ='Income Statement'!H6*0.03 -> 1599.8756 | I8: ='Income Statement'!I6*0.03 -> 1701.7828
A9: Total operating income | B9: =SUM(B4:B8) -> 34000 | C9: =SUM(C4:C8) -> 36000 | D9: =SUM(D4:D8) -> 40500 | E9: =SUM(E4:E8) -> 43570.6 | F9: =SUM(F4:F8) -> 46685.71 | G9: =SUM(G4:G8) -> 49958.088 | H9: =SUM(H4:H8) -> 53329.188 | I9: =SUM(I4:I8) -> 56726.095
A11: Shares indicative (group operating-income mix); International runs dilutive to group NIM/RoE via IAS-29 hyperinflation (Turkiye).

Sheet Relative & Normalized
A1: Relative multiples & justified P/B (sustainable-ROE lens)
A2: For a bank the 'normalized-earnings' lens is a sustainable-ROE justified P/B. Links to Assumptions.
A3: Lens | B3: Workings | C3: SAR/share
A4: Relative P/E | B4: 2026E EPS x peer P/E | C4: ='Income Statement'!E16*Assumptions!$B$18 -> 46.428726
A5: Relative P/B | B5: current common BVPS x peer P/B | C5: =('Balance Sheet'!D17/Assumptions!$B$5)*Assumptions!$B$19 -> 45.75
A6: Relative blend | B6: average of P/E and P/B | C6: =AVERAGE(C4,C5) -> 46.089363
A7: Justified P/B | B7: (ROE−g)/(Ke−g) x forward BVPS | C7: =((Assumptions!$B$15-Assumptions!$B$10)/(Assumptions!$B$9-Assumptions!$B$10))*('Balance Sheet'!E17/Assumptions!$B$5) -> 46.911928
A8: justified P/B multiple (x) | C8: =(Assumptions!$B$15-Assumptions!$B$10)/(Assumptions!$B$9-Assumptions!$B$10) -> 1.4516129
A9: current common BVPS (SAR) | C9: ='Balance Sheet'!D17/Assumptions!$B$5 -> 30.5

Sheet DCF
A1: Discounted cash flow — Free Cash Flow to the Firm (FCFF)
A2: Full waterfall: revenue → EBIT → NOPAT → FCFF, discounted at WACC (≈ Ke for a bank). EV less AT1 = equity. Links to Income Statement / Balance Sheet / Assumptions.
B3: 2026E | C3: 2027E | D3: 2028E | E3: 2029E | F3: 2030E
A4: Revenue (total operating income) | B4: ='Income Statement'!E6 -> 43570.6 | C4: ='Income Statement'!F6 -> 46685.71 | D4: ='Income Statement'!G6 -> 49958.088 | E4: ='Income Statement'!H6 -> 53329.188 | F4: ='Income Statement'!I6 -> 56726.095
A5: EBITDA | B5: =B7+B6 -> 32373.287 | C5: =C7+C6 -> 34872.489 | D5: =D7+D6 -> 37369.719 | E5: =E7+E6 -> 39911.3 | F5: =F7+F6 -> 42528.311
A6: D&A | B6: 2000 | C6: 2100 | D6: 2200 | E6: 2300 | F6: 2400
A7: EBIT | B7: ='Income Statement'!E10 -> 30373.287 | C7: ='Income Statement'!F10 -> 32772.489 | D7: ='Income Statement'!G10 -> 35169.719 | E7: ='Income Statement'!H10 -> 37611.3 | F7: ='Income Statement'!I10 -> 40128.311
A8: NOPAT (EBIT×(1−t)) | B8: =B7*(1-Assumptions!$B$11) -> 26424.76 | C8: =C7*(1-Assumptions!$B$11) -> 28512.065 | D8: =D7*(1-Assumptions!$B$11) -> 30597.655 | E8: =E7*(1-Assumptions!$B$11) -> 32721.831 | F8: =F7*(1-Assumptions!$B$11) -> 34911.631
A9: + D&A | B9: =B6 -> 2000 | C9: =C6 -> 2100 | D9: =D6 -> 2200 | E9: =E6 -> 2300 | F9: =F6 -> 2400
A10: − Capex | B10: -2000 | C10: -2100 | D10: -2200 | E10: -2300 | F10: -2400
A11: − Δ working capital | B11: -12200 | C11: -12500 | D11: -12600 | E11: -13400 | F11: -13400
A12: Free cash flow to firm | B12: =B8+B9+B10+B11 -> 14224.76 | C12: =C8+C9+C10+C11 -> 16012.065 | D12: =D8+D9+D10+D11 -> 17997.655 | E12: =E8+E9+E10+E11 -> 19321.831 | F12: =F8+F9+F10+F11 -> 21511.631
A13: Discount factor | B13: =1/(1+Assumptions!$B$9)^1 -> 0.90334237 | C13: =1/(1+Assumptions!$B$9)^2 -> 0.81602743 | D13: =1/(1+Assumptions!$B$9)^3 -> 0.73715215 | E13: =1/(1+Assumptions!$B$9)^4 -> 0.66590077 | F13: =1/(1+Assumptions!$B$9)^5 -> 0.60153638
A14: PV of FCFF | B14: =B12*B13 -> 12849.828 | C14: =C12*C13 -> 13066.284 | D14: =D12*D13 -> 13267.01 | E14: =E12*E13 -> 12866.422 | F14: =F12*F13 -> 12940.028
A16: Σ PV of explicit FCFF (2026–30) | B16: =SUM(B14:F14) -> 64989.573
A17: Terminal FCFF (2031 = 2030 × (1+g)) | B17: =F12*(1+Assumptions!$B$10) -> 22479.654
A18: Terminal value = TFCFF/(WACC−g) | B18: =B17/(Assumptions!$B$9-Assumptions!$B$10) -> 362575.06
A19: PV of terminal value | B19: =B18*F13 -> 218102.09
A20: Enterprise value (SAR mn) | B20: =B16+B19 -> 283091.66
A21: less: AT1 sukuk (debt-like) | B21: =-'Balance Sheet'!D16 -> -14000
A22: Equity value (SAR mn) | B22: =B20+B21 -> 269091.66
A23: DCF (FCFF) fair value per share (SAR) | B23: =B22/Assumptions!$B$5 -> 44.848611
A24: terminal value as % of enterprise value | B24: =B19/B20 -> 0.77042922
A26: WACC = cost of equity Ke (= rf + beta x ERP); for a bank WACC ≈ Ke and EV ≈ equity value (deposits are operating, not financing debt). Δ working capital carries the incremental regulatory-capital reinvestment for RWA growth. TV disclosed as % of EV (device A-7).

Sheet Income Statement
A1: Income statement (SAR mn, consolidated)
A2: 2023A–2025E disclosed / estimated (blue); 2026E–2030E forecast (formulas linking to Assumptions)
B3: 2023A | C3: 2024A | D3: 2025E | E3: 2026E | F3: 2027E | G3: 2028E | H3: 2029E | I3: 2030E
A4: Net special commission income (NSCI) | B4: 26300 | C4: 27400 | D4: 30500 | E4: =Assumptions!B36*(('Balance Sheet'!D4+'Balance Sheet'!D5)+('Balance Sheet'!E4+'Balance Sheet'!E5))/2 -> 33270.6 | F4: =Assumptions!C36*(('Balance Sheet'!E4+'Balance Sheet'!E5)+('Balance Sheet'!F4+'Balance Sheet'!F5))/2 -> 35767.71 | G4: =Assumptions!D36*(('Balance Sheet'!F4+'Balance Sheet'!F5)+('Balance Sheet'!G4+'Balance Sheet'!G5))/2 -> 38330.418 | H4: =Assumptions!E36*(('Balance Sheet'!G4+'Balance Sheet'!G5)+('Balance Sheet'!H4+'Balance Sheet'!H5))/2 -> 40945.719 | I4: =Assumptions!F36*(('Balance Sheet'!H4+'Balance Sheet'!H5)+('Balance Sheet'!I4+'Balance Sheet'!I5))/2 -> 43599.618
A5: Fee & other non-commission income | B5: 7700 | C5: 8600 | D5: 10000 | E5: =D5*(1+Assumptions!B37) -> 10300 | F5: =E5*(1+Assumptions!C37) -> 10918 | G5: =F5*(1+Assumptions!D37) -> 11627.67 | H5: =G5*(1+Assumptions!E37) -> 12383.469 | I5: =H5*(1+Assumptions!F37) -> 13126.477
A6: Total operating income | B6: =B4+B5 -> 34000 | C6: =C4+C5 -> 36000 | D6: =D4+D5 -> 40500 | E6: =E4+E5 -> 43570.6 | F6: =F4+F5 -> 46685.71 | G6: =G4+G5 -> 49958.088 | H6: =H4+H5 -> 53329.188 | I6: =I4+I5 -> 56726.095
A7: Operating expenses | B7: -9350 | C7: -10190 | D7: -10935 | E7: =-Assumptions!B38*E6 -> -11546.209 | F7: =-Assumptions!C38*F6 -> -12138.285 | G7: =-Assumptions!D38*G6 -> -12889.187 | H7: =-Assumptions!E38*H6 -> -13598.943 | I7: =-Assumptions!F38*I6 -> -14351.702
A8: Pre-provision operating profit | B8: =B6+B7 -> 24650 | C8: =C6+C7 -> 25810 | D8: =D6+D7 -> 29565 | E8: =E6+E7 -> 32024.391 | F8: =F6+F7 -> 34547.425 | G8: =G6+G7 -> 37068.901 | H8: =H6+H7 -> 39730.245 | I8: =I6+I7 -> 42374.393
A9: Net impairment (ECL) charge | B9: -900 | C9: -1046 | D9: -1310 | E9: =-Assumptions!B39/10000*'Balance Sheet'!E4 -> -1651.104 | F9: =-Assumptions!C39/10000*'Balance Sheet'!F4 -> -1774.9368 | G9: =-Assumptions!D39/10000*'Balance Sheet'!G4 -> -1899.1824 | H9: =-Assumptions!E39/10000*'Balance Sheet'!H4 -> -2118.9449 | I9: =-Assumptions!F39/10000*'Balance Sheet'!I4 -> -2246.0816
A10: Profit before zakat & tax | B10: =B8+B9 -> 23750 | C10: =C8+C9 -> 24764 | D10: =D8+D9 -> 28255 | E10: =E8+E9 -> 30373.287 | F10: =F8+F9 -> 32772.489 | G10: =G8+G9 -> 35169.719 | H10: =H8+H9 -> 37611.3 | I10: =I8+I9 -> 40128.311
A11: Zakat & income tax | B11: -3750 | C11: -3571 | D11: -3205 | E11: =-Assumptions!$B$11*E10 -> -3948.5273 | F11: =-Assumptions!$B$11*F10 -> -4260.4235 | G11: =-Assumptions!$B$11*G10 -> -4572.0634 | H11: =-Assumptions!$B$11*H10 -> -4889.469 | I11: =-Assumptions!$B$11*I10 -> -5216.6804
A12: Net income (attributable) | B12: =B10+B11 -> 20000 | C12: =C10+C11 -> 21193 | D12: =D10+D11 -> 25050 | E12: =E10+E11 -> 26424.76 | F12: =F10+F11 -> 28512.065 | G12: =G10+G11 -> 30597.655 | H12: =H10+H11 -> 32721.831 | I12: =I10+I11 -> 34911.631
A13: AT1 sukuk coupon | B13: -700 | C13: -800 | D13: -1000 | E13: =-Assumptions!B42 -> -1100 | F13: =-Assumptions!C42 -> -1200 | G13: =-Assumptions!D42 -> -1250 | H13: =-Assumptions!E42 -> -1300 | I13: =-Assumptions!F42 -> -1350
A14: Net income to common | B14: =B12+B13 -> 19300 | C14: =C12+C13 -> 20393 | D14: =D12+D13 -> 24050 | E14: =E12+E13 -> 25324.76 | F14: =F12+F13 -> 27312.065 | G14: =G12+G13 -> 29347.655 | H14: =H12+H13 -> 31421.831 | I14: =I12+I13 -> 33561.631
A16: EPS (SAR, post-AT1) | B16: =B14/Assumptions!$B$5 -> 3.2166667 | C16: =C14/Assumptions!$B$5 -> 3.3988333 | D16: =D14/Assumptions!$B$5 -> 4.0083333 | E16: =E14/Assumptions!$B$5 -> 4.2207933 | F16: =F14/Assumptions!$B$5 -> 4.5520108 | G16: =G14/Assumptions!$B$5 -> 4.8912759 | H16: =H14/Assumptions!$B$5 -> 5.2369718 | I16: =I14/Assumptions!$B$5 -> 5.5936051
A18: Source: SNB IR / Tadawul filings — FY2024 annual, 9M-2025 reviewed statements, SNB Q4-2024 earnings call (29-Jan-2025). 2025E = 9M actual + Q4 estimate (final FY2025 audit to confirm). Forecast = formulas linking to Assumptions.

Sheet Balance Sheet
A1: Balance sheet (SAR mn, consolidated)
A2: Historical anchored to disclosed totals (blue); forecast rolls forward. Balance is a plug on Other funding.
B3: 2023A | C3: 2024A | D3: 2025E | E3: 2026E | F3: 2027E | G3: 2028E | H3: 2029E | I3: 2030E
A4: Net financing | B4: 600000 | C4: 654000 | D4: 728000 | E4: =D4*(1+Assumptions!B33) -> 786240 | F4: =E4*(1+Assumptions!C33) -> 845208 | G4: =F4*(1+Assumptions!D33) -> 904372.56 | H4: =G4*(1+Assumptions!E33) -> 963156.78 | I4: =H4*(1+Assumptions!F33) -> 1020946.2
A5: Investments (securities) | B5: 270000 | C5: 300000 | D5: 340000 | E5: =D5*(1+Assumptions!B34) -> 363800 | F5: =E5*(1+Assumptions!C34) -> 389266 | G5: =F5*(1+Assumptions!D34) -> 416514.62 | H5: =G5*(1+Assumptions!E34) -> 445670.64 | I5: =H5*(1+Assumptions!F34) -> 476867.59
A6: Cash, interbank & other assets | B6: 167000 | C6: 150000 | D6: 187000 | E6: =D6*1.06 -> 198220 | F6: =E6*1.06 -> 210113.2 | G6: =F6*1.06 -> 222719.99 | H6: =G6*1.06 -> 236083.19 | I6: =H6*1.06 -> 250248.18
A7: Total assets | B7: =B4+B5+B6 -> 1037000 | C7: =C4+C5+C6 -> 1104000 | D7: =D4+D5+D6 -> 1255000 | E7: =E4+E5+E6 -> 1348260 | F7: =F4+F5+F6 -> 1444587.2 | G7: =G4+G5+G6 -> 1543607.2 | H7: =H4+H5+H6 -> 1644910.6 | I7: =I4+I5+I6 -> 1748062
A9: Customer deposits | B9: 638000 | C9: 625000 | D9: 690000 | E9: =D9*(1+Assumptions!B35) -> 746580 | F9: =E9*(1+Assumptions!C35) -> 804813.24 | G9: =F9*(1+Assumptions!D35) -> 861150.17 | H9: =G9*(1+Assumptions!E35) -> 917986.08 | I9: =H9*(1+Assumptions!F35) -> 974901.21
A10: Other funding & liabilities (plug) | B10: =B7-B12-B9 -> 233000 | C10: =C7-C12-C9 -> 303000 | D10: =D7-D12-D9 -> 368000 | E10: =E7-E12-E9 -> 392777.36 | F10: =F7-F12-F9 -> 418580.89 | G10: =G7-G12-G9 -> 448644.45 | H10: =H7-H12-H9 -> 480229.02 | I10: =I7-I12-I9 -> 513040.58
A12: Total equity | B12: 166000 | C12: 176000 | D12: 197000 | E12: =D12+'Income Statement'!E14*(1-Assumptions!B40) -> 208902.64 | F12: =E12+'Income Statement'!F14*(1-Assumptions!C40) -> 221193.07 | G12: =F12+'Income Statement'!G14*(1-Assumptions!D40) -> 233812.56 | H12: =G12+'Income Statement'!H14*(1-Assumptions!E40) -> 246695.51 | I12: =H12+'Income Statement'!I14*(1-Assumptions!F40) -> 260120.16
A13: Total liabilities & equity | B13: =B9+B10+B12 -> 1037000 | C13: =C9+C10+C12 -> 1104000 | D13: =D9+D10+D12 -> 1255000 | E13: =E9+E10+E12 -> 1348260 | F13: =F9+F10+F12 -> 1444587.2 | G13: =G9+G10+G12 -> 1543607.2 | H13: =H9+H10+H12 -> 1644910.6 | I13: =I9+I10+I12 -> 1748062
A14: Balance check (assets − L&E) | B14: =B7-B13 -> 0 | C14: =C7-C13 -> 0 | D14: =D7-D13 -> 0 | E14: =E7-E13 -> 0 | F14: =F7-F13 -> 0 | G14: =G7-G13 -> 0 | H14: =H7-H13 -> 0 | I14: =I7-I13 -> 0
A15: Risk-weighted assets (memo) | B15: 700000 | C15: 750000 | D15: 830000 | E15: =D15*(1+Assumptions!B41) -> 899720 | F15: =E15*(1+Assumptions!C41) -> 969898.16 | G15: =F15*(1+Assumptions!D41) -> 1039730.8 | H15: =G15*(1+Assumptions!E41) -> 1114591.4 | I15: =H15*(1+Assumptions!F41) -> 1189269.1
A16: AT1 sukuk (memo) | B16: 12000 | C16: 14000 | D16: 14000 | E16: 15000 | F16: 15000 | G16: 16000 | H16: 16000 | I16: 16000
A17: Common equity (CET1 base = equity − AT1) | B17: =B12-B16 -> 154000 | C17: =C12-C16 -> 162000 | D17: =D12-D16 -> 183000 | E17: =E12-E16 -> 193902.64 | F17: =F12-F16 -> 206193.07 | G17: =G12-G16 -> 217812.56 | H17: =H12-H16 -> 230695.51 | I17: =I12-I16 -> 244120.16
A18: Net financing / deposits (LDR) | B18: =B4/B9 -> 0.94043887 | C18: =C4/C9 -> 1.0464 | D18: =D4/D9 -> 1.0550725 | E18: =E4/E9 -> 1.0531222 | F18: =F4/F9 -> 1.0501915 | G18: =G4/G9 -> 1.0501915 | H18: =H4/H9 -> 1.0492063 | I18: =I4/I9 -> 1.0472304

Sheet Cash Flow
A1: Capital & dividend flow (SAR mn, forecast)
A2: Bank analogue of the cash-flow statement: capital generation, dividend capacity, and the CET1 trajectory.
B3: 2026E | C3: 2027E | D3: 2028E | E3: 2029E | F3: 2030E
A4: Net income to common | B4: ='Income Statement'!E14 -> 25324.76 | C4: ='Income Statement'!F14 -> 27312.065 | D4: ='Income Statement'!G14 -> 29347.655 | E4: ='Income Statement'!H14 -> 31421.831 | F4: ='Income Statement'!I14 -> 33561.631
A5: Common dividends paid | B5: =-'Income Statement'!E14*Assumptions!B40 -> -13422.123 | C5: =-'Income Statement'!F14*Assumptions!C40 -> -15021.636 | D5: =-'Income Statement'!G14*Assumptions!D40 -> -16728.164 | E5: =-'Income Statement'!H14*Assumptions!E40 -> -18538.88 | F5: =-'Income Statement'!I14*Assumptions!F40 -> -20136.978
A6: Retained earnings | B6: =B4+B5 -> 11902.637 | C6: =C4+C5 -> 12290.429 | D6: =D4+D5 -> 12619.492 | E6: =E4+E5 -> 12882.951 | F6: =F4+F5 -> 13424.652
A7: Capital needed for RWA growth (ΔRWA x CET1 target) | B7: =-('Balance Sheet'!E15-'Balance Sheet'!D15)*Assumptions!$B$16 -> -11852.4 | C7: =-('Balance Sheet'!F15-'Balance Sheet'!E15)*Assumptions!$B$16 -> -11930.287 | D7: =-('Balance Sheet'!G15-'Balance Sheet'!F15)*Assumptions!$B$16 -> -11871.553 | E7: =-('Balance Sheet'!H15-'Balance Sheet'!G15)*Assumptions!$B$16 -> -12726.305 | F7: =-('Balance Sheet'!I15-'Balance Sheet'!H15)*Assumptions!$B$16 -> -12695.197
A8: Capital surplus / (deficit) | B8: =B6+B7 -> 50.237054 | C8: =C6+C7 -> 360.14209 | D8: =D6+D7 -> 747.93829 | E8: =E6+E7 -> 156.64531 | F8: =F6+F7 -> 729.45565
A10: Common equity (CET1 base) | B10: ='Balance Sheet'!E17 -> 193902.64 | C10: ='Balance Sheet'!F17 -> 206193.07 | D10: ='Balance Sheet'!G17 -> 217812.56 | E10: ='Balance Sheet'!H17 -> 230695.51 | F10: ='Balance Sheet'!I17 -> 244120.16
A11: CET1 ratio (common equity / RWA) | B11: ='Balance Sheet'!E17/'Balance Sheet'!E15 -> 0.21551442 | C11: ='Balance Sheet'!F17/'Balance Sheet'!F15 -> 0.21259249 | D11: ='Balance Sheet'!G17/'Balance Sheet'!G15 -> 0.20948937 | E11: ='Balance Sheet'!H17/'Balance Sheet'!H15 -> 0.20697764 | F11: ='Balance Sheet'!I17/'Balance Sheet'!I15 -> 0.20526907

Sheet Summary Financials
A1: Summary financials (SAR mn)
A2: Every cell links to the statement sheets.
B3: 2023A | C3: 2024A | D3: 2025E | E3: 2026E | F3: 2027E | G3: 2028E | H3: 2029E | I3: 2030E
A4: Total operating income | B4: ='Income Statement'!B6 -> 34000 | C4: ='Income Statement'!C6 -> 36000 | D4: ='Income Statement'!D6 -> 40500 | E4: ='Income Statement'!E6 -> 43570.6 | F4: ='Income Statement'!F6 -> 46685.71 | G4: ='Income Statement'!G6 -> 49958.088 | H4: ='Income Statement'!H6 -> 53329.188 | I4: ='Income Statement'!I6 -> 56726.095
A5: Pre-provision operating profit | B5: ='Income Statement'!B8 -> 24650 | C5: ='Income Statement'!C8 -> 25810 | D5: ='Income Statement'!D8 -> 29565 | E5: ='Income Statement'!E8 -> 32024.391 | F5: ='Income Statement'!F8 -> 34547.425 | G5: ='Income Statement'!G8 -> 37068.901 | H5: ='Income Statement'!H8 -> 39730.245 | I5: ='Income Statement'!I8 -> 42374.393
A6: Net income (attributable) | B6: ='Income Statement'!B12 -> 20000 | C6: ='Income Statement'!C12 -> 21193 | D6: ='Income Statement'!D12 -> 25050 | E6: ='Income Statement'!E12 -> 26424.76 | F6: ='Income Statement'!F12 -> 28512.065 | G6: ='Income Statement'!G12 -> 30597.655 | H6: ='Income Statement'!H12 -> 32721.831 | I6: ='Income Statement'!I12 -> 34911.631
A7: Net financing | B7: ='Balance Sheet'!B4 -> 600000 | C7: ='Balance Sheet'!C4 -> 654000 | D7: ='Balance Sheet'!D4 -> 728000 | E7: ='Balance Sheet'!E4 -> 786240 | F7: ='Balance Sheet'!F4 -> 845208 | G7: ='Balance Sheet'!G4 -> 904372.56 | H7: ='Balance Sheet'!H4 -> 963156.78 | I7: ='Balance Sheet'!I4 -> 1020946.2
A8: Customer deposits | B8: ='Balance Sheet'!B9 -> 638000 | C8: ='Balance Sheet'!C9 -> 625000 | D8: ='Balance Sheet'!D9 -> 690000 | E8: ='Balance Sheet'!E9 -> 746580 | F8: ='Balance Sheet'!F9 -> 804813.24 | G8: ='Balance Sheet'!G9 -> 861150.17 | H8: ='Balance Sheet'!H9 -> 917986.08 | I8: ='Balance Sheet'!I9 -> 974901.21
A9: Total assets | B9: ='Balance Sheet'!B7 -> 1037000 | C9: ='Balance Sheet'!C7 -> 1104000 | D9: ='Balance Sheet'!D7 -> 1255000 | E9: ='Balance Sheet'!E7 -> 1348260 | F9: ='Balance Sheet'!F7 -> 1444587.2 | G9: ='Balance Sheet'!G7 -> 1543607.2 | H9: ='Balance Sheet'!H7 -> 1644910.6 | I9: ='Balance Sheet'!I7 -> 1748062
A10: Total equity | B10: ='Balance Sheet'!B12 -> 166000 | C10: ='Balance Sheet'!C12 -> 176000 | D10: ='Balance Sheet'!D12 -> 197000 | E10: ='Balance Sheet'!E12 -> 208902.64 | F10: ='Balance Sheet'!F12 -> 221193.07 | G10: ='Balance Sheet'!G12 -> 233812.56 | H10: ='Balance Sheet'!H12 -> 246695.51 | I10: ='Balance Sheet'!I12 -> 260120.16
A11: Risk-weighted assets | B11: ='Balance Sheet'!B15 -> 700000 | C11: ='Balance Sheet'!C15 -> 750000 | D11: ='Balance Sheet'!D15 -> 830000 | E11: ='Balance Sheet'!E15 -> 899720 | F11: ='Balance Sheet'!F15 -> 969898.16 | G11: ='Balance Sheet'!G15 -> 1039730.8 | H11: ='Balance Sheet'!H15 -> 1114591.4 | I11: ='Balance Sheet'!I15 -> 1189269.1

Sheet Monte Carlo
A1: Monte Carlo — engine outputs
A2: 50,000 paths · YZ-HAR width · Student-t(5) · drift OFF (international) · 16 factors · seed 42 (values, not a sheet simulation).
A4: Percentile map (SAR/share)
A5: Horizon | B5: p5 | C5: p25 | D5: p50 | E5: p75 | F5: p95
A6: T+20 sessions | B6: 33.75 | C6: 37.1 | D6: 39.03 | E6: 40.93 | F6: 44.44
A7: T+60 sessions | B7: 30.81 | C7: 35.62 | D7: 39 | E7: 42.56 | F7: 48.66
A9: Inputs (from Assumptions)
A10: Diffusion volatility (annualized) | D10: =Assumptions!$B$27 -> 0.2119
A11: Net 3-month factor drift | D11: =Assumptions!$B$28 -> 0.019
A12: Innovations / drift regime | D12: Student-t(5) · OFF
A14: Level-touch ladder
A15: Level (SAR) | B15: T+20 | C15: T+60
A16: 46 | B16: 0.035 | C16: 0.182
A17: 44 | B17: 0.092 | C17: 0.31
A18: 42 | B18: 0.239 | C18: 0.498
A19: 40 | B19: 0.588 | C19: 0.762
A20: 38 | B20: 0.573 | C20: 0.751
A21: 36 | B21: 0.229 | C21: 0.476
A22: 34 | B22: 0.084 | C22: 0.274

Sheet Sensitivity
A1: DDM sensitivity — the cost-of-equity swing
A2: Fair value (SAR/share) by Ke x terminal growth. Live off the DDM DPS path and Assumptions.
A4: Ke ↓ / g → | B4: 0.035 | C4: 0.04 | D4: 0.045 | E4: 0.05 | F4: 0.055
A5: 0.095 | B5: =DDM!$B$6/(1+$A5)^1+DDM!$C$6/(1+$A5)^2+DDM!$D$6/(1+$A5)^3+DDM!$E$6/(1+$A5)^4+DDM!$F$6/(1+$A5)^5+(DDM!$F$6*(1+B$4)/($A5-B$4))/(1+$A5)^5 -> 47.311361 | C5: =DDM!$B$6/(1+$A5)^1+DDM!$C$6/(1+$A5)^2+DDM!$D$6/(1+$A5)^3+DDM!$E$6/(1+$A5)^4+DDM!$F$6/(1+$A5)^5+(DDM!$F$6*(1+C$4)/($A5-C$4))/(1+$A5)^5 -> 50.848423 | D5: =DDM!$B$6/(1+$A5)^1+DDM!$C$6/(1+$A5)^2+DDM!$D$6/(1+$A5)^3+DDM!$E$6/(1+$A5)^4+DDM!$F$6/(1+$A5)^5+(DDM!$F$6*(1+D$4)/($A5-D$4))/(1+$A5)^5 -> 55.092897 | E5: =DDM!$B$6/(1+$A5)^1+DDM!$C$6/(1+$A5)^2+DDM!$D$6/(1+$A5)^3+DDM!$E$6/(1+$A5)^4+DDM!$F$6/(1+$A5)^5+(DDM!$F$6*(1+E$4)/($A5-E$4))/(1+$A5)^5 -> 60.280588 | F5: =DDM!$B$6/(1+$A5)^1+DDM!$C$6/(1+$A5)^2+DDM!$D$6/(1+$A5)^3+DDM!$E$6/(1+$A5)^4+DDM!$F$6/(1+$A5)^5+(DDM!$F$6*(1+F$4)/($A5-F$4))/(1+$A5)^5 -> 66.765201
A6: 0.1 | B6: =DDM!$B$6/(1+$A6)^1+DDM!$C$6/(1+$A6)^2+DDM!$D$6/(1+$A6)^3+DDM!$E$6/(1+$A6)^4+DDM!$F$6/(1+$A6)^5+(DDM!$F$6*(1+B$4)/($A6-B$4))/(1+$A6)^5 -> 43.574045 | C6: =DDM!$B$6/(1+$A6)^1+DDM!$C$6/(1+$A6)^2+DDM!$D$6/(1+$A6)^3+DDM!$E$6/(1+$A6)^4+DDM!$F$6/(1+$A6)^5+(DDM!$F$6*(1+C$4)/($A6-C$4))/(1+$A6)^5 -> 46.512896 | D6: =DDM!$B$6/(1+$A6)^1+DDM!$C$6/(1+$A6)^2+DDM!$D$6/(1+$A6)^3+DDM!$E$6/(1+$A6)^4+DDM!$F$6/(1+$A6)^5+(DDM!$F$6*(1+D$4)/($A6-D$4))/(1+$A6)^5 -> 49.986085 | E6: =DDM!$B$6/(1+$A6)^1+DDM!$C$6/(1+$A6)^2+DDM!$D$6/(1+$A6)^3+DDM!$E$6/(1+$A6)^4+DDM!$F$6/(1+$A6)^5+(DDM!$F$6*(1+E$4)/($A6-E$4))/(1+$A6)^5 -> 54.153912 | F6: =DDM!$B$6/(1+$A6)^1+DDM!$C$6/(1+$A6)^2+DDM!$D$6/(1+$A6)^3+DDM!$E$6/(1+$A6)^4+DDM!$F$6/(1+$A6)^5+(DDM!$F$6*(1+F$4)/($A6-F$4))/(1+$A6)^5 -> 59.247922
A7: 0.107 | B7: =DDM!$B$6/(1+$A7)^1+DDM!$C$6/(1+$A7)^2+DDM!$D$6/(1+$A7)^3+DDM!$E$6/(1+$A7)^4+DDM!$F$6/(1+$A7)^5+(DDM!$F$6*(1+B$4)/($A7-B$4))/(1+$A7)^5 -> 39.216399 | C7: =DDM!$B$6/(1+$A7)^1+DDM!$C$6/(1+$A7)^2+DDM!$D$6/(1+$A7)^3+DDM!$E$6/(1+$A7)^4+DDM!$F$6/(1+$A7)^5+(DDM!$F$6*(1+C$4)/($A7-C$4))/(1+$A7)^5 -> 41.532808 | D7: =DDM!$B$6/(1+$A7)^1+DDM!$C$6/(1+$A7)^2+DDM!$D$6/(1+$A7)^3+DDM!$E$6/(1+$A7)^4+DDM!$F$6/(1+$A7)^5+(DDM!$F$6*(1+D$4)/($A7-D$4))/(1+$A7)^5 -> 44.222831 | E7: =DDM!$B$6/(1+$A7)^1+DDM!$C$6/(1+$A7)^2+DDM!$D$6/(1+$A7)^3+DDM!$E$6/(1+$A7)^4+DDM!$F$6/(1+$A7)^5+(DDM!$F$6*(1+E$4)/($A7-E$4))/(1+$A7)^5 -> 47.384789 | F7: =DDM!$B$6/(1+$A7)^1+DDM!$C$6/(1+$A7)^2+DDM!$D$6/(1+$A7)^3+DDM!$E$6/(1+$A7)^4+DDM!$F$6/(1+$A7)^5+(DDM!$F$6*(1+F$4)/($A7-F$4))/(1+$A7)^5 -> 51.154815
A8: 0.115 | B8: =DDM!$B$6/(1+$A8)^1+DDM!$C$6/(1+$A8)^2+DDM!$D$6/(1+$A8)^3+DDM!$E$6/(1+$A8)^4+DDM!$F$6/(1+$A8)^5+(DDM!$F$6*(1+B$4)/($A8-B$4))/(1+$A8)^5 -> 35.173202 | C8: =DDM!$B$6/(1+$A8)^1+DDM!$C$6/(1+$A8)^2+DDM!$D$6/(1+$A8)^3+DDM!$E$6/(1+$A8)^4+DDM!$F$6/(1+$A8)^5+(DDM!$F$6*(1+C$4)/($A8-C$4))/(1+$A8)^5 -> 36.982717 | D8: =DDM!$B$6/(1+$A8)^1+DDM!$C$6/(1+$A8)^2+DDM!$D$6/(1+$A8)^3+DDM!$E$6/(1+$A8)^4+DDM!$F$6/(1+$A8)^5+(DDM!$F$6*(1+D$4)/($A8-D$4))/(1+$A8)^5 -> 39.050735 | E8: =DDM!$B$6/(1+$A8)^1+DDM!$C$6/(1+$A8)^2+DDM!$D$6/(1+$A8)^3+DDM!$E$6/(1+$A8)^4+DDM!$F$6/(1+$A8)^5+(DDM!$F$6*(1+E$4)/($A8-E$4))/(1+$A8)^5 -> 41.43691 | F8: =DDM!$B$6/(1+$A8)^1+DDM!$C$6/(1+$A8)^2+DDM!$D$6/(1+$A8)^3+DDM!$E$6/(1+$A8)^4+DDM!$F$6/(1+$A8)^5+(DDM!$F$6*(1+F$4)/($A8-F$4))/(1+$A8)^5 -> 44.22078
A9: 0.125 | B9: =DDM!$B$6/(1+$A9)^1+DDM!$C$6/(1+$A9)^2+DDM!$D$6/(1+$A9)^3+DDM!$E$6/(1+$A9)^4+DDM!$F$6/(1+$A9)^5+(DDM!$F$6*(1+B$4)/($A9-B$4))/(1+$A9)^5 -> 31.134097 | C9: =DDM!$B$6/(1+$A9)^1+DDM!$C$6/(1+$A9)^2+DDM!$D$6/(1+$A9)^3+DDM!$E$6/(1+$A9)^4+DDM!$F$6/(1+$A9)^5+(DDM!$F$6*(1+C$4)/($A9-C$4))/(1+$A9)^5 -> 32.503533 | D9: =DDM!$B$6/(1+$A9)^1+DDM!$C$6/(1+$A9)^2+DDM!$D$6/(1+$A9)^3+DDM!$E$6/(1+$A9)^4+DDM!$F$6/(1+$A9)^5+(DDM!$F$6*(1+D$4)/($A9-D$4))/(1+$A9)^5 -> 34.044147 | E9: =DDM!$B$6/(1+$A9)^1+DDM!$C$6/(1+$A9)^2+DDM!$D$6/(1+$A9)^3+DDM!$E$6/(1+$A9)^4+DDM!$F$6/(1+$A9)^5+(DDM!$F$6*(1+E$4)/($A9-E$4))/(1+$A9)^5 -> 35.790177 | F9: =DDM!$B$6/(1+$A9)^1+DDM!$C$6/(1+$A9)^2+DDM!$D$6/(1+$A9)^3+DDM!$E$6/(1+$A9)^4+DDM!$F$6/(1+$A9)^5+(DDM!$F$6*(1+F$4)/($A9-F$4))/(1+$A9)^5 -> 37.78564
A11: Cells near spot (SAR 38.96) show how much easing-cycle NIM support and payout growth are already in the price.

Sheet Per-Share & Ratios
A1: Per-share & ratios (the standardized dashboard)
A2: Links to statements / Assumptions. Bank Data-Miner panel.
B3: 2023A | C3: 2024A | D3: 2025E | E3: 2026E | F3: 2027E | G3: 2028E | H3: 2029E | I3: 2030E
A4: EPS (SAR) | B4: ='Income Statement'!B16 -> 3.2166667 | C4: ='Income Statement'!C16 -> 3.3988333 | D4: ='Income Statement'!D16 -> 4.0083333 | E4: ='Income Statement'!E16 -> 4.2207933 | F4: ='Income Statement'!F16 -> 4.5520108 | G4: ='Income Statement'!G16 -> 4.8912759 | H4: ='Income Statement'!H16 -> 5.2369718 | I4: ='Income Statement'!I16 -> 5.5936051
A5: DPS (SAR) | B5: 1.67 | C5: 1.81 | D5: 2.04 | E5: =Assumptions!B40*E4 -> 2.2370204 | F5: =Assumptions!C40*F4 -> 2.503606 | G5: =Assumptions!D40*G4 -> 2.7880273 | H5: =Assumptions!E40*H4 -> 3.0898134 | I5: =Assumptions!F40*I4 -> 3.3561631
A6: Book value/share (SAR, common) | B6: ='Balance Sheet'!B17/Assumptions!$B$5 -> 25.666667 | C6: ='Balance Sheet'!C17/Assumptions!$B$5 -> 27 | D6: ='Balance Sheet'!D17/Assumptions!$B$5 -> 30.5 | E6: ='Balance Sheet'!E17/Assumptions!$B$5 -> 32.317106 | F6: ='Balance Sheet'!F17/Assumptions!$B$5 -> 34.365511 | G6: ='Balance Sheet'!G17/Assumptions!$B$5 -> 36.302093 | H6: ='Balance Sheet'!H17/Assumptions!$B$5 -> 38.449251 | I6: ='Balance Sheet'!I17/Assumptions!$B$5 -> 40.686693
A7: Dividend yield | B7: =B5/Assumptions!$B$4 -> 0.042864476 | C7: =C5/Assumptions!$B$4 -> 0.046457906 | D7: =D5/Assumptions!$B$4 -> 0.052361396 | E7: =E5/Assumptions!$B$4 -> 0.057418389 | F7: =F5/Assumptions!$B$4 -> 0.064260933 | G7: =G5/Assumptions!$B$4 -> 0.071561274 | H7: =H5/Assumptions!$B$4 -> 0.079307325 | I7: =I5/Assumptions!$B$4 -> 0.086143816
A8: P/E (x) | B8: =Assumptions!$B$4/B4 -> 12.111917 | C8: =Assumptions!$B$4/C4 -> 11.462757 | D8: =Assumptions!$B$4/D4 -> 9.7197505 | E8: =Assumptions!$B$4/E4 -> 9.2304923 | F8: =Assumptions!$B$4/F4 -> 8.5588548 | G8: =Assumptions!$B$4/G4 -> 7.9652019 | H8: =Assumptions!$B$4/H4 -> 7.4394137 | I8: =Assumptions!$B$4/I4 -> 6.9650966
A9: P/B (x) | B9: =Assumptions!$B$4/B6 -> 1.5179221 | C9: =Assumptions!$B$4/C6 -> 1.442963 | D9: =Assumptions!$B$4/D6 -> 1.277377 | E9: =Assumptions!$B$4/E6 -> 1.2055535 | F9: =Assumptions!$B$4/F6 -> 1.1336948 | G9: =Assumptions!$B$4/G6 -> 1.0732164 | H9: =Assumptions!$B$4/H6 -> 1.0132837 | I9: =Assumptions!$B$4/I6 -> 0.95756122
A10: NIM | B10: 0.0313 | C10: 0.03 | D10: 0.0305 | E10: =Assumptions!B36 -> 0.03 | F10: =Assumptions!C36 -> 0.03 | G10: =Assumptions!D36 -> 0.03 | H10: =Assumptions!E36 -> 0.03 | I10: =Assumptions!F36 -> 0.03
A11: Cost-to-income | B11: =-'Income Statement'!B7/'Income Statement'!B6 -> 0.275 | C11: =-'Income Statement'!C7/'Income Statement'!C6 -> 0.28305556 | D11: =-'Income Statement'!D7/'Income Statement'!D6 -> 0.27 | E11: =-'Income Statement'!E7/'Income Statement'!E6 -> 0.265 | F11: =-'Income Statement'!F7/'Income Statement'!F6 -> 0.26 | G11: =-'Income Statement'!G7/'Income Statement'!G6 -> 0.258 | H11: =-'Income Statement'!H7/'Income Statement'!H6 -> 0.255 | I11: =-'Income Statement'!I7/'Income Statement'!I6 -> 0.253
A12: ROTE | B12: ='Income Statement'!B14/'Balance Sheet'!B17 -> 0.12532468 | C12: ='Income Statement'!C14/AVERAGE('Balance Sheet'!B17,'Balance Sheet'!C17) -> 0.12906962 | D12: ='Income Statement'!D14/AVERAGE('Balance Sheet'!C17,'Balance Sheet'!D17) -> 0.13942029 | E12: ='Income Statement'!E14/AVERAGE('Balance Sheet'!D17,'Balance Sheet'!E17) -> 0.13438356 | F12: ='Income Statement'!F14/AVERAGE('Balance Sheet'!E17,'Balance Sheet'!F17) -> 0.13652766 | G12: ='Income Statement'!G14/AVERAGE('Balance Sheet'!F17,'Balance Sheet'!G17) -> 0.1384305 | H12: ='Income Statement'!H14/AVERAGE('Balance Sheet'!G17,'Balance Sheet'!H17) -> 0.14011713 | I12: ='Income Statement'!I14/AVERAGE('Balance Sheet'!H17,'Balance Sheet'!I17) -> 0.14136699
A13: Cost of risk (bps) | B13: =-'Income Statement'!B9/'Balance Sheet'!B4*10000 -> 15 | C13: =-'Income Statement'!C9/'Balance Sheet'!C4*10000 -> 15.993884 | D13: =-'Income Statement'!D9/'Balance Sheet'!D4*10000 -> 17.994505 | E13: =-'Income Statement'!E9/'Balance Sheet'!E4*10000 -> 21 | F13: =-'Income Statement'!F9/'Balance Sheet'!F4*10000 -> 21 | G13: =-'Income Statement'!G9/'Balance Sheet'!G4*10000 -> 21 | H13: =-'Income Statement'!H9/'Balance Sheet'!H4*10000 -> 22 | I13: =-'Income Statement'!I9/'Balance Sheet'!I4*10000 -> 22
A14: NPL ratio | B14: 0.012 | C14: 0.0116 | D14: 0.0115 | E14: 0.012 | F14: 0.0122 | G14: 0.0124 | H14: 0.0125 | I14: 0.0125
A15: CET1 ratio | B15: ='Balance Sheet'!B17/'Balance Sheet'!B15 -> 0.22 | C15: ='Balance Sheet'!C17/'Balance Sheet'!C15 -> 0.216 | D15: ='Balance Sheet'!D17/'Balance Sheet'!D15 -> 0.22048193 | E15: ='Balance Sheet'!E17/'Balance Sheet'!E15 -> 0.21551442 | F15: ='Balance Sheet'!F17/'Balance Sheet'!F15 -> 0.21259249 | G15: ='Balance Sheet'!G17/'Balance Sheet'!G15 -> 0.20948937 | H15: ='Balance Sheet'!H17/'Balance Sheet'!H15 -> 0.20697764 | I15: ='Balance Sheet'!I17/'Balance Sheet'!I15 -> 0.20526907
A16: LDR (fin/deposits) | B16: ='Balance Sheet'!B18 -> 0.94043887 | C16: ='Balance Sheet'!C18 -> 1.0464 | D16: ='Balance Sheet'!D18 -> 1.0550725 | E16: ='Balance Sheet'!E18 -> 1.0531222 | F16: ='Balance Sheet'!F18 -> 1.0501915 | G16: ='Balance Sheet'!G18 -> 1.0501915 | H16: ='Balance Sheet'!H18 -> 1.0492063 | I16: ='Balance Sheet'!I18 -> 1.0472304
A17: Financing growth YoY | C17: ='Balance Sheet'!C4/'Balance Sheet'!B4-1 -> 0.09 | D17: ='Balance Sheet'!D4/'Balance Sheet'!C4-1 -> 0.11314985 | E17: ='Balance Sheet'!E4/'Balance Sheet'!D4-1 -> 0.08 | F17: ='Balance Sheet'!F4/'Balance Sheet'!E4-1 -> 0.075 | G17: ='Balance Sheet'!G4/'Balance Sheet'!F4-1 -> 0.07 | H17: ='Balance Sheet'!H4/'Balance Sheet'!G4-1 -> 0.065 | I17: ='Balance Sheet'!I4/'Balance Sheet'!H4-1 -> 0.06

Sheet Peer & Sector
A1: Peer set & sector
A2: Saudi banks (Tadawul). Multiples indicative; not model inputs.
A3: Cohort | B3: Closest peers | C3: Typical valuation
A4: Largest KSA banks | B4: Al Rajhi (1120), Riyad (1010), SAB (1060) | C4: P/E ~10–16x; P/B ~1.3–3.5x; ROE 13–20%
A5: Mid-cap KSA banks | B5: Alinma (1150), BSF (1050), ANB (1080) | C5: P/E ~9–12x; P/B ~1.1–1.6x; ROE 11–15%
A6: SNB positioning | B6: Largest by assets; ~1.3x P/B, ~10x fwd P/E | C6: 16%+ ROTE, 72% CASA, T1 CAR 20.3% — cheap vs quality
A8: Analyst context: ANB Capital (Dec-2024) residual-income Ke 11%, fair value ~SAR 46; sector ROE ~15% (Fitch). Not used as model inputs.
