Workbook

Sheet READ FIRST
A1: Testahil — Saudi Telecom Company (Tadawul: 7010)
A3: Companion model · Independent Valuation Study · Educational analysis · Not investment advice
A5: What this workbook is. A transparent companion to the stc valuation study. Every blue cell is an input; every
A6: black cell is a formula; green cells link across sheets. All inputs live on the Assumptions sheet — change one
A7: (the EBITDA margin path, capex intensity, the beta, terminal growth, a stake mark) and the whole model reprices.
A9: What it is not. It is not investment advice, a recommendation, or a price target. Values are model outputs shown
A10: as ranges. The preparer is not licensed by any securities regulator and may hold a position in the security.
A12: Entity note. Saudi Telecom Company (stc Group) is the Kingdom’s incumbent operator: stc KSA (consumer,
A13: enterprise, wholesale) plus subsidiaries — solutions by stc (79%, listed 7202), stc bank (85%, SAMA-licensed
A14: Jan-2025), stc Kuwait (51.8%), stc Bahrain (100%), center3 (data centres), sirar, iot squared (50% PIF JV) —
A15: and minority stakes: 43.06% of Digital Infrastructure Co (TAWAL+GLIC towers, PIF-controlled) and 9.97% of
A16: Telefónica. House lens: going-concern FCFF DCF (primary), cross-checked by the dividend-policy DDM,
... A25: Per-Share & Ratios · Peer & Sector.

Sheet Summary
A1: Valuation summary — Saudi Telecom Company (Tadawul: 7010)
A2: Four-lens fair value vs spot. Base links live; bear/bull are scenario outputs (study §1.5).
B5: Bear | C5: Base | D5: Bull | E5: Weight
A6: FCFF DCF (primary) | B6: 35.5 | C6: ='Valuation Bridge'!C13 | D6: 69.1 | E6: =Assumptions!B32
A7: Dividend discount (policy lens) | B7: 32.1 | C7: ='Valuation Bridge'!C22 | D7: 57.5 | E7: =Assumptions!B33
A8: Relative (EV/EBITDA) | B8: 42.1 | C8: ='Relative & Normalized'!C6 | D8: 52.4 | E8: =Assumptions!B34
A9: Normalized earnings | B9: 36.8 | C9: ='Relative & Normalized'!C9 | D9: 50.3 | E9: =Assumptions!B35
A10: Weighted central | B10: =SUMPRODUCT(B6:B9,$E$6:$E$9) | C10: =SUMPRODUCT(C6:C9,$E$6:$E$9) | D10: =SUMPRODUCT(D6:D9,$E$6:$E$9)
A12: Spot price (SAR) | B12: =Assumptions!B5
A13: Upside to central base | B13: =C10/Assumptions!B5-1
A15: Read: modestly undervalued — the DCF and relative lenses sit above spot, the dividend and normalized lenses close to it; the swing is capex intensity vs the locked SAR 2.20 payout, the beta/discount-rate question, and the KSA mobile competitive picture.

Sheet Fundamental Valuation
A1: Fundamental valuation — football-field data
A2: Bear/base/bull per lens (links to Summary).
A5: Lens | B5: Bear | C5: Base | D5: Bull
A6: FCFF DCF (primary) | B6: =Summary!B6 | C6: =Summary!C6 | D6: =Summary!D6
A7: Dividend discount (policy lens) | B7: =Summary!B7 | C7: =Summary!C7 | D7: =Summary!D7
A8: Relative (EV/EBITDA) | B8: =Summary!B8 | C8: =Summary!C8 | D8: =Summary!D8
A9: Normalized earnings | B9: =Summary!B9 | C9: =Summary!C9 | D9: =Summary!D9
A10: Weighted central | B10: =Summary!B10 | C10: =Summary!C10 | D10: =Summary!D10
A11: Spot | B11: =Assumptions!B5

Sheet Assumptions
A1: Assumptions — the single input layer
A2: All blue cells are inputs. Every other sheet links here.
A4: ANCHORS
A5: Spot price (SAR/share) | B5: 43.58 | C5: 7 Jul 2026 close, attached daily history
A6: Shares outstanding (mn) | B6: 4989.8 | C6: 5,000mn issued − ~10.2mn treasury; 26mn ESIP buyback approved 7-May-2026 not yet netted
A7: Normalized effective zakat & income tax | B7: 0.097 | C7: stc is a zakat payer (statutory 2.5% on the zakat base) plus foreign-subsidiary income taxes/WHT. Both framings: statutory 2.5% vs normalized effective ~9.7% (FY23 9.5%, FY24 9.8%; FY25 was a one-off net CREDIT of SAR 466mn from prior-year provision reversals). The model uses the normalized effective rate.
A8: COST OF CAPITAL — bottom-up, sourced (house rule §3.5-G; full sourcing rows 84+)
A9: Risk-free rate (SAR 10Y sovereign, derived 8-Jul-2026) | B9: 0.055 | C9: DERIVED: KSA govt-guaranteed USD 10Y priced UST+95bp on 8-Jul-2026 (SRC $1.5bn 10y sukuk; UST 10Y 4.45%) = 5.40%, plus the SAR-over-USD sovereign pickup documented in the Saudi Exchange "KSA Sovereign Local Currency Debt Primer Update" (21-May-2026); cross-checked vs FAB Securities 5.5% SAR rf (Feb-2026). No free live SAR 10Y screen quote exists — flagged as derived, not a screen print. NEVER shortcut to UST (peg ≠ equivalence).
A10: Equity beta (regressed vs TASI — see row 88) | B10: 0.48 | C10: GENUINE REGRESSION: daily stc-vs-TASI, n=40 paired sessions (5-May→7-Jul-2026): beta 0.475, R²=0.143, SE=0.189 — passes the house usability gate (n≥24, R²≥5%, SE<|β|, β>0). Flag: 9-week window (longer TASI history not programmatically accessible); the beta sensitivity grid below is therefore mandatory reading.
A11: Equity risk premium — Saudi Arabia, rating-based (primary; CDS alt. row 86) | B11: 0.0501 | C11: Damodaran ORIGINAL file (ctryprem.html), Saudi Arabia row, "Last updated: January 5, 2026": Moody’s Aa3, CRP 0.78% + mature-market 4.23% = 5.01%. Rating-based = "standard practice" primary; the CDS-based 5.72% is the "more current" alternative (note: for Saudi the CDS basis is HIGHER, unlike Egypt).
A12: Cost of equity Ke = rf + β × ERP | B12: =B9+B10*B11 | C12: Primary Ke (rating-based ERP), used in the base-case WACC.
A13: Pre-tax cost of debt (blended, sourced — row 89) | B13: 0.05 | C13: stc's own instruments: Jan-2026 $2bn sukuk 4.489% (5y, T+75) / 5.083% (10y, T+90); 2019 $1.25bn sukuk 3.89%; SAR murabaha ≈ 3M SAIBOR 4.79% (Apr-2026) + 60–100bp. Weighted outstanding ≈ 5.0% pre-tax.
A14: After-tax Kd | B14: =B13*(1-B7)
A15: Debt weight D/(D+E) — computed, never assumed | B15: =22475/(B5*B6+22475) | C15: Market cap = spot × shares = SAR 217.5bn; total debt = Q1-26 IR-disclosed SAR 22,475mn (post Jan-26 $2bn sukuk; excludes leases 2,296).
A16: WACC (rating-based ERP, primary) | B16: =(1-B15)*B12+B15*B14
A17: Terminal growth g (nominal SAR) | B17: 0.025 | C17: ≈ Saudi long-run nominal GDP-lite for a mature telecom; sensitized §1.9
A18: EV → EQUITY BRIDGE (marks)
A19: Investments in associates & JVs (incl. 43.06% DIIC/TAWAL) | B19: 4641 | C19: 31-Dec-25, Q1-26 FS comparative (carrying value)
A20: Telefónica 9.97% stake (market mark) | B20: 8630 | C20: 561mn shares × €3.50 (6-Jul-26) × 4.40 SAR/EUR ≈ SAR 8.6bn; cost €2.1bn (Sep-2023) ≈ SAR 8.5bn
A21: Net debt (IR basis, Q1-2026) | B21: 7063 | C21: Total debt 22,475 − IR cash 15,412 (IR cash excludes ~SAR 6.0bn stc bank banking-operations cash). Two framings: FS cash+murabaha 21,442 → net debt ~1,033; IR basis 7,063 used (conservative, core-group).
A22: Non-controlling interests (book) | B22: 2335 | C22: 31-Mar-26 FS
A23: DDM (the locked SAR 0.55/quarter policy)
A24: DPS path FY26E–FY30E (SAR) | C24: 2.2 | D24: 2.2 | E24: 2.3 | F24: 2.4 | G24: 2.55
A25: DDM terminal dividend growth | B25: 0.03 | C25: post-policy (2027+) payout growth ≈ EPS growth at ~75% payout
A26: RELATIVE & NORMALIZED
A27: Justified EV/EBITDA (base) | B27: 9 | C27: GCC band ~8–10×; stc trades ~9.5× trailing
A28: FY26E net profit for the relative P/E cross-check | B28: 14090 | C28: IS-build aligned (attributable)
A29: Normalized PAT (ex one-offs) | B29: 14400 | C29: FY25 14,828 less the +466 zakat credit ≈ 14,360; mid-cycle margins
A30: Justified through-cycle P/E | B30: 15
A31: SYNTHESIS WEIGHTS
A32: FCFF DCF weight | B32: 0.35
A33: DDM weight | B33: 0.25
A34: Relative weight | B34: 0.2
A35: Normalized-earnings weight | B35: 0.2
A36: MONTE CARLO (YZ-HAR v2 — engine outputs on the Monte Carlo sheet)
A37: Anchor volatility (HAR forecast, annualized) | B37: 0.1509
A38: Secular drift (daily) — zero-drift class | B38: 0 | C38: International/GCC name: zero drift passed Step 0; secular drift failed (−4.8%)
A39: Net factor drift per quarter (16-factor stack) | B39: 0.0072
A40: Paths / seed | B40: 50,000 / 42
A41: FORECAST DRIVERS (FY26E–FY30E) — top-down (§3.5-C gate: subs × ARPU not disclosed)
...

Sheet Valuation Bridge
A1: Valuation bridge — FCFF DCF (primary) + the dividend-policy DDM
A2: Core-operations EV from the DCF sheet; stakes marked separately; DDM = the locked SAR 0.55/quarter policy. Links to DCF / Assumptions.
A5: Component | B5: Basis | C5: Value (SAR mn)
A6: Core operations enterprise value | B6: FCFF DCF (§1.1): Σ PV FCFF + PV terminal | C6: =DCF!B21
A7: of which terminal value (device A-7) | B7: % of core EV | C7: =DCF!B22
A8: + Investments in associates & JVs | B8: 43.06% DIIC/TAWAL at carrying value | C8: =Assumptions!B19
A9: + Telefónica 9.97% | B9: Market mark: 561mn sh × €3.50 × 4.40 | C9: =Assumptions!B20
A10: − Net debt (IR basis, Q1-26) | B10: Total debt 22,475 − core cash 15,412 | C10: =-Assumptions!B21
A11: − Non-controlling interests | B11: Book, 31-Mar-26 | C11: =-Assumptions!B22
A12: Equity value | C12: =C6+Assumptions!B19+Assumptions!B20-Assumptions!B21-Assumptions!B22
A13: DCF fair value per share (SAR) | C13: =C12/Assumptions!B6
A14: Upside / (downside) vs spot | C14: =C13/Assumptions!B5-1
A16: DDM — the locked dividend policy as a lens
A17: DPS (SAR) | C17: =Assumptions!C24 | D17: =Assumptions!D24 | E17: =Assumptions!E24 | F17: =Assumptions!F24 | G17: =Assumptions!G24
A18: PV of DPS @ Ke | C18: =C17/(1+Assumptions!$B$12)^1 | D18: =D17/(1+Assumptions!$B$12)^2 | E18: =E17/(1+Assumptions!$B$12)^3 | F18: =F17/(1+Assumptions!$B$12)^4 | G18: =G17/(1+Assumptions!$B$12)^5
A19: Σ PV of explicit DPS (FY26–30E) | C19: =SUM(C18:G18)
A20: Terminal value = DPS30 × (1+g) / (Ke − g) | C20: =G17*(1+Assumptions!$B$25)/(Assumptions!$B$12-Assumptions!$B$25)
A21: PV of terminal value | C21: =C20/(1+Assumptions!$B$12)^5
A22: DDM fair value per share (SAR) | C22: =C19+C21
A23: terminal as % of DDM value (device A-7) | C23: =C21/C22
A25: Market-implied read: at spot, the market pays ≈ core EV of SAR 209bn for operations that produce ~SAR 10–11bn of model FCFF — an implied core FCFF yield of ~5% against a 7.6% WACC, i.e. the market already prices a large share of the terminal growth. The regular dividend (SAR 2.20 ≈ 5.0% yield) is ~0.9–1.0× covered by model FY26E FCF at the guided capex band — the balance sheet (SAR 15.4bn core cash) carries the difference; §1.7 of the study sensitizes this in real units.

Sheet Segments
A1: Segment view — stc KSA units + subsidiaries
A2: FY24–FY25 disclosed per stc’s FY2025 presentation (restated); FY23 available at group level only on the restated continuing-ops basis. Forecast links to Assumptions growth drivers.
B4: FY23 | C4: FY24 | D4: FY25 | E4: FY26E | F4: FY27E | G4: FY28E | H4: FY29E | I4: FY30E
A6: KSA Consumer (CBU) | C6: 31741 | D6: 32826 | E6: =D6*(1+Assumptions!$C$43) | F6: =E6*(1+Assumptions!$D$43) | G6: =F6*(1+Assumptions!$E$43) | H6: =G6*(1+Assumptions!$F$43) | I6: =H6*(1+Assumptions!$G$43)
A7: KSA Enterprise (EBU) | C7: 13466 | D7: 13514 | E7: =D7*(1+Assumptions!$C$44) | F7: =E7*(1+Assumptions!$D$44) | G7: =F7*(1+Assumptions!$E$44) | H7: =G7*(1+Assumptions!$F$44) | I7: =H7*(1+Assumptions!$G$44)
A8: KSA Wholesale & Carrier | C8: 4313 | D8: 4779 | E8: =D8*(1+Assumptions!$C$45) | F8: =E8*(1+Assumptions!$D$45) | G8: =F8*(1+Assumptions!$E$45) | H8: =G8*(1+Assumptions!$F$45) | I8: =H8*(1+Assumptions!$G$45)
A9: stc KSA total | C9: =C6+C7+C8 | D9: =D6+D7+D8 | E9: =E6+E7+E8 | F9: =F6+F7+F8 | G9: =G6+G7+G8 | H9: =H6+H7+H8 | I9: =I6+I7+I8
A10: Subsidiaries, net of eliminations | C10: 26249 | D10: 26700 | E10: =D10*(1+Assumptions!$C$46) | F10: =E10*(1+Assumptions!$D$46) | G10: =F10*(1+Assumptions!$E$46) | H10: =G10*(1+Assumptions!$F$46) | I10: =H10*(1+Assumptions!$G$46)
A11: Group revenue | B11: 71777 | C11: 75893 | D11: 77819 | E11: =E9+E10 | F11: =F9+F10 | G11: =G9+G10 | H11: =H9+H10 | I11: =I9+I10
A13: Group EBITDA | B13: 22445 | C13: 23951 | D13: 24469 | E13: =E11*Assumptions!$C$47 | F13: =F11*Assumptions!$D$47 | G13: =G11*Assumptions!$E$47 | H13: =H11*Assumptions!$F$47 | I13: =I11*Assumptions!$G$47
A14: EBITDA margin | B14: =B13/B11 | C14: =C13/C11 | D14: =D13/D11 | E14: =E13/E11 | F14: =F13/F11 | G14: =G13/G11 | H14: =H13/H11 | I14: =I13/I11
A16: Named subsidiary revenue, FY2025 (gross, incl. inter-segment — context, not modelled lines):
A17: solutions by stc (7202, 79%) | B17: 12,730
A18: channels | B18: ~14,085
A19: stc bank (85%) | B19: 1,968 (+11%)
A20: SCCC cloud (55%) | B20: 1,962 (+62%)
A21: iot squared (50%) | B21: 1,928
A22: sirar (100%) | B22: 1,401 (+13%)
A23: center3 (100%) | B23: ~827
A25: Source: stc FY2025 earnings presentation & Q1-2026 release (stc.com IR). KSA unit splits disclosed from FY24 on the restated basis; FY23 KSA split not restated — group only. Q1-26: KSA 13,001 (CBU 8,283 +5.2%, EBU 3,483 −3.6%, W&C 1,235 +6.2%).

Sheet Relative & Normalized
A1: Relative & normalized-earnings lenses
A2: Links to Assumptions, DCF and the Income Statement.
A5: Lens | B5: Workings | C5: SAR/share
A6: Relative EV/EBITDA | B6: FY26E EBITDA × justified multiple + stakes − net debt − NCI, /sh | C6: =(DCF!B7*Assumptions!B27+Assumptions!B19+Assumptions!B20-Assumptions!B21-Assumptions!B22)/Assumptions!B6
A7: implied P/E cross-check at that value | C7: =C6*Assumptions!B6/Assumptions!B28
A8: IS-build FY26E EPS, for reference | C8: ='Income Statement'!E21
A9: Normalized earnings power | B9: Normalized PAT (ex one-offs) × through-cycle P/E, /sh | C9: =Assumptions!B29*Assumptions!B30/Assumptions!B6
A10: normalized EPS (SAR) | C10: =Assumptions!B29/Assumptions!B6
A12: P/B cross-check: spot / FY25 BVPS | C12: =Assumptions!B5/('Balance Sheet'!D14/Assumptions!B6)
A13: Dividend yield — two framings: regular declared 2.20/sh = 5.0%; cash paid during 2025 (incl. the SAR 2.00 special for FY24) 4.20/sh = 9.6%.

Sheet DCF
A1: DCF — going-concern FCFF, explicit 5 years
A2: Revenue → EBITDA → D&A → EBIT → NOPAT → +D&A → −Capex → −ΔWC → FCFF → discount factor → PV. WACC built bottom-up on Assumptions (rf + β×ERP, both ERP bases published).
B4: FY26E | C4: FY27E | D4: FY28E | E4: FY29E | F4: FY30E
A6: Group revenue | B6: =Segments!E11 | C6: =Segments!F11 | D6: =Segments!G11 | E6: =Segments!H11 | F6: =Segments!I11
A7: EBITDA | B7: =Segments!E13 | C7: =Segments!F13 | D7: =Segments!G13 | E7: =Segments!H13 | F7: =Segments!I13
A8: D&A | B8: =-B6*Assumptions!$C$48 | C8: =-C6*Assumptions!$D$48 | D8: =-D6*Assumptions!$E$48 | E8: =-E6*Assumptions!$F$48 | F8: =-F6*Assumptions!$G$48
A9: EBIT | B9: =B7+B8 | C9: =C7+C8 | D9: =D7+D8 | E9: =E7+E8 | F9: =F7+F8
A10: NOPAT = EBIT × (1 − zakat/tax) | B10: =B9*(1-Assumptions!$B$7) | C10: =C9*(1-Assumptions!$B$7) | D10: =D9*(1-Assumptions!$B$7) | E10: =E9*(1-Assumptions!$B$7) | F10: =F9*(1-Assumptions!$B$7)
A11: + D&A | B11: =-B8 | C11: =-C8 | D11: =-D8 | E11: =-E8 | F11: =-F8
A12: − Capex | B12: =-B6*Assumptions!$C$49 | C12: =-C6*Assumptions!$D$49 | D12: =-D6*Assumptions!$E$49 | E12: =-E6*Assumptions!$F$49 | F12: =-F6*Assumptions!$G$49
A13: − Increase in net working capital | B13: =-B6*Assumptions!$C$50 | C13: =-C6*Assumptions!$D$50 | D13: =-D6*Assumptions!$E$50 | E13: =-E6*Assumptions!$F$50 | F13: =-F6*Assumptions!$G$50
A14: FCFF | B14: =SUM(B10:B13) | C14: =SUM(C10:C13) | D14: =SUM(D10:D13) | E14: =SUM(E10:E13) | F14: =SUM(F10:F13)
A15: Discount factor | B15: =1/(1+Assumptions!$B$16)^1 | C15: =1/(1+Assumptions!$B$16)^2 | D15: =1/(1+Assumptions!$B$16)^3 | E15: =1/(1+Assumptions!$B$16)^4 | F15: =1/(1+Assumptions!$B$16)^5
A16: PV of FCFF | B16: =B14*B15 | C16: =C14*C15 | D16: =D14*D15 | E16: =E14*E15 | F16: =F14*F15
A18: Σ PV of explicit FCFF (FY26–30E) | B18: =SUM(B16:F16)
A19: Terminal value (Gordon, g = Assumptions B17) | B19: =F14*(1+Assumptions!$B$17)/(Assumptions!$B$16-Assumptions!$B$17)
A20: PV of terminal value | B20: =B19*F15
A21: Enterprise value — core operations | B21: =B18+B20
A22: % terminal of EV (device A-7) | B22: =B20/B21
A23: + Investments in associates (DIIC/TAWAL 43.06%) | B23: =Assumptions!$B$19
A24: + Telefónica 9.97% (market mark) | B24: =Assumptions!$B$20
A25: − Net debt (IR basis, Q1-26) | B25: =-Assumptions!$B$21
A26: − Non-controlling interests | B26: =-Assumptions!$B$22
A27: Equity value | B27: =B21+Assumptions!$B$19+Assumptions!$B$20-Assumptions!$B$21-Assumptions!$B$22
A28: DCF fair value per share (SAR) | B28: =B27/Assumptions!$B$6
A29: Upside / (downside) vs spot | B29: =B28/Assumptions!$B$5-1
A31: WACC is built on Assumptions as Ke = rf + β×ERP blended with after-tax Kd (§3.5-G); the alternative CDS-based WACC is on Assumptions row 88. Terminal value is disclosed as % of EV above rather than blended away (device A-7).

Sheet Income Statement
A1: Income statement (SAR mn, consolidated, continuing operations)
A2: FY23–FY25 as disclosed in stc IR releases, restated continuing-ops basis (blue); FY26E–FY30E formulas linked to Segments and Assumptions.
B4: FY23 | C4: FY24 | D4: FY25 | E4: FY26E | F4: FY27E | G4: FY28E | H4: FY29E | I4: FY30E
A6: Total revenue | B6: 71777 | C6: 75893 | D6: 77819 | E6: =Segments!E11 | F6: =Segments!F11 | G6: =Segments!G11 | H6: =Segments!H11 | I6: =Segments!I11
A7: Gross profit | B7: 34740 | C7: 37326 | D7: 37700 | E7: =E6*Assumptions!$C$55 | F7: =F6*Assumptions!$D$55 | G7: =G6*Assumptions!$E$55 | H7: =H6*Assumptions!$F$55 | I7: =I6*Assumptions!$G$55
A8: Gross margin | B8: =B7/B6 | C8: =C7/C6 | D8: =D7/D6 | E8: =E7/E6 | F8: =F7/F6 | G8: =G7/G6 | H8: =H7/H6 | I8: =I7/I6
A9: EBITDA | B9: 22445 | C9: 23951 | D9: 24469 | E9: =Segments!E13 | F9: =Segments!F13 | G9: =Segments!G13 | H9: =Segments!H13 | I9: =Segments!I13
A10: EBITDA margin | B10: =B9/B6 | C10: =C9/C6 | D10: =D9/D6 | E10: =E9/E6 | F10: =F9/F6 | G10: =G9/G6 | H10: =H9/H6 | I10: =I9/I6
A11: Depreciation, amortisation & impairment | B11: -9284 | C11: -9525 | D11: -10031 | E11: =-E6*Assumptions!$C$48 | F11: =-F6*Assumptions!$D$48 | G11: =-G6*Assumptions!$E$48 | H11: =-H6*Assumptions!$F$48 | I11: =-I6*Assumptions!$G$48
A12: Operating profit (EBIT) | B12: 13161 | C12: 14426 | D12: 14438 | E12: =E9+E11 | F12: =F9+F11 | G12: =G9+G11 | H12: =H9+H11 | I12: =I9+I11
A13: Associates, net finance, impairments & other | B13: 826 | C13: -2292 | D13: 285 | E13: =Assumptions!$C$51+Assumptions!$C$52 | F13: =Assumptions!$D$51+Assumptions!$D$52 | G13: =Assumptions!$E$51+Assumptions!$E$52 | H13: =Assumptions!$F$51+Assumptions!$F$52 | I13: =Assumptions!$G$51+Assumptions!$G$52
A14: Profit before zakat & income tax | B14: 13987 | C14: 12134 | D14: 14723 | E14: =E12+E13 | F14: =F12+F13 | G14: =G12+G13 | H14: =H12+H13 | I14: =I12+I13
A15: Zakat & income tax | B15: -1327 | C15: -1192 | D15: 466 | E15: =-E14*Assumptions!$B$7 | F15: =-F14*Assumptions!$B$7 | G15: =-G14*Assumptions!$B$7 | H15: =-H14*Assumptions!$B$7 | I15: =-I14*Assumptions!$B$7
A16: Profit from continuing operations | B16: 12660 | C16: 10942 | D16: 15189 | E16: =E14+E15 | F16: =F14+F15 | G16: =G14+G15 | H16: =H14+H15 | I16: =I14+I15
A17: Profit from discontinued operations | B17: 759 | C17: 13973 | D17: 0 | E17: =0 | F17: =0 | G17: =0 | H17: =0 | I17: =0
A18: Non-controlling interests | B18: -124 | C18: -226 | D18: -361 | E18: =-(E16)*Assumptions!$C$53 | F18: =-(F16)*Assumptions!$D$53 | G18: =-(G16)*Assumptions!$E$53 | H18: =-(H16)*Assumptions!$F$53 | I18: =-(I16)*Assumptions!$G$53
A19: Net profit (attributable) | B19: 13295 | C19: 24689 | D19: 14828 | E19: =E16+E17+E18 | F19: =F16+F17+F18 | G19: =G16+G17+G18 | H19: =H16+H17+H18 | I19: =I16+I17+I18
A20: Net margin (attributable) | B20: =B19/B6 | C20: =C19/C6 | D20: =D19/D6 | E20: =E19/E6 | F20: =F19/F6 | G20: =G19/G6 | H20: =H19/H6 | I20: =I19/I6
A21: EPS (SAR) | B21: =B19/Assumptions!$B$6 | C21: =C19/Assumptions!$B$6 | D21: =D19/Assumptions!$B$6 | E21: =E19/Assumptions!$B$6 | F21: =F19/Assumptions!$B$6 | G21: =G19/Assumptions!$B$6 | H21: =H19/Assumptions!$B$6 | I21: =I19/Assumptions!$B$6
A23: Sources: stc FY2024/FY2025 IR releases + Q1-2026 interim FS (all stc.com). FY23/FY24 restated to continuing operations (TAWAL + Digital Infrastructure Co reclassified as discontinued; FY24 discontinued profit 13,973 incl. the SAR 12,885mn disposal gain). One-offs: FY23 AlKhobar land gain +1,296, WHT reversal +724, ERP −863; FY24 WHT reversal +1,500, ERP −2,577, BGSM impairment −764; FY25 zakat credit +466, ERP ≈ −824. "Share of associates + net finance & other" is the residual bridging disclosed EBIT to disclosed profit before zakat — stc does not publish those lines separately in the IR release layout; the FY25 annual FS carries the full detail.

Sheet Balance Sheet
A1: Balance sheet (SAR mn, consolidated)
A2: FY23–FY25 grouped from stc disclosure to a house layout (blue; FY25 detail from the Q1-2026 FS comparatives). Forecast rolls forward clean-surplus; the check row is zero by construction.
B4: FY23 | C4: FY24 | D4: FY25 | E4: FY26E | F4: FY27E | G4: FY28E | H4: FY29E | I4: FY30E
A6: Net fixed & intangible assets (PP&E, ROU, intangibles, inv. prop.) | B6: =B12-B7-B8-B9-B10-B11 | C6: =C12-C7-C8-C9-C10-C11 | D6: =D12-D7-D8-D9-D10-D11 | E6: =D6+Segments!E11*Assumptions!$C$49+'Income Statement'!E11 | F6: =E6+Segments!F11*Assumptions!$D$49+'Income Statement'!F11 | G6: =F6+Segments!G11*Assumptions!$E$49+'Income Statement'!G11 | H6: =G6+Segments!H11*Assumptions!$F$49+'Income Statement'!H11 | I6: =H6+Segments!I11*Assumptions!$G$49+'Income Statement'!I11
A7: Investments in associates & JVs | B7: 3800 | C7: 4200 | D7: 4641 | E7: =D7+Assumptions!$C$51 | F7: =E7+Assumptions!$D$51 | G7: =F7+Assumptions!$E$51 | H7: =G7+Assumptions!$F$51 | I7: =H7+Assumptions!$G$51
A8: Financial assets (incl. Telefónica 9.97%) | B8: 22000 | C8: 23500 | D8: 24893 | E8: =D8 | F8: =E8 | G8: =F8 | H8: =G8 | I8: =H8
A9: Trade receivables, net | B9: 24500 | C9: 25800 | D9: 26727 | E9: =D9+Segments!E11*Assumptions!$C$50 | F9: =E9+Segments!F11*Assumptions!$D$50 | G9: =F9+Segments!G11*Assumptions!$E$50 | H9: =G9+Segments!H11*Assumptions!$F$50 | I9: =H9+Segments!I11*Assumptions!$G$50
A10: Cash, equivalents & short-term murabahas | B10: 28138 | C10: 30755 | D10: 15080 | E10: ='Cash Flow'!E17 | F10: ='Cash Flow'!F17 | G10: ='Cash Flow'!G17 | H10: ='Cash Flow'!H17 | I10: ='Cash Flow'!I17
A11: Other assets | B11: 2600 | C11: 2600 | D11: 2952 | E11: =D11 | F11: =E11 | G11: =F11 | H11: =G11 | I11: =H11
A12: TOTAL ASSETS | B12: 159646 | C12: 160638 | D12: 157477 | E12: =SUM(E6:E11) | F12: =SUM(F6:F11) | G12: =SUM(G6:G11) | H12: =SUM(H6:H11) | I12: =SUM(I6:I11)
A14: Equity attributable to shareholders | B14: 78985 | C14: 89417 | D14: 83414 | E14: =D14+'Income Statement'!E19-Assumptions!$C$54*Assumptions!$B$6 | F14: =E14+'Income Statement'!F19-Assumptions!$D$54*Assumptions!$B$6 | G14: =F14+'Income Statement'!G19-Assumptions!$E$54*Assumptions!$B$6 | H14: =G14+'Income Statement'!H19-Assumptions!$F$54*Assumptions!$B$6 | I14: =H14+'Income Statement'!I19-Assumptions!$G$54*Assumptions!$B$6
A15: Non-controlling interests | B15: 2530 | C15: 3069 | D15: 3482 | E15: =D15-'Income Statement'!E18 | F15: =E15-'Income Statement'!F18 | G15: =F15-'Income Statement'!G18 | H15: =G15-'Income Statement'!H18 | I15: =H15-'Income Statement'!I18
A16: Total equity | B16: =B14+B15 | C16: =C14+C15 | D16: =D14+D15 | E16: =E14+E15 | F16: =F14+F15 | G16: =G14+G15 | H16: =H14+H15 | I16: =I14+I15
A17: Borrowings & sukuk (excl. leases) | B17: 21958 | C17: 15132 | D17: 15191 | E17: =D17+7284 | F17: =E17 | G17: =F17 | H17: =G17 | I17: =H17
A18: Lease liabilities | B18: 6985 | C18: 4580 | D18: 2253 | E18: =D18 | F18: =E18 | G18: =F18 | H18: =G18 | I18: =H18
A19: Trade payables & financial liabilities | B19: 25000 | C19: 26500 | D19: 29610 | E19: =D19 | F19: =E19 | G19: =F19 | H19: =G19 | I19: =H19
A20: Zakat payable, provisions & other liabilities | B20: =B12-B16-B17-B18-B19 | C20: =C12-C16-C17-C18-C19 | D20: =D12-D16-D17-D18-D19 | E20: =D20 | F20: =E20 | G20: =F20 | H20: =G20 | I20: =H20
A21: TOTAL EQUITY & LIABILITIES | B21: =B16+B17+B18+B19+B20 | C21: =C16+C17+C18+C19+C20 | D21: =D16+D17+D18+D19+D20 | E21: =E16+E17+E18+E19+E20 | F21: =F16+F17+F18+F19+F20 | G21: =G16+G17+G18+G19+G20 | H21: =H16+H17+H18+H19+H20 | I21: =I16+I17+I18+I19+I20
A23: Balance check (assets − L&E) | B23: =B12-B21 | C23: =C12-C21 | D23: =D12-D21 | E23: =E12-E21 | F23: =F12-F21 | G23: =G12-G21 | H23: =H12-H21 | I23: =I12-I21
A24: Net debt — IR basis (borrowings − cash, group def.) | B24: =B17-B10 | C24: =C17-C10 | D24: =D17-D10 | E24: =E17-E10 | F24: =F17-F10 | G24: =G17-G10 | H24: =H17-H10 | I24: =I17-I10
A25: Historic mapping: disclosed IR anchors (total assets, cash+murabaha, total debt, attributable equity) are blue as reported; FY25 line detail (associates 4,641 · financial assets 24,893 · receivables 26,727 · leases 2,253 · payables+financial liabilities 29,610 · NCI 3,482) is from the Q1-2026 FS 31-Dec-25 comparatives; FY23/FY24 line detail is estimated to tie to the disclosed totals (flagged). "Net fixed & intangible assets" and "Zakat payable, provisions & other liabilities" are the balancing lines — shown as formulas off the disclosed totals, so the balance check is exact in every column. FY26E borrowings step up SAR +7,284mn (the completed Jan-2026 $2bn sukuk net of amortisation); gross debt flat thereafter. Two cash framings: FS cash incl. stc bank (21,442 at Q1-26) vs IR core-group cash (15,412) — the model rolls the IR-basis series (FY25: 15,080).
A26: Historic mapping: FY25 line detail from the Q1-2026 FS 31-Dec-25 comparatives (PP&E 95,313 + ROU 2,635 + intangibles 28,139 + inv. property 350 grouped; cash 13,376 + murabaha 1,732). FY23/FY24 detail lines are grouped estimates reconciling to the disclosed IR totals (blue totals are as-disclosed); "Other" lines are the disclosed-total balancing items, shown as formulas. FY26E borrowings step up SAR +7,284mn = the Jan-2026 $2bn sukuk (net of FY26 amortisation) — thereafter gross debt held flat. Two cash framings exist (FS 21,442 incl. stc bank vs IR 15,412 core): the model rolls the FS-basis cash from FY25’s 15,108 (cash + murabaha) and states the IR basis in the net-debt memo.

Sheet Cash Flow
A1: Cash flow (SAR mn, forecast)
A2: Derived from the Income Statement and Balance Sheet; closing cash ties to the Balance Sheet, so the check row is zero.
E4: FY26E | F4: FY27E | G4: FY28E | H4: FY29E | I4: FY30E
A6: Profit for the period (incl. NCI) | E6: ='Income Statement'!E16 | F6: ='Income Statement'!F16 | G6: ='Income Statement'!G16 | H6: ='Income Statement'!H16 | I6: ='Income Statement'!I16
A7: + D&A | E7: =-'Income Statement'!E11 | F7: =-'Income Statement'!F11 | G7: =-'Income Statement'!G11 | H7: =-'Income Statement'!H11 | I7: =-'Income Statement'!I11
A8: − Associates income (non-cash) | E8: =-Assumptions!$C$51 | F8: =-Assumptions!$D$51 | G8: =-Assumptions!$E$51 | H8: =-Assumptions!$F$51 | I8: =-Assumptions!$G$51
A9: − Increase in trade receivables (ΔWC) | E9: =-(('Balance Sheet'!E9)-('Balance Sheet'!D9)) | F9: =-(('Balance Sheet'!F9)-('Balance Sheet'!E9)) | G9: =-(('Balance Sheet'!G9)-('Balance Sheet'!F9)) | H9: =-(('Balance Sheet'!H9)-('Balance Sheet'!G9)) | I9: =-(('Balance Sheet'!I9)-('Balance Sheet'!H9))
A10: Operating cash flow | E10: =SUM(E6:E9) | F10: =SUM(F6:F9) | G10: =SUM(G6:G9) | H10: =SUM(H6:H9) | I10: =SUM(I6:I9)
A11: − Capex | E11: =-Segments!E11*Assumptions!$C$49 | F11: =-Segments!F11*Assumptions!$D$49 | G11: =-Segments!G11*Assumptions!$E$49 | H11: =-Segments!H11*Assumptions!$F$49 | I11: =-Segments!I11*Assumptions!$G$49
A12: Free cash flow | E12: =E10+E11 | F12: =F10+F11 | G12: =G10+G11 | H12: =H10+H11 | I12: =I10+I11
A13: + Increase in borrowings (net) | E13: =7284 | F13: =0 | G13: =0 | H13: =0 | I13: =0
A14: − Dividends paid (attributable) | E14: =-Assumptions!$C$54*Assumptions!$B$6 | F14: =-Assumptions!$D$54*Assumptions!$B$6 | G14: =-Assumptions!$E$54*Assumptions!$B$6 | H14: =-Assumptions!$F$54*Assumptions!$B$6 | I14: =-Assumptions!$G$54*Assumptions!$B$6
A15: Net change in cash | E15: =E12+E13+E14 | F15: =F12+F13+F14 | G15: =G12+G13+G14 | H15: =H12+H13+H14 | I15: =I12+I13+I14
A16: Opening cash | E16: ='Balance Sheet'!D10 | F16: =E17 | G16: =F17 | H16: =G17 | I16: =H17
A17: Closing cash | E17: =E16+E15 | F17: =F16+F15 | G17: =G16+G15 | H17: =H16+H15 | I17: =I16+I15
A19: NCI profit is retained (no NCI dividend modelled — solutions’ minority dividend leakage is inside "net finance & other"). Historical group cash flows: OCF 22,418 / 19,885 / 18,283 and FCF 12,628 / 7,959 / 6,488 (FY23/24/25, stc IR releases; restated). The FY26E borrowings line is the Jan-2026 sukuk already completed.

Sheet Summary Financials
A1: Summary financials (SAR mn)
A2: Every cell links to the statement sheets.
B4: FY23 | C4: FY24 | D4: FY25 | E4: FY26E | F4: FY27E | G4: FY28E | H4: FY29E | I4: FY30E
A6: Revenue | B6: ='Income Statement'!B6 | C6: ='Income Statement'!C6 | D6: ='Income Statement'!D6 | E6: ='Income Statement'!E6 | F6: ='Income Statement'!F6 | G6: ='Income Statement'!G6 | H6: ='Income Statement'!H6 | I6: ='Income Statement'!I6
A7: EBITDA | B7: ='Income Statement'!B9 | C7: ='Income Statement'!C9 | D7: ='Income Statement'!D9 | E7: ='Income Statement'!E9 | F7: ='Income Statement'!F9 | G7: ='Income Statement'!G9 | H7: ='Income Statement'!H9 | I7: ='Income Statement'!I9
A8: EBIT | B8: ='Income Statement'!B12 | C8: ='Income Statement'!C12 | D8: ='Income Statement'!D12 | E8: ='Income Statement'!E12 | F8: ='Income Statement'!F12 | G8: ='Income Statement'!G12 | H8: ='Income Statement'!H12 | I8: ='Income Statement'!I12
A9: Net profit (attributable) | B9: ='Income Statement'!B19 | C9: ='Income Statement'!C19 | D9: ='Income Statement'!D19 | E9: ='Income Statement'!E19 | F9: ='Income Statement'!F19 | G9: ='Income Statement'!G19 | H9: ='Income Statement'!H19 | I9: ='Income Statement'!I19
A10: Total assets | B10: ='Balance Sheet'!B12 | C10: ='Balance Sheet'!C12 | D10: ='Balance Sheet'!D12 | E10: ='Balance Sheet'!E12 | F10: ='Balance Sheet'!F12 | G10: ='Balance Sheet'!G12 | H10: ='Balance Sheet'!H12 | I10: ='Balance Sheet'!I12
A11: Total equity | B11: ='Balance Sheet'!B16 | C11: ='Balance Sheet'!C16 | D11: ='Balance Sheet'!D16 | E11: ='Balance Sheet'!E16 | F11: ='Balance Sheet'!F16 | G11: ='Balance Sheet'!G16 | H11: ='Balance Sheet'!H16 | I11: ='Balance Sheet'!I16
A12: Net debt (IR basis) | B12: ='Balance Sheet'!B24 | C12: ='Balance Sheet'!C24 | D12: ='Balance Sheet'!D24 | E12: ='Balance Sheet'!E24 | F12: ='Balance Sheet'!F24 | G12: ='Balance Sheet'!G24 | H12: ='Balance Sheet'!H24 | I12: ='Balance Sheet'!I24
A13: Free cash flow (forecast) | E13: ='Cash Flow'!E12 | F13: ='Cash Flow'!F12 | G13: ='Cash Flow'!G12 | H13: ='Cash Flow'!H12 | I13: ='Cash Flow'!I12
A14: Free cash flow (historical, disclosed) | B14: 12628 | C14: 7959 | D14: 6488

Sheet Monte Carlo
A1: Monte Carlo — engine outputs (YZ-HAR v2)
A2: 50,000 paths · 16 factors · seed 42 · computed by the Testahil MC engine (values, not a sheet simulation). Zero drift — the Step 0-passed configuration for this name.
A5: The probability read (T+60)
A6: P(price above spot) | B6: 0.54698
A7: P(+10%) vs P(−10%) — odds | B7: 10% vs 6% · 1.7:1
A8: Median level (SAR) and % move | B8: 43.91 (+0.7%)
A9: 50% band (25th–75th) | B9: 42.0 – 45.8 (-3.6% / +5.2%)
A10: Touch(+10%) / touch(−10%) | B10: 17% / 11%
A12: Percentile map (SAR/share)
A13: Horizon | B13: p5 | C13: p25 | D13: p50 | E13: p75 | F13: p95
A14: T+20 sessions | B14: 40.8 | C14: 42.6 | D14: 43.7 | E14: 44.8 | F14: 46.8
A15: T+60 sessions | B15: 39 | C15: 42 | D15: 43.9 | E15: 45.8 | F15: 49.5
A17: Engine inputs (from Assumptions)
A18: Anchor volatility (HAR, annualized) | B18: =Assumptions!B37
A19: Secular drift (daily) — zero-drift class | B19: =Assumptions!B38
A20: Net factor drift / quarter | B20: =Assumptions!B39
A22: Level-touch ladder (probability of touching by horizon)
A23: Level (SAR) | B23: T+20 | C23: T+60
A24: 50 | B24: 0.00844 | C24: 0.06708
A25: 48 | B25: 0.03116 | C25: 0.16298
A26: 46 | B26: 0.15438 | C26: 0.40508
A27: 44 | B27: 0.71468 | C27: 0.84502
A28: 42 | B28: 0.26218 | C28: 0.4823
A29: 40 | B29: 0.03876 | C29: 0.16472
A30: 38 | B30: 0.00724 | C30: 0.05186
A31: 36 | B31: 0.00156 | C31: 0.01692

Sheet Sensitivity
A1: DCF sensitivity — WACC × terminal growth (live formulas)
A2: Fair value per share (SAR). Recomputes the full FCFF stream off the DCF sheet; the centre cell is the base case.
A5: WACC \ terminal g | B5: 0.015 | C5: 0.02 | D5: 0.025 | E5: 0.03 | F5: 0.035
A6: 0.065872674 | B6: =(SUMPRODUCT(DCF!$B$14:$F$14,1/(1+$A6)^{1,2,3,4,5})+DCF!$F$14*(1+B$5)/($A6-B$5)/(1+$A6)^5+Assumptions!$B$19+Assumptions!$B$20-Assumptions!$B$21-Assumptions!$B$22)/Assumptions!$B$6 | C6: =(SUMPRODUCT(DCF!$B$14:$F$14,1/(1+$A6)^{1,2,3,4,5})+DCF!$F$14*(1+C$5)/($A6-C$5)/(1+$A6)^5+Assumptions!$B$19+Assumptions!$B$20-Assumptions!$B$21-Assumptions!$B$22)/Assumptions!$B$6 | D6: =(SUMPRODUCT(DCF!$B$14:$F$14,1/(1+$A6)^{1,2,3,4,5})+DCF!$F$14*(1+D$5)/($A6-D$5)/(1+$A6)^5+Assumptions!$B$19+Assumptions!$B$20-Assumptions!$B$21-Assumptions!$B$22)/Assumptions!$B$6 | E6: =(SUMPRODUCT(DCF!$B$14:$F$14,1/(1+$A6)^{1,2,3,4,5})+DCF!$F$14*(1+E$5)/($A6-E$5)/(1+$A6)^5+Assumptions!$B$19+Assumptions!$B$20-Assumptions!$B$21-Assumptions!$B$22)/Assumptions!$B$6 | F6: =(SUMPRODUCT(DCF!$B$14:$F$14,1/(1+$A6)^{1,2,3,4,5})+DCF!$F$14*(1+F$5)/($A6-F$5)/(1+$A6)^5+Assumptions!$B$19+Assumptions!$B$20-Assumptions!$B$21-Assumptions!$B$22)/Assumptions!$B$6
A7: 0.070872674 | B7: =(SUMPRODUCT(DCF!$B$14:$F$14,1/(1+$A7)^{1,2,3,4,5})+DCF!$F$14*(1+B$5)/($A7-B$5)/(1+$A7)^5+Assumptions!$B$19+Assumptions!$B$20-Assumptions!$B$21-Assumptions!$B$22)/Assumptions!$B$6 | C7: =(SUMPRODUCT(DCF!$B$14:$F$14,1/(1+$A7)^{1,2,3,4,5})+DCF!$F$14*(1+C$5)/($A7-C$5)/(1+$A7)^5+Assumptions!$B$19+Assumptions!$B$20-Assumptions!$B$21-Assumptions!$B$22)/Assumptions!$B$6 | D7: =(SUMPRODUCT(DCF!$B$14:$F$14,1/(1+$A7)^{1,2,3,4,5})+DCF!$F$14*(1+D$5)/($A7-D$5)/(1+$A7)^5+Assumptions!$B$19+Assumptions!$B$20-Assumptions!$B$21-Assumptions!$B$22)/Assumptions!$B$6 | E7: =(SUMPRODUCT(DCF!$B$14:$F$14,1/(1+$A7)^{1,2,3,4,5})+DCF!$F$14*(1+E$5)/($A7-E$5)/(1+$A7)^5+Assumptions!$B$19+Assumptions!$B$20-Assumptions!$B$21-Assumptions!$B$22)/Assumptions!$B$6 | F7: =(SUMPRODUCT(DCF!$B$14:$F$14,1/(1+$A7)^{1,2,3,4,5})+DCF!$F$14*(1+F$5)/($A7-F$5)/(1+$A7)^5+Assumptions!$B$19+Assumptions!$B$20-Assumptions!$B$21-Assumptions!$B$22)/Assumptions!$B$6
A8: 0.075872674 | B8: =(SUMPRODUCT(DCF!$B$14:$F$14,1/(1+$A8)^{1,2,3,4,5})+DCF!$F$14*(1+B$5)/($A8-B$5)/(1+$A8)^5+Assumptions!$B$19+Assumptions!$B$20-Assumptions!$B$21-Assumptions!$B$22)/Assumptions!$B$6 | C8: =(SUMPRODUCT(DCF!$B$14:$F$14,1/(1+$A8)^{1,2,3,4,5})+DCF!$F$14*(1+C$5)/($A8-C$5)/(1+$A8)^5+Assumptions!$B$19+Assumptions!$B$20-Assumptions!$B$21-Assumptions!$B$22)/Assumptions!$B$6 | D8: =(SUMPRODUCT(DCF!$B$14:$F$14,1/(1+$A8)^{1,2,3,4,5})+DCF!$F$14*(1+D$5)/($A8-D$5)/(1+$A8)^5+Assumptions!$B$19+Assumptions!$B$20-Assumptions!$B$21-Assumptions!$B$22)/Assumptions!$B$6 | E8: =(SUMPRODUCT(DCF!$B$14:$F$14,1/(1+$A8)^{1,2,3,4,5})+DCF!$F$14*(1+E$5)/($A8-E$5)/(1+$A8)^5+Assumptions!$B$19+Assumptions!$B$20-Assumptions!$B$21-Assumptions!$B$22)/Assumptions!$B$6 | F8: =(SUMPRODUCT(DCF!$B$14:$F$14,1/(1+$A8)^{1,2,3,4,5})+DCF!$F$14*(1+F$5)/($A8-F$5)/(1+$A8)^5+Assumptions!$B$19+Assumptions!$B$20-Assumptions!$B$21-Assumptions!$B$22)/Assumptions!$B$6
A9: 0.080872674 | B9: =(SUMPRODUCT(DCF!$B$14:$F$14,1/(1+$A9)^{1,2,3,4,5})+DCF!$F$14*(1+B$5)/($A9-B$5)/(1+$A9)^5+Assumptions!$B$19+Assumptions!$B$20-Assumptions!$B$21-Assumptions!$B$22)/Assumptions!$B$6 | C9: =(SUMPRODUCT(DCF!$B$14:$F$14,1/(1+$A9)^{1,2,3,4,5})+DCF!$F$14*(1+C$5)/($A9-C$5)/(1+$A9)^5+Assumptions!$B$19+Assumptions!$B$20-Assumptions!$B$21-Assumptions!$B$22)/Assumptions!$B$6 | D9: =(SUMPRODUCT(DCF!$B$14:$F$14,1/(1+$A9)^{1,2,3,4,5})+DCF!$F$14*(1+D$5)/($A9-D$5)/(1+$A9)^5+Assumptions!$B$19+Assumptions!$B$20-Assumptions!$B$21-Assumptions!$B$22)/Assumptions!$B$6 | E9: =(SUMPRODUCT(DCF!$B$14:$F$14,1/(1+$A9)^{1,2,3,4,5})+DCF!$F$14*(1+E$5)/($A9-E$5)/(1+$A9)^5+Assumptions!$B$19+Assumptions!$B$20-Assumptions!$B$21-Assumptions!$B$22)/Assumptions!$B$6 | F9: =(SUMPRODUCT(DCF!$B$14:$F$14,1/(1+$A9)^{1,2,3,4,5})+DCF!$F$14*(1+F$5)/($A9-F$5)/(1+$A9)^5+Assumptions!$B$19+Assumptions!$B$20-Assumptions!$B$21-Assumptions!$B$22)/Assumptions!$B$6
A10: 0.085872674 | B10: =(SUMPRODUCT(DCF!$B$14:$F$14,1/(1+$A10)^{1,2,3,4,5})+DCF!$F$14*(1+B$5)/($A10-B$5)/(1+$A10)^5+Assumptions!$B$19+Assumptions!$B$20-Assumptions!$B$21-Assumptions!$B$22)/Assumptions!$B$6 | C10: =(SUMPRODUCT(DCF!$B$14:$F$14,1/(1+$A10)^{1,2,3,4,5})+DCF!$F$14*(1+C$5)/($A10-C$5)/(1+$A10)^5+Assumptions!$B$19+Assumptions!$B$20-Assumptions!$B$21-Assumptions!$B$22)/Assumptions!$B$6 | D10: =(SUMPRODUCT(DCF!$B$14:$F$14,1/(1+$A10)^{1,2,3,4,5})+DCF!$F$14*(1+D$5)/($A10-D$5)/(1+$A10)^5+Assumptions!$B$19+Assumptions!$B$20-Assumptions!$B$21-Assumptions!$B$22)/Assumptions!$B$6 | E10: =(SUMPRODUCT(DCF!$B$14:$F$14,1/(1+$A10)^{1,2,3,4,5})+DCF!$F$14*(1+E$5)/($A10-E$5)/(1+$A10)^5+Assumptions!$B$19+Assumptions!$B$20-Assumptions!$B$21-Assumptions!$B$22)/Assumptions!$B$6 | F10: =(SUMPRODUCT(DCF!$B$14:$F$14,1/(1+$A10)^{1,2,3,4,5})+DCF!$F$14*(1+F$5)/($A10-F$5)/(1+$A10)^5+Assumptions!$B$19+Assumptions!$B$20-Assumptions!$B$21-Assumptions!$B$22)/Assumptions!$B$6
A12: The WACC axis centres on the sourced bottom-up build (rf 5.5% + β 0.48 × ERP 5.01%, blended with after-tax Kd 4.5%); the CDS-ERP alternative WACC (7.90%) sits between rows 3 and 4. At β = 1.0 the WACC is 9.90% — off this grid deliberately: see the beta grid below.
A14: Beta sensitivity (regressed β = 0.48 on a 9-week window — grid mandatory)
A15: beta | B15: Ke (rating ERP) | C15: WACC | D15: DCF value/sh
A16: 0.3 | B16: =Assumptions!$B$9+A16*Assumptions!$B$11 | C16: =(1-Assumptions!$B$15)*B16+Assumptions!$B$15*Assumptions!$B$14 | D16: =(SUMPRODUCT(DCF!$B$14:$F$14,1/(1+C16)^{1,2,3,4,5})+DCF!$F$14*(1+Assumptions!$B$17)/(C16-Assumptions!$B$17)/(1+C16)^5+Assumptions!$B$19+Assumptions!$B$20-Assumptions!$B$21-Assumptions!$B$22)/Assumptions!$B$6
A17: 0.48 | B17: =Assumptions!$B$9+A17*Assumptions!$B$11 | C17: =(1-Assumptions!$B$15)*B17+Assumptions!$B$15*Assumptions!$B$14 | D17: =(SUMPRODUCT(DCF!$B$14:$F$14,1/(1+C17)^{1,2,3,4,5})+DCF!$F$14*(1+Assumptions!$B$17)/(C17-Assumptions!$B$17)/(1+C17)^5+Assumptions!$B$19+Assumptions!$B$20-Assumptions!$B$21-Assumptions!$B$22)/Assumptions!$B$6 | E17: <- regressed base
A18: 0.7 | B18: =Assumptions!$B$9+A18*Assumptions!$B$11 | C18: =(1-Assumptions!$B$15)*B18+Assumptions!$B$15*Assumptions!$B$14 | D18: =(SUMPRODUCT(DCF!$B$14:$F$14,1/(1+C18)^{1,2,3,4,5})+DCF!$F$14*(1+Assumptions!$B$17)/(C18-Assumptions!$B$17)/(1+C18)^5+Assumptions!$B$19+Assumptions!$B$20-Assumptions!$B$21-Assumptions!$B$22)/Assumptions!$B$6
A19: 0.85 | B19: =Assumptions!$B$9+A19*Assumptions!$B$11 | C19: =(1-Assumptions!$B$15)*B19+Assumptions!$B$15*Assumptions!$B$14 | D19: =(SUMPRODUCT(DCF!$B$14:$F$14,1/(1+C19)^{1,2,3,4,5})+DCF!$F$14*(1+Assumptions!$B$17)/(C19-Assumptions!$B$17)/(1+C19)^5+Assumptions!$B$19+Assumptions!$B$20-Assumptions!$B$21-Assumptions!$B$22)/Assumptions!$B$6
A20: 1 | B20: =Assumptions!$B$9+A20*Assumptions!$B$11 | C20: =(1-Assumptions!$B$15)*B20+Assumptions!$B$15*Assumptions!$B$14 | D20: =(SUMPRODUCT(DCF!$B$14:$F$14,1/(1+C20)^{1,2,3,4,5})+DCF!$F$14*(1+Assumptions!$B$17)/(C20-Assumptions!$B$17)/(1+C20)^5+Assumptions!$B$19+Assumptions!$B$20-Assumptions!$B$21-Assumptions!$B$22)/Assumptions!$B$6 | E20: <- house fallback had the regression failed
A21: 1.2 | B21: =Assumptions!$B$9+A21*Assumptions!$B$11 | C21: =(1-Assumptions!$B$15)*B21+Assumptions!$B$15*Assumptions!$B$14 | D21: =(SUMPRODUCT(DCF!$B$14:$F$14,1/(1+C21)^{1,2,3,4,5})+DCF!$F$14*(1+Assumptions!$B$17)/(C21-Assumptions!$B$17)/(1+C21)^5+Assumptions!$B$19+Assumptions!$B$20-Assumptions!$B$21-Assumptions!$B$22)/Assumptions!$B$6

Sheet Per-Share & Ratios
A1: Per-share & ratios — the standing dashboard (device A-5)
A2: Links to statements / Assumptions.
B4: FY23 | C4: FY24 | D4: FY25 | E4: FY26E | F4: FY27E | G4: FY28E | H4: FY29E | I4: FY30E
A6: EPS (SAR) | B6: ='Income Statement'!B19/Assumptions!$B$6 | C6: ='Income Statement'!C19/Assumptions!$B$6 | D6: ='Income Statement'!D19/Assumptions!$B$6 | E6: ='Income Statement'!E19/Assumptions!$B$6 | F6: ='Income Statement'!F19/Assumptions!$B$6 | G6: ='Income Statement'!G19/Assumptions!$B$6 | H6: ='Income Statement'!H19/Assumptions!$B$6 | I6: ='Income Statement'!I19/Assumptions!$B$6
A7: DPS declared (SAR) | B7: 1.6 | C7: 3.75 | D7: 2.2 | E7: =Assumptions!C24 | F7: =Assumptions!D24 | G7: =Assumptions!E24 | H7: =Assumptions!F24 | I7: =Assumptions!G24
A8: Book value / share (SAR) | B8: ='Balance Sheet'!B14/Assumptions!$B$6 | C8: ='Balance Sheet'!C14/Assumptions!$B$6 | D8: ='Balance Sheet'!D14/Assumptions!$B$6 | E8: ='Balance Sheet'!E14/Assumptions!$B$6 | F8: ='Balance Sheet'!F14/Assumptions!$B$6 | G8: ='Balance Sheet'!G14/Assumptions!$B$6 | H8: ='Balance Sheet'!H14/Assumptions!$B$6 | I8: ='Balance Sheet'!I14/Assumptions!$B$6
A9: P/E at spot (×) | B9: =Assumptions!$B$5/('Income Statement'!B19/Assumptions!$B$6) | C9: =Assumptions!$B$5/('Income Statement'!C19/Assumptions!$B$6) | D9: =Assumptions!$B$5/('Income Statement'!D19/Assumptions!$B$6) | E9: =Assumptions!$B$5/('Income Statement'!E19/Assumptions!$B$6) | F9: =Assumptions!$B$5/('Income Statement'!F19/Assumptions!$B$6) | G9: =Assumptions!$B$5/('Income Statement'!G19/Assumptions!$B$6) | H9: =Assumptions!$B$5/('Income Statement'!H19/Assumptions!$B$6) | I9: =Assumptions!$B$5/('Income Statement'!I19/Assumptions!$B$6)
A10: P/B at spot (×) | B10: =Assumptions!$B$5/('Balance Sheet'!B14/Assumptions!$B$6) | C10: =Assumptions!$B$5/('Balance Sheet'!C14/Assumptions!$B$6) | D10: =Assumptions!$B$5/('Balance Sheet'!D14/Assumptions!$B$6) | E10: =Assumptions!$B$5/('Balance Sheet'!E14/Assumptions!$B$6) | F10: =Assumptions!$B$5/('Balance Sheet'!F14/Assumptions!$B$6) | G10: =Assumptions!$B$5/('Balance Sheet'!G14/Assumptions!$B$6) | H10: =Assumptions!$B$5/('Balance Sheet'!H14/Assumptions!$B$6) | I10: =Assumptions!$B$5/('Balance Sheet'!I14/Assumptions!$B$6)
A11: Dividend yield at spot (declared) | B11: =B7/Assumptions!$B$5 | C11: =C7/Assumptions!$B$5 | D11: =D7/Assumptions!$B$5 | E11: =E7/Assumptions!$B$5 | F11: =F7/Assumptions!$B$5 | G11: =G7/Assumptions!$B$5 | H11: =H7/Assumptions!$B$5 | I11: =I7/Assumptions!$B$5
A12: Payout (of attributable NP) | B12: =B7*Assumptions!$B$6/'Income Statement'!B19 | C12: =C7*Assumptions!$B$6/'Income Statement'!C19 | D12: =D7*Assumptions!$B$6/'Income Statement'!D19 | E12: =E7*Assumptions!$B$6/'Income Statement'!E19 | F12: =F7*Assumptions!$B$6/'Income Statement'!F19 | G12: =G7*Assumptions!$B$6/'Income Statement'!G19 | H12: =H7*Assumptions!$B$6/'Income Statement'!H19 | I12: =I7*Assumptions!$B$6/'Income Statement'!I19
A13: EBITDA margin | B13: ='Income Statement'!B9/'Income Statement'!B6 | C13: ='Income Statement'!C9/'Income Statement'!C6 | D13: ='Income Statement'!D9/'Income Statement'!D6 | E13: ='Income Statement'!E9/'Income Statement'!E6 | F13: ='Income Statement'!F9/'Income Statement'!F6 | G13: ='Income Statement'!G9/'Income Statement'!G6 | H13: ='Income Statement'!H9/'Income Statement'!H6 | I13: ='Income Statement'!I9/'Income Statement'!I6
A14: Net margin | B14: ='Income Statement'!B19/'Income Statement'!B6 | C14: ='Income Statement'!C19/'Income Statement'!C6 | D14: ='Income Statement'!D19/'Income Statement'!D6 | E14: ='Income Statement'!E19/'Income Statement'!E6 | F14: ='Income Statement'!F19/'Income Statement'!F6 | G14: ='Income Statement'!G19/'Income Statement'!G6 | H14: ='Income Statement'!H19/'Income Statement'!H6 | I14: ='Income Statement'!I19/'Income Statement'!I6
A15: ROAE (attributable) | B15: ='Income Statement'!B19/'Balance Sheet'!B14 | C15: ='Income Statement'!C19/'Balance Sheet'!C14 | D15: ='Income Statement'!D19/'Balance Sheet'!D14 | E15: ='Income Statement'!E19/'Balance Sheet'!E14 | F15: ='Income Statement'!F19/'Balance Sheet'!F14 | G15: ='Income Statement'!G19/'Balance Sheet'!G14 | H15: ='Income Statement'!H19/'Balance Sheet'!H14 | I15: ='Income Statement'!I19/'Balance Sheet'!I14
A16: Net debt (IR) / EBITDA (×) | B16: ='Balance Sheet'!B24/'Income Statement'!B9 | C16: ='Balance Sheet'!C24/'Income Statement'!C9 | D16: ='Balance Sheet'!D24/'Income Statement'!D9 | E16: ='Balance Sheet'!E24/'Income Statement'!E9 | F16: ='Balance Sheet'!F24/'Income Statement'!F9 | G16: ='Balance Sheet'!G24/'Income Statement'!G9 | H16: ='Balance Sheet'!H24/'Income Statement'!H9 | I16: ='Balance Sheet'!I24/'Income Statement'!I9
A17: Capex intensity (% of revenue) | B17: 0.136 | C17: 0.157 | D17: 0.152 | E17: =-'Cash Flow'!E11/'Income Statement'!E6 | F17: =-'Cash Flow'!F11/'Income Statement'!F6 | G17: =-'Cash Flow'!G11/'Income Statement'!G6 | H17: =-'Cash Flow'!H11/'Income Statement'!H6 | I17: =-'Cash Flow'!I11/'Income Statement'!I6
A18: FCF yield at spot (forecast) | E18: ='Cash Flow'!E12/(Assumptions!$B$5*Assumptions!$B$6) | F18: ='Cash Flow'!F12/(Assumptions!$B$5*Assumptions!$B$6) | G18: ='Cash Flow'!G12/(Assumptions!$B$5*Assumptions!$B$6) | H18: ='Cash Flow'!H12/(Assumptions!$B$5*Assumptions!$B$6) | I18: ='Cash Flow'!I12/(Assumptions!$B$5*Assumptions!$B$6)
A19: Revenue YoY | C19: ='Income Statement'!C6/'Income Statement'!B6-1 | D19: ='Income Statement'!D6/'Income Statement'!C6-1 | E19: ='Income Statement'!E6/'Income Statement'!D6-1 | F19: ='Income Statement'!F6/'Income Statement'!E6-1 | G19: ='Income Statement'!G6/'Income Statement'!F6-1 | H19: ='Income Statement'!H6/'Income Statement'!G6-1 | I19: ='Income Statement'!I6/'Income Statement'!H6-1
A20: EPS YoY | C20: =('Income Statement'!C19/'Income Statement'!B19)-1 | D20: =('Income Statement'!D19/'Income Statement'!C19)-1 | E20: =('Income Statement'!E19/'Income Statement'!D19)-1 | F20: =('Income Statement'!F19/'Income Statement'!E19)-1 | G20: =('Income Statement'!G19/'Income Statement'!F19)-1 | H20: =('Income Statement'!H19/'Income Statement'!G19)-1 | I20: =('Income Statement'!I19/'Income Statement'!H19)-1
A22: FY24 EPS/DPS carry the TAWAL disposal gain and the SAR 2.00 special dividend — the payout row prints >100% on the cash-paid framing (141% LTM per stc). Declared-regular vs cash-paid framings both stated (house rule).

Sheet Peer & Sector
A1: Peer set & sector
A2: GCC/regional telecoms; multiples approximate, as-of dates flagged (context, not model inputs).
A5: Name | B5: Mkt | C5: P/E (t) | D5: EV/EBITDA | E5: Div yield | F5: Note
A6: stc (7010) | B6: KSA | C6: 14.7× | D6: 9.5× | E6: 5.0% (9.6% incl. special) | F6: Incumbent; ~57% mobile share; net debt ~0
A7: Mobily (7020) | B7: KSA | C7: 13.5× | D7: ~7.4× | E7: 4.5% | F7: No.2; e& anchor shareholder; fastest sub growth
A8: Zain KSA (7030) | B8: KSA | C8: 12.8× | D8: n/a | E8: 4.9% | F8: No.3; tower-light; higher leverage
A9: e& (EAND) | B9: UAE | C9: 13.2× | D9: n/a | E9: 5.1% | F9: UAE incumbent + international portfolio
A10: Ooredoo (ORDS) | B10: Qatar | C10: 10.7× | D10: n/a | E10: 5.7% | F10: Multi-market; data-centre pivot
A11: du (DU) | B11: UAE | C11: 17.6× | D11: n/a | E11: 5.5% | F11: No.2 UAE; hyperscale DC momentum
A12: Omantel / Beyon / ETEL | B12: Oman/Bah/Egy | C12: 11.5× / 11.1× / 8.8× | D12: n/a | E12: 3.9% / 7.1% / 1.5% | F12: Regional context
A14: Sector: KSA mobile ≈ 57/27/16 stc/Mobily/Zain; Nov-2024 CST spectrum auction (stc: 600MHz + 3.8GHz); 10,800+ stc 5G sites, 63% populated coverage; FTTH 3.75mn; FWA one of the highest-adoption markets globally; center3–HUMAIN 1GW AI-DC ambition; SilkLink Syria fibre corridor (SAR 3bn, Feb-2026). Peer P/E band 10.7–17.6×; stc premium tracks its share, balance sheet and yield.
A15: Analyst context (not a model input): 17 analysts, 8 Buy / 9 Hold, average 12m TP SAR 47.9 (41.1–55.0), Jul-2026.
