Workbook

Sheet READ FIRST
A1: Testahil — Tata Motors Passenger Vehicles Ltd (NSE: TMPV)
A2: Companion model · Independent Valuation Study · Educational analysis · Not investment advice
A5: What this workbook is. A transparent companion to the TMPV valuation study. Every blue cell is an input; every
A6: black cell is a formula; green cells link across sheets. All inputs live on the Assumptions sheet — change one
A7: (the holdco discount, a JLR multiple, a growth rate) and the whole model reprices.
A9: What it is not. It is not investment advice, a recommendation, or a price target. Values are model outputs shown
A10: as ranges. The preparer is not licensed by any securities regulator and may hold a position in the security.
A12: Entity note. Following the Oct-2025 demerger, the name 'Tata Motors Limited' now belongs to the separately-listed
A13: commercial-vehicle company (NSE: TMCV). This model concerns the passenger-vehicle entity, NSE: TMPV (PV + EV + JLR).
A15: Currency. ₹ crore unless stated; JLR in £; FX at study date GBP/INR 125, USD/INR 88. Spot ₹352.20 (30 Jun 2026).
A16: Historical financials are company disclosure (FY26 results, 14 May 2026); some balance-sheet line items are
A17: estimated to balance to disclosed totals (equity, borrowings, cash, provisions) — flagged on the Balance Sheet.
... A20: Income Statement · Balance Sheet · Cash Flow · Summary Financials · Monte Carlo · Sensitivity · Per-Share & Ratios · Peer & Sector.

Sheet Summary
A1: Valuation summary — Tata Motors PV (NSE: TMPV)
A2: Four-lens fair value vs spot. Base links live; bear/bull are scenario outputs (see study §1.5).
B3: Bear | C3: Base | D3: Bull | E3: Weight
A4: Sum-of-the-parts | B4: 221 | C4: =SOTP!C14 -> 379.07558 | D4: 641 | E4: =Assumptions!$B$32 -> 0.4
A5: Consolidated DCF | B5: 217 | C5: =DCF!B19 -> 369.99371 | D5: 582 | E5: =Assumptions!$B$33 -> 0.2
A6: Relative multiples | B6: 223 | C6: ='Relative & Normalized'!C4 -> 327.24113 | D6: 426 | E6: =Assumptions!$B$34 -> 0.15
A7: Normalized earnings | B7: 285 | C7: ='Relative & Normalized'!C6 -> 415.50118 | D7: 570 | E7: =Assumptions!$B$35 -> 0.25
A8: Weighted central | B8: =SUMPRODUCT(B4:B7,E4:E7) -> 236.5 | C8: =SUMPRODUCT(C4:C7,E4:E7) -> 378.59044 | D8: =SUMPRODUCT(D4:D7,E4:E7) -> 579.2
A10: Spot price (₹) | C10: =Assumptions!$B$4 -> 352.2
A11: Upside to central base | C11: =C8/C10-1 -> 0.07493026
A13: Read: modestly undervalued; the swing factor is JLR's margin normalization and the conglomerate discount.

Sheet Fundamental Valuation
A1: Fundamental valuation — football field data
A2: Bear/base/bull per lens (links to Summary).
A3: Lens | B3: Bear | C3: Base | D3: Bull
A4: Sum-of-the-parts | B4: =Summary!B4 -> 221 | C4: =Summary!C4 -> 379.07558 | D4: =Summary!D4 -> 641
A5: Consolidated DCF | B5: =Summary!B5 -> 217 | C5: =Summary!C5 -> 369.99371 | D5: =Summary!D5 -> 582
A6: Relative multiples | B6: =Summary!B6 -> 223 | C6: =Summary!C6 -> 327.24113 | D6: =Summary!D6 -> 426
A7: Normalized earnings | B7: =Summary!B7 -> 285 | C7: =Summary!C7 -> 415.50118 | D7: =Summary!D7 -> 570
A8: Weighted central | B8: =Summary!B8 -> 236.5 | C8: =Summary!C8 -> 378.59044 | D8: =Summary!D8 -> 579.2
A9: Spot | C9: =Assumptions!$B$4 -> 352.2

Sheet Assumptions
A1: Assumptions — the single input layer
A2: All blue cells are inputs. Every other sheet links here.
A3: ANCHORS
A4: Spot price (₹/share) | B4: 352.2
A5: Shares outstanding (cr) | B5: 368.23
A6: GBP/INR | B6: 125
A7: USD/INR | B7: 88
A8: Consolidated net debt (₹ cr) | B8: 30700
A9: WACC | B9: 0.13
A10: Terminal growth | B10: 0.05
A11: Tax rate | B11: 0.25
A13: SOTP — base marks
A14: JLR normalized revenue (£bn) | B14: 28
A15: JLR normalized EBITDA margin | B15: 0.12
A16: JLR EV/EBITDA multiple | B16: 3
A17: JLR net debt (£bn) | B17: 2.6
A18: India PV-ICE normalized EBITDA (₹ cr) | B18: 3560
A19: India PV-ICE EV/EBITDA | B19: 7
A20: India EV (TPEM) mark (₹ cr) | B20: 38000
A21: Other (JV/brand/financing, ₹ cr) | B21: 6000
A22: Conglomerate / complexity discount | B22: 0.15
A23: Other revenue, forecast (₹ cr) | B23: 4000
A25: RELATIVE & NORMALIZED
A26: Normalized consolidated EBITDA (₹ cr) | B26: 42000
A27: EV/EBITDA target multiple | B27: 3.6
A28: Mid-cycle PAT (₹ cr) | B28: 18000
A29: Justified P/E | B29: 8.5
A31: SYNTHESIS WEIGHTS
A32: SOTP weight | B32: 0.4
A33: DCF weight | B33: 0.2
A34: Relative weight | B34: 0.15
A35: Normalized-earnings weight | B35: 0.25
A37: WORKING CAPITAL (% of revenue)
A38: Inventory | B38: 0.135
A39: Receivables | B39: 0.085
A40: Payables | B40: 0.22
A42: MONTE CARLO
A43: Diffusion volatility (annualized) | B43: 0.35401235
A44: Net 3-month drift | B44: 0.01785
A45: KVOL (calibration multiplier) | B45: 1.15
...

Sheet SOTP
A1: Sum-of-the-parts (primary lens)
A2: Each part marked on the basis that fits it, spot-FX. Links to Assumptions.
A3: Part | B3: Basis | C3: Value (₹ cr)
A4: Jaguar Land Rover | B4: Norm. EBITDA × EV/EBITDA, £→₹ | C4: =Assumptions!$B$14*Assumptions!$B$15*Assumptions!$B$16*Assumptions!$B$6*100 -> 126000
A5: India PV (ICE) | B5: EBITDA × multiple | C5: =Assumptions!$B$18*Assumptions!$B$19 -> 24920
A6: India EV (TPEM) | B6: Haircut private mark | C6: =Assumptions!$B$20 -> 38000
A7: Other (JV/brand/financing) | B7: Residual | C7: =Assumptions!$B$21 -> 6000
A8: Σ Enterprise value | C8: =SUM(C4:C7) -> 194920
A9: less: consolidated net debt | C9: =-Assumptions!$B$8 -> -30700
A10: Equity value (pre-discount) | C10: =C8+C9 -> 164220
A11: per share (₹) | C11: =C10/Assumptions!$B$5 -> 445.97127
A12: less: conglomerate discount | B12: applied | C12: =-C10*Assumptions!$B$22 -> -24633
A13: SOTP equity value | C13: =C10+C12 -> 139587
A14: SOTP fair value per share (₹) | C14: =C13/Assumptions!$B$5 -> 379.07558
A15: JLR EV (£bn), for reference | C15: =Assumptions!$B$14*Assumptions!$B$15*Assumptions!$B$16 -> 10.08

Sheet Segments
A1: Segment view
A2: Revenue and EBIT by segment, FY24–FY31 (links to Income Statement).
B3: FY24 | C3: FY25 | D3: FY26 | E3: FY27E | F3: FY28E | G3: FY29E | H3: FY30E | I3: FY31E
A4: JLR revenue | B4: ='Income Statement'!B4 -> 301548 | C4: ='Income Statement'!C4 -> 314220 | D4: ='Income Statement'!D4 -> 273303 | E4: ='Income Statement'!E4 -> 311565.42 | F4: ='Income Statement'!F4 -> 336490.65 | G4: ='Income Statement'!G4 -> 356680.09 | H4: ='Income Statement'!H4 -> 374514.1 | I4: ='Income Statement'!I4 -> 389494.66
A5: India PV+EV revenue | B5: ='Income Statement'!B5 -> 52353 | C5: ='Income Statement'!C5 -> 48451 | D5: ='Income Statement'!D5 -> 58465 | E5: ='Income Statement'!E5 -> 68988.7 | F5: ='Income Statement'!F5 -> 80026.892 | G5: ='Income Statement'!G5 -> 91230.657 | H5: ='Income Statement'!H5 -> 102178.34 | I5: ='Income Statement'!I5 -> 112396.17
A6: JLR EBIT | B6: ='Income Statement'!B9 -> 25632 | C6: ='Income Statement'!C9 -> 27764 | D6: ='Income Statement'!D9 -> 2680 | E6: ='Income Statement'!E9 -> 12462.617 | F6: ='Income Statement'!F9 -> 18506.986 | G6: ='Income Statement'!G9 -> 23184.206 | H6: ='Income Statement'!H9 -> 26215.987 | I6: ='Income Statement'!I9 -> 27264.626
A7: India EBIT | B7: ='Income Statement'!B10 -> 1000 | C7: ='Income Statement'!C10 -> 471 | D7: ='Income Statement'!D10 -> 825 | E7: ='Income Statement'!E10 -> 1724.7175 | F7: ='Income Statement'!F10 -> 2400.8068 | G7: ='Income Statement'!G10 -> 3193.073 | H7: ='Income Statement'!H10 -> 4087.1334 | I7: ='Income Statement'!I10 -> 5057.8276
A8: JLR EBIT margin | B8: =B6/B4 -> 0.085001393 | C8: =C6/C4 -> 0.088358475 | D8: =D6/D4 -> 0.0098059663 | E8: =E6/E4 -> 0.04 | F8: =F6/F4 -> 0.055 | G8: =G6/G4 -> 0.065 | H8: =H6/H4 -> 0.07 | I8: =I6/I4 -> 0.07
A9: India EBIT margin | B9: =B7/B5 -> 0.019101102 | C9: =C7/C5 -> 0.0097211616 | D9: =D7/D5 -> 0.014111007 | E9: =E7/E5 -> 0.025 | F9: =F7/F5 -> 0.03 | G9: =G7/G5 -> 0.035 | H9: =H7/H5 -> 0.04 | I9: =I7/I5 -> 0.045
A10: JLR % of revenue | B10: =B4/'Income Statement'!B7 -> 0.85183051 | C10: =C4/'Income Statement'!C7 -> 0.85830415 | D10: =D4/'Income Statement'!D7 -> 0.81441496 | E10: =E4/'Income Statement'!E7 -> 0.81019915 | F10: =F4/'Income Statement'!F7 -> 0.8001822 | G10: =G4/'Income Statement'!G7 -> 0.7892711 | H10: =H4/'Income Statement'!H7 -> 0.77911378 | I10: =I4/'Income Statement'!I7 -> 0.7699184

Sheet Relative & Normalized
A1: Relative & normalized-earnings lenses
A2: Links to Assumptions.
A3: Lens | B3: Workings | C3: ₹/share
A4: Relative EV/EBITDA | B4: Norm EBITDA × mult − net debt, /sh | C4: =(Assumptions!$B$26*Assumptions!$B$27-Assumptions!$B$8)/Assumptions!$B$5 -> 327.24113
A5: implied EV (₹ cr) | C5: =Assumptions!$B$26*Assumptions!$B$27 -> 151200
A6: Normalized earnings | B6: Mid-cycle PAT × P/E, /sh | C6: =Assumptions!$B$28*Assumptions!$B$29/Assumptions!$B$5 -> 415.50118
A7: normalized EPS (₹) | C7: =Assumptions!$B$28/Assumptions!$B$5 -> 48.882492

Sheet DCF
A1: Discounted cash flow — explicit 5-year FCFF
A2: NOPAT + D&A − capex − ΔWC, discounted at WACC. Links to Income Statement / Balance Sheet / Assumptions.
B3: FY27E | C3: FY28E | D3: FY29E | E3: FY30E | F3: FY31E
A4: EBIT | E4: ='Income Statement'!E12 -> 14187.334 | F4: ='Income Statement'!F12 -> 20907.793 | G4: ='Income Statement'!G12 -> 26377.279 | H4: ='Income Statement'!H12 -> 30303.12 | I4: ='Income Statement'!I12 -> 32322.454
A5: NOPAT = EBIT×(1−tax) | E5: =E4*(1-Assumptions!$B$11) -> 10640.501 | F5: =F4*(1-Assumptions!$B$11) -> 15680.845 | G5: =G4*(1-Assumptions!$B$11) -> 19782.959 | H5: =H4*(1-Assumptions!$B$11) -> 22727.34 | I5: =I4*(1-Assumptions!$B$11) -> 24241.84
A6: + D&A | E6: ='Income Statement'!E13 -> 21150.477 | F6: ='Income Statement'!F13 -> 22707.947 | G6: ='Income Statement'!G13 -> 23951.27 | H6: ='Income Statement'!H13 -> 24996.007 | I6: ='Income Statement'!I13 -> 25800.432
A7: − Capex | E7: =-Assumptions!E57 -> -38000 | F7: =-Assumptions!F57 -> -37000 | G7: =-Assumptions!G57 -> -33000 | H7: =-Assumptions!H57 -> -31000 | I7: =-Assumptions!I57 -> -30000
A8: − Increase in net WC | E8: =-(('Balance Sheet'!E5+'Balance Sheet'!E6-'Balance Sheet'!E15)-('Balance Sheet'!D5+'Balance Sheet'!D6-'Balance Sheet'!D15)) -> 0 | F8: =-(('Balance Sheet'!F5+'Balance Sheet'!F6-'Balance Sheet'!F15)-('Balance Sheet'!E5+'Balance Sheet'!E6-'Balance Sheet'!E15)) -> 0 | G8: =-(('Balance Sheet'!G5+'Balance Sheet'!G6-'Balance Sheet'!G15)-('Balance Sheet'!F5+'Balance Sheet'!F6-'Balance Sheet'!F15)) -> 0 | H8: =-(('Balance Sheet'!H5+'Balance Sheet'!H6-'Balance Sheet'!H15)-('Balance Sheet'!G5+'Balance Sheet'!G6-'Balance Sheet'!G15)) -> 0 | I8: =-(('Balance Sheet'!I5+'Balance Sheet'!I6-'Balance Sheet'!I15)-('Balance Sheet'!H5+'Balance Sheet'!H6-'Balance Sheet'!H15)) -> 0
A9: FCFF | E9: =E5+E6+E7+E8 -> -6209.0227 | F9: =F5+F6+F7+F8 -> 1388.792 | G9: =G5+G6+G7+G8 -> 10734.229 | H9: =H5+H6+H7+H8 -> 16723.347 | I9: =I5+I6+I7+I8 -> 20042.273
A10: Discount factor | E10: =1/(1+Assumptions!$B$9)^1 -> 0.88495575 | F10: =1/(1+Assumptions!$B$9)^2 -> 0.78314668 | G10: =1/(1+Assumptions!$B$9)^3 -> 0.69305016 | H10: =1/(1+Assumptions!$B$9)^4 -> 0.61331873 | I10: =1/(1+Assumptions!$B$9)^5 -> 0.54275994
A11: PV of FCFF | E11: =E9*E10 -> -5494.7103 | F11: =F9*F10 -> 1087.6278 | G11: =G9*G10 -> 7439.3592 | H11: =H9*H10 -> 10256.742 | I11: =I9*I10 -> 10878.143
A13: Σ PV of explicit FCFF (FY27–31) | B13: =SUM(E11:I11) -> 24167.161
A14: Terminal value (Gordon) | B14: =I9*(1+Assumptions!$B$10)/(Assumptions!$B$9-Assumptions!$B$10) -> 263054.83
A15: PV of terminal value | B15: =B14/(1+Assumptions!$B$9)^5 -> 142775.62
A16: Enterprise value | B16: =B13+B15 -> 166942.78
A17: less: consolidated net debt | B17: =-Assumptions!$B$8 -> -30700
A18: Equity value | B18: =B16+B17 -> 136242.78
A19: Fair value per share (₹) | B19: =B18/Assumptions!$B$5 -> 369.99371
A20: % terminal of EV | B20: =B15/B16 -> 0.85523686

Sheet Income Statement
A1: Income statement (₹ cr, consolidated, continuing ops)
A2: FY24–FY26 disclosed (blue); FY27–FY31 forecast (formulas linking to Assumptions)
B3: FY24 | C3: FY25 | D3: FY26 | E3: FY27E | F3: FY28E | G3: FY29E | H3: FY30E | I3: FY31E
A4: JLR revenue | B4: 301548 | C4: 314220 | D4: 273303 | E4: =D4*(1+Assumptions!E49) -> 311565.42 | F4: =E4*(1+Assumptions!F49) -> 336490.65 | G4: =F4*(1+Assumptions!G49) -> 356680.09 | H4: =G4*(1+Assumptions!H49) -> 374514.1 | I4: =H4*(1+Assumptions!I49) -> 389494.66
A5: India PV+EV revenue | B5: 52353 | C5: 48451 | D5: 58465 | E5: =D5*(1+Assumptions!E50) -> 68988.7 | F5: =E5*(1+Assumptions!F50) -> 80026.892 | G5: =F5*(1+Assumptions!G50) -> 91230.657 | H5: =G5*(1+Assumptions!H50) -> 102178.34 | I5: =H5*(1+Assumptions!I50) -> 112396.17
A6: Other revenue | B6: 99 | C6: 3423 | D6: 3814 | E6: =Assumptions!$B$23 -> 4000 | F6: =Assumptions!$B$23 -> 4000 | G6: =Assumptions!$B$23 -> 4000 | H6: =Assumptions!$B$23 -> 4000 | I6: =Assumptions!$B$23 -> 4000
A7: Total revenue | B7: =SUM(B4:B6) -> 354000 | C7: =SUM(C4:C6) -> 366094 | D7: =SUM(D4:D6) -> 335582 | E7: =SUM(E4:E6) -> 384554.12 | F7: =SUM(F4:F6) -> 420517.55 | G7: =SUM(G4:G6) -> 451910.75 | H7: =SUM(H4:H6) -> 480692.43 | I7: =SUM(I4:I6) -> 505890.83
A9: JLR EBIT | B9: 25632 | C9: 27764 | D9: 2680 | E9: =E4*Assumptions!E51 -> 12462.617 | F9: =F4*Assumptions!F51 -> 18506.986 | G9: =G4*Assumptions!G51 -> 23184.206 | H9: =H4*Assumptions!H51 -> 26215.987 | I9: =I4*Assumptions!I51 -> 27264.626
A10: India EBIT | B10: 1000 | C10: 471 | D10: 825 | E10: =E5*Assumptions!E52 -> 1724.7175 | F10: =F5*Assumptions!F52 -> 2400.8068 | G10: =G5*Assumptions!G52 -> 3193.073 | H10: =H5*Assumptions!H52 -> 4087.1334 | I10: =I5*Assumptions!I52 -> 5057.8276
A11: Corporate / other / elim | B11: -2200 | C11: -5000 | D11: 185 | E11: 0 | F11: 0 | G11: 0 | H11: 0 | I11: 0
A12: EBIT | B12: =SUM(B9:B11) -> 24432 | C12: =SUM(C9:C11) -> 23235 | D12: =SUM(D9:D11) -> 3690 | E12: =SUM(E9:E11) -> 14187.334 | F12: =SUM(F9:F11) -> 20907.793 | G12: =SUM(G9:G11) -> 26377.279 | H12: =SUM(H9:H11) -> 30303.12 | I12: =SUM(I9:I11) -> 32322.454
A13: D&A | B13: 23600 | C13: 23900 | D13: 19130 | E13: =E7*Assumptions!E53 -> 21150.477 | F13: =F7*Assumptions!F53 -> 22707.947 | G13: =G7*Assumptions!G53 -> 23951.27 | H13: =H7*Assumptions!H53 -> 24996.007 | I13: =I7*Assumptions!I53 -> 25800.432
A14: EBITDA | B14: =B12+B13 -> 48032 | C14: =C12+C13 -> 47135 | D14: =D12+D13 -> 22820 | E14: =E12+E13 -> 35337.811 | F14: =F12+F13 -> 43615.74 | G14: =G12+G13 -> 50328.549 | H14: =H12+H13 -> 55299.127 | I14: =I12+I13 -> 58122.886
A15: EBITDA margin | B15: =B14/B7 -> 0.13568362 | C15: =C14/C7 -> 0.12875109 | D15: =D14/D7 -> 0.068001263 | E15: =E14/E7 -> 0.091892946 | F15: =F14/F7 -> 0.10371919 | G15: =G14/G7 -> 0.11136834 | H15: =H14/H7 -> 0.11504056 | I15: =I14/I7 -> 0.11489215
A16: Finance cost | B16: 4500 | C16: 3901 | D16: 2827 | E16: =Assumptions!E54 -> 2800 | F16: =Assumptions!F54 -> 2600 | G16: =Assumptions!G54 -> 2400 | H16: =Assumptions!H54 -> 2200 | I16: =Assumptions!I54 -> 2000
A17: Other income | B17: 2721 | C17: 2769 | D17: 2700 | E17: =Assumptions!E55 -> 2700 | F17: =Assumptions!F55 -> 2750 | G17: =Assumptions!G55 -> 2800 | H17: =Assumptions!H55 -> 2850 | I17: =Assumptions!I55 -> 2900
A18: JV / associates | B18: 700 | C18: 288 | D18: -1044 | E18: =Assumptions!E56 -> 0 | F18: =Assumptions!F56 -> 300 | G18: =Assumptions!G56 -> 500 | H18: =Assumptions!H56 -> 700 | I18: =Assumptions!I56 -> 800
A19: PBT (before exceptionals) | B19: =B12-B16+B17+B18 -> 23353 | C19: =C12-C16+C17+C18 -> 22391 | D19: =D12-D16+D17+D18 -> 2519 | E19: =E12-E16+E17+E18 -> 14087.334 | F19: =F12-F16+F17+F18 -> 21357.793 | G19: =G12-G16+G17+G18 -> 27277.279 | H19: =H12-H16+H17+H18 -> 31653.12 | I19: =I12-I16+I17+I18 -> 34022.454
A20: Exceptional items | B20: 0 | C20: -196 | D20: -4142 | E20: 0 | F20: 0 | G20: 0 | H20: 0 | I20: 0
A21: PBT | B21: =B19+B20 -> 23353 | C21: =C19+C20 -> 22195 | D21: =D19+D20 -> -1623 | E21: =E19+E20 -> 14087.334 | F21: =F19+F20 -> 21357.793 | G21: =G19+G20 -> 27277.279 | H21: =H19+H20 -> 31653.12 | I21: =I19+I20 -> 34022.454
A22: Tax | B22: 5838.25 | C22: 2801 | D22: -246 | E22: =MAX(0,E21)*Assumptions!$B$11 -> 3521.8336 | F22: =MAX(0,F21)*Assumptions!$B$11 -> 5339.4482 | G22: =MAX(0,G21)*Assumptions!$B$11 -> 6819.3198 | H22: =MAX(0,H21)*Assumptions!$B$11 -> 7913.2801 | I22: =MAX(0,I21)*Assumptions!$B$11 -> 8505.6135
A23: PAT | B23: 17514.75 | C23: 19394 | D23: -1377 | E23: =E21-E22 -> 10565.501 | F23: =F21-F22 -> 16018.345 | G23: =G21-G22 -> 20457.959 | H23: =H21-H22 -> 23739.84 | I23: =I21-I22 -> 25516.84
A25: Source: TMPV FY26 results (14 May 2026); FY24 a PV-entity proxy (£28,995mn@~104 + India ₹52,353cr). Forecast = formulas.

Sheet Balance Sheet
A1: Balance sheet (₹ cr, consolidated)
A2: Historical anchored to disclosed equity/borrowings/cash/provisions; PP&E plugs to balance. Forecast rolls forward.
B3: FY24 | C3: FY25 | D3: FY26 | E3: FY27E | F3: FY28E | G3: FY29E | H3: FY30E | I3: FY31E
A4: PP&E + intangibles | B4: =(B12+B13+B14+B15+B16)-(B5+B6+B7+B8+B9) -> 206500 | C4: =(C12+C13+C14+C15+C16)-(C5+C6+C7+C8+C9) -> 198954 | D4: =(D12+D13+D14+D15+D16)-(D5+D6+D7+D8+D9) -> 195405 | E4: =D4+Assumptions!E57-'Income Statement'!E13 -> 212254.52 | F4: =E4+Assumptions!F57-'Income Statement'!F13 -> 226546.58 | G4: =F4+Assumptions!G57-'Income Statement'!G13 -> 235595.31 | H4: =G4+Assumptions!H57-'Income Statement'!H13 -> 241599.3 | I4: =H4+Assumptions!I57-'Income Statement'!I13 -> 245798.87
A5: Inventory | B5: ='Income Statement'!B7*Assumptions!$B$38 -> 47790 | C5: ='Income Statement'!C7*Assumptions!$B$38 -> 49422.69 | D5: ='Income Statement'!D7*Assumptions!$B$38 -> 45303.57 | E5: ='Income Statement'!E7*Assumptions!$B$38 -> 51914.806 | F5: ='Income Statement'!F7*Assumptions!$B$38 -> 56769.869 | G5: ='Income Statement'!G7*Assumptions!$B$38 -> 61007.951 | H5: ='Income Statement'!H7*Assumptions!$B$38 -> 64893.478 | I5: ='Income Statement'!I7*Assumptions!$B$38 -> 68295.262
A6: Receivables | B6: ='Income Statement'!B7*Assumptions!$B$39 -> 30090 | C6: ='Income Statement'!C7*Assumptions!$B$39 -> 31117.99 | D6: ='Income Statement'!D7*Assumptions!$B$39 -> 28524.47 | E6: ='Income Statement'!E7*Assumptions!$B$39 -> 32687.1 | F6: ='Income Statement'!F7*Assumptions!$B$39 -> 35743.991 | G6: ='Income Statement'!G7*Assumptions!$B$39 -> 38412.414 | H6: ='Income Statement'!H7*Assumptions!$B$39 -> 40858.857 | I6: ='Income Statement'!I7*Assumptions!$B$39 -> 43000.721
A7: Cash & equivalents | B7: 27500 | C7: 24600 | D7: 22880 | E7: =D7+('Income Statement'!E23+'Income Statement'!E13-((E5+E6-E15)-(D5+D6-D15)))-Assumptions!E57-Assumptions!E58-Assumptions!E59 -> 14395.977 | F7: =E7+('Income Statement'!F23+'Income Statement'!F13-((F5+F6-F15)-(E5+E6-E15)))-Assumptions!F57-Assumptions!F58-Assumptions!F59 -> 13522.269 | G7: =F7+('Income Statement'!G23+'Income Statement'!G13-((G5+G6-G15)-(F5+F6-F15)))-Assumptions!G57-Assumptions!G58-Assumptions!G59 -> 17731.498 | H7: =G7+('Income Statement'!H23+'Income Statement'!H13-((H5+H6-H15)-(G5+G6-G15)))-Assumptions!H57-Assumptions!H58-Assumptions!H59 -> 26467.345 | I7: =H7+('Income Statement'!I23+'Income Statement'!I13-((I5+I6-I15)-(H5+H6-H15)))-Assumptions!I57-Assumptions!I58-Assumptions!I59 -> 37784.618
A8: Current investments | B8: 14000 | C8: 15200 | D8: 16200 | E8: =D8 -> 16200 | F8: =E8 -> 16200 | G8: =F8 -> 16200 | H8: =G8 -> 16200 | I8: =H8 -> 16200
A9: Other assets | B9: 38000 | C9: 39000 | D9: 40000 | E9: =D9 -> 40000 | F9: =E9 -> 40000 | G9: =F9 -> 40000 | H9: =G9 -> 40000 | I9: =H9 -> 40000
A10: Total assets | B10: =SUM(B4:B9) -> 363880 | C10: =SUM(C4:C9) -> 358294.68 | D10: =SUM(D4:D9) -> 348313.04 | E10: =SUM(E4:E9) -> 367452.41 | F10: =SUM(F4:F9) -> 388782.71 | G10: =SUM(G4:G9) -> 408947.17 | H10: =SUM(H4:H9) -> 430018.98 | I10: =SUM(I4:I9) -> 451079.47
A12: Equity | B12: 131500 | C12: 122754 | D12: 118842 | E12: =D12+'Income Statement'!E23-Assumptions!E58 -> 127207.5 | F12: =E12+'Income Statement'!F23-Assumptions!F58 -> 140625.85 | G12: =F12+'Income Statement'!G23-Assumptions!G58 -> 157883.8 | H12: =G12+'Income Statement'!H23-Assumptions!H58 -> 177623.64 | I12: =H12+'Income Statement'!I23-Assumptions!I58 -> 198140.49
A13: Borrowings | B13: 78500 | C13: 74200 | D13: 69953 | E13: =D13-Assumptions!E59 -> 69953 | F13: =E13-Assumptions!F59 -> 69953 | G13: =F13-Assumptions!G59 -> 65953 | H13: =G13-Assumptions!H59 -> 60953 | I13: =H13-Assumptions!I59 -> 55953
A14: Provisions | B14: 34000 | C14: 36800 | D14: 39690 | E14: =D14 -> 39690 | F14: =E14 -> 39690 | G14: =F14 -> 39690 | H14: =G14 -> 39690 | I14: =H14 -> 39690
A15: Payables | B15: ='Income Statement'!B7*Assumptions!$B$40 -> 77880 | C15: ='Income Statement'!C7*Assumptions!$B$40 -> 80540.68 | D15: ='Income Statement'!D7*Assumptions!$B$40 -> 73828.04 | E15: ='Income Statement'!E7*Assumptions!$B$40 -> 84601.906 | F15: ='Income Statement'!F7*Assumptions!$B$40 -> 92513.86 | G15: ='Income Statement'!G7*Assumptions!$B$40 -> 99420.365 | H15: ='Income Statement'!H7*Assumptions!$B$40 -> 105752.34 | I15: ='Income Statement'!I7*Assumptions!$B$40 -> 111295.98
A16: Other liabilities | B16: 42000 | C16: 44000 | D16: 46000 | E16: =D16 -> 46000 | F16: =E16 -> 46000 | G16: =F16 -> 46000 | H16: =G16 -> 46000 | I16: =H16 -> 46000
A17: Total liabilities & equity | B17: =B12+B13+B14+B15+B16 -> 363880 | C17: =C12+C13+C14+C15+C16 -> 358294.68 | D17: =D12+D13+D14+D15+D16 -> 348313.04 | E17: =E12+E13+E14+E15+E16 -> 367452.41 | F17: =F12+F13+F14+F15+F16 -> 388782.71 | G17: =G12+G13+G14+G15+G16 -> 408947.17 | H17: =H12+H13+H14+H15+H16 -> 430018.98 | I17: =I12+I13+I14+I15+I16 -> 451079.47
A19: Balance check (assets − L&E) | B19: =B10-B17 -> 0 | C19: =C10-C17 -> 0 | D19: =D10-D17 -> 0 | E19: =E10-E17 -> 0 | F19: =F10-F17 -> 0 | G19: =G10-G17 -> 0 | H19: =H10-H17 -> 0 | I19: =I10-I17 -> 0
A20: Net debt | B20: =B13-B7-B8 -> 37000 | C20: =C13-C7-C8 -> 34400 | D20: =D13-D7-D8 -> 30873 | E20: =E13-E7-E8 -> 39357.023 | F20: =F13-F7-F8 -> 40230.731 | G20: =G13-G7-G8 -> 32021.502 | H20: =H13-H7-H8 -> 18285.655 | I20: =I13-I7-I8 -> 1968.3822

Sheet Cash Flow
A1: Cash flow (₹ cr, forecast)
A2: Derived from the Income Statement and Balance Sheet. Closing cash ties to the Balance Sheet.
B3: FY27E | C3: FY28E | D3: FY29E | E3: FY30E | F3: FY31E
A4: PAT | E4: ='Income Statement'!E23 -> 10565.501 | F4: ='Income Statement'!F23 -> 16018.345 | G4: ='Income Statement'!G23 -> 20457.959 | H4: ='Income Statement'!H23 -> 23739.84 | I4: ='Income Statement'!I23 -> 25516.84
A5: + D&A | E5: ='Income Statement'!E13 -> 21150.477 | F5: ='Income Statement'!F13 -> 22707.947 | G5: ='Income Statement'!G13 -> 23951.27 | H5: ='Income Statement'!H13 -> 24996.007 | I5: ='Income Statement'!I13 -> 25800.432
A6: − Increase in net working capital | E6: =-(('Balance Sheet'!E5+'Balance Sheet'!E6-'Balance Sheet'!E15)-('Balance Sheet'!D5+'Balance Sheet'!D6-'Balance Sheet'!D15)) -> 0 | F6: =-(('Balance Sheet'!F5+'Balance Sheet'!F6-'Balance Sheet'!F15)-('Balance Sheet'!E5+'Balance Sheet'!E6-'Balance Sheet'!E15)) -> 0 | G6: =-(('Balance Sheet'!G5+'Balance Sheet'!G6-'Balance Sheet'!G15)-('Balance Sheet'!F5+'Balance Sheet'!F6-'Balance Sheet'!F15)) -> 0 | H6: =-(('Balance Sheet'!H5+'Balance Sheet'!H6-'Balance Sheet'!H15)-('Balance Sheet'!G5+'Balance Sheet'!G6-'Balance Sheet'!G15)) -> 0 | I6: =-(('Balance Sheet'!I5+'Balance Sheet'!I6-'Balance Sheet'!I15)-('Balance Sheet'!H5+'Balance Sheet'!H6-'Balance Sheet'!H15)) -> 0
A7: Operating cash flow | E7: =E4+E5+E6 -> 31715.977 | F7: =F4+F5+F6 -> 38726.292 | G7: =G4+G5+G6 -> 44409.229 | H7: =H4+H5+H6 -> 48735.847 | I7: =I4+I5+I6 -> 51317.273
A8: − Capex | E8: =-Assumptions!E57 -> -38000 | F8: =-Assumptions!F57 -> -37000 | G8: =-Assumptions!G57 -> -33000 | H8: =-Assumptions!H57 -> -31000 | I8: =-Assumptions!I57 -> -30000
A9: Free cash flow | E9: =E7+E8 -> -6284.0227 | F9: =F7+F8 -> 1726.292 | G9: =G7+G8 -> 11409.229 | H9: =H7+H8 -> 17735.847 | I9: =I7+I8 -> 21317.273
A10: − Dividend | E10: =-Assumptions!E58 -> -2200 | F10: =-Assumptions!F58 -> -2600 | G10: =-Assumptions!G58 -> -3200 | H10: =-Assumptions!H58 -> -4000 | I10: =-Assumptions!I58 -> -5000
A11: − Debt repayment | E11: =-Assumptions!E59 -> 0 | F11: =-Assumptions!F59 -> 0 | G11: =-Assumptions!G59 -> -4000 | H11: =-Assumptions!H59 -> -5000 | I11: =-Assumptions!I59 -> -5000
A12: Net change in cash | E12: =E9+E10+E11 -> -8484.0227 | F12: =F9+F10+F11 -> -873.70801 | G12: =G9+G10+G11 -> 4209.229 | H12: =H9+H10+H11 -> 8735.8467 | I12: =I9+I10+I11 -> 11317.273
A13: Opening cash | E13: ='Balance Sheet'!D7 -> 22880 | F13: ='Balance Sheet'!E7 -> 14395.977 | G13: ='Balance Sheet'!F7 -> 13522.269 | H13: ='Balance Sheet'!G7 -> 17731.498 | I13: ='Balance Sheet'!H7 -> 26467.345
A14: Closing cash | E14: =E13+E12 -> 14395.977 | F14: =F13+F12 -> 13522.269 | G14: =G13+G12 -> 17731.498 | H14: =H13+H12 -> 26467.345 | I14: =I13+I12 -> 37784.618

Sheet Summary Financials
A1: Summary financials (₹ cr)
A2: Every cell links to the statement sheets.
B3: FY24 | C3: FY25 | D3: FY26 | E3: FY27E | F3: FY28E | G3: FY29E | H3: FY30E | I3: FY31E
A4: Revenue | B4: ='Income Statement'!B7 -> 354000 | C4: ='Income Statement'!C7 -> 366094 | D4: ='Income Statement'!D7 -> 335582 | E4: ='Income Statement'!E7 -> 384554.12 | F4: ='Income Statement'!F7 -> 420517.55 | G4: ='Income Statement'!G7 -> 451910.75 | H4: ='Income Statement'!H7 -> 480692.43 | I4: ='Income Statement'!I7 -> 505890.83
A5: EBITDA | B5: ='Income Statement'!B14 -> 48032 | C5: ='Income Statement'!C14 -> 47135 | D5: ='Income Statement'!D14 -> 22820 | E5: ='Income Statement'!E14 -> 35337.811 | F5: ='Income Statement'!F14 -> 43615.74 | G5: ='Income Statement'!G14 -> 50328.549 | H5: ='Income Statement'!H14 -> 55299.127 | I5: ='Income Statement'!I14 -> 58122.886
A6: EBIT | B6: ='Income Statement'!B12 -> 24432 | C6: ='Income Statement'!C12 -> 23235 | D6: ='Income Statement'!D12 -> 3690 | E6: ='Income Statement'!E12 -> 14187.334 | F6: ='Income Statement'!F12 -> 20907.793 | G6: ='Income Statement'!G12 -> 26377.279 | H6: ='Income Statement'!H12 -> 30303.12 | I6: ='Income Statement'!I12 -> 32322.454
A7: PAT | B7: ='Income Statement'!B23 -> 17514.75 | C7: ='Income Statement'!C23 -> 19394 | D7: ='Income Statement'!D23 -> -1377 | E7: ='Income Statement'!E23 -> 10565.501 | F7: ='Income Statement'!F23 -> 16018.345 | G7: ='Income Statement'!G23 -> 20457.959 | H7: ='Income Statement'!H23 -> 23739.84 | I7: ='Income Statement'!I23 -> 25516.84
A8: Total assets | B8: ='Balance Sheet'!B10 -> 363880 | C8: ='Balance Sheet'!C10 -> 358294.68 | D8: ='Balance Sheet'!D10 -> 348313.04 | E8: ='Balance Sheet'!E10 -> 367452.41 | F8: ='Balance Sheet'!F10 -> 388782.71 | G8: ='Balance Sheet'!G10 -> 408947.17 | H8: ='Balance Sheet'!H10 -> 430018.98 | I8: ='Balance Sheet'!I10 -> 451079.47
A9: Equity | B9: ='Balance Sheet'!B12 -> 131500 | C9: ='Balance Sheet'!C12 -> 122754 | D9: ='Balance Sheet'!D12 -> 118842 | E9: ='Balance Sheet'!E12 -> 127207.5 | F9: ='Balance Sheet'!F12 -> 140625.85 | G9: ='Balance Sheet'!G12 -> 157883.8 | H9: ='Balance Sheet'!H12 -> 177623.64 | I9: ='Balance Sheet'!I12 -> 198140.49
A10: Net debt | B10: ='Balance Sheet'!B20 -> 37000 | C10: ='Balance Sheet'!C20 -> 34400 | D10: ='Balance Sheet'!D20 -> 30873 | E10: ='Balance Sheet'!E20 -> 39357.023 | F10: ='Balance Sheet'!F20 -> 40230.731 | G10: ='Balance Sheet'!G20 -> 32021.502 | H10: ='Balance Sheet'!H20 -> 18285.655 | I10: ='Balance Sheet'!I20 -> 1968.3822
A11: Free cash flow | E11: ='Cash Flow'!E9 -> -6284.0227 | F11: ='Cash Flow'!F9 -> 1726.292 | G11: ='Cash Flow'!G9 -> 11409.229 | H11: ='Cash Flow'!H9 -> 17735.847 | I11: ='Cash Flow'!I9 -> 21317.273

Sheet Monte Carlo
A1: Monte Carlo — engine outputs
A2: 50,000 paths · 16 factors · seed 42 · computed by the Testahil MC engine (values, not a sheet simulation).
A3: Percentile map (₹/share)
A4: Horizon | B4: p5 | C4: p25 | D4: p50 | E4: p75 | F4: p95
A5: T+20 sessions | B5: 294 | C5: 327 | D5: 353 | E5: 379 | F5: 422
A6: T+60 sessions | B6: 258 | C6: 310 | D6: 352 | E6: 400 | F6: 481
A8: Inputs (from Assumptions): σ | D8: =Assumptions!$B$43 -> 0.35401235
A9: net 3-month drift | D9: =Assumptions!$B$44 -> 0.01785
A10: KVOL (calibration) | D10: =Assumptions!$B$45 -> 1.15
A12: Level-touch ladder
A13: Level | B13: T+20 | C13: T+60
A14: 420 | B14: 0.084 | C14: 0.315
A15: 400 | B15: 0.197 | C15: 0.456
A16: 380 | B16: 0.406 | C16: 0.632
A17: 360 | B17: 0.74 | C17: 0.849
A18: 340 | B18: 0.645 | C18: 0.79
A19: 320 | B19: 0.312 | C19: 0.559
A20: 300 | B20: 0.112 | C20: 0.356

Sheet Sensitivity
A1: SOTP sensitivity — the JLR swing
A2: Fair value (₹/share, post-discount) by JLR EBITDA margin × EV/EBITDA multiple. Live off Assumptions.
A4: margin \ mult | B4: 2.5 | C4: 2.75 | D4: 3 | E4: 3.25 | F4: 3.5 | G4: 3.75
A5: 0.1 | B5: =((Assumptions!$B$14*$A5*B$4*Assumptions!$B$6*100)+Assumptions!$B$18*Assumptions!$B$19+Assumptions!$B$20+Assumptions!$B$21-Assumptions!$B$8)*(1-Assumptions!$B$22)/Assumptions!$B$5 -> 290.20449 | C5: =((Assumptions!$B$14*$A5*C$4*Assumptions!$B$6*100)+Assumptions!$B$18*Assumptions!$B$19+Assumptions!$B$20+Assumptions!$B$21-Assumptions!$B$8)*(1-Assumptions!$B$22)/Assumptions!$B$5 -> 310.40247 | D5: =((Assumptions!$B$14*$A5*D$4*Assumptions!$B$6*100)+Assumptions!$B$18*Assumptions!$B$19+Assumptions!$B$20+Assumptions!$B$21-Assumptions!$B$8)*(1-Assumptions!$B$22)/Assumptions!$B$5 -> 330.60044 | E5: =((Assumptions!$B$14*$A5*E$4*Assumptions!$B$6*100)+Assumptions!$B$18*Assumptions!$B$19+Assumptions!$B$20+Assumptions!$B$21-Assumptions!$B$8)*(1-Assumptions!$B$22)/Assumptions!$B$5 -> 350.79841 | F5: =((Assumptions!$B$14*$A5*F$4*Assumptions!$B$6*100)+Assumptions!$B$18*Assumptions!$B$19+Assumptions!$B$20+Assumptions!$B$21-Assumptions!$B$8)*(1-Assumptions!$B$22)/Assumptions!$B$5 -> 370.99639 | G5: =((Assumptions!$B$14*$A5*G$4*Assumptions!$B$6*100)+Assumptions!$B$18*Assumptions!$B$19+Assumptions!$B$20+Assumptions!$B$21-Assumptions!$B$8)*(1-Assumptions!$B$22)/Assumptions!$B$5 -> 391.19436
A6: 0.11 | B6: =((Assumptions!$B$14*$A6*B$4*Assumptions!$B$6*100)+Assumptions!$B$18*Assumptions!$B$19+Assumptions!$B$20+Assumptions!$B$21-Assumptions!$B$8)*(1-Assumptions!$B$22)/Assumptions!$B$5 -> 310.40247 | C6: =((Assumptions!$B$14*$A6*C$4*Assumptions!$B$6*100)+Assumptions!$B$18*Assumptions!$B$19+Assumptions!$B$20+Assumptions!$B$21-Assumptions!$B$8)*(1-Assumptions!$B$22)/Assumptions!$B$5 -> 332.62024 | D6: =((Assumptions!$B$14*$A6*D$4*Assumptions!$B$6*100)+Assumptions!$B$18*Assumptions!$B$19+Assumptions!$B$20+Assumptions!$B$21-Assumptions!$B$8)*(1-Assumptions!$B$22)/Assumptions!$B$5 -> 354.83801 | E6: =((Assumptions!$B$14*$A6*E$4*Assumptions!$B$6*100)+Assumptions!$B$18*Assumptions!$B$19+Assumptions!$B$20+Assumptions!$B$21-Assumptions!$B$8)*(1-Assumptions!$B$22)/Assumptions!$B$5 -> 377.05578 | F6: =((Assumptions!$B$14*$A6*F$4*Assumptions!$B$6*100)+Assumptions!$B$18*Assumptions!$B$19+Assumptions!$B$20+Assumptions!$B$21-Assumptions!$B$8)*(1-Assumptions!$B$22)/Assumptions!$B$5 -> 399.27355 | G6: =((Assumptions!$B$14*$A6*G$4*Assumptions!$B$6*100)+Assumptions!$B$18*Assumptions!$B$19+Assumptions!$B$20+Assumptions!$B$21-Assumptions!$B$8)*(1-Assumptions!$B$22)/Assumptions!$B$5 -> 421.49132
A7: 0.12 | B7: =((Assumptions!$B$14*$A7*B$4*Assumptions!$B$6*100)+Assumptions!$B$18*Assumptions!$B$19+Assumptions!$B$20+Assumptions!$B$21-Assumptions!$B$8)*(1-Assumptions!$B$22)/Assumptions!$B$5 -> 330.60044 | C7: =((Assumptions!$B$14*$A7*C$4*Assumptions!$B$6*100)+Assumptions!$B$18*Assumptions!$B$19+Assumptions!$B$20+Assumptions!$B$21-Assumptions!$B$8)*(1-Assumptions!$B$22)/Assumptions!$B$5 -> 354.83801 | D7: =((Assumptions!$B$14*$A7*D$4*Assumptions!$B$6*100)+Assumptions!$B$18*Assumptions!$B$19+Assumptions!$B$20+Assumptions!$B$21-Assumptions!$B$8)*(1-Assumptions!$B$22)/Assumptions!$B$5 -> 379.07558 | E7: =((Assumptions!$B$14*$A7*E$4*Assumptions!$B$6*100)+Assumptions!$B$18*Assumptions!$B$19+Assumptions!$B$20+Assumptions!$B$21-Assumptions!$B$8)*(1-Assumptions!$B$22)/Assumptions!$B$5 -> 403.31315 | F7: =((Assumptions!$B$14*$A7*F$4*Assumptions!$B$6*100)+Assumptions!$B$18*Assumptions!$B$19+Assumptions!$B$20+Assumptions!$B$21-Assumptions!$B$8)*(1-Assumptions!$B$22)/Assumptions!$B$5 -> 427.55072 | G7: =((Assumptions!$B$14*$A7*G$4*Assumptions!$B$6*100)+Assumptions!$B$18*Assumptions!$B$19+Assumptions!$B$20+Assumptions!$B$21-Assumptions!$B$8)*(1-Assumptions!$B$22)/Assumptions!$B$5 -> 451.78828
A8: 0.13 | B8: =((Assumptions!$B$14*$A8*B$4*Assumptions!$B$6*100)+Assumptions!$B$18*Assumptions!$B$19+Assumptions!$B$20+Assumptions!$B$21-Assumptions!$B$8)*(1-Assumptions!$B$22)/Assumptions!$B$5 -> 350.79841 | C8: =((Assumptions!$B$14*$A8*C$4*Assumptions!$B$6*100)+Assumptions!$B$18*Assumptions!$B$19+Assumptions!$B$20+Assumptions!$B$21-Assumptions!$B$8)*(1-Assumptions!$B$22)/Assumptions!$B$5 -> 377.05578 | D8: =((Assumptions!$B$14*$A8*D$4*Assumptions!$B$6*100)+Assumptions!$B$18*Assumptions!$B$19+Assumptions!$B$20+Assumptions!$B$21-Assumptions!$B$8)*(1-Assumptions!$B$22)/Assumptions!$B$5 -> 403.31315 | E8: =((Assumptions!$B$14*$A8*E$4*Assumptions!$B$6*100)+Assumptions!$B$18*Assumptions!$B$19+Assumptions!$B$20+Assumptions!$B$21-Assumptions!$B$8)*(1-Assumptions!$B$22)/Assumptions!$B$5 -> 429.57051 | F8: =((Assumptions!$B$14*$A8*F$4*Assumptions!$B$6*100)+Assumptions!$B$18*Assumptions!$B$19+Assumptions!$B$20+Assumptions!$B$21-Assumptions!$B$8)*(1-Assumptions!$B$22)/Assumptions!$B$5 -> 455.82788 | G8: =((Assumptions!$B$14*$A8*G$4*Assumptions!$B$6*100)+Assumptions!$B$18*Assumptions!$B$19+Assumptions!$B$20+Assumptions!$B$21-Assumptions!$B$8)*(1-Assumptions!$B$22)/Assumptions!$B$5 -> 482.08525
A9: 0.14 | B9: =((Assumptions!$B$14*$A9*B$4*Assumptions!$B$6*100)+Assumptions!$B$18*Assumptions!$B$19+Assumptions!$B$20+Assumptions!$B$21-Assumptions!$B$8)*(1-Assumptions!$B$22)/Assumptions!$B$5 -> 370.99639 | C9: =((Assumptions!$B$14*$A9*C$4*Assumptions!$B$6*100)+Assumptions!$B$18*Assumptions!$B$19+Assumptions!$B$20+Assumptions!$B$21-Assumptions!$B$8)*(1-Assumptions!$B$22)/Assumptions!$B$5 -> 399.27355 | D9: =((Assumptions!$B$14*$A9*D$4*Assumptions!$B$6*100)+Assumptions!$B$18*Assumptions!$B$19+Assumptions!$B$20+Assumptions!$B$21-Assumptions!$B$8)*(1-Assumptions!$B$22)/Assumptions!$B$5 -> 427.55072 | E9: =((Assumptions!$B$14*$A9*E$4*Assumptions!$B$6*100)+Assumptions!$B$18*Assumptions!$B$19+Assumptions!$B$20+Assumptions!$B$21-Assumptions!$B$8)*(1-Assumptions!$B$22)/Assumptions!$B$5 -> 455.82788 | F9: =((Assumptions!$B$14*$A9*F$4*Assumptions!$B$6*100)+Assumptions!$B$18*Assumptions!$B$19+Assumptions!$B$20+Assumptions!$B$21-Assumptions!$B$8)*(1-Assumptions!$B$22)/Assumptions!$B$5 -> 484.10504 | G9: =((Assumptions!$B$14*$A9*G$4*Assumptions!$B$6*100)+Assumptions!$B$18*Assumptions!$B$19+Assumptions!$B$20+Assumptions!$B$21-Assumptions!$B$8)*(1-Assumptions!$B$22)/Assumptions!$B$5 -> 512.38221
A11: Cells near spot (₹352) indicate how much JLR recovery is already in the price.

Sheet Per-Share & Ratios
A1: Per-share & ratios
A2: Links to statements / Assumptions.
B3: FY24 | C3: FY25 | D3: FY26 | E3: FY27E | F3: FY28E | G3: FY29E | H3: FY30E | I3: FY31E
A4: EPS (₹) | B4: ='Income Statement'!B23/Assumptions!$B$5 -> 47.564701 | C4: ='Income Statement'!C23/Assumptions!$B$5 -> 52.668169 | D4: ='Income Statement'!D23/Assumptions!$B$5 -> -3.7395106 | E4: ='Income Statement'!E23/Assumptions!$B$5 -> 28.692667 | F4: ='Income Statement'!F23/Assumptions!$B$5 -> 43.500922 | G4: ='Income Statement'!G23/Assumptions!$B$5 -> 55.557557 | H4: ='Income Statement'!H23/Assumptions!$B$5 -> 64.470141 | I4: ='Income Statement'!I23/Assumptions!$B$5 -> 69.29593
A5: Book value/share (₹) | B5: ='Balance Sheet'!B12/Assumptions!$B$5 -> 357.11376 | C5: ='Balance Sheet'!C12/Assumptions!$B$5 -> 333.3623 | D5: ='Balance Sheet'!D12/Assumptions!$B$5 -> 322.73851 | E5: ='Balance Sheet'!E12/Assumptions!$B$5 -> 345.45665 | F5: ='Balance Sheet'!F12/Assumptions!$B$5 -> 381.89676 | G5: ='Balance Sheet'!G12/Assumptions!$B$5 -> 428.7641 | H5: ='Balance Sheet'!H12/Assumptions!$B$5 -> 482.37147 | I5: ='Balance Sheet'!I12/Assumptions!$B$5 -> 538.08893
A6: EBITDA margin | B6: ='Income Statement'!B14/'Income Statement'!B7 -> 0.13568362 | C6: ='Income Statement'!C14/'Income Statement'!C7 -> 0.12875109 | D6: ='Income Statement'!D14/'Income Statement'!D7 -> 0.068001263 | E6: ='Income Statement'!E14/'Income Statement'!E7 -> 0.091892946 | F6: ='Income Statement'!F14/'Income Statement'!F7 -> 0.10371919 | G6: ='Income Statement'!G14/'Income Statement'!G7 -> 0.11136834 | H6: ='Income Statement'!H14/'Income Statement'!H7 -> 0.11504056 | I6: ='Income Statement'!I14/'Income Statement'!I7 -> 0.11489215
A7: EBIT margin | B7: ='Income Statement'!B12/'Income Statement'!B7 -> 0.069016949 | C7: ='Income Statement'!C12/'Income Statement'!C7 -> 0.063467306 | D7: ='Income Statement'!D12/'Income Statement'!D7 -> 0.010995822 | E7: ='Income Statement'!E12/'Income Statement'!E7 -> 0.036892946 | F7: ='Income Statement'!F12/'Income Statement'!F7 -> 0.049719192 | G7: ='Income Statement'!G12/'Income Statement'!G7 -> 0.058368337 | H7: ='Income Statement'!H12/'Income Statement'!H7 -> 0.06304056 | I7: ='Income Statement'!I12/'Income Statement'!I7 -> 0.063892152
A8: Net debt / EBITDA | B8: ='Balance Sheet'!B20/'Income Statement'!B14 -> 0.77031979 | C8: ='Balance Sheet'!C20/'Income Statement'!C14 -> 0.72981861 | D8: ='Balance Sheet'!D20/'Income Statement'!D14 -> 1.3528922 | E8: ='Balance Sheet'!E20/'Income Statement'!E14 -> 1.1137369 | F8: ='Balance Sheet'!F20/'Income Statement'!F14 -> 0.92239019 | G8: ='Balance Sheet'!G20/'Income Statement'!G14 -> 0.63624926 | H8: ='Balance Sheet'!H20/'Income Statement'!H14 -> 0.33066806 | I8: ='Balance Sheet'!I20/'Income Statement'!I14 -> 0.033865871
A9: Revenue YoY | C9: ='Income Statement'!C7/'Income Statement'!B7-1 -> 0.034163842 | D9: ='Income Statement'!D7/'Income Statement'!C7-1 -> -0.083344715 | E9: ='Income Statement'!E7/'Income Statement'!D7-1 -> 0.1459319 | F9: ='Income Statement'!F7/'Income Statement'!E7-1 -> 0.093519803 | G9: ='Income Statement'!G7/'Income Statement'!F7-1 -> 0.074653732 | H9: ='Income Statement'!H7/'Income Statement'!G7-1 -> 0.063688867 | I9: ='Income Statement'!I7/'Income Statement'!H7-1 -> 0.05242104

Sheet Peer & Sector
A1: Peer set & sector
A2: No clean comparable — split by part.
A3: Part | B3: Closest peers | C3: Typical valuation
A4: JLR (premium auto) | B4: Mercedes-Benz, BMW, Aston Martin | C4: EV/EBITDA ~2.5–4.0x; cyclical
A5: India PV (ICE) | B5: Maruti Suzuki, M&M, Hyundai India | C5: P/E ~20–28x; EV/EBITDA ~12–18x
A6: India EV (TPEM) | B6: BYD, MG (JSW), Mahindra EV | C6: Growth / strategic; private marks
A8: Analyst targets (context): Nomura ₹373 (Neutral), BofA ₹335 (Underperform), HSBC ₹450 (Hold). Not used as model inputs.
