Workbook

Sheet READ FIRST
A1: Testahil — Emirates Central Cooling Systems Corporation PJSC (DFM: EMPOWER)
A3: Companion model · Independent Valuation Study · Educational analysis · Not investment advice
A5: What this workbook is. A transparent companion to the Empower valuation study. Every blue cell is an
A6: input; every black cell is a formula; green cells link across sheets.
A8: IT IS FORMULA-DRIVEN. Every figure that can be derived arithmetically from a driver is a live formula,
A9: so you can change a blue cell on Assumptions and watch the model reprice: the cost of capital is built
A10: from the risk-free rate, beta and the premium rather than pasted; the revenue engine multiplies
A11: per-refrigeration-ton rates by the connected-capacity path; and the income statement, balance sheet,
A12: cash flow, ratios and all four lenses chain off the same cells.
A14: EXACTLY THREE THINGS ARE PASTED VALUES, and it is worth knowing which:
A16: 1. AUDITED AND DISCLOSED HISTORY — the FY2023-25 statement lines, the 30-Jun-2026 reviewed balance
A17: sheet, disclosed connected capacity, and the consumption revenue disclosed in the auditor's
... A50: Per-Share & Ratios · Peer & Sector.

Sheet Summary
A1: Summary — valuation at a glance
A2: All values link live to their source sheets; the weights are visible inputs. Two tax framings are shown side by side, never averaged.
A4: Lens | B4: AED/share | C4: Weight | D4: Contribution | E4: vs spot | G4: Terminal value share of EV
A5: Discounted cash flow (9% framing) | B5: ='SOTP Bridge'!C13 | C5: =Assumptions!$C$69 | D5: =B5*C5 | E5: =B5/Assumptions!$C$5-1 | G5: ='SOTP Bridge'!C15
A6: Relative multiples (peer EV/EBITDA) | B6: ='Relative & Normalized'!C11 | C6: =Assumptions!$C$70 | D6: =B6*C6 | E6: =B6/Assumptions!$C$5-1
A7: Normalised earnings power | B7: ='Relative & Normalized'!C29 | C7: =Assumptions!$C$71 | D7: =B7*C7 | E7: =B7/Assumptions!$C$5-1
A8: Book value and sustainable return | B8: ='Relative & Normalized'!C34 | C8: =Assumptions!$C$72 | D8: =B8*C8 | E8: =B8/Assumptions!$C$5-1
A9: Central fair value (9% framing) — weighted blend | B9: =SUM(D5:D8) | C9: =SUM(C5:C8) | E9: =B9/Assumptions!$C$5-1
A10: Central fair value (15% framing) — same weights, top-up tax throughout | B10: =Assumptions!$C$69*'SOTP Bridge'!D13+Assumptions!$C$70*B6+Assumptions!$C$71*B7*(1-Assumptions!$C$73)+Assumptions!$C$72*B8 | E10: =B10/Assumptions!$C$5-1
A11: Bear case — full model re-run (does not redraw with drivers) | B11: 1.4614917 | E11: =B11/Assumptions!$C$5-1
A12: Bull case — full model re-run (does not redraw with drivers) | B12: 2.2207957 | E12: =B12/Assumptions!$C$5-1
A13: Dividend cross-check | B13: ='Relative & Normalized'!C38 | E13: =B13/Assumptions!$C$5-1
A14: Discounted cash flow on the CDS premium basis | B14: ='SOTP Bridge'!E13
A15: Market price (anchor, 07-Aug-2026) | B15: =Assumptions!$C$5
A16: DEWA control-transaction price, Feb-2026 (reference point, not fair value) | B16: =Assumptions!$C$74
A17: The Feb-2026 DEWA purchase of Dubai Holding's 24% at AED 2.16 was a related-party CONTROL transaction — a disclosed reference point above every lens here, never a fair-value estimate for minority shares.
A19: Key figure | B19: Value
A20: Shares outstanding (mn) | B20: =Assumptions!$C$6
A21: Market capitalisation (AED mn) | B21: =DCF!C46
A22: Net debt, 30-Jun-2026 (AED mn) | B22: =DCF!C47
A23: FY2025 revenue (AED mn) | B23: ='Income Statement'!D5
A24: FY2025 EBITDA (AED mn) | B24: ='Income Statement'!D8
A25: FY2025 attributable profit (AED mn) | B25: ='Income Statement'!D17
A26: Cost of equity (rating basis) | B26: =DCF!C44
A27: Cost of capital (9% framing, rating basis) | B27: =DCF!C50
A28: Cost of capital (15% framing, rating basis) | B28: =DCF!C51
A29: Terminal growth | B29: =Assumptions!$C$49

Sheet Fundamental Valuation
A1: Fundamental valuation — four lenses, two framings, one field
A4: Lens | B4: Basis | C4: AED per share
A5: Discounted cash flow | B5: five-year free-cash-flow build, reinvestment-consistent terminal value | C5: ='SOTP Bridge'!C13
A6: Relative multiples | B6: peer EV/EBITDA on FY2026E EBITDA | C6: ='Relative & Normalized'!C11
A7: Normalised earnings power | B7: unshocked year one x justified price/earnings | C7: ='Relative & Normalized'!C29
A8: Book value and sustainable return | B8: justified price/book on sustainable return | C8: ='Relative & Normalized'!C34
A9: Weighted central (9% framing) | C9: =Summary!B9
A11: THE TWO CONTESTED JUDGEMENTS — PUBLISHED BOTH WAYS, NEVER AVERAGED
A12: Discounted cash flow per share | B12: 9% corporate tax | C12: 15% top-up tax
A13: Consumption per-RT RECOVERS to the FY2025 level (base) | B13: ='SOTP Bridge'!C13 | C13: ='SOTP Bridge'!D13
A14: Consumption per-RT never recovers (full model re-run; does not redraw) | B14: 2.1226445 | C14: 1.9706922
A16: Scenario field (full model re-runs; do not redraw with drivers)
A17: Bear — demand re-escalation, halved connections, 15% tax, repriced risk | C17: 1.4614917
A18: Central (9% framing) | C18: =Summary!B9
A19: Bull — clean recovery, top-of-guidance connections, 9% tax | C19: 2.2207957
A21: Market price | C21: =Summary!B15
A22: DEWA control-transaction price (reference only) | C22: =Assumptions!$C$74

Sheet Assumptions
A1: Assumptions — every input in the model
A2: Blue cells are inputs; change one and the model reprices. Column H gives the source and date of each input.
A3: Input | B3: FY2026E | C3: FY2027E | D3: FY2028E | E3: FY2029E | F3: FY2030E | H3: Source
A4: Anchors
A5: Spot price (AED) | C5: 1.5 | H5: Uploaded DFM daily price history, last close (2026-08-07)
A6: Shares outstanding (mn) | C6: 10000 | H6: Share capital note 16: AED 1,000,000k at AED 0.10 par = 10,000,000,000 shares, unchanged since the Nov-2022 IPO (EPS note 35 cross-check: 896,754k / 0.090 = 9,964mn wtd) (2026-02-09)
A7: Corporate tax rate (headline framing) | C7: 0.09 | H7: UAE federal corporate tax 9% (FY2025 audited effective rate exactly 9.0%: 99,226k tax on 1,103,161k PBT; note 28) (2026-02-09)
A8: Top-up tax rate (alternative framing) | C8: 0.15 | H8: OECD Pillar-Two UAE domestic minimum top-up tax 15% for groups >= EUR 750m revenue — whether DEWA-level (80%) consolidation sweeps Empower in is CONTESTED; computed as the full alternative framing (2026-08-09)
A9: Profit for the year, FY2025 (AED mn) | C9: 1003.935 | H9: Profit after tax, FY2025 audited FS (2026-02-09)
A10: Profit attributable to non-controlling interests, FY2025 (AED mn) | C10: 10.633 | H10: Profit attributable to NCI, FY2025 audited FS (2026-02-09)
A11: Profit attributable to shareholders, FY2025 (AED mn) | C11: 993.302 | H11: Profit attributable to equity holders, FY2025 (2026-02-09)
A13: Unit build — the two-leg revenue build (pasted anchors; everything downstream is formula)
A14: Connected capacity, end-FY2024 (k RT) | C14: 1566 | H14: Connected capacity history, k RT, H1-2026 earnings deck p13 (2023 not charted; interpolation never used — growth is computed 2024->2025) (2026-08-05)
A15: Connected capacity, end-FY2025 (k RT) | C15: 1656 | H15: Connected capacity history, k RT, H1-2026 earnings deck p13 (2023 not charted; interpolation never used — growth is computed 2024->2025) (2026-08-05)
A16: New connections by year (k RT) | B16: 105 | C16: 100 | D16: 90 | E16: 80 | F16: 70 | H16: FY2026 = guidance midpoint (100-110k, H1-2026 earnings deck p13); then the contracted backlog (2,018k at Jun-26) tapering 100/90/80/70k as the pipeline matures
A17: Consumption revenue per average connected RT, FY2025 (AED k) | C17: 1.1942222 | H17: Consumption revenue (auditor key-audit-matter figure, FY2025 audited FS) / average connected RT ((1,566+1,656)/2)
A18: FY2026 consumption shock (per-RT, full year) | C18: -0.06 | H18: H1-2026 equivalent full-load hours -9.0% y/y (deck p4); full-year effect smaller as H2-2025 was itself soft
A19: Consumption per-RT recovery level from FY2027 (share of FY2025) | C19: 1 | H19: Base case: full recovery to the FY2025 level; the recovery grid on the Sensitivity sheet re-runs the whole model at other levels
A20: Capacity and connection revenue per average connected RT, FY2025 (AED k) | C20: 0.91756549 | H20: Implied: (revenue - consumption - pipes) / average connected RT; no per-RT tariff schedule is published — flagged
A21: Pre-insulated pipes revenue (AED mn, held flat) | C21: 17.214 | H21: Sale of pre-insulated pipes (Logstor), revenue note 23, FY2025 audited FS (2026-02-09)
A22: Electricity and water cost as a share of consumption revenue | C22: 0.76285467 | H22: DEWA purchases (related-party note 12) / consumption revenue, FY2025; FY2024 prints 72.5% on the same basis
A23: Other cash cost of sales, FY2025 (AED mn) | C23: 162.419 | H23: Cost of sales less DEWA purchases less the depreciation and amortisation inside cost of sales (FY2025 audited FS notes)
A24: General and administrative cash cost, FY2025 (AED mn) | C24: 236.074 | H24: G&A expenses less the depreciation inside G&A (FY2025 audited FS)
A25: Other income (AED mn, held flat) | C25: 14.624 | H25: Other income, FY2025 audited FS (2026-02-09)
A26: Reversal of credit-loss allowance, FY2025 (AED mn; not forecast) | C26: 16.137 | H26: Reversal of expected credit losses, FY2025 audited FS (2026-02-09)
A27: Concession interest income, FY2025 (AED mn) | C27: 58.307 | H27: Interest income on financial assets at amortised cost, FY2025 audited FS (2026-02-09)
A28: Concession interest annual decay | C28: 0.03 | H28: Amortising concession receivable — interest income runs off as the asset amortises
A29: Wage and services cost escalator | C29: 0.025 | H29: UAE CPI / wage class; applied to cash cost of sales and cash G&A only
A31: Capital intensity and working capital
A32: Capital expenditure per added RT (AED mn per k RT) | C32: 4.8893222 | H32: FY2025 capital expenditure / FY2025 net connections added (90k RT)
A33: Maintenance capital expenditure (share of opening plant) | C33: 0.008 | H33: House assumption for a young plant fleet; flagged as an estimate
A34: Net property, plant and equipment, end-FY2025 (AED mn) | C34: 7194.99 | H34: FY2025 audited balance sheet
A35: Depreciation rate on opening plant | C35: 0.050348956 | H35: FY2025 plant depreciation / opening net plant (FY2025 audited cash-flow note)
A36: Amortisation and right-of-use depreciation (AED mn, flat) | C36: 17.518 | H36: FY2025 intangibles amortisation + right-of-use depreciation
A37: Net working capital, end-FY2025 (AED mn) | C37: -1756.752 | H37: Inventories + receivables + due from related parties - payables (ex capex accruals) - due to related parties, FY2025 audited balance sheet
A38: Net working capital as a share of revenue | C38: -0.51377473 | H38: End-FY2025 net working capital / FY2025 revenue (negative: customer deposits and payables fund the cycle)
A39: Terminal invested-capital addition — concession financial asset (AED mn) | C39: 1150 | H39: Airport concession receivable at amortised cost, carried in terminal invested capital at approximate book value
A41: Cost of capital
A42: Risk-free rate (AED sovereign) | C42: 0.0448 | H42: UAE dirham T-Bond, Jan-2031 tranche, auction YTM 30-Jul-2026 — the longest AED sovereign print (4.4y tenor; the 5y+ tenor gap vs the cash-flow horizon is flagged, spread over UST was ~4bp at issue) (2026-07-30)
A43: Sovereign default spread — rating basis | C43: 0.00393 | H43: UAE adjusted default spread, rating basis (Aa2), Damodaran ctryprem July-2026 edition (data 30-Jun-2026) (2026-07-01)
...

Sheet SOTP Bridge
A1: Enterprise value to equity — the bridge
A2: Three parallel constructions: the 9% corporate-tax framing, the 15% top-up-tax framing, and the CDS premium basis. The two tax framings are published side by side, never averaged.
A4: Step | C4: 9% framing | D4: 15% framing | E4: CDS basis
A5: Enterprise value | C5: =DCF!C32 | D5: =DCF!C65 | E5: =DCF!C74
A6: Less net debt (30-Jun-2026) | C6: =-DCF!$C$47 | D6: =-DCF!$C$47 | E6: =-DCF!$C$47
A7: Plus investment properties at book | C7: =Assumptions!$C$56 | D7: =Assumptions!$C$56 | E7: =Assumptions!$C$56
A8: Plus financial assets at fair value through profit or loss | C8: =Assumptions!$C$57 | D8: =Assumptions!$C$57 | E8: =Assumptions!$C$57
A9: Plus financial assets at fair value through OCI | C9: =Assumptions!$C$58 | D9: =Assumptions!$C$58 | E9: =Assumptions!$C$58
A10: Equity value | C10: =SUM(C5:C9) | D10: =SUM(D5:D9) | E10: =SUM(E5:E9)
A11: Less non-controlling interests (at their share of profit) | C11: =-C10*$C$14 | D11: =-D10*$C$14 | E11: =-E10*$C$14
A12: Equity attributable to shareholders | C12: =C10+C11 | D12: =D10+D11 | E12: =E10+E11
A13: Fair value per share (AED) | C13: =C12/Assumptions!$C$6 | D13: =D12/Assumptions!$C$6 | E13: =E12/Assumptions!$C$6
A14: Non-controlling share of group profit | C14: =Assumptions!$C$10/Assumptions!$C$9
A15: Terminal value as a share of enterprise value | C15: =DCF!C33 | D15: =DCF!C64/DCF!C65 | E15: =DCF!C73/DCF!C74
A17: The bridge is struck on the 30-Jun-2026 reviewed balance sheet — the latest statement of financial position. Investment properties and the two fair-value portfolios are non-operating and enter at book; the concession financial asset stays inside invested capital and is NOT added again here.

Sheet Segments
A1: Segments — the two-leg unit build
A2: Consumption (per-RT rate x average connected RT) + capacity/connection (per-RT rate x average connected RT) + pipes. Disclosed anchors are pasted; everything downstream is a formula.
A4: k RT / AED mn | B4: FY2025 | C4: FY2026E | D4: FY2027E | E4: FY2028E | F4: FY2029E | G4: FY2030E
A5: New connections added (k RT) | B5: - | C5: =Assumptions!$B$16 | D5: =Assumptions!$C$16 | E5: =Assumptions!$D$16 | F5: =Assumptions!$E$16 | G5: =Assumptions!$F$16
A6: Connected capacity, year-end (k RT) | B6: =Assumptions!$C$15 | C6: =B6+C5 | D6: =C6+D5 | E6: =D6+E5 | F6: =E6+F5 | G6: =F6+G5
A7: Average connected capacity (k RT) | B7: =(Assumptions!$C$14+Assumptions!$C$15)/2 | C7: =(B6+C6)/2 | D7: =(C6+D6)/2 | E7: =(D6+E6)/2 | F7: =(E6+F6)/2 | G7: =(F6+G6)/2
A8: Consumption revenue per average RT (AED k) | B8: =Assumptions!$C$17 | C8: =Assumptions!$C$17*(1+Assumptions!$C$18) | D8: =Assumptions!$C$17*Assumptions!$C$19 | E8: =Assumptions!$C$17*Assumptions!$C$19 | F8: =Assumptions!$C$17*Assumptions!$C$19 | G8: =Assumptions!$C$17*Assumptions!$C$19
A9: Consumption leg | B9: 1923.892 | C9: =C8*C7 | D9: =D8*D7 | E9: =E8*E7 | F9: =F8*F7 | G9: =G8*G7
A10: Capacity, connection and other services leg | B10: ='Income Statement'!D5-B9-Assumptions!$C$21 | C10: =Assumptions!$C$20*C7 | D10: =Assumptions!$C$20*D7 | E10: =Assumptions!$C$20*E7 | F10: =Assumptions!$C$20*F7 | G10: =Assumptions!$C$20*G7
A11: Pre-insulated pipes | B11: =Assumptions!$C$21 | C11: =Assumptions!$C$21 | D11: =Assumptions!$C$21 | E11: =Assumptions!$C$21 | F11: =Assumptions!$C$21 | G11: =Assumptions!$C$21
A12: Total revenue | B12: =SUM(B9:B11) | C12: =SUM(C9:C11) | D12: =SUM(D9:D11) | E12: =SUM(E9:E11) | F12: =SUM(F9:F11) | G12: =SUM(G9:G11)
A14: Cost stack — one escalator per driver class | B14: FY2025 | C14: FY2026E | D14: FY2027E | E14: FY2028E | F14: FY2029E | G14: FY2030E
A15: Electricity and water purchased from DEWA | B15: =Assumptions!$C$22*B9 | C15: =Assumptions!$C$22*C9 | D15: =Assumptions!$C$22*D9 | E15: =Assumptions!$C$22*E9 | F15: =Assumptions!$C$22*F9 | G15: =Assumptions!$C$22*G9
A16: Other cash cost of sales (wage class) | B16: =Assumptions!$C$23 | C16: =B16*(1+Assumptions!$C$29) | D16: =C16*(1+Assumptions!$C$29) | E16: =D16*(1+Assumptions!$C$29) | F16: =E16*(1+Assumptions!$C$29) | G16: =F16*(1+Assumptions!$C$29)
A17: General and administrative cash cost (wage class) | B17: =Assumptions!$C$24 | C17: =B17*(1+Assumptions!$C$29) | D17: =C17*(1+Assumptions!$C$29) | E17: =D17*(1+Assumptions!$C$29) | F17: =E17*(1+Assumptions!$C$29) | G17: =F17*(1+Assumptions!$C$29)
A18: Concession interest income | B18: =Assumptions!$C$27 | C18: =B18*(1-Assumptions!$C$28) | D18: =C18*(1-Assumptions!$C$28) | E18: =D18*(1-Assumptions!$C$28) | F18: =E18*(1-Assumptions!$C$28) | G18: =F18*(1-Assumptions!$C$28)
A19: Other income | B19: =Assumptions!$C$25 | C19: =Assumptions!$C$25 | D19: =Assumptions!$C$25 | E19: =Assumptions!$C$25 | F19: =Assumptions!$C$25 | G19: =Assumptions!$C$25
A20: Reversal of credit-loss allowance (not forecast) | B20: =Assumptions!$C$26 | C20: 0 | D20: 0 | E20: 0 | F20: 0 | G20: 0
A21: EBITDA | B21: =B12+B18-B15-B16-B17+B19+B20 | C21: =C12+C18-C15-C16-C17+C19+C20 | D21: =D12+D18-D15-D16-D17+D19+D20 | E21: =E12+E18-E15-E16-E17+E19+E20 | F21: =F12+F18-F15-F16-F17+F19+F20 | G21: =G12+G18-G15-G16-G17+G19+G20
A22: EBITDA margin | B22: =B21/B12 | C22: =C21/C12 | D22: =D21/D12 | E22: =E21/E12 | F22: =F21/F12 | G22: =G21/G12
A24: The FY2025 column rebuilds the audited year from the same identity: it lands within note-level rounding of the audited operating profit plus depreciation (1,642.2). The capacity-leg per-RT rate is implied — no per-RT tariff schedule is published — and is flagged as such on the Assumptions sheet.
A25: Cost classes escalate on their own drivers: DEWA purchases follow the consumption leg (pass-through ratio held at the FY2025 print), wage-class lines escalate at the wage rate, and the concession interest amortises. No blended index is applied across physically distinct cost lines.
A26: Cross-check: H1-2026 revenue of 1,519.4 scaled by the FY2025 seasonal split implies roughly 3,575 for FY2026; the model carries 3,503, within 4% (H2 carries the summer consumption peak).

Sheet Relative & Normalized
A1: Relative multiples, normalised earnings power, book value and dividends
A4: Relative lens — peer EV/EBITDA applied to the model year one | B4: Value
A5: FY2026E group EBITDA (AED mn) | C5: =DCF!B6
A6: Peer EV/EBITDA (Tabreed) | C6: =Assumptions!$C$66
A7: Implied enterprise value (AED mn) | C7: =C5*C6
A8: Less net debt | C8: =-DCF!$C$47
A9: Plus investment properties and fair-value assets | C9: =Assumptions!$C$56+Assumptions!$C$57+Assumptions!$C$58
A10: Equity value (AED mn) | C10: =C7+C8+C9
A11: Implied value per share (AED) | C11: =C10*(1-'SOTP Bridge'!$C$14)/Assumptions!$C$6
A12: Peer price/earnings (Tabreed) on FY2026E attributable profit | C12: =Assumptions!$C$67*'Income Statement'!E17/Assumptions!$C$6
A14: Own trailing multiples | B14: Value
A15: Trailing enterprise value / EBITDA | C15: =(Assumptions!$C$5*Assumptions!$C$6+DCF!$C$47)/'Income Statement'!D8
A16: Trailing price / earnings | C16: =Assumptions!$C$5/'Income Statement'!D18
A17: Trailing price / book (30-Jun-2026) | C17: =Assumptions!$C$5/C32
A18: Net debt / FY2025 EBITDA | C18: =DCF!$C$47/'Income Statement'!D8
A20: Normalised earnings power — FY2026E without the consumption shock | B20: Value
A21: Revenue at the unshocked per-RT level (AED mn) | C21: =Assumptions!$C$17*Segments!C7+Segments!C10+Assumptions!$C$21
A22: Normalised EBITDA (AED mn) | C22: =C21+Segments!C18-Assumptions!$C$22*Assumptions!$C$17*Segments!C7-Segments!C16-Segments!C17+Assumptions!$C$25
A23: Less depreciation and amortisation (FY2026E) | C23: =-DCF!B12
A24: Net finance charge (FY2026E) | C24: ='Income Statement'!E12
A25: Normalised attributable profit (AED mn) | C25: =(C22+C23+C24)*(1-Assumptions!$C$7)*(1-'SOTP Bridge'!$C$14)
A26: Normalised earnings per share (AED) | C26: =C25/Assumptions!$C$6
A27: Sustainable return on equity (FY2025 profit / average equity) | C27: =Assumptions!$C$11/((Assumptions!$C$60+Assumptions!$C$61)/2)
A28: Justified price/earnings — (1 - g/return) x (1 + g) / (cost of equity - g) | C28: =(1-Assumptions!$C$49/C27)*(1+Assumptions!$C$49)/(DCF!$C$44-Assumptions!$C$49)
A29: Implied value per share (AED) | C29: =C26*C28
A31: Book value and sustainable return | B31: Value
A32: Book value per share, 30-Jun-2026 (AED) | C32: =Assumptions!$C$59/Assumptions!$C$6
A33: Justified price/book — (return - g) / (cost of equity - g) | C33: =(C27-Assumptions!$C$49)/(DCF!$C$44-Assumptions!$C$49)
A34: Implied value per share (AED) | C34: =C32*C33
A36: Dividend cross-check | B36: Value
A37: Dividend per share — committed distribution (AED) | C37: =Assumptions!$C$63/Assumptions!$C$6
A38: Dividend value — grown at terminal growth, at the cost of equity (AED) | C38: =C37*(1+Assumptions!$C$49)/(DCF!$C$44-Assumptions!$C$49)
A40: Trailing price/book references the book-value cell below it (row 32). The normalised lens re-runs year one at the FY2025 per-RT consumption level: it answers what the business earns if the warm-winter shock proves cyclical. The book-value cell rows anchor the trailing multiple above.

Sheet DCF
A1: Discounted cash flow — the full waterfall
A2: Every line is a live formula. The cost of capital is built below in both premium bases and both tax framings; the terminal value is reinvestment-consistent.
A4: AED mn | B4: FY2026E | C4: FY2027E | D4: FY2028E | E4: FY2029E | F4: FY2030E
A5: Revenue | B5: =Segments!C12 | C5: =Segments!D12 | D5: =Segments!E12 | E5: =Segments!F12 | F5: =Segments!G12
A6: EBITDA | B6: =Segments!C21 | C6: =Segments!D21 | D6: =Segments!E21 | E6: =Segments!F21 | F6: =Segments!G21
A7: EBITDA margin | B7: =B6/B5 | C7: =C6/C5 | D7: =D6/D5 | E7: =E6/E5 | F7: =F6/F5
A8: Opening net plant | B8: =Assumptions!$C$34 | C8: =B11 | D8: =C11 | E8: =D11 | F8: =E11
A9: Capital expenditure (per added RT + maintenance) | B9: =Assumptions!$C$32*Segments!C5+Assumptions!$C$33*B8 | C9: =Assumptions!$C$32*Segments!D5+Assumptions!$C$33*C8 | D9: =Assumptions!$C$32*Segments!E5+Assumptions!$C$33*D8 | E9: =Assumptions!$C$32*Segments!F5+Assumptions!$C$33*E8 | F9: =Assumptions!$C$32*Segments!G5+Assumptions!$C$33*F8
A10: Depreciation on plant | B10: =Assumptions!$C$35*B8 | C10: =Assumptions!$C$35*C8 | D10: =Assumptions!$C$35*D8 | E10: =Assumptions!$C$35*E8 | F10: =Assumptions!$C$35*F8
A11: Closing net plant | B11: =B8+B9-B10 | C11: =C8+C9-C10 | D11: =D8+D9-D10 | E11: =E8+E9-E10 | F11: =F8+F9-F10
A12: Depreciation and amortisation (incl. right-of-use and intangibles) | B12: =B10+Assumptions!$C$36 | C12: =C10+Assumptions!$C$36 | D12: =D10+Assumptions!$C$36 | E12: =E10+Assumptions!$C$36 | F12: =F10+Assumptions!$C$36
A13: EBIT | B13: =B6-B12 | C13: =C6-C12 | D13: =D6-D12 | E13: =E6-E12 | F13: =F6-F12
A14: NOPAT — EBIT x (1 - corporate tax) | B14: =B13*(1-Assumptions!$C$7) | C14: =C13*(1-Assumptions!$C$7) | D14: =D13*(1-Assumptions!$C$7) | E14: =E13*(1-Assumptions!$C$7) | F14: =F13*(1-Assumptions!$C$7)
A15: Add back depreciation and amortisation | B15: =B12 | C15: =C12 | D15: =D12 | E15: =E12 | F15: =F12
A16: Less capital expenditure | B16: =-B9 | C16: =-C9 | D16: =-D9 | E16: =-E9 | F16: =-F9
A17: Less change in net working capital | B17: =-(Assumptions!$C$38*B5-Assumptions!$C$37) | C17: =-Assumptions!$C$38*(C5-B5) | D17: =-Assumptions!$C$38*(D5-C5) | E17: =-Assumptions!$C$38*(E5-D5) | F17: =-Assumptions!$C$38*(F5-E5)
A18: Free cash flow to the firm | B18: =B14+B15+B16+B17 | C18: =C14+C15+C16+C17 | D18: =D14+D15+D16+D17 | E18: =E14+E15+E16+E17 | F18: =F14+F15+F16+F17
A19: Discount factor (9% framing, rating basis) | B19: =1/(1+$C$50) | C19: =B19/(1+$C$50) | D19: =C19/(1+$C$50) | E19: =D19/(1+$C$50) | F19: =E19/(1+$C$50)
A20: Present value of free cash flow | B20: =B18*B19 | C20: =C18*C19 | D20: =D18*D19 | E20: =E18*E19 | F20: =F18*F19
A22: TERMINAL VALUE — reinvestment-consistent (9% framing)
A23: Net working capital, FY2030 | C23: =Assumptions!$C$38*F5
A24: Terminal invested capital (plant + concession asset + working capital) | C24: =F11+Assumptions!$C$39+C23
A25: Terminal return on invested capital | C25: =F14/C24
A26: Reinvestment rate (growth / return on capital) | C26: =Assumptions!$C$49/C25
A27: Terminal-year NOPAT (grown one year) | C27: =F14*(1+Assumptions!$C$49)
A28: Terminal free cash flow | C28: =C27*(1-C26)
A29: Terminal value | C29: =C28/($C$50-Assumptions!$C$49)
A30: Present value of the terminal value | C30: =C29*F19
A31: Present value of the five forecast years | C31: =SUM(B20:F20)
A32: Enterprise value | C32: =C30+C31
A33: Terminal value as a share of enterprise value | C33: =C30/C32
A35: Fair value per share (9% framing) — from the bridge | C35: ='SOTP Bridge'!C13
A37: COST OF CAPITAL — BUILT HERE, NOT ASSUMED
A38: Component | C38: Rating basis | D38: CDS basis
A39: Risk-free rate (AED sovereign) | C39: =Assumptions!$C$42 | D39: =Assumptions!$C$42
A40: Less sovereign default spread | C40: =Assumptions!$C$43 | D40: =Assumptions!$C$44
A41: Risk-free rate net of the sovereign spread | C41: =C39-C40 | D41: =D39-D40
A42: Beta | C42: =Assumptions!$C$47 | D42: =Assumptions!$C$47
A43: Equity risk premium | C43: =Assumptions!$C$45 | D43: =Assumptions!$C$46
A44: Cost of equity | C44: =C41+C42*C43 | D44: =D41+D42*D43
...

Sheet Income Statement
A1: Income statement — three years audited, five years forecast
A2: AED mn, consolidated. History is the audited record; every forecast line is a formula (9% corporate-tax framing; the 15% framing runs on the DCF sheet).
A4: AED mn | B4: FY2023 | C4: FY2024 | D4: FY2025 | E4: FY2026E | F4: FY2027E | G4: FY2028E | H4: FY2029E | I4: FY2030E
A5: Revenue | B5: 3035.203 | C5: 3260.489 | D5: 3419.304 | E5: =DCF!B5 | F5: =DCF!C5 | G5: =DCF!D5 | H5: =DCF!E5 | I5: =DCF!F5
A6: Concession interest income (inside gross profit) | B6: 38.711 | C6: 59.151 | D6: 58.307 | E6: =Segments!C18 | F6: =Segments!D18 | G6: =Segments!E18 | H6: =Segments!F18 | I6: =Segments!G18
A7: Gross profit | B7: 1333.036 | C7: 1402.143 | D7: 1488.328 | E7: - | F7: - | G7: - | H7: - | I7: -
A8: EBITDA | B8: =B11-B10 | C8: =C11-C10 | D8: =D11-D10 | E8: =DCF!B6 | F8: =DCF!C6 | G8: =DCF!D6 | H8: =DCF!E6 | I8: =DCF!F6
A9: EBITDA margin | B9: =B8/B5 | C9: =C8/C5 | D9: =D8/D5 | E9: =E8/E5 | F9: =F8/F5 | G9: =G8/G5 | H9: =H8/H5 | I9: =I8/I5
A10: Depreciation and amortisation | B10: -348.199 | C10: -359.081 | D10: -369.717 | E10: =-DCF!B12 | F10: =-DCF!C12 | G10: =-DCF!D12 | H10: =-DCF!E12 | I10: =-DCF!F12
A11: Operating profit (EBIT) | B11: 1119.871 | C11: 1192.444 | D11: 1272.512 | E11: =E8+E10 | F11: =F8+F10 | G11: =G8+G10 | H11: =H8+H10 | I11: =I8+I10
A12: Net finance income / (costs) | B12: =B13-B11 | C12: =C13-C11 | D12: =D13-D11 | E12: =-(Assumptions!$C$48*Assumptions!$C$52-Assumptions!$C$62*Assumptions!$C$54) | F12: =-(Assumptions!$C$48*Assumptions!$C$52-Assumptions!$C$62*Assumptions!$C$54) | G12: =-(Assumptions!$C$48*Assumptions!$C$52-Assumptions!$C$62*Assumptions!$C$54) | H12: =-(Assumptions!$C$48*Assumptions!$C$52-Assumptions!$C$62*Assumptions!$C$54) | I12: =-(Assumptions!$C$48*Assumptions!$C$52-Assumptions!$C$62*Assumptions!$C$54)
A13: Profit before tax | B13: 942.631 | C13: 998.332 | D13: 1103.161 | E13: =E11+E12 | F13: =F11+F12 | G13: =G11+G12 | H13: =H11+H12 | I13: =I11+I12
A14: Income tax | B14: 17.454 | C14: -90.097 | D14: -99.226 | E14: =-E13*Assumptions!$C$7 | F14: =-F13*Assumptions!$C$7 | G14: =-G13*Assumptions!$C$7 | H14: =-H13*Assumptions!$C$7 | I14: =-I13*Assumptions!$C$7
A15: Profit for the year | B15: 960.085 | C15: 908.235 | D15: 1003.935 | E15: =E13+E14 | F15: =F13+F14 | G15: =G13+G14 | H15: =H13+H14 | I15: =I13+I14
A16: Non-controlling interests | B16: =B17-B15 | C16: =C17-C15 | D16: =D17-D15 | E16: =-E15*'SOTP Bridge'!$C$14 | F16: =-F15*'SOTP Bridge'!$C$14 | G16: =-G15*'SOTP Bridge'!$C$14 | H16: =-H15*'SOTP Bridge'!$C$14 | I16: =-I15*'SOTP Bridge'!$C$14
A17: Profit attributable to shareholders | B17: 952.927 | C17: 896.754 | D17: 993.302 | E17: =E15+E16 | F17: =F15+F16 | G17: =G15+G16 | H17: =H15+H16 | I17: =I15+I16
A18: Earnings per share (AED) | B18: =B17/Assumptions!$C$6 | C18: =C17/Assumptions!$C$6 | D18: =D17/Assumptions!$C$6 | E18: =E17/Assumptions!$C$6 | F18: =F17/Assumptions!$C$6 | G18: =G17/Assumptions!$C$6 | H18: =H17/Assumptions!$C$6 | I18: =I17/Assumptions!$C$6
A20: Every FY2023-25 line is the audited figure (the EBITDA, net-finance and non-controlling rows are arithmetic identities of audited lines). The forecast finance line holds the 30-Jun-2026 debt book and cash balance flat at the marginal cost of debt and deposit yield; the FY2023 tax line is a credit (first recognition of deferred tax ahead of UAE corporate tax).

Sheet Balance Sheet
A1: Balance sheet — condensed
A2: AED mn. FY2024 and FY2025 are audited closing figures; 30-Jun-2026 is the reviewed interim. The forecast rolls forward from the model: plant from the capex/depreciation chain, equity from retained profit less the committed dividend, net debt from free cash flow.
A4: AED mn | B4: FY2024 | C4: FY2025 | D4: 30-Jun-26 | E4: FY2026E | F4: FY2027E | G4: FY2028E | H4: FY2029E | I4: FY2030E
A5: Property, plant and equipment (net) | B5: 6995.16 | C5: 7194.99 | D5: 7274.608 | E5: =DCF!B11 | F5: =DCF!C11 | G5: =DCF!D11 | H5: =DCF!E11 | I5: =DCF!F11
A6: Investment properties | B6: 118.015 | C6: 170.793 | D6: 168.716 | E6: =$D6 | F6: =$D6 | G6: =$D6 | H6: =$D6 | I6: =$D6
A7: Concession financial asset (current + non-current) | B7: 1324.787 | C7: 1304.839 | D7: 1294.442 | E7: =$D7 | F7: =$D7 | G7: =$D7 | H7: =$D7 | I7: =$D7
A8: Financial assets at fair value (through P&L and OCI) | B8: 81.175 | C8: 101.239 | D8: 127.975 | E8: =$D8 | F8: =$D8 | G8: =$D8 | H8: =$D8 | I8: =$D8
A9: Cash, equivalents and term deposits | B9: 1966.891 | C9: 2313.449 | D9: 2512.224 | E9: =(Assumptions!$C$52+Assumptions!$C$53)-E16 | F9: =(Assumptions!$C$52+Assumptions!$C$53)-F16 | G9: =(Assumptions!$C$52+Assumptions!$C$53)-G16 | H9: =(Assumptions!$C$52+Assumptions!$C$53)-H16 | I9: =(Assumptions!$C$52+Assumptions!$C$53)-I16
A10: Total assets (as reported) | B10: 11183.046 | C10: 11816.822 | D10: 12267.233 | E10: - | F10: - | G10: - | H10: - | I10: -
A11: Borrowings and lease liabilities (gross debt) | B11: 5498.415 | C11: 5505.304 | D11: 5503.717 | E11: =Assumptions!$C$52+Assumptions!$C$53 | F11: =Assumptions!$C$52+Assumptions!$C$53 | G11: =Assumptions!$C$52+Assumptions!$C$53 | H11: =Assumptions!$C$52+Assumptions!$C$53 | I11: =Assumptions!$C$52+Assumptions!$C$53
A12: Trade and other payables | B12: 1677.637 | C12: 2165.056 | D12: 2458.563 | E12: - | F12: - | G12: - | H12: - | I12: -
A13: Equity attributable to shareholders | B13: 3197.59 | C13: 3310.933 | D13: 3337.585 | E13: =C13+'Income Statement'!E17-Assumptions!$C$63 | F13: =E13+'Income Statement'!F17-Assumptions!$C$63 | G13: =F13+'Income Statement'!G17-Assumptions!$C$63 | H13: =G13+'Income Statement'!H17-Assumptions!$C$63 | I13: =H13+'Income Statement'!I17-Assumptions!$C$63
A14: Non-controlling interests | B14: 175.745 | C14: 186.378 | D14: 190.745 | E14: =C14-'Income Statement'!E16 | F14: =E14-'Income Statement'!F16 | G14: =F14-'Income Statement'!G16 | H14: =G14-'Income Statement'!H16 | I14: =H14-'Income Statement'!I16
A15: Net working capital (model definition) | B15: - | C15: =Assumptions!$C$37 | D15: - | E15: =Assumptions!$C$38*'Income Statement'!E5 | F15: =Assumptions!$C$38*'Income Statement'!F5 | G15: =Assumptions!$C$38*'Income Statement'!G5 | H15: =Assumptions!$C$38*'Income Statement'!H5 | I15: =Assumptions!$C$38*'Income Statement'!I5
A16: Net debt (gross debt - cash and deposits) | B16: =B11-B9 | C16: =C11-C9 | D16: =D11-D9 | E16: =D16-(DCF!B18+'Income Statement'!E12*(1-Assumptions!$C$7))+Assumptions!$C$63 | F16: =E16-(DCF!C18+'Income Statement'!F12*(1-Assumptions!$C$7))+Assumptions!$C$63 | G16: =F16-(DCF!D18+'Income Statement'!G12*(1-Assumptions!$C$7))+Assumptions!$C$63 | H16: =G16-(DCF!E18+'Income Statement'!H12*(1-Assumptions!$C$7))+Assumptions!$C$63 | I16: =H16-(DCF!F18+'Income Statement'!I12*(1-Assumptions!$C$7))+Assumptions!$C$63
A17: Net debt / EBITDA | B17: - | C17: =C16/'Income Statement'!D8 | D17: - | E17: =E16/'Income Statement'!E8 | F17: =F16/'Income Statement'!F8 | G17: =G16/'Income Statement'!G8 | H17: =H16/'Income Statement'!H8 | I17: =I16/'Income Statement'!I8
A19: This is a CONDENSED layout and does not foot to zero: government grants, end-of-service benefits, tax liabilities, retentions and the remaining current items are not shown separately. The forecast net-debt roll starts from the 30-Jun-2026 reviewed position (the bridge anchor), charges the committed dividend, and credits each year's free cash flow after the after-tax finance charge. The forecast equity roll starts from the FY2025 audited closing equity.

Sheet Cash Flow
A1: Cash flow — historical markers and the forecast waterfall
A2: AED mn. The forecast links line-for-line to the DCF waterfall.
A4: AED mn | B4: FY2024 | C4: FY2025 | D4: FY2026E | E4: FY2027E | F4: FY2028E | G4: FY2029E | H4: FY2030E
A5: EBITDA | B5: ='Income Statement'!C8 | C5: ='Income Statement'!D8 | D5: ='Income Statement'!E8 | E5: ='Income Statement'!F8 | F5: ='Income Statement'!G8 | G5: ='Income Statement'!H8 | H5: ='Income Statement'!I8
A6: Net cash from operating activities (as reported) | B6: 1824.402 | C6: 1862.042 | D6: - | E6: - | F6: - | G6: - | H6: -
A7: NOPAT | B7: - | C7: - | D7: =DCF!B14 | E7: =DCF!C14 | F7: =DCF!D14 | G7: =DCF!E14 | H7: =DCF!F14
A8: Add back depreciation and amortisation | B8: - | C8: - | D8: =DCF!B15 | E8: =DCF!C15 | F8: =DCF!D15 | G8: =DCF!E15 | H8: =DCF!F15
A9: Capital expenditure | B9: -306.781 | C9: -440.039 | D9: =DCF!B16 | E9: =DCF!C16 | F9: =DCF!D16 | G9: =DCF!E16 | H9: =DCF!F16
A10: Change in net working capital | B10: - | C10: - | D10: =DCF!B17 | E10: =DCF!C17 | F10: =DCF!D17 | G10: =DCF!E17 | H10: =DCF!F17
A11: Free cash flow to the firm | B11: - | C11: - | D11: =D7+D8+D9+D10 | E11: =E7+E8+E9+E10 | F11: =F7+F8+F9+F10 | G11: =G7+G8+G9+G10 | H11: =H7+H8+H9+H10
A12: Net finance charge after tax | B12: - | C12: - | D12: ='Income Statement'!E12*(1-Assumptions!$C$7) | E12: ='Income Statement'!F12*(1-Assumptions!$C$7) | F12: ='Income Statement'!G12*(1-Assumptions!$C$7) | G12: ='Income Statement'!H12*(1-Assumptions!$C$7) | H12: ='Income Statement'!I12*(1-Assumptions!$C$7)
A13: Free cash flow to equity | B13: - | C13: - | D13: =D11+D12 | E13: =E11+E12 | F13: =F11+F12 | G13: =G11+G12 | H13: =H11+H12
A14: Dividends paid | B14: -850 | C14: -875 | D14: =-Assumptions!$C$63 | E14: =-Assumptions!$C$63 | F14: =-Assumptions!$C$63 | G14: =-Assumptions!$C$63 | H14: =-Assumptions!$C$63
A15: Change in net debt (dividend less equity free cash flow) | B15: - | C15: - | D15: =-D13-D14 | E15: =-E13-E14 | F15: =-F13-F14 | G15: =-G13-G14 | H15: =-H13-H14
A16: Closing net debt | B16: - | C16: - | D16: ='Balance Sheet'!E16 | E16: ='Balance Sheet'!F16 | F16: ='Balance Sheet'!G16 | G16: ='Balance Sheet'!H16 | H16: ='Balance Sheet'!I16
A18: The company converts EBITDA to operating cash at a high rate — the negative working-capital cycle (customer deposits and long payables) funds growth. The committed dividend exceeds equity free cash flow in the first forecast year by design; the net-debt roll on the Balance Sheet carries the difference.

Sheet Summary Financials
A1: Summary financials — the eight-year picture
A2: AED mn unless stated. Every cell on this sheet is a link or a ratio; nothing is typed twice.
A4: AED mn | B4: FY2023 | C4: FY2024 | D4: FY2025 | E4: FY2026E | F4: FY2027E | G4: FY2028E | H4: FY2029E | I4: FY2030E
A5: Revenue | B5: ='Income Statement'!B5 | C5: ='Income Statement'!C5 | D5: ='Income Statement'!D5 | E5: ='Income Statement'!E5 | F5: ='Income Statement'!F5 | G5: ='Income Statement'!G5 | H5: ='Income Statement'!H5 | I5: ='Income Statement'!I5
A6: Revenue growth | B6: - | C6: =C5/B5-1 | D6: =D5/C5-1 | E6: =E5/D5-1 | F6: =F5/E5-1 | G6: =G5/F5-1 | H6: =H5/G5-1 | I6: =I5/H5-1
A7: EBITDA | B7: ='Income Statement'!B8 | C7: ='Income Statement'!C8 | D7: ='Income Statement'!D8 | E7: ='Income Statement'!E8 | F7: ='Income Statement'!F8 | G7: ='Income Statement'!G8 | H7: ='Income Statement'!H8 | I7: ='Income Statement'!I8
A8: EBITDA margin | B8: =B7/B5 | C8: =C7/C5 | D8: =D7/D5 | E8: =E7/E5 | F8: =F7/F5 | G8: =G7/G5 | H8: =H7/H5 | I8: =I7/I5
A9: Operating profit (EBIT) | B9: ='Income Statement'!B11 | C9: ='Income Statement'!C11 | D9: ='Income Statement'!D11 | E9: ='Income Statement'!E11 | F9: ='Income Statement'!F11 | G9: ='Income Statement'!G11 | H9: ='Income Statement'!H11 | I9: ='Income Statement'!I11
A10: Attributable profit | B10: ='Income Statement'!B17 | C10: ='Income Statement'!C17 | D10: ='Income Statement'!D17 | E10: ='Income Statement'!E17 | F10: ='Income Statement'!F17 | G10: ='Income Statement'!G17 | H10: ='Income Statement'!H17 | I10: ='Income Statement'!I17
A11: Free cash flow to the firm | B11: - | C11: - | D11: - | E11: ='Cash Flow'!D11 | F11: ='Cash Flow'!E11 | G11: ='Cash Flow'!F11 | H11: ='Cash Flow'!G11 | I11: ='Cash Flow'!H11
A12: Net debt | B12: - | C12: ='Balance Sheet'!B16 | D12: ='Balance Sheet'!C16 | E12: ='Balance Sheet'!E16 | F12: ='Balance Sheet'!F16 | G12: ='Balance Sheet'!G16 | H12: ='Balance Sheet'!H16 | I12: ='Balance Sheet'!I16
A13: Invested capital (plant + concession + working capital) | B13: - | C13: - | D13: - | E13: =DCF!B11+Assumptions!$C$39+'Balance Sheet'!E15 | F13: =DCF!C11+Assumptions!$C$39+'Balance Sheet'!F15 | G13: =DCF!D11+Assumptions!$C$39+'Balance Sheet'!G15 | H13: =DCF!E11+Assumptions!$C$39+'Balance Sheet'!H15 | I13: =DCF!F11+Assumptions!$C$39+'Balance Sheet'!I15
A14: Return on invested capital (NOPAT / same-year capital) | B14: - | C14: - | D14: - | E14: =DCF!B14/E13 | F14: =DCF!C14/F13 | G14: =DCF!D14/G13 | H14: =DCF!E14/H13 | I14: =DCF!F14/I13
A16: Return on invested capital comfortably clears the cost of capital across the forecast — the economics of a regulated district-cooling monopoly with a negative working-capital cycle. The terminal reinvestment rate on the DCF sheet is set from exactly this capital base.

Sheet Monte Carlo
A1: Probabilistic price map
A2: A map of price dispersion around the market price. It carries no view on value and is never blended with the valuation. Each figure is a complete simulation output, not a formula, and does not redraw when a driver changes.
A4: Horizon | B4: 5th | C4: 25th | D4: Median | E4: 75th | F4: 95th | G4: P(above spot)
A5: One month — to 2026-09-07 | B5: 1.3077784 | C5: 1.4214639 | D5: 1.4973047 | E5: 1.5776085 | F5: 1.7105962 | G5: 0.49096
A6: Three months — to 2026-11-09 | B6: 1.1631291 | C6: 1.3569288 | D6: 1.4935901 | E6: 1.6434801 | F6: 1.9204096 | G6: 0.48788
A8: Level event | B8: One month | C8: Three months
A9: Finishes 10% or more above the market price | B9: 0.10862 | C9: 0.2411
A10: Finishes 10% or more below the market price | B10: 0.09634 | C10: 0.23902
A11: Touches 10% above at any point | B11: 0.18294 | C11: 0.45114
A12: Touches 10% below at any point | B12: 0.15638 | C12: 0.4303
A14: Simulation setting | B14: Value
A15: Anchor date | C15: 2026-08-07
A16: Market price at the anchor (AED) | C16: =Assumptions!$C$5
A17: Annualised volatility (three-month anchor) | C17: 0.31638504
A18: Simulated paths | C18: 50000
A20: Calibration backtest, in plain language: the shares listed in November 2022, so only 10 non-overlapping three-month windows exist (2023-11-30 to 2026-03-04). Over that short record the model's bands were, if anything, slightly generous: every outcome landed inside the 80% band, and the centre of the distribution sat where it should (average percentile of outcomes 0.46 against an ideal 0.50). A record this short cannot establish forecasting skill either way; read the bands as honest dispersion, not precision.

Sheet Sensitivity
A1: Sensitivity — what the valuation needs the world to do
A2: AED per share. The two grids are complete model re-runs cell by cell — they do NOT redraw when a driver changes. The one-way growth row underneath IS live and reprices with the workbook.
A4: Cost of capital (rows) x terminal growth (columns) — 9% framing
B5: 1.5% | C5: 2.0% | D5: 2.5% | E5: 3.0% | F5: 3.5%
A6: 6.61% | B6: 2.3646158 | C6: 2.5469583 | D6: 2.7730466 | E6: 3.0610401 | F6: 3.440764
A7: 7.11% | B7: 2.1288864 | C7: 2.2720047 | D7: 2.4456375 | E7: 2.6609119 | F7: 2.9351144
A8: 7.61% | B8: 1.9316814 | C8: 2.0459571 | D8: 2.1821334 | E8: 2.3473311 | F8: 2.5521331
A9: 8.11% | B9: 1.7642648 | C9: 1.8568189 | D9: 1.9654625 | E9: 2.0949157 | F9: 2.2519442
A10: 8.61% | B10: 1.620357 | C10: 1.6962213 | D10: 1.7841377 | E10: 1.8873267 | F10: 2.0102683
A12: THE CRUX — consumption per-RT recovery level from FY2027 (share of FY2025); full model re-run per cell
A13: Recovery level | B13: Fair value per share (9%)
A14: 0.9 | B14: 2.0829852
A15: 0.94 | B15: 2.1226445
A16: 0.97 | B16: 2.152389
A17: 1 | B17: 2.1821334
A18: 1.03 | B18: 2.2118779
A19: Never recovers (persists at the FY2026 level) | B19: 2.1226445 | C19: 1.9706922 | D19: at 15% top-up tax
A21: LIVE one-way sensitivity — terminal growth at the base cost of capital (each cell a formula off the DCF sheet)
A22: Terminal growth | B22: 0.015 | C22: 0.02 | D22: 0.025 | E22: 0.03 | F22: 0.035
A23: Fair value per share (AED, live formula) | B23: =((DCF!$C$31+DCF!$F$14*(1+B22)*(1-B22/DCF!$C$25)/(DCF!$C$50-B22)*DCF!$F$19)-DCF!$C$47+Assumptions!$C$56+Assumptions!$C$57+Assumptions!$C$58)*(1-'SOTP Bridge'!$C$14)/Assumptions!$C$6 | C23: =((DCF!$C$31+DCF!$F$14*(1+C22)*(1-C22/DCF!$C$25)/(DCF!$C$50-C22)*DCF!$F$19)-DCF!$C$47+Assumptions!$C$56+Assumptions!$C$57+Assumptions!$C$58)*(1-'SOTP Bridge'!$C$14)/Assumptions!$C$6 | D23: =((DCF!$C$31+DCF!$F$14*(1+D22)*(1-D22/DCF!$C$25)/(DCF!$C$50-D22)*DCF!$F$19)-DCF!$C$47+Assumptions!$C$56+Assumptions!$C$57+Assumptions!$C$58)*(1-'SOTP Bridge'!$C$14)/Assumptions!$C$6 | E23: =((DCF!$C$31+DCF!$F$14*(1+E22)*(1-E22/DCF!$C$25)/(DCF!$C$50-E22)*DCF!$F$19)-DCF!$C$47+Assumptions!$C$56+Assumptions!$C$57+Assumptions!$C$58)*(1-'SOTP Bridge'!$C$14)/Assumptions!$C$6 | F23: =((DCF!$C$31+DCF!$F$14*(1+F22)*(1-F22/DCF!$C$25)/(DCF!$C$50-F22)*DCF!$F$19)-DCF!$C$47+Assumptions!$C$56+Assumptions!$C$57+Assumptions!$C$58)*(1-'SOTP Bridge'!$C$14)/Assumptions!$C$6 | G23: Swing: | H23: =MAX(B23:F23)-MIN(B23:F23)
A25: The live row reproduces the middle row of the pasted grid at the moment of writing; if a driver is changed on the Assumptions sheet the live row will move and the pasted grids will not — that difference is intentional and is the quickest way to see that a driver change has repriced the model.

Sheet Per-Share & Ratios
A1: Per-share and ratio analysis
A2: The indicator set for a regulated utility with a concession asset. Every cell is a formula off the statements.
A4: Measure | B4: FY2023 | C4: FY2024 | D4: FY2025 | E4: FY2026E | F4: FY2027E | G4: FY2028E | H4: FY2029E | I4: FY2030E
A5: Earnings per share (AED) | B5: ='Income Statement'!B18 | C5: ='Income Statement'!C18 | D5: ='Income Statement'!D18 | E5: ='Income Statement'!E18 | F5: ='Income Statement'!F18 | G5: ='Income Statement'!G18 | H5: ='Income Statement'!H18 | I5: ='Income Statement'!I18
A6: Dividend per share (AED) | B6: - | C6: - | D6: =Assumptions!$C$63/Assumptions!$C$6 | E6: =Assumptions!$C$63/Assumptions!$C$6 | F6: =Assumptions!$C$63/Assumptions!$C$6 | G6: =Assumptions!$C$63/Assumptions!$C$6 | H6: =Assumptions!$C$63/Assumptions!$C$6 | I6: =Assumptions!$C$63/Assumptions!$C$6
A7: Dividend cover (attributable profit / dividend) | B7: - | C7: - | D7: ='Income Statement'!D17/Assumptions!$C$63 | E7: ='Income Statement'!E17/Assumptions!$C$63 | F7: ='Income Statement'!F17/Assumptions!$C$63 | G7: ='Income Statement'!G17/Assumptions!$C$63 | H7: ='Income Statement'!H17/Assumptions!$C$63 | I7: ='Income Statement'!I17/Assumptions!$C$63
A8: Book value per share (AED) | B8: - | C8: ='Balance Sheet'!B13/Assumptions!$C$6 | D8: ='Balance Sheet'!C13/Assumptions!$C$6 | E8: ='Balance Sheet'!E13/Assumptions!$C$6 | F8: ='Balance Sheet'!F13/Assumptions!$C$6 | G8: ='Balance Sheet'!G13/Assumptions!$C$6 | H8: ='Balance Sheet'!H13/Assumptions!$C$6 | I8: ='Balance Sheet'!I13/Assumptions!$C$6
A9: Free cash flow to the firm per share (AED) | B9: - | C9: - | D9: - | E9: ='Cash Flow'!D11/Assumptions!$C$6 | F9: ='Cash Flow'!E11/Assumptions!$C$6 | G9: ='Cash Flow'!F11/Assumptions!$C$6 | H9: ='Cash Flow'!G11/Assumptions!$C$6 | I9: ='Cash Flow'!H11/Assumptions!$C$6
A10: Gross margin | B10: ='Income Statement'!B7/'Income Statement'!B5 | C10: ='Income Statement'!C7/'Income Statement'!C5 | D10: ='Income Statement'!D7/'Income Statement'!D5 | E10: - | F10: - | G10: - | H10: - | I10: -
A11: EBITDA margin | B11: ='Income Statement'!B9 | C11: ='Income Statement'!C9 | D11: ='Income Statement'!D9 | E11: ='Income Statement'!E9 | F11: ='Income Statement'!F9 | G11: ='Income Statement'!G9 | H11: ='Income Statement'!H9 | I11: ='Income Statement'!I9
A12: Operating margin | B12: ='Income Statement'!B11/'Income Statement'!B5 | C12: ='Income Statement'!C11/'Income Statement'!C5 | D12: ='Income Statement'!D11/'Income Statement'!D5 | E12: ='Income Statement'!E11/'Income Statement'!E5 | F12: ='Income Statement'!F11/'Income Statement'!F5 | G12: ='Income Statement'!G11/'Income Statement'!G5 | H12: ='Income Statement'!H11/'Income Statement'!H5 | I12: ='Income Statement'!I11/'Income Statement'!I5
A13: Net margin (attributable) | B13: ='Income Statement'!B17/'Income Statement'!B5 | C13: ='Income Statement'!C17/'Income Statement'!C5 | D13: ='Income Statement'!D17/'Income Statement'!D5 | E13: ='Income Statement'!E17/'Income Statement'!E5 | F13: ='Income Statement'!F17/'Income Statement'!F5 | G13: ='Income Statement'!G17/'Income Statement'!G5 | H13: ='Income Statement'!H17/'Income Statement'!H5 | I13: ='Income Statement'!I17/'Income Statement'!I5
A14: Return on equity (average base) | B14: - | C14: - | D14: ='Income Statement'!D17/(('Balance Sheet'!B13+'Balance Sheet'!C13)/2) | E14: ='Income Statement'!E17/(('Balance Sheet'!C13+'Balance Sheet'!E13)/2) | F14: ='Income Statement'!F17/(('Balance Sheet'!E13+'Balance Sheet'!F13)/2) | G14: ='Income Statement'!G17/(('Balance Sheet'!F13+'Balance Sheet'!G13)/2) | H14: ='Income Statement'!H17/(('Balance Sheet'!G13+'Balance Sheet'!H13)/2) | I14: ='Income Statement'!I17/(('Balance Sheet'!H13+'Balance Sheet'!I13)/2)
A15: Net debt / EBITDA | B15: - | C15: ='Balance Sheet'!B16/'Income Statement'!C8 | D15: ='Balance Sheet'!C16/'Income Statement'!D8 | E15: ='Balance Sheet'!E16/'Income Statement'!E8 | F15: ='Balance Sheet'!F16/'Income Statement'!F8 | G15: ='Balance Sheet'!G16/'Income Statement'!G8 | H15: ='Balance Sheet'!H16/'Income Statement'!H8 | I15: ='Balance Sheet'!I16/'Income Statement'!I8
A16: Capital expenditure / revenue | B16: - | C16: =-'Cash Flow'!B9/'Income Statement'!C5 | D16: =-'Cash Flow'!C9/'Income Statement'!D5 | E16: =-'Cash Flow'!D9/'Income Statement'!E5 | F16: =-'Cash Flow'!E9/'Income Statement'!F5 | G16: =-'Cash Flow'!F9/'Income Statement'!G5 | H16: =-'Cash Flow'!G9/'Income Statement'!H5 | I16: =-'Cash Flow'!H9/'Income Statement'!I5
A17: Payout ratio (dividend / attributable profit) | B17: - | C17: - | D17: =Assumptions!$C$63/'Income Statement'!D17 | E17: =Assumptions!$C$63/'Income Statement'!E17 | F17: =Assumptions!$C$63/'Income Statement'!F17 | G17: =Assumptions!$C$63/'Income Statement'!G17 | H17: =Assumptions!$C$63/'Income Statement'!H17 | I17: =Assumptions!$C$63/'Income Statement'!I17
A19: The dividend exceeds attributable profit in the near years by design — the committed AED 875m distribution is funded by the negative working-capital cycle and the balance sheet, and the net-debt roll on the Balance Sheet carries it explicitly.

Sheet Peer & Sector
A1: Peer frame and sector context
A2: One close listed peer exists; the parent is context, not a comparable. Cross-check inputs only, never a source for the company's own numbers.
A4: Company / frame | B4: Market | C4: Relevance | D4: Caution
A5: Tabreed (National Central Cooling Co) | B5: Dubai (DFM) | C5: the only other listed GCC district-cooling pure play — the primary multiple cross-check | D5: roughly 4.6x net debt / EBITDA against Empower's 1.8x, and a concession mix that skews the EV multiple
A6: DEWA (parent, 80% owner) | B6: Dubai (DFM) | C6: majority owner since Feb-2026; its multiple frames how Dubai prices regulated utility earnings | D6: a vertically-integrated generation and distribution utility, not a district-cooling comparable
A7: Regional listed utilities | B7: GCC | C7: the broad frame for regulated-return infrastructure in pegged-currency markets | D7: tariff regimes and concession structures differ materially by emirate and state
A9: Multiple | B9: Peer | C9: Empower (model)
A10: EV / EBITDA (Tabreed, FY2025; priced Aug-2026) | B10: =Assumptions!$C$66 | C10: ='Relative & Normalized'!C15
A11: Price / earnings (Tabreed, trailing; priced Aug-2026) | B11: =Assumptions!$C$67 | C11: ='Relative & Normalized'!C16
A12: Price / earnings (DEWA, trailing; priced Aug-2026) | B12: =Assumptions!$C$68 | C12: ='Relative & Normalized'!C16
A13: Dividend yield at the market price | C13: =Assumptions!$C$63/Assumptions!$C$6/Assumptions!$C$5
A15: Peer multiples are dated, disclosed cross-check inputs (see the Assumptions sheet for source and date). Empower trades at a discount to Tabreed on EV/EBITDA with less than half the leverage; the model's relative lens applies the peer multiple to Empower's own forecast EBITDA rather than endorsing either price.
