Workbook

Sheet READ FIRST
B2: GB Corp (GBCO.CA / EGX) — valuation model, fundamental refresh of 19 August 2026
B4: Built bottom-up and formula-pure. Blue cells are the only values in the computation sheets: each is a disclosed figure from the 30-Jun-2026 reviewed statements or the 2Q/1H26 release, a sourced market quote, or a stated judgement with its rationale. Every other number is a live formula — FY26E itself is derived (H1 actual + a second half built on the FY25 measured seasonal split with explicit tempering inputs), volumes run at the finest disclosed level (locally assembled vs imported cars; buses, trucks and equipment), unit costs escalate on their own physical classes, and margins are outputs.
B6: The terminal value pays for its growth: reinvestment is forced to growth divided by the terminal return on capital (both visible cells on Assumptions/DCF). The July construction — Gordon on year-five cash flow, whose hidden implied return was 25% — is shown as a labelled alternative and priced on the Sensitivity sheet.
B8: The contested stake is computed both ways, side by side, never averaged: MNT-Halan at the June-2026 round mark and at the company's own carrying value, which the reviewer could not verify (qualified conclusion, second consecutive period).
B10: The price-probability sheet reproduces the published page unchanged (struck 22 July 2026) — this refresh moves the fundamental range only.
B12: Change any blue driver and the fair value reprices through Segments, the cash-flow model, the bridge and the synthesis. All amounts EGP millions unless stated.

Sheet Summary
B2: GB Corp — fair value at a glance (refresh of 19 August 2026)
A4: Last library close (22-Jul-26) | B4: =Assumptions!$B$6
A5: Fair value — bear | B5: ='Fundamental Valuation'!B15
A6: Fair value — base (round mark) | B6: ='Fundamental Valuation'!B16
A7: Central under the balance-sheet mark | B7: ='Fundamental Valuation'!B12
A8: Fair value — bull | B8: ='Fundamental Valuation'!B17
A10: MNT-Halan gap per share (round vs book, post-discount) | B10: =(Assumptions!$B$107-Assumptions!$B$78)*(1-Assumptions!$B$84)/Assumptions!$B$5
A11: Terminal share of automotive enterprise value | B11: =DCF!B44
A13: H1-26 group revenue (+35.2%) | B13: 48474.374
A14: H1-26 group net profit (−24.5%) | B14: 1262.006
A15: Automotive net debt 30-Jun-26 (2.14x EBITDA) | B15: 14493.6
A17: The July study's published range was 23.3 / 35.7 / 51. This refresh re-built the model bottom-up on the first-half accounts and made the terminal value pay for its growth.

Sheet Fundamental Valuation
B2: Four lenses, one field — both framings carried to the end
A4: Lens | B4: Value / share | C4: Weight
A5: Sum of the parts — round mark | B5: ='SOTP Bridge'!B13 | C5: =Assumptions!$B$85
A6: Sum of the parts — balance-sheet mark | B6: ='SOTP Bridge'!C13 | C6: same weight — the framings alternate, they never blend
A7: Book value & sustainable return | B7: =Assumptions!$B$76/Assumptions!$B$5 | C7: =Assumptions!$B$86
A8: Relative multiples | B8: ='Relative & Normalized'!C6 | C8: =Assumptions!$B$87
A9: Normalised earnings power | B9: ='Relative & Normalized'!C14 | C9: =Assumptions!$B$88
A11: Weighted central — round mark | B11: =B5*C5+B7*C7+B8*C8+B9*C9
A12: Weighted central — balance-sheet mark | B12: =B6*C5+B7*C7+B8*C8+B9*C9
A14: Published range — all three formulas
A15: Bear (balance-sheet-mark world: bear legs, 0.8x book, bear multiples) | B15: =C5*'SOTP Bridge'!C15+C7*B7*Assumptions!$B$89+C8*'Relative & Normalized'!B6+C9*'Relative & Normalized'!B14
A16: Base (round-mark central) | B16: =B11
A17: Bull (round-mark world: bull legs, marked book, bull multiples) | B17: =C5*'SOTP Bridge'!B16+C7*(Assumptions!$B$76+Assumptions!$B$107-Assumptions!$B$78)/Assumptions!$B$5+C8*'Relative & Normalized'!D6+C9*'Relative & Normalized'!D14

Sheet Assumptions
B2: Assumptions — every driver, with source and date. Blue = input, black = formula.
B4: Capital, market & terminal
A5: Shares outstanding (mn) | B5: 1085.5 | C5: 2Q/1H26 release, shareholder information
A6: Last library close (22-Jul-26) | B6: 31.31 | C6: published page anchor
A7: EGX quote, company IR page (19-Aug-26) | B7: 29.7 | C7: market-value weight basis
A8: Statutory corporate tax | B8: 0.225 | C8: FS note 11-C
A9: Terminal growth, nominal EGP | B9: 0.115 | C9: long-run inflation 9-10% + 1.5-2% real
A10: Terminal return on invested capital | B10: 0.225 | C10: anchored on the leg's realized LTM ROCE 22.9% (release table 10); sensitized 15-25%
B12: Cost of capital (rf* = observed yield − the sovereign's own default spread)
A13: Egypt 10Y local yield (19-Aug-26) | B13: 0.2292 | C13: investing.com
A14: Adjusted default spread, rating basis | B14: 0.0637 | C14: Damodaran Jan-2026
A15: Sovereign CDS spread | B15: 0.0341 | C15: Damodaran Jan-2026
A16: Total equity risk premium, rating basis | B16: 0.1394 | C16: Damodaran Jan-2026
A17: Total equity risk premium, CDS basis | B17: 0.0941 | C17: Damodaran Jan-2026
A18: Beta vs the exchange's published index | B18: 0.89274821 | C18: own weekly 5y Dimson regression vs EGX 30: n=255, R2 0.24, SE 0.202
A19: Avg rate, current EGP borrowings H1-26 | B19: 0.2082 | C19: FS note 26; the book is variable-rate (note 29), so the average IS marginal
A20: USD tranche, local-equivalent | B20: 0.1968 | C20: 7.78% coupon (note 26) + expected depreciation (CPI differential)
A21: EGP share of auto-leg debt | B21: 0.9 | C21: per-tranche split not disclosed; bounded <=17% USD from note 29; flagged
A22: Auto gross debt + leasing notes (30-Jun-26) | B22: 25078.9 | C22: release table 7
A23: Market capitalisation | B23: =Assumptions!$B$7*Assumptions!$B$5 | C23: IR quote x shares
A24: Equity weight | B24: =Assumptions!$B$23/(Assumptions!$B$23+Assumptions!$B$22) | C24: market values
A25: Debt weight | B25: =1-Assumptions!$B$24
A26: Cost of equity, CDS basis | B26: =Assumptions!$B$13-Assumptions!$B$15+Assumptions!$B$18*Assumptions!$B$17
A27: Cost of equity, rating basis | B27: =Assumptions!$B$13-Assumptions!$B$14+Assumptions!$B$18*Assumptions!$B$16
A28: Blended pre-tax cost of debt | B28: =Assumptions!$B$21*Assumptions!$B$19+(1-Assumptions!$B$21)*Assumptions!$B$20
A29: After-tax cost of debt | B29: =Assumptions!$B$28*(1-Assumptions!$B$8)
A30: WACC — CDS basis (primary) | B30: =Assumptions!$B$24*Assumptions!$B$26+Assumptions!$B$25*Assumptions!$B$29
A31: WACC — rating basis (shown alongside) | B31: =Assumptions!$B$24*Assumptions!$B$27+Assumptions!$B$25*Assumptions!$B$29
B33: Growth, cost and operating paths (FY27E-FY30E; FY26E is DERIVED on Segments)
A34: PC total volume growth | E34: derived | F34: 0.09 | G34: 0.08 | H34: 0.06 | I34: 0.05
A35: PC price growth | E35: derived | F35: 0.08 | G35: 0.07 | H35: 0.06 | I35: 0.06
A36: CKD volume growth (the localization driver) | E36: derived | F36: 0.12 | G36: 0.1 | H36: 0.07 | I36: 0.06
A37: CV&CE volume growth | E37: derived | F37: 0.14 | G37: 0.1 | H37: 0.08 | I37: 0.07
A38: CV&CE price growth | E38: derived | F38: 0.07 | G38: 0.06 | H38: 0.06 | I38: 0.05
A39: Bus volume growth (the recovery driver) | E39: derived | F39: 0.16 | G39: 0.12 | H39: 0.09 | I39: 0.08
A40: Construction-equipment units (planned) | E40: 32 | F40: 34 | G40: 36 | H40: 38 | I40: 40
A41: Light-Mobility volume growth | E41: derived | F41: 0.16 | G41: 0.13 | H41: 0.11 | I41: 0.09
A42: Light-Mobility price growth | E42: derived | F42: 0.06 | G42: 0.05 | H42: 0.05 | I42: 0.05
A43: Trading revenue growth | E43: derived | F43: 0.11 | G43: 0.1 | H43: 0.09 | I43: 0.08
A44: Other-auto revenue growth | E44: derived | F44: 0.1 | G44: 0.1 | H44: 0.09 | I44: 0.08
...

Sheet SOTP Bridge
B2: The group as the sum of its parts — the contested stake both ways, never averaged
B4: Round mark | C4: Balance-sheet mark
A5: Automotive equity value (cash-flow model) | B5: =DCF!B42 | C5: =DCF!B42
A6: GB Capital operating equity (ex-associates) | B6: =Assumptions!$B$106 | C6: =Assumptions!$B$106
A7: MNT-Halan stake | B7: =Assumptions!$B$107 | C7: =Assumptions!$B$78
A8: Other associates | B8: =Assumptions!$B$82 | C8: =Assumptions!$B$82
A9: Investments at fair value (OCI) | B9: =Assumptions!$B$83 | C9: =Assumptions!$B$83
A10: Sum of the parts | B10: =SUM(B5:B9) | C10: =SUM(C5:C9)
A11: Holding-company discount | B11: =-B10*Assumptions!$B$84 | C11: =-C10*Assumptions!$B$84
A12: Equity value | B12: =B10+B11 | C12: =C10+C11
A13: Per share | B13: =B12/Assumptions!$B$5 | C13: =C12/Assumptions!$B$5
A15: Bear per share (bear equity, leg haircuts, bear discount) | B15: =(DCF!B61+Assumptions!$B$106*Assumptions!$B$102+Assumptions!$B$107*Assumptions!$B$98+Assumptions!$B$82+Assumptions!$B$83)*(1-Assumptions!$B$104)/Assumptions!$B$5 | C15: =(DCF!B61+Assumptions!$B$106*Assumptions!$B$102+(Assumptions!$B$78+Assumptions!$B$82+Assumptions!$B$83)*Assumptions!$B$100)*(1-Assumptions!$B$104)/Assumptions!$B$5
A16: Bull per share (bull equity, leg uplifts, bull discount) | B16: =(DCF!B65+Assumptions!$B$106*Assumptions!$B$103+Assumptions!$B$107*Assumptions!$B$99+Assumptions!$B$82+Assumptions!$B$83)*(1-Assumptions!$B$105)/Assumptions!$B$5 | C16: =(DCF!B65+Assumptions!$B$106*Assumptions!$B$103+(Assumptions!$B$78+Assumptions!$B$82+Assumptions!$B$83)*Assumptions!$B$101)*(1-Assumptions!$B$105)/Assumptions!$B$5
A18: The whole gap between the two columns is one judgement about one stake. The reviewer could not verify the carrying value (qualified conclusion, second period); the round is real bank-led money but a first close. Neither is averaged away — the study carries both to the end.

Sheet Segments
B2: The bottom-up build — every disclosed unit grown on its own driver; FY26E derived from the H1 actual + the FY25 measured seasonal split; margins are OUTPUTS
B4: FY23 | C4: FY24 | D4: FY25 | E4: FY26E | F4: FY27E | G4: FY28E | H4: FY29E | I4: FY30E
A5: PC — locally assembled units (CKD, the launch-calendar driver) | B5: n/d | C5: n/d | D5: n/d | E5: =$B$42*(E7/$B$41)*$B$73 | F5: =E5*(1+Assumptions!F$36) | G5: =F5*(1+Assumptions!G$36) | H5: =G5*(1+Assumptions!H$36) | I5: =H5*(1+Assumptions!I$36)
A6: PC — imported units (CBU, residual import requirement) | B6: n/d | C6: n/d | D6: n/d | E6: =E7-E5 | F6: =F7-F5 | G6: =G7-G5 | H6: =H7-H5 | I6: =I7-I5
A7: PC — total units | B7: 26994 | C7: 42043 | D7: 56548 | E7: =$B$41+$B$41*(1-$B$75)/$B$75*$B$65 | F7: =E7*(1+Assumptions!F$34) | G7: =F7*(1+Assumptions!G$34) | H7: =G7*(1+Assumptions!H$34) | I7: =H7*(1+Assumptions!I$34)
A8: PC — price per unit (EGP mn) | B8: =B9/B7 | C8: =C9/C7 | D8: =D9/D7 | E8: =E9/E7 | F8: =E8*(1+Assumptions!F$35) | G8: =F8*(1+Assumptions!G$35) | H8: =G8*(1+Assumptions!H$35) | I8: =H8*(1+Assumptions!I$35)
A9: PC — revenue | B9: 16544.3 | C9: 36533.4 | D9: 52827.3 | E9: =$B$43+(E7-$B$41)*$B$80*$B$70 | F9: =F7*F8 | G9: =G7*G8 | H9: =H7*H8 | I9: =I7*I8
A10: PC — cost per unit (class-escalated) | E10: =E8*(1-$B$60) | F10: =E10*(1+Assumptions!$B$65*Assumptions!F$45+(1-Assumptions!$B$65)*Assumptions!F$46) | G10: =F10*(1+Assumptions!G$35) | H10: =G10*(1+Assumptions!H$35) | I10: =H10*(1+Assumptions!I$35)
A11: PC — gross profit | E11: =E9-E7*E10 | F11: =(F8-F10)*F7 | G11: =(G8-G10)*G7 | H11: =(H8-H10)*H7 | I11: =(I8-I10)*I7
A12: CV&CE — bus units (the recovery driver) | B12: n/d | C12: n/d | D12: n/d | E12: =$B$45*(E15/$B$44)*$B$74 | F12: =E12*(1+Assumptions!F$39) | G12: =F12*(1+Assumptions!G$39) | H12: =G12*(1+Assumptions!H$39) | I12: =H12*(1+Assumptions!I$39)
A13: CV&CE — truck units (residual) | B13: n/d | C13: n/d | D13: n/d | E13: =E15-E12-E14 | F13: =F15-F12-F14 | G13: =G15-G12-G14 | H13: =H15-H12-H14 | I13: =I15-I12-I14
A14: CV&CE — construction-equipment units (planned) | B14: n/d | C14: n/d | D14: n/d | E14: =Assumptions!E$40 | F14: =Assumptions!F$40 | G14: =Assumptions!G$40 | H14: =Assumptions!H$40 | I14: =Assumptions!I$40
A15: CV&CE — total units | B15: 2273 | C15: 2096 | D15: 3404 | E15: =$B$44+$B$44*(1-$B$76)/$B$76*$B$66 | F15: =E15*(1+Assumptions!F$37) | G15: =F15*(1+Assumptions!G$37) | H15: =G15*(1+Assumptions!H$37) | I15: =H15*(1+Assumptions!I$37)
A16: CV&CE — price per unit | B16: =B17/B15 | C16: =C17/C15 | D16: =D17/D15 | E16: =E17/E15 | F16: =E16*(1+Assumptions!F$38) | G16: =F16*(1+Assumptions!G$38) | H16: =G16*(1+Assumptions!H$38) | I16: =H16*(1+Assumptions!I$38)
A17: CV&CE — revenue | B17: 2323 | C17: 3984.5 | D17: 5956.8 | E17: =$B$46+(E15-$B$44)*$B$81*$B$71 | F17: =F15*F16 | G17: =G15*G16 | H17: =H15*H16 | I17: =I15*I16
A18: CV&CE — cost per unit (class-escalated) | E18: =E16*(1-$B$61) | F18: =E18*(1+Assumptions!$B$66*Assumptions!F$45+(1-Assumptions!$B$66)*Assumptions!F$46) | G18: =F18*(1+Assumptions!G$38) | H18: =G18*(1+Assumptions!H$38) | I18: =H18*(1+Assumptions!I$38)
A19: CV&CE — gross profit | E19: =E17-E15*E18 | F19: =(F16-F18)*F15 | G19: =(G16-G18)*G15 | H19: =(H16-H18)*H15 | I19: =(I16-I18)*I15
A20: 2-3-4W — units | B20: 13610 | C20: 20189 | D20: 33906 | E20: =$B$47+$B$47*(1-$B$77)/$B$77*$B$67 | F20: =E20*(1+Assumptions!F$41) | G20: =F20*(1+Assumptions!G$41) | H20: =G20*(1+Assumptions!H$41) | I20: =H20*(1+Assumptions!I$41)
A21: 2-3-4W — price per unit | B21: =B22/B20 | C21: =C22/C20 | D21: =D22/D20 | E21: =E22/E20 | F21: =E21*(1+Assumptions!F$42) | G21: =F21*(1+Assumptions!G$42) | H21: =G21*(1+Assumptions!H$42) | I21: =H21*(1+Assumptions!I$42)
A22: 2-3-4W — revenue | B22: 854.2 | C22: 1378.2 | D22: 2203.8 | E22: =$B$48+(E20-$B$47)*$B$82*$B$72 | F22: =F20*F21 | G22: =G20*G21 | H22: =H20*H21 | I22: =I20*I21
A23: 2-3-4W — cost per unit (class-escalated) | E23: =E21*(1-$B$62) | F23: =E23*(1+Assumptions!$B$67*Assumptions!F$45+(1-Assumptions!$B$67)*Assumptions!F$46) | G23: =F23*(1+Assumptions!G$42) | H23: =G23*(1+Assumptions!H$42) | I23: =H23*(1+Assumptions!I$42)
A24: 2-3-4W — gross profit | E24: =E22-E20*E23 | F24: =(F21-F23)*F20 | G24: =(G21-G23)*G20 | H24: =(H21-H23)*H20 | I24: =(I21-I23)*I20
A25: Trading — revenue | B25: 2506.8 | C25: 3815.5 | D25: 4242.8 | E25: =$B$49*(1+(1-$B$78)/$B$78*$B$68) | F25: =E25*(1+Assumptions!F$43) | G25: =F25*(1+Assumptions!G$43) | H25: =G25*(1+Assumptions!H$43) | I25: =H25*(1+Assumptions!I$43)
A26: Trading — cost ratio (class-escalated) | E26: =1-$B$63 | F26: =E26*(1+Assumptions!$B$68*Assumptions!F$45+(1-Assumptions!$B$68)*Assumptions!F$46)/(1+Assumptions!$B$69)*Assumptions!$B$70 | G26: =F26 | H26: =G26 | I26: =H26
A27: Trading — gross profit | E27: =E25*(1-E26) | F27: =F25*(1-F26) | G27: =G25*(1-G26) | H27: =H25*(1-H26) | I27: =I25*(1-I26)
A28: Other automotive — revenue | B28: 7625.2 | C28: 1353.4 | D28: 1127.6 | E28: =$B$50*(1+(1-$B$79)/$B$79*$B$69) | F28: =E28*(1+Assumptions!F$44) | G28: =F28*(1+Assumptions!G$44) | H28: =G28*(1+Assumptions!H$44) | I28: =H28*(1+Assumptions!I$44)
A29: Other automotive — cost ratio | E29: =1-$B$64 | F29: =E29*(1+Assumptions!$B$68*Assumptions!F$45+(1-Assumptions!$B$68)*Assumptions!F$46)/(1+Assumptions!$B$69) | G29: =F29 | H29: =G29 | I29: =H29
A30: AUTOMOTIVE REVENUE | B30: =B9+B17+B22+B25+B28 | C30: =C9+C17+C22+C25+C28 | D30: =D9+D17+D22+D25+D28 | E30: =E9+E17+E22+E25+E28 | F30: =F9+F17+F22+F25+F28 | G30: =G9+G17+G22+G25+G28 | H30: =H9+H17+H22+H25+H28 | I30: =I9+I17+I22+I25+I28
A31: AUTOMOTIVE GROSS PROFIT | B31: 5813.1 | C31: 9057.4 | D31: 9837.1 | E31: =$B$52+(E30-$B$51)*$B$86 | F31: =F11+F19+F24+F27+F28*(1-F29) | G31: =G11+G19+G24+G27+G28*(1-G29) | H31: =H11+H19+H24+H27+H28*(1-H29) | I31: =I11+I19+I24+I27+I28*(1-I29)
A32: Automotive gross margin (an OUTPUT) | B32: =B31/B30 | C32: =C31/C30 | D32: =D31/D30 | E32: =E31/E30 | F32: =F31/F30 | G32: =G31/G30 | H32: =H31/H30 | I32: =I31/I30
A34: GB Capital revenue | B34: 4950.9 | C34: 7383.6 | D34: 14743 | E34: 18700 | F34: =E34*(1+Assumptions!F$53) | G34: =F34*(1+Assumptions!G$53) | H34: =G34*(1+Assumptions!H$53) | I34: =H34*(1+Assumptions!I$53)
A35: GB Capital net profit (path input, incl associates) | E35: =Assumptions!E$54 | F35: =Assumptions!F$54 | G35: =Assumptions!G$54 | H35: =Assumptions!H$54 | I35: =Assumptions!I$54
A37: FY27E unit costs carry each class's escalator against its price once (the measured compression year); from FY28E cost moves with price — held flat both directions. Trading FY27E divides out its price growth and carries the 1.04 inventory-reset. 'n/d' = the subtype split is not disclosed for that year.
A40: Disclosed anchors (statements & release, 13-Aug-2026)
A41: PC volumes H1-26 (units) | B41: 29554
A42: CKD volumes H1-26 | B42: 15454
A43: PC revenue H1-26 | B43: 30595.7
A44: CV&CE volumes H1-26 | B44: 2490
A45: Bus volumes H1-26 | B45: 1002
A46: CV&CE revenue H1-26 | B46: 4749.1
...

Sheet Relative & Normalized
B2: Relative multiples and normalised earnings power
A4: FY26E group earnings per share | B4: ='Income Statement'!E17
A5: Multiple band (bear / base / bull) | B5: =Assumptions!$B$90 | C5: =Assumptions!$B$91 | D5: =Assumptions!$B$92
A6: Relative lens value | B6: =B4*B5 | C6: =B4*C5 | D6: =B4*D5
A8: Normalisation walk (mid-cycle)
A9: FY27E automotive operating profit | B9: =DCF!F10
A10: Financing cost at the eased-cycle rate on today's net debt | B10: =-Assumptions!$B$71*Assumptions!$B$64
A11: Tax at the statutory rate (no loss-stranding) | B11: =-(B9+B10)*Assumptions!$B$8
A12: GB Capital net profit, FY27E (incl associates) | B12: =Segments!F35
A13: Normalised group profit | B13: =B9+B10+B11+B12
A14: Normalised earnings lens (bear / base / bull) | B14: =B13*Assumptions!$B$96/Assumptions!$B$5*Assumptions!$B$93 | C14: =B13/Assumptions!$B$5*Assumptions!$B$94 | D14: =B13*Assumptions!$B$97/Assumptions!$B$5*Assumptions!$B$95
A16: The two distortions, priced (per share, FY26E basis)
A17: Tax above statute on unshielded regional losses | B17: =(Assumptions!E$49-Assumptions!$B$8)*('Income Statement'!E14/(1-Assumptions!E$49))/Assumptions!$B$5
A18: Funding cost above the eased-cycle rate | B18: =Assumptions!$B$71*(Assumptions!E$52-Assumptions!$B$64)*(1-Assumptions!$B$8)/Assumptions!$B$5

Sheet DCF
B2: Automotive leg — free cash flow to the firm; the terminal growth is PAID FOR (reinvestment = growth / terminal return)
E4: FY26E | F4: FY27E | G4: FY28E | H4: FY29E | I4: FY30E
A5: Revenue | E5: =Segments!E30 | F5: =Segments!F30 | G5: =Segments!G30 | H5: =Segments!H30 | I5: =Segments!I30
A6: Gross profit | E6: =Segments!E31 | F6: =Segments!F31 | G6: =Segments!G31 | H6: =Segments!H31 | I6: =Segments!I31
A7: GS&A | E7: =-E5*Assumptions!E$47 | F7: =-F5*Assumptions!F$47 | G7: =-G5*Assumptions!G$47 | H7: =-H5*Assumptions!H$47 | I7: =-I5*Assumptions!I$47
A8: Other operating income | E8: =E5*Assumptions!$B$58 | F8: =F5*Assumptions!$B$58 | G8: =G5*Assumptions!$B$58 | H8: =H5*Assumptions!$B$58 | I8: =I5*Assumptions!$B$58
A9: Net provisions | E9: =E5*Assumptions!$B$59 | F9: =F5*Assumptions!$B$59 | G9: =G5*Assumptions!$B$59 | H9: =H5*Assumptions!$B$59 | I9: =I5*Assumptions!$B$59
A10: Operating profit | E10: =E6+E7+E8+E9 | F10: =F6+F7+F8+F9 | G10: =G6+G7+G8+G9 | H10: =H6+H7+H8+H9 | I10: =I6+I7+I8+I9
A11: Effective tax rate | E11: =Assumptions!E$49 | F11: =Assumptions!F$49 | G11: =Assumptions!G$49 | H11: =Assumptions!H$49 | I11: =Assumptions!I$49
A12: Net operating profit after tax | E12: =E10*(1-E11) | F12: =F10*(1-F11) | G12: =G10*(1-G11) | H12: =H10*(1-H11) | I12: =I10*(1-I11)
A13: Depreciation & amortisation | E13: =E5*Assumptions!E$48 | F13: =F5*Assumptions!F$48 | G13: =G5*Assumptions!G$48 | H13: =H5*Assumptions!H$48 | I13: =I5*Assumptions!I$48
A14: EBITDA | E14: =E10+E13 | F14: =F10+F13 | G14: =G10+G13 | H14: =H10+H13 | I14: =I10+I13
A15: Capital expenditure | E15: =-Assumptions!E$50 | F15: =-Assumptions!F$50 | G15: =-Assumptions!G$50 | H15: =-Assumptions!H$50 | I15: =-Assumptions!I$50
A16: Working capital (level) | E16: =E5*Assumptions!E$51 | F16: =F5*Assumptions!F$51 | G16: =G5*Assumptions!G$51 | H16: =H5*Assumptions!H$51 | I16: =I5*Assumptions!I$51
A17: Change in working capital | E17: =E16-B22 | F17: =F16-E16 | G17: =G16-F16 | H17: =H16-G16 | I17: =I16-H16
A18: Free cash flow to the firm | E18: =E12+E13+E15-E17 | F18: =F12+F13+F15-F17 | G18: =G12+G13+G15-G17 | H18: =H12+H13+H15-H17 | I18: =I12+I13+I15-I17
A20: The realized first half (model definition, from the disclosed actuals)
A21: H1-26 operating profit (release) | B21: 3127
A22: FY25 working capital (base) | B22: 18917
A23: H1-26 working capital | B23: 17092.8
A24: H1-26 effective tax rate | B24: 0.4104
A25: H1-26 depreciation & amortisation | B25: 401.2
A26: H1-26 capital expenditure | B26: 1376.5
A27: H1-26 realized free cash flow | B27: =B21*(1-B24)+B25-B26-(B23-B22)
A28: H2-26E free cash flow | B28: =E18-B27
A30: Discount period (years, from 30-Jun-26, mid-period) | E30: 0.5 | F30: 1.5 | G30: 2.5 | H30: 3.5 | I30: 4.5
A31: Discount factor | E31: =1/(1+Assumptions!$B$30)^E30 | F31: =1/(1+Assumptions!$B$30)^F30 | G31: =1/(1+Assumptions!$B$30)^G30 | H31: =1/(1+Assumptions!$B$30)^H30 | I31: =1/(1+Assumptions!$B$30)^I30
A32: Present value | E32: =B28*E31 | F32: =F18*F31 | G32: =G18*G31 | H32: =H18*H31 | I32: =I18*I31
A34: Sum of discounted flows | B34: =SUM(E32:I32)
A35: Terminal reinvestment rate (growth / terminal return) | B35: =Assumptions!$B$9/Assumptions!$B$10
A36: Terminal cash flow (FY30E NOPAT grown, less forced reinvestment) | B36: =I12*(1+Assumptions!$B$9)*(1-B35)
A37: Terminal value | B37: =B36/(Assumptions!$B$30-Assumptions!$B$9)
A38: Present value of the terminal value | B38: =B37*I31
A39: Enterprise value — automotive | B39: =B34+B38
A40: Less net debt (30-Jun-26) | B40: =-Assumptions!$B$71
A41: Less non-controlling interests | B41: =-Assumptions!$B$72
A42: Automotive equity value | B42: =B39+B40+B41
A43: Per share | B43: =B42/Assumptions!$B$5
A44: Terminal share of enterprise value | B44: =B38/B39
A45: Alternative (the July construction): Gordon on year-five free cash flow | B45: =B34+I18*(1+Assumptions!$B$9)/(Assumptions!$B$30-Assumptions!$B$9)*I31-Assumptions!$B$71-Assumptions!$B$72
...

Sheet Income Statement
B2: Group income statement — three disclosed years and the five-year model
B4: FY23 | C4: FY24 | D4: FY25 | E4: FY26E | F4: FY27E | G4: FY28E | H4: FY29E | I4: FY30E
A5: Automotive revenue | B5: =Segments!B30 | C5: =Segments!C30 | D5: =Segments!D30 | E5: =Segments!E30 | F5: =Segments!F30 | G5: =Segments!G30 | H5: =Segments!H30 | I5: =Segments!I30
A6: GB Capital revenue | B6: 4950.9 | C6: 7383.6 | D6: 14743 | E6: =Segments!E34 | F6: =Segments!F34 | G6: =Segments!G34 | H6: =Segments!H34 | I6: =Segments!I34
A7: Inter-segment eliminations | B7: -487.7 | C7: -479.1 | D7: -871.5 | E7: =-(E5+E6)*Assumptions!$B$60 | F7: =-(F5+F6)*Assumptions!$B$60 | G7: =-(G5+G6)*Assumptions!$B$60 | H7: =-(H5+H6)*Assumptions!$B$60 | I7: =-(I5+I6)*Assumptions!$B$60
A8: Group revenue | B8: =SUM(B5:B7) | C8: =SUM(C5:C7) | D8: =SUM(D5:D7) | E8: =SUM(E5:E7) | F8: =SUM(F5:F7) | G8: =SUM(G5:G7) | H8: =SUM(H5:H7) | I8: =SUM(I5:I7)
A10: Automotive operating profit | B10: 3460.9 | C10: 5564.9 | D10: 5830.9 | E10: =DCF!E10 | F10: =DCF!F10 | G10: =DCF!G10 | H10: =DCF!H10 | I10: =DCF!I10
A11: Automotive finance cost | E11: =-(Assumptions!$B$63+0.5*Assumptions!$B$71*Assumptions!E$52) | F11: =-'Balance Sheet'!E10*Assumptions!F$52 | G11: =-'Balance Sheet'!F10*Assumptions!G$52 | H11: =-'Balance Sheet'!G10*Assumptions!H$52 | I11: =-'Balance Sheet'!H10*Assumptions!I$52
A12: Automotive profit before tax | E12: =E10+E11 | F12: =F10+F11 | G12: =G10+G11 | H12: =H10+H11 | I12: =I10+I11
A13: Automotive tax | E13: =-E12*DCF!E11 | F13: =-F12*DCF!F11 | G13: =-G12*DCF!G11 | H13: =-H12*DCF!H11 | I13: =-I12*DCF!I11
A14: Automotive net profit | E14: =E12+E13 | F14: =F12+F13 | G14: =G12+G13 | H14: =H12+H13 | I14: =I12+I13
A15: GB Capital net profit (incl associates) | E15: =Segments!E35 | F15: =Segments!F35 | G15: =Segments!G35 | H15: =Segments!H35 | I15: =Segments!I35
A16: Group net profit (attributable) | B16: 1890.8 | C16: 2928.1 | D16: 2880 | E16: =E14+E15 | F16: =F14+F15 | G16: =G14+G15 | H16: =H14+H15 | I16: =I14+I15
A17: Earnings per share (EGP) | B17: =B16/Assumptions!$B$5 | C17: =C16/Assumptions!$B$5 | D17: =D16/Assumptions!$B$5 | E17: =E16/Assumptions!$B$5 | F17: =F16/Assumptions!$B$5 | G17: =G16/Assumptions!$B$5 | H17: =H16/Assumptions!$B$5 | I17: =I16/Assumptions!$B$5
A19: History: the model's FY26E includes the realized half (revenue 48,474.4, attributable profit 1,262.0, earnings per share 1.163 — all disclosed).

Sheet Balance Sheet
B2: Condensed balance-sheet model — every roll a formula
D4: FY25 | E4: FY26E | F4: FY27E | G4: FY28E | H4: FY29E | I4: FY30E
A5: Automotive working capital | D5: 18917 | E5: =DCF!E16 | F5: =DCF!F16 | G5: =DCF!G16 | H5: =DCF!H16 | I5: =DCF!I16
A6: Net PP&E and intangibles (roll: + capex − D&A) | D6: 13389.1 | E6: =D6-DCF!E15-DCF!E13 | F6: =E6-DCF!F15-DCF!F13 | G6: =F6-DCF!G15-DCF!G13 | H6: =G6-DCF!H15-DCF!H13 | I6: =H6-DCF!I15-DCF!I13
A7: Investments in associates (roll: + equity pickup) | D7: 15732.4 | E7: =D7+Assumptions!E$55 | F7: =E7+Assumptions!F$55 | G7: =F7+Assumptions!G$55 | H7: =G7+Assumptions!H$55 | I7: =H7+Assumptions!I$55
A8: GB Capital operating net assets (held) | E8: =Assumptions!$B$106 | F8: =Assumptions!$B$106 | G8: =Assumptions!$B$106 | H8: =Assumptions!$B$106 | I8: =Assumptions!$B$106
A10: Automotive net debt (cash-sweep roll) | D10: 14493.6 | E10: =D10-(DCF!E18+'Income Statement'!E11*(1-DCF!E11)-E12*Assumptions!$B$62) | F10: =E10-(DCF!F18+'Income Statement'!F11*(1-DCF!F11)-F12*Assumptions!$B$62) | G10: =F10-(DCF!G18+'Income Statement'!G11*(1-DCF!G11)-G12*Assumptions!$B$62) | H10: =G10-(DCF!H18+'Income Statement'!H11*(1-DCF!H11)-H12*Assumptions!$B$62) | I10: =H10-(DCF!I18+'Income Statement'!I11*(1-DCF!I11)-I12*Assumptions!$B$62)
A11: Parent equity (roll: + profit − dividend) | D11: 33454.268 | E11: =D11+'Income Statement'!E16-E12 | F11: =E11+'Income Statement'!F16-F12 | G11: =F11+'Income Statement'!G16-G12 | H11: =G11+'Income Statement'!H16-H12 | I11: =H11+'Income Statement'!I16-I12
A12: Dividends paid | E12: =Assumptions!$B$61*Assumptions!$B$5 | F12: =Assumptions!$B$61*Assumptions!$B$5 | G12: =Assumptions!$B$61*Assumptions!$B$5 | H12: =Assumptions!$B$61*Assumptions!$B$5 | I12: =Assumptions!$B$61*Assumptions!$B$5
A14: The D column carries the disclosed anchors: FY25 restated associates (15,732.4 after the +2,460.2 restatement) and the 30-Jun-26 net debt / parent equity. Conversion cycle measured at 30-Jun-26: 122 days inventory, 27 receivables, 82 payables — the working-capital ratio path projects that cycle.
A16: Book value per share | E16: =E11/Assumptions!$B$5 | F16: =F11/Assumptions!$B$5 | G16: =G11/Assumptions!$B$5 | H16: =H11/Assumptions!$B$5 | I16: =I11/Assumptions!$B$5

Sheet Cash Flow
B2: Condensed group cash-flow model
E4: FY26E | F4: FY27E | G4: FY28E | H4: FY29E | I4: FY30E
A5: Group net profit | E5: ='Income Statement'!E16 | F5: ='Income Statement'!F16 | G5: ='Income Statement'!G16 | H5: ='Income Statement'!H16 | I5: ='Income Statement'!I16
A6: Depreciation & amortisation | E6: =DCF!E13 | F6: =DCF!F13 | G6: =DCF!G13 | H6: =DCF!H13 | I6: =DCF!I13
A7: Change in working capital | E7: =-DCF!E17 | F7: =-DCF!F17 | G7: =-DCF!G17 | H7: =-DCF!H17 | I7: =-DCF!I17
A8: Capital expenditure | E8: =DCF!E15 | F8: =DCF!F15 | G8: =DCF!G15 | H8: =DCF!H15 | I8: =DCF!I15
A9: Dividends paid | E9: =-'Balance Sheet'!E12 | F9: =-'Balance Sheet'!F12 | G9: =-'Balance Sheet'!G12 | H9: =-'Balance Sheet'!H12 | I9: =-'Balance Sheet'!I12
A10: Cash flow after dividends | E10: =SUM(E5:E9) | F10: =SUM(F5:F9) | G10: =SUM(G5:G9) | H10: =SUM(H5:H9) | I10: =SUM(I5:I9)
A11: Change in automotive net debt (sweep) | E11: ='Balance Sheet'!E10-Assumptions!$B$71 | F11: ='Balance Sheet'!F10-'Balance Sheet'!E10 | G11: ='Balance Sheet'!G10-'Balance Sheet'!F10 | H11: ='Balance Sheet'!H10-'Balance Sheet'!G10 | I11: ='Balance Sheet'!I10-'Balance Sheet'!H10

Sheet Summary Financials
B2: Summary financials (links)
B4: FY23 | C4: FY24 | D4: FY25 | E4: FY26E | F4: FY27E | G4: FY28E | H4: FY29E | I4: FY30E
A5: Group revenue | B5: ='Income Statement'!B8 | C5: ='Income Statement'!C8 | D5: ='Income Statement'!D8 | E5: ='Income Statement'!E8 | F5: ='Income Statement'!F8 | G5: ='Income Statement'!G8 | H5: ='Income Statement'!H8 | I5: ='Income Statement'!I8
A6: Automotive EBITDA | B6: 3794.6 | C6: 5880.5 | D6: 6363.3 | E6: =DCF!E14 | F6: =DCF!F14 | G6: =DCF!G14 | H6: =DCF!H14 | I6: =DCF!I14
A7: Group net profit (attributable) | B7: ='Income Statement'!B16 | C7: ='Income Statement'!C16 | D7: ='Income Statement'!D16 | E7: ='Income Statement'!E16 | F7: ='Income Statement'!F16 | G7: ='Income Statement'!G16 | H7: ='Income Statement'!H16 | I7: ='Income Statement'!I16
A8: Earnings per share (EGP) | B8: ='Income Statement'!B17 | C8: ='Income Statement'!C17 | D8: ='Income Statement'!D17 | E8: ='Income Statement'!E17 | F8: ='Income Statement'!F17 | G8: ='Income Statement'!G17 | H8: ='Income Statement'!H17 | I8: ='Income Statement'!I17

Sheet Monte Carlo
B2: Published price-probability map — reproduced unchanged from the live page
A4: A copy, not a computation: struck on the closing library of 2026-07-22, computed 2026-07-28, anchored at the 31.31 close. This refresh changes the fundamental range only; the map was NOT re-struck and its 1-month window resolves 2026-08-23. A fresh price data-set re-strikes it on its own clock.
A6: Horizon | C6: 5th | D6: 25th | E6: median | F6: 75th | G6: 95th
A7: 1 month (resolves 23-Aug-26) | C7: 25.55 | D7: 29.31 | E7: 31.78 | F7: 34.47 | G7: 39.54
A8: 3 months (resolves 22-Oct-26) | C8: 22.08 | D8: 28.34 | E8: 32.8 | F8: 37.86 | G8: 48.54
A10: Touch ladder (level, probability within 1 month / 3 months, %)
B11: 40 | C11: 7 | D11: 30
B12: 38 | C12: 13 | D12: 40
B13: 36 | C13: 25 | D13: 54
B14: 34 | C14: 46 | D14: 71
B15: 32 | C15: 78 | D15: 89
B16: 30 | C16: 59 | D16: 73
B17: 28 | C17: 27 | D17: 48
B18: 26 | C18: 11 | D18: 30

Sheet Sensitivity
B2: Live sensitivities — every cell a formula
A4: Sum of the parts per share: stake mark x holding discount
C5: 0 | D5: 0.05 | E5: 0.1 | F5: 0.15 | G5: 0.2
B6: 0.5 | C6: =(DCF!$B$42+Assumptions!$B$106+Assumptions!$B$107*$B6+Assumptions!$B$82+Assumptions!$B$83)*(1-C$5)/Assumptions!$B$5 | D6: =(DCF!$B$42+Assumptions!$B$106+Assumptions!$B$107*$B6+Assumptions!$B$82+Assumptions!$B$83)*(1-D$5)/Assumptions!$B$5 | E6: =(DCF!$B$42+Assumptions!$B$106+Assumptions!$B$107*$B6+Assumptions!$B$82+Assumptions!$B$83)*(1-E$5)/Assumptions!$B$5 | F6: =(DCF!$B$42+Assumptions!$B$106+Assumptions!$B$107*$B6+Assumptions!$B$82+Assumptions!$B$83)*(1-F$5)/Assumptions!$B$5 | G6: =(DCF!$B$42+Assumptions!$B$106+Assumptions!$B$107*$B6+Assumptions!$B$82+Assumptions!$B$83)*(1-G$5)/Assumptions!$B$5
B7: 0.625 | C7: =(DCF!$B$42+Assumptions!$B$106+Assumptions!$B$107*$B7+Assumptions!$B$82+Assumptions!$B$83)*(1-C$5)/Assumptions!$B$5 | D7: =(DCF!$B$42+Assumptions!$B$106+Assumptions!$B$107*$B7+Assumptions!$B$82+Assumptions!$B$83)*(1-D$5)/Assumptions!$B$5 | E7: =(DCF!$B$42+Assumptions!$B$106+Assumptions!$B$107*$B7+Assumptions!$B$82+Assumptions!$B$83)*(1-E$5)/Assumptions!$B$5 | F7: =(DCF!$B$42+Assumptions!$B$106+Assumptions!$B$107*$B7+Assumptions!$B$82+Assumptions!$B$83)*(1-F$5)/Assumptions!$B$5 | G7: =(DCF!$B$42+Assumptions!$B$106+Assumptions!$B$107*$B7+Assumptions!$B$82+Assumptions!$B$83)*(1-G$5)/Assumptions!$B$5
B8: 0.75 | C8: =(DCF!$B$42+Assumptions!$B$106+Assumptions!$B$107*$B8+Assumptions!$B$82+Assumptions!$B$83)*(1-C$5)/Assumptions!$B$5 | D8: =(DCF!$B$42+Assumptions!$B$106+Assumptions!$B$107*$B8+Assumptions!$B$82+Assumptions!$B$83)*(1-D$5)/Assumptions!$B$5 | E8: =(DCF!$B$42+Assumptions!$B$106+Assumptions!$B$107*$B8+Assumptions!$B$82+Assumptions!$B$83)*(1-E$5)/Assumptions!$B$5 | F8: =(DCF!$B$42+Assumptions!$B$106+Assumptions!$B$107*$B8+Assumptions!$B$82+Assumptions!$B$83)*(1-F$5)/Assumptions!$B$5 | G8: =(DCF!$B$42+Assumptions!$B$106+Assumptions!$B$107*$B8+Assumptions!$B$82+Assumptions!$B$83)*(1-G$5)/Assumptions!$B$5
B9: 0.875 | C9: =(DCF!$B$42+Assumptions!$B$106+Assumptions!$B$107*$B9+Assumptions!$B$82+Assumptions!$B$83)*(1-C$5)/Assumptions!$B$5 | D9: =(DCF!$B$42+Assumptions!$B$106+Assumptions!$B$107*$B9+Assumptions!$B$82+Assumptions!$B$83)*(1-D$5)/Assumptions!$B$5 | E9: =(DCF!$B$42+Assumptions!$B$106+Assumptions!$B$107*$B9+Assumptions!$B$82+Assumptions!$B$83)*(1-E$5)/Assumptions!$B$5 | F9: =(DCF!$B$42+Assumptions!$B$106+Assumptions!$B$107*$B9+Assumptions!$B$82+Assumptions!$B$83)*(1-F$5)/Assumptions!$B$5 | G9: =(DCF!$B$42+Assumptions!$B$106+Assumptions!$B$107*$B9+Assumptions!$B$82+Assumptions!$B$83)*(1-G$5)/Assumptions!$B$5
B10: 1 | C10: =(DCF!$B$42+Assumptions!$B$106+Assumptions!$B$107*$B10+Assumptions!$B$82+Assumptions!$B$83)*(1-C$5)/Assumptions!$B$5 | D10: =(DCF!$B$42+Assumptions!$B$106+Assumptions!$B$107*$B10+Assumptions!$B$82+Assumptions!$B$83)*(1-D$5)/Assumptions!$B$5 | E10: =(DCF!$B$42+Assumptions!$B$106+Assumptions!$B$107*$B10+Assumptions!$B$82+Assumptions!$B$83)*(1-E$5)/Assumptions!$B$5 | F10: =(DCF!$B$42+Assumptions!$B$106+Assumptions!$B$107*$B10+Assumptions!$B$82+Assumptions!$B$83)*(1-F$5)/Assumptions!$B$5 | G10: =(DCF!$B$42+Assumptions!$B$106+Assumptions!$B$107*$B10+Assumptions!$B$82+Assumptions!$B$83)*(1-G$5)/Assumptions!$B$5
A12: The crux as a ladder: the second close, priced through the whole synthesis
A13: Round valuation (USD mn) | B13: Stake value (EGP mn) | C13: Sum of the parts / share | D13: Weighted central / share
A14: 1000 | B14: =Assumptions!$B$79*A14*Assumptions!$B$81 | C14: =(DCF!$B$42+Assumptions!$B$106+B14+Assumptions!$B$82+Assumptions!$B$83)*(1-Assumptions!$B$84)/Assumptions!$B$5 | D14: ='Fundamental Valuation'!C5*C14+'Fundamental Valuation'!C7*'Fundamental Valuation'!B7+'Fundamental Valuation'!C8*'Fundamental Valuation'!B8+'Fundamental Valuation'!C9*'Fundamental Valuation'!B9
A15: 1200 | B15: =Assumptions!$B$79*A15*Assumptions!$B$81 | C15: =(DCF!$B$42+Assumptions!$B$106+B15+Assumptions!$B$82+Assumptions!$B$83)*(1-Assumptions!$B$84)/Assumptions!$B$5 | D15: ='Fundamental Valuation'!C5*C15+'Fundamental Valuation'!C7*'Fundamental Valuation'!B7+'Fundamental Valuation'!C8*'Fundamental Valuation'!B8+'Fundamental Valuation'!C9*'Fundamental Valuation'!B9
A16: 1400 | B16: =Assumptions!$B$79*A16*Assumptions!$B$81 | C16: =(DCF!$B$42+Assumptions!$B$106+B16+Assumptions!$B$82+Assumptions!$B$83)*(1-Assumptions!$B$84)/Assumptions!$B$5 | D16: ='Fundamental Valuation'!C5*C16+'Fundamental Valuation'!C7*'Fundamental Valuation'!B7+'Fundamental Valuation'!C8*'Fundamental Valuation'!B8+'Fundamental Valuation'!C9*'Fundamental Valuation'!B9
A17: 1600 | B17: =Assumptions!$B$79*A17*Assumptions!$B$81 | C17: =(DCF!$B$42+Assumptions!$B$106+B17+Assumptions!$B$82+Assumptions!$B$83)*(1-Assumptions!$B$84)/Assumptions!$B$5 | D17: ='Fundamental Valuation'!C5*C17+'Fundamental Valuation'!C7*'Fundamental Valuation'!B7+'Fundamental Valuation'!C8*'Fundamental Valuation'!B8+'Fundamental Valuation'!C9*'Fundamental Valuation'!B9
A18: the balance-sheet carrying instead | B18: =Assumptions!$B$78 | C18: ='SOTP Bridge'!C13 | D18: ='Fundamental Valuation'!B12
A20: Terminal-value construction (the disciplined base vs the alternatives)
A21: Terminal return on capital | B21: Automotive equity (EGP mn) | C21: Per share
A22: 0.15 | B22: =DCF!B34+DCF!I12*(1+Assumptions!$B$9)*(1-Assumptions!$B$9/A22)/(Assumptions!$B$30-Assumptions!$B$9)*DCF!I31-Assumptions!$B$71-Assumptions!$B$72 | C22: =B22/Assumptions!$B$5
A23: 0.2 | B23: =DCF!B34+DCF!I12*(1+Assumptions!$B$9)*(1-Assumptions!$B$9/A23)/(Assumptions!$B$30-Assumptions!$B$9)*DCF!I31-Assumptions!$B$71-Assumptions!$B$72 | C23: =B23/Assumptions!$B$5
A24: 0.225 | B24: =DCF!B34+DCF!I12*(1+Assumptions!$B$9)*(1-Assumptions!$B$9/A24)/(Assumptions!$B$30-Assumptions!$B$9)*DCF!I31-Assumptions!$B$71-Assumptions!$B$72 | C24: =B24/Assumptions!$B$5
A25: 0.25 | B25: =DCF!B34+DCF!I12*(1+Assumptions!$B$9)*(1-Assumptions!$B$9/A25)/(Assumptions!$B$30-Assumptions!$B$9)*DCF!I31-Assumptions!$B$71-Assumptions!$B$72 | C25: =B25/Assumptions!$B$5
A26: July construction (Gordon on year-five cash flow) | B26: =DCF!B45 | C26: =B26/Assumptions!$B$5

Sheet Per-Share & Ratios
B2: Per-share values and ratios
E4: FY26E | F4: FY27E | G4: FY28E | H4: FY29E | I4: FY30E
A5: Earnings per share | E5: ='Income Statement'!E17 | F5: ='Income Statement'!F17 | G5: ='Income Statement'!G17 | H5: ='Income Statement'!H17 | I5: ='Income Statement'!I17
A6: Book value per share | E6: ='Balance Sheet'!E16 | F6: ='Balance Sheet'!F16 | G6: ='Balance Sheet'!G16 | H6: ='Balance Sheet'!H16 | I6: ='Balance Sheet'!I16
A7: Return on equity | E7: ='Income Statement'!E16/'Balance Sheet'!E11 | F7: ='Income Statement'!F16/'Balance Sheet'!F11 | G7: ='Income Statement'!G16/'Balance Sheet'!G11 | H7: ='Income Statement'!H16/'Balance Sheet'!H11 | I7: ='Income Statement'!I16/'Balance Sheet'!I11
A8: Net debt / automotive EBITDA | E8: ='Balance Sheet'!E10/DCF!E14 | F8: ='Balance Sheet'!F10/DCF!F14 | G8: ='Balance Sheet'!G10/DCF!G14 | H8: ='Balance Sheet'!H10/DCF!H14 | I8: ='Balance Sheet'!I10/DCF!I14
A9: Price / earnings at the last close | E9: =Assumptions!$B$6/'Income Statement'!E17 | F9: =Assumptions!$B$6/'Income Statement'!F17 | G9: =Assumptions!$B$6/'Income Statement'!G17 | H9: =Assumptions!$B$6/'Income Statement'!H17 | I9: =Assumptions!$B$6/'Income Statement'!I17
A10: Price / book at the last close | E10: =Assumptions!$B$6/'Balance Sheet'!E16 | F10: =Assumptions!$B$6/'Balance Sheet'!F16 | G10: =Assumptions!$B$6/'Balance Sheet'!G16 | H10: =Assumptions!$B$6/'Balance Sheet'!H16 | I10: =Assumptions!$B$6/'Balance Sheet'!I16
A11: Dividend yield at the last close | E11: =Assumptions!$B$61/Assumptions!$B$6 | F11: =Assumptions!$B$61/Assumptions!$B$6 | G11: =Assumptions!$B$61/Assumptions!$B$6 | H11: =Assumptions!$B$61/Assumptions!$B$6 | I11: =Assumptions!$B$61/Assumptions!$B$6

Sheet Peer & Sector
B2: Peer frame (context only — never a source for the subject's numbers)
A4: Peer | B4: Trailing P/E | C4: Note
A5: Contact Financial (EGX) — consumer/NBFS | B5: 9.41 | C5: the direct Egyptian financing peer
A6: Dogus Otomotiv (Istanbul) — auto distribution | B6: 12.55 | C6: P/B 0.62 on inflation-restated book
A7: AutoNation (US) — auto retail | B7: 9.11 | C7: mature-market anchor; forward 8.35
A8: Bajaj Auto (India) — two/three-wheelers | B8: 27.56 | C8: partner brand; far richer market
A10: GB Corp at the last close on FY26E earnings | B10: =Assumptions!$B$6/'Income Statement'!E17
A11: GB Corp at the last close on restated book | B11: =Assumptions!$B$6/'Fundamental Valuation'!B7
A13: Peer marks 19-Aug-2026, aggregator-sourced (market data only). Logged discrepancy: Contact Financial's market capitalisation is quoted between EGP 4.5bn and 6.6bn across services on different dates.
