Workbook

Sheet READ FIRST
A1: Testahil — Savola Group Company (Tadawul: 2050)
A3: Companion model · Independent Valuation Study · Educational analysis · Not investment advice
A5: What this workbook is. A transparent companion to the Savola Group valuation study. Every blue cell is
A6: an input; every black cell is a formula; green cells link across sheets.
A8: IT IS FORMULA-DRIVEN. Every figure that can be derived arithmetically from a driver is a live formula, so
A9: you can change a blue cell on Assumptions and watch the model reprice: the cost of capital is built from
A10: the risk-free rate net of the sovereign spread, beta and the premium rather than pasted; the discount
A11: factors compound; and the segment build, income statement, balance sheet, cash flow, ratios and all four
A12: lenses chain off the same cells.
A14: THIS IS THE SECOND EDITION (19-Aug-2026). It restrikes the 18-Aug first edition after a four-critique
A15: external audit: the settled 18-Aug close (25.40) replaces an intraday print; the cash-flow waterfall now
A16: charges the FULL lease additions; the terminal return on capital is COMPUTED from the model's own year
... A78: Per-Share & Ratios · Peer & Sector.

Sheet Summary
A1: Summary — valuation at a glance
A2: All values link live to their source sheets
A4: Lens | B4: Bear | C4: Base | D4: Bull | E4: Weight | F4: Contribution | G4: vs spot
A5: Discounted cash flow (Framing A) | B5: 7.697414 | C5: =DCF!C64 | D5: 31.72731 | E5: =Assumptions!$C$148 | F5: =C5*E5 | G5: =C5/$C$14-1
A6: Relative multiples | B6: ='Relative & Normalized'!C15 | C6: ='Relative & Normalized'!C14 | D6: ='Relative & Normalized'!D15 | E6: =Assumptions!$C$149 | F6: =C6*E6 | G6: =C6/$C$14-1
A7: Normalised earnings power | B7: ='Relative & Normalized'!E23 | C7: ='Relative & Normalized'!C23 | D7: ='Relative & Normalized'!F23 | E7: =Assumptions!$C$150 | F7: =C7*E7 | G7: =C7/$C$14-1
A8: Book value and sustainable return | B8: ='Relative & Normalized'!E29 | C8: ='Relative & Normalized'!C29 | D8: ='Relative & Normalized'!F29 | E8: =Assumptions!$C$151 | F8: =C8*E8 | G8: =C8/$C$14-1
A9: Weighted central | B9: =B5*E5+B6*E6+B7*E7+B8*E8 | C9: =SUM(F5:F8) | D9: =D5*E5+D6*E6+D7*E7+D8*E8 | E9: =SUM(E5:E8) | G9: =C9/$C$14-1
A10: Span across lenses (min/max — NOT weighted) | B10: =MIN(B5:B8) | D10: =MAX(D5:D8)
A11: Contested judgement, other way — Framing B (−6% then −3% forever) | C11: 17.527742 | G11: =C11/$C$14-1
A12: Terminal value share of DCF enterprise value | C12: =DCF!C34
A13: Expert panel median | C13: ='Fundamental Valuation'!C31 | G13: =C13/$C$14-1
A14: Market price (settled 18-Aug-2026 close) | C14: =Assumptions!$C$5
A16: Key figure | C16: Value
A17: Shares issued (mn) | C17: =Assumptions!$C$6
A18: Market capitalisation (SAR mn) | C18: =$C$14*Assumptions!$C$6
A19: FY2025 revenue (SAR mn, audited) | C19: ='Income Statement'!D5
A20: FY2025 operating EBITDA (SAR mn) | C20: ='Income Statement'!D9
A21: FY2026E revenue (SAR mn) | C21: ='Income Statement'!E5
A22: FY2026E EPS (SAR) | C22: ='Income Statement'!E17
A23: Cost of capital — explicit window | C23: =DCF!C52
A24: Cost of capital — terminal | C24: =DCF!C58
A25: Terminal growth | C25: =Assumptions!$C$110
A26: Terminal asset life, derived from note 6 (years) | C26: =Assumptions!$C$106
A27: Terminal free cash flow as a share of terminal profit | C27: =DCF!C29/DCF!C24
A28: Net debt, 30-Jun-2026 (company definition, SAR mn) | C28: 851
A29: Weighted central — first edition, 18-Aug-2026 (superseded by this edition) | C29: 28.016591

Sheet Fundamental Valuation
A1: Fundamental valuation — four lenses, the contested judgement, the panel
A4: Lens / step | B4: Basis | C4: SAR per share
A5: Discounted cash flow (Framing A) | B5: five-year FCFF (full lease additions charged) + computed-return terminal | C5: =DCF!C64
A6: bear | B6: Framing B density (−6% then −3%) · oil GP/t −40 · sugar −15 · half volume growth · flat store opex | C6: 7.697414
A7: bull | B7: oil GP/t +25 · sugar +10 · volumes x1.2 · Panda gross margin +40bp | C7: 31.72731
A8: Relative multiples | B8: trailing peer-mix P/E x trailing recurring EPS, conglomerate discount applied | C8: ='Relative & Normalized'!C14
A9: Normalised earnings power | B9: mid-cycle margin on FY2026E revenue | C9: ='Relative & Normalized'!C23
A10: Book value and sustainable return | B10: justified P/B on 30-Jun-2026 book; ROE = model FY2026E | C10: ='Relative & Normalized'!C29
A12: Weighted central | C12: =Summary!C9
A14: THE CONTESTED JUDGEMENT — PANDA'S EXPANSION, BOTH WAYS
A15: Framing A: density stabilises as CXR and e-commerce mature | C15: =DCF!C64
A16: Framing B: the density erosion never fades — −6% in FY2026E, then −3% every year forever (engine re-run) | C16: 17.527742
A17: The judgement is worth (Framing A less Framing B, per share) | C17: =C15-C16
A18: CDS-basis fair value (same model, CDS sovereign basis, Jan-2026 vintage flagged; engine re-run) | C18: 21.859103
A20: JUDGEMENT VARIANTS — every lever value published (engine re-runs)
A21: Store path at the H1-2026 run-rate (+8/yr instead of guidance; lease growth scaled to the 0.4x cadence) | C21: 18.230567
A22: Density opening at −7.1% (the June-2025 = 213 assumption end of the range) | C22: 23.139473
A23: Density opening at −6.0% (the interpolated end; the base input) | C23: 23.820773
A24: Asset life read at twice the directly measured average age of the base — the heavier of the two readings of note 6 | C24: 21.816341
A26: EXPERT PANEL
A27: Expert | B27: Method | C27: Base (SAR/share) | D27: Low | E27: High
A28: Expert 1 | B28: segment sum-of-the-parts | C28: 37.596912 | D28: 31.305745 | E28: 43.88808
A29: Expert 2 | B29: two-stage dividend model | C29: 19.036446 | D29: 17.151314 | E29: 21.588262
A30: Expert 3 | B30: residual income / economic profit | C30: 21.540468 | D30: 20.590568 | E30: 23.401665
A31: Panel median | C31: =MEDIAN(C28:C30)
A33: The risk-free rate, priced both ways
A34: The base is the PUBLISHED SAR sovereign curve: FTSE SAGBI 7-10y yield 5.52% (31-Jul-2026 factsheet; iBoxx SAR sukuk 5.44% at 6.07y corroborates). Discounting at −50bp / +50bp instead is an engine re-run worth the figures at right | C34: 26.340361 | D34: 21.139026

Sheet Assumptions
A1: Assumptions — every input in the model
A2: Blue cells are inputs. Change one and the model reprices: everything downstream is a formula.
A3: Input | B3: 2026E | C3: 2027E | D3: 2028E | E3: 2029E | F3: 2030E
A4: Anchors
A5: Spot price (SAR, SETTLED 18-Aug-2026 close) | C5: 30.3
A6: Shares issued (mn) | C6: 300
A7: Shares outstanding ex-treasury (mn; Q2-2026 interims EPS-note divisor) | C7: 296.682
A8: Combined zakat + income tax rate on core profit | C8: 0.195
A9: Dividend payout (stated policy 50-60% of net profit; midpoint) | C9: 0.55
A10: Days from the 31-Dec-2025 valuation date to the 18-Aug-2026 anchor | C10: 246
A11: Dividend gone ex between valuation date and anchor (SAR/share) | C11: 1.7
A13: FY2025 disclosed bases (audited statements + company presentations)
A14: Group revenue FY2025 | C14: 26081.053
A15: Group gross profit FY2025 | C15: 5088.894
A16: Oil volume FY2025 (k MT) | C16: 1322
A17: Oil revenue FY2025 | C17: 7098
A18: Sugar volume FY2025 (k MT) | C18: 2162
A19: Sugar revenue FY2025 | C19: 4868
A20: Pasta volume FY2025 (k MT, DISCLOSED — FY2025 presentation p17) | C20: 263
A21: Pasta revenue FY2025 | C21: 545
A22: Nuts & spices revenue FY2025 (residual to the audited segment) | C22: 768.85
A23: Panda (Retail) segment revenue FY2025 | C23: 11327.912
A24: Food Services (Herfy) segment revenue FY2025 | C24: 1082.562
A25: Frozen Food (Al Kabeer) segment revenue FY2025 | C25: 804.997
... A28: Panda stores at Dec-2025 | C28: 227
A30: Unit build — Food Processing (volume x price x GP/tonne; margins are outputs)
A31: Oil volume growth | B31: 0.125 | C31: 0.04 | D31: 0.03 | E31: 0.025 | F31: 0.02
A32: Oil revenue-per-tonne growth | B32: 0.005 | C32: 0.015 | D32: 0.015 | E32: 0.01 | F32: 0.01
A33: Oil gross profit per tonne (SAR/t) | B33: 740 | C33: 745 | D33: 745 | E33: 745 | F33: 745
A34: Sugar volume growth | B34: 0.055 | C34: 0.025 | D34: 0.02 | E34: 0.02 | F34: 0.015
A35: Sugar revenue-per-tonne growth | B35: -0.075 | C35: 0.005 | D35: 0.005 | E35: 0.005 | F35: 0.005
A36: Sugar gross profit per tonne (SAR/t) | B36: 215 | C36: 212 | D36: 212 | E36: 212 | F36: 212
A37: Pasta volume growth | B37: 0.03 | C37: 0.03 | D37: 0.025 | E37: 0.02 | F37: 0.02
A38: Pasta revenue-per-tonne growth | B38: 0.02 | C38: 0.01 | D38: 0.01 | E38: 0.01 | F38: 0.01
A39: Pasta gross profit per tonne (SAR/t) | B39: 520 | C39: 520 | D39: 520 | E39: 520 | F39: 520
A40: Nuts & spices revenue path (Mehbaj folded in, flagged) | B40: 730 | C40: 800 | D40: 848 | E40: 890 | F40: 926
A41: Nuts & spices gross margin path | B41: 0.265 | C41: 0.27 | D41: 0.27 | E41: 0.27 | F41: 0.27
A42: Oil operating cost / revenue (measured FY2025) | C42: 0.0556
A43: Sugar operating cost / revenue (measured FY2025) | C43: 0.016
A44: Pasta operating cost / revenue (measured FY2025) | C44: 0.079
...

Sheet SOTP Bridge
A1: Enterprise value to equity — the bridge
A2: Dec-2025 legs roll to the anchor at the cost of equity; the three anchor-dated legs (Kinan capitalized, Herfy NCI at market, Mehbaj) sit OUTSIDE the roll
A4: Step | B4: SAR mn | C4: Per share (SAR)
A5: Present value of the five forecast years | C5: =DCF!C33
A6: Present value of the terminal value | C6: =DCF!C32
A7: Enterprise value (operating) | C7: =C5+C6
A8: Government sukuk and other non-current investments | C8: =Assumptions!$C$119
A9: Current investments (T-bills, Almarai FVTPL) | C9: =Assumptions!$C$120
A10: Tiryaki sale-proceeds receivable (on the audited 31-Dec-2025 balance sheet; carved out of working capital) | C10: =Assumptions!$C$132
A11: Investment property (its inter-segment rent is OUTSIDE group EBITDA, so the asset belongs here) | C11: =Assumptions!$C$121
A12: Cash and cash equivalents | C12: =Assumptions!$C$113
A13: Less loans and borrowings | C13: =-Assumptions!$C$114
A14: Less lease liabilities | C14: =-Assumptions!$C$115
A15: Less employee benefits liabilities | C15: =-Assumptions!$C$116
A16: Less asset-restoration provision | C16: =-Assumptions!$C$117
A17: Less other net liabilities (tax/zakat accruals, deferred tax, net) | C17: =-Assumptions!$C$118
A18: Less other non-controlling interests at book | C18: =-(Assumptions!$C$124-Assumptions!$C$125)
A19: Dec-2025-dated legs, subtotal | C19: =SUM(C7:C18)
A20: x accretion to 18-Aug-2026 at the cost of equity (Dec legs only) | C20: =(1+DCF!C44)^(Assumptions!$C$10/365)
A21: Dec legs rolled to the anchor | C21: =C19*C20
A22: ANCHOR-DATED LEGS (held outside the roll)
A23: Kinan at capitalized earnings (annualized H1-2026 share / cost of equity — an H1-2026 run-rate value) | C23: =Assumptions!$C$82*2/DCF!C44
A24: Less Herfy's 51% NCI at Herfy's own settled 18-Aug-2026 price | C24: =-0.51*Assumptions!$C$122*Assumptions!$C$123
A25: Less Al Mehbaj consideration (Jul-2026 acquisition whose revenue the forecast carries) | C25: =-Assumptions!$C$133
A26: Equity value attributable to owners AT THE ANCHOR | C26: =C21+C23+C24+C25 | D26: =C26/Assumptions!$C$7-Assumptions!$C$11
A27: 31-Dec-2025-basis view (Dec legs unrolled; anchor legs at their own dates) | C27: =C19+C23+C24+C25 | D27: =C27/Assumptions!$C$7
A29: Terminal value as a share of enterprise value | C29: =DCF!C34
A30: Kinan alternatives: carrying value 435.5 (floor) · share of net assets 600.9 (disclosed) · capitalized earnings (used). First edition note superseded: the Tiryaki receivable IS on the 31-Dec-2025 balance sheet (notes 14/22) and now sits in the bridge; only its share settlement happened in H1-2026.

Sheet Segments
A1: Segments — the unit build; every margin is an output
A2: Volumes compound on their drivers; revenue = volume x price; gross profit = volume x GP/tonne; Panda = stores x sales per store
A4: Food Processing unit build | B4: 2026E | C4: 2027E | D4: 2028E | E4: 2029E | F4: 2030E
A5: Oil volume (k MT) | B5: =Assumptions!$C$16*(1+Assumptions!$B$31) | C5: =B5*(1+Assumptions!$C$31) | D5: =C5*(1+Assumptions!$D$31) | E5: =D5*(1+Assumptions!$E$31) | F5: =E5*(1+Assumptions!$F$31)
A6: Oil revenue per tonne (SAR/t) | B6: =Assumptions!$C$17/Assumptions!$C$16*1000*(1+Assumptions!$B$32) | C6: =B6*(1+Assumptions!$C$32) | D6: =C6*(1+Assumptions!$D$32) | E6: =D6*(1+Assumptions!$E$32) | F6: =E6*(1+Assumptions!$F$32)
A7: Oil revenue | B7: =B5*B6/1000 | C7: =C5*C6/1000 | D7: =D5*D6/1000 | E7: =E5*E6/1000 | F7: =F5*F6/1000
A8: Oil gross profit (= volume x GP/tonne) | B8: =B5*Assumptions!$B$33/1000 | C8: =C5*Assumptions!$C$33/1000 | D8: =D5*Assumptions!$D$33/1000 | E8: =E5*Assumptions!$E$33/1000 | F8: =F5*Assumptions!$F$33/1000
A9: Oil EBITDA (= GP − measured opex ratio x revenue) | B9: =B8-B7*Assumptions!$C$42 | C9: =C8-C7*Assumptions!$C$42 | D9: =D8-D7*Assumptions!$C$42 | E9: =E8-E7*Assumptions!$C$42 | F9: =F8-F7*Assumptions!$C$42
A10: Sugar volume (k MT) | B10: =Assumptions!$C$18*(1+Assumptions!$B$34) | C10: =B10*(1+Assumptions!$C$34) | D10: =C10*(1+Assumptions!$D$34) | E10: =D10*(1+Assumptions!$E$34) | F10: =E10*(1+Assumptions!$F$34)
A11: Sugar revenue per tonne (SAR/t) | B11: =Assumptions!$C$19/Assumptions!$C$18*1000*(1+Assumptions!$B$35) | C11: =B11*(1+Assumptions!$C$35) | D11: =C11*(1+Assumptions!$D$35) | E11: =D11*(1+Assumptions!$E$35) | F11: =E11*(1+Assumptions!$F$35)
A12: Sugar revenue | B12: =B10*B11/1000 | C12: =C10*C11/1000 | D12: =D10*D11/1000 | E12: =E10*E11/1000 | F12: =F10*F11/1000
A13: Sugar gross profit | B13: =B10*Assumptions!$B$36/1000 | C13: =C10*Assumptions!$C$36/1000 | D13: =D10*Assumptions!$D$36/1000 | E13: =E10*Assumptions!$E$36/1000 | F13: =F10*Assumptions!$F$36/1000
A14: Sugar EBITDA | B14: =B13-B12*Assumptions!$C$43 | C14: =C13-C12*Assumptions!$C$43 | D14: =D13-D12*Assumptions!$C$43 | E14: =E13-E12*Assumptions!$C$43 | F14: =F13-F12*Assumptions!$C$43
A15: Pasta volume (k MT) | B15: =Assumptions!$C$20*(1+Assumptions!$B$37) | C15: =B15*(1+Assumptions!$C$37) | D15: =C15*(1+Assumptions!$D$37) | E15: =D15*(1+Assumptions!$E$37) | F15: =E15*(1+Assumptions!$F$37)
A16: Pasta revenue per tonne (SAR/t) | B16: =Assumptions!$C$21/Assumptions!$C$20*1000*(1+Assumptions!$B$38) | C16: =B16*(1+Assumptions!$C$38) | D16: =C16*(1+Assumptions!$D$38) | E16: =D16*(1+Assumptions!$E$38) | F16: =E16*(1+Assumptions!$F$38)
A17: Pasta revenue | B17: =B15*B16/1000 | C17: =C15*C16/1000 | D17: =D15*D16/1000 | E17: =E15*E16/1000 | F17: =F15*F16/1000
A18: Pasta gross profit | B18: =B15*Assumptions!$B$39/1000 | C18: =C15*Assumptions!$C$39/1000 | D18: =D15*Assumptions!$D$39/1000 | E18: =E15*Assumptions!$E$39/1000 | F18: =F15*Assumptions!$F$39/1000
A19: Pasta EBITDA | B19: =B18-B17*Assumptions!$C$44 | C19: =C18-C17*Assumptions!$C$44 | D19: =D18-D17*Assumptions!$C$44 | E19: =E18-E17*Assumptions!$C$44 | F19: =F18-F17*Assumptions!$C$44
A20: Nuts & spices revenue (driver path) | B20: =Assumptions!$B$40 | C20: =Assumptions!$C$40 | D20: =Assumptions!$D$40 | E20: =Assumptions!$E$40 | F20: =Assumptions!$F$40
A21: Nuts & spices gross profit | B21: =B20*Assumptions!$B$41 | C21: =C20*Assumptions!$C$41 | D21: =D20*Assumptions!$D$41 | E21: =E20*Assumptions!$E$41 | F21: =F20*Assumptions!$F$41
A22: Nuts & spices EBITDA | B22: =B21-B20*Assumptions!$C$45 | C22: =C21-C20*Assumptions!$C$45 | D22: =D21-D20*Assumptions!$C$45 | E22: =E21-E20*Assumptions!$C$45 | F22: =F21-F20*Assumptions!$C$45
A23: Food Processing revenue | B23: =B7+B12+B17+B20 | C23: =C7+C12+C17+C20 | D23: =D7+D12+D17+D20 | E23: =E7+E12+E17+E20 | F23: =F7+F12+F17+F20
A24: Food Processing gross profit | B24: =B8+B13+B18+B21 | C24: =C8+C13+C18+C21 | D24: =D8+D13+D18+D21 | E24: =E8+E13+E18+E21 | F24: =F8+F13+F18+F21
A25: Food Processing EBITDA | B25: =B9+B14+B19+B22 | C25: =C9+C14+C19+C22 | D25: =D9+D14+D19+D22 | E25: =E9+E14+E19+E22 | F25: =F9+F14+F19+F22
A27: Panda (Retail) build | B27: 2026E | C27: 2027E | D27: 2028E | E27: 2029E | F27: 2030E
A28: Average stores in year | B28: =(Assumptions!$C$28+Assumptions!$B$48)/2 | C28: =(Assumptions!$B$48+Assumptions!$C$48)/2 | D28: =(Assumptions!$C$48+Assumptions!$D$48)/2 | E28: =(Assumptions!$D$48+Assumptions!$E$48)/2 | F28: =(Assumptions!$E$48+Assumptions!$F$48)/2
A29: Sales per average store (SAR mn) | B29: =Assumptions!$C$23/((Assumptions!$C$27+Assumptions!$C$28)/2)*(1+Assumptions!$B$49) | C29: =B29*(1+Assumptions!$C$49) | D29: =C29*(1+Assumptions!$D$49) | E29: =D29*(1+Assumptions!$E$49) | F29: =E29*(1+Assumptions!$F$49)
A30: Panda revenue (= stores x sales/store) | B30: =B28*B29 | C30: =C28*C29 | D30: =D28*D29 | E30: =E28*E29 | F30: =F28*F29
A31: Panda gross profit (margin held at the H1-2026 actual) | B31: =B30*Assumptions!$C$50 | C31: =C30*Assumptions!$C$50 | D31: =D30*Assumptions!$C$50 | E31: =E30*Assumptions!$C$50 | F31: =F30*Assumptions!$C$50
A32: Panda store-opex ratio (Framing A scale gains from FY2028) | B32: =Assumptions!$C$51 | C32: =Assumptions!$C$51 | D32: =Assumptions!$C$51-Assumptions!$C$52 | E32: =Assumptions!$C$51-2*Assumptions!$C$52 | F32: =Assumptions!$C$51-3*Assumptions!$C$52
A33: Panda EBITDA (an output) | B33: =B31-B30*B32 | C33: =C31-C30*C32 | D33: =D31-D30*D32 | E33: =E31-E30*E32 | F33: =F31-F30*F32
A35: Food Services, Frozen Food, eliminations, group | B35: 2026E | C35: 2027E | D35: 2028E | E35: 2029E | F35: 2030E
A36: Herfy revenue | B36: =Assumptions!$C$24*(1+Assumptions!$B$55) | C36: =B36*(1+Assumptions!$C$55) | D36: =C36*(1+Assumptions!$D$55) | E36: =D36*(1+Assumptions!$E$55) | F36: =E36*(1+Assumptions!$F$55)
A37: Herfy EBITDA | B37: =B36*Assumptions!$C$56 | C37: =C36*Assumptions!$C$56 | D37: =D36*Assumptions!$C$56 | E37: =E36*Assumptions!$C$56 | F37: =F36*Assumptions!$C$56
A38: Al Kabeer revenue | B38: =Assumptions!$C$25*(1+Assumptions!$B$57) | C38: =B38*(1+Assumptions!$C$57) | D38: =C38*(1+Assumptions!$D$57) | E38: =D38*(1+Assumptions!$E$57) | F38: =E38*(1+Assumptions!$F$57)
A39: Al Kabeer EBITDA | B39: =B38*Assumptions!$C$58 | C39: =C38*Assumptions!$C$58 | D39: =D38*Assumptions!$C$58 | E39: =E38*Assumptions!$C$58 | F39: =F38*Assumptions!$C$58
A40: Eliminations (proportional to Food Processing) | B40: =B23*Assumptions!$C$61 | C40: =C23*Assumptions!$C$61 | D40: =D23*Assumptions!$C$61 | E40: =E23*Assumptions!$C$61 | F40: =F23*Assumptions!$C$61
A41: Group revenue | B41: =B23+B30+B36+B38+B40+Assumptions!$C$26 | C41: =C23+C30+C36+C38+C40+Assumptions!$C$26 | D41: =D23+D30+D36+D38+D40+Assumptions!$C$26 | E41: =E23+E30+E36+E38+E40+Assumptions!$C$26 | F41: =F23+F30+F36+F38+F40+Assumptions!$C$26
A42: Unallocated corporate costs | B42: =-Assumptions!$B$62 | C42: =-Assumptions!$C$62 | D42: =-Assumptions!$D$62 | E42: =-Assumptions!$E$62 | F42: =-Assumptions!$F$62
A43: Group operating EBITDA (output) | B43: =B25+B33+B37+B39+B42 | C43: =C25+C33+C37+C39+C42 | D43: =D25+D33+D37+D39+D42 | E43: =E25+E33+E37+E39+E42 | F43: =F25+F33+F37+F39+F42
...

Sheet Relative & Normalized
A1: Relative, normalised and book lenses
A2: The peer-mix multiple is computed from quoted peers, discounted for the conglomerate/Egypt mix, and applied to model earnings
A4: PEER-MIX MULTIPLE
A5: Processing-leg P/E = median (NADEC, Wilmar) | C5: =MEDIAN(Assumptions!$C$141,Assumptions!$C$142)
A6: Retail-leg P/E = BinDawood (Al Othaim n/m after its 11-Aug-2026 H1 loss) | C6: =Assumptions!$C$140
A7: Processing-leg weight = FP EBITDA / (FP + Panda EBITDA), FY2026E — COMPUTED from the segment sheet | C7: =Segments!B25/(Segments!B25+Segments!B33)
A8: Mix-weighted peer P/E | C8: =C7*C5+(1-C7)*C6
A9: Applied multiple after the disclosed discount | C9: =C8*(1-Assumptions!$C$143)
A11: RELATIVE LENS — trailing multiple on TRAILING earnings
A12: Trailing recurring net income to 30-Jun-2026 = FY2025 recurring − H1-2025 recurring + H1-2026 recurring (all three company-disclosed) | C12: =Assumptions!$C$145-Assumptions!$C$147+Assumptions!$C$146
A13: Trailing recurring EPS (on the ex-treasury divisor) | C13: =C12/Assumptions!$C$7
A14: Relative lens value = applied multiple x trailing recurring EPS (anchor-dated by construction: the multiples are 18-Aug quotes) | C14: =C9*C13
A15: bear (30% discount) / bull (10% discount) | C15: =C8*0.7*C13 | D15: =C8*0.9*C13
A16: forward variant (the first edition's construction: applied multiple x FY2026E EPS — a trailing multiple on forward earnings imports the peers' growth twice; shown, not used) | C16: =C9*'Income Statement'!E17
A18: NORMALISED EARNINGS POWER
A19: FY2026E revenue (the trailing-multiple year; FY2027E under a trailing multiple would double-count growth) | C19: =Segments!B41
A20: Normalised EBITDA at the mid-cycle margin | C20: =C19*Assumptions!$C$144
A21: Normalised net profit (same D&A, finance, tax and minority frame) | C21: =(C20-'Income Statement'!E10+'Income Statement'!E12)*(1-Assumptions!$C$8)*(1-Assumptions!$C$81)+'Income Statement'!E14
A22: Normalised EPS | C22: =C21/Assumptions!$C$7
A23: Normalised lens value = applied multiple x normalised EPS | C23: =C9*C22 | E23: =C8*0.7*C22 | F23: =C8*0.9*C22
A25: BOOK VALUE AND SUSTAINABLE RETURN
A26: Book value per share (30-Jun-2026 reviewed equity, ex the 1.70 dividend paid) | C26: =Assumptions!$C$131/Assumptions!$C$7
A27: Sustainable return on equity = the model's OWN FY2026E attributable profit (recurring construction) / FY2025 opening equity — one FY2026 base across lenses | C27: ='Income Statement'!E16/Assumptions!$C$130
A28: Justified price-to-book = (ROE − g) / (Ke − g) | C28: =(C27-Assumptions!$C$110)/(DCF!C44-Assumptions!$C$110)
A29: Book lens value = justified P/B x book value per share | C29: =C28*C26 | E29: =MAX(C28-0.15,0.5)*C26 | F29: =(C28+0.15)*C26
A31: DIVIDEND-DISCOUNT CROSSWALK — the multiple our own cost of equity supports, computed three ways (none is typed; the study quotes the range)
A32: Two-stage (model earnings growth 5.8% for five years, then terminal growth) | C32: 8.3539254
A33: Gordon forward form = payout / (Ke − g) | C33: =Assumptions!$C$9/(DCF!C44-Assumptions!$C$110)
A34: Implied by Expert 2's dividend model (its value / FY2026E EPS) | C34: 7.8909095
A35: The market pays the peer set 16.2x against the 7.1x-8.4x this study's cost of equity supports. That gap (the price of capital) is why the DCF sits below the peer-anchored lenses; it is examined in the study rather than averaged away.

Sheet DCF
A1: DCF — the waterfall, the cost of capital built in-sheet, and the terminal
A2: NOPAT = EBIT x (1 − combined zakat/tax); lease replacement equals right-of-use depreciation; leases carry a debt weight
A4: SAR mn | B4: 2026E | C4: 2027E | D4: 2028E | E4: 2029E | F4: 2030E
A5: Revenue | B5: =Segments!B41 | C5: =Segments!C41 | D5: =Segments!D41 | E5: =Segments!E41 | F5: =Segments!F41
A6: EBITDA | B6: =Segments!B43 | C6: =Segments!C43 | D6: =Segments!D43 | E6: =Segments!E43 | F6: =Segments!F43
A7: EBITDA margin | B7: =B6/B5 | C7: =C6/C5 | D7: =D6/D5 | E7: =E6/E5 | F7: =F6/F5
A8: Less depreciation and amortisation | B8: =-'Income Statement'!E10 | C8: =-'Income Statement'!F10 | D8: =-'Income Statement'!G10 | E8: =-'Income Statement'!H10 | F8: =-'Income Statement'!I10
A9: EBIT | B9: =B6+B8 | C9: =C6+C8 | D9: =D6+D8 | E9: =E6+E8 | F9: =F6+F8
A10: NOPAT = EBIT x (1 − combined zakat/tax rate) | B10: =B9*(1-Assumptions!$C$8) | C10: =C9*(1-Assumptions!$C$8) | D10: =D9*(1-Assumptions!$C$8) | E10: =E9*(1-Assumptions!$C$8) | F10: =F9*(1-Assumptions!$C$8)
A11: Add back depreciation and amortisation | B11: =-B8 | C11: =-C8 | D11: =-D8 | E11: =-E8 | F11: =-F8
A12: Less capital expenditure | B12: =-Assumptions!$B$65 | C12: =-Assumptions!$C$65 | D12: =-Assumptions!$D$65 | E12: =-Assumptions!$E$65 | F12: =-Assumptions!$F$65
A13: Less lease renewals (= right-of-use depreciation) | B13: =-'Cash Flow'!B19 | C13: =-'Cash Flow'!C19 | D13: =-'Cash Flow'!D19 | E13: =-'Cash Flow'!E19 | F13: =-'Cash Flow'!F19
A14: Less lease-book growth (new-store leases; full additions charged) | B14: =-('Balance Sheet'!E24-Assumptions!$C$115) | C14: =-('Balance Sheet'!F24-'Balance Sheet'!E24) | D14: =-('Balance Sheet'!G24-'Balance Sheet'!F24) | E14: =-('Balance Sheet'!H24-'Balance Sheet'!G24) | F14: =-('Balance Sheet'!I24-'Balance Sheet'!H24)
A15: Less increase in net working capital | B15: ='Cash Flow'!B7 | C15: ='Cash Flow'!C7 | D15: ='Cash Flow'!D7 | E15: ='Cash Flow'!E7 | F15: ='Cash Flow'!F7
A16: Free cash flow to the firm | B16: =B10+B11+B12+B13+B14+B15 | C16: =C10+C11+C12+C13+C14+C15 | D16: =D10+D11+D12+D13+D14+D15 | E16: =E10+E11+E12+E13+E14+E15 | F16: =F10+F11+F12+F13+F14+F15
A17: Discount factor (compounding at the explicit cost of capital) | B17: =1/(1+$C$52) | C17: =B17/(1+$C$52) | D17: =C17/(1+$C$52) | E17: =D17/(1+$C$52) | F17: =E17/(1+$C$52)
A18: Present value of free cash flow | B18: =B16*B17 | C18: =C16*C17 | D18: =D16*D17 | E18: =E16*E17 | F18: =F16*F17
A20: TERMINAL BLOCK
A21: Terminal REAL growth (stated) | C21: =Assumptions!$C$104
A22: Terminal inflation — Saudi house macro path | C22: =Assumptions!$C$105
A23: Terminal growth = (1+inflation)(1+real growth) − 1 | C23: =(1+C22)*(1+C21)-1
A24: Year-five operating profit after tax (the perpetuity grows it once) | C24: =F10
A25: Plus owned and intangible depreciation (the right-of-use charge cancels out of this model's own free cash flow and is not added back here) | C25: =740.0006883973025
A26: Less capital maintenance at replacement cost — that charge escalated over half the derived asset life | C26: =-C25*(1+C22)^(Assumptions!$C$106/2)
A27: Less capital for real growth (real growth x capital per unit of growth) | C27: =-C21*Assumptions!$C$108
A28: Less inflation on the working capital and lease book the group carries | C28: =-C22*5687.100743
A29: Terminal free cash flow | C29: =SUM(C24:C28)
A30: Terminal value at end of year five | C30: =C29*(1+C23)/($C$58-C23)
A31: Memo — the no-growth perpetuity at book depreciation (a diagnostic, not a bound) | C31: =C24/$C$58
A32: Present value of the terminal value | C32: =C30*F17
A33: Present value of the five explicit years | C33: =SUM(B18:F18)
A34: Terminal value share of enterprise value | C34: =C32/C35
A35: Enterprise value (operating) | C35: =C33+C32
A37: Downside variant — the asset life read at twice the directly measured average age (engine re-run, published beside the base, never averaged) | C37: 21.816341
A38: COST OF CAPITAL — BUILT, NOT PASTED (v2: rf net of the sovereign spread; both ERP bases shown)
A39: Observed 10Y SAR sovereign yield (FTSE SAGBI 7-10y) | C39: =Assumptions!$C$88
A40: Less sovereign default spread (rating basis) | C40: =-Assumptions!$C$89
A41: Normalized risk-free rate rf* | C41: =C39+C40
A42: Beta (own stock vs TASI, five-year weekly) | C42: =Assumptions!$C$93
A43: Equity risk premium (rating basis) | C43: =Assumptions!$C$90
...

Sheet Income Statement
A1: Income statement — three audited years and the five-year forecast
A2: FY2023 is the continuing basis of the FY2024 statements and still includes Turkiye (disposed 2025); FY2024-25 are the FY2025 audited basis (ex-Turkiye)
A4: SAR mn | B4: FY2023 | C4: FY2024 | D4: FY2025 | E4: 2026E | F4: 2027E | G4: 2028E | H4: 2029E | I4: 2030E
A5: Revenues | B5: 24149.521 | C5: 23045.574 | D5: 26081.053 | E5: =Segments!B41 | F5: =Segments!C41 | G5: =Segments!D41 | H5: =Segments!E41 | I5: =Segments!F41
A6: Cost of revenues (audited; forecast modelled at category level) | B6: -19103.682 | C6: -18212.904 | D6: -20992.159
A7: Gross profit (audited columns) | B7: =B5+B6 | C7: =C5+C6 | D7: =D5+D6
A8: Operating costs before D&A (selling, admin, net other; forecast = revenue less EBITDA) | B8: -3808.82 | C8: -3870.832 | D8: -3927.981 | E8: =-(E5-E9) | F8: =-(F5-F9) | G8: =-(G5-G9) | H8: =-(H5-H9) | I8: =-(I5-I9)
A9: Operating EBITDA (before associates and impairments) | B9: =B7+B8+B10 | C9: =C7+C8+C10 | D9: =D7+D8+D10 | E9: =Segments!B43 | F9: =Segments!C43 | G9: =Segments!D43 | H9: =Segments!E43 | I9: =Segments!F43
A10: Depreciation and amortisation | B10: 1064.59 | C10: 1099.866 | D10: 1190.022 | E10: ='Balance Sheet'!D5*Assumptions!$C$66+Assumptions!$C$67+'Cash Flow'!B19 | F10: ='Balance Sheet'!E5*Assumptions!$C$66+Assumptions!$C$67+'Cash Flow'!C19 | G10: ='Balance Sheet'!F5*Assumptions!$C$66+Assumptions!$C$67+'Cash Flow'!D19 | H10: ='Balance Sheet'!G5*Assumptions!$C$66+Assumptions!$C$67+'Cash Flow'!E19 | I10: ='Balance Sheet'!H5*Assumptions!$C$66+Assumptions!$C$67+'Cash Flow'!F19
A11: EBIT | B11: =B9-B10 | C11: =C9-C10 | D11: =D9-D10 | E11: =E9-E10 | F11: =F9-F10 | G11: =G9-G10 | H11: =H9-H10 | I11: =I9-I10
A12: Net finance cost (on prior-year net debt and lease book) | D12: -275.525 | E12: =MAX('Balance Sheet'!D31,0)*-DCF!$C$45-'Balance Sheet'!D24*Assumptions!$C$70+MAX(-'Balance Sheet'!D31,0)*Assumptions!$C$85 | F12: =MAX('Balance Sheet'!E31,0)*-DCF!$C$45-'Balance Sheet'!E24*Assumptions!$C$70+MAX(-'Balance Sheet'!E31,0)*Assumptions!$C$85 | G12: =MAX('Balance Sheet'!F31,0)*-DCF!$C$45-'Balance Sheet'!F24*Assumptions!$C$70+MAX(-'Balance Sheet'!F31,0)*Assumptions!$C$85 | H12: =MAX('Balance Sheet'!G31,0)*-DCF!$C$45-'Balance Sheet'!G24*Assumptions!$C$70+MAX(-'Balance Sheet'!G31,0)*Assumptions!$C$85 | I12: =MAX('Balance Sheet'!H31,0)*-DCF!$C$45-'Balance Sheet'!H24*Assumptions!$C$70+MAX(-'Balance Sheet'!H31,0)*Assumptions!$C$85
A13: Core profit after zakat and tax (= (EBIT + net finance) x (1 − rate)) | E13: =(E11+E12)*(1-Assumptions!$C$8) | F13: =(F11+F12)*(1-Assumptions!$C$8) | G13: =(G11+G12)*(1-Assumptions!$C$8) | H13: =(H11+H12)*(1-Assumptions!$C$8) | I13: =(I11+I12)*(1-Assumptions!$C$8)
A14: Share of results of Kinan (net of zakat and tax) | D14: 51.775 | E14: =Assumptions!$C$82*2*(1+Assumptions!$C$83)^0 | F14: =Assumptions!$C$82*2*(1+Assumptions!$C$83)^1 | G14: =Assumptions!$C$82*2*(1+Assumptions!$C$83)^2 | H14: =Assumptions!$C$82*2*(1+Assumptions!$C$83)^3 | I14: =Assumptions!$C$82*2*(1+Assumptions!$C$83)^4
A15: Profit attributable to non-controlling interests | D15: -66.037 | E15: =E13*Assumptions!$C$81 | F15: =F13*Assumptions!$C$81 | G15: =G13*Assumptions!$C$81 | H15: =H13*Assumptions!$C$81 | I15: =I13*Assumptions!$C$81
A16: Profit attributable to owners | B16: 899.185 | C16: 9974.266 | D16: 874.462 | E16: =E13*(1-Assumptions!$C$81)+E14 | F16: =F13*(1-Assumptions!$C$81)+F14 | G16: =G13*(1-Assumptions!$C$81)+G14 | H16: =H13*(1-Assumptions!$C$81)+H14 | I16: =I13*(1-Assumptions!$C$81)+I14
A17: Earnings per share (SAR) | D17: 2.93 | E17: =E16/Assumptions!$C$7 | F17: =F16/Assumptions!$C$7 | G17: =G16/Assumptions!$C$7 | H17: =H16/Assumptions!$C$7 | I17: =I16/Assumptions!$C$7
A18: FY2024 attributable profit includes the SAR 11,554.7mn Almarai distribution gain (audited FY2024 statements, segment note). FY2025 recurring net profit is 539.1 per the company's own bridge, whose items are a 300.0 zakat-and-other-accrual reversal, a 32.3 Turkiye gain and a 40.2 put-option gain (the audited FS note 29 zakat credit is 217.4; the announcement quotes 247.3 gross of related expenses — three disclosed figures on three bases). The forecast is the recurring construction.

Sheet Balance Sheet
A1: Balance sheet — audited FY2025 and the forecast roll-forward
A2: The sheet FOOTS: the check row at the bottom is assets less liabilities less equity and evaluates to zero in every year
A4: SAR mn | D4: FY2025 | E4: 2026E | F4: 2027E | G4: 2028E | H4: 2029E | I4: 2030E
A5: Property, plant and equipment (opening + capex − depreciation) | D5: =Assumptions!$C$126 | E5: =D5+Assumptions!$B$65-Assumptions!$C$67-'Balance Sheet'!D5*Assumptions!$C$66 | F5: =E5+Assumptions!$C$65-Assumptions!$C$67-E5*Assumptions!$C$66 | G5: =F5+Assumptions!$D$65-Assumptions!$C$67-F5*Assumptions!$C$66 | H5: =G5+Assumptions!$E$65-Assumptions!$C$67-G5*Assumptions!$C$66 | I5: =H5+Assumptions!$F$65-Assumptions!$C$67-H5*Assumptions!$C$66
A6: Right-of-use assets (grow with the lease book) | D6: =Assumptions!$C$127 | E6: =D6+Assumptions!$C$115*Assumptions!$B$69 | F6: =E6+'Balance Sheet'!E24*Assumptions!$C$69 | G6: =F6+'Balance Sheet'!F24*Assumptions!$D$69 | H6: =G6+'Balance Sheet'!G24*Assumptions!$E$69 | I6: =H6+'Balance Sheet'!H24*Assumptions!$F$69
A7: Intangible assets and goodwill (held: capex = amortisation) | D7: =Assumptions!$C$128 | E7: =Assumptions!$C$128 | F7: =Assumptions!$C$128 | G7: =Assumptions!$C$128 | H7: =Assumptions!$C$128 | I7: =Assumptions!$C$128
A8: Investment property (held) | D8: =Assumptions!$C$121 | E8: =Assumptions!$C$121 | F8: =Assumptions!$C$121 | G8: =Assumptions!$C$121 | H8: =Assumptions!$C$121 | I8: =Assumptions!$C$121
A9: Kinan (equity method: + share of results − dividends) | D9: =Assumptions!$C$129 | E9: =D9+'Income Statement'!E14-Assumptions!$C$84*(1+Assumptions!$C$83)^0 | F9: =E9+'Income Statement'!F14-Assumptions!$C$84*(1+Assumptions!$C$83)^1 | G9: =F9+'Income Statement'!G14-Assumptions!$C$84*(1+Assumptions!$C$83)^2 | H9: =G9+'Income Statement'!H14-Assumptions!$C$84*(1+Assumptions!$C$83)^3 | I9: =H9+'Income Statement'!I14-Assumptions!$C$84*(1+Assumptions!$C$83)^4
A10: Non-current investments (held) | D10: =Assumptions!$C$119 | E10: =Assumptions!$C$119 | F10: =Assumptions!$C$119 | G10: =Assumptions!$C$119 | H10: =Assumptions!$C$119 | I10: =Assumptions!$C$119
A11: Current investments (held) | D11: =Assumptions!$C$120 | E11: =Assumptions!$C$120 | F11: =Assumptions!$C$120 | G11: =Assumptions!$C$120 | H11: =Assumptions!$C$120 | I11: =Assumptions!$C$120
A12: Tiryaki stake (the 274.6 sale-proceeds receivable reclassified from working capital; settled in shares H1-2026) | D12: =Assumptions!$C$132 | E12: =Assumptions!$C$132 | F12: =Assumptions!$C$132 | G12: =Assumptions!$C$132 | H12: =Assumptions!$C$132 | I12: =Assumptions!$C$132
A13: Cost of revenues ratio (measured FY2025, drives inventory and payables) | D13: =1-Assumptions!$C$15/Assumptions!$C$14
A14: Inventories (days on cost of revenues) | D14: 4680.559 | E14: =Segments!B41*'Balance Sheet'!$D$13*Assumptions!$C$73/365 | F14: =Segments!C41*'Balance Sheet'!$D$13*Assumptions!$C$73/365 | G14: =Segments!D41*'Balance Sheet'!$D$13*Assumptions!$C$73/365 | H14: =Segments!E41*'Balance Sheet'!$D$13*Assumptions!$C$73/365 | I14: =Segments!F41*'Balance Sheet'!$D$13*Assumptions!$C$73/365
A15: Trade receivables (days on revenue) | D15: 1856.697 | E15: =Segments!B41*Assumptions!$C$74/365 | F15: =Segments!C41*Assumptions!$C$74/365 | G15: =Segments!D41*Assumptions!$C$74/365 | H15: =Segments!E41*Assumptions!$C$74/365 | I15: =Segments!F41*Assumptions!$C$74/365
A16: Prepayments and other receivables, EX the Tiryaki receivable (audited 1,346.5 less 274.6; % of revenue in the forecast) | D16: 1071.885 | E16: =Segments!B41*Assumptions!$C$76 | F16: =Segments!C41*Assumptions!$C$76 | G16: =Segments!D41*Assumptions!$C$76 | H16: =Segments!E41*Assumptions!$C$76 | I16: =Segments!F41*Assumptions!$C$76
A17: Trade payables (days on cost of revenues) | D17: -3915.807 | E17: =-Segments!B41*'Balance Sheet'!$D$13*Assumptions!$C$75/365 | F17: =-Segments!C41*'Balance Sheet'!$D$13*Assumptions!$C$75/365 | G17: =-Segments!D41*'Balance Sheet'!$D$13*Assumptions!$C$75/365 | H17: =-Segments!E41*'Balance Sheet'!$D$13*Assumptions!$C$75/365 | I17: =-Segments!F41*'Balance Sheet'!$D$13*Assumptions!$C$75/365
A18: Accrued and other liabilities (% of revenue) | D18: -2829.405 | E18: =-Segments!B41*Assumptions!$C$77 | F18: =-Segments!C41*Assumptions!$C$77 | G18: =-Segments!D41*Assumptions!$C$77 | H18: =-Segments!E41*Assumptions!$C$77 | I18: =-Segments!F41*Assumptions!$C$77
A19: Contract liabilities (% of revenue) | D19: -151.99 | E19: =-Segments!B41*Assumptions!$C$78 | F19: =-Segments!C41*Assumptions!$C$78 | G19: =-Segments!D41*Assumptions!$C$78 | H19: =-Segments!E41*Assumptions!$C$78 | I19: =-Segments!F41*Assumptions!$C$78
A20: Net working capital | D20: 711.939 | E20: =SUM(E14:E19) | F20: =SUM(F14:F19) | G20: =SUM(G14:G19) | H20: =SUM(H14:H19) | I20: =SUM(I14:I19)
A21: Cash and cash equivalents (from the cash-flow walk) | D21: =Assumptions!$C$113 | E21: ='Cash Flow'!B17 | F21: ='Cash Flow'!C17 | G21: ='Cash Flow'!D17 | H21: ='Cash Flow'!E17 | I21: ='Cash Flow'!F17
A22: Total assets (condensed) | E22: =E5+E6+E7+E8+E9+E10+E11+E12+E20+E21 | F22: =F5+F6+F7+F8+F9+F10+F11+F12+F20+F21 | G22: =G5+G6+G7+G8+G9+G10+G11+G12+G20+G21 | H22: =H5+H6+H7+H8+H9+H10+H11+H12+H20+H21 | I22: =I5+I6+I7+I8+I9+I10+I11+I12+I20+I21
A23: Loans and borrowings (held at the FY2025 level) | D23: =Assumptions!$C$114 | E23: =Assumptions!$C$114 | F23: =Assumptions!$C$114 | G23: =Assumptions!$C$114 | H23: =Assumptions!$C$114 | I23: =Assumptions!$C$114
A24: Lease liabilities (grow with the store network) | D24: =Assumptions!$C$115 | E24: =Assumptions!$C$115*(1+Assumptions!$B$69) | F24: =E24*(1+Assumptions!$C$69) | G24: =F24*(1+Assumptions!$D$69) | H24: =G24*(1+Assumptions!$E$69) | I24: =H24*(1+Assumptions!$F$69)
A25: Employee benefits liabilities (held) | D25: =Assumptions!$C$116 | E25: =Assumptions!$C$116 | F25: =Assumptions!$C$116 | G25: =Assumptions!$C$116 | H25: =Assumptions!$C$116 | I25: =Assumptions!$C$116
A26: Asset-restoration provision (held) | D26: =Assumptions!$C$117 | E26: =Assumptions!$C$117 | F26: =Assumptions!$C$117 | G26: =Assumptions!$C$117 | H26: =Assumptions!$C$117 | I26: =Assumptions!$C$117
A27: Other net liabilities (tax/zakat accruals + DTL − DTA − other, held) | D27: =Assumptions!$C$118 | E27: =Assumptions!$C$118 | F27: =Assumptions!$C$118 | G27: =Assumptions!$C$118 | H27: =Assumptions!$C$118 | I27: =Assumptions!$C$118
A28: Equity attributable to owners (+ profit − dividends) | D28: =Assumptions!$C$130 | E28: =D28+'Income Statement'!E16-'Cash Flow'!B13*-1 | F28: =E28+'Income Statement'!F16-'Cash Flow'!C13*-1 | G28: =F28+'Income Statement'!G16-'Cash Flow'!D13*-1 | H28: =G28+'Income Statement'!H16-'Cash Flow'!E13*-1 | I28: =H28+'Income Statement'!I16-'Cash Flow'!F13*-1
A29: Non-controlling interests (+ NCI profit − NCI dividends) | D29: =Assumptions!$C$124 | E29: =D29+'Income Statement'!E15-'Cash Flow'!B14*-1 | F29: =E29+'Income Statement'!F15-'Cash Flow'!C14*-1 | G29: =F29+'Income Statement'!G15-'Cash Flow'!D14*-1 | H29: =G29+'Income Statement'!H15-'Cash Flow'!E14*-1 | I29: =H29+'Income Statement'!I15-'Cash Flow'!F14*-1
A30: FOOT CHECK: assets − liabilities − equity (must be zero) | E30: =E22-E23-E24-E25-E26-E27-E28-E29 | F30: =F22-F23-F24-F25-F26-F27-F28-F29 | G30: =G22-G23-G24-G25-G26-G27-G28-G29 | H30: =H22-H23-H24-H25-H26-H27-H28-H29 | I30: =I22-I23-I24-I25-I26-I27-I28-I29
A31: Net debt (loans − cash − current investments; company definition) | D31: =Assumptions!$C$114-Assumptions!$C$113-Assumptions!$C$120 | E31: =E23-E21-E11 | F31: =F23-F21-F11 | G31: =G23-G21-G11 | H31: =H23-H21-H11 | I31: =I23-I21-I11

Sheet Cash Flow
A1: Cash flow — the walk that closes the balance sheet
A2: Lease principal equals right-of-use depreciation; new store leases are non-cash additions
A4: SAR mn | B4: 2026E | C4: 2027E | D4: 2028E | E4: 2029E | F4: 2030E
A5: Core profit after zakat and tax | B5: ='Income Statement'!E13 | C5: ='Income Statement'!F13 | D5: ='Income Statement'!G13 | E5: ='Income Statement'!H13 | F5: ='Income Statement'!I13
A6: Add back depreciation and amortisation | B6: ='Income Statement'!E10 | C6: ='Income Statement'!F10 | D6: ='Income Statement'!G10 | E6: ='Income Statement'!H10 | F6: ='Income Statement'!I10
A7: Working-capital investment (increase is an outflow) | B7: =-('Balance Sheet'!E20-'Balance Sheet'!D20) | C7: =-('Balance Sheet'!F20-'Balance Sheet'!E20) | D7: =-('Balance Sheet'!G20-'Balance Sheet'!F20) | E7: =-('Balance Sheet'!H20-'Balance Sheet'!G20) | F7: =-('Balance Sheet'!I20-'Balance Sheet'!H20)
A8: Dividend received from Kinan | B8: =Assumptions!$C$84*(1+Assumptions!$C$83)^0 | C8: =Assumptions!$C$84*(1+Assumptions!$C$83)^1 | D8: =Assumptions!$C$84*(1+Assumptions!$C$83)^2 | E8: =Assumptions!$C$84*(1+Assumptions!$C$83)^3 | F8: =Assumptions!$C$84*(1+Assumptions!$C$83)^4
A9: Net cash from operating activities | B9: =B5+B6+B7+B8 | C9: =C5+C6+C7+C8 | D9: =D5+D6+D7+D8 | E9: =E5+E6+E7+E8 | F9: =F5+F6+F7+F8
A10: Capital expenditure (property, plant, equipment and intangibles) | B10: =-Assumptions!$B$65 | C10: =-Assumptions!$C$65 | D10: =-Assumptions!$D$65 | E10: =-Assumptions!$E$65 | F10: =-Assumptions!$F$65
A11: Net cash used in investing activities | B11: =B10 | C11: =C10 | D11: =D10 | E11: =E10 | F11: =F10
A12: Payment of lease liabilities — principal (= right-of-use depreciation) | B12: =-'Cash Flow'!B19 | C12: =-'Cash Flow'!C19 | D12: =-'Cash Flow'!D19 | E12: =-'Cash Flow'!E19 | F12: =-'Cash Flow'!F19
A13: Dividends paid to owners (policy payout on the current year's profit) | B13: =-'Income Statement'!E16*Assumptions!$C$9 | C13: =-'Income Statement'!F16*Assumptions!$C$9 | D13: =-'Income Statement'!G16*Assumptions!$C$9 | E13: =-'Income Statement'!H16*Assumptions!$C$9 | F13: =-'Income Statement'!I16*Assumptions!$C$9
A14: Dividends paid to non-controlling interests | B14: =-'Income Statement'!E15*Assumptions!$C$9 | C14: =-'Income Statement'!F15*Assumptions!$C$9 | D14: =-'Income Statement'!G15*Assumptions!$C$9 | E14: =-'Income Statement'!H15*Assumptions!$C$9 | F14: =-'Income Statement'!I15*Assumptions!$C$9
A15: Net cash used in financing activities | B15: =B12+B13+B14 | C15: =C12+C13+C14 | D15: =D12+D13+D14 | E15: =E12+E13+E14 | F15: =F12+F13+F14
A16: Net change in cash | B16: =B9+B11+B15 | C16: =C9+C11+C15 | D16: =D9+D11+D15 | E16: =E9+E11+E15 | F16: =F9+F11+F15
A17: Cash and cash equivalents at year end | B17: =Assumptions!$C$113+B16 | C17: =B17+C16 | D17: =C17+D16 | E17: =D17+E16 | F17: =E17+F16
A19: Memo: right-of-use depreciation (grows with the store network) | B19: =Assumptions!$C$68*(1+Assumptions!$B$69) | C19: =B19*(1+Assumptions!$C$69) | D19: =C19*(1+Assumptions!$D$69) | E19: =D19*(1+Assumptions!$E$69) | F19: =E19*(1+Assumptions!$F$69)
A20: The dividend row applies the stated 50-60% policy (midpoint) to the current year's attributable profit; Savola's actual FY2025 dividend of SAR 510mn was paid during H1-2026.

Sheet Summary Financials
A1: Summary financials and returns
A4: SAR mn | B4: FY2025 | C4: 2026E | D4: 2027E | E4: 2028E | F4: 2029E | G4: 2030E
A5: Revenue | B5: 26081.053 | C5: ='Income Statement'!E5 | D5: ='Income Statement'!F5 | E5: ='Income Statement'!G5 | F5: ='Income Statement'!H5 | G5: ='Income Statement'!I5
A6: Operating EBITDA | B6: 2350.935 | C6: ='Income Statement'!E9 | D6: ='Income Statement'!F9 | E6: ='Income Statement'!G9 | F6: ='Income Statement'!H9 | G6: ='Income Statement'!I9
A7: EBITDA margin | B7: 0.090139574 | C7: =C6/C5 | D7: =D6/D5 | E7: =E6/E5 | F7: =F6/F5 | G7: =G6/G5
A8: Profit attributable to owners | B8: 874.462 | C8: ='Income Statement'!E16 | D8: ='Income Statement'!F16 | E8: ='Income Statement'!G16 | F8: ='Income Statement'!H16 | G8: ='Income Statement'!I16
A9: EPS (SAR) | B9: 2.93 | C9: ='Income Statement'!E17 | D9: ='Income Statement'!F17 | E9: ='Income Statement'!G17 | F9: ='Income Statement'!H17 | G9: ='Income Statement'!I17
A10: Capital expenditure | B10: 858.5 | C10: =Assumptions!$B$65 | D10: =Assumptions!$C$65 | E10: =Assumptions!$D$65 | F10: =Assumptions!$E$65 | G10: =Assumptions!$F$65
A11: Free cash flow to the firm | C11: =DCF!B16 | D11: =DCF!C16 | E11: =DCF!D16 | F11: =DCF!E16 | G11: =DCF!F16
A12: Net debt (company definition) | B12: 903.985 | C12: ='Balance Sheet'!E31 | D12: ='Balance Sheet'!F31 | E12: ='Balance Sheet'!G31 | F12: ='Balance Sheet'!H31 | G12: ='Balance Sheet'!I31
A13: Equity attributable to owners | B13: 5516.027 | C13: ='Balance Sheet'!E28 | D13: ='Balance Sheet'!F28 | E13: ='Balance Sheet'!G28 | F13: ='Balance Sheet'!H28 | G13: ='Balance Sheet'!I28
A15: Operating invested capital (equity + minorities + debt + leases − cash − investments − Kinan − Tiryaki − investment property; the terminal return runs on this row) | C15: ='Balance Sheet'!E28+'Balance Sheet'!E29+Assumptions!$C$114+'Balance Sheet'!E24-'Balance Sheet'!E21-Assumptions!$C$120-Assumptions!$C$119-'Balance Sheet'!E9-Assumptions!$C$132-Assumptions!$C$121 | D15: ='Balance Sheet'!F28+'Balance Sheet'!F29+Assumptions!$C$114+'Balance Sheet'!F24-'Balance Sheet'!F21-Assumptions!$C$120-Assumptions!$C$119-'Balance Sheet'!F9-Assumptions!$C$132-Assumptions!$C$121 | E15: ='Balance Sheet'!G28+'Balance Sheet'!G29+Assumptions!$C$114+'Balance Sheet'!G24-'Balance Sheet'!G21-Assumptions!$C$120-Assumptions!$C$119-'Balance Sheet'!G9-Assumptions!$C$132-Assumptions!$C$121 | F15: ='Balance Sheet'!H28+'Balance Sheet'!H29+Assumptions!$C$114+'Balance Sheet'!H24-'Balance Sheet'!H21-Assumptions!$C$120-Assumptions!$C$119-'Balance Sheet'!H9-Assumptions!$C$132-Assumptions!$C$121 | G15: ='Balance Sheet'!I28+'Balance Sheet'!I29+Assumptions!$C$114+'Balance Sheet'!I24-'Balance Sheet'!I21-Assumptions!$C$120-Assumptions!$C$119-'Balance Sheet'!I9-Assumptions!$C$132-Assumptions!$C$121
A16: Return on invested capital (NOPAT / opening invested capital) | C16: =DCF!B10/(Assumptions!$C$130+Assumptions!$C$124+Assumptions!$C$114+Assumptions!$C$115-Assumptions!$C$113-Assumptions!$C$120-Assumptions!$C$119-Assumptions!$C$129-Assumptions!$C$132-Assumptions!$C$121) | D16: =DCF!C10/C15 | E16: =DCF!D10/D15 | F16: =DCF!E10/E15 | G16: =DCF!F10/F15
A17: Return on equity (attributable profit / opening equity) | C17: ='Income Statement'!E16/Assumptions!$C$130 | D17: ='Income Statement'!F16/'Balance Sheet'!E28 | E17: ='Income Statement'!G16/'Balance Sheet'!F28 | F17: ='Income Statement'!H16/'Balance Sheet'!G28 | G17: ='Income Statement'!I16/'Balance Sheet'!H28

Sheet Monte Carlo
A1: Monte Carlo price map — engine output (pasted by construction)
A2: Each figure is a 50,000-path simulation of the whole price process; the grid does not redraw when a driver changes
A4: Anchor: SAR 25.40 (settled close) on 2026-08-18 · annualized volatility ~30% · 50,000 simulated paths on a fixed seed (42), carry-anchored heavy-tailed process
A6: Horizon | B6: p5 | C6: p25 | D6: p50 | E6: p75 | F6: p95 | G6: P(above spot)
A7: One month (to 2026-09-20) | B7: 21.873551 | C7: 24.017467 | D7: 25.474168 | E7: 27.044477 | F7: 29.721402 | G7: 0.51302
A8: Three months (to 2026-11-18) | B8: 19.762378 | C8: 23.19101 | D8: 25.683865 | E8: 28.416887 | F8: 33.354301 | G8: 0.52964
A10: Touch probability within 3M | B10: +5% | C10: +10% | D10: +15% | E10: −5% | F10: −10% | G10: −15%
A11: Probability the level trades at least once | B11: 0.71174 | C11: 0.5072 | D11: 0.34442 | E11: 0.65962 | F11: 0.41738 | G11: 0.2407
A13: Backtest of the same price engine on Savola (plain language):
A14: Over the last five years (2021-10-26 to 2026-04-28), 19 non-overlapping three-month forecasts scored +0.9% against a carry-anchored random walk.
A15: Realized outcomes fell inside the 50/80/90% bands 53%/79%/84% of the time; the forecast percentiles were roughly uniform (chi-square p = 0.28, KS p = 0.64).
A16: Across the full cleaned history (58 windows) the score was +0.4%; the engine is statistically indistinguishable from the benchmark on this name — the map is honest about dispersion, not a source of edge.

Sheet Sensitivity
A1: Sensitivity — engine re-runs (pasted by construction)
A2: Each cell is a complete revaluation of the whole model; the grids do not redraw when a driver changes
A4: Fair value per share at the anchor: cost of capital x terminal growth
A5: WACC \ g | B5: 1.7% | C5: 2.2% | D5: 2.7% | E5: 3.2% | F5: 3.7%
A6: 7.06% | B6: 30.316577 | C6: 31.716309 | D6: 33.382996 | E6: 35.411872 | F6: 37.949587
A7: 7.56% | B7: 25.940202 | C7: 26.900569 | D7: 28.018462 | E7: 29.344108 | F7: 30.951622
A8: 8.06% | B8: 22.221165 | C8: 22.864321 | D8: 23.596156 | E8: 24.44223 | F8: 25.438963
A9: 8.56% | B9: 19.022494 | C9: 19.433099 | D9: 19.888261 | E9: 20.399698 | F9: 20.983628
A10: 9.06% | B10: 16.242778 | C10: 16.480868 | D10: 16.734917 | E10: 17.008784 | F10: 17.307679
A12: Beta (the 90% confidence interval of the measured beta spans 0.73-1.44)
A13: Beta | B13: Fair value (SAR)
A14: 0.73 | B14: 34.964857
A15: 0.9 | B15: 28.931491
A16: 1 | B16: 25.93572
A17: 1.087 | B17: 23.596156
A18: 1.2 | B18: 20.869474
A19: 1.44 | B19: 16.007682
A21: Risk-free construction
A22: 10Y SAR level | B22: Fair value (SAR)
A23: 5.02% | B23: 26.340361
A24: 5.52% (base) | B24: 23.596156
A25: 6.02% | B25: 21.139026

Sheet Per-Share & Ratios
A1: Per-share figures, ratios and operating KPIs
A4: Per share (SAR) | B4: 2026E | C4: 2027E | D4: 2028E | E4: 2029E | F4: 2030E
A5: EPS | B5: ='Income Statement'!E17 | C5: ='Income Statement'!F17 | D5: ='Income Statement'!G17 | E5: ='Income Statement'!H17 | F5: ='Income Statement'!I17
A6: Dividend per share (policy payout) | B6: ='Income Statement'!E16*Assumptions!$C$9/Assumptions!$C$7 | C6: ='Income Statement'!F16*Assumptions!$C$9/Assumptions!$C$7 | D6: ='Income Statement'!G16*Assumptions!$C$9/Assumptions!$C$7 | E6: ='Income Statement'!H16*Assumptions!$C$9/Assumptions!$C$7 | F6: ='Income Statement'!I16*Assumptions!$C$9/Assumptions!$C$7
A7: Book value per share | B7: ='Balance Sheet'!E28/Assumptions!$C$7 | C7: ='Balance Sheet'!F28/Assumptions!$C$7 | D7: ='Balance Sheet'!G28/Assumptions!$C$7 | E7: ='Balance Sheet'!H28/Assumptions!$C$7 | F7: ='Balance Sheet'!I28/Assumptions!$C$7
A8: Free cash flow to the firm per share | B8: =DCF!B16/Assumptions!$C$7 | C8: =DCF!C16/Assumptions!$C$7 | D8: =DCF!D16/Assumptions!$C$7 | E8: =DCF!E16/Assumptions!$C$7 | F8: =DCF!F16/Assumptions!$C$7
A10: Ratios | B10: 2026E | C10: 2027E | D10: 2028E | E10: 2029E | F10: 2030E
A11: Net debt / EBITDA (loans basis) | B11: ='Balance Sheet'!E31/Segments!B43 | C11: ='Balance Sheet'!F31/Segments!C43 | D11: ='Balance Sheet'!G31/Segments!D43 | E11: ='Balance Sheet'!H31/Segments!E43 | F11: ='Balance Sheet'!I31/Segments!F43
A12: Payout ratio (policy) | B12: =Assumptions!$C$9 | C12: =Assumptions!$C$9 | D12: =Assumptions!$C$9 | E12: =Assumptions!$C$9 | F12: =Assumptions!$C$9
A13: Dividend yield at spot | B13: ='Income Statement'!E16*Assumptions!$C$9/Assumptions!$C$7/Assumptions!$C$5 | C13: ='Income Statement'!F16*Assumptions!$C$9/Assumptions!$C$7/Assumptions!$C$5 | D13: ='Income Statement'!G16*Assumptions!$C$9/Assumptions!$C$7/Assumptions!$C$5 | E13: ='Income Statement'!H16*Assumptions!$C$9/Assumptions!$C$7/Assumptions!$C$5 | F13: ='Income Statement'!I16*Assumptions!$C$9/Assumptions!$C$7/Assumptions!$C$5
A15: Operating KPIs (from the unit build) | B15: 2026E | C15: 2027E | D15: 2028E | E15: 2029E | F15: 2030E
A16: Oil volume (k MT) | B16: =Segments!B5 | C16: =Segments!C5 | D16: =Segments!D5 | E16: =Segments!E5 | F16: =Segments!F5
A17: Sugar volume (k MT) | B17: =Segments!B10 | C17: =Segments!C10 | D17: =Segments!D10 | E17: =Segments!E10 | F17: =Segments!F10
A18: Pasta volume (k MT) | B18: =Segments!B15 | C18: =Segments!C15 | D18: =Segments!D15 | E18: =Segments!E15 | F18: =Segments!F15
A19: Panda stores (year end) | B19: =Assumptions!$B$48 | C19: =Assumptions!$C$48 | D19: =Assumptions!$D$48 | E19: =Assumptions!$E$48 | F19: =Assumptions!$F$48
A20: Panda sales per average store (SAR mn) | B20: =Segments!B29 | C20: =Segments!C29 | D20: =Segments!D29 | E20: =Segments!E29 | F20: =Segments!F29
A21: Group EBITDA margin (output) | B21: =Segments!B44 | C21: =Segments!C44 | D21: =Segments!D44 | E21: =Segments!E44 | F21: =Segments!F44

Sheet Peer & Sector
A1: Peer frame — market data, cross-check only
A2: Settled closes of 18-Aug-2026; the peer-mix multiple used by the lenses is computed on the Relative & Normalized sheet from these cells
A4: Company | B4: Exchange | C4: P/E (TTM) | D4: Note
A5: Almarai | B5: Tadawul 2280 | C5: =Assumptions!$C$139 | D5: GCC food & beverage leader
A6: Al Othaim Markets | B6: Tadawul 4001 | C6: n/m | D6: n/m — H1-2026 attributable loss announced 11-Aug-2026 (TTM earnings ~79mn); excluded like Herfy
A7: BinDawood Holding | B7: Tadawul 4161 | C7: =Assumptions!$C$140 | D7: Saudi grocery retail
A8: NADEC | B8: Tadawul 6010 | C8: =Assumptions!$C$141 | D8: Saudi agri-food
A9: Wilmar International | B9: SGX F34 | C9: =Assumptions!$C$142 | D9: international agri-food analogue
A10: Herfy Food Services | B10: Tadawul 6002 | C10: n/m | D10: loss-making; consolidated at 49%
A12: Savola at the model fair value (Framing A)
A13: Implied P/E on FY2026E EPS | C13: =DCF!C64/'Income Statement'!E17
A14: Implied EV / FY2026E EBITDA (lease-inclusive) | C14: =(DCF!C35)/Segments!B43
A15: P/E at spot on FY2026E EPS | C15: =Assumptions!$C$5/'Income Statement'!E17
A16: Herfy market value feeds the bridge directly: the 51% outside shareholding is deducted at Herfy's own market price rather than book.
