Workbook

Sheet READ FIRST
A1: Testahil — Arabian Cement Company S.A.E. (EGX: ARCC) — revision 4
A4: Companion model · Independent Valuation Study · Educational analysis · Not investment advice
A6: REVISION 3 CORRECTS THE PRICE PATH, WHICH THE AUDITED RECORD DISPROVED. Revision 2 rebuilt every company
A7: figure on the statements but left one forecast driver where revision 1 had put it: local realised price
A8: growing 3.0% in FY2026 against 11.5% cost inflation, and about 4% a year after that. The statements that had
A9: just been read contradict it. FY2024: revenue +44.5% against total cash cost +41.8%. FY2025: revenue +42.6%
A10: against cash cost +12.5%, which is why the audited gross margin went 21.2% to 23.9% to 40.6%. Q1-2026 then
A11: printed revenue +17.3% at a 42.9% gross margin against 40.6% for the full prior year — still WIDENING. In
A12: every period the accounts cover, price outran cost. The old path also implied a producer unable to raise
A13: price even at the central bank's own 7% medium-term target, while the same model had utilisation RISING
A14: from 69.7% to 78.2% — volume gained and real price lost at once, two conservatisms stacked rather than one
A15: judgement made. The path is recalibrated to 8.0% / 9.0% / 8.0% / 7.0% / 6.5%, still below the cost path in
... A83: No rating and no price target. Fair-value ranges and distributions only.

Sheet Summary
A1: Summary valuation table
A2: Every value linked live from its own sheet.
A4: Lens | B4: Value per share (EGP) | C4: Role | D4: Versus spot | E4: Terminal value % of EV
A5: DCF (cash flow) | B5: =DCF!B44 | C5: PRIMARY — the central | D5: =B5/Assumptions!$B$5-1 | E5: =DCF!B34
A6: Relative multiples | B6: ='Relative & Normalized'!B23 | C6: cross-check | D6: =B6/Assumptions!$B$5-1 | E6: —
A7: Asset / replacement cost | B7: ='Fundamental Valuation'!B13 | C7: cross-check | D7: =B7/Assumptions!$B$5-1 | E7: —
A8: Normalised earnings | B8: ='Relative & Normalized'!B31 | C8: DIAGNOSTIC — not a lens for this class, reaches no published number | D8: =B8/Assumptions!$B$5-1
A9: CENTRAL FAIR VALUE — the cash-flow lens, not a blend | B9: =B5 | D9: =B9/Assumptions!$B$5-1
A10: Lowest of the three cross-checks | B10: =MIN(B6:B8) | D10: =B10/Assumptions!$B$5-1
A11: Highest of the three cross-checks | B11: =MAX(B6:B8) | D11: =B11/Assumptions!$B$5-1
A12: Market price, 2026-09-03 | B12: =Assumptions!$B$5
A13: Market capitalisation (EGP mn) | B13: =DCF!C45
A14: RETIRED: the 50/20/22/8 blend this edition dropped | B14: =B5*0.50+B6*0.20+B8*0.22+B7*0.08 | C14: weights nobody tested; kept visible, not used
A15: THE THREE-PANEL VALUATIONS
B16: Low (EGP) | C16: Central (EGP) | D16: High (EGP) | E16: Versus spot
A17: Expert 1 — Replacement-cost industrialist | B17: =((Assumptions!$B$153-15)*Assumptions!$B$13*Assumptions!$B$11+DCF!$B$40+DCF!$B$41)/DCF!$B$43 | C17: =(Assumptions!$B$153*Assumptions!$B$13*Assumptions!$B$11+DCF!$B$40+DCF!$B$41)/DCF!$B$43 | D17: =((Assumptions!$B$153+15)*Assumptions!$B$13*Assumptions!$B$11+DCF!$B$40+DCF!$B$41)/DCF!$B$43 | E17: =C17/Assumptions!$B$5-1
A18: Expert 2 — Mid-cycle earnings-power analyst | B18: =('Relative & Normalized'!$B$12*(Assumptions!$B$155-1)+DCF!$B$40+DCF!$B$41)/DCF!$B$43 | C18: =('Relative & Normalized'!$B$12*Assumptions!$B$155+DCF!$B$40+DCF!$B$41)/DCF!$B$43 | D18: =('Relative & Normalized'!$B$12*(Assumptions!$B$155+1)+DCF!$B$40+DCF!$B$41)/DCF!$B$43 | E18: =C18/Assumptions!$B$5-1
A19: Expert 3 — Cash-return and distribution investor | B19: =(AVERAGE(DCF!C15:F15)/0.20+DCF!$B$40+DCF!$B$41)/DCF!$B$43 | C19: =(AVERAGE(DCF!C15:F15)/0.175+DCF!$B$40+DCF!$B$41)/DCF!$B$43 | D19: =(AVERAGE(DCF!C15:F15)/0.15+DCF!$B$40+DCF!$B$41)/DCF!$B$43 | E19: =C19/Assumptions!$B$5-1
A20: Panel median | C20: =MEDIAN(C17:C19) | E20: =C20/Assumptions!$B$5-1
A22: Terminal value as a percentage of enterprise value is shown beside the cash-flow lens and links
A23: live to the DCF sheet — it is never typed.

Sheet Fundamental Valuation
A1: Asset lens, contested choices, and the terminal reconciliation
A4: ASSET / REPLACEMENT-COST LENS
A5: Cement capacity (Mt/yr, audited note 1) | B5: =Assumptions!$B$13
A6: Replacement cost per annual tonne (USD) | B6: =Assumptions!$B$152
A7: Justified enterprise value per annual tonne (USD) | B7: =Assumptions!$B$153
A8: Discount to replacement cost | B8: =B7/B6-1
A9: Implied enterprise value (EGP mn) | B9: =B7*B5*Assumptions!$B$11
A10: Plus net cash | B10: =DCF!B40
A11: Less non-controlling interests | B11: =DCF!B41
A12: Equity value | B12: =B9+B10+B11
A13: Value per share (EGP) | B13: =B12/DCF!$B$43
A14: Memo: what the MARKET is paying per annual tonne (USD) | B14: =(Assumptions!$B$5*DCF!$B$43-DCF!B40+Assumptions!$B$118)/Assumptions!$B$13/Assumptions!$B$11
A15: Memo: audited net book value of property and construction (EGP mn) | B15: =Assumptions!$B$106+Assumptions!$B$107
A16: Memo: that book value per annual tonne (USD) | B16: =B15/Assumptions!$B$13/Assumptions!$B$11
A18: CONTESTED CHOICES — EACH COMPUTED, NOT ARGUED
A19: Choice | B19: Adopted | C19: Alternative | D19: Fair value adopted | E19: Fair value alternative | F19: Effect
A20: Cost of debt: the POUND-EQUIVALENT cost of a euro debt book (adopted) vs the contracted euro rate | B20: 13.36% | C20: 7.89% | D20: =DCF!$B$44 | E20: 66.644423 | F20: =E20/D20-1
A21: Beta: same-country peer median (adopted, tier 2) vs the own-stock regression against the EGX30 that is too weak to use: its R-squared of 0.047 leaves the slope indistinguishable from noise | B21: 0.928 | C21: 0.698 | D21: =DCF!$B$44 | E21: 74.543903 | F21: =E21/D21-1
A22: Capex: economic maintenance in dollars per tonne (adopted) vs book depreciation | B22: USD 3.23/t | C22: book depreciation | D22: =DCF!$B$44 | E22: 70.624335 | F22: =E22/D22-1
A24: Column E holds whole-model re-runs — class 3 pasted cells. The EFFECT column is a live formula.
A26: TERMINAL RECONCILIATION — NOW BUILDABLE, BECAUSE CAPEX IS DISCLOSED
B27: FY2023 | C27: FY2024 | D27: FY2025
A28: Capital expenditure (audited) | B28: =Assumptions!$B$83 | C28: =Assumptions!$B$84 | D28: =Assumptions!$B$85
A29: Capex / EBITDA | B29: =B28/'Income Statement'!B14 | C29: =C28/'Income Statement'!C14 | D29: =D28/'Income Statement'!D14
A30: Depreciation (audited) | B30: =Assumptions!$B$80 | C30: =Assumptions!$B$81 | D30: =Assumptions!$B$82
A31: Net reinvestment (capex less depreciation) | B31: =B28-B30 | C31: =C28-C30 | D31: =D28-D30
A32: NOPAT | B32: ='Income Statement'!B11*(1-'Income Statement'!B19) | C32: ='Income Statement'!C11*(1-'Income Statement'!C19) | D32: ='Income Statement'!D11*(1-'Income Statement'!D19)
A33: Reinvestment rate | B33: =B31/B32 | C33: =C31/C32 | D33: =D31/D32
A34: Return on BOOK invested capital | B34: =B32/(Assumptions!$B$117+Assumptions!$B$125) | C34: =C32/(Assumptions!$B$116+Assumptions!$B$124) | D34: =D32/(Assumptions!$B$115+DCF!$C$44)
A35: Implied growth (return x reinvestment) | B35: =B34*B33 | C35: =C34*C33 | D35: =D34*D33
A36: Character | B36: stable — self-funded | C36: stable — self-funded | D36: stable — self-funded
A38: Terminal return on capital, REPLACEMENT-COST basis | B38: =DCF!B24
A39: Terminal return on capital, BOOK basis (FY2025) | B39: =DCF!B25
A40: Terminal rate | B40: =DCF!$C$50
A41: Terminal growth adopted | B41: =Assumptions!$B$50
A43: On the BOOK basis the return on capital is far above the terminal rate and growth would be free.
A44: The book carries a plant built around 2010 at pre-devaluation historic cost. The terminal block is
A45: struck on REPLACEMENT cost instead, where the return sits below the rate and growth must be paid
A46: for. That single choice is the most consequential judgement in this model, and it is visible here.

Sheet Assumptions
A1: Assumptions — every driver
A2: Blue cells are inputs. Nothing below a driver is typed.
A4: MARKET AND SHARE COUNT
A5: Spot price | B5: 77 | C5: EGP, close 06-Aug-2026
A6: Ordinary shares issued | B6: 378.7397 | C6: mn — audited note 20
A7: Treasury shares held | B7: 3.872255 | C7: mn — audited note 21
A8: Statutory tax rate | B8: 0.225
A9: Effective tax rate | B9: 0.2382 | C9: audited: tax over pre-tax profit
A10: Beta (own-stock weekly regression) | B10: 0.92752207
A11: USD/EGP at the valuation date | B11: 50.3
A12: PLANT — AUDITED NOTE 1
A13: Cement capacity | B13: 5 | C13: Mt/yr
A14: Kiln clinker capacity | B14: 4.2 | C14: Mt/yr
A15: Clinker factor | B15: 0.7329 | C15: t clinker / t cement
A16: EXPORT SPLIT — the one ratio the export leg needs; both prices come OUT
A17: Export clinker price as a fraction of export cement | B17: 0.65
A18: Average USD/EGP FY2025 | B18: 49.26 | C18: audited note 2.5
A19: Services revenue as a share of goods revenue | B19: 0.06325
A20: PATHS — FY2025A then FY2026E to FY2030E
B21: FY2025A | C21: FY2026E | D21: FY2027E | E21: FY2028E | F21: FY2029E | G21: FY2030E
A22: Kiln utilisation (THE volume driver) | B22: 0.917 | C22: 0.92 | D22: 0.925 | E22: 0.93 | F22: 0.933 | G22: 0.935
A23: Clinker sold as clinker, share of clinker made | B23: 0.3377 | C23: 0.33 | D23: 0.32 | E23: 0.31 | F23: 0.305 | G23: 0.3
A24: Cement exported, share of cement sold | B24: 0.1772 | C24: 0.18 | D24: 0.18 | E24: 0.175 | F24: 0.17 | G24: 0.165
A25: Cement stock draw (Mt) | B25: 0.0725 | C25: 0 | D25: 0 | E25: 0 | F25: 0 | G25: 0
A26: Local price index | B26: 1 | C26: 1.08 | D26: 1.2096 | E26: 1.318464 | F26: 1.417349 | G26: 1.516563
A27: Export price index (USD) | B27: 1 | C27: 0.968 | D27: 0.944 | E27: 0.927 | F27: 0.911 | G27: 0.895
A28: USD/EGP path | B28: 49.26 | C28: 55.11 | D28: 60.22 | E28: 64.04 | F28: 67.17 | G28: 70.11
A29: Local cost-inflation index | B29: 1 | C29: 1.115 | D29: 1.2488 | E29: 1.361192 | F29: 1.463281 | G29: 1.565711
A30: Alternative-fuel saving on materials | B30: 0 | C30: 0.015 | D30: 0.03 | E30: 0.04 | F30: 0.048 | G30: 0.055
A31: FORECAST DRIVERS — FY2026E to FY2030E
B32: FY2026E | C32: FY2027E | D32: FY2028E | E32: FY2029E | F32: FY2030E
A33: Depreciation as % of revenue | B33: 0.025 | C33: 0.027 | D33: 0.029 | E33: 0.031 | F33: 0.033
A34: EGP marginal cost-of-debt path | B34: 0.206 | C34: 0.181 | D34: 0.161 | E34: 0.149 | F34: 0.14
A35: Yield earned on cash | B35: 0.15 | C35: 0.13 | D35: 0.12 | E35: 0.112 | F35: 0.108
A36: Maintenance capital expenditure | B36: 3.23 | C36: USD/t capacity
A37: Change in working capital / change in revenue | B37: 0.12
A38: Dividend payout ratio | B38: 0.556
A39: COST OF CAPITAL
A40: Risk-free rate (EGP 10-year government) | B40: 0.2295
A41: Sovereign default spread (netted out) | B41: 0.034
...

Sheet SOTP Bridge
A1: Enterprise value to equity bridge
B4: EGP mn | C4: Per share (EGP)
A5: Present value of explicit free cash flow | B5: =DCF!B31 | C5: =B5/DCF!$B$43
A6: Present value of terminal value | B6: =DCF!B32 | C6: =B6/DCF!$B$43
A7: Enterprise value | B7: =DCF!B33 | C7: =B7/DCF!$B$43
A8: Plus net cash at the valuation date | B8: =DCF!B40 | C8: =B8/DCF!$B$43
A9: Less non-controlling interests | B9: =DCF!B41 | C9: =B9/DCF!$B$43
A10: Equity value | B10: =DCF!B42 | C10: =B10/DCF!$B$43
A12: TERMINAL VALUE AS % OF ENTERPRISE VALUE | B12: =DCF!B34
A13: Memo: spot price | C13: =Assumptions!$B$5
A14: Fair value less spot | C14: =C10-C13
A15: Upside / (downside) to the cash-flow lens | C15: =C10/C13-1
A16: Memo: enterprise value per annual tonne of capacity (USD) | C16: =B7/Assumptions!$B$13/Assumptions!$B$11
A18: Terminal value share links live to the DCF sheet — never typed. The bridge ADDS net cash and
A19: DEDUCTS minority interests; both signs are asserted in the build. The FY2025 dividend declared and
A20: unpaid at 31 March 2026 is removed from cash: a buyer at today's price does not receive it.

Sheet Segments
A1: Unit build — the PLANT drives the tonnes, and the prices come OUT
A2: Revision 3 assumed a price and divided revenue by it. That made the FY2025 check an identity that could not fail. Here the drivers are physical and all three realised prices are derived, so they can be tested against the market and disagree.
A4: FY2025 — THE PLANT IN TONNES (drivers in green, everything else derived)
A5: Kiln clinker capacity (Mt, audited note 1) | B5: =Assumptions!$B$14
A6: Kiln utilisation | B6: =Assumptions!$B$22
A7: Clinker produced (Mt) | B7: =B5*B6
A8: Share sold as clinker | B8: =Assumptions!$B$23
A9: Clinker EXPORTED (Mt) | B9: =B7*B8
A10: Clinker ground into cement (Mt) | B10: =B7-B9
A11: Clinker factor (t clinker / t cement) | B11: =Assumptions!$B$15
A12: Cement produced (Mt) | B12: =B10/B11
A13: Cement mill capacity (Mt, audited note 1) | B13: =Assumptions!$B$13
A14: Mill utilisation | B14: =B12/B13
A15: Cement exported, share of cement sold | B15: =Assumptions!$B$24
A16: Cement EXPORTED (Mt) | B16: =B29*B15
A17: Cement sold LOCALLY (Mt) | B17: =B29-B16
A18: TOTAL DESPATCHES FY2025 (Mt) | B18: =B29+B9
A19: Plus draw from finished-goods stock (Mt) | B19: =Assumptions!$B$25
A20: FY2025 PRICES — DERIVED FROM THE AUDITED REVENUE NOTE, AND TESTABLE
A21: Local sales of goods (audited note 4) | B21: =Assumptions!$B$91
A22: LOCAL CEMENT PRICE (EGP/t) — DERIVED | B22: =B21/B17
A23: Export sales of goods (audited note 4) | B23: =Assumptions!$B$93
A24: Clinker price as a fraction of cement | B24: =Assumptions!$B$17
A25: Export cement-equivalent tonnes | B25: =B16+B9*B24
A26: EXPORT CEMENT PRICE (USD/t) — DERIVED | B26: =B23/B25/Assumptions!$B$18
A27: EXPORT CLINKER PRICE (USD/t) — DERIVED | B27: =B26*B24
A28: Cement exports as a share of cement PRODUCED — the 30% statutory cap bites here | B28: =B16/B12
A29: Cement SOLD (Mt) | B29: =B12+B19
A30: FY2025 CASH COST — DISCLOSED, AND ALLOCATED TO ITS OWN DRIVER
A31: Materials and fuel (note 5) | B31: =Assumptions!$B$97
A32: Transportation (note 5) | B32: =Assumptions!$B$98
A33: Overheads (note 5) plus cash administration (note 6) | B33: =Assumptions!$B$99+Assumptions!$B$61-Assumptions!$B$100
A34: Total cash cost (EGP mn) | B34: =SUM(B31:B33)
A35: Materials and fuel per tonne of CLINKER — the kiln burns it | B35: =B31/B7
A36: Transportation per tonne DESPATCHED | B36: =B32/B18
A37: Overheads and administration per tonne DESPATCHED | B37: =B33/B18
A38: TOTAL CASH COST PER TONNE SOLD | B38: =B34/B18
A40: Provisions and expected credit losses are NOT in this stack. They are operating charges that
A41: belong in the EBITDA bridge, but they are not cash cost per tonne. Revision 3 carried them here.
A43: THE BUILD — FY2025A THEN FY2026E TO FY2030E
...

Sheet Relative & Normalized
A1: Relative multiples and normalised earnings power
A4: NORMALISED EARNINGS BASE
A5: FY2025 revenue, audited (the cyclical peak) | B5: =Assumptions!$B$55
A6: Haircut to the revenue base | B6: =Assumptions!$B$157
A7: Normalised revenue | B7: =B5*B6
A8: Mid-cycle EBITDA margin | B8: =Assumptions!$B$156
A9: Normalised EBITDA | B9: =B7*B8
A10: Less audited depreciation | B10: =-Assumptions!$B$82
A11: Normalised EBIT | B11: =B9+B10
A12: Normalised NOPAT | B12: =B11*(1-Assumptions!$B$9)
A13: Memo: audited FY2023 EBITDA margin | B13: ='Income Statement'!B15
A14: Memo: audited FY2024 EBITDA margin | B14: ='Income Statement'!C15
A15: Memo: audited FY2025 EBITDA margin | B15: ='Income Statement'!D15
A17: RELATIVE LENS — EV/EBITDA ON NORMALISED EARNINGS
A18: Justified EV/EBITDA | B18: =Assumptions!$B$154
A19: Implied enterprise value | B19: =B9*B18
A20: Plus net cash | B20: =DCF!B40
A21: Less non-controlling interests | B21: =DCF!B41
A22: Equity value | B22: =B19+B20+B21
A23: Value per share (EGP) | B23: =B22/DCF!$B$43
A25: NORMALISED-EARNINGS LENS
A26: Justified price / earnings | B26: =Assumptions!$B$155
A27: Capitalised operating earnings | B27: =B12*B26
A28: Plus net cash, at FACE | B28: =DCF!B40
A29: Less non-controlling interests | B29: =DCF!B41
A30: Equity value | B30: =B27+B28+B29
A31: Value per share (EGP) | B31: =B30/DCF!$B$43
A33: Cash is added at FACE in both lenses rather than capitalised at the operating multiple.

Sheet DCF
A1: Discounted cash flow — the primary lens
A2: Cost of capital built here, facility by facility, never pasted.
B4: FY2026E | C4: FY2027E | D4: FY2028E | E4: FY2029E | F4: FY2030E
A5: Revenue | B5: ='Segments'!C63 | C5: ='Segments'!D63 | D5: ='Segments'!E63 | E5: ='Segments'!F63 | F5: ='Segments'!G63
A6: EBITDA margin | B6: =B7/B5 | C6: =C7/C5 | D6: =D7/D5 | E6: =E7/E5 | F6: =F7/F5
A7: EBITDA | B7: ='Segments'!C71 | C7: ='Segments'!D71 | D7: ='Segments'!E71 | E7: ='Segments'!F71 | F7: ='Segments'!G71
A8: Depreciation and amortisation | B8: =B5*Assumptions!$B$33*Assumptions!$B$146 | C8: =C5*Assumptions!$C$33*Assumptions!$B$146 | D8: =D5*Assumptions!$D$33*Assumptions!$B$146 | E8: =E5*Assumptions!$E$33*Assumptions!$B$146 | F8: =F5*Assumptions!$F$33*Assumptions!$B$146
A9: EBIT | B9: =B7-B8+Assumptions!$B$147*'Segments'!C60+Assumptions!$B$147*'Segments'!C61+Assumptions!$B$148*Assumptions!$C$29 | C9: =C7-C8+Assumptions!$B$147*'Segments'!D60+Assumptions!$B$147*'Segments'!D61+Assumptions!$B$148*Assumptions!$D$29 | D9: =D7-D8+Assumptions!$B$147*'Segments'!E60+Assumptions!$B$147*'Segments'!E61+Assumptions!$B$148*Assumptions!$E$29 | E9: =E7-E8+Assumptions!$B$147*'Segments'!F60+Assumptions!$B$147*'Segments'!F61+Assumptions!$B$148*Assumptions!$F$29 | F9: =F7-F8+Assumptions!$B$147*'Segments'!G60+Assumptions!$B$147*'Segments'!G61+Assumptions!$B$148*Assumptions!$G$29
A10: Tax rate (effective) | B10: =Assumptions!$B$9 | C10: =Assumptions!$B$9 | D10: =Assumptions!$B$9 | E10: =Assumptions!$B$9 | F10: =Assumptions!$B$9
A11: NOPAT (EBIT × (1 − t)) | B11: =B9*(1-B10) | C11: =C9*(1-C10) | D11: =D9*(1-D10) | E11: =E9*(1-E10) | F11: =F9*(1-F10)
A12: Plus depreciation | B12: =B8 | C12: =C8 | D12: =D8 | E12: =E8 | F12: =F8
A13: Less capital expenditure | B13: =-Assumptions!$B$13*Assumptions!$B$36*Assumptions!$C$28 | C13: =-Assumptions!$B$13*Assumptions!$B$36*Assumptions!$D$28 | D13: =-Assumptions!$B$13*Assumptions!$B$36*Assumptions!$E$28 | E13: =-Assumptions!$B$13*Assumptions!$B$36*Assumptions!$F$28 | F13: =-Assumptions!$B$13*Assumptions!$B$36*Assumptions!$G$28
A14: Less change in working capital | B14: =-(B5-Assumptions!$B$55)*Assumptions!$B$37 | C14: =-(C5-B5)*Assumptions!$B$37 | D14: =-(D5-C5)*Assumptions!$B$37 | E14: =-(E5-D5)*Assumptions!$B$37 | F14: =-(F5-E5)*Assumptions!$B$37
A15: FREE CASH FLOW TO THE FIRM | B15: =(B11+B12+B13+B14)*(1-Assumptions!$B$51) | C15: =C11+C12+C13+C14 | D15: =D11+D12+D13+D14 | E15: =E11+E12+E13+E14 | F15: =F11+F12+F13+F14
A16: Glide fraction | B16: =(Assumptions!$B$34-Assumptions!$B$34)/(Assumptions!$B$34-Assumptions!$F$34) | C16: =(Assumptions!$B$34-Assumptions!$C$34)/(Assumptions!$B$34-Assumptions!$F$34) | D16: =(Assumptions!$B$34-Assumptions!$D$34)/(Assumptions!$B$34-Assumptions!$F$34) | E16: =(Assumptions!$B$34-Assumptions!$E$34)/(Assumptions!$B$34-Assumptions!$F$34) | F16: =(Assumptions!$B$34-Assumptions!$F$34)/(Assumptions!$B$34-Assumptions!$F$34)
A17: Forward cost of capital | B17: =$C$40-($C$40-$C$50)*B16 | C17: =$C$40-($C$40-$C$50)*C16 | D17: =$C$40-($C$40-$C$50)*D16 | E17: =$C$40-($C$40-$C$50)*E16 | F17: =$C$40-($C$40-$C$50)*F16
A18: Discount factor | B18: =1/(1+B17)^((1-Assumptions!$B$51)/2) | C18: =1/((1+B17)^(1-Assumptions!$B$51)*(1+C17)^0.5) | D18: =1/((1+B17)^(1-Assumptions!$B$51)*(1+C17)*(1+D17)^0.5) | E18: =1/((1+B17)^(1-Assumptions!$B$51)*(1+C17)*(1+D17)*(1+E17)^0.5) | F18: =1/((1+B17)^(1-Assumptions!$B$51)*(1+C17)*(1+D17)*(1+E17)*(1+F17)^0.5)
A19: PRESENT VALUE OF FCFF | B19: =B15*B18 | C19: =C15*C18 | D19: =D15*D18 | E19: =E15*E18 | F19: =F15*F18
A21: TERMINAL BLOCK
A22: Replacement-cost invested capital, in TERMINAL-year pounds (EGP mn) | B22: =Assumptions!$B$13*Assumptions!$B$152*Assumptions!$B$11*Assumptions!$G$29 | C22: Capital maintenance at the DISCLOSED 20-year useful life (replacement cost / life) | D22: =B22/20.0
A23: Terminal NOPAT (year 5 NOPAT grown at g) | B23: =F11*(1+Assumptions!$B$50) | C23: Book depreciation already inside terminal NOPAT, added back | D23: =F8
A24: Memo: return on invested capital at replacement cost | B24: =B23/B22 | C24: Inflation on working capital (terminal inflation x working-capital level) | D24: =Assumptions!$B$50*F5*0.12000000
A25: Memo: FY2025 return on BOOK invested capital | B25: =('Income Statement'!D12*(1-Assumptions!$B$9))/(Assumptions!$B$115+$C$44) | C25: Growth capital (REAL growth x replacement cost; real growth derives from the nominal rate and the house inflation path) | D25: =((1+Assumptions!$B$50)/(1+0.07000000)-1)*B22
A26: Memo: reinvestment rate the RETIRED construction charged (g / return) | B26: =Assumptions!$B$50/B24 | C26: Terminal free cash flow (NOPAT + depreciation - maintenance - working capital - growth capital) | D26: =F11+D23-D22-D24-D25
A27: Terminal value | B27: =D26*(1+Assumptions!$B$50)/($C$50-Assumptions!$B$50)
A28: Present value of terminal value | B28: =B27*B29
A29: End-of-window discount factor (t = 4.417y, not the year-5 mid-point) | B29: =1/((1+B17)^(1-Assumptions!$B$51)*(1+C17)*(1+D17)*(1+E17)*(1+F17))
A30: ENTERPRISE TO EQUITY BRIDGE
A31: Present value of explicit years (FY2026E-FY2030E) | B31: =SUM(B19:F19)
A32: Present value of terminal value | B32: =B28
A33: Enterprise value | B33: =B31+B32
A34: TERMINAL VALUE AS % OF ENTERPRISE VALUE | B34: =B32/B33
A35: Cash and bank balances, reviewed 30 June 2026 — THE DISCLOSED BALANCE | B35: =Assumptions!$B$139 | E35: COST OF CAPITAL — BUILT HERE, FACILITY BY FACILITY (labels in column E:
A36: (memo) the roll-forward the previous edition had to use instead | B36: =Assumptions!$B$112+B15/(1-Assumptions!$B$51)*Assumptions!$B$51+Assumptions!$B$112*Assumptions!$B$35*Assumptions!$B$51*(1-Assumptions!$B$9)-Assumptions!$B$131 | C36: =Assumptions!$B$40 | E36: Risk-free rate (observed EGP 10-year)
A37: (memo) what that roll-forward missed, per share | B37: =(B36-Assumptions!$B$138-B38-B39)/B43 | C37: =-Assumptions!$B$41 | E37: Less sovereign default spread
A38: Cash at the valuation date (30 June 2026) | B38: =Assumptions!$B$139 | C38: =C36+C37 | E38: Normalised risk-free rate
A39: Less interest-bearing debt, reviewed 30 June 2026 | B39: =-Assumptions!$B$140 | C39: =C38+Assumptions!$B$10*Assumptions!$B$42 | E39: Cost of equity (rf* + beta × premium)
A40: Net cash (ADDED — the company is net cash) | B40: =B38+B39 | C40: =(1-C43)*C39+C43*C42 | E40: WACC — explicit window
A41: Less non-controlling interests (reviewed 30 June 2026) | B41: =-Assumptions!$B$141 | C41: =(Assumptions!$B$120*Assumptions!$B$44+Assumptions!$B$121*(Assumptions!$B$43+0.03+Assumptions!$B$45)+Assumptions!$B$122*(Assumptions!$B$43+0.0435+Assumptions!$B$45)+Assumptions!$B$123*Assumptions!$B$44)/C44 | E41: Cost of debt, blended by currency, POUND-EQUIVALENT
A42: Equity value | B42: =B33+B40+B41 | C42: =C41*(1-Assumptions!$B$8) | E42: Cost of debt after tax
...

Sheet Income Statement
A1: Income statement — 3 AUDITED years + 5-year forecast
A2: EGP mn
B4: FY2023 | C4: FY2024 | D4: FY2025 | E4: FY2026E | F4: FY2027E | G4: FY2028E | H4: FY2029E | I4: FY2030E
A5: Revenue | B5: =Assumptions!$B$53 | C5: =Assumptions!$B$54 | D5: =Assumptions!$B$55 | E5: =DCF!B5 | F5: =DCF!C5 | G5: =DCF!D5 | H5: =DCF!E5 | I5: =DCF!F5
A6: Cost of sales | B6: =-Assumptions!$B$56 | C6: =-Assumptions!$B$57 | D6: =-Assumptions!$B$58
A7: Gross profit | B7: =B5+B6 | C7: =C5+C6 | D7: =D5+D6
A8: Gross margin | B8: =B7/B5 | C8: =C7/C5 | D8: =D7/D5
A9: General and administrative expenses | B9: =-Assumptions!$B$59 | C9: =-Assumptions!$B$60 | D9: =-Assumptions!$B$61
A10: Provisions and credit losses | B10: =-Assumptions!$B$62-Assumptions!$B$65 | C10: =-Assumptions!$B$63-Assumptions!$B$66 | D10: =-Assumptions!$B$64-Assumptions!$B$67
A11: OPERATING PROFIT | B11: =B7+B9+B10 | C11: =C7+C9+C10 | D11: =D7+D9+D10 | E11: =E14-E13+Assumptions!$B$147*'Segments'!C60+Assumptions!$B$147*'Segments'!C61+Assumptions!$B$148*Assumptions!$C$29 | F11: =F14-F13+Assumptions!$B$147*'Segments'!D60+Assumptions!$B$147*'Segments'!D61+Assumptions!$B$148*Assumptions!$D$29 | G11: =G14-G13+Assumptions!$B$147*'Segments'!E60+Assumptions!$B$147*'Segments'!E61+Assumptions!$B$148*Assumptions!$E$29 | H11: =H14-H13+Assumptions!$B$147*'Segments'!F60+Assumptions!$B$147*'Segments'!F61+Assumptions!$B$148*Assumptions!$F$29 | I11: =I14-I13+Assumptions!$B$147*'Segments'!G60+Assumptions!$B$147*'Segments'!G61+Assumptions!$B$148*Assumptions!$G$29
A12: Operating profit, opening the EBITDA bridge | B12: =B11 | C12: =C11 | D12: =D11 | E12: =E11 | F12: =F11 | G12: =G11 | H12: =H11 | I12: =I11
A13: Depreciation and amortisation | B13: =Assumptions!$B$80 | C13: =Assumptions!$B$81 | D13: =Assumptions!$B$82 | E13: =DCF!B8 | F13: =DCF!C8 | G13: =DCF!D8 | H13: =DCF!E8 | I13: =DCF!F8
A14: EBITDA | B14: =B12+B13 | C14: =C12+C13 | D14: =D12+D13 | E14: =DCF!B7 | F14: =DCF!C7 | G14: =DCF!D7 | H14: =DCF!E7 | I14: =DCF!F7
A15: EBITDA margin | B15: =B14/B5 | C15: =C14/C5 | D15: =D14/D5 | E15: =E14/E5 | F15: =F14/F5 | G15: =G14/G5 | H15: =H14/H5 | I15: =I14/I5
A16: Net finance and other income | B16: =Assumptions!$B$68-B11 | C16: =Assumptions!$B$69-C11 | D16: =Assumptions!$B$86+Assumptions!$B$87-Assumptions!$B$88+Assumptions!$B$89+1.14 | E16: =('Balance Sheet'!D9-Assumptions!$B$131)*Assumptions!$B$35-DCF!$C$44*(1-DCF!$C$46)*Assumptions!$B$34-DCF!$C$44*DCF!$C$46*(Assumptions!$B$43+0.0435) | F16: ='Balance Sheet'!E9*Assumptions!$C$35-DCF!$C$44*(1-DCF!$C$46)*Assumptions!$C$34-DCF!$C$44*DCF!$C$46*(Assumptions!$B$43+0.0435) | G16: ='Balance Sheet'!F9*Assumptions!$D$35-DCF!$C$44*(1-DCF!$C$46)*Assumptions!$D$34-DCF!$C$44*DCF!$C$46*(Assumptions!$B$43+0.0435) | H16: ='Balance Sheet'!G9*Assumptions!$E$35-DCF!$C$44*(1-DCF!$C$46)*Assumptions!$E$34-DCF!$C$44*DCF!$C$46*(Assumptions!$B$43+0.0435) | I16: ='Balance Sheet'!H9*Assumptions!$F$35-DCF!$C$44*(1-DCF!$C$46)*Assumptions!$F$34-DCF!$C$44*DCF!$C$46*(Assumptions!$B$43+0.0435)
A17: Profit before tax | B17: =Assumptions!$B$68 | C17: =Assumptions!$B$69 | D17: =Assumptions!$B$70 | E17: =E11+E16 | F17: =F11+F16 | G17: =G11+G16 | H17: =H11+H16 | I17: =I11+I16
A18: Income tax | B18: =-Assumptions!$B$71 | C18: =-Assumptions!$B$72 | D18: =-Assumptions!$B$73 | E18: =-E17*Assumptions!$B$9 | F18: =-F17*Assumptions!$B$9 | G18: =-G17*Assumptions!$B$9 | H18: =-H17*Assumptions!$B$9 | I18: =-I17*Assumptions!$B$9
A19: Effective tax rate | B19: =-B18/B17 | C19: =-C18/C17 | D19: =-D18/D17 | E19: =-E18/E17 | F19: =-F18/F17 | G19: =-G18/G17 | H19: =-H18/H17 | I19: =-I18/I17
A20: Attributable profit | B20: =Assumptions!$B$74 | C20: =Assumptions!$B$75 | D20: =Assumptions!$B$76 | E20: =E17+E18 | F20: =F17+F18 | G20: =G17+G18 | H20: =H17+H18 | I20: =I17+I18
A21: Earnings per share (EGP) | B21: =Assumptions!$B$77 | C21: =Assumptions!$B$78 | D21: =Assumptions!$B$79 | E21: =E20/DCF!$B$43 | F21: =F20/DCF!$B$43 | G21: =G20/DCF!$B$43 | H21: =H20/DCF!$B$43 | I21: =I20/DCF!$B$43
A22: Dividends declared | C22: =Assumptions!$B$132 | D22: =Assumptions!$B$131 | E22: =E20*Assumptions!$B$38 | F22: =F20*Assumptions!$B$38 | G22: =G20*Assumptions!$B$38 | H22: =H20*Assumptions!$B$38 | I22: =I20*Assumptions!$B$38
A23: Dividend per share (EGP) | C23: =C22/DCF!$B$43 | D23: =D22/DCF!$B$43 | E23: =E22/DCF!$B$43 | F23: =F22/DCF!$B$43 | G23: =G22/DCF!$B$43 | H23: =H22/DCF!$B$43 | I23: =I22/DCF!$B$43
A24: FY2025 check: components of non-operating income against the audited residual | B24: =D16-(D17-D11)
A25: FY2023-FY2025 revenue, cost of sales, administrative expenses, provisions, pre-tax profit, tax,
A26: attributable profit, earnings per share and depreciation are AUDITED figures. Operating profit,
A27: EBITDA, margins and the effective tax rate are formulas over them. Nothing historical is derived
A28: by closing an assumption, which is what revision 1 had to do.

Sheet Balance Sheet
A1: Balance sheet — 3 AUDITED years + 5-year forecast
A2: EGP mn
B4: FY2023 | C4: FY2024 | D4: FY2025 | E4: FY2026E | F4: FY2027E | G4: FY2028E | H4: FY2029E | I4: FY2030E
A5: Property, plant and equipment | D5: =Assumptions!$B$106
A6: Assets under construction | D6: =Assumptions!$B$107
A7: Intangible assets | D7: =Assumptions!$B$108
A8: Total non-current assets | D8: =SUM(D5:D7) | E8: =D8-DCF!B8-DCF!B13 | F8: =E8-DCF!C8-DCF!C13 | G8: =F8-DCF!D8-DCF!D13 | H8: =G8-DCF!E8-DCF!E13 | I8: =H8-DCF!F8-DCF!F13
A9: Cash and bank balances | B9: =Assumptions!$B$114 | C9: =Assumptions!$B$113 | D9: =Assumptions!$B$112 | E9: =D9-Assumptions!$B$131+'Income Statement'!E20+DCF!B8+DCF!B13+DCF!B14-'Income Statement'!E22 | F9: =E9+'Income Statement'!F20+DCF!C8+DCF!C13+DCF!C14-'Income Statement'!F22 | G9: =F9+'Income Statement'!G20+DCF!D8+DCF!D13+DCF!D14-'Income Statement'!G22 | H9: =G9+'Income Statement'!H20+DCF!E8+DCF!E13+DCF!E14-'Income Statement'!H22 | I9: =H9+'Income Statement'!I20+DCF!F8+DCF!F13+DCF!F14-'Income Statement'!I22
A10: Inventories, receivables and debtors | D10: =Assumptions!$B$109+Assumptions!$B$110+Assumptions!$B$111 | E10: =D10-DCF!B14 | F10: =E10-DCF!C14 | G10: =F10-DCF!D14 | H10: =G10-DCF!E14 | I10: =H10-DCF!F14
A11: TOTAL ASSETS | B11: =Assumptions!$B$104 | C11: =Assumptions!$B$103 | D11: =Assumptions!$B$102 | E11: =E8+E9+E10 | F11: =F8+F9+F10 | G11: =G8+G9+G10 | H11: =H8+H9+H10 | I11: =I8+I9+I10
A12: Interest-bearing debt | B12: =Assumptions!$B$125 | C12: =Assumptions!$B$124 | D12: =DCF!C44 | E12: =DCF!$C$44 | F12: =DCF!$C$44 | G12: =DCF!$C$44 | H12: =DCF!$C$44 | I12: =DCF!$C$44
A13: Other liabilities | D13: =D14-D12 | E13: =D13 | F13: =D13 | G13: =D13 | H13: =D13 | I13: =D13
A14: Total liabilities | D14: =Assumptions!$B$105 | E14: =E12+E13 | F14: =F12+F13 | G14: =G12+G13 | H14: =H12+H13 | I14: =I12+I13
A15: Equity attributable to owners | B15: =Assumptions!$B$117 | C15: =Assumptions!$B$116 | D15: =Assumptions!$B$115 | E15: =D15-Assumptions!$B$131+'Income Statement'!E20-'Income Statement'!E22 | F15: =E15+'Income Statement'!F20-'Income Statement'!F22 | G15: =F15+'Income Statement'!G20-'Income Statement'!G22 | H15: =G15+'Income Statement'!H20-'Income Statement'!H22 | I15: =H15+'Income Statement'!I20-'Income Statement'!I22
A16: Net (cash) / debt | B16: =B12-B9 | C16: =C12-C9 | D16: =D12-D9 | E16: =E12-E9 | F16: =F12-F9 | G16: =G12-G9 | H16: =H12-H9 | I16: =I12-I9
A17: Book value per share (EGP) | B17: =B15/DCF!$B$43 | C17: =C15/DCF!$B$43 | D17: =D15/DCF!$B$43 | E17: =E15/DCF!$B$43 | F17: =F15/DCF!$B$43 | G17: =G15/DCF!$B$43 | H17: =H15/DCF!$B$43 | I17: =I15/DCF!$B$43
A18: Return on equity | B18: ='Income Statement'!B20/B15 | C18: ='Income Statement'!C20/C15 | D18: ='Income Statement'!D20/D15 | E18: ='Income Statement'!E20/E15 | F18: ='Income Statement'!F20/F15 | G18: ='Income Statement'!G20/G15 | H18: ='Income Statement'!H20/H15 | I18: ='Income Statement'!I20/I15
A20: THE AUDITED BALANCE SHEET CLOSES — A CHECK REVISION 1 COULD NOT RUN
A21: Total assets (audited) | B21: =Assumptions!$B$102
A22: Less total liabilities (audited) | B22: =-Assumptions!$B$105
A23: Equals total equity | B23: =B21+B22
A24: Equity attributable to owners plus minorities (audited) | B24: =Assumptions!$B$115+Assumptions!$B$118
A25: Difference | B25: =B23-B24
A27: Revision 1 was offered EGP 2,894.13mn as total liabilities and rejected it because it would not
A28: close; it derived EGP 4,140.99mn instead. The audited statements show 2,894.13 is total CURRENT
A29: liabilities and the total is 4,140.99. The derivation was right, and row 25 now closes to zero.

Sheet Cash Flow
A1: Cash flow — audited FY2025 and the forecast, linked to the waterfall
A2: EGP mn
B4: FY2025A | C4: FY2026E | D4: FY2027E | E4: FY2028E | F4: FY2029E | G4: FY2030E
A5: Attributable profit | B5: ='Income Statement'!D20 | C5: ='Income Statement'!E20 | D5: ='Income Statement'!F20 | E5: ='Income Statement'!G20 | F5: ='Income Statement'!H20 | G5: ='Income Statement'!I20
A6: Add back depreciation | B6: =Assumptions!$B$82 | C6: =DCF!B8 | D6: =DCF!C8 | E6: =DCF!D8 | F6: =DCF!E8 | G6: =DCF!F8
A7: Less change in working capital | C7: =DCF!B14 | D7: =DCF!C14 | E7: =DCF!D14 | F7: =DCF!E14 | G7: =DCF!F14
A8: Cash from operations | B8: =B5+B6 | C8: =C5+C6+C7 | D8: =D5+D6+D7 | E8: =E5+E6+E7 | F8: =F5+F6+F7 | G8: =G5+G6+G7
A9: Capital expenditure | B9: =-Assumptions!$B$85 | C9: =DCF!B13 | D9: =DCF!C13 | E9: =DCF!D13 | F9: =DCF!E13 | G9: =DCF!F13
A10: Free cash flow to equity | B10: =B8+B9 | C10: =C8+C9 | D10: =D8+D9 | E10: =E8+E9 | F10: =F8+F9 | G10: =G8+G9
A11: Dividends declared | B11: =-Assumptions!$B$131 | C11: =-'Income Statement'!E22 | D11: =-'Income Statement'!F22 | E11: =-'Income Statement'!G22 | F11: =-'Income Statement'!H22 | G11: =-'Income Statement'!I22
A12: Closing cash | B12: =Assumptions!$B$112 | C12: ='Balance Sheet'!E9 | D12: ='Balance Sheet'!F9 | E12: ='Balance Sheet'!G9 | F12: ='Balance Sheet'!H9 | G12: ='Balance Sheet'!I9
A13: Memo: free cash flow to the firm | C13: =DCF!B15 | D13: =DCF!C15 | E13: =DCF!D15 | F13: =DCF!E15 | G13: =DCF!F15
A15: The FY2025 column is the AUDITED outturn: attributable profit, depreciation and capital
A16: expenditure all read from the audited cash flow statement. The forecast columns LINK to the DCF
A17: and Income Statement sheets, so the statement and the valuation cannot disagree by construction.

Sheet Summary Financials
A1: Summary financials — eight years on one screen
A2: EGP mn
B4: FY2023 | C4: FY2024 | D4: FY2025 | E4: FY2026E | F4: FY2027E | G4: FY2028E | H4: FY2029E | I4: FY2030E
A5: Revenue | B5: ='Income Statement'!B5 | C5: ='Income Statement'!C5 | D5: ='Income Statement'!D5 | E5: ='Income Statement'!E5 | F5: ='Income Statement'!F5 | G5: ='Income Statement'!G5 | H5: ='Income Statement'!H5 | I5: ='Income Statement'!I5
A6: EBITDA | B6: ='Income Statement'!B14 | C6: ='Income Statement'!C14 | D6: ='Income Statement'!D14 | E6: ='Income Statement'!E14 | F6: ='Income Statement'!F14 | G6: ='Income Statement'!G14 | H6: ='Income Statement'!H14 | I6: ='Income Statement'!I14
A7: EBITDA margin | B7: ='Income Statement'!B15 | C7: ='Income Statement'!C15 | D7: ='Income Statement'!D15 | E7: ='Income Statement'!E15 | F7: ='Income Statement'!F15 | G7: ='Income Statement'!G15 | H7: ='Income Statement'!H15 | I7: ='Income Statement'!I15
A8: Operating profit | B8: ='Income Statement'!B11 | C8: ='Income Statement'!C11 | D8: ='Income Statement'!D11 | E8: ='Income Statement'!E11 | F8: ='Income Statement'!F11 | G8: ='Income Statement'!G11 | H8: ='Income Statement'!H11 | I8: ='Income Statement'!I11
A9: Attributable profit | B9: ='Income Statement'!B20 | C9: ='Income Statement'!C20 | D9: ='Income Statement'!D20 | E9: ='Income Statement'!E20 | F9: ='Income Statement'!F20 | G9: ='Income Statement'!G20 | H9: ='Income Statement'!H20 | I9: ='Income Statement'!I20
A10: Earnings per share (EGP) | B10: ='Income Statement'!B21 | C10: ='Income Statement'!C21 | D10: ='Income Statement'!D21 | E10: ='Income Statement'!E21 | F10: ='Income Statement'!F21 | G10: ='Income Statement'!G21 | H10: ='Income Statement'!H21 | I10: ='Income Statement'!I21
A12: GROWTH
A13: Revenue growth | C13: =C5/B5-1 | D13: =D5/C5-1 | E13: =E5/D5-1 | F13: =F5/E5-1 | G13: =G5/F5-1 | H13: =H5/G5-1 | I13: =I5/H5-1
A14: EBITDA growth | C14: =C6/B6-1 | D14: =D6/C6-1 | E14: =E6/D6-1 | F14: =F6/E6-1 | G14: =G6/F6-1 | H14: =H6/G6-1 | I14: =I6/H6-1
A15: Profit growth | C15: =C9/B9-1 | D15: =D9/C9-1 | E15: =E9/D9-1 | F15: =F9/E9-1 | G15: =G9/F9-1 | H15: =H9/G9-1 | I15: =I9/H9-1
A18: Every cell on this sheet is a link or a formula. Nothing is restated.

Sheet Monte Carlo
A1: Probabilistic price map — ILLUSTRATIVE ONLY
A2: Percentiles are the output of a 50,000-path simulation: pasted, class 2.
A3: This map is NOT a valuation. It does not redraw when a valuation driver changes.
B6: One month | C6: Three months
A7: 5th percentile | B7: 50.444111 | C7: 43.922515
A8: 25th percentile | B8: 55.934078 | C8: 53.711182
A9: Median | B9: 59.448465 | C9: 60.456482
A10: 75th percentile | B10: 63.21157 | C10: 67.968663
A11: 95th percentile | B11: 70.085724 | C11: 83.168398
A12: Spot | B12: =Assumptions!$B$5 | C12: =Assumptions!$B$5
A14: Probability of finishing above spot | B14: 0.53378 | C14: 0.55584
A15: Probability of finishing 10% or more above | B15: 0.16972 | C15: 0.33954
A16: Probability of finishing 10% or more below | B16: 0.11564 | C16: 0.2301
A17: Probability of TOUCHING +10% at any point | B17: 0.2777 | C17: 0.57952
A18: Probability of TOUCHING -10% at any point | B18: 0.19752 | C18: 0.45536
A20: Median versus spot | B20: =B9/B12-1 | C20: =C9/C12-1
A21: Width of the 5th-95th band, as % of spot | B21: =(B11-B7)/B12 | C21: =(C11-C7)/C12
A23: HOW WELL CALIBRATED IS THIS MAP? — MEASURED, NOT ASSERTED
A24: Windows scored | B24: 16
A25: Coverage of the 50% band (nominal 50%) | B25: 0.5625
A26: Coverage of the 80% band (nominal 80%) | B26: 1
A27: Coverage of the 90% band (nominal 90%) | B27: 1
A28: Cone width against the benchmark | B28: 1.2342923
A31: The bands cover MORE than their nominal share, so the map is too wide rather than mis-centred.

Sheet Sensitivity
A1: Sensitivity — whole-model re-runs (class 3, pasted)
A2: Each cell is a complete revaluation. THESE GRIDS DO NOT REDRAW.
A4: Fair value per share (EGP): explicit-window cost of capital against terminal growth
B5: g = 3% | C5: g = 4% | D5: g = 5% | E5: g = 6% | F5: g = 7%
A6: 0.24599726 | B6: 73.151156 | C6: 72.391218 | D6: 71.434758 | E6: 70.234005 | F6: 68.724345
A7: 0.26099726 | B7: 71.955377 | C7: 71.209929 | D7: 70.271705 | E7: 69.093847 | F7: 67.612971
A8: 0.27599726 | B8: 70.790274 | C8: 70.058933 | D8: 69.138463 | E8: 67.982893 | F8: 66.530041
A9: 0.29099726 | B9: 69.654802 | C9: 68.937196 | D9: 68.034014 | E9: 66.900149 | F9: 65.474583
A10: 0.30599726 | B10: 68.547958 | C10: 67.843731 | D10: 66.957387 | E10: 65.844661 | F10: 64.445672
A12: Fair value per share (EGP): explicit-window rate against TERMINAL rate
B13: terminal 16.3% | C13: terminal 17.3% | D13: terminal 18.3% | E13: terminal 19.3% | F13: terminal 20.3%
A14: 0.24599726 | B14: 79.148697 | C14: 73.439341 | D14: 68.724345 | E14: 64.762155 | F14: 61.383636
A15: 0.26099726 | B15: 77.831865 | C15: 72.23506 | D15: 67.612971 | E15: 63.728817 | F15: 60.416805
A16: 0.27599726 | B16: 76.549056 | C16: 71.061745 | D16: 66.530041 | E16: 62.721804 | F16: 59.474493
A17: 0.29099726 | B17: 75.299106 | C17: 69.918337 | D17: 65.474583 | E17: 61.740221 | F17: 58.555871
A18: 0.30599726 | B18: 74.080897 | C18: 68.803824 | D18: 64.445672 | E18: 60.783212 | F18: 57.660142
A20: Fair value per share (EGP): beta
B21: 0.60 | C21: 0.80 | D21: 1.00 | E21: 1.15 | F21: 1.30
A22: Fair value | B22: 79.156434 | C22: 70.34566 | D22: 63.474709 | E22: 59.235406 | F22: 55.593044
A24: Fair value per share (EGP): margin shift
B25: -4% | C25: -2% | D25: +0% | E25: +2% | F25: +4%
A26: Fair value | B26: 56.683206 | C26: 61.606623 | D26: 66.530041 | E26: 71.453458 | F26: 76.376875
A28: Fair value per share (EGP): net cash (EGP mn)
B29: -813 | C29: -63 | D29: 687 | E29: 1,437 | F29: 2,187
A30: Fair value | B30: 62.528626 | C30: 64.529333 | D30: 66.530041 | E30: 68.530748 | F30: 70.531455
A32: Note the growth column of the first grid: HIGHER terminal growth gives a LOWER value, because the
A33: terminal return on replacement-cost capital sits below the hurdle. Read off the grid, never typed:
A34: revision 3 carried this note unchanged after its own grid had reversed, and it contradicted itself.

Sheet Per-Share & Ratios
A1: Per-share figures, ratios and reconciliations
B4: FY2023 | C4: FY2024 | D4: FY2025 | E4: FY2026E | F4: FY2027E | G4: FY2028E | H4: FY2029E | I4: FY2030E
A5: Earnings per share (EGP) | B5: ='Income Statement'!B21 | C5: ='Income Statement'!C21 | D5: ='Income Statement'!D21 | E5: ='Income Statement'!E21 | F5: ='Income Statement'!F21 | G5: ='Income Statement'!G21 | H5: ='Income Statement'!H21 | I5: ='Income Statement'!I21
A6: Book value per share (EGP) | B6: ='Balance Sheet'!B17 | C6: ='Balance Sheet'!C17 | D6: ='Balance Sheet'!D17 | E6: ='Balance Sheet'!E17 | F6: ='Balance Sheet'!F17 | G6: ='Balance Sheet'!G17 | H6: ='Balance Sheet'!H17 | I6: ='Balance Sheet'!I17
A7: Price / earnings (at spot) | B7: =Assumptions!$B$5/B5 | C7: =Assumptions!$B$5/C5 | D7: =Assumptions!$B$5/D5 | E7: =Assumptions!$B$5/E5 | F7: =Assumptions!$B$5/F5 | G7: =Assumptions!$B$5/G5 | H7: =Assumptions!$B$5/H5 | I7: =Assumptions!$B$5/I5
A8: Price / book (at spot) | B8: =Assumptions!$B$5/B6 | C8: =Assumptions!$B$5/C6 | D8: =Assumptions!$B$5/D6 | E8: =Assumptions!$B$5/E6 | F8: =Assumptions!$B$5/F6 | G8: =Assumptions!$B$5/G6 | H8: =Assumptions!$B$5/H6 | I8: =Assumptions!$B$5/I6
A9: EBITDA per tonne (EGP) | D9: ='Income Statement'!D14/'Segments'!B55 | E9: ='Income Statement'!E14/'Segments'!C55 | F9: ='Income Statement'!F14/'Segments'!D55 | G9: ='Income Statement'!G14/'Segments'!E55 | H9: ='Income Statement'!H14/'Segments'!F55 | I9: ='Income Statement'!I14/'Segments'!G55
A10: Return on equity | B10: ='Balance Sheet'!B18 | C10: ='Balance Sheet'!C18 | D10: ='Balance Sheet'!D18 | E10: ='Balance Sheet'!E18 | F10: ='Balance Sheet'!F18 | G10: ='Balance Sheet'!G18 | H10: ='Balance Sheet'!H18 | I10: ='Balance Sheet'!I18
A11: Net (cash) / EBITDA | B11: ='Balance Sheet'!B16/'Income Statement'!B14 | C11: ='Balance Sheet'!C16/'Income Statement'!C14 | D11: ='Balance Sheet'!D16/'Income Statement'!D14 | E11: ='Balance Sheet'!E16/'Income Statement'!E14 | F11: ='Balance Sheet'!F16/'Income Statement'!F14 | G11: ='Balance Sheet'!G16/'Income Statement'!G14 | H11: ='Balance Sheet'!H16/'Income Statement'!H14 | I11: ='Balance Sheet'!I16/'Income Statement'!I14
A13: RECONCILIATIONS AGAINST THE AUDITED ACCOUNTS
A14: Shares issued (audited note 20) | B14: =Assumptions!$B$6
A15: Less treasury shares (audited note 21) | B15: =-Assumptions!$B$7
A16: Shares outstanding — ADOPTED | B16: =B14+B15
A17: Shares implied by the FY2025 dividend at EGP 5.34 per share | B17: =Assumptions!$B$131/5.34
A18: Difference | B18: =B17/B16-1
A19: Issued capital implied at EGP 2 par (EGP mn) | B19: =Assumptions!$B$6*2
A20: Q1-2026 revenue growth on Q1-2025 | B20: =Assumptions!$B$133/Assumptions!$B$134-1
A21: FY2026 revenue implied by holding that growth | B21: =Assumptions!$B$55*Assumptions!$B$133/Assumptions!$B$134
A22: FY2026 revenue this model forecasts | B22: =DCF!B5
A23: The forecast against the run rate | B23: =B22/B21-1
A24: Q1-2026 gross margin | B24: =Assumptions!$B$135/Assumptions!$B$133
A25: FY2025 gross margin | B25: ='Income Statement'!D8
A26: Q1-2026 attributable profit annualised at four times | B26: =4*Assumptions!$B$136
A27: FY2026 profit this model forecasts | B27: ='Income Statement'!E20
A28: The forecast against the annualised first quarter | B28: =B27/B26-1
A29: Q1-2026 net cash, free of the declared dividend | B29: =Assumptions!$B$137-Assumptions!$B$138-Assumptions!$B$149
A30: Net cash at the valuation date in this model | B30: =DCF!B40
A32: The share count is now read directly from the audited capital and treasury notes, and the FY2025
A33: dividend divides to the same count exactly. Revision 1 reached 374.87mn by triangulation and was
A34: right; this is the confirmation rather than the estimate.

Sheet Peer & Sector
A1: Peer set and the Egyptian cement balance
B4: Revenue (EGP mn) | C4: Profit (EGP mn) | D4: Market cap (EGP mn) | E4: Price / earnings | F4: Price / sales | G4: Net margin
A5: Arabian Cement (ARCC) | B5: =Assumptions!$B$55 | C5: =Assumptions!$B$76 | D5: =DCF!C45 | E5: =D5/C5 | F5: =D5/B5 | G5: =C5/B5
A6: Sinai Cement (SCEM) | B6: =Assumptions!$B$164 | C6: =Assumptions!$B$165 | D6: =Assumptions!$B$166 | E6: =D6/C6 | F6: =D6/B6 | G6: =C6/B6
A7: Misr Beni Suef Cement (MBSC) | B7: =Assumptions!$B$167 | C7: =Assumptions!$B$168 | D7: =Assumptions!$B$169 | E7: =D7/C7 | F7: =D7/B7 | G7: =C7/B7
A9: Peer average price / earnings (excluding the subject) | E9: =AVERAGE(E6:E7)
A10: Subject premium / (discount) to the peer average | E10: =E5/E9-1
A12: THE EGYPTIAN CEMENT BALANCE
A13: Nameplate capacity (Mt) | B13: =Assumptions!$B$159
A14: Production 2025 (Mt) | B14: =Assumptions!$B$160
A15: Domestic consumption 2025 (Mt) | B15: =Assumptions!$B$161
A16: Exports 2025 (Mt) | B16: =Assumptions!$B$162
A17: Dormant capacity under revival (Mt) | B17: =Assumptions!$B$163
A18: Sector utilisation | B18: =B14/B13
A19: The subject as a share of national capacity | B19: =Assumptions!$B$13/B13
A20: Revival capacity as a share of consumption | B20: =B17/B15
A21: The subject's own volume as a share of national production | B21: ='Segments'!B18/B14
A23: Every multiple here is RECOMPUTED from revenue, profit and market capitalisation rather than
A24: quoted, because the published multiples for this peer set do not reconcile.
